# Ancient Warfare Structure Template File
# Auto-generated structure template file. created on: 4/22/2023 at: 16:36:57
# Lines beginning with # denote comments

header:
version=2.11
name=SB_T2Keep_Brick_jacaranda
mods=biomesoplenty
size=48,30,45
offset=36,1,44
:endheader

#### VALIDATION ####
validation:
type=ground
structureAuthor=TheOddlySeagull
survival=true
worldGenEnabled=false
unique=false
preserveBlocks=false
preventNaturalHostileSpawns=false
selectionWeight=1
clusterValue=1
minDuplicateDistance=1
dimensionWhiteList=true
dimensionList=
biomeGroupList=
biomeWhiteList=true
biomeList=
leveling=0
fill=0
border=0
blockSwap=false
territoryName=
biomeReplacement=minecraft:
minGenerationHeight=0
maxGenerationHeight=255
:endvalidation

#### LAYERS ####
layer: 0
1,1,1,1,1,1,1,1,1,1,1,1,1,1,1,1,1,1,1,1,1,1,1,1,1,1,1,1,1,1,1,1,1,1,1,1,1,1,1,1,1,1,1,1,1,1,1,1
1,1,2,2,2,2,2,1,1,1,1,1,1,1,1,1,1,1,1,1,1,1,1,1,1,1,1,1,1,1,1,1,1,1,1,1,1,1,1,1,1,2,2,2,2,2,1,1
1,2,2,2,2,2,2,2,1,1,1,1,1,1,1,1,1,1,1,1,1,1,1,1,2,2,2,2,2,1,1,1,1,1,1,1,1,1,1,1,2,2,2,2,2,2,2,1
1,2,2,3,3,3,2,2,2,2,2,2,2,2,2,2,2,2,2,2,2,2,2,2,2,2,2,2,2,2,2,2,2,2,2,2,2,2,2,2,2,2,3,3,3,2,2,1
1,2,2,3,2,3,2,2,2,2,2,2,2,2,2,2,2,2,2,2,2,2,2,2,2,2,2,2,2,2,2,2,2,2,2,2,2,2,2,2,2,2,3,2,3,2,2,1
1,2,2,3,3,3,2,2,2,2,2,2,2,2,2,2,2,2,2,2,2,2,2,2,2,2,2,2,2,2,2,2,2,2,2,2,2,2,2,2,2,2,3,3,3,2,2,1
1,2,2,2,2,2,2,2,4,4,4,4,4,2,8,8,3,3,3,2,2,3,3,3,3,3,3,3,3,3,3,3,2,3,3,3,3,3,3,3,2,2,2,2,2,2,2,1
1,1,2,2,2,2,2,4,4,4,4,4,4,2,8,8,3,3,3,2,2,3,2,2,2,2,2,2,2,2,2,3,2,3,3,3,3,3,3,3,2,2,2,2,2,2,1,1
1,1,1,2,2,2,4,4,4,4,4,4,4,8,8,8,2,3,3,2,2,3,2,2,2,2,2,2,2,2,2,3,2,3,3,3,3,3,3,3,2,3,2,2,2,1,1,1
1,1,1,2,2,2,4,4,4,4,4,4,4,2,3,3,3,3,3,2,2,3,2,2,3,3,3,3,3,2,2,3,2,3,3,3,3,3,3,3,2,3,2,2,2,1,1,1
1,1,1,2,2,2,4,4,4,4,4,4,4,2,3,3,3,3,3,2,2,3,2,2,3,2,2,2,3,2,2,3,2,3,3,3,3,3,3,3,2,3,2,2,2,1,1,1
1,1,1,2,2,2,4,4,4,4,4,4,2,2,2,2,2,2,2,2,2,3,2,2,3,2,2,2,3,2,2,3,2,2,2,2,2,2,2,2,2,2,2,2,2,1,1,1
1,1,1,2,2,2,4,4,4,4,4,4,4,2,1,1,1,1,1,2,2,3,2,2,3,2,2,2,3,2,2,3,2,2,1,1,1,1,2,3,3,3,2,2,2,1,1,1
1,1,1,2,2,2,4,4,2,2,2,2,2,1,1,1,1,1,1,2,2,3,2,2,3,2,2,2,3,2,2,3,2,2,1,1,1,1,2,3,3,3,2,2,2,1,1,1
1,1,1,2,2,2,4,4,2,4,4,4,2,1,1,1,1,1,1,2,2,3,2,2,3,2,2,2,3,2,2,3,2,2,1,1,1,1,2,3,3,3,2,2,2,1,1,1
1,1,1,2,2,2,4,4,2,4,4,4,2,1,1,1,1,1,1,2,2,3,2,2,3,2,2,2,3,2,2,3,2,2,1,1,1,1,2,2,2,2,2,2,2,1,1,1
1,1,1,2,2,2,4,4,2,4,4,4,2,1,1,1,1,1,1,2,2,3,2,2,3,2,2,2,3,2,2,3,2,2,1,1,1,1,1,1,1,1,2,2,2,1,1,1
1,1,1,2,2,2,2,2,2,2,2,2,2,1,1,1,1,1,1,2,2,3,2,2,3,2,2,2,3,2,2,3,2,2,1,1,1,1,1,1,1,1,2,2,2,1,1,1
1,1,1,2,2,2,1,6,1,1,1,1,1,1,1,1,1,1,1,2,2,3,2,2,3,2,2,2,3,2,2,3,2,2,1,1,1,1,1,5,1,1,2,2,2,1,1,1
1,1,1,2,2,2,1,1,6,1,6,1,1,1,1,1,1,1,1,2,2,3,2,2,3,3,3,3,3,2,2,3,2,2,1,1,1,1,1,1,1,1,2,2,2,1,1,1
1,1,1,2,2,2,1,1,1,1,6,6,1,1,1,1,1,1,1,2,2,3,2,2,2,2,2,2,2,2,2,3,2,2,1,1,1,1,1,1,1,1,2,2,2,1,1,1
1,1,1,2,2,2,1,1,1,1,1,1,6,1,1,1,1,1,1,2,2,3,2,2,2,2,2,2,2,2,2,3,2,2,2,2,2,1,1,5,1,1,2,2,2,2,1,1
1,1,2,2,2,2,1,1,1,1,1,1,1,6,1,1,1,2,2,2,2,2,3,3,3,3,3,3,3,3,3,2,2,2,2,2,2,1,1,1,4,4,2,2,2,2,1,1
1,1,2,2,2,2,1,1,1,1,1,1,6,6,6,1,1,2,3,3,3,2,2,2,2,2,2,2,2,2,2,2,3,3,3,2,2,1,1,1,4,4,2,2,2,2,1,1
1,1,2,2,2,2,1,1,1,1,1,1,1,6,6,1,1,2,3,2,3,2,2,2,1,6,6,6,1,2,2,2,3,2,3,2,2,2,2,2,2,2,2,2,2,1,1,1
1,1,1,2,2,2,1,1,1,1,1,1,1,1,6,1,1,2,3,3,3,2,1,1,1,6,6,6,1,1,1,2,3,3,3,2,2,2,2,2,2,2,2,2,2,1,1,1
1,1,1,2,2,2,1,1,1,1,1,1,1,1,6,6,6,2,2,2,2,2,1,1,1,6,6,6,1,1,1,2,2,2,2,2,1,1,6,6,1,1,2,2,2,1,1,1
1,1,1,2,2,2,1,1,1,1,1,1,1,1,1,6,6,3,2,3,2,3,1,1,6,6,6,6,6,1,1,1,1,1,1,1,1,1,6,6,1,1,2,2,2,1,1,1
1,1,1,2,2,2,1,1,1,1,1,1,1,6,6,6,6,3,2,3,2,3,6,6,6,6,6,6,6,6,6,6,1,1,1,1,1,6,6,6,1,1,2,2,2,1,1,1
1,1,1,2,2,2,1,1,1,1,1,1,1,1,6,6,6,3,2,3,2,3,6,6,6,6,6,6,6,6,6,6,6,6,1,1,1,6,6,6,1,1,2,2,2,1,1,1
1,1,1,2,2,2,1,1,1,1,1,1,1,6,6,6,6,3,2,3,2,3,6,6,6,6,6,6,6,6,6,6,6,6,6,1,1,6,6,1,1,1,2,2,2,1,1,1
1,1,1,2,2,2,1,1,1,1,6,6,6,6,1,1,6,3,2,3,2,3,1,1,1,1,1,1,1,1,6,6,6,6,6,6,1,6,6,1,1,1,2,2,2,1,1,1
1,1,1,2,2,2,1,1,6,6,6,1,1,6,6,1,6,2,2,2,2,2,1,1,1,1,1,1,1,1,1,1,6,6,6,6,1,6,6,1,1,1,2,2,2,1,1,1
1,1,1,2,2,2,1,1,6,6,1,6,6,1,1,1,6,2,3,3,3,2,1,1,1,1,1,1,1,1,1,1,1,6,6,6,6,6,6,1,1,1,2,2,2,1,1,1
1,1,1,2,2,2,1,5,7,7,5,7,7,5,1,6,1,2,3,2,3,2,1,1,1,1,1,1,1,1,1,1,1,6,6,6,6,6,6,1,1,1,2,2,2,1,1,1
1,1,1,2,2,2,1,9,6,1,9,6,1,9,5,7,7,2,3,3,3,2,1,1,1,1,1,1,1,1,1,1,1,1,6,6,6,6,6,1,1,1,2,2,2,1,1,1
1,1,1,2,2,2,1,9,1,6,9,6,6,9,9,6,6,2,2,2,2,2,1,1,1,1,1,1,1,1,1,1,1,1,6,6,6,6,6,1,1,1,2,2,2,1,1,1
1,1,2,2,2,2,2,9,6,1,9,1,1,9,9,6,6,6,2,2,2,1,1,1,1,1,1,2,2,2,2,2,1,1,6,6,6,6,6,1,1,2,2,2,2,2,1,1
1,2,2,2,2,2,2,2,1,1,5,6,1,5,9,6,6,6,2,2,2,1,1,1,1,1,2,2,2,2,2,2,2,3,3,3,3,3,3,3,2,2,2,2,2,2,2,1
1,2,2,3,3,3,2,2,2,2,2,2,2,2,2,2,2,2,2,2,2,2,2,2,2,2,2,2,3,3,3,2,2,2,2,2,2,2,2,2,2,2,3,3,3,2,2,1
1,2,2,3,2,3,2,2,2,2,2,2,2,2,2,2,2,2,2,2,2,2,2,2,2,2,2,2,3,2,3,2,2,3,3,2,3,2,3,3,2,2,3,2,3,2,2,1
1,2,2,3,3,3,2,2,2,2,2,2,2,2,2,2,2,2,2,2,2,2,2,2,2,2,2,2,3,3,3,2,2,2,2,2,2,2,2,2,2,2,3,3,3,2,2,1
1,2,2,2,2,2,2,2,1,1,1,1,1,1,2,2,1,1,1,1,1,1,1,1,1,1,2,2,2,2,2,2,2,3,3,2,3,2,3,3,2,2,2,2,2,2,2,1
1,1,2,2,2,2,2,1,1,1,1,1,1,1,1,1,1,1,1,1,1,1,1,1,1,1,1,2,2,2,2,2,1,1,3,2,3,2,3,1,1,2,2,2,2,2,1,1
1,1,1,1,1,1,1,1,1,1,1,1,1,1,1,1,1,1,1,1,1,1,1,1,1,1,1,1,1,1,1,1,1,1,3,2,3,2,3,1,1,1,1,1,1,1,1,1
:endlayer
layer: 1
0,0,0,0,0,0,0,0,0,0,0,0,0,0,0,0,0,0,0,0,0,0,0,0,0,0,0,0,0,0,0,0,0,0,0,0,0,0,0,0,0,0,0,0,0,0,0,0
0,0,2,2,2,2,2,0,0,0,0,0,0,0,0,0,0,0,0,0,0,0,0,0,0,0,0,0,0,0,0,0,0,0,0,0,0,0,0,0,0,2,2,2,2,2,0,0
0,2,2,2,2,2,2,2,0,0,0,0,0,0,0,0,0,0,0,0,0,0,0,0,2,2,2,2,2,0,0,0,0,0,0,0,0,0,0,0,2,2,2,2,2,2,2,0
0,2,2,3,3,3,2,2,2,2,2,2,2,2,2,2,2,2,2,2,2,2,2,2,2,2,2,2,2,2,2,2,2,2,2,2,2,2,2,2,2,2,3,3,3,2,2,0
0,2,2,3,2,3,2,2,2,2,2,2,2,2,2,2,2,2,2,2,2,2,2,2,2,2,2,2,2,2,2,2,2,2,2,2,2,2,2,2,2,2,3,2,3,2,2,0
0,2,2,3,3,3,2,2,2,2,2,2,2,2,2,2,2,2,2,2,2,2,2,2,2,0,0,0,2,2,2,2,2,2,2,2,2,2,2,2,2,2,3,3,3,2,2,0
0,2,2,2,2,2,2,2,4,23,0,0,5,2,0,0,0,0,0,2,2,0,0,0,18,8,8,8,18,0,0,5,2,0,0,0,0,0,0,0,2,2,2,2,2,2,2,0
0,0,2,2,2,2,2,0,4,24,5,0,0,2,0,0,0,0,0,0,0,0,0,0,0,0,0,0,0,0,0,5,2,0,0,0,0,0,0,0,2,2,2,2,2,2,0,0
0,0,0,2,2,2,0,0,4,0,0,0,0,0,0,0,2,0,0,0,0,0,0,0,0,0,0,0,0,0,0,0,2,0,0,0,0,0,0,0,13,0,2,2,2,0,0,0
0,0,0,2,2,2,5,0,5,0,0,0,0,2,0,0,21,8,0,0,0,0,0,0,0,0,0,0,0,0,0,0,0,0,0,0,0,0,0,0,13,0,2,2,2,0,0,0
0,0,0,2,2,2,0,0,0,0,0,0,5,2,0,0,21,8,8,2,2,0,0,0,0,0,0,0,0,0,0,0,2,0,0,0,0,0,0,0,13,0,2,2,2,0,0,0
0,0,0,2,2,2,0,0,0,0,0,0,2,2,2,2,2,2,2,2,2,5,0,0,0,0,0,0,0,0,0,5,2,2,2,0,2,2,2,0,2,2,2,2,2,0,0,0
0,0,0,2,2,2,0,0,0,0,0,0,4,2,0,0,0,0,0,2,2,5,0,0,0,0,0,0,0,0,0,5,2,2,0,0,0,0,2,0,0,0,2,2,2,0,0,0
0,0,0,2,2,2,0,0,5,4,4,4,5,0,0,0,12,0,0,20,2,0,0,0,0,0,0,0,0,0,0,0,2,16,0,12,0,0,2,0,0,0,2,2,2,0,0,0
0,0,0,2,2,2,0,0,4,0,0,0,4,0,0,0,0,0,0,3,2,19,0,0,0,0,12,0,0,0,0,17,2,3,0,0,0,0,2,0,0,0,2,2,2,0,0,0
0,0,0,2,2,2,0,0,0,0,0,0,4,0,0,0,0,0,0,20,2,0,0,0,0,0,0,0,0,0,0,0,2,16,0,0,0,0,2,2,0,2,2,2,2,0,0,0
0,0,0,2,2,2,0,0,4,0,0,0,4,0,0,0,0,0,0,2,2,5,0,0,0,0,0,0,0,0,0,5,2,2,0,0,0,0,0,0,0,0,2,2,2,0,0,0
0,0,0,2,2,2,5,0,5,4,4,4,5,0,0,0,0,0,0,2,2,5,0,0,0,0,0,0,0,0,0,5,2,2,0,0,0,0,0,0,0,0,2,2,2,0,0,0
0,0,0,2,2,2,0,0,0,0,0,0,0,0,0,12,0,0,0,20,2,0,0,0,0,0,0,0,0,0,0,0,2,16,0,0,0,0,0,5,0,0,2,2,2,0,0,0
0,0,0,2,2,2,0,0,0,0,0,0,0,0,0,0,0,0,0,3,2,19,0,0,0,0,0,0,0,0,0,17,2,3,0,0,0,12,0,0,0,0,2,2,2,0,0,0
0,0,0,2,2,2,22,22,22,0,0,0,0,0,0,0,0,0,0,20,2,0,0,0,0,0,0,0,0,0,0,0,2,16,0,0,0,0,0,0,0,0,2,2,2,0,0,0
0,0,0,2,2,2,0,12,22,22,22,0,0,0,0,0,0,0,0,2,2,5,0,0,0,0,0,0,0,0,0,5,2,2,14,14,14,0,0,5,10,10,2,2,2,2,0,0
0,0,2,2,2,2,0,0,0,0,22,22,0,0,0,0,0,2,2,2,2,5,0,0,0,0,0,0,0,0,0,5,2,2,2,2,15,0,0,0,11,11,2,2,2,2,0,0
0,0,2,2,2,2,0,0,0,0,0,22,0,0,0,0,0,2,3,3,3,2,2,2,2,0,0,0,2,2,2,2,3,3,3,2,15,0,0,0,0,0,2,2,2,2,0,0
0,0,2,2,2,2,0,0,0,0,0,22,22,0,0,0,0,2,3,2,3,2,2,2,0,0,0,0,0,2,2,2,3,2,3,2,2,2,0,0,2,2,2,2,2,0,0,0
0,0,0,2,2,2,0,0,0,0,0,0,22,0,0,0,12,2,3,3,3,2,0,0,0,0,0,0,0,0,0,2,3,3,3,2,2,2,0,0,2,2,2,2,2,0,0,0
0,0,0,2,2,2,0,0,0,0,0,0,22,0,0,0,0,2,2,2,2,2,0,0,0,0,0,0,0,0,0,2,2,2,2,2,0,0,0,0,0,0,2,2,2,0,0,0
0,0,0,2,2,2,0,0,0,12,0,0,22,0,0,0,0,0,0,0,0,0,0,0,0,0,0,0,0,0,0,0,0,0,0,0,0,0,0,0,0,0,2,2,2,0,0,0
0,0,0,2,2,2,0,0,0,0,0,22,22,0,0,0,0,0,0,0,0,0,0,0,0,0,0,0,0,0,0,0,0,0,0,12,0,0,0,0,0,0,2,2,2,0,0,0
0,0,0,2,2,2,0,0,22,22,22,22,0,0,0,0,0,0,0,0,0,0,0,0,0,0,0,0,0,0,0,0,0,0,0,0,0,0,0,0,0,12,2,2,2,0,0,0
0,0,0,2,2,2,22,22,22,0,0,0,0,0,0,0,0,0,0,0,0,0,0,0,0,0,0,0,0,0,0,0,0,0,0,0,0,0,0,0,0,0,2,2,2,0,0,0
0,0,0,2,2,2,0,0,0,0,0,0,0,0,0,0,0,0,0,0,0,0,0,0,0,0,12,0,0,0,0,0,0,0,0,0,0,0,0,0,0,0,2,2,2,0,0,0
0,0,0,2,2,2,0,0,0,0,0,0,0,0,0,0,0,2,2,2,2,2,0,0,0,0,0,0,0,0,0,0,0,0,0,0,0,0,0,0,0,0,2,2,2,0,0,0
0,0,0,2,2,2,0,0,0,0,0,0,0,0,0,0,0,2,3,3,3,2,0,0,0,0,0,0,0,0,0,0,0,0,0,0,0,0,0,0,0,0,2,2,2,0,0,0
0,0,0,2,2,2,0,5,0,0,5,0,0,5,0,0,0,2,3,2,3,2,0,0,0,0,0,0,0,0,12,0,0,0,0,0,0,0,0,0,0,0,2,2,2,0,0,0
0,0,0,2,2,2,0,22,0,0,22,0,0,0,5,0,5,2,3,3,3,2,0,12,0,0,0,0,0,0,0,0,0,0,0,0,0,0,0,12,0,0,2,2,2,0,0,0
0,0,0,2,2,2,0,22,0,0,22,0,0,0,4,0,0,2,2,2,2,2,0,0,0,0,0,0,0,0,0,0,0,0,0,0,0,0,0,0,0,0,2,2,2,0,0,0
0,0,2,2,2,2,2,22,0,0,22,0,0,0,4,0,0,0,2,2,2,0,0,0,0,0,0,2,2,2,2,2,0,0,0,0,0,0,0,0,0,2,2,2,2,2,0,0
0,2,2,2,2,2,2,2,0,0,5,0,0,5,4,0,0,0,2,2,2,0,0,0,0,0,2,2,2,2,2,2,2,0,0,0,0,0,0,0,2,2,2,2,2,2,2,0
0,2,2,3,3,3,2,2,2,2,2,2,2,2,2,2,2,2,2,2,2,2,2,2,2,2,2,2,3,3,3,2,2,0,0,0,0,0,0,0,2,2,3,3,3,2,2,0
0,2,2,3,2,3,2,2,2,2,2,2,2,2,2,2,2,2,2,2,2,2,2,2,2,2,2,2,3,2,3,2,2,0,0,0,12,0,0,0,2,2,3,2,3,2,2,0
0,2,2,3,3,3,2,2,2,2,2,2,2,2,2,2,2,2,2,2,2,2,2,2,2,2,2,2,3,3,3,2,2,0,0,0,0,0,0,0,2,2,3,3,3,2,2,0
0,2,2,2,2,2,2,2,0,0,0,0,0,0,2,2,0,0,0,0,0,0,0,0,0,0,2,2,2,2,2,2,2,0,0,0,0,0,0,0,2,2,2,2,2,2,2,0
0,0,2,2,2,2,2,0,0,0,0,0,0,0,0,0,0,0,0,0,0,0,0,0,0,0,0,2,2,2,2,2,0,0,0,0,0,0,0,0,0,2,2,2,2,2,0,0
0,0,0,0,0,0,0,0,0,0,0,0,0,0,0,0,0,0,0,0,0,0,0,0,0,0,0,0,0,0,0,0,0,0,0,0,0,0,0,0,0,0,0,0,0,0,0,0
:endlayer
layer: 2
0,0,0,0,0,0,0,0,0,0,0,0,0,0,0,0,0,0,0,0,0,0,0,0,0,0,0,0,0,0,0,0,0,0,0,0,0,0,0,0,0,0,0,0,0,0,0,0
0,0,2,2,2,2,2,0,0,0,0,0,0,0,0,0,0,0,0,0,0,0,0,0,0,0,0,0,0,0,0,0,0,0,0,0,0,0,0,0,0,2,2,2,2,2,0,0
0,2,2,2,2,2,2,2,0,0,0,0,0,0,0,0,0,0,0,0,0,0,0,0,2,2,2,2,2,0,0,0,0,0,0,0,0,0,0,0,2,2,2,2,2,2,2,0
0,2,2,3,3,3,2,2,2,2,2,2,2,2,2,2,2,2,2,2,2,2,2,2,2,2,2,2,2,2,2,2,2,2,2,2,2,2,2,2,2,2,3,3,3,2,2,0
0,2,2,3,2,3,2,2,2,2,2,2,2,2,2,2,2,2,2,2,2,2,2,2,2,2,2,2,2,2,2,2,2,2,2,2,2,2,2,2,2,2,3,2,3,2,2,0
0,2,2,3,3,3,2,2,2,2,2,2,2,2,2,2,2,2,2,2,2,2,2,2,2,0,0,0,2,2,2,2,2,2,2,2,2,2,2,2,2,2,3,3,3,2,2,0
0,2,2,2,2,2,2,2,4,0,24,23,5,2,0,0,0,0,0,2,2,0,0,0,28,0,0,0,28,0,0,5,2,0,0,0,0,0,0,0,2,2,2,2,2,2,2,0
0,0,2,2,2,2,2,0,4,0,5,0,0,2,0,0,26,0,0,0,0,0,0,0,0,0,0,0,0,0,0,5,2,0,0,0,0,0,0,0,2,2,2,2,2,2,0,0
0,0,0,2,2,2,0,0,4,0,0,0,0,0,21,21,2,0,0,0,0,0,0,0,0,0,0,0,0,0,0,0,2,0,0,0,0,0,0,0,25,0,2,2,2,0,0,0
0,0,0,2,2,2,5,0,5,0,0,0,0,2,8,8,0,0,0,0,0,0,0,0,0,0,0,0,0,0,0,0,0,0,0,0,0,0,0,0,0,0,2,2,2,0,0,0
0,0,0,2,2,2,0,0,0,0,0,0,5,2,8,8,0,0,0,2,2,0,0,0,0,0,0,0,0,0,0,0,2,0,0,0,0,0,0,0,26,0,2,2,2,0,0,0
0,0,0,2,2,2,0,0,0,0,0,0,2,2,2,2,2,2,2,2,2,5,0,0,0,0,0,0,0,0,0,5,2,2,2,0,2,27,2,0,2,2,2,2,2,0,0,0
0,0,0,2,2,2,0,0,0,0,0,0,4,2,0,0,0,0,0,2,2,5,0,0,0,0,0,0,0,0,0,5,2,2,0,0,0,0,2,0,0,0,2,2,2,0,0,0
0,0,0,2,2,2,0,0,5,4,4,4,5,0,0,0,0,0,0,0,27,0,0,0,0,0,0,0,0,0,0,0,27,0,0,0,0,0,27,0,0,0,2,2,2,0,0,0
0,0,0,2,2,2,0,0,4,0,0,0,4,0,0,0,0,0,0,28,27,0,0,0,0,0,0,0,0,0,0,0,27,28,0,0,0,0,2,0,0,0,2,2,2,0,0,0
0,0,0,2,2,2,0,0,0,0,0,0,27,0,0,0,0,0,0,0,27,0,0,0,0,0,0,0,0,0,0,0,27,0,0,0,0,0,2,2,0,2,2,2,2,0,0,0
0,0,0,2,2,2,0,0,4,0,0,0,4,0,0,0,0,0,0,2,2,5,0,0,0,0,0,0,0,0,0,5,2,2,0,0,0,0,0,0,0,0,2,2,2,0,0,0
0,0,0,2,2,2,5,0,5,4,27,4,5,0,0,0,0,0,0,2,2,5,0,0,0,0,0,0,0,0,0,5,2,2,0,0,0,0,0,0,0,0,2,2,2,0,0,0
0,0,0,2,2,2,0,0,0,0,0,0,0,0,0,0,0,0,0,0,27,0,0,0,0,0,0,0,0,0,0,0,27,0,0,0,0,0,0,5,0,0,2,2,2,0,0,0
0,0,0,2,2,2,0,0,0,0,0,0,0,0,0,0,0,0,0,28,27,0,0,0,0,0,0,0,0,0,0,0,27,28,0,0,0,0,0,0,0,0,2,2,2,0,0,0
0,0,0,2,2,2,0,0,0,0,0,0,0,0,0,0,0,0,0,0,27,0,0,0,0,0,0,0,0,0,0,0,27,0,0,0,0,0,0,0,10,10,2,2,2,0,0,0
0,0,0,2,2,2,0,0,0,0,0,0,0,0,0,0,0,0,0,2,2,5,0,0,0,0,0,0,0,0,0,5,2,2,0,0,0,0,0,5,11,11,2,2,2,2,0,0
0,0,2,2,2,2,0,0,0,0,0,0,0,0,0,0,0,2,2,2,2,5,0,0,0,0,0,0,0,0,0,5,2,2,0,2,0,0,0,0,0,0,2,2,2,2,0,0
0,0,2,2,2,2,0,0,0,0,0,0,0,0,0,0,0,2,3,3,3,2,2,2,2,0,0,0,2,2,2,2,0,0,0,0,0,0,0,0,0,0,2,2,2,2,0,0
0,0,2,2,2,2,0,0,0,0,0,0,0,0,0,0,0,2,3,2,3,2,2,2,0,0,0,0,0,2,2,2,0,2,0,2,2,2,0,0,2,2,2,2,2,0,0,0
0,0,0,2,2,2,0,0,0,0,0,0,0,0,0,0,0,2,3,3,3,2,25,0,0,0,0,0,0,0,25,2,0,21,8,2,2,2,0,0,2,2,2,2,2,0,0,0
0,0,0,2,2,2,0,0,0,0,0,0,0,0,0,0,0,2,2,2,2,2,0,0,0,0,0,0,0,0,0,2,2,2,2,2,0,0,0,0,0,0,2,2,2,0,0,0
0,0,0,2,2,2,0,0,0,0,0,0,0,0,0,0,0,0,0,25,0,0,0,0,0,0,0,0,0,0,0,0,0,0,0,0,0,0,0,0,0,0,2,2,2,0,0,0
0,0,0,2,2,2,0,0,0,0,0,0,0,0,0,0,0,0,0,0,0,0,0,0,0,0,0,0,0,0,0,0,0,0,0,0,0,0,0,0,0,0,2,2,2,0,0,0
0,0,0,2,2,2,0,0,0,0,0,0,0,0,0,0,0,0,0,0,0,0,0,0,0,0,0,0,0,0,0,0,0,0,0,0,0,0,0,0,0,0,2,2,2,0,0,0
0,0,0,2,2,2,0,0,0,0,0,0,0,0,0,0,0,0,0,0,0,0,0,0,0,0,0,0,0,0,0,0,0,0,0,0,0,0,0,0,0,0,2,2,2,0,0,0
0,0,0,2,2,2,0,0,0,0,0,0,0,0,0,0,0,0,0,26,0,0,0,0,0,0,0,0,0,0,0,0,0,0,0,0,0,0,0,0,0,0,2,2,2,0,0,0
0,0,0,2,2,2,0,0,0,0,0,0,0,0,0,0,0,2,2,2,2,2,0,0,0,0,0,0,0,0,0,0,0,0,0,0,0,0,0,0,0,0,2,2,2,0,0,0
0,0,0,2,2,2,0,26,0,0,26,0,0,26,0,0,0,2,3,3,3,2,0,0,0,0,0,0,0,0,0,0,0,0,0,0,0,0,0,0,0,0,2,2,2,0,0,0
0,0,0,2,2,2,0,5,0,0,5,0,0,5,0,0,26,2,3,2,3,2,0,0,0,0,0,0,0,0,0,0,0,0,0,0,0,0,0,0,0,0,2,2,2,0,0,0
0,0,0,2,2,2,0,0,0,0,0,0,0,0,5,0,5,2,3,3,3,2,0,0,0,0,0,0,0,0,0,0,0,0,0,0,0,0,0,0,0,0,2,2,2,0,0,0
0,0,0,2,2,2,0,0,0,0,0,0,0,0,4,0,0,2,2,2,2,2,0,0,0,0,0,0,0,0,0,0,0,0,0,0,0,0,0,0,0,0,2,2,2,0,0,0
0,0,2,2,2,2,2,0,0,0,0,0,0,0,22,0,0,0,2,2,2,0,0,0,0,0,0,2,2,2,2,2,0,0,0,0,0,0,0,0,0,2,2,2,2,2,0,0
0,2,2,2,2,2,2,2,0,0,5,0,0,5,4,0,0,0,2,2,2,0,0,0,0,0,2,2,2,2,2,2,2,0,0,0,0,0,0,0,2,2,2,2,2,2,2,0
0,2,2,3,3,3,2,2,2,2,2,2,2,2,2,2,2,2,2,2,2,2,2,2,2,2,2,2,3,3,3,2,2,0,0,0,0,0,0,0,2,2,3,3,3,2,2,0
0,2,2,3,2,3,2,2,2,2,2,2,2,2,2,2,2,2,2,2,2,2,2,2,2,2,2,2,3,2,3,2,2,0,0,0,0,0,0,0,2,2,3,2,3,2,2,0
0,2,2,3,3,3,2,2,2,2,2,2,2,2,2,2,2,2,2,2,2,2,2,2,2,2,2,2,3,3,3,2,2,0,0,0,0,0,0,0,2,2,3,3,3,2,2,0
0,2,2,2,2,2,2,2,0,0,0,0,0,0,2,2,0,0,0,0,0,0,0,0,0,0,2,2,2,2,2,2,2,0,0,0,0,0,0,0,2,2,2,2,2,2,2,0
0,0,2,2,2,2,2,0,0,0,0,0,0,0,0,0,0,0,0,0,0,0,0,0,0,0,0,2,2,2,2,2,0,0,0,0,0,0,0,0,0,2,2,2,2,2,0,0
0,0,0,0,0,0,0,0,0,0,0,0,0,0,0,0,0,0,0,0,0,0,0,0,0,0,0,0,0,0,0,0,0,0,0,0,0,0,0,0,0,0,0,0,0,0,0,0
:endlayer
layer: 3
0,0,0,0,0,0,0,0,0,0,0,0,0,0,0,0,0,0,0,0,0,0,0,0,0,0,0,0,0,0,0,0,0,0,0,0,0,0,0,0,0,0,0,0,0,0,0,0
0,0,2,2,2,2,2,0,0,0,0,0,0,0,0,0,0,0,0,0,0,0,0,0,0,0,0,0,0,0,0,0,0,0,0,0,0,0,0,0,0,2,2,2,2,2,0,0
0,2,2,2,2,2,2,2,0,0,0,0,0,0,0,0,0,0,0,0,0,0,0,0,2,2,2,2,2,0,0,0,0,0,0,0,0,0,0,0,2,2,2,2,2,2,2,0
0,2,2,3,3,3,2,2,2,2,2,2,2,2,2,2,2,2,2,2,2,2,2,2,2,2,2,2,2,2,2,2,2,2,2,2,2,2,2,2,2,2,3,3,3,2,2,0
0,2,2,3,2,3,2,2,2,2,2,2,2,2,2,2,2,2,2,2,2,2,2,2,2,2,2,2,2,2,2,2,2,2,2,2,2,2,2,2,2,2,3,2,3,2,2,0
0,2,2,3,3,3,2,2,2,2,2,2,2,2,2,2,2,2,2,2,2,2,2,2,2,32,0,31,2,2,2,2,2,2,2,2,2,2,2,2,2,2,3,3,3,2,2,0
0,2,2,2,2,2,2,2,4,0,0,0,5,2,8,8,21,0,0,2,2,0,0,25,28,0,0,0,28,25,0,5,2,0,25,0,0,0,25,0,2,2,2,2,2,2,2,0
0,0,2,2,2,2,2,19,4,0,5,24,33,2,8,8,21,0,0,0,25,0,0,0,0,0,0,0,0,0,0,5,2,0,0,0,0,0,0,0,20,2,2,2,2,2,0,0
0,0,0,2,2,2,25,0,4,0,25,23,0,2,0,0,2,19,0,0,0,0,0,0,0,0,0,0,0,0,0,0,2,0,0,0,0,0,0,0,29,0,2,2,2,0,0,0
0,0,0,2,2,2,5,4,5,0,0,0,10,2,0,0,0,0,0,0,26,0,0,0,0,0,0,0,0,0,0,0,31,0,0,0,0,0,0,0,0,0,2,2,2,0,0,0
0,0,0,2,2,2,0,0,0,0,0,0,5,2,0,0,0,0,0,2,2,0,0,0,0,0,0,0,0,0,0,0,2,0,0,0,0,0,0,0,30,0,2,2,2,0,0,0
0,0,0,2,2,2,0,0,0,0,0,0,2,2,2,2,2,27,2,2,2,5,0,0,0,0,0,0,0,0,0,5,2,2,2,2,2,27,2,2,2,2,2,2,2,0,0,0
0,0,0,2,2,2,0,0,26,0,0,0,4,2,0,0,0,0,0,2,2,5,0,0,0,0,0,0,0,0,0,5,2,2,0,0,0,0,2,0,0,0,2,2,2,0,0,0
0,0,0,2,2,2,0,17,5,4,4,4,5,0,0,0,0,0,0,0,27,0,0,0,0,0,0,0,0,0,0,0,27,0,0,0,0,0,27,0,0,17,2,2,2,0,0,0
0,0,0,2,2,2,0,0,4,0,0,0,4,0,0,0,0,0,0,28,27,0,0,0,0,0,0,0,0,0,0,0,27,28,0,0,0,0,2,0,0,0,2,2,2,0,0,0
0,0,0,2,2,2,0,0,4,19,0,0,27,0,0,0,0,0,0,0,27,0,0,0,0,0,0,0,0,0,0,0,27,0,0,0,0,0,2,2,2,2,2,2,2,0,0,0
0,0,0,2,2,2,0,0,4,0,0,0,4,0,0,0,0,0,0,2,2,5,0,0,0,0,0,0,0,0,0,5,2,2,0,0,0,0,0,0,0,0,2,2,2,0,0,0
0,0,0,2,2,2,5,4,5,4,27,4,5,0,0,0,0,0,0,2,2,5,0,0,0,0,0,0,0,0,0,5,2,2,0,0,0,0,0,0,0,0,2,2,2,0,0,0
0,0,0,2,2,2,0,0,0,0,0,0,0,0,0,0,0,0,0,0,27,0,0,0,0,0,0,0,0,0,0,0,27,0,0,0,0,0,0,5,0,0,2,2,2,0,0,0
0,0,0,2,2,2,0,0,0,0,0,0,0,0,0,0,0,0,0,28,27,0,0,0,0,0,0,0,0,0,0,0,27,28,0,0,0,0,0,9,10,10,2,2,2,0,0,0
0,0,0,2,2,2,0,0,0,0,0,0,0,0,0,0,0,0,0,0,27,0,0,0,0,0,0,0,0,0,0,0,27,0,0,0,0,0,0,9,11,11,2,2,2,0,0,0
0,0,0,2,2,2,0,0,0,0,0,0,0,0,0,0,0,0,0,2,2,5,0,0,0,0,0,0,0,0,0,5,2,2,0,0,0,0,0,5,0,0,2,2,2,2,0,0
0,0,2,2,2,2,0,0,0,0,0,0,0,0,0,0,0,2,2,2,2,5,0,0,0,0,0,0,0,0,0,5,2,2,0,2,0,0,0,0,0,0,2,2,2,2,0,0
0,0,2,2,2,2,0,0,0,0,0,0,0,0,0,0,0,2,3,3,3,2,2,2,2,0,0,0,2,2,2,2,0,26,0,0,0,26,0,0,26,0,2,2,2,2,0,0
0,0,2,2,2,2,0,0,0,0,0,0,0,0,0,0,0,2,3,2,3,2,2,2,0,0,0,0,0,2,2,2,21,2,0,2,2,2,32,31,2,2,2,2,2,0,0,0
0,0,0,2,2,2,0,0,0,0,0,0,0,0,0,0,0,2,3,3,3,2,0,0,0,0,0,0,0,0,0,2,8,0,0,2,2,2,32,31,2,2,2,2,2,0,0,0
0,0,0,2,2,2,0,0,0,0,0,0,0,0,0,0,0,2,2,2,2,2,0,0,0,0,0,0,0,0,0,2,2,0,2,2,0,0,0,0,0,0,2,2,2,0,0,0
0,0,0,2,2,2,0,0,0,0,0,0,0,0,0,0,0,0,0,0,0,0,0,0,0,0,0,0,0,0,0,0,0,0,0,0,0,0,0,0,0,0,2,2,2,0,0,0
0,0,0,2,2,2,0,0,0,0,0,0,0,0,0,0,0,0,0,0,0,0,0,0,0,0,0,0,0,0,0,0,0,0,0,0,0,0,0,0,0,0,2,2,2,0,0,0
0,0,0,2,2,2,0,0,0,0,0,0,0,0,0,0,0,0,0,0,0,0,0,0,0,0,0,0,0,0,0,0,0,0,0,0,0,0,0,0,0,0,2,2,2,0,0,0
0,0,0,2,2,2,0,0,0,0,0,0,0,0,0,0,0,0,0,0,0,0,0,0,0,0,0,0,0,0,0,0,0,0,0,0,0,0,0,0,0,0,2,2,2,0,0,0
0,0,0,2,2,2,0,0,0,0,0,0,0,0,0,0,0,0,0,0,0,0,0,0,0,0,0,0,0,0,0,0,0,0,0,0,0,0,0,0,0,0,2,2,2,0,0,0
0,0,0,2,2,2,0,0,0,0,0,0,0,0,0,0,0,2,2,2,2,2,0,0,0,0,0,0,0,0,0,0,0,0,0,0,0,0,0,0,0,0,2,2,2,0,0,0
0,0,0,2,2,2,0,22,0,0,22,0,0,22,0,0,0,2,3,3,3,2,0,0,0,0,0,0,0,0,0,0,0,0,0,0,0,0,0,0,0,0,2,2,2,0,0,0
0,0,0,2,2,2,22,5,0,0,5,0,0,5,0,0,0,2,3,2,3,2,0,0,0,0,0,0,0,0,0,0,0,0,0,0,0,0,0,0,0,0,2,2,2,0,0,0
0,0,0,2,2,2,0,22,0,0,22,0,0,0,5,4,5,2,3,3,3,2,0,0,0,0,0,0,0,0,0,0,0,0,0,0,0,0,0,0,0,0,2,2,2,0,0,0
0,0,0,2,2,2,0,22,0,0,22,0,0,0,4,0,0,2,2,2,2,2,0,0,0,0,0,0,0,0,0,0,0,0,0,0,0,0,0,0,0,0,2,2,2,0,0,0
0,0,2,2,2,2,2,22,0,0,22,0,0,0,4,0,0,0,2,2,2,0,0,0,0,0,0,2,2,2,2,2,0,0,0,0,0,0,0,0,0,2,2,2,2,2,0,0
0,2,2,2,2,2,2,2,0,0,5,0,0,5,4,0,0,0,2,2,2,0,0,0,0,0,2,2,2,2,2,2,2,0,0,0,0,0,0,0,2,2,2,2,2,2,2,0
0,2,2,3,3,3,2,2,2,2,2,2,2,2,2,2,2,2,2,2,2,2,2,2,2,2,2,2,3,3,3,2,2,0,0,0,0,0,0,0,2,2,3,3,3,2,2,0
0,2,2,3,2,3,2,2,2,2,2,2,2,2,2,2,2,2,2,2,2,2,2,2,2,2,2,2,3,2,3,2,2,19,0,0,0,0,0,17,2,2,3,2,3,2,2,0
0,2,2,3,3,3,2,2,2,2,2,2,2,2,2,2,2,2,2,2,2,2,2,2,2,2,2,2,3,3,3,2,2,0,0,0,0,0,0,0,2,2,3,3,3,2,2,0
0,2,2,2,2,2,2,2,0,0,0,0,0,0,2,2,0,0,0,0,0,0,0,0,0,0,2,2,2,2,2,2,2,0,0,0,0,0,0,0,2,2,2,2,2,2,2,0
0,0,2,2,2,2,2,0,0,0,0,0,0,0,0,0,0,0,0,0,0,0,0,0,0,0,0,2,2,2,2,2,0,0,0,0,0,0,0,0,0,2,2,2,2,2,0,0
0,0,0,0,0,0,0,0,0,0,0,0,0,0,0,0,0,0,0,0,0,0,0,0,0,0,0,0,0,25,0,0,0,0,0,0,0,0,0,0,0,0,0,25,0,0,0,0
:endlayer
layer: 4
0,0,0,0,0,0,0,0,0,0,0,0,0,0,0,0,0,0,0,0,0,0,0,0,0,0,0,0,0,0,0,0,0,0,0,0,0,0,0,0,0,0,0,0,0,0,0,0
0,0,2,2,2,2,2,0,0,0,0,0,0,0,0,0,0,0,0,0,0,0,0,0,0,0,0,0,0,0,0,0,0,0,0,0,0,0,0,0,0,2,2,2,2,2,0,0
0,2,2,2,2,2,2,2,0,0,0,0,0,0,0,0,0,0,0,0,0,0,0,0,2,2,2,2,2,0,0,0,0,0,0,0,0,0,0,0,2,2,2,2,2,2,2,0
0,2,2,3,3,3,2,2,2,2,2,2,2,2,2,2,2,2,2,2,2,2,2,2,2,2,2,2,2,2,2,2,2,2,2,2,2,2,2,2,2,2,3,3,3,2,2,0
0,2,2,3,2,3,2,2,2,2,2,2,2,2,2,2,2,2,2,2,2,2,2,2,2,2,2,2,2,2,2,2,2,2,2,2,2,2,2,2,2,2,3,2,3,2,2,0
0,2,2,3,3,3,2,2,2,2,2,2,2,2,2,2,2,2,2,2,2,2,2,2,2,2,2,2,2,2,2,2,2,2,2,2,2,2,2,2,2,2,3,3,3,2,2,0
0,2,2,2,2,2,2,2,9,23,26,0,5,2,0,0,0,8,8,2,2,0,0,0,8,34,21,34,8,0,0,5,2,0,0,0,0,0,0,0,2,2,2,2,2,2,2,0
0,0,2,2,2,2,2,7,9,23,5,0,9,2,0,0,0,8,8,0,29,0,0,0,0,0,0,0,0,0,0,5,2,0,0,0,0,0,0,0,0,2,2,2,2,2,0,0
0,0,0,2,2,2,9,23,9,23,24,0,9,2,0,0,2,21,21,0,0,0,0,0,0,0,0,0,0,0,0,0,2,0,0,0,0,0,0,0,20,2,2,2,2,0,0,0
0,0,0,2,2,2,9,7,7,7,7,7,9,2,0,0,25,0,0,0,30,0,0,0,0,0,0,0,0,0,0,17,2,0,0,0,0,0,0,0,20,2,2,2,2,0,0,0
0,0,0,2,2,2,9,23,9,23,23,23,5,2,0,0,0,0,0,2,2,0,0,0,0,0,0,0,0,0,0,0,2,0,0,0,0,0,0,0,20,2,2,2,2,0,0,0
0,0,0,2,2,2,9,23,9,23,23,23,2,2,2,27,2,27,2,2,2,5,0,0,0,0,0,0,0,0,0,5,2,2,2,2,2,2,2,2,2,2,2,2,2,0,0,0
0,0,0,2,2,2,9,23,9,23,23,23,9,2,0,0,0,0,0,2,2,5,0,0,0,0,0,0,0,0,0,5,2,2,11,11,11,11,2,0,0,0,2,2,2,0,0,0
0,0,0,2,2,2,9,7,7,7,7,7,9,0,0,0,0,0,0,29,27,0,0,0,0,0,0,0,0,0,0,0,27,29,0,0,0,0,2,0,0,0,2,2,2,0,0,0
0,0,0,2,2,2,9,23,9,23,23,23,9,0,0,0,0,0,0,28,27,0,0,0,0,0,0,0,0,0,0,0,27,28,0,0,0,0,2,0,0,0,2,2,2,0,0,0
0,0,0,2,2,2,9,23,9,23,23,23,9,0,0,0,0,0,0,30,27,0,0,0,0,0,0,0,0,0,0,0,27,30,0,0,0,0,2,2,2,2,2,2,2,0,0,0
0,0,0,2,2,2,9,23,9,23,23,23,9,0,0,0,0,0,0,2,2,5,0,0,0,0,0,0,0,0,0,5,2,2,0,0,0,0,0,0,0,0,2,2,2,0,0,0
0,0,0,2,2,2,5,7,7,7,7,7,5,0,0,0,0,0,0,2,2,5,0,0,0,0,0,0,0,0,0,5,2,2,0,0,0,0,0,0,0,0,2,2,2,0,0,0
0,0,0,2,2,2,0,0,0,0,0,0,0,0,0,0,0,0,0,29,27,0,0,0,0,0,0,0,0,0,0,0,27,29,0,0,0,0,0,5,10,10,2,2,2,0,0,0
0,0,0,2,2,2,0,0,0,0,0,0,0,0,0,0,0,0,0,28,27,0,0,0,0,0,0,0,0,0,0,0,27,28,0,0,0,0,0,22,11,11,2,2,2,0,0,0
0,0,0,2,2,2,0,0,0,0,0,0,0,0,0,0,0,0,0,30,27,0,0,0,0,0,0,0,0,0,0,0,27,30,0,0,0,0,0,22,0,0,2,2,2,0,0,0
0,0,0,2,2,2,0,0,0,0,0,0,0,0,0,0,0,0,0,2,2,5,0,0,0,0,0,0,0,0,0,5,2,2,0,0,0,0,0,5,19,0,2,2,2,2,0,0
0,0,2,2,2,2,0,0,0,0,0,0,0,0,0,0,0,2,2,2,2,5,0,0,0,0,0,0,0,0,0,5,2,2,2,2,0,0,0,0,0,0,2,2,2,2,0,0
0,0,2,2,2,2,0,0,0,0,0,0,0,0,0,0,0,2,3,3,3,2,2,2,2,32,0,31,2,2,2,2,8,21,0,2,0,0,0,0,0,0,2,2,2,2,0,0
0,0,2,2,2,2,0,0,0,0,0,0,0,0,0,0,0,2,3,2,3,2,2,2,0,0,0,0,0,2,2,2,0,2,0,2,2,2,2,2,2,2,2,2,2,0,0,0
0,0,0,2,2,2,0,0,0,0,0,0,0,0,0,0,0,2,3,3,3,2,0,0,0,0,0,0,0,0,0,2,0,0,0,2,2,2,2,2,2,2,2,2,2,0,0,0
0,0,0,2,2,2,0,0,0,0,0,0,0,0,0,0,0,2,2,2,2,2,0,0,0,0,0,0,0,0,0,2,2,21,2,2,0,0,0,0,0,0,2,2,2,0,0,0
0,0,0,2,2,2,0,0,0,0,0,0,0,0,0,0,0,33,0,0,0,33,0,0,0,0,0,0,0,0,0,0,0,0,0,0,0,0,0,0,0,0,2,2,2,0,0,0
0,0,0,2,2,2,0,0,0,0,0,0,0,0,0,0,0,23,0,0,0,23,0,0,0,0,0,0,0,0,0,0,0,0,0,0,0,0,0,0,0,0,2,2,2,0,0,0
0,0,0,2,2,2,0,0,0,0,0,0,0,0,0,0,0,0,0,0,0,0,0,0,0,0,0,0,0,0,0,0,0,0,0,0,0,0,0,0,0,0,2,2,2,0,0,0
0,0,0,2,2,2,0,0,0,0,0,0,0,0,0,0,0,23,0,0,0,23,0,0,0,0,0,0,0,0,0,0,0,0,0,0,0,0,0,0,0,0,2,2,2,0,0,0
0,0,0,2,2,2,0,0,0,0,0,0,0,0,0,0,0,10,0,0,0,10,0,0,0,0,0,0,0,0,0,0,0,0,0,0,0,0,0,0,0,0,2,2,2,0,0,0
0,0,0,2,2,2,0,0,0,0,0,0,0,0,0,0,0,2,2,2,2,2,0,0,0,0,0,0,0,0,0,0,0,0,0,0,0,0,0,0,0,0,2,2,2,0,0,0
0,0,0,2,2,2,24,24,24,24,24,24,24,24,24,0,0,2,3,3,3,2,0,0,0,0,0,0,0,0,0,0,0,0,0,0,0,0,0,0,0,0,2,2,2,0,0,0
0,0,0,2,2,2,24,24,24,24,24,24,24,4,4,23,23,2,3,2,3,2,0,0,0,0,0,0,0,0,0,0,0,0,0,0,0,0,0,0,0,0,2,2,2,0,0,0
0,0,0,2,2,2,23,23,23,23,23,23,23,4,5,7,5,2,3,3,3,2,0,0,0,0,0,0,0,0,0,0,0,0,0,0,0,0,0,0,0,0,2,2,2,0,0,0
0,0,0,2,2,2,23,23,23,23,23,23,23,23,9,0,0,2,2,2,2,2,0,0,0,0,0,0,0,0,0,0,0,0,0,0,0,0,0,0,0,0,2,2,2,0,0,0
0,0,2,2,2,2,2,22,0,0,22,0,0,4,9,0,0,0,2,2,2,0,0,0,0,0,0,2,2,2,2,2,0,0,0,0,0,0,0,0,0,2,2,2,2,2,0,0
0,2,2,2,2,2,2,2,7,7,7,7,7,5,9,0,0,0,2,2,2,0,0,0,0,0,2,2,2,2,2,2,2,0,0,0,0,0,0,0,2,2,2,2,2,2,2,0
0,2,2,3,3,3,2,2,2,2,2,2,2,2,2,2,2,2,2,2,2,2,2,2,2,2,2,2,3,3,3,2,2,0,0,0,0,0,0,0,2,2,3,3,3,2,2,0
0,2,2,3,2,3,2,2,2,2,2,2,2,2,2,2,2,2,2,2,2,2,2,2,2,2,2,2,3,2,3,2,2,0,0,0,0,0,0,0,2,2,3,2,3,2,2,0
0,2,2,3,3,3,2,2,2,2,2,2,2,2,2,2,2,2,2,2,2,2,2,2,2,2,2,2,3,3,3,2,2,0,0,0,0,0,0,0,2,2,3,3,3,2,2,0
0,2,2,2,2,2,2,2,0,0,0,0,0,0,2,2,0,0,0,0,0,0,0,0,0,0,2,2,2,2,2,2,2,0,0,0,0,0,0,0,2,2,2,2,2,2,2,0
0,0,2,2,2,2,2,0,0,0,0,0,0,0,0,0,0,0,0,0,0,0,0,0,0,0,0,2,2,2,2,2,0,0,0,0,0,0,0,0,0,2,2,2,2,2,0,0
0,0,0,0,0,0,0,0,0,0,0,0,0,0,0,0,0,0,0,0,0,0,0,0,0,0,0,0,0,0,0,0,0,0,0,0,0,0,0,0,0,0,0,0,0,0,0,0
:endlayer
layer: 5
0,0,0,0,0,0,0,0,0,0,0,0,0,0,0,0,0,0,0,0,0,0,0,0,0,0,0,0,0,0,0,0,0,0,0,0,0,0,0,0,0,0,0,0,0,0,0,0
0,0,2,2,2,2,2,0,0,0,0,0,0,0,0,0,0,0,0,0,0,0,0,0,0,0,0,0,0,0,0,0,0,0,0,0,0,0,0,0,0,2,2,2,2,2,0,0
0,2,2,2,2,2,2,2,0,0,0,0,0,0,0,0,0,0,0,0,0,0,0,0,2,2,2,2,2,0,0,0,0,0,0,0,0,0,0,0,2,2,2,2,2,2,2,0
0,2,2,3,3,3,2,2,2,2,2,2,2,2,2,2,2,2,2,2,2,2,2,2,2,2,2,2,2,2,2,2,2,2,2,2,2,2,2,2,2,2,3,3,3,2,2,0
0,2,2,3,2,3,2,2,2,2,2,2,2,2,2,2,2,2,2,2,2,2,2,2,2,2,2,2,2,2,2,2,2,2,2,2,2,2,2,2,2,2,3,2,3,2,2,0
0,2,2,3,3,3,2,2,2,2,2,2,2,2,2,2,2,2,2,2,2,2,2,2,2,2,2,2,2,2,2,2,2,2,2,2,2,2,2,2,2,2,3,3,3,2,2,0
0,2,2,2,2,2,2,2,5,0,0,0,5,2,0,0,0,0,0,2,2,38,0,0,0,0,0,0,0,0,37,5,2,33,33,33,33,33,33,33,2,2,2,2,2,2,2,0
0,0,2,2,2,2,2,0,0,0,22,0,0,2,0,0,0,0,0,2,2,38,0,0,0,0,0,0,0,0,37,5,2,0,0,0,0,0,0,0,0,2,2,2,2,2,0,0
0,0,0,2,2,2,5,0,0,0,0,0,0,2,0,17,2,0,0,2,2,23,0,0,0,0,0,0,0,0,0,23,2,0,0,0,0,0,0,0,0,20,2,2,2,0,0,0
0,0,0,2,2,2,0,0,0,39,0,0,0,2,0,0,21,8,8,2,2,0,0,0,0,0,0,0,0,0,0,0,2,0,0,0,0,0,0,0,0,2,2,2,2,0,0,0
0,0,0,2,2,2,0,0,22,4,4,4,5,2,0,0,21,8,8,2,2,23,0,0,0,0,0,0,0,0,0,23,2,10,10,10,10,10,10,10,10,2,2,2,2,0,0,0
0,0,0,2,2,2,0,0,5,0,0,0,2,2,2,27,2,2,2,2,2,5,38,0,0,0,0,0,0,0,37,5,2,2,11,11,11,11,2,2,2,2,2,2,2,0,0,0
0,0,0,2,2,2,0,0,0,0,0,0,4,2,0,0,0,0,0,2,2,5,38,0,0,0,0,0,0,0,37,5,2,2,0,0,0,0,2,32,29,29,2,2,2,0,0,0
0,0,0,2,2,2,5,0,5,0,0,0,5,0,0,0,0,0,0,20,2,23,0,0,0,0,0,0,0,0,0,23,2,16,0,0,0,0,2,32,21,31,2,2,2,0,0,0
0,0,0,2,2,2,0,0,0,4,0,0,4,0,0,0,0,0,0,3,2,0,0,0,0,0,0,0,0,0,0,0,2,3,0,0,0,0,2,30,30,30,2,2,2,0,0,0
0,0,0,2,2,2,0,0,0,0,4,0,4,0,0,0,0,0,0,20,2,23,0,0,0,0,0,0,0,0,0,23,2,16,0,0,0,0,2,2,2,2,2,2,2,0,0,0
0,0,0,2,2,2,0,0,0,0,0,4,4,0,0,0,0,0,0,2,2,5,38,0,0,0,0,0,0,0,37,5,2,2,0,0,0,0,0,0,0,0,2,2,2,0,0,0
0,0,0,2,2,2,5,4,4,4,4,4,5,0,0,0,0,0,0,2,2,5,38,0,0,0,0,0,0,0,37,5,2,2,0,0,0,0,0,0,10,10,2,2,2,0,0,0
0,0,0,2,2,2,0,0,0,0,0,0,0,0,0,0,0,0,0,20,2,23,0,0,0,0,0,0,0,0,0,23,2,16,0,0,0,0,0,5,11,11,2,2,2,0,0,0
0,0,0,2,2,2,0,0,0,0,0,0,0,0,0,0,0,0,0,3,2,0,0,0,0,0,0,0,0,0,0,0,2,3,0,0,0,0,0,0,0,0,2,2,2,0,0,0
0,0,0,2,2,2,0,0,0,0,0,0,0,0,0,0,0,0,0,20,2,23,0,0,0,0,0,0,0,0,0,23,2,16,0,0,0,0,0,0,0,0,2,2,2,0,0,0
0,0,0,2,2,2,0,0,0,0,0,0,0,0,0,0,0,0,0,2,2,5,38,0,0,0,0,0,0,0,37,5,2,2,0,0,0,0,0,24,0,0,2,2,2,2,0,0
0,0,2,2,2,2,0,0,0,0,0,0,0,0,0,0,0,2,2,2,2,5,38,0,0,0,26,0,0,0,37,5,2,2,2,2,0,0,0,0,0,0,2,2,2,2,0,0
0,0,2,2,2,2,0,0,0,0,0,0,0,0,0,0,0,2,3,3,3,2,2,2,2,2,2,2,2,2,2,2,0,0,8,2,0,0,0,0,0,0,2,2,2,2,0,0
0,0,2,2,2,2,0,0,0,0,0,0,0,0,0,0,0,2,3,2,3,2,2,2,32,0,25,0,31,2,2,2,0,2,21,2,35,35,35,35,35,35,2,2,2,0,0,0
0,0,0,2,2,2,0,0,0,0,0,0,0,0,0,0,0,2,3,3,3,2,0,0,0,0,0,0,0,0,0,2,0,25,0,2,36,36,36,36,36,36,2,2,2,0,0,0
0,0,0,2,2,2,0,0,0,0,0,0,0,0,0,0,0,2,2,2,2,2,0,0,0,0,0,0,0,0,0,2,2,2,2,2,0,0,0,0,0,0,2,2,2,0,0,0
0,0,0,2,2,2,0,0,0,0,0,0,0,0,0,0,0,4,9,4,9,4,0,0,0,0,0,0,0,0,0,0,0,0,0,0,0,0,0,0,0,0,2,2,2,0,0,0
0,0,0,2,2,2,0,0,0,0,0,0,0,0,0,0,0,4,9,33,9,4,0,0,0,0,0,0,0,0,0,0,0,0,0,0,0,0,0,0,0,0,2,2,2,0,0,0
0,0,0,2,2,2,0,0,0,0,0,0,0,0,0,0,0,4,9,0,9,4,0,0,0,0,0,0,0,0,0,0,0,0,0,0,0,0,0,0,0,0,2,2,2,0,0,0
0,0,0,2,2,2,0,0,0,0,0,0,0,0,0,0,0,4,9,10,9,4,0,0,0,0,0,0,0,0,0,0,0,0,0,0,0,0,0,0,0,0,2,2,2,0,0,0
0,0,0,2,2,2,0,0,0,0,0,0,0,0,0,0,0,4,9,4,9,4,0,0,0,0,0,0,0,0,0,0,0,0,0,0,0,0,0,0,0,0,2,2,2,0,0,0
0,0,0,2,2,2,0,0,0,0,0,0,0,0,0,0,0,2,2,2,2,2,0,0,0,0,0,0,0,0,0,0,0,0,0,0,0,0,0,0,0,0,2,2,2,0,0,0
0,0,0,2,2,2,0,0,0,0,0,0,0,0,0,0,0,2,3,3,3,2,0,0,0,0,0,0,0,0,0,0,0,0,0,0,0,0,0,0,0,0,2,2,2,0,0,0
0,0,0,2,2,2,0,0,0,0,0,0,0,0,0,0,0,2,3,2,3,2,0,0,0,0,0,0,0,0,0,0,0,0,0,0,0,0,0,0,0,0,2,2,2,0,0,0
0,0,0,2,2,2,0,0,0,12,0,0,0,24,24,24,24,2,3,3,3,2,0,0,0,0,0,0,0,0,0,0,0,0,0,0,0,0,0,0,0,0,2,2,2,0,0,0
0,0,0,2,2,2,0,0,0,0,0,0,0,4,4,23,23,2,2,2,2,2,0,0,0,0,0,0,0,0,0,0,0,0,0,0,0,0,0,0,0,0,2,2,2,0,0,0
0,0,2,2,2,2,2,24,24,24,24,24,24,4,4,0,0,0,2,2,2,0,0,0,0,0,0,2,2,2,2,2,0,0,0,0,0,0,0,0,0,2,2,2,2,2,0,0
0,2,2,2,2,2,2,2,24,24,24,24,24,4,4,23,23,23,2,2,2,0,0,0,0,0,2,2,2,2,2,2,2,32,0,0,0,0,0,31,2,2,2,2,2,2,2,0
0,2,2,3,3,3,2,2,2,2,2,2,2,2,2,2,2,2,2,2,2,2,2,2,2,2,2,2,3,3,3,2,2,0,0,0,0,0,0,0,2,2,3,3,3,2,2,0
0,2,2,3,2,3,2,2,2,2,2,2,2,2,2,2,2,2,2,2,2,2,2,2,2,2,2,2,3,2,3,2,2,0,0,0,0,0,0,0,2,2,3,2,3,2,2,0
0,2,2,3,3,3,2,2,2,2,2,2,2,2,2,2,2,2,2,2,2,2,2,2,2,2,2,2,3,3,3,2,2,0,0,0,0,0,0,0,2,2,3,3,3,2,2,0
0,2,2,2,2,2,2,2,0,0,0,0,0,0,2,2,0,0,0,0,0,0,0,0,0,0,2,2,2,2,2,2,2,32,0,0,0,0,0,31,2,2,2,2,2,2,2,0
0,0,2,2,2,2,2,0,0,0,0,0,0,0,0,0,0,0,0,0,0,0,0,0,0,0,0,2,2,2,2,2,0,0,0,0,0,0,0,0,0,2,2,2,2,2,0,0
0,0,0,0,0,0,0,0,0,0,0,0,0,0,0,0,0,0,0,0,0,0,0,0,0,0,0,0,0,0,0,0,0,0,0,0,0,0,0,0,0,0,0,0,0,0,0,0
:endlayer
layer: 6
0,0,0,0,0,0,0,0,0,0,0,0,0,0,0,0,0,0,0,0,0,0,0,0,0,0,0,0,0,0,0,0,0,0,0,0,0,0,0,0,0,0,0,0,0,0,0,0
0,0,2,2,2,2,2,0,0,0,0,0,0,0,0,0,0,0,0,0,0,0,0,0,0,0,30,0,0,0,0,0,0,0,0,0,0,0,0,0,0,2,2,2,2,2,0,0
0,2,2,2,2,2,2,2,0,0,0,0,0,0,0,0,0,0,0,0,0,0,0,0,2,2,2,2,2,0,0,0,0,0,0,0,0,0,0,0,2,2,2,2,2,2,2,0
0,2,2,3,3,3,2,2,2,2,2,2,2,2,2,2,2,2,2,2,2,2,2,2,2,2,2,2,2,2,2,2,2,2,2,2,2,2,2,2,2,2,3,3,3,2,2,0
0,2,2,3,2,3,2,2,2,2,2,2,2,2,2,2,2,2,2,2,2,2,2,2,2,2,2,2,2,2,2,2,2,2,2,2,2,2,2,2,2,2,3,2,3,2,2,0
0,2,2,3,3,3,2,2,2,2,2,2,2,2,2,2,2,2,2,2,2,2,2,2,2,2,2,2,2,2,2,2,2,2,2,2,2,2,2,2,2,2,3,3,3,2,2,0
0,2,2,2,2,2,2,2,5,0,0,0,5,2,0,0,0,0,0,2,2,9,7,7,7,7,7,7,7,7,7,9,2,40,40,40,40,40,40,40,2,2,2,2,2,2,2,0
0,0,2,2,2,2,2,0,0,0,22,0,0,2,0,0,26,0,0,2,2,9,7,7,7,7,7,7,7,7,7,9,2,33,33,33,33,33,33,33,33,2,2,2,2,2,0,0
0,0,0,2,2,2,5,0,0,0,0,0,0,2,21,21,2,0,0,2,2,9,0,0,0,0,0,0,0,0,0,9,2,0,0,0,0,0,0,0,0,0,2,2,2,0,0,0
0,0,0,2,2,2,0,0,0,39,0,0,0,2,8,8,0,0,0,2,2,9,0,0,0,0,0,0,0,0,0,9,2,10,10,10,10,10,10,10,10,2,2,2,2,0,0,0
0,0,0,2,2,2,19,0,22,4,4,4,5,2,8,8,0,0,0,2,2,9,0,0,0,0,0,0,0,0,0,9,2,11,11,11,11,11,11,11,11,11,2,2,2,0,0,0
0,0,0,2,2,2,0,0,5,0,0,0,2,2,2,2,2,27,2,2,2,9,7,7,7,7,7,7,7,7,7,9,2,2,0,0,0,0,2,2,2,2,2,2,2,0,0,0
0,0,0,2,2,2,0,0,0,0,0,0,4,2,0,0,0,0,0,2,2,9,7,7,7,7,7,7,7,7,7,9,2,2,0,0,0,0,2,2,2,2,2,2,2,0,0,0
0,0,0,2,2,2,5,0,5,0,0,0,5,0,0,0,0,0,0,0,2,9,0,0,0,0,0,0,0,0,0,9,2,0,0,0,0,0,2,2,2,2,2,2,2,0,0,0
0,0,0,2,2,2,0,0,0,4,0,0,4,0,0,0,0,0,0,28,2,9,0,0,0,0,0,0,0,0,0,9,2,28,0,0,0,0,2,2,2,2,2,2,2,0,0,0
0,0,0,2,2,2,0,0,0,0,4,0,27,0,0,0,0,0,0,0,2,9,0,0,0,0,0,0,0,0,0,9,2,0,0,0,0,0,2,2,2,2,2,2,2,0,0,0
0,0,0,2,2,2,0,0,0,0,0,4,4,0,0,0,0,0,0,2,2,9,7,7,7,7,7,7,7,7,7,9,2,2,0,0,0,0,0,9,10,10,2,2,2,0,0,0
0,0,0,2,2,2,5,4,27,4,27,4,5,0,0,0,0,0,0,2,2,9,7,7,7,7,7,7,7,7,7,9,2,2,0,0,0,0,0,9,11,11,2,2,2,0,0,0
0,0,0,2,2,2,0,0,0,0,0,0,0,0,0,0,0,0,0,0,2,9,0,0,0,0,0,0,0,0,0,9,2,0,0,0,0,0,0,5,0,0,2,2,2,0,0,0
0,0,0,2,2,2,0,0,0,0,0,0,0,0,0,0,0,0,0,28,2,9,0,0,0,0,0,0,0,0,0,9,2,28,0,0,0,0,0,0,0,0,2,2,2,0,0,0
0,0,0,2,2,2,0,0,0,0,0,0,0,0,0,0,0,0,0,0,2,9,0,0,0,0,0,0,0,0,0,9,2,0,0,0,0,0,0,0,0,0,2,2,2,30,0,0
0,0,30,2,2,2,0,0,0,0,0,0,0,0,0,0,0,0,0,2,2,9,7,7,7,7,7,7,7,7,7,9,2,2,0,0,0,0,0,0,0,0,2,2,2,2,0,0
0,0,2,2,2,2,0,0,0,0,0,0,0,0,0,0,0,2,2,2,2,9,7,7,7,7,7,7,7,7,7,9,2,2,2,2,0,0,0,0,0,0,2,2,2,2,32,0
0,31,2,2,2,2,0,0,0,0,0,0,0,0,0,0,0,2,0,0,0,2,2,2,2,2,2,2,2,2,2,2,0,0,0,2,0,0,0,0,0,0,2,2,2,2,0,0
0,0,2,2,2,2,0,0,0,0,0,0,0,0,0,0,0,2,21,2,0,2,2,36,2,2,2,2,2,36,2,2,0,2,0,0,0,0,0,0,0,0,2,2,2,29,0,0
0,0,29,2,2,2,0,0,0,0,0,0,0,0,0,0,0,2,8,0,0,2,0,0,0,0,0,0,0,0,0,2,0,21,8,2,0,0,0,0,0,0,2,2,2,0,0,0
0,0,0,2,2,2,0,0,0,0,0,0,0,0,0,0,0,2,2,0,2,2,0,0,0,0,0,0,0,0,0,2,2,2,2,2,0,0,0,0,0,0,2,2,2,0,0,0
0,0,0,2,2,2,0,0,0,0,0,0,0,0,0,0,0,4,0,0,0,4,0,0,0,0,0,0,0,0,0,0,0,0,0,0,0,0,0,0,0,0,2,2,2,0,0,0
0,0,0,2,2,2,0,0,0,0,0,0,0,0,0,0,0,43,0,0,0,42,0,0,0,0,0,0,0,0,0,0,0,0,0,0,0,0,0,0,0,0,2,2,2,0,0,0
0,0,0,2,2,2,0,0,0,0,0,0,0,0,0,0,0,4,19,0,0,4,0,0,0,0,0,0,0,0,0,0,0,0,0,0,0,0,0,0,0,0,2,2,2,0,0,0
0,0,0,2,2,2,0,0,0,0,0,0,0,0,0,0,0,43,0,0,0,42,0,0,0,0,0,0,0,0,0,0,0,0,0,0,0,0,0,0,0,0,2,2,2,0,0,0
0,0,0,2,2,2,0,0,0,0,0,0,0,0,0,0,0,4,0,0,0,4,0,0,0,0,0,0,0,0,0,0,0,0,0,0,0,0,0,0,0,0,2,2,2,0,0,0
0,0,0,2,2,2,0,0,0,0,0,0,0,0,0,0,0,2,2,0,2,2,0,0,0,0,0,0,0,0,0,0,0,0,0,0,0,0,0,0,0,0,2,2,2,0,0,0
0,0,0,2,2,2,0,0,0,0,0,0,0,0,0,0,0,2,0,0,8,2,0,0,0,0,0,0,0,0,0,0,0,0,0,0,0,0,0,0,0,0,2,2,2,0,0,0
0,0,0,2,2,2,0,0,0,0,0,0,0,0,0,0,0,2,0,2,3,2,0,0,0,0,0,0,0,0,0,0,0,0,0,0,0,0,0,0,0,0,2,2,2,0,0,0
0,0,0,2,2,2,0,0,0,0,0,0,0,0,0,0,0,2,3,3,3,2,0,0,0,0,0,0,0,0,0,0,0,0,0,0,0,0,0,0,0,0,2,2,2,0,0,0
0,0,0,2,2,2,0,0,0,0,0,0,0,0,0,12,0,2,2,2,2,2,0,0,0,0,0,0,0,0,0,0,0,0,0,0,0,0,0,0,0,0,2,2,2,0,0,0
0,0,2,2,2,2,2,0,0,0,0,0,0,24,24,24,24,24,2,2,2,0,0,0,0,0,0,2,2,2,2,2,0,0,0,0,0,0,0,0,0,2,2,2,2,2,0,0
0,2,2,2,2,2,2,2,0,0,0,0,0,0,0,0,0,0,2,2,2,0,0,0,0,0,2,2,2,2,2,2,2,2,32,41,0,41,31,2,2,2,2,2,2,2,2,0
0,2,2,3,3,3,2,2,2,2,2,2,2,2,2,2,2,2,2,2,2,2,2,2,2,2,2,2,3,3,3,2,2,0,0,0,0,0,0,0,2,2,3,3,3,2,2,0
0,2,2,3,2,3,2,2,2,2,2,2,2,2,2,2,2,2,2,2,2,2,2,2,2,2,2,2,3,2,3,2,2,0,0,0,0,0,0,0,2,2,3,2,3,2,2,0
0,2,2,3,3,3,2,2,2,2,2,2,2,2,2,2,2,2,2,2,2,2,2,2,2,2,2,2,3,3,3,2,2,0,0,0,0,0,0,0,2,2,3,3,3,2,2,0
0,2,2,2,2,2,2,2,0,0,0,0,0,31,2,2,32,0,0,0,0,0,0,0,0,0,2,2,2,2,2,2,2,2,32,41,0,41,31,2,2,2,2,2,2,2,2,0
0,0,2,2,2,2,2,0,0,0,0,0,0,0,29,29,0,0,0,0,0,0,0,0,0,0,0,2,2,2,2,2,0,0,0,0,0,0,0,0,0,2,2,2,2,2,0,0
0,0,0,0,0,0,0,0,0,0,0,0,0,0,0,0,0,0,0,0,0,0,0,0,0,0,0,0,0,0,0,0,0,0,0,0,0,0,0,0,0,0,0,0,0,0,0,0
:endlayer
layer: 7
0,0,0,0,0,0,0,0,0,0,0,0,0,0,0,0,0,0,0,0,0,0,0,0,0,0,0,0,0,0,0,0,0,0,0,0,0,0,0,0,0,0,0,0,0,0,0,0
0,0,2,2,2,2,2,0,0,0,0,0,0,0,0,0,0,0,0,0,0,0,0,0,41,30,2,30,41,0,0,0,0,0,0,0,0,0,0,0,0,2,2,2,2,2,0,0
0,2,2,2,2,2,2,2,21,46,21,46,21,46,21,46,21,46,21,46,21,46,21,31,2,2,2,2,2,32,21,46,21,46,21,46,21,46,21,46,2,2,2,2,2,2,2,0
0,2,2,3,3,3,2,2,2,2,2,2,2,2,2,2,2,2,2,2,2,2,2,2,2,2,2,2,2,2,2,2,2,2,2,2,2,2,2,2,2,2,3,3,3,2,2,0
0,2,2,3,2,3,2,2,2,2,2,2,2,2,2,2,2,2,2,2,2,2,2,2,2,2,2,2,2,2,2,2,2,2,2,2,2,2,2,2,2,2,3,2,3,2,2,0
0,2,2,3,3,3,2,2,2,2,2,2,2,2,2,2,2,2,2,2,2,2,2,2,2,2,2,2,2,2,2,2,2,2,2,2,2,2,2,2,2,2,3,3,3,2,2,0
0,2,2,2,2,2,2,2,5,33,33,33,5,2,8,8,21,21,21,2,2,4,4,4,4,4,4,4,4,4,4,4,2,0,0,0,0,0,0,0,2,2,2,2,2,2,2,0
0,0,2,2,2,2,2,0,0,0,22,0,33,2,8,8,21,21,21,2,2,4,4,4,4,4,4,4,4,4,4,4,2,40,40,40,40,40,40,40,40,2,2,2,2,2,0,0
0,0,45,2,2,2,5,0,0,0,0,0,0,2,0,0,2,19,0,2,2,4,4,4,4,4,4,4,4,4,4,4,2,7,7,7,7,7,7,7,7,7,2,2,2,44,0,0
0,0,21,2,2,2,38,0,0,39,0,0,10,2,0,0,25,0,0,2,2,4,4,4,4,4,4,4,4,4,4,4,2,11,11,11,11,11,11,11,11,2,2,2,2,21,0,0
0,0,45,2,2,2,38,0,22,4,4,4,5,2,0,0,0,0,0,2,2,4,4,4,4,4,4,4,4,4,4,4,2,0,0,0,0,0,0,0,0,0,2,2,2,44,0,0
0,0,21,2,2,2,38,0,5,0,0,0,2,2,2,27,2,27,2,2,2,4,4,4,4,4,4,4,4,4,4,4,2,16,0,0,0,0,2,2,2,2,2,2,2,21,0,0
0,0,45,2,2,2,38,0,4,0,0,0,4,2,0,0,0,0,0,2,2,4,4,4,4,4,4,4,4,4,4,4,2,16,0,0,0,0,2,2,2,2,2,2,2,44,0,0
0,0,21,2,2,2,5,4,5,0,0,17,5,0,0,0,0,0,0,0,2,4,4,4,4,4,4,4,4,4,4,4,2,0,0,0,0,0,2,2,2,2,2,2,2,21,0,0
0,0,45,2,2,2,38,0,0,4,0,0,4,0,0,0,0,0,0,0,2,4,4,4,4,4,4,4,4,4,4,4,2,0,0,0,0,0,2,2,2,2,2,2,2,44,0,0
0,0,21,2,2,2,38,0,0,0,4,0,27,0,0,0,0,0,0,0,2,4,4,4,4,4,4,4,4,4,4,4,2,0,0,0,0,0,2,2,2,2,2,2,2,21,0,0
0,0,45,2,2,2,38,0,0,26,0,4,4,0,0,0,0,0,0,20,2,4,4,4,4,4,4,4,4,4,4,4,2,16,0,0,0,0,0,22,11,11,2,2,2,44,0,0
0,0,21,2,2,2,5,4,27,4,27,4,5,0,0,0,0,0,0,20,2,4,4,4,4,4,4,4,4,4,4,4,2,16,0,0,0,0,0,22,0,0,2,2,2,21,0,0
0,0,45,2,2,2,44,0,0,0,0,0,0,0,0,0,0,0,0,0,2,4,4,4,4,4,4,4,4,4,4,4,2,0,0,0,0,0,0,5,19,0,2,2,2,44,0,0
0,0,21,2,2,2,44,0,0,0,0,0,0,0,0,0,0,0,0,0,2,4,4,4,4,4,4,4,4,4,4,4,2,0,0,0,0,0,0,0,0,0,2,2,2,21,0,0
0,0,45,2,2,2,44,0,0,0,0,0,0,0,0,0,0,0,0,0,2,4,4,4,4,4,4,4,4,4,4,4,2,0,0,0,0,0,0,0,0,45,2,2,2,2,0,0
0,0,2,2,2,2,44,0,0,0,0,0,0,0,0,0,0,0,0,20,2,4,4,4,4,4,4,4,4,4,4,4,2,16,0,0,0,0,0,0,0,45,2,2,2,2,30,0
0,30,2,2,2,2,44,0,0,0,0,0,0,0,0,0,0,2,2,2,2,2,4,4,4,4,4,4,4,4,4,2,2,2,2,2,0,0,0,0,0,45,2,2,2,2,2,0
0,2,2,2,2,2,44,0,0,0,0,0,0,0,0,0,0,2,8,21,0,2,2,2,2,2,2,2,2,2,2,2,0,26,0,2,0,0,0,0,0,45,2,2,2,2,29,0
0,29,2,2,2,2,44,0,0,0,0,0,0,0,0,0,0,0,0,2,19,2,36,0,36,36,36,36,36,0,36,2,21,2,0,21,0,0,0,0,0,45,2,2,2,2,0,0
0,0,2,2,2,2,44,0,0,0,0,0,0,0,0,0,0,2,0,0,0,2,0,0,0,0,0,0,0,0,0,2,8,0,0,2,0,0,0,0,0,45,2,2,2,21,0,0
0,0,45,2,2,2,44,0,0,0,0,0,0,0,0,0,0,2,2,0,2,2,0,0,0,0,0,0,0,0,0,2,2,0,2,2,0,0,0,0,0,45,2,2,2,44,0,0
0,0,21,2,2,2,44,0,0,0,0,0,0,0,0,0,0,24,0,0,0,24,0,0,0,0,0,0,0,0,0,0,0,0,0,0,0,0,0,0,0,45,2,2,2,21,0,0
0,0,45,2,2,2,44,0,0,0,0,0,0,0,0,0,0,0,0,0,0,0,0,0,0,0,0,0,0,0,0,0,0,0,0,0,0,0,0,0,0,45,2,2,2,44,0,0
0,0,21,2,2,2,44,0,0,0,0,0,0,0,0,0,0,24,0,0,0,24,0,0,0,0,0,0,0,0,0,0,0,0,0,0,0,0,0,0,0,45,2,2,2,21,0,0
0,0,45,2,2,2,44,0,0,0,0,0,0,0,0,0,0,0,0,0,0,0,0,0,0,0,0,0,0,0,0,0,0,0,0,0,0,0,0,0,0,45,2,2,2,44,0,0
0,0,21,2,2,2,44,0,0,0,0,0,0,0,0,0,0,24,0,0,0,24,0,0,0,0,0,0,0,0,0,0,0,0,0,0,0,0,0,0,0,45,2,2,2,21,0,0
0,0,45,2,2,2,44,0,0,0,0,0,0,0,0,0,0,2,2,0,2,2,0,0,0,0,0,0,0,0,0,0,0,0,0,0,0,0,0,0,0,45,2,2,2,44,0,0
0,0,21,2,2,2,44,0,0,0,0,0,0,0,0,0,0,2,0,0,0,2,0,0,0,0,0,0,0,0,0,0,0,0,0,0,0,0,0,0,0,45,2,2,2,21,0,0
0,0,45,2,2,2,44,0,0,0,0,0,0,0,0,0,0,2,0,2,0,2,0,0,0,0,0,0,0,0,0,0,0,0,0,0,0,0,0,0,0,45,2,2,2,44,0,0
0,0,21,2,2,2,44,0,0,0,0,0,0,0,0,0,0,2,3,3,8,2,0,0,0,0,0,0,0,0,0,0,0,0,0,0,0,0,0,0,0,45,2,2,2,21,0,0
0,0,45,2,2,2,44,0,0,0,0,0,0,0,0,0,0,2,2,2,2,2,0,0,0,0,0,0,0,0,0,0,0,0,0,0,0,0,0,0,0,45,2,2,2,44,0,0
0,0,2,2,2,2,2,0,0,0,0,0,0,0,0,0,0,45,2,2,2,44,0,0,0,0,0,2,2,2,2,2,0,0,0,0,0,0,0,0,0,2,2,2,2,2,0,0
0,2,2,2,2,2,2,2,46,46,46,46,46,46,46,46,46,45,2,2,2,44,46,46,46,46,2,2,2,2,2,2,2,2,2,2,2,2,2,2,2,2,2,2,2,2,2,0
0,2,2,3,3,3,2,2,2,2,2,2,2,2,2,2,2,2,2,2,2,2,2,2,2,2,2,2,0,0,8,2,2,2,2,2,2,2,2,2,2,2,3,3,3,2,2,0
0,2,2,3,2,3,2,2,2,2,2,2,2,2,2,2,2,2,2,2,2,2,2,2,2,2,3,8,0,2,3,2,2,32,0,41,0,41,0,31,2,2,3,2,3,2,2,0
0,2,2,3,3,3,2,2,2,2,2,2,2,2,2,2,2,2,2,2,2,2,2,2,2,2,2,2,0,25,3,2,2,2,2,2,2,2,2,2,2,2,3,3,3,2,2,0
0,2,2,2,2,2,2,2,34,21,34,21,34,3,2,2,3,34,21,34,21,34,21,34,21,34,2,2,2,2,2,2,2,2,2,2,2,2,2,2,2,2,2,2,2,2,2,0
0,0,2,2,2,2,2,0,0,0,0,0,0,0,3,3,0,0,0,0,0,0,0,0,0,0,0,2,2,2,2,2,0,0,0,0,0,0,0,0,0,2,2,2,2,2,0,0
0,0,0,0,0,0,0,0,0,0,0,0,0,0,0,0,0,0,0,0,0,0,0,0,0,0,0,0,0,0,0,0,0,0,0,0,0,0,0,0,0,0,0,0,0,0,0,0
:endlayer
layer: 8
0,0,0,0,0,0,0,0,0,0,0,0,0,0,0,0,0,0,0,0,0,0,0,0,0,0,0,0,0,0,0,0,0,0,0,0,0,0,0,0,0,0,0,0,0,0,0,0
0,0,2,2,2,2,2,0,0,0,0,0,0,0,0,0,0,0,0,0,0,0,0,0,8,8,8,8,8,0,0,0,0,0,0,0,0,0,0,0,0,2,2,2,2,2,0,0
0,2,2,2,2,2,2,2,14,3,14,3,14,3,14,3,14,3,14,3,14,3,14,3,0,0,0,0,0,3,14,3,14,3,14,3,14,3,14,3,2,2,2,2,2,2,2,0
0,2,2,0,0,0,2,2,0,0,0,25,0,0,0,0,0,25,0,0,0,0,0,25,0,0,0,0,0,25,0,0,0,0,0,25,0,0,0,0,2,2,8,21,0,2,2,0
0,2,2,21,2,0,0,0,0,0,0,0,0,2,0,0,0,0,0,2,0,0,0,0,0,0,0,0,0,0,0,0,0,0,0,0,0,0,0,0,0,0,0,2,19,2,2,0
0,2,2,8,0,0,2,2,0,0,0,0,2,2,2,0,2,2,2,2,2,2,2,2,2,2,2,2,2,2,2,2,2,8,8,8,8,8,8,8,2,2,0,0,0,2,2,0
0,2,2,2,0,2,2,2,5,7,7,7,7,2,0,0,0,0,0,0,0,0,0,0,0,5,0,0,0,0,0,0,2,0,0,0,0,0,0,0,2,2,2,0,2,2,2,0
0,0,2,2,0,2,2,0,0,0,22,0,9,2,0,0,0,0,0,0,0,0,0,0,0,0,0,0,0,0,0,0,2,0,0,0,0,0,0,0,0,2,2,0,2,2,0,0
0,0,3,19,0,43,5,0,0,0,0,0,9,2,0,17,2,8,8,0,0,0,0,0,0,0,0,0,0,0,0,0,16,24,24,24,24,24,24,24,24,24,47,0,0,3,0,0
0,0,47,0,0,43,9,0,0,39,0,0,9,2,0,0,21,8,8,2,2,0,0,0,0,5,0,0,0,0,0,0,2,0,0,0,0,0,0,0,0,2,3,0,0,15,0,0
0,0,3,0,0,43,9,7,7,7,7,7,9,2,0,0,21,8,8,2,2,0,0,0,0,4,0,0,0,0,0,0,16,0,0,0,0,0,0,0,0,0,47,0,17,3,0,0
0,0,47,0,0,43,9,23,9,23,23,23,2,2,2,27,2,2,2,2,2,0,0,0,0,4,0,0,0,0,0,0,2,0,0,0,0,0,3,14,3,14,3,0,0,15,0,0
0,0,3,0,0,43,9,23,9,23,23,23,9,2,0,0,0,0,0,2,2,0,0,0,0,5,4,4,5,4,4,5,2,0,0,0,0,0,47,0,25,0,0,0,0,3,0,0
0,0,47,0,0,43,9,7,7,7,7,7,9,42,0,0,0,0,0,0,20,0,0,0,0,0,0,0,0,0,0,0,16,0,0,0,0,0,3,0,0,0,0,0,0,15,0,0
0,0,3,19,0,43,9,23,23,9,23,23,9,42,0,0,0,0,0,0,2,0,0,0,0,0,0,0,0,0,0,0,2,0,0,0,0,0,47,0,0,0,0,0,0,3,0,0
0,0,47,0,0,43,9,23,23,9,4,23,9,42,0,0,0,0,0,0,20,0,0,0,0,0,0,0,0,0,0,0,16,0,0,0,0,0,3,18,0,0,0,0,0,15,0,0
0,0,3,0,0,43,9,23,23,9,23,4,9,42,0,0,0,0,0,0,2,5,4,0,0,4,5,4,0,0,4,5,2,0,0,0,0,0,0,0,0,0,3,0,0,3,0,0
0,0,47,0,0,43,5,7,7,7,7,7,5,42,0,0,0,0,0,0,2,0,0,0,0,0,4,0,0,0,0,0,2,0,0,0,0,0,0,0,0,0,47,0,0,15,0,0
0,0,3,0,0,43,3,0,0,0,0,0,37,42,0,0,0,0,0,0,20,0,0,0,0,0,4,0,0,0,0,0,16,0,0,0,0,0,0,24,0,0,3,0,0,3,0,0
0,0,47,0,0,0,15,0,0,0,0,0,0,0,0,0,0,0,0,0,2,0,0,0,0,0,5,0,0,0,0,0,2,0,0,0,0,0,0,0,0,0,15,0,0,15,0,0
0,0,3,19,0,0,3,0,0,0,0,0,0,0,0,0,0,0,0,0,20,0,0,0,0,0,4,0,0,0,0,0,16,0,0,0,0,0,0,0,0,3,0,0,17,3,0,0
0,0,8,0,0,0,15,0,0,0,0,0,0,0,0,0,0,0,0,0,2,0,0,0,0,0,4,0,0,0,0,0,2,0,0,0,0,0,0,0,0,47,0,0,0,0,8,0
0,8,0,0,0,0,3,0,0,0,0,0,0,0,0,0,0,2,2,2,2,2,0,0,0,0,5,0,0,0,0,2,2,2,2,2,0,0,0,0,0,3,0,0,0,0,8,0
0,8,0,0,0,0,15,0,0,0,0,0,0,0,0,0,0,2,0,0,8,2,2,36,2,2,2,2,2,36,2,2,8,21,0,2,0,0,0,0,0,47,0,0,0,0,8,0
0,8,0,0,0,0,3,0,0,0,0,0,0,0,0,0,0,21,0,2,21,2,0,0,0,0,0,0,0,0,0,0,0,2,0,2,0,0,0,0,0,3,0,0,17,3,0,0
0,0,8,0,0,0,15,0,0,0,0,0,0,0,0,0,0,2,0,0,0,2,0,0,0,0,0,0,0,0,0,2,0,0,0,2,0,0,0,0,0,47,0,0,0,15,0,0
0,0,3,19,0,0,3,0,0,0,0,0,0,0,0,0,0,2,2,2,2,2,0,0,0,0,0,0,0,0,0,2,2,21,2,2,0,0,0,0,0,3,0,0,0,3,0,0
0,0,47,0,0,0,15,0,0,0,0,0,0,0,0,0,0,0,0,0,0,0,0,0,0,0,0,0,0,0,0,0,0,0,0,0,0,0,0,0,0,47,0,0,0,15,0,0
0,0,3,0,0,0,3,0,0,0,0,0,0,0,0,0,0,0,0,0,0,0,0,0,0,0,0,0,0,0,0,0,0,0,0,0,0,0,0,0,0,3,0,0,0,3,0,0
0,0,47,0,0,0,15,0,0,0,0,0,0,0,0,0,0,0,0,0,0,0,0,0,0,0,0,0,0,0,0,0,0,0,0,0,0,0,0,0,0,47,0,0,0,15,0,0
0,0,3,0,0,0,3,0,0,0,0,0,0,0,0,0,0,0,0,0,0,0,0,0,0,0,0,0,0,0,0,0,0,0,0,0,0,0,0,0,0,3,0,0,17,3,0,0
0,0,47,0,0,0,15,0,0,0,0,0,0,0,0,0,0,0,0,0,0,0,0,0,0,0,0,0,0,0,0,0,0,0,0,0,0,0,0,0,0,47,0,0,0,15,0,0
0,0,3,19,0,0,3,0,0,0,0,0,0,0,0,0,0,2,2,2,2,2,0,0,0,0,0,0,0,0,0,0,0,0,0,0,0,0,0,0,0,3,0,0,0,3,0,0
0,0,47,0,0,0,15,0,0,0,0,0,0,0,0,0,0,2,0,26,0,2,0,0,0,0,0,0,0,0,0,0,0,0,0,0,0,0,0,0,0,47,0,0,0,15,0,0
0,0,3,0,0,0,3,0,0,0,0,0,0,0,0,0,0,2,21,2,0,2,0,0,0,0,0,0,0,0,0,0,0,0,0,0,0,0,0,0,0,3,0,0,0,3,0,0
0,0,47,0,0,0,15,0,0,0,0,0,0,0,0,0,0,2,8,0,0,2,0,0,0,0,0,0,0,0,0,0,0,0,0,0,0,0,0,0,0,47,0,0,0,15,0,0
0,0,3,0,0,0,3,0,0,0,0,0,0,0,0,0,0,2,2,0,2,2,0,0,0,0,0,0,0,0,0,0,0,0,0,0,0,0,0,0,0,3,0,0,17,3,0,0
0,0,2,2,0,2,2,0,0,0,0,0,0,0,0,0,0,3,0,0,0,3,0,0,0,0,0,2,2,2,2,2,0,0,0,0,0,0,0,0,0,2,2,0,2,2,0,0
0,2,2,2,0,2,2,2,3,14,3,14,3,14,3,14,3,0,0,0,0,0,3,14,3,14,2,2,2,2,2,2,2,7,7,7,7,7,7,7,2,2,2,0,2,2,2,0
0,2,2,0,0,0,2,2,0,0,0,0,0,0,25,0,0,0,0,0,0,0,0,0,0,0,2,2,0,0,0,2,2,18,18,18,18,18,18,18,2,2,0,0,8,2,2,0
0,2,2,0,2,0,0,0,0,0,0,0,0,0,0,0,0,0,0,0,0,0,0,0,0,0,0,0,0,2,0,0,0,8,0,8,0,8,0,8,0,0,0,2,3,2,2,0
0,2,2,0,21,8,2,2,0,0,26,0,0,0,0,0,0,0,0,0,0,26,0,0,0,0,2,2,0,21,8,2,2,14,14,14,14,14,14,14,2,2,0,0,3,2,2,0
0,2,2,2,2,2,2,2,3,18,3,18,3,8,0,0,8,3,18,3,18,3,18,3,18,3,2,2,2,2,2,2,2,7,7,7,7,7,7,7,2,2,2,2,2,2,2,0
0,0,2,2,2,2,2,0,0,0,0,0,0,0,8,8,0,0,0,0,0,0,0,0,0,0,0,2,2,2,2,2,0,0,0,0,0,0,0,0,0,2,2,2,2,2,0,0
0,0,0,0,0,0,0,0,0,0,0,0,0,0,0,0,0,0,0,0,0,0,0,0,0,0,0,0,0,0,0,0,0,0,0,0,0,0,0,0,0,0,0,0,0,0,0,0
:endlayer
layer: 9
0,0,0,0,0,0,0,0,0,0,0,0,0,0,0,0,0,0,0,0,0,0,0,0,0,0,0,0,0,0,0,0,0,0,0,0,0,0,0,0,0,0,0,0,0,0,0,0
0,0,2,2,2,2,2,0,0,0,0,0,0,0,0,0,0,0,0,0,0,0,0,0,0,0,0,0,0,0,0,0,0,0,0,0,0,0,0,0,0,2,2,2,2,2,0,0
0,2,2,2,2,2,2,2,0,8,0,8,0,8,0,8,0,8,0,8,0,8,0,8,0,0,0,0,0,8,0,8,0,8,0,8,0,8,0,8,2,2,2,2,2,2,2,0
0,2,2,8,21,0,2,2,0,0,0,0,0,0,0,0,0,0,0,0,0,0,0,0,0,0,0,0,0,0,0,0,0,0,0,0,0,0,0,0,2,2,0,0,8,2,2,0
0,2,2,0,2,19,0,0,0,0,0,0,0,2,0,0,0,0,0,2,0,0,0,0,0,0,0,0,0,0,0,0,0,0,0,0,0,0,0,0,0,0,0,2,21,2,2,0
0,2,2,0,0,0,2,2,0,0,0,37,2,2,2,0,2,0,2,2,2,2,2,27,2,2,2,2,2,27,2,2,2,0,0,0,0,0,0,0,2,2,0,0,0,2,2,0
0,2,2,2,0,2,2,2,5,4,4,5,42,2,0,0,0,0,0,0,0,0,0,0,0,5,0,0,0,0,0,0,2,0,0,0,0,0,0,0,2,2,2,0,2,2,2,0
0,0,2,2,0,2,2,38,0,0,22,37,42,2,0,0,26,0,0,0,0,0,0,0,0,0,0,0,0,0,0,0,2,0,0,0,0,0,0,0,0,2,2,0,2,2,0,0
0,0,8,0,0,0,43,38,0,0,0,37,42,2,21,21,2,0,0,0,0,0,0,0,0,0,0,0,0,0,0,0,27,0,0,0,0,0,0,0,0,0,0,0,0,8,0,0
0,0,0,0,0,0,43,38,0,0,0,37,42,2,8,8,0,0,0,2,2,0,0,0,0,5,0,0,0,0,0,0,2,0,0,0,0,0,0,0,0,2,8,0,0,0,0,0
0,0,8,0,0,0,43,4,22,12,22,4,42,2,8,8,0,0,0,2,2,0,0,0,0,4,0,0,0,0,0,0,27,0,0,0,0,0,0,0,0,0,0,0,0,8,0,0
0,0,0,0,0,0,43,4,0,0,0,4,2,2,2,2,2,27,2,2,2,0,0,0,0,4,0,0,0,0,0,0,2,0,0,0,0,0,8,0,8,0,8,0,0,0,0,0
0,0,8,0,0,0,43,4,0,0,0,4,42,2,0,0,0,0,0,2,2,0,0,0,0,5,4,4,5,4,4,5,2,0,0,0,0,0,0,0,0,0,0,0,0,8,0,0
0,0,0,0,0,0,43,4,0,0,0,4,42,0,0,0,0,0,0,0,27,0,0,0,0,0,0,0,0,0,0,0,27,0,0,0,0,0,8,0,0,0,0,0,0,0,0,0
0,0,8,0,0,0,43,4,0,0,0,4,42,0,0,0,0,0,0,0,2,0,0,0,0,0,0,0,0,0,0,0,2,0,0,0,0,0,0,0,0,0,0,0,0,8,0,0
0,0,0,0,0,0,43,4,0,0,0,4,42,0,0,0,0,0,0,0,27,0,0,0,0,0,0,0,0,0,0,0,27,0,0,0,0,0,8,0,0,0,0,0,0,0,0,0
0,0,8,0,0,0,43,4,0,0,0,4,42,0,0,0,0,0,0,0,2,5,4,0,0,4,5,4,0,0,4,5,2,0,0,0,0,0,0,0,0,0,8,0,0,8,0,0
0,0,0,0,0,0,43,5,4,4,4,5,42,0,0,0,0,0,0,0,2,0,0,0,0,0,4,0,0,0,0,0,2,0,0,0,0,0,0,0,0,0,0,0,0,0,0,0
0,0,8,0,0,0,43,38,0,0,0,37,42,0,0,0,0,0,0,0,27,0,0,0,0,0,4,0,0,0,0,0,27,0,0,0,0,0,0,0,0,0,8,0,0,8,0,0
0,0,0,0,0,0,0,0,0,0,0,0,0,0,0,0,0,0,0,0,2,0,0,0,0,0,5,0,0,0,0,0,2,0,0,0,0,0,0,0,0,0,0,0,0,0,0,0
0,0,8,0,0,0,8,0,0,0,0,0,0,0,0,0,0,0,0,0,27,0,0,0,0,0,4,0,0,0,0,0,27,0,0,0,0,0,0,0,0,8,0,0,0,8,0,0
0,0,0,0,0,0,0,0,0,0,0,0,0,0,0,0,0,0,0,0,2,0,0,0,0,0,4,0,0,0,0,0,2,0,0,0,0,0,0,0,0,0,0,0,0,0,0,0
0,0,0,0,0,0,8,0,0,0,0,0,0,0,0,0,0,2,2,2,2,2,0,0,0,0,5,0,0,0,0,2,2,0,2,2,0,0,0,0,0,8,0,0,0,0,0,0
0,0,0,0,0,0,0,0,0,0,0,0,0,0,0,0,0,2,0,0,0,2,2,27,2,27,2,27,2,27,2,2,0,0,8,2,0,0,0,0,0,0,0,0,0,0,0,0
0,0,0,0,0,0,8,0,0,0,0,0,0,0,0,0,0,2,17,2,0,0,0,0,0,0,0,0,0,0,0,21,0,2,21,2,0,0,0,0,0,8,0,0,0,8,0,0
0,0,0,0,0,0,0,0,0,0,0,0,0,0,0,0,0,2,0,21,8,2,0,0,0,0,0,0,0,0,0,2,0,25,0,2,0,0,0,0,0,0,0,0,0,0,0,0
0,0,8,0,0,0,8,0,0,0,0,0,0,0,0,0,0,2,2,2,2,2,0,0,0,0,0,0,0,0,0,2,2,2,2,2,0,0,0,0,0,8,0,0,0,8,0,0
0,0,0,0,0,0,0,0,0,0,0,0,0,0,0,0,0,0,0,0,0,0,0,0,0,0,0,0,0,0,0,0,0,0,0,0,0,0,0,0,0,0,0,0,0,0,0,0
0,0,8,0,0,0,8,0,0,0,0,0,0,0,0,0,0,0,0,0,0,0,0,0,0,0,0,0,0,0,0,0,0,0,0,0,0,0,0,0,0,8,0,0,0,8,0,0
0,0,0,0,0,0,0,0,0,0,0,0,0,0,0,0,0,0,0,0,0,0,0,0,0,0,0,0,0,0,0,0,0,0,0,0,0,0,0,0,0,0,0,0,0,0,0,0
0,0,8,0,0,0,8,0,0,0,0,0,0,0,0,0,0,0,0,0,0,0,0,0,0,0,0,0,0,0,0,0,0,0,0,0,0,0,0,0,0,8,0,0,0,8,0,0
0,0,0,0,0,0,0,0,0,0,0,0,0,0,0,0,0,0,0,0,0,0,0,0,0,0,0,0,0,0,0,0,0,0,0,0,0,0,0,0,0,0,0,0,0,0,0,0
0,0,8,0,0,0,8,0,0,0,0,0,0,0,0,0,0,2,2,2,2,2,0,0,0,0,0,0,0,0,0,0,0,0,0,0,0,0,0,0,0,8,0,0,0,8,0,0
0,0,0,0,0,0,0,0,0,0,0,0,0,0,0,0,0,2,8,21,0,2,0,0,0,0,0,0,0,0,0,0,0,0,0,0,0,0,0,0,0,0,0,0,0,0,0,0
0,0,8,0,0,0,8,0,0,0,0,0,0,0,0,0,0,2,0,2,0,2,0,0,0,0,0,0,0,0,0,0,0,0,0,0,0,0,0,0,0,8,0,0,0,8,0,0
0,0,0,0,0,0,0,0,0,0,0,0,0,0,0,0,0,2,0,0,0,2,0,0,0,0,0,0,0,0,0,0,0,0,0,0,0,0,0,0,0,0,0,0,0,0,0,0
0,0,8,0,0,0,8,0,0,0,0,0,0,0,0,0,0,2,2,0,2,2,0,0,0,0,0,0,0,0,0,0,0,0,0,0,0,0,0,0,0,8,0,0,0,8,0,0
0,0,2,2,0,2,2,0,0,0,0,0,0,0,0,0,0,8,0,0,0,8,0,0,0,0,0,2,2,2,2,2,0,0,0,0,0,0,0,0,0,2,2,0,2,2,0,0
0,2,2,2,0,2,2,2,8,0,8,0,8,0,8,0,8,0,0,0,0,0,8,0,8,0,2,2,2,2,2,2,2,5,0,5,0,5,0,5,2,2,2,0,2,2,2,0
0,2,2,0,26,0,2,2,0,0,0,0,0,0,0,0,0,0,0,0,0,0,0,0,0,0,2,2,0,26,0,2,2,0,0,0,0,0,0,0,2,2,0,0,0,2,2,0
0,2,2,21,2,0,0,0,0,0,0,0,0,0,0,0,0,0,0,0,0,0,0,0,0,0,0,0,21,2,0,0,0,0,0,0,0,0,0,0,0,0,17,2,0,2,2,0
0,2,2,8,0,0,2,2,0,0,0,0,0,0,0,0,0,0,0,0,0,0,0,0,0,0,2,2,8,0,0,2,2,0,0,0,0,0,0,0,2,2,0,21,8,2,2,0
0,2,2,2,2,2,2,2,8,0,8,0,8,0,0,0,0,8,0,8,0,8,0,8,0,8,2,2,2,2,2,2,2,5,0,5,0,5,0,5,2,2,2,2,2,2,2,0
0,0,2,2,2,2,2,0,0,0,0,0,0,0,0,0,0,0,0,0,0,0,0,0,0,0,0,2,2,2,2,2,0,0,0,0,0,0,0,0,0,2,2,2,2,2,0,0
0,0,0,0,0,0,0,0,0,0,0,0,0,0,0,0,0,0,0,0,0,0,0,0,0,0,0,0,0,0,0,0,0,0,0,0,0,0,0,0,0,0,0,0,0,0,0,0
:endlayer
layer: 10
0,0,0,0,0,0,0,0,0,0,0,0,0,0,0,0,0,0,0,0,0,0,0,0,0,0,0,0,0,0,0,0,0,0,0,0,0,0,0,0,0,0,0,0,0,0,0,0
0,0,2,2,2,2,2,0,0,0,0,0,0,0,0,0,0,0,0,0,0,0,0,0,0,0,0,0,0,0,0,0,0,0,0,0,0,0,0,0,0,2,2,2,2,2,0,0
0,2,2,2,2,2,2,2,0,0,0,0,0,0,0,0,0,0,0,0,0,0,0,0,0,0,0,0,0,0,0,0,0,0,0,0,0,0,0,0,2,2,2,2,2,2,2,0
0,2,2,0,0,8,2,2,0,0,0,0,0,0,0,0,0,0,0,0,0,0,0,0,0,0,0,0,0,0,0,0,0,0,0,0,0,0,0,0,2,2,0,0,0,2,2,0
0,2,2,0,2,21,2,2,0,0,0,0,0,2,0,0,0,0,0,2,0,0,0,0,0,0,26,0,0,0,0,0,0,0,0,0,0,0,0,0,2,2,17,2,0,2,2,0
0,2,2,0,0,0,2,2,38,0,37,42,2,2,2,2,2,21,2,2,2,2,2,27,2,2,2,2,2,27,2,2,2,0,0,0,0,0,0,0,2,2,0,21,8,2,2,0
0,2,2,2,2,2,2,2,5,4,5,42,0,2,8,8,21,0,0,0,29,0,0,0,0,5,0,0,0,0,0,0,2,0,0,0,0,0,0,0,2,2,2,2,2,2,2,0
0,0,2,2,2,2,2,43,38,0,37,42,0,2,8,8,21,0,0,0,0,0,0,0,0,33,0,0,0,0,0,0,2,0,0,0,0,0,0,0,0,2,2,2,2,2,0,0
0,0,0,0,0,0,0,43,38,0,37,42,0,2,0,0,2,19,0,0,30,0,0,0,0,10,0,0,0,0,0,0,27,0,0,0,0,0,0,0,0,0,0,0,0,0,0,0
0,0,0,0,0,0,0,43,38,0,37,42,0,27,0,0,0,0,0,2,2,0,0,0,0,5,0,0,0,0,0,0,2,0,0,0,0,0,0,0,0,28,0,0,0,0,0,0
0,0,0,0,0,0,0,43,38,0,37,42,0,2,0,0,0,0,0,2,2,0,0,0,0,4,0,0,0,0,0,0,27,0,0,0,0,0,0,0,0,0,0,0,0,0,0,0
0,0,0,0,0,0,0,43,38,0,37,42,2,2,2,27,2,27,2,2,2,0,0,0,0,4,0,0,0,0,0,0,2,0,0,0,0,0,0,0,0,0,0,0,0,0,0,0
0,0,0,0,0,0,0,43,38,0,37,42,0,2,0,0,0,0,0,2,2,0,0,0,0,5,4,4,5,4,4,5,2,0,0,0,0,0,0,0,0,0,0,0,0,0,0,0
0,0,0,0,0,0,0,43,38,0,37,42,0,0,0,0,0,0,0,0,27,0,0,0,0,0,0,0,0,0,0,0,27,0,0,0,0,0,0,0,0,0,0,0,0,0,0,0
0,0,0,0,0,0,0,43,38,0,37,42,0,0,0,0,0,0,0,0,2,0,0,0,0,0,0,0,0,0,0,0,2,0,0,0,0,0,0,0,0,0,0,0,0,0,0,0
0,0,0,0,0,0,0,43,38,0,37,42,0,0,0,0,0,0,0,0,27,0,0,0,0,0,0,0,0,0,0,0,27,0,0,0,0,0,0,0,0,0,0,0,0,0,0,0
0,0,0,0,0,0,0,43,38,26,37,42,0,0,0,0,0,0,0,0,2,5,4,38,37,4,5,4,38,37,4,5,2,0,0,0,0,0,0,0,0,0,0,0,0,0,0,0
0,0,0,0,0,0,0,43,5,4,5,42,0,0,0,0,0,0,0,0,2,0,0,0,0,0,4,0,0,0,0,0,2,0,0,0,0,0,0,0,0,0,0,0,0,0,0,0
0,0,0,0,0,0,0,43,38,0,37,42,0,0,0,0,0,0,0,0,27,0,0,0,0,0,4,0,0,0,0,0,27,0,0,0,0,0,0,0,0,0,0,0,0,0,0,0
0,0,0,0,0,0,0,0,0,0,0,0,0,0,0,0,0,0,0,0,2,0,0,0,0,0,5,0,0,0,0,0,2,0,0,0,0,0,0,0,0,0,0,0,0,0,0,0
0,0,0,0,0,0,0,0,0,0,0,0,0,0,0,0,0,0,0,0,27,0,0,0,0,0,4,0,0,0,0,0,27,0,0,0,0,0,0,0,0,0,0,0,0,0,0,0
0,0,0,0,0,0,0,0,0,0,0,0,0,0,0,0,0,0,0,0,2,0,0,0,0,0,4,0,0,0,0,0,2,0,0,0,0,0,0,0,0,0,0,0,0,0,0,0
0,0,0,0,0,0,0,0,0,0,0,0,0,0,0,0,0,2,2,2,2,2,0,0,0,0,5,0,0,0,0,2,2,21,2,2,0,0,0,0,0,0,0,0,0,0,0,0
0,0,0,0,0,0,0,0,0,0,0,0,0,0,0,0,0,2,0,0,0,2,2,27,2,27,2,27,2,27,2,2,0,0,0,2,0,0,0,0,0,0,0,0,0,0,0,0
0,0,0,0,0,0,0,0,0,0,0,0,0,0,0,0,0,2,21,2,0,21,0,0,0,0,0,0,0,0,0,2,0,2,0,0,0,0,0,0,0,0,0,0,0,0,0,0
0,0,0,0,0,0,0,0,0,0,0,0,0,0,0,0,0,2,8,0,0,2,0,0,0,0,0,0,0,0,0,2,0,21,8,2,0,0,0,0,0,0,0,0,0,0,0,0
0,0,0,0,0,0,0,0,0,0,0,0,0,0,0,0,0,2,2,0,2,2,0,0,0,0,0,0,0,0,0,2,2,2,2,2,0,0,0,0,0,0,0,0,0,0,0,0
0,0,0,0,0,0,0,0,0,0,0,0,0,0,0,0,0,0,0,0,0,0,0,0,0,0,0,0,0,0,0,0,0,0,0,0,0,0,0,0,0,0,0,0,0,0,0,0
0,0,0,0,0,0,0,0,0,0,0,0,0,0,0,0,0,0,0,0,0,0,0,0,0,0,0,0,0,0,0,0,0,0,0,0,0,0,0,0,0,0,0,0,0,0,0,0
0,0,0,0,0,0,0,0,0,0,0,0,0,0,0,0,0,0,0,0,0,0,0,0,0,0,0,0,0,0,0,0,0,0,0,0,0,0,0,0,0,0,0,0,0,0,0,0
0,0,0,0,0,0,0,0,0,0,0,0,0,0,0,0,0,0,0,0,0,0,0,0,0,0,0,0,0,0,0,0,0,0,0,0,0,0,0,0,0,0,0,0,0,0,0,0
0,0,0,0,0,0,0,0,0,0,0,0,0,0,0,0,0,0,0,0,0,0,0,0,0,0,0,0,0,0,0,0,0,0,0,0,0,0,0,0,0,0,0,0,0,0,0,0
0,0,0,0,0,0,0,0,0,0,0,0,0,0,0,0,0,2,2,2,2,2,0,0,0,0,0,0,0,0,0,0,0,0,0,0,0,0,0,0,0,0,0,0,0,0,0,0
0,0,0,0,0,0,0,0,0,0,0,0,0,0,0,0,0,2,0,0,8,2,0,0,0,0,0,0,0,0,0,0,0,0,0,0,0,0,0,0,0,0,0,0,0,0,0,0
0,0,0,0,0,0,0,0,0,0,0,0,0,0,0,0,0,2,0,2,21,2,0,0,0,0,0,0,0,0,0,0,0,0,0,0,0,0,0,0,0,0,0,0,0,0,0,0
0,0,0,0,0,0,0,0,0,0,0,0,0,0,0,0,0,2,0,25,0,2,0,0,0,0,0,0,0,0,0,0,0,0,0,0,0,0,0,0,0,0,0,0,0,0,0,0
0,0,0,0,0,0,0,0,0,0,0,0,0,0,0,0,0,2,2,2,2,2,0,0,0,0,0,0,0,0,0,0,0,0,0,0,0,0,0,0,0,0,0,0,0,0,0,0
0,0,2,2,30,2,2,0,0,0,0,0,0,0,0,0,0,0,0,0,0,0,0,0,0,0,0,2,2,2,2,2,0,0,0,0,0,0,0,0,0,2,2,2,2,2,0,0
0,2,2,2,29,2,2,2,0,0,0,0,0,0,0,0,0,0,0,0,0,0,0,0,0,0,2,2,2,2,2,2,2,5,23,5,23,5,23,5,2,2,2,2,2,2,2,0
0,2,2,8,21,0,2,2,0,0,0,0,0,0,0,0,0,0,0,0,0,0,0,0,0,0,2,2,8,21,0,2,2,0,0,0,0,0,0,0,2,2,0,0,0,2,2,0
0,2,2,0,2,0,31,32,0,0,0,0,0,0,0,0,0,0,0,0,0,0,0,0,0,0,31,32,0,2,0,41,0,0,0,0,0,0,0,0,0,41,21,2,0,2,2,0
0,2,2,0,0,0,2,2,0,0,0,0,0,0,0,0,0,0,0,0,0,0,0,0,0,0,2,2,0,0,0,2,2,0,0,0,0,0,0,0,2,2,8,0,0,2,2,0
0,2,2,2,2,2,2,2,0,0,0,0,0,0,0,0,0,0,0,0,0,0,0,0,0,0,2,2,2,2,2,2,2,5,23,5,23,5,23,5,2,2,2,2,2,2,2,0
0,0,2,2,2,2,2,0,0,0,0,0,0,0,0,0,0,0,0,0,0,0,0,0,0,0,0,2,2,2,2,2,0,0,0,0,0,0,0,0,0,2,2,2,2,2,0,0
0,0,0,0,0,0,0,0,0,0,0,0,0,0,0,0,0,0,0,0,0,0,0,0,0,0,0,0,0,0,0,0,0,0,0,0,0,0,0,0,0,0,0,0,0,0,0,0
:endlayer
layer: 11
0,0,0,0,0,0,0,0,0,0,0,0,0,0,0,0,0,0,0,0,0,0,0,0,0,0,0,0,0,0,0,0,0,0,0,0,0,0,0,0,0,0,0,0,0,0,0,0
0,0,2,2,2,2,2,0,0,0,0,0,0,0,0,0,0,0,0,0,0,0,0,0,0,0,0,0,0,0,0,0,0,0,0,0,0,0,0,0,0,2,2,2,2,2,0,0
0,2,2,2,2,2,2,2,0,0,0,0,0,0,0,0,0,0,0,0,0,0,0,0,0,0,0,0,0,0,0,0,0,0,0,0,0,0,0,0,2,2,2,2,2,2,2,0
0,2,2,0,0,0,2,2,0,0,0,0,0,0,0,0,0,0,0,0,0,0,0,0,0,0,0,0,0,0,0,0,0,0,0,0,0,0,0,0,2,2,0,0,0,2,2,0
0,2,2,17,2,0,2,2,0,0,0,0,0,2,0,0,0,0,0,2,0,0,0,0,0,0,0,0,0,0,0,0,0,0,0,0,0,0,0,0,2,2,21,2,19,2,2,0
0,2,2,0,21,8,2,2,43,10,42,0,2,2,2,0,2,2,2,2,2,2,2,2,2,2,2,2,2,2,2,2,2,0,0,0,0,0,0,0,2,2,8,0,0,2,2,0
0,2,2,2,2,2,2,2,43,5,42,0,0,2,0,0,0,8,8,2,2,0,0,0,0,5,0,0,0,0,0,0,2,0,0,0,0,0,0,0,2,2,2,2,2,2,2,0
0,0,2,2,2,2,2,0,43,9,42,0,0,27,0,0,0,8,8,2,2,0,0,0,0,4,0,0,0,0,0,0,2,0,0,0,0,0,0,0,0,2,2,2,2,2,0,0
0,0,0,0,0,0,0,0,43,9,42,0,0,2,0,17,2,21,21,2,2,0,0,0,0,4,0,0,0,0,0,0,2,0,0,0,0,0,0,0,0,0,0,0,0,0,0,0
0,0,0,0,0,0,0,0,43,9,42,0,0,27,0,0,25,21,21,2,2,0,0,0,0,5,0,0,0,0,0,0,2,0,0,0,0,0,0,0,0,8,0,0,0,0,0,0
0,0,0,0,0,0,0,0,43,9,42,0,0,2,0,0,0,21,21,2,2,0,0,0,0,4,0,0,0,0,0,0,2,0,0,0,0,0,0,0,0,0,0,0,0,0,0,0
0,0,0,0,0,0,0,0,43,9,42,0,2,2,2,27,2,2,2,2,2,0,0,0,0,4,0,0,0,0,0,0,2,0,0,0,0,0,0,0,0,0,0,0,0,0,0,0
0,0,0,0,0,0,0,0,43,9,42,0,0,2,0,0,0,0,0,2,2,0,0,0,0,5,4,4,5,4,4,5,2,0,0,0,0,0,0,0,0,0,0,0,0,0,0,0
0,0,0,0,0,0,0,0,43,9,42,0,0,0,0,0,0,0,0,0,2,0,0,0,0,0,0,0,0,0,0,0,2,0,0,0,0,0,0,0,0,0,0,0,0,0,0,0
0,0,0,0,0,0,0,0,43,9,42,0,0,0,0,0,0,0,0,0,2,0,0,0,0,0,0,0,0,0,0,0,2,0,0,0,0,0,0,0,0,0,0,0,0,0,0,0
0,0,0,0,0,0,0,0,43,9,42,0,0,0,0,0,0,0,0,0,2,0,0,0,0,0,0,0,0,0,0,0,2,0,0,0,0,0,0,0,0,0,0,0,0,0,0,0
0,0,0,0,0,0,0,0,43,9,42,0,0,0,0,0,0,0,0,0,2,5,4,4,4,4,5,4,4,4,4,5,2,0,0,0,0,0,0,0,0,0,0,0,0,0,0,0
0,0,0,0,0,0,0,0,43,5,42,0,0,0,0,0,0,0,0,0,2,0,0,0,0,0,4,0,0,0,0,0,2,0,0,0,0,0,0,0,0,0,0,0,0,0,0,0
0,0,0,0,0,0,0,0,43,33,42,0,0,0,0,0,0,0,0,0,2,0,0,0,0,0,4,0,0,0,0,0,2,0,0,0,0,0,0,0,0,0,0,0,0,0,0,0
0,0,0,0,0,0,0,0,0,0,0,0,0,0,0,0,0,0,0,0,2,0,0,0,0,0,5,0,0,0,0,0,2,0,0,0,0,0,0,0,0,0,0,0,0,0,0,0
0,0,0,0,0,0,0,0,0,0,0,0,0,0,0,0,0,0,0,0,2,0,0,0,0,0,4,0,0,0,0,0,2,0,0,0,0,0,0,0,0,0,0,0,0,0,0,0
0,0,0,0,0,0,0,0,0,0,0,0,0,0,0,0,0,0,0,0,2,0,0,0,0,0,4,0,0,0,0,0,2,0,0,0,0,0,0,0,0,0,0,0,0,0,0,0
0,0,0,0,0,0,0,0,0,0,0,0,0,0,0,0,0,2,2,2,2,2,0,0,0,0,5,0,0,0,0,2,2,2,2,2,0,0,0,0,0,0,0,0,0,0,0,0
0,0,0,0,0,0,0,0,0,0,0,0,0,0,0,0,0,2,8,21,0,2,2,2,2,2,2,2,2,2,2,2,0,26,0,2,0,0,0,0,0,0,0,0,0,0,0,0
0,0,0,0,0,0,0,0,0,0,0,0,0,0,0,0,0,0,0,2,19,2,0,0,0,0,0,0,0,0,0,2,21,2,0,21,0,0,0,0,0,0,0,0,0,0,0,0
0,0,0,0,0,0,0,0,0,0,0,0,0,0,0,0,0,2,0,0,0,2,0,0,0,0,0,0,0,0,0,2,8,0,0,2,0,0,0,0,0,0,0,0,0,0,0,0
0,0,0,0,0,0,0,0,0,0,0,0,0,0,0,0,0,2,2,21,2,2,0,0,0,0,0,0,0,0,0,2,2,0,2,2,0,0,0,0,0,0,0,0,0,0,0,0
0,0,0,0,0,0,0,0,0,0,0,0,0,0,0,0,0,0,0,0,0,0,0,0,0,0,0,0,0,0,0,0,0,0,0,0,0,0,0,0,0,0,0,0,0,0,0,0
0,0,0,0,0,0,0,0,0,0,0,0,0,0,0,0,0,0,0,0,0,0,0,0,0,0,0,0,0,0,0,0,0,0,0,0,0,0,0,0,0,0,0,0,0,0,0,0
0,0,0,0,0,0,0,0,0,0,0,0,0,0,0,0,0,0,0,0,0,0,0,0,0,0,0,0,0,0,0,0,0,0,0,0,0,0,0,0,0,0,0,0,0,0,0,0
0,0,0,0,0,0,0,0,0,0,0,0,0,0,0,0,0,0,0,0,0,0,0,0,0,0,0,0,0,0,0,0,0,0,0,0,0,0,0,0,0,0,0,0,0,0,0,0
0,0,0,0,0,0,0,0,0,0,0,0,0,0,0,0,46,46,46,46,46,46,44,0,0,0,0,0,0,0,0,0,0,0,0,0,0,0,0,0,0,0,0,0,0,0,0,0
0,0,0,0,0,0,0,0,0,0,0,0,0,0,0,0,45,2,2,2,2,2,44,0,0,0,0,0,0,0,0,0,0,0,0,0,0,0,0,0,0,0,0,0,0,0,0,0
0,0,0,0,0,0,0,0,0,0,0,0,0,0,0,0,45,2,0,26,0,2,44,0,0,0,0,0,0,0,0,0,0,0,0,0,0,0,0,0,0,0,0,0,0,0,0,0
0,0,0,0,0,0,0,0,0,0,0,0,0,0,0,0,45,2,21,2,0,2,44,0,0,0,0,0,0,0,0,0,0,0,0,0,0,0,0,0,0,0,0,0,0,0,0,0
0,0,0,0,0,0,0,0,0,0,0,0,0,0,0,0,45,2,21,21,8,2,44,0,0,0,0,0,0,0,0,0,0,0,0,0,0,0,0,0,0,0,0,0,0,0,0,0
0,0,0,0,0,0,0,0,0,0,0,0,0,0,0,0,45,2,2,2,2,2,44,0,0,0,0,0,0,0,0,0,0,0,0,0,0,0,0,0,0,0,0,0,0,0,0,0
0,0,2,2,2,2,2,0,0,0,0,0,0,0,0,0,45,34,34,34,34,34,44,0,0,0,0,2,2,2,2,2,23,23,23,23,23,23,23,23,23,2,2,2,2,2,0,0
0,2,2,2,2,2,2,2,0,0,0,0,0,0,0,0,0,0,0,0,0,0,0,0,0,0,2,2,2,2,2,2,2,7,7,7,7,7,7,7,2,2,2,2,2,2,2,0
0,2,2,0,0,8,2,2,0,0,0,0,0,0,0,0,0,0,0,0,0,0,0,0,0,0,2,2,0,0,8,2,2,0,0,0,25,0,0,0,2,2,8,21,0,2,2,0
0,2,2,0,2,21,2,2,0,0,0,0,0,0,0,0,0,0,0,0,0,0,0,0,0,0,2,2,0,2,21,2,32,0,0,0,0,0,0,0,31,2,0,2,19,2,2,0
0,2,2,0,25,0,2,2,0,0,0,0,0,0,0,0,0,0,0,0,0,0,0,0,0,0,2,2,0,25,0,2,2,0,0,0,26,0,0,0,2,2,0,0,0,2,2,0
0,2,2,2,2,2,2,2,0,0,0,0,0,0,0,0,0,0,0,0,0,0,0,0,0,0,2,2,2,2,2,2,2,7,7,7,7,7,7,7,2,2,2,2,2,2,2,0
0,0,2,2,2,2,2,0,0,0,0,0,0,0,0,0,0,0,0,0,0,0,0,0,0,0,0,2,2,2,2,2,23,23,23,23,23,23,23,23,23,2,2,2,2,2,0,0
0,0,0,0,0,0,0,0,0,0,0,0,0,0,0,0,0,0,0,0,0,0,0,0,0,0,0,0,0,0,0,0,0,0,0,0,0,0,0,0,0,0,0,0,0,0,0,0
:endlayer
layer: 12
0,0,46,21,46,21,46,0,0,0,0,0,0,0,0,0,0,0,0,0,0,0,0,0,0,0,0,0,0,0,0,0,0,0,0,0,0,0,0,0,0,46,21,46,21,46,0,0
0,21,2,2,2,2,2,21,0,0,0,0,0,0,0,0,0,0,0,0,0,0,0,0,0,0,0,0,0,0,0,0,0,0,0,0,0,0,0,0,21,2,2,2,2,2,21,0
45,2,2,2,2,2,2,2,44,0,0,0,0,0,0,0,0,0,0,0,0,0,0,0,0,0,0,0,0,0,0,0,0,0,0,0,0,0,0,45,2,2,2,2,2,2,2,44
21,2,2,21,21,0,2,2,21,0,0,0,0,0,0,0,0,0,0,0,0,0,0,0,0,0,0,0,0,0,0,0,0,0,0,0,0,0,0,21,2,2,8,21,21,2,2,21
45,2,2,21,2,19,2,2,44,0,0,0,0,2,0,0,0,0,0,2,46,21,46,21,46,21,46,21,46,21,46,21,46,0,0,0,0,0,0,45,2,2,17,2,21,2,2,44
21,2,2,8,0,0,2,2,21,24,0,0,2,2,2,21,2,0,2,2,2,2,2,2,2,2,2,2,2,2,2,2,2,44,0,0,0,0,0,21,2,2,0,0,0,2,2,21
45,2,2,2,2,2,2,2,44,24,0,0,0,2,0,0,0,0,0,2,2,23,23,23,23,9,23,23,23,23,23,23,2,21,0,0,0,0,0,45,2,2,2,2,2,2,2,44
0,21,2,2,2,2,2,21,0,24,0,0,0,27,0,0,26,0,0,2,2,23,23,23,23,9,23,23,23,23,23,23,2,44,0,0,0,0,0,0,21,2,2,2,2,2,21,0
0,0,34,21,34,21,34,0,0,24,0,0,0,2,21,21,2,0,0,8,3,7,7,7,7,9,7,7,7,7,7,7,2,21,0,0,0,0,0,0,0,34,21,34,21,34,0,0
0,0,0,0,0,0,0,0,0,24,0,0,0,2,8,8,8,0,0,2,2,23,23,23,23,9,23,23,23,23,23,23,2,44,0,0,0,0,0,0,0,0,0,0,0,0,0,0
0,0,0,0,0,0,0,0,0,24,0,0,0,2,8,8,8,0,0,2,2,23,23,23,23,9,23,23,23,23,23,23,2,21,0,0,0,0,0,0,0,0,0,0,0,0,0,0
0,0,0,0,0,0,0,0,0,24,0,0,2,2,2,2,2,27,2,2,2,23,23,23,23,9,23,23,23,23,23,23,2,44,0,0,0,0,0,0,0,0,0,0,0,0,0,0
0,0,0,0,0,0,0,0,0,24,0,0,0,2,0,0,0,0,0,2,2,7,7,7,7,7,7,7,7,7,7,7,2,21,0,0,0,0,0,0,0,0,0,0,0,0,0,0
0,0,0,0,0,0,0,0,0,24,0,0,0,0,0,0,0,0,0,45,2,23,23,23,9,23,23,23,9,23,23,23,2,44,0,0,0,0,0,0,0,0,0,0,0,0,0,0
0,0,0,0,0,0,0,0,0,24,0,0,0,0,0,0,0,0,0,21,2,23,23,23,9,23,23,23,9,23,23,23,2,21,0,0,0,0,0,0,0,0,0,0,0,0,0,0
0,0,0,0,0,0,0,0,0,24,0,0,0,0,0,0,0,0,0,45,2,23,23,23,9,23,23,23,9,23,23,23,2,44,0,0,0,0,0,0,0,0,0,0,0,0,0,0
0,0,0,0,0,0,0,0,0,24,0,0,0,0,0,0,0,0,0,21,2,7,7,7,7,7,7,7,7,7,7,7,2,21,0,0,0,0,0,0,0,0,0,0,0,0,0,0
0,0,0,0,0,0,0,0,0,24,0,0,0,0,0,0,0,0,0,45,2,23,23,23,23,23,9,23,23,23,23,23,2,44,0,0,0,0,0,0,0,0,0,0,0,0,0,0
0,0,0,0,0,0,0,0,0,24,0,0,0,0,0,0,0,0,0,21,2,23,23,23,23,23,9,23,23,23,23,23,2,21,0,0,0,0,0,0,0,0,0,0,0,0,0,0
0,0,0,0,0,0,0,0,0,0,0,0,0,0,0,0,0,0,0,45,2,23,23,23,23,23,9,23,23,23,23,23,2,44,0,0,0,0,0,0,0,0,0,0,0,0,0,0
0,0,0,0,0,0,0,0,0,0,0,0,0,0,0,0,0,0,0,21,2,7,7,7,7,7,9,7,7,7,7,7,2,21,0,0,0,0,0,0,0,0,0,0,0,0,0,0
0,0,0,0,0,0,0,0,0,0,0,0,0,0,0,0,0,0,0,45,2,23,23,23,23,23,9,23,23,23,23,23,2,44,0,0,0,0,0,0,0,0,0,0,0,0,0,0
0,0,0,0,0,0,0,0,0,0,0,0,0,0,0,0,0,2,2,2,2,2,23,23,23,23,9,23,23,23,23,2,2,2,2,2,0,0,0,0,0,0,0,0,0,0,0,0
0,0,0,0,0,0,0,0,0,0,0,0,0,0,0,0,0,2,0,0,8,2,2,2,2,2,2,2,2,2,2,2,8,21,0,2,0,0,0,0,0,0,0,0,0,0,0,0
0,0,0,0,0,0,0,0,0,0,0,0,0,0,0,0,0,21,0,2,21,2,34,21,34,21,34,21,34,21,34,2,0,2,0,2,0,0,0,0,0,0,0,0,0,0,0,0
0,0,0,0,0,0,0,0,0,0,0,0,0,0,0,0,0,2,0,0,0,2,0,0,0,0,0,0,0,0,0,2,0,0,0,2,0,0,0,0,0,0,0,0,0,0,0,0
0,0,0,0,0,0,0,0,0,0,0,0,0,0,0,0,0,2,2,2,2,2,0,0,0,0,0,0,0,0,0,2,2,21,2,2,0,0,0,0,0,0,0,0,0,0,0,0
0,0,0,0,0,0,0,0,0,0,0,0,0,0,0,0,0,0,0,0,0,0,0,0,0,0,0,0,0,0,0,0,0,0,0,0,0,0,0,0,0,0,0,0,0,0,0,0
0,0,0,0,0,0,0,0,0,0,0,0,0,0,0,0,0,0,0,0,0,0,0,0,0,0,0,0,0,0,0,0,0,0,0,0,0,0,0,0,0,0,0,0,0,0,0,0
0,0,0,0,0,0,0,0,0,0,0,0,0,0,0,0,0,0,0,0,0,0,0,0,0,0,0,0,0,0,0,0,0,0,0,0,0,0,0,0,0,0,0,0,0,0,0,0
0,0,0,0,0,0,0,0,0,0,0,0,0,0,0,0,0,0,0,0,0,0,0,0,0,0,0,0,0,0,0,0,0,0,0,0,0,0,0,0,0,0,0,0,0,0,0,0
0,0,0,0,0,0,0,0,0,0,0,0,0,0,0,0,3,14,3,14,3,14,3,0,0,0,0,0,0,0,0,0,0,0,0,0,0,0,0,0,0,0,0,0,0,0,0,0
0,0,0,0,0,0,0,0,0,0,0,0,0,0,0,0,47,0,0,25,0,0,15,0,0,0,0,0,0,0,0,0,0,0,0,0,0,0,0,0,0,0,0,0,0,0,0,0
0,0,0,0,0,0,0,0,0,0,0,0,0,0,0,0,3,0,0,0,0,0,3,0,0,0,0,0,0,0,0,0,0,0,0,0,0,0,0,0,0,0,0,0,0,0,0,0
0,0,0,0,0,0,0,0,0,0,0,0,0,0,0,0,47,19,0,28,0,17,15,0,0,0,0,0,0,0,0,0,0,0,0,0,0,0,0,0,0,0,0,0,0,0,0,0
0,0,0,0,0,0,0,0,0,0,0,0,0,0,0,0,3,0,0,0,0,0,3,0,0,0,0,0,0,0,0,0,0,0,0,0,0,0,0,0,0,0,0,0,0,0,0,0
0,0,46,21,46,21,46,0,0,0,0,0,0,0,0,0,47,0,0,26,0,0,15,0,0,0,0,0,0,0,0,0,0,0,0,0,0,0,0,0,0,0,0,0,0,0,0,0
0,21,2,2,2,2,2,21,0,0,0,0,0,0,0,0,3,18,3,18,3,18,3,0,0,0,0,2,2,2,2,2,0,0,0,0,12,0,0,0,0,2,2,2,2,2,0,0
45,2,2,2,2,2,2,2,44,0,0,0,0,0,0,0,0,0,0,0,0,0,0,0,0,0,2,2,2,2,2,2,2,24,24,24,24,24,24,24,2,2,2,2,2,2,2,0
21,2,2,0,26,0,2,2,21,0,0,0,0,0,0,0,0,0,0,0,0,0,0,0,0,0,2,2,0,0,0,2,2,23,23,23,23,23,23,23,2,2,0,0,8,2,2,0
45,2,2,21,2,0,2,2,44,0,0,0,0,0,0,0,0,0,0,0,0,0,0,0,0,0,2,2,0,2,0,2,2,0,0,0,0,0,0,0,2,2,0,2,21,2,2,0
21,2,2,21,21,8,2,2,21,0,0,0,0,0,0,0,0,0,0,0,0,0,0,0,0,0,2,2,0,21,8,2,2,23,23,23,23,23,23,23,2,2,0,0,0,2,2,0
45,2,2,2,2,2,2,2,44,0,0,0,0,0,0,0,0,0,0,0,0,0,0,0,0,0,2,2,2,2,2,2,2,24,24,24,24,24,24,24,2,2,2,2,2,2,2,0
0,21,2,2,2,2,2,21,0,0,0,0,0,0,0,0,0,0,0,0,0,0,0,0,0,0,0,2,2,2,2,2,0,0,0,0,12,0,0,0,0,2,2,2,2,2,0,0
0,0,34,21,34,21,34,0,0,0,0,0,0,0,0,0,0,0,0,0,0,0,0,0,0,0,0,0,0,0,0,0,0,0,0,0,0,0,0,0,0,0,0,0,0,0,0,0
:endlayer
layer: 13
0,0,14,3,14,3,14,0,0,0,0,0,0,0,0,0,0,0,0,0,0,0,0,0,0,0,0,0,0,0,0,0,0,0,0,0,0,0,0,0,0,14,3,14,3,14,0,0
0,3,0,0,25,0,0,3,0,0,0,0,0,0,0,0,0,0,0,0,0,0,0,0,0,0,0,0,0,0,0,0,0,0,0,0,0,0,0,0,3,0,0,25,0,0,3,0
47,0,0,0,0,0,0,0,15,0,0,0,0,0,0,0,0,0,0,0,0,0,0,0,0,0,0,0,0,0,0,0,0,0,0,0,0,0,0,47,0,0,0,0,0,0,0,15
3,0,0,0,0,0,0,0,3,0,0,0,0,0,0,0,0,0,0,0,0,0,0,0,0,0,0,0,0,0,0,0,0,0,0,0,0,0,0,3,0,0,0,0,0,0,0,3
47,19,0,0,28,0,0,17,15,0,0,0,0,2,0,0,0,0,0,2,3,14,3,14,3,14,3,14,3,14,3,14,3,0,0,0,0,0,0,47,19,0,0,28,0,0,17,15
3,0,0,0,0,0,0,0,3,0,0,0,2,2,2,2,2,21,2,2,2,0,0,0,0,2,2,2,0,0,0,0,0,3,0,0,0,0,0,3,0,0,0,0,0,0,0,3
47,0,0,0,0,0,0,0,15,0,0,0,0,2,8,8,21,0,0,2,0,0,0,0,0,0,0,0,0,0,0,0,0,15,0,0,0,0,0,47,0,0,0,0,0,0,0,15
0,3,0,0,26,0,0,3,0,0,0,0,0,2,8,8,21,0,0,2,28,0,5,4,4,4,5,4,4,4,5,0,0,3,0,0,0,0,0,0,3,0,0,26,0,0,3,0
0,0,18,3,18,3,18,0,0,0,0,0,0,2,0,0,2,19,0,0,0,0,4,0,0,0,0,0,0,0,4,0,0,15,0,0,0,0,0,0,0,18,3,18,3,18,0,0
0,0,0,0,0,0,0,0,0,0,0,0,0,27,0,0,0,0,0,2,28,0,0,0,0,0,0,0,0,0,0,0,0,3,0,0,0,0,0,0,0,0,0,0,0,0,0,0
0,0,0,0,0,0,0,0,0,0,0,0,0,2,0,0,0,0,0,2,0,0,4,0,0,0,0,0,0,0,4,0,0,15,0,0,0,0,0,0,0,0,0,0,0,0,0,0
0,0,0,0,0,0,0,0,0,0,0,0,2,2,2,27,2,27,2,2,2,0,5,0,0,0,0,0,0,0,5,0,0,3,0,0,0,0,0,0,0,0,0,0,0,0,0,0
0,0,0,0,0,0,0,0,0,0,0,0,0,2,0,0,0,0,0,2,0,0,4,0,0,0,0,0,0,0,4,0,0,15,0,0,0,0,0,0,0,0,0,0,0,0,0,0
0,0,0,0,0,0,0,0,0,0,0,0,0,0,0,0,0,0,0,3,0,0,4,0,0,0,0,0,0,0,4,0,0,3,0,0,0,0,0,0,0,0,0,0,0,0,0,0
0,0,0,0,0,0,0,0,0,0,0,0,0,0,0,0,0,0,0,47,0,0,4,0,0,0,12,0,0,0,4,0,0,15,0,0,0,0,0,0,0,0,0,0,0,0,0,0
0,0,0,0,0,0,0,0,0,0,0,0,0,0,0,0,0,0,0,3,0,0,4,0,0,0,0,0,0,0,4,0,0,3,0,0,0,0,0,0,0,0,0,0,0,0,0,0
0,0,0,0,0,0,0,0,0,0,0,0,0,0,0,0,0,0,0,47,0,0,4,0,0,0,0,0,0,0,4,0,0,15,0,0,0,0,0,0,0,0,0,0,0,0,0,0
0,0,0,0,0,0,0,0,0,0,0,0,0,0,0,0,0,0,0,3,0,0,5,0,0,0,0,0,0,0,5,0,0,3,0,0,0,0,0,0,0,0,0,0,0,0,0,0
0,0,0,0,0,0,0,0,0,0,0,0,0,0,0,0,0,0,0,47,0,0,4,0,0,0,0,0,0,0,4,0,0,15,0,0,0,0,0,0,0,0,0,0,0,0,0,0
0,0,0,0,0,0,0,0,0,0,0,0,0,0,0,0,0,0,0,3,0,0,0,0,0,0,0,0,0,0,4,0,0,3,0,0,0,0,0,0,0,0,0,0,0,0,0,0
0,0,0,0,0,0,0,0,0,0,0,0,0,0,0,0,0,0,0,47,0,0,4,0,0,0,0,0,0,0,4,0,0,15,0,0,0,0,0,0,0,0,0,0,0,0,0,0
0,0,0,0,0,0,0,0,0,0,0,0,0,0,0,0,0,0,0,3,0,0,5,4,4,4,5,4,0,4,5,0,0,3,0,0,0,0,0,0,0,0,0,0,0,0,0,0
0,0,0,0,0,0,0,0,0,0,0,0,0,0,0,0,0,2,2,2,0,2,0,0,0,0,0,0,0,0,0,2,0,2,2,2,0,0,0,0,0,0,0,0,0,0,0,0
0,0,0,0,0,0,0,0,0,0,0,0,0,0,0,0,0,2,0,0,0,0,0,0,0,0,0,0,0,0,0,0,0,0,8,2,0,0,0,0,0,0,0,0,0,0,0,0
0,0,0,0,0,0,0,0,0,0,0,0,0,0,0,0,0,2,17,2,0,2,3,18,3,18,3,18,3,18,3,2,0,2,21,2,0,0,0,0,0,0,0,0,0,0,0,0
0,0,0,0,0,0,0,0,0,0,0,0,0,0,0,0,0,2,0,21,8,2,0,0,0,0,0,0,0,0,0,2,0,25,0,2,0,0,0,0,0,0,0,0,0,0,0,0
0,0,0,0,0,0,0,0,0,0,0,0,0,0,0,0,0,2,2,2,2,2,0,0,0,0,0,0,0,0,0,2,2,2,2,2,0,0,0,0,0,0,0,0,0,0,0,0
0,0,0,0,0,0,0,0,0,0,0,0,0,0,0,0,0,0,0,0,0,0,0,0,0,0,0,0,0,0,0,0,0,0,0,0,0,0,0,0,0,0,0,0,0,0,0,0
0,0,0,0,0,0,0,0,0,0,0,0,0,0,0,0,0,0,0,0,0,0,0,0,0,0,0,0,0,0,0,0,0,0,0,0,0,0,0,0,0,0,0,0,0,0,0,0
0,0,0,0,0,0,0,0,0,0,0,0,0,0,0,0,0,0,0,0,0,0,0,0,0,0,0,0,0,0,0,0,0,0,0,0,0,0,0,0,0,0,0,0,0,0,0,0
0,0,0,0,0,0,0,0,0,0,0,0,0,0,0,0,0,0,0,0,0,0,0,0,0,0,0,0,0,0,0,0,0,0,0,0,0,0,0,0,0,0,0,0,0,0,0,0
0,0,0,0,0,0,0,0,0,0,0,0,0,0,0,0,8,0,8,0,8,0,8,0,0,0,0,0,0,0,0,0,0,0,0,0,0,0,0,0,0,0,0,0,0,0,0,0
0,0,0,0,0,0,0,0,0,0,0,0,0,0,0,0,0,0,0,0,0,0,0,0,0,0,0,0,0,0,0,0,0,0,0,0,0,0,0,0,0,0,0,0,0,0,0,0
0,0,0,0,0,0,0,0,0,0,0,0,0,0,0,0,8,0,0,0,0,0,8,0,0,0,0,0,0,0,0,0,0,0,0,0,0,0,0,0,0,0,0,0,0,0,0,0
0,0,0,0,0,0,0,0,0,0,0,0,0,0,0,0,0,0,0,28,0,0,0,0,0,0,0,0,0,0,0,0,0,0,0,0,0,0,0,0,0,0,0,0,0,0,0,0
0,0,0,0,0,0,0,0,0,0,0,0,0,0,0,0,8,0,0,0,0,0,8,0,0,0,0,0,0,0,0,0,0,0,0,0,0,0,0,0,0,0,0,0,0,0,0,0
0,0,14,3,14,3,14,0,0,0,0,0,0,0,0,0,0,0,0,0,0,0,0,0,0,0,0,0,0,0,0,0,0,0,0,0,0,0,0,0,0,0,0,0,0,0,0,0
0,3,0,0,25,0,0,3,0,0,0,0,0,0,0,0,8,0,8,0,8,0,8,0,0,0,0,2,2,2,2,2,0,0,0,0,0,0,0,0,0,2,2,2,2,2,0,0
47,0,0,0,0,0,0,0,15,0,0,0,0,0,0,0,0,0,0,0,0,0,0,0,0,0,2,2,2,2,2,2,2,0,0,0,0,0,0,0,2,2,2,2,2,2,2,0
3,0,0,0,0,0,0,0,3,0,0,0,0,0,0,0,0,0,0,0,0,0,0,0,0,0,2,2,0,26,0,2,2,0,0,0,12,0,0,0,2,2,0,0,0,2,2,0
47,19,0,0,28,0,0,17,15,0,0,0,0,0,0,0,0,0,0,0,0,0,0,0,0,0,2,2,21,2,0,2,2,24,24,24,24,24,24,24,2,2,17,2,0,2,2,0
3,0,0,0,0,0,0,0,3,0,0,0,0,0,0,0,0,0,0,0,0,0,0,0,0,0,2,2,8,0,0,2,2,0,0,0,12,0,0,0,2,2,0,21,8,2,2,0
47,0,0,0,0,0,0,0,15,0,0,0,0,0,0,0,0,0,0,0,0,0,0,0,0,0,2,2,2,2,2,2,2,0,0,0,0,0,0,0,2,2,2,2,2,2,2,0
0,3,0,0,26,0,0,3,0,0,0,0,0,0,0,0,0,0,0,0,0,0,0,0,0,0,0,2,2,2,2,2,0,0,0,0,0,0,0,0,0,2,2,2,2,2,0,0
0,0,18,3,18,3,18,0,0,0,0,0,0,0,0,0,0,0,0,0,0,0,0,0,0,0,0,0,0,0,0,0,0,0,0,0,0,0,0,0,0,0,0,0,0,0,0,0
:endlayer
layer: 14
0,0,0,8,0,8,0,0,0,0,0,0,0,0,0,0,0,0,0,0,0,0,0,0,0,0,0,0,0,0,0,0,0,0,0,0,0,0,0,0,0,0,8,0,8,0,0,0
0,8,0,0,0,0,0,8,0,0,0,0,0,0,0,0,0,0,0,0,0,0,0,0,0,0,0,0,0,0,0,0,0,0,0,0,0,0,0,0,8,0,0,0,0,0,8,0
0,0,0,0,0,0,0,0,0,0,0,0,0,0,0,0,0,0,0,0,0,0,0,0,0,0,0,0,0,0,0,0,0,0,0,0,0,0,0,0,0,0,0,0,0,0,0,0
8,0,0,0,0,0,0,0,8,0,0,0,0,0,0,0,0,0,0,0,0,0,0,0,0,0,0,0,0,0,0,0,0,0,0,0,0,0,0,8,0,0,0,0,0,0,0,8
0,0,0,0,28,0,0,0,0,0,0,0,0,2,0,0,0,0,0,2,8,0,8,0,8,0,8,0,8,0,8,0,8,0,0,0,0,0,0,0,0,0,0,28,0,0,0,0
8,0,0,0,0,0,0,0,8,0,0,0,2,2,2,0,2,2,2,2,2,0,0,0,0,2,2,2,0,0,0,0,0,8,0,0,0,0,0,8,0,0,0,0,0,0,0,8
0,0,0,0,0,0,0,0,0,0,0,0,0,2,0,0,0,8,8,2,0,0,26,0,0,0,26,0,0,0,26,0,0,0,0,0,0,0,0,0,0,0,0,0,0,0,0,0
0,8,0,0,0,0,0,8,0,0,0,0,0,27,0,0,0,8,8,2,28,17,5,4,22,4,5,4,22,4,5,19,0,8,0,0,0,0,0,0,8,0,0,0,0,0,8,0
0,0,0,8,0,8,0,0,0,0,0,0,0,2,0,17,2,21,21,0,0,0,4,0,0,0,25,0,0,0,4,0,0,0,0,0,0,0,0,0,0,0,8,0,8,0,0,0
0,0,0,0,0,0,0,0,0,0,0,0,0,27,0,0,25,21,21,2,28,0,0,0,0,0,0,0,0,0,0,0,0,8,0,0,0,0,0,0,0,0,0,0,0,0,0,0
0,0,0,0,0,0,0,0,0,0,0,0,0,2,0,0,0,21,21,2,0,0,4,0,0,0,0,0,0,0,4,0,0,0,0,0,0,0,0,0,0,0,0,0,0,0,0,0
0,0,0,0,0,0,0,0,0,0,0,0,2,2,2,27,2,2,2,2,2,17,5,19,0,0,0,0,0,17,5,19,0,8,0,0,0,0,0,0,0,0,0,0,0,0,0,0
0,0,0,0,0,0,0,0,0,0,0,0,0,2,0,0,0,0,0,2,0,0,4,0,0,0,0,0,0,0,4,0,0,0,0,0,0,0,0,0,0,0,0,0,0,0,0,0
0,0,0,0,0,0,0,0,0,0,0,0,0,0,0,0,0,0,0,8,0,0,22,0,0,0,0,0,0,0,22,0,0,8,0,0,0,0,0,0,0,0,0,0,0,0,0,0
0,0,0,0,0,0,0,0,0,0,0,0,0,0,0,0,0,0,0,0,0,0,4,0,0,0,0,0,0,0,4,0,0,0,0,0,0,0,0,0,0,0,0,0,0,0,0,0
0,0,0,0,0,0,0,0,0,0,0,0,0,0,0,0,0,0,0,8,0,0,22,0,0,0,0,0,0,0,22,0,0,8,0,0,0,0,0,0,0,0,0,0,0,0,0,0
0,0,0,0,0,0,0,0,0,0,0,0,0,0,0,0,0,0,0,0,0,0,4,0,0,0,0,0,0,0,4,0,0,0,0,0,0,0,0,0,0,0,0,0,0,0,0,0
0,0,0,0,0,0,0,0,0,0,0,0,0,0,0,0,0,0,0,8,0,17,5,19,0,0,0,0,0,17,5,19,0,8,0,0,0,0,0,0,0,0,0,0,0,0,0,0
0,0,0,0,0,0,0,0,0,0,0,0,0,0,0,0,0,0,0,0,0,0,4,0,0,0,0,0,0,0,4,0,0,0,0,0,0,0,0,0,0,0,0,0,0,0,0,0
0,0,0,0,0,0,0,0,0,0,0,0,0,0,0,0,0,0,0,8,0,0,0,0,0,0,0,0,0,0,22,0,0,8,0,0,0,0,0,0,0,0,0,0,0,0,0,0
0,0,0,0,0,0,0,0,0,0,0,0,0,0,0,0,0,0,0,0,0,0,4,0,0,0,26,0,0,0,4,0,0,0,0,0,0,0,0,0,0,0,0,0,0,0,0,0
0,0,0,0,0,0,0,0,0,0,0,0,0,0,0,0,0,0,0,8,0,17,5,4,22,4,5,4,0,4,5,19,0,8,0,0,0,0,0,0,0,0,0,0,0,0,0,0
0,0,0,0,0,0,0,0,0,0,0,0,0,0,0,0,0,2,2,2,0,2,25,0,0,0,25,0,0,0,25,2,0,2,2,2,0,0,0,0,0,0,0,0,0,0,0,0
0,0,0,0,0,0,0,0,0,0,0,0,0,0,0,0,0,2,0,0,0,0,0,0,0,0,0,0,0,0,0,0,0,0,0,2,0,0,0,0,0,0,0,0,0,0,0,0
0,0,0,0,0,0,0,0,0,0,0,0,0,0,0,0,0,2,21,2,0,2,8,0,8,0,8,0,8,0,8,2,0,2,0,0,0,0,0,0,0,0,0,0,0,0,0,0
0,0,0,0,0,0,0,0,0,0,0,0,0,0,0,0,0,2,8,0,0,2,0,0,0,0,0,0,0,0,0,2,0,21,8,2,0,0,0,0,0,0,0,0,0,0,0,0
0,0,0,0,0,0,0,0,0,0,0,0,0,0,0,0,0,2,2,0,2,2,0,0,0,0,0,0,0,0,0,2,2,2,2,2,0,0,0,0,0,0,0,0,0,0,0,0
0,0,0,0,0,0,0,0,0,0,0,0,0,0,0,0,0,0,0,0,0,0,0,0,0,0,0,0,0,0,0,0,0,0,0,0,0,0,0,0,0,0,0,0,0,0,0,0
0,0,0,0,0,0,0,0,0,0,0,0,0,0,0,0,0,0,0,0,0,0,0,0,0,0,0,0,0,0,0,0,0,0,0,0,0,0,0,0,0,0,0,0,0,0,0,0
0,0,0,0,0,0,0,0,0,0,0,0,0,0,0,0,0,0,0,0,0,0,0,0,0,0,0,0,0,0,0,0,0,0,0,0,0,0,0,0,0,0,0,0,0,0,0,0
0,0,0,0,0,0,0,0,0,0,0,0,0,0,0,0,0,0,0,0,0,0,0,0,0,0,0,0,0,0,0,0,0,0,0,0,0,0,0,0,0,0,0,0,0,0,0,0
0,0,0,0,0,0,0,0,0,0,0,0,0,0,0,0,0,0,0,0,0,0,0,0,0,0,0,0,0,0,0,0,0,0,0,0,0,0,0,0,0,0,0,0,0,0,0,0
0,0,0,0,0,0,0,0,0,0,0,0,0,0,0,0,0,0,0,0,0,0,0,0,0,0,0,0,0,0,0,0,0,0,0,0,0,0,0,0,0,0,0,0,0,0,0,0
0,0,0,0,0,0,0,0,0,0,0,0,0,0,0,0,0,0,0,0,0,0,0,0,0,0,0,0,0,0,0,0,0,0,0,0,0,0,0,0,0,0,0,0,0,0,0,0
0,0,0,0,0,0,0,0,0,0,0,0,0,0,0,0,0,0,0,22,0,0,0,0,0,0,0,0,0,0,0,0,0,0,0,0,0,0,0,0,0,0,0,0,0,0,0,0
0,0,0,0,0,0,0,0,0,0,0,0,0,0,0,0,0,0,0,0,0,0,0,0,0,0,0,0,0,0,0,0,0,0,0,0,0,0,0,0,0,0,0,0,0,0,0,0
0,0,0,8,0,8,0,0,0,0,0,0,0,0,0,0,0,0,0,0,0,0,0,0,0,0,0,46,21,46,21,46,0,0,0,0,0,0,0,0,0,46,21,46,21,46,0,0
0,8,0,0,0,0,0,8,0,0,0,0,0,0,0,0,0,0,0,0,0,0,0,0,0,0,21,2,2,2,2,2,21,0,0,0,0,0,0,0,21,2,2,2,2,2,21,0
0,0,0,0,0,0,0,0,0,0,0,0,0,0,0,0,0,0,0,0,0,0,0,0,0,45,2,2,2,2,2,2,2,44,0,0,0,0,0,45,2,2,2,2,2,2,2,44
8,0,0,0,0,0,0,0,8,0,0,0,0,0,0,0,0,0,0,0,0,0,0,0,0,21,2,2,8,21,21,2,2,21,0,0,0,0,0,21,2,2,21,21,0,2,2,21
0,0,0,0,28,0,0,0,0,0,0,0,0,0,0,0,0,0,0,0,0,0,0,0,0,45,2,2,0,2,21,2,2,44,0,0,0,0,0,45,2,2,21,2,19,2,2,44
8,0,0,0,0,0,0,0,8,0,0,0,0,0,0,0,0,0,0,0,0,0,0,0,0,21,2,2,0,25,0,2,2,21,0,0,0,0,0,21,2,2,8,0,0,2,2,21
0,0,0,0,0,0,0,0,0,0,0,0,0,0,0,0,0,0,0,0,0,0,0,0,0,45,2,2,2,2,2,2,2,44,0,0,0,0,0,45,2,2,2,2,2,2,2,44
0,8,0,0,0,0,0,8,0,0,0,0,0,0,0,0,0,0,0,0,0,0,0,0,0,0,21,2,2,2,2,2,21,0,0,0,0,0,0,0,21,2,2,2,2,2,21,0
0,0,0,8,0,8,0,0,0,0,0,0,0,0,0,0,0,0,0,0,0,0,0,0,0,0,0,34,21,34,21,34,0,0,0,0,0,0,0,0,0,34,21,34,21,34,0,0
:endlayer
layer: 15
0,0,0,0,0,0,0,0,0,0,0,0,0,0,0,0,0,0,0,0,0,0,0,0,0,0,0,0,0,0,0,0,0,0,0,0,0,0,0,0,0,0,0,0,0,0,0,0
0,0,0,0,0,0,0,0,0,0,0,0,0,0,0,0,0,0,0,0,0,0,0,0,0,0,0,0,0,0,0,0,0,0,0,0,0,0,0,0,0,0,0,0,0,0,0,0
0,0,0,0,0,0,0,0,0,0,0,0,0,0,0,0,0,0,0,0,0,0,0,0,0,0,0,0,0,0,0,0,0,0,0,0,0,0,0,0,0,0,0,0,0,0,0,0
0,0,0,0,0,0,0,0,0,0,0,0,0,0,0,0,0,0,0,0,0,0,0,0,0,0,0,0,0,0,0,0,0,0,0,0,0,0,0,0,0,0,0,0,0,0,0,0
0,0,0,0,28,0,0,0,0,0,0,0,0,2,0,0,0,0,0,2,0,0,0,0,0,0,0,0,0,0,0,0,0,0,0,0,0,0,0,0,0,0,0,28,0,0,0,0
0,0,0,0,0,0,0,0,0,0,0,0,2,2,2,21,2,0,2,2,2,0,0,0,0,20,2,16,0,0,0,0,0,0,0,0,0,0,0,0,0,0,0,0,0,0,0,0
0,0,0,0,0,0,0,0,0,0,0,0,0,2,0,0,0,0,0,2,0,23,23,23,23,23,23,23,23,23,23,23,0,0,0,0,0,0,0,0,0,0,0,0,0,0,0,0
0,0,0,0,0,0,0,0,0,0,0,0,0,27,0,0,26,0,0,27,8,23,5,4,4,4,5,4,4,4,5,23,0,0,0,0,0,0,0,0,0,0,0,0,0,0,0,0
0,0,0,0,0,0,0,0,0,0,0,0,0,2,21,21,2,0,0,2,21,23,4,0,0,0,0,0,0,0,4,23,0,0,0,0,0,0,0,0,0,0,0,0,0,0,0,0
0,0,0,0,0,0,0,0,0,0,0,0,0,2,8,8,8,0,0,2,8,23,4,0,0,0,0,0,0,0,4,23,0,0,0,0,0,0,0,0,0,0,0,0,0,0,0,0
0,0,0,0,0,0,0,0,0,0,0,0,0,2,8,8,8,0,0,2,0,23,4,0,0,0,0,0,0,0,4,23,0,0,0,0,0,0,0,0,0,0,0,0,0,0,0,0
0,0,0,0,0,0,0,0,0,0,0,0,2,2,2,2,2,27,2,2,2,23,5,0,0,0,0,0,0,0,5,23,0,0,0,0,0,0,0,0,0,0,0,0,0,0,0,0
0,0,0,0,0,0,0,0,0,0,0,0,0,2,0,0,0,0,0,2,0,23,4,0,0,0,0,0,0,0,4,23,0,0,0,0,0,0,0,0,0,0,0,0,0,0,0,0
0,0,0,0,0,0,0,0,0,0,0,0,0,0,0,0,0,0,0,0,0,23,4,0,0,0,0,0,0,0,4,23,0,0,0,0,0,0,0,0,0,0,0,0,0,0,0,0
0,0,0,0,0,0,0,0,0,0,0,0,0,0,0,0,0,0,0,0,0,23,4,0,0,0,0,0,0,0,4,23,0,0,0,0,0,0,0,0,0,0,0,0,0,0,0,0
0,0,0,0,0,0,0,0,0,0,0,0,0,0,0,0,0,0,0,0,0,23,4,0,0,0,0,0,0,0,4,23,0,0,0,0,0,0,0,0,0,0,0,0,0,0,0,0
0,0,0,0,0,0,0,0,0,0,0,0,0,0,0,0,0,0,0,0,0,23,4,0,0,0,0,0,0,0,4,23,0,0,0,0,0,0,0,0,0,0,0,0,0,0,0,0
0,0,0,0,0,0,0,0,0,0,0,0,0,0,0,0,0,0,0,0,0,23,5,0,0,0,0,0,0,0,5,23,0,0,0,0,0,0,0,0,0,0,0,0,0,0,0,0
0,0,0,0,0,0,0,0,0,0,0,0,0,0,0,0,0,0,0,0,0,23,4,0,0,0,0,0,0,0,4,23,0,0,0,0,0,0,0,0,0,0,0,0,0,0,0,0
0,0,0,0,0,0,0,0,0,0,0,0,0,0,0,0,0,0,0,0,0,23,4,0,0,0,0,0,0,0,4,23,0,0,0,0,0,0,0,0,0,0,0,0,0,0,0,0
0,0,0,0,0,0,0,0,0,0,0,0,0,0,0,0,0,0,0,0,0,23,4,0,0,0,0,0,0,0,4,23,0,0,0,0,0,0,0,0,0,0,0,0,0,0,0,0
0,0,0,0,0,0,0,0,0,0,0,0,0,0,0,0,0,0,0,0,0,23,5,4,4,4,5,4,4,4,5,23,0,0,0,0,0,0,0,0,0,0,0,0,0,0,0,0
0,0,0,0,0,0,0,0,0,0,0,0,0,0,0,0,0,2,2,2,2,2,23,23,23,23,23,23,23,23,23,2,2,2,2,2,0,0,0,0,0,0,0,0,0,0,0,0
0,0,0,0,0,0,0,0,0,0,0,0,0,0,0,0,0,2,8,21,0,2,0,0,0,0,0,0,0,0,0,2,0,26,0,2,0,0,0,0,0,0,0,0,0,0,0,0
0,0,0,0,0,0,0,0,0,0,0,0,0,0,0,0,0,2,0,2,19,2,0,0,0,0,0,0,0,0,0,2,21,2,0,21,0,0,0,0,0,0,0,0,0,0,0,0
0,0,0,0,0,0,0,0,0,0,0,0,0,0,0,0,0,2,0,0,0,2,0,0,0,0,0,0,0,0,0,2,8,0,0,2,0,0,0,0,0,0,0,0,0,0,0,0
0,0,0,0,0,0,0,0,0,0,0,0,0,0,0,0,0,2,2,21,2,2,0,0,0,0,0,0,0,0,0,2,2,2,2,2,0,0,0,0,0,0,0,0,0,0,0,0
0,0,0,0,0,0,0,0,0,0,0,0,0,0,0,0,0,0,0,0,0,0,0,0,0,0,0,0,0,0,0,0,0,0,0,0,0,0,0,0,0,0,0,0,0,0,0,0
0,0,0,0,0,0,0,0,0,0,0,0,0,0,0,0,0,0,0,0,0,0,0,0,0,0,0,0,0,0,0,0,0,0,0,0,0,0,0,0,0,0,0,0,0,0,0,0
0,0,0,0,0,0,0,0,0,0,0,0,0,0,0,0,0,0,0,0,0,0,0,0,0,0,0,0,0,0,0,0,0,0,0,0,0,0,0,0,0,0,0,0,0,0,0,0
0,0,0,0,0,0,0,0,0,0,0,0,0,0,0,0,0,0,0,0,0,0,0,0,0,0,0,0,0,0,0,0,0,0,0,0,0,0,0,0,0,0,0,0,0,0,0,0
0,0,0,0,0,0,0,0,0,0,0,0,0,0,0,0,0,0,0,0,0,0,0,0,0,0,0,0,0,0,0,0,0,0,0,0,0,0,0,0,0,0,0,0,0,0,0,0
0,0,0,0,0,0,0,0,0,0,0,0,0,0,0,0,0,0,0,0,0,0,0,0,0,0,0,0,0,0,0,0,0,0,0,0,0,0,0,0,0,0,0,0,0,0,0,0
0,0,0,0,0,0,0,0,0,0,0,0,0,0,0,0,0,0,0,0,0,0,0,0,0,0,0,0,0,0,0,0,0,0,0,0,0,0,0,0,0,0,0,0,0,0,0,0
0,0,0,0,0,0,0,0,0,0,0,0,0,0,0,0,0,0,0,12,0,0,0,0,0,0,0,0,0,0,0,0,0,0,0,0,0,0,0,0,0,0,0,0,0,0,0,0
0,0,0,0,0,0,0,0,0,0,0,0,0,0,0,0,0,0,0,0,0,0,0,0,0,0,0,0,0,0,0,0,0,0,0,0,0,0,0,0,0,0,0,0,0,0,0,0
0,0,0,0,0,0,0,0,0,0,0,0,0,0,0,0,0,0,0,0,0,0,0,0,0,0,0,14,3,14,3,14,0,0,0,0,0,0,0,0,0,14,3,14,3,14,0,0
0,0,0,0,0,0,0,0,0,0,0,0,0,0,0,0,0,0,0,0,0,0,0,0,0,0,3,0,0,25,0,0,3,0,0,0,0,0,0,0,3,0,0,25,0,0,3,0
0,0,0,0,0,0,0,0,0,0,0,0,0,0,0,0,0,0,0,0,0,0,0,0,0,47,0,0,0,0,0,0,0,15,0,0,0,0,0,47,0,0,0,0,0,0,0,15
0,0,0,0,0,0,0,0,0,0,0,0,0,0,0,0,0,0,0,0,0,0,0,0,0,3,0,0,0,0,0,0,0,3,0,0,0,0,0,3,0,0,0,0,0,0,0,3
0,0,0,0,28,0,0,0,0,0,0,0,0,0,0,0,0,0,0,0,0,0,0,0,0,47,19,0,0,28,0,0,17,15,0,0,0,0,0,47,19,0,0,28,0,0,17,15
0,0,0,0,0,0,0,0,0,0,0,0,0,0,0,0,0,0,0,0,0,0,0,0,0,3,0,0,0,0,0,0,0,3,0,0,0,0,0,3,0,0,0,0,0,0,0,3
0,0,0,0,0,0,0,0,0,0,0,0,0,0,0,0,0,0,0,0,0,0,0,0,0,47,0,0,0,0,0,0,0,15,0,0,0,0,0,47,0,0,0,0,0,0,0,15
0,0,0,0,0,0,0,0,0,0,0,0,0,0,0,0,0,0,0,0,0,0,0,0,0,0,3,0,0,26,0,0,3,0,0,0,0,0,0,0,3,0,0,26,0,0,3,0
0,0,0,0,0,0,0,0,0,0,0,0,0,0,0,0,0,0,0,0,0,0,0,0,0,0,0,18,3,18,3,18,0,0,0,0,0,0,0,0,0,18,3,18,3,18,0,0
:endlayer
layer: 16
0,0,0,0,0,0,0,0,0,0,0,0,0,0,0,0,0,0,0,0,0,0,0,0,0,0,0,0,0,0,0,0,0,0,0,0,0,0,0,0,0,0,0,0,0,0,0,0
0,0,0,0,0,0,0,0,0,0,0,0,0,0,0,0,0,0,0,0,0,0,0,0,0,0,0,0,0,0,0,0,0,0,0,0,0,0,0,0,0,0,0,0,0,0,0,0
0,0,0,0,0,0,0,0,0,0,0,0,0,0,0,0,0,0,0,0,0,0,0,0,0,0,0,0,0,0,0,0,0,0,0,0,0,0,0,0,0,0,0,0,0,0,0,0
0,0,0,0,0,0,0,0,0,0,0,0,0,0,0,0,0,0,0,0,0,0,0,0,0,0,0,0,0,0,0,0,0,0,0,0,0,0,0,0,0,0,0,0,0,0,0,0
0,0,0,0,22,0,0,0,0,0,0,0,0,2,0,0,0,0,0,2,0,0,0,0,0,0,0,0,0,0,0,0,0,0,0,0,0,0,0,0,0,0,0,22,0,0,0,0
0,0,0,0,0,0,0,0,0,0,0,0,2,2,2,2,2,21,2,2,2,0,0,0,0,0,2,0,0,0,0,0,0,0,0,0,0,0,0,0,0,0,0,0,0,0,0,0
0,0,0,0,0,0,0,0,0,0,0,0,0,2,8,8,21,0,0,2,0,0,0,0,0,0,12,0,0,0,0,0,0,0,0,0,0,0,0,0,0,0,0,0,0,0,0,0
0,0,0,0,0,0,0,0,0,0,0,0,0,2,8,8,21,0,0,27,0,0,24,24,24,24,24,24,24,24,24,0,0,0,0,0,0,0,0,0,0,0,0,0,0,0,0,0
0,0,0,0,0,0,0,0,0,0,0,0,0,2,0,0,2,19,0,2,0,0,24,23,23,23,23,23,23,23,24,0,0,0,0,0,0,0,0,0,0,0,0,0,0,0,0,0
0,0,0,0,0,0,0,0,0,0,0,0,0,27,0,0,25,0,0,27,0,0,24,23,0,0,0,0,0,23,24,0,0,0,0,0,0,0,0,0,0,0,0,0,0,0,0,0
0,0,0,0,0,0,0,0,0,0,0,0,0,2,0,0,0,0,0,2,0,0,24,23,0,0,0,0,0,23,24,0,0,0,0,0,0,0,0,0,0,0,0,0,0,0,0,0
0,0,0,0,0,0,0,0,0,0,0,0,2,2,2,27,2,27,2,2,2,0,24,23,0,0,0,0,0,23,24,0,0,0,0,0,0,0,0,0,0,0,0,0,0,0,0,0
0,0,0,0,0,0,0,0,0,0,0,0,0,2,0,0,0,0,0,2,0,0,24,23,0,0,0,0,0,23,24,0,0,0,0,0,0,0,0,0,0,0,0,0,0,0,0,0
0,0,0,0,0,0,0,0,0,0,0,0,0,0,0,0,0,0,0,0,0,0,24,23,0,0,0,0,0,23,24,0,0,0,0,0,0,0,0,0,0,0,0,0,0,0,0,0
0,0,0,0,0,0,0,0,0,0,0,0,0,0,0,0,0,0,0,0,0,12,24,23,0,0,0,0,0,23,24,12,0,0,0,0,0,0,0,0,0,0,0,0,0,0,0,0
0,0,0,0,0,0,0,0,0,0,0,0,0,0,0,0,0,0,0,0,0,0,24,23,0,0,0,0,0,23,24,0,0,0,0,0,0,0,0,0,0,0,0,0,0,0,0,0
0,0,0,0,0,0,0,0,0,0,0,0,0,0,0,0,0,0,0,0,0,0,24,23,0,0,0,0,0,23,24,0,0,0,0,0,0,0,0,0,0,0,0,0,0,0,0,0
0,0,0,0,0,0,0,0,0,0,0,0,0,0,0,0,0,0,0,0,0,0,24,23,0,0,0,0,0,23,24,0,0,0,0,0,0,0,0,0,0,0,0,0,0,0,0,0
0,0,0,0,0,0,0,0,0,0,0,0,0,0,0,0,0,0,0,0,0,0,24,23,0,0,0,0,0,23,24,0,0,0,0,0,0,0,0,0,0,0,0,0,0,0,0,0
0,0,0,0,0,0,0,0,0,0,0,0,0,0,0,0,0,0,0,0,0,0,24,23,0,0,0,0,0,23,24,0,0,0,0,0,0,0,0,0,0,0,0,0,0,0,0,0
0,0,0,0,0,0,0,0,0,0,0,0,0,0,0,0,0,0,0,0,0,0,24,23,23,23,23,23,23,23,24,0,0,0,0,0,0,0,0,0,0,0,0,0,0,0,0,0
0,0,0,0,0,0,0,0,0,0,0,0,0,0,0,0,46,46,46,46,46,46,3,24,24,24,24,24,24,24,3,46,46,46,46,46,46,0,0,0,0,0,0,0,0,0,0,0
0,0,0,0,0,0,0,0,0,0,0,0,0,0,0,0,45,2,2,2,2,2,44,0,0,0,12,0,0,0,45,2,2,2,2,2,44,0,0,0,0,0,0,0,0,0,0,0
0,0,0,0,0,0,0,0,0,0,0,0,0,0,0,0,45,2,0,0,8,2,44,0,0,0,0,0,0,0,45,2,8,21,21,2,44,0,0,0,0,0,0,0,0,0,0,0
0,0,0,0,0,0,0,0,0,0,0,0,0,0,0,0,45,2,17,2,21,2,44,0,0,0,0,0,0,0,45,2,0,2,21,2,44,0,0,0,0,0,0,0,0,0,0,0
0,0,0,0,0,0,0,0,0,0,0,0,0,0,0,0,45,2,0,21,21,2,44,0,0,0,0,0,0,0,45,2,0,25,0,2,44,0,0,0,0,0,0,0,0,0,0,0
0,0,0,0,0,0,0,0,0,0,0,0,0,0,0,0,45,2,2,2,2,2,44,0,0,0,0,0,0,0,45,2,2,2,2,2,44,0,0,0,0,0,0,0,0,0,0,0
0,0,0,0,0,0,0,0,0,0,0,0,0,0,0,0,45,34,34,34,34,34,44,0,0,0,0,0,0,0,45,34,34,34,34,34,44,0,0,0,0,0,0,0,0,0,0,0
0,0,0,0,0,0,0,0,0,0,0,0,0,0,0,0,0,0,0,0,0,0,0,0,0,0,0,0,0,0,0,0,0,0,0,0,0,0,0,0,0,0,0,0,0,0,0,0
0,0,0,0,0,0,0,0,0,0,0,0,0,0,0,0,0,0,0,0,0,0,0,0,0,0,0,0,0,0,0,0,0,0,0,0,0,0,0,0,0,0,0,0,0,0,0,0
0,0,0,0,0,0,0,0,0,0,0,0,0,0,0,0,0,0,0,0,0,0,0,0,0,0,0,0,0,0,0,0,0,0,0,0,0,0,0,0,0,0,0,0,0,0,0,0
0,0,0,0,0,0,0,0,0,0,0,0,0,0,0,0,0,0,0,0,0,0,0,0,0,0,0,0,0,0,0,0,0,0,0,0,0,0,0,0,0,0,0,0,0,0,0,0
0,0,0,0,0,0,0,0,0,0,0,0,0,0,0,0,0,0,0,0,0,0,0,0,0,0,0,0,0,0,0,0,0,0,0,0,0,0,0,0,0,0,0,0,0,0,0,0
0,0,0,0,0,0,0,0,0,0,0,0,0,0,0,0,0,0,0,0,0,0,0,0,0,0,0,0,0,0,0,0,0,0,0,0,0,0,0,0,0,0,0,0,0,0,0,0
0,0,0,0,0,0,0,0,0,0,0,0,0,0,0,0,0,0,0,0,0,0,0,0,0,0,0,0,0,0,0,0,0,0,0,0,0,0,0,0,0,0,0,0,0,0,0,0
0,0,0,0,0,0,0,0,0,0,0,0,0,0,0,0,0,0,0,0,0,0,0,0,0,0,0,0,0,0,0,0,0,0,0,0,0,0,0,0,0,0,0,0,0,0,0,0
0,0,0,0,0,0,0,0,0,0,0,0,0,0,0,0,0,0,0,0,0,0,0,0,0,0,0,0,8,0,8,0,0,0,0,0,0,0,0,0,0,0,8,0,8,0,0,0
0,0,0,0,0,0,0,0,0,0,0,0,0,0,0,0,0,0,0,0,0,0,0,0,0,0,8,0,0,0,0,0,8,0,0,0,0,0,0,0,8,0,0,0,0,0,8,0
0,0,0,0,0,0,0,0,0,0,0,0,0,0,0,0,0,0,0,0,0,0,0,0,0,0,0,0,0,0,0,0,0,0,0,0,0,0,0,0,0,0,0,0,0,0,0,0
0,0,0,0,0,0,0,0,0,0,0,0,0,0,0,0,0,0,0,0,0,0,0,0,0,8,0,0,0,0,0,0,0,8,0,0,0,0,0,8,0,0,0,0,0,0,0,8
0,0,0,0,22,0,0,0,0,0,0,0,0,0,0,0,0,0,0,0,0,0,0,0,0,0,0,0,0,28,0,0,0,0,0,0,0,0,0,0,0,0,0,28,0,0,0,0
0,0,0,0,0,0,0,0,0,0,0,0,0,0,0,0,0,0,0,0,0,0,0,0,0,8,0,0,0,0,0,0,0,8,0,0,0,0,0,8,0,0,0,0,0,0,0,8
0,0,0,0,0,0,0,0,0,0,0,0,0,0,0,0,0,0,0,0,0,0,0,0,0,0,0,0,0,0,0,0,0,0,0,0,0,0,0,0,0,0,0,0,0,0,0,0
0,0,0,0,0,0,0,0,0,0,0,0,0,0,0,0,0,0,0,0,0,0,0,0,0,0,8,0,0,0,0,0,8,0,0,0,0,0,0,0,8,0,0,0,0,0,8,0
0,0,0,0,0,0,0,0,0,0,0,0,0,0,0,0,0,0,0,0,0,0,0,0,0,0,0,0,8,0,8,0,0,0,0,0,0,0,0,0,0,0,8,0,8,0,0,0
:endlayer
layer: 17
0,0,0,0,0,0,0,0,0,0,0,0,0,0,0,0,0,0,0,0,0,0,0,0,0,0,0,0,0,0,0,0,0,0,0,0,0,0,0,0,0,0,0,0,0,0,0,0
0,0,0,0,0,0,0,0,0,0,0,0,0,0,0,0,0,0,0,0,0,0,0,0,0,0,0,0,0,0,0,0,0,0,0,0,0,0,0,0,0,0,0,0,0,0,0,0
0,0,0,0,0,0,0,0,0,0,0,0,0,0,0,0,0,0,0,0,0,0,0,0,0,0,0,0,0,0,0,0,0,0,0,0,0,0,0,0,0,0,0,0,0,0,0,0
0,0,0,0,0,0,0,0,0,0,0,0,0,0,0,0,0,0,0,0,0,0,0,0,0,0,0,0,0,0,0,0,0,0,0,0,0,0,0,0,0,0,0,0,0,0,0,0
0,0,0,0,12,0,0,0,0,0,0,0,0,2,0,0,0,0,0,2,0,0,0,0,0,0,0,0,0,0,0,0,0,0,0,0,0,0,0,0,0,0,0,12,0,0,0,0
0,0,0,0,0,0,0,0,0,0,0,0,2,2,2,0,2,2,2,2,2,0,0,0,0,0,2,0,0,0,0,0,0,0,0,0,0,0,0,0,0,0,0,0,0,0,0,0
0,0,0,0,0,0,0,0,0,0,0,0,0,2,0,0,0,8,8,2,0,0,0,0,0,0,0,0,0,0,0,0,0,0,0,0,0,0,0,0,0,0,0,0,0,0,0,0
0,0,0,0,0,0,0,0,0,0,0,0,0,27,0,0,0,8,8,2,0,0,0,0,0,0,0,0,0,0,0,0,0,0,0,0,0,0,0,0,0,0,0,0,0,0,0,0
0,0,0,0,0,0,0,0,0,0,0,0,0,2,0,17,2,8,8,2,0,0,0,0,0,0,12,0,0,0,0,0,0,0,0,0,0,0,0,0,0,0,0,0,0,0,0,0
0,0,0,0,0,0,0,0,0,0,0,0,0,27,0,0,21,21,21,27,0,0,0,0,24,24,24,24,24,0,0,0,0,0,0,0,0,0,0,0,0,0,0,0,0,0,0,0
0,0,0,0,0,0,0,0,0,0,0,0,0,2,0,0,21,21,21,2,0,0,0,0,24,23,23,23,24,0,0,0,0,0,0,0,0,0,0,0,0,0,0,0,0,0,0,0
0,0,0,0,0,0,0,0,0,0,0,0,2,2,2,27,2,2,2,2,2,0,0,0,24,23,0,23,24,0,0,0,0,0,0,0,0,0,0,0,0,0,0,0,0,0,0,0
0,0,0,0,0,0,0,0,0,0,0,0,0,2,0,0,0,0,0,2,0,0,0,0,24,23,0,23,24,0,0,0,0,0,0,0,0,0,0,0,0,0,0,0,0,0,0,0
0,0,0,0,0,0,0,0,0,0,0,0,0,0,0,0,0,0,0,0,0,0,0,0,24,23,0,23,24,0,0,0,0,0,0,0,0,0,0,0,0,0,0,0,0,0,0,0
0,0,0,0,0,0,0,0,0,0,0,0,0,0,0,0,0,0,0,0,0,0,0,12,24,23,0,23,24,12,0,0,0,0,0,0,0,0,0,0,0,0,0,0,0,0,0,0
0,0,0,0,0,0,0,0,0,0,0,0,0,0,0,0,0,0,0,0,0,0,0,0,24,23,0,23,24,0,0,0,0,0,0,0,0,0,0,0,0,0,0,0,0,0,0,0
0,0,0,0,0,0,0,0,0,0,0,0,0,0,0,0,0,0,0,0,0,0,0,0,24,23,0,23,24,0,0,0,0,0,0,0,0,0,0,0,0,0,0,0,0,0,0,0
0,0,0,0,0,0,0,0,0,0,0,0,0,0,0,0,0,0,0,0,0,0,0,0,24,23,0,23,24,0,0,0,0,0,0,0,0,0,0,0,0,0,0,0,0,0,0,0
0,0,0,0,0,0,0,0,0,0,0,0,0,0,0,0,0,0,0,0,0,0,0,0,24,23,23,23,24,0,0,0,0,0,0,0,0,0,0,0,0,0,0,0,0,0,0,0
0,0,0,0,0,0,0,0,0,0,0,0,0,0,0,0,0,0,0,0,0,0,0,0,24,24,24,24,24,0,0,0,0,0,0,0,0,0,0,0,0,0,0,0,0,0,0,0
0,0,0,0,0,0,0,0,0,0,0,0,0,0,0,0,0,0,0,0,0,0,0,0,0,0,12,0,0,0,0,0,0,0,0,0,0,0,0,0,0,0,0,0,0,0,0,0
0,0,0,0,0,0,0,0,0,0,0,0,0,0,0,0,3,14,3,14,3,14,3,0,0,0,0,0,0,0,3,14,3,14,3,14,3,0,0,0,0,0,0,0,0,0,0,0
0,0,0,0,0,0,0,0,0,0,0,0,0,0,0,0,47,0,0,25,0,0,15,0,0,0,0,0,0,0,47,0,0,25,0,0,15,0,0,0,0,0,0,0,0,0,0,0
0,0,0,0,0,0,0,0,0,0,0,0,0,0,0,0,3,0,0,0,0,0,3,0,0,0,0,0,0,0,3,0,0,0,0,0,3,0,0,0,0,0,0,0,0,0,0,0
0,0,0,0,0,0,0,0,0,0,0,0,0,0,0,0,47,19,0,28,0,17,15,0,0,0,0,0,0,0,47,19,0,28,0,17,15,0,0,0,0,0,0,0,0,0,0,0
0,0,0,0,0,0,0,0,0,0,0,0,0,0,0,0,3,0,0,0,0,0,3,0,0,0,0,0,0,0,3,0,0,0,0,0,3,0,0,0,0,0,0,0,0,0,0,0
0,0,0,0,0,0,0,0,0,0,0,0,0,0,0,0,47,0,0,26,0,0,15,0,0,0,0,0,0,0,47,0,0,26,0,0,15,0,0,0,0,0,0,0,0,0,0,0
0,0,0,0,0,0,0,0,0,0,0,0,0,0,0,0,3,18,3,18,3,18,3,0,0,0,0,0,0,0,3,18,3,18,3,18,3,0,0,0,0,0,0,0,0,0,0,0
0,0,0,0,0,0,0,0,0,0,0,0,0,0,0,0,0,0,0,0,0,0,0,0,0,0,0,0,0,0,0,0,0,0,0,0,0,0,0,0,0,0,0,0,0,0,0,0
0,0,0,0,0,0,0,0,0,0,0,0,0,0,0,0,0,0,0,0,0,0,0,0,0,0,0,0,0,0,0,0,0,0,0,0,0,0,0,0,0,0,0,0,0,0,0,0
0,0,0,0,0,0,0,0,0,0,0,0,0,0,0,0,0,0,0,0,0,0,0,0,0,0,0,0,0,0,0,0,0,0,0,0,0,0,0,0,0,0,0,0,0,0,0,0
0,0,0,0,0,0,0,0,0,0,0,0,0,0,0,0,0,0,0,0,0,0,0,0,0,0,0,0,0,0,0,0,0,0,0,0,0,0,0,0,0,0,0,0,0,0,0,0
0,0,0,0,0,0,0,0,0,0,0,0,0,0,0,0,0,0,0,0,0,0,0,0,0,0,0,0,0,0,0,0,0,0,0,0,0,0,0,0,0,0,0,0,0,0,0,0
0,0,0,0,0,0,0,0,0,0,0,0,0,0,0,0,0,0,0,0,0,0,0,0,0,0,0,0,0,0,0,0,0,0,0,0,0,0,0,0,0,0,0,0,0,0,0,0
0,0,0,0,0,0,0,0,0,0,0,0,0,0,0,0,0,0,0,0,0,0,0,0,0,0,0,0,0,0,0,0,0,0,0,0,0,0,0,0,0,0,0,0,0,0,0,0
0,0,0,0,0,0,0,0,0,0,0,0,0,0,0,0,0,0,0,0,0,0,0,0,0,0,0,0,0,0,0,0,0,0,0,0,0,0,0,0,0,0,0,0,0,0,0,0
0,0,0,0,0,0,0,0,0,0,0,0,0,0,0,0,0,0,0,0,0,0,0,0,0,0,0,0,0,0,0,0,0,0,0,0,0,0,0,0,0,0,0,0,0,0,0,0
0,0,0,0,0,0,0,0,0,0,0,0,0,0,0,0,0,0,0,0,0,0,0,0,0,0,0,0,0,0,0,0,0,0,0,0,0,0,0,0,0,0,0,0,0,0,0,0
0,0,0,0,0,0,0,0,0,0,0,0,0,0,0,0,0,0,0,0,0,0,0,0,0,0,0,0,0,0,0,0,0,0,0,0,0,0,0,0,0,0,0,0,0,0,0,0
0,0,0,0,0,0,0,0,0,0,0,0,0,0,0,0,0,0,0,0,0,0,0,0,0,0,0,0,0,0,0,0,0,0,0,0,0,0,0,0,0,0,0,0,0,0,0,0
0,0,0,0,12,0,0,0,0,0,0,0,0,0,0,0,0,0,0,0,0,0,0,0,0,0,0,0,0,28,0,0,0,0,0,0,0,0,0,0,0,0,0,28,0,0,0,0
0,0,0,0,0,0,0,0,0,0,0,0,0,0,0,0,0,0,0,0,0,0,0,0,0,0,0,0,0,0,0,0,0,0,0,0,0,0,0,0,0,0,0,0,0,0,0,0
0,0,0,0,0,0,0,0,0,0,0,0,0,0,0,0,0,0,0,0,0,0,0,0,0,0,0,0,0,0,0,0,0,0,0,0,0,0,0,0,0,0,0,0,0,0,0,0
0,0,0,0,0,0,0,0,0,0,0,0,0,0,0,0,0,0,0,0,0,0,0,0,0,0,0,0,0,0,0,0,0,0,0,0,0,0,0,0,0,0,0,0,0,0,0,0
0,0,0,0,0,0,0,0,0,0,0,0,0,0,0,0,0,0,0,0,0,0,0,0,0,0,0,0,0,0,0,0,0,0,0,0,0,0,0,0,0,0,0,0,0,0,0,0
:endlayer
layer: 18
0,0,0,0,0,0,0,0,0,0,0,0,0,0,0,0,0,0,0,0,0,0,0,0,0,0,0,0,0,0,0,0,0,0,0,0,0,0,0,0,0,0,0,0,0,0,0,0
0,0,0,0,0,0,0,0,0,0,0,0,0,0,0,0,0,0,0,0,0,0,0,0,0,0,0,0,0,0,0,0,0,0,0,0,0,0,0,0,0,0,0,0,0,0,0,0
0,0,0,0,0,0,0,0,0,0,0,0,0,0,0,0,0,0,0,0,0,0,0,0,0,0,0,0,0,0,0,0,0,0,0,0,0,0,0,0,0,0,0,0,0,0,0,0
0,0,0,0,0,0,0,0,0,0,0,0,0,0,0,0,0,0,0,0,0,0,0,0,0,0,0,0,0,0,0,0,0,0,0,0,0,0,0,0,0,0,0,0,0,0,0,0
0,0,0,0,0,0,0,0,0,0,0,0,0,2,0,0,0,0,0,2,0,0,0,0,0,0,0,0,0,0,0,0,0,0,0,0,0,0,0,0,0,0,0,0,0,0,0,0
0,0,0,0,0,0,0,0,0,0,0,0,2,2,2,21,2,0,2,2,2,0,0,0,0,0,28,0,0,0,0,0,0,0,0,0,0,0,0,0,0,0,0,0,0,0,0,0
0,0,0,0,0,0,0,0,0,0,0,0,0,2,0,0,0,0,0,2,0,0,0,0,0,0,0,0,0,0,0,0,0,0,0,0,0,0,0,0,0,0,0,0,0,0,0,0
0,0,0,0,0,0,0,0,0,0,0,0,0,27,0,0,26,0,0,27,0,0,0,0,0,0,0,0,0,0,0,0,0,0,0,0,0,0,0,0,0,0,0,0,0,0,0,0
0,0,0,0,0,0,0,0,0,0,0,0,0,2,21,21,2,0,0,2,0,0,0,0,0,0,0,0,0,0,0,0,0,0,0,0,0,0,0,0,0,0,0,0,0,0,0,0
0,0,0,0,0,0,0,0,0,0,0,0,0,2,8,8,0,0,0,2,0,0,0,0,0,0,0,0,0,0,0,0,0,0,0,0,0,0,0,0,0,0,0,0,0,0,0,0
0,0,0,0,0,0,0,0,0,0,0,0,0,2,8,8,0,0,0,2,0,0,0,0,0,0,12,0,0,0,0,0,0,0,0,0,0,0,0,0,0,0,0,0,0,0,0,0
0,0,0,0,0,0,0,0,0,0,0,0,2,2,2,2,2,27,2,2,2,0,0,0,0,0,24,0,0,0,0,0,0,0,0,0,0,0,0,0,0,0,0,0,0,0,0,0
0,0,0,0,0,0,0,0,0,0,0,0,0,2,0,0,0,0,0,2,0,0,0,0,0,0,24,0,0,0,0,0,0,0,0,0,0,0,0,0,0,0,0,0,0,0,0,0
0,0,0,0,0,0,0,0,0,0,0,0,0,0,0,0,0,0,0,0,0,0,0,0,0,0,24,0,0,0,0,0,0,0,0,0,0,0,0,0,0,0,0,0,0,0,0,0
0,0,0,0,0,0,0,0,0,0,0,0,0,0,0,0,0,0,0,0,0,0,0,0,0,12,24,12,0,0,0,0,0,0,0,0,0,0,0,0,0,0,0,0,0,0,0,0
0,0,0,0,0,0,0,0,0,0,0,0,0,0,0,0,0,0,0,0,0,0,0,0,0,0,24,0,0,0,0,0,0,0,0,0,0,0,0,0,0,0,0,0,0,0,0,0
0,0,0,0,0,0,0,0,0,0,0,0,0,0,0,0,0,0,0,0,0,0,0,0,0,0,24,0,0,0,0,0,0,0,0,0,0,0,0,0,0,0,0,0,0,0,0,0
0,0,0,0,0,0,0,0,0,0,0,0,0,0,0,0,0,0,0,0,0,0,0,0,0,0,24,0,0,0,0,0,0,0,0,0,0,0,0,0,0,0,0,0,0,0,0,0
0,0,0,0,0,0,0,0,0,0,0,0,0,0,0,0,0,0,0,0,0,0,0,0,0,0,12,0,0,0,0,0,0,0,0,0,0,0,0,0,0,0,0,0,0,0,0,0
0,0,0,0,0,0,0,0,0,0,0,0,0,0,0,0,0,0,0,0,0,0,0,0,0,0,0,0,0,0,0,0,0,0,0,0,0,0,0,0,0,0,0,0,0,0,0,0
0,0,0,0,0,0,0,0,0,0,0,0,0,0,0,0,0,0,0,0,0,0,0,0,0,0,0,0,0,0,0,0,0,0,0,0,0,0,0,0,0,0,0,0,0,0,0,0
0,0,0,0,0,0,0,0,0,0,0,0,0,0,0,0,8,0,8,0,8,0,8,0,0,0,0,0,0,0,8,0,8,0,8,0,8,0,0,0,0,0,0,0,0,0,0,0
0,0,0,0,0,0,0,0,0,0,0,0,0,0,0,0,0,0,0,0,0,0,0,0,0,0,0,0,0,0,0,0,0,0,0,0,0,0,0,0,0,0,0,0,0,0,0,0
0,0,0,0,0,0,0,0,0,0,0,0,0,0,0,0,8,0,0,0,0,0,8,0,0,0,0,0,0,0,8,0,0,0,0,0,8,0,0,0,0,0,0,0,0,0,0,0
0,0,0,0,0,0,0,0,0,0,0,0,0,0,0,0,0,0,0,28,0,0,0,0,0,0,0,0,0,0,0,0,0,28,0,0,0,0,0,0,0,0,0,0,0,0,0,0
0,0,0,0,0,0,0,0,0,0,0,0,0,0,0,0,8,0,0,0,0,0,8,0,0,0,0,0,0,0,8,0,0,0,0,0,8,0,0,0,0,0,0,0,0,0,0,0
0,0,0,0,0,0,0,0,0,0,0,0,0,0,0,0,0,0,0,0,0,0,0,0,0,0,0,0,0,0,0,0,0,0,0,0,0,0,0,0,0,0,0,0,0,0,0,0
0,0,0,0,0,0,0,0,0,0,0,0,0,0,0,0,8,0,8,0,8,0,8,0,0,0,0,0,0,0,8,0,8,0,8,0,8,0,0,0,0,0,0,0,0,0,0,0
0,0,0,0,0,0,0,0,0,0,0,0,0,0,0,0,0,0,0,0,0,0,0,0,0,0,0,0,0,0,0,0,0,0,0,0,0,0,0,0,0,0,0,0,0,0,0,0
0,0,0,0,0,0,0,0,0,0,0,0,0,0,0,0,0,0,0,0,0,0,0,0,0,0,0,0,0,0,0,0,0,0,0,0,0,0,0,0,0,0,0,0,0,0,0,0
0,0,0,0,0,0,0,0,0,0,0,0,0,0,0,0,0,0,0,0,0,0,0,0,0,0,0,0,0,0,0,0,0,0,0,0,0,0,0,0,0,0,0,0,0,0,0,0
0,0,0,0,0,0,0,0,0,0,0,0,0,0,0,0,0,0,0,0,0,0,0,0,0,0,0,0,0,0,0,0,0,0,0,0,0,0,0,0,0,0,0,0,0,0,0,0
0,0,0,0,0,0,0,0,0,0,0,0,0,0,0,0,0,0,0,0,0,0,0,0,0,0,0,0,0,0,0,0,0,0,0,0,0,0,0,0,0,0,0,0,0,0,0,0
0,0,0,0,0,0,0,0,0,0,0,0,0,0,0,0,0,0,0,0,0,0,0,0,0,0,0,0,0,0,0,0,0,0,0,0,0,0,0,0,0,0,0,0,0,0,0,0
0,0,0,0,0,0,0,0,0,0,0,0,0,0,0,0,0,0,0,0,0,0,0,0,0,0,0,0,0,0,0,0,0,0,0,0,0,0,0,0,0,0,0,0,0,0,0,0
0,0,0,0,0,0,0,0,0,0,0,0,0,0,0,0,0,0,0,0,0,0,0,0,0,0,0,0,0,0,0,0,0,0,0,0,0,0,0,0,0,0,0,0,0,0,0,0
0,0,0,0,0,0,0,0,0,0,0,0,0,0,0,0,0,0,0,0,0,0,0,0,0,0,0,0,0,0,0,0,0,0,0,0,0,0,0,0,0,0,0,0,0,0,0,0
0,0,0,0,0,0,0,0,0,0,0,0,0,0,0,0,0,0,0,0,0,0,0,0,0,0,0,0,0,0,0,0,0,0,0,0,0,0,0,0,0,0,0,0,0,0,0,0
0,0,0,0,0,0,0,0,0,0,0,0,0,0,0,0,0,0,0,0,0,0,0,0,0,0,0,0,0,0,0,0,0,0,0,0,0,0,0,0,0,0,0,0,0,0,0,0
0,0,0,0,0,0,0,0,0,0,0,0,0,0,0,0,0,0,0,0,0,0,0,0,0,0,0,0,0,0,0,0,0,0,0,0,0,0,0,0,0,0,0,0,0,0,0,0
0,0,0,0,0,0,0,0,0,0,0,0,0,0,0,0,0,0,0,0,0,0,0,0,0,0,0,0,0,22,0,0,0,0,0,0,0,0,0,0,0,0,0,22,0,0,0,0
0,0,0,0,0,0,0,0,0,0,0,0,0,0,0,0,0,0,0,0,0,0,0,0,0,0,0,0,0,0,0,0,0,0,0,0,0,0,0,0,0,0,0,0,0,0,0,0
0,0,0,0,0,0,0,0,0,0,0,0,0,0,0,0,0,0,0,0,0,0,0,0,0,0,0,0,0,0,0,0,0,0,0,0,0,0,0,0,0,0,0,0,0,0,0,0
0,0,0,0,0,0,0,0,0,0,0,0,0,0,0,0,0,0,0,0,0,0,0,0,0,0,0,0,0,0,0,0,0,0,0,0,0,0,0,0,0,0,0,0,0,0,0,0
0,0,0,0,0,0,0,0,0,0,0,0,0,0,0,0,0,0,0,0,0,0,0,0,0,0,0,0,0,0,0,0,0,0,0,0,0,0,0,0,0,0,0,0,0,0,0,0
:endlayer
layer: 19
0,0,0,0,0,0,0,0,0,0,0,0,0,0,0,0,0,0,0,0,0,0,0,0,0,0,0,0,0,0,0,0,0,0,0,0,0,0,0,0,0,0,0,0,0,0,0,0
0,0,0,0,0,0,0,0,0,0,0,0,0,0,0,0,0,0,0,0,0,0,0,0,0,0,0,0,0,0,0,0,0,0,0,0,0,0,0,0,0,0,0,0,0,0,0,0
0,0,0,0,0,0,0,0,0,0,0,0,0,0,0,0,0,0,0,0,0,0,0,0,0,0,0,0,0,0,0,0,0,0,0,0,0,0,0,0,0,0,0,0,0,0,0,0
0,0,0,0,0,0,0,0,0,0,0,0,0,0,0,0,0,0,0,0,0,0,0,0,0,0,0,0,0,0,0,0,0,0,0,0,0,0,0,0,0,0,0,0,0,0,0,0
0,0,0,0,0,0,0,0,0,0,0,0,0,2,0,0,0,0,0,2,0,0,0,0,0,0,0,0,0,0,0,0,0,0,0,0,0,0,0,0,0,0,0,0,0,0,0,0
0,0,0,0,0,0,0,0,0,0,0,0,2,2,2,2,2,21,2,2,2,0,0,0,0,0,8,0,0,0,0,0,0,0,0,0,0,0,0,0,0,0,0,0,0,0,0,0
0,0,0,0,0,0,0,0,0,0,0,0,0,2,8,8,21,0,0,2,0,0,0,0,0,0,0,0,0,0,0,0,0,0,0,0,0,0,0,0,0,0,0,0,0,0,0,0
0,0,0,0,0,0,0,0,0,0,0,0,0,2,8,8,21,0,0,27,0,0,0,0,0,0,0,0,0,0,0,0,0,0,0,0,0,0,0,0,0,0,0,0,0,0,0,0
0,0,0,0,0,0,0,0,0,0,0,0,0,2,0,0,2,19,0,2,0,0,0,0,0,0,0,0,0,0,0,0,0,0,0,0,0,0,0,0,0,0,0,0,0,0,0,0
0,0,0,0,0,0,0,0,0,0,0,0,0,2,0,0,0,0,0,27,0,0,0,0,0,0,0,0,0,0,0,0,0,0,0,0,0,0,0,0,0,0,0,0,0,0,0,0
0,0,0,0,0,0,0,0,0,0,0,0,0,2,0,0,0,0,0,2,0,0,0,0,0,0,0,0,0,0,0,0,0,0,0,0,0,0,0,0,0,0,0,0,0,0,0,0
0,0,0,0,0,0,0,0,0,0,0,0,2,2,2,27,2,27,2,2,2,0,0,0,0,0,0,0,0,0,0,0,0,0,0,0,0,0,0,0,0,0,0,0,0,0,0,0
0,0,0,0,0,0,0,0,0,0,0,0,0,2,0,0,0,0,0,2,0,0,0,0,0,0,0,0,0,0,0,0,0,0,0,0,0,0,0,0,0,0,0,0,0,0,0,0
0,0,0,0,0,0,0,0,0,0,0,0,0,0,0,0,0,0,0,0,0,0,0,0,0,0,0,0,0,0,0,0,0,0,0,0,0,0,0,0,0,0,0,0,0,0,0,0
0,0,0,0,0,0,0,0,0,0,0,0,0,0,0,0,0,0,0,0,0,0,0,0,0,0,0,0,0,0,0,0,0,0,0,0,0,0,0,0,0,0,0,0,0,0,0,0
0,0,0,0,0,0,0,0,0,0,0,0,0,0,0,0,0,0,0,0,0,0,0,0,0,0,0,0,0,0,0,0,0,0,0,0,0,0,0,0,0,0,0,0,0,0,0,0
0,0,0,0,0,0,0,0,0,0,0,0,0,0,0,0,0,0,0,0,0,0,0,0,0,0,0,0,0,0,0,0,0,0,0,0,0,0,0,0,0,0,0,0,0,0,0,0
0,0,0,0,0,0,0,0,0,0,0,0,0,0,0,0,0,0,0,0,0,0,0,0,0,0,0,0,0,0,0,0,0,0,0,0,0,0,0,0,0,0,0,0,0,0,0,0
0,0,0,0,0,0,0,0,0,0,0,0,0,0,0,0,0,0,0,0,0,0,0,0,0,0,0,0,0,0,0,0,0,0,0,0,0,0,0,0,0,0,0,0,0,0,0,0
0,0,0,0,0,0,0,0,0,0,0,0,0,0,0,0,0,0,0,0,0,0,0,0,0,0,0,0,0,0,0,0,0,0,0,0,0,0,0,0,0,0,0,0,0,0,0,0
0,0,0,0,0,0,0,0,0,0,0,0,0,0,0,0,0,0,0,0,0,0,0,0,0,0,0,0,0,0,0,0,0,0,0,0,0,0,0,0,0,0,0,0,0,0,0,0
0,0,0,0,0,0,0,0,0,0,0,0,0,0,0,0,0,0,0,0,0,0,0,0,0,0,0,0,0,0,0,0,0,0,0,0,0,0,0,0,0,0,0,0,0,0,0,0
0,0,0,0,0,0,0,0,0,0,0,0,0,0,0,0,0,0,0,0,0,0,0,0,0,0,0,0,0,0,0,0,0,0,0,0,0,0,0,0,0,0,0,0,0,0,0,0
0,0,0,0,0,0,0,0,0,0,0,0,0,0,0,0,0,0,0,0,0,0,0,0,0,0,0,0,0,0,0,0,0,0,0,0,0,0,0,0,0,0,0,0,0,0,0,0
0,0,0,0,0,0,0,0,0,0,0,0,0,0,0,0,0,0,0,22,0,0,0,0,0,0,0,0,0,0,0,0,0,22,0,0,0,0,0,0,0,0,0,0,0,0,0,0
0,0,0,0,0,0,0,0,0,0,0,0,0,0,0,0,0,0,0,0,0,0,0,0,0,0,0,0,0,0,0,0,0,0,0,0,0,0,0,0,0,0,0,0,0,0,0,0
0,0,0,0,0,0,0,0,0,0,0,0,0,0,0,0,0,0,0,0,0,0,0,0,0,0,0,0,0,0,0,0,0,0,0,0,0,0,0,0,0,0,0,0,0,0,0,0
0,0,0,0,0,0,0,0,0,0,0,0,0,0,0,0,0,0,0,0,0,0,0,0,0,0,0,0,0,0,0,0,0,0,0,0,0,0,0,0,0,0,0,0,0,0,0,0
0,0,0,0,0,0,0,0,0,0,0,0,0,0,0,0,0,0,0,0,0,0,0,0,0,0,0,0,0,0,0,0,0,0,0,0,0,0,0,0,0,0,0,0,0,0,0,0
0,0,0,0,0,0,0,0,0,0,0,0,0,0,0,0,0,0,0,0,0,0,0,0,0,0,0,0,0,0,0,0,0,0,0,0,0,0,0,0,0,0,0,0,0,0,0,0
0,0,0,0,0,0,0,0,0,0,0,0,0,0,0,0,0,0,0,0,0,0,0,0,0,0,0,0,0,0,0,0,0,0,0,0,0,0,0,0,0,0,0,0,0,0,0,0
0,0,0,0,0,0,0,0,0,0,0,0,0,0,0,0,0,0,0,0,0,0,0,0,0,0,0,0,0,0,0,0,0,0,0,0,0,0,0,0,0,0,0,0,0,0,0,0
0,0,0,0,0,0,0,0,0,0,0,0,0,0,0,0,0,0,0,0,0,0,0,0,0,0,0,0,0,0,0,0,0,0,0,0,0,0,0,0,0,0,0,0,0,0,0,0
0,0,0,0,0,0,0,0,0,0,0,0,0,0,0,0,0,0,0,0,0,0,0,0,0,0,0,0,0,0,0,0,0,0,0,0,0,0,0,0,0,0,0,0,0,0,0,0
0,0,0,0,0,0,0,0,0,0,0,0,0,0,0,0,0,0,0,0,0,0,0,0,0,0,0,0,0,0,0,0,0,0,0,0,0,0,0,0,0,0,0,0,0,0,0,0
0,0,0,0,0,0,0,0,0,0,0,0,0,0,0,0,0,0,0,0,0,0,0,0,0,0,0,0,0,0,0,0,0,0,0,0,0,0,0,0,0,0,0,0,0,0,0,0
0,0,0,0,0,0,0,0,0,0,0,0,0,0,0,0,0,0,0,0,0,0,0,0,0,0,0,0,0,0,0,0,0,0,0,0,0,0,0,0,0,0,0,0,0,0,0,0
0,0,0,0,0,0,0,0,0,0,0,0,0,0,0,0,0,0,0,0,0,0,0,0,0,0,0,0,0,0,0,0,0,0,0,0,0,0,0,0,0,0,0,0,0,0,0,0
0,0,0,0,0,0,0,0,0,0,0,0,0,0,0,0,0,0,0,0,0,0,0,0,0,0,0,0,0,0,0,0,0,0,0,0,0,0,0,0,0,0,0,0,0,0,0,0
0,0,0,0,0,0,0,0,0,0,0,0,0,0,0,0,0,0,0,0,0,0,0,0,0,0,0,0,0,0,0,0,0,0,0,0,0,0,0,0,0,0,0,0,0,0,0,0
0,0,0,0,0,0,0,0,0,0,0,0,0,0,0,0,0,0,0,0,0,0,0,0,0,0,0,0,0,12,0,0,0,0,0,0,0,0,0,0,0,0,0,12,0,0,0,0
0,0,0,0,0,0,0,0,0,0,0,0,0,0,0,0,0,0,0,0,0,0,0,0,0,0,0,0,0,0,0,0,0,0,0,0,0,0,0,0,0,0,0,0,0,0,0,0
0,0,0,0,0,0,0,0,0,0,0,0,0,0,0,0,0,0,0,0,0,0,0,0,0,0,0,0,0,0,0,0,0,0,0,0,0,0,0,0,0,0,0,0,0,0,0,0
0,0,0,0,0,0,0,0,0,0,0,0,0,0,0,0,0,0,0,0,0,0,0,0,0,0,0,0,0,0,0,0,0,0,0,0,0,0,0,0,0,0,0,0,0,0,0,0
0,0,0,0,0,0,0,0,0,0,0,0,0,0,0,0,0,0,0,0,0,0,0,0,0,0,0,0,0,0,0,0,0,0,0,0,0,0,0,0,0,0,0,0,0,0,0,0
:endlayer
layer: 20
0,0,0,0,0,0,0,0,0,0,0,0,0,0,0,0,0,0,0,0,0,0,0,0,0,0,0,0,0,0,0,0,0,0,0,0,0,0,0,0,0,0,0,0,0,0,0,0
0,0,0,0,0,0,0,0,0,0,0,0,0,0,0,0,0,0,0,0,0,0,0,0,0,0,0,0,0,0,0,0,0,0,0,0,0,0,0,0,0,0,0,0,0,0,0,0
0,0,0,0,0,0,0,0,0,0,0,0,0,0,0,0,0,0,0,0,0,0,0,0,0,0,0,0,0,0,0,0,0,0,0,0,0,0,0,0,0,0,0,0,0,0,0,0
0,0,0,0,0,0,0,0,0,0,0,0,0,0,0,0,0,0,0,0,0,0,0,0,0,0,0,0,0,0,0,0,0,0,0,0,0,0,0,0,0,0,0,0,0,0,0,0
0,0,0,0,0,0,0,0,0,0,0,0,0,2,0,0,0,0,0,2,0,0,0,0,0,0,0,0,0,0,0,0,0,0,0,0,0,0,0,0,0,0,0,0,0,0,0,0
0,0,0,0,0,0,0,0,0,0,0,0,2,2,2,2,2,2,2,2,2,0,0,0,0,0,0,0,0,0,0,0,0,0,0,0,0,0,0,0,0,0,0,0,0,0,0,0
0,0,0,0,0,0,0,0,0,0,0,0,0,2,0,0,0,8,8,2,0,0,0,0,0,0,0,0,0,0,0,0,0,0,0,0,0,0,0,0,0,0,0,0,0,0,0,0
0,0,0,0,0,0,0,0,0,0,0,0,0,2,0,0,0,8,8,2,0,0,0,0,0,0,0,0,0,0,0,0,0,0,0,0,0,0,0,0,0,0,0,0,0,0,0,0
0,0,0,0,0,0,0,0,0,0,0,0,0,2,0,0,2,21,21,2,0,0,0,0,0,0,0,0,0,0,0,0,0,0,0,0,0,0,0,0,0,0,0,0,0,0,0,0
0,0,0,0,0,0,0,0,0,0,0,0,0,2,0,0,25,0,0,27,0,0,0,0,0,0,0,0,0,0,0,0,0,0,0,0,0,0,0,0,0,0,0,0,0,0,0,0
0,0,0,0,0,0,0,0,0,0,0,0,0,2,0,0,0,0,0,2,0,0,0,0,0,0,0,0,0,0,0,0,0,0,0,0,0,0,0,0,0,0,0,0,0,0,0,0
0,0,0,0,0,0,0,0,0,0,0,0,2,2,2,27,2,2,2,2,2,0,0,0,0,0,0,0,0,0,0,0,0,0,0,0,0,0,0,0,0,0,0,0,0,0,0,0
0,0,0,0,0,0,0,0,0,0,0,0,0,2,0,0,0,0,0,2,0,0,0,0,0,0,0,0,0,0,0,0,0,0,0,0,0,0,0,0,0,0,0,0,0,0,0,0
0,0,0,0,0,0,0,0,0,0,0,0,0,0,0,0,0,0,0,0,0,0,0,0,0,0,0,0,0,0,0,0,0,0,0,0,0,0,0,0,0,0,0,0,0,0,0,0
0,0,0,0,0,0,0,0,0,0,0,0,0,0,0,0,0,0,0,0,0,0,0,0,0,0,0,0,0,0,0,0,0,0,0,0,0,0,0,0,0,0,0,0,0,0,0,0
0,0,0,0,0,0,0,0,0,0,0,0,0,0,0,0,0,0,0,0,0,0,0,0,0,0,0,0,0,0,0,0,0,0,0,0,0,0,0,0,0,0,0,0,0,0,0,0
0,0,0,0,0,0,0,0,0,0,0,0,0,0,0,0,0,0,0,0,0,0,0,0,0,0,0,0,0,0,0,0,0,0,0,0,0,0,0,0,0,0,0,0,0,0,0,0
0,0,0,0,0,0,0,0,0,0,0,0,0,0,0,0,0,0,0,0,0,0,0,0,0,0,0,0,0,0,0,0,0,0,0,0,0,0,0,0,0,0,0,0,0,0,0,0
0,0,0,0,0,0,0,0,0,0,0,0,0,0,0,0,0,0,0,0,0,0,0,0,0,0,0,0,0,0,0,0,0,0,0,0,0,0,0,0,0,0,0,0,0,0,0,0
0,0,0,0,0,0,0,0,0,0,0,0,0,0,0,0,0,0,0,0,0,0,0,0,0,0,0,0,0,0,0,0,0,0,0,0,0,0,0,0,0,0,0,0,0,0,0,0
0,0,0,0,0,0,0,0,0,0,0,0,0,0,0,0,0,0,0,0,0,0,0,0,0,0,0,0,0,0,0,0,0,0,0,0,0,0,0,0,0,0,0,0,0,0,0,0
0,0,0,0,0,0,0,0,0,0,0,0,0,0,0,0,0,0,0,0,0,0,0,0,0,0,0,0,0,0,0,0,0,0,0,0,0,0,0,0,0,0,0,0,0,0,0,0
0,0,0,0,0,0,0,0,0,0,0,0,0,0,0,0,0,0,0,0,0,0,0,0,0,0,0,0,0,0,0,0,0,0,0,0,0,0,0,0,0,0,0,0,0,0,0,0
0,0,0,0,0,0,0,0,0,0,0,0,0,0,0,0,0,0,0,0,0,0,0,0,0,0,0,0,0,0,0,0,0,0,0,0,0,0,0,0,0,0,0,0,0,0,0,0
0,0,0,0,0,0,0,0,0,0,0,0,0,0,0,0,0,0,0,12,0,0,0,0,0,0,0,0,0,0,0,0,0,12,0,0,0,0,0,0,0,0,0,0,0,0,0,0
0,0,0,0,0,0,0,0,0,0,0,0,0,0,0,0,0,0,0,0,0,0,0,0,0,0,0,0,0,0,0,0,0,0,0,0,0,0,0,0,0,0,0,0,0,0,0,0
0,0,0,0,0,0,0,0,0,0,0,0,0,0,0,0,0,0,0,0,0,0,0,0,0,0,0,0,0,0,0,0,0,0,0,0,0,0,0,0,0,0,0,0,0,0,0,0
0,0,0,0,0,0,0,0,0,0,0,0,0,0,0,0,0,0,0,0,0,0,0,0,0,0,0,0,0,0,0,0,0,0,0,0,0,0,0,0,0,0,0,0,0,0,0,0
0,0,0,0,0,0,0,0,0,0,0,0,0,0,0,0,0,0,0,0,0,0,0,0,0,0,0,0,0,0,0,0,0,0,0,0,0,0,0,0,0,0,0,0,0,0,0,0
0,0,0,0,0,0,0,0,0,0,0,0,0,0,0,0,0,0,0,0,0,0,0,0,0,0,0,0,0,0,0,0,0,0,0,0,0,0,0,0,0,0,0,0,0,0,0,0
0,0,0,0,0,0,0,0,0,0,0,0,0,0,0,0,0,0,0,0,0,0,0,0,0,0,0,0,0,0,0,0,0,0,0,0,0,0,0,0,0,0,0,0,0,0,0,0
0,0,0,0,0,0,0,0,0,0,0,0,0,0,0,0,0,0,0,0,0,0,0,0,0,0,0,0,0,0,0,0,0,0,0,0,0,0,0,0,0,0,0,0,0,0,0,0
0,0,0,0,0,0,0,0,0,0,0,0,0,0,0,0,0,0,0,0,0,0,0,0,0,0,0,0,0,0,0,0,0,0,0,0,0,0,0,0,0,0,0,0,0,0,0,0
0,0,0,0,0,0,0,0,0,0,0,0,0,0,0,0,0,0,0,0,0,0,0,0,0,0,0,0,0,0,0,0,0,0,0,0,0,0,0,0,0,0,0,0,0,0,0,0
0,0,0,0,0,0,0,0,0,0,0,0,0,0,0,0,0,0,0,0,0,0,0,0,0,0,0,0,0,0,0,0,0,0,0,0,0,0,0,0,0,0,0,0,0,0,0,0
0,0,0,0,0,0,0,0,0,0,0,0,0,0,0,0,0,0,0,0,0,0,0,0,0,0,0,0,0,0,0,0,0,0,0,0,0,0,0,0,0,0,0,0,0,0,0,0
0,0,0,0,0,0,0,0,0,0,0,0,0,0,0,0,0,0,0,0,0,0,0,0,0,0,0,0,0,0,0,0,0,0,0,0,0,0,0,0,0,0,0,0,0,0,0,0
0,0,0,0,0,0,0,0,0,0,0,0,0,0,0,0,0,0,0,0,0,0,0,0,0,0,0,0,0,0,0,0,0,0,0,0,0,0,0,0,0,0,0,0,0,0,0,0
0,0,0,0,0,0,0,0,0,0,0,0,0,0,0,0,0,0,0,0,0,0,0,0,0,0,0,0,0,0,0,0,0,0,0,0,0,0,0,0,0,0,0,0,0,0,0,0
0,0,0,0,0,0,0,0,0,0,0,0,0,0,0,0,0,0,0,0,0,0,0,0,0,0,0,0,0,0,0,0,0,0,0,0,0,0,0,0,0,0,0,0,0,0,0,0
0,0,0,0,0,0,0,0,0,0,0,0,0,0,0,0,0,0,0,0,0,0,0,0,0,0,0,0,0,0,0,0,0,0,0,0,0,0,0,0,0,0,0,0,0,0,0,0
0,0,0,0,0,0,0,0,0,0,0,0,0,0,0,0,0,0,0,0,0,0,0,0,0,0,0,0,0,0,0,0,0,0,0,0,0,0,0,0,0,0,0,0,0,0,0,0
0,0,0,0,0,0,0,0,0,0,0,0,0,0,0,0,0,0,0,0,0,0,0,0,0,0,0,0,0,0,0,0,0,0,0,0,0,0,0,0,0,0,0,0,0,0,0,0
0,0,0,0,0,0,0,0,0,0,0,0,0,0,0,0,0,0,0,0,0,0,0,0,0,0,0,0,0,0,0,0,0,0,0,0,0,0,0,0,0,0,0,0,0,0,0,0
0,0,0,0,0,0,0,0,0,0,0,0,0,0,0,0,0,0,0,0,0,0,0,0,0,0,0,0,0,0,0,0,0,0,0,0,0,0,0,0,0,0,0,0,0,0,0,0
:endlayer
layer: 21
0,0,0,0,0,0,0,0,0,0,0,0,0,0,0,0,0,0,0,0,0,0,0,0,0,0,0,0,0,0,0,0,0,0,0,0,0,0,0,0,0,0,0,0,0,0,0,0
0,0,0,0,0,0,0,0,0,0,0,0,0,0,0,0,0,0,0,0,0,0,0,0,0,0,0,0,0,0,0,0,0,0,0,0,0,0,0,0,0,0,0,0,0,0,0,0
0,0,0,0,0,0,0,0,0,0,0,0,0,0,0,0,0,0,0,0,0,0,0,0,0,0,0,0,0,0,0,0,0,0,0,0,0,0,0,0,0,0,0,0,0,0,0,0
0,0,0,0,0,0,0,0,0,0,0,0,0,0,0,0,0,0,0,0,0,0,0,0,0,0,0,0,0,0,0,0,0,0,0,0,0,0,0,0,0,0,0,0,0,0,0,0
0,0,0,0,0,0,0,0,0,0,0,0,0,2,46,21,46,21,46,2,0,0,0,0,0,0,0,0,0,0,0,0,0,0,0,0,0,0,0,0,0,0,0,0,0,0,0,0
0,0,0,0,0,0,0,0,0,0,0,0,2,2,2,2,2,2,2,2,2,0,0,0,0,0,0,0,0,0,0,0,0,0,0,0,0,0,0,0,0,0,0,0,0,0,0,0
0,0,0,0,0,0,0,0,0,0,0,0,45,2,0,0,0,0,0,2,44,0,0,0,0,0,0,0,0,0,0,0,0,0,0,0,0,0,0,0,0,0,0,0,0,0,0,0
0,0,0,0,0,0,0,0,0,0,0,0,21,2,0,0,0,0,0,2,21,0,0,0,0,0,0,0,0,0,0,0,0,0,0,0,0,0,0,0,0,0,0,0,0,0,0,0
0,0,0,0,0,0,0,0,0,0,0,0,45,2,21,21,2,0,0,2,44,0,0,0,0,0,0,0,0,0,0,0,0,0,0,0,0,0,0,0,0,0,0,0,0,0,0,0
0,0,0,0,0,0,0,0,0,0,0,0,21,2,21,21,21,8,8,2,21,0,0,0,0,0,0,0,0,0,0,0,0,0,0,0,0,0,0,0,0,0,0,0,0,0,0,0
0,0,0,0,0,0,0,0,0,0,0,0,45,2,21,21,21,8,8,2,44,0,0,0,0,0,0,0,0,0,0,0,0,0,0,0,0,0,0,0,0,0,0,0,0,0,0,0
0,0,0,0,0,0,0,0,0,0,0,0,2,2,2,2,2,2,2,2,2,0,0,0,0,0,0,0,0,0,0,0,0,0,0,0,0,0,0,0,0,0,0,0,0,0,0,0
0,0,0,0,0,0,0,0,0,0,0,0,0,2,34,21,34,21,34,2,0,0,0,0,0,0,0,0,0,0,0,0,0,0,0,0,0,0,0,0,0,0,0,0,0,0,0,0
0,0,0,0,0,0,0,0,0,0,0,0,0,0,0,0,0,0,0,0,0,0,0,0,0,0,0,0,0,0,0,0,0,0,0,0,0,0,0,0,0,0,0,0,0,0,0,0
0,0,0,0,0,0,0,0,0,0,0,0,0,0,0,0,0,0,0,0,0,0,0,0,0,0,0,0,0,0,0,0,0,0,0,0,0,0,0,0,0,0,0,0,0,0,0,0
0,0,0,0,0,0,0,0,0,0,0,0,0,0,0,0,0,0,0,0,0,0,0,0,0,0,0,0,0,0,0,0,0,0,0,0,0,0,0,0,0,0,0,0,0,0,0,0
0,0,0,0,0,0,0,0,0,0,0,0,0,0,0,0,0,0,0,0,0,0,0,0,0,0,0,0,0,0,0,0,0,0,0,0,0,0,0,0,0,0,0,0,0,0,0,0
0,0,0,0,0,0,0,0,0,0,0,0,0,0,0,0,0,0,0,0,0,0,0,0,0,0,0,0,0,0,0,0,0,0,0,0,0,0,0,0,0,0,0,0,0,0,0,0
0,0,0,0,0,0,0,0,0,0,0,0,0,0,0,0,0,0,0,0,0,0,0,0,0,0,0,0,0,0,0,0,0,0,0,0,0,0,0,0,0,0,0,0,0,0,0,0
0,0,0,0,0,0,0,0,0,0,0,0,0,0,0,0,0,0,0,0,0,0,0,0,0,0,0,0,0,0,0,0,0,0,0,0,0,0,0,0,0,0,0,0,0,0,0,0
0,0,0,0,0,0,0,0,0,0,0,0,0,0,0,0,0,0,0,0,0,0,0,0,0,0,0,0,0,0,0,0,0,0,0,0,0,0,0,0,0,0,0,0,0,0,0,0
0,0,0,0,0,0,0,0,0,0,0,0,0,0,0,0,0,0,0,0,0,0,0,0,0,0,0,0,0,0,0,0,0,0,0,0,0,0,0,0,0,0,0,0,0,0,0,0
0,0,0,0,0,0,0,0,0,0,0,0,0,0,0,0,0,0,0,0,0,0,0,0,0,0,0,0,0,0,0,0,0,0,0,0,0,0,0,0,0,0,0,0,0,0,0,0
0,0,0,0,0,0,0,0,0,0,0,0,0,0,0,0,0,0,0,0,0,0,0,0,0,0,0,0,0,0,0,0,0,0,0,0,0,0,0,0,0,0,0,0,0,0,0,0
0,0,0,0,0,0,0,0,0,0,0,0,0,0,0,0,0,0,0,0,0,0,0,0,0,0,0,0,0,0,0,0,0,0,0,0,0,0,0,0,0,0,0,0,0,0,0,0
0,0,0,0,0,0,0,0,0,0,0,0,0,0,0,0,0,0,0,0,0,0,0,0,0,0,0,0,0,0,0,0,0,0,0,0,0,0,0,0,0,0,0,0,0,0,0,0
0,0,0,0,0,0,0,0,0,0,0,0,0,0,0,0,0,0,0,0,0,0,0,0,0,0,0,0,0,0,0,0,0,0,0,0,0,0,0,0,0,0,0,0,0,0,0,0
0,0,0,0,0,0,0,0,0,0,0,0,0,0,0,0,0,0,0,0,0,0,0,0,0,0,0,0,0,0,0,0,0,0,0,0,0,0,0,0,0,0,0,0,0,0,0,0
0,0,0,0,0,0,0,0,0,0,0,0,0,0,0,0,0,0,0,0,0,0,0,0,0,0,0,0,0,0,0,0,0,0,0,0,0,0,0,0,0,0,0,0,0,0,0,0
0,0,0,0,0,0,0,0,0,0,0,0,0,0,0,0,0,0,0,0,0,0,0,0,0,0,0,0,0,0,0,0,0,0,0,0,0,0,0,0,0,0,0,0,0,0,0,0
0,0,0,0,0,0,0,0,0,0,0,0,0,0,0,0,0,0,0,0,0,0,0,0,0,0,0,0,0,0,0,0,0,0,0,0,0,0,0,0,0,0,0,0,0,0,0,0
0,0,0,0,0,0,0,0,0,0,0,0,0,0,0,0,0,0,0,0,0,0,0,0,0,0,0,0,0,0,0,0,0,0,0,0,0,0,0,0,0,0,0,0,0,0,0,0
0,0,0,0,0,0,0,0,0,0,0,0,0,0,0,0,0,0,0,0,0,0,0,0,0,0,0,0,0,0,0,0,0,0,0,0,0,0,0,0,0,0,0,0,0,0,0,0
0,0,0,0,0,0,0,0,0,0,0,0,0,0,0,0,0,0,0,0,0,0,0,0,0,0,0,0,0,0,0,0,0,0,0,0,0,0,0,0,0,0,0,0,0,0,0,0
0,0,0,0,0,0,0,0,0,0,0,0,0,0,0,0,0,0,0,0,0,0,0,0,0,0,0,0,0,0,0,0,0,0,0,0,0,0,0,0,0,0,0,0,0,0,0,0
0,0,0,0,0,0,0,0,0,0,0,0,0,0,0,0,0,0,0,0,0,0,0,0,0,0,0,0,0,0,0,0,0,0,0,0,0,0,0,0,0,0,0,0,0,0,0,0
0,0,0,0,0,0,0,0,0,0,0,0,0,0,0,0,0,0,0,0,0,0,0,0,0,0,0,0,0,0,0,0,0,0,0,0,0,0,0,0,0,0,0,0,0,0,0,0
0,0,0,0,0,0,0,0,0,0,0,0,0,0,0,0,0,0,0,0,0,0,0,0,0,0,0,0,0,0,0,0,0,0,0,0,0,0,0,0,0,0,0,0,0,0,0,0
0,0,0,0,0,0,0,0,0,0,0,0,0,0,0,0,0,0,0,0,0,0,0,0,0,0,0,0,0,0,0,0,0,0,0,0,0,0,0,0,0,0,0,0,0,0,0,0
0,0,0,0,0,0,0,0,0,0,0,0,0,0,0,0,0,0,0,0,0,0,0,0,0,0,0,0,0,0,0,0,0,0,0,0,0,0,0,0,0,0,0,0,0,0,0,0
0,0,0,0,0,0,0,0,0,0,0,0,0,0,0,0,0,0,0,0,0,0,0,0,0,0,0,0,0,0,0,0,0,0,0,0,0,0,0,0,0,0,0,0,0,0,0,0
0,0,0,0,0,0,0,0,0,0,0,0,0,0,0,0,0,0,0,0,0,0,0,0,0,0,0,0,0,0,0,0,0,0,0,0,0,0,0,0,0,0,0,0,0,0,0,0
0,0,0,0,0,0,0,0,0,0,0,0,0,0,0,0,0,0,0,0,0,0,0,0,0,0,0,0,0,0,0,0,0,0,0,0,0,0,0,0,0,0,0,0,0,0,0,0
0,0,0,0,0,0,0,0,0,0,0,0,0,0,0,0,0,0,0,0,0,0,0,0,0,0,0,0,0,0,0,0,0,0,0,0,0,0,0,0,0,0,0,0,0,0,0,0
0,0,0,0,0,0,0,0,0,0,0,0,0,0,0,0,0,0,0,0,0,0,0,0,0,0,0,0,0,0,0,0,0,0,0,0,0,0,0,0,0,0,0,0,0,0,0,0
:endlayer
layer: 22
0,0,0,0,0,0,0,0,0,0,0,0,0,0,0,0,0,0,0,0,0,0,0,0,0,0,0,0,0,0,0,0,0,0,0,0,0,0,0,0,0,0,0,0,0,0,0,0
0,0,0,0,0,0,0,0,0,0,0,0,0,0,0,0,0,0,0,0,0,0,0,0,0,0,0,0,0,0,0,0,0,0,0,0,0,0,0,0,0,0,0,0,0,0,0,0
0,0,0,0,0,0,0,0,0,0,0,0,0,0,0,0,0,0,0,0,0,0,0,0,0,0,0,0,0,0,0,0,0,0,0,0,0,0,0,0,0,0,0,0,0,0,0,0
0,0,0,0,0,0,0,0,0,0,0,0,0,0,0,0,0,0,0,0,0,0,0,0,0,0,0,0,0,0,0,0,0,0,0,0,0,0,0,0,0,0,0,0,0,0,0,0
0,0,0,0,0,0,0,0,0,0,0,0,0,3,14,3,14,3,14,3,0,0,0,0,0,0,0,0,0,0,0,0,0,0,0,0,0,0,0,0,0,0,0,0,0,0,0,0
