# Ancient Warfare Structure Template File
# Auto-generated structure template file. created on: 1/9/2024 at: 0:19:46
# Lines beginning with # denote comments

header:
version=2.11
name=SB_DarokCol_Chapel_1
mods=
size=17,14,21
offset=8,0,20
:endheader

#### VALIDATION ####
validation:
type=ground
structureAuthor=TheOddlySeagull
survival=true
worldGenEnabled=false
unique=false
preserveBlocks=false
preventNaturalHostileSpawns=true
selectionWeight=1
clusterValue=1
minDuplicateDistance=1
dimensionWhiteList=true
dimensionList=
biomeGroupList=
biomeWhiteList=true
biomeList=
leveling=10
fill=10
border=5
blockSwap=false
territoryName=
biomeReplacement=minecraft:
minGenerationHeight=0
maxGenerationHeight=255
:endvalidation

#### LAYERS ####
layer: 0
0,0,0,0,0,0,0,0,0,0,0,0,0,0,0,0,0
0,0,0,0,0,0,0,0,0,0,0,0,0,0,0,0,0
0,0,0,0,0,0,1,7,7,7,1,0,0,0,0,0,0
0,0,0,0,0,1,4,3,4,3,4,1,0,0,0,0,0
0,0,0,0,1,3,4,3,4,3,4,3,1,0,0,0,0
0,0,0,1,4,3,4,3,4,3,4,3,4,1,0,0,0
0,0,1,3,4,3,4,3,4,3,4,3,4,3,1,0,0
0,0,2,3,4,3,4,3,4,3,4,3,4,3,2,0,0
0,0,2,3,4,3,4,3,4,3,4,3,4,3,2,0,0
0,0,2,3,4,3,4,3,4,3,4,3,4,3,2,0,0
0,0,1,3,4,3,4,3,4,3,4,3,4,3,1,0,0
0,0,0,1,4,3,4,3,4,3,4,3,4,1,0,0,0
0,0,0,0,1,3,4,3,4,3,4,3,1,0,0,0,0
0,0,0,0,0,1,4,3,4,3,4,1,0,0,0,0,0
0,0,0,0,0,0,1,7,7,7,1,0,0,0,0,0,0
0,0,0,0,0,0,2,4,4,4,2,0,0,0,0,0,0
0,0,0,0,0,0,2,4,4,4,2,0,0,0,0,0,0
0,0,0,0,0,0,2,4,4,4,2,0,0,0,0,0,0
0,0,0,0,0,0,1,7,7,7,1,0,0,0,0,0,0
0,0,0,0,0,0,5,6,6,6,8,0,0,0,0,0,0
0,0,0,0,0,0,0,0,0,0,0,0,0,0,0,0,0
:endlayer
layer: 1
0,0,0,0,0,0,0,0,0,0,0,0,0,0,0,0,0
0,0,0,0,0,0,0,0,0,0,0,0,0,0,0,0,0
0,0,0,0,0,0,1,9,9,9,1,0,0,0,0,0,0
0,0,0,0,0,9,10,0,0,0,10,9,0,0,0,0,0
0,0,0,0,9,0,0,14,14,14,0,0,9,0,0,0,0
0,0,0,9,0,0,13,14,14,14,13,0,0,9,0,0,0
0,0,1,10,0,0,10,13,13,13,10,0,0,10,1,0,0
0,0,9,0,0,0,0,0,14,0,0,0,0,0,9,0,0
0,0,9,0,11,11,11,11,14,11,11,11,11,0,9,0,0
0,0,9,0,0,0,0,0,14,0,0,0,0,0,9,0,0
0,0,1,10,11,11,11,11,14,11,11,11,11,10,1,0,0
0,0,0,9,0,0,0,0,14,0,0,0,0,9,0,0,0
0,0,0,0,9,0,0,0,14,0,0,0,9,0,0,0,0
0,0,0,0,0,9,10,0,14,0,10,9,0,0,0,0,0
0,0,0,0,0,0,1,9,15,9,1,0,0,0,0,0,0
0,0,0,0,0,0,12,0,0,0,12,0,0,0,0,0,0
0,0,0,0,0,0,12,0,0,0,12,0,0,0,0,0,0
0,0,0,0,0,0,12,0,0,0,12,0,0,0,0,0,0
0,0,0,0,0,0,1,0,0,0,1,0,0,0,0,0,0
0,0,0,0,0,0,0,0,0,0,0,0,0,0,0,0,0
0,0,0,0,0,0,0,0,0,0,0,0,0,0,0,0,0
:endlayer
layer: 2
0,0,0,0,0,0,0,0,0,0,0,0,0,0,0,0,0
0,0,0,0,0,0,0,0,0,0,0,0,0,0,0,0,0
0,0,0,0,0,0,1,9,12,9,1,0,0,0,0,0,0
0,0,0,0,12,9,16,0,0,0,16,9,12,0,0,0,0
0,0,0,12,12,0,0,0,0,0,0,0,12,12,0,0,0
0,0,0,9,0,0,0,0,0,0,0,0,0,9,0,0,0
0,0,1,16,0,0,16,0,0,0,16,0,0,16,1,0,0
0,0,9,0,0,0,0,0,0,0,0,0,0,0,9,0,0
0,0,12,0,0,0,0,0,0,0,0,0,0,0,12,0,0
0,0,9,0,0,0,0,0,0,0,0,0,0,0,9,0,0
0,0,1,16,0,0,0,0,0,0,0,0,0,16,1,0,0
0,0,0,9,0,0,0,0,0,0,0,0,0,9,0,0,0
0,0,0,12,12,0,0,0,0,0,0,0,12,12,0,0,0
0,0,0,0,12,9,16,0,0,0,16,9,12,0,0,0,0
0,0,0,0,0,0,1,9,17,9,1,0,0,0,0,0,0
0,0,0,0,0,0,0,0,0,0,0,0,0,0,0,0,0
0,0,0,0,0,0,0,0,0,0,0,0,0,0,0,0,0
0,0,0,0,0,0,0,0,0,0,0,0,0,0,0,0,0
0,0,0,0,0,0,1,0,0,0,1,0,0,0,0,0,0
0,0,0,0,0,0,0,0,0,0,0,0,0,0,0,0,0
0,0,0,0,0,0,0,0,0,0,0,0,0,0,0,0,0
:endlayer
layer: 3
0,0,0,0,0,0,0,0,0,0,0,0,0,0,0,0,0
0,0,0,0,0,0,0,0,0,0,0,0,0,0,0,0,0
0,0,0,0,0,0,1,9,12,9,1,0,0,0,0,0,0
0,0,0,0,12,9,0,0,0,0,0,9,12,0,0,0,0
0,0,0,12,12,0,0,0,0,0,0,0,12,12,0,0,0
0,0,0,9,0,0,0,0,0,0,0,0,0,9,0,0,0
0,0,1,0,0,0,0,0,0,0,0,0,0,0,1,0,0
0,0,9,0,0,0,0,0,0,0,0,0,0,0,9,0,0
0,0,12,0,0,0,0,0,0,0,0,0,0,0,12,0,0
0,0,9,0,0,0,0,0,0,0,0,0,0,0,9,0,0
0,0,1,0,0,0,0,0,0,0,0,0,0,0,1,0,0
0,0,0,9,0,0,0,0,0,0,0,0,0,9,0,0,0
0,0,0,12,12,0,0,0,0,0,0,0,12,12,0,0,0
0,0,0,0,12,9,0,0,0,0,0,9,12,0,0,0,0
0,0,0,0,0,0,1,9,9,9,1,0,0,0,0,0,0
0,0,0,0,0,0,19,0,0,0,19,0,0,0,0,0,0
0,0,0,0,0,0,0,0,0,0,0,0,0,0,0,0,0
0,0,0,0,0,0,18,0,0,0,18,0,0,0,0,0,0
0,0,0,0,0,0,1,20,0,21,1,0,0,0,0,0,0
0,0,0,0,0,0,0,0,0,0,0,0,0,0,0,0,0
0,0,0,0,0,0,0,0,0,0,0,0,0,0,0,0,0
:endlayer
layer: 4
0,0,0,0,0,0,0,0,0,0,0,0,0,0,0,0,0
0,0,0,0,0,0,0,0,0,0,0,0,0,0,0,0,0
0,0,0,0,0,0,1,9,12,9,1,0,0,0,0,0,0
0,0,0,0,12,9,0,0,0,0,0,9,12,0,0,0,0
0,0,0,12,12,0,0,0,0,0,0,0,12,12,0,0,0
0,0,0,9,0,0,0,0,0,0,0,0,0,9,0,0,0
0,0,1,0,0,0,0,0,0,0,0,0,0,0,1,0,0
0,0,9,0,0,0,0,0,0,0,0,0,0,0,9,0,0
0,0,12,0,0,0,0,0,10,0,0,0,0,0,12,0,0
0,0,9,0,0,0,0,0,0,0,0,0,0,0,9,0,0
0,0,1,0,0,0,0,0,0,0,0,0,0,0,1,0,0
0,0,0,9,0,0,0,0,0,0,0,0,0,9,0,0,0
0,0,0,12,12,0,0,0,0,0,0,0,12,12,0,0,0
0,0,0,0,12,9,0,0,0,0,0,9,12,0,0,0,0
0,0,0,0,0,22,1,7,7,7,1,25,0,0,0,0,0
0,0,0,0,0,22,2,0,0,0,2,25,0,0,0,0,0
0,0,0,0,0,22,2,0,0,0,2,25,0,0,0,0,0
0,0,0,0,0,22,2,0,0,0,2,25,0,0,0,0,0
0,0,0,0,0,22,1,7,7,7,1,25,0,0,0,0,0
0,0,0,0,0,22,23,0,0,0,24,25,0,0,0,0,0
0,0,0,0,0,0,0,0,0,0,0,0,0,0,0,0,0
:endlayer
layer: 5
0,0,0,0,0,0,0,0,0,0,0,0,0,0,0,0,0
0,0,0,0,0,22,11,11,11,11,11,25,0,0,0,0,0
0,0,0,0,22,11,1,7,7,7,1,11,25,0,0,0,0
0,0,0,22,11,1,3,0,0,0,3,1,11,25,0,0,0
0,0,22,11,1,3,0,0,0,0,0,3,1,11,25,0,0
0,11,11,1,3,0,0,0,0,0,0,0,3,1,11,25,0
0,22,1,3,0,0,0,0,0,0,0,0,0,3,1,25,0
0,22,2,0,0,0,0,0,10,0,0,0,0,0,2,25,0
0,22,2,0,0,0,0,10,10,10,0,0,0,0,2,25,0
0,22,2,0,0,0,0,0,10,0,0,0,0,0,2,25,0
0,22,1,3,0,0,0,0,0,0,0,0,0,3,1,25,0
0,26,22,1,3,0,0,0,0,0,0,0,3,1,25,26,0
0,0,26,22,1,3,0,0,0,0,0,3,1,25,26,0,0
0,0,0,26,22,1,3,0,0,0,3,1,25,26,0,0,0
0,0,0,0,26,22,1,1,9,1,1,25,26,0,0,0,0
0,0,0,0,0,26,22,2,0,2,25,26,0,0,0,0,0
0,0,0,0,0,0,22,2,0,2,25,0,0,0,0,0,0
0,0,0,0,0,0,22,2,0,2,25,0,0,0,0,0,0
0,0,0,0,0,0,22,1,9,1,25,0,0,0,0,0,0
0,0,0,0,0,0,22,23,0,24,25,0,0,0,0,0,0
0,0,0,0,0,0,0,0,0,0,0,0,0,0,0,0,0
:endlayer
layer: 6
0,0,0,0,0,0,0,0,0,0,0,0,0,0,0,0,0
0,0,0,0,0,0,0,0,0,0,0,0,0,0,0,0,0
0,0,0,0,0,0,22,11,11,11,11,0,0,0,0,0,0
0,0,0,0,0,22,11,1,7,1,25,11,0,0,0,0,0
0,0,0,0,22,11,1,3,0,3,1,25,11,0,0,0,0
0,0,0,22,11,1,3,0,0,0,3,1,25,11,0,0,0
0,0,22,11,1,3,0,0,0,0,0,3,1,25,11,0,0
0,0,22,1,3,0,0,0,16,0,0,0,3,1,25,0,0
0,0,22,2,0,0,0,16,10,16,0,0,0,2,25,0,0
0,0,22,1,3,0,0,0,16,0,0,0,3,1,25,0,0
0,0,26,22,1,3,0,0,0,0,0,3,1,26,25,0,0
0,0,0,26,22,1,3,0,0,0,3,1,26,25,0,0,0
0,0,0,0,26,22,1,3,0,3,1,26,25,0,0,0,0
0,0,0,0,0,26,22,1,1,1,26,25,0,0,0,0,0
0,0,0,0,0,0,26,22,2,26,25,0,0,0,0,0,0
0,0,0,0,0,0,0,22,2,25,0,0,0,0,0,0,0
0,0,0,0,0,0,0,22,2,25,0,0,0,0,0,0,0
0,0,0,0,0,0,0,22,2,25,0,0,0,0,0,0,0
0,0,0,0,0,0,0,22,1,25,0,0,0,0,0,0,0
0,0,0,0,0,0,0,22,27,25,0,0,0,0,0,0,0
0,0,0,0,0,0,0,0,0,0,0,0,0,0,0,0,0
:endlayer
layer: 7
0,0,0,0,0,0,0,0,0,0,0,0,0,0,0,0,0
0,0,0,0,0,0,0,0,0,0,0,0,0,0,0,0,0
0,0,0,0,0,0,0,0,0,0,0,0,0,0,0,0,0
0,0,0,0,0,0,0,11,11,11,0,0,0,0,0,0,0
0,0,0,0,0,0,11,22,1,25,11,0,0,0,0,0,0
0,0,0,0,0,11,22,1,3,1,25,11,0,0,0,0,0
0,0,0,0,11,22,1,3,0,3,1,25,11,0,0,0,0
0,0,0,11,22,1,3,0,0,0,3,1,25,11,0,0,0
0,0,0,22,1,3,0,0,10,0,0,3,1,25,0,0,0
0,0,0,22,26,1,3,0,0,0,3,1,26,25,0,0,0
0,0,0,0,22,26,1,3,0,3,1,26,25,0,0,0,0
0,0,0,0,0,22,26,1,3,1,26,25,0,0,0,0,0
0,0,0,0,0,0,22,26,1,26,25,0,0,0,0,0,0
0,0,0,0,0,0,0,22,26,25,0,0,0,0,0,0,0
0,0,0,0,0,0,0,0,28,0,0,0,0,0,0,0,0
0,0,0,0,0,0,0,0,28,0,0,0,0,0,0,0,0
0,0,0,0,0,0,0,0,28,0,0,0,0,0,0,0,0
0,0,0,0,0,0,0,0,28,0,0,0,0,0,0,0,0
0,0,0,0,0,0,0,0,28,0,0,0,0,0,0,0,0
0,0,0,0,0,0,0,0,26,0,0,0,0,0,0,0,0
0,0,0,0,0,0,0,0,0,0,0,0,0,0,0,0,0
:endlayer
layer: 8
0,0,0,0,0,0,0,0,0,0,0,0,0,0,0,0,0
0,0,0,0,0,0,0,0,0,0,0,0,0,0,0,0,0
0,0,0,0,0,0,0,0,0,0,0,0,0,0,0,0,0
0,0,0,0,0,0,0,0,0,0,0,0,0,0,0,0,0
0,0,0,0,0,0,0,0,28,0,0,0,0,0,0,0,0
0,0,0,0,0,0,0,11,11,11,0,0,0,0,0,0,0
0,0,0,0,0,0,11,22,1,25,11,0,0,0,0,0,0
0,0,0,0,0,11,22,1,3,1,25,11,0,0,0,0,0
0,0,0,0,28,22,1,3,10,3,1,25,28,0,0,0,0
0,0,0,0,0,26,22,1,3,1,25,26,0,0,0,0,0
0,0,0,0,0,0,26,22,1,25,26,0,0,0,0,0,0
0,0,0,0,0,0,0,22,26,26,0,0,0,0,0,0,0
0,0,0,0,0,0,0,0,28,0,0,0,0,0,0,0,0
0,0,0,0,0,0,0,0,0,0,0,0,0,0,0,0,0
0,0,0,0,0,0,0,0,0,0,0,0,0,0,0,0,0
0,0,0,0,0,0,0,0,0,0,0,0,0,0,0,0,0
0,0,0,0,0,0,0,0,0,0,0,0,0,0,0,0,0
0,0,0,0,0,0,0,0,0,0,0,0,0,0,0,0,0
0,0,0,0,0,0,0,0,0,0,0,0,0,0,0,0,0
0,0,0,0,0,0,0,0,10,0,0,0,0,0,0,0,0
0,0,0,0,0,0,0,0,0,0,0,0,0,0,0,0,0
:endlayer
layer: 9
0,0,0,0,0,0,0,0,0,0,0,0,0,0,0,0,0
0,0,0,0,0,0,0,0,0,0,0,0,0,0,0,0,0
0,0,0,0,0,0,0,0,0,0,0,0,0,0,0,0,0
0,0,0,0,0,0,0,0,0,0,0,0,0,0,0,0,0
0,0,0,0,0,0,0,0,0,0,0,0,0,0,0,0,0
0,0,0,0,0,0,0,0,0,0,0,0,0,0,0,0,0
0,0,0,0,0,0,0,0,28,0,0,0,0,0,0,0,0
0,0,0,0,0,0,0,22,11,11,0,0,0,0,0,0,0
0,0,0,0,0,0,28,22,1,25,28,0,0,0,0,0,0
0,0,0,0,0,0,0,26,26,25,0,0,0,0,0,0,0
0,0,0,0,0,0,0,0,28,0,0,0,0,0,0,0,0
0,0,0,0,0,0,0,0,0,0,0,0,0,0,0,0,0
0,0,0,0,0,0,0,0,0,0,0,0,0,0,0,0,0
0,0,0,0,0,0,0,0,0,0,0,0,0,0,0,0,0
0,0,0,0,0,0,0,0,0,0,0,0,0,0,0,0,0
0,0,0,0,0,0,0,0,0,0,0,0,0,0,0,0,0
0,0,0,0,0,0,0,0,0,0,0,0,0,0,0,0,0
0,0,0,0,0,0,0,0,0,0,0,0,0,0,0,0,0
0,0,0,0,0,0,0,0,0,0,0,0,0,0,0,0,0
0,0,0,0,0,0,0,0,16,0,0,0,0,0,0,0,0
0,0,0,0,0,0,0,0,0,0,0,0,0,0,0,0,0
:endlayer
layer: 10
0,0,0,0,0,0,0,0,0,0,0,0,0,0,0,0,0
0,0,0,0,0,0,0,0,0,0,0,0,0,0,0,0,0
0,0,0,0,0,0,0,0,0,0,0,0,0,0,0,0,0
0,0,0,0,0,0,0,0,0,0,0,0,0,0,0,0,0
0,0,0,0,0,0,0,0,0,0,0,0,0,0,0,0,0
0,0,0,0,0,0,0,0,0,0,0,0,0,0,0,0,0
0,0,0,0,0,0,0,0,0,0,0,0,0,0,0,0,0
0,0,0,0,0,0,0,0,0,0,0,0,0,0,0,0,0
0,0,0,0,0,0,0,0,1,0,0,0,0,0,0,0,0
0,0,0,0,0,0,0,0,0,0,0,0,0,0,0,0,0
0,0,0,0,0,0,0,0,0,0,0,0,0,0,0,0,0
0,0,0,0,0,0,0,0,0,0,0,0,0,0,0,0,0
0,0,0,0,0,0,0,0,0,0,0,0,0,0,0,0,0
0,0,0,0,0,0,0,0,0,0,0,0,0,0,0,0,0
0,0,0,0,0,0,0,0,0,0,0,0,0,0,0,0,0
0,0,0,0,0,0,0,0,0,0,0,0,0,0,0,0,0
0,0,0,0,0,0,0,0,0,0,0,0,0,0,0,0,0
0,0,0,0,0,0,0,0,0,0,0,0,0,0,0,0,0
0,0,0,0,0,0,0,0,0,0,0,0,0,0,0,0,0
0,0,0,0,0,0,0,0,0,0,0,0,0,0,0,0,0
0,0,0,0,0,0,0,0,0,0,0,0,0,0,0,0,0
:endlayer
layer: 11
0,0,0,0,0,0,0,0,0,0,0,0,0,0,0,0,0
0,0,0,0,0,0,0,0,0,0,0,0,0,0,0,0,0
0,0,0,0,0,0,0,0,0,0,0,0,0,0,0,0,0
0,0,0,0,0,0,0,0,0,0,0,0,0,0,0,0,0
0,0,0,0,0,0,0,0,0,0,0,0,0,0,0,0,0
0,0,0,0,0,0,0,0,0,0,0,0,0,0,0,0,0
0,0,0,0,0,0,0,0,0,0,0,0,0,0,0,0,0
0,0,0,0,0,0,0,0,0,0,0,0,0,0,0,0,0
0,0,0,0,0,0,0,0,12,0,0,0,0,0,0,0,0
0,0,0,0,0,0,0,0,0,0,0,0,0,0,0,0,0
0,0,0,0,0,0,0,0,0,0,0,0,0,0,0,0,0
0,0,0,0,0,0,0,0,0,0,0,0,0,0,0,0,0
0,0,0,0,0,0,0,0,0,0,0,0,0,0,0,0,0
0,0,0,0,0,0,0,0,0,0,0,0,0,0,0,0,0
0,0,0,0,0,0,0,0,0,0,0,0,0,0,0,0,0
0,0,0,0,0,0,0,0,0,0,0,0,0,0,0,0,0
0,0,0,0,0,0,0,0,0,0,0,0,0,0,0,0,0
0,0,0,0,0,0,0,0,0,0,0,0,0,0,0,0,0
0,0,0,0,0,0,0,0,0,0,0,0,0,0,0,0,0
0,0,0,0,0,0,0,0,0,0,0,0,0,0,0,0,0
0,0,0,0,0,0,0,0,0,0,0,0,0,0,0,0,0
:endlayer
layer: 12
0,0,0,0,0,0,0,0,0,0,0,0,0,0,0,0,0
0,0,0,0,0,0,0,0,0,0,0,0,0,0,0,0,0
0,0,0,0,0,0,0,0,0,0,0,0,0,0,0,0,0
0,0,0,0,0,0,0,0,0,0,0,0,0,0,0,0,0
0,0,0,0,0,0,0,0,0,0,0,0,0,0,0,0,0
0,0,0,0,0,0,0,0,0,0,0,0,0,0,0,0,0
0,0,0,0,0,0,0,0,0,0,0,0,0,0,0,0,0
0,0,0,0,0,0,0,0,0,0,0,0,0,0,0,0,0
0,0,0,0,0,0,0,0,12,0,0,0,0,0,0,0,0
0,0,0,0,0,0,0,0,0,0,0,0,0,0,0,0,0
0,0,0,0,0,0,0,0,0,0,0,0,0,0,0,0,0
0,0,0,0,0,0,0,0,0,0,0,0,0,0,0,0,0
0,0,0,0,0,0,0,0,0,0,0,0,0,0,0,0,0
0,0,0,0,0,0,0,0,0,0,0,0,0,0,0,0,0
0,0,0,0,0,0,0,0,0,0,0,0,0,0,0,0,0
0,0,0,0,0,0,0,0,0,0,0,0,0,0,0,0,0
0,0,0,0,0,0,0,0,0,0,0,0,0,0,0,0,0
0,0,0,0,0,0,0,0,0,0,0,0,0,0,0,0,0
0,0,0,0,0,0,0,0,0,0,0,0,0,0,0,0,0
0,0,0,0,0,0,0,0,0,0,0,0,0,0,0,0,0
0,0,0,0,0,0,0,0,0,0,0,0,0,0,0,0,0
:endlayer
layer: 13
0,0,0,0,0,0,0,0,0,0,0,0,0,0,0,0,0
0,0,0,0,0,0,0,0,0,0,0,0,0,0,0,0,0
0,0,0,0,0,0,0,0,0,0,0,0,0,0,0,0,0
0,0,0,0,0,0,0,0,0,0,0,0,0,0,0,0,0
0,0,0,0,0,0,0,0,0,0,0,0,0,0,0,0,0
0,0,0,0,0,0,0,0,0,0,0,0,0,0,0,0,0
0,0,0,0,0,0,0,0,0,0,0,0,0,0,0,0,0
0,0,0,0,0,0,0,0,0,0,0,0,0,0,0,0,0
0,0,0,0,0,0,0,0,16,0,0,0,0,0,0,0,0
0,0,0,0,0,0,0,0,0,0,0,0,0,0,0,0,0
0,0,0,0,0,0,0,0,0,0,0,0,0,0,0,0,0
0,0,0,0,0,0,0,0,0,0,0,0,0,0,0,0,0
0,0,0,0,0,0,0,0,0,0,0,0,0,0,0,0,0
0,0,0,0,0,0,0,0,0,0,0,0,0,0,0,0,0
0,0,0,0,0,0,0,0,0,0,0,0,0,0,0,0,0
0,0,0,0,0,0,0,0,0,0,0,0,0,0,0,0,0
0,0,0,0,0,0,0,0,0,0,0,0,0,0,0,0,0
0,0,0,0,0,0,0,0,0,0,0,0,0,0,0,0,0
0,0,0,0,0,0,0,0,0,0,0,0,0,0,0,0,0
0,0,0,0,0,0,0,0,0,0,0,0,0,0,0,0,0
0,0,0,0,0,0,0,0,0,0,0,0,0,0,0,0,0
:endlayer

#### RULES ####
rule:
plugin=vanillaBlocks
number=1
data:
JSON:{blockState:{blockName:"minecraft:log",properties:{variant:"spruce",axis:"y"}}}
:enddata
:endrule

rule:
plugin=vanillaBlocks
number=2
data:
JSON:{blockState:{blockName:"minecraft:log",properties:{variant:"spruce",axis:"z"}}}
:enddata
:endrule

rule:
plugin=vanillaBlocks
number=3
data:
JSON:{blockState:{blockName:"minecraft:wooden_slab",properties:{half:"top",variant:"dark_oak"}}}
:enddata
:endrule

rule:
plugin=vanillaBlocks
number=4
data:
JSON:{blockState:{blockName:"minecraft:planks",properties:{variant:"dark_oak"}}}
:enddata
:endrule

rule:
plugin=vanillaBlocks
number=5
data:
JSON:{blockState:{blockName:"minecraft:oak_stairs",properties:{half:"bottom",shape:"straight",facing:"east"}}}
:enddata
:endrule

rule:
plugin=vanillaBlocks
number=6
data:
JSON:{blockState:{blockName:"minecraft:oak_stairs",properties:{half:"bottom",shape:"straight",facing:"north"}}}
:enddata
:endrule

rule:
plugin=vanillaBlocks
number=7
data:
JSON:{blockState:{blockName:"minecraft:log",properties:{variant:"spruce",axis:"x"}}}
:enddata
:endrule

rule:
plugin=vanillaBlocks
number=8
data:
JSON:{blockState:{blockName:"minecraft:oak_stairs",properties:{half:"bottom",shape:"straight",facing:"west"}}}
:enddata
:endrule

rule:
plugin=vanillaBlocks
number=9
data:
JSON:{blockState:{blockName:"minecraft:planks",properties:{variant:"oak"}}}
:enddata
:endrule

rule:
plugin=vanillaBlocks
number=10
data:
JSON:{blockState:{blockName:"minecraft:spruce_fence",properties:{east:"false",south:"false",north:"false",west:"false"}}}
:enddata
:endrule

rule:
plugin=vanillaBlocks
number=11
data:
JSON:{blockState:{blockName:"minecraft:spruce_stairs",properties:{half:"bottom",shape:"straight",facing:"south"}}}
:enddata
:endrule

rule:
plugin=vanillaBlocks
number=12
data:
JSON:{blockState:{blockName:"minecraft:acacia_fence",properties:{east:"false",south:"false",north:"false",west:"false"}}}
:enddata
:endrule

rule:
plugin=vanillaBlocks
number=13
data:
JSON:{blockState:{blockName:"minecraft:planks",properties:{variant:"spruce"}}}
:enddata
:endrule

rule:
plugin=vanillaBlocks
number=14
data:
JSON:{blockState:{blockName:"minecraft:carpet",properties:{color:"red"}}}
:enddata
:endrule

rule:
plugin=doors
number=15
data:
JSON:{blockState:{blockName:"minecraft:spruce_door",properties:{hinge:"left",half:"lower",powered:"false",facing:"north",open:"false"}}}
:enddata
:endrule

rule:
plugin=vanillaBlocks
number=16
data:
JSON:{blockState:{blockName:"minecraft:torch",properties:{facing:"up"}}}
:enddata
:endrule

rule:
plugin=doors
number=17
data:
JSON:{blockState:{blockName:"minecraft:spruce_door",properties:{hinge:"left",half:"upper",powered:"false",facing:"west",open:"false"}}}
:enddata
:endrule

rule:
plugin=vanillaBlocks
number=18
data:
JSON:{blockState:{blockName:"minecraft:torch",properties:{facing:"north"}}}
:enddata
:endrule

rule:
plugin=vanillaBlocks
number=19
data:
JSON:{blockState:{blockName:"minecraft:torch",properties:{facing:"south"}}}
:enddata
:endrule

rule:
plugin=vanillaBlocks
number=20
data:
JSON:{blockState:{blockName:"minecraft:oak_stairs",properties:{half:"top",shape:"straight",facing:"west"}}}
:enddata
:endrule

rule:
plugin=vanillaBlocks
number=21
data:
JSON:{blockState:{blockName:"minecraft:oak_stairs",properties:{half:"top",shape:"straight",facing:"east"}}}
:enddata
:endrule

rule:
plugin=vanillaBlocks
number=22
data:
JSON:{blockState:{blockName:"minecraft:spruce_stairs",properties:{half:"bottom",shape:"straight",facing:"east"}}}
:enddata
:endrule

rule:
plugin=vanillaBlocks
number=23
data:
JSON:{blockState:{blockName:"minecraft:spruce_stairs",properties:{half:"top",shape:"straight",facing:"west"}}}
:enddata
:endrule

rule:
plugin=vanillaBlocks
number=24
data:
JSON:{blockState:{blockName:"minecraft:spruce_stairs",properties:{half:"top",shape:"straight",facing:"east"}}}
:enddata
:endrule

rule:
plugin=vanillaBlocks
number=25
data:
JSON:{blockState:{blockName:"minecraft:spruce_stairs",properties:{half:"bottom",shape:"straight",facing:"west"}}}
:enddata
:endrule

rule:
plugin=vanillaBlocks
number=26
data:
JSON:{blockState:{blockName:"minecraft:spruce_stairs",properties:{half:"bottom",shape:"straight",facing:"north"}}}
:enddata
:endrule

rule:
plugin=vanillaBlocks
number=27
data:
JSON:{blockState:{blockName:"minecraft:spruce_stairs",properties:{half:"top",shape:"straight",facing:"north"}}}
:enddata
:endrule

rule:
plugin=vanillaBlocks
number=28
data:
JSON:{blockState:{blockName:"minecraft:wooden_slab",properties:{half:"bottom",variant:"spruce"}}}
:enddata
:endrule

#### ENTITIES ####
