# Ancient Warfare Structure Template File
# Auto-generated structure template file. created on: 9/23/2023 at: 0:43:35
# Lines beginning with # denote comments

header:
version=2.11
name=SB_KieavarusCol_House_1H3R_2_willow
mods=biomesoplenty
size=17,13,13
offset=8,1,12
:endheader

#### VALIDATION ####
validation:
type=ground
structureAuthor=TheOddlySeagull
survival=true
worldGenEnabled=false
unique=false
preserveBlocks=false
preventNaturalHostileSpawns=false
selectionWeight=1
clusterValue=1
minDuplicateDistance=1
dimensionWhiteList=true
dimensionList=
biomeGroupList=
biomeWhiteList=true
biomeList=
leveling=0
fill=0
border=0
blockSwap=false
territoryName=
biomeReplacement=minecraft:
minGenerationHeight=0
maxGenerationHeight=255
:endvalidation

#### LAYERS ####
layer: 0
1,2,1,1,1,1,2,1,1,1,2,1,1,1,1,2,1
2,2,2,2,2,2,2,2,2,2,2,2,2,2,2,2,2
1,2,3,3,3,3,2,3,3,3,3,3,3,3,3,2,1
1,2,3,3,3,3,2,3,3,3,3,3,3,3,3,2,1
1,2,3,3,3,3,2,3,3,3,3,3,3,3,3,2,1
1,2,3,3,3,3,2,3,3,3,3,3,3,3,3,2,1
2,2,2,2,2,2,2,3,3,3,3,3,3,3,3,2,2
1,2,3,3,3,3,2,3,3,3,3,3,3,3,3,2,1
1,2,3,3,3,3,2,3,3,3,3,3,3,3,3,2,1
1,2,3,3,3,3,2,3,3,3,3,3,3,3,3,2,1
1,2,3,3,3,3,2,3,3,3,3,3,3,3,3,2,1
2,2,2,2,2,2,2,2,2,2,2,2,2,2,2,2,2
1,2,1,1,1,1,2,2,2,2,2,1,1,1,1,2,1
:endlayer
layer: 1
0,4,0,0,0,0,4,0,0,0,4,0,0,0,0,4,0
4,4,3,3,3,3,4,3,3,3,4,3,3,3,3,4,4
0,3,0,0,0,0,3,0,0,0,0,0,0,0,0,3,0
0,3,0,0,0,0,0,0,0,0,0,0,0,0,0,3,0
0,3,0,0,0,0,0,0,0,0,0,0,0,0,0,3,0
0,3,0,0,0,0,3,0,0,0,0,0,0,0,0,3,0
4,4,3,3,3,3,4,0,0,0,0,0,0,0,0,4,4
0,3,0,0,0,0,3,0,0,0,0,0,0,0,0,3,0
0,3,0,0,0,0,0,0,0,0,0,0,0,0,0,3,0
0,3,0,0,0,0,0,0,0,0,0,5,6,0,0,3,0
0,3,0,0,0,0,3,0,0,0,7,5,6,0,0,3,0
4,4,3,3,3,3,4,3,0,3,4,3,3,3,3,4,4
0,4,0,0,0,0,4,0,0,0,4,0,0,0,0,4,0
:endlayer
layer: 2
0,4,0,0,0,0,4,0,0,0,4,0,0,0,0,4,0
4,4,3,8,8,3,4,3,8,3,4,3,8,8,3,4,4
9,3,0,0,0,0,3,0,0,0,0,0,0,0,0,3,9
0,3,0,0,0,0,0,0,0,0,0,0,0,0,0,3,0
0,3,0,0,0,0,0,0,0,0,0,0,0,0,0,3,0
7,3,0,0,0,0,3,0,0,0,0,0,0,0,0,3,7
4,4,3,3,3,3,4,0,0,0,0,0,0,0,0,4,4
9,3,0,0,0,0,3,0,0,0,0,0,0,0,0,3,9
0,3,0,0,0,0,0,0,0,0,0,0,0,0,0,3,0
0,3,0,0,0,0,0,0,0,0,5,6,0,0,0,3,0
7,3,0,0,0,0,3,0,0,0,5,6,0,0,0,3,7
4,4,3,8,8,3,4,3,0,3,4,3,8,8,3,4,4
0,4,0,0,0,0,4,0,0,0,4,0,0,0,0,4,0
:endlayer
layer: 3
10,4,11,0,0,12,4,11,0,12,4,11,0,0,12,4,10
10,13,3,3,3,3,4,3,3,3,4,3,3,3,3,13,10
10,13,0,0,0,0,3,0,0,0,9,0,0,0,0,13,10
10,13,0,0,0,0,3,0,0,0,0,0,0,0,0,13,10
10,13,11,0,0,0,3,0,0,0,0,0,0,0,0,13,10
10,13,0,0,0,0,3,0,0,0,0,0,0,0,0,13,10
10,13,3,3,3,3,4,11,0,0,0,0,0,0,12,13,10
10,13,0,0,0,0,3,0,0,0,0,0,0,0,0,13,10
10,13,11,0,0,0,3,0,0,0,0,0,0,0,0,13,10
10,13,0,0,0,0,3,0,0,5,6,0,0,0,0,13,10
10,13,0,0,0,0,3,0,0,5,6,0,0,0,0,13,10
10,13,3,3,3,3,4,3,3,3,4,3,3,3,3,13,10
10,4,11,0,0,12,4,11,0,12,4,11,0,0,12,4,10
:endlayer
layer: 4
0,10,0,0,0,0,4,0,0,0,4,0,0,0,0,10,0
0,10,14,14,14,14,14,14,14,14,14,14,14,14,14,10,0
0,10,15,16,16,16,13,3,3,3,3,3,3,3,3,10,0
0,10,3,3,3,3,13,16,16,16,16,16,16,16,5,10,0
0,10,15,16,16,16,13,3,3,3,3,3,3,3,3,10,0
0,10,3,3,3,3,13,16,16,16,16,16,16,16,5,10,0
0,10,14,14,14,14,13,14,14,14,14,14,14,14,14,10,0
0,10,3,3,3,3,13,16,16,16,16,16,16,16,5,10,0
0,10,15,16,16,16,13,3,3,3,3,3,3,3,3,10,0
0,10,3,3,3,3,13,16,5,6,0,0,0,0,5,10,0
0,10,15,16,16,16,13,3,3,6,0,0,0,0,5,10,0
0,10,14,14,14,14,14,14,14,14,14,14,14,14,14,10,0
0,10,0,0,0,0,4,0,0,0,4,0,0,0,0,10,0
:endlayer
layer: 5
0,0,10,0,0,0,4,0,0,0,4,0,0,0,10,0,0
0,0,10,3,3,3,4,3,3,3,4,3,3,3,10,0,0
0,0,10,0,0,0,0,0,0,0,0,0,0,0,10,0,0
0,0,10,0,0,0,0,0,0,0,0,0,0,0,10,0,0
0,0,10,0,0,0,0,0,0,0,0,0,0,0,10,0,0
0,0,10,0,0,0,0,0,0,0,0,0,0,0,10,0,0
0,0,10,3,3,3,4,0,0,0,4,3,3,3,10,0,0
0,0,10,0,0,0,0,0,0,0,0,0,0,0,10,0,0
0,0,10,0,0,0,0,0,0,0,8,8,8,8,10,0,0
0,0,10,0,0,0,0,0,0,0,0,0,0,0,10,0,0
0,0,10,0,0,0,0,0,0,0,0,0,0,0,10,0,0
0,0,10,3,3,3,4,3,3,3,4,3,3,3,10,0,0
0,0,10,0,0,0,4,0,0,0,4,0,0,0,10,0,0
:endlayer
layer: 6
0,0,0,10,0,0,4,0,0,0,4,0,0,10,0,0,0
0,0,0,10,3,3,4,3,8,3,4,3,3,10,0,0,0
0,0,17,10,0,0,0,0,0,0,0,0,0,10,17,0,0
0,0,0,10,0,0,0,0,0,0,0,0,0,10,0,0,0
0,0,0,10,0,0,0,0,0,0,0,0,0,10,0,0,0
0,0,0,10,0,0,0,0,0,0,0,0,0,10,0,0,0
0,0,0,10,3,3,4,0,0,0,4,3,3,10,0,0,0
0,0,0,10,0,0,0,0,0,0,0,0,0,10,0,0,0
0,0,0,10,0,0,0,0,0,0,0,0,0,10,0,0,0
0,0,0,10,0,0,0,0,0,0,0,0,0,10,0,0,0
0,0,17,10,0,0,0,0,0,0,0,0,0,10,17,0,0
0,0,0,10,3,3,4,3,8,3,4,3,3,10,0,0,0
0,0,0,10,0,0,4,0,0,0,4,0,0,10,0,0,0
:endlayer
layer: 7
0,0,0,0,10,0,4,0,0,0,4,0,10,0,0,0,0
0,0,0,0,10,3,4,3,3,3,4,3,10,0,0,0,0
0,0,0,0,10,0,9,0,0,0,9,0,10,0,0,0,0
0,0,0,0,10,0,0,0,0,0,0,0,10,0,0,0,0
0,0,0,0,10,0,0,0,0,0,0,0,10,0,0,0,0
0,0,0,0,10,0,7,0,0,0,7,0,10,0,0,0,0
0,0,0,0,10,3,4,0,0,0,4,3,10,0,0,0,0
0,0,0,0,10,0,9,0,0,0,9,0,10,0,0,0,0
0,0,0,0,10,0,0,0,0,0,0,0,10,0,0,0,0
0,0,0,0,10,0,0,0,0,0,0,0,10,0,0,0,0
0,0,0,0,10,0,7,0,0,0,7,0,10,0,0,0,0
0,0,0,0,10,3,4,3,3,3,4,3,10,0,0,0,0
0,0,0,0,10,0,4,0,0,0,4,0,10,0,0,0,0
:endlayer
layer: 8
0,0,0,0,0,10,4,0,0,0,4,10,0,0,0,0,0
0,0,0,0,0,10,4,14,14,14,4,10,0,0,0,0,0
0,0,0,0,0,10,0,0,0,0,0,10,0,0,0,0,0
0,0,0,0,0,10,0,0,0,0,0,10,0,0,0,0,0
0,0,0,0,0,10,0,0,0,0,0,10,0,0,0,0,0
0,0,0,0,0,10,0,0,0,0,0,10,0,0,0,0,0
0,0,0,0,0,10,4,15,0,5,4,10,0,0,0,0,0
0,0,0,0,0,10,0,0,0,0,0,10,0,0,0,0,0
0,0,0,0,0,10,0,0,0,0,0,10,0,0,0,0,0
0,0,0,0,0,10,0,0,0,0,0,10,0,0,0,0,0
0,0,0,0,0,10,0,0,0,0,0,10,0,0,0,0,0
0,0,0,0,0,10,4,14,14,14,4,10,0,0,0,0,0
0,0,0,0,0,10,4,0,0,0,4,10,0,0,0,0,0
:endlayer
layer: 9
0,0,0,0,0,0,10,15,0,5,10,0,0,0,0,0,0
0,0,0,0,0,0,10,3,3,3,10,0,0,0,0,0,0
0,0,0,0,0,17,10,0,0,0,10,17,0,0,0,0,0
0,0,0,0,0,0,10,0,0,0,10,0,0,0,0,0,0
0,0,0,0,0,0,10,0,0,0,10,0,0,0,0,0,0
0,0,0,0,0,0,10,0,0,0,10,0,0,0,0,0,0
0,0,0,0,0,0,10,14,14,14,10,0,0,0,0,0,0
0,0,0,0,0,0,10,0,0,0,10,0,0,0,0,0,0
0,0,0,0,0,0,10,0,0,0,10,0,0,0,0,0,0
0,0,0,0,0,0,10,0,0,0,10,0,0,0,0,0,0
0,0,0,0,0,17,10,0,0,0,10,17,0,0,0,0,0
0,0,0,0,0,0,10,3,3,3,10,0,0,0,0,0,0
0,0,0,0,0,0,10,15,0,5,10,0,0,0,0,0,0
:endlayer
layer: 10
0,0,0,0,0,0,0,10,18,10,0,0,0,0,0,0,0
0,0,0,0,0,0,0,10,3,10,0,0,0,0,0,0,0
0,0,0,0,0,0,0,10,0,10,0,0,0,0,0,0,0
0,0,0,0,0,0,0,10,0,10,0,0,0,0,0,0,0
0,0,0,0,0,0,0,10,0,10,0,0,0,0,0,0,0
0,0,0,0,0,0,0,10,0,10,0,0,0,0,0,0,0
0,0,0,0,0,0,0,10,3,10,0,0,0,0,0,0,0
0,0,0,0,0,0,0,10,0,10,0,0,0,0,0,0,0
0,0,0,0,0,0,0,10,0,10,0,0,0,0,0,0,0
0,0,0,0,0,0,0,10,0,10,0,0,0,0,0,0,0
0,0,0,0,0,0,0,10,0,10,0,0,0,0,0,0,0
0,0,0,0,0,0,0,10,3,10,0,0,0,0,0,0,0
0,0,0,0,0,0,0,10,19,10,0,0,0,0,0,0,0
:endlayer
layer: 11
0,0,0,0,0,0,0,0,10,0,0,0,0,0,0,0,0
0,0,0,0,0,0,0,0,10,0,0,0,0,0,0,0,0
0,0,0,0,0,0,0,0,10,0,0,0,0,0,0,0,0
0,0,0,0,0,0,0,0,10,0,0,0,0,0,0,0,0
0,0,0,0,0,0,0,0,10,0,0,0,0,0,0,0,0
0,0,0,0,0,0,0,0,10,0,0,0,0,0,0,0,0
0,0,0,0,0,0,0,0,10,0,0,0,0,0,0,0,0
0,0,0,0,0,0,0,0,10,0,0,0,0,0,0,0,0
0,0,0,0,0,0,0,0,10,0,0,0,0,0,0,0,0
0,0,0,0,0,0,0,0,10,0,0,0,0,0,0,0,0
0,0,0,0,0,0,0,0,10,0,0,0,0,0,0,0,0
0,0,0,0,0,0,0,0,10,0,0,0,0,0,0,0,0
0,0,0,0,0,0,0,0,10,0,0,0,0,0,0,0,0
:endlayer
layer: 12
0,0,0,0,0,0,0,0,0,0,0,0,0,0,0,0,0
0,0,0,0,0,0,0,0,0,0,0,0,0,0,0,0,0
0,0,0,0,0,0,0,0,17,0,0,0,0,0,0,0,0
0,0,0,0,0,0,0,0,0,0,0,0,0,0,0,0,0
0,0,0,0,0,0,0,0,0,0,0,0,0,0,0,0,0
0,0,0,0,0,0,0,0,0,0,0,0,0,0,0,0,0
0,0,0,0,0,0,0,0,0,0,0,0,0,0,0,0,0
0,0,0,0,0,0,0,0,0,0,0,0,0,0,0,0,0
0,0,0,0,0,0,0,0,0,0,0,0,0,0,0,0,0
0,0,0,0,0,0,0,0,0,0,0,0,0,0,0,0,0
0,0,0,0,0,0,0,0,17,0,0,0,0,0,0,0,0
0,0,0,0,0,0,0,0,0,0,0,0,0,0,0,0,0
0,0,0,0,0,0,0,0,0,0,0,0,0,0,0,0,0
:endlayer

#### RULES ####
rule:
plugin=vanillaBlocks
number=1
data:
JSON:{blockState:{blockName:"minecraft:grass",properties:{snowy:"false"}}}
:enddata
:endrule

rule:
plugin=vanillaBlocks
number=2
data:
JSON:{blockState:{blockName:"minecraft:cobblestone"}}
:enddata
:endrule

rule:
plugin=vanillaBlocks
number=3
data:
JSON:{blockState:{blockName:"biomesoplenty:planks_0",properties:{variant:"willow"}}}
:enddata
:endrule

rule:
plugin=vanillaBlocks
number=4
data:
JSON:{blockState:{blockName:"biomesoplenty:log_2",properties:{variant:"willow",axis:"y"}}}
:enddata
:endrule

rule:
plugin=vanillaBlocks
number=5
data:
JSON:{blockState:{blockName:"biomesoplenty:willow_stairs",properties:{half:"top",shape:"straight",facing:"east"}}}
:enddata
:endrule

rule:
plugin=vanillaBlocks
number=6
data:
JSON:{blockState:{blockName:"biomesoplenty:willow_stairs",properties:{half:"bottom",shape:"straight",facing:"west"}}}
:enddata
:endrule

rule:
plugin=vanillaBlocks
number=7
data:
JSON:{blockState:{blockName:"minecraft:torch",properties:{facing:"north"}}}
:enddata
:endrule

rule:
plugin=vanillaBlocks
number=8
data:
JSON:{blockState:{blockName:"biomesoplenty:willow_fence",properties:{east:"false",south:"false",north:"false",west:"false"}}}
:enddata
:endrule

rule:
plugin=vanillaBlocks
number=9
data:
JSON:{blockState:{blockName:"minecraft:torch",properties:{facing:"south"}}}
:enddata
:endrule

rule:
plugin=vanillaBlocks
number=10
data:
JSON:{blockState:{blockName:"minecraft:wool",properties:{color:"brown"}}}
:enddata
:endrule

rule:
plugin=vanillaBlocks
number=11
data:
JSON:{blockState:{blockName:"minecraft:torch",properties:{facing:"east"}}}
:enddata
:endrule

rule:
plugin=vanillaBlocks
number=12
data:
JSON:{blockState:{blockName:"minecraft:torch",properties:{facing:"west"}}}
:enddata
:endrule

rule:
plugin=vanillaBlocks
number=13
data:
JSON:{blockState:{blockName:"biomesoplenty:log_2",properties:{variant:"willow",axis:"z"}}}
:enddata
:endrule

rule:
plugin=vanillaBlocks
number=14
data:
JSON:{blockState:{blockName:"biomesoplenty:log_2",properties:{variant:"willow",axis:"x"}}}
:enddata
:endrule

rule:
plugin=vanillaBlocks
number=15
data:
JSON:{blockState:{blockName:"biomesoplenty:willow_stairs",properties:{half:"top",shape:"straight",facing:"west"}}}
:enddata
:endrule

rule:
plugin=vanillaBlocks
number=16
data:
JSON:{blockState:{blockName:"biomesoplenty:wood_slab_1",properties:{half:"top",variant:"willow"}}}
:enddata
:endrule

rule:
plugin=vanillaBlocks
number=17
data:
JSON:{blockState:{blockName:"minecraft:torch",properties:{facing:"up"}}}
:enddata
:endrule

rule:
plugin=vanillaBlocks
number=18
data:
JSON:{blockState:{blockName:"biomesoplenty:willow_stairs",properties:{half:"top",shape:"straight",facing:"south"}}}
:enddata
:endrule

rule:
plugin=vanillaBlocks
number=19
data:
JSON:{blockState:{blockName:"biomesoplenty:willow_stairs",properties:{half:"top",shape:"straight",facing:"north"}}}
:enddata
:endrule

#### ENTITIES ####
