# Ancient Warfare Structure Template File
# Auto-generated structure template file. created on: 9/23/2023 at: 13:18:16
# Lines beginning with # denote comments

header:
version=2.11
name=SB_KieavarusCol_House_1H6R_1_ebony
mods=biomesoplenty
size=28,14,15
offset=6,1,14
:endheader

#### VALIDATION ####
validation:
type=ground
structureAuthor=TheOddlySeagull
survival=true
worldGenEnabled=false
unique=false
preserveBlocks=false
preventNaturalHostileSpawns=false
selectionWeight=1
clusterValue=1
minDuplicateDistance=1
dimensionWhiteList=true
dimensionList=
biomeGroupList=
biomeWhiteList=true
biomeList=
leveling=0
fill=0
border=0
blockSwap=false
territoryName=
biomeReplacement=minecraft:
minGenerationHeight=0
maxGenerationHeight=255
:endvalidation

#### LAYERS ####
layer: 0
1,1,1,1,1,1,1,1,1,1,1,1,1,1,1,1,1,2,1,1,1,1,2,1,1,1,1,1
1,1,1,1,1,1,1,1,1,1,1,1,1,2,2,2,2,2,2,2,2,2,2,2,2,2,2,1
1,1,1,1,1,1,1,1,1,1,1,1,1,2,4,4,2,2,4,4,2,4,4,2,4,4,2,1
1,2,2,2,2,2,2,2,2,2,2,2,2,2,2,2,4,4,4,2,4,2,2,2,2,2,2,1
1,2,2,2,2,2,4,4,2,2,4,2,2,2,4,4,2,2,2,2,4,2,2,2,2,2,2,1
1,2,2,2,4,4,2,2,2,2,2,4,4,2,2,2,4,4,2,2,4,4,4,2,2,4,2,2
1,2,2,4,4,2,4,4,2,2,4,2,4,2,2,4,4,4,2,4,4,2,2,4,4,2,2,1
1,2,2,4,4,4,4,4,2,4,2,4,2,2,4,2,4,2,2,4,2,4,4,2,2,2,2,1
1,2,4,2,4,2,2,4,4,2,4,2,4,2,2,4,4,2,2,4,2,2,4,2,2,2,2,1
1,2,4,2,2,2,2,2,2,4,4,4,4,2,2,2,4,4,2,2,4,2,4,4,2,2,2,2
1,2,2,2,4,4,4,2,2,2,2,4,2,2,4,2,2,2,4,2,4,4,4,2,4,2,2,1
1,2,2,2,2,2,2,2,2,2,2,2,2,2,4,2,4,4,4,2,2,2,4,4,4,4,2,1
1,1,1,1,3,2,2,2,2,2,4,4,4,2,2,2,2,4,4,2,4,4,4,4,2,2,2,1
1,1,1,1,3,2,2,2,2,2,2,2,2,2,2,2,2,2,2,2,2,2,2,2,2,2,2,1
1,1,1,1,3,2,2,3,3,2,2,2,2,2,1,1,1,2,1,1,1,1,2,1,1,1,1,1
:endlayer
layer: 1
0,0,0,0,0,0,0,0,0,0,0,0,0,0,0,0,0,5,0,0,0,0,5,0,0,0,0,0
0,0,0,0,0,0,0,0,0,0,0,0,0,5,7,7,7,7,7,7,7,7,7,7,7,7,5,0
0,0,0,0,0,0,0,0,0,0,0,0,0,10,11,11,11,10,11,11,11,11,10,11,11,11,10,0
0,5,7,7,7,7,7,7,7,7,7,7,7,5,11,11,11,10,11,11,11,11,10,11,11,11,10,0
0,10,8,8,8,8,8,8,8,10,8,8,8,10,11,11,11,10,11,11,11,11,10,11,11,11,10,0
0,10,8,8,8,8,8,8,8,10,8,8,8,10,11,11,11,10,11,11,11,11,10,11,11,11,10,5
0,10,8,8,8,8,8,8,8,10,8,8,8,10,11,11,11,10,11,11,11,11,10,11,11,11,10,0
0,10,7,7,7,7,7,7,7,7,7,7,7,10,11,11,11,10,11,11,11,11,10,11,11,11,10,0
0,10,8,8,8,10,8,8,8,8,8,8,8,10,11,11,11,10,11,11,11,11,10,11,11,11,10,0
0,10,8,8,8,10,8,8,8,8,8,8,8,10,7,7,7,10,7,7,7,7,10,7,7,7,10,5
0,10,8,8,8,10,8,8,8,8,8,8,8,10,11,11,11,10,11,11,11,11,10,11,11,11,10,0
0,5,7,7,7,7,7,7,7,7,7,7,7,5,11,11,11,10,11,11,11,11,10,11,11,11,10,0
0,0,0,0,0,0,0,0,0,9,8,8,8,10,11,11,11,10,11,11,11,11,10,11,11,11,10,0
0,0,0,0,0,0,0,0,0,9,8,8,8,5,7,7,7,7,7,7,7,7,7,7,7,7,5,0
0,0,0,0,0,0,0,0,0,5,6,6,6,5,0,0,0,5,0,0,0,0,5,0,0,0,0,0
:endlayer
layer: 2
0,0,0,0,0,0,0,0,0,0,0,0,0,0,0,0,0,5,0,0,0,0,5,0,0,0,0,0
0,0,0,0,0,0,0,0,0,0,0,0,0,5,8,8,8,5,8,8,8,8,5,8,8,8,5,0
0,0,0,0,0,0,0,0,0,0,0,0,0,8,0,0,0,0,0,0,0,0,0,0,0,0,8,0
0,5,8,8,8,5,8,8,8,5,8,8,8,5,0,0,0,0,0,0,0,0,0,0,0,0,8,0
0,8,0,0,0,0,0,0,0,8,0,0,0,8,0,0,0,0,0,0,0,0,0,0,0,0,8,0
0,8,0,0,0,0,0,0,0,8,0,0,0,5,0,0,0,0,0,0,0,0,5,0,0,0,5,5
0,8,0,0,0,0,0,0,0,8,0,0,0,0,0,0,0,0,0,0,0,0,8,0,0,0,8,0
0,5,8,8,8,5,0,0,0,5,0,0,0,0,0,0,0,0,9,13,0,0,8,0,0,0,8,0
0,8,0,0,0,0,0,0,0,0,0,0,0,0,0,0,0,0,9,13,0,0,8,0,0,0,8,0
0,8,0,0,0,0,0,0,0,0,0,0,0,5,0,0,0,5,8,8,8,8,5,8,8,8,5,5
0,8,0,0,0,0,0,0,0,0,0,0,0,8,0,0,0,0,0,0,0,0,0,0,0,0,8,0
0,5,8,8,8,5,8,8,8,5,8,0,8,5,0,0,0,0,0,0,0,0,0,0,0,0,8,0
0,0,0,0,0,0,0,0,0,0,0,0,0,8,0,0,0,0,0,0,0,0,0,0,0,0,8,0
0,0,0,0,0,0,0,0,0,0,0,0,0,5,8,8,8,5,8,8,8,8,5,8,8,8,5,0
0,0,0,0,0,0,0,0,0,5,12,12,12,5,0,0,0,5,0,0,0,0,5,0,0,0,0,0
:endlayer
layer: 3
0,0,0,0,0,0,0,0,0,0,0,0,0,17,0,0,0,5,16,0,0,15,5,0,0,0,17,0
0,0,0,0,0,0,0,0,0,0,0,0,15,5,8,12,8,5,8,12,12,8,5,8,12,8,5,16
0,17,0,0,0,17,0,0,0,17,0,0,0,8,0,0,0,0,0,0,0,0,0,0,0,0,8,0
15,5,8,12,8,5,8,12,8,5,8,12,8,5,0,0,0,0,0,0,0,0,0,0,0,0,12,0
0,8,0,0,0,0,0,0,0,8,0,0,0,8,0,0,0,0,0,0,0,0,0,0,0,0,8,0
0,12,0,0,0,0,0,0,0,8,0,0,0,5,0,0,0,0,0,0,0,0,5,0,0,0,5,5
0,8,0,0,0,0,0,0,0,8,0,0,0,0,0,0,0,0,0,0,0,0,8,0,0,0,8,14
0,5,8,8,8,5,0,0,0,5,0,0,0,0,0,0,0,0,0,9,13,0,8,0,0,0,12,0
0,8,0,0,0,0,0,0,0,0,0,0,0,0,0,0,0,0,0,9,13,0,8,0,0,0,8,17
0,12,0,0,0,0,0,0,0,0,0,0,0,5,0,0,0,5,8,8,8,8,5,8,8,8,5,5
0,8,0,0,0,0,0,0,0,0,0,0,0,8,0,0,0,0,0,0,0,0,0,0,0,0,8,0
15,5,8,12,8,5,8,12,8,5,8,0,8,5,0,0,0,0,0,0,0,0,0,0,0,0,12,0
0,14,0,0,0,14,0,0,0,14,0,0,0,8,0,0,0,0,0,0,0,0,0,0,0,0,8,0
0,0,0,0,0,0,0,0,0,0,0,0,15,5,8,12,8,5,8,12,12,8,5,8,12,8,5,16
0,0,0,0,0,0,0,0,0,12,0,0,0,12,0,0,0,5,16,0,0,15,5,0,0,0,14,0
:endlayer
layer: 4
0,0,0,0,0,0,0,0,0,0,0,0,0,0,0,0,0,5,0,0,0,0,5,0,0,0,0,0
0,0,0,0,0,0,0,0,0,0,0,0,0,5,8,8,8,5,8,8,8,8,5,8,8,8,5,0
0,0,0,0,0,0,0,0,0,0,0,0,0,8,0,0,0,14,0,0,0,0,6,0,0,0,8,0
0,5,8,8,8,5,8,8,8,5,8,8,8,5,0,0,0,0,0,0,0,0,11,0,0,0,8,0
0,8,0,0,0,14,0,0,0,8,0,0,0,8,0,0,0,0,0,0,0,0,18,0,0,0,8,0
0,8,0,0,0,0,0,0,0,8,0,0,0,5,16,0,0,0,0,0,0,15,5,16,0,15,5,5
0,8,0,0,0,0,0,0,0,8,0,0,0,6,0,0,0,0,0,0,0,0,8,0,0,0,8,0
0,5,8,8,8,5,13,11,19,5,16,0,0,11,0,0,0,0,0,0,9,13,8,0,0,0,8,0
0,8,0,0,0,6,0,0,0,14,0,0,0,18,0,0,0,17,0,0,9,13,8,0,0,0,8,0
0,8,16,0,0,11,0,0,0,0,0,0,0,5,13,11,19,5,8,8,8,8,5,8,8,8,5,5
0,8,0,0,0,18,0,0,0,0,0,0,0,8,0,0,0,14,0,0,0,0,14,0,0,0,8,0
0,5,8,8,8,5,8,8,8,5,8,8,8,5,16,0,0,0,0,0,0,0,0,0,0,0,8,0
0,0,0,0,0,0,0,0,0,0,0,0,0,8,0,0,0,17,0,0,0,0,17,0,0,0,8,0
0,0,0,0,0,0,0,0,0,0,0,0,0,5,8,8,8,5,8,8,8,8,5,8,8,8,5,0
0,0,0,0,0,0,0,0,0,12,0,0,0,12,0,0,0,5,0,0,0,0,5,0,0,0,0,0
:endlayer
layer: 5
0,0,0,0,0,0,0,0,0,0,0,0,20,20,20,20,20,20,20,20,20,20,20,20,20,20,20,20
0,0,0,0,0,0,0,0,0,0,0,0,0,5,7,7,7,7,7,7,7,7,7,7,7,7,5,0
20,20,20,20,20,20,20,20,20,20,20,20,20,10,11,8,11,10,11,11,11,11,10,11,8,11,10,0
0,5,7,7,7,7,7,7,7,7,7,7,7,10,11,8,11,10,8,8,8,8,10,11,8,11,10,0
0,10,11,8,11,10,11,8,11,10,11,8,11,10,11,8,11,10,11,11,11,11,10,11,8,11,10,0
0,10,11,8,11,10,11,8,11,10,11,8,11,10,7,7,7,10,8,8,8,8,10,7,7,7,10,5
0,10,11,8,11,10,11,8,11,10,11,8,11,10,11,8,11,10,7,7,7,7,10,11,8,11,10,0
0,10,7,7,7,7,7,7,7,7,7,7,7,10,11,8,11,10,0,0,0,9,10,11,8,11,10,0
0,10,11,8,11,10,11,8,11,10,11,8,11,10,11,8,11,10,0,0,0,9,10,11,8,11,10,0
0,10,11,8,11,10,11,8,11,10,11,8,11,10,7,7,7,10,7,7,7,7,10,7,7,7,10,5
0,10,11,8,11,10,11,8,11,10,11,8,11,10,11,8,11,10,11,11,11,11,10,11,8,11,10,0
0,5,7,7,7,7,7,7,7,7,7,7,7,10,11,8,11,10,8,8,8,8,10,11,8,11,10,0
20,20,20,20,20,20,20,20,20,20,20,20,20,10,11,8,11,10,11,11,11,11,10,11,8,11,10,0
0,0,0,0,0,0,0,0,0,0,0,0,0,5,7,7,7,7,7,7,7,7,7,7,7,7,5,0
0,0,0,0,0,0,0,0,0,20,20,20,20,20,20,20,20,20,20,20,20,20,20,20,20,20,20,20
:endlayer
layer: 6
0,0,0,0,0,0,0,0,0,0,0,0,0,0,0,0,0,0,0,0,0,0,0,0,0,0,0,0
0,0,0,0,0,0,0,0,0,0,0,0,20,20,20,20,20,20,20,20,20,20,20,20,20,20,20,20
0,0,0,0,0,0,0,0,0,0,0,0,0,8,0,0,0,0,0,0,0,0,0,0,0,0,8,0
20,20,20,20,20,20,20,20,20,20,20,20,20,8,0,0,0,0,0,21,0,0,0,0,0,0,8,0
0,8,0,0,0,0,0,0,0,0,0,0,0,8,0,0,0,0,0,0,0,0,0,0,0,0,8,0
0,8,0,0,0,0,0,0,0,0,0,0,0,5,0,0,0,0,0,0,0,0,0,0,0,0,5,5
0,8,0,0,0,0,0,0,0,0,0,0,0,0,0,0,0,12,12,12,12,0,0,0,0,0,8,0
0,8,0,0,0,0,0,21,0,0,0,0,0,0,0,0,0,12,0,0,0,0,0,0,0,0,8,0
0,8,0,0,0,0,0,0,0,0,0,0,0,0,0,0,0,12,0,0,0,0,0,0,0,0,8,0
0,8,0,0,0,0,0,0,0,0,0,0,0,5,0,0,0,12,12,12,12,0,0,0,0,0,5,5
0,8,0,0,0,0,0,0,0,0,0,0,0,8,0,0,0,0,0,0,0,0,0,0,0,0,8,0
20,20,20,20,20,20,20,20,20,20,20,20,20,8,0,0,0,0,0,21,0,0,0,0,0,0,8,0
0,0,0,0,0,0,0,0,0,0,17,0,0,8,0,0,0,0,0,0,0,0,0,0,0,0,8,0
0,0,0,0,0,0,0,0,0,20,20,20,20,20,20,20,20,20,20,20,20,20,20,20,20,20,20,20
0,0,0,0,0,0,0,0,0,0,0,0,0,0,0,0,0,0,0,0,0,0,0,0,0,0,0,0
:endlayer
layer: 7
0,0,0,0,0,0,0,0,0,0,0,0,0,0,0,0,0,0,0,0,0,0,0,0,0,0,0,0
0,0,0,0,0,0,0,0,0,0,0,0,0,0,0,0,0,0,0,0,0,0,0,0,0,0,0,0
0,0,0,0,0,0,0,0,0,0,0,0,20,20,20,20,20,20,20,20,20,20,20,20,20,20,20,20
0,0,0,0,0,0,0,0,0,0,0,0,0,8,0,0,0,0,0,0,0,0,0,0,0,0,8,0
20,20,20,20,20,20,20,20,20,20,20,20,20,8,0,0,0,0,0,0,0,0,0,0,0,0,8,0
0,8,16,0,0,0,0,0,0,0,0,0,15,5,16,0,0,0,0,0,0,0,0,0,0,15,5,5
0,8,0,0,0,0,0,0,0,0,0,0,0,0,0,0,0,0,0,0,0,0,0,0,0,0,8,0
0,12,0,0,0,0,0,0,0,0,0,0,0,0,0,0,0,0,0,0,0,0,0,0,0,0,12,0
0,8,0,0,0,0,0,0,0,0,0,0,0,0,0,0,0,0,0,0,0,0,0,0,0,0,8,0
0,8,16,0,0,0,0,0,0,0,0,0,15,5,16,0,0,0,0,0,0,0,0,0,0,15,5,5
20,20,20,20,20,20,20,20,20,20,20,20,20,8,0,0,0,0,0,0,0,0,0,0,0,0,8,0
0,0,0,0,0,0,0,0,0,0,0,0,0,8,0,0,0,0,0,0,0,0,0,0,0,0,8,0
0,0,0,0,0,0,0,0,0,0,0,0,20,20,20,20,20,20,20,20,20,20,20,20,20,20,20,20
0,0,0,0,0,0,0,0,0,0,0,0,0,0,0,0,0,0,0,0,0,0,0,0,0,0,0,0
0,0,0,0,0,0,0,0,0,0,0,0,0,0,0,0,0,0,0,0,0,0,0,0,0,0,0,0
:endlayer
layer: 8
0,0,0,0,0,0,0,0,0,0,0,0,0,0,0,0,0,0,0,0,0,0,0,0,0,0,0,0
0,0,0,0,0,0,0,0,0,0,0,0,0,0,0,0,0,0,0,0,0,0,0,0,0,0,0,0
0,0,0,0,0,0,0,0,0,0,0,0,0,0,21,0,0,0,0,0,0,0,0,0,0,21,0,0
0,0,0,0,0,0,0,0,0,0,0,0,20,20,20,20,20,20,20,20,20,20,20,20,20,20,20,20
0,0,21,0,0,0,0,21,0,0,0,0,21,8,0,0,0,0,0,0,0,0,0,0,0,0,8,0
20,20,20,20,20,20,20,20,20,20,20,20,20,5,0,0,0,0,0,0,0,0,0,0,0,0,5,5
0,8,0,0,0,0,0,0,0,0,0,0,0,6,0,0,0,0,0,0,0,0,0,0,0,0,8,0
0,8,0,0,0,0,0,0,0,0,0,0,0,11,0,0,0,0,0,0,0,0,0,0,0,0,8,0
0,8,0,0,0,0,0,0,0,0,0,0,0,18,0,0,0,0,0,0,0,0,0,0,0,0,8,0
20,20,20,20,20,20,20,20,20,20,20,20,20,5,0,0,0,0,0,0,0,0,0,0,0,0,5,5
0,0,21,0,0,0,0,21,0,0,0,0,21,8,0,0,0,0,0,0,0,0,0,0,0,0,8,0
0,0,0,0,0,0,0,0,0,0,0,0,20,20,20,20,20,20,20,20,20,20,20,20,20,20,20,20
0,0,0,0,0,0,0,0,0,0,0,0,0,0,21,0,0,0,0,0,0,0,0,0,0,21,0,0
0,0,0,0,0,0,0,0,0,0,0,0,0,0,0,0,0,0,0,0,0,0,0,0,0,0,0,0
0,0,0,0,0,0,0,0,0,0,0,0,0,0,0,0,0,0,0,0,0,0,0,0,0,0,0,0
:endlayer
layer: 9
0,0,0,0,0,0,0,0,0,0,0,0,0,0,0,0,0,0,0,0,0,0,0,0,0,0,0,0
0,0,0,0,0,0,0,0,0,0,0,0,0,0,0,0,0,0,0,0,0,0,0,0,0,0,0,0
0,0,0,0,0,0,0,0,0,0,0,0,0,0,0,0,0,0,0,0,0,0,0,0,0,0,0,0
0,0,0,0,0,0,0,0,0,0,0,0,0,0,0,0,0,0,21,0,0,21,0,0,0,0,0,0
0,0,0,0,0,0,0,0,0,0,0,0,20,20,20,20,20,20,20,20,20,20,20,20,20,20,20,20
0,0,0,0,0,0,0,0,0,0,0,0,0,5,0,0,0,0,0,0,0,0,0,0,0,0,5,5
20,20,20,20,20,20,20,20,20,20,20,20,20,10,0,0,0,0,0,0,0,0,0,0,0,0,10,0
0,8,0,0,0,0,0,0,0,0,0,0,0,10,0,0,0,0,0,0,0,0,0,0,0,0,10,0
20,20,20,20,20,20,20,20,20,20,20,20,20,10,0,0,0,0,0,0,0,0,0,0,0,0,10,0
0,0,0,0,0,0,0,0,0,0,0,0,0,5,0,0,0,0,0,0,0,0,0,0,0,0,5,5
0,0,0,0,0,0,0,0,0,0,0,0,20,20,20,20,20,20,20,20,20,20,20,20,20,20,20,20
0,0,0,0,0,0,0,0,0,0,0,0,0,0,0,0,0,0,21,0,0,21,0,0,0,0,0,0
0,0,0,0,0,0,0,0,0,0,0,0,0,0,0,0,0,0,0,0,0,0,0,0,0,0,0,0
0,0,0,0,0,0,0,0,0,0,0,0,0,0,0,0,0,0,0,0,0,0,0,0,0,0,0,0
0,0,0,0,0,0,0,0,0,0,0,0,0,0,0,0,0,0,0,0,0,0,0,0,0,0,0,0
:endlayer
layer: 10
0,0,0,0,0,0,0,0,0,0,0,0,0,0,0,0,0,0,0,0,0,0,0,0,0,0,0,0
0,0,0,0,0,0,0,0,0,0,0,0,0,0,0,0,0,0,0,0,0,0,0,0,0,0,0,0
0,0,0,0,0,0,0,0,0,0,0,0,0,0,0,0,0,0,0,0,0,0,0,0,0,0,0,0
0,0,0,0,0,0,0,0,0,0,0,0,0,0,0,0,0,0,0,0,0,0,0,0,0,0,0,0
0,0,0,0,0,0,0,0,0,0,0,0,0,0,0,0,0,0,0,0,0,0,0,0,0,0,0,0
0,0,0,0,0,0,0,0,0,0,0,0,20,20,20,20,20,20,20,20,20,20,20,20,20,20,20,20
0,0,0,0,0,0,0,0,0,0,0,0,0,8,0,0,0,0,0,0,0,0,0,0,0,0,8,6
20,20,20,20,20,20,20,20,20,20,20,20,20,8,0,0,0,0,0,0,0,0,0,0,0,0,8,22
0,0,0,0,0,0,0,0,0,0,0,0,0,8,0,0,0,0,0,0,0,0,0,0,0,0,8,18
0,0,0,0,0,0,0,0,0,0,0,0,20,20,20,20,20,20,20,20,20,20,20,20,20,20,20,20
0,0,0,0,0,0,0,0,0,0,0,0,0,0,0,0,0,0,0,0,0,0,0,0,0,0,0,0
0,0,0,0,0,0,0,0,0,0,0,0,0,0,0,0,0,0,0,0,0,0,0,0,0,0,0,0
0,0,0,0,0,0,0,0,0,0,0,0,0,0,0,0,0,0,0,0,0,0,0,0,0,0,0,0
0,0,0,0,0,0,0,0,0,0,0,0,0,0,0,0,0,0,0,0,0,0,0,0,0,0,0,0
0,0,0,0,0,0,0,0,0,0,0,0,0,0,0,0,0,0,0,0,0,0,0,0,0,0,0,0
:endlayer
layer: 11
0,0,0,0,0,0,0,0,0,0,0,0,0,0,0,0,0,0,0,0,0,0,0,0,0,0,0,0
0,0,0,0,0,0,0,0,0,0,0,0,0,0,0,0,0,0,0,0,0,0,0,0,0,0,0,0
0,0,0,0,0,0,0,0,0,0,0,0,0,0,0,0,0,0,0,0,0,0,0,0,0,0,0,0
0,0,0,0,0,0,0,0,0,0,0,0,0,0,0,0,0,0,0,0,0,0,0,0,0,0,0,0
0,0,0,0,0,0,0,0,0,0,0,0,0,0,0,0,0,0,0,0,0,0,0,0,0,0,0,0
0,0,0,0,0,0,0,0,0,0,0,0,0,0,21,0,0,0,0,0,0,0,0,0,0,21,0,0
0,0,0,0,0,0,0,0,0,0,0,0,20,20,20,20,20,20,20,20,20,20,20,20,20,20,20,20
0,0,21,0,0,0,0,21,0,0,0,0,21,8,0,0,0,0,0,0,0,0,0,0,0,0,8,12
0,0,0,0,0,0,0,0,0,0,0,0,20,20,20,20,20,20,20,20,20,20,20,20,20,20,20,20
0,0,0,0,0,0,0,0,0,0,0,0,0,0,21,0,0,0,0,0,0,0,0,0,0,21,0,0
0,0,0,0,0,0,0,0,0,0,0,0,0,0,0,0,0,0,0,0,0,0,0,0,0,0,0,0
0,0,0,0,0,0,0,0,0,0,0,0,0,0,0,0,0,0,0,0,0,0,0,0,0,0,0,0
0,0,0,0,0,0,0,0,0,0,0,0,0,0,0,0,0,0,0,0,0,0,0,0,0,0,0,0
0,0,0,0,0,0,0,0,0,0,0,0,0,0,0,0,0,0,0,0,0,0,0,0,0,0,0,0
0,0,0,0,0,0,0,0,0,0,0,0,0,0,0,0,0,0,0,0,0,0,0,0,0,0,0,0
:endlayer
layer: 12
0,0,0,0,0,0,0,0,0,0,0,0,0,0,0,0,0,0,0,0,0,0,0,0,0,0,0,0
0,0,0,0,0,0,0,0,0,0,0,0,0,0,0,0,0,0,0,0,0,0,0,0,0,0,0,0
0,0,0,0,0,0,0,0,0,0,0,0,0,0,0,0,0,0,0,0,0,0,0,0,0,0,0,0
0,0,0,0,0,0,0,0,0,0,0,0,0,0,0,0,0,0,0,0,0,0,0,0,0,0,0,0
0,0,0,0,0,0,0,0,0,0,0,0,0,0,0,0,0,0,0,0,0,0,0,0,0,0,0,0
0,0,0,0,0,0,0,0,0,0,0,0,0,0,0,0,0,0,0,0,0,0,0,0,0,0,0,0
0,0,0,0,0,0,0,0,0,0,0,0,0,0,0,0,0,0,0,0,0,0,0,0,0,0,0,0
0,0,0,0,0,0,0,0,0,0,0,0,20,20,20,20,20,20,20,20,20,20,20,20,20,20,20,20
0,0,0,0,0,0,0,0,0,0,0,0,0,0,0,0,0,0,0,0,0,0,0,0,0,0,0,0
0,0,0,0,0,0,0,0,0,0,0,0,0,0,0,0,0,0,0,0,0,0,0,0,0,0,0,0
0,0,0,0,0,0,0,0,0,0,0,0,0,0,0,0,0,0,0,0,0,0,0,0,0,0,0,0
0,0,0,0,0,0,0,0,0,0,0,0,0,0,0,0,0,0,0,0,0,0,0,0,0,0,0,0
0,0,0,0,0,0,0,0,0,0,0,0,0,0,0,0,0,0,0,0,0,0,0,0,0,0,0,0
0,0,0,0,0,0,0,0,0,0,0,0,0,0,0,0,0,0,0,0,0,0,0,0,0,0,0,0
0,0,0,0,0,0,0,0,0,0,0,0,0,0,0,0,0,0,0,0,0,0,0,0,0,0,0,0
:endlayer
layer: 13
0,0,0,0,0,0,0,0,0,0,0,0,0,0,0,0,0,0,0,0,0,0,0,0,0,0,0,0
0,0,0,0,0,0,0,0,0,0,0,0,0,0,0,0,0,0,0,0,0,0,0,0,0,0,0,0
0,0,0,0,0,0,0,0,0,0,0,0,0,0,0,0,0,0,0,0,0,0,0,0,0,0,0,0
0,0,0,0,0,0,0,0,0,0,0,0,0,0,0,0,0,0,0,0,0,0,0,0,0,0,0,0
0,0,0,0,0,0,0,0,0,0,0,0,0,0,0,0,0,0,0,0,0,0,0,0,0,0,0,0
0,0,0,0,0,0,0,0,0,0,0,0,0,0,0,0,0,0,0,0,0,0,0,0,0,0,0,0
0,0,0,0,0,0,0,0,0,0,0,0,0,0,0,0,0,0,0,0,0,0,0,0,0,0,0,0
0,0,0,0,0,0,0,0,0,0,0,0,0,0,0,0,0,21,0,0,0,0,21,0,0,0,0,0
0,0,0,0,0,0,0,0,0,0,0,0,0,0,0,0,0,0,0,0,0,0,0,0,0,0,0,0
0,0,0,0,0,0,0,0,0,0,0,0,0,0,0,0,0,0,0,0,0,0,0,0,0,0,0,0
0,0,0,0,0,0,0,0,0,0,0,0,0,0,0,0,0,0,0,0,0,0,0,0,0,0,0,0
0,0,0,0,0,0,0,0,0,0,0,0,0,0,0,0,0,0,0,0,0,0,0,0,0,0,0,0
0,0,0,0,0,0,0,0,0,0,0,0,0,0,0,0,0,0,0,0,0,0,0,0,0,0,0,0
0,0,0,0,0,0,0,0,0,0,0,0,0,0,0,0,0,0,0,0,0,0,0,0,0,0,0,0
0,0,0,0,0,0,0,0,0,0,0,0,0,0,0,0,0,0,0,0,0,0,0,0,0,0,0,0
:endlayer

#### RULES ####
rule:
plugin=vanillaBlocks
number=1
data:
JSON:{blockState:{blockName:"minecraft:grass",properties:{snowy:"false"}}}
:enddata
:endrule

rule:
plugin=vanillaBlocks
number=2
data:
JSON:{blockState:{blockName:"minecraft:cobblestone"}}
:enddata
:endrule

rule:
plugin=vanillaBlocks
number=3
data:
JSON:{blockState:{blockName:"minecraft:stonebrick",properties:{variant:"stonebrick"}}}
:enddata
:endrule

rule:
plugin=vanillaBlocks
number=4
data:
JSON:{blockState:{blockName:"minecraft:dirt",properties:{variant:"dirt",snowy:"false"}}}
:enddata
:endrule

rule:
plugin=vanillaBlocks
number=5
data:
JSON:{blockState:{blockName:"biomesoplenty:log_3",properties:{variant:"ebony",axis:"y"}}}
:enddata
:endrule

rule:
plugin=vanillaBlocks
number=6
data:
JSON:{blockState:{blockName:"biomesoplenty:ebony_stairs",properties:{half:"top",shape:"straight",facing:"north"}}}
:enddata
:endrule

rule:
plugin=vanillaBlocks
number=7
data:
JSON:{blockState:{blockName:"biomesoplenty:log_3",properties:{variant:"ebony",axis:"x"}}}
:enddata
:endrule

rule:
plugin=vanillaBlocks
number=8
data:
JSON:{blockState:{blockName:"biomesoplenty:planks_0",properties:{variant:"ebony"}}}
:enddata
:endrule

rule:
plugin=vanillaBlocks
number=9
data:
JSON:{blockState:{blockName:"biomesoplenty:ebony_stairs",properties:{half:"bottom",shape:"straight",facing:"east"}}}
:enddata
:endrule

rule:
plugin=vanillaBlocks
number=10
data:
JSON:{blockState:{blockName:"biomesoplenty:log_3",properties:{variant:"ebony",axis:"z"}}}
:enddata
:endrule

rule:
plugin=vanillaBlocks
number=11
data:
JSON:{blockState:{blockName:"biomesoplenty:wood_slab_1",properties:{half:"top",variant:"ebony"}}}
:enddata
:endrule

rule:
plugin=vanillaBlocks
number=12
data:
JSON:{blockState:{blockName:"biomesoplenty:ebony_fence",properties:{east:"false",south:"false",north:"false",west:"false"}}}
:enddata
:endrule

rule:
plugin=vanillaBlocks
number=13
data:
JSON:{blockState:{blockName:"biomesoplenty:ebony_stairs",properties:{half:"top",shape:"straight",facing:"west"}}}
:enddata
:endrule

rule:
plugin=vanillaBlocks
number=14
data:
JSON:{blockState:{blockName:"minecraft:torch",properties:{facing:"south"}}}
:enddata
:endrule

rule:
plugin=vanillaBlocks
number=15
data:
JSON:{blockState:{blockName:"minecraft:torch",properties:{facing:"west"}}}
:enddata
:endrule

rule:
plugin=vanillaBlocks
number=16
data:
JSON:{blockState:{blockName:"minecraft:torch",properties:{facing:"east"}}}
:enddata
:endrule

rule:
plugin=vanillaBlocks
number=17
data:
JSON:{blockState:{blockName:"minecraft:torch",properties:{facing:"north"}}}
:enddata
:endrule

rule:
plugin=vanillaBlocks
number=18
data:
JSON:{blockState:{blockName:"biomesoplenty:ebony_stairs",properties:{half:"top",shape:"straight",facing:"south"}}}
:enddata
:endrule

rule:
plugin=vanillaBlocks
number=19
data:
JSON:{blockState:{blockName:"biomesoplenty:ebony_stairs",properties:{half:"top",shape:"straight",facing:"east"}}}
:enddata
:endrule

rule:
plugin=vanillaBlocks
number=20
data:
JSON:{blockState:{blockName:"minecraft:wool",properties:{color:"brown"}}}
:enddata
:endrule

rule:
plugin=vanillaBlocks
number=21
data:
JSON:{blockState:{blockName:"minecraft:torch",properties:{facing:"up"}}}
:enddata
:endrule

rule:
plugin=vanillaBlocks
number=22
data:
JSON:{blockState:{blockName:"biomesoplenty:wood_slab_1",properties:{half:"bottom",variant:"ebony"}}}
:enddata
:endrule

#### ENTITIES ####
