# Ancient Warfare Structure Template File
# Auto-generated structure template file. created on: 9/23/2023 at: 0:40:8
# Lines beginning with # denote comments

header:
version=2.11
name=SB_KieavarusCol_House_2H10R_1_cherry
mods=biomesoplenty
size=18,18,23
offset=14,1,22
:endheader

#### VALIDATION ####
validation:
type=ground
structureAuthor=TheOddlySeagull
survival=true
worldGenEnabled=false
unique=false
preserveBlocks=false
preventNaturalHostileSpawns=false
selectionWeight=1
clusterValue=1
minDuplicateDistance=1
dimensionWhiteList=true
dimensionList=
biomeGroupList=
biomeWhiteList=true
biomeList=
leveling=0
fill=0
border=0
blockSwap=false
territoryName=
biomeReplacement=minecraft:
minGenerationHeight=0
maxGenerationHeight=255
:endvalidation

#### LAYERS ####
layer: 0
1,1,1,2,1,1,1,2,1,1,1,2,1,1,1,1,1,1
1,2,2,2,2,2,2,2,2,2,2,2,2,2,1,1,1,1
1,2,3,3,2,2,3,2,3,2,3,3,2,2,1,1,1,1
2,2,2,3,3,2,3,3,3,2,3,2,2,2,1,1,1,1
1,2,2,3,3,3,2,3,3,2,3,2,2,2,1,1,2,1
1,2,3,2,3,2,3,2,2,2,2,2,3,2,1,1,1,1
1,2,2,3,3,2,3,2,3,2,2,3,3,2,1,1,1,1
1,2,3,2,3,3,2,2,3,3,3,2,3,2,1,1,1,1
2,2,3,3,3,3,2,2,3,3,3,3,2,2,1,1,2,1
1,2,2,3,3,3,3,2,3,3,3,2,3,2,1,1,1,1
2,2,3,3,3,2,2,2,2,3,3,2,2,2,1,1,1,1
1,2,3,2,2,3,3,3,2,3,3,3,3,2,1,1,1,1
1,2,3,3,3,3,3,3,2,3,3,2,3,2,2,2,2,1
1,2,2,3,3,3,3,3,3,3,2,2,3,2,2,2,1,1
1,2,3,3,2,2,3,3,2,3,2,3,3,2,2,2,1,1
2,2,2,3,3,3,3,3,2,3,3,2,3,2,2,2,1,1
1,2,2,3,2,2,2,3,2,3,2,3,2,2,2,2,2,1
1,2,2,2,2,2,2,2,2,2,2,2,2,2,2,2,4,1
1,1,1,2,2,2,3,3,2,2,3,2,1,4,2,2,4,1
1,1,1,2,3,3,2,3,3,3,2,2,1,4,2,2,4,1
1,1,1,2,3,3,3,2,2,3,3,2,1,4,2,2,4,1
1,1,1,2,2,2,2,2,2,2,2,2,1,4,2,2,4,1
1,1,1,1,1,2,1,1,1,2,1,1,1,4,2,2,4,1
:endlayer
layer: 1
0,0,0,5,0,0,0,5,0,0,0,5,0,0,0,0,0,0
0,5,6,5,6,6,6,5,6,6,6,5,6,5,0,0,0,0
0,6,2,2,2,2,2,3,3,3,2,3,3,6,0,0,0,0
5,5,3,2,3,3,3,3,3,2,3,2,2,5,0,0,0,0
0,6,3,2,2,2,3,2,2,2,2,2,2,6,0,0,5,0
0,6,3,2,2,2,3,3,3,2,2,2,3,6,0,0,0,0
0,6,2,2,3,2,2,2,2,3,3,2,3,6,0,0,0,0
0,6,2,2,3,3,3,2,2,3,3,2,2,6,0,0,0,0
5,5,2,2,3,3,3,3,3,3,2,3,3,5,0,0,5,0
0,6,2,3,3,3,2,3,2,3,3,2,3,6,0,0,0,0
5,5,3,3,2,3,2,3,2,3,2,2,3,5,0,0,0,0
0,6,3,3,2,3,3,2,3,3,2,2,3,6,0,0,0,0
0,6,3,3,2,2,3,3,3,2,2,2,3,6,6,6,5,0
0,6,2,2,2,3,3,3,3,2,3,2,3,6,6,6,0,0
0,6,3,3,2,3,2,2,2,2,2,2,3,6,6,6,0,0
5,5,2,2,2,2,2,2,2,2,3,3,2,5,7,7,8,0
0,6,3,2,2,3,2,2,2,3,3,3,3,6,0,0,5,0
0,5,6,5,6,6,6,5,6,6,6,5,6,5,0,0,0,0
0,0,0,6,2,3,2,3,3,2,3,6,0,0,0,0,0,0
0,0,0,6,3,2,3,3,3,3,2,6,0,0,0,0,0,0
0,0,0,6,2,3,3,3,2,2,2,6,0,0,0,0,0,0
0,0,0,5,6,5,6,6,6,5,6,5,0,0,0,0,0,0
0,0,0,0,0,5,0,0,0,5,0,0,0,0,0,0,0,0
:endlayer
layer: 2
0,0,0,5,0,0,0,5,0,0,0,5,0,0,0,0,0,0
0,5,10,10,10,10,10,10,10,10,10,10,10,5,0,0,0,0
0,9,6,6,6,6,6,9,6,6,6,6,6,9,0,0,0,0
5,9,6,6,6,6,6,9,6,6,6,6,6,9,0,0,0,0
0,9,6,6,6,6,6,9,6,6,6,6,6,9,0,0,5,0
0,9,6,6,6,6,6,9,6,6,6,6,6,9,0,0,0,0
0,9,6,6,6,6,6,9,6,6,6,6,6,9,0,0,0,0
0,9,6,6,6,6,6,9,6,6,6,6,6,9,0,0,0,0
5,9,10,10,10,10,10,10,10,10,10,10,10,9,0,0,5,0
0,9,6,6,6,6,6,9,6,6,6,6,6,9,0,0,0,0
5,9,6,6,6,6,6,9,6,6,6,6,6,9,0,0,0,0
0,9,6,6,6,6,6,9,6,6,6,6,6,9,11,11,0,0
0,9,6,6,6,6,6,9,6,6,6,6,6,9,6,6,5,0
0,9,6,6,6,6,6,9,6,6,6,6,6,9,6,6,8,0
0,9,6,6,6,6,6,9,6,6,6,6,6,9,7,7,11,0
5,9,6,6,6,6,6,9,6,6,6,6,6,9,0,0,12,0
0,9,6,6,6,6,6,9,6,6,6,6,6,9,0,0,5,0
0,5,10,5,10,10,10,5,10,10,10,5,10,5,0,0,0,0
0,0,0,9,6,6,6,6,6,6,6,9,0,0,0,0,0,0
0,0,0,9,6,6,6,6,6,6,6,9,0,0,0,0,0,0
0,0,0,9,6,6,6,6,6,6,6,9,0,0,0,0,0,0
0,0,0,5,10,10,10,10,10,10,10,5,0,0,0,0,0,0
0,0,0,0,0,5,0,0,0,5,0,0,0,0,0,0,0,0
:endlayer
layer: 3
0,14,0,5,16,0,13,5,16,0,13,5,0,14,0,0,0,0
13,5,6,5,6,6,6,5,6,6,6,5,6,5,16,0,0,0
0,6,0,0,0,0,0,6,0,0,0,0,0,6,0,0,0,0
5,5,0,0,0,0,0,6,0,0,0,0,0,5,0,0,14,0
15,6,0,0,0,0,0,6,0,0,0,0,0,6,0,0,5,16
0,6,0,0,0,0,0,6,0,0,0,0,0,6,0,0,0,0
0,6,0,0,0,0,0,6,0,0,0,0,0,6,0,0,0,0
14,6,0,0,0,0,0,6,0,0,0,0,0,6,0,0,0,0
5,5,6,0,0,0,6,5,6,0,0,0,6,5,16,0,5,16
0,6,0,0,0,0,0,0,0,0,0,0,0,6,0,0,9,0
5,5,0,0,0,0,0,0,0,0,0,0,0,5,11,11,9,0
15,6,0,0,0,0,0,0,0,0,0,0,0,6,7,7,9,0
0,6,0,0,0,0,0,5,0,0,0,0,0,0,0,0,5,16
0,6,0,0,0,0,0,6,0,0,0,0,0,0,0,0,12,0
14,6,0,0,0,0,0,6,0,0,0,0,0,6,0,0,12,0
5,5,0,0,0,0,0,6,0,0,0,0,0,5,0,0,12,0
0,6,0,0,0,0,0,6,0,0,0,0,0,6,0,0,5,16
13,5,6,5,6,6,6,5,0,0,0,5,6,5,16,0,0,0
0,15,0,6,0,0,0,0,0,0,0,6,0,15,0,0,0,0
0,0,0,6,0,0,0,0,0,0,0,6,0,0,0,0,0,0
0,0,0,6,0,0,0,0,0,0,0,6,0,0,0,0,0,0
0,0,13,5,6,5,6,6,6,5,6,5,16,0,0,0,0,0
0,0,0,15,0,5,16,0,13,5,0,15,0,0,0,0,0,0
:endlayer
layer: 4
0,0,0,5,0,0,0,5,0,0,0,5,0,0,0,0,0,0
0,5,6,5,6,12,6,5,6,12,6,5,6,5,0,0,0,0
0,6,0,0,0,0,0,6,0,0,0,0,0,6,0,0,0,0
5,5,0,0,0,0,0,6,0,0,0,0,0,5,0,0,0,0
0,6,0,0,0,0,0,6,0,0,0,0,0,6,0,0,5,0
0,12,0,0,0,0,0,6,0,0,0,0,0,12,0,0,9,0
0,12,0,0,0,0,0,6,0,0,0,0,0,12,0,0,9,0
0,6,0,0,0,0,0,6,0,0,0,0,0,6,0,0,9,0
5,5,6,0,0,0,6,5,6,0,0,0,6,5,0,0,5,0
0,6,0,0,0,0,0,0,0,0,0,0,0,6,11,11,0,0
5,5,0,0,0,0,0,0,0,0,0,0,0,5,7,7,11,0
0,6,0,0,0,0,0,0,0,0,0,0,0,6,0,0,12,0
0,12,0,0,0,0,0,5,0,0,0,0,0,0,0,0,5,0
0,12,0,0,0,0,0,6,0,0,0,0,0,0,0,0,0,0
0,6,0,0,0,0,0,6,0,0,0,0,0,6,0,0,0,0
5,5,0,0,0,0,0,6,0,0,0,0,0,5,0,0,0,0
0,6,0,0,0,0,0,6,0,0,0,0,0,6,0,0,5,0
0,5,6,5,6,6,6,5,0,0,0,5,6,5,0,0,0,0
0,0,0,6,0,0,0,0,0,0,0,6,0,0,0,0,0,0
0,0,0,12,0,0,0,0,0,0,0,12,0,0,0,0,0,0
0,0,0,6,0,0,0,0,0,0,0,6,0,0,0,0,0,0
0,0,0,5,6,5,6,12,6,5,6,5,0,0,0,0,0,0
0,0,0,0,0,5,0,0,0,5,0,0,0,0,0,0,0,0
:endlayer
layer: 5
0,0,0,5,0,0,0,5,0,0,0,5,0,0,0,0,0,0
0,5,6,5,6,6,6,5,6,6,6,5,6,5,0,0,0,0
0,6,0,15,0,0,0,6,0,0,0,15,0,6,0,0,0,0
5,5,16,0,0,0,0,6,0,0,0,0,13,5,0,0,0,0
0,6,0,0,0,0,0,6,0,0,0,0,0,6,0,0,5,0
0,6,0,0,0,0,0,6,16,0,0,0,0,6,0,0,0,0
0,6,0,0,0,0,13,6,0,0,0,0,0,6,0,0,0,0
0,6,0,0,0,0,0,6,0,0,0,0,0,6,0,0,0,0
5,5,6,8,17,18,6,5,6,8,17,18,6,5,11,11,5,0
0,6,0,0,0,0,0,19,0,0,0,0,0,6,7,7,11,0
5,5,16,0,0,0,0,17,0,0,0,0,13,5,0,0,12,0
0,6,0,0,0,0,0,11,0,0,0,0,0,6,0,0,0,0
0,6,0,0,0,0,13,5,16,0,0,0,0,6,0,0,5,0
0,6,0,0,0,0,0,6,0,0,0,0,0,6,0,0,19,0
0,6,0,0,0,0,0,6,0,0,0,0,0,6,0,0,0,0
5,5,16,0,0,0,0,6,0,0,0,0,13,5,0,0,11,0
0,6,0,14,0,0,0,6,0,0,0,14,0,6,0,0,5,0
0,5,6,5,6,6,6,5,8,17,18,5,6,5,20,20,20,20
0,0,0,6,0,0,0,15,0,0,0,6,0,0,0,0,0,0
0,0,0,6,0,0,0,0,0,0,0,6,0,0,0,0,0,0
0,0,0,6,0,14,0,0,0,14,0,6,0,0,0,0,0,0
0,0,0,5,6,5,6,12,6,5,6,5,0,0,0,0,0,0
0,0,0,0,0,5,0,0,0,5,0,0,0,0,0,0,0,0
:endlayer
layer: 6
0,0,0,5,0,0,0,5,0,0,0,5,0,0,0,0,0,0
0,5,10,10,10,10,10,10,10,10,10,10,10,5,0,0,0,0
0,9,17,17,17,17,17,9,17,17,17,17,17,9,0,0,0,0
5,9,6,6,6,6,6,9,6,6,6,6,6,9,0,0,0,0
0,9,17,17,17,17,17,9,17,17,17,17,17,9,10,10,5,0
0,9,6,6,6,6,6,9,6,6,6,6,6,9,17,17,8,0
0,9,17,17,17,17,17,9,17,17,17,17,17,9,17,17,8,0
0,9,6,6,6,6,6,9,6,6,6,6,6,9,11,11,8,0
5,9,10,10,10,10,10,10,10,10,10,10,10,9,7,7,5,0
0,9,6,6,6,6,6,9,6,6,6,6,6,9,0,0,12,0
5,9,17,17,17,17,17,9,17,17,17,17,17,9,0,0,0,0
0,9,6,6,6,6,6,9,6,6,6,6,6,9,0,0,11,0
0,9,17,17,17,17,17,9,17,17,17,17,17,9,20,20,20,20
0,9,6,6,6,6,6,9,6,6,6,6,6,9,0,0,9,0
0,9,17,17,17,17,17,9,17,17,17,17,17,9,0,13,9,0
5,9,6,6,6,6,6,9,6,6,6,6,6,9,0,0,9,0
0,9,17,17,17,17,17,9,17,17,17,17,17,9,20,20,20,20
0,5,10,10,10,10,10,10,10,10,10,10,10,5,0,0,0,0
0,0,20,9,17,6,17,6,17,6,17,9,20,0,0,0,0,0
0,0,20,9,17,6,17,6,17,6,17,9,20,0,0,0,0,0
0,0,20,9,17,6,17,6,17,6,17,9,20,0,0,0,0,0
0,0,20,5,6,5,6,6,6,5,6,5,20,0,0,0,0,0
0,0,20,0,0,5,0,0,0,5,0,0,20,0,0,0,0,0
:endlayer
layer: 7
0,0,0,5,0,0,0,5,0,0,0,5,0,0,0,0,0,0
0,5,6,5,6,6,6,5,6,6,6,5,6,5,0,0,0,0
0,6,0,0,0,0,0,6,0,0,18,21,0,6,0,0,0,0
5,5,0,0,0,0,0,0,0,0,0,0,0,5,0,0,0,0
0,6,0,0,0,0,0,0,0,0,0,0,0,6,12,12,5,0
0,6,0,0,0,0,0,0,0,0,0,0,0,0,0,0,12,0
0,6,0,0,0,0,0,0,0,0,0,0,0,0,0,0,12,0
0,6,0,0,0,0,0,6,0,0,0,0,0,6,0,0,12,0
5,5,6,0,0,0,6,5,6,0,0,0,6,5,0,0,5,0
0,6,0,0,0,0,0,6,0,0,0,0,0,6,0,0,0,0
5,5,0,0,0,0,0,5,0,0,0,0,0,5,0,0,11,0
0,6,0,0,0,0,0,0,0,0,0,0,0,6,20,20,20,20
0,6,0,0,0,0,0,0,0,0,0,0,0,6,0,0,0,0
0,6,0,0,0,0,0,0,0,0,0,0,0,6,20,20,20,20
0,6,0,0,0,0,0,0,0,0,0,0,0,6,0,0,6,0
5,5,0,0,0,0,0,5,0,0,0,0,0,5,20,20,20,20
0,6,0,0,0,0,0,6,0,0,0,0,0,6,0,0,0,0
0,5,6,5,8,0,0,5,0,0,18,5,6,5,0,0,0,0
0,0,0,20,0,0,0,0,0,0,0,20,0,0,0,0,0,0
0,0,0,20,0,0,0,0,0,0,0,20,0,0,0,0,0,0
0,0,0,20,0,0,0,0,0,0,0,20,0,0,0,0,0,0
0,0,0,20,10,10,10,10,10,10,10,20,0,0,0,0,0,0
0,0,0,20,0,5,0,0,0,5,0,20,0,0,0,0,0,0
:endlayer
layer: 8
0,0,0,5,0,0,0,5,0,0,0,5,0,0,0,0,0,0
0,5,6,5,6,12,6,5,6,6,6,5,6,5,0,0,0,0
0,6,0,0,0,0,0,6,16,18,21,0,0,6,0,0,0,0
5,5,0,0,0,0,0,0,0,0,0,0,0,5,0,0,0,0
0,6,0,0,0,0,0,0,0,0,0,0,0,6,0,0,5,0
0,12,0,0,0,0,0,0,0,0,0,0,0,0,0,0,0,0
0,12,0,0,0,0,0,0,0,0,0,0,0,0,0,0,0,0
0,6,0,0,0,0,0,6,0,0,0,0,0,6,0,0,0,0
5,5,6,0,0,0,6,5,6,0,0,0,6,5,0,0,5,0
0,6,0,0,0,0,0,6,0,0,0,0,0,6,0,0,11,0
5,5,0,0,0,0,0,5,0,0,0,0,0,5,20,20,20,20
0,6,0,0,0,0,0,0,0,0,0,0,0,6,0,0,0,0
0,12,0,0,0,0,0,0,0,0,0,0,0,12,0,0,0,0
0,12,0,0,0,0,0,0,0,0,0,0,0,12,0,22,0,0
0,6,0,0,0,0,0,0,0,0,0,0,0,6,20,20,20,20
5,5,0,0,0,0,0,5,0,0,0,0,0,5,0,22,0,0
0,6,0,0,0,0,0,6,0,0,0,0,0,6,0,0,0,0
0,5,6,5,6,8,0,5,0,18,6,5,6,5,0,0,0,0
0,0,0,0,20,0,0,0,0,0,20,0,0,0,0,0,0,0
0,0,0,0,20,0,0,0,0,0,20,0,0,0,0,0,0,0
0,0,0,0,20,0,0,0,0,0,20,0,0,0,0,0,0,0
0,0,0,0,20,6,6,6,6,6,20,0,0,0,0,0,0,0
0,0,0,0,20,5,19,19,19,5,20,0,0,0,0,0,0,0
:endlayer
layer: 9
0,0,0,5,0,0,0,5,0,0,0,5,0,0,0,0,0,0
0,5,6,5,6,6,6,5,6,6,6,5,6,5,0,0,0,0
0,6,0,15,0,0,13,6,18,21,0,15,0,6,0,0,0,0
5,5,16,0,0,0,0,19,0,0,0,0,13,5,20,20,20,20
0,6,0,0,0,0,0,17,0,0,0,0,0,6,0,0,5,0
0,6,0,0,0,0,0,17,0,0,0,0,0,6,0,0,19,0
0,6,0,0,0,0,0,11,0,0,0,0,0,6,0,0,0,0
0,6,0,0,0,0,13,6,16,0,0,0,0,6,0,0,11,0
5,5,6,8,17,18,6,5,6,8,17,18,6,5,0,0,5,0
0,6,0,0,0,0,0,6,0,0,0,0,0,6,20,20,20,20
5,5,16,0,0,0,13,5,16,0,0,0,13,5,0,22,0,0
0,6,0,0,0,0,0,19,0,0,0,0,0,6,0,0,0,0
0,6,0,0,0,0,0,0,0,0,0,0,0,6,0,0,0,0
0,6,0,0,0,0,0,0,0,0,0,0,0,6,0,0,0,0
0,6,0,0,0,0,0,11,0,0,0,0,0,6,0,0,0,0
5,5,16,0,0,0,13,5,16,0,0,0,13,5,0,0,0,0
0,6,0,14,0,0,0,6,0,0,0,14,0,6,0,0,0,0
0,5,6,5,6,6,8,5,18,6,6,5,6,5,0,0,0,0
0,0,0,0,0,20,0,15,0,20,0,0,0,0,0,0,0,0
0,0,0,0,0,20,0,0,0,20,0,0,0,0,0,0,0,0
0,0,0,0,22,20,0,14,0,20,22,0,0,0,0,0,0,0
0,0,0,0,0,20,6,6,6,20,0,0,0,0,0,0,0,0
0,0,0,0,0,20,10,10,10,20,0,0,0,0,0,0,0,0
:endlayer
layer: 10
20,0,0,5,0,0,0,5,0,0,0,5,0,0,20,0,0,0
20,5,10,10,10,10,10,10,10,10,10,10,10,5,20,0,0,0
20,9,17,17,17,17,17,9,21,0,0,0,0,9,20,0,0,0
20,9,6,6,6,6,6,9,6,6,6,6,6,9,20,0,0,0
20,9,17,17,17,17,17,9,17,17,17,17,17,9,20,20,20,20
20,9,6,6,6,6,6,9,6,6,6,6,6,9,0,0,9,0
20,9,17,17,17,17,17,9,17,17,17,17,17,9,0,13,9,0
20,9,6,6,6,6,6,9,6,6,6,6,6,9,0,0,9,0
20,9,10,10,10,10,10,9,10,10,10,10,10,9,20,20,20,20
20,9,6,6,6,6,6,9,6,6,6,6,6,9,20,0,0,0
20,9,17,17,17,17,17,9,17,17,17,17,17,9,20,0,0,0
20,9,6,6,6,6,6,9,6,6,6,6,6,9,20,0,0,0
20,9,17,17,17,17,17,9,17,17,17,17,17,9,20,0,0,0
20,9,6,6,6,6,6,9,6,6,6,6,6,9,20,0,0,0
20,9,17,17,17,17,17,9,17,17,17,17,17,9,20,0,0,0
20,9,6,6,6,6,6,9,6,6,6,6,6,9,20,0,0,0
20,9,17,17,17,17,17,9,17,17,17,17,17,9,20,0,0,0
20,5,10,10,10,10,10,10,10,10,10,10,10,5,20,0,0,0
20,0,0,0,0,0,20,0,20,0,0,0,0,0,20,0,0,0
0,0,0,0,0,0,20,0,20,0,0,0,0,0,0,0,0,0
0,0,0,0,0,0,20,0,20,0,0,0,0,0,0,0,0,0
0,0,0,0,0,0,20,6,20,0,0,0,0,0,0,0,0,0
0,0,0,0,0,0,20,12,20,0,0,0,0,0,0,0,0,0
:endlayer
layer: 11
0,20,0,5,0,0,0,5,0,0,0,5,0,20,0,0,0,0
0,20,6,6,6,6,6,5,6,6,6,6,6,20,0,0,0,0
0,20,0,0,0,0,0,0,0,0,0,0,0,20,0,0,0,0
0,20,0,0,0,0,0,0,0,12,12,12,12,20,0,0,0,0
0,20,0,0,0,0,0,0,0,0,0,0,0,20,0,0,0,0
0,20,0,0,0,0,0,0,0,0,0,0,0,20,20,20,20,20
0,20,0,0,0,0,0,0,0,0,0,0,0,20,8,0,6,0
0,20,0,0,0,0,0,0,0,0,0,0,0,20,20,20,20,20
0,20,6,6,6,5,0,0,0,5,6,6,6,20,0,0,0,0
0,20,0,0,0,0,0,0,0,0,0,0,0,20,0,0,0,0
0,20,0,0,0,0,0,0,0,0,0,0,0,20,0,0,0,0
0,20,0,0,0,0,0,0,0,0,0,0,0,20,0,0,0,0
0,20,0,0,0,0,0,0,0,0,0,0,0,20,0,0,0,0
0,20,0,0,0,0,0,0,0,0,0,0,0,20,0,0,0,0
0,20,0,0,0,0,0,0,0,0,0,0,0,20,0,0,0,0
0,20,0,0,0,0,0,0,0,0,0,0,0,20,0,0,0,0
0,20,0,0,0,0,0,0,0,0,0,0,0,20,0,0,0,0
0,20,6,6,6,5,6,6,6,5,6,6,6,20,0,0,0,0
0,20,0,0,0,0,0,20,0,0,0,0,0,20,0,0,0,0
0,0,0,0,0,0,0,20,0,0,0,0,0,0,0,0,0,0
0,0,0,0,0,0,0,20,0,0,0,0,0,0,0,0,0,0
0,0,0,0,0,0,0,20,0,0,0,0,0,0,0,0,0,0
0,0,0,0,0,0,0,20,0,0,0,0,0,0,0,0,0,0
:endlayer
layer: 12
0,0,20,5,0,0,0,5,0,0,0,5,20,0,0,0,0,0
0,0,20,6,6,12,6,5,6,12,6,6,20,0,0,0,0,0
0,0,20,0,0,0,0,0,0,0,0,0,20,0,0,0,0,0
0,0,20,0,0,0,0,0,0,0,0,0,20,0,0,0,0,0
0,0,20,0,0,0,0,0,0,0,0,0,20,0,0,0,0,0
0,0,20,16,0,0,0,0,0,0,0,13,20,0,0,22,0,0
0,0,20,0,0,0,0,0,0,0,0,0,20,20,20,20,20,20
0,0,20,0,0,0,0,0,0,0,0,0,20,0,0,22,0,0
0,0,20,6,6,5,0,0,0,5,6,6,20,0,0,0,0,0
0,0,20,0,0,0,0,0,0,0,0,0,20,0,0,0,0,0
0,0,20,0,0,0,0,0,0,0,0,0,20,0,0,0,0,0
0,0,20,0,0,0,0,0,0,0,0,0,20,0,0,0,0,0
0,0,20,0,0,0,0,0,0,0,0,0,20,0,0,0,0,0
0,0,20,16,0,0,0,0,0,0,0,13,20,0,0,0,0,0
0,0,20,0,0,0,0,0,0,0,0,0,20,0,0,0,0,0
0,0,20,0,0,0,0,0,0,0,0,0,20,0,0,0,0,0
0,0,20,0,0,0,0,0,0,0,0,0,20,0,0,0,0,0
0,0,20,6,6,5,6,12,6,5,6,6,20,0,0,0,0,0
0,0,20,0,0,0,0,0,0,0,0,0,20,0,0,0,0,0
0,0,0,0,0,0,0,0,0,0,0,0,0,0,0,0,0,0
0,0,0,0,0,0,0,22,0,0,0,0,0,0,0,0,0,0
0,0,0,0,0,0,0,0,0,0,0,0,0,0,0,0,0,0
0,0,0,0,0,0,0,0,0,0,0,0,0,0,0,0,0,0
:endlayer
layer: 13
0,0,0,20,8,0,0,5,0,0,18,20,0,0,0,0,0,0
0,0,0,20,6,6,6,5,6,6,6,20,0,0,0,0,0,0
0,0,22,20,0,0,0,15,0,0,0,20,22,0,0,0,0,0
0,0,0,20,0,0,0,0,0,0,0,20,0,0,0,0,0,0
0,0,0,20,0,0,0,0,0,0,0,20,0,0,0,0,0,0
0,0,0,20,0,0,0,0,0,0,0,20,0,0,0,0,0,0
0,0,0,20,0,0,0,0,0,0,0,20,0,0,0,0,0,0
0,0,22,20,0,14,0,0,0,14,0,20,22,0,0,0,0,0
0,0,0,20,6,5,0,0,0,5,6,20,0,0,0,0,0,0
0,0,0,20,0,15,0,0,0,15,0,20,0,0,0,0,0,0
0,0,0,20,0,0,0,0,0,0,0,20,0,0,0,0,0,0
0,0,22,20,0,0,0,0,0,0,0,20,22,0,0,0,0,0
0,0,0,20,0,0,0,0,0,0,0,20,0,0,0,0,0,0
0,0,0,20,0,0,0,0,0,0,0,20,0,0,0,0,0,0
0,0,0,20,0,0,0,0,0,0,0,20,0,0,0,0,0,0
0,0,0,20,0,0,0,0,0,0,0,20,0,0,0,0,0,0
0,0,22,20,0,14,0,0,0,14,0,20,22,0,0,0,0,0
0,0,0,20,6,5,6,12,6,5,6,20,0,0,0,0,0,0
0,0,0,20,0,0,0,0,0,0,0,20,0,0,0,0,0,0
0,0,0,0,0,0,0,0,0,0,0,0,0,0,0,0,0,0
0,0,0,0,0,0,0,0,0,0,0,0,0,0,0,0,0,0
0,0,0,0,0,0,0,0,0,0,0,0,0,0,0,0,0,0
0,0,0,0,0,0,0,0,0,0,0,0,0,0,0,0,0,0
:endlayer
layer: 14
0,0,0,0,20,8,0,5,0,18,20,0,0,0,0,0,0,0
0,0,0,0,20,10,10,10,10,10,20,0,0,0,0,0,0,0
0,0,0,0,20,0,0,0,0,0,20,0,0,0,0,0,0,0
0,0,0,0,20,0,0,0,0,0,20,0,0,0,0,0,0,0
0,0,0,0,20,0,0,0,0,0,20,0,0,0,0,0,0,0
0,0,0,0,20,0,0,0,0,0,20,0,0,0,0,0,0,0
0,0,0,0,20,0,0,0,0,0,20,0,0,0,0,0,0,0
0,0,0,0,20,0,0,0,0,0,20,0,0,0,0,0,0,0
0,0,0,0,20,5,8,17,18,5,20,0,0,0,0,0,0,0
0,0,0,0,20,0,0,0,0,0,20,0,0,0,0,0,0,0
0,0,0,0,20,0,0,0,0,0,20,0,0,0,0,0,0,0
0,0,0,0,20,0,0,0,0,0,20,0,0,0,0,0,0,0
0,0,0,0,20,0,0,0,0,0,20,0,0,0,0,0,0,0
0,0,0,0,20,0,0,0,0,0,20,0,0,0,0,0,0,0
0,0,0,0,20,0,0,0,0,0,20,0,0,0,0,0,0,0
0,0,0,0,20,0,0,0,0,0,20,0,0,0,0,0,0,0
0,0,0,0,20,0,0,0,0,0,20,0,0,0,0,0,0,0
0,0,0,0,20,5,6,6,6,5,20,0,0,0,0,0,0,0
0,0,0,0,20,0,0,0,0,0,20,0,0,0,0,0,0,0
0,0,0,0,0,0,0,0,0,0,0,0,0,0,0,0,0,0
0,0,0,0,0,0,0,0,0,0,0,0,0,0,0,0,0,0
0,0,0,0,0,0,0,0,0,0,0,0,0,0,0,0,0,0
0,0,0,0,0,0,0,0,0,0,0,0,0,0,0,0,0,0
:endlayer
layer: 15
0,0,0,0,0,20,8,5,18,20,0,0,0,0,0,0,0,0
0,0,0,0,0,20,6,6,6,20,0,0,0,0,0,0,0,0
0,0,0,0,0,20,0,0,0,20,0,0,0,0,0,0,0,0
0,0,0,0,0,20,0,0,0,20,0,0,0,0,0,0,0,0
0,0,0,0,0,20,0,0,0,20,0,0,0,0,0,0,0,0
0,0,0,0,0,20,0,0,0,20,0,0,0,0,0,0,0,0
0,0,0,0,0,20,0,0,0,20,0,0,0,0,0,0,0,0
0,0,0,0,0,20,0,0,0,20,0,0,0,0,0,0,0,0
0,0,0,0,0,20,10,10,10,20,0,0,0,0,0,0,0,0
0,0,0,0,0,20,0,0,0,20,0,0,0,0,0,0,0,0
0,0,0,0,0,20,0,0,0,20,0,0,0,0,0,0,0,0
0,0,0,0,0,20,0,0,0,20,0,0,0,0,0,0,0,0
0,0,0,0,0,20,0,0,0,20,0,0,0,0,0,0,0,0
0,0,0,0,0,20,0,0,0,20,0,0,0,0,0,0,0,0
0,0,0,0,0,20,0,0,0,20,0,0,0,0,0,0,0,0
0,0,0,0,0,20,0,0,0,20,0,0,0,0,0,0,0,0
0,0,0,0,0,20,0,0,0,20,0,0,0,0,0,0,0,0
0,0,0,0,0,20,10,10,10,20,0,0,0,0,0,0,0,0
0,0,0,0,0,20,0,0,0,20,0,0,0,0,0,0,0,0
0,0,0,0,0,0,0,0,0,0,0,0,0,0,0,0,0,0
0,0,0,0,0,0,0,0,0,0,0,0,0,0,0,0,0,0
0,0,0,0,0,0,0,0,0,0,0,0,0,0,0,0,0,0
0,0,0,0,0,0,0,0,0,0,0,0,0,0,0,0,0,0
:endlayer
layer: 16
0,0,0,0,0,0,20,5,20,0,0,0,0,0,0,0,0,0
0,0,0,0,0,0,20,6,20,0,0,0,0,0,0,0,0,0
0,0,0,0,0,22,20,0,20,22,0,0,0,0,0,0,0,0
0,0,0,0,0,0,20,0,20,0,0,0,0,0,0,0,0,0
0,0,0,0,0,0,20,0,20,0,0,0,0,0,0,0,0,0
0,0,0,0,0,0,20,0,20,0,0,0,0,0,0,0,0,0
0,0,0,0,0,0,20,0,20,0,0,0,0,0,0,0,0,0
0,0,0,0,0,22,20,0,20,22,0,0,0,0,0,0,0,0
0,0,0,0,0,0,20,6,20,0,0,0,0,0,0,0,0,0
0,0,0,0,0,0,20,0,20,0,0,0,0,0,0,0,0,0
0,0,0,0,0,0,20,0,20,0,0,0,0,0,0,0,0,0
0,0,0,0,0,22,20,0,20,22,0,0,0,0,0,0,0,0
0,0,0,0,0,0,20,0,20,0,0,0,0,0,0,0,0,0
0,0,0,0,0,0,20,0,20,0,0,0,0,0,0,0,0,0
0,0,0,0,0,0,20,0,20,0,0,0,0,0,0,0,0,0
0,0,0,0,0,0,20,0,20,0,0,0,0,0,0,0,0,0
0,0,0,0,0,22,20,0,20,22,0,0,0,0,0,0,0,0
0,0,0,0,0,0,20,6,20,0,0,0,0,0,0,0,0,0
0,0,0,0,0,0,20,0,20,0,0,0,0,0,0,0,0,0
0,0,0,0,0,0,0,0,0,0,0,0,0,0,0,0,0,0
0,0,0,0,0,0,0,0,0,0,0,0,0,0,0,0,0,0
0,0,0,0,0,0,0,0,0,0,0,0,0,0,0,0,0,0
0,0,0,0,0,0,0,0,0,0,0,0,0,0,0,0,0,0
:endlayer
layer: 17
0,0,0,0,0,0,0,20,0,0,0,0,0,0,0,0,0,0
0,0,0,0,0,0,0,20,0,0,0,0,0,0,0,0,0,0
0,0,0,0,0,0,0,20,0,0,0,0,0,0,0,0,0,0
0,0,0,0,0,0,0,20,0,0,0,0,0,0,0,0,0,0
0,0,0,0,0,0,0,20,0,0,0,0,0,0,0,0,0,0
0,0,0,0,0,0,0,20,0,0,0,0,0,0,0,0,0,0
0,0,0,0,0,0,0,20,0,0,0,0,0,0,0,0,0,0
0,0,0,0,0,0,0,20,0,0,0,0,0,0,0,0,0,0
0,0,0,0,0,0,0,20,0,0,0,0,0,0,0,0,0,0
0,0,0,0,0,0,0,20,0,0,0,0,0,0,0,0,0,0
0,0,0,0,0,0,0,20,0,0,0,0,0,0,0,0,0,0
0,0,0,0,0,0,0,20,0,0,0,0,0,0,0,0,0,0
0,0,0,0,0,0,0,20,0,0,0,0,0,0,0,0,0,0
0,0,0,0,0,0,0,20,0,0,0,0,0,0,0,0,0,0
0,0,0,0,0,0,0,20,0,0,0,0,0,0,0,0,0,0
0,0,0,0,0,0,0,20,0,0,0,0,0,0,0,0,0,0
0,0,0,0,0,0,0,20,0,0,0,0,0,0,0,0,0,0
0,0,0,0,0,0,0,20,0,0,0,0,0,0,0,0,0,0
0,0,0,0,0,0,0,20,0,0,0,0,0,0,0,0,0,0
0,0,0,0,0,0,0,0,0,0,0,0,0,0,0,0,0,0
0,0,0,0,0,0,0,0,0,0,0,0,0,0,0,0,0,0
0,0,0,0,0,0,0,0,0,0,0,0,0,0,0,0,0,0
0,0,0,0,0,0,0,0,0,0,0,0,0,0,0,0,0,0
:endlayer

#### RULES ####
rule:
plugin=vanillaBlocks
number=1
data:
JSON:{blockState:{blockName:"minecraft:grass",properties:{snowy:"false"}}}
:enddata
:endrule

rule:
plugin=vanillaBlocks
number=2
data:
JSON:{blockState:{blockName:"minecraft:cobblestone"}}
:enddata
:endrule

rule:
plugin=vanillaBlocks
number=3
data:
JSON:{blockState:{blockName:"minecraft:dirt",properties:{variant:"dirt",snowy:"false"}}}
:enddata
:endrule

rule:
plugin=vanillaBlocks
number=4
data:
JSON:{blockState:{blockName:"minecraft:stonebrick",properties:{variant:"stonebrick"}}}
:enddata
:endrule

rule:
plugin=vanillaBlocks
number=5
data:
JSON:{blockState:{blockName:"biomesoplenty:log_0",properties:{variant:"cherry",axis:"y"}}}
:enddata
:endrule

rule:
plugin=vanillaBlocks
number=6
data:
JSON:{blockState:{blockName:"biomesoplenty:planks_0",properties:{variant:"cherry"}}}
:enddata
:endrule

rule:
plugin=vanillaBlocks
number=7
data:
JSON:{blockState:{blockName:"biomesoplenty:cherry_stairs",properties:{half:"bottom",shape:"straight",facing:"north"}}}
:enddata
:endrule

rule:
plugin=vanillaBlocks
number=8
data:
JSON:{blockState:{blockName:"biomesoplenty:cherry_stairs",properties:{half:"top",shape:"straight",facing:"west"}}}
:enddata
:endrule

rule:
plugin=vanillaBlocks
number=9
data:
JSON:{blockState:{blockName:"biomesoplenty:log_0",properties:{variant:"cherry",axis:"z"}}}
:enddata
:endrule

rule:
plugin=vanillaBlocks
number=10
data:
JSON:{blockState:{blockName:"biomesoplenty:log_0",properties:{variant:"cherry",axis:"x"}}}
:enddata
:endrule

rule:
plugin=vanillaBlocks
number=11
data:
JSON:{blockState:{blockName:"biomesoplenty:cherry_stairs",properties:{half:"top",shape:"straight",facing:"south"}}}
:enddata
:endrule

rule:
plugin=vanillaBlocks
number=12
data:
JSON:{blockState:{blockName:"biomesoplenty:cherry_fence",properties:{east:"false",south:"false",north:"false",west:"false"}}}
:enddata
:endrule

rule:
plugin=vanillaBlocks
number=13
data:
JSON:{blockState:{blockName:"minecraft:torch",properties:{facing:"west"}}}
:enddata
:endrule

rule:
plugin=vanillaBlocks
number=14
data:
JSON:{blockState:{blockName:"minecraft:torch",properties:{facing:"north"}}}
:enddata
:endrule

rule:
plugin=vanillaBlocks
number=15
data:
JSON:{blockState:{blockName:"minecraft:torch",properties:{facing:"south"}}}
:enddata
:endrule

rule:
plugin=vanillaBlocks
number=16
data:
JSON:{blockState:{blockName:"minecraft:torch",properties:{facing:"east"}}}
:enddata
:endrule

rule:
plugin=vanillaBlocks
number=17
data:
JSON:{blockState:{blockName:"biomesoplenty:wood_slab_0",properties:{half:"top",variant:"cherry"}}}
:enddata
:endrule

rule:
plugin=vanillaBlocks
number=18
data:
JSON:{blockState:{blockName:"biomesoplenty:cherry_stairs",properties:{half:"top",shape:"straight",facing:"east"}}}
:enddata
:endrule

rule:
plugin=vanillaBlocks
number=19
data:
JSON:{blockState:{blockName:"biomesoplenty:cherry_stairs",properties:{half:"top",shape:"straight",facing:"north"}}}
:enddata
:endrule

rule:
plugin=vanillaBlocks
number=20
data:
JSON:{blockState:{blockName:"minecraft:wool",properties:{color:"brown"}}}
:enddata
:endrule

rule:
plugin=vanillaBlocks
number=21
data:
JSON:{blockState:{blockName:"biomesoplenty:cherry_stairs",properties:{half:"bottom",shape:"straight",facing:"west"}}}
:enddata
:endrule

rule:
plugin=vanillaBlocks
number=22
data:
JSON:{blockState:{blockName:"minecraft:torch",properties:{facing:"up"}}}
:enddata
:endrule

#### ENTITIES ####
