# Ancient Warfare Structure Template File
# Auto-generated structure template file. created on: 9/23/2023 at: 0:42:46
# Lines beginning with # denote comments

header:
version=2.11
name=SB_KieavarusCol_House_1H3R_1_jacaranda
mods=biomesoplenty
size=17,13,11
offset=1,1,10
:endheader

#### VALIDATION ####
validation:
type=ground
structureAuthor=TheOddlySeagull
survival=true
worldGenEnabled=false
unique=false
preserveBlocks=false
preventNaturalHostileSpawns=false
selectionWeight=1
clusterValue=1
minDuplicateDistance=1
dimensionWhiteList=true
dimensionList=
biomeGroupList=
biomeWhiteList=true
biomeList=
leveling=0
fill=0
border=0
blockSwap=false
territoryName=
biomeReplacement=minecraft:
minGenerationHeight=0
maxGenerationHeight=255
:endvalidation

#### LAYERS ####
layer: 0
1,1,1,1,1,1,1,2,1,1,1,2,1,1,1,1,1
1,1,1,2,2,2,2,2,2,2,2,2,2,2,2,2,1
2,1,1,2,2,3,3,2,2,2,2,2,3,3,3,2,1
1,1,1,2,2,3,2,2,2,2,2,3,3,2,3,2,1
1,1,1,2,2,3,2,2,2,2,3,2,3,3,3,2,1
1,1,1,2,2,2,3,3,3,3,2,3,3,2,3,2,1
1,1,1,2,3,2,3,3,3,2,3,2,2,2,3,2,1
1,1,1,2,3,3,3,3,2,2,3,2,3,3,2,2,1
2,2,2,2,3,3,3,3,2,2,2,2,2,3,2,2,1
4,2,2,2,2,2,2,2,2,2,2,2,2,2,2,2,1
4,2,2,4,1,1,1,2,1,1,1,2,1,1,1,1,1
:endlayer
layer: 1
0,0,0,0,0,0,0,5,0,0,0,5,0,0,0,0,0
0,0,0,5,6,6,6,5,6,6,6,5,6,6,6,5,0
5,0,0,6,2,2,3,3,2,3,2,2,2,3,2,6,0
0,0,0,6,3,2,3,2,3,2,3,2,3,2,2,6,0
0,0,0,6,2,3,2,3,3,3,3,2,3,2,3,6,0
0,0,7,5,2,3,3,2,2,2,2,2,3,2,2,5,0
0,0,0,6,3,2,2,2,3,3,2,3,2,2,3,6,0
0,0,0,6,3,2,3,3,2,2,3,3,3,2,2,6,0
5,8,8,6,2,3,3,3,3,2,3,2,3,3,3,6,0
0,9,9,5,6,6,6,5,6,6,6,5,6,6,6,5,0
0,0,0,0,0,0,0,5,0,0,0,5,0,0,0,0,0
:endlayer
layer: 2
0,0,0,0,0,0,0,5,0,0,0,5,0,0,0,0,0
0,0,0,5,11,11,11,11,11,11,11,11,11,11,11,5,0
5,14,12,10,6,6,6,6,6,6,6,10,6,6,6,10,0
15,13,13,10,6,6,6,6,6,6,6,10,6,6,6,10,0
13,13,13,10,6,6,6,6,6,6,6,10,6,6,6,10,0
13,13,13,5,6,6,6,6,6,6,6,10,11,11,11,10,0
13,13,13,10,6,6,6,6,6,6,6,10,6,6,6,10,0
8,8,8,10,6,6,6,6,6,6,6,10,6,6,6,10,0
5,9,9,10,6,6,6,6,6,6,6,10,6,6,6,10,0
0,0,0,5,11,11,11,11,11,11,11,11,11,11,11,5,0
0,0,0,0,0,0,0,5,0,0,0,5,0,0,0,0,0
:endlayer
layer: 3
0,0,0,17,0,0,0,5,0,17,0,5,0,0,0,17,0
0,0,7,5,6,6,6,5,6,6,6,5,6,6,6,5,16
5,20,20,6,0,0,0,0,0,0,0,6,0,0,0,6,0
20,0,0,0,0,0,0,0,0,0,0,0,0,0,0,6,0
20,0,0,6,19,0,0,0,0,0,0,6,0,0,0,6,0
20,0,0,5,15,0,0,0,0,0,0,5,6,6,6,5,16
20,0,0,6,0,0,0,0,0,0,0,6,0,0,0,6,0
20,0,0,6,0,0,0,0,0,0,0,0,0,0,0,6,0
5,0,0,6,0,0,0,0,0,0,0,6,0,0,0,6,0
0,0,7,5,6,6,6,5,6,6,6,5,6,6,6,5,16
0,0,0,18,0,0,0,5,0,18,0,5,0,0,0,18,0
:endlayer
layer: 4
0,0,0,0,0,0,0,5,0,0,0,5,0,0,0,0,0
0,0,0,5,6,20,6,5,6,20,6,5,6,20,6,5,0
20,0,0,6,0,0,0,0,0,0,0,6,0,0,0,6,0
0,0,0,0,0,0,0,0,0,0,0,0,0,0,0,20,0
0,0,0,6,0,0,0,0,0,0,0,6,0,0,0,6,0
0,0,0,5,19,0,0,0,0,0,0,5,6,6,6,5,0
0,0,0,6,15,0,0,0,0,0,0,6,0,0,0,6,0
0,0,0,20,0,0,0,0,0,0,0,0,0,0,0,20,0
20,0,0,6,0,0,0,0,0,0,0,6,0,0,0,6,0
0,0,0,5,6,20,6,5,6,20,6,5,6,20,6,5,0
0,0,0,0,0,0,0,5,0,0,0,5,0,0,0,0,0
:endlayer
layer: 5
0,0,0,0,0,0,0,5,0,0,0,5,0,0,0,0,0
0,0,0,5,6,6,6,5,6,6,6,5,6,6,6,5,0
21,0,0,6,0,0,0,18,0,0,0,6,0,0,0,6,0
21,0,0,6,0,0,0,0,0,0,0,6,0,0,7,6,0
21,0,0,6,0,0,0,0,0,0,0,6,0,0,0,6,0
21,0,7,5,16,0,0,0,0,0,7,5,6,6,6,5,0
21,0,0,6,19,0,0,0,0,0,0,6,0,0,0,6,0
21,0,0,6,15,0,0,0,0,0,0,6,0,0,7,6,0
21,0,0,6,0,0,0,17,0,0,0,6,0,0,0,6,0
0,0,0,5,6,6,6,5,6,6,6,5,6,6,6,5,0
0,0,0,0,0,0,0,5,0,0,0,5,0,0,0,0,0
:endlayer
layer: 6
0,0,21,21,21,21,21,21,21,21,21,21,21,21,21,21,21
0,0,0,5,11,11,11,11,11,11,11,11,11,11,11,5,0
0,21,21,10,0,6,13,6,13,6,13,10,13,6,13,10,0
0,21,21,10,0,6,13,6,13,6,13,10,13,6,13,10,0
0,21,21,10,0,6,13,6,13,6,13,10,13,6,13,10,0
0,21,21,10,0,6,13,6,13,6,13,10,11,11,11,10,0
0,21,21,10,0,6,13,6,13,6,13,10,13,6,13,10,0
0,21,21,10,19,6,13,6,13,6,13,10,13,6,13,10,0
0,21,21,10,15,6,13,6,13,6,13,10,13,6,13,10,0
0,0,0,5,11,11,11,11,11,11,11,11,11,11,11,5,0
0,0,21,21,21,21,21,21,21,21,21,21,21,21,21,21,21
:endlayer
layer: 7
0,0,0,0,0,0,0,0,0,0,0,0,0,0,0,0,0
0,0,21,21,21,21,21,21,21,21,21,21,21,21,21,21,21
0,0,0,6,0,20,0,0,0,0,0,0,0,0,0,6,0
0,0,7,5,0,20,0,0,0,0,0,0,0,0,0,5,0
0,0,0,6,0,20,0,0,0,0,0,0,0,0,0,6,0
0,0,0,6,0,20,0,0,0,22,0,0,0,0,0,6,0
0,0,0,6,0,0,0,0,0,0,0,0,0,0,0,6,0
0,0,7,5,0,0,0,0,0,0,0,0,0,0,0,5,0
0,0,0,6,0,0,0,0,0,0,0,0,0,0,0,6,0
0,0,21,21,21,21,21,21,21,21,21,21,21,21,21,21,21
0,0,0,0,0,0,0,0,0,0,0,0,0,0,0,0,0
:endlayer
layer: 8
0,0,0,0,0,0,0,0,0,0,0,0,0,0,0,0,0
0,0,0,0,0,0,0,0,0,0,0,0,0,0,0,0,0
0,0,21,21,21,21,21,21,21,21,21,21,21,21,21,21,21
0,0,0,5,0,0,0,0,0,0,0,0,0,0,0,5,0
0,0,0,6,0,0,0,0,0,0,0,0,0,0,0,6,0
0,0,0,20,0,0,0,0,0,0,0,0,0,0,0,20,0
0,0,0,6,0,0,0,0,0,0,0,0,0,0,0,6,0
0,0,0,5,0,0,0,0,0,0,0,0,0,0,0,5,0
0,0,21,21,21,21,21,21,21,21,21,21,21,21,21,21,21
0,0,0,0,0,0,0,0,0,0,0,0,0,0,0,0,0
0,0,0,0,0,0,0,0,0,0,0,0,0,0,0,0,0
:endlayer
layer: 9
0,0,0,0,0,0,0,0,0,0,0,0,0,0,0,0,0
0,0,0,0,0,0,0,0,0,0,0,0,0,0,0,0,0
0,0,0,0,22,0,0,0,0,22,0,0,0,0,22,0,0
0,0,21,21,21,21,21,21,21,21,21,21,21,21,21,21,21
0,0,0,10,0,0,0,0,0,0,0,0,0,0,0,10,0
0,0,0,10,16,0,0,0,0,0,0,0,0,0,7,10,0
0,0,0,10,0,0,0,0,0,0,0,0,0,0,0,10,0
0,0,21,21,21,21,21,21,21,21,21,21,21,21,21,21,21
0,0,0,0,22,0,0,0,0,22,0,0,0,0,22,0,0
0,0,0,0,0,0,0,0,0,0,0,0,0,0,0,0,0
0,0,0,0,0,0,0,0,0,0,0,0,0,0,0,0,0
:endlayer
layer: 10
0,0,0,0,0,0,0,0,0,0,0,0,0,0,0,0,0
0,0,0,0,0,0,0,0,0,0,0,0,0,0,0,0,0
0,0,0,0,0,0,0,0,0,0,0,0,0,0,0,0,0
0,0,0,0,0,0,0,0,0,0,0,0,0,0,0,0,0
0,0,21,21,21,21,21,21,21,21,21,21,21,21,21,21,21
0,0,0,6,0,0,0,0,0,0,0,0,0,0,0,6,0
0,0,21,21,21,21,21,21,21,21,21,21,21,21,21,21,21
0,0,0,0,0,0,0,0,0,0,0,0,0,0,0,0,0
0,0,0,0,0,0,0,0,0,0,0,0,0,0,0,0,0
0,0,0,0,0,0,0,0,0,0,0,0,0,0,0,0,0
0,0,0,0,0,0,0,0,0,0,0,0,0,0,0,0,0
:endlayer
layer: 11
0,0,0,0,0,0,0,0,0,0,0,0,0,0,0,0,0
0,0,0,0,0,0,0,0,0,0,0,0,0,0,0,0,0
0,0,0,0,0,0,0,0,0,0,0,0,0,0,0,0,0
0,0,0,0,0,0,0,0,0,0,0,0,0,0,0,0,0
0,0,0,0,0,0,0,0,0,0,0,0,0,0,0,0,0
0,0,21,21,21,21,21,21,21,21,21,21,21,21,21,21,21
0,0,0,0,0,0,0,0,0,0,0,0,0,0,0,0,0
0,0,0,0,0,0,0,0,0,0,0,0,0,0,0,0,0
0,0,0,0,0,0,0,0,0,0,0,0,0,0,0,0,0
0,0,0,0,0,0,0,0,0,0,0,0,0,0,0,0,0
0,0,0,0,0,0,0,0,0,0,0,0,0,0,0,0,0
:endlayer
layer: 12
0,0,0,0,0,0,0,0,0,0,0,0,0,0,0,0,0
0,0,0,0,0,0,0,0,0,0,0,0,0,0,0,0,0
0,0,0,0,0,0,0,0,0,0,0,0,0,0,0,0,0
0,0,0,0,0,0,0,0,0,0,0,0,0,0,0,0,0
0,0,0,0,0,0,0,0,0,0,0,0,0,0,0,0,0
0,0,0,0,22,0,0,0,0,22,0,0,0,0,22,0,0
0,0,0,0,0,0,0,0,0,0,0,0,0,0,0,0,0
0,0,0,0,0,0,0,0,0,0,0,0,0,0,0,0,0
0,0,0,0,0,0,0,0,0,0,0,0,0,0,0,0,0
0,0,0,0,0,0,0,0,0,0,0,0,0,0,0,0,0
0,0,0,0,0,0,0,0,0,0,0,0,0,0,0,0,0
:endlayer

#### RULES ####
rule:
plugin=vanillaBlocks
number=1
data:
JSON:{blockState:{blockName:"minecraft:grass",properties:{snowy:"false"}}}
:enddata
:endrule

rule:
plugin=vanillaBlocks
number=2
data:
JSON:{blockState:{blockName:"minecraft:cobblestone"}}
:enddata
:endrule

rule:
plugin=vanillaBlocks
number=3
data:
JSON:{blockState:{blockName:"minecraft:dirt",properties:{variant:"dirt",snowy:"false"}}}
:enddata
:endrule

rule:
plugin=vanillaBlocks
number=4
data:
JSON:{blockState:{blockName:"minecraft:stonebrick",properties:{variant:"stonebrick"}}}
:enddata
:endrule

rule:
plugin=vanillaBlocks
number=5
data:
JSON:{blockState:{blockName:"biomesoplenty:log_3",properties:{variant:"jacaranda",axis:"y"}}}
:enddata
:endrule

rule:
plugin=vanillaBlocks
number=6
data:
JSON:{blockState:{blockName:"biomesoplenty:planks_0",properties:{variant:"jacaranda"}}}
:enddata
:endrule

rule:
plugin=vanillaBlocks
number=7
data:
JSON:{blockState:{blockName:"minecraft:torch",properties:{facing:"west"}}}
:enddata
:endrule

rule:
plugin=vanillaBlocks
number=8
data:
JSON:{blockState:{blockName:"biomesoplenty:jacaranda_stairs",properties:{half:"top",shape:"straight",facing:"south"}}}
:enddata
:endrule

rule:
plugin=vanillaBlocks
number=9
data:
JSON:{blockState:{blockName:"biomesoplenty:jacaranda_stairs",properties:{half:"bottom",shape:"straight",facing:"north"}}}
:enddata
:endrule

rule:
plugin=vanillaBlocks
number=10
data:
JSON:{blockState:{blockName:"biomesoplenty:log_3",properties:{variant:"jacaranda",axis:"z"}}}
:enddata
:endrule

rule:
plugin=vanillaBlocks
number=11
data:
JSON:{blockState:{blockName:"biomesoplenty:log_3",properties:{variant:"jacaranda",axis:"x"}}}
:enddata
:endrule

rule:
plugin=vanillaBlocks
number=12
data:
JSON:{blockState:{blockName:"biomesoplenty:jacaranda_stairs",properties:{half:"top",shape:"straight",facing:"east"}}}
:enddata
:endrule

rule:
plugin=vanillaBlocks
number=13
data:
JSON:{blockState:{blockName:"biomesoplenty:wood_slab_1",properties:{half:"top",variant:"jacaranda"}}}
:enddata
:endrule

rule:
plugin=vanillaBlocks
number=14
data:
JSON:{blockState:{blockName:"biomesoplenty:jacaranda_stairs",properties:{half:"top",shape:"straight",facing:"west"}}}
:enddata
:endrule

rule:
plugin=vanillaBlocks
number=15
data:
JSON:{blockState:{blockName:"biomesoplenty:jacaranda_stairs",properties:{half:"top",shape:"straight",facing:"north"}}}
:enddata
:endrule

rule:
plugin=vanillaBlocks
number=16
data:
JSON:{blockState:{blockName:"minecraft:torch",properties:{facing:"east"}}}
:enddata
:endrule

rule:
plugin=vanillaBlocks
number=17
data:
JSON:{blockState:{blockName:"minecraft:torch",properties:{facing:"north"}}}
:enddata
:endrule

rule:
plugin=vanillaBlocks
number=18
data:
JSON:{blockState:{blockName:"minecraft:torch",properties:{facing:"south"}}}
:enddata
:endrule

rule:
plugin=vanillaBlocks
number=19
data:
JSON:{blockState:{blockName:"biomesoplenty:jacaranda_stairs",properties:{half:"bottom",shape:"straight",facing:"south"}}}
:enddata
:endrule

rule:
plugin=vanillaBlocks
number=20
data:
JSON:{blockState:{blockName:"biomesoplenty:jacaranda_fence",properties:{east:"false",south:"false",north:"false",west:"false"}}}
:enddata
:endrule

rule:
plugin=vanillaBlocks
number=21
data:
JSON:{blockState:{blockName:"minecraft:wool",properties:{color:"brown"}}}
:enddata
:endrule

rule:
plugin=vanillaBlocks
number=22
data:
JSON:{blockState:{blockName:"minecraft:torch",properties:{facing:"up"}}}
:enddata
:endrule

#### ENTITIES ####
