# Ancient Warfare Structure Template File
# Auto-generated structure template file. created on: 9/23/2023 at: 0:39:3
# Lines beginning with # denote comments

header:
version=2.11
name=SB_KieavarusCol_House_1H8R_1_pine
mods=biomesoplenty
size=15,23,32
offset=2,1,31
:endheader

#### VALIDATION ####
validation:
type=ground
structureAuthor=TheOddlySeagull
survival=true
worldGenEnabled=false
unique=false
preserveBlocks=false
preventNaturalHostileSpawns=false
selectionWeight=1
clusterValue=1
minDuplicateDistance=1
dimensionWhiteList=true
dimensionList=
biomeGroupList=
biomeWhiteList=true
biomeList=
leveling=0
fill=0
border=0
blockSwap=false
territoryName=
biomeReplacement=minecraft:
minGenerationHeight=0
maxGenerationHeight=255
:endvalidation

#### LAYERS ####
layer: 0
3,3,3,3,3,3,3,3,3,3,3,3,3,3,3
3,3,3,3,3,2,2,2,2,2,2,2,3,3,3
3,3,3,3,3,2,2,4,4,4,2,2,3,3,3
3,3,3,3,3,2,2,2,4,4,4,2,3,3,3
3,3,3,3,3,2,2,4,4,4,4,2,3,3,3
3,3,3,3,3,2,4,4,4,2,2,2,3,3,3
2,3,3,2,2,2,2,2,2,2,2,2,2,2,2
3,3,3,2,4,2,4,2,2,2,2,4,4,2,3
3,3,3,2,4,2,2,2,4,4,2,4,4,2,3
3,3,3,2,2,4,4,4,4,4,4,2,4,2,3
3,3,3,2,2,4,2,2,4,4,2,2,2,2,3
2,3,3,2,2,4,2,2,4,4,2,4,2,2,2
3,3,3,2,4,2,4,2,4,4,2,2,4,2,3
3,3,3,2,4,4,2,2,4,2,2,4,2,2,3
3,3,3,2,4,4,4,4,4,4,2,4,4,2,3
3,3,3,2,4,2,2,4,2,4,4,4,4,2,3
2,3,3,2,4,2,2,2,4,4,2,2,4,2,2
3,3,3,2,4,2,2,2,4,4,4,4,4,2,3
3,3,3,2,4,2,2,2,4,2,4,2,2,2,3
3,3,3,2,2,2,4,2,2,4,2,4,2,2,3
3,3,3,2,2,4,2,2,4,4,2,2,4,2,3
2,2,2,2,2,2,2,2,2,2,2,2,2,2,3
3,2,2,2,2,2,2,4,4,4,4,4,2,3,3
3,2,2,2,2,4,2,4,4,2,2,4,2,2,3
3,2,2,2,2,2,4,4,2,2,4,4,2,3,3
2,2,2,2,2,2,4,4,4,4,2,4,2,3,3
1,2,2,2,2,4,4,4,4,4,4,4,2,3,3
1,2,2,2,2,2,2,4,4,2,2,4,2,2,3
1,2,2,2,2,2,2,4,4,2,2,2,2,3,3
1,2,2,2,2,2,2,2,2,2,2,2,2,3,3
1,2,2,2,1,3,2,3,3,3,2,3,3,3,3
1,2,2,2,1,3,3,3,3,3,3,3,3,3,3
:endlayer
layer: 1
0,0,0,0,0,0,0,0,0,0,0,0,0,0,0
0,0,0,0,0,5,11,11,5,11,11,5,0,0,0
0,0,0,0,0,11,2,2,4,4,2,11,0,0,0
0,0,0,0,0,11,4,4,4,4,2,11,0,0,0
0,0,0,0,0,11,4,4,2,2,2,11,0,0,0
0,0,0,0,0,11,4,2,2,2,4,11,0,0,0
5,0,10,5,11,5,11,11,11,11,11,5,11,5,5
0,0,0,11,2,2,2,4,2,2,2,2,2,11,0
0,0,0,11,4,2,4,4,4,2,4,2,4,11,0
0,0,0,11,2,2,2,2,4,4,4,2,2,11,0
0,0,0,11,4,4,4,2,4,4,4,4,4,11,0
5,0,10,5,2,4,4,2,2,2,4,4,4,5,5
0,0,0,11,2,2,2,4,4,4,4,4,2,11,0
0,0,0,11,4,4,2,4,4,2,4,2,4,11,0
0,0,0,11,4,4,2,2,4,4,2,4,2,11,0
0,0,0,11,4,4,4,2,2,2,2,4,2,11,0
5,0,10,5,4,2,4,2,4,4,4,2,2,5,5
0,0,0,11,2,2,4,4,2,4,2,4,2,11,0
0,0,0,11,4,4,4,4,2,4,2,4,4,11,0
0,0,0,11,4,4,4,2,2,4,4,2,2,11,0
0,0,0,11,4,2,5,4,2,2,5,2,2,11,0
5,9,9,5,5,11,11,11,5,11,11,11,5,5,0
0,0,0,0,11,4,4,2,4,4,4,2,11,0,0
0,8,8,5,11,2,2,2,4,4,2,4,11,5,0
6,7,7,7,11,2,2,2,2,4,4,4,11,0,0
5,0,0,0,5,4,2,2,2,2,2,2,5,0,0
0,0,0,0,11,2,2,2,2,2,2,2,11,0,0
0,0,0,5,11,4,2,2,4,4,2,4,11,5,0
0,0,0,0,11,2,2,4,4,2,2,4,11,0,0
0,0,0,0,5,11,11,11,5,11,11,11,5,0,0
0,0,0,0,0,0,5,0,0,0,5,0,0,0,0
0,0,0,0,0,0,0,0,0,0,0,0,0,0,0
:endlayer
layer: 2
0,0,0,0,0,0,0,0,0,0,0,0,0,0,0
0,0,0,0,0,5,14,14,14,14,14,5,0,0,0
0,0,0,0,0,15,11,11,11,11,11,15,0,0,0
0,0,0,0,0,15,11,11,11,11,11,15,0,0,0
0,0,0,0,0,15,11,11,11,11,11,15,0,0,0
0,0,0,0,0,15,11,11,11,11,11,15,0,0,0
5,14,14,5,14,5,14,14,14,14,14,5,14,5,5
13,12,6,15,11,11,11,11,15,11,11,11,11,15,0
12,12,6,15,11,11,11,11,15,11,11,11,11,15,0
12,12,6,15,11,11,11,11,15,11,11,11,11,15,0
8,12,6,15,11,11,11,11,15,11,11,11,11,15,0
5,14,14,15,14,14,14,14,14,14,14,14,14,15,5
13,12,6,15,11,11,11,11,15,11,11,11,11,15,0
12,12,6,15,11,11,11,11,15,11,11,11,11,15,0
12,12,6,15,11,11,11,11,15,11,11,11,11,15,0
8,12,6,15,11,11,11,11,15,11,11,11,11,15,0
5,14,14,15,14,14,14,14,14,14,14,14,14,15,5
13,12,6,15,11,11,11,11,15,11,11,11,11,15,0
12,12,6,15,11,11,11,11,15,11,11,11,11,15,0
12,12,6,15,11,11,11,11,15,11,11,11,11,15,0
8,12,6,15,11,11,5,11,15,11,5,11,11,15,0
5,14,14,5,5,14,14,14,14,14,14,14,5,5,0
6,11,11,11,15,11,11,11,11,11,11,11,15,0,0
8,7,7,5,15,11,11,11,11,11,11,11,15,5,0
9,0,0,0,15,11,11,11,11,11,11,11,15,0,0
5,0,0,0,15,11,11,11,11,11,11,11,15,0,0
0,0,0,0,15,11,11,11,11,11,11,11,15,0,0
0,0,0,5,15,11,11,11,11,11,11,11,15,5,0
0,0,0,0,15,11,11,11,11,11,11,11,15,0,0
0,0,0,0,5,14,14,14,14,14,14,14,5,0,0
0,0,0,0,0,0,5,0,0,0,5,0,0,0,0
0,0,0,0,0,0,0,0,0,0,0,0,0,0,0
:endlayer
layer: 3
0,0,0,0,0,16,0,0,0,0,0,16,0,0,0
0,0,0,0,10,5,11,11,11,11,11,5,19,0,0
0,0,0,0,0,11,0,0,0,0,0,11,0,0,0
0,0,0,0,0,11,0,0,0,0,0,11,0,0,0
0,0,0,0,0,11,0,0,0,0,0,11,0,0,0
0,0,0,0,0,11,0,0,0,0,0,11,0,16,0
5,9,9,5,11,5,0,0,5,11,11,5,11,5,5
9,0,0,11,0,0,0,0,11,0,0,0,0,11,17
9,0,0,0,0,0,0,0,0,0,0,0,0,11,0
9,0,0,0,0,0,0,0,0,0,0,0,0,11,0
9,0,0,11,0,0,0,0,11,0,0,0,0,11,16
5,0,0,5,0,0,0,0,5,11,11,11,11,5,5
9,0,0,11,18,0,0,0,11,0,0,0,0,11,17
9,0,0,11,13,0,0,0,0,0,0,0,0,11,0
9,0,0,11,0,0,0,0,0,0,0,0,0,11,0
9,0,0,11,0,0,0,0,11,0,0,0,0,11,16
5,0,0,5,0,0,0,0,5,11,11,11,11,5,5
9,0,0,11,0,0,0,0,0,0,0,0,0,11,0
9,0,0,11,0,0,0,0,0,0,0,0,0,11,0
9,0,0,11,0,0,0,0,0,0,0,0,0,11,0
9,0,0,11,0,0,5,0,0,0,5,0,0,11,0
5,0,0,5,5,11,5,0,0,0,5,11,5,5,19
9,0,0,0,11,0,0,0,0,0,0,0,11,0,0
9,0,0,5,5,0,0,0,0,0,0,0,5,5,0
9,0,0,17,11,0,0,0,0,0,0,0,11,17,0
5,0,0,0,11,0,0,0,20,0,0,0,11,0,0
0,0,0,16,11,0,0,0,0,0,0,0,11,16,0
0,0,0,5,5,0,0,0,0,0,0,0,5,5,0
0,0,0,0,11,0,0,0,0,0,0,0,11,0,0
0,0,0,0,5,11,5,11,11,11,5,11,5,0,0
0,0,0,0,0,0,5,19,0,10,5,0,0,0,0
0,0,0,0,0,0,0,0,0,0,0,0,0,0,0
:endlayer
layer: 4
0,0,0,0,0,0,0,0,0,0,0,0,0,0,0
0,0,0,0,0,5,11,11,9,11,11,5,0,0,0
0,0,0,0,0,11,0,0,0,0,0,11,0,0,0
0,0,0,0,0,9,0,0,0,0,0,9,0,0,0
0,0,0,0,0,9,0,0,0,0,0,9,0,0,0
0,0,0,0,0,11,0,0,0,0,0,11,0,0,0
9,0,0,5,11,5,0,0,5,11,11,5,11,5,5
0,0,0,11,0,0,0,0,11,0,0,0,0,11,0
0,0,0,0,0,0,0,0,0,0,0,0,0,9,0
0,0,0,0,0,0,0,0,0,0,0,0,0,9,0
0,0,0,11,0,0,0,0,11,0,0,0,0,11,0
9,0,0,5,0,0,0,0,5,11,11,11,11,5,5
0,0,0,11,0,0,0,0,11,0,0,0,0,11,0
0,0,0,11,18,0,0,0,0,0,0,0,0,9,0
0,0,0,11,13,0,0,0,0,0,0,0,0,9,0
0,0,0,11,0,0,0,0,11,0,0,0,0,11,0
9,0,0,5,19,0,0,10,5,11,11,11,11,5,5
0,0,0,11,0,0,0,0,0,0,0,0,0,11,0
0,0,0,9,0,0,0,0,0,0,0,0,0,9,0
0,0,0,9,0,0,0,0,0,0,0,0,0,9,0
0,0,0,11,0,0,5,0,0,0,5,0,0,11,0
9,0,0,5,5,11,5,0,0,0,5,11,5,5,0
0,0,0,0,11,0,0,0,0,0,0,0,11,0,0
0,0,0,5,5,0,0,0,0,0,0,0,5,5,0
0,0,0,0,11,0,0,0,0,0,0,0,11,0,0
9,0,0,0,9,0,0,0,0,0,0,0,9,0,0
0,0,0,0,11,0,0,0,0,0,0,0,11,0,0
0,0,0,5,5,0,0,0,0,0,0,0,5,5,0
0,0,0,0,11,0,0,0,0,0,0,0,11,0,0
0,0,0,0,5,11,5,11,9,11,5,11,5,0,0
0,0,0,0,0,0,5,0,0,0,5,0,0,0,0
0,0,0,0,0,0,0,0,0,0,0,0,0,0,0
:endlayer
layer: 5
0,0,0,0,0,0,0,0,0,0,0,0,0,0,0
0,0,0,0,0,5,11,11,11,11,11,5,0,0,0
0,0,0,0,0,11,17,0,0,0,17,11,0,0,0
0,0,0,0,0,11,0,0,0,0,0,11,0,0,0
0,0,0,0,0,11,0,0,0,0,0,11,0,0,0
0,0,0,0,0,11,0,0,16,0,0,11,0,0,0
9,0,10,5,11,5,21,6,5,11,11,5,11,5,5
0,0,0,11,0,17,0,0,11,0,0,17,0,11,0
0,0,0,11,0,0,0,0,13,0,0,0,0,11,0
0,0,0,11,0,0,0,0,8,0,0,0,0,11,0
0,0,0,11,0,0,0,0,11,0,0,16,0,11,0
9,0,10,5,19,0,0,10,5,11,11,11,11,5,5
0,0,0,11,0,0,0,0,11,0,0,17,0,11,0
0,0,0,11,0,0,0,0,13,0,0,0,0,11,0
0,0,0,11,18,0,0,0,8,0,0,0,0,11,0
0,0,0,11,13,0,0,0,11,0,0,16,0,11,0
9,0,10,5,21,12,12,6,5,11,11,11,11,5,5
0,0,0,11,0,0,0,0,0,0,0,0,0,11,0
0,0,0,11,0,0,0,0,0,0,0,0,0,11,0
0,0,0,11,0,0,16,0,0,0,16,0,0,11,0
0,0,0,11,0,0,5,0,0,0,5,0,0,11,0
9,0,10,5,5,11,5,21,12,6,5,11,5,5,0
0,0,0,0,11,0,17,0,0,0,17,0,11,0,0
0,0,0,5,5,19,0,0,0,0,0,10,5,5,0
0,0,0,0,11,0,0,0,0,0,0,0,11,0,0
9,0,0,0,11,0,0,0,0,0,0,0,11,0,0
0,0,0,0,11,0,0,0,0,0,0,0,11,0,0
0,0,0,5,5,19,0,0,0,0,0,10,5,5,0
0,0,0,0,11,0,16,0,0,0,16,0,11,0,0
0,0,0,10,5,11,5,11,11,11,5,11,5,19,0
0,0,0,0,17,0,5,0,0,0,5,0,17,0,0
0,0,0,0,0,0,0,0,0,0,0,0,0,0,0
:endlayer
layer: 6
0,0,0,0,22,0,0,0,0,0,0,0,22,0,0
0,0,0,0,22,5,14,14,14,14,14,5,22,0,0
0,0,0,0,22,11,12,11,12,11,12,11,22,0,0
0,0,0,0,22,11,12,11,12,11,12,11,22,0,0
0,0,0,0,22,11,12,11,12,11,12,11,22,0,0
0,0,0,0,22,11,12,11,12,11,12,11,22,0,0
22,0,0,5,14,5,14,14,14,14,14,5,14,5,5
22,0,0,15,12,11,12,11,15,11,12,11,12,15,0
22,0,0,15,12,11,12,11,15,11,12,11,12,15,0
22,0,0,15,12,11,12,11,15,11,12,11,12,15,0
22,0,0,15,12,11,12,11,15,11,12,11,12,15,0
22,0,0,5,14,14,14,14,14,14,14,14,14,5,5
22,0,0,15,0,6,12,11,15,11,12,11,12,15,0
22,0,0,15,0,11,12,11,15,11,12,11,12,15,0
22,0,0,15,0,11,12,11,15,11,12,11,12,15,0
22,0,0,15,18,11,12,11,15,11,12,11,12,15,0
22,0,0,5,14,14,14,14,14,14,14,14,14,5,5
22,0,0,15,12,11,12,11,15,11,12,11,12,15,0
22,0,0,15,12,11,12,11,15,11,12,11,12,15,0
22,0,0,15,12,11,12,11,15,11,12,11,12,15,0
22,0,0,15,12,11,5,11,15,11,5,11,12,15,0
22,0,0,5,5,14,14,14,14,14,14,14,5,5,0
22,0,0,0,15,12,11,12,12,12,11,12,15,0,0
22,0,0,5,15,11,11,11,11,11,11,11,15,5,0
22,0,0,0,15,12,11,12,12,12,11,12,15,0,0
22,0,0,0,15,12,11,12,12,12,11,12,15,0,0
0,0,0,0,15,12,11,12,12,12,11,12,15,0,0
0,0,0,5,15,11,11,11,11,11,11,11,15,5,0
0,0,0,0,15,12,11,12,12,12,11,12,15,0,0
0,0,0,0,5,14,14,14,14,14,14,14,5,0,0
0,0,0,0,0,0,5,0,0,0,5,0,0,0,0
0,0,0,0,0,0,0,0,0,0,0,0,0,0,0
:endlayer
layer: 7
0,0,0,0,0,22,0,0,0,0,0,22,0,0,0
0,0,0,0,0,22,11,11,11,11,11,22,0,0,0
0,0,0,0,0,22,0,0,0,0,0,22,0,0,0
0,0,0,0,0,22,0,0,0,0,0,22,0,0,0
0,0,0,0,0,22,0,0,0,0,0,22,0,0,0
0,0,0,0,0,22,0,0,0,0,0,22,0,0,0
0,22,0,5,11,5,11,11,0,11,11,5,11,5,5
0,22,0,11,0,0,0,0,0,0,0,0,0,11,0
0,22,0,11,0,0,0,0,0,0,0,0,0,11,0
0,22,0,11,0,0,0,0,0,0,0,0,0,11,0
0,22,0,11,0,0,0,0,0,0,0,0,0,11,0
0,22,0,5,11,11,11,11,5,0,0,0,0,5,5
0,22,0,11,6,24,0,0,0,0,0,0,0,11,0
0,22,0,11,0,9,0,0,0,0,0,0,0,11,0
0,22,0,11,0,9,0,0,0,0,0,0,0,11,0
0,22,0,11,0,0,0,0,0,0,0,0,0,11,0
0,22,0,5,11,0,0,0,0,0,0,0,11,5,5
0,22,0,11,0,0,0,0,0,0,0,0,0,11,0
0,22,0,11,0,0,0,0,0,0,0,0,0,11,0
0,22,0,11,0,0,0,0,0,0,0,0,0,11,0
0,22,0,11,0,0,5,0,0,0,5,0,0,11,0
0,22,0,5,5,11,5,11,0,11,5,11,5,5,0
0,22,0,22,11,0,0,0,0,0,0,0,11,0,0
0,22,0,5,5,0,0,0,0,0,0,0,5,5,0
0,22,0,22,11,0,0,0,0,0,0,0,11,0,0
0,22,0,22,11,0,0,0,0,0,0,0,11,0,0
0,0,0,0,11,0,0,0,0,0,0,0,11,0,0
0,0,0,5,5,0,0,0,0,0,0,0,5,5,0
0,0,0,0,11,23,0,0,0,0,0,0,11,0,0
0,0,0,0,5,11,5,11,11,11,5,11,5,0,0
0,0,0,0,0,0,5,0,0,0,5,0,0,0,0
0,0,0,0,0,0,0,0,0,0,0,0,0,0,0
:endlayer
layer: 8
0,0,0,0,0,0,22,0,0,0,22,0,0,0,0
0,0,0,0,0,0,22,11,9,11,22,0,0,0,0
0,0,0,0,0,20,22,0,0,0,22,20,0,0,0
0,0,0,0,0,0,22,0,0,0,22,0,0,0,0
0,0,0,0,0,0,22,0,0,0,22,0,0,0,0
0,0,0,0,0,0,22,0,0,0,22,0,0,0,0
0,0,22,5,11,5,11,11,0,11,11,5,11,5,5
0,0,22,11,0,0,0,0,0,0,0,0,0,11,0
0,20,22,11,0,0,0,0,0,0,0,0,0,9,0
0,0,22,11,0,0,0,0,0,0,0,0,0,9,0
0,0,22,11,0,0,0,0,0,0,0,0,0,11,0
0,0,22,5,11,11,11,11,5,0,0,0,0,5,5
0,0,22,11,24,0,0,0,0,0,0,0,0,11,0
0,20,22,11,13,9,0,0,0,0,0,0,0,9,0
0,0,22,11,0,9,0,0,0,0,0,0,0,9,0
0,0,22,11,0,0,0,0,0,0,0,0,0,11,0
0,0,22,5,11,0,0,0,0,0,0,0,11,5,5
0,0,22,11,0,0,0,0,0,0,0,0,0,11,22
0,20,22,11,0,0,0,0,0,0,0,0,0,11,22
0,0,22,11,0,0,0,0,0,0,0,0,0,11,22
0,0,22,11,0,0,5,0,0,0,5,0,0,11,22
0,0,22,5,5,11,5,11,0,11,5,11,5,5,22
0,0,22,11,11,0,0,0,0,0,0,0,11,0,22
0,20,22,5,5,0,0,0,0,0,0,0,5,5,0
0,0,22,0,11,0,0,0,0,0,0,0,11,0,0
0,0,22,0,9,0,0,0,0,0,0,0,9,0,0
0,0,0,0,11,0,0,0,0,0,0,0,11,0,0
0,0,0,5,5,0,0,0,0,0,0,0,5,5,0
0,0,0,0,11,23,0,0,0,0,0,0,11,0,0
0,0,0,0,5,11,5,11,9,11,5,11,5,0,0
0,0,0,0,0,0,5,0,0,0,5,0,0,0,0
0,0,0,0,0,0,0,0,0,0,0,0,0,0,0
:endlayer
layer: 9
0,0,0,0,0,0,0,22,0,22,0,0,0,0,0
0,0,0,0,0,0,0,22,11,22,0,0,0,0,0
0,0,0,0,0,0,0,22,17,22,0,0,0,0,0
0,0,0,0,0,0,0,22,0,22,0,0,0,0,0
0,0,0,0,0,0,0,22,0,22,0,0,0,0,0
0,0,0,0,0,0,0,22,16,22,0,0,0,0,0
0,0,0,5,11,5,11,11,11,11,11,5,11,5,5
0,0,0,11,0,17,0,0,0,0,0,17,0,11,0
0,0,0,9,0,0,0,0,0,0,0,0,0,11,0
0,0,0,9,0,0,0,0,0,0,0,0,0,11,0
0,0,0,11,0,0,0,0,16,0,0,0,0,11,0
0,0,0,5,11,11,11,11,5,21,12,12,6,5,5
0,0,0,11,0,0,0,0,17,0,0,0,0,11,0
0,0,0,9,18,9,0,0,0,0,0,0,0,11,0
0,0,0,9,13,9,0,0,0,0,0,0,0,11,0
0,0,0,11,16,0,0,0,0,0,0,0,16,11,0
0,0,0,5,11,21,0,0,0,0,0,6,11,5,5
0,0,0,22,21,0,0,0,0,0,0,0,6,22,0
0,0,0,22,21,0,0,0,0,0,0,0,6,22,0
0,0,0,22,21,0,16,0,0,0,16,0,6,22,0
0,0,0,22,21,0,5,0,0,0,5,0,6,22,0
0,0,0,22,5,11,5,11,11,11,5,11,5,22,0
0,0,0,22,11,0,0,0,17,0,0,0,11,22,0
0,0,0,5,5,0,0,0,0,0,0,0,5,5,0
0,0,0,0,11,0,0,0,0,0,0,0,11,0,0
0,0,0,0,11,19,0,0,0,0,0,10,11,0,0
0,0,0,0,11,0,0,0,0,0,0,0,11,0,0
0,0,0,5,5,0,0,0,0,0,0,0,5,5,0
0,0,0,0,11,23,0,0,16,0,0,0,11,0,0
0,0,0,0,5,11,5,11,11,11,5,11,5,0,0
0,0,0,0,0,0,5,0,0,0,5,0,0,0,0
0,0,0,0,0,0,0,0,0,0,0,0,0,0,0
:endlayer
layer: 10
0,0,0,0,0,0,0,0,22,0,0,0,0,0,0
0,0,0,0,0,0,0,0,22,0,0,0,0,0,0
0,0,0,0,0,0,0,0,22,0,0,0,0,0,0
0,0,0,0,0,0,0,0,22,0,0,0,0,0,0
0,0,0,0,0,0,0,0,22,0,0,0,0,0,0
0,0,0,0,0,0,0,0,22,0,0,0,0,0,0
0,0,0,5,14,5,14,14,14,14,14,5,14,5,5
0,0,0,11,12,12,12,12,15,12,12,12,12,11,21
0,0,0,11,11,11,11,11,15,11,11,11,11,11,21
0,0,0,11,12,12,12,12,15,12,12,12,12,11,21
0,0,0,11,11,11,11,11,15,11,11,11,11,11,21
0,0,0,5,14,14,14,14,14,14,14,14,14,5,5
0,0,0,11,0,0,0,11,12,11,12,11,12,11,21
0,0,0,11,0,11,11,11,12,11,12,11,12,11,21
0,0,0,11,18,11,12,11,12,11,12,11,12,11,21
0,0,0,11,13,11,12,11,12,11,12,11,12,11,21
0,0,0,5,14,14,14,14,14,14,14,14,14,5,5
0,0,0,0,22,0,0,0,0,0,0,0,22,0,0
0,0,0,0,22,0,0,0,0,0,0,0,22,0,0
0,0,0,0,22,0,0,0,0,0,0,0,22,0,0
0,0,0,0,22,0,5,0,0,0,5,0,22,0,0
0,0,0,0,5,14,14,14,14,14,14,14,5,20,0
0,0,0,0,15,12,11,12,12,12,11,12,15,0,0
0,0,0,5,15,11,11,11,11,11,11,11,15,5,0
0,0,0,0,15,12,11,12,12,12,11,12,15,0,0
0,0,0,0,15,12,11,12,12,12,11,12,15,0,0
0,0,0,0,15,12,11,12,12,12,11,12,15,0,0
0,0,0,5,15,11,11,11,11,11,11,11,15,5,0
0,0,0,0,15,23,11,12,12,12,11,12,15,0,0
0,0,0,0,5,14,14,14,14,14,14,14,5,0,0
0,0,0,0,0,0,5,0,0,0,5,0,0,0,0
0,0,0,0,0,0,0,0,0,0,0,0,0,0,0
:endlayer
layer: 11
0,0,0,0,0,0,0,0,0,0,0,0,0,0,0
0,0,0,0,0,0,0,0,0,0,0,0,0,0,0
0,0,0,0,0,0,0,0,20,0,0,0,0,0,0
0,0,0,0,0,0,0,0,0,0,0,0,0,0,0
0,0,0,0,0,0,0,0,0,0,0,0,0,0,0
0,0,22,0,0,0,0,0,0,0,0,0,0,0,22
0,0,22,5,11,5,11,11,11,11,11,5,11,5,22
0,0,22,15,0,0,0,0,0,0,0,0,0,15,22
0,0,22,15,0,0,0,0,0,0,0,0,0,15,22
0,0,22,15,0,0,0,0,0,0,0,0,0,15,22
0,0,22,15,0,0,0,0,0,0,0,0,0,15,22
0,0,22,15,9,9,9,9,0,0,0,0,0,15,22
0,0,22,15,0,0,0,9,0,0,0,0,0,15,22
0,0,22,15,0,9,9,9,0,0,0,0,0,15,22
0,0,22,15,0,0,0,0,0,0,0,0,0,15,22
0,0,22,15,0,0,0,0,0,0,0,0,0,15,22
0,0,22,5,11,5,11,11,5,11,11,5,11,5,22
0,0,22,0,0,22,0,0,0,0,0,22,0,0,22
0,0,0,0,0,22,0,0,0,0,0,22,0,0,0
0,0,0,0,20,22,0,0,0,0,0,22,20,0,0
0,0,0,0,0,22,5,0,0,0,5,22,0,0,0
0,0,0,0,5,11,5,11,11,11,5,11,5,0,0
0,0,0,0,11,0,0,0,0,0,0,0,11,0,0
0,0,0,5,5,0,0,0,0,0,0,0,5,5,0
0,0,0,0,11,0,0,0,0,0,0,0,11,0,0
0,0,0,0,11,0,0,0,0,0,0,0,11,0,0
0,0,0,0,11,0,0,0,0,0,0,0,11,0,0
0,0,0,5,5,0,0,0,0,0,0,0,5,5,0
0,0,0,0,11,23,0,0,0,0,0,0,11,0,0
0,0,0,0,5,11,5,11,11,11,5,11,5,0,0
0,0,0,0,0,0,5,0,0,0,5,0,0,0,0
0,0,0,0,0,0,0,0,0,0,0,0,0,0,0
:endlayer
layer: 12
0,0,0,0,0,0,0,0,0,0,0,0,0,0,0
0,0,0,0,0,0,0,0,0,0,0,0,0,0,0
0,0,0,0,0,0,0,0,0,0,0,0,0,0,0
0,0,0,0,0,0,0,0,0,0,0,0,0,0,0
0,0,0,0,0,0,0,0,0,0,0,0,0,0,0
0,0,0,22,0,0,0,0,0,0,0,0,0,22,0
0,0,0,22,14,14,14,14,14,14,14,14,14,22,0
0,0,0,22,0,0,0,0,0,0,0,0,0,22,0
0,0,0,22,0,0,0,0,0,0,0,0,0,22,0
0,0,0,22,0,0,0,0,0,0,0,0,0,22,0
0,0,0,22,0,0,0,0,0,0,0,0,0,22,0
0,0,0,22,19,0,0,0,0,0,0,0,10,22,0
0,0,0,22,0,0,0,0,0,0,0,0,0,22,0
0,0,0,22,0,0,0,0,0,0,0,0,0,22,0
0,0,0,22,0,0,0,0,0,0,0,0,0,22,0
0,0,0,22,0,0,0,0,0,0,0,0,0,22,0
0,0,0,22,14,14,14,14,14,14,14,14,14,22,0
0,0,0,22,0,0,22,0,0,0,22,0,0,22,0
0,0,0,0,0,0,22,0,0,0,22,0,0,0,0
0,0,0,0,0,0,22,0,0,0,22,0,0,0,0
0,0,0,0,0,0,5,21,0,6,5,0,0,0,0
0,0,0,0,5,11,5,11,11,11,5,11,5,0,0
0,0,0,0,11,0,0,0,0,0,0,0,11,0,0
0,0,0,5,5,0,0,0,0,0,0,0,5,5,0
0,0,0,0,11,0,0,0,0,0,0,0,11,0,0
0,0,0,0,9,0,0,0,0,0,0,0,9,0,0
0,0,0,0,11,0,0,0,0,0,0,0,11,0,0
0,0,0,5,5,0,0,0,0,0,0,0,5,5,0
0,0,0,0,11,23,0,0,0,0,0,0,11,0,0
0,0,0,0,5,11,5,11,9,11,5,11,5,0,0
0,0,0,0,0,0,5,0,0,0,5,0,0,0,0
0,0,0,0,0,0,0,0,0,0,0,0,0,0,0
:endlayer
layer: 13
0,0,0,0,0,0,0,0,0,0,0,0,0,0,0
0,0,0,0,0,0,0,0,0,0,0,0,0,0,0
0,0,0,0,0,0,0,0,0,0,0,0,0,0,0
0,0,0,0,0,0,0,0,0,0,0,0,0,0,0
0,0,0,0,0,0,0,0,0,0,0,0,0,0,0
0,0,0,0,22,0,0,0,0,0,0,0,22,0,0
0,0,0,0,22,11,11,5,11,5,11,11,22,0,0
0,0,0,0,22,0,0,17,0,17,0,0,22,0,0
0,0,0,0,22,0,0,0,0,0,0,0,22,0,0
0,0,0,0,22,0,0,0,0,0,0,0,22,0,0
0,0,0,0,22,0,0,0,0,0,0,0,22,0,0
0,0,0,20,22,0,0,0,0,0,0,0,22,20,0
0,0,0,0,22,0,0,0,0,0,0,0,22,0,0
0,0,0,0,22,0,0,0,0,0,0,0,22,0,0
0,0,0,0,22,0,0,0,0,0,0,0,22,0,0
0,0,0,0,22,0,0,16,0,16,0,0,22,0,0
0,0,0,0,22,11,11,5,11,5,11,11,22,0,0
0,0,0,0,22,0,0,22,0,22,0,0,22,0,0
0,0,0,0,0,0,0,22,0,22,0,0,0,0,0
0,0,0,0,0,0,0,22,0,22,0,0,0,0,0
0,0,0,0,0,0,5,22,8,22,5,0,0,0,0
0,0,0,0,5,11,5,11,11,11,5,11,5,0,0
0,0,0,0,11,0,0,0,17,0,0,0,11,0,0
0,0,0,5,5,0,0,0,0,0,0,0,5,5,0
0,0,0,0,11,0,0,0,0,0,0,0,11,0,0
0,0,0,0,11,19,0,0,0,0,0,10,11,0,0
0,0,0,0,11,0,0,0,0,0,0,0,11,0,0
0,0,0,5,5,0,0,0,0,0,0,0,5,5,0
0,0,0,0,11,23,0,0,16,0,0,0,11,0,0
0,0,0,0,5,11,5,11,11,11,5,11,5,0,0
0,0,0,0,0,0,5,0,0,0,5,0,0,0,0
0,0,0,0,0,0,0,0,0,0,0,0,0,0,0
:endlayer
layer: 14
0,0,0,0,0,0,0,0,0,0,0,0,0,0,0
0,0,0,0,0,0,0,0,0,0,0,0,0,0,0
0,0,0,0,0,0,0,0,0,0,0,0,0,0,0
0,0,0,0,0,0,0,0,0,0,0,0,0,0,0
0,0,0,0,0,0,0,0,0,0,0,0,0,0,0
0,0,0,0,0,22,0,0,0,0,0,22,0,0,0
0,0,0,0,0,22,11,5,9,5,11,22,0,0,0
0,0,0,0,20,22,0,0,0,0,0,22,20,0,0
0,0,0,0,0,22,0,0,0,0,0,22,0,0,0
0,0,0,0,0,22,0,0,0,0,0,22,0,0,0
0,0,0,0,0,22,0,0,0,0,0,22,0,0,0
0,0,0,0,0,22,0,0,0,0,0,22,0,0,0
0,0,0,0,0,22,0,0,0,0,0,22,0,0,0
0,0,0,0,0,22,0,0,0,0,0,22,0,0,0
0,0,0,0,0,22,0,0,0,0,0,22,0,0,0
0,0,0,0,20,22,0,0,0,0,0,22,20,0,0
0,0,0,0,0,22,11,5,11,5,11,22,0,0,0
0,0,0,0,0,22,0,0,22,0,0,22,0,0,0
0,0,0,0,0,0,0,0,22,0,0,0,0,0,0
0,0,0,0,0,0,0,20,22,20,0,0,0,0,0
0,0,0,0,0,0,5,0,22,0,5,0,0,0,0
0,0,0,0,5,14,14,14,14,14,14,14,5,0,0
0,0,0,0,15,12,11,12,12,12,11,12,15,0,0
0,0,0,5,15,11,11,11,11,11,11,11,15,5,0
0,0,0,0,15,12,11,12,12,12,11,12,15,0,0
0,0,0,0,15,12,11,12,12,12,11,12,15,0,0
0,0,0,0,15,12,11,12,12,12,11,12,15,0,0
0,0,0,5,15,11,11,11,11,11,11,11,15,5,0
0,0,0,0,15,23,11,12,12,12,11,12,15,0,0
0,0,0,0,5,14,14,14,14,14,14,14,5,0,0
0,0,0,0,0,0,5,0,0,0,5,0,0,0,0
0,0,0,0,0,0,0,0,0,0,0,0,0,0,0
:endlayer
layer: 15
0,0,0,0,0,0,0,0,0,0,0,0,0,0,0
0,0,0,0,0,0,0,0,0,0,0,0,0,0,0
0,0,0,0,0,0,0,0,0,0,0,0,0,0,0
0,0,0,0,0,0,0,0,0,0,0,0,0,0,0
0,0,0,0,0,0,0,0,0,0,0,0,0,0,0
0,0,0,0,0,0,22,0,0,0,22,0,0,0,0
0,0,0,0,0,0,22,5,11,5,22,0,0,0,0
0,0,0,0,0,0,22,0,0,0,22,0,0,0,0
0,0,0,0,0,0,22,0,0,0,22,0,0,0,0
0,0,0,0,0,0,22,0,0,0,22,0,0,0,0
0,0,0,0,0,0,22,0,0,0,22,0,0,0,0
0,0,0,0,0,0,22,0,0,0,22,0,0,0,0
0,0,0,0,0,0,22,0,0,0,22,0,0,0,0
0,0,0,0,0,0,22,0,0,0,22,0,0,0,0
0,0,0,0,0,0,22,0,0,0,22,0,0,0,0
0,0,0,0,0,0,22,0,0,0,22,0,0,0,0
0,0,0,0,0,0,22,5,11,5,22,0,0,0,0
0,0,0,0,0,0,22,0,0,0,22,0,0,0,0
0,0,0,0,0,0,0,0,0,0,0,0,0,0,0
0,0,0,0,0,0,8,0,0,0,8,0,0,0,0
0,0,0,0,0,0,5,0,0,0,5,0,0,0,0
0,0,0,0,5,11,5,9,5,9,5,11,5,0,0
0,0,0,0,11,0,0,0,0,0,0,0,11,0,0
0,0,6,5,5,0,0,0,0,0,0,0,5,5,21
0,0,0,0,9,0,0,0,0,0,0,0,9,0,0
0,0,0,0,5,0,0,0,0,0,0,0,5,0,0
0,0,0,0,9,0,0,0,0,0,0,0,9,0,0
0,0,6,5,5,0,0,0,0,0,0,0,5,5,21
0,0,0,0,11,23,0,0,0,0,0,0,11,0,0
0,0,0,0,5,11,5,9,5,9,5,11,5,0,0
0,0,0,0,0,0,5,0,0,0,5,0,0,0,0
0,0,0,0,0,0,13,0,0,0,13,0,0,0,0
:endlayer
layer: 16
0,0,0,0,0,0,0,0,0,0,0,0,0,0,0
0,0,0,0,0,0,0,0,0,0,0,0,0,0,0
0,0,0,0,0,0,0,0,0,0,0,0,0,0,0
0,0,0,0,0,0,0,0,0,0,0,0,0,0,0
0,0,0,0,0,0,0,0,0,0,0,0,0,0,0
0,0,0,0,0,0,0,22,0,22,0,0,0,0,0
0,0,0,0,0,0,0,22,14,22,0,0,0,0,0
0,0,0,0,0,0,0,22,0,22,0,0,0,0,0
0,0,0,0,0,0,0,22,0,22,0,0,0,0,0
0,0,0,0,0,0,0,22,0,22,0,0,0,0,0
0,0,0,0,0,0,0,22,0,22,0,0,0,0,0
0,0,0,0,0,0,0,22,0,22,0,0,0,0,0
0,0,0,0,0,0,0,22,0,22,0,0,0,0,0
0,0,0,0,0,0,0,22,0,22,0,0,0,0,0
0,0,0,0,0,0,0,22,0,22,0,0,0,0,0
0,0,0,0,0,0,0,22,0,22,0,0,0,0,0
0,0,0,0,0,0,0,22,11,22,0,0,0,0,0
0,0,0,0,0,0,0,22,9,22,0,0,0,0,0
0,0,0,0,0,0,0,0,0,0,0,0,0,0,0
0,0,22,22,22,22,22,22,22,22,22,22,22,22,22
0,0,22,0,8,0,5,0,0,0,5,0,8,0,22
0,0,22,6,5,11,5,11,5,11,5,11,5,21,22
0,0,22,0,11,0,0,0,0,0,0,0,11,0,22
0,0,22,5,5,0,0,0,0,0,0,0,5,5,22
0,0,22,0,11,0,0,0,0,0,0,0,11,0,22
0,0,22,0,5,0,0,0,0,0,0,0,5,0,22
0,0,22,0,11,0,0,0,0,0,0,0,11,0,22
0,0,22,5,5,0,0,0,0,0,0,0,5,5,22
0,0,22,0,11,23,0,0,0,0,0,0,11,0,22
0,0,22,6,5,11,5,11,5,11,5,11,5,21,22
0,0,22,0,13,0,5,0,0,0,5,0,13,0,22
0,0,22,22,22,22,22,22,22,22,22,22,22,22,22
:endlayer
layer: 17
0,0,0,0,0,0,0,0,0,0,0,0,0,0,0
0,0,0,0,0,0,0,0,0,0,0,0,0,0,0
0,0,0,0,0,0,0,0,0,0,0,0,0,0,0
0,0,0,0,0,0,0,0,0,0,0,0,0,0,0
0,0,0,0,0,0,0,0,0,0,0,0,0,0,0
0,0,0,0,0,0,0,0,22,0,0,0,0,0,0
0,0,0,0,0,0,0,0,22,0,0,0,0,0,0
0,0,0,0,0,0,0,20,22,20,0,0,0,0,0
0,0,0,0,0,0,0,0,22,0,0,0,0,0,0
0,0,0,0,0,0,0,0,22,0,0,0,0,0,0
0,0,0,0,0,0,0,0,22,0,0,0,0,0,0
0,0,0,0,0,0,0,0,22,0,0,0,0,0,0
0,0,0,0,0,0,0,0,22,0,0,0,0,0,0
0,0,0,0,0,0,0,0,22,0,0,0,0,0,0
0,0,0,0,0,0,0,0,22,0,0,0,0,0,0
0,0,0,0,0,0,0,20,22,20,0,0,0,0,0
0,0,0,0,0,0,0,0,22,0,0,0,0,0,0
0,0,0,0,0,0,0,0,22,0,0,0,0,0,0
0,0,0,0,0,0,0,0,0,0,0,0,0,0,0
0,0,0,0,0,0,0,0,0,0,0,0,0,0,0
0,0,0,22,22,22,22,22,22,22,22,22,22,22,0
0,0,0,22,5,14,14,14,14,14,14,14,5,22,0
0,0,0,22,15,0,0,0,17,0,0,0,15,22,0
0,0,0,22,15,0,0,0,0,0,0,0,15,22,0
0,0,0,22,15,0,0,0,0,0,0,0,15,22,0
0,0,0,22,15,19,0,0,0,0,0,10,15,22,0
0,0,0,22,15,0,0,0,0,0,0,0,15,22,0
0,0,0,22,15,0,0,0,0,0,0,0,15,22,0
0,0,0,22,15,23,0,0,16,0,0,0,15,22,0
0,0,0,22,5,14,14,14,14,14,14,14,5,22,0
0,0,0,22,22,22,22,22,22,22,22,22,22,22,0
0,0,0,0,0,0,0,0,0,0,0,0,0,0,0
:endlayer
layer: 18
0,0,0,0,0,0,0,0,0,0,0,0,0,0,0
0,0,0,0,0,0,0,0,0,0,0,0,0,0,0
0,0,0,0,0,0,0,0,0,0,0,0,0,0,0
0,0,0,0,0,0,0,0,0,0,0,0,0,0,0
0,0,0,0,0,0,0,0,0,0,0,0,0,0,0
0,0,0,0,0,0,0,0,0,0,0,0,0,0,0
0,0,0,0,0,0,0,0,0,0,0,0,0,0,0
0,0,0,0,0,0,0,0,0,0,0,0,0,0,0
0,0,0,0,0,0,0,0,0,0,0,0,0,0,0
0,0,0,0,0,0,0,0,0,0,0,0,0,0,0
0,0,0,0,0,0,0,0,0,0,0,0,0,0,0
0,0,0,0,0,0,0,0,0,0,0,0,0,0,0
0,0,0,0,0,0,0,0,0,0,0,0,0,0,0
0,0,0,0,0,0,0,0,0,0,0,0,0,0,0
0,0,0,0,0,0,0,0,0,0,0,0,0,0,0
0,0,0,0,0,0,0,0,0,0,0,0,0,0,0
0,0,0,0,0,0,0,0,0,0,0,0,0,0,0
0,0,0,0,0,0,0,0,0,0,0,0,0,0,0
0,0,0,0,0,0,0,0,0,0,0,0,0,0,0
0,0,0,0,0,0,0,0,0,0,0,0,0,0,0
0,0,0,20,0,0,0,0,20,0,0,0,0,20,0
0,0,0,0,22,22,22,22,22,22,22,22,22,0,0
0,0,0,0,22,13,13,13,13,13,13,6,22,0,0
0,0,0,0,22,21,0,0,0,0,0,6,22,0,0
0,0,0,0,22,21,0,0,0,0,0,6,22,0,0
0,0,0,20,22,21,0,0,0,0,0,6,22,20,0
0,0,0,0,22,21,0,0,0,0,0,6,22,0,0
0,0,0,0,22,21,0,0,0,0,0,6,22,0,0
0,0,0,0,22,8,8,8,8,8,8,8,22,0,0
0,0,0,0,22,22,22,22,22,22,22,22,22,0,0
0,0,0,20,0,0,0,0,20,0,0,0,0,20,0
0,0,0,0,0,0,0,0,0,0,0,0,0,0,0
:endlayer
layer: 19
0,0,0,0,0,0,0,0,0,0,0,0,0,0,0
0,0,0,0,0,0,0,0,0,0,0,0,0,0,0
0,0,0,0,0,0,0,0,0,0,0,0,0,0,0
0,0,0,0,0,0,0,0,0,0,0,0,0,0,0
0,0,0,0,0,0,0,0,0,0,0,0,0,0,0
0,0,0,0,0,0,0,0,0,0,0,0,0,0,0
0,0,0,0,0,0,0,0,0,0,0,0,0,0,0
0,0,0,0,0,0,0,0,0,0,0,0,0,0,0
0,0,0,0,0,0,0,0,0,0,0,0,0,0,0
0,0,0,0,0,0,0,0,0,0,0,0,0,0,0
0,0,0,0,0,0,0,0,0,0,0,0,0,0,0
0,0,0,0,0,0,0,0,0,0,0,0,0,0,0
0,0,0,0,0,0,0,0,0,0,0,0,0,0,0
0,0,0,0,0,0,0,0,0,0,0,0,0,0,0
0,0,0,0,0,0,0,0,0,0,0,0,0,0,0
0,0,0,0,0,0,0,0,0,0,0,0,0,0,0
0,0,0,0,0,0,0,0,0,0,0,0,0,0,0
0,0,0,0,0,0,0,0,0,0,0,0,0,0,0
0,0,0,0,0,0,0,0,0,0,0,0,0,0,0
0,0,0,0,0,0,0,0,0,0,0,0,0,0,0
0,0,0,0,0,0,0,0,0,0,0,0,0,0,0
0,0,0,0,0,0,0,0,0,0,0,0,0,0,0
0,0,0,0,0,22,22,22,22,22,22,22,0,0,0
0,0,0,0,0,22,21,13,13,13,13,22,0,0,0
0,0,0,0,0,22,21,0,0,0,6,22,0,0,0
0,0,0,0,0,22,21,0,0,0,6,22,0,0,0
0,0,0,0,0,22,21,0,0,0,6,22,0,0,0
0,0,0,0,0,22,21,8,8,8,6,22,0,0,0
0,0,0,0,0,22,22,22,22,22,22,22,0,0,0
0,0,0,0,0,0,0,0,0,0,0,0,0,0,0
0,0,0,0,0,0,0,0,0,0,0,0,0,0,0
0,0,0,0,0,0,0,0,0,0,0,0,0,0,0
:endlayer
layer: 20
0,0,0,0,0,0,0,0,0,0,0,0,0,0,0
0,0,0,0,0,0,0,0,0,0,0,0,0,0,0
0,0,0,0,0,0,0,0,0,0,0,0,0,0,0
0,0,0,0,0,0,0,0,0,0,0,0,0,0,0
0,0,0,0,0,0,0,0,0,0,0,0,0,0,0
0,0,0,0,0,0,0,0,0,0,0,0,0,0,0
0,0,0,0,0,0,0,0,0,0,0,0,0,0,0
0,0,0,0,0,0,0,0,0,0,0,0,0,0,0
0,0,0,0,0,0,0,0,0,0,0,0,0,0,0
0,0,0,0,0,0,0,0,0,0,0,0,0,0,0
0,0,0,0,0,0,0,0,0,0,0,0,0,0,0
0,0,0,0,0,0,0,0,0,0,0,0,0,0,0
0,0,0,0,0,0,0,0,0,0,0,0,0,0,0
0,0,0,0,0,0,0,0,0,0,0,0,0,0,0
0,0,0,0,0,0,0,0,0,0,0,0,0,0,0
0,0,0,0,0,0,0,0,0,0,0,0,0,0,0
0,0,0,0,0,0,0,0,0,0,0,0,0,0,0
0,0,0,0,0,0,0,0,0,0,0,0,0,0,0
0,0,0,0,0,0,0,0,0,0,0,0,0,0,0
0,0,0,0,0,0,0,0,0,0,0,0,0,0,0
0,0,0,0,0,0,0,0,0,0,0,0,0,0,0
0,0,0,0,0,0,0,0,0,0,0,0,0,0,0
0,0,0,0,0,20,0,0,0,0,0,20,0,0,0
0,0,0,0,0,0,22,22,22,22,22,0,0,0,0
0,0,0,0,0,0,22,13,13,6,22,0,0,0,0
0,0,0,0,0,0,22,21,0,6,22,0,0,0,0
0,0,0,0,0,0,22,8,8,8,22,0,0,0,0
0,0,0,0,0,0,22,22,22,22,22,0,0,0,0
0,0,0,0,0,20,0,0,0,0,0,20,0,0,0
0,0,0,0,0,0,0,0,0,0,0,0,0,0,0
0,0,0,0,0,0,0,0,0,0,0,0,0,0,0
0,0,0,0,0,0,0,0,0,0,0,0,0,0,0
:endlayer
layer: 21
0,0,0,0,0,0,0,0,0,0,0,0,0,0,0
0,0,0,0,0,0,0,0,0,0,0,0,0,0,0
0,0,0,0,0,0,0,0,0,0,0,0,0,0,0
0,0,0,0,0,0,0,0,0,0,0,0,0,0,0
0,0,0,0,0,0,0,0,0,0,0,0,0,0,0
0,0,0,0,0,0,0,0,0,0,0,0,0,0,0
0,0,0,0,0,0,0,0,0,0,0,0,0,0,0
0,0,0,0,0,0,0,0,0,0,0,0,0,0,0
0,0,0,0,0,0,0,0,0,0,0,0,0,0,0
0,0,0,0,0,0,0,0,0,0,0,0,0,0,0
0,0,0,0,0,0,0,0,0,0,0,0,0,0,0
0,0,0,0,0,0,0,0,0,0,0,0,0,0,0
0,0,0,0,0,0,0,0,0,0,0,0,0,0,0
0,0,0,0,0,0,0,0,0,0,0,0,0,0,0
0,0,0,0,0,0,0,0,0,0,0,0,0,0,0
0,0,0,0,0,0,0,0,0,0,0,0,0,0,0
0,0,0,0,0,0,0,0,0,0,0,0,0,0,0
0,0,0,0,0,0,0,0,0,0,0,0,0,0,0
0,0,0,0,0,0,0,0,0,0,0,0,0,0,0
0,0,0,0,0,0,0,0,0,0,0,0,0,0,0
0,0,0,0,0,0,0,0,0,0,0,0,0,0,0
0,0,0,0,0,0,0,0,0,0,0,0,0,0,0
0,0,0,0,0,0,0,0,0,0,0,0,0,0,0
0,0,0,0,0,0,0,0,0,0,0,0,0,0,0
0,0,0,0,0,0,0,22,22,22,0,0,0,0,0
0,0,0,0,0,0,0,22,11,22,0,0,0,0,0
0,0,0,0,0,0,0,22,22,22,0,0,0,0,0
0,0,0,0,0,0,0,0,0,0,0,0,0,0,0
0,0,0,0,0,0,0,0,0,0,0,0,0,0,0
0,0,0,0,0,0,0,0,0,0,0,0,0,0,0
0,0,0,0,0,0,0,0,0,0,0,0,0,0,0
0,0,0,0,0,0,0,0,0,0,0,0,0,0,0
:endlayer
layer: 22
0,0,0,0,0,0,0,0,0,0,0,0,0,0,0
0,0,0,0,0,0,0,0,0,0,0,0,0,0,0
0,0,0,0,0,0,0,0,0,0,0,0,0,0,0
0,0,0,0,0,0,0,0,0,0,0,0,0,0,0
0,0,0,0,0,0,0,0,0,0,0,0,0,0,0
0,0,0,0,0,0,0,0,0,0,0,0,0,0,0
0,0,0,0,0,0,0,0,0,0,0,0,0,0,0
0,0,0,0,0,0,0,0,0,0,0,0,0,0,0
0,0,0,0,0,0,0,0,0,0,0,0,0,0,0
0,0,0,0,0,0,0,0,0,0,0,0,0,0,0
0,0,0,0,0,0,0,0,0,0,0,0,0,0,0
0,0,0,0,0,0,0,0,0,0,0,0,0,0,0
0,0,0,0,0,0,0,0,0,0,0,0,0,0,0
0,0,0,0,0,0,0,0,0,0,0,0,0,0,0
0,0,0,0,0,0,0,0,0,0,0,0,0,0,0
0,0,0,0,0,0,0,0,0,0,0,0,0,0,0
0,0,0,0,0,0,0,0,0,0,0,0,0,0,0
0,0,0,0,0,0,0,0,0,0,0,0,0,0,0
0,0,0,0,0,0,0,0,0,0,0,0,0,0,0
0,0,0,0,0,0,0,0,0,0,0,0,0,0,0
0,0,0,0,0,0,0,0,0,0,0,0,0,0,0
0,0,0,0,0,0,0,0,0,0,0,0,0,0,0
0,0,0,0,0,0,0,0,0,0,0,0,0,0,0
0,0,0,0,0,0,0,0,0,0,0,0,0,0,0
0,0,0,0,0,0,0,20,0,20,0,0,0,0,0
0,0,0,0,0,0,0,0,22,0,0,0,0,0,0
0,0,0,0,0,0,0,20,0,20,0,0,0,0,0
0,0,0,0,0,0,0,0,0,0,0,0,0,0,0
0,0,0,0,0,0,0,0,0,0,0,0,0,0,0
0,0,0,0,0,0,0,0,0,0,0,0,0,0,0
0,0,0,0,0,0,0,0,0,0,0,0,0,0,0
0,0,0,0,0,0,0,0,0,0,0,0,0,0,0
:endlayer

#### RULES ####
rule:
plugin=vanillaBlocks
number=1
data:
JSON:{blockState:{blockName:"minecraft:stonebrick",properties:{variant:"stonebrick"}}}
:enddata
:endrule

rule:
plugin=vanillaBlocks
number=2
data:
JSON:{blockState:{blockName:"minecraft:cobblestone"}}
:enddata
:endrule

rule:
plugin=vanillaBlocks
number=3
data:
JSON:{blockState:{blockName:"minecraft:grass",properties:{snowy:"false"}}}
:enddata
:endrule

rule:
plugin=vanillaBlocks
number=4
data:
JSON:{blockState:{blockName:"minecraft:dirt",properties:{variant:"dirt",snowy:"false"}}}
:enddata
:endrule

rule:
plugin=vanillaBlocks
number=5
data:
JSON:{blockState:{blockName:"biomesoplenty:log_2",properties:{variant:"pine",axis:"y"}}}
:enddata
:endrule

rule:
plugin=vanillaBlocks
number=6
data:
JSON:{blockState:{blockName:"biomesoplenty:pine_stairs",properties:{half:"top",shape:"straight",facing:"east"}}}
:enddata
:endrule

rule:
plugin=vanillaBlocks
number=7
data:
JSON:{blockState:{blockName:"biomesoplenty:pine_stairs",properties:{half:"bottom",shape:"straight",facing:"north"}}}
:enddata
:endrule

rule:
plugin=vanillaBlocks
number=8
data:
JSON:{blockState:{blockName:"biomesoplenty:pine_stairs",properties:{half:"top",shape:"straight",facing:"south"}}}
:enddata
:endrule

rule:
plugin=vanillaBlocks
number=9
data:
JSON:{blockState:{blockName:"biomesoplenty:pine_fence",properties:{east:"false",south:"false",north:"false",west:"false"}}}
:enddata
:endrule

rule:
plugin=vanillaBlocks
number=10
data:
JSON:{blockState:{blockName:"minecraft:torch",properties:{facing:"west"}}}
:enddata
:endrule

rule:
plugin=vanillaBlocks
number=11
data:
JSON:{blockState:{blockName:"biomesoplenty:planks_0",properties:{variant:"pine"}}}
:enddata
:endrule

rule:
plugin=vanillaBlocks
number=12
data:
JSON:{blockState:{blockName:"biomesoplenty:wood_slab_1",properties:{half:"top",variant:"pine"}}}
:enddata
:endrule

rule:
plugin=vanillaBlocks
number=13
data:
JSON:{blockState:{blockName:"biomesoplenty:pine_stairs",properties:{half:"top",shape:"straight",facing:"north"}}}
:enddata
:endrule

rule:
plugin=vanillaBlocks
number=14
data:
JSON:{blockState:{blockName:"biomesoplenty:log_2",properties:{variant:"pine",axis:"x"}}}
:enddata
:endrule

rule:
plugin=vanillaBlocks
number=15
data:
JSON:{blockState:{blockName:"biomesoplenty:log_2",properties:{variant:"pine",axis:"z"}}}
:enddata
:endrule

rule:
plugin=vanillaBlocks
number=16
data:
JSON:{blockState:{blockName:"minecraft:torch",properties:{facing:"north"}}}
:enddata
:endrule

rule:
plugin=vanillaBlocks
number=17
data:
JSON:{blockState:{blockName:"minecraft:torch",properties:{facing:"south"}}}
:enddata
:endrule

rule:
plugin=vanillaBlocks
number=18
data:
JSON:{blockState:{blockName:"biomesoplenty:pine_stairs",properties:{half:"bottom",shape:"straight",facing:"south"}}}
:enddata
:endrule

rule:
plugin=vanillaBlocks
number=19
data:
JSON:{blockState:{blockName:"minecraft:torch",properties:{facing:"east"}}}
:enddata
:endrule

rule:
plugin=vanillaBlocks
number=20
data:
JSON:{blockState:{blockName:"minecraft:torch",properties:{facing:"up"}}}
:enddata
:endrule

rule:
plugin=vanillaBlocks
number=21
data:
JSON:{blockState:{blockName:"biomesoplenty:pine_stairs",properties:{half:"top",shape:"straight",facing:"west"}}}
:enddata
:endrule

rule:
plugin=vanillaBlocks
number=22
data:
JSON:{blockState:{blockName:"minecraft:wool",properties:{color:"brown"}}}
:enddata
:endrule

rule:
plugin=vanillaBlocks
number=23
data:
JSON:{blockState:{blockName:"minecraft:ladder",properties:{facing:"north"}}}
:enddata
:endrule

rule:
plugin=vanillaBlocks
number=24
data:
JSON:{blockState:{blockName:"biomesoplenty:pine_stairs",properties:{half:"bottom",shape:"straight",facing:"west"}}}
:enddata
:endrule

#### ENTITIES ####
