# Ancient Warfare Structure Template File
# Auto-generated structure template file. created on: 9/23/2023 at: 20:42:54
# Lines beginning with # denote comments

header:
version=2.11
name=SB_KievarusCol_House_1H3R_3_palm
mods=biomesoplenty
size=23,16,13
offset=11,1,12
:endheader

#### VALIDATION ####
validation:
type=ground
structureAuthor=TheOddlySeagull
survival=true
worldGenEnabled=false
unique=false
preserveBlocks=false
preventNaturalHostileSpawns=false
selectionWeight=1
clusterValue=1
minDuplicateDistance=1
dimensionWhiteList=true
dimensionList=
biomeGroupList=
biomeWhiteList=true
biomeList=
leveling=0
fill=0
border=0
blockSwap=false
territoryName=
biomeReplacement=minecraft:
minGenerationHeight=0
maxGenerationHeight=255
:endvalidation

#### LAYERS ####
layer: 0
1,1,1,1,1,2,1,1,1,2,1,1,1,2,1,1,1,2,1,1,1,1,1
1,1,1,1,2,2,2,2,2,2,2,2,2,2,2,2,2,2,2,1,1,1,1
1,1,1,1,1,2,2,2,2,3,2,3,3,2,3,2,2,2,1,1,1,1,1
1,1,1,1,1,2,2,2,2,3,3,3,3,3,2,2,3,2,1,1,1,1,1
1,2,2,2,2,2,3,3,3,3,3,2,2,2,3,3,2,2,2,2,2,2,1
1,2,2,2,2,2,2,2,2,2,2,2,2,3,3,3,3,2,2,2,2,2,1
1,2,2,2,2,2,2,3,2,2,2,2,3,3,2,3,3,2,2,2,2,2,1
1,2,2,2,2,2,2,2,3,2,2,3,3,3,3,2,2,2,2,2,2,2,1
1,2,2,2,2,2,3,2,3,2,3,2,3,2,2,3,2,2,2,2,2,2,1
1,1,1,1,1,2,3,2,2,3,3,3,2,2,2,2,3,2,1,1,1,1,1
1,1,1,1,1,2,2,2,2,2,3,3,3,3,3,3,3,2,1,1,1,1,1
1,1,1,1,2,2,2,2,2,2,2,2,2,2,2,2,2,2,2,1,1,1,1
1,1,1,1,1,2,1,1,1,2,1,1,1,2,1,1,1,2,1,1,1,1,1
:endlayer
layer: 1
0,0,0,0,0,4,0,0,0,4,0,0,0,4,0,0,0,4,0,0,0,0,0
0,0,0,0,4,4,0,0,0,4,0,0,0,4,0,0,0,4,4,0,0,0,0
0,0,0,0,0,5,0,0,0,0,0,0,0,0,0,0,0,5,0,0,0,0,0
0,0,0,0,0,5,0,0,0,0,0,0,0,0,0,0,0,5,0,0,0,0,0
0,4,5,5,5,4,0,0,0,0,0,0,0,0,0,0,0,4,5,5,5,4,0
0,5,5,5,5,6,0,0,0,0,0,0,0,0,0,0,0,8,5,5,5,5,0
0,5,5,4,5,6,0,0,0,0,0,7,0,0,0,0,0,8,5,4,5,5,0
0,5,5,5,5,6,0,0,0,0,0,0,0,0,0,0,0,8,5,5,5,5,0
0,4,5,5,5,4,0,0,0,0,0,0,0,0,0,0,0,4,5,5,5,4,0
0,0,0,0,0,5,0,0,0,0,0,0,0,0,0,0,0,5,0,0,0,0,0
0,0,0,0,0,5,0,0,0,0,0,0,0,0,0,0,0,5,0,0,0,0,0
0,0,0,0,4,4,0,0,0,4,0,0,0,4,0,0,0,4,4,0,0,0,0
0,0,0,0,0,4,0,0,0,4,0,0,0,4,0,0,0,4,0,0,0,0,0
:endlayer
layer: 2
0,0,0,0,0,4,0,0,0,4,0,0,0,4,0,0,0,4,0,0,0,0,0
0,0,0,0,4,4,0,0,0,4,0,0,0,4,0,0,0,4,4,0,0,0,0
0,0,0,0,0,5,0,0,0,0,0,0,0,0,0,0,0,5,0,0,0,0,0
0,0,0,0,0,5,0,0,0,0,0,0,0,0,0,0,0,5,0,0,0,0,0
0,4,10,10,10,4,0,0,0,0,0,0,0,0,0,0,0,4,10,10,10,4,0
0,9,0,0,0,0,0,0,0,0,0,0,0,0,0,0,0,0,13,12,0,9,0
0,9,11,4,0,0,0,0,0,0,0,0,0,0,0,0,0,0,0,4,14,9,0
0,9,0,12,13,0,0,0,0,0,0,0,0,0,0,0,0,0,0,0,0,9,0
0,4,10,10,10,4,0,0,0,0,0,0,0,0,0,0,0,4,10,10,10,4,0
0,0,0,0,0,5,0,0,0,0,0,0,0,0,0,0,0,5,0,0,0,0,0
0,0,0,0,0,5,0,0,0,0,0,0,0,0,0,0,0,5,0,0,0,0,0
0,0,0,0,4,4,0,0,0,4,0,0,0,4,0,0,0,4,4,0,0,0,0
0,0,0,0,0,4,0,0,0,4,0,0,0,4,0,0,0,4,0,0,0,0,0
:endlayer
layer: 3
0,0,0,0,11,4,0,0,0,4,0,0,0,4,0,0,0,4,14,0,0,0,0
0,0,0,0,4,4,0,0,0,4,0,0,0,4,0,0,0,4,4,0,0,0,0
0,0,0,0,0,5,0,0,0,15,0,0,0,15,0,0,0,5,0,0,0,0,0
0,16,0,0,0,5,0,0,0,0,0,0,0,0,0,0,0,5,0,0,0,16,0
11,4,5,5,5,4,14,0,0,0,0,0,0,0,0,0,11,4,5,5,5,4,14
0,5,0,16,0,0,0,0,0,0,0,0,0,0,0,0,0,0,0,0,13,5,0
0,5,12,4,0,0,0,0,0,0,0,0,0,0,0,0,0,0,0,4,12,5,0
0,5,13,0,0,0,0,0,0,0,0,0,0,0,0,0,0,0,0,15,0,5,0
11,4,5,5,5,4,14,0,0,0,0,0,0,0,0,0,11,4,5,5,5,4,14
0,15,0,0,0,5,0,0,0,0,0,0,0,0,0,0,0,5,0,0,0,15,0
0,0,0,0,0,5,0,0,0,16,0,0,0,16,0,0,0,5,0,0,0,0,0
0,0,0,0,4,4,0,0,0,4,0,0,0,4,0,0,0,4,4,0,0,0,0
0,0,0,0,11,4,0,0,0,4,0,0,0,4,0,0,0,4,14,0,0,0,0
:endlayer
layer: 4
0,0,0,0,0,4,0,0,0,4,0,0,0,4,0,0,0,4,0,0,0,0,0
0,0,0,0,4,4,17,12,18,4,17,12,18,4,17,12,18,4,4,0,0,0,0
0,0,0,0,0,5,0,0,0,12,0,0,0,12,0,0,0,5,0,0,0,0,0
0,0,0,0,0,5,0,0,0,12,0,0,0,12,0,0,0,5,0,0,0,0,0
0,4,5,5,5,4,0,0,0,0,0,0,0,0,0,0,0,4,5,5,5,4,0
0,5,13,12,0,12,0,0,0,0,0,0,0,0,0,0,0,12,0,0,0,5,0
0,5,0,4,14,12,0,0,0,0,0,0,0,0,0,0,0,12,11,4,0,5,0
0,5,0,0,0,12,0,0,0,0,0,0,0,0,0,0,0,12,0,12,13,5,0
0,4,5,5,5,4,0,0,0,0,0,0,0,0,0,0,0,4,5,5,5,4,0
0,0,0,0,0,5,0,0,0,12,0,0,0,12,0,0,0,5,0,0,0,0,0
0,0,0,0,0,5,0,0,0,12,0,0,0,12,0,0,0,5,0,0,0,0,0
0,0,0,0,4,4,17,12,18,4,17,12,18,4,17,12,18,4,4,0,0,0,0
0,0,0,0,0,4,0,0,0,4,0,0,0,4,0,0,0,4,0,0,0,0,0
:endlayer
layer: 5
0,0,0,0,0,4,0,0,0,4,0,0,0,4,0,0,0,4,0,0,0,0,0
0,0,0,0,8,4,10,10,10,10,10,10,10,10,10,10,10,4,6,0,0,0,0
0,0,0,0,0,9,12,5,12,5,12,5,12,5,12,5,12,9,0,0,0,0,0
0,0,0,0,0,9,12,5,12,5,12,5,12,5,12,5,12,9,0,0,0,0,0
0,4,10,10,10,4,12,5,12,5,12,5,12,5,12,5,12,4,10,10,10,4,0
0,9,0,0,13,9,12,5,12,5,12,5,12,5,12,5,12,9,12,16,0,9,0
0,9,0,4,12,9,12,5,12,5,12,5,12,5,12,5,12,9,12,4,0,9,0
0,9,0,15,12,9,12,5,12,5,12,5,12,5,12,5,12,9,13,0,0,9,0
0,4,10,10,10,4,12,5,12,5,12,5,12,5,12,5,12,4,10,10,10,4,0
0,0,0,0,0,9,12,5,12,5,12,5,12,5,12,5,12,9,0,0,0,0,0
0,0,0,0,0,9,12,5,12,5,12,5,12,5,12,5,12,9,0,0,0,0,0
0,0,0,0,8,4,10,10,10,10,10,10,10,10,10,10,10,4,6,0,0,0,0
0,0,0,0,0,4,0,0,0,4,0,0,0,4,0,0,0,4,0,0,0,0,0
:endlayer
layer: 6
0,0,0,0,0,4,0,0,0,4,0,0,0,4,0,0,0,4,0,0,0,0,0
0,0,0,0,0,4,5,5,5,4,5,5,5,4,5,5,5,4,0,0,0,0,0
0,0,0,0,0,5,0,0,0,0,0,0,0,0,0,0,0,5,0,0,0,0,0
0,0,0,0,0,5,0,0,0,0,0,0,0,0,0,0,0,5,0,0,0,0,0
0,4,5,5,5,4,0,0,0,4,0,0,0,4,0,0,0,4,5,5,5,4,0
0,5,0,0,0,0,0,0,0,5,0,0,0,5,0,0,0,0,0,19,0,5,0
0,5,11,4,0,0,0,0,0,5,0,0,0,5,0,0,0,0,0,4,14,5,0
0,5,0,19,0,0,0,0,0,5,0,0,0,5,0,0,0,0,0,0,0,5,0
0,4,5,5,5,4,5,5,5,4,0,0,0,4,21,0,0,4,5,5,5,4,0
0,0,0,0,0,5,0,0,0,0,0,0,0,5,20,0,0,5,0,0,0,0,0
0,0,0,0,0,5,0,0,0,0,0,0,0,5,0,0,0,5,0,0,0,0,0
0,0,0,0,0,4,5,5,5,4,5,5,5,4,5,5,5,4,0,0,0,0,0
0,0,0,0,0,4,0,0,0,4,0,0,0,4,0,0,0,4,0,0,0,0,0
:endlayer
layer: 7
0,0,0,0,0,4,0,0,0,4,0,0,0,4,0,0,0,4,0,0,0,0,0
0,0,0,0,0,4,5,19,5,4,5,19,5,4,5,19,5,4,0,0,0,0,0
0,0,0,0,0,5,0,0,0,0,0,0,0,0,0,0,0,5,0,0,0,0,0
0,0,0,0,0,5,0,0,0,0,0,0,0,0,0,0,0,5,0,0,0,0,0
0,4,5,19,5,4,0,0,0,4,0,0,0,4,0,0,0,4,5,19,5,4,0
0,5,0,16,0,0,0,0,0,5,0,0,0,5,0,0,0,0,0,0,0,5,0
0,19,0,4,0,0,0,0,0,5,0,0,0,5,0,0,0,0,0,4,0,19,0
0,5,0,0,0,0,0,0,0,5,0,0,0,5,21,0,0,0,0,15,0,5,0
0,4,5,19,5,4,5,5,5,4,0,0,0,4,20,0,0,4,5,19,5,4,0
0,0,0,0,0,5,0,0,0,0,0,0,0,5,0,0,0,5,0,0,0,0,0
0,0,0,0,0,5,0,0,0,0,0,0,0,5,0,0,0,5,0,0,0,0,0
0,0,0,0,0,4,5,19,5,4,5,19,5,4,5,19,5,4,0,0,0,0,0
0,0,0,0,0,4,0,0,0,4,0,0,0,4,0,0,0,4,0,0,0,0,0
:endlayer
layer: 8
0,0,0,0,0,4,12,12,12,4,12,12,12,4,12,12,12,4,0,0,0,0,0
0,0,0,0,0,4,5,5,5,4,5,5,5,4,5,5,5,4,0,0,0,0,0
0,0,0,0,0,5,0,0,0,15,0,0,0,15,0,0,0,5,0,0,0,0,0
0,0,0,0,0,5,0,0,0,0,0,0,0,0,0,0,0,5,0,0,0,0,0
0,4,5,5,5,4,17,12,18,4,17,12,18,4,17,12,18,4,5,5,5,4,0
0,5,0,0,0,22,0,0,0,5,0,0,0,5,0,0,0,22,0,0,0,5,0
0,5,0,4,14,12,0,0,0,5,0,0,0,5,21,0,0,12,11,4,0,5,0
0,5,0,0,0,21,0,0,0,5,0,0,0,5,20,0,0,21,0,0,0,5,0
0,4,5,5,5,4,5,5,5,4,14,0,11,4,0,0,11,4,5,5,5,4,0
0,0,0,0,0,5,0,0,0,0,0,0,0,5,0,0,0,5,0,0,0,0,0
0,0,0,0,0,5,0,0,0,16,0,0,0,5,0,0,0,5,0,0,0,0,0
0,0,0,0,0,4,5,5,5,4,5,5,5,4,5,5,5,4,0,0,0,0,0
0,0,0,0,0,4,12,12,12,4,12,12,12,4,12,12,12,4,0,0,0,0,0
:endlayer
layer: 9
0,0,0,0,23,23,23,23,23,23,23,23,23,23,23,23,23,23,23,0,0,0,0
0,0,0,0,0,4,10,10,10,10,10,10,10,10,10,10,10,4,0,0,0,0,0
0,0,0,0,0,9,12,5,12,9,12,5,12,9,12,5,12,9,0,0,0,0,0
23,23,23,23,23,9,12,5,12,9,12,5,12,9,12,5,12,9,23,23,23,23,23
12,4,10,10,10,9,10,10,10,10,10,10,10,10,10,10,10,9,10,10,10,4,12
0,9,0,0,0,9,12,5,12,9,12,5,12,9,21,5,12,9,0,16,0,9,0
0,9,0,4,0,9,12,5,12,9,12,5,12,9,20,5,12,9,0,4,0,9,0
0,9,0,15,0,9,12,5,12,9,12,5,12,9,0,5,12,9,0,0,0,9,0
12,4,10,10,10,9,10,10,10,10,10,10,10,9,0,5,12,9,10,10,10,4,12
23,23,23,23,23,9,12,5,12,9,12,5,12,9,0,5,12,9,23,23,23,23,23
0,0,0,0,0,9,12,5,12,9,12,5,12,9,0,5,12,9,0,0,0,0,0
0,0,0,0,0,4,10,10,10,10,10,10,10,10,10,10,10,4,0,0,0,0,0
0,0,0,0,23,23,23,23,23,23,23,23,23,23,23,23,23,23,23,0,0,0,0
:endlayer
layer: 10
0,0,0,0,0,0,0,0,0,0,0,0,0,0,0,0,0,0,0,0,0,0,0
0,0,0,0,23,23,23,23,23,23,23,23,23,23,23,23,23,23,23,0,0,0,0
0,0,0,0,0,5,0,0,0,5,0,0,0,5,0,0,0,5,0,0,0,0,0
0,0,0,0,0,5,0,0,0,5,0,0,0,5,0,0,0,5,0,0,0,0,0
23,23,23,23,23,5,0,0,0,4,0,0,0,4,0,0,0,5,23,23,23,23,23
22,5,0,0,0,5,0,0,0,0,0,0,0,0,0,0,0,5,0,0,0,5,22
12,5,11,4,0,5,0,0,0,0,0,0,0,0,0,0,0,5,0,4,14,5,12
21,5,0,0,0,5,0,0,0,0,0,0,0,0,0,0,0,5,0,0,0,5,21
23,23,23,23,23,5,0,0,0,4,0,0,0,4,0,0,0,5,23,23,23,23,23
0,0,0,0,0,5,0,0,0,5,0,0,0,5,0,0,0,5,0,0,0,0,0
0,0,0,0,0,5,0,0,0,5,0,0,0,5,0,0,0,5,0,0,0,0,0
0,0,0,0,23,23,23,23,23,23,23,23,23,23,23,23,23,23,23,0,0,0,0
0,0,0,0,0,0,0,0,0,0,0,0,0,0,0,0,0,0,0,0,0,0,0
:endlayer
layer: 11
0,0,0,0,0,0,0,0,0,0,0,0,0,0,0,0,0,0,0,0,0,0,0
0,0,0,0,0,0,0,0,0,0,0,0,0,0,0,0,0,0,0,0,0,0,0
0,0,0,0,23,23,23,23,23,23,23,23,23,23,23,23,23,23,23,0,0,0,0
0,0,0,0,0,5,0,0,0,5,0,0,0,5,0,0,0,5,0,0,0,0,0
0,0,7,0,0,19,0,0,0,4,0,0,0,4,0,0,0,19,0,0,7,0,0
23,23,23,23,23,5,0,0,0,0,0,0,0,0,0,0,0,5,23,23,23,23,23
19,5,10,10,10,5,0,0,0,0,0,0,0,0,0,0,0,5,10,10,10,5,19
23,23,23,23,23,5,0,0,0,0,0,0,0,0,0,0,0,5,23,23,23,23,23
0,0,7,0,0,19,0,0,0,4,0,0,0,4,0,0,0,19,0,0,7,0,0
0,0,0,0,0,5,0,0,0,5,0,0,0,5,0,0,0,5,0,0,0,0,0
0,0,0,0,23,23,23,23,23,23,23,23,23,23,23,23,23,23,23,0,0,0,0
0,0,0,0,0,0,0,0,0,0,0,0,0,0,0,0,0,0,0,0,0,0,0
0,0,0,0,0,0,0,0,0,0,0,0,0,0,0,0,0,0,0,0,0,0,0
:endlayer
layer: 12
0,0,0,0,0,0,0,0,0,0,0,0,0,0,0,0,0,0,0,0,0,0,0
0,0,0,0,0,0,0,0,0,0,0,0,0,0,0,0,0,0,0,0,0,0,0
0,0,0,0,0,0,7,0,0,0,0,7,0,0,0,0,7,0,0,0,0,0,0
0,0,0,0,23,23,23,23,23,23,23,23,23,23,23,23,23,23,23,0,0,0,0
0,0,0,0,0,5,0,0,11,4,14,0,11,4,14,0,0,5,0,0,0,0,0
0,0,0,0,0,5,0,0,0,22,0,0,0,22,0,0,0,5,0,0,0,0,0
23,23,23,23,23,5,0,0,0,12,0,0,0,12,0,0,0,5,23,23,23,23,23
0,0,0,0,0,5,0,0,0,21,0,0,0,21,0,0,0,5,0,0,0,0,0
0,0,0,0,0,5,0,0,11,4,14,0,11,4,14,0,0,5,0,0,0,0,0
0,0,0,0,23,23,23,23,23,23,23,23,23,23,23,23,23,23,23,0,0,0,0
0,0,0,0,0,0,7,0,0,0,0,7,0,0,0,0,7,0,0,0,0,0,0
0,0,0,0,0,0,0,0,0,0,0,0,0,0,0,0,0,0,0,0,0,0,0
0,0,0,0,0,0,0,0,0,0,0,0,0,0,0,0,0,0,0,0,0,0,0
:endlayer
layer: 13
0,0,0,0,0,0,0,0,0,0,0,0,0,0,0,0,0,0,0,0,0,0,0
0,0,0,0,0,0,0,0,0,0,0,0,0,0,0,0,0,0,0,0,0,0,0
0,0,0,0,0,0,0,0,0,0,0,0,0,0,0,0,0,0,0,0,0,0,0
0,0,0,0,0,0,0,0,0,0,0,0,0,0,0,0,0,0,0,0,0,0,0
0,0,0,0,23,23,23,23,23,23,23,23,23,23,23,23,23,23,23,0,0,0,0
0,0,0,0,0,5,0,0,0,9,0,0,0,9,0,0,0,5,0,0,0,0,0
0,0,7,0,0,19,0,0,0,9,0,0,0,9,0,0,0,19,0,0,7,0,0
0,0,0,0,0,5,0,0,0,9,0,0,0,9,0,0,0,5,0,0,0,0,0
0,0,0,0,23,23,23,23,23,23,23,23,23,23,23,23,23,23,23,0,0,0,0
0,0,0,0,0,0,0,0,0,0,0,0,0,0,0,0,0,0,0,0,0,0,0
0,0,0,0,0,0,0,0,0,0,0,0,0,0,0,0,0,0,0,0,0,0,0
0,0,0,0,0,0,0,0,0,0,0,0,0,0,0,0,0,0,0,0,0,0,0
0,0,0,0,0,0,0,0,0,0,0,0,0,0,0,0,0,0,0,0,0,0,0
:endlayer
layer: 14
0,0,0,0,0,0,0,0,0,0,0,0,0,0,0,0,0,0,0,0,0,0,0
0,0,0,0,0,0,0,0,0,0,0,0,0,0,0,0,0,0,0,0,0,0,0
0,0,0,0,0,0,0,0,0,0,0,0,0,0,0,0,0,0,0,0,0,0,0
0,0,0,0,0,0,0,0,0,0,0,0,0,0,0,0,0,0,0,0,0,0,0
0,0,0,0,0,0,0,0,0,0,0,0,0,0,0,0,0,0,0,0,0,0,0
0,0,0,0,23,23,23,23,23,23,23,23,23,23,23,23,23,23,23,0,0,0,0
0,0,0,0,0,5,0,0,0,5,0,0,0,5,0,0,0,5,0,0,0,0,0
0,0,0,0,23,23,23,23,23,23,23,23,23,23,23,23,23,23,23,0,0,0,0
0,0,0,0,0,0,0,0,0,0,0,0,0,0,0,0,0,0,0,0,0,0,0
0,0,0,0,0,0,0,0,0,0,0,0,0,0,0,0,0,0,0,0,0,0,0
0,0,0,0,0,0,0,0,0,0,0,0,0,0,0,0,0,0,0,0,0,0,0
0,0,0,0,0,0,0,0,0,0,0,0,0,0,0,0,0,0,0,0,0,0,0
0,0,0,0,0,0,0,0,0,0,0,0,0,0,0,0,0,0,0,0,0,0,0
:endlayer
layer: 15
0,0,0,0,0,0,0,0,0,0,0,0,0,0,0,0,0,0,0,0,0,0,0
0,0,0,0,0,0,0,0,0,0,0,0,0,0,0,0,0,0,0,0,0,0,0
0,0,0,0,0,0,0,0,0,0,0,0,0,0,0,0,0,0,0,0,0,0,0
0,0,0,0,0,0,0,0,0,0,0,0,0,0,0,0,0,0,0,0,0,0,0
0,0,0,0,0,0,0,0,0,0,0,0,0,0,0,0,0,0,0,0,0,0,0
0,0,0,0,0,0,7,0,0,0,0,7,0,0,0,0,7,0,0,0,0,0,0
0,0,0,0,23,23,23,23,23,23,23,23,23,23,23,23,23,23,23,0,0,0,0
0,0,0,0,0,0,7,0,0,0,0,7,0,0,0,0,7,0,0,0,0,0,0
0,0,0,0,0,0,0,0,0,0,0,0,0,0,0,0,0,0,0,0,0,0,0
0,0,0,0,0,0,0,0,0,0,0,0,0,0,0,0,0,0,0,0,0,0,0
0,0,0,0,0,0,0,0,0,0,0,0,0,0,0,0,0,0,0,0,0,0,0
0,0,0,0,0,0,0,0,0,0,0,0,0,0,0,0,0,0,0,0,0,0,0
0,0,0,0,0,0,0,0,0,0,0,0,0,0,0,0,0,0,0,0,0,0,0
:endlayer

#### RULES ####
rule:
plugin=vanillaBlocks
number=1
data:
JSON:{blockState:{blockName:"minecraft:grass",properties:{snowy:"false"}}}
:enddata
:endrule

rule:
plugin=vanillaBlocks
number=2
data:
JSON:{blockState:{blockName:"minecraft:cobblestone"}}
:enddata
:endrule

rule:
plugin=vanillaBlocks
number=3
data:
JSON:{blockState:{blockName:"minecraft:gravel"}}
:enddata
:endrule

rule:
plugin=vanillaBlocks
number=4
data:
JSON:{blockState:{blockName:"biomesoplenty:log_1",properties:{variant:"palm",axis:"y"}}}
:enddata
:endrule

rule:
plugin=vanillaBlocks
number=5
data:
JSON:{blockState:{blockName:"biomesoplenty:planks_0",properties:{variant:"palm"}}}
:enddata
:endrule

rule:
plugin=vanillaBlocks
number=6
data:
JSON:{blockState:{blockName:"biomesoplenty:palm_stairs",properties:{half:"bottom",shape:"straight",facing:"west"}}}
:enddata
:endrule

rule:
plugin=vanillaBlocks
number=7
data:
JSON:{blockState:{blockName:"minecraft:torch",properties:{facing:"up"}}}
:enddata
:endrule

rule:
plugin=vanillaBlocks
number=8
data:
JSON:{blockState:{blockName:"biomesoplenty:palm_stairs",properties:{half:"bottom",shape:"straight",facing:"east"}}}
:enddata
:endrule

rule:
plugin=vanillaBlocks
number=9
data:
JSON:{blockState:{blockName:"biomesoplenty:log_1",properties:{variant:"palm",axis:"z"}}}
:enddata
:endrule

rule:
plugin=vanillaBlocks
number=10
data:
JSON:{blockState:{blockName:"biomesoplenty:log_1",properties:{variant:"palm",axis:"x"}}}
:enddata
:endrule

rule:
plugin=vanillaBlocks
number=11
data:
JSON:{blockState:{blockName:"minecraft:torch",properties:{facing:"west"}}}
:enddata
:endrule

rule:
plugin=vanillaBlocks
number=12
data:
JSON:{blockState:{blockName:"biomesoplenty:wood_slab_0",properties:{half:"top",variant:"palm"}}}
:enddata
:endrule

rule:
plugin=vanillaBlocks
number=13
data:
JSON:{blockState:{blockName:"biomesoplenty:wood_slab_0",properties:{half:"bottom",variant:"palm"}}}
:enddata
:endrule

rule:
plugin=vanillaBlocks
number=14
data:
JSON:{blockState:{blockName:"minecraft:torch",properties:{facing:"east"}}}
:enddata
:endrule

rule:
plugin=vanillaBlocks
number=15
data:
JSON:{blockState:{blockName:"minecraft:torch",properties:{facing:"south"}}}
:enddata
:endrule

rule:
plugin=vanillaBlocks
number=16
data:
JSON:{blockState:{blockName:"minecraft:torch",properties:{facing:"north"}}}
:enddata
:endrule

rule:
plugin=vanillaBlocks
number=17
data:
JSON:{blockState:{blockName:"biomesoplenty:palm_stairs",properties:{half:"top",shape:"straight",facing:"west"}}}
:enddata
:endrule

rule:
plugin=vanillaBlocks
number=18
data:
JSON:{blockState:{blockName:"biomesoplenty:palm_stairs",properties:{half:"top",shape:"straight",facing:"east"}}}
:enddata
:endrule

rule:
plugin=vanillaBlocks
number=19
data:
JSON:{blockState:{blockName:"biomesoplenty:palm_fence",properties:{east:"false",south:"false",north:"false",west:"false"}}}
:enddata
:endrule

rule:
plugin=vanillaBlocks
number=20
data:
JSON:{blockState:{blockName:"biomesoplenty:palm_stairs",properties:{half:"bottom",shape:"straight",facing:"north"}}}
:enddata
:endrule

rule:
plugin=vanillaBlocks
number=21
data:
JSON:{blockState:{blockName:"biomesoplenty:palm_stairs",properties:{half:"top",shape:"straight",facing:"south"}}}
:enddata
:endrule

rule:
plugin=vanillaBlocks
number=22
data:
JSON:{blockState:{blockName:"biomesoplenty:palm_stairs",properties:{half:"top",shape:"straight",facing:"north"}}}
:enddata
:endrule

rule:
plugin=vanillaBlocks
number=23
data:
JSON:{blockState:{blockName:"minecraft:wool",properties:{color:"brown"}}}
:enddata
:endrule

#### ENTITIES ####
