# Ancient Warfare Structure Template File
# Auto-generated structure template file. created on: 5/7/2021 at: 11:47:32
# Lines beginning with # denote comments

header:
version=2.11
name=SurvivalBuild_RuralLife_Res_WoodenFortifiedHouse_darkoak
mods=
size=23,9,16
offset=11,1,15
:endheader

#### VALIDATION ####
validation:
type=ground
structureAuthor=TheOddlySeagull
survival=true
worldGenEnabled=false
unique=false
preserveBlocks=false
preventNaturalHostileSpawns=false
selectionWeight=1
clusterValue=1
minDuplicateDistance=1
dimensionWhiteList=true
dimensionList=
biomeGroupList=
biomeWhiteList=true
biomeList=
leveling=0
fill=0
border=0
blockSwap=false
territoryName=
biomeReplacement=minecraft:
minGenerationHeight=0
maxGenerationHeight=255
:endvalidation

#### LAYERS ####
layer: 0
1,1,1,1,1,1,1,1,1,2,1,1,2,1,1,2,1,1,1,1,1,1,1
1,1,2,3,3,3,2,4,4,4,4,4,4,4,4,2,3,3,3,3,2,1,1
1,1,3,1,1,1,5,6,6,5,6,6,6,6,6,5,1,1,1,1,3,1,1
1,1,3,1,1,1,5,6,6,5,6,6,6,6,6,5,1,1,1,1,3,1,1
1,1,3,1,1,1,2,4,4,2,6,6,6,6,6,5,1,1,1,1,3,1,1
1,1,3,1,1,1,1,1,1,5,6,6,6,6,6,5,1,1,1,1,3,1,1
1,3,3,1,1,1,1,1,1,5,6,6,6,6,6,5,1,1,1,1,3,3,1
1,3,3,1,1,1,1,1,1,2,4,4,4,4,4,2,1,1,1,1,3,3,1
1,3,3,1,1,1,1,1,1,1,1,1,1,1,1,1,1,1,1,1,3,3,1
1,3,3,1,1,1,1,1,1,1,1,1,1,1,1,1,1,1,1,1,3,3,1
1,1,3,1,1,1,1,1,1,1,1,1,1,1,1,1,1,1,1,1,3,1,1
1,1,3,1,1,1,1,1,1,1,1,1,1,1,1,1,1,1,1,1,3,1,1
1,1,3,1,1,1,1,1,1,1,1,1,1,1,1,1,1,1,1,1,3,1,1
1,1,3,1,1,1,3,1,1,1,1,1,1,1,1,1,3,1,1,1,3,1,1
1,1,2,3,3,3,3,3,3,2,4,4,4,2,3,3,3,3,3,3,2,1,1
1,1,1,1,1,1,1,1,1,1,1,1,1,1,1,1,1,1,1,1,1,1,1
:endlayer
layer: 1
0,0,0,0,0,0,0,0,0,2,0,0,2,0,0,2,0,0,0,0,0,0,0
0,0,2,3,3,3,2,3,3,2,3,3,2,3,3,2,3,3,3,3,2,0,0
0,0,3,0,0,0,3,0,0,0,0,0,0,0,0,3,0,0,0,0,3,0,0
0,0,3,0,0,0,3,0,0,0,0,0,0,0,0,3,0,0,0,0,3,0,0
0,0,3,0,0,0,2,3,3,2,0,0,0,0,0,2,0,0,0,0,3,0,0
0,0,3,0,0,0,0,0,0,3,0,0,0,0,0,3,0,0,0,0,3,0,0
0,7,3,0,0,0,0,0,0,3,0,0,0,0,0,3,0,0,0,0,3,7,0
0,3,3,0,0,0,0,0,0,2,0,0,2,3,3,2,0,0,0,0,3,3,0
0,3,3,0,0,0,0,0,0,0,0,0,0,0,0,0,0,0,0,0,3,3,0
0,7,3,0,0,0,0,0,0,0,0,0,0,0,0,0,0,0,0,0,3,7,0
0,0,3,0,0,0,0,0,0,0,0,0,0,0,0,0,0,0,0,0,3,0,0
0,0,3,0,0,0,0,0,0,0,0,0,0,0,0,0,0,0,0,0,3,0,0
0,0,3,0,0,0,0,0,0,0,0,0,0,0,0,0,0,0,0,0,3,0,0
0,0,3,0,6,8,0,0,0,0,0,0,0,0,0,0,0,8,6,0,3,0,0
0,0,2,3,3,3,3,3,3,2,0,0,0,2,3,3,3,3,3,3,2,0,0
0,0,0,0,0,0,0,0,0,0,0,0,0,0,0,0,0,0,0,0,0,0,0
:endlayer
layer: 2
0,0,0,0,0,0,0,0,0,9,0,0,9,0,0,9,0,0,0,0,0,0,0
0,0,2,3,3,3,2,3,3,2,3,3,2,3,3,2,3,3,3,3,2,0,0
0,0,3,6,6,6,3,0,0,0,0,0,0,0,0,7,0,6,6,6,3,0,0
0,0,3,6,0,0,3,0,0,0,0,0,0,0,0,7,0,0,0,6,3,0,0
0,0,3,6,0,0,2,7,7,2,0,0,0,0,0,2,0,0,0,6,3,0,0
0,0,3,6,0,0,0,0,0,3,0,0,0,0,0,3,0,0,0,6,3,0,0
0,7,3,6,0,0,0,0,0,3,0,0,0,0,0,3,0,0,0,6,3,7,0
0,3,3,6,0,0,0,0,0,2,0,0,2,7,7,2,0,0,0,6,3,3,0
0,3,3,6,0,0,0,0,0,0,0,0,0,0,0,0,0,0,0,6,3,3,0
0,7,3,6,0,0,0,0,0,0,0,0,0,0,0,0,0,0,0,6,3,7,0
0,0,3,6,0,0,0,0,0,0,0,0,0,0,0,0,0,0,0,6,3,0,0
0,0,3,6,0,0,0,0,0,0,0,0,0,0,0,0,0,0,0,6,3,0,0
0,0,3,6,0,0,0,0,0,0,0,0,0,0,0,0,0,0,0,6,3,0,0
0,0,3,8,0,0,0,0,0,0,0,0,0,0,0,0,0,0,0,8,3,0,0
0,0,2,3,3,3,3,3,3,2,0,0,0,2,3,3,3,3,3,3,2,0,0
0,0,0,0,0,0,0,0,0,0,0,0,0,0,0,0,0,0,0,0,0,0,0
:endlayer
layer: 3
0,0,0,0,0,0,0,0,0,0,0,0,0,0,0,0,0,0,0,0,0,0,0
0,0,2,8,3,8,2,3,3,2,3,3,2,3,3,2,3,8,3,8,2,0,0
0,0,8,0,0,0,3,0,0,0,0,0,0,0,0,7,0,0,0,0,8,0,0
0,0,3,0,0,0,3,0,0,0,0,0,0,0,0,7,0,0,0,0,3,0,0
0,0,8,0,0,0,2,7,7,2,0,0,0,0,0,2,0,0,0,0,8,0,0
0,0,3,0,0,0,0,0,0,3,0,0,0,0,0,3,0,0,0,0,3,0,0
0,10,3,0,0,0,0,0,0,3,0,0,0,0,0,3,0,0,0,0,3,11,0
10,3,8,0,0,0,0,0,0,2,12,12,2,7,7,2,0,0,0,0,8,3,11
10,3,8,0,0,0,0,0,0,0,0,0,0,0,0,0,0,0,0,0,8,3,11
0,10,3,0,0,0,0,0,0,0,0,0,0,0,0,0,0,0,0,0,3,11,0
0,0,3,0,0,0,0,0,0,0,0,0,0,0,0,0,0,0,0,0,3,0,0
0,0,8,0,0,0,0,0,0,0,0,0,0,0,0,0,0,0,0,0,8,0,0
0,0,3,0,0,0,0,0,0,0,0,0,0,0,0,0,0,0,0,0,3,0,0
0,0,8,0,0,0,0,0,0,0,0,0,0,0,0,0,0,0,0,0,8,0,0
0,0,2,8,3,8,3,8,3,2,0,0,0,2,3,8,3,8,3,8,2,0,0
0,0,0,0,0,0,0,0,0,0,0,0,0,0,0,0,0,0,0,0,0,0,0
:endlayer
layer: 4
0,0,0,0,0,9,9,9,13,11,0,0,0,0,0,10,14,0,0,0,0,0,0
0,0,8,0,8,12,2,4,4,4,4,4,4,4,4,2,14,0,8,0,8,0,0
0,0,0,0,0,0,5,0,0,0,0,0,0,0,0,5,14,0,0,0,0,0,0
0,0,8,0,0,0,5,0,0,0,0,0,0,0,0,5,14,0,0,0,8,0,0
0,0,0,0,0,15,2,4,4,2,0,0,0,0,0,5,14,0,0,0,0,0,0
0,0,8,0,0,16,16,16,16,5,0,0,0,0,0,5,14,0,0,0,8,0,0
0,8,0,0,0,0,0,0,13,5,0,0,0,0,0,5,14,0,0,0,0,8,0
8,0,0,0,0,0,0,0,13,2,4,4,4,4,4,2,14,0,0,0,0,0,8
8,0,0,0,0,0,0,0,13,11,0,0,0,0,0,10,14,0,0,0,0,0,8
0,8,0,0,0,0,0,0,0,0,0,0,0,0,0,0,0,0,0,0,0,8,0
0,0,8,0,0,0,0,0,0,0,0,0,0,0,0,0,0,0,0,0,8,0,0
0,0,0,0,0,0,0,0,0,0,0,0,0,0,0,0,0,0,0,0,0,0,0
0,0,8,0,0,0,0,0,0,0,0,0,0,0,0,0,0,0,0,0,8,0,0
0,0,0,0,0,0,0,0,6,15,6,6,6,15,6,0,0,0,0,0,0,0,0
0,0,8,0,8,0,8,0,3,2,4,4,4,2,3,0,8,0,8,0,8,0,0
0,0,0,0,0,0,0,0,6,12,6,6,6,12,6,0,0,0,0,0,0,0,0
:endlayer
layer: 5
0,0,0,0,0,0,0,0,0,13,11,0,0,0,10,14,0,0,0,0,0,0,0
0,0,0,0,0,9,9,9,9,13,2,3,3,3,2,14,0,0,0,0,0,0,0
0,0,0,0,0,13,3,12,12,12,11,0,0,0,10,14,0,0,0,0,0,0,0
0,0,0,0,0,13,3,15,15,15,11,0,0,0,10,14,0,0,0,0,0,0,0
0,0,0,0,0,16,16,16,16,13,11,0,0,0,10,14,0,0,0,0,0,0,0
0,0,0,0,0,0,0,0,0,13,11,0,0,0,10,14,0,0,0,0,0,0,0
0,0,0,0,0,0,0,0,0,13,11,0,0,0,10,14,0,0,0,0,0,0,0
0,0,0,0,0,0,0,0,0,13,2,3,3,3,2,14,0,0,0,0,0,0,0
0,0,0,0,0,0,0,0,0,13,11,0,0,0,10,14,0,0,0,0,0,0,0
0,0,0,0,0,0,0,0,0,0,0,0,0,0,0,0,0,0,0,0,0,0,0
0,0,0,0,0,0,0,0,0,0,0,0,0,0,0,0,0,0,0,0,0,0,0
0,0,0,0,0,0,0,0,0,0,0,0,0,0,0,0,0,0,0,0,0,0,0
0,0,0,0,0,0,0,0,0,0,0,0,0,0,0,0,0,0,0,0,0,0,0
0,0,0,0,0,0,0,0,0,0,0,0,0,0,0,0,0,0,0,0,0,0,0
0,0,0,0,0,0,0,0,8,8,8,8,8,8,8,0,0,0,0,0,0,0,0
0,0,0,0,0,0,0,0,0,0,0,0,0,0,0,0,0,0,0,0,0,0,0
:endlayer
layer: 6
0,0,0,0,0,0,0,0,0,0,13,11,0,10,14,0,0,0,0,0,0,0,0
0,0,0,0,0,0,0,0,0,0,13,2,3,2,14,0,0,0,0,0,0,0,0
0,0,0,0,0,0,13,9,9,9,9,11,0,10,14,0,0,0,0,0,0,0,0
0,0,0,0,0,0,13,16,16,16,16,11,0,10,14,0,0,0,0,0,0,0,0
0,0,0,0,0,0,0,0,0,0,13,11,0,10,14,0,0,0,0,0,0,0,0
0,0,0,0,0,0,0,0,0,0,13,11,0,10,14,0,0,0,0,0,0,0,0
0,0,0,0,0,0,0,0,0,0,13,11,0,10,14,0,0,0,0,0,0,0,0
0,0,0,0,0,0,0,0,0,0,13,2,3,2,14,0,0,0,0,0,0,0,0
0,0,0,0,0,0,0,0,0,0,13,11,0,10,14,0,0,0,0,0,0,0,0
0,0,0,0,0,0,0,0,0,0,0,0,0,0,0,0,0,0,0,0,0,0,0
0,0,0,0,0,0,0,0,0,0,0,0,0,0,0,0,0,0,0,0,0,0,0
0,0,0,0,0,0,0,0,0,0,0,0,0,0,0,0,0,0,0,0,0,0,0
0,0,0,0,0,0,0,0,0,0,0,0,0,0,0,0,0,0,0,0,0,0,0
0,0,0,0,0,0,0,0,0,0,0,0,0,0,0,0,0,0,0,0,0,0,0
0,0,0,0,0,0,0,0,0,0,0,0,0,0,0,0,0,0,0,0,0,0,0
0,0,0,0,0,0,0,0,0,0,0,0,0,0,0,0,0,0,0,0,0,0,0
:endlayer
layer: 7
0,0,0,0,0,0,0,0,0,0,0,13,9,14,0,0,0,0,0,0,0,0,0
0,0,0,0,0,0,0,0,0,0,0,13,2,14,0,0,0,0,0,0,0,0,0
0,0,0,0,0,0,0,0,0,0,0,13,5,14,0,0,0,0,0,0,0,0,0
0,0,0,0,0,0,0,0,0,0,0,13,5,14,0,0,0,0,0,0,0,0,0
0,0,0,0,0,0,0,0,0,0,0,13,5,14,0,0,0,0,0,0,0,0,0
0,0,0,0,0,0,0,0,0,0,0,13,5,14,0,0,0,0,0,0,0,0,0
0,0,0,0,0,0,0,0,0,0,0,13,5,14,0,0,0,0,0,0,0,0,0
0,0,0,0,0,0,0,0,0,0,0,13,2,14,0,0,0,0,0,0,0,0,0
0,0,0,0,0,0,0,0,0,0,0,13,16,14,0,0,0,0,0,0,0,0,0
0,0,0,0,0,0,0,0,0,0,0,0,0,0,0,0,0,0,0,0,0,0,0
0,0,0,0,0,0,0,0,0,0,0,0,0,0,0,0,0,0,0,0,0,0,0
0,0,0,0,0,0,0,0,0,0,0,0,0,0,0,0,0,0,0,0,0,0,0
0,0,0,0,0,0,0,0,0,0,0,0,0,0,0,0,0,0,0,0,0,0,0
0,0,0,0,0,0,0,0,0,0,0,0,0,0,0,0,0,0,0,0,0,0,0
0,0,0,0,0,0,0,0,0,0,0,0,0,0,0,0,0,0,0,0,0,0,0
0,0,0,0,0,0,0,0,0,0,0,0,0,0,0,0,0,0,0,0,0,0,0
:endlayer
layer: 8
0,0,0,0,0,0,0,0,0,0,0,0,0,0,0,0,0,0,0,0,0,0,0
0,0,0,0,0,0,0,0,0,0,0,0,8,0,0,0,0,0,0,0,0,0,0
0,0,0,0,0,0,0,0,0,0,0,0,8,0,0,0,0,0,0,0,0,0,0
0,0,0,0,0,0,0,0,0,0,0,0,8,0,0,0,0,0,0,0,0,0,0
0,0,0,0,0,0,0,0,0,0,0,0,8,0,0,0,0,0,0,0,0,0,0
0,0,0,0,0,0,0,0,0,0,0,0,8,0,0,0,0,0,0,0,0,0,0
0,0,0,0,0,0,0,0,0,0,0,0,8,0,0,0,0,0,0,0,0,0,0
0,0,0,0,0,0,0,0,0,0,0,0,8,0,0,0,0,0,0,0,0,0,0
0,0,0,0,0,0,0,0,0,0,0,0,0,0,0,0,0,0,0,0,0,0,0
0,0,0,0,0,0,0,0,0,0,0,0,0,0,0,0,0,0,0,0,0,0,0
0,0,0,0,0,0,0,0,0,0,0,0,0,0,0,0,0,0,0,0,0,0,0
0,0,0,0,0,0,0,0,0,0,0,0,0,0,0,0,0,0,0,0,0,0,0
0,0,0,0,0,0,0,0,0,0,0,0,0,0,0,0,0,0,0,0,0,0,0
0,0,0,0,0,0,0,0,0,0,0,0,0,0,0,0,0,0,0,0,0,0,0
0,0,0,0,0,0,0,0,0,0,0,0,0,0,0,0,0,0,0,0,0,0,0
0,0,0,0,0,0,0,0,0,0,0,0,0,0,0,0,0,0,0,0,0,0,0
:endlayer

#### RULES ####
rule:
plugin=vanillaBlocks
number=1
data:
JSON:{blockState:{blockName:"minecraft:grass",properties:{snowy:"false"}}}
:enddata
:endrule

rule:
plugin=vanillaBlocks
number=2
data:
JSON:{blockState:{blockName:"minecraft:log2",properties:{variant:"dark_oak",axis:"y"}}}
:enddata
:endrule

rule:
plugin=vanillaBlocks
number=3
data:
JSON:{blockState:{blockName:"minecraft:planks",properties:{variant:"dark_oak"}}}
:enddata
:endrule

rule:
plugin=vanillaBlocks
number=4
data:
JSON:{blockState:{blockName:"minecraft:log2",properties:{variant:"dark_oak",axis:"x"}}}
:enddata
:endrule

rule:
plugin=vanillaBlocks
number=5
data:
JSON:{blockState:{blockName:"minecraft:log2",properties:{variant:"dark_oak",axis:"z"}}}
:enddata
:endrule

rule:
plugin=vanillaBlocks
number=6
data:
JSON:{blockState:{blockName:"minecraft:wooden_slab",properties:{half:"top",variant:"dark_oak"}}}
:enddata
:endrule

rule:
plugin=vanillaBlocks
number=7
data:
JSON:{blockState:{blockName:"minecraft:dark_oak_fence",properties:{east:"false",south:"false",north:"false",west:"false"}}}
:enddata
:endrule

rule:
plugin=vanillaBlocks
number=8
data:
JSON:{blockState:{blockName:"minecraft:wooden_slab",properties:{half:"bottom",variant:"dark_oak"}}}
:enddata
:endrule

rule:
plugin=vanillaBlocks
number=9
data:
JSON:{blockState:{blockName:"minecraft:dark_oak_stairs",properties:{half:"bottom",shape:"straight",facing:"south"}}}
:enddata
:endrule

rule:
plugin=vanillaBlocks
number=10
data:
JSON:{blockState:{blockName:"minecraft:dark_oak_stairs",properties:{half:"top",shape:"straight",facing:"east"}}}
:enddata
:endrule

rule:
plugin=vanillaBlocks
number=11
data:
JSON:{blockState:{blockName:"minecraft:dark_oak_stairs",properties:{half:"top",shape:"straight",facing:"west"}}}
:enddata
:endrule

rule:
plugin=vanillaBlocks
number=12
data:
JSON:{blockState:{blockName:"minecraft:dark_oak_stairs",properties:{half:"top",shape:"straight",facing:"north"}}}
:enddata
:endrule

rule:
plugin=vanillaBlocks
number=13
data:
JSON:{blockState:{blockName:"minecraft:dark_oak_stairs",properties:{half:"bottom",shape:"straight",facing:"east"}}}
:enddata
:endrule

rule:
plugin=vanillaBlocks
number=14
data:
JSON:{blockState:{blockName:"minecraft:dark_oak_stairs",properties:{half:"bottom",shape:"straight",facing:"west"}}}
:enddata
:endrule

rule:
plugin=vanillaBlocks
number=15
data:
JSON:{blockState:{blockName:"minecraft:dark_oak_stairs",properties:{half:"top",shape:"straight",facing:"south"}}}
:enddata
:endrule

rule:
plugin=vanillaBlocks
number=16
data:
JSON:{blockState:{blockName:"minecraft:dark_oak_stairs",properties:{half:"bottom",shape:"straight",facing:"north"}}}
:enddata
:endrule

#### ENTITIES ####
