# Ancient Warfare Structure Template File
# Auto-generated structure template file. created on: 5/7/2021 at: 11:47:49
# Lines beginning with # denote comments

header:
version=2.11
name=SurvivalBuild_RuralLife_Res_WoodenFortifiedHouse_ENVIRONSfrozen
mods=environs
size=23,9,16
offset=11,1,15
:endheader

#### VALIDATION ####
validation:
type=ground
structureAuthor=TheOddlySeagull
survival=true
worldGenEnabled=false
unique=false
preserveBlocks=false
preventNaturalHostileSpawns=false
selectionWeight=1
clusterValue=1
minDuplicateDistance=1
dimensionWhiteList=true
dimensionList=
biomeGroupList=
biomeWhiteList=true
biomeList=
leveling=0
fill=0
border=0
blockSwap=false
territoryName=
biomeReplacement=minecraft:
minGenerationHeight=0
maxGenerationHeight=255
:endvalidation

#### LAYERS ####
layer: 0
1,1,1,1,1,1,1,1,1,2,1,1,2,1,1,2,1,1,1,1,1,1,1
1,1,2,3,3,3,2,2,2,2,2,2,2,2,2,2,3,3,3,3,2,1,1
1,1,3,1,1,1,2,4,4,2,4,4,4,4,4,2,1,1,1,1,3,1,1
1,1,3,1,1,1,2,4,4,2,4,4,4,4,4,2,1,1,1,1,3,1,1
1,1,3,1,1,1,2,2,2,2,4,4,4,4,4,2,1,1,1,1,3,1,1
1,1,3,1,1,1,1,1,1,2,4,4,4,4,4,2,1,1,1,1,3,1,1
1,3,3,1,1,1,1,1,1,2,4,4,4,4,4,2,1,1,1,1,3,3,1
1,3,3,1,1,1,1,1,1,2,2,2,2,2,2,2,1,1,1,1,3,3,1
1,3,3,1,1,1,1,1,1,1,1,1,1,1,1,1,1,1,1,1,3,3,1
1,3,3,1,1,1,1,1,1,1,1,1,1,1,1,1,1,1,1,1,3,3,1
1,1,3,1,1,1,1,1,1,1,1,1,1,1,1,1,1,1,1,1,3,1,1
1,1,3,1,1,1,1,1,1,1,1,1,1,1,1,1,1,1,1,1,3,1,1
1,1,3,1,1,1,1,1,1,1,1,1,1,1,1,1,1,1,1,1,3,1,1
1,1,3,1,1,1,3,1,1,1,1,1,1,1,1,1,3,1,1,1,3,1,1
1,1,2,3,3,3,3,3,3,2,2,2,2,2,3,3,3,3,3,3,2,1,1
1,1,1,1,1,1,1,1,1,1,1,1,1,1,1,1,1,1,1,1,1,1,1
:endlayer
layer: 1
0,0,0,0,0,0,0,0,0,2,0,0,2,0,0,2,0,0,0,0,0,0,0
0,0,2,3,3,3,2,3,3,2,3,3,2,3,3,2,3,3,3,3,2,0,0
0,0,3,0,0,0,3,0,0,0,0,0,0,0,0,3,0,0,0,0,3,0,0
0,0,3,0,0,0,3,0,0,0,0,0,0,0,0,3,0,0,0,0,3,0,0
0,0,3,0,0,0,2,3,3,2,0,0,0,0,0,2,0,0,0,0,3,0,0
0,0,3,0,0,0,0,0,0,3,0,0,0,0,0,3,0,0,0,0,3,0,0
0,5,3,0,0,0,0,0,0,3,0,0,0,0,0,3,0,0,0,0,3,5,0
0,3,3,0,0,0,0,0,0,2,0,0,2,3,3,2,0,0,0,0,3,3,0
0,3,3,0,0,0,0,0,0,0,0,0,0,0,0,0,0,0,0,0,3,3,0
0,5,3,0,0,0,0,0,0,0,0,0,0,0,0,0,0,0,0,0,3,5,0
0,0,3,0,0,0,0,0,0,0,0,0,0,0,0,0,0,0,0,0,3,0,0
0,0,3,0,0,0,0,0,0,0,0,0,0,0,0,0,0,0,0,0,3,0,0
0,0,3,0,0,0,0,0,0,0,0,0,0,0,0,0,0,0,0,0,3,0,0
0,0,3,0,4,6,0,0,0,0,0,0,0,0,0,0,0,6,4,0,3,0,0
0,0,2,3,3,3,3,3,3,2,0,0,0,2,3,3,3,3,3,3,2,0,0
0,0,0,0,0,0,0,0,0,0,0,0,0,0,0,0,0,0,0,0,0,0,0
:endlayer
layer: 2
0,0,0,0,0,0,0,0,0,7,0,0,7,0,0,7,0,0,0,0,0,0,0
0,0,2,3,3,3,2,3,3,2,3,3,2,3,3,2,3,3,3,3,2,0,0
0,0,3,4,4,4,3,0,0,0,0,0,0,0,0,5,0,4,4,4,3,0,0
0,0,3,4,0,0,3,0,0,0,0,0,0,0,0,5,0,0,0,4,3,0,0
0,0,3,4,0,0,2,5,5,2,0,0,0,0,0,2,0,0,0,4,3,0,0
0,0,3,4,0,0,0,0,0,3,0,0,0,0,0,3,0,0,0,4,3,0,0
0,5,3,4,0,0,0,0,0,3,0,0,0,0,0,3,0,0,0,4,3,5,0
0,3,3,4,0,0,0,0,0,2,0,0,2,5,5,2,0,0,0,4,3,3,0
0,3,3,4,0,0,0,0,0,0,0,0,0,0,0,0,0,0,0,4,3,3,0
0,5,3,4,0,0,0,0,0,0,0,0,0,0,0,0,0,0,0,4,3,5,0
0,0,3,4,0,0,0,0,0,0,0,0,0,0,0,0,0,0,0,4,3,0,0
0,0,3,4,0,0,0,0,0,0,0,0,0,0,0,0,0,0,0,4,3,0,0
0,0,3,4,0,0,0,0,0,0,0,0,0,0,0,0,0,0,0,4,3,0,0
0,0,3,6,0,0,0,0,0,0,0,0,0,0,0,0,0,0,0,6,3,0,0
0,0,2,3,3,3,3,3,3,2,0,0,0,2,3,3,3,3,3,3,2,0,0
0,0,0,0,0,0,0,0,0,0,0,0,0,0,0,0,0,0,0,0,0,0,0
:endlayer
layer: 3
0,0,0,0,0,0,0,0,0,0,0,0,0,0,0,0,0,0,0,0,0,0,0
0,0,2,6,3,6,2,3,3,2,3,3,2,3,3,2,3,6,3,6,2,0,0
0,0,6,0,0,0,3,0,0,0,0,0,0,0,0,5,0,0,0,0,6,0,0
0,0,3,0,0,0,3,0,0,0,0,0,0,0,0,5,0,0,0,0,3,0,0
0,0,6,0,0,0,2,5,5,2,0,0,0,0,0,2,0,0,0,0,6,0,0
0,0,3,0,0,0,0,0,0,3,0,0,0,0,0,3,0,0,0,0,3,0,0
0,8,3,0,0,0,0,0,0,3,0,0,0,0,0,3,0,0,0,0,3,9,0
8,3,6,0,0,0,0,0,0,2,10,10,2,5,5,2,0,0,0,0,6,3,9
8,3,6,0,0,0,0,0,0,0,0,0,0,0,0,0,0,0,0,0,6,3,9
0,8,3,0,0,0,0,0,0,0,0,0,0,0,0,0,0,0,0,0,3,9,0
0,0,3,0,0,0,0,0,0,0,0,0,0,0,0,0,0,0,0,0,3,0,0
0,0,6,0,0,0,0,0,0,0,0,0,0,0,0,0,0,0,0,0,6,0,0
0,0,3,0,0,0,0,0,0,0,0,0,0,0,0,0,0,0,0,0,3,0,0
0,0,6,0,0,0,0,0,0,0,0,0,0,0,0,0,0,0,0,0,6,0,0
0,0,2,6,3,6,3,6,3,2,0,0,0,2,3,6,3,6,3,6,2,0,0
0,0,0,0,0,0,0,0,0,0,0,0,0,0,0,0,0,0,0,0,0,0,0
:endlayer
layer: 4
0,0,0,0,0,7,7,7,11,9,0,0,0,0,0,8,12,0,0,0,0,0,0
0,0,6,0,6,10,2,2,2,2,2,2,2,2,2,2,12,0,6,0,6,0,0
0,0,0,0,0,0,2,0,0,0,0,0,0,0,0,2,12,0,0,0,0,0,0
0,0,6,0,0,0,2,0,0,0,0,0,0,0,0,2,12,0,0,0,6,0,0
0,0,0,0,0,13,2,2,2,2,0,0,0,0,0,2,12,0,0,0,0,0,0
0,0,6,0,0,14,14,14,14,2,0,0,0,0,0,2,12,0,0,0,6,0,0
0,6,0,0,0,0,0,0,11,2,0,0,0,0,0,2,12,0,0,0,0,6,0
6,0,0,0,0,0,0,0,11,2,2,2,2,2,2,2,12,0,0,0,0,0,6
6,0,0,0,0,0,0,0,11,9,0,0,0,0,0,8,12,0,0,0,0,0,6
0,6,0,0,0,0,0,0,0,0,0,0,0,0,0,0,0,0,0,0,0,6,0
0,0,6,0,0,0,0,0,0,0,0,0,0,0,0,0,0,0,0,0,6,0,0
0,0,0,0,0,0,0,0,0,0,0,0,0,0,0,0,0,0,0,0,0,0,0
0,0,6,0,0,0,0,0,0,0,0,0,0,0,0,0,0,0,0,0,6,0,0
0,0,0,0,0,0,0,0,4,13,4,4,4,13,4,0,0,0,0,0,0,0,0
0,0,6,0,6,0,6,0,3,2,2,2,2,2,3,0,6,0,6,0,6,0,0
0,0,0,0,0,0,0,0,4,10,4,4,4,10,4,0,0,0,0,0,0,0,0
:endlayer
layer: 5
0,0,0,0,0,0,0,0,0,11,9,0,0,0,8,12,0,0,0,0,0,0,0
0,0,0,0,0,7,7,7,7,11,2,3,3,3,2,12,0,0,0,0,0,0,0
0,0,0,0,0,11,3,10,10,10,9,0,0,0,8,12,0,0,0,0,0,0,0
0,0,0,0,0,11,3,13,13,13,9,0,0,0,8,12,0,0,0,0,0,0,0
0,0,0,0,0,14,14,14,14,11,9,0,0,0,8,12,0,0,0,0,0,0,0
0,0,0,0,0,0,0,0,0,11,9,0,0,0,8,12,0,0,0,0,0,0,0
0,0,0,0,0,0,0,0,0,11,9,0,0,0,8,12,0,0,0,0,0,0,0
0,0,0,0,0,0,0,0,0,11,2,3,3,3,2,12,0,0,0,0,0,0,0
0,0,0,0,0,0,0,0,0,11,9,0,0,0,8,12,0,0,0,0,0,0,0
0,0,0,0,0,0,0,0,0,0,0,0,0,0,0,0,0,0,0,0,0,0,0
0,0,0,0,0,0,0,0,0,0,0,0,0,0,0,0,0,0,0,0,0,0,0
0,0,0,0,0,0,0,0,0,0,0,0,0,0,0,0,0,0,0,0,0,0,0
0,0,0,0,0,0,0,0,0,0,0,0,0,0,0,0,0,0,0,0,0,0,0
0,0,0,0,0,0,0,0,0,0,0,0,0,0,0,0,0,0,0,0,0,0,0
0,0,0,0,0,0,0,0,6,6,6,6,6,6,6,0,0,0,0,0,0,0,0
0,0,0,0,0,0,0,0,0,0,0,0,0,0,0,0,0,0,0,0,0,0,0
:endlayer
layer: 6
0,0,0,0,0,0,0,0,0,0,11,9,0,8,12,0,0,0,0,0,0,0,0
0,0,0,0,0,0,0,0,0,0,11,2,3,2,12,0,0,0,0,0,0,0,0
0,0,0,0,0,0,11,7,7,7,7,9,0,8,12,0,0,0,0,0,0,0,0
0,0,0,0,0,0,11,14,14,14,14,9,0,8,12,0,0,0,0,0,0,0,0
0,0,0,0,0,0,0,0,0,0,11,9,0,8,12,0,0,0,0,0,0,0,0
0,0,0,0,0,0,0,0,0,0,11,9,0,8,12,0,0,0,0,0,0,0,0
0,0,0,0,0,0,0,0,0,0,11,9,0,8,12,0,0,0,0,0,0,0,0
0,0,0,0,0,0,0,0,0,0,11,2,3,2,12,0,0,0,0,0,0,0,0
0,0,0,0,0,0,0,0,0,0,11,9,0,8,12,0,0,0,0,0,0,0,0
0,0,0,0,0,0,0,0,0,0,0,0,0,0,0,0,0,0,0,0,0,0,0
0,0,0,0,0,0,0,0,0,0,0,0,0,0,0,0,0,0,0,0,0,0,0
0,0,0,0,0,0,0,0,0,0,0,0,0,0,0,0,0,0,0,0,0,0,0
0,0,0,0,0,0,0,0,0,0,0,0,0,0,0,0,0,0,0,0,0,0,0
0,0,0,0,0,0,0,0,0,0,0,0,0,0,0,0,0,0,0,0,0,0,0
0,0,0,0,0,0,0,0,0,0,0,0,0,0,0,0,0,0,0,0,0,0,0
0,0,0,0,0,0,0,0,0,0,0,0,0,0,0,0,0,0,0,0,0,0,0
:endlayer
layer: 7
0,0,0,0,0,0,0,0,0,0,0,11,7,12,0,0,0,0,0,0,0,0,0
0,0,0,0,0,0,0,0,0,0,0,11,2,12,0,0,0,0,0,0,0,0,0
0,0,0,0,0,0,0,0,0,0,0,11,2,12,0,0,0,0,0,0,0,0,0
0,0,0,0,0,0,0,0,0,0,0,11,2,12,0,0,0,0,0,0,0,0,0
0,0,0,0,0,0,0,0,0,0,0,11,2,12,0,0,0,0,0,0,0,0,0
0,0,0,0,0,0,0,0,0,0,0,11,2,12,0,0,0,0,0,0,0,0,0
0,0,0,0,0,0,0,0,0,0,0,11,2,12,0,0,0,0,0,0,0,0,0
0,0,0,0,0,0,0,0,0,0,0,11,2,12,0,0,0,0,0,0,0,0,0
0,0,0,0,0,0,0,0,0,0,0,11,14,12,0,0,0,0,0,0,0,0,0
0,0,0,0,0,0,0,0,0,0,0,0,0,0,0,0,0,0,0,0,0,0,0
0,0,0,0,0,0,0,0,0,0,0,0,0,0,0,0,0,0,0,0,0,0,0
0,0,0,0,0,0,0,0,0,0,0,0,0,0,0,0,0,0,0,0,0,0,0
0,0,0,0,0,0,0,0,0,0,0,0,0,0,0,0,0,0,0,0,0,0,0
0,0,0,0,0,0,0,0,0,0,0,0,0,0,0,0,0,0,0,0,0,0,0
0,0,0,0,0,0,0,0,0,0,0,0,0,0,0,0,0,0,0,0,0,0,0
0,0,0,0,0,0,0,0,0,0,0,0,0,0,0,0,0,0,0,0,0,0,0
:endlayer
layer: 8
0,0,0,0,0,0,0,0,0,0,0,0,0,0,0,0,0,0,0,0,0,0,0
0,0,0,0,0,0,0,0,0,0,0,0,6,0,0,0,0,0,0,0,0,0,0
0,0,0,0,0,0,0,0,0,0,0,0,6,0,0,0,0,0,0,0,0,0,0
0,0,0,0,0,0,0,0,0,0,0,0,6,0,0,0,0,0,0,0,0,0,0
0,0,0,0,0,0,0,0,0,0,0,0,6,0,0,0,0,0,0,0,0,0,0
0,0,0,0,0,0,0,0,0,0,0,0,6,0,0,0,0,0,0,0,0,0,0
0,0,0,0,0,0,0,0,0,0,0,0,6,0,0,0,0,0,0,0,0,0,0
0,0,0,0,0,0,0,0,0,0,0,0,6,0,0,0,0,0,0,0,0,0,0
0,0,0,0,0,0,0,0,0,0,0,0,0,0,0,0,0,0,0,0,0,0,0
0,0,0,0,0,0,0,0,0,0,0,0,0,0,0,0,0,0,0,0,0,0,0
0,0,0,0,0,0,0,0,0,0,0,0,0,0,0,0,0,0,0,0,0,0,0
0,0,0,0,0,0,0,0,0,0,0,0,0,0,0,0,0,0,0,0,0,0,0
0,0,0,0,0,0,0,0,0,0,0,0,0,0,0,0,0,0,0,0,0,0,0
0,0,0,0,0,0,0,0,0,0,0,0,0,0,0,0,0,0,0,0,0,0,0
0,0,0,0,0,0,0,0,0,0,0,0,0,0,0,0,0,0,0,0,0,0,0
0,0,0,0,0,0,0,0,0,0,0,0,0,0,0,0,0,0,0,0,0,0,0
:endlayer

#### RULES ####
rule:
plugin=vanillaBlocks
number=1
data:
JSON:{blockState:{blockName:"minecraft:grass",properties:{snowy:"false"}}}
:enddata
:endrule

rule:
plugin=vanillaBlocks
number=2
data:
JSON:{blockState:{blockName:"environs:frozen_log",properties:{axis:"y"}}}
:enddata
:endrule

rule:
plugin=vanillaBlocks
number=3
data:
JSON:{blockState:{blockName:"environs:frozen_planks"}}
:enddata
:endrule

rule:
plugin=vanillaBlocks
number=4
data:
JSON:{blockState:{blockName:"environs:frozen_slab",properties:{half:"top",variant:"default"}}}
:enddata
:endrule

rule:
plugin=vanillaBlocks
number=5
data:
JSON:{blockState:{blockName:"environs:frozen_fence",properties:{east:"false",south:"false",north:"false",west:"false"}}}
:enddata
:endrule

rule:
plugin=vanillaBlocks
number=6
data:
JSON:{blockState:{blockName:"environs:frozen_slab",properties:{half:"bottom",variant:"default"}}}
:enddata
:endrule

rule:
plugin=vanillaBlocks
number=7
data:
JSON:{blockState:{blockName:"environs:frozen_stairs",properties:{half:"bottom",shape:"straight",facing:"south"}}}
:enddata
:endrule

rule:
plugin=vanillaBlocks
number=8
data:
JSON:{blockState:{blockName:"environs:frozen_stairs",properties:{half:"top",shape:"straight",facing:"east"}}}
:enddata
:endrule

rule:
plugin=vanillaBlocks
number=9
data:
JSON:{blockState:{blockName:"environs:frozen_stairs",properties:{half:"top",shape:"straight",facing:"west"}}}
:enddata
:endrule

rule:
plugin=vanillaBlocks
number=10
data:
JSON:{blockState:{blockName:"environs:frozen_stairs",properties:{half:"top",shape:"straight",facing:"north"}}}
:enddata
:endrule

rule:
plugin=vanillaBlocks
number=11
data:
JSON:{blockState:{blockName:"environs:frozen_stairs",properties:{half:"bottom",shape:"straight",facing:"east"}}}
:enddata
:endrule

rule:
plugin=vanillaBlocks
number=12
data:
JSON:{blockState:{blockName:"environs:frozen_stairs",properties:{half:"bottom",shape:"straight",facing:"west"}}}
:enddata
:endrule

rule:
plugin=vanillaBlocks
number=13
data:
JSON:{blockState:{blockName:"environs:frozen_stairs",properties:{half:"top",shape:"straight",facing:"south"}}}
:enddata
:endrule

rule:
plugin=vanillaBlocks
number=14
data:
JSON:{blockState:{blockName:"environs:frozen_stairs",properties:{half:"bottom",shape:"straight",facing:"north"}}}
:enddata
:endrule

#### ENTITIES ####
