# Ancient Warfare Structure Template File
# Auto-generated structure template file. created on: 5/7/2021 at: 11:47:11
# Lines beginning with # denote comments

header:
version=2.11
name=SurvivalBuild_RuralLife_Res_WoodenFortifiedHouse_oakspruceA
mods=
size=23,9,16
offset=11,1,15
:endheader

#### VALIDATION ####
validation:
type=ground
structureAuthor=TheOddlySeagull
survival=true
worldGenEnabled=false
unique=false
preserveBlocks=false
preventNaturalHostileSpawns=false
selectionWeight=1
clusterValue=1
minDuplicateDistance=1
dimensionWhiteList=true
dimensionList=
biomeGroupList=
biomeWhiteList=true
biomeList=
leveling=0
fill=0
border=0
blockSwap=false
territoryName=
biomeReplacement=minecraft:
minGenerationHeight=0
maxGenerationHeight=255
:endvalidation

#### LAYERS ####
layer: 0
1,1,1,1,1,1,1,1,1,2,1,1,2,1,1,2,1,1,1,1,1,1,1
1,1,2,3,3,3,2,4,4,4,4,4,4,4,4,2,3,3,3,3,2,1,1
1,1,3,1,1,1,5,6,6,5,6,6,6,6,6,5,1,1,1,1,3,1,1
1,1,3,1,1,1,5,6,6,5,6,6,6,6,6,5,1,1,1,1,3,1,1
1,1,3,1,1,1,2,4,4,2,6,6,6,6,6,5,1,1,1,1,3,1,1
1,1,3,1,1,1,1,1,1,5,6,6,6,6,6,5,1,1,1,1,3,1,1
1,3,3,1,1,1,1,1,1,5,6,6,6,6,6,5,1,1,1,1,3,3,1
1,3,3,1,1,1,1,1,1,2,4,4,4,4,4,2,1,1,1,1,3,3,1
1,3,3,1,1,1,1,1,1,1,1,1,1,1,1,1,1,1,1,1,3,3,1
1,3,3,1,1,1,1,1,1,1,1,1,1,1,1,1,1,1,1,1,3,3,1
1,1,3,1,1,1,1,1,1,1,1,1,1,1,1,1,1,1,1,1,3,1,1
1,1,3,1,1,1,1,1,1,1,1,1,1,1,1,1,1,1,1,1,3,1,1
1,1,3,1,1,1,1,1,1,1,1,1,1,1,1,1,1,1,1,1,3,1,1
1,1,3,1,1,1,7,1,1,1,1,1,1,1,1,1,7,1,1,1,3,1,1
1,1,2,3,3,3,3,3,3,2,4,4,4,2,3,3,3,3,3,3,2,1,1
1,1,1,1,1,1,1,1,1,1,1,1,1,1,1,1,1,1,1,1,1,1,1
:endlayer
layer: 1
0,0,0,0,0,0,0,0,0,2,0,0,2,0,0,2,0,0,0,0,0,0,0
0,0,2,3,3,3,2,3,3,2,3,3,2,3,3,2,3,3,3,3,2,0,0
0,0,3,0,0,0,3,0,0,0,0,0,0,0,0,3,0,0,0,0,3,0,0
0,0,3,0,0,0,3,0,0,0,0,0,0,0,0,3,0,0,0,0,3,0,0
0,0,3,0,0,0,2,3,3,2,0,0,0,0,0,2,0,0,0,0,3,0,0
0,0,3,0,0,0,0,0,0,3,0,0,0,0,0,3,0,0,0,0,3,0,0
0,8,3,0,0,0,0,0,0,3,0,0,0,0,0,3,0,0,0,0,3,8,0
0,3,3,0,0,0,0,0,0,2,0,0,2,3,3,2,0,0,0,0,3,3,0
0,3,3,0,0,0,0,0,0,0,0,0,0,0,0,0,0,0,0,0,3,3,0
0,8,3,0,0,0,0,0,0,0,0,0,0,0,0,0,0,0,0,0,3,8,0
0,0,3,0,0,0,0,0,0,0,0,0,0,0,0,0,0,0,0,0,3,0,0
0,0,3,0,0,0,0,0,0,0,0,0,0,0,0,0,0,0,0,0,3,0,0
0,0,3,0,0,0,0,0,0,0,0,0,0,0,0,0,0,0,0,0,3,0,0
0,0,3,0,6,9,0,0,0,0,0,0,0,0,0,0,0,9,6,0,3,0,0
0,0,2,3,3,3,3,3,3,2,0,0,0,2,3,3,3,3,3,3,2,0,0
0,0,0,0,0,0,0,0,0,0,0,0,0,0,0,0,0,0,0,0,0,0,0
:endlayer
layer: 2
0,0,0,0,0,0,0,0,0,10,0,0,10,0,0,10,0,0,0,0,0,0,0
0,0,2,3,3,3,2,3,3,2,3,3,2,3,3,2,3,3,3,3,2,0,0
0,0,3,6,6,6,3,0,0,0,0,0,0,0,0,8,0,6,6,6,3,0,0
0,0,3,6,0,0,3,0,0,0,0,0,0,0,0,8,0,0,0,6,3,0,0
0,0,3,6,0,0,2,8,8,2,0,0,0,0,0,2,0,0,0,6,3,0,0
0,0,3,6,0,0,0,0,0,3,0,0,0,0,0,3,0,0,0,6,3,0,0
0,8,3,6,0,0,0,0,0,3,0,0,0,0,0,3,0,0,0,6,3,8,0
0,3,3,6,0,0,0,0,0,2,0,0,2,8,8,2,0,0,0,6,3,3,0
0,3,3,6,0,0,0,0,0,0,0,0,0,0,0,0,0,0,0,6,3,3,0
0,8,3,6,0,0,0,0,0,0,0,0,0,0,0,0,0,0,0,6,3,8,0
0,0,3,6,0,0,0,0,0,0,0,0,0,0,0,0,0,0,0,6,3,0,0
0,0,3,6,0,0,0,0,0,0,0,0,0,0,0,0,0,0,0,6,3,0,0
0,0,3,6,0,0,0,0,0,0,0,0,0,0,0,0,0,0,0,6,3,0,0
0,0,3,9,0,0,0,0,0,0,0,0,0,0,0,0,0,0,0,9,3,0,0
0,0,2,3,3,3,3,3,3,2,0,0,0,2,3,3,3,3,3,3,2,0,0
0,0,0,0,0,0,0,0,0,0,0,0,0,0,0,0,0,0,0,0,0,0,0
:endlayer
layer: 3
0,0,0,0,0,0,0,0,0,0,0,0,0,0,0,0,0,0,0,0,0,0,0
0,0,2,9,3,9,2,3,3,2,3,3,2,3,3,2,3,9,3,9,2,0,0
0,0,9,0,0,0,3,0,0,0,0,0,0,0,0,8,0,0,0,0,9,0,0
0,0,3,0,0,0,3,0,0,0,0,0,0,0,0,8,0,0,0,0,3,0,0
0,0,9,0,0,0,2,8,8,2,0,0,0,0,0,2,0,0,0,0,9,0,0
0,0,3,0,0,0,0,0,0,3,0,0,0,0,0,3,0,0,0,0,3,0,0
0,11,3,0,0,0,0,0,0,3,0,0,0,0,0,3,0,0,0,0,3,12,0
11,3,9,0,0,0,0,0,0,2,13,13,2,8,8,2,0,0,0,0,9,3,12
11,3,9,0,0,0,0,0,0,0,0,0,0,0,0,0,0,0,0,0,9,3,12
0,11,3,0,0,0,0,0,0,0,0,0,0,0,0,0,0,0,0,0,3,12,0
0,0,3,0,0,0,0,0,0,0,0,0,0,0,0,0,0,0,0,0,3,0,0
0,0,9,0,0,0,0,0,0,0,0,0,0,0,0,0,0,0,0,0,9,0,0
0,0,3,0,0,0,0,0,0,0,0,0,0,0,0,0,0,0,0,0,3,0,0
0,0,9,0,0,0,0,0,0,0,0,0,0,0,0,0,0,0,0,0,9,0,0
0,0,2,9,3,9,3,9,3,2,0,0,0,2,3,9,3,9,3,9,2,0,0
0,0,0,0,0,0,0,0,0,0,0,0,0,0,0,0,0,0,0,0,0,0,0
:endlayer
layer: 4
0,0,0,0,0,10,10,10,14,15,0,0,0,0,0,16,17,0,0,0,0,0,0
0,0,9,0,9,18,2,4,4,4,4,4,4,4,4,2,17,0,9,0,9,0,0
0,0,0,0,0,0,5,0,0,0,0,0,0,0,0,5,17,0,0,0,0,0,0
0,0,9,0,0,0,5,0,0,0,0,0,0,0,0,5,17,0,0,0,9,0,0
0,0,0,0,0,19,2,4,4,2,0,0,0,0,0,5,17,0,0,0,0,0,0
0,0,9,0,0,20,20,20,20,5,0,0,0,0,0,5,17,0,0,0,9,0,0
0,9,0,0,0,0,0,0,14,5,0,0,0,0,0,5,17,0,0,0,0,9,0
9,0,0,0,0,0,0,0,14,2,4,4,4,4,4,2,17,0,0,0,0,0,9
9,0,0,0,0,0,0,0,14,15,0,0,0,0,0,16,17,0,0,0,0,0,9
0,9,0,0,0,0,0,0,0,0,0,0,0,0,0,0,0,0,0,0,0,9,0
0,0,9,0,0,0,0,0,0,0,0,0,0,0,0,0,0,0,0,0,9,0,0
0,0,0,0,0,0,0,0,0,0,0,0,0,0,0,0,0,0,0,0,0,0,0
0,0,9,0,0,0,0,0,0,0,0,0,0,0,0,0,0,0,0,0,9,0,0
0,0,0,0,0,0,0,0,6,19,6,6,6,19,6,0,0,0,0,0,0,0,0
0,0,9,0,9,0,9,0,7,2,4,4,4,2,7,0,9,0,9,0,9,0,0
0,0,0,0,0,0,0,0,6,18,6,6,6,18,6,0,0,0,0,0,0,0,0
:endlayer
layer: 5
0,0,0,0,0,0,0,0,0,14,15,0,0,0,16,17,0,0,0,0,0,0,0
0,0,0,0,0,10,10,10,10,14,2,3,3,3,2,17,0,0,0,0,0,0,0
0,0,0,0,0,14,3,13,13,13,12,0,0,0,11,17,0,0,0,0,0,0,0
0,0,0,0,0,14,3,21,21,21,12,0,0,0,11,17,0,0,0,0,0,0,0
0,0,0,0,0,20,20,20,20,14,12,0,0,0,11,17,0,0,0,0,0,0,0
0,0,0,0,0,0,0,0,0,14,12,0,0,0,11,17,0,0,0,0,0,0,0
0,0,0,0,0,0,0,0,0,14,12,0,0,0,11,17,0,0,0,0,0,0,0
0,0,0,0,0,0,0,0,0,14,2,3,3,3,2,17,0,0,0,0,0,0,0
0,0,0,0,0,0,0,0,0,14,15,0,0,0,16,17,0,0,0,0,0,0,0
0,0,0,0,0,0,0,0,0,0,0,0,0,0,0,0,0,0,0,0,0,0,0
0,0,0,0,0,0,0,0,0,0,0,0,0,0,0,0,0,0,0,0,0,0,0
0,0,0,0,0,0,0,0,0,0,0,0,0,0,0,0,0,0,0,0,0,0,0
0,0,0,0,0,0,0,0,0,0,0,0,0,0,0,0,0,0,0,0,0,0,0
0,0,0,0,0,0,0,0,0,0,0,0,0,0,0,0,0,0,0,0,0,0,0
0,0,0,0,0,0,0,0,9,9,9,9,9,9,9,0,0,0,0,0,0,0,0
0,0,0,0,0,0,0,0,0,0,0,0,0,0,0,0,0,0,0,0,0,0,0
:endlayer
layer: 6
0,0,0,0,0,0,0,0,0,0,14,15,0,16,17,0,0,0,0,0,0,0,0
0,0,0,0,0,0,0,0,0,0,14,2,3,2,17,0,0,0,0,0,0,0,0
0,0,0,0,0,0,14,10,10,10,10,12,0,11,17,0,0,0,0,0,0,0,0
0,0,0,0,0,0,14,20,20,20,20,12,0,11,17,0,0,0,0,0,0,0,0
0,0,0,0,0,0,0,0,0,0,14,12,0,11,17,0,0,0,0,0,0,0,0
0,0,0,0,0,0,0,0,0,0,14,12,0,11,17,0,0,0,0,0,0,0,0
0,0,0,0,0,0,0,0,0,0,14,12,0,11,17,0,0,0,0,0,0,0,0
0,0,0,0,0,0,0,0,0,0,14,2,3,2,17,0,0,0,0,0,0,0,0
0,0,0,0,0,0,0,0,0,0,14,15,0,16,17,0,0,0,0,0,0,0,0
0,0,0,0,0,0,0,0,0,0,0,0,0,0,0,0,0,0,0,0,0,0,0
0,0,0,0,0,0,0,0,0,0,0,0,0,0,0,0,0,0,0,0,0,0,0
0,0,0,0,0,0,0,0,0,0,0,0,0,0,0,0,0,0,0,0,0,0,0
0,0,0,0,0,0,0,0,0,0,0,0,0,0,0,0,0,0,0,0,0,0,0
0,0,0,0,0,0,0,0,0,0,0,0,0,0,0,0,0,0,0,0,0,0,0
0,0,0,0,0,0,0,0,0,0,0,0,0,0,0,0,0,0,0,0,0,0,0
0,0,0,0,0,0,0,0,0,0,0,0,0,0,0,0,0,0,0,0,0,0,0
:endlayer
layer: 7
0,0,0,0,0,0,0,0,0,0,0,14,10,17,0,0,0,0,0,0,0,0,0
0,0,0,0,0,0,0,0,0,0,0,14,2,17,0,0,0,0,0,0,0,0,0
0,0,0,0,0,0,0,0,0,0,0,14,5,17,0,0,0,0,0,0,0,0,0
0,0,0,0,0,0,0,0,0,0,0,14,5,17,0,0,0,0,0,0,0,0,0
0,0,0,0,0,0,0,0,0,0,0,14,5,17,0,0,0,0,0,0,0,0,0
0,0,0,0,0,0,0,0,0,0,0,14,5,17,0,0,0,0,0,0,0,0,0
0,0,0,0,0,0,0,0,0,0,0,14,5,17,0,0,0,0,0,0,0,0,0
0,0,0,0,0,0,0,0,0,0,0,14,2,17,0,0,0,0,0,0,0,0,0
0,0,0,0,0,0,0,0,0,0,0,14,20,17,0,0,0,0,0,0,0,0,0
0,0,0,0,0,0,0,0,0,0,0,0,0,0,0,0,0,0,0,0,0,0,0
0,0,0,0,0,0,0,0,0,0,0,0,0,0,0,0,0,0,0,0,0,0,0
0,0,0,0,0,0,0,0,0,0,0,0,0,0,0,0,0,0,0,0,0,0,0
0,0,0,0,0,0,0,0,0,0,0,0,0,0,0,0,0,0,0,0,0,0,0
0,0,0,0,0,0,0,0,0,0,0,0,0,0,0,0,0,0,0,0,0,0,0
0,0,0,0,0,0,0,0,0,0,0,0,0,0,0,0,0,0,0,0,0,0,0
0,0,0,0,0,0,0,0,0,0,0,0,0,0,0,0,0,0,0,0,0,0,0
:endlayer
layer: 8
0,0,0,0,0,0,0,0,0,0,0,0,0,0,0,0,0,0,0,0,0,0,0
0,0,0,0,0,0,0,0,0,0,0,0,9,0,0,0,0,0,0,0,0,0,0
0,0,0,0,0,0,0,0,0,0,0,0,9,0,0,0,0,0,0,0,0,0,0
0,0,0,0,0,0,0,0,0,0,0,0,9,0,0,0,0,0,0,0,0,0,0
0,0,0,0,0,0,0,0,0,0,0,0,9,0,0,0,0,0,0,0,0,0,0
0,0,0,0,0,0,0,0,0,0,0,0,9,0,0,0,0,0,0,0,0,0,0
0,0,0,0,0,0,0,0,0,0,0,0,9,0,0,0,0,0,0,0,0,0,0
0,0,0,0,0,0,0,0,0,0,0,0,9,0,0,0,0,0,0,0,0,0,0
0,0,0,0,0,0,0,0,0,0,0,0,0,0,0,0,0,0,0,0,0,0,0
0,0,0,0,0,0,0,0,0,0,0,0,0,0,0,0,0,0,0,0,0,0,0
0,0,0,0,0,0,0,0,0,0,0,0,0,0,0,0,0,0,0,0,0,0,0
0,0,0,0,0,0,0,0,0,0,0,0,0,0,0,0,0,0,0,0,0,0,0
0,0,0,0,0,0,0,0,0,0,0,0,0,0,0,0,0,0,0,0,0,0,0
0,0,0,0,0,0,0,0,0,0,0,0,0,0,0,0,0,0,0,0,0,0,0
0,0,0,0,0,0,0,0,0,0,0,0,0,0,0,0,0,0,0,0,0,0,0
0,0,0,0,0,0,0,0,0,0,0,0,0,0,0,0,0,0,0,0,0,0,0
:endlayer

#### RULES ####
rule:
plugin=vanillaBlocks
number=1
data:
JSON:{blockState:{blockName:"minecraft:grass",properties:{snowy:"false"}}}
:enddata
:endrule

rule:
plugin=vanillaBlocks
number=2
data:
JSON:{blockState:{blockName:"minecraft:log",properties:{variant:"spruce",axis:"y"}}}
:enddata
:endrule

rule:
plugin=vanillaBlocks
number=3
data:
JSON:{blockState:{blockName:"minecraft:planks",properties:{variant:"oak"}}}
:enddata
:endrule

rule:
plugin=vanillaBlocks
number=4
data:
JSON:{blockState:{blockName:"minecraft:log",properties:{variant:"spruce",axis:"x"}}}
:enddata
:endrule

rule:
plugin=vanillaBlocks
number=5
data:
JSON:{blockState:{blockName:"minecraft:log",properties:{variant:"spruce",axis:"z"}}}
:enddata
:endrule

rule:
plugin=vanillaBlocks
number=6
data:
JSON:{blockState:{blockName:"minecraft:wooden_slab",properties:{half:"top",variant:"spruce"}}}
:enddata
:endrule

rule:
plugin=vanillaBlocks
number=7
data:
JSON:{blockState:{blockName:"minecraft:planks",properties:{variant:"spruce"}}}
:enddata
:endrule

rule:
plugin=vanillaBlocks
number=8
data:
JSON:{blockState:{blockName:"minecraft:spruce_fence",properties:{east:"false",south:"false",north:"false",west:"false"}}}
:enddata
:endrule

rule:
plugin=vanillaBlocks
number=9
data:
JSON:{blockState:{blockName:"minecraft:wooden_slab",properties:{half:"bottom",variant:"spruce"}}}
:enddata
:endrule

rule:
plugin=vanillaBlocks
number=10
data:
JSON:{blockState:{blockName:"minecraft:spruce_stairs",properties:{half:"bottom",shape:"straight",facing:"south"}}}
:enddata
:endrule

rule:
plugin=vanillaBlocks
number=11
data:
JSON:{blockState:{blockName:"minecraft:oak_stairs",properties:{half:"top",shape:"straight",facing:"east"}}}
:enddata
:endrule

rule:
plugin=vanillaBlocks
number=12
data:
JSON:{blockState:{blockName:"minecraft:oak_stairs",properties:{half:"top",shape:"straight",facing:"west"}}}
:enddata
:endrule

rule:
plugin=vanillaBlocks
number=13
data:
JSON:{blockState:{blockName:"minecraft:oak_stairs",properties:{half:"top",shape:"straight",facing:"north"}}}
:enddata
:endrule

rule:
plugin=vanillaBlocks
number=14
data:
JSON:{blockState:{blockName:"minecraft:spruce_stairs",properties:{half:"bottom",shape:"straight",facing:"east"}}}
:enddata
:endrule

rule:
plugin=vanillaBlocks
number=15
data:
JSON:{blockState:{blockName:"minecraft:spruce_stairs",properties:{half:"top",shape:"straight",facing:"west"}}}
:enddata
:endrule

rule:
plugin=vanillaBlocks
number=16
data:
JSON:{blockState:{blockName:"minecraft:spruce_stairs",properties:{half:"top",shape:"straight",facing:"east"}}}
:enddata
:endrule

rule:
plugin=vanillaBlocks
number=17
data:
JSON:{blockState:{blockName:"minecraft:spruce_stairs",properties:{half:"bottom",shape:"straight",facing:"west"}}}
:enddata
:endrule

rule:
plugin=vanillaBlocks
number=18
data:
JSON:{blockState:{blockName:"minecraft:spruce_stairs",properties:{half:"top",shape:"straight",facing:"north"}}}
:enddata
:endrule

rule:
plugin=vanillaBlocks
number=19
data:
JSON:{blockState:{blockName:"minecraft:spruce_stairs",properties:{half:"top",shape:"straight",facing:"south"}}}
:enddata
:endrule

rule:
plugin=vanillaBlocks
number=20
data:
JSON:{blockState:{blockName:"minecraft:spruce_stairs",properties:{half:"bottom",shape:"straight",facing:"north"}}}
:enddata
:endrule

rule:
plugin=vanillaBlocks
number=21
data:
JSON:{blockState:{blockName:"minecraft:oak_stairs",properties:{half:"top",shape:"straight",facing:"south"}}}
:enddata
:endrule

#### ENTITIES ####
