# Ancient Warfare Structure Template File
# Auto-generated structure template file. created on: 5/6/2021 at: 13:20:51
# Lines beginning with # denote comments

header:
version=2.11
name=SurvivalBuild_FortWall_extreme_type1_protection1_StraightTowerWithStairTower_QUARKmarble
mods=quark
size=32,41,16
offset=0,5,15
:endheader

#### VALIDATION ####
validation:
type=ground
structureAuthor=TheOddlySeagull
survival=true
worldGenEnabled=false
unique=false
preserveBlocks=false
preventNaturalHostileSpawns=false
selectionWeight=1
clusterValue=1
minDuplicateDistance=1
dimensionWhiteList=true
dimensionList=
biomeGroupList=
biomeWhiteList=true
biomeList=
leveling=0
fill=0
border=0
blockSwap=false
territoryName=
biomeReplacement=minecraft:
minGenerationHeight=0
maxGenerationHeight=255
:endvalidation

#### LAYERS ####
layer: 0
1,1,1,2,2,2,2,2,2,2,2,2,2,1,1,1,1,1,1,1,1,1,1,1,1,1,1,1,1,1,1,1
1,1,1,2,2,2,2,2,2,2,2,2,2,1,1,1,1,1,1,1,1,1,1,1,1,1,1,1,1,1,1,1
1,1,1,2,2,2,2,2,2,2,2,2,2,1,1,1,1,1,1,1,1,1,1,1,1,1,1,1,1,1,1,1
1,1,1,2,2,2,2,2,2,2,2,2,2,1,1,1,1,1,1,1,1,1,1,1,1,1,1,1,1,1,1,1
1,1,1,2,2,2,2,2,2,2,2,2,2,1,1,1,1,1,1,1,1,1,1,1,1,1,1,1,1,1,1,1
1,1,2,2,2,2,2,2,2,2,2,2,2,1,1,1,1,1,1,1,1,1,1,1,1,1,1,1,1,1,1,1
1,2,2,2,2,2,2,2,2,2,2,2,2,1,1,1,1,1,1,1,1,1,1,1,1,1,1,1,1,1,1,1
1,2,2,2,2,2,2,2,2,2,2,2,2,1,1,1,1,1,1,1,1,1,1,1,1,1,1,1,1,1,1,1
1,2,2,2,2,2,2,2,2,2,2,2,2,1,1,1,1,1,1,1,1,1,1,1,1,1,1,1,1,1,1,1
1,2,2,2,2,2,2,2,2,2,2,2,2,1,1,1,1,1,1,1,1,1,1,1,1,1,1,1,1,1,1,1
1,1,2,2,2,2,2,2,2,2,2,2,2,1,1,1,1,1,1,1,1,1,1,1,1,1,1,1,1,1,1,1
1,1,1,2,2,2,2,2,2,2,2,2,2,1,1,1,1,1,1,1,1,1,1,1,1,1,1,1,1,1,1,1
1,1,1,2,2,2,2,2,2,2,2,2,2,1,1,1,1,1,1,1,1,1,1,1,1,1,1,1,1,1,1,1
1,1,1,2,2,2,2,2,2,2,2,2,2,1,1,1,1,1,1,1,1,1,1,1,1,1,1,1,1,1,1,1
1,1,1,2,2,2,2,2,2,2,2,2,2,1,1,1,1,1,1,1,1,1,1,1,1,1,1,1,1,1,1,1
1,1,1,2,2,2,2,2,2,2,2,2,2,1,1,1,1,1,1,1,1,1,1,1,1,1,1,1,1,1,1,1
:endlayer
layer: 1
1,1,1,2,2,2,2,2,2,2,2,2,2,1,1,1,1,1,1,1,1,1,1,1,1,1,1,1,1,1,1,1
1,1,1,2,2,2,2,2,2,2,2,2,2,1,1,1,1,1,1,1,1,1,1,1,1,1,1,1,1,1,1,1
1,1,1,2,2,2,2,2,2,2,2,2,2,1,1,1,1,1,1,1,1,1,1,1,1,1,1,1,1,1,1,1
1,1,1,2,2,2,2,2,2,2,2,2,2,1,1,1,1,1,1,1,1,1,1,1,1,1,1,1,1,1,1,1
1,1,1,2,2,2,2,2,2,2,2,2,2,1,1,1,1,1,1,1,1,1,1,1,1,1,1,1,1,1,1,1
1,1,2,2,2,2,2,2,2,2,2,2,2,1,1,1,1,1,1,1,1,1,1,1,1,1,1,1,1,1,1,1
1,2,2,2,2,2,2,2,2,2,2,2,2,1,1,1,1,1,1,1,1,1,1,1,1,1,1,1,1,1,1,1
1,2,2,2,2,2,2,2,2,2,2,2,2,1,1,1,1,1,1,1,1,1,1,1,1,1,1,1,1,1,1,1
1,2,2,2,2,2,2,2,2,2,2,2,2,1,1,1,1,1,1,1,1,1,1,1,1,1,1,1,1,1,1,1
1,2,2,2,2,2,2,2,2,2,2,2,2,1,1,1,1,1,1,1,1,1,1,1,1,1,1,1,1,1,1,1
1,1,2,2,2,2,2,2,2,2,2,2,2,1,1,1,1,1,1,1,1,1,1,1,1,1,1,1,1,1,1,1
1,1,1,2,2,2,2,2,2,2,2,2,2,1,1,1,1,1,1,1,1,1,1,1,1,1,1,1,1,1,1,1
1,1,1,2,2,2,2,2,2,2,2,2,2,1,1,1,1,1,1,1,1,1,1,1,1,1,1,1,1,1,1,1
1,1,1,2,2,2,2,2,2,2,2,2,2,1,1,1,1,1,1,1,1,1,1,1,1,1,1,1,1,1,1,1
1,1,1,2,2,2,2,2,2,2,2,2,2,1,1,1,1,1,1,1,1,1,1,1,1,1,1,1,1,1,1,1
1,1,1,2,2,2,2,2,2,2,2,2,2,1,1,1,1,1,1,1,1,1,1,1,1,1,1,1,1,1,1,1
:endlayer
layer: 2
3,3,3,2,2,2,2,2,2,2,2,2,2,1,1,1,3,3,3,3,3,3,3,3,3,3,3,3,3,3,3,3
3,3,3,3,2,2,2,2,2,2,2,2,2,1,1,1,3,3,3,3,3,3,3,3,3,3,3,3,3,3,3,3
3,3,3,3,2,2,2,2,2,2,2,2,2,1,1,1,3,3,3,3,3,3,2,2,2,2,3,3,3,3,3,3
3,3,3,3,2,2,2,2,2,2,2,2,2,1,1,1,3,3,3,3,3,2,2,2,2,2,2,3,3,3,3,3
3,3,2,2,2,2,2,2,2,2,2,2,2,1,1,1,3,3,3,3,2,2,2,2,2,2,2,2,3,3,3,3
3,2,2,2,2,2,2,2,2,2,2,2,2,1,1,1,3,3,3,2,2,2,2,2,2,2,2,2,2,3,3,3
2,2,2,2,2,2,2,2,2,2,2,2,2,1,1,1,3,3,3,2,2,2,2,2,2,2,2,2,2,2,3,3
2,2,2,2,2,2,2,2,2,2,2,2,2,1,1,1,3,3,2,2,2,2,2,2,2,2,2,2,2,2,3,3
2,2,2,2,2,2,2,2,2,2,2,2,2,1,1,1,3,3,2,2,2,2,2,2,2,2,2,2,2,2,3,3
2,2,2,2,2,2,2,2,2,2,2,2,2,1,1,1,3,3,3,2,2,2,2,2,2,2,2,2,2,2,3,3
3,2,2,2,2,2,2,2,2,2,2,2,2,1,1,1,3,3,3,2,2,2,2,2,2,2,2,2,2,3,3,3
3,3,2,2,2,2,2,2,2,2,2,2,2,1,1,1,3,3,3,3,2,2,2,2,2,2,2,2,3,3,3,3
3,3,3,3,2,2,2,2,2,2,2,2,2,1,1,1,3,3,3,3,3,2,2,2,2,2,2,3,3,3,3,3
3,3,3,3,2,2,2,2,2,2,2,2,2,1,1,1,3,3,3,3,3,3,3,2,2,3,3,3,3,3,3,3
3,3,3,3,2,2,2,2,2,2,2,2,2,1,1,1,3,3,3,3,3,3,3,3,3,3,3,3,3,3,3,3
3,3,3,2,2,2,2,2,2,2,2,2,2,1,1,1,3,3,3,3,3,3,3,3,3,3,3,3,3,3,3,3
:endlayer
layer: 3
3,3,3,2,2,2,2,2,2,2,2,2,2,1,1,1,3,3,3,3,3,3,3,3,3,3,3,3,3,3,3,3
3,3,3,3,2,2,2,2,2,2,2,2,2,1,1,1,3,3,3,3,3,3,3,3,3,3,3,3,3,3,3,3
3,3,3,3,2,2,2,2,2,2,2,2,2,1,1,1,3,3,3,3,3,3,2,2,2,2,3,3,3,3,3,3
3,3,3,3,2,2,2,2,2,2,2,2,2,1,1,1,3,3,3,3,3,2,2,2,2,2,2,3,3,3,3,3
3,3,2,2,2,2,2,2,2,2,2,2,2,1,1,1,3,3,3,3,2,2,2,2,2,2,2,2,3,3,3,3
3,2,2,2,2,2,2,2,2,2,2,2,2,1,1,1,3,3,3,2,2,2,2,2,2,2,2,2,2,3,3,3
2,2,2,2,2,2,2,2,2,2,2,2,2,1,1,1,3,3,3,2,2,2,2,2,2,2,2,2,2,2,3,3
2,2,2,2,2,2,2,2,2,2,2,2,2,1,1,1,3,3,2,2,2,2,2,2,2,2,2,2,2,2,3,3
2,2,2,2,2,2,2,2,2,2,2,2,2,1,1,1,3,3,2,2,2,2,2,2,2,2,2,2,2,2,3,3
2,2,2,2,2,2,2,2,2,2,2,2,2,1,1,1,3,3,3,2,2,2,2,2,2,2,2,2,2,2,3,3
3,2,2,2,2,2,2,2,2,2,2,2,2,1,1,1,3,3,3,2,2,2,2,2,2,2,2,2,2,3,3,3
3,3,2,2,2,2,2,2,2,2,2,2,2,1,1,1,3,3,3,3,2,2,2,2,2,2,2,2,3,3,3,3
3,3,3,3,2,2,2,2,2,2,2,2,2,1,1,1,3,3,3,3,3,2,2,2,2,2,2,3,3,3,3,3
3,3,3,3,2,2,2,2,2,2,2,2,2,1,1,1,3,3,3,3,3,3,3,2,2,3,3,3,3,3,3,3
3,3,3,3,2,2,2,2,2,2,2,2,2,1,1,1,3,3,3,3,3,3,3,3,3,3,3,3,3,3,3,3
3,3,3,2,2,2,2,2,2,2,2,2,2,1,1,1,3,3,3,3,3,3,3,3,3,3,3,3,3,3,3,3
:endlayer
layer: 4
4,4,4,2,2,2,2,2,2,2,2,2,2,5,5,5,4,4,4,4,4,4,4,5,5,4,4,4,4,4,4,4
4,4,4,4,2,2,2,2,2,2,2,2,5,5,5,5,4,4,4,4,4,4,4,5,5,4,4,4,4,4,4,4
4,4,4,4,2,2,2,2,2,2,2,2,5,5,5,5,4,4,4,4,4,4,2,2,2,2,4,4,4,4,4,4
4,4,4,4,2,2,2,2,2,2,2,2,5,5,5,5,4,4,4,4,4,2,2,2,2,2,2,4,4,4,4,4
4,4,2,2,2,2,2,2,2,2,2,2,5,5,5,5,4,4,4,4,2,2,2,2,2,2,2,2,4,4,4,4
4,2,2,2,2,2,2,2,2,2,2,2,5,5,5,5,4,4,4,2,2,2,2,2,2,2,2,2,2,4,4,4
2,2,2,2,2,2,2,2,2,2,2,2,5,5,5,5,4,4,4,2,2,2,2,2,2,2,2,2,2,2,4,4
2,2,2,2,2,2,2,2,2,2,2,2,2,5,5,5,4,4,2,2,2,2,2,2,2,2,2,2,2,2,5,5
2,2,2,2,2,2,2,2,2,2,2,2,2,5,5,5,4,4,2,2,2,2,2,2,2,2,2,2,2,2,5,5
2,2,2,2,2,2,2,2,2,2,2,2,5,5,5,5,4,4,4,2,2,2,2,2,2,2,2,2,2,2,4,4
4,2,2,2,2,2,2,2,2,2,2,2,5,5,5,5,4,4,4,2,2,2,2,2,2,2,2,2,2,4,4,4
4,4,2,2,2,2,2,2,2,2,2,2,5,5,5,5,4,4,4,4,2,2,2,2,2,2,2,2,4,4,4,4
4,4,4,4,2,2,2,2,2,2,2,2,5,5,5,5,4,4,4,4,4,2,2,2,2,2,2,4,4,4,4,4
4,4,4,4,2,2,2,2,2,2,2,2,5,5,5,5,4,4,4,4,4,4,4,2,2,4,4,4,4,4,4,4
4,4,4,4,2,2,2,2,2,2,2,2,5,5,5,5,4,4,4,4,4,4,4,4,4,4,4,4,4,4,4,4
4,4,4,2,2,2,2,2,2,2,2,2,2,5,5,5,4,4,4,4,4,4,4,4,4,4,4,4,4,4,4,4
:endlayer
layer: 5
0,0,0,2,2,2,2,2,2,2,2,2,2,0,0,0,0,0,0,0,0,0,0,0,0,0,0,0,0,0,0,0
0,0,0,0,2,2,2,2,2,2,2,2,0,0,0,0,0,0,0,0,0,0,0,0,0,0,0,0,0,0,0,0
0,0,0,0,2,2,2,2,2,2,2,2,6,0,0,0,0,0,0,0,0,0,2,0,0,2,0,0,0,0,0,0
0,0,0,0,2,2,2,2,2,2,2,2,7,0,0,0,0,0,0,0,0,2,2,0,0,2,2,0,0,0,0,0
0,0,2,2,2,2,2,2,2,2,2,2,7,0,0,0,0,0,0,0,2,2,2,0,0,2,2,2,0,0,0,0
0,2,2,2,2,2,2,2,2,2,2,2,6,0,0,0,0,0,0,2,2,2,0,0,0,0,2,2,2,0,0,0
2,2,2,2,2,2,2,2,2,2,2,2,0,0,0,0,0,0,0,2,2,0,0,0,0,0,0,2,2,2,0,0
2,2,2,2,2,2,2,2,2,2,2,2,2,0,0,0,0,0,2,2,2,8,8,2,2,0,0,0,0,0,0,0
2,2,2,2,2,2,2,2,2,2,2,2,2,0,0,0,0,0,2,2,2,7,7,2,2,0,0,0,0,0,0,0
2,2,2,2,2,2,2,2,2,2,2,2,0,0,0,0,0,0,0,2,2,0,0,0,0,0,0,2,2,2,0,0
0,2,2,2,2,2,2,2,2,2,2,2,6,0,0,0,0,0,0,2,2,2,0,0,0,0,2,2,2,0,0,0
0,0,2,2,2,2,2,2,2,2,2,2,7,0,0,0,0,0,0,0,2,2,2,2,2,2,2,2,0,0,0,0
0,0,0,0,2,2,2,2,2,2,2,2,7,0,0,0,0,0,0,0,0,2,2,2,2,2,2,0,0,0,0,0
0,0,0,0,2,2,2,2,2,2,2,2,6,0,0,0,0,0,0,0,0,0,0,2,2,0,0,0,0,0,0,0
0,0,0,0,2,2,2,2,2,2,2,2,0,0,0,0,0,0,0,0,0,0,0,0,0,0,0,0,0,0,0,0
0,0,0,2,2,2,2,2,2,2,2,2,2,0,0,0,0,0,0,0,0,0,0,0,0,0,0,0,0,0,0,0
:endlayer
layer: 6
0,0,9,2,2,2,2,2,2,2,2,2,2,0,0,0,0,0,0,0,0,0,0,0,0,0,0,0,0,0,0,0
0,0,0,7,2,2,2,2,2,2,2,2,0,0,0,0,0,0,0,0,0,0,0,0,0,0,0,0,0,0,0,0
0,0,0,9,2,2,2,2,2,2,2,2,0,0,0,0,0,0,0,0,0,0,2,0,0,2,0,0,0,0,0,0
0,0,0,7,2,2,2,2,2,2,2,2,0,0,0,0,0,0,0,0,0,2,2,0,0,2,2,0,0,0,0,0
0,0,2,2,2,2,2,2,2,2,2,2,0,0,0,0,0,0,0,0,2,2,2,0,0,2,2,2,0,0,0,0
0,2,2,2,2,2,2,2,2,2,2,2,0,0,0,0,0,0,0,2,2,2,0,0,0,0,2,2,2,0,0,0
2,2,2,2,2,2,2,2,2,2,2,2,0,0,0,0,0,0,0,2,2,0,0,0,0,0,0,2,2,2,0,0
2,2,2,2,2,2,2,2,2,2,2,2,2,0,0,0,0,0,2,2,2,0,0,2,2,0,0,0,0,0,0,0
2,2,2,2,2,2,2,2,2,2,2,2,2,0,0,0,0,0,2,2,2,0,0,2,2,0,0,0,0,0,0,0
2,2,2,2,2,2,2,2,2,2,2,2,0,0,0,0,0,0,0,2,2,8,8,7,0,0,0,2,2,2,0,0
0,2,2,2,2,2,2,2,2,2,2,2,0,0,0,0,0,0,0,2,2,2,8,7,0,0,2,2,2,0,0,0
0,0,2,2,2,2,2,2,2,2,2,2,0,0,0,0,0,0,0,0,2,2,2,2,2,2,2,2,0,0,0,0
0,0,0,7,2,2,2,2,2,2,2,2,0,0,0,0,0,0,0,0,0,2,2,2,2,2,2,0,0,0,0,0
0,0,0,9,2,2,2,2,2,2,2,2,0,0,0,0,0,0,0,0,0,0,0,2,2,0,0,0,0,0,0,0
0,0,0,7,2,2,2,2,2,2,2,2,0,0,0,0,0,0,0,0,0,0,0,0,0,0,0,0,0,0,0,0
0,0,9,2,2,2,2,2,2,2,2,2,2,0,0,0,0,0,0,0,0,0,0,0,0,0,0,0,0,0,0,0
:endlayer
layer: 7
0,0,8,2,2,2,2,2,2,2,2,2,2,0,0,0,0,0,0,0,0,0,0,0,0,0,0,0,0,0,0,0
0,0,0,0,2,2,2,2,2,2,2,2,0,0,0,0,0,0,0,0,0,0,0,0,0,0,0,0,0,0,0,0
0,0,0,8,2,2,2,2,2,2,2,2,0,0,0,0,0,0,0,0,0,9,2,10,10,2,11,0,0,0,0,0
0,0,0,0,2,2,2,2,2,2,2,2,0,0,0,0,0,0,0,0,10,2,2,2,2,2,2,10,0,0,0,0
0,0,2,2,2,2,2,2,2,2,2,2,0,0,0,0,0,0,0,9,2,2,2,12,12,2,2,2,11,0,0,0
0,2,2,2,2,2,2,2,2,2,2,2,0,0,0,0,0,0,0,2,2,2,0,0,0,0,2,2,2,10,0,0
2,2,2,2,2,2,2,2,2,2,2,2,0,0,0,0,0,0,10,2,2,0,0,0,0,0,0,2,2,2,0,0
2,2,2,2,2,2,2,2,2,2,2,2,2,0,0,0,0,0,2,2,2,0,0,2,2,0,0,9,2,11,0,0
2,2,2,2,2,2,2,2,2,2,2,2,2,0,0,0,0,0,2,2,2,0,0,2,2,0,0,9,2,11,0,0
2,2,2,2,2,2,2,2,2,2,2,2,0,0,0,0,0,0,12,2,2,0,0,0,8,7,7,2,2,2,0,0
0,2,2,2,2,2,2,2,2,2,2,2,0,0,0,0,0,0,0,2,2,2,0,0,8,7,2,2,2,12,0,0
0,0,2,2,2,2,2,2,2,2,2,2,0,0,0,0,0,0,0,9,2,2,2,2,2,2,2,2,11,0,0,0
0,0,0,0,2,2,2,2,2,2,2,2,0,0,0,0,0,0,0,0,12,2,2,2,2,2,2,12,0,0,0,0
0,0,0,8,2,2,2,2,2,2,2,2,0,0,0,0,0,0,0,0,0,0,9,2,2,11,0,0,0,0,0,0
0,0,0,0,2,2,2,2,2,2,2,2,0,0,0,0,0,0,0,0,0,0,0,0,0,0,0,0,0,0,0,0
0,0,8,2,2,2,2,2,2,2,2,2,2,0,0,0,0,0,0,0,0,0,0,0,0,0,0,0,0,0,0,0
:endlayer
layer: 8
0,0,0,2,2,2,2,2,2,2,2,2,2,0,0,0,0,0,0,0,0,0,0,0,0,0,0,0,0,0,0,0
0,0,0,0,13,2,2,2,2,2,2,2,0,0,0,0,0,0,0,0,0,0,8,7,7,8,0,0,0,0,0,0
0,0,0,0,2,2,2,2,2,2,2,2,0,0,0,0,0,0,0,0,0,8,2,2,2,2,8,0,0,0,0,0
0,0,0,0,13,2,2,2,2,2,2,2,0,0,0,0,0,0,0,13,6,2,2,2,2,2,2,14,13,0,0,0
0,0,13,2,2,2,2,2,2,2,2,2,0,0,0,0,0,0,0,15,2,2,2,2,2,2,2,2,15,0,0,0
0,16,2,2,2,2,2,2,2,2,2,2,0,0,0,0,0,0,8,2,2,2,0,0,0,0,2,2,2,8,0,0
14,2,2,2,2,2,2,2,2,2,2,2,0,0,0,0,0,0,8,2,2,0,0,0,0,0,0,2,2,2,8,0
2,2,2,2,2,2,2,2,2,2,2,2,2,0,0,0,0,7,2,2,2,0,0,2,2,7,7,2,2,2,7,0
2,2,2,2,2,2,2,2,2,2,2,2,2,0,0,0,0,7,2,2,2,0,0,2,2,8,8,2,2,2,7,0
14,2,2,2,2,2,2,2,2,2,2,2,0,0,0,0,0,0,8,2,2,0,0,0,0,0,0,2,2,2,8,0
0,15,2,2,2,2,2,2,2,2,2,2,0,0,0,0,0,0,8,2,2,2,0,0,0,0,2,2,2,8,0,0
0,0,13,2,2,2,2,2,2,2,2,2,0,0,0,0,0,0,0,16,2,2,2,2,2,2,2,2,16,0,0,0
0,0,0,0,13,2,2,2,2,2,2,2,0,0,0,0,0,0,0,13,6,2,2,2,2,2,2,14,13,0,0,0
0,0,0,0,2,2,2,2,2,2,2,2,0,0,0,0,0,0,0,0,0,8,8,2,2,8,8,0,0,0,0,0
0,0,0,0,13,2,2,2,2,2,2,2,0,0,0,0,0,0,0,0,0,0,0,7,7,0,0,0,0,0,0,0
0,0,0,2,2,2,2,2,2,2,2,2,2,0,0,0,0,0,0,0,0,0,0,0,0,0,0,0,0,0,0,0
:endlayer
layer: 9
0,0,0,2,2,2,2,2,2,2,2,2,2,0,0,0,0,0,0,0,0,0,0,0,0,0,0,0,0,0,0,0
0,0,0,0,2,2,2,2,2,2,2,2,0,0,0,0,0,0,0,0,0,0,0,0,0,0,0,0,0,0,0,0
0,0,0,0,14,2,2,2,2,2,2,6,0,0,0,0,0,0,0,0,0,0,14,2,2,6,0,0,0,0,0,0
0,0,0,0,2,2,2,2,2,2,2,6,0,0,0,0,0,0,0,8,0,2,2,2,2,2,2,0,8,0,0,0
0,0,17,2,2,2,2,2,2,2,2,6,0,0,0,0,0,0,0,0,2,2,2,2,2,2,2,2,0,0,0,0
0,0,2,2,2,2,2,2,2,2,2,6,0,0,0,0,0,0,0,2,2,2,0,0,7,8,2,2,2,0,0,0
0,2,2,2,2,2,2,2,2,2,2,2,0,0,0,0,0,0,0,2,2,0,0,0,7,8,8,2,2,16,0,0
14,2,2,2,2,2,2,2,2,2,2,2,2,0,0,0,0,0,2,2,2,0,0,2,2,0,0,2,2,2,0,0
14,2,2,2,2,2,2,2,2,2,2,2,2,0,0,0,0,0,2,2,2,0,0,2,2,0,0,2,2,2,0,0
0,2,2,2,2,2,2,2,2,2,2,2,0,0,0,0,0,0,0,2,2,0,0,0,0,0,0,2,2,15,0,0
0,0,2,2,2,2,2,2,2,2,2,6,0,0,0,0,0,0,0,2,2,2,0,0,0,0,2,2,2,0,0,0
0,0,17,2,2,2,2,2,2,2,2,6,0,0,0,0,0,0,0,0,2,2,2,2,2,2,2,2,0,0,0,0
0,0,0,0,2,2,2,2,2,2,2,6,0,0,0,0,0,0,0,8,0,2,2,2,2,2,2,0,8,0,0,0
0,0,0,0,14,2,2,2,2,2,2,6,0,0,0,0,0,0,0,0,0,0,0,2,2,0,0,0,0,0,0,0
0,0,0,0,2,2,2,2,2,2,2,2,0,0,0,0,0,0,0,0,0,0,0,0,0,0,0,0,0,0,0,0
0,0,0,2,2,2,2,2,2,2,2,2,2,0,0,0,0,0,0,0,0,0,0,0,0,0,0,0,0,0,0,0
:endlayer
layer: 10
0,0,0,2,2,2,2,2,2,2,2,2,2,0,0,0,0,0,0,0,0,0,0,0,0,0,0,0,0,0,0,0
0,0,0,0,14,2,2,2,2,2,2,6,0,0,0,0,0,0,0,0,0,0,0,0,0,0,0,0,0,0,0,0
0,0,0,0,0,2,2,2,2,2,2,0,0,0,0,0,0,0,0,0,0,0,0,2,2,0,0,0,0,0,0,0
0,0,0,0,14,2,2,2,2,2,2,0,0,0,0,0,0,0,0,0,0,2,2,2,2,2,2,0,0,0,0,0
0,0,17,2,2,2,2,2,2,2,2,0,0,0,0,0,0,0,0,0,2,2,2,2,2,2,2,2,0,0,0,0
0,0,2,2,2,2,2,2,2,2,2,0,0,0,0,0,0,0,0,2,2,2,7,8,0,0,2,2,2,0,0,0
0,2,2,2,2,2,2,2,2,2,2,6,0,0,0,0,0,0,0,2,2,7,7,8,0,0,0,2,2,0,0,0
0,2,2,2,2,2,2,2,2,2,2,2,2,0,0,0,0,0,2,2,2,0,0,2,2,0,0,2,2,2,0,0
0,2,2,2,2,2,2,2,2,2,2,2,2,0,0,0,0,0,2,2,2,0,0,2,2,0,0,2,2,2,0,0
0,2,2,2,2,2,2,2,2,2,2,6,0,0,0,0,0,0,0,2,2,0,0,0,0,0,0,2,2,0,0,0
0,0,2,2,2,2,2,2,2,2,2,0,0,0,0,0,0,0,0,2,2,2,0,0,0,0,2,2,2,0,0,0
0,0,17,2,2,2,2,2,2,2,2,0,0,0,0,0,0,0,0,0,2,2,2,2,2,2,2,2,0,0,0,0
0,0,0,0,14,2,2,2,2,2,2,0,0,0,0,0,0,0,0,0,0,2,2,2,2,2,2,0,0,0,0,0
0,0,0,0,0,2,2,2,2,2,2,0,0,0,0,0,0,0,0,0,0,0,0,2,2,0,0,0,0,0,0,0
0,0,0,0,14,2,2,2,2,2,2,6,0,0,0,0,0,0,0,0,0,0,0,0,0,0,0,0,0,0,0,0
0,0,0,2,2,2,2,2,2,2,2,2,2,0,0,0,0,0,0,0,0,0,0,0,0,0,0,0,0,0,0,0
:endlayer
layer: 11
0,0,0,14,2,2,2,2,2,2,2,2,0,0,0,0,0,0,0,0,0,0,0,0,0,0,0,0,0,0,0,0
0,0,0,0,0,2,2,2,2,2,2,0,0,0,0,0,0,0,0,0,0,0,0,0,0,0,0,0,0,0,0,0
0,0,0,0,0,2,2,2,2,2,2,0,0,0,0,0,0,0,0,0,0,0,0,16,16,0,0,0,0,0,0,0
0,0,0,0,0,2,2,2,2,2,2,0,0,0,0,0,0,0,0,0,0,14,2,2,2,2,6,0,0,0,0,0
0,0,17,2,2,2,2,2,2,2,2,0,0,0,0,0,0,0,0,0,2,2,2,2,2,2,2,2,0,0,0,0
0,0,2,2,2,2,2,2,2,2,2,0,0,0,0,0,0,0,0,16,2,2,0,0,0,0,2,2,16,0,0,0
0,2,2,2,2,2,2,2,2,2,2,0,0,0,0,0,0,0,0,2,2,0,0,0,0,0,0,2,2,0,0,0
0,2,2,2,2,2,2,2,2,2,2,2,6,0,0,0,0,0,14,2,2,8,8,2,2,0,0,2,2,6,0,0
0,2,2,2,2,2,2,2,2,2,2,2,6,0,0,0,0,0,14,2,2,7,7,2,2,0,0,2,2,6,0,0
0,2,2,2,2,2,2,2,2,2,2,0,0,0,0,0,0,0,0,2,2,0,0,0,0,0,0,2,2,0,0,0
0,0,2,2,2,2,2,2,2,2,2,0,0,0,0,0,0,0,0,15,2,2,0,0,0,0,2,2,15,0,0,0
0,0,17,2,2,2,2,2,2,2,2,0,0,0,0,0,0,0,0,0,2,2,2,2,2,2,2,2,0,0,0,0
0,0,0,0,0,2,2,2,2,2,2,0,0,0,0,0,0,0,0,0,0,14,2,2,2,2,6,0,0,0,0,0
0,0,0,0,0,2,2,2,2,2,2,0,0,0,0,0,0,0,0,0,0,0,0,15,15,0,0,0,0,0,0,0
0,0,0,0,0,2,2,2,2,2,2,0,0,0,0,0,0,0,0,0,0,0,0,0,0,0,0,0,0,0,0,0
0,0,0,14,2,2,2,2,2,2,2,2,6,0,0,0,0,0,0,0,0,0,0,0,0,0,0,0,0,0,0,0
:endlayer
layer: 12
0,0,0,0,2,2,2,2,2,2,2,2,0,0,0,0,0,0,0,0,0,0,0,0,0,0,0,0,0,0,0,0
0,0,0,0,0,2,2,2,2,2,2,0,0,0,0,0,0,0,0,0,0,0,0,0,0,0,0,0,0,0,0,0
0,0,0,0,0,2,2,2,2,2,2,0,0,0,0,0,0,0,0,0,0,0,0,0,0,0,0,0,0,0,0,0
0,0,0,0,0,2,2,2,2,2,2,0,0,0,0,0,0,0,0,0,0,0,2,2,2,2,0,0,0,0,0,0
0,0,17,2,2,2,2,2,2,2,2,0,0,0,0,0,0,0,0,0,2,2,2,2,2,2,2,2,0,0,0,0
0,0,2,2,2,2,2,2,2,2,2,0,0,0,0,0,0,0,0,0,2,2,0,0,0,0,2,2,0,0,0,0
0,2,2,2,2,2,2,2,2,2,2,0,0,0,0,0,0,0,0,2,2,0,0,0,0,0,0,2,2,0,0,0
0,2,2,2,2,2,2,2,2,2,2,2,0,0,0,0,0,0,0,2,2,0,0,2,2,0,0,2,2,0,0,0
0,2,2,2,2,2,2,2,2,2,2,2,0,0,0,0,0,0,0,2,2,0,0,2,2,0,0,2,2,0,0,0
0,2,2,2,2,2,2,2,2,2,2,0,0,0,0,0,0,0,0,2,2,8,8,7,0,0,0,2,2,0,0,0
0,0,2,2,2,2,2,2,2,2,2,0,0,0,0,0,0,0,0,0,2,2,8,7,0,0,2,2,0,0,0,0
0,0,17,2,2,2,2,2,2,2,2,0,0,0,0,0,0,0,0,0,2,2,2,2,2,2,2,2,0,0,0,0
0,0,0,0,0,2,2,2,2,2,2,0,0,0,0,0,0,0,0,0,0,0,2,2,2,2,0,0,0,0,0,0
0,0,0,0,0,2,2,2,2,2,2,0,0,0,0,0,0,0,0,0,0,0,0,0,0,0,0,0,0,0,0,0
0,0,0,0,0,2,2,2,2,2,2,0,0,0,0,0,0,0,0,0,0,0,0,0,0,0,0,0,0,0,0,0
0,0,0,0,2,2,2,2,2,2,2,2,0,0,0,0,0,0,0,0,0,0,0,0,0,0,0,0,0,0,0,0
:endlayer
layer: 13
0,0,0,0,2,2,2,2,2,2,2,2,0,0,0,0,0,0,0,0,0,0,0,0,0,0,0,0,0,0,0,0
0,0,0,0,0,2,2,2,2,2,2,0,0,0,0,0,0,0,0,0,0,0,0,0,0,0,0,0,0,0,0,0
0,0,0,0,0,2,2,2,2,2,2,0,0,0,0,0,0,0,0,0,0,0,0,0,0,0,0,0,0,0,0,0
0,0,0,0,0,2,2,2,2,2,2,0,0,0,0,0,0,0,0,0,0,0,2,2,2,2,0,0,0,0,0,0
0,0,17,2,2,2,2,2,2,2,2,0,0,0,0,0,0,0,0,0,2,2,2,2,2,2,2,2,0,0,0,0
0,0,2,2,2,2,2,2,2,2,2,0,0,0,0,0,0,0,0,0,2,2,0,0,0,0,2,2,0,0,0,0
0,2,2,2,2,2,2,2,2,2,2,0,0,0,0,0,0,0,0,2,2,0,0,0,0,0,0,2,2,0,0,0
0,2,2,2,2,2,2,2,2,2,2,2,0,0,0,0,0,0,0,2,2,0,0,2,2,0,0,2,2,0,0,0
0,2,2,2,2,2,2,2,2,2,2,2,0,0,0,0,0,0,0,2,2,0,0,2,2,0,0,2,2,0,0,0
0,2,2,2,2,2,2,2,2,2,2,0,0,0,0,0,0,0,0,2,2,0,0,0,8,7,7,2,2,0,0,0
0,0,2,2,2,2,2,2,2,2,2,0,0,0,0,0,0,0,0,0,2,2,0,0,8,7,2,2,0,0,0,0
0,0,17,2,2,2,2,2,2,2,2,0,0,0,0,0,0,0,0,0,2,2,2,2,2,2,2,2,0,0,0,0
0,0,0,0,0,2,2,2,2,2,2,0,0,0,0,0,0,0,0,0,0,0,2,2,2,2,0,0,0,0,0,0
0,0,0,0,0,2,2,2,2,2,2,0,0,0,0,0,0,0,0,0,0,0,0,0,0,0,0,0,0,0,0,0
0,0,0,0,0,2,2,2,2,2,2,0,0,0,0,0,0,0,0,0,0,0,0,0,0,0,0,0,0,0,0,0
0,0,0,0,2,2,2,2,2,2,2,2,0,0,0,0,0,0,0,0,0,0,0,0,0,0,0,0,0,0,0,0
:endlayer
layer: 14
0,0,0,0,2,2,2,2,2,2,2,2,0,0,0,0,0,0,0,0,0,0,0,0,0,0,0,0,0,0,0,0
0,0,0,0,0,2,2,2,2,2,2,0,0,0,0,0,0,0,0,0,0,0,0,0,0,0,0,0,0,0,0,0
0,0,0,0,0,2,2,2,2,2,2,0,0,0,0,0,0,0,0,0,0,0,0,0,0,0,0,0,0,0,0,0
0,0,0,0,0,2,2,2,2,2,2,0,0,0,0,0,0,0,0,0,0,0,2,2,2,2,0,0,0,0,0,0
0,0,17,2,2,2,2,2,2,2,2,0,0,0,0,0,0,0,0,0,2,2,2,2,2,2,2,2,0,0,0,0
0,0,2,2,2,2,2,2,2,2,2,0,0,0,0,0,0,0,0,0,2,2,0,0,0,0,2,2,0,0,0,0
0,2,2,2,2,2,2,2,2,2,2,0,0,0,0,0,0,0,0,2,2,0,0,0,0,0,0,2,2,0,0,0
0,2,2,2,2,2,2,2,2,2,2,2,0,0,0,0,0,0,0,2,2,0,0,2,2,7,7,2,2,0,0,0
0,2,2,2,2,2,2,2,2,2,2,2,0,0,0,0,0,0,0,2,2,0,0,2,2,8,8,2,2,0,0,0
0,2,2,2,2,2,2,2,2,2,2,0,0,0,0,0,0,0,0,2,2,0,0,0,0,0,0,2,2,0,0,0
0,0,2,2,2,2,2,2,2,2,2,0,0,0,0,0,0,0,0,0,2,2,0,0,0,0,2,2,0,0,0,0
0,0,17,2,2,2,2,2,2,2,2,0,0,0,0,0,0,0,0,0,2,2,2,2,2,2,2,2,0,0,0,0
0,0,0,0,0,2,2,2,2,2,2,0,0,0,0,0,0,0,0,0,0,0,2,2,2,2,0,0,0,0,0,0
0,0,0,0,0,2,2,2,2,2,2,0,0,0,0,0,0,0,0,0,0,0,0,0,0,0,0,0,0,0,0,0
0,0,0,0,0,2,2,2,2,2,2,0,0,0,0,0,0,0,0,0,0,0,0,0,0,0,0,0,0,0,0,0
0,0,0,0,2,2,2,2,2,2,2,2,0,0,0,0,0,0,0,0,0,0,0,0,0,0,0,0,0,0,0,0
:endlayer
layer: 15
0,0,0,0,2,2,2,2,2,2,2,2,0,0,0,0,0,0,0,0,0,0,0,0,0,0,0,0,0,0,0,0
0,0,0,0,0,2,2,2,2,2,2,0,0,0,0,0,0,0,0,0,0,0,0,0,0,0,0,0,0,0,0,0
0,0,0,0,0,2,2,2,2,2,2,0,0,0,0,0,0,0,0,0,0,0,0,0,0,0,0,0,0,0,0,0
0,0,7,10,7,2,2,2,2,2,2,0,0,0,0,0,0,0,0,0,0,0,2,2,2,2,0,0,0,0,0,0
0,7,2,2,2,2,2,2,2,2,2,0,0,0,0,0,0,0,0,0,2,2,2,2,2,2,2,2,0,0,0,0
0,9,2,2,2,2,2,2,2,2,2,0,0,0,0,0,0,0,0,9,2,2,0,0,7,8,2,2,0,0,0,0
7,2,2,2,2,2,2,2,2,2,2,0,0,0,0,0,0,0,0,2,2,0,0,0,7,8,8,2,2,0,0,0
9,2,2,2,2,2,2,2,2,2,2,2,0,0,0,0,0,0,0,2,2,0,0,2,2,0,0,2,2,0,0,0
9,2,2,2,2,2,2,2,2,2,2,2,0,0,0,0,0,0,0,2,2,0,0,2,2,0,0,2,2,0,0,0
7,2,2,2,2,2,2,2,2,2,2,0,0,0,0,0,0,0,0,2,2,0,0,0,0,0,0,2,2,0,0,0
0,9,2,2,2,2,2,2,2,2,2,0,0,0,0,0,0,0,0,9,2,2,0,0,0,0,2,2,0,0,0,0
0,7,2,2,2,2,2,2,2,2,2,0,0,0,0,0,0,0,0,0,2,2,2,2,2,2,2,2,0,0,0,0
0,0,7,12,7,2,2,2,2,2,2,0,0,0,0,0,0,0,0,0,0,0,2,2,2,2,0,0,0,0,0,0
0,0,0,0,0,2,2,2,2,2,2,0,0,0,0,0,0,0,0,0,0,0,0,0,0,0,0,0,0,0,0,0
0,0,0,0,0,2,2,2,2,2,2,0,0,0,0,0,0,0,0,0,0,0,0,0,0,0,0,0,0,0,0,0
0,0,0,0,2,2,2,2,2,2,2,2,0,0,0,0,0,0,0,0,0,0,0,0,0,0,0,0,0,0,0,0
:endlayer
layer: 16
0,0,0,0,2,2,2,2,2,2,2,2,0,0,0,0,0,0,0,0,0,0,0,0,0,0,0,0,0,0,0,0
0,0,0,0,0,2,2,2,2,2,2,0,0,0,0,0,0,0,0,0,0,0,0,0,0,0,0,0,0,0,0,0
0,0,0,0,0,2,2,2,2,2,2,0,0,0,0,0,0,0,0,0,0,0,0,0,0,0,0,0,0,0,0,0
0,0,0,8,0,2,2,2,2,2,2,0,0,0,0,0,0,0,0,0,0,0,2,2,2,2,0,0,0,0,0,0
0,0,17,2,2,2,2,2,2,2,2,0,0,0,0,0,0,0,0,0,2,2,2,2,2,2,2,2,0,0,0,0
0,8,2,2,2,2,2,2,2,2,2,0,0,0,0,0,0,0,0,2,2,2,7,8,0,0,2,2,0,0,0,0
0,2,2,2,2,2,2,2,2,2,2,0,0,0,0,0,0,0,0,2,2,7,7,8,0,0,0,2,2,0,0,0
8,14,2,2,2,2,2,2,2,2,2,2,0,0,0,0,0,0,0,2,2,0,0,2,2,0,0,2,2,0,0,0
8,2,2,2,2,2,2,2,2,2,2,2,0,0,0,0,0,0,0,2,2,0,0,2,2,0,0,2,2,0,0,0
0,2,2,2,2,2,2,2,2,2,2,0,0,0,0,0,0,0,0,2,2,0,0,0,0,0,0,2,2,0,0,0
0,8,2,2,2,2,2,2,2,2,2,0,0,0,0,0,0,0,0,2,2,2,0,0,0,0,2,2,0,0,0,0
0,0,17,2,2,2,2,2,2,2,2,0,0,0,0,0,0,0,0,0,2,2,2,2,2,2,2,2,0,0,0,0
0,0,0,8,0,2,2,2,2,2,2,0,0,0,0,0,0,0,0,0,0,0,2,2,2,2,0,0,0,0,0,0
0,0,0,0,0,2,2,2,2,2,2,0,0,0,0,0,0,0,0,0,0,0,0,0,0,0,0,0,0,0,0,0
0,0,0,0,0,2,2,2,2,2,2,0,0,0,0,0,0,0,0,0,0,0,0,0,0,0,0,0,0,0,0,0
0,0,0,0,2,2,2,2,2,2,2,2,0,0,0,0,0,0,0,0,0,0,0,0,0,0,0,0,0,0,0,0
:endlayer
layer: 17
0,0,0,0,13,2,2,2,2,2,2,13,0,0,0,0,0,0,0,0,0,0,0,0,0,0,0,0,0,0,0,0
0,0,0,0,12,2,2,2,2,2,2,12,0,0,0,0,0,0,0,0,0,0,0,0,0,0,0,0,0,0,0,0
0,0,0,0,0,2,2,2,2,2,2,0,0,0,0,0,0,0,0,0,0,0,0,0,0,0,0,0,0,0,0,0
0,0,0,0,10,2,2,2,2,2,2,0,0,0,0,0,0,0,0,0,0,0,2,2,2,2,0,0,0,0,0,0
0,0,17,2,2,2,2,2,2,2,2,0,0,0,0,0,0,0,0,0,2,2,2,2,2,2,2,2,0,0,0,0
0,0,2,2,2,2,2,2,2,2,2,0,0,0,0,0,0,0,0,2,2,2,0,0,0,0,2,2,0,0,0,0
0,2,2,2,2,2,2,2,2,2,2,10,0,0,0,0,0,0,0,2,2,0,0,0,0,0,0,2,2,0,0,0
0,0,13,2,2,2,2,2,2,2,2,13,0,0,0,0,0,0,0,2,2,8,8,2,2,0,0,2,2,0,0,0
0,2,2,2,2,2,2,2,2,2,2,13,0,0,0,0,0,0,0,2,2,7,7,2,2,0,0,2,2,0,0,0
0,2,2,2,2,2,2,2,2,2,2,12,0,0,0,0,0,0,0,2,2,0,0,0,0,0,0,2,2,0,0,0
0,0,2,2,2,2,2,2,2,2,2,0,0,0,0,0,0,0,0,2,2,2,0,0,0,0,2,2,0,0,0,0
0,0,17,2,2,2,2,2,2,2,2,0,0,0,0,0,0,0,0,0,2,2,2,2,2,2,2,2,0,0,0,0
0,0,0,0,12,2,2,2,2,2,2,0,0,0,0,0,0,0,0,0,0,0,2,2,2,2,0,0,0,0,0,0
0,0,0,0,0,2,2,2,2,2,2,0,0,0,0,0,0,0,0,0,0,0,0,0,0,0,0,0,0,0,0,0
0,0,0,0,10,2,2,2,2,2,2,10,0,0,0,0,0,0,0,0,0,0,0,0,0,0,0,0,0,0,0,0
0,0,0,0,13,2,2,2,2,2,2,13,0,0,0,0,0,0,0,0,0,0,0,0,0,0,0,0,0,0,0,0
:endlayer
layer: 18
0,0,0,0,2,2,2,2,2,2,2,2,11,0,0,0,0,0,0,0,0,0,0,0,0,0,0,0,0,0,0,0
0,0,0,0,2,2,2,2,2,2,2,2,0,0,0,0,0,0,0,0,0,0,0,0,0,0,0,0,0,0,0,0
0,0,0,0,2,2,2,2,2,2,2,12,0,0,0,0,0,0,0,0,0,0,0,0,0,0,0,0,0,0,0,0
0,0,0,0,2,2,2,2,2,2,2,7,0,0,0,0,0,0,0,0,0,0,2,2,2,2,0,0,0,0,0,0
0,0,17,2,2,2,2,2,2,2,2,7,0,0,0,0,0,0,0,0,2,2,2,2,2,2,2,2,0,0,0,0
0,0,2,2,2,2,2,2,2,2,2,10,0,0,0,0,0,0,9,2,2,2,0,0,0,0,2,2,0,0,0,0
0,2,2,2,2,2,2,2,2,2,2,2,0,0,0,0,0,0,0,2,2,0,0,0,0,0,0,2,2,0,0,0
0,9,2,2,2,2,2,2,2,2,2,2,11,0,0,0,0,0,0,2,2,0,0,2,2,0,0,2,2,0,0,0
0,2,2,2,2,2,2,2,2,2,2,2,11,0,0,0,0,0,0,2,2,0,0,2,2,0,0,2,2,0,0,0
0,2,2,2,2,2,2,2,2,2,2,2,0,0,0,0,0,0,0,2,2,8,8,7,0,0,0,2,2,0,0,0
0,0,2,2,2,2,2,2,2,2,2,12,0,0,0,0,0,0,9,2,2,2,8,7,0,0,2,2,0,0,0,0
0,0,17,2,2,2,2,2,2,2,2,7,0,0,0,0,0,0,0,0,2,2,2,2,2,2,2,2,0,0,0,0
0,0,0,0,2,2,2,2,2,2,2,7,0,0,0,0,0,0,0,0,0,0,2,2,2,2,0,0,0,0,0,0
0,0,0,0,2,2,2,2,2,2,2,10,0,0,0,0,0,0,0,0,0,0,0,0,0,0,0,0,0,0,0,0
0,0,0,0,2,2,2,2,2,2,2,2,0,0,0,0,0,0,0,0,0,0,0,0,0,0,0,0,0,0,0,0
0,0,0,0,2,2,2,2,2,2,2,2,11,0,0,0,0,0,0,0,0,0,0,0,0,0,0,0,0,0,0,0
:endlayer
layer: 19
0,0,0,9,2,2,2,2,2,2,2,2,13,0,0,0,0,0,0,0,0,0,0,0,0,0,0,0,0,0,0,0
0,0,0,0,2,2,2,2,2,2,2,2,0,0,0,0,0,0,0,0,0,0,0,0,0,0,0,0,0,0,0,0
0,0,0,9,2,2,2,2,2,2,2,2,0,0,0,0,0,0,0,0,0,0,0,0,0,0,0,0,0,0,0,0
0,0,0,0,2,2,2,2,2,2,2,2,0,0,0,0,0,0,0,0,0,0,2,2,2,2,0,0,0,0,0,0
0,0,17,2,2,2,2,2,2,2,2,2,0,0,0,0,0,0,0,0,2,2,2,2,2,2,2,2,0,0,0,0
0,0,2,2,2,2,2,2,2,2,2,2,11,0,0,0,0,0,2,2,2,2,0,0,0,0,2,2,0,0,0,0
0,2,2,2,2,2,2,2,2,2,2,2,0,0,0,0,0,0,9,2,2,0,0,0,0,0,0,2,2,0,0,0
0,2,2,2,2,2,2,2,2,2,2,2,13,0,0,0,0,0,9,2,2,0,0,2,2,0,0,2,2,0,0,0
0,2,2,2,2,2,2,2,2,2,2,2,13,0,0,0,0,0,9,2,2,0,0,2,2,0,0,2,2,0,0,0
0,2,2,2,2,2,2,2,2,2,2,2,0,0,0,0,0,0,9,2,2,0,0,0,8,7,7,2,2,0,0,0
0,0,2,2,2,2,2,2,2,2,2,2,11,0,0,0,0,0,2,2,2,2,0,0,8,7,2,2,0,0,0,0
0,0,17,2,2,2,2,2,2,2,2,2,0,0,0,0,0,0,0,0,2,2,2,2,2,2,2,2,0,0,0,0
0,0,0,0,2,2,2,2,2,2,2,2,0,0,0,0,0,0,0,0,0,0,2,2,2,2,0,0,0,0,0,0
0,0,0,9,2,2,2,2,2,2,2,2,0,0,0,0,0,0,0,0,0,0,0,0,0,0,0,0,0,0,0,0
0,0,0,0,2,2,2,2,2,2,2,2,0,0,0,0,0,0,0,0,0,0,0,0,0,0,0,0,0,0,0,0
0,0,0,9,2,2,2,2,2,2,2,2,13,0,0,0,0,0,0,0,0,0,0,0,0,0,0,0,0,0,0,0
:endlayer
layer: 20
0,0,0,2,2,2,2,2,2,2,2,2,2,0,0,0,0,0,0,0,0,0,0,0,0,0,0,0,0,0,0,0
0,0,0,9,2,2,2,2,2,2,2,2,12,0,0,0,0,0,0,0,0,0,0,0,0,0,0,0,0,0,0,0
0,0,0,2,2,2,2,2,2,2,2,2,7,0,0,0,0,0,0,0,0,0,0,0,0,0,0,0,0,0,0,0
0,0,0,9,2,2,2,2,2,2,2,2,0,0,0,0,0,0,0,0,0,0,2,2,2,2,0,0,0,0,0,0
0,0,17,2,2,2,2,2,2,2,2,2,0,0,0,0,0,0,0,0,2,2,2,2,2,2,2,2,0,0,0,0
0,0,2,2,2,2,2,2,2,2,2,2,2,11,0,0,0,9,2,2,2,2,0,0,0,0,2,2,0,0,0,0
0,2,2,2,2,2,2,2,2,2,2,2,10,0,0,0,0,0,2,2,2,0,0,0,0,0,0,2,2,0,0,0
0,2,2,2,2,2,2,2,2,2,2,2,2,0,0,0,0,0,2,2,2,0,0,2,2,7,7,2,2,0,0,0
0,14,2,2,2,2,2,2,2,2,2,2,2,0,0,0,0,0,2,2,2,0,0,2,2,8,8,2,2,0,0,0
0,2,2,2,2,2,2,2,2,2,2,2,12,0,0,0,0,0,2,2,2,0,0,0,0,0,0,2,2,0,0,0
0,0,2,2,2,2,2,2,2,2,2,2,2,11,0,0,0,9,2,2,2,2,0,0,0,0,2,2,0,0,0,0
0,0,17,2,2,2,2,2,2,2,2,2,0,0,0,0,0,0,0,0,2,2,2,2,2,2,2,2,0,0,0,0
0,0,0,9,2,2,2,2,2,2,2,2,0,0,0,0,0,0,0,0,0,0,2,2,2,2,0,0,0,0,0,0
0,0,0,2,2,2,2,2,2,2,2,2,7,0,0,0,0,0,0,0,0,0,0,0,0,0,0,0,0,0,0,0
0,0,0,9,2,2,2,2,2,2,2,2,10,0,0,0,0,0,0,0,0,0,0,0,0,0,0,0,0,0,0,0
0,0,0,2,2,2,2,2,2,2,2,2,2,0,0,0,0,0,0,0,0,0,0,0,0,0,0,0,0,0,0,0
:endlayer
layer: 21
0,0,0,2,2,2,2,2,2,2,2,2,2,11,0,0,0,0,0,0,0,0,0,0,0,0,0,0,0,0,0,0
0,0,0,2,2,2,2,2,2,2,2,2,2,11,0,0,0,0,0,0,0,0,0,0,0,0,0,0,0,0,0,0
0,0,0,13,2,2,2,2,2,2,2,2,2,7,0,0,0,0,0,0,0,0,0,10,10,0,0,0,0,0,0,0
0,0,0,2,2,2,2,2,2,2,2,2,2,7,0,0,0,0,0,0,0,10,2,2,2,2,10,0,0,0,0,0
0,0,17,2,2,2,2,2,2,2,2,2,2,10,7,10,7,10,7,10,2,2,2,2,2,2,2,2,0,0,0,0
0,0,2,2,2,2,2,2,2,2,2,2,2,2,2,2,2,2,2,2,2,2,0,0,7,8,2,2,11,0,0,0
0,2,2,2,2,2,2,2,2,2,2,2,2,11,7,7,9,2,2,2,2,0,0,0,7,8,8,2,2,0,0,0
0,2,2,2,2,2,2,2,2,2,2,2,2,11,0,0,9,2,2,2,2,0,0,2,2,0,0,2,2,11,0,0
0,0,13,2,2,2,2,2,2,2,2,2,2,11,0,0,9,2,2,2,2,0,0,2,2,0,0,2,2,11,0,0
0,2,2,2,2,2,2,2,2,2,2,2,2,11,7,7,9,2,2,2,2,0,0,0,0,0,0,2,2,0,0,0
0,0,2,2,2,2,2,2,2,2,2,2,2,2,2,2,2,2,2,2,2,2,0,0,0,0,2,2,11,0,0,0
0,0,17,2,2,2,2,2,2,2,2,2,2,12,7,12,7,12,7,12,2,2,2,2,2,2,2,2,0,0,0,0
0,0,0,2,2,2,2,2,2,2,2,2,2,7,0,0,0,0,0,0,0,12,2,2,2,2,12,0,0,0,0,0
0,0,0,13,2,2,2,2,2,2,2,2,2,7,0,0,0,0,0,0,0,0,0,12,12,0,0,0,0,0,0,0
0,0,0,2,2,2,2,2,2,2,2,2,2,11,0,0,0,0,0,0,0,0,0,0,0,0,0,0,0,0,0,0
0,0,0,2,2,2,2,2,2,2,2,2,2,11,0,0,0,0,0,0,0,0,0,0,0,0,0,0,0,0,0,0
:endlayer
layer: 22
0,0,0,2,2,2,8,0,0,0,0,0,8,2,0,0,0,0,0,0,0,0,0,0,0,0,0,0,0,0,0,0
0,0,0,14,2,2,8,8,8,8,8,8,8,6,0,0,0,0,0,0,0,0,0,0,0,0,0,0,0,0,0,0
0,0,0,2,2,2,2,2,2,2,2,2,2,2,0,0,0,0,0,0,0,0,10,2,2,10,0,0,0,0,0,0
0,0,0,14,2,8,8,2,2,2,2,2,2,2,10,7,10,7,10,7,10,2,2,2,2,2,2,11,0,0,0,0
0,0,17,2,2,0,0,2,2,2,2,2,2,2,2,2,2,2,2,2,2,2,2,2,2,2,2,2,10,0,0,0
0,0,2,2,8,0,0,18,2,2,2,2,2,2,2,2,2,2,2,2,2,2,7,8,0,0,2,2,2,0,0,0
0,2,2,2,8,0,0,19,2,2,2,2,2,2,2,2,2,2,2,2,2,7,7,8,0,0,0,2,2,11,0,0
0,2,2,2,2,2,2,2,2,2,2,2,2,2,2,2,2,2,2,2,2,0,0,2,2,0,0,2,2,2,0,0
0,9,2,2,2,2,2,2,2,2,2,2,2,2,2,2,2,2,2,2,2,0,0,2,2,0,0,2,2,2,0,0
0,2,2,2,2,2,2,2,2,2,2,2,2,2,2,2,2,2,2,2,2,0,0,0,0,0,0,2,2,11,0,0
0,0,2,2,2,2,2,2,2,2,2,2,2,2,2,2,2,2,2,2,2,2,0,0,0,0,2,2,2,0,0,0
0,0,17,2,2,2,2,2,2,2,2,2,2,2,2,2,2,2,2,2,2,2,2,2,2,2,2,2,12,0,0,0
0,0,0,14,2,2,2,2,2,2,2,2,2,2,12,7,12,7,12,7,12,2,2,2,2,2,2,11,0,0,0,0
0,0,0,2,2,2,2,2,2,2,2,2,2,2,0,0,0,0,0,0,0,0,12,2,2,12,0,0,0,0,0,0
0,0,0,14,2,2,8,8,8,8,8,8,8,6,0,0,0,0,0,0,0,0,0,0,0,0,0,0,0,0,0,0
0,0,0,2,2,2,8,0,0,0,0,0,8,2,0,0,0,0,0,0,0,0,0,0,0,0,0,0,0,0,0,0
:endlayer
layer: 23
0,0,0,2,0,0,0,0,0,0,0,0,0,8,0,0,0,0,0,0,0,0,0,0,0,0,0,0,0,0,0,0
0,0,0,0,0,0,0,0,0,0,0,0,0,0,0,0,0,0,0,0,0,0,0,0,0,0,0,0,0,0,0,0
0,0,0,14,0,0,0,0,0,0,0,0,0,2,0,0,0,0,0,0,0,0,2,2,2,2,0,0,0,0,0,0
0,0,0,0,2,0,0,2,0,0,0,0,0,2,2,16,2,16,2,16,2,2,2,2,2,2,2,2,0,0,0,0
0,0,17,2,2,0,0,2,2,17,0,0,0,2,0,0,0,0,0,0,8,2,2,2,2,2,2,2,2,0,0,0
0,0,2,2,0,0,0,9,2,2,0,0,0,0,0,0,0,0,0,8,2,2,0,0,0,0,2,2,2,0,0,0
0,2,2,0,0,0,0,9,2,2,2,0,0,0,0,0,0,0,8,2,2,0,0,0,0,0,0,2,2,2,0,0
0,2,6,0,0,2,2,2,2,2,2,0,0,0,0,0,0,0,8,2,2,8,8,2,2,7,7,2,2,2,0,0
0,2,2,0,0,2,2,8,8,2,2,0,0,0,0,0,0,0,8,2,2,7,7,2,2,7,7,2,2,2,0,0
0,2,2,0,0,0,0,0,0,2,2,0,0,0,0,0,0,0,8,2,2,7,7,7,7,7,7,2,2,2,0,0
0,0,2,2,0,0,0,0,2,2,0,0,0,0,0,0,0,0,0,8,2,2,7,7,7,7,2,2,2,0,0,0
0,0,17,2,2,0,0,2,2,17,0,0,0,2,0,0,0,0,0,0,8,2,2,2,2,2,2,2,2,0,0,0
0,0,0,0,2,0,0,2,0,0,0,0,0,2,2,15,2,15,2,15,2,2,2,2,2,2,2,2,0,0,0,0
0,0,0,14,0,0,0,0,0,0,0,0,0,2,0,0,0,0,0,0,0,0,2,2,2,2,0,0,0,0,0,0
0,0,0,0,0,0,0,0,0,0,0,0,0,0,0,0,0,0,0,0,0,0,0,0,0,0,0,0,0,0,0,0
0,0,0,2,0,0,0,0,0,0,0,0,0,8,0,0,0,0,0,0,0,0,0,0,0,0,0,0,0,0,0,0
:endlayer
layer: 24
0,0,0,15,0,0,0,0,0,0,0,0,0,0,0,0,0,0,0,0,0,0,0,0,0,0,0,0,0,0,0,0
0,0,0,0,0,0,0,0,0,0,0,0,0,0,0,0,0,0,0,0,0,0,0,0,0,0,0,0,0,0,0,0
0,0,0,0,0,0,0,0,0,0,0,0,0,8,0,0,0,0,0,0,0,0,16,2,2,16,0,0,0,0,0,0
0,0,0,0,2,0,0,2,0,0,0,0,0,2,6,0,8,0,8,0,8,2,8,8,8,8,2,16,0,0,0,0
0,0,17,2,2,7,7,2,2,17,0,0,0,2,0,0,0,0,0,0,0,0,0,0,0,0,8,8,6,0,0,0
0,0,2,2,0,0,7,8,2,2,0,0,0,0,0,0,0,0,0,0,0,0,0,0,0,0,0,8,2,0,0,0
0,2,2,0,0,0,7,8,8,2,2,0,0,0,0,0,0,0,0,0,0,0,0,0,0,0,0,0,8,6,0,0
0,8,0,0,0,2,2,0,0,14,2,0,0,0,0,0,0,0,0,0,0,0,0,2,2,0,0,0,8,2,0,0
0,2,2,0,0,2,2,0,0,2,2,0,0,0,0,0,0,0,0,0,0,0,0,2,2,0,0,0,8,2,0,0
0,2,2,0,0,0,0,0,0,2,2,0,0,0,0,0,0,0,0,0,0,0,0,0,0,0,0,0,8,6,0,0
0,0,2,2,0,0,0,0,2,2,0,0,0,0,0,0,0,0,0,0,0,0,0,0,0,0,0,8,2,0,0,0
0,0,17,2,2,0,0,2,2,17,0,0,0,2,0,0,0,0,0,0,0,0,0,0,0,0,8,8,6,0,0,0
0,0,0,0,2,0,0,2,0,0,0,0,0,2,6,0,8,0,8,0,8,2,8,8,8,8,2,15,0,0,0,0
0,0,0,0,0,0,0,0,0,0,0,0,0,8,0,0,0,0,0,0,0,0,15,2,2,15,0,0,0,0,0,0
0,0,0,0,0,0,0,0,0,0,0,0,0,0,0,0,0,0,0,0,0,0,0,0,0,0,0,0,0,0,0,0
0,0,0,16,0,0,0,0,0,0,0,0,0,0,0,0,0,0,0,0,0,0,0,0,0,0,0,0,0,0,0,0
:endlayer
layer: 25
0,0,0,0,0,0,0,0,0,0,0,0,0,0,0,0,0,0,0,0,0,0,0,0,0,0,0,0,0,0,0,0
0,0,0,0,0,0,0,0,0,0,0,0,0,0,0,0,0,0,0,0,0,0,0,0,0,0,0,0,0,0,0,0
0,0,0,0,0,0,0,0,0,0,0,0,0,0,0,0,0,0,0,0,0,0,0,8,8,0,0,0,0,0,0,0
0,0,0,0,2,10,10,2,0,0,0,0,0,16,0,0,0,0,0,0,0,8,0,0,0,0,8,0,0,0,0,0
0,0,17,2,2,2,15,2,2,17,0,0,0,15,0,0,0,0,0,0,0,0,0,0,0,0,0,0,0,0,0,0
0,0,2,2,7,8,0,0,2,2,0,0,0,0,0,0,0,0,0,0,0,0,0,0,0,0,0,0,8,0,0,0
0,2,2,7,7,8,0,0,0,2,2,0,0,0,0,0,0,0,0,0,0,0,0,0,0,0,0,0,0,0,0,0
0,0,0,0,0,2,2,0,0,0,8,0,0,0,0,0,0,0,0,0,0,0,0,2,2,0,0,0,0,8,0,0
0,2,2,0,0,2,2,0,0,2,2,0,0,0,0,0,0,0,0,0,0,0,0,2,2,0,0,0,0,8,0,0
0,2,2,0,0,0,0,0,0,2,2,0,0,0,0,0,0,0,0,0,0,0,0,0,0,0,0,0,0,0,0,0
0,0,2,2,0,0,0,0,2,2,0,0,0,0,0,0,0,0,0,0,0,0,0,0,0,0,0,0,8,0,0,0
0,0,17,2,2,10,10,2,2,17,0,0,0,16,0,0,0,0,0,0,0,0,0,0,0,0,0,0,0,0,0,0
0,0,0,0,2,12,12,2,0,0,0,0,0,15,0,0,0,0,0,0,0,8,0,0,0,0,8,0,0,0,0,0
0,0,0,0,0,0,0,0,0,0,0,0,0,0,0,0,0,0,0,0,0,0,0,8,8,0,0,0,0,0,0,0
0,0,0,0,0,0,0,0,0,0,0,0,0,0,0,0,0,0,0,0,0,0,0,0,0,0,0,0,0,0,0,0
0,0,0,0,0,0,0,0,0,0,0,0,0,0,0,0,0,0,0,0,0,0,0,0,0,0,0,0,0,0,0,0
:endlayer
layer: 26
0,0,0,0,0,0,0,0,0,0,0,0,0,0,0,0,0,0,0,0,0,0,0,0,0,0,0,0,0,0,0,0
0,0,0,0,0,0,0,0,0,0,0,0,0,0,0,0,0,0,0,0,0,0,0,0,0,0,0,0,0,0,0,0
0,0,0,0,0,0,0,0,0,0,0,0,0,0,0,0,0,0,0,0,0,0,0,0,0,0,0,0,0,0,0,0
0,0,0,0,2,2,8,2,0,0,0,0,0,0,0,0,0,0,0,0,0,0,0,0,0,0,0,0,0,0,0,0
0,0,17,2,2,2,0,2,2,17,0,0,0,0,0,0,0,0,0,0,0,0,0,0,0,0,0,0,0,0,0,0
0,0,2,2,0,0,0,0,2,2,0,0,0,0,0,0,0,0,0,0,0,0,0,0,0,0,0,0,0,0,0,0
0,2,2,0,0,0,0,0,0,2,2,0,0,0,0,0,0,0,0,0,0,0,0,0,0,0,0,0,0,0,0,0
0,9,11,8,8,2,2,0,0,0,0,0,0,0,0,0,0,0,0,0,0,0,0,16,6,0,0,0,0,0,0,0
0,2,2,7,7,2,2,0,0,2,2,0,0,0,0,0,0,0,0,0,0,0,0,14,15,0,0,0,0,0,0,0
0,2,2,0,0,0,0,0,0,2,2,0,0,0,0,0,0,0,0,0,0,0,0,0,0,0,0,0,0,0,0,0
0,0,2,2,0,0,0,0,2,2,0,0,0,0,0,0,0,0,0,0,0,0,0,0,0,0,0,0,0,0,0,0
0,0,17,2,2,2,2,2,2,17,0,0,0,0,0,0,0,0,0,0,0,0,0,0,0,0,0,0,0,0,0,0
0,0,0,0,2,2,2,2,0,0,0,0,0,0,0,0,0,0,0,0,0,0,0,0,0,0,0,0,0,0,0,0
0,0,0,0,0,0,0,0,0,0,0,0,0,0,0,0,0,0,0,0,0,0,0,0,0,0,0,0,0,0,0,0
0,0,0,0,0,0,0,0,0,0,0,0,0,0,0,0,0,0,0,0,0,0,0,0,0,0,0,0,0,0,0,0
0,0,0,0,0,0,0,0,0,0,0,0,0,0,0,0,0,0,0,0,0,0,0,0,0,0,0,0,0,0,0,0
:endlayer
layer: 27
0,0,0,0,0,0,0,0,0,0,0,0,0,0,0,0,0,0,0,0,0,0,0,0,0,0,0,0,0,0,0,0
0,0,0,0,0,0,0,0,0,0,0,0,0,0,0,0,0,0,0,0,0,0,0,0,0,0,0,0,0,0,0,0
0,0,0,0,0,0,0,0,0,0,0,0,0,0,0,0,0,0,0,0,0,0,0,0,0,0,0,0,0,0,0,0
0,0,0,0,2,2,0,2,0,0,0,0,0,0,0,0,0,0,0,0,0,0,0,0,0,0,0,0,0,0,0,0
0,0,17,2,2,2,0,2,2,17,0,0,0,0,0,0,0,0,0,0,0,0,0,0,0,0,0,0,0,0,0,0
0,0,2,2,0,0,0,0,2,2,0,0,0,0,0,0,0,0,0,0,0,0,0,0,0,0,0,0,0,0,0,0
0,2,2,0,0,0,0,0,0,2,2,0,0,0,0,0,0,0,0,0,0,0,0,0,0,0,0,0,0,0,0,0
0,2,2,0,0,2,2,0,0,9,11,0,0,0,0,0,0,0,0,0,0,0,0,0,0,0,0,0,0,0,0,0
0,2,6,0,0,2,2,0,0,2,2,0,0,0,0,0,0,0,0,0,0,0,0,0,0,0,0,0,0,0,0,0
0,2,2,8,8,7,0,0,0,2,2,0,0,0,0,0,0,0,0,0,0,0,0,0,0,0,0,0,0,0,0,0
0,0,2,2,8,7,0,0,2,2,0,0,0,0,0,0,0,0,0,0,0,0,0,0,0,0,0,0,0,0,0,0
0,0,17,2,2,2,2,2,2,17,0,0,0,0,0,0,0,0,0,0,0,0,0,0,0,0,0,0,0,0,0,0
0,0,0,0,2,2,2,2,0,0,0,0,0,0,0,0,0,0,0,0,0,0,0,0,0,0,0,0,0,0,0,0
0,0,0,0,0,0,0,0,0,0,0,0,0,0,0,0,0,0,0,0,0,0,0,0,0,0,0,0,0,0,0,0
0,0,0,0,0,0,0,0,0,0,0,0,0,0,0,0,0,0,0,0,0,0,0,0,0,0,0,0,0,0,0,0
0,0,0,0,0,0,0,0,0,0,0,0,0,0,0,0,0,0,0,0,0,0,0,0,0,0,0,0,0,0,0,0
:endlayer
layer: 28
0,0,0,0,0,0,0,0,0,0,0,0,0,0,0,0,0,0,0,0,0,0,0,0,0,0,0,0,0,0,0,0
0,0,0,0,0,0,0,0,0,0,0,0,0,0,0,0,0,0,0,0,0,0,0,0,0,0,0,0,0,0,0,0
0,0,0,0,0,0,0,0,0,0,0,0,0,0,0,0,0,0,0,0,0,0,0,0,0,0,0,0,0,0,0,0
0,0,0,0,2,2,10,2,0,0,0,0,0,0,0,0,0,0,0,0,0,0,0,0,0,0,0,0,0,0,0,0
0,0,17,2,2,2,12,2,2,17,0,0,0,0,0,0,0,0,0,0,0,0,0,0,0,0,0,0,0,0,0,0
0,0,2,2,0,0,0,0,2,2,0,0,0,0,0,0,0,0,0,0,0,0,0,0,0,0,0,0,0,0,0,0
0,2,2,0,0,0,0,0,0,2,2,0,0,0,0,0,0,0,0,0,0,0,0,0,0,0,0,0,0,0,0,0
0,2,2,0,0,2,2,0,0,2,2,0,0,0,0,0,0,0,0,0,0,0,0,0,0,0,0,0,0,0,0,0
0,8,0,0,0,2,2,0,0,2,2,0,0,0,0,0,0,0,0,0,0,0,0,0,0,0,0,0,0,0,0,0
0,2,2,0,0,0,8,7,7,2,2,0,0,0,0,0,0,0,0,0,0,0,0,0,0,0,0,0,0,0,0,0
0,0,2,2,0,0,8,7,2,2,0,0,0,0,0,0,0,0,0,0,0,0,0,0,0,0,0,0,0,0,0,0
0,0,17,2,2,16,2,2,2,17,0,0,0,0,0,0,0,0,0,0,0,0,0,0,0,0,0,0,0,0,0,0
0,0,0,0,2,2,2,2,0,0,0,0,0,0,0,0,0,0,0,0,0,0,0,0,0,0,0,0,0,0,0,0
0,0,0,0,0,0,0,0,0,0,0,0,0,0,0,0,0,0,0,0,0,0,0,0,0,0,0,0,0,0,0,0
0,0,0,0,0,0,0,0,0,0,0,0,0,0,0,0,0,0,0,0,0,0,0,0,0,0,0,0,0,0,0,0
0,0,0,0,0,0,0,0,0,0,0,0,0,0,0,0,0,0,0,0,0,0,0,0,0,0,0,0,0,0,0,0
:endlayer
layer: 29
0,0,0,0,0,0,0,0,0,0,0,0,0,0,0,0,0,0,0,0,0,0,0,0,0,0,0,0,0,0,0,0
0,0,0,0,0,0,0,0,0,0,0,0,0,0,0,0,0,0,0,0,0,0,0,0,0,0,0,0,0,0,0,0
0,0,0,0,0,0,0,0,0,0,0,0,0,0,0,0,0,0,0,0,0,0,0,0,0,0,0,0,0,0,0,0
0,0,0,0,2,2,2,2,0,0,0,0,0,0,0,0,0,0,0,0,0,0,0,0,0,0,0,0,0,0,0,0
0,0,17,2,2,2,2,2,2,17,0,0,0,0,0,0,0,0,0,0,0,0,0,0,0,0,0,0,0,0,0,0
0,0,2,2,0,0,0,0,2,2,0,0,0,0,0,0,0,0,0,0,0,0,0,0,0,0,0,0,0,0,0,0
0,2,2,0,0,0,0,0,0,2,2,0,0,0,0,0,0,0,0,0,0,0,0,0,0,0,0,0,0,0,0,0
0,2,2,0,0,2,2,7,7,2,2,0,0,0,0,0,0,0,0,0,0,0,0,0,0,0,0,0,0,0,0,0
0,0,0,0,0,2,2,8,8,14,2,0,0,0,0,0,0,0,0,0,0,0,0,0,0,0,0,0,0,0,0,0
0,2,2,0,0,0,0,0,0,2,2,0,0,0,0,0,0,0,0,0,0,0,0,0,0,0,0,0,0,0,0,0
0,0,2,2,0,0,0,0,2,2,0,0,0,0,0,0,0,0,0,0,0,0,0,0,0,0,0,0,0,0,0,0
0,0,17,2,2,0,2,2,2,17,0,0,0,0,0,0,0,0,0,0,0,0,0,0,0,0,0,0,0,0,0,0
0,0,0,0,2,8,2,2,0,0,0,0,0,0,0,0,0,0,0,0,0,0,0,0,0,0,0,0,0,0,0,0
0,0,0,0,0,0,0,0,0,0,0,0,0,0,0,0,0,0,0,0,0,0,0,0,0,0,0,0,0,0,0,0
0,0,0,0,0,0,0,0,0,0,0,0,0,0,0,0,0,0,0,0,0,0,0,0,0,0,0,0,0,0,0,0
0,0,0,0,0,0,0,0,0,0,0,0,0,0,0,0,0,0,0,0,0,0,0,0,0,0,0,0,0,0,0,0
:endlayer
layer: 30
0,0,0,0,0,0,0,0,0,0,0,0,0,0,0,0,0,0,0,0,0,0,0,0,0,0,0,0,0,0,0,0
0,0,0,0,0,0,0,0,0,0,0,0,0,0,0,0,0,0,0,0,0,0,0,0,0,0,0,0,0,0,0,0
0,0,0,0,0,0,0,0,0,0,0,0,0,0,0,0,0,0,0,0,0,0,0,0,0,0,0,0,0,0,0,0
0,0,0,0,2,2,2,2,0,0,0,0,0,0,0,0,0,0,0,0,0,0,0,0,0,0,0,0,0,0,0,0
0,0,17,2,2,2,2,2,2,17,0,0,0,0,0,0,0,0,0,0,0,0,0,0,0,0,0,0,0,0,0,0
0,0,2,2,0,0,7,8,2,2,0,0,0,0,0,0,0,0,0,0,0,0,0,0,0,0,0,0,0,0,0,0
0,2,2,0,0,0,7,8,8,2,2,0,0,0,0,0,0,0,0,0,0,0,0,0,0,0,0,0,0,0,0,0
0,2,2,0,0,2,2,0,0,2,2,0,0,0,0,0,0,0,0,0,0,0,0,0,0,0,0,0,0,0,0,0
0,9,11,0,0,2,2,0,0,0,8,0,0,0,0,0,0,0,0,0,0,0,0,0,0,0,0,0,0,0,0,0
0,2,2,0,0,0,0,0,0,2,2,0,0,0,0,0,0,0,0,0,0,0,0,0,0,0,0,0,0,0,0,0
0,0,2,2,0,0,0,0,2,2,0,0,0,0,0,0,0,0,0,0,0,0,0,0,0,0,0,0,0,0,0,0
0,0,17,2,2,0,2,2,2,17,0,0,0,0,0,0,0,0,0,0,0,0,0,0,0,0,0,0,0,0,0,0
0,0,0,0,2,0,2,2,0,0,0,0,0,0,0,0,0,0,0,0,0,0,0,0,0,0,0,0,0,0,0,0
0,0,0,0,0,0,0,0,0,0,0,0,0,0,0,0,0,0,0,0,0,0,0,0,0,0,0,0,0,0,0,0
0,0,0,0,0,0,0,0,0,0,0,0,0,0,0,0,0,0,0,0,0,0,0,0,0,0,0,0,0,0,0,0
0,0,0,0,0,0,0,0,0,0,0,0,0,0,0,0,0,0,0,0,0,0,0,0,0,0,0,0,0,0,0,0
:endlayer
layer: 31
0,0,0,0,0,0,0,0,0,0,0,0,0,0,0,0,0,0,0,0,0,0,0,0,0,0,0,0,0,0,0,0
0,0,0,0,0,0,0,0,0,0,0,0,0,0,0,0,0,0,0,0,0,0,0,0,0,0,0,0,0,0,0,0
0,0,0,0,0,0,0,0,0,0,0,0,0,0,0,0,0,0,0,0,0,0,0,0,0,0,0,0,0,0,0,0
0,0,0,0,2,2,2,2,0,0,0,0,0,0,0,0,0,0,0,0,0,0,0,0,0,0,0,0,0,0,0,0
0,0,17,2,2,15,2,2,2,17,0,0,0,0,0,0,0,0,0,0,0,0,0,0,0,0,0,0,0,0,0,0
0,0,2,2,7,8,0,0,2,2,0,0,0,0,0,0,0,0,0,0,0,0,0,0,0,0,0,0,0,0,0,0
0,2,2,7,7,8,0,0,0,2,2,0,0,0,0,0,0,0,0,0,0,0,0,0,0,0,0,0,0,0,0,0
0,2,2,0,0,2,2,0,0,2,2,0,0,0,0,0,0,0,0,0,0,0,0,0,0,0,0,0,0,0,0,0
0,2,2,0,0,2,2,0,0,0,0,0,0,0,0,0,0,0,0,0,0,0,0,0,0,0,0,0,0,0,0,0
0,2,2,0,0,0,0,0,0,2,2,0,0,0,0,0,0,0,0,0,0,0,0,0,0,0,0,0,0,0,0,0
0,0,2,2,0,0,0,0,2,2,0,0,0,0,0,0,0,0,0,0,0,0,0,0,0,0,0,0,0,0,0,0
0,0,17,2,2,10,2,2,2,17,0,0,0,0,0,0,0,0,0,0,0,0,0,0,0,0,0,0,0,0,0,0
0,0,0,0,2,12,2,2,0,0,0,0,0,0,0,0,0,0,0,0,0,0,0,0,0,0,0,0,0,0,0,0
0,0,0,0,0,0,0,0,0,0,0,0,0,0,0,0,0,0,0,0,0,0,0,0,0,0,0,0,0,0,0,0
0,0,0,0,0,0,0,0,0,0,0,0,0,0,0,0,0,0,0,0,0,0,0,0,0,0,0,0,0,0,0,0
0,0,0,0,0,0,0,0,0,0,0,0,0,0,0,0,0,0,0,0,0,0,0,0,0,0,0,0,0,0,0,0
:endlayer
layer: 32
0,0,0,0,0,0,0,0,0,0,0,0,0,0,0,0,0,0,0,0,0,0,0,0,0,0,0,0,0,0,0,0
0,0,0,0,0,0,0,0,0,0,0,0,0,0,0,0,0,0,0,0,0,0,0,0,0,0,0,0,0,0,0,0
0,0,0,0,0,0,0,0,0,0,0,0,0,0,0,0,0,0,0,0,0,0,0,0,0,0,0,0,0,0,0,0
0,0,0,0,2,8,2,2,0,0,0,0,0,0,0,0,0,0,0,0,0,0,0,0,0,0,0,0,0,0,0,0
0,0,17,2,2,0,2,2,2,17,0,0,0,0,0,0,0,0,0,0,0,0,0,0,0,0,0,0,0,0,0,0
0,0,2,2,0,0,0,0,2,2,0,0,0,0,0,0,0,0,0,0,0,0,0,0,0,0,0,0,0,0,0,0
0,2,2,0,0,0,0,0,0,2,2,0,0,0,0,0,0,0,0,0,0,0,0,0,0,0,0,0,0,0,0,0
0,8,0,8,8,2,2,0,0,2,2,0,0,0,0,0,0,0,0,0,0,0,0,0,0,0,0,0,0,0,0,0
0,2,2,7,7,2,2,0,0,9,11,0,0,0,0,0,0,0,0,0,0,0,0,0,0,0,0,0,0,0,0,0
0,2,2,0,0,0,0,0,0,2,2,0,0,0,0,0,0,0,0,0,0,0,0,0,0,0,0,0,0,0,0,0
0,0,2,2,0,0,0,0,2,2,0,0,0,0,0,0,0,0,0,0,0,0,0,0,0,0,0,0,0,0,0,0
0,0,17,2,2,2,2,2,2,17,0,0,0,0,0,0,0,0,0,0,0,0,0,0,0,0,0,0,0,0,0,0
0,0,0,0,2,2,2,2,0,0,0,0,0,0,0,0,0,0,0,0,0,0,0,0,0,0,0,0,0,0,0,0
0,0,0,0,0,0,0,0,0,0,0,0,0,0,0,0,0,0,0,0,0,0,0,0,0,0,0,0,0,0,0,0
0,0,0,0,0,0,0,0,0,0,0,0,0,0,0,0,0,0,0,0,0,0,0,0,0,0,0,0,0,0,0,0
0,0,0,0,0,0,0,0,0,0,0,0,0,0,0,0,0,0,0,0,0,0,0,0,0,0,0,0,0,0,0,0
:endlayer
layer: 33
0,0,0,0,0,0,0,0,0,0,0,0,0,0,0,0,0,0,0,0,0,0,0,0,0,0,0,0,0,0,0,0
0,0,0,0,0,0,0,0,0,0,0,0,0,0,0,0,0,0,0,0,0,0,0,0,0,0,0,0,0,0,0,0
0,0,0,0,0,0,0,0,0,0,0,0,0,0,0,0,0,0,0,0,0,0,0,0,0,0,0,0,0,0,0,0
0,0,0,0,2,0,2,2,0,0,0,0,0,0,0,0,0,0,0,0,0,0,0,0,0,0,0,0,0,0,0,0
0,0,17,2,2,0,2,2,2,17,0,0,0,0,0,0,0,0,0,0,0,0,0,0,0,0,0,0,0,0,0,0
0,0,2,2,0,0,0,0,2,2,0,0,0,0,0,0,0,0,0,0,0,0,0,0,0,0,0,0,0,0,0,0
0,2,2,0,0,0,0,0,0,2,2,0,0,0,0,0,0,0,0,0,0,0,0,0,0,0,0,0,0,0,0,0
0,0,0,0,0,2,2,0,0,2,2,0,0,0,0,0,0,0,0,0,0,0,0,0,0,0,0,0,0,0,0,0
0,2,2,0,0,2,2,0,0,2,2,0,0,0,0,0,0,0,0,0,0,0,0,0,0,0,0,0,0,0,0,0
0,2,2,8,8,7,0,0,0,2,2,0,0,0,0,0,0,0,0,0,0,0,0,0,0,0,0,0,0,0,0,0
0,0,2,2,8,7,0,0,2,2,0,0,0,0,0,0,0,0,0,0,0,0,0,0,0,0,0,0,0,0,0,0
0,0,17,2,2,2,2,2,2,17,0,0,0,0,0,0,0,0,0,0,0,0,0,0,0,0,0,0,0,0,0,0
0,0,0,0,2,2,2,2,0,0,0,0,0,0,0,0,0,0,0,0,0,0,0,0,0,0,0,0,0,0,0,0
0,0,0,0,0,0,0,0,0,0,0,0,0,0,0,0,0,0,0,0,0,0,0,0,0,0,0,0,0,0,0,0
0,0,0,0,0,0,0,0,0,0,0,0,0,0,0,0,0,0,0,0,0,0,0,0,0,0,0,0,0,0,0,0
0,0,0,0,0,0,0,0,0,0,0,0,0,0,0,0,0,0,0,0,0,0,0,0,0,0,0,0,0,0,0,0
:endlayer
layer: 34
0,0,0,0,0,0,0,0,0,0,0,0,0,0,0,0,0,0,0,0,0,0,0,0,0,0,0,0,0,0,0,0
0,0,0,0,0,0,0,0,0,0,0,0,0,0,0,0,0,0,0,0,0,0,0,0,0,0,0,0,0,0,0,0
0,0,0,0,0,0,0,0,0,0,0,0,0,0,0,0,0,0,0,0,0,0,0,0,0,0,0,0,0,0,0,0
0,0,0,0,2,10,2,2,0,0,0,0,0,0,0,0,0,0,0,0,0,0,0,0,0,0,0,0,0,0,0,0
0,0,17,2,2,12,2,2,2,17,0,0,0,0,0,0,0,0,0,0,0,0,0,0,0,0,0,0,0,0,0,0
0,0,2,2,0,0,0,0,2,2,0,0,0,0,0,0,0,0,0,0,0,0,0,0,0,0,0,0,0,0,0,0
0,2,2,0,0,0,0,0,0,2,2,0,0,0,0,0,0,0,0,0,0,0,0,0,0,0,0,0,0,0,0,0
0,9,0,0,0,2,2,0,0,2,2,0,0,0,0,0,0,0,0,0,0,0,0,0,0,0,0,0,0,0,0,0
0,2,2,0,0,2,2,0,0,2,2,0,0,0,0,0,0,0,0,0,0,0,0,0,0,0,0,0,0,0,0,0
0,2,2,0,0,0,8,7,7,2,2,0,0,0,0,0,0,0,0,0,0,0,0,0,0,0,0,0,0,0,0,0
0,0,2,2,0,0,8,7,2,2,0,0,0,0,0,0,0,0,0,0,0,0,0,0,0,0,0,0,0,0,0,0
0,0,17,2,2,2,2,2,2,17,0,0,0,0,0,0,0,0,0,0,0,0,0,0,0,0,0,0,0,0,0,0
0,0,0,0,2,2,2,2,0,0,0,0,0,0,0,0,0,0,0,0,0,0,0,0,0,0,0,0,0,0,0,0
0,0,0,0,0,0,0,0,0,0,0,0,0,0,0,0,0,0,0,0,0,0,0,0,0,0,0,0,0,0,0,0
0,0,0,0,0,0,0,0,0,0,0,0,0,0,0,0,0,0,0,0,0,0,0,0,0,0,0,0,0,0,0,0
0,0,0,0,0,0,0,0,0,0,0,0,0,0,0,0,0,0,0,0,0,0,0,0,0,0,0,0,0,0,0,0
:endlayer
layer: 35
0,0,0,0,0,0,0,0,0,0,0,0,0,0,0,0,0,0,0,0,0,0,0,0,0,0,0,0,0,0,0,0
0,0,0,0,0,0,0,0,0,0,0,0,0,0,0,0,0,0,0,0,0,0,0,0,0,0,0,0,0,0,0,0
0,0,0,0,0,10,10,0,0,0,0,0,0,0,0,0,0,0,0,0,0,0,0,0,0,0,0,0,0,0,0,0
0,0,0,0,2,2,2,2,0,0,0,0,0,0,0,0,0,0,0,0,0,0,0,0,0,0,0,0,0,0,0,0
0,0,17,2,2,2,2,2,2,17,0,0,0,0,0,0,0,0,0,0,0,0,0,0,0,0,0,0,0,0,0,0
0,0,2,2,0,0,0,0,2,2,0,0,0,0,0,0,0,0,0,0,0,0,0,0,0,0,0,0,0,0,0,0
0,2,2,0,0,0,0,0,0,2,2,0,0,0,0,0,0,0,0,0,0,0,0,0,0,0,0,0,0,0,0,0
9,2,11,0,0,2,2,7,7,2,2,11,0,0,0,0,0,0,0,0,0,0,0,0,0,0,0,0,0,0,0,0
9,2,2,0,0,2,2,8,8,2,2,11,0,0,0,0,0,0,0,0,0,0,0,0,0,0,0,0,0,0,0,0
0,2,2,0,0,0,0,0,0,2,2,0,0,0,0,0,0,0,0,0,0,0,0,0,0,0,0,0,0,0,0,0
0,0,2,2,0,0,0,0,2,2,0,0,0,0,0,0,0,0,0,0,0,0,0,0,0,0,0,0,0,0,0,0
0,0,17,2,2,2,2,2,2,17,0,0,0,0,0,0,0,0,0,0,0,0,0,0,0,0,0,0,0,0,0,0
0,0,0,0,2,2,2,2,0,0,0,0,0,0,0,0,0,0,0,0,0,0,0,0,0,0,0,0,0,0,0,0
0,0,0,0,0,12,12,0,0,0,0,0,0,0,0,0,0,0,0,0,0,0,0,0,0,0,0,0,0,0,0,0
0,0,0,0,0,0,0,0,0,0,0,0,0,0,0,0,0,0,0,0,0,0,0,0,0,0,0,0,0,0,0,0
0,0,0,0,0,0,0,0,0,0,0,0,0,0,0,0,0,0,0,0,0,0,0,0,0,0,0,0,0,0,0,0
:endlayer
layer: 36
0,0,0,0,0,0,0,0,0,0,0,0,0,0,0,0,0,0,0,0,0,0,0,0,0,0,0,0,0,0,0,0
0,0,0,0,0,0,0,0,0,0,0,0,0,0,0,0,0,0,0,0,0,0,0,0,0,0,0,0,0,0,0,0
0,0,0,0,10,2,2,10,0,0,0,0,0,0,0,0,0,0,0,0,0,0,0,0,0,0,0,0,0,0,0,0
0,0,7,9,2,2,2,2,11,7,0,0,0,0,0,0,0,0,0,0,0,0,0,0,0,0,0,0,0,0,0,0
0,7,13,2,2,2,2,2,2,13,7,0,0,0,0,0,0,0,0,0,0,0,0,0,0,0,0,0,0,0,0,0
0,10,2,2,0,0,7,8,2,2,10,0,0,0,0,0,0,0,0,0,0,0,0,0,0,0,0,0,0,0,0,0
9,2,2,0,0,0,7,8,8,2,2,11,0,0,0,0,0,0,0,0,0,0,0,0,0,0,0,0,0,0,0,0
2,2,2,0,0,2,2,0,0,2,2,2,0,0,0,0,0,0,0,0,0,0,0,0,0,0,0,0,0,0,0,0
2,2,2,0,0,2,2,0,0,2,2,2,0,0,0,0,0,0,0,0,0,0,0,0,0,0,0,0,0,0,0,0
9,2,2,0,0,0,0,0,0,2,2,11,0,0,0,0,0,0,0,0,0,0,0,0,0,0,0,0,0,0,0,0
0,12,2,2,0,0,0,0,2,2,12,0,0,0,0,0,0,0,0,0,0,0,0,0,0,0,0,0,0,0,0,0
0,7,13,2,2,2,2,2,2,13,7,0,0,0,0,0,0,0,0,0,0,0,0,0,0,0,0,0,0,0,0,0
0,0,7,9,2,2,2,2,11,7,0,0,0,0,0,0,0,0,0,0,0,0,0,0,0,0,0,0,0,0,0,0
0,0,0,0,12,2,2,12,0,0,0,0,0,0,0,0,0,0,0,0,0,0,0,0,0,0,0,0,0,0,0,0
0,0,0,0,0,0,0,0,0,0,0,0,0,0,0,0,0,0,0,0,0,0,0,0,0,0,0,0,0,0,0,0
0,0,0,0,0,0,0,0,0,0,0,0,0,0,0,0,0,0,0,0,0,0,0,0,0,0,0,0,0,0,0,0
:endlayer
layer: 37
0,0,0,0,0,0,0,0,0,0,0,0,0,0,0,0,0,0,0,0,0,0,0,0,0,0,0,0,0,0,0,0
0,0,0,0,0,0,0,0,0,0,0,0,0,0,0,0,0,0,0,0,0,0,0,0,0,0,0,0,0,0,0,0
0,0,0,9,13,11,9,13,11,0,0,0,0,0,0,0,0,0,0,0,0,0,0,0,0,0,0,0,0,0,0,0
0,7,2,2,2,2,2,2,2,2,7,0,0,0,0,0,0,0,0,0,0,0,0,0,0,0,0,0,0,0,0,0
0,2,2,2,2,2,2,2,2,2,2,0,0,0,0,0,0,0,0,0,0,0,0,0,0,0,0,0,0,0,0,0
10,2,2,2,7,8,0,0,2,2,2,10,0,0,0,0,0,0,0,0,0,0,0,0,0,0,0,0,0,0,0,0
13,2,2,7,7,8,0,0,0,2,2,13,0,0,0,0,0,0,0,0,0,0,0,0,0,0,0,0,0,0,0,0
12,2,2,7,7,2,2,0,0,2,2,12,0,0,0,0,0,0,0,0,0,0,0,0,0,0,0,0,0,0,0,0
10,2,2,7,7,2,2,0,0,2,2,10,0,0,0,0,0,0,0,0,0,0,0,0,0,0,0,0,0,0,0,0
13,2,2,7,7,7,7,7,7,2,2,13,0,0,0,0,0,0,0,0,0,0,0,0,0,0,0,0,0,0,0,0
12,2,2,2,7,7,7,7,2,2,2,12,0,0,0,0,0,0,0,0,0,0,0,0,0,0,0,0,0,0,0,0
0,2,2,2,2,2,2,2,2,2,2,0,0,0,0,0,0,0,0,0,0,0,0,0,0,0,0,0,0,0,0,0
0,7,2,2,2,2,2,2,2,2,7,0,0,0,0,0,0,0,0,0,0,0,0,0,0,0,0,0,0,0,0,0
0,0,0,9,13,11,9,13,11,0,0,0,0,0,0,0,0,0,0,0,0,0,0,0,0,0,0,0,0,0,0,0
0,0,0,0,0,0,0,0,0,0,0,0,0,0,0,0,0,0,0,0,0,0,0,0,0,0,0,0,0,0,0,0
0,0,0,0,0,0,0,0,0,0,0,0,0,0,0,0,0,0,0,0,0,0,0,0,0,0,0,0,0,0,0,0
:endlayer
layer: 38
0,0,0,0,0,0,0,0,0,0,0,0,0,0,0,0,0,0,0,0,0,0,0,0,0,0,0,0,0,0,0,0
0,0,0,0,0,0,0,0,0,0,0,0,0,0,0,0,0,0,0,0,0,0,0,0,0,0,0,0,0,0,0,0
0,0,0,2,16,2,2,16,2,0,0,0,0,0,0,0,0,0,0,0,0,0,0,0,0,0,0,0,0,0,0,0
0,2,16,15,0,0,0,0,15,16,2,0,0,0,0,0,0,0,0,0,0,0,0,0,0,0,0,0,0,0,0,0
0,14,0,0,0,0,0,0,0,0,6,0,0,0,0,0,0,0,0,0,0,0,0,0,0,0,0,0,0,0,0,0
2,6,0,0,0,0,0,0,8,0,14,2,0,0,0,0,0,0,0,0,0,0,0,0,0,0,0,0,0,0,0,0
14,0,0,0,0,0,0,0,0,0,0,6,0,0,0,0,0,0,0,0,0,0,0,0,0,0,0,0,0,0,0,0
2,0,0,0,0,2,2,0,0,0,0,2,0,0,0,0,0,0,0,0,0,0,0,0,0,0,0,0,0,0,0,0
2,0,0,0,16,2,2,16,8,0,0,2,0,0,0,0,0,0,0,0,0,0,0,0,0,0,0,0,0,0,0,0
14,0,0,0,14,20,21,6,0,0,0,6,0,0,0,0,0,0,0,0,0,0,0,0,0,0,0,0,0,0,0,0
2,6,0,0,0,0,0,0,0,0,14,2,0,0,0,0,0,0,0,0,0,0,0,0,0,0,0,0,0,0,0,0
0,14,0,0,0,0,0,0,0,0,6,0,0,0,0,0,0,0,0,0,0,0,0,0,0,0,0,0,0,0,0,0
0,2,15,16,0,0,0,0,16,15,2,0,0,0,0,0,0,0,0,0,0,0,0,0,0,0,0,0,0,0,0,0
0,0,0,2,15,2,2,15,2,0,0,0,0,0,0,0,0,0,0,0,0,0,0,0,0,0,0,0,0,0,0,0
0,0,0,0,0,0,0,0,0,0,0,0,0,0,0,0,0,0,0,0,0,0,0,0,0,0,0,0,0,0,0,0
0,0,0,0,0,0,0,0,0,0,0,0,0,0,0,0,0,0,0,0,0,0,0,0,0,0,0,0,0,0,0,0
:endlayer
layer: 39
0,0,0,0,0,0,0,0,0,0,0,0,0,0,0,0,0,0,0,0,0,0,0,0,0,0,0,0,0,0,0,0
0,0,0,0,0,0,0,0,0,0,0,0,0,0,0,0,0,0,0,0,0,0,0,0,0,0,0,0,0,0,0,0
0,0,0,8,0,8,8,0,8,0,0,0,0,0,0,0,0,0,0,0,0,0,0,0,0,0,0,0,0,0,0,0
0,8,0,0,0,0,0,0,0,0,8,0,0,0,0,0,0,0,0,0,0,0,0,0,0,0,0,0,0,0,0,0
0,0,0,0,0,0,0,0,0,0,0,0,0,0,0,0,0,0,0,0,0,0,0,0,0,0,0,0,0,0,0,0
8,0,0,0,0,0,0,0,0,0,0,8,0,0,0,0,0,0,0,0,0,0,0,0,0,0,0,0,0,0,0,0
0,0,0,0,0,0,0,0,0,0,0,0,0,0,0,0,0,0,0,0,0,0,0,0,0,0,0,0,0,0,0,0
8,0,0,0,0,2,2,0,0,0,0,8,0,0,0,0,0,0,0,0,0,0,0,0,0,0,0,0,0,0,0,0
8,0,0,0,0,2,2,0,0,0,0,8,0,0,0,0,0,0,0,0,0,0,0,0,0,0,0,0,0,0,0,0
0,0,0,0,0,8,8,0,0,0,0,0,0,0,0,0,0,0,0,0,0,0,0,0,0,0,0,0,0,0,0,0
8,0,0,0,0,0,0,0,0,0,0,8,0,0,0,0,0,0,0,0,0,0,0,0,0,0,0,0,0,0,0,0
0,0,0,0,0,0,0,0,0,0,0,0,0,0,0,0,0,0,0,0,0,0,0,0,0,0,0,0,0,0,0,0
0,8,0,0,0,0,0,0,0,0,8,0,0,0,0,0,0,0,0,0,0,0,0,0,0,0,0,0,0,0,0,0
0,0,0,8,0,8,8,0,8,0,0,0,0,0,0,0,0,0,0,0,0,0,0,0,0,0,0,0,0,0,0,0
0,0,0,0,0,0,0,0,0,0,0,0,0,0,0,0,0,0,0,0,0,0,0,0,0,0,0,0,0,0,0,0
0,0,0,0,0,0,0,0,0,0,0,0,0,0,0,0,0,0,0,0,0,0,0,0,0,0,0,0,0,0,0,0
:endlayer
layer: 40
0,0,0,0,0,0,0,0,0,0,0,0,0,0,0,0,0,0,0,0,0,0,0,0,0,0,0,0,0,0,0,0
0,0,0,0,0,0,0,0,0,0,0,0,0,0,0,0,0,0,0,0,0,0,0,0,0,0,0,0,0,0,0,0
0,0,0,0,0,0,0,0,0,0,0,0,0,0,0,0,0,0,0,0,0,0,0,0,0,0,0,0,0,0,0,0
0,0,0,0,0,0,0,0,0,0,0,0,0,0,0,0,0,0,0,0,0,0,0,0,0,0,0,0,0,0,0,0
0,0,0,0,0,0,0,0,0,0,0,0,0,0,0,0,0,0,0,0,0,0,0,0,0,0,0,0,0,0,0,0
0,0,0,0,0,0,0,0,0,0,0,0,0,0,0,0,0,0,0,0,0,0,0,0,0,0,0,0,0,0,0,0
0,0,0,0,0,0,0,0,0,0,0,0,0,0,0,0,0,0,0,0,0,0,0,0,0,0,0,0,0,0,0,0
0,0,0,0,0,16,6,0,0,0,0,0,0,0,0,0,0,0,0,0,0,0,0,0,0,0,0,0,0,0,0,0
0,0,0,0,0,14,15,0,0,0,0,0,0,0,0,0,0,0,0,0,0,0,0,0,0,0,0,0,0,0,0,0
0,0,0,0,0,0,0,0,0,0,0,0,0,0,0,0,0,0,0,0,0,0,0,0,0,0,0,0,0,0,0,0
0,0,0,0,0,0,0,0,0,0,0,0,0,0,0,0,0,0,0,0,0,0,0,0,0,0,0,0,0,0,0,0
0,0,0,0,0,0,0,0,0,0,0,0,0,0,0,0,0,0,0,0,0,0,0,0,0,0,0,0,0,0,0,0
0,0,0,0,0,0,0,0,0,0,0,0,0,0,0,0,0,0,0,0,0,0,0,0,0,0,0,0,0,0,0,0
0,0,0,0,0,0,0,0,0,0,0,0,0,0,0,0,0,0,0,0,0,0,0,0,0,0,0,0,0,0,0,0
0,0,0,0,0,0,0,0,0,0,0,0,0,0,0,0,0,0,0,0,0,0,0,0,0,0,0,0,0,0,0,0
0,0,0,0,0,0,0,0,0,0,0,0,0,0,0,0,0,0,0,0,0,0,0,0,0,0,0,0,0,0,0,0
:endlayer

#### RULES ####
rule:
plugin=vanillaBlocks
number=1
data:
JSON:{blockState:{blockName:"minecraft:cobblestone"}}
:enddata
:endrule

rule:
plugin=vanillaBlocks
number=2
data:
JSON:{blockState:{blockName:"quark:world_stone_bricks",properties:{variant:"stone_marble_bricks"}}}
:enddata
:endrule

rule:
plugin=vanillaBlocks
number=3
data:
JSON:{blockState:{blockName:"minecraft:dirt",properties:{variant:"dirt",snowy:"false"}}}
:enddata
:endrule

rule:
plugin=vanillaBlocks
number=4
data:
JSON:{blockState:{blockName:"minecraft:grass",properties:{snowy:"false"}}}
:enddata
:endrule

rule:
plugin=vanillaBlocks
number=5
data:
JSON:{blockState:{blockName:"minecraft:gravel"}}
:enddata
:endrule

rule:
plugin=vanillaBlocks
number=6
data:
JSON:{blockState:{blockName:"quark:stone_marble_bricks_stairs",properties:{half:"bottom",shape:"straight",facing:"west"}}}
:enddata
:endrule

rule:
plugin=vanillaBlocks
number=7
data:
JSON:{blockState:{blockName:"quark:stone_marble_bricks_slab",properties:{half:"top",prop:"blarg"}}}
:enddata
:endrule

rule:
plugin=vanillaBlocks
number=8
data:
JSON:{blockState:{blockName:"quark:stone_marble_bricks_slab",properties:{half:"bottom",prop:"blarg"}}}
:enddata
:endrule

rule:
plugin=vanillaBlocks
number=9
data:
JSON:{blockState:{blockName:"quark:stone_marble_bricks_stairs",properties:{half:"top",shape:"straight",facing:"east"}}}
:enddata
:endrule

rule:
plugin=vanillaBlocks
number=10
data:
JSON:{blockState:{blockName:"quark:stone_marble_bricks_stairs",properties:{half:"top",shape:"straight",facing:"south"}}}
:enddata
:endrule

rule:
plugin=vanillaBlocks
number=11
data:
JSON:{blockState:{blockName:"quark:stone_marble_bricks_stairs",properties:{half:"top",shape:"straight",facing:"west"}}}
:enddata
:endrule

rule:
plugin=vanillaBlocks
number=12
data:
JSON:{blockState:{blockName:"quark:stone_marble_bricks_stairs",properties:{half:"top",shape:"straight",facing:"north"}}}
:enddata
:endrule

rule:
plugin=vanillaBlocks
number=13
data:
JSON:{blockState:{blockName:"quark:world_stone_carved",properties:{variant:"stone_slate_carved"}}}
:enddata
:endrule

rule:
plugin=vanillaBlocks
number=14
data:
JSON:{blockState:{blockName:"quark:stone_marble_bricks_stairs",properties:{half:"bottom",shape:"straight",facing:"east"}}}
:enddata
:endrule

rule:
plugin=vanillaBlocks
number=15
data:
JSON:{blockState:{blockName:"quark:stone_marble_bricks_stairs",properties:{half:"bottom",shape:"straight",facing:"north"}}}
:enddata
:endrule

rule:
plugin=vanillaBlocks
number=16
data:
JSON:{blockState:{blockName:"quark:stone_marble_bricks_stairs",properties:{half:"bottom",shape:"straight",facing:"south"}}}
:enddata
:endrule

rule:
plugin=vanillaBlocks
number=17
data:
JSON:{blockState:{blockName:"quark:slate_wall",properties:{east:"false",south:"false",north:"false",west:"false",up:"false"}}}
:enddata
:endrule

rule:
plugin=inventory
number=18
data:
JSON:{blockState:{blockName:"minecraft:chest",properties:{facing:"west"}},lootLevel:0,teData:{Items:[],id:"minecraft:chest",Lock:""},inventoryData:{length:0,inventoryContents:[]},legacyFeatures:1b}
:enddata
:endrule

rule:
plugin=inventory
number=19
data:
JSON:{blockState:{blockName:"minecraft:chest",properties:{facing:"west"}},lootLevel:0,teData:{Items:[],id:"minecraft:chest",Lock:""},inventoryData:{length:0,inventoryContents:[]},legacyFeatures:1b}
:enddata
:endrule

rule:
plugin=inventory
number=20
data:
JSON:{blockState:{blockName:"minecraft:chest",properties:{facing:"south"}},lootLevel:0,teData:{Items:[],id:"minecraft:chest",Lock:""},inventoryData:{length:0,inventoryContents:[]},legacyFeatures:1b}
:enddata
:endrule

rule:
plugin=inventory
number=21
data:
JSON:{blockState:{blockName:"minecraft:chest",properties:{facing:"south"}},lootLevel:0,teData:{Items:[],id:"minecraft:chest",Lock:""},inventoryData:{length:0,inventoryContents:[]},legacyFeatures:1b}
:enddata
:endrule

#### ENTITIES ####
