# Ancient Warfare Structure Template File
# Auto-generated structure template file. created on: 9/24/2023 at: 10:57:57
# Lines beginning with # denote comments

header:
version=2.11
name=SB_KievarusCol_WaystoneShrine_1_oak
mods=
size=19,29,19
offset=9,1,18
:endheader

#### VALIDATION ####
validation:
type=ground
structureAuthor=TheOddlySeagull
survival=true
worldGenEnabled=false
unique=false
preserveBlocks=false
preventNaturalHostileSpawns=false
selectionWeight=1
clusterValue=1
minDuplicateDistance=1
dimensionWhiteList=true
dimensionList=
biomeGroupList=
biomeWhiteList=true
biomeList=
leveling=0
fill=0
border=0
blockSwap=false
territoryName=
biomeReplacement=minecraft:
minGenerationHeight=0
maxGenerationHeight=255
:endvalidation

#### LAYERS ####
layer: 0
1,1,1,1,1,1,1,2,3,3,3,2,1,1,1,1,1,1,1
1,1,1,1,1,1,1,2,3,3,3,2,1,1,1,1,1,1,1
1,1,1,1,1,1,1,2,3,3,3,2,1,1,1,1,1,1,1
1,1,1,3,3,3,3,3,3,3,3,3,3,3,3,3,1,1,1
1,1,1,3,4,4,4,4,4,4,4,4,4,4,4,3,1,1,1
1,1,1,3,4,3,3,3,4,3,4,4,3,4,3,3,1,1,1
1,1,1,3,3,3,4,3,3,4,4,3,4,4,3,3,1,1,1
2,2,2,3,3,4,3,4,4,3,4,3,4,3,4,3,2,2,2
3,3,3,3,4,4,3,4,4,3,4,4,4,3,4,3,3,3,3
3,3,3,3,4,3,3,4,4,4,3,3,4,4,3,3,3,3,3
3,3,3,3,3,3,3,4,3,3,4,3,4,4,4,3,3,3,3
2,2,2,3,3,4,4,3,3,3,3,3,4,3,4,3,2,2,2
1,1,1,3,4,4,3,4,4,4,4,3,3,3,4,3,1,1,1
1,1,1,3,3,3,4,4,4,4,3,4,4,4,4,3,1,1,1
1,1,1,3,4,3,4,4,4,3,3,3,4,4,4,3,1,1,1
1,1,1,3,3,3,3,3,3,3,3,3,3,3,3,3,1,1,1
1,1,1,1,1,1,1,2,3,3,3,2,1,1,1,1,1,1,1
1,1,1,1,1,1,1,2,3,3,3,2,1,1,1,1,1,1,1
1,1,1,1,1,1,1,2,3,3,3,2,1,1,1,1,1,1,1
:endlayer
layer: 1
0,0,0,0,0,0,0,0,0,0,0,0,0,0,0,0,0,0,0
0,0,0,0,0,0,0,0,0,0,0,0,0,0,0,0,0,0,0
0,0,0,0,0,0,0,0,0,0,0,0,0,0,0,0,0,0,0
0,0,0,5,2,2,2,5,7,7,7,5,2,2,2,5,0,0,0
0,0,0,2,3,3,3,2,3,3,3,2,3,3,3,2,0,0,0
0,0,0,2,3,3,3,2,3,3,3,2,3,3,3,2,0,0,0
0,0,0,2,3,3,2,3,3,3,3,3,2,3,3,2,0,0,0
0,0,0,5,2,2,3,3,2,2,2,3,3,2,2,5,0,0,0
0,0,0,9,3,3,3,2,3,3,3,2,3,3,3,6,0,0,0
0,0,0,9,3,3,3,2,3,3,3,2,3,3,3,6,0,0,0
0,0,0,9,3,3,3,2,3,3,3,2,3,3,3,6,0,0,0
0,0,0,5,2,2,3,3,2,2,2,3,3,2,2,5,0,0,0
0,0,0,2,3,3,2,3,3,3,3,3,2,3,3,2,0,0,0
0,0,0,2,3,3,3,2,3,3,3,2,3,3,3,2,0,0,0
0,0,0,2,3,3,3,2,3,3,3,2,3,3,3,2,0,0,0
0,0,0,5,2,2,2,5,8,8,8,5,2,2,2,5,0,0,0
0,0,0,0,0,0,0,0,0,0,0,0,0,0,0,0,0,0,0
0,0,0,0,0,0,0,0,0,0,0,0,0,0,0,0,0,0,0
0,0,0,0,0,0,0,0,0,0,0,0,0,0,0,0,0,0,0
:endlayer
layer: 2
0,0,0,0,0,0,0,0,0,0,0,0,0,0,0,0,0,0,0
0,0,0,0,0,0,0,0,0,0,0,0,0,0,0,0,0,0,0
0,0,0,0,0,0,0,0,0,0,0,0,0,0,0,0,0,0,0
0,0,0,5,10,10,10,5,0,0,0,5,10,10,10,5,0,0,0
0,0,0,10,0,0,0,0,0,0,0,0,0,0,0,10,0,0,0
0,0,0,10,0,0,0,0,0,0,0,0,0,0,0,10,0,0,0
0,0,0,10,0,0,0,0,0,0,0,0,0,0,0,10,0,0,0
0,0,0,5,0,0,0,10,11,11,11,10,0,0,0,5,0,0,0
0,0,0,0,0,0,0,11,3,3,3,11,0,0,0,0,0,0,0
0,0,0,0,0,0,0,11,3,3,3,11,0,0,0,0,0,0,0
0,0,0,0,0,0,0,11,3,3,3,11,0,0,0,0,0,0,0
0,0,0,5,0,0,0,10,11,11,11,10,0,0,0,5,0,0,0
0,0,0,10,0,0,0,0,0,0,0,0,0,0,0,10,0,0,0
0,0,0,10,0,0,0,0,0,0,0,0,0,0,0,10,0,0,0
0,0,0,10,0,0,0,0,0,0,0,0,0,0,0,10,0,0,0
0,0,0,5,10,10,10,5,0,0,0,5,10,10,10,5,0,0,0
0,0,0,0,0,0,0,0,0,0,0,0,0,0,0,0,0,0,0
0,0,0,0,0,0,0,0,0,0,0,0,0,0,0,0,0,0,0
0,0,0,0,0,0,0,0,0,0,0,0,0,0,0,0,0,0,0
:endlayer
layer: 3
0,0,0,0,0,0,0,0,0,0,0,0,0,0,0,0,0,0,0
0,0,0,0,0,0,0,0,0,0,0,0,0,0,0,0,0,0,0
0,0,0,13,0,0,0,13,0,0,0,13,0,0,0,13,0,0,0
0,0,17,5,0,0,0,5,0,0,0,5,0,0,0,5,12,0,0
0,0,0,0,0,0,0,0,0,0,0,0,0,0,0,0,0,0,0
0,0,0,0,0,0,0,0,0,0,0,0,0,0,0,0,0,0,0
0,0,0,0,0,0,0,0,0,0,0,0,0,0,0,0,0,0,0
0,0,17,5,0,0,0,15,0,0,0,15,0,0,0,5,12,0,0
0,0,0,0,0,0,0,0,0,0,0,0,0,0,0,0,0,0,0
0,0,0,0,0,0,0,0,0,16,0,0,0,0,0,0,0,0,0
0,0,0,0,0,0,0,0,0,0,0,0,0,0,0,0,0,0,0
0,0,17,5,0,0,0,15,0,0,0,15,0,0,0,5,12,0,0
0,0,0,0,0,0,0,0,0,0,0,0,0,0,0,0,0,0,0
0,0,0,0,0,0,0,0,0,0,0,0,0,0,0,0,0,0,0
0,0,0,0,0,0,0,0,0,0,0,0,0,0,0,0,0,0,0
0,0,17,5,0,0,0,5,0,0,0,5,0,0,0,5,12,0,0
0,0,0,14,0,0,0,14,0,0,0,14,0,0,0,14,0,0,0
0,0,0,0,0,0,0,0,0,0,0,0,0,0,0,0,0,0,0
0,0,0,0,0,0,0,0,0,0,0,0,0,0,0,0,0,0,0
:endlayer
layer: 4
0,0,0,0,0,0,0,0,0,0,0,0,0,0,0,0,0,0,0
0,0,0,0,0,0,0,0,0,0,0,0,0,0,0,0,0,0,0
0,0,0,0,0,0,0,0,0,0,0,0,0,0,0,0,0,0,0
0,0,0,5,0,0,0,5,0,0,0,5,0,0,0,5,0,0,0
0,0,0,0,0,0,0,14,0,0,0,14,0,0,0,0,0,0,0
0,0,0,0,0,0,0,0,0,0,0,0,0,0,0,0,0,0,0
0,0,0,0,0,0,0,0,0,0,0,0,0,0,0,0,0,0,0
0,0,0,5,12,0,0,0,0,0,0,0,0,0,17,5,0,0,0
0,0,0,0,0,0,0,0,0,0,0,0,0,0,0,0,0,0,0
0,0,0,0,0,0,0,0,0,18,0,0,0,0,0,0,0,0,0
0,0,0,0,0,0,0,0,0,0,0,0,0,0,0,0,0,0,0
0,0,0,5,12,0,0,0,0,0,0,0,0,0,17,5,0,0,0
0,0,0,0,0,0,0,0,0,0,0,0,0,0,0,0,0,0,0
0,0,0,0,0,0,0,0,0,0,0,0,0,0,0,0,0,0,0
0,0,0,0,0,0,0,13,0,0,0,13,0,0,0,0,0,0,0
0,0,0,5,0,0,0,5,0,0,0,5,0,0,0,5,0,0,0
0,0,0,0,0,0,0,0,0,0,0,0,0,0,0,0,0,0,0
0,0,0,0,0,0,0,0,0,0,0,0,0,0,0,0,0,0,0
0,0,0,0,0,0,0,0,0,0,0,0,0,0,0,0,0,0,0
:endlayer
layer: 5
0,0,0,0,0,0,0,0,0,0,0,0,0,0,0,0,0,0,0
0,0,0,0,0,0,0,0,0,0,0,0,0,0,0,0,0,0,0
0,0,0,0,0,0,0,0,0,0,0,0,0,0,0,0,0,0,0
0,0,0,5,23,20,22,5,23,20,22,5,23,20,22,5,0,0,0
0,0,0,19,0,0,0,0,0,0,0,0,0,0,0,19,0,0,0
0,0,0,20,0,0,0,0,0,0,0,0,0,0,0,20,0,0,0
0,0,0,21,0,0,0,0,0,0,0,0,0,0,0,21,0,0,0
0,0,0,5,0,0,0,0,0,0,0,0,0,0,0,5,0,0,0
0,0,0,19,0,0,0,0,0,0,0,0,0,0,0,19,0,0,0
0,0,0,20,0,0,0,0,0,0,0,0,0,0,0,20,0,0,0
0,0,0,21,0,0,0,0,0,0,0,0,0,0,0,21,0,0,0
0,0,0,5,0,0,0,0,0,0,0,0,0,0,0,5,0,0,0
0,0,0,19,0,0,0,0,0,0,0,0,0,0,0,19,0,0,0
0,0,0,20,0,0,0,0,0,0,0,0,0,0,0,20,0,0,0
0,0,0,21,0,0,0,0,0,0,0,0,0,0,0,21,0,0,0
0,0,0,5,23,20,22,5,23,20,22,5,23,20,22,5,0,0,0
0,0,0,0,0,0,0,0,0,0,0,0,0,0,0,0,0,0,0
0,0,0,0,0,0,0,0,0,0,0,0,0,0,0,0,0,0,0
0,0,0,0,0,0,0,0,0,0,0,0,0,0,0,0,0,0,0
:endlayer
layer: 6
0,0,0,0,0,0,0,0,0,0,0,0,0,0,0,0,0,0,0
0,0,0,0,0,0,0,0,0,0,0,0,0,0,0,0,0,0,0
0,0,0,0,0,0,0,0,0,0,0,0,0,0,0,0,0,0,0
0,0,0,5,25,25,25,25,25,25,25,25,25,25,25,5,0,0,0
0,0,0,24,0,0,0,19,0,0,0,19,0,0,0,24,0,0,0
0,0,0,24,0,0,0,0,0,0,0,0,0,0,0,24,0,0,0
0,0,0,24,0,0,0,0,0,0,0,0,0,0,0,24,0,0,0
0,0,0,24,23,0,0,0,0,0,0,0,0,0,22,24,0,0,0
0,0,0,24,0,0,0,0,0,0,0,0,0,0,0,24,0,0,0
0,0,0,24,0,0,0,0,0,0,0,0,0,0,0,24,0,0,0
0,0,0,24,0,0,0,0,0,0,0,0,0,0,0,24,0,0,0
0,0,0,24,23,0,0,0,0,0,0,0,0,0,22,24,0,0,0
0,0,0,24,0,0,0,0,0,0,0,0,0,0,0,24,0,0,0
0,0,0,24,0,0,0,0,0,0,0,0,0,0,0,24,0,0,0
0,0,0,24,0,0,0,21,0,0,0,21,0,0,0,24,0,0,0
0,0,0,5,25,25,25,25,25,25,25,25,25,25,25,5,0,0,0
0,0,0,0,0,0,0,0,0,0,0,0,0,0,0,0,0,0,0
0,0,0,0,0,0,0,0,0,0,0,0,0,0,0,0,0,0,0
0,0,0,0,0,0,0,0,0,0,0,0,0,0,0,0,0,0,0
:endlayer
layer: 7
0,0,0,0,0,0,0,0,0,0,0,0,0,0,0,0,0,0,0
0,0,0,0,0,0,0,0,0,0,0,0,0,0,0,0,0,0,0
0,0,0,0,0,0,0,0,0,0,0,0,0,0,0,0,0,0,0
0,0,0,5,20,20,20,5,29,0,28,5,20,20,20,5,0,0,0
0,0,0,20,0,0,0,15,0,0,0,15,0,0,0,20,0,0,0
0,0,0,20,0,0,0,0,0,0,0,0,0,0,0,20,0,0,0
0,0,0,20,0,0,0,0,0,0,0,0,0,0,0,20,0,0,0
0,0,0,5,15,0,0,0,0,0,0,0,0,0,15,5,0,0,0
0,0,0,26,0,0,0,0,0,0,0,0,0,0,0,26,0,0,0
0,0,0,0,0,0,0,0,0,0,0,0,0,0,0,0,0,0,0
0,0,0,27,0,0,0,0,0,0,0,0,0,0,0,27,0,0,0
0,0,0,5,15,0,0,0,0,0,0,0,0,0,15,5,0,0,0
0,0,0,20,0,0,0,0,0,0,0,0,0,0,0,20,0,0,0
0,0,0,20,0,0,0,0,0,0,0,0,0,0,0,20,0,0,0
0,0,0,20,0,0,0,15,0,0,0,15,0,0,0,20,0,0,0
0,0,0,5,20,20,20,5,29,0,28,5,20,20,20,5,0,0,0
0,0,0,0,0,0,0,0,0,0,0,0,0,0,0,0,0,0,0
0,0,0,0,0,0,0,0,0,0,0,0,0,0,0,0,0,0,0
0,0,0,0,0,0,0,0,0,0,0,0,0,0,0,0,0,0,0
:endlayer
layer: 8
0,0,0,0,0,0,0,0,0,0,0,0,0,0,0,0,0,0,0
0,0,0,0,0,0,0,0,0,0,0,0,0,0,0,0,0,0,0
0,0,0,0,0,0,0,0,0,0,0,0,0,0,0,0,0,0,0
0,0,0,5,20,20,20,5,23,0,22,5,20,20,20,5,0,0,0
0,0,0,20,10,0,0,0,0,0,0,0,0,0,10,20,0,0,0
0,0,0,20,0,0,0,0,0,0,0,0,0,0,0,20,0,0,0
0,0,0,20,0,0,0,0,0,0,0,0,0,0,0,20,0,0,0
0,0,0,5,0,0,0,0,0,0,0,0,0,0,0,5,0,0,0
0,0,0,19,0,0,0,0,0,0,0,0,0,0,0,19,0,0,0
0,0,0,0,0,0,0,0,0,0,0,0,0,0,0,0,0,0,0
0,0,0,21,0,0,0,0,0,0,0,0,0,0,0,21,0,0,0
0,0,0,5,0,0,0,0,0,0,0,0,0,0,0,5,0,0,0
0,0,0,20,0,0,0,0,0,0,0,0,0,0,0,20,0,0,0
0,0,0,20,0,0,0,0,0,0,0,0,0,0,0,20,0,0,0
0,0,0,20,10,0,0,0,0,0,0,0,0,0,10,20,0,0,0
0,0,0,5,20,20,20,5,23,0,22,5,20,20,20,5,0,0,0
0,0,0,0,0,0,0,0,0,0,0,0,0,0,0,0,0,0,0
0,0,0,0,0,0,0,0,0,0,0,0,0,0,0,0,0,0,0
0,0,0,0,0,0,0,0,0,0,0,0,0,0,0,0,0,0,0
:endlayer
layer: 9
0,0,0,0,0,0,0,0,0,0,0,0,0,0,0,0,0,0,0
0,30,30,30,30,30,30,30,30,30,30,30,30,30,30,30,30,30,0
0,30,0,21,0,0,0,21,0,0,0,21,0,0,0,21,0,30,0
0,30,22,5,25,25,25,25,25,25,25,25,25,25,25,5,23,30,0
0,30,0,24,10,0,0,0,0,0,0,0,0,0,10,24,0,30,0
0,30,0,24,0,0,0,0,0,0,0,0,0,0,0,24,0,30,0
0,30,0,24,0,0,0,0,0,0,0,0,0,0,0,24,0,30,0
0,30,22,24,0,0,0,0,0,0,0,0,0,0,0,24,23,30,0
0,30,0,24,0,0,0,0,0,0,0,0,0,0,0,24,0,30,0
0,30,0,24,0,0,0,0,0,0,0,0,0,0,0,24,0,30,0
0,30,0,24,0,0,0,0,0,0,0,0,0,0,0,24,0,30,0
0,30,22,24,0,0,0,0,0,0,0,0,0,0,0,24,23,30,0
0,30,0,24,0,0,0,0,0,0,0,0,0,0,0,24,0,30,0
0,30,0,24,0,0,0,0,0,0,0,0,0,0,0,24,0,30,0
0,30,0,24,10,0,0,0,0,0,0,0,0,0,10,24,0,30,0
0,30,22,5,25,25,25,25,25,25,25,25,25,25,25,5,23,30,0
0,30,0,19,0,0,0,19,0,0,0,19,0,0,0,19,0,30,0
0,30,30,30,30,30,30,30,30,30,30,30,30,30,30,30,30,30,0
0,0,0,0,0,0,0,0,0,0,0,0,0,0,0,0,0,0,0
:endlayer
layer: 10
0,0,0,0,0,0,0,0,0,0,0,0,0,0,0,0,0,0,0
0,0,0,0,0,0,0,0,0,0,0,0,0,0,0,0,0,0,0
0,0,30,30,30,30,30,30,30,30,30,30,30,30,30,30,30,0,0
0,0,30,5,20,20,20,5,20,20,20,5,20,20,20,5,30,0,0
0,0,30,20,20,0,0,0,0,0,0,0,0,0,20,20,30,0,0
0,0,30,20,0,0,0,0,0,0,0,0,0,0,0,20,30,0,0
0,0,30,20,0,0,0,0,0,0,0,0,0,0,0,20,30,0,0
0,0,30,5,0,0,0,0,0,0,0,0,0,0,0,5,30,0,0
0,0,30,20,0,0,0,0,0,0,0,0,0,0,0,20,30,0,0
0,0,30,20,0,0,0,0,0,0,0,0,0,0,0,20,30,0,0
0,0,30,20,0,0,0,0,0,0,0,0,0,0,0,20,30,0,0
0,0,30,5,0,0,0,0,0,0,0,0,0,0,0,5,30,0,0
0,0,30,20,0,0,0,0,0,0,0,0,0,0,0,20,30,0,0
0,0,30,20,0,0,0,0,0,0,0,0,0,0,0,20,30,0,0
0,0,30,20,20,0,0,0,0,0,0,0,0,0,20,20,30,0,0
0,0,30,5,20,20,20,5,20,20,20,5,20,20,20,5,30,0,0
0,0,30,30,30,30,30,30,30,30,30,30,30,30,30,30,30,0,0
0,0,0,0,0,0,0,0,0,0,0,0,0,0,0,0,0,0,0
0,0,0,0,0,0,0,0,0,0,0,0,0,0,0,0,0,0,0
:endlayer
layer: 11
0,0,0,0,0,0,0,0,0,0,0,0,0,0,0,0,0,0,0
0,0,0,0,0,0,0,0,0,0,0,0,0,0,0,0,0,0,0
0,0,0,0,0,0,0,0,0,0,0,0,0,0,0,0,0,0,0
0,0,0,30,30,30,30,30,30,30,30,30,30,30,30,30,0,0,0
0,0,0,30,20,19,19,19,19,19,19,19,19,19,20,30,0,0,0
0,0,0,30,23,10,0,0,0,0,0,0,0,10,22,30,0,0,0
0,0,0,30,23,0,0,0,0,0,0,0,0,0,22,30,0,0,0
0,0,0,30,23,0,0,0,0,0,0,0,0,0,22,30,0,0,0
0,0,0,30,23,0,0,0,0,0,0,0,0,0,22,30,0,0,0
0,0,0,30,23,0,0,0,0,0,0,0,0,0,22,30,0,0,0
0,0,0,30,23,0,0,0,0,0,0,0,0,0,22,30,0,0,0
0,0,0,30,23,0,0,0,0,0,0,0,0,0,22,30,0,0,0
0,0,0,30,23,0,0,0,0,0,0,0,0,0,22,30,0,0,0
0,0,0,30,23,10,0,0,0,0,0,0,0,10,22,30,0,0,0
0,0,0,30,20,21,21,21,21,21,21,21,21,21,20,30,0,0,0
0,0,0,30,30,30,30,30,30,30,30,30,30,30,30,30,0,0,0
0,0,0,0,0,0,0,0,0,0,0,0,0,0,0,0,0,0,0
0,0,0,0,0,0,0,0,0,0,0,0,0,0,0,0,0,0,0
0,0,0,0,0,0,0,0,0,0,0,0,0,0,0,0,0,0,0
:endlayer
layer: 12
0,0,0,0,0,0,0,0,0,0,0,0,0,0,0,0,0,0,0
0,0,0,0,0,0,0,0,0,0,0,0,0,0,0,0,0,0,0
0,0,0,0,0,0,0,0,0,0,0,0,0,0,0,0,0,0,0
0,0,0,15,0,0,0,15,0,0,0,15,0,0,0,15,0,0,0
0,0,0,0,30,30,30,30,30,30,30,30,30,30,30,0,0,0,0
0,0,0,0,30,20,19,19,19,19,19,19,19,20,30,0,0,0,0
0,0,0,0,30,23,10,0,0,0,0,0,10,22,30,0,0,0,0
0,0,0,15,30,23,0,0,0,0,0,0,0,22,30,15,0,0,0
0,0,0,0,30,23,0,0,0,0,0,0,0,22,30,0,0,0,0
0,0,0,0,30,23,0,0,0,0,0,0,0,22,30,0,0,0,0
0,0,0,0,30,23,0,0,0,0,0,0,0,22,30,0,0,0,0
0,0,0,15,30,23,0,0,0,0,0,0,0,22,30,15,0,0,0
0,0,0,0,30,23,10,0,0,0,0,0,10,22,30,0,0,0,0
0,0,0,0,30,20,21,21,21,21,21,21,21,20,30,0,0,0,0
0,0,0,0,30,30,30,30,30,30,30,30,30,30,30,0,0,0,0
0,0,0,15,0,0,0,15,0,0,0,15,0,0,0,15,0,0,0
0,0,0,0,0,0,0,0,0,0,0,0,0,0,0,0,0,0,0
0,0,0,0,0,0,0,0,0,0,0,0,0,0,0,0,0,0,0
0,0,0,0,0,0,0,0,0,0,0,0,0,0,0,0,0,0,0
:endlayer
layer: 13
0,0,0,0,0,0,0,0,0,0,0,0,0,0,0,0,0,0,0
0,0,0,0,0,0,0,0,0,0,0,0,0,0,0,0,0,0,0
0,0,0,0,0,0,0,0,0,0,0,0,0,0,0,0,0,0,0
0,0,0,0,0,0,0,0,0,0,0,0,0,0,0,0,0,0,0
0,0,0,0,0,0,0,0,0,0,0,0,0,0,0,0,0,0,0
0,0,0,0,0,30,30,30,30,30,30,30,30,30,0,0,0,0,0
0,0,0,0,0,30,20,19,19,19,19,19,20,30,0,0,0,0,0
0,0,0,0,0,30,23,10,0,0,0,10,22,30,0,0,0,0,0
0,0,0,0,0,30,23,0,0,0,0,0,22,30,0,0,0,0,0
0,0,0,0,0,30,23,0,0,0,0,0,22,30,0,0,0,0,0
0,0,0,0,0,30,23,0,0,0,0,0,22,30,0,0,0,0,0
0,0,0,0,0,30,23,10,0,0,0,10,22,30,0,0,0,0,0
0,0,0,0,0,30,20,21,21,21,21,21,20,30,0,0,0,0,0
0,0,0,0,0,30,30,30,30,30,30,30,30,30,0,0,0,0,0
0,0,0,0,0,0,0,0,0,0,0,0,0,0,0,0,0,0,0
0,0,0,0,0,0,0,0,0,0,0,0,0,0,0,0,0,0,0
0,0,0,0,0,0,0,0,0,0,0,0,0,0,0,0,0,0,0
0,0,0,0,0,0,0,0,0,0,0,0,0,0,0,0,0,0,0
0,0,0,0,0,0,0,0,0,0,0,0,0,0,0,0,0,0,0
:endlayer
layer: 14
0,0,0,0,0,0,0,0,0,0,0,0,0,0,0,0,0,0,0
0,0,0,0,0,0,0,0,0,0,0,0,0,0,0,0,0,0,0
0,0,0,0,0,0,0,0,0,0,0,0,0,0,0,0,0,0,0
0,0,0,0,0,0,0,0,0,0,0,0,0,0,0,0,0,0,0
0,0,0,0,0,0,0,0,0,0,0,0,0,0,0,0,0,0,0
0,0,0,0,0,0,0,0,0,0,0,0,0,0,0,0,0,0,0
0,0,0,0,0,0,30,30,30,30,30,30,30,0,0,0,0,0,0
0,0,0,0,0,0,30,25,25,25,25,24,30,0,0,0,0,0,0
0,0,0,0,0,0,30,24,0,14,0,24,30,0,0,0,0,0,0
0,0,0,0,0,0,30,24,12,0,17,24,30,0,0,0,0,0,0
0,0,0,0,0,0,30,24,0,13,0,24,30,0,0,0,0,0,0
0,0,0,0,0,0,30,24,25,25,25,25,30,0,0,0,0,0,0
0,0,0,0,0,0,30,30,30,30,30,30,30,0,0,0,0,0,0
0,0,0,0,0,0,0,0,0,0,0,0,0,0,0,0,0,0,0
0,0,0,0,0,0,0,0,0,0,0,0,0,0,0,0,0,0,0
0,0,0,0,0,0,0,0,0,0,0,0,0,0,0,0,0,0,0
0,0,0,0,0,0,0,0,0,0,0,0,0,0,0,0,0,0,0
0,0,0,0,0,0,0,0,0,0,0,0,0,0,0,0,0,0,0
0,0,0,0,0,0,0,0,0,0,0,0,0,0,0,0,0,0,0
:endlayer
layer: 15
0,0,0,0,0,0,0,0,0,0,0,0,0,0,0,0,0,0,0
0,0,0,0,0,0,0,0,0,0,0,0,0,0,0,0,0,0,0
0,0,0,0,0,0,0,0,0,0,0,0,0,0,0,0,0,0,0
0,0,0,0,0,0,0,0,0,0,0,0,0,0,0,0,0,0,0
0,0,0,0,0,0,0,0,0,0,0,0,0,0,0,0,0,0,0
0,0,0,0,0,0,0,0,0,0,0,0,0,0,0,0,0,0,0
0,0,0,0,0,0,0,0,0,15,0,0,0,0,0,0,0,0,0
0,0,0,0,0,0,0,27,20,5,20,27,0,0,0,0,0,0,0
0,0,0,0,0,0,0,5,0,0,0,5,0,0,0,0,0,0,0
0,0,0,0,0,0,15,20,0,0,0,20,15,0,0,0,0,0,0
0,0,0,0,0,0,0,5,0,0,0,5,0,0,0,0,0,0,0
0,0,0,0,0,0,0,26,20,5,20,26,0,0,0,0,0,0,0
0,0,0,0,0,0,0,0,0,15,0,0,0,0,0,0,0,0,0
0,0,0,0,0,0,0,0,0,0,0,0,0,0,0,0,0,0,0
0,0,0,0,0,0,0,0,0,0,0,0,0,0,0,0,0,0,0
0,0,0,0,0,0,0,0,0,0,0,0,0,0,0,0,0,0,0
0,0,0,0,0,0,0,0,0,0,0,0,0,0,0,0,0,0,0
0,0,0,0,0,0,0,0,0,0,0,0,0,0,0,0,0,0,0
0,0,0,0,0,0,0,0,0,0,0,0,0,0,0,0,0,0,0
:endlayer
layer: 16
0,0,0,0,0,0,0,0,0,0,0,0,0,0,0,0,0,0,0
0,0,0,0,0,0,0,0,0,0,0,0,0,0,0,0,0,0,0
0,0,0,0,0,0,0,0,0,0,0,0,0,0,0,0,0,0,0
0,0,0,0,0,0,0,0,0,0,0,0,0,0,0,0,0,0,0
0,0,0,0,0,0,0,0,0,0,0,0,0,0,0,0,0,0,0
0,0,0,0,0,0,0,0,0,0,0,0,0,0,0,0,0,0,0
0,0,0,0,0,0,0,0,0,0,0,0,0,0,0,0,0,0,0
0,0,0,0,0,0,0,0,20,5,20,0,0,0,0,0,0,0,0
0,0,0,0,0,0,0,5,0,0,0,5,0,0,0,0,0,0,0
0,0,0,0,0,0,0,10,0,0,0,10,0,0,0,0,0,0,0
0,0,0,0,0,0,0,5,0,0,0,5,0,0,0,0,0,0,0
0,0,0,0,0,0,0,0,20,5,20,0,0,0,0,0,0,0,0
0,0,0,0,0,0,0,0,0,0,0,0,0,0,0,0,0,0,0
0,0,0,0,0,0,0,0,0,0,0,0,0,0,0,0,0,0,0
0,0,0,0,0,0,0,0,0,0,0,0,0,0,0,0,0,0,0
0,0,0,0,0,0,0,0,0,0,0,0,0,0,0,0,0,0,0
0,0,0,0,0,0,0,0,0,0,0,0,0,0,0,0,0,0,0
0,0,0,0,0,0,0,0,0,0,0,0,0,0,0,0,0,0,0
0,0,0,0,0,0,0,0,0,0,0,0,0,0,0,0,0,0,0
:endlayer
layer: 17
0,0,0,0,0,0,0,0,0,0,0,0,0,0,0,0,0,0,0
0,0,0,0,0,0,0,0,0,0,0,0,0,0,0,0,0,0,0
0,0,0,0,0,0,0,0,0,0,0,0,0,0,0,0,0,0,0
0,0,0,0,0,0,0,0,0,0,0,0,0,0,0,0,0,0,0
0,0,0,0,0,0,0,0,0,0,0,0,0,0,0,0,0,0,0
0,0,0,0,0,0,0,0,0,0,0,0,0,0,0,0,0,0,0
0,0,0,0,0,0,0,0,0,0,0,0,0,0,0,0,0,0,0
0,0,0,0,0,0,0,10,20,5,20,10,0,0,0,0,0,0,0
0,0,0,0,0,0,0,5,0,0,0,5,0,0,0,0,0,0,0
0,0,0,0,0,0,0,20,0,0,0,20,0,0,0,0,0,0,0
0,0,0,0,0,0,0,5,0,0,0,5,0,0,0,0,0,0,0
0,0,0,0,0,0,0,10,20,5,20,10,0,0,0,0,0,0,0
0,0,0,0,0,0,0,0,0,0,0,0,0,0,0,0,0,0,0
0,0,0,0,0,0,0,0,0,0,0,0,0,0,0,0,0,0,0
0,0,0,0,0,0,0,0,0,0,0,0,0,0,0,0,0,0,0
0,0,0,0,0,0,0,0,0,0,0,0,0,0,0,0,0,0,0
0,0,0,0,0,0,0,0,0,0,0,0,0,0,0,0,0,0,0
0,0,0,0,0,0,0,0,0,0,0,0,0,0,0,0,0,0,0
0,0,0,0,0,0,0,0,0,0,0,0,0,0,0,0,0,0,0
:endlayer
layer: 18
0,0,0,0,0,0,0,0,0,0,0,0,0,0,0,0,0,0,0
0,0,0,0,0,0,0,0,0,0,0,0,0,0,0,0,0,0,0
0,0,0,0,0,0,0,0,0,0,0,0,0,0,0,0,0,0,0
0,0,0,0,0,0,0,0,0,0,0,0,0,0,0,0,0,0,0
0,0,0,0,0,0,0,0,0,0,0,0,0,0,0,0,0,0,0
0,0,0,0,0,0,0,0,0,0,0,0,0,0,0,0,0,0,0
0,0,0,0,0,0,0,0,30,30,30,0,0,0,0,0,0,0,0
0,0,0,0,0,0,0,30,25,5,25,30,0,0,0,0,0,0,0
0,0,0,0,0,0,30,5,0,0,0,5,30,0,0,0,0,0,0
0,0,0,0,0,0,30,24,0,0,0,24,30,0,0,0,0,0,0
0,0,0,0,0,0,30,5,0,0,0,5,30,0,0,0,0,0,0
0,0,0,0,0,0,0,30,25,5,25,30,0,0,0,0,0,0,0
0,0,0,0,0,0,0,0,30,30,30,0,0,0,0,0,0,0,0
0,0,0,0,0,0,0,0,0,0,0,0,0,0,0,0,0,0,0
0,0,0,0,0,0,0,0,0,0,0,0,0,0,0,0,0,0,0
0,0,0,0,0,0,0,0,0,0,0,0,0,0,0,0,0,0,0
0,0,0,0,0,0,0,0,0,0,0,0,0,0,0,0,0,0,0
0,0,0,0,0,0,0,0,0,0,0,0,0,0,0,0,0,0,0
0,0,0,0,0,0,0,0,0,0,0,0,0,0,0,0,0,0,0
:endlayer
layer: 19
0,0,0,0,0,0,0,0,0,0,0,0,0,0,0,0,0,0,0
0,0,0,0,0,0,0,0,0,0,0,0,0,0,0,0,0,0,0
0,0,0,0,0,0,0,0,0,0,0,0,0,0,0,0,0,0,0
0,0,0,0,0,0,0,0,0,0,0,0,0,0,0,0,0,0,0
0,0,0,0,0,0,0,0,0,0,0,0,0,0,0,0,0,0,0
0,0,0,0,0,0,0,0,0,0,0,0,0,0,0,0,0,0,0
0,0,0,0,0,0,0,30,30,30,30,30,0,0,0,0,0,0,0
0,0,0,0,0,0,30,30,20,20,20,30,30,0,0,0,0,0,0
0,0,0,0,0,0,30,20,0,0,0,20,30,0,0,0,0,0,0
0,0,0,0,0,0,30,20,0,0,0,20,30,0,0,0,0,0,0
0,0,0,0,0,0,30,20,0,0,0,20,30,0,0,0,0,0,0
0,0,0,0,0,0,30,30,20,20,20,30,30,0,0,0,0,0,0
0,0,0,0,0,0,0,30,30,30,30,30,0,0,0,0,0,0,0
0,0,0,0,0,0,0,0,0,0,0,0,0,0,0,0,0,0,0
0,0,0,0,0,0,0,0,0,0,0,0,0,0,0,0,0,0,0
0,0,0,0,0,0,0,0,0,0,0,0,0,0,0,0,0,0,0
0,0,0,0,0,0,0,0,0,0,0,0,0,0,0,0,0,0,0
0,0,0,0,0,0,0,0,0,0,0,0,0,0,0,0,0,0,0
0,0,0,0,0,0,0,0,0,0,0,0,0,0,0,0,0,0,0
:endlayer
layer: 20
0,0,0,0,0,0,0,0,0,0,0,0,0,0,0,0,0,0,0
0,0,0,0,0,0,0,0,0,0,0,0,0,0,0,0,0,0,0
0,0,0,0,0,0,0,0,0,0,0,0,0,0,0,0,0,0,0
0,0,0,0,0,0,0,0,0,0,0,0,0,0,0,0,0,0,0
0,0,0,0,0,0,0,0,0,0,0,0,0,0,0,0,0,0,0
0,0,0,0,0,0,0,0,0,0,0,0,0,0,0,0,0,0,0
0,0,0,0,0,0,0,0,30,30,30,0,0,0,0,0,0,0,0
0,0,0,0,0,0,0,30,20,20,20,30,0,0,0,0,0,0,0
0,0,0,0,0,0,30,20,10,14,10,20,30,0,0,0,0,0,0
0,0,0,0,0,0,30,20,12,0,17,20,30,0,0,0,0,0,0
0,0,0,0,0,0,30,20,10,13,10,20,30,0,0,0,0,0,0
0,0,0,0,0,0,0,30,20,20,20,30,0,0,0,0,0,0,0
0,0,0,0,0,0,0,0,30,30,30,0,0,0,0,0,0,0,0
0,0,0,0,0,0,0,0,0,0,0,0,0,0,0,0,0,0,0
0,0,0,0,0,0,0,0,0,0,0,0,0,0,0,0,0,0,0
0,0,0,0,0,0,0,0,0,0,0,0,0,0,0,0,0,0,0
0,0,0,0,0,0,0,0,0,0,0,0,0,0,0,0,0,0,0
0,0,0,0,0,0,0,0,0,0,0,0,0,0,0,0,0,0,0
0,0,0,0,0,0,0,0,0,0,0,0,0,0,0,0,0,0,0
:endlayer
layer: 21
0,0,0,0,0,0,0,0,0,0,0,0,0,0,0,0,0,0,0
0,0,0,0,0,0,0,0,0,0,0,0,0,0,0,0,0,0,0
0,0,0,0,0,0,0,0,0,0,0,0,0,0,0,0,0,0,0
0,0,0,0,0,0,0,0,0,0,0,0,0,0,0,0,0,0,0
0,0,0,0,0,0,0,0,0,0,0,0,0,0,0,0,0,0,0
0,0,0,0,0,0,0,0,0,0,0,0,0,0,0,0,0,0,0
0,0,0,0,0,0,0,0,0,30,0,0,0,0,0,0,0,0,0
0,0,0,0,0,0,0,30,30,20,30,30,0,0,0,0,0,0,0
0,0,0,0,0,0,0,30,20,19,20,30,0,0,0,0,0,0,0
0,0,0,0,0,0,30,20,23,10,22,20,30,0,0,0,0,0,0
0,0,0,0,0,0,0,30,20,21,20,30,0,0,0,0,0,0,0
0,0,0,0,0,0,0,30,30,20,30,30,0,0,0,0,0,0,0
0,0,0,0,0,0,0,0,0,30,0,0,0,0,0,0,0,0,0
0,0,0,0,0,0,0,0,0,0,0,0,0,0,0,0,0,0,0
0,0,0,0,0,0,0,0,0,0,0,0,0,0,0,0,0,0,0
0,0,0,0,0,0,0,0,0,0,0,0,0,0,0,0,0,0,0
0,0,0,0,0,0,0,0,0,0,0,0,0,0,0,0,0,0,0
0,0,0,0,0,0,0,0,0,0,0,0,0,0,0,0,0,0,0
0,0,0,0,0,0,0,0,0,0,0,0,0,0,0,0,0,0,0
:endlayer
layer: 22
0,0,0,0,0,0,0,0,0,0,0,0,0,0,0,0,0,0,0
0,0,0,0,0,0,0,0,0,0,0,0,0,0,0,0,0,0,0
0,0,0,0,0,0,0,0,0,0,0,0,0,0,0,0,0,0,0
0,0,0,0,0,0,0,0,0,0,0,0,0,0,0,0,0,0,0
0,0,0,0,0,0,0,0,0,0,0,0,0,0,0,0,0,0,0
0,0,0,0,0,0,0,0,0,0,0,0,0,0,0,0,0,0,0
0,0,0,0,0,0,0,0,0,0,0,0,0,0,0,0,0,0,0
0,0,0,0,0,0,0,0,30,30,30,0,0,0,0,0,0,0,0
0,0,0,0,0,0,0,30,30,20,30,30,0,0,0,0,0,0,0
0,0,0,0,0,0,0,30,20,10,20,30,0,0,0,0,0,0,0
0,0,0,0,0,0,0,30,30,20,30,30,0,0,0,0,0,0,0
0,0,0,0,0,0,0,0,30,30,30,0,0,0,0,0,0,0,0
0,0,0,0,0,0,0,0,0,0,0,0,0,0,0,0,0,0,0
0,0,0,0,0,0,0,0,0,0,0,0,0,0,0,0,0,0,0
0,0,0,0,0,0,0,0,0,0,0,0,0,0,0,0,0,0,0
0,0,0,0,0,0,0,0,0,0,0,0,0,0,0,0,0,0,0
0,0,0,0,0,0,0,0,0,0,0,0,0,0,0,0,0,0,0
0,0,0,0,0,0,0,0,0,0,0,0,0,0,0,0,0,0,0
0,0,0,0,0,0,0,0,0,0,0,0,0,0,0,0,0,0,0
:endlayer
layer: 23
0,0,0,0,0,0,0,0,0,0,0,0,0,0,0,0,0,0,0
0,0,0,0,0,0,0,0,0,0,0,0,0,0,0,0,0,0,0
0,0,0,0,0,0,0,0,0,0,0,0,0,0,0,0,0,0,0
0,0,0,0,0,0,0,0,0,0,0,0,0,0,0,0,0,0,0
0,0,0,0,0,0,0,0,0,0,0,0,0,0,0,0,0,0,0
0,0,0,0,0,0,0,0,0,0,0,0,0,0,0,0,0,0,0
0,0,0,0,0,0,0,0,0,0,0,0,0,0,0,0,0,0,0
0,0,0,0,0,0,0,0,0,15,0,0,0,0,0,0,0,0,0
0,0,0,0,0,0,0,0,30,30,30,0,0,0,0,0,0,0,0
0,0,0,0,0,0,0,15,30,20,30,15,0,0,0,0,0,0,0
0,0,0,0,0,0,0,0,30,30,30,0,0,0,0,0,0,0,0
0,0,0,0,0,0,0,0,0,15,0,0,0,0,0,0,0,0,0
0,0,0,0,0,0,0,0,0,0,0,0,0,0,0,0,0,0,0
0,0,0,0,0,0,0,0,0,0,0,0,0,0,0,0,0,0,0
0,0,0,0,0,0,0,0,0,0,0,0,0,0,0,0,0,0,0
0,0,0,0,0,0,0,0,0,0,0,0,0,0,0,0,0,0,0
0,0,0,0,0,0,0,0,0,0,0,0,0,0,0,0,0,0,0
0,0,0,0,0,0,0,0,0,0,0,0,0,0,0,0,0,0,0
0,0,0,0,0,0,0,0,0,0,0,0,0,0,0,0,0,0,0
:endlayer
layer: 24
0,0,0,0,0,0,0,0,0,0,0,0,0,0,0,0,0,0,0
0,0,0,0,0,0,0,0,0,0,0,0,0,0,0,0,0,0,0
0,0,0,0,0,0,0,0,0,0,0,0,0,0,0,0,0,0,0
0,0,0,0,0,0,0,0,0,0,0,0,0,0,0,0,0,0,0
0,0,0,0,0,0,0,0,0,0,0,0,0,0,0,0,0,0,0
0,0,0,0,0,0,0,0,0,0,0,0,0,0,0,0,0,0,0
0,0,0,0,0,0,0,0,0,0,0,0,0,0,0,0,0,0,0
0,0,0,0,0,0,0,0,0,0,0,0,0,0,0,0,0,0,0
0,0,0,0,0,0,0,0,0,30,0,0,0,0,0,0,0,0,0
0,0,0,0,0,0,0,0,30,20,30,0,0,0,0,0,0,0,0
0,0,0,0,0,0,0,0,0,30,0,0,0,0,0,0,0,0,0
0,0,0,0,0,0,0,0,0,0,0,0,0,0,0,0,0,0,0
0,0,0,0,0,0,0,0,0,0,0,0,0,0,0,0,0,0,0
0,0,0,0,0,0,0,0,0,0,0,0,0,0,0,0,0,0,0
0,0,0,0,0,0,0,0,0,0,0,0,0,0,0,0,0,0,0
0,0,0,0,0,0,0,0,0,0,0,0,0,0,0,0,0,0,0
0,0,0,0,0,0,0,0,0,0,0,0,0,0,0,0,0,0,0
0,0,0,0,0,0,0,0,0,0,0,0,0,0,0,0,0,0,0
0,0,0,0,0,0,0,0,0,0,0,0,0,0,0,0,0,0,0
:endlayer
layer: 25
0,0,0,0,0,0,0,0,0,0,0,0,0,0,0,0,0,0,0
0,0,0,0,0,0,0,0,0,0,0,0,0,0,0,0,0,0,0
0,0,0,0,0,0,0,0,0,0,0,0,0,0,0,0,0,0,0
0,0,0,0,0,0,0,0,0,0,0,0,0,0,0,0,0,0,0
0,0,0,0,0,0,0,0,0,0,0,0,0,0,0,0,0,0,0
0,0,0,0,0,0,0,0,0,0,0,0,0,0,0,0,0,0,0
0,0,0,0,0,0,0,0,0,0,0,0,0,0,0,0,0,0,0
0,0,0,0,0,0,0,0,0,0,0,0,0,0,0,0,0,0,0
0,0,0,0,0,0,0,0,0,30,0,0,0,0,0,0,0,0,0
0,0,0,0,0,0,0,0,30,20,30,0,0,0,0,0,0,0,0
0,0,0,0,0,0,0,0,0,30,0,0,0,0,0,0,0,0,0
0,0,0,0,0,0,0,0,0,0,0,0,0,0,0,0,0,0,0
0,0,0,0,0,0,0,0,0,0,0,0,0,0,0,0,0,0,0
0,0,0,0,0,0,0,0,0,0,0,0,0,0,0,0,0,0,0
0,0,0,0,0,0,0,0,0,0,0,0,0,0,0,0,0,0,0
0,0,0,0,0,0,0,0,0,0,0,0,0,0,0,0,0,0,0
0,0,0,0,0,0,0,0,0,0,0,0,0,0,0,0,0,0,0
0,0,0,0,0,0,0,0,0,0,0,0,0,0,0,0,0,0,0
0,0,0,0,0,0,0,0,0,0,0,0,0,0,0,0,0,0,0
:endlayer
layer: 26
0,0,0,0,0,0,0,0,0,0,0,0,0,0,0,0,0,0,0
0,0,0,0,0,0,0,0,0,0,0,0,0,0,0,0,0,0,0
0,0,0,0,0,0,0,0,0,0,0,0,0,0,0,0,0,0,0
0,0,0,0,0,0,0,0,0,0,0,0,0,0,0,0,0,0,0
0,0,0,0,0,0,0,0,0,0,0,0,0,0,0,0,0,0,0
0,0,0,0,0,0,0,0,0,0,0,0,0,0,0,0,0,0,0
0,0,0,0,0,0,0,0,0,0,0,0,0,0,0,0,0,0,0
0,0,0,0,0,0,0,0,0,0,0,0,0,0,0,0,0,0,0
0,0,0,0,0,0,0,0,0,0,0,0,0,0,0,0,0,0,0
0,0,0,0,0,0,0,0,0,30,0,0,0,0,0,0,0,0,0
0,0,0,0,0,0,0,0,0,0,0,0,0,0,0,0,0,0,0
0,0,0,0,0,0,0,0,0,0,0,0,0,0,0,0,0,0,0
0,0,0,0,0,0,0,0,0,0,0,0,0,0,0,0,0,0,0
0,0,0,0,0,0,0,0,0,0,0,0,0,0,0,0,0,0,0
0,0,0,0,0,0,0,0,0,0,0,0,0,0,0,0,0,0,0
0,0,0,0,0,0,0,0,0,0,0,0,0,0,0,0,0,0,0
0,0,0,0,0,0,0,0,0,0,0,0,0,0,0,0,0,0,0
0,0,0,0,0,0,0,0,0,0,0,0,0,0,0,0,0,0,0
0,0,0,0,0,0,0,0,0,0,0,0,0,0,0,0,0,0,0
:endlayer
layer: 27
0,0,0,0,0,0,0,0,0,0,0,0,0,0,0,0,0,0,0
0,0,0,0,0,0,0,0,0,0,0,0,0,0,0,0,0,0,0
0,0,0,0,0,0,0,0,0,0,0,0,0,0,0,0,0,0,0
0,0,0,0,0,0,0,0,0,0,0,0,0,0,0,0,0,0,0
0,0,0,0,0,0,0,0,0,0,0,0,0,0,0,0,0,0,0
0,0,0,0,0,0,0,0,0,0,0,0,0,0,0,0,0,0,0
0,0,0,0,0,0,0,0,0,0,0,0,0,0,0,0,0,0,0
0,0,0,0,0,0,0,0,0,0,0,0,0,0,0,0,0,0,0
0,0,0,0,0,0,0,0,0,0,0,0,0,0,0,0,0,0,0
0,0,0,0,0,0,0,0,0,30,0,0,0,0,0,0,0,0,0
0,0,0,0,0,0,0,0,0,0,0,0,0,0,0,0,0,0,0
0,0,0,0,0,0,0,0,0,0,0,0,0,0,0,0,0,0,0
0,0,0,0,0,0,0,0,0,0,0,0,0,0,0,0,0,0,0
0,0,0,0,0,0,0,0,0,0,0,0,0,0,0,0,0,0,0
0,0,0,0,0,0,0,0,0,0,0,0,0,0,0,0,0,0,0
0,0,0,0,0,0,0,0,0,0,0,0,0,0,0,0,0,0,0
0,0,0,0,0,0,0,0,0,0,0,0,0,0,0,0,0,0,0
0,0,0,0,0,0,0,0,0,0,0,0,0,0,0,0,0,0,0
0,0,0,0,0,0,0,0,0,0,0,0,0,0,0,0,0,0,0
:endlayer
layer: 28
0,0,0,0,0,0,0,0,0,0,0,0,0,0,0,0,0,0,0
0,0,0,0,0,0,0,0,0,0,0,0,0,0,0,0,0,0,0
0,0,0,0,0,0,0,0,0,0,0,0,0,0,0,0,0,0,0
0,0,0,0,0,0,0,0,0,0,0,0,0,0,0,0,0,0,0
0,0,0,0,0,0,0,0,0,0,0,0,0,0,0,0,0,0,0
0,0,0,0,0,0,0,0,0,0,0,0,0,0,0,0,0,0,0
0,0,0,0,0,0,0,0,0,0,0,0,0,0,0,0,0,0,0
0,0,0,0,0,0,0,0,0,0,0,0,0,0,0,0,0,0,0
0,0,0,0,0,0,0,0,0,0,0,0,0,0,0,0,0,0,0
0,0,0,0,0,0,0,0,0,15,0,0,0,0,0,0,0,0,0
0,0,0,0,0,0,0,0,0,0,0,0,0,0,0,0,0,0,0
0,0,0,0,0,0,0,0,0,0,0,0,0,0,0,0,0,0,0
0,0,0,0,0,0,0,0,0,0,0,0,0,0,0,0,0,0,0
0,0,0,0,0,0,0,0,0,0,0,0,0,0,0,0,0,0,0
0,0,0,0,0,0,0,0,0,0,0,0,0,0,0,0,0,0,0
0,0,0,0,0,0,0,0,0,0,0,0,0,0,0,0,0,0,0
0,0,0,0,0,0,0,0,0,0,0,0,0,0,0,0,0,0,0
0,0,0,0,0,0,0,0,0,0,0,0,0,0,0,0,0,0,0
0,0,0,0,0,0,0,0,0,0,0,0,0,0,0,0,0,0,0
:endlayer

#### RULES ####
rule:
plugin=vanillaBlocks
number=1
data:
JSON:{blockState:{blockName:"minecraft:grass",properties:{snowy:"false"}}}
:enddata
:endrule

rule:
plugin=vanillaBlocks
number=2
data:
JSON:{blockState:{blockName:"minecraft:stonebrick",properties:{variant:"stonebrick"}}}
:enddata
:endrule

rule:
plugin=vanillaBlocks
number=3
data:
JSON:{blockState:{blockName:"minecraft:cobblestone"}}
:enddata
:endrule

rule:
plugin=vanillaBlocks
number=4
data:
JSON:{blockState:{blockName:"minecraft:dirt",properties:{variant:"dirt",snowy:"false"}}}
:enddata
:endrule

rule:
plugin=vanillaBlocks
number=5
data:
JSON:{blockState:{blockName:"minecraft:log",properties:{variant:"oak",axis:"y"}}}
:enddata
:endrule

rule:
plugin=vanillaBlocks
number=6
data:
JSON:{blockState:{blockName:"minecraft:stone_brick_stairs",properties:{half:"bottom",shape:"straight",facing:"west"}}}
:enddata
:endrule

rule:
plugin=vanillaBlocks
number=7
data:
JSON:{blockState:{blockName:"minecraft:stone_brick_stairs",properties:{half:"bottom",shape:"straight",facing:"south"}}}
:enddata
:endrule

rule:
plugin=vanillaBlocks
number=8
data:
JSON:{blockState:{blockName:"minecraft:stone_brick_stairs",properties:{half:"bottom",shape:"straight",facing:"north"}}}
:enddata
:endrule

rule:
plugin=vanillaBlocks
number=9
data:
JSON:{blockState:{blockName:"minecraft:stone_brick_stairs",properties:{half:"bottom",shape:"straight",facing:"east"}}}
:enddata
:endrule

rule:
plugin=vanillaBlocks
number=10
data:
JSON:{blockState:{blockName:"minecraft:fence",properties:{east:"false",south:"false",north:"false",west:"false"}}}
:enddata
:endrule

rule:
plugin=vanillaBlocks
number=11
data:
JSON:{blockState:{blockName:"minecraft:stone_slab",properties:{half:"bottom",variant:"stone_brick"}}}
:enddata
:endrule

rule:
plugin=vanillaBlocks
number=12
data:
JSON:{blockState:{blockName:"minecraft:torch",properties:{facing:"east"}}}
:enddata
:endrule

rule:
plugin=vanillaBlocks
number=13
data:
JSON:{blockState:{blockName:"minecraft:torch",properties:{facing:"north"}}}
:enddata
:endrule

rule:
plugin=vanillaBlocks
number=14
data:
JSON:{blockState:{blockName:"minecraft:torch",properties:{facing:"south"}}}
:enddata
:endrule

rule:
plugin=vanillaBlocks
number=15
data:
JSON:{blockState:{blockName:"minecraft:torch",properties:{facing:"up"}}}
:enddata
:endrule

rule:
plugin=blockTile
number=16
data:
JSON:{blockState:{blockName:"waystones:waystone",properties:{facing:"north",base:"true"}},teData:{WaystoneName:"Kievarus Shrine",Owner:{L:-5246186782518495579L,M:-3431673226102095866L},IsDummy:0b,WasGenerated:0b,IsMossy:0b,id:"waystones:waystone",IsGlobal:0b}}
:enddata
:endrule

rule:
plugin=vanillaBlocks
number=17
data:
JSON:{blockState:{blockName:"minecraft:torch",properties:{facing:"west"}}}
:enddata
:endrule

rule:
plugin=blockTile
number=18
data:
JSON:{blockState:{blockName:"waystones:waystone",properties:{facing:"east",base:"false"}},teData:{IsDummy:1b,id:"waystones:waystone"}}
:enddata
:endrule

rule:
plugin=vanillaBlocks
number=19
data:
JSON:{blockState:{blockName:"minecraft:oak_stairs",properties:{half:"top",shape:"straight",facing:"north"}}}
:enddata
:endrule

rule:
plugin=vanillaBlocks
number=20
data:
JSON:{blockState:{blockName:"minecraft:planks",properties:{variant:"oak"}}}
:enddata
:endrule

rule:
plugin=vanillaBlocks
number=21
data:
JSON:{blockState:{blockName:"minecraft:oak_stairs",properties:{half:"top",shape:"straight",facing:"south"}}}
:enddata
:endrule

rule:
plugin=vanillaBlocks
number=22
data:
JSON:{blockState:{blockName:"minecraft:oak_stairs",properties:{half:"top",shape:"straight",facing:"east"}}}
:enddata
:endrule

rule:
plugin=vanillaBlocks
number=23
data:
JSON:{blockState:{blockName:"minecraft:oak_stairs",properties:{half:"top",shape:"straight",facing:"west"}}}
:enddata
:endrule

rule:
plugin=vanillaBlocks
number=24
data:
JSON:{blockState:{blockName:"minecraft:log",properties:{variant:"oak",axis:"z"}}}
:enddata
:endrule

rule:
plugin=vanillaBlocks
number=25
data:
JSON:{blockState:{blockName:"minecraft:log",properties:{variant:"oak",axis:"x"}}}
:enddata
:endrule

rule:
plugin=vanillaBlocks
number=26
data:
JSON:{blockState:{blockName:"minecraft:oak_stairs",properties:{half:"bottom",shape:"straight",facing:"north"}}}
:enddata
:endrule

rule:
plugin=vanillaBlocks
number=27
data:
JSON:{blockState:{blockName:"minecraft:oak_stairs",properties:{half:"bottom",shape:"straight",facing:"south"}}}
:enddata
:endrule

rule:
plugin=vanillaBlocks
number=28
data:
JSON:{blockState:{blockName:"minecraft:oak_stairs",properties:{half:"bottom",shape:"straight",facing:"east"}}}
:enddata
:endrule

rule:
plugin=vanillaBlocks
number=29
data:
JSON:{blockState:{blockName:"minecraft:oak_stairs",properties:{half:"bottom",shape:"straight",facing:"west"}}}
:enddata
:endrule

rule:
plugin=vanillaBlocks
number=30
data:
JSON:{blockState:{blockName:"minecraft:wool",properties:{color:"brown"}}}
:enddata
:endrule

#### ENTITIES ####
