# Ancient Warfare Structure Template File
# Auto-generated structure template file. created on: 3/19/2021 at: 17:42:52
# Lines beginning with # denote comments

header:
version=2.11
name=SurvivalBuild_SiegeCampTentL_spruce
mods=
size=21,11,12
offset=10,0,11
:endheader

#### VALIDATION ####
validation:
type=ground
structureAuthor=TheOddlySeagull
survival=true
worldGenEnabled=false
unique=false
preserveBlocks=false
preventNaturalHostileSpawns=false
selectionWeight=1
clusterValue=1
minDuplicateDistance=1
dimensionWhiteList=true
dimensionList=
biomeGroupList=
biomeWhiteList=true
biomeList=
leveling=0
fill=0
border=0
blockSwap=false
territoryName=
biomeReplacement=minecraft:
minGenerationHeight=0
maxGenerationHeight=255
:endvalidation

#### LAYERS ####
layer: 0
0,0,0,0,1,2,2,2,2,2,2,2,2,2,2,2,1,0,0,0,0
0,0,1,2,2,1,0,0,0,0,1,0,0,0,0,1,2,2,1,0,0
0,1,2,0,0,0,0,0,0,0,0,0,0,0,0,0,0,0,2,1,0
0,2,1,0,0,0,0,0,0,0,0,0,0,0,0,0,0,0,1,2,0
0,2,0,0,0,0,0,0,0,0,0,0,0,0,0,0,0,0,0,2,0
0,2,0,0,0,0,3,0,0,0,0,0,0,0,3,0,0,0,0,2,0
0,2,0,0,0,0,0,0,0,0,0,0,0,0,0,0,0,0,0,2,0
0,2,1,0,0,0,0,0,0,0,0,0,0,0,0,0,0,0,1,2,0
0,1,2,0,0,0,0,0,0,0,0,0,0,0,0,0,0,0,2,1,0
0,0,1,2,2,1,0,0,0,0,0,0,0,0,0,1,2,2,1,0,0
0,0,0,0,1,2,2,2,2,0,0,0,2,2,2,2,1,0,0,0,0
0,0,0,0,0,0,0,0,1,0,0,0,1,0,0,0,0,0,0,0,0
:endlayer
layer: 1
0,0,0,0,1,4,5,4,5,4,6,4,5,4,5,4,1,0,0,0,0
0,0,1,4,5,1,0,0,0,0,1,0,0,0,0,1,5,4,1,0,0
0,1,5,0,0,0,0,0,0,0,0,0,0,0,0,0,0,0,5,1,0
0,4,1,0,0,0,0,0,0,0,0,0,0,0,0,0,0,0,1,4,0
0,5,0,0,0,0,0,0,0,0,0,0,0,0,0,0,0,0,0,5,0
0,4,0,0,0,0,3,0,0,0,0,0,0,0,3,0,0,0,0,4,0
0,5,0,0,0,0,0,0,0,0,0,0,0,0,0,0,0,0,0,5,0
0,4,1,0,0,0,0,0,0,0,0,0,0,0,0,0,0,0,1,4,0
0,1,5,0,0,0,0,0,0,0,0,0,0,0,0,0,0,0,5,1,0
0,0,1,4,5,1,0,0,0,0,0,0,0,0,0,1,5,4,1,0,0
0,0,0,0,1,4,6,4,5,0,0,0,5,4,6,4,1,0,0,0,0
0,0,0,0,0,0,0,0,1,0,0,0,1,0,0,0,0,0,0,0,0
:endlayer
layer: 2
0,0,0,0,1,4,5,4,5,6,10,6,5,4,5,4,1,0,0,0,0
0,0,1,4,5,1,0,0,8,0,1,0,8,0,0,1,5,4,1,0,0
0,1,5,8,0,0,0,0,0,0,0,0,0,0,0,0,0,8,5,1,0
0,4,1,0,0,0,0,0,0,0,0,0,0,0,0,0,0,0,1,4,0
1,5,0,0,0,0,7,0,0,0,0,0,0,0,7,0,0,0,0,5,1
0,1,0,0,0,9,3,11,0,0,0,0,0,9,3,11,0,0,0,1,0
1,5,0,0,0,0,8,0,0,0,0,0,0,0,8,0,0,0,0,5,1
0,4,1,0,0,0,0,0,0,0,0,0,0,0,0,0,0,0,1,4,0
0,1,5,7,0,0,0,0,0,0,0,0,0,0,0,0,0,7,5,1,0
0,0,1,4,5,1,0,0,0,0,0,0,0,0,0,1,5,4,1,0,0
0,0,0,0,1,6,10,6,5,4,0,4,5,6,10,6,1,0,0,0,0
0,0,0,0,0,0,0,8,1,0,0,0,1,8,0,0,0,0,0,0,0
:endlayer
layer: 3
0,0,0,0,1,4,5,4,5,4,6,4,5,4,5,4,1,0,0,0,0
0,0,1,4,5,1,0,0,0,0,1,0,0,0,0,1,5,4,1,0,0
0,1,5,0,0,0,0,0,0,0,0,0,0,0,0,0,0,0,5,1,0
0,4,1,0,0,0,0,0,0,0,0,0,0,0,0,0,0,0,1,4,0
12,5,0,0,0,0,0,0,0,0,0,0,0,0,0,0,0,0,0,5,12
13,4,0,0,0,0,3,0,0,0,0,0,0,0,3,0,0,0,0,4,13
12,5,0,0,0,0,0,0,0,0,0,0,0,0,0,0,0,0,0,5,12
0,4,1,0,0,0,0,0,0,0,0,0,0,0,0,0,0,0,1,4,0
0,1,5,0,0,0,0,0,0,0,0,0,0,0,0,0,0,0,5,1,0
0,0,1,4,5,1,0,0,0,0,7,0,0,0,0,1,5,4,1,0,0
0,0,0,0,1,4,6,4,5,4,5,4,5,4,6,4,1,0,0,0,0
0,0,0,0,0,0,0,0,12,13,13,13,12,0,0,0,0,0,0,0,0
:endlayer
layer: 4
0,0,0,0,0,0,0,0,0,0,0,0,0,0,0,0,0,0,0,0,0
0,0,0,0,0,4,5,4,5,4,5,4,5,4,5,4,0,0,0,0,0
0,0,0,4,5,1,0,0,0,0,1,0,0,0,0,1,5,4,0,0,0
0,0,4,1,0,0,0,0,0,0,0,0,0,0,0,0,0,1,4,0,0
0,0,5,0,0,0,0,0,0,0,0,0,0,0,0,0,0,0,5,0,0
0,0,4,0,0,0,3,0,0,0,0,0,0,0,3,0,0,0,4,0,0
0,0,5,0,0,0,0,0,0,0,0,0,0,0,0,0,0,0,5,0,0
0,0,4,1,0,0,0,0,0,0,0,0,0,0,0,0,0,1,4,0,0
0,0,0,4,5,1,0,0,0,0,0,0,0,0,0,1,5,4,0,0,0
0,0,0,0,0,4,5,4,5,4,5,4,5,4,5,4,0,0,0,0,0
0,0,0,0,0,0,0,0,0,0,0,0,0,0,0,0,0,0,0,0,0
0,0,0,0,0,0,0,0,0,0,0,0,0,0,0,0,0,0,0,0,0
:endlayer
layer: 5
0,0,0,0,0,0,0,0,0,0,0,0,0,0,0,0,0,0,0,0,0
0,0,0,0,0,0,0,0,0,0,0,0,0,0,0,0,0,0,0,0,0
0,0,0,0,0,4,5,4,5,4,5,4,5,4,5,4,0,0,0,0,0
0,0,0,4,5,1,0,0,0,4,4,4,0,0,0,1,5,4,0,0,0
0,0,0,5,0,0,0,0,0,0,1,0,0,0,0,0,0,5,0,0,0
0,0,0,4,0,0,3,0,0,0,0,0,0,0,3,0,0,4,0,0,0
0,0,0,5,0,0,0,0,0,0,1,0,0,0,0,0,0,5,0,0,0
0,0,0,4,5,1,0,0,0,4,4,4,0,0,0,1,5,4,0,0,0
0,0,0,0,0,4,5,4,5,4,5,4,5,4,5,4,0,0,0,0,0
0,0,0,0,0,0,0,0,0,0,0,0,0,0,0,0,0,0,0,0,0
0,0,0,0,0,0,0,0,0,0,0,0,0,0,0,0,0,0,0,0,0
0,0,0,0,0,0,0,0,0,0,0,0,0,0,0,0,0,0,0,0,0
:endlayer
layer: 6
0,0,0,0,0,0,0,0,0,0,0,0,0,0,0,0,0,0,0,0,0
0,0,0,0,0,0,0,0,0,0,0,0,0,0,0,0,0,0,0,0,0
0,0,0,0,0,0,7,0,0,0,0,0,0,0,7,0,0,0,0,0,0
0,0,0,0,0,2,2,2,2,0,7,0,2,2,2,2,0,0,0,0,0
0,0,0,0,2,2,1,2,2,2,2,2,2,2,1,2,2,0,0,0,0
0,0,0,9,2,1,3,1,0,2,2,2,0,1,3,1,2,11,0,0,0
0,0,0,0,2,2,1,2,2,2,2,2,2,2,1,2,2,0,0,0,0
0,0,0,0,0,2,2,2,2,0,8,0,2,2,2,2,0,0,0,0,0
0,0,0,0,0,0,8,0,0,0,0,0,0,0,8,0,0,0,0,0,0
0,0,0,0,0,0,0,0,0,0,0,0,0,0,0,0,0,0,0,0,0
0,0,0,0,0,0,0,0,0,0,0,0,0,0,0,0,0,0,0,0,0
0,0,0,0,0,0,0,0,0,0,0,0,0,0,0,0,0,0,0,0,0
:endlayer
layer: 7
0,0,0,0,0,0,0,0,0,0,0,0,0,0,0,0,0,0,0,0,0
0,0,0,0,0,0,0,0,0,0,0,0,0,0,0,0,0,0,0,0,0
0,0,0,0,0,0,0,0,0,0,0,0,0,0,0,0,0,0,0,0,0
0,0,0,0,0,0,0,0,0,0,0,0,0,0,0,0,0,0,0,0,0
0,0,0,0,0,0,2,0,0,0,0,0,0,0,2,0,0,0,0,0,0
0,0,0,0,0,2,3,2,2,0,0,0,2,2,3,2,0,0,0,0,0
0,0,0,0,0,0,2,0,0,0,0,0,0,0,2,0,0,0,0,0,0
0,0,0,0,0,0,0,0,0,0,0,0,0,0,0,0,0,0,0,0,0
0,0,0,0,0,0,0,0,0,0,0,0,0,0,0,0,0,0,0,0,0
0,0,0,0,0,0,0,0,0,0,0,0,0,0,0,0,0,0,0,0,0
0,0,0,0,0,0,0,0,0,0,0,0,0,0,0,0,0,0,0,0,0
0,0,0,0,0,0,0,0,0,0,0,0,0,0,0,0,0,0,0,0,0
:endlayer
layer: 8
0,0,0,0,0,0,0,0,0,0,0,0,0,0,0,0,0,0,0,0,0
0,0,0,0,0,0,0,0,0,0,0,0,0,0,0,0,0,0,0,0,0
0,0,0,0,0,0,0,0,0,0,0,0,0,0,0,0,0,0,0,0,0
0,0,0,0,0,0,0,0,0,0,0,0,0,0,0,0,0,0,0,0,0
0,0,0,0,0,0,0,0,0,0,0,0,0,0,0,0,0,0,0,0,0
0,0,0,0,0,0,2,0,0,0,0,0,0,0,2,0,0,0,0,0,0
0,0,0,0,0,0,0,0,0,0,0,0,0,0,0,0,0,0,0,0,0
0,0,0,0,0,0,0,0,0,0,0,0,0,0,0,0,0,0,0,0,0
0,0,0,0,0,0,0,0,0,0,0,0,0,0,0,0,0,0,0,0,0
0,0,0,0,0,0,0,0,0,0,0,0,0,0,0,0,0,0,0,0,0
0,0,0,0,0,0,0,0,0,0,0,0,0,0,0,0,0,0,0,0,0
0,0,0,0,0,0,0,0,0,0,0,0,0,0,0,0,0,0,0,0,0
:endlayer
layer: 9
0,0,0,0,0,0,0,0,0,0,0,0,0,0,0,0,0,0,0,0,0
0,0,0,0,0,0,0,0,0,0,0,0,0,0,0,0,0,0,0,0,0
0,0,0,0,0,0,0,0,0,0,0,0,0,0,0,0,0,0,0,0,0
0,0,0,0,0,0,0,0,0,0,0,0,0,0,0,0,0,0,0,0,0
0,0,0,0,0,0,0,0,0,0,0,0,0,0,0,0,0,0,0,0,0
0,0,0,0,0,0,1,0,0,0,0,0,0,0,1,0,0,0,0,0,0
0,0,0,0,0,0,0,0,0,0,0,0,0,0,0,0,0,0,0,0,0
0,0,0,0,0,0,0,0,0,0,0,0,0,0,0,0,0,0,0,0,0
0,0,0,0,0,0,0,0,0,0,0,0,0,0,0,0,0,0,0,0,0
0,0,0,0,0,0,0,0,0,0,0,0,0,0,0,0,0,0,0,0,0
0,0,0,0,0,0,0,0,0,0,0,0,0,0,0,0,0,0,0,0,0
0,0,0,0,0,0,0,0,0,0,0,0,0,0,0,0,0,0,0,0,0
:endlayer
layer: 10
0,0,0,0,0,0,0,0,0,0,0,0,0,0,0,0,0,0,0,0,0
0,0,0,0,0,0,0,0,0,0,0,0,0,0,0,0,0,0,0,0,0
0,0,0,0,0,0,0,0,0,0,0,0,0,0,0,0,0,0,0,0,0
0,0,0,0,0,0,0,0,0,0,0,0,0,0,0,0,0,0,0,0,0
0,0,0,0,0,0,0,0,0,0,0,0,0,0,0,0,0,0,0,0,0
0,0,0,0,0,0,1,0,0,0,0,0,0,0,1,0,0,0,0,0,0
0,0,0,0,0,0,0,0,0,0,0,0,0,0,0,0,0,0,0,0,0
0,0,0,0,0,0,0,0,0,0,0,0,0,0,0,0,0,0,0,0,0
0,0,0,0,0,0,0,0,0,0,0,0,0,0,0,0,0,0,0,0,0
0,0,0,0,0,0,0,0,0,0,0,0,0,0,0,0,0,0,0,0,0
0,0,0,0,0,0,0,0,0,0,0,0,0,0,0,0,0,0,0,0,0
0,0,0,0,0,0,0,0,0,0,0,0,0,0,0,0,0,0,0,0,0
:endlayer

#### RULES ####
rule:
plugin=vanillaBlocks
number=1
data:
JSON:{blockState:{blockName:"minecraft:spruce_fence",properties:{east:"false",south:"false",north:"false",west:"false"}}}
:enddata
:endrule

rule:
plugin=vanillaBlocks
number=2
data:
JSON:{blockState:{blockName:"minecraft:wool",properties:{color:"white"}}}
:enddata
:endrule

rule:
plugin=vanillaBlocks
number=3
data:
JSON:{blockState:{blockName:"minecraft:log",properties:{variant:"spruce",axis:"y"}}}
:enddata
:endrule

rule:
plugin=vanillaBlocks
number=4
data:
JSON:{blockState:{blockName:"minecraft:wool",properties:{color:"blue"}}}
:enddata
:endrule

rule:
plugin=vanillaBlocks
number=5
data:
JSON:{blockState:{blockName:"minecraft:wool",properties:{color:"cyan"}}}
:enddata
:endrule

rule:
plugin=vanillaBlocks
number=6
data:
JSON:{blockState:{blockName:"minecraft:wool",properties:{color:"light_blue"}}}
:enddata
:endrule

rule:
plugin=vanillaBlocks
number=7
data:
JSON:{blockState:{blockName:"minecraft:torch",properties:{facing:"north"}}}
:enddata
:endrule

rule:
plugin=vanillaBlocks
number=8
data:
JSON:{blockState:{blockName:"minecraft:torch",properties:{facing:"south"}}}
:enddata
:endrule

rule:
plugin=vanillaBlocks
number=9
data:
JSON:{blockState:{blockName:"minecraft:torch",properties:{facing:"west"}}}
:enddata
:endrule

rule:
plugin=vanillaBlocks
number=10
data:
JSON:{blockState:{blockName:"minecraft:wool",properties:{color:"orange"}}}
:enddata
:endrule

rule:
plugin=vanillaBlocks
number=11
data:
JSON:{blockState:{blockName:"minecraft:torch",properties:{facing:"east"}}}
:enddata
:endrule

rule:
plugin=vanillaBlocks
number=12
data:
JSON:{blockState:{blockName:"minecraft:wooden_slab",properties:{half:"bottom",variant:"spruce"}}}
:enddata
:endrule

rule:
plugin=vanillaBlocks
number=13
data:
JSON:{blockState:{blockName:"minecraft:wooden_slab",properties:{half:"top",variant:"spruce"}}}
:enddata
:endrule

#### ENTITIES ####
