# Ancient Warfare Structure Template File
# Auto-generated structure template file. created on: 3/19/2021 at: 18:0:25
# Lines beginning with # denote comments

header:
version=2.11
name=SurvivalBuild_SiegeCampTentL_BOPmagical
mods=biomesoplenty
size=21,11,12
offset=10,0,11
:endheader

#### VALIDATION ####
validation:
type=ground
structureAuthor=TheOddlySeagull
survival=true
worldGenEnabled=false
unique=false
preserveBlocks=false
preventNaturalHostileSpawns=false
selectionWeight=1
clusterValue=1
minDuplicateDistance=1
dimensionWhiteList=true
dimensionList=
biomeGroupList=
biomeWhiteList=true
biomeList=
leveling=0
fill=0
border=0
blockSwap=false
territoryName=
biomeReplacement=minecraft:
minGenerationHeight=0
maxGenerationHeight=255
:endvalidation

#### LAYERS ####
layer: 0
0,0,0,0,1,2,2,2,2,2,2,2,2,2,2,2,1,0,0,0,0
0,0,1,2,2,1,0,0,0,0,1,0,0,0,0,1,2,2,1,0,0
0,1,2,0,0,0,0,0,0,0,0,0,0,0,0,0,0,0,2,1,0
0,2,1,0,0,0,0,0,0,0,0,0,0,0,0,0,0,0,1,2,0
0,2,0,0,0,0,0,0,0,0,0,0,0,0,0,0,0,0,0,2,0
0,2,0,0,0,0,3,0,0,0,0,0,0,0,3,0,0,0,0,2,0
0,2,0,0,0,0,0,0,0,0,0,0,0,0,0,0,0,0,0,2,0
0,2,1,0,0,0,0,0,0,0,0,0,0,0,0,0,0,0,1,2,0
0,1,2,0,0,0,0,0,0,0,0,0,0,0,0,0,0,0,2,1,0
0,0,1,2,2,1,0,0,0,0,0,0,0,0,0,1,2,2,1,0,0
0,0,0,0,1,2,2,2,2,0,0,0,2,2,2,2,1,0,0,0,0
0,0,0,0,0,0,0,0,1,0,0,0,1,0,0,0,0,0,0,0,0
:endlayer
layer: 1
0,0,0,0,1,2,2,2,2,2,2,2,2,2,2,2,1,0,0,0,0
0,0,1,2,2,1,0,0,0,0,1,0,0,0,0,1,2,2,1,0,0
0,1,2,0,0,0,0,0,0,0,0,0,0,0,0,0,0,0,2,1,0
0,2,1,0,0,0,0,0,0,0,0,0,0,0,0,0,0,0,1,2,0
0,2,0,0,0,0,0,0,0,0,0,0,0,0,0,0,0,0,0,2,0
0,2,0,0,0,0,3,0,0,0,0,0,0,0,3,0,0,0,0,2,0
0,2,0,0,0,0,0,0,0,0,0,0,0,0,0,0,0,0,0,2,0
0,2,1,0,0,0,0,0,0,0,0,0,0,0,0,0,0,0,1,2,0
0,1,2,0,0,0,0,0,0,0,0,0,0,0,0,0,0,0,2,1,0
0,0,1,2,2,1,0,0,0,0,0,0,0,0,0,1,2,2,1,0,0
0,0,0,0,1,2,2,2,2,0,0,0,2,2,2,2,1,0,0,0,0
0,0,0,0,0,0,0,0,1,0,0,0,1,0,0,0,0,0,0,0,0
:endlayer
layer: 2
0,0,0,0,1,2,2,2,2,2,2,2,2,2,2,2,1,0,0,0,0
0,0,1,2,2,1,0,0,5,0,1,0,5,0,0,1,2,2,1,0,0
0,1,2,5,0,0,0,0,0,0,0,0,0,0,0,0,0,5,2,1,0
0,2,1,0,0,0,0,0,0,0,0,0,0,0,0,0,0,0,1,2,0
1,2,0,0,0,0,4,0,0,0,0,0,0,0,4,0,0,0,0,2,1
0,1,0,0,0,6,3,7,0,0,0,0,0,6,3,7,0,0,0,1,0
1,2,0,0,0,0,5,0,0,0,0,0,0,0,5,0,0,0,0,2,1
0,2,1,0,0,0,0,0,0,0,0,0,0,0,0,0,0,0,1,2,0
0,1,2,4,0,0,0,0,0,0,0,0,0,0,0,0,0,4,2,1,0
0,0,1,2,2,1,0,0,0,0,0,0,0,0,0,1,2,2,1,0,0
0,0,0,0,1,2,2,2,2,2,0,2,2,2,2,2,1,0,0,0,0
0,0,0,0,0,0,0,5,1,0,0,0,1,5,0,0,0,0,0,0,0
:endlayer
layer: 3
0,0,0,0,1,10,10,10,10,10,10,10,10,10,10,10,1,0,0,0,0
0,0,1,10,10,1,0,0,0,0,1,0,0,0,0,1,10,10,1,0,0
0,1,10,0,0,0,0,0,0,0,0,0,0,0,0,0,0,0,10,1,0
0,10,1,0,0,0,0,0,0,0,0,0,0,0,0,0,0,0,1,10,0
8,10,0,0,0,0,0,0,0,0,0,0,0,0,0,0,0,0,0,10,8
9,10,0,0,0,0,3,0,0,0,0,0,0,0,3,0,0,0,0,10,9
8,10,0,0,0,0,0,0,0,0,0,0,0,0,0,0,0,0,0,10,8
0,10,1,0,0,0,0,0,0,0,0,0,0,0,0,0,0,0,1,10,0
0,1,10,0,0,0,0,0,0,0,0,0,0,0,0,0,0,0,10,1,0
0,0,1,10,10,1,0,0,0,0,4,0,0,0,0,1,10,10,1,0,0
0,0,0,0,1,10,10,10,10,10,10,10,10,10,10,10,1,0,0,0,0
0,0,0,0,0,0,0,0,8,9,9,9,8,0,0,0,0,0,0,0,0
:endlayer
layer: 4
0,0,0,0,0,0,0,0,0,0,0,0,0,0,0,0,0,0,0,0,0
0,0,0,0,0,12,11,12,11,12,11,12,11,12,11,12,0,0,0,0,0
0,0,0,12,11,1,0,0,0,0,1,0,0,0,0,1,11,12,0,0,0
0,0,11,1,0,0,0,0,0,0,0,0,0,0,0,0,0,1,11,0,0
0,0,12,0,0,0,0,0,0,0,0,0,0,0,0,0,0,0,12,0,0
0,0,11,0,0,0,3,0,0,0,0,0,0,0,3,0,0,0,11,0,0
0,0,12,0,0,0,0,0,0,0,0,0,0,0,0,0,0,0,12,0,0
0,0,11,1,0,0,0,0,0,0,0,0,0,0,0,0,0,1,11,0,0
0,0,0,12,11,1,0,0,0,0,0,0,0,0,0,1,11,12,0,0,0
0,0,0,0,0,12,11,12,11,12,11,12,11,12,11,12,0,0,0,0,0
0,0,0,0,0,0,0,0,0,0,0,0,0,0,0,0,0,0,0,0,0
0,0,0,0,0,0,0,0,0,0,0,0,0,0,0,0,0,0,0,0,0
:endlayer
layer: 5
0,0,0,0,0,0,0,0,0,0,0,0,0,0,0,0,0,0,0,0,0
0,0,0,0,0,0,0,0,0,0,0,0,0,0,0,0,0,0,0,0,0
0,0,0,0,0,12,12,12,12,12,12,12,12,12,12,12,0,0,0,0,0
0,0,0,12,12,1,0,0,0,12,12,12,0,0,0,1,12,12,0,0,0
0,0,0,12,0,0,0,0,0,0,1,0,0,0,0,0,0,12,0,0,0
0,0,0,12,0,0,3,0,0,0,0,0,0,0,3,0,0,12,0,0,0
0,0,0,12,0,0,0,0,0,0,1,0,0,0,0,0,0,12,0,0,0
0,0,0,12,12,1,0,0,0,12,12,12,0,0,0,1,12,12,0,0,0
0,0,0,0,0,12,12,12,12,12,12,12,12,12,12,12,0,0,0,0,0
0,0,0,0,0,0,0,0,0,0,0,0,0,0,0,0,0,0,0,0,0
0,0,0,0,0,0,0,0,0,0,0,0,0,0,0,0,0,0,0,0,0
0,0,0,0,0,0,0,0,0,0,0,0,0,0,0,0,0,0,0,0,0
:endlayer
layer: 6
0,0,0,0,0,0,0,0,0,0,0,0,0,0,0,0,0,0,0,0,0
0,0,0,0,0,0,0,0,0,0,0,0,0,0,0,0,0,0,0,0,0
0,0,0,0,0,0,4,0,0,0,0,0,0,0,4,0,0,0,0,0,0
0,0,0,0,0,13,13,13,13,0,4,0,13,13,13,13,0,0,0,0,0
0,0,0,0,13,13,1,13,13,13,13,13,13,13,1,13,13,0,0,0,0
0,0,0,6,13,1,3,1,0,13,13,13,0,1,3,1,13,7,0,0,0
0,0,0,0,13,13,1,13,13,13,13,13,13,13,1,13,13,0,0,0,0
0,0,0,0,0,13,13,13,13,0,5,0,13,13,13,13,0,0,0,0,0
0,0,0,0,0,0,5,0,0,0,0,0,0,0,5,0,0,0,0,0,0
0,0,0,0,0,0,0,0,0,0,0,0,0,0,0,0,0,0,0,0,0
0,0,0,0,0,0,0,0,0,0,0,0,0,0,0,0,0,0,0,0,0
0,0,0,0,0,0,0,0,0,0,0,0,0,0,0,0,0,0,0,0,0
:endlayer
layer: 7
0,0,0,0,0,0,0,0,0,0,0,0,0,0,0,0,0,0,0,0,0
0,0,0,0,0,0,0,0,0,0,0,0,0,0,0,0,0,0,0,0,0
0,0,0,0,0,0,0,0,0,0,0,0,0,0,0,0,0,0,0,0,0
0,0,0,0,0,0,0,0,0,0,0,0,0,0,0,0,0,0,0,0,0
0,0,0,0,0,0,12,0,0,0,0,0,0,0,12,0,0,0,0,0,0
0,0,0,0,0,12,3,12,12,0,0,0,12,12,3,12,0,0,0,0,0
0,0,0,0,0,0,12,0,0,0,0,0,0,0,12,0,0,0,0,0,0
0,0,0,0,0,0,0,0,0,0,0,0,0,0,0,0,0,0,0,0,0
0,0,0,0,0,0,0,0,0,0,0,0,0,0,0,0,0,0,0,0,0
0,0,0,0,0,0,0,0,0,0,0,0,0,0,0,0,0,0,0,0,0
0,0,0,0,0,0,0,0,0,0,0,0,0,0,0,0,0,0,0,0,0
0,0,0,0,0,0,0,0,0,0,0,0,0,0,0,0,0,0,0,0,0
:endlayer
layer: 8
0,0,0,0,0,0,0,0,0,0,0,0,0,0,0,0,0,0,0,0,0
0,0,0,0,0,0,0,0,0,0,0,0,0,0,0,0,0,0,0,0,0
0,0,0,0,0,0,0,0,0,0,0,0,0,0,0,0,0,0,0,0,0
0,0,0,0,0,0,0,0,0,0,0,0,0,0,0,0,0,0,0,0,0
0,0,0,0,0,0,0,0,0,0,0,0,0,0,0,0,0,0,0,0,0
0,0,0,0,0,0,11,0,0,0,0,0,0,0,11,0,0,0,0,0,0
0,0,0,0,0,0,0,0,0,0,0,0,0,0,0,0,0,0,0,0,0
0,0,0,0,0,0,0,0,0,0,0,0,0,0,0,0,0,0,0,0,0
0,0,0,0,0,0,0,0,0,0,0,0,0,0,0,0,0,0,0,0,0
0,0,0,0,0,0,0,0,0,0,0,0,0,0,0,0,0,0,0,0,0
0,0,0,0,0,0,0,0,0,0,0,0,0,0,0,0,0,0,0,0,0
0,0,0,0,0,0,0,0,0,0,0,0,0,0,0,0,0,0,0,0,0
:endlayer
layer: 9
0,0,0,0,0,0,0,0,0,0,0,0,0,0,0,0,0,0,0,0,0
0,0,0,0,0,0,0,0,0,0,0,0,0,0,0,0,0,0,0,0,0
0,0,0,0,0,0,0,0,0,0,0,0,0,0,0,0,0,0,0,0,0
0,0,0,0,0,0,0,0,0,0,0,0,0,0,0,0,0,0,0,0,0
0,0,0,0,0,0,0,0,0,0,0,0,0,0,0,0,0,0,0,0,0
0,0,0,0,0,0,1,0,0,0,0,0,0,0,1,0,0,0,0,0,0
0,0,0,0,0,0,0,0,0,0,0,0,0,0,0,0,0,0,0,0,0
0,0,0,0,0,0,0,0,0,0,0,0,0,0,0,0,0,0,0,0,0
0,0,0,0,0,0,0,0,0,0,0,0,0,0,0,0,0,0,0,0,0
0,0,0,0,0,0,0,0,0,0,0,0,0,0,0,0,0,0,0,0,0
0,0,0,0,0,0,0,0,0,0,0,0,0,0,0,0,0,0,0,0,0
0,0,0,0,0,0,0,0,0,0,0,0,0,0,0,0,0,0,0,0,0
:endlayer
layer: 10
0,0,0,0,0,0,0,0,0,0,0,0,0,0,0,0,0,0,0,0,0
0,0,0,0,0,0,0,0,0,0,0,0,0,0,0,0,0,0,0,0,0
0,0,0,0,0,0,0,0,0,0,0,0,0,0,0,0,0,0,0,0,0
0,0,0,0,0,0,0,0,0,0,0,0,0,0,0,0,0,0,0,0,0
0,0,0,0,0,0,0,0,0,0,0,0,0,0,0,0,0,0,0,0,0
0,0,0,0,0,0,1,0,0,0,0,0,0,0,1,0,0,0,0,0,0
0,0,0,0,0,0,0,0,0,0,0,0,0,0,0,0,0,0,0,0,0
0,0,0,0,0,0,0,0,0,0,0,0,0,0,0,0,0,0,0,0,0
0,0,0,0,0,0,0,0,0,0,0,0,0,0,0,0,0,0,0,0,0
0,0,0,0,0,0,0,0,0,0,0,0,0,0,0,0,0,0,0,0,0
0,0,0,0,0,0,0,0,0,0,0,0,0,0,0,0,0,0,0,0,0
0,0,0,0,0,0,0,0,0,0,0,0,0,0,0,0,0,0,0,0,0
:endlayer

#### RULES ####
rule:
plugin=vanillaBlocks
number=1
data:
JSON:{blockState:{blockName:"biomesoplenty:magic_fence",properties:{east:"false",south:"false",north:"false",west:"false"}}}
:enddata
:endrule

rule:
plugin=vanillaBlocks
number=2
data:
JSON:{blockState:{blockName:"minecraft:wool",properties:{color:"silver"}}}
:enddata
:endrule

rule:
plugin=vanillaBlocks
number=3
data:
JSON:{blockState:{blockName:"biomesoplenty:log_1",properties:{variant:"magic",axis:"y"}}}
:enddata
:endrule

rule:
plugin=vanillaBlocks
number=4
data:
JSON:{blockState:{blockName:"minecraft:torch",properties:{facing:"north"}}}
:enddata
:endrule

rule:
plugin=vanillaBlocks
number=5
data:
JSON:{blockState:{blockName:"minecraft:torch",properties:{facing:"south"}}}
:enddata
:endrule

rule:
plugin=vanillaBlocks
number=6
data:
JSON:{blockState:{blockName:"minecraft:torch",properties:{facing:"west"}}}
:enddata
:endrule

rule:
plugin=vanillaBlocks
number=7
data:
JSON:{blockState:{blockName:"minecraft:torch",properties:{facing:"east"}}}
:enddata
:endrule

rule:
plugin=vanillaBlocks
number=8
data:
JSON:{blockState:{blockName:"biomesoplenty:wood_slab_0",properties:{half:"bottom",variant:"magic"}}}
:enddata
:endrule

rule:
plugin=vanillaBlocks
number=9
data:
JSON:{blockState:{blockName:"biomesoplenty:wood_slab_0",properties:{half:"top",variant:"magic"}}}
:enddata
:endrule

rule:
plugin=vanillaBlocks
number=10
data:
JSON:{blockState:{blockName:"minecraft:wool",properties:{color:"blue"}}}
:enddata
:endrule

rule:
plugin=vanillaBlocks
number=11
data:
JSON:{blockState:{blockName:"minecraft:wool",properties:{color:"red"}}}
:enddata
:endrule

rule:
plugin=vanillaBlocks
number=12
data:
JSON:{blockState:{blockName:"minecraft:wool",properties:{color:"white"}}}
:enddata
:endrule

rule:
plugin=vanillaBlocks
number=13
data:
JSON:{blockState:{blockName:"minecraft:wool",properties:{color:"light_blue"}}}
:enddata
:endrule

#### ENTITIES ####
