# Ancient Warfare Structure Template File
# Auto-generated structure template file. created on: 3/19/2021 at: 17:53:11
# Lines beginning with # denote comments

header:
version=2.11
name=SurvivalBuild_SiegeCampTentL_darkoak
mods=
size=21,11,12
offset=10,0,11
:endheader

#### VALIDATION ####
validation:
type=ground
structureAuthor=TheOddlySeagull
survival=true
worldGenEnabled=false
unique=false
preserveBlocks=false
preventNaturalHostileSpawns=false
selectionWeight=1
clusterValue=1
minDuplicateDistance=1
dimensionWhiteList=true
dimensionList=
biomeGroupList=
biomeWhiteList=true
biomeList=
leveling=0
fill=0
border=0
blockSwap=false
territoryName=
biomeReplacement=minecraft:
minGenerationHeight=0
maxGenerationHeight=255
:endvalidation

#### LAYERS ####
layer: 0
0,0,0,0,1,2,2,2,2,2,2,2,2,2,2,2,1,0,0,0,0
0,0,1,2,2,1,0,0,0,0,1,0,0,0,0,1,2,2,1,0,0
0,1,2,0,0,0,0,0,0,0,0,0,0,0,0,0,0,0,2,1,0
0,2,1,0,0,0,0,0,0,0,0,0,0,0,0,0,0,0,1,2,0
0,2,0,0,0,0,0,0,0,0,0,0,0,0,0,0,0,0,0,2,0
0,2,0,0,0,0,3,0,0,0,0,0,0,0,3,0,0,0,0,2,0
0,2,0,0,0,0,0,0,0,0,0,0,0,0,0,0,0,0,0,2,0
0,2,1,0,0,0,0,0,0,0,0,0,0,0,0,0,0,0,1,2,0
0,1,2,0,0,0,0,0,0,0,0,0,0,0,0,0,0,0,2,1,0
0,0,1,2,2,1,0,0,0,0,0,0,0,0,0,1,2,2,1,0,0
0,0,0,0,1,2,2,2,2,0,0,0,2,2,2,2,1,0,0,0,0
0,0,0,0,0,0,0,0,1,0,0,0,1,0,0,0,0,0,0,0,0
:endlayer
layer: 1
0,0,0,0,1,4,4,4,4,4,4,4,4,4,4,4,1,0,0,0,0
0,0,1,4,4,1,0,0,0,0,1,0,0,0,0,1,4,4,1,0,0
0,1,4,0,0,0,0,0,0,0,0,0,0,0,0,0,0,0,4,1,0
0,4,1,0,0,0,0,0,0,0,0,0,0,0,0,0,0,0,1,4,0
0,4,0,0,0,0,0,0,0,0,0,0,0,0,0,0,0,0,0,4,0
0,4,0,0,0,0,3,0,0,0,0,0,0,0,3,0,0,0,0,4,0
0,4,0,0,0,0,0,0,0,0,0,0,0,0,0,0,0,0,0,4,0
0,4,1,0,0,0,0,0,0,0,0,0,0,0,0,0,0,0,1,4,0
0,1,4,0,0,0,0,0,0,0,0,0,0,0,0,0,0,0,4,1,0
0,0,1,4,4,1,0,0,0,0,0,0,0,0,0,1,4,4,1,0,0
0,0,0,0,1,4,4,4,4,0,0,0,4,4,4,4,1,0,0,0,0
0,0,0,0,0,0,0,0,1,0,0,0,1,0,0,0,0,0,0,0,0
:endlayer
layer: 2
0,0,0,0,1,2,4,2,4,2,4,2,4,2,4,2,1,0,0,0,0
0,0,1,2,4,1,0,0,6,0,1,0,6,0,0,1,4,2,1,0,0
0,1,4,0,0,0,0,0,0,0,0,0,0,0,0,0,0,0,4,1,0
0,2,1,0,0,0,0,0,0,0,0,0,0,0,0,0,0,0,1,2,0
1,4,0,0,0,0,7,0,0,0,0,0,0,0,7,0,0,0,0,4,1
0,1,0,0,0,5,3,8,0,0,0,0,0,5,3,8,0,0,0,1,0
1,4,0,0,0,0,6,0,0,0,0,0,0,0,6,0,0,0,0,4,1
0,2,1,0,0,0,0,0,0,0,0,0,0,0,0,0,0,0,1,2,0
0,1,4,0,0,0,0,0,0,0,0,0,0,0,0,0,0,0,4,1,0
0,0,1,2,4,1,0,0,0,0,0,0,0,0,0,1,4,2,1,0,0
0,0,0,0,1,2,4,2,4,2,0,2,4,2,4,2,1,0,0,0,0
0,0,0,0,0,0,0,0,1,0,0,0,1,0,0,0,0,0,0,0,0
:endlayer
layer: 3
0,0,0,0,1,11,2,11,2,11,2,11,2,11,2,11,1,0,0,0,0
0,0,1,11,2,1,0,0,0,0,1,0,0,0,0,1,2,11,1,0,0
0,1,2,0,0,0,0,0,0,0,0,0,0,0,0,0,0,0,2,1,0
0,11,1,0,0,0,0,0,0,0,0,0,0,0,0,0,0,0,1,11,0
9,2,0,0,0,0,0,0,0,0,0,0,0,0,0,0,0,0,0,2,9
10,11,0,0,0,0,3,0,0,0,0,0,0,0,3,0,0,0,0,11,10
9,2,0,0,0,0,0,0,0,0,0,0,0,0,0,0,0,0,0,2,9
0,11,1,0,0,0,0,0,0,0,0,0,0,0,0,0,0,0,1,11,0
0,1,2,0,0,0,0,0,0,0,0,0,0,0,0,0,0,0,2,1,0
0,0,1,11,2,1,0,0,0,0,0,0,0,0,0,1,2,11,1,0,0
0,0,0,0,1,11,2,11,2,11,2,11,2,11,2,11,1,0,0,0,0
0,0,0,0,0,0,0,0,9,10,10,10,9,0,0,0,0,0,0,0,0
:endlayer
layer: 4
0,0,0,0,0,0,0,0,0,0,0,0,0,0,0,0,0,0,0,0,0
0,0,0,0,0,2,4,2,4,2,4,2,4,2,4,2,0,0,0,0,0
0,0,0,2,4,1,0,0,0,0,1,0,0,0,0,1,4,2,0,0,0
0,0,2,1,0,0,0,0,0,0,0,0,0,0,0,0,0,1,2,0,0
0,0,4,0,0,0,0,0,0,0,0,0,0,0,0,0,0,0,4,0,0
0,0,2,0,0,0,3,0,0,0,0,0,0,0,3,0,0,0,2,0,0
0,0,4,0,0,0,0,0,0,0,0,0,0,0,0,0,0,0,4,0,0
0,0,2,1,0,0,0,0,0,0,0,0,0,0,0,0,0,1,2,0,0
0,0,0,2,4,1,0,0,0,0,0,0,0,0,0,1,4,2,0,0,0
0,0,0,0,0,2,4,2,4,2,4,2,4,2,4,2,0,0,0,0,0
0,0,0,0,0,0,0,0,0,0,0,0,0,0,0,0,0,0,0,0,0
0,0,0,0,0,0,0,0,0,0,0,0,0,0,0,0,0,0,0,0,0
:endlayer
layer: 5
0,0,0,0,0,0,0,0,0,0,0,0,0,0,0,0,0,0,0,0,0
0,0,0,0,0,0,0,0,0,0,0,0,0,0,0,0,0,0,0,0,0
0,0,0,0,0,2,4,2,4,2,4,2,4,2,4,2,0,0,0,0,0
0,0,0,2,4,1,0,0,0,2,4,2,0,0,0,1,4,2,0,0,0
0,0,0,4,0,0,0,0,0,0,1,0,0,0,0,0,0,4,0,0,0
0,0,0,2,0,0,3,0,0,0,0,0,0,0,3,0,0,2,0,0,0
0,0,0,4,0,0,0,0,0,0,1,0,0,0,0,0,0,4,0,0,0
0,0,0,2,4,1,0,0,0,2,4,2,0,0,0,1,4,2,0,0,0
0,0,0,0,0,2,4,2,4,2,4,2,4,2,4,2,0,0,0,0,0
0,0,0,0,0,0,0,0,0,0,0,0,0,0,0,0,0,0,0,0,0
0,0,0,0,0,0,0,0,0,0,0,0,0,0,0,0,0,0,0,0,0
0,0,0,0,0,0,0,0,0,0,0,0,0,0,0,0,0,0,0,0,0
:endlayer
layer: 6
0,0,0,0,0,0,0,0,0,0,0,0,0,0,0,0,0,0,0,0,0
0,0,0,0,0,0,0,0,0,0,0,0,0,0,0,0,0,0,0,0,0
0,0,0,0,0,0,7,0,0,0,0,0,0,0,7,0,0,0,0,0,0
0,0,0,0,0,2,4,2,4,0,7,0,4,2,4,2,0,0,0,0,0
0,0,0,0,4,2,1,2,4,2,4,2,4,2,1,2,4,0,0,0,0
0,0,0,0,2,1,3,1,0,2,2,2,0,1,3,1,2,0,0,0,0
0,0,0,0,4,2,1,2,4,2,4,2,4,2,1,2,4,0,0,0,0
0,0,0,0,0,2,4,2,4,0,6,0,4,2,4,2,0,0,0,0,0
0,0,0,0,0,0,6,0,0,0,0,0,0,0,6,0,0,0,0,0,0
0,0,0,0,0,0,0,0,0,0,0,0,0,0,0,0,0,0,0,0,0
0,0,0,0,0,0,0,0,0,0,0,0,0,0,0,0,0,0,0,0,0
0,0,0,0,0,0,0,0,0,0,0,0,0,0,0,0,0,0,0,0,0
:endlayer
layer: 7
0,0,0,0,0,0,0,0,0,0,0,0,0,0,0,0,0,0,0,0,0
0,0,0,0,0,0,0,0,0,0,0,0,0,0,0,0,0,0,0,0,0
0,0,0,0,0,0,0,0,0,0,0,0,0,0,0,0,0,0,0,0,0
0,0,0,0,0,0,0,0,0,0,0,0,0,0,0,0,0,0,0,0,0
0,0,0,0,0,0,2,0,0,0,0,0,0,0,2,0,0,0,0,0,0
0,0,0,0,0,2,3,2,2,0,0,0,2,2,3,2,0,0,0,0,0
0,0,0,0,0,0,2,0,0,0,0,0,0,0,2,0,0,0,0,0,0
0,0,0,0,0,0,0,0,0,0,0,0,0,0,0,0,0,0,0,0,0
0,0,0,0,0,0,0,0,0,0,0,0,0,0,0,0,0,0,0,0,0
0,0,0,0,0,0,0,0,0,0,0,0,0,0,0,0,0,0,0,0,0
0,0,0,0,0,0,0,0,0,0,0,0,0,0,0,0,0,0,0,0,0
0,0,0,0,0,0,0,0,0,0,0,0,0,0,0,0,0,0,0,0,0
:endlayer
layer: 8
0,0,0,0,0,0,0,0,0,0,0,0,0,0,0,0,0,0,0,0,0
0,0,0,0,0,0,0,0,0,0,0,0,0,0,0,0,0,0,0,0,0
0,0,0,0,0,0,0,0,0,0,0,0,0,0,0,0,0,0,0,0,0
0,0,0,0,0,0,0,0,0,0,0,0,0,0,0,0,0,0,0,0,0
0,0,0,0,0,0,0,0,0,0,0,0,0,0,0,0,0,0,0,0,0
0,0,0,0,0,0,2,0,0,0,0,0,0,0,2,0,0,0,0,0,0
0,0,0,0,0,0,0,0,0,0,0,0,0,0,0,0,0,0,0,0,0
0,0,0,0,0,0,0,0,0,0,0,0,0,0,0,0,0,0,0,0,0
0,0,0,0,0,0,0,0,0,0,0,0,0,0,0,0,0,0,0,0,0
0,0,0,0,0,0,0,0,0,0,0,0,0,0,0,0,0,0,0,0,0
0,0,0,0,0,0,0,0,0,0,0,0,0,0,0,0,0,0,0,0,0
0,0,0,0,0,0,0,0,0,0,0,0,0,0,0,0,0,0,0,0,0
:endlayer
layer: 9
0,0,0,0,0,0,0,0,0,0,0,0,0,0,0,0,0,0,0,0,0
0,0,0,0,0,0,0,0,0,0,0,0,0,0,0,0,0,0,0,0,0
0,0,0,0,0,0,0,0,0,0,0,0,0,0,0,0,0,0,0,0,0
0,0,0,0,0,0,0,0,0,0,0,0,0,0,0,0,0,0,0,0,0
0,0,0,0,0,0,0,0,0,0,0,0,0,0,0,0,0,0,0,0,0
0,0,0,0,0,0,1,0,0,0,0,0,0,0,1,0,0,0,0,0,0
0,0,0,0,0,0,0,0,0,0,0,0,0,0,0,0,0,0,0,0,0
0,0,0,0,0,0,0,0,0,0,0,0,0,0,0,0,0,0,0,0,0
0,0,0,0,0,0,0,0,0,0,0,0,0,0,0,0,0,0,0,0,0
0,0,0,0,0,0,0,0,0,0,0,0,0,0,0,0,0,0,0,0,0
0,0,0,0,0,0,0,0,0,0,0,0,0,0,0,0,0,0,0,0,0
0,0,0,0,0,0,0,0,0,0,0,0,0,0,0,0,0,0,0,0,0
:endlayer
layer: 10
0,0,0,0,0,0,0,0,0,0,0,0,0,0,0,0,0,0,0,0,0
0,0,0,0,0,0,0,0,0,0,0,0,0,0,0,0,0,0,0,0,0
0,0,0,0,0,0,0,0,0,0,0,0,0,0,0,0,0,0,0,0,0
0,0,0,0,0,0,0,0,0,0,0,0,0,0,0,0,0,0,0,0,0
0,0,0,0,0,0,0,0,0,0,0,0,0,0,0,0,0,0,0,0,0
0,0,0,0,0,0,1,0,0,0,0,0,0,0,1,0,0,0,0,0,0
0,0,0,0,0,0,0,0,0,0,0,0,0,0,0,0,0,0,0,0,0
0,0,0,0,0,0,0,0,0,0,0,0,0,0,0,0,0,0,0,0,0
0,0,0,0,0,0,0,0,0,0,0,0,0,0,0,0,0,0,0,0,0
0,0,0,0,0,0,0,0,0,0,0,0,0,0,0,0,0,0,0,0,0
0,0,0,0,0,0,0,0,0,0,0,0,0,0,0,0,0,0,0,0,0
0,0,0,0,0,0,0,0,0,0,0,0,0,0,0,0,0,0,0,0,0
:endlayer

#### RULES ####
rule:
plugin=vanillaBlocks
number=1
data:
JSON:{blockState:{blockName:"minecraft:dark_oak_fence",properties:{east:"false",south:"false",north:"false",west:"false"}}}
:enddata
:endrule

rule:
plugin=vanillaBlocks
number=2
data:
JSON:{blockState:{blockName:"minecraft:wool",properties:{color:"cyan"}}}
:enddata
:endrule

rule:
plugin=vanillaBlocks
number=3
data:
JSON:{blockState:{blockName:"minecraft:log2",properties:{variant:"dark_oak",axis:"y"}}}
:enddata
:endrule

rule:
plugin=vanillaBlocks
number=4
data:
JSON:{blockState:{blockName:"minecraft:wool",properties:{color:"white"}}}
:enddata
:endrule

rule:
plugin=vanillaBlocks
number=5
data:
JSON:{blockState:{blockName:"minecraft:torch",properties:{facing:"west"}}}
:enddata
:endrule

rule:
plugin=vanillaBlocks
number=6
data:
JSON:{blockState:{blockName:"minecraft:torch",properties:{facing:"south"}}}
:enddata
:endrule

rule:
plugin=vanillaBlocks
number=7
data:
JSON:{blockState:{blockName:"minecraft:torch",properties:{facing:"north"}}}
:enddata
:endrule

rule:
plugin=vanillaBlocks
number=8
data:
JSON:{blockState:{blockName:"minecraft:torch",properties:{facing:"east"}}}
:enddata
:endrule

rule:
plugin=vanillaBlocks
number=9
data:
JSON:{blockState:{blockName:"minecraft:wooden_slab",properties:{half:"bottom",variant:"dark_oak"}}}
:enddata
:endrule

rule:
plugin=vanillaBlocks
number=10
data:
JSON:{blockState:{blockName:"minecraft:wooden_slab",properties:{half:"top",variant:"dark_oak"}}}
:enddata
:endrule

rule:
plugin=vanillaBlocks
number=11
data:
JSON:{blockState:{blockName:"minecraft:wool",properties:{color:"light_blue"}}}
:enddata
:endrule

#### ENTITIES ####
