# Ancient Warfare Structure Template File
# Auto-generated structure template file. created on: 3/11/2021 at: 10:58:38
# Lines beginning with # denote comments

header:
version=2.11
name=SurvivalBuild_SiegeFort_BOPredwood
mods=biomesoplenty
size=45,15,25
offset=21,0,24
:endheader

#### VALIDATION ####
validation:
type=ground
structureAuthor=TheOddlySeagull
survival=true
worldGenEnabled=false
unique=false
preserveBlocks=false
preventNaturalHostileSpawns=false
selectionWeight=1
clusterValue=1
minDuplicateDistance=1
dimensionWhiteList=true
dimensionList=
biomeGroupList=
biomeWhiteList=true
biomeList=
leveling=0
fill=0
border=0
blockSwap=false
territoryName=
biomeReplacement=minecraft:
minGenerationHeight=0
maxGenerationHeight=255
:endvalidation

#### LAYERS ####
layer: 0
0,0,0,0,0,0,0,0,0,0,0,0,0,0,0,0,0,0,0,0,0,0,0,0,0,0,0,0,0,0,0,0,0,0,0,0,0,0,0,0,0,0,0,0,0
0,1,2,2,1,0,0,0,0,0,0,0,0,0,1,2,2,1,0,0,0,0,0,0,0,0,0,1,2,2,1,0,0,0,0,0,0,0,0,0,1,2,2,1,0
0,3,4,4,3,4,1,4,1,4,1,4,1,4,3,4,4,3,4,1,4,1,4,1,4,1,4,3,4,4,3,4,1,4,1,4,1,4,1,4,3,4,4,3,0
0,3,4,4,3,5,0,0,0,0,0,0,0,6,3,4,4,3,5,0,0,0,0,0,0,0,6,3,4,4,3,5,0,0,0,0,0,0,0,0,3,4,4,3,0
0,1,2,2,1,5,0,0,0,0,0,0,0,6,1,2,2,1,5,0,0,1,0,1,0,0,6,1,2,2,1,5,0,0,0,0,0,0,0,0,1,2,2,1,0
0,0,4,7,7,7,0,0,0,0,0,0,0,0,0,0,0,0,0,0,0,4,0,4,0,0,0,0,0,0,0,0,0,0,0,0,0,0,0,0,0,0,4,0,0
0,0,1,0,0,0,0,0,0,0,0,0,0,0,0,0,0,0,0,0,0,4,0,4,0,0,0,0,0,0,0,0,0,0,0,0,0,0,0,0,0,0,1,0,0
0,0,4,0,0,0,0,0,0,0,0,0,0,0,0,0,0,0,0,0,8,4,4,4,9,0,0,0,0,0,0,0,0,0,0,0,0,0,0,0,0,0,4,0,0
0,0,1,0,0,0,0,0,10,0,0,0,0,0,0,0,0,0,0,0,0,7,7,7,0,0,0,0,0,0,0,0,0,0,0,0,0,0,0,0,0,0,1,0,0
0,0,4,0,0,0,0,0,0,0,0,0,0,0,0,0,0,0,0,0,0,0,0,0,0,0,0,0,0,0,0,0,0,0,0,0,10,0,0,0,0,0,4,0,0
0,0,1,0,0,0,0,0,0,0,0,0,0,0,10,0,0,0,0,0,0,0,0,0,0,0,0,0,0,0,10,0,0,0,0,0,0,0,0,0,0,0,1,0,0
0,0,4,11,11,0,0,0,0,0,0,0,0,0,0,0,0,0,0,0,0,0,0,0,0,0,0,0,0,0,0,0,0,0,0,0,0,0,0,0,11,11,4,0,0
0,0,1,12,12,0,0,0,0,0,0,0,0,0,0,0,0,0,0,0,0,0,0,0,0,0,0,0,0,0,0,0,0,0,0,0,0,0,0,0,12,12,1,0,0
0,0,4,0,0,0,0,0,0,0,0,0,0,0,0,0,0,0,0,0,0,10,0,0,0,6,11,11,5,0,0,0,0,0,0,0,0,0,0,0,0,0,4,0,0
0,0,1,0,0,0,0,0,0,0,10,0,0,0,0,0,0,0,0,0,0,0,0,1,2,2,2,2,2,2,2,2,2,2,1,0,0,0,0,0,0,0,1,0,0
0,0,4,0,0,0,0,0,0,0,0,0,0,0,0,0,0,0,0,0,0,0,0,3,4,4,4,4,4,4,4,4,4,4,3,0,0,0,0,0,0,0,4,0,0
0,0,1,0,0,1,0,0,0,0,0,0,0,0,0,0,0,0,0,0,0,0,0,3,4,4,4,4,4,4,4,4,4,4,3,0,0,0,0,1,0,0,1,0,0
0,0,4,0,0,0,0,0,0,0,0,0,0,0,0,0,0,11,11,11,0,0,0,3,4,4,4,4,4,4,4,4,4,4,3,0,0,0,0,0,0,0,4,0,0
0,0,1,0,0,0,0,0,0,0,0,0,0,6,4,1,4,1,4,1,0,0,0,1,4,4,4,4,4,4,4,4,4,4,3,0,0,0,0,0,0,0,1,0,0
0,0,4,11,11,5,0,0,0,0,0,0,0,6,4,4,4,4,4,4,0,0,0,4,4,4,4,4,4,4,4,4,4,4,3,0,0,0,0,6,11,11,4,0,0
0,1,2,2,1,5,0,0,0,0,0,0,0,6,1,2,2,1,4,4,0,0,0,4,4,1,2,2,2,2,2,2,2,2,1,0,0,0,0,6,1,2,2,1,0
0,3,4,4,3,5,0,0,0,0,0,0,0,6,3,4,4,3,4,4,0,0,0,4,4,3,4,4,3,4,4,4,4,4,4,0,0,0,0,6,3,4,4,3,0
0,3,4,4,3,4,1,4,1,4,1,4,1,4,3,4,4,3,4,1,0,0,0,1,4,3,4,4,3,4,1,4,1,4,1,4,1,4,1,4,3,4,4,3,0
0,1,2,2,1,0,0,0,0,0,0,0,0,0,1,2,2,1,0,0,0,0,0,0,0,1,2,2,1,0,0,0,0,0,0,0,0,0,0,0,1,2,2,1,0
0,0,0,0,0,0,0,0,0,0,0,0,0,0,0,0,0,0,0,0,0,0,0,0,0,0,0,0,0,0,0,0,0,0,0,0,0,0,0,0,0,0,0,0,0
:endlayer
layer: 1
0,0,0,0,0,0,0,0,0,0,0,0,0,0,0,0,0,0,0,0,0,0,0,0,0,0,0,0,0,0,0,0,0,0,0,0,0,0,0,0,0,0,0,0,0
0,1,4,11,1,0,0,0,0,0,0,0,0,0,1,4,11,1,0,0,0,0,0,0,0,0,0,1,11,4,1,0,0,0,0,0,0,0,0,0,1,11,4,1,0
0,4,0,0,4,4,1,4,1,4,1,4,1,4,4,0,0,4,4,1,4,1,4,1,4,1,4,4,0,0,4,4,1,4,1,4,1,4,1,4,4,0,0,4,0
0,6,0,0,0,0,0,0,0,0,0,0,0,0,0,0,0,0,0,0,0,0,0,0,0,0,0,0,0,0,0,0,0,0,0,0,0,0,0,0,0,0,0,5,0
0,1,4,0,1,0,0,0,0,0,0,0,0,0,1,4,4,1,0,0,0,1,0,1,0,0,0,1,4,4,1,0,0,0,0,0,0,0,0,0,1,0,4,1,0
0,0,4,0,0,0,0,0,0,0,0,0,0,0,0,0,0,0,0,0,0,3,0,3,0,0,0,0,0,0,0,0,0,0,0,0,0,0,0,0,0,0,4,0,0
0,0,1,0,0,0,0,0,0,0,0,0,0,0,0,0,0,0,0,0,0,3,13,3,0,0,0,0,0,0,0,0,0,0,0,0,0,0,0,0,0,0,1,0,0
0,0,4,0,0,0,0,0,0,0,0,0,0,0,0,0,0,0,0,0,0,7,7,7,0,0,0,0,0,0,0,0,0,0,0,0,0,0,0,0,0,0,4,0,0
0,0,1,0,0,0,0,0,0,0,0,0,0,0,0,0,0,0,0,0,0,0,0,0,0,0,0,0,0,0,0,0,0,0,0,0,0,0,0,0,0,0,1,0,0
0,0,4,0,0,0,0,0,0,0,0,0,0,0,0,0,0,0,0,0,0,0,0,0,0,0,0,0,0,0,0,0,0,0,0,0,0,0,0,0,0,0,4,0,0
0,0,1,0,0,0,0,0,0,0,0,0,0,0,0,0,0,0,0,0,0,0,0,0,0,0,0,0,0,0,0,0,0,0,0,0,0,0,0,0,0,0,1,0,0
0,0,4,0,0,0,0,0,0,0,0,0,0,0,0,0,0,0,0,0,0,0,0,0,0,0,0,0,0,0,0,0,0,0,0,0,0,0,0,0,0,0,4,0,0
0,0,1,11,11,0,0,0,0,0,0,0,0,0,0,0,0,0,0,0,0,0,0,0,0,0,0,0,0,0,0,0,0,0,0,0,0,0,0,0,11,11,1,0,0
0,0,4,12,12,0,0,0,0,0,0,0,0,0,0,0,0,0,0,0,0,0,0,0,0,0,0,0,0,0,0,0,0,0,0,0,0,0,0,0,12,12,4,0,0
0,0,1,0,0,0,0,0,0,0,0,0,0,0,0,0,0,0,0,0,0,0,0,1,4,1,0,0,1,4,1,4,1,4,1,0,0,0,0,0,0,0,1,0,0
0,0,4,0,0,0,0,0,0,0,0,0,0,0,0,0,0,0,0,0,0,0,0,4,0,0,0,0,0,14,5,0,0,0,4,0,0,0,0,0,0,0,4,0,0
0,0,1,0,0,1,0,0,0,0,0,0,0,0,0,0,0,0,0,0,0,0,0,1,0,0,0,0,0,14,5,0,0,0,1,0,0,0,0,1,0,0,1,0,0
0,0,4,0,0,0,0,0,0,0,0,0,0,0,0,15,0,0,0,0,0,0,0,4,0,0,0,0,0,0,0,0,0,0,4,0,0,0,0,0,0,0,4,0,0
0,0,1,0,0,0,0,0,0,0,0,0,0,0,6,1,4,1,0,1,0,0,0,1,0,0,0,0,0,0,0,0,0,0,1,0,0,0,0,0,0,0,1,0,0
0,0,4,0,0,0,0,0,0,0,0,0,0,0,6,4,0,0,0,4,0,0,0,4,0,0,0,0,0,0,0,0,0,0,4,0,0,0,0,0,0,0,4,0,0
0,1,4,0,1,0,0,0,0,0,0,0,0,0,1,4,4,1,0,5,0,0,0,6,0,1,4,4,1,4,1,4,1,4,1,0,0,0,0,0,1,0,4,1,0
0,6,0,0,0,0,0,0,0,0,0,0,0,0,0,0,0,0,0,4,0,0,0,4,0,0,0,0,4,4,4,4,4,4,4,0,0,0,0,0,0,0,0,5,0
0,4,0,0,4,4,1,4,1,4,1,4,1,4,4,0,0,4,4,1,0,0,0,1,4,4,0,0,4,4,1,4,1,4,1,4,1,4,1,4,4,0,0,4,0
0,1,4,7,1,0,0,0,0,0,0,0,0,0,1,4,7,1,0,0,0,0,0,0,0,1,7,4,1,0,0,0,0,0,0,0,0,0,0,0,1,7,4,1,0
0,0,0,0,0,0,0,0,0,0,0,0,0,0,0,0,0,0,0,0,0,0,0,0,0,0,0,0,0,0,0,0,0,0,0,0,0,0,0,0,0,0,0,0,0
:endlayer
layer: 2
0,0,0,0,0,0,0,0,0,0,0,0,0,0,0,0,0,0,0,0,0,0,0,0,0,0,0,0,0,0,0,0,0,0,0,0,0,0,0,0,0,0,0,0,0
0,1,4,0,1,0,0,0,0,0,0,0,0,0,1,4,0,1,0,0,0,0,0,0,0,0,0,1,0,4,1,0,0,0,0,0,0,0,0,0,1,0,4,1,0
0,4,0,0,4,4,1,4,1,4,1,4,1,4,4,0,0,4,4,1,4,1,4,1,4,1,4,4,0,0,4,4,1,4,1,4,1,4,1,4,4,0,0,4,0
0,0,0,0,0,0,0,0,0,0,0,0,0,0,0,0,0,0,0,0,0,4,0,4,0,0,0,0,0,0,0,0,0,0,0,0,0,0,0,0,0,0,0,0,0
0,1,4,0,1,0,0,0,0,0,0,0,0,0,1,4,4,1,0,0,0,1,0,1,0,0,0,1,4,4,1,0,0,0,0,0,0,0,0,0,1,0,4,1,0
0,0,4,0,0,0,0,0,0,0,0,0,0,0,0,0,0,0,0,0,0,4,13,4,0,0,0,0,0,0,0,0,0,0,0,0,0,0,0,0,0,0,4,0,0
0,0,1,0,0,0,0,0,0,0,0,0,0,0,0,0,0,0,0,0,0,7,7,7,0,0,0,0,0,0,0,0,0,0,0,0,0,0,0,0,0,0,1,0,0
0,0,4,0,0,0,0,0,0,0,0,0,0,0,0,0,0,0,0,0,0,0,0,0,0,0,0,0,0,0,0,0,0,0,0,0,0,0,0,0,0,0,4,0,0
0,0,1,0,0,0,0,0,0,0,0,0,0,0,0,0,0,0,0,0,0,0,0,0,0,0,0,0,0,0,0,0,0,0,0,0,0,0,0,0,0,0,1,0,0
0,0,4,0,0,0,0,0,0,0,0,0,0,0,0,0,0,0,0,0,0,0,0,0,0,0,0,0,0,0,0,0,0,0,0,0,0,0,0,0,0,0,4,0,0
0,0,1,0,0,0,0,0,0,0,0,0,0,0,0,0,0,0,0,0,0,0,0,0,0,0,0,0,0,0,0,0,0,0,0,0,0,0,0,0,0,0,1,0,0
0,0,4,0,0,0,0,0,0,0,0,0,0,0,0,0,0,0,0,0,0,0,0,0,0,0,0,0,0,0,0,0,0,0,0,0,0,0,0,0,0,0,4,0,0
0,0,1,0,0,0,0,0,0,0,0,0,0,0,0,0,0,0,0,0,0,0,0,0,0,0,0,0,0,0,0,0,0,0,0,0,0,0,0,0,0,0,1,0,0
0,0,4,11,11,0,0,0,0,0,0,0,0,0,0,0,0,0,0,0,0,0,0,0,0,0,0,0,0,0,0,0,0,0,0,0,0,0,0,0,11,11,4,0,0
0,0,1,12,12,0,0,0,0,0,0,0,0,0,0,0,0,0,0,0,0,0,0,1,4,1,0,0,1,4,1,4,1,4,1,0,0,0,0,0,12,12,1,0,0
0,0,4,0,0,0,0,0,0,0,0,0,0,0,0,0,0,0,0,0,0,0,0,4,0,0,0,0,14,5,0,0,0,0,4,0,0,0,0,0,0,0,4,0,0
0,0,1,0,0,1,0,0,0,0,0,0,0,0,0,0,0,0,0,0,0,0,0,1,0,0,0,0,14,5,0,0,0,0,1,0,0,0,0,1,0,0,1,0,0
0,0,4,0,0,0,0,0,0,0,0,0,0,0,0,0,0,0,0,0,0,0,0,4,0,0,0,0,0,0,0,0,0,0,4,0,0,0,0,0,0,0,4,0,0
0,0,1,0,0,0,0,0,0,0,0,0,0,0,0,6,4,1,0,1,9,0,8,1,0,0,0,0,0,0,0,0,0,0,1,0,0,0,0,0,0,0,1,0,0
0,0,4,0,0,0,0,0,0,0,0,0,0,0,0,6,16,0,0,4,0,0,0,4,0,0,0,0,0,0,0,0,0,0,4,0,0,0,0,0,0,0,4,0,0
0,1,4,0,1,0,0,0,0,0,0,0,0,0,1,4,4,1,0,0,0,0,0,0,0,1,4,4,1,4,1,4,1,4,1,0,0,0,0,0,1,0,4,1,0
0,0,0,0,0,0,0,0,0,0,0,0,0,0,0,0,0,0,0,4,0,0,0,4,0,0,0,0,4,4,4,4,4,4,4,0,0,0,0,0,0,0,0,0,0
0,4,0,0,4,4,1,4,1,4,1,4,1,4,4,0,0,4,4,1,9,0,8,1,4,4,0,0,4,4,1,4,1,4,1,4,1,4,1,4,4,0,0,4,0
0,1,4,0,1,0,0,0,0,0,0,0,0,0,1,4,0,1,0,17,0,0,0,17,0,1,0,4,1,0,0,0,0,0,0,0,0,0,0,0,1,0,4,1,0
0,0,0,0,0,0,0,0,0,0,0,0,0,0,0,0,0,0,0,0,0,0,0,0,0,0,0,0,0,0,0,0,0,0,0,0,0,0,0,0,0,0,0,0,0
:endlayer
layer: 3
0,0,0,0,0,0,0,0,0,0,0,0,0,0,0,0,0,0,0,0,0,0,0,0,0,0,0,0,0,0,0,0,0,0,0,0,0,0,0,0,0,0,0,0,0
0,1,4,13,1,0,0,0,0,0,0,0,0,0,1,4,13,1,0,0,0,0,0,0,0,0,0,1,13,4,1,0,0,0,0,0,0,0,0,0,1,13,4,1,0
0,4,0,0,4,4,1,4,1,4,1,4,1,4,4,0,0,4,4,1,4,1,4,1,4,1,4,4,0,0,4,4,1,4,1,4,1,4,1,4,4,0,0,4,0
0,14,0,15,4,0,0,0,0,17,0,0,0,0,4,0,15,4,0,0,14,4,17,4,16,0,0,4,0,15,4,0,0,0,17,0,0,0,0,0,4,15,0,16,0
0,1,4,4,1,9,0,0,0,0,0,0,0,0,1,4,4,1,0,0,8,1,13,1,9,0,0,1,4,4,1,0,0,0,0,0,0,0,0,8,1,4,4,1,0
0,0,4,0,17,0,0,0,0,0,0,0,0,0,17,0,0,17,0,0,0,7,7,7,0,0,0,17,0,0,17,0,0,0,0,0,0,0,0,0,17,0,4,0,0
0,0,1,0,0,0,0,0,0,0,0,0,0,0,0,0,0,0,0,0,0,0,0,0,0,0,0,0,0,0,0,0,0,0,0,0,0,0,0,0,0,0,1,0,0
0,0,4,0,0,0,0,0,0,0,0,0,0,0,0,0,0,0,0,0,0,0,0,0,0,0,0,0,0,0,0,0,0,0,0,0,0,0,0,0,0,0,4,0,0
0,0,1,9,0,0,0,0,0,0,0,0,0,0,0,0,0,0,0,0,0,0,0,0,0,0,0,0,0,0,0,0,0,0,0,0,0,0,0,0,0,8,1,0,0
0,0,4,0,0,0,0,0,0,0,0,0,0,0,0,0,0,0,0,0,0,0,0,0,0,0,0,0,0,0,0,0,0,0,0,0,0,0,0,0,0,0,4,0,0
0,0,1,0,0,0,0,0,0,0,0,0,0,0,0,0,0,0,0,0,0,0,0,0,0,0,0,0,0,0,0,0,0,0,0,0,0,0,0,0,0,0,1,0,0
0,0,4,0,0,0,0,0,0,0,0,0,0,0,0,0,0,0,0,0,0,0,0,0,0,0,0,0,0,0,0,0,0,0,0,0,0,0,0,0,0,0,4,0,0
0,0,1,0,0,0,0,0,0,0,0,0,0,0,0,0,0,0,0,0,0,0,0,0,0,0,0,0,0,0,0,0,0,0,0,0,0,0,0,0,0,0,1,0,0
0,0,4,0,0,0,0,0,0,0,0,0,0,0,0,0,0,0,0,0,0,0,0,0,0,15,0,0,15,0,0,0,0,0,15,0,0,0,0,0,0,0,4,0,0
0,0,1,11,11,0,0,0,0,0,0,0,0,0,0,0,0,0,0,0,0,0,0,1,4,1,4,4,1,4,1,4,1,4,1,9,0,0,0,0,11,11,1,0,0
0,0,4,12,12,15,0,0,0,0,0,0,0,0,0,0,0,0,0,0,0,0,0,4,0,0,0,14,5,0,0,0,17,0,4,0,0,0,0,15,12,12,4,0,0
0,0,1,0,0,1,9,0,0,0,0,0,0,0,0,0,0,0,0,0,0,0,0,1,9,0,0,14,5,0,0,0,0,0,1,0,0,0,8,1,0,0,1,0,0
0,0,4,0,0,0,0,0,0,0,0,0,0,0,0,0,0,0,0,15,0,0,0,4,0,0,0,0,0,0,0,0,0,0,4,0,0,0,0,0,0,0,4,0,0
0,0,1,0,0,0,0,0,0,0,0,0,0,0,0,0,6,1,4,1,16,0,14,1,0,0,0,0,0,0,0,0,0,8,1,0,0,0,0,0,0,0,1,0,0
0,0,4,0,15,0,0,0,0,0,0,0,0,0,15,0,6,16,0,4,0,0,0,4,0,0,0,0,15,0,0,0,0,0,4,9,0,0,0,0,15,0,4,0,0
0,1,4,4,1,9,0,0,0,0,0,0,0,8,1,4,4,1,0,16,0,0,0,14,0,1,4,4,1,4,1,4,1,4,1,0,0,0,0,8,1,4,4,1,0
0,14,0,8,4,0,0,0,0,15,0,0,0,0,4,0,0,15,0,4,0,0,0,4,15,4,0,0,4,4,4,4,4,4,4,0,0,0,0,0,4,17,0,16,0
0,4,0,0,4,4,1,4,1,4,1,4,1,4,4,0,0,4,4,1,16,0,14,1,4,4,0,0,4,4,1,4,1,4,1,4,1,4,1,4,4,0,0,4,0
0,1,4,12,1,0,0,0,0,0,0,0,0,0,1,4,12,1,0,0,0,0,0,0,0,1,12,4,1,0,0,0,0,0,0,0,0,0,0,0,1,12,4,1,0
0,0,0,0,0,0,0,0,0,0,0,0,0,0,0,0,0,0,0,0,0,0,0,0,0,0,0,0,0,0,0,0,0,0,0,0,0,0,0,0,0,0,0,0,0
:endlayer
layer: 4
0,0,0,0,0,0,0,0,0,0,0,0,0,0,0,0,0,0,0,0,0,0,0,0,0,0,0,0,0,0,0,0,0,0,0,0,0,0,0,0,0,0,0,0,0
0,1,2,2,1,0,13,0,13,0,13,0,13,0,1,2,2,1,0,13,0,13,0,13,0,13,0,1,2,2,1,0,13,0,13,0,13,0,13,0,1,2,2,1,0
0,3,18,18,3,2,2,2,2,2,2,2,2,2,3,18,18,3,2,2,2,2,2,2,2,2,2,3,18,18,3,2,2,2,2,2,2,2,2,2,3,18,18,3,0
0,3,18,18,3,18,12,18,12,18,12,18,12,18,3,18,18,3,18,14,4,3,4,3,4,16,18,3,18,18,3,18,12,18,12,18,12,18,12,18,3,18,18,3,0
0,1,2,2,1,0,0,0,0,0,0,0,0,0,1,2,2,1,0,0,18,7,7,7,18,0,0,1,2,2,1,0,0,0,0,0,0,0,0,0,1,2,2,1,0
0,0,3,18,0,0,0,0,0,0,0,0,0,0,0,0,0,0,0,0,0,0,0,0,0,0,0,0,0,0,0,0,0,0,0,0,0,0,0,0,0,18,3,0,0
0,14,3,16,0,0,0,0,0,0,0,0,0,0,0,0,0,0,0,0,0,0,0,0,0,0,0,0,0,0,0,0,0,0,0,0,0,0,0,0,0,14,3,16,0
0,0,3,18,0,0,0,0,0,0,0,0,0,0,0,0,0,0,0,0,0,0,0,0,0,0,0,0,0,0,0,0,0,0,0,0,0,0,0,0,0,18,3,0,0
0,14,3,16,0,0,0,0,0,0,0,0,0,0,0,0,0,0,0,0,0,0,0,0,0,0,0,0,0,0,0,0,0,0,0,0,0,0,0,0,0,14,3,16,0
0,0,3,18,0,0,0,0,0,0,0,0,0,0,0,0,0,0,0,0,0,0,0,0,0,0,0,0,0,0,0,0,0,0,0,0,0,0,0,0,0,18,3,0,0
0,14,3,16,0,0,0,0,0,0,0,0,0,0,0,0,0,0,0,0,0,0,0,0,0,0,0,0,0,0,0,0,0,0,0,0,0,0,0,0,0,14,3,16,0
0,0,3,18,0,0,0,0,0,0,0,0,0,0,0,0,0,0,0,0,0,0,0,0,0,0,0,0,0,0,0,0,0,0,0,0,0,0,0,0,0,18,3,0,0
0,14,3,0,0,0,0,0,0,0,0,0,0,0,0,0,0,0,0,0,0,0,0,0,0,0,0,0,0,0,0,0,0,0,0,0,0,0,0,0,0,0,3,16,0
0,0,3,0,0,0,0,0,0,0,0,0,0,0,0,0,0,0,0,0,0,0,14,13,13,0,0,0,0,0,0,0,0,0,0,0,0,0,0,0,0,0,3,0,0
0,14,3,0,0,0,0,0,0,0,0,0,0,0,0,0,0,0,0,0,0,0,14,4,2,2,2,2,2,2,2,2,2,2,1,0,0,0,0,0,0,0,3,16,0
0,0,3,11,11,0,0,0,0,0,0,0,0,0,0,0,0,0,0,0,0,0,14,3,18,3,14,5,0,0,0,14,3,18,3,0,0,0,0,0,11,11,3,0,0
0,14,3,2,2,1,0,0,0,0,0,0,0,0,0,0,0,0,0,0,0,0,18,3,18,3,14,5,0,0,0,14,3,18,3,0,0,0,0,1,2,2,3,16,0
0,0,3,18,18,3,0,0,0,0,0,0,0,0,0,0,0,0,18,13,18,18,18,3,18,3,2,2,2,2,2,2,2,2,3,0,0,0,0,3,18,18,3,0,0
0,14,3,18,18,3,0,0,0,0,0,0,0,0,0,0,0,6,2,2,2,2,2,3,18,3,18,18,3,18,18,3,18,18,3,0,0,0,0,3,18,18,3,16,0
0,0,3,18,18,3,0,0,0,0,0,0,0,0,0,0,0,6,4,3,4,4,4,3,18,3,18,18,3,18,18,3,18,18,3,0,0,0,0,3,18,18,3,0,0
0,1,2,2,1,3,0,0,0,0,0,0,0,0,1,2,2,1,2,2,2,2,2,3,2,1,2,2,1,2,2,2,2,2,3,0,0,0,0,3,1,2,2,1,0
0,3,18,18,3,3,13,18,13,18,13,18,13,18,3,18,18,3,18,3,4,4,4,3,18,3,18,18,3,4,4,4,4,4,3,18,13,18,13,3,3,18,18,3,0
0,3,18,18,3,2,2,2,2,2,2,2,2,2,3,18,18,3,2,2,2,2,2,2,2,3,18,18,3,2,2,2,2,2,2,2,2,2,2,2,3,18,18,3,0
0,1,2,2,1,0,12,0,12,0,12,0,12,0,1,2,2,1,0,12,0,18,0,12,0,1,2,2,1,0,12,0,12,0,12,0,12,0,12,0,1,2,2,1,0
0,0,0,0,0,0,0,0,0,0,0,0,0,0,0,0,0,0,0,0,0,0,0,0,0,0,0,0,0,0,0,0,0,0,0,0,0,0,0,0,0,0,0,0,0
:endlayer
layer: 5
0,0,0,0,0,0,0,0,0,0,0,0,0,0,0,0,0,0,0,0,0,0,0,0,0,0,0,0,0,0,0,0,0,0,0,0,0,0,0,0,0,0,0,0,0
0,1,11,11,1,2,2,2,2,2,2,2,2,2,1,11,11,1,2,2,2,2,2,2,2,2,2,1,11,11,1,2,2,2,2,2,2,2,2,2,1,11,11,1,0
0,6,0,0,0,0,0,0,0,0,0,0,0,0,0,0,0,0,0,0,0,0,0,0,0,0,0,0,0,0,0,0,0,0,0,0,0,0,0,0,0,0,0,5,0
0,6,0,0,4,0,0,0,0,0,0,0,0,0,4,0,0,4,0,0,0,0,0,0,0,0,0,4,0,0,4,0,0,0,0,0,0,0,0,0,4,0,0,5,0
0,1,0,4,1,0,0,0,0,0,0,0,0,0,1,4,4,1,0,0,0,0,0,0,0,0,0,1,4,4,1,0,0,0,0,0,0,0,0,0,1,4,0,1,0
0,3,0,0,0,0,0,0,0,0,0,0,0,0,0,0,0,0,0,0,0,0,0,0,0,0,0,0,0,0,0,0,0,0,0,0,0,0,0,0,0,0,0,3,0
0,3,0,0,0,0,0,0,0,0,0,0,0,0,0,0,0,0,0,0,0,0,0,0,0,0,0,0,0,0,0,0,0,0,0,0,0,0,0,0,0,0,0,3,0
0,3,0,0,0,0,0,0,0,0,0,0,0,0,0,0,0,0,0,0,0,0,0,0,0,0,0,0,0,0,0,0,0,0,0,0,0,0,0,0,0,0,0,3,0
0,3,0,0,0,0,0,0,0,0,0,0,0,0,0,0,0,0,0,0,0,0,0,0,0,0,0,0,0,0,0,0,0,0,0,0,0,0,0,0,0,0,0,3,0
0,3,0,0,0,0,0,0,0,0,0,0,0,0,0,0,0,0,0,0,0,0,0,0,0,0,0,0,0,0,0,0,0,0,0,0,0,0,0,0,0,0,0,3,0
0,3,0,0,0,0,0,0,0,0,0,0,0,0,0,0,0,0,0,0,0,0,0,0,0,0,0,0,0,0,0,0,0,0,0,0,0,0,0,0,0,0,0,3,0
0,3,0,0,0,0,0,0,0,0,0,0,0,0,0,0,0,0,0,0,0,0,0,0,0,0,0,0,0,0,0,0,0,0,0,0,0,0,0,0,0,0,0,3,0
0,3,0,0,0,0,0,0,0,0,0,0,0,0,0,0,0,0,0,0,0,0,0,0,0,0,0,0,0,0,0,0,0,0,0,0,0,0,0,0,0,0,0,3,0
0,3,0,0,0,0,0,0,0,0,0,0,0,0,0,0,0,0,0,0,0,0,19,19,19,0,0,0,0,0,0,0,0,0,0,0,0,0,0,0,0,0,0,3,0
0,3,0,0,0,0,0,0,0,0,0,0,0,0,0,0,0,0,0,0,0,0,19,0,0,1,11,11,1,4,4,1,4,4,1,0,0,0,0,0,0,0,0,3,0
0,3,0,0,0,0,0,0,0,0,0,0,0,0,0,0,0,0,0,0,0,0,19,0,0,4,0,0,0,0,14,5,0,0,5,0,0,0,0,0,0,0,0,3,0
0,3,0,0,0,1,0,0,0,0,0,0,0,0,0,0,0,0,0,0,0,0,0,0,0,1,0,0,0,0,14,5,0,0,5,0,0,0,0,1,0,0,0,3,0
0,3,0,0,0,19,0,0,0,0,0,0,0,0,0,0,0,0,0,0,0,0,0,0,0,0,0,0,0,0,0,0,0,0,1,0,0,0,0,19,0,0,0,3,0
0,3,0,0,0,5,0,0,0,0,0,0,0,0,0,0,0,0,0,0,0,0,0,0,0,1,0,0,0,0,0,0,0,0,5,0,0,0,0,6,0,0,0,3,0
0,3,0,0,0,19,0,0,0,0,0,0,0,0,0,0,0,0,0,0,0,0,0,0,0,4,0,0,0,0,0,0,0,0,5,0,0,0,0,19,0,0,0,3,0
0,1,0,4,1,5,0,0,0,0,0,0,0,0,1,11,11,1,4,1,0,0,0,1,4,1,0,0,1,4,1,0,1,4,1,0,0,0,0,6,1,4,0,1,0
0,6,0,0,4,0,0,0,0,0,0,0,0,0,0,0,0,0,0,0,0,0,0,0,0,0,0,0,0,0,0,0,0,0,0,0,0,0,0,0,4,0,0,5,0
0,6,0,0,0,0,0,0,0,0,0,0,0,0,4,0,0,4,0,0,0,0,0,0,0,4,0,0,4,0,0,0,0,0,0,0,0,0,0,0,0,0,0,5,0
0,1,7,7,1,2,2,2,2,2,2,2,2,2,1,7,7,1,2,2,2,2,2,2,2,1,7,7,1,2,2,2,2,2,2,2,2,2,2,2,1,7,7,1,0
0,0,0,0,0,0,0,0,0,0,0,0,0,0,0,0,0,0,0,0,0,0,0,0,0,0,0,0,0,0,0,0,0,0,0,0,0,0,0,0,0,0,0,0,0
:endlayer
layer: 6
0,0,0,0,0,0,0,0,0,0,0,0,0,0,0,0,0,0,0,0,0,0,0,0,0,0,0,0,0,0,0,0,0,0,0,0,0,0,0,0,0,0,0,0,0
0,1,0,0,1,0,11,0,11,0,11,0,11,0,1,0,0,1,0,11,0,11,0,11,0,11,0,1,0,0,1,0,11,0,11,0,11,0,11,0,1,0,0,1,0
0,0,0,0,0,0,0,0,0,0,17,0,0,0,0,0,0,0,0,0,0,0,0,17,0,0,0,0,0,0,0,0,0,0,17,0,0,0,0,0,0,0,0,0,0
0,0,0,0,4,0,0,0,0,0,0,0,0,0,4,0,0,4,0,0,0,0,0,0,0,0,0,4,0,0,4,0,0,0,0,0,0,0,0,0,4,0,0,0,0
0,1,0,4,1,0,0,0,0,0,0,0,0,0,1,4,4,1,0,0,0,0,0,0,0,0,0,1,4,4,1,0,0,0,0,0,0,0,0,0,1,4,0,1,0
0,0,0,0,0,0,0,0,0,0,0,0,0,0,0,0,0,0,0,0,0,0,0,0,0,0,0,0,0,0,0,0,0,0,0,0,0,0,0,0,0,0,0,0,0
0,6,0,0,0,0,0,0,0,0,0,0,0,0,0,0,0,0,0,0,0,0,0,0,0,0,0,0,0,0,0,0,0,0,0,0,0,0,0,0,0,0,0,5,0
0,0,0,0,0,0,0,0,0,0,0,0,0,0,0,0,0,0,0,0,0,0,0,0,0,0,0,0,0,0,0,0,0,0,0,0,0,0,0,0,0,0,0,0,0
0,6,0,0,0,0,0,0,0,0,0,0,0,0,0,0,0,0,0,0,0,0,0,0,0,0,0,0,0,0,0,0,0,0,0,0,0,0,0,0,0,0,0,5,0
0,0,0,0,0,0,0,0,0,0,0,0,0,0,0,0,0,0,0,0,0,0,0,0,0,0,0,0,0,0,0,0,0,0,0,0,0,0,0,0,0,0,0,0,0
0,6,0,0,0,0,0,0,0,0,0,0,0,0,0,0,0,0,0,0,0,0,0,0,0,0,0,0,0,0,0,0,0,0,0,0,0,0,0,0,0,0,0,5,0
0,0,0,0,0,0,0,0,0,0,0,0,0,0,0,0,0,0,0,0,0,0,0,0,0,0,0,0,0,0,0,0,0,0,0,0,0,0,0,0,0,0,0,0,0
0,6,9,0,0,0,0,0,0,0,0,0,0,0,0,0,0,0,0,0,0,0,0,0,0,0,0,0,0,0,0,0,0,0,0,0,0,0,0,0,0,0,8,5,0
0,0,0,0,0,0,0,0,0,0,0,0,0,0,0,0,0,0,0,0,0,0,0,0,0,0,0,0,0,0,0,0,0,0,0,0,0,0,0,0,0,0,0,0,0
0,6,0,0,0,0,0,0,0,0,0,0,0,0,0,0,0,0,0,0,0,0,0,0,0,1,0,0,1,4,4,1,4,4,1,0,0,0,0,0,0,0,0,5,0
0,0,0,0,0,0,0,0,0,0,0,0,0,0,0,0,0,0,0,0,0,0,0,0,0,4,0,0,0,14,5,0,0,0,0,0,0,0,0,0,0,0,0,0,0
0,6,0,0,0,19,0,0,0,0,0,0,0,0,0,0,0,0,0,0,0,0,0,0,0,1,0,0,0,14,5,0,0,0,0,0,0,0,0,19,0,0,0,5,0
0,0,0,0,0,0,0,0,0,0,0,0,0,0,0,0,0,0,0,0,0,0,0,0,0,0,0,0,0,0,0,0,0,0,1,0,0,0,0,0,0,0,0,0,0
0,6,0,0,0,0,0,0,0,0,0,0,0,0,0,0,0,0,0,0,0,0,0,0,0,1,0,0,0,0,0,0,0,0,0,0,0,0,0,0,0,0,0,5,0
0,0,0,0,0,0,0,0,0,0,0,0,0,0,0,0,0,0,0,0,0,0,0,0,0,4,0,0,0,0,0,0,0,0,0,0,0,0,0,0,0,0,0,0,0
0,1,0,4,1,0,0,0,0,0,0,0,0,0,1,0,0,1,4,1,0,0,0,1,4,1,0,0,1,4,1,0,1,4,1,0,0,0,0,0,1,4,0,1,0
0,0,0,0,4,0,0,0,0,0,0,0,0,0,0,0,0,0,0,0,0,0,0,0,0,0,0,0,0,0,0,0,0,0,0,0,0,0,0,0,4,0,0,0,0
0,0,0,0,0,0,0,0,0,0,0,0,0,0,4,0,0,4,0,0,0,0,0,0,0,4,0,0,4,0,0,0,0,0,15,0,0,0,0,0,0,0,0,0,0
0,1,0,0,1,0,7,0,7,0,7,0,7,0,1,0,0,1,0,7,0,7,0,7,0,1,0,0,1,0,7,0,7,0,7,0,7,0,7,0,1,0,0,1,0
0,0,0,0,0,0,0,0,0,0,0,0,0,0,0,0,0,0,0,0,0,0,0,0,0,0,0,0,0,0,0,0,0,0,0,0,0,0,0,0,0,0,0,0,0
:endlayer
layer: 7
0,20,0,0,20,0,0,0,0,0,0,0,0,0,20,0,0,20,0,0,0,0,0,0,0,0,0,20,0,0,20,0,0,0,0,0,0,0,0,0,20,0,0,20,0
20,1,13,13,1,20,0,0,0,0,0,0,0,20,1,13,13,1,20,0,0,0,0,0,0,0,20,1,13,13,1,20,0,0,0,0,0,0,0,20,1,13,13,1,20
0,4,0,0,4,0,0,0,0,0,0,0,0,0,4,0,0,4,0,0,0,0,0,0,0,0,0,4,0,0,4,0,0,0,0,0,0,0,0,0,4,0,0,16,0
0,4,0,0,4,9,0,0,0,0,0,0,0,8,4,0,0,4,9,0,0,0,0,0,0,0,8,4,0,0,4,9,0,0,0,0,0,0,0,8,4,0,0,16,0
20,1,4,4,1,20,0,0,0,0,0,0,0,20,1,4,4,1,20,0,0,0,0,0,0,0,20,1,4,4,1,20,0,0,0,0,0,0,0,20,1,4,4,1,20
0,20,0,17,20,0,0,0,0,0,0,0,0,0,20,0,0,20,0,0,0,0,0,0,0,0,0,20,0,0,20,0,0,0,0,0,0,0,0,0,20,17,0,20,0
0,0,0,0,0,0,0,0,0,0,0,0,0,0,0,0,0,0,0,0,0,0,0,0,0,0,0,0,0,0,0,0,0,0,0,0,0,0,0,0,0,0,0,0,0
0,0,0,0,0,0,0,0,0,0,0,0,0,0,0,0,0,0,0,0,0,0,0,0,0,0,0,0,0,0,0,0,0,0,0,0,0,0,0,0,0,0,0,0,0
0,0,0,0,0,0,0,0,0,0,0,0,0,0,0,0,0,0,0,0,0,0,0,0,0,0,0,0,0,0,0,0,0,0,0,0,0,0,0,0,0,0,0,0,0
0,0,0,0,0,0,0,0,0,0,0,0,0,0,0,0,0,0,0,0,0,0,0,0,0,0,0,0,0,0,0,0,0,0,0,0,0,0,0,0,0,0,0,0,0
0,0,0,0,0,0,0,0,0,0,0,0,0,0,0,0,0,0,0,0,0,0,0,0,0,0,0,0,0,0,0,0,0,0,0,0,0,0,0,0,0,0,0,0,0
0,0,0,0,0,0,0,0,0,0,0,0,0,0,0,0,0,0,0,0,0,0,0,0,0,0,0,0,0,0,0,0,0,0,0,0,0,0,0,0,0,0,0,0,0
0,0,0,0,0,0,0,0,0,0,0,0,0,0,0,0,0,0,0,0,0,0,0,0,0,0,0,0,0,0,0,0,0,0,0,0,0,0,0,0,0,0,0,0,0
0,0,0,0,0,0,0,0,0,0,0,0,0,0,0,0,0,0,0,0,0,0,0,0,0,0,0,0,0,0,0,0,0,0,0,0,0,0,0,0,0,0,0,0,0
0,0,0,0,0,0,0,0,0,0,0,0,0,0,0,0,0,0,0,0,0,0,0,0,0,1,13,13,1,4,4,1,4,4,1,0,0,0,0,0,0,0,0,0,0
0,0,0,0,0,0,0,0,0,0,0,0,0,0,0,0,0,0,0,0,0,0,0,0,8,4,0,0,14,5,0,0,0,0,16,0,0,0,0,0,0,0,0,0,0
0,0,0,0,0,0,0,0,0,0,0,0,0,0,0,0,0,0,0,0,0,0,0,0,0,1,9,0,14,5,0,0,0,0,16,0,0,0,0,0,0,0,0,0,0
0,0,0,0,0,0,0,0,0,0,0,0,0,0,0,0,0,0,0,0,0,0,0,0,0,4,0,0,0,0,0,0,0,8,1,0,0,0,0,0,0,0,0,0,0
0,0,0,0,0,0,0,0,0,0,0,0,0,0,0,0,0,0,0,0,0,0,0,0,0,1,0,0,0,0,0,0,0,0,16,0,0,0,0,0,0,0,0,0,0
0,20,0,15,20,0,0,0,0,0,0,0,0,0,20,0,0,20,0,15,0,0,0,15,0,4,0,0,0,0,15,0,0,0,16,0,0,0,0,0,20,15,0,20,0
20,1,4,4,1,20,0,0,0,0,0,0,0,20,1,13,13,1,4,1,16,0,14,1,4,1,16,14,1,4,1,4,1,4,1,0,0,0,0,20,1,4,4,1,20
0,14,0,0,4,9,0,0,0,0,0,0,0,0,4,0,0,4,0,17,0,0,0,17,0,4,0,0,4,0,0,0,0,0,0,0,0,0,0,8,4,0,0,16,0
0,14,0,0,4,0,0,0,0,0,0,0,0,8,4,0,0,4,0,0,0,0,0,0,0,4,9,0,4,0,0,0,0,0,0,0,0,0,0,0,4,0,0,16,0
20,1,12,12,1,20,0,0,0,0,0,0,0,20,1,12,12,1,20,0,0,0,0,0,0,1,12,12,1,0,0,0,0,0,0,0,0,0,0,20,1,12,12,1,20
0,20,0,0,20,0,0,0,0,0,0,0,0,0,20,0,0,20,0,0,0,0,0,0,0,0,0,0,0,0,0,0,0,0,0,0,0,0,0,0,20,0,0,20,0
:endlayer
layer: 8
11,11,11,11,11,5,0,0,0,0,0,0,0,11,11,11,11,11,5,0,0,0,0,0,0,0,11,11,11,11,11,5,0,0,0,0,0,0,0,11,11,11,11,11,5
6,1,2,2,1,5,0,0,0,0,0,0,0,6,1,2,2,1,5,0,0,0,0,0,0,0,6,1,2,2,1,5,0,0,0,0,0,0,0,6,1,2,2,1,5
6,3,0,0,3,5,0,0,0,0,0,0,0,6,3,0,0,3,5,0,0,0,0,0,0,0,6,3,0,0,3,5,0,0,0,0,0,0,0,6,3,0,0,3,5
6,3,0,0,3,5,0,0,0,0,0,0,0,6,3,0,0,3,5,0,0,0,0,0,0,0,6,3,0,0,3,5,0,0,0,0,0,0,0,6,3,0,0,3,5
6,1,2,2,1,5,0,0,0,0,0,0,0,6,1,2,2,1,5,0,0,0,0,0,0,0,6,1,2,2,1,5,0,0,0,0,0,0,0,6,1,2,2,1,5
7,7,7,7,7,7,0,0,0,0,0,0,0,7,7,7,7,7,7,0,0,0,0,0,0,0,7,7,7,7,7,7,0,0,0,0,0,0,0,7,7,7,7,7,7
0,0,0,0,0,0,0,0,0,0,0,0,0,0,0,0,0,0,0,0,0,0,0,0,0,0,0,0,0,0,0,0,0,0,0,0,0,0,0,0,0,0,0,0,0
0,0,0,0,0,0,0,0,0,0,0,0,0,0,0,0,0,0,0,0,0,0,0,0,0,0,0,0,0,0,0,0,0,0,0,0,0,0,0,0,0,0,0,0,0
0,0,0,0,0,0,0,0,0,0,0,0,0,0,0,0,0,0,0,0,0,0,0,0,0,0,0,0,0,0,0,0,0,0,0,0,0,0,0,0,0,0,0,0,0
0,0,0,0,0,0,0,0,0,0,0,0,0,0,0,0,0,0,0,0,0,0,0,0,0,0,0,0,0,0,0,0,0,0,0,0,0,0,0,0,0,0,0,0,0
0,0,0,0,0,0,0,0,0,0,0,0,0,0,0,0,0,0,0,0,0,0,0,0,0,0,0,0,0,0,0,0,0,0,0,0,0,0,0,0,0,0,0,0,0
0,0,0,0,0,0,0,0,0,0,0,0,0,0,0,0,0,0,0,0,0,0,0,0,0,0,0,0,0,0,0,0,0,0,0,0,0,0,0,0,0,0,0,0,0
0,0,0,0,0,0,0,0,0,0,0,0,0,0,0,0,0,0,0,0,0,0,0,0,0,0,0,0,0,0,0,0,0,0,0,0,0,0,0,0,0,0,0,0,0
0,0,0,0,0,0,0,0,0,0,0,0,0,0,0,0,0,0,0,0,0,0,0,0,14,13,13,0,0,0,0,0,0,13,13,16,0,0,0,0,0,0,0,0,0
0,0,0,0,0,0,0,0,0,0,0,0,0,0,0,0,0,0,0,0,0,0,0,0,14,4,2,2,2,2,2,2,2,2,4,16,0,0,0,0,0,0,0,0,0
0,0,0,0,0,0,0,0,0,0,0,0,0,0,0,0,0,0,0,0,0,0,0,0,14,3,18,3,5,0,0,0,3,18,3,16,0,0,0,0,0,0,0,0,0
0,0,0,0,0,0,0,0,0,0,0,0,0,0,0,0,0,0,0,0,0,0,0,0,0,3,18,3,5,0,0,0,3,18,3,0,0,0,0,0,0,0,0,0,0
0,0,0,0,0,0,0,0,0,0,0,0,0,0,0,0,0,0,0,0,0,0,0,0,0,3,2,2,2,2,2,2,2,2,3,0,0,0,0,0,0,0,0,0,0
0,0,0,0,0,0,0,0,0,0,0,0,0,0,0,0,0,0,0,0,0,0,0,0,0,3,18,18,3,18,18,3,18,18,3,0,0,0,0,0,0,0,0,0,0
6,11,11,11,11,5,0,0,0,0,0,0,0,11,11,11,11,11,5,0,0,0,0,0,0,3,18,18,3,18,18,3,18,18,3,16,0,0,0,6,11,11,11,11,5
6,1,2,2,1,5,0,0,0,0,0,0,0,6,1,2,2,1,2,2,2,2,2,2,2,1,2,2,1,2,2,2,2,2,4,16,0,0,0,6,1,2,2,1,5
6,3,17,0,3,5,0,0,0,0,0,0,0,6,3,0,0,3,5,0,0,0,0,0,0,3,18,18,3,0,0,0,0,12,12,16,0,0,0,6,3,9,0,3,5
6,3,0,0,3,5,0,0,0,0,0,0,0,6,3,9,0,3,5,0,0,0,0,0,0,3,18,18,3,0,0,0,0,0,0,0,0,0,0,6,3,0,0,3,5
6,1,2,2,1,5,0,0,0,0,0,0,0,6,1,2,2,1,5,0,0,0,0,0,0,1,2,2,1,0,0,0,0,0,0,0,0,0,0,6,1,2,2,1,5
7,7,7,7,7,7,0,0,0,0,0,0,0,6,7,7,7,7,7,0,0,0,0,0,0,0,0,0,0,0,0,0,0,0,0,0,0,0,0,6,7,7,7,7,7
:endlayer
layer: 9
0,0,0,0,0,0,0,0,0,0,0,0,0,0,0,0,0,0,0,0,0,0,0,0,0,0,0,0,0,0,0,0,0,0,0,0,0,0,0,0,0,0,0,0,0
0,19,19,19,19,0,0,0,0,0,0,0,0,0,19,19,19,19,0,0,0,0,0,0,0,0,0,19,19,19,19,0,0,0,0,0,0,0,0,0,19,19,19,19,0
0,19,4,4,19,0,0,0,0,0,0,0,0,0,19,4,4,19,0,0,0,0,0,0,0,0,0,19,4,4,19,0,0,0,0,0,0,0,0,0,19,4,4,19,0
0,19,4,4,19,0,0,0,0,0,0,0,0,0,19,4,4,19,0,0,0,0,0,0,0,0,0,19,4,4,19,0,0,0,0,0,0,0,0,0,19,4,4,19,0
0,19,19,19,19,0,0,0,0,0,0,0,0,0,19,19,19,19,0,0,0,0,0,0,0,0,0,19,19,19,19,0,0,0,0,0,0,0,0,0,19,19,19,19,0
0,0,0,0,0,0,0,0,0,0,0,0,0,0,0,0,0,0,0,0,0,0,0,0,0,0,0,0,0,0,0,0,0,0,0,0,0,0,0,0,0,0,0,0,0
0,0,0,0,0,0,0,0,0,0,0,0,0,0,0,0,0,0,0,0,0,0,0,0,0,0,0,0,0,0,0,0,0,0,0,0,0,0,0,0,0,0,0,0,0
0,0,0,0,0,0,0,0,0,0,0,0,0,0,0,0,0,0,0,0,0,0,0,0,0,0,0,0,0,0,0,0,0,0,0,0,0,0,0,0,0,0,0,0,0
0,0,0,0,0,0,0,0,0,0,0,0,0,0,0,0,0,0,0,0,0,0,0,0,0,0,0,0,0,0,0,0,0,0,0,0,0,0,0,0,0,0,0,0,0
0,0,0,0,0,0,0,0,0,0,0,0,0,0,0,0,0,0,0,0,0,0,0,0,0,0,0,0,0,0,0,0,0,0,0,0,0,0,0,0,0,0,0,0,0
0,0,0,0,0,0,0,0,0,0,0,0,0,0,0,0,0,0,0,0,0,0,0,0,0,0,0,0,0,0,0,0,0,0,0,0,0,0,0,0,0,0,0,0,0
0,0,0,0,0,0,0,0,0,0,0,0,0,0,0,0,0,0,0,0,0,0,0,0,0,0,0,0,0,0,0,0,0,0,0,0,0,0,0,0,0,0,0,0,0
0,0,0,0,0,0,0,0,0,0,0,0,0,0,0,0,0,0,0,0,0,0,0,0,0,0,0,0,0,0,0,0,0,0,0,0,0,0,0,0,0,0,0,0,0
0,0,0,0,0,0,0,0,0,0,0,0,0,0,0,0,0,0,0,0,0,0,0,0,19,19,19,0,0,0,0,0,0,19,19,19,0,0,0,0,0,0,0,0,0
0,0,0,0,0,0,0,0,0,0,0,0,0,0,0,0,0,0,0,0,0,0,0,0,19,0,0,1,4,11,11,4,1,0,0,19,0,0,0,0,0,0,0,0,0
0,0,0,0,0,0,0,0,0,0,0,0,0,0,0,0,0,0,0,0,0,0,0,0,19,0,0,0,0,0,0,0,20,0,0,19,0,0,0,0,0,0,0,0,0
0,0,0,0,0,0,0,0,0,0,0,0,0,0,0,0,0,0,0,0,0,0,0,0,0,1,0,0,0,0,0,0,20,0,1,0,0,0,0,0,0,0,0,0,0
0,0,0,0,0,0,0,0,0,0,0,0,0,0,0,0,0,0,0,0,0,0,0,0,0,4,0,0,0,20,20,20,20,0,4,0,0,0,0,0,0,0,0,0,0
0,0,0,0,0,0,0,0,0,0,0,0,0,0,0,0,0,0,0,0,0,0,0,0,0,6,0,0,0,0,0,0,0,0,1,0,0,0,0,0,0,0,0,0,0
0,0,0,0,0,0,0,0,0,0,0,0,0,0,0,0,0,0,0,0,0,0,0,0,0,4,0,0,0,0,0,0,0,0,0,19,0,0,0,0,0,0,0,0,0
0,19,19,19,19,0,0,0,0,0,0,0,0,0,19,19,19,19,20,20,20,20,20,20,20,1,0,0,1,4,7,4,1,0,0,19,0,0,0,0,19,19,19,19,0
0,19,4,4,19,0,0,0,0,0,0,0,0,0,19,4,4,19,0,0,0,0,0,0,0,6,0,0,5,0,0,0,0,19,19,19,0,0,0,0,19,4,4,19,0
0,19,4,4,19,0,0,0,0,0,0,0,0,0,19,4,4,19,0,0,0,0,0,0,0,6,0,0,5,0,0,0,0,0,0,0,0,0,0,0,19,4,4,19,0
0,19,19,19,19,0,0,0,0,0,0,0,0,0,19,19,19,19,0,0,0,0,0,0,0,1,7,7,1,0,0,0,0,0,0,0,0,0,0,0,19,19,19,19,0
0,0,0,0,0,0,0,0,0,0,0,0,0,0,0,0,0,0,0,0,0,0,0,0,0,0,0,0,0,0,0,0,0,0,0,0,0,0,0,0,0,0,0,0,0
:endlayer
layer: 10
0,0,0,0,0,0,0,0,0,0,0,0,0,0,0,0,0,0,0,0,0,0,0,0,0,0,0,0,0,0,0,0,0,0,0,0,0,0,0,0,0,0,0,0,0
0,0,0,0,0,0,0,0,0,0,0,0,0,0,0,0,0,0,0,0,0,0,0,0,0,0,0,0,0,0,0,0,0,0,0,0,0,0,0,0,0,0,0,0,0
0,0,0,0,0,0,0,0,0,0,0,0,0,0,0,0,0,0,0,0,0,0,0,0,0,0,0,0,0,0,0,0,0,0,0,0,0,0,0,0,0,0,0,0,0
0,0,0,10,0,0,0,0,0,0,0,0,0,0,0,0,10,0,0,0,0,0,0,0,0,0,0,0,0,10,0,0,0,0,0,0,0,0,0,0,0,10,0,0,0
0,0,0,0,0,0,0,0,0,0,0,0,0,0,0,0,0,0,0,0,0,0,0,0,0,0,0,0,0,0,0,0,0,0,0,0,0,0,0,0,0,0,0,0,0
0,0,0,0,0,0,0,0,0,0,0,0,0,0,0,0,0,0,0,0,0,0,0,0,0,0,0,0,0,0,0,0,0,0,0,0,0,0,0,0,0,0,0,0,0
0,0,0,0,0,0,0,0,0,0,0,0,0,0,0,0,0,0,0,0,0,0,0,0,0,0,0,0,0,0,0,0,0,0,0,0,0,0,0,0,0,0,0,0,0
0,0,0,0,0,0,0,0,0,0,0,0,0,0,0,0,0,0,0,0,0,0,0,0,0,0,0,0,0,0,0,0,0,0,0,0,0,0,0,0,0,0,0,0,0
0,0,0,0,0,0,0,0,0,0,0,0,0,0,0,0,0,0,0,0,0,0,0,0,0,0,0,0,0,0,0,0,0,0,0,0,0,0,0,0,0,0,0,0,0
0,0,0,0,0,0,0,0,0,0,0,0,0,0,0,0,0,0,0,0,0,0,0,0,0,0,0,0,0,0,0,0,0,0,0,0,0,0,0,0,0,0,0,0,0
0,0,0,0,0,0,0,0,0,0,0,0,0,0,0,0,0,0,0,0,0,0,0,0,0,0,0,0,0,0,0,0,0,0,0,0,0,0,0,0,0,0,0,0,0
0,0,0,0,0,0,0,0,0,0,0,0,0,0,0,0,0,0,0,0,0,0,0,0,0,0,0,0,0,0,0,0,0,0,0,0,0,0,0,0,0,0,0,0,0
0,0,0,0,0,0,0,0,0,0,0,0,0,0,0,0,0,0,0,0,0,0,0,0,0,0,0,0,0,0,0,0,0,0,0,0,0,0,0,0,0,0,0,0,0
0,0,0,0,0,0,0,0,0,0,0,0,0,0,0,0,0,0,0,0,0,0,0,0,0,0,0,0,0,0,0,0,0,0,0,0,0,0,0,0,0,0,0,0,0
0,0,0,0,0,0,0,0,0,0,0,0,0,0,0,0,0,0,0,0,0,0,0,0,0,0,0,1,11,0,0,11,1,0,0,0,0,0,0,0,0,0,0,0,0
0,0,0,0,0,0,0,0,0,0,0,0,0,0,0,0,0,0,0,0,0,0,0,0,0,0,0,0,17,0,0,17,0,0,0,0,0,0,0,0,0,0,0,0,0
0,0,0,0,0,0,0,0,0,0,0,0,0,0,0,0,0,0,0,0,0,0,0,0,0,1,0,0,0,0,0,0,0,0,1,0,0,0,0,0,0,0,0,0,0
0,0,0,0,0,0,0,0,0,0,0,0,0,0,0,0,0,0,0,0,0,0,0,0,0,6,9,0,0,0,0,0,0,8,5,0,0,0,0,0,0,0,0,0,0
0,0,0,0,0,0,0,0,0,0,0,0,0,0,0,0,0,0,0,0,0,0,0,0,0,0,0,0,0,0,0,0,0,0,1,0,0,0,0,0,0,0,0,0,0
0,0,0,0,0,0,0,0,0,0,0,0,0,0,0,0,0,0,0,0,0,0,0,0,0,6,9,0,0,15,0,15,0,0,0,0,0,0,0,0,0,0,0,0,0
0,0,0,0,0,0,0,0,0,0,0,0,0,0,0,0,0,0,0,0,0,0,0,0,0,1,0,0,1,7,0,7,1,0,0,0,0,0,0,0,0,0,0,0,0
0,0,0,10,0,0,0,0,0,0,0,0,0,0,0,10,0,0,0,0,0,0,0,0,0,0,0,0,0,0,0,0,0,0,0,0,0,0,0,0,0,10,0,0,0
0,0,0,0,0,0,0,0,0,0,0,0,0,0,0,0,0,0,0,0,0,0,0,0,0,0,0,0,0,0,0,0,0,0,0,0,0,0,0,0,0,0,0,0,0
0,0,0,0,0,0,0,0,0,0,0,0,0,0,0,0,0,0,0,0,0,0,0,0,0,1,0,0,1,0,0,0,0,0,0,0,0,0,0,0,0,0,0,0,0
0,0,0,0,0,0,0,0,0,0,0,0,0,0,0,0,0,0,0,0,0,0,0,0,0,0,0,0,0,0,0,0,0,0,0,0,0,0,0,0,0,0,0,0,0
:endlayer
layer: 11
0,0,0,0,0,0,0,0,0,0,0,0,0,0,0,0,0,0,0,0,0,0,0,0,0,0,0,0,0,0,0,0,0,0,0,0,0,0,0,0,0,0,0,0,0
0,0,0,0,0,0,0,0,0,0,0,0,0,0,0,0,0,0,0,0,0,0,0,0,0,0,0,0,0,0,0,0,0,0,0,0,0,0,0,0,0,0,0,0,0
0,0,0,0,0,0,0,0,0,0,0,0,0,0,0,0,0,0,0,0,0,0,0,0,0,0,0,0,0,0,0,0,0,0,0,0,0,0,0,0,0,0,0,0,0
0,0,0,0,0,0,0,0,0,0,0,0,0,0,0,0,0,0,0,0,0,0,0,0,0,0,0,0,0,0,0,0,0,0,0,0,0,0,0,0,0,0,0,0,0
0,0,0,0,0,0,0,0,0,0,0,0,0,0,0,0,0,0,0,0,0,0,0,0,0,0,0,0,0,0,0,0,0,0,0,0,0,0,0,0,0,0,0,0,0
0,0,0,0,0,0,0,0,0,0,0,0,0,0,0,0,0,0,0,0,0,0,0,0,0,0,0,0,0,0,0,0,0,0,0,0,0,0,0,0,0,0,0,0,0
0,0,0,0,0,0,0,0,0,0,0,0,0,0,0,0,0,0,0,0,0,0,0,0,0,0,0,0,0,0,0,0,0,0,0,0,0,0,0,0,0,0,0,0,0
0,0,0,0,0,0,0,0,0,0,0,0,0,0,0,0,0,0,0,0,0,0,0,0,0,0,0,0,0,0,0,0,0,0,0,0,0,0,0,0,0,0,0,0,0
0,0,0,0,0,0,0,0,0,0,0,0,0,0,0,0,0,0,0,0,0,0,0,0,0,0,0,0,0,0,0,0,0,0,0,0,0,0,0,0,0,0,0,0,0
0,0,0,0,0,0,0,0,0,0,0,0,0,0,0,0,0,0,0,0,0,0,0,0,0,0,0,0,0,0,0,0,0,0,0,0,0,0,0,0,0,0,0,0,0
0,0,0,0,0,0,0,0,0,0,0,0,0,0,0,0,0,0,0,0,0,0,0,0,0,0,0,0,0,0,0,0,0,0,0,0,0,0,0,0,0,0,0,0,0
0,0,0,0,0,0,0,0,0,0,0,0,0,0,0,0,0,0,0,0,0,0,0,0,0,0,0,0,0,0,0,0,0,0,0,0,0,0,0,0,0,0,0,0,0
0,0,0,0,0,0,0,0,0,0,0,0,0,0,0,0,0,0,0,0,0,0,0,0,0,0,0,0,0,0,0,0,0,0,0,0,0,0,0,0,0,0,0,0,0
0,0,0,0,0,0,0,0,0,0,0,0,0,0,0,0,0,0,0,0,0,0,0,0,0,0,0,0,0,0,0,0,0,0,0,0,0,0,0,0,0,0,0,0,0
0,0,0,0,0,0,0,0,0,0,0,0,0,0,0,0,0,0,0,0,0,0,0,0,0,0,0,19,0,0,0,0,19,0,0,0,0,0,0,0,0,0,0,0,0
0,0,0,0,0,0,0,0,0,0,0,0,0,0,0,0,0,0,0,0,0,0,0,0,0,0,0,0,0,0,0,0,0,0,0,0,0,0,0,0,0,0,0,0,0
0,0,0,0,0,0,0,0,0,0,0,0,0,0,0,0,0,0,0,0,0,0,0,0,0,19,0,0,0,0,0,0,0,0,19,0,0,0,0,0,0,0,0,0,0
0,0,0,0,0,0,0,0,0,0,0,0,0,0,0,0,0,0,0,0,0,0,0,0,0,0,0,0,0,0,0,0,0,0,0,0,0,0,0,0,0,0,0,0,0
0,0,0,0,0,0,0,0,0,0,0,0,0,0,0,0,0,0,0,0,0,0,0,0,0,0,0,0,0,0,0,0,0,0,19,0,0,0,0,0,0,0,0,0,0
0,0,0,0,0,0,0,0,0,0,0,0,0,0,0,0,0,0,0,0,0,0,0,0,0,0,0,0,0,0,0,0,0,0,0,0,0,0,0,0,0,0,0,0,0
0,0,0,0,0,0,0,0,0,0,0,0,0,0,0,0,0,0,0,0,0,0,0,0,0,1,4,4,1,0,0,0,19,0,0,0,0,0,0,0,0,0,0,0,0
0,0,0,0,0,0,0,0,0,0,0,0,0,0,0,0,0,0,0,0,0,0,0,0,0,14,0,0,16,0,0,0,0,0,0,0,0,0,0,0,0,0,0,0,0
0,0,0,0,0,0,0,0,0,0,0,0,0,0,0,0,0,0,0,0,0,0,0,0,0,14,0,0,16,0,0,0,0,0,0,0,0,0,0,0,0,0,0,0,0
0,0,0,0,0,0,0,0,0,0,0,0,0,0,0,0,0,0,0,0,0,0,0,0,0,1,12,12,1,0,0,0,0,0,0,0,0,0,0,0,0,0,0,0,0
0,0,0,0,0,0,0,0,0,0,0,0,0,0,0,0,0,0,0,0,0,0,0,0,0,0,0,0,0,0,0,0,0,0,0,0,0,0,0,0,0,0,0,0,0
:endlayer
layer: 12
0,0,0,0,0,0,0,0,0,0,0,0,0,0,0,0,0,0,0,0,0,0,0,0,0,0,0,0,0,0,0,0,0,0,0,0,0,0,0,0,0,0,0,0,0
0,0,0,0,0,0,0,0,0,0,0,0,0,0,0,0,0,0,0,0,0,0,0,0,0,0,0,0,0,0,0,0,0,0,0,0,0,0,0,0,0,0,0,0,0
0,0,0,0,0,0,0,0,0,0,0,0,0,0,0,0,0,0,0,0,0,0,0,0,0,0,0,0,0,0,0,0,0,0,0,0,0,0,0,0,0,0,0,0,0
0,0,0,0,0,0,0,0,0,0,0,0,0,0,0,0,0,0,0,0,0,0,0,0,0,0,0,0,0,0,0,0,0,0,0,0,0,0,0,0,0,0,0,0,0
0,0,0,0,0,0,0,0,0,0,0,0,0,0,0,0,0,0,0,0,0,0,0,0,0,0,0,0,0,0,0,0,0,0,0,0,0,0,0,0,0,0,0,0,0
0,0,0,0,0,0,0,0,0,0,0,0,0,0,0,0,0,0,0,0,0,0,0,0,0,0,0,0,0,0,0,0,0,0,0,0,0,0,0,0,0,0,0,0,0
0,0,0,0,0,0,0,0,0,0,0,0,0,0,0,0,0,0,0,0,0,0,0,0,0,0,0,0,0,0,0,0,0,0,0,0,0,0,0,0,0,0,0,0,0
0,0,0,0,0,0,0,0,0,0,0,0,0,0,0,0,0,0,0,0,0,0,0,0,0,0,0,0,0,0,0,0,0,0,0,0,0,0,0,0,0,0,0,0,0
0,0,0,0,0,0,0,0,0,0,0,0,0,0,0,0,0,0,0,0,0,0,0,0,0,0,0,0,0,0,0,0,0,0,0,0,0,0,0,0,0,0,0,0,0
0,0,0,0,0,0,0,0,0,0,0,0,0,0,0,0,0,0,0,0,0,0,0,0,0,0,0,0,0,0,0,0,0,0,0,0,0,0,0,0,0,0,0,0,0
0,0,0,0,0,0,0,0,0,0,0,0,0,0,0,0,0,0,0,0,0,0,0,0,0,0,0,0,0,0,0,0,0,0,0,0,0,0,0,0,0,0,0,0,0
0,0,0,0,0,0,0,0,0,0,0,0,0,0,0,0,0,0,0,0,0,0,0,0,0,0,0,0,0,0,0,0,0,0,0,0,0,0,0,0,0,0,0,0,0
0,0,0,0,0,0,0,0,0,0,0,0,0,0,0,0,0,0,0,0,0,0,0,0,0,0,0,0,0,0,0,0,0,0,0,0,0,0,0,0,0,0,0,0,0
0,0,0,0,0,0,0,0,0,0,0,0,0,0,0,0,0,0,0,0,0,0,0,0,0,0,0,0,0,0,0,0,0,0,0,0,0,0,0,0,0,0,0,0,0
0,0,0,0,0,0,0,0,0,0,0,0,0,0,0,0,0,0,0,0,0,0,0,0,0,0,0,0,0,0,0,0,0,0,0,0,0,0,0,0,0,0,0,0,0
0,0,0,0,0,0,0,0,0,0,0,0,0,0,0,0,0,0,0,0,0,0,0,0,0,0,0,0,0,0,0,0,0,0,0,0,0,0,0,0,0,0,0,0,0
0,0,0,0,0,0,0,0,0,0,0,0,0,0,0,0,0,0,0,0,0,0,0,0,0,0,0,0,0,0,0,0,0,0,0,0,0,0,0,0,0,0,0,0,0
0,0,0,0,0,0,0,0,0,0,0,0,0,0,0,0,0,0,0,0,0,0,0,0,0,0,0,0,0,0,0,0,0,0,0,0,0,0,0,0,0,0,0,0,0
0,0,0,0,0,0,0,0,0,0,0,0,0,0,0,0,0,0,0,0,0,0,0,0,0,0,0,0,0,0,0,0,0,0,0,0,0,0,0,0,0,0,0,0,0
0,0,0,0,0,0,0,0,0,0,0,0,0,0,0,0,0,0,0,0,0,0,0,0,11,11,11,11,11,5,0,0,0,0,0,0,0,0,0,0,0,0,0,0,0
0,0,0,0,0,0,0,0,0,0,0,0,0,0,0,0,0,0,0,0,0,0,0,0,6,1,2,2,1,5,0,0,0,0,0,0,0,0,0,0,0,0,0,0,0
0,0,0,0,0,0,0,0,0,0,0,0,0,0,0,0,0,0,0,0,0,0,0,0,6,3,0,0,3,5,0,0,0,0,0,0,0,0,0,0,0,0,0,0,0
0,0,0,0,0,0,0,0,0,0,0,0,0,0,0,0,0,0,0,0,0,0,0,0,6,3,0,0,3,5,0,0,0,0,0,0,0,0,0,0,0,0,0,0,0
0,0,0,0,0,0,0,0,0,0,0,0,0,0,0,0,0,0,0,0,0,0,0,0,6,1,2,2,1,5,0,0,0,0,0,0,0,0,0,0,0,0,0,0,0
0,0,0,0,0,0,0,0,0,0,0,0,0,0,0,0,0,0,0,0,0,0,0,0,6,7,7,7,7,5,0,0,0,0,0,0,0,0,0,0,0,0,0,0,0
:endlayer
layer: 13
0,0,0,0,0,0,0,0,0,0,0,0,0,0,0,0,0,0,0,0,0,0,0,0,0,0,0,0,0,0,0,0,0,0,0,0,0,0,0,0,0,0,0,0,0
0,0,0,0,0,0,0,0,0,0,0,0,0,0,0,0,0,0,0,0,0,0,0,0,0,0,0,0,0,0,0,0,0,0,0,0,0,0,0,0,0,0,0,0,0
0,0,0,0,0,0,0,0,0,0,0,0,0,0,0,0,0,0,0,0,0,0,0,0,0,0,0,0,0,0,0,0,0,0,0,0,0,0,0,0,0,0,0,0,0
0,0,0,0,0,0,0,0,0,0,0,0,0,0,0,0,0,0,0,0,0,0,0,0,0,0,0,0,0,0,0,0,0,0,0,0,0,0,0,0,0,0,0,0,0
0,0,0,0,0,0,0,0,0,0,0,0,0,0,0,0,0,0,0,0,0,0,0,0,0,0,0,0,0,0,0,0,0,0,0,0,0,0,0,0,0,0,0,0,0
0,0,0,0,0,0,0,0,0,0,0,0,0,0,0,0,0,0,0,0,0,0,0,0,0,0,0,0,0,0,0,0,0,0,0,0,0,0,0,0,0,0,0,0,0
0,0,0,0,0,0,0,0,0,0,0,0,0,0,0,0,0,0,0,0,0,0,0,0,0,0,0,0,0,0,0,0,0,0,0,0,0,0,0,0,0,0,0,0,0
0,0,0,0,0,0,0,0,0,0,0,0,0,0,0,0,0,0,0,0,0,0,0,0,0,0,0,0,0,0,0,0,0,0,0,0,0,0,0,0,0,0,0,0,0
0,0,0,0,0,0,0,0,0,0,0,0,0,0,0,0,0,0,0,0,0,0,0,0,0,0,0,0,0,0,0,0,0,0,0,0,0,0,0,0,0,0,0,0,0
0,0,0,0,0,0,0,0,0,0,0,0,0,0,0,0,0,0,0,0,0,0,0,0,0,0,0,0,0,0,0,0,0,0,0,0,0,0,0,0,0,0,0,0,0
0,0,0,0,0,0,0,0,0,0,0,0,0,0,0,0,0,0,0,0,0,0,0,0,0,0,0,0,0,0,0,0,0,0,0,0,0,0,0,0,0,0,0,0,0
0,0,0,0,0,0,0,0,0,0,0,0,0,0,0,0,0,0,0,0,0,0,0,0,0,0,0,0,0,0,0,0,0,0,0,0,0,0,0,0,0,0,0,0,0
0,0,0,0,0,0,0,0,0,0,0,0,0,0,0,0,0,0,0,0,0,0,0,0,0,0,0,0,0,0,0,0,0,0,0,0,0,0,0,0,0,0,0,0,0
0,0,0,0,0,0,0,0,0,0,0,0,0,0,0,0,0,0,0,0,0,0,0,0,0,0,0,0,0,0,0,0,0,0,0,0,0,0,0,0,0,0,0,0,0
0,0,0,0,0,0,0,0,0,0,0,0,0,0,0,0,0,0,0,0,0,0,0,0,0,0,0,0,0,0,0,0,0,0,0,0,0,0,0,0,0,0,0,0,0
0,0,0,0,0,0,0,0,0,0,0,0,0,0,0,0,0,0,0,0,0,0,0,0,0,0,0,0,0,0,0,0,0,0,0,0,0,0,0,0,0,0,0,0,0
0,0,0,0,0,0,0,0,0,0,0,0,0,0,0,0,0,0,0,0,0,0,0,0,0,0,0,0,0,0,0,0,0,0,0,0,0,0,0,0,0,0,0,0,0
0,0,0,0,0,0,0,0,0,0,0,0,0,0,0,0,0,0,0,0,0,0,0,0,0,0,0,0,0,0,0,0,0,0,0,0,0,0,0,0,0,0,0,0,0
0,0,0,0,0,0,0,0,0,0,0,0,0,0,0,0,0,0,0,0,0,0,0,0,0,0,0,0,0,0,0,0,0,0,0,0,0,0,0,0,0,0,0,0,0
0,0,0,0,0,0,0,0,0,0,0,0,0,0,0,0,0,0,0,0,0,0,0,0,0,0,0,0,0,0,0,0,0,0,0,0,0,0,0,0,0,0,0,0,0
0,0,0,0,0,0,0,0,0,0,0,0,0,0,0,0,0,0,0,0,0,0,0,0,0,19,19,19,19,0,0,0,0,0,0,0,0,0,0,0,0,0,0,0,0
0,0,0,0,0,0,0,0,0,0,0,0,0,0,0,0,0,0,0,0,0,0,0,0,0,19,4,4,19,0,0,0,0,0,0,0,0,0,0,0,0,0,0,0,0
0,0,0,0,0,0,0,0,0,0,0,0,0,0,0,0,0,0,0,0,0,0,0,0,0,19,4,4,19,0,0,0,0,0,0,0,0,0,0,0,0,0,0,0,0
0,0,0,0,0,0,0,0,0,0,0,0,0,0,0,0,0,0,0,0,0,0,0,0,0,19,19,19,19,0,0,0,0,0,0,0,0,0,0,0,0,0,0,0,0
0,0,0,0,0,0,0,0,0,0,0,0,0,0,0,0,0,0,0,0,0,0,0,0,0,0,0,0,0,0,0,0,0,0,0,0,0,0,0,0,0,0,0,0,0
:endlayer
layer: 14
0,0,0,0,0,0,0,0,0,0,0,0,0,0,0,0,0,0,0,0,0,0,0,0,0,0,0,0,0,0,0,0,0,0,0,0,0,0,0,0,0,0,0,0,0
0,0,0,0,0,0,0,0,0,0,0,0,0,0,0,0,0,0,0,0,0,0,0,0,0,0,0,0,0,0,0,0,0,0,0,0,0,0,0,0,0,0,0,0,0
0,0,0,0,0,0,0,0,0,0,0,0,0,0,0,0,0,0,0,0,0,0,0,0,0,0,0,0,0,0,0,0,0,0,0,0,0,0,0,0,0,0,0,0,0
0,0,0,0,0,0,0,0,0,0,0,0,0,0,0,0,0,0,0,0,0,0,0,0,0,0,0,0,0,0,0,0,0,0,0,0,0,0,0,0,0,0,0,0,0
0,0,0,0,0,0,0,0,0,0,0,0,0,0,0,0,0,0,0,0,0,0,0,0,0,0,0,0,0,0,0,0,0,0,0,0,0,0,0,0,0,0,0,0,0
0,0,0,0,0,0,0,0,0,0,0,0,0,0,0,0,0,0,0,0,0,0,0,0,0,0,0,0,0,0,0,0,0,0,0,0,0,0,0,0,0,0,0,0,0
0,0,0,0,0,0,0,0,0,0,0,0,0,0,0,0,0,0,0,0,0,0,0,0,0,0,0,0,0,0,0,0,0,0,0,0,0,0,0,0,0,0,0,0,0
0,0,0,0,0,0,0,0,0,0,0,0,0,0,0,0,0,0,0,0,0,0,0,0,0,0,0,0,0,0,0,0,0,0,0,0,0,0,0,0,0,0,0,0,0
0,0,0,0,0,0,0,0,0,0,0,0,0,0,0,0,0,0,0,0,0,0,0,0,0,0,0,0,0,0,0,0,0,0,0,0,0,0,0,0,0,0,0,0,0
0,0,0,0,0,0,0,0,0,0,0,0,0,0,0,0,0,0,0,0,0,0,0,0,0,0,0,0,0,0,0,0,0,0,0,0,0,0,0,0,0,0,0,0,0
0,0,0,0,0,0,0,0,0,0,0,0,0,0,0,0,0,0,0,0,0,0,0,0,0,0,0,0,0,0,0,0,0,0,0,0,0,0,0,0,0,0,0,0,0
0,0,0,0,0,0,0,0,0,0,0,0,0,0,0,0,0,0,0,0,0,0,0,0,0,0,0,0,0,0,0,0,0,0,0,0,0,0,0,0,0,0,0,0,0
0,0,0,0,0,0,0,0,0,0,0,0,0,0,0,0,0,0,0,0,0,0,0,0,0,0,0,0,0,0,0,0,0,0,0,0,0,0,0,0,0,0,0,0,0
0,0,0,0,0,0,0,0,0,0,0,0,0,0,0,0,0,0,0,0,0,0,0,0,0,0,0,0,0,0,0,0,0,0,0,0,0,0,0,0,0,0,0,0,0
0,0,0,0,0,0,0,0,0,0,0,0,0,0,0,0,0,0,0,0,0,0,0,0,0,0,0,0,0,0,0,0,0,0,0,0,0,0,0,0,0,0,0,0,0
0,0,0,0,0,0,0,0,0,0,0,0,0,0,0,0,0,0,0,0,0,0,0,0,0,0,0,0,0,0,0,0,0,0,0,0,0,0,0,0,0,0,0,0,0
0,0,0,0,0,0,0,0,0,0,0,0,0,0,0,0,0,0,0,0,0,0,0,0,0,0,0,0,0,0,0,0,0,0,0,0,0,0,0,0,0,0,0,0,0
0,0,0,0,0,0,0,0,0,0,0,0,0,0,0,0,0,0,0,0,0,0,0,0,0,0,0,0,0,0,0,0,0,0,0,0,0,0,0,0,0,0,0,0,0
0,0,0,0,0,0,0,0,0,0,0,0,0,0,0,0,0,0,0,0,0,0,0,0,0,0,0,0,0,0,0,0,0,0,0,0,0,0,0,0,0,0,0,0,0
0,0,0,0,0,0,0,0,0,0,0,0,0,0,0,0,0,0,0,0,0,0,0,0,0,0,0,0,0,0,0,0,0,0,0,0,0,0,0,0,0,0,0,0,0
0,0,0,0,0,0,0,0,0,0,0,0,0,0,0,0,0,0,0,0,0,0,0,0,0,0,0,0,0,0,0,0,0,0,0,0,0,0,0,0,0,0,0,0,0
0,0,0,0,0,0,0,0,0,0,0,0,0,0,0,0,0,0,0,0,0,0,0,0,0,0,0,10,0,0,0,0,0,0,0,0,0,0,0,0,0,0,0,0,0
0,0,0,0,0,0,0,0,0,0,0,0,0,0,0,0,0,0,0,0,0,0,0,0,0,0,0,0,0,0,0,0,0,0,0,0,0,0,0,0,0,0,0,0,0
0,0,0,0,0,0,0,0,0,0,0,0,0,0,0,0,0,0,0,0,0,0,0,0,0,0,0,0,0,0,0,0,0,0,0,0,0,0,0,0,0,0,0,0,0
0,0,0,0,0,0,0,0,0,0,0,0,0,0,0,0,0,0,0,0,0,0,0,0,0,0,0,0,0,0,0,0,0,0,0,0,0,0,0,0,0,0,0,0,0
:endlayer

#### RULES ####
rule:
plugin=vanillaBlocks
number=1
data:
JSON:{blockState:{blockName:"biomesoplenty:log_2",properties:{variant:"redwood",axis:"y"}}}
:enddata
:endrule

rule:
plugin=vanillaBlocks
number=2
data:
JSON:{blockState:{blockName:"biomesoplenty:log_2",properties:{variant:"redwood",axis:"x"}}}
:enddata
:endrule

rule:
plugin=vanillaBlocks
number=3
data:
JSON:{blockState:{blockName:"biomesoplenty:log_2",properties:{variant:"redwood",axis:"z"}}}
:enddata
:endrule

rule:
plugin=vanillaBlocks
number=4
data:
JSON:{blockState:{blockName:"biomesoplenty:planks_0",properties:{variant:"redwood"}}}
:enddata
:endrule

rule:
plugin=vanillaBlocks
number=5
data:
JSON:{blockState:{blockName:"biomesoplenty:redwood_stairs",properties:{half:"bottom",shape:"straight",facing:"west"}}}
:enddata
:endrule

rule:
plugin=vanillaBlocks
number=6
data:
JSON:{blockState:{blockName:"biomesoplenty:redwood_stairs",properties:{half:"bottom",shape:"straight",facing:"east"}}}
:enddata
:endrule

rule:
plugin=vanillaBlocks
number=7
data:
JSON:{blockState:{blockName:"biomesoplenty:redwood_stairs",properties:{half:"bottom",shape:"straight",facing:"north"}}}
:enddata
:endrule

rule:
plugin=vanillaBlocks
number=8
data:
JSON:{blockState:{blockName:"minecraft:torch",properties:{facing:"west"}}}
:enddata
:endrule

rule:
plugin=vanillaBlocks
number=9
data:
JSON:{blockState:{blockName:"minecraft:torch",properties:{facing:"east"}}}
:enddata
:endrule

rule:
plugin=vanillaBlocks
number=10
data:
JSON:{blockState:{blockName:"minecraft:torch",properties:{facing:"up"}}}
:enddata
:endrule

rule:
plugin=vanillaBlocks
number=11
data:
JSON:{blockState:{blockName:"biomesoplenty:redwood_stairs",properties:{half:"bottom",shape:"straight",facing:"south"}}}
:enddata
:endrule

rule:
plugin=vanillaBlocks
number=12
data:
JSON:{blockState:{blockName:"biomesoplenty:redwood_stairs",properties:{half:"top",shape:"straight",facing:"north"}}}
:enddata
:endrule

rule:
plugin=vanillaBlocks
number=13
data:
JSON:{blockState:{blockName:"biomesoplenty:redwood_stairs",properties:{half:"top",shape:"straight",facing:"south"}}}
:enddata
:endrule

rule:
plugin=vanillaBlocks
number=14
data:
JSON:{blockState:{blockName:"biomesoplenty:redwood_stairs",properties:{half:"top",shape:"straight",facing:"east"}}}
:enddata
:endrule

rule:
plugin=vanillaBlocks
number=15
data:
JSON:{blockState:{blockName:"minecraft:torch",properties:{facing:"north"}}}
:enddata
:endrule

rule:
plugin=vanillaBlocks
number=16
data:
JSON:{blockState:{blockName:"biomesoplenty:redwood_stairs",properties:{half:"top",shape:"straight",facing:"west"}}}
:enddata
:endrule

rule:
plugin=vanillaBlocks
number=17
data:
JSON:{blockState:{blockName:"minecraft:torch",properties:{facing:"south"}}}
:enddata
:endrule

rule:
plugin=vanillaBlocks
number=18
data:
JSON:{blockState:{blockName:"biomesoplenty:wood_slab_1",properties:{half:"top",variant:"redwood"}}}
:enddata
:endrule

rule:
plugin=vanillaBlocks
number=19
data:
JSON:{blockState:{blockName:"biomesoplenty:wood_slab_1",properties:{half:"bottom",variant:"redwood"}}}
:enddata
:endrule

rule:
plugin=vanillaBlocks
number=20
data:
JSON:{blockState:{blockName:"biomesoplenty:redwood_fence",properties:{east:"false",south:"false",north:"false",west:"false"}}}
:enddata
:endrule

#### ENTITIES ####
