# Ancient Warfare Structure Template File
# Auto-generated structure template file. created on: 1/9/2024 at: 0:9:9
# Lines beginning with # denote comments

header:
version=2.11
name=SB_DarokCol_PortSmall_1
mods=
size=20,17,17
offset=16,0,14
:endheader

#### VALIDATION ####
validation:
type=harbor
structureAuthor=TheOddlySeagull
survival=true
worldGenEnabled=false
unique=false
preserveBlocks=false
preventNaturalHostileSpawns=true
selectionWeight=1
clusterValue=1
minDuplicateDistance=1
dimensionWhiteList=true
dimensionList=
biomeGroupList=
biomeWhiteList=true
biomeList=
leveling=10
fill=10
border=5
blockSwap=false
territoryName=
biomeReplacement=minecraft:
:endvalidation

#### LAYERS ####
layer: 0
0,0,0,0,0,0,0,0,0,0,0,0,0,0,0,0,0,0,0,0
0,0,8,0,0,0,0,0,0,0,0,0,0,0,0,0,0,0,0,0
0,4,2,0,0,0,2,3,3,3,2,3,3,3,2,0,0,0,2,0
0,0,0,0,0,0,3,5,5,5,5,5,5,5,3,0,0,0,0,0
0,0,0,0,0,0,3,5,5,5,5,5,5,5,3,0,0,0,0,0
0,0,0,0,0,0,3,5,5,5,5,5,5,5,3,0,0,0,0,0
0,4,2,0,0,0,2,5,5,5,2,5,5,5,2,0,0,0,2,0
0,0,0,0,0,0,3,5,5,5,5,5,5,5,3,0,0,0,0,0
0,0,0,0,0,0,3,5,5,5,5,5,5,5,3,0,0,0,0,0
0,0,0,0,0,0,3,5,5,5,5,5,5,5,3,0,0,0,0,0
0,4,2,0,0,0,2,5,5,5,2,5,5,5,2,7,7,7,2,0
0,0,0,0,0,0,3,5,5,5,5,5,5,5,3,6,6,6,0,0
0,0,0,0,0,0,3,5,5,5,5,5,5,5,3,0,0,0,0,0
0,0,0,0,0,0,3,5,5,5,5,5,5,5,3,0,0,0,0,0
0,4,2,0,0,0,2,3,3,3,2,3,3,3,2,0,0,0,0,0
0,0,1,0,0,0,0,0,0,0,0,0,0,0,0,0,0,0,0,0
0,0,0,0,0,0,0,0,0,0,0,0,0,0,0,0,0,0,0,0
:endlayer
layer: 1
0,0,0,0,0,0,0,0,0,0,0,0,0,0,0,0,0,0,0,0
0,0,8,0,0,0,0,0,0,0,0,0,0,0,0,0,0,0,0,0
0,4,2,10,10,10,2,9,9,9,2,9,9,9,2,9,9,9,2,0
0,0,10,10,10,10,11,12,12,12,11,12,12,12,11,10,10,10,11,0
0,0,10,10,10,10,11,12,12,12,11,12,12,12,11,10,10,10,11,0
0,0,10,10,10,10,11,12,12,12,11,12,12,12,11,10,10,10,11,0
0,4,2,9,9,9,2,9,9,9,2,9,9,9,2,9,9,9,2,0
0,0,10,10,10,10,11,12,12,12,11,12,12,12,11,10,10,10,11,0
0,0,10,10,10,10,11,12,12,12,11,12,12,12,11,10,10,10,11,0
0,0,10,10,10,10,11,12,12,12,11,12,12,12,11,7,7,7,11,0
0,4,2,9,9,9,2,9,9,9,2,9,9,9,2,6,6,6,2,0
0,0,10,10,10,10,11,12,12,12,11,12,12,12,11,0,0,0,0,0
0,0,10,10,10,10,11,12,12,12,11,12,12,12,11,0,0,0,0,0
0,0,10,10,10,10,11,12,12,12,11,12,12,12,11,0,0,0,0,0
0,4,2,10,10,10,2,9,9,9,2,9,9,9,2,0,0,0,0,0
0,0,1,0,0,0,0,0,0,0,0,0,0,0,0,0,0,0,0,0
0,0,0,0,0,0,0,0,0,0,0,0,0,0,0,0,0,0,0,0
:endlayer
layer: 2
0,0,0,0,0,0,0,0,0,0,0,0,0,0,0,0,0,0,0,0
0,0,0,0,0,0,0,0,0,0,0,0,0,0,0,0,0,0,0,0
0,0,14,0,0,0,2,13,13,13,2,13,13,13,2,14,14,14,2,0
0,0,0,0,0,0,13,0,0,0,0,0,0,0,13,0,0,0,14,0
0,0,0,0,0,0,13,0,0,0,0,0,0,18,13,0,0,0,14,0
0,0,0,0,0,0,13,0,0,0,0,0,0,17,13,0,0,0,14,0
0,0,14,0,0,0,2,0,0,0,2,0,0,0,2,0,0,0,2,0
0,0,0,0,0,0,13,0,0,0,0,0,0,0,13,0,0,0,14,0
0,0,0,0,0,0,16,0,0,0,0,0,0,0,15,0,0,0,14,0
0,0,0,0,0,0,13,0,0,0,0,0,0,0,13,0,0,0,14,0
0,0,14,0,0,0,2,0,0,0,2,0,0,0,2,0,0,0,2,0
0,0,0,0,0,0,13,0,0,0,0,0,0,0,13,0,0,0,0,0
0,0,0,0,0,0,13,0,0,0,0,0,0,0,13,0,0,0,0,0
0,0,0,0,0,0,13,0,0,0,0,0,0,0,13,0,0,0,0,0
0,0,14,0,0,0,2,13,13,13,2,13,13,13,2,0,0,0,0,0
0,0,0,0,0,0,0,0,0,0,0,0,0,0,0,0,0,0,0,0
0,0,0,0,0,0,0,0,0,0,0,0,0,0,0,0,0,0,0,0
:endlayer
layer: 3
0,0,0,0,0,0,0,0,0,0,0,0,0,0,0,0,0,0,0,0
0,0,0,0,0,0,14,0,0,0,14,0,0,0,14,0,0,0,0,0
0,0,20,0,0,0,2,13,19,13,2,13,19,13,2,0,0,0,14,0
0,0,0,0,0,0,13,0,0,0,0,0,0,0,13,0,0,0,0,0
0,0,0,0,0,0,19,0,0,0,0,0,0,0,19,0,0,0,0,0
0,0,0,0,0,0,13,0,0,0,0,0,0,18,13,0,0,0,0,0
0,0,20,0,0,0,2,0,0,0,2,0,0,17,2,0,0,0,14,0
0,0,0,0,0,0,13,0,0,0,0,0,0,0,13,0,0,0,0,0
0,0,0,0,0,0,22,0,0,0,0,0,0,0,21,0,0,0,0,0
0,0,0,0,0,0,13,0,0,0,0,0,0,0,13,0,0,0,0,0
0,0,20,0,0,0,2,0,0,0,2,0,0,0,2,0,0,0,14,0
0,0,0,0,0,0,13,0,0,0,0,0,0,0,13,0,0,0,0,0
0,0,0,0,0,0,19,0,0,0,0,0,0,0,19,0,0,0,0,0
0,0,0,0,0,0,13,0,0,0,0,0,0,0,13,0,0,0,0,0
0,0,20,0,0,0,2,13,19,13,2,13,19,13,2,0,0,0,0,0
0,0,0,0,0,0,14,0,0,0,14,0,0,0,14,0,0,0,0,0
0,0,0,0,0,0,0,0,0,0,0,0,0,0,0,0,0,0,0,0
:endlayer
layer: 4
0,0,0,0,0,0,0,0,0,0,0,0,0,0,0,0,0,0,0,0
0,0,0,0,0,10,7,10,0,10,7,10,0,10,7,10,0,0,0,0
0,0,0,0,0,24,2,13,19,13,2,13,19,13,2,23,0,0,20,0
0,0,0,0,0,0,13,0,0,0,26,0,0,0,13,0,0,0,0,0
0,0,0,0,0,0,19,0,0,0,0,0,0,0,19,0,0,0,0,0
0,0,0,0,0,0,13,0,0,0,25,0,0,0,13,0,0,0,0,0
0,0,0,0,0,24,2,23,0,24,2,23,0,18,2,23,0,0,20,0
0,0,0,0,0,0,13,0,0,0,26,0,0,17,13,0,0,0,0,0
0,0,0,0,0,0,13,0,0,0,0,0,0,0,13,0,0,0,0,0
0,0,0,0,0,0,13,0,0,0,25,0,0,0,13,0,0,0,0,0
0,0,0,0,0,24,2,23,0,24,2,23,0,24,2,23,0,0,20,0
0,0,0,0,0,0,13,0,0,0,26,0,0,0,13,0,0,0,0,0
0,0,0,0,0,0,19,0,0,0,0,0,0,0,19,0,0,0,0,0
0,0,0,0,0,0,13,0,0,0,25,0,0,0,13,0,0,0,0,0
0,0,0,0,0,24,2,13,19,13,2,13,19,13,2,23,0,0,0,0
0,0,0,0,0,10,17,10,0,10,17,10,0,10,17,10,0,0,0,0
0,0,0,0,0,0,0,0,0,0,0,0,0,0,0,0,0,0,0,0
:endlayer
layer: 5
0,0,0,0,0,0,0,0,0,0,0,0,0,0,0,0,0,0,0,0
0,0,0,0,0,18,18,18,18,18,18,18,18,18,18,18,0,0,0,0
0,0,0,0,0,17,2,9,9,9,2,9,9,9,2,17,0,0,0,0
0,0,0,0,0,0,11,10,10,10,11,10,10,0,11,0,0,0,0,0
0,0,0,0,0,0,11,10,10,10,11,10,10,0,11,0,0,0,0,0
0,0,0,0,0,0,11,10,10,10,11,10,10,0,11,0,0,0,0,0
0,0,0,0,0,0,2,9,9,9,2,10,10,0,2,0,0,0,0,0
0,0,0,0,0,0,11,10,10,10,11,10,10,18,11,0,0,0,0,0
0,0,0,0,0,0,11,10,10,10,11,10,10,17,11,0,0,0,0,0
0,0,0,0,0,0,11,10,10,10,11,10,10,10,11,0,0,0,0,0
0,0,0,0,0,0,2,9,9,9,2,9,9,9,2,0,0,0,0,0
0,0,0,0,0,0,11,10,10,10,11,10,10,10,11,0,0,0,0,0
0,0,0,0,0,0,11,10,10,10,11,10,10,10,11,0,0,0,0,0
0,0,0,0,0,0,11,10,10,10,11,10,10,10,11,0,0,0,0,0
0,0,0,0,0,7,2,9,9,9,2,9,9,9,2,7,0,0,0,0
0,0,0,0,0,6,6,6,6,6,6,6,6,6,6,6,0,0,0,0
0,0,0,0,0,0,0,0,0,0,0,0,0,0,0,0,0,0,0,0
:endlayer
layer: 6
0,0,0,0,0,0,0,0,0,0,0,0,0,0,0,0,0,0,0,0
0,0,0,0,0,0,0,0,0,0,0,0,0,0,0,0,0,0,0,0
0,0,0,0,0,18,18,18,18,18,18,18,18,18,18,18,0,0,0,0
0,0,0,0,0,17,2,9,9,9,2,9,9,9,2,17,0,0,0,0
0,0,0,0,0,0,13,0,0,0,0,0,19,0,13,0,0,0,0,0
0,0,0,0,0,0,13,0,0,0,0,0,19,0,13,0,0,0,0,0
0,0,0,0,0,0,2,0,0,0,2,0,19,0,2,0,0,0,0,0
0,0,0,0,0,0,13,27,0,0,0,0,0,0,13,0,0,0,0,0
0,0,0,0,0,0,13,0,0,0,0,0,0,0,13,0,0,0,0,0
0,0,0,0,0,0,13,0,0,0,0,0,0,0,13,0,0,0,0,0
0,0,0,0,0,0,2,0,0,0,2,0,0,0,2,0,0,0,0,0
0,0,0,0,0,0,13,0,0,0,0,0,0,0,13,0,0,0,0,0
0,0,0,0,0,0,13,0,0,0,0,0,0,0,13,0,0,0,0,0
0,0,0,0,0,7,2,9,9,9,2,9,9,9,2,7,0,0,0,0
0,0,0,0,0,6,6,6,6,6,6,6,6,6,6,6,0,0,0,0
0,0,0,0,0,0,0,0,0,0,0,0,0,0,0,0,0,0,0,0
0,0,0,0,0,0,0,0,0,0,0,0,0,0,0,0,0,0,0,0
:endlayer
layer: 7
0,0,0,0,0,0,0,0,0,0,0,0,0,0,0,0,0,0,0,0
0,0,0,0,0,0,0,0,0,0,0,0,0,0,0,0,0,0,0,0
0,0,0,0,0,0,0,0,0,0,0,0,0,0,0,0,0,0,0,0
0,0,0,0,0,18,18,18,18,18,18,18,18,18,18,18,0,0,0,0
0,0,0,0,0,17,2,9,9,9,2,9,9,9,2,17,0,0,0,0
0,0,0,0,0,0,13,0,0,0,0,0,0,0,13,0,0,0,0,0
0,0,0,0,0,0,2,0,0,0,2,0,0,0,2,0,0,0,0,0
0,0,0,0,0,0,13,27,0,0,0,0,0,0,13,0,0,0,0,0
0,0,0,0,0,0,19,0,0,0,0,0,0,0,19,0,0,0,0,0
0,0,0,0,0,0,13,0,0,0,0,0,0,0,13,0,0,0,0,0
0,0,0,0,0,0,2,0,0,0,2,0,0,0,2,0,0,0,0,0
0,0,0,0,0,0,13,0,0,0,0,0,0,0,13,0,0,0,0,0
0,0,0,0,0,7,2,9,9,9,2,9,9,9,2,7,0,0,0,0
0,0,0,0,0,6,6,6,6,6,6,6,6,6,6,6,0,0,0,0
0,0,0,0,0,0,0,0,0,0,0,0,0,0,0,0,0,0,0,0
0,0,0,0,0,0,0,0,0,0,0,0,0,0,0,0,0,0,0,0
0,0,0,0,0,0,0,0,0,0,0,0,0,0,0,0,0,0,0,0
:endlayer
layer: 8
0,0,0,0,0,0,0,0,0,0,0,0,0,0,0,0,0,0,0,0
0,0,0,0,0,0,0,0,0,0,0,0,0,0,0,0,0,0,0,0
0,0,0,0,0,0,0,0,0,0,0,0,0,0,0,0,0,0,0,0
0,0,0,0,0,0,0,0,0,0,0,0,0,0,0,0,0,0,0,0
0,0,0,0,0,18,18,18,18,18,18,18,18,18,18,18,0,0,0,0
0,0,0,0,0,17,2,9,9,9,2,9,9,9,2,17,0,0,0,0
0,0,0,0,0,0,2,23,0,24,2,23,0,24,2,0,0,0,0,0
0,0,0,0,0,0,13,27,0,0,26,0,0,0,13,0,0,0,0,0
0,0,0,0,0,0,19,0,0,0,0,0,0,0,19,0,0,0,0,0
0,0,0,0,0,0,13,0,0,0,25,0,0,0,13,0,0,0,0,0
0,0,0,0,0,0,2,23,0,24,2,23,0,24,2,0,0,0,0,0
0,0,0,0,0,7,2,9,9,9,2,9,9,9,2,7,0,0,0,0
0,0,0,0,0,6,6,6,6,6,6,6,6,6,6,6,0,0,0,0
0,0,0,0,0,0,0,0,0,0,0,0,0,0,0,0,0,0,0,0
0,0,0,0,0,0,0,0,0,0,0,0,0,0,0,0,0,0,0,0
0,0,0,0,0,0,0,0,0,0,0,0,0,0,0,0,0,0,0,0
0,0,0,0,0,0,0,0,0,0,0,0,0,0,0,0,0,0,0,0
:endlayer
layer: 9
0,0,0,0,0,0,0,0,0,0,0,0,0,0,0,0,0,0,0,0
0,0,0,0,0,0,0,0,0,0,0,0,0,0,0,0,0,0,0,0
0,0,0,0,0,0,0,0,0,0,0,0,0,0,0,0,0,0,0,0
0,0,0,0,0,0,0,0,0,0,0,0,0,0,0,0,0,0,0,0
0,0,0,0,0,0,0,0,0,0,0,0,0,0,0,0,0,0,0,0
0,0,0,0,0,18,18,18,18,18,18,18,18,18,18,18,0,0,0,0
0,0,0,0,0,17,2,9,9,9,2,9,9,9,2,17,0,0,0,0
0,0,0,0,0,0,11,27,10,10,11,0,0,0,11,0,0,0,0,0
0,0,0,0,0,0,11,10,10,10,11,0,0,0,11,0,0,0,0,0
0,0,0,0,0,0,11,10,10,10,11,0,0,0,11,0,0,0,0,0
0,0,0,0,0,7,2,9,9,9,2,9,9,9,2,7,0,0,0,0
0,0,0,0,0,6,6,6,6,6,6,6,6,6,6,6,0,0,0,0
0,0,0,0,0,0,0,0,0,0,0,0,0,0,0,0,0,0,0,0
0,0,0,0,0,0,0,0,0,0,0,0,0,0,0,0,0,0,0,0
0,0,0,0,0,0,0,0,0,0,0,0,0,0,0,0,0,0,0,0
0,0,0,0,0,0,0,0,0,0,0,0,0,0,0,0,0,0,0,0
0,0,0,0,0,0,0,0,0,0,0,0,0,0,0,0,0,0,0,0
:endlayer
layer: 10
0,0,0,0,0,0,0,0,0,0,0,0,0,0,0,0,0,0,0,0
0,0,0,0,0,0,0,0,0,0,0,0,0,0,0,0,0,0,0,0
0,0,0,0,0,0,0,0,0,0,0,0,0,0,0,0,0,0,0,0
0,0,0,0,0,0,0,0,0,0,0,0,0,0,0,0,0,0,0,0
0,0,0,0,0,0,0,0,0,0,0,0,0,0,0,0,0,0,0,0
0,0,0,0,0,0,0,0,0,0,0,0,0,0,0,0,0,0,0,0
0,0,0,0,0,28,2,13,13,13,2,18,18,18,18,18,0,0,0,0
0,0,0,0,0,29,13,27,0,0,2,9,9,9,2,17,0,0,0,0
0,0,0,0,0,29,13,0,0,0,0,0,0,0,13,0,0,0,0,0
0,0,0,0,0,29,13,0,0,0,2,9,9,9,2,7,0,0,0,0
0,0,0,0,0,28,2,13,13,13,2,6,6,6,6,6,0,0,0,0
0,0,0,0,0,0,0,0,0,0,0,0,0,0,0,0,0,0,0,0
0,0,0,0,0,0,0,0,0,0,0,0,0,0,0,0,0,0,0,0
0,0,0,0,0,0,0,0,0,0,0,0,0,0,0,0,0,0,0,0
0,0,0,0,0,0,0,0,0,0,0,0,0,0,0,0,0,0,0,0
0,0,0,0,0,0,0,0,0,0,0,0,0,0,0,0,0,0,0,0
0,0,0,0,0,0,0,0,0,0,0,0,0,0,0,0,0,0,0,0
:endlayer
layer: 11
0,0,0,0,0,0,0,0,0,0,0,0,0,0,0,0,0,0,0,0
0,0,0,0,0,0,0,0,0,0,0,0,0,0,0,0,0,0,0,0
0,0,0,0,0,0,0,0,0,0,0,0,0,0,0,0,0,0,0,0
0,0,0,0,0,0,0,0,0,0,0,0,0,0,0,0,0,0,0,0
0,0,0,0,0,0,0,0,0,0,0,0,0,0,0,0,0,0,0,0
0,0,0,0,0,0,25,0,0,0,25,0,0,0,0,0,0,0,0,0
0,0,0,0,0,14,2,13,19,13,2,0,0,0,0,0,0,0,0,0
0,0,0,0,0,0,13,27,0,0,13,18,18,18,18,18,0,0,0,0
0,0,0,0,0,0,19,0,0,0,2,9,9,9,2,30,0,0,0,0
0,0,0,0,0,0,13,0,0,0,13,6,6,6,6,6,0,0,0,0
0,0,0,0,0,14,2,13,19,13,2,0,0,0,0,0,0,0,0,0
0,0,0,0,0,0,26,0,0,0,26,0,0,0,0,0,0,0,0,0
0,0,0,0,0,0,0,0,0,0,0,0,0,0,0,0,0,0,0,0
0,0,0,0,0,0,0,0,0,0,0,0,0,0,0,0,0,0,0,0
0,0,0,0,0,0,0,0,0,0,0,0,0,0,0,0,0,0,0,0
0,0,0,0,0,0,0,0,0,0,0,0,0,0,0,0,0,0,0,0
0,0,0,0,0,0,0,0,0,0,0,0,0,0,0,0,0,0,0,0
:endlayer
layer: 12
0,0,0,0,0,0,0,0,0,0,0,0,0,0,0,0,0,0,0,0
0,0,0,0,0,0,0,0,0,0,0,0,0,0,0,0,0,0,0,0
0,0,0,0,0,0,0,0,0,0,0,0,0,0,0,0,0,0,0,0
0,0,0,0,0,0,0,0,0,0,0,0,0,0,0,0,0,0,0,0
0,0,0,0,0,0,0,0,0,0,0,0,0,0,0,0,0,0,0,0
0,0,0,0,0,10,7,10,0,10,7,10,0,0,0,0,0,0,0,0
0,0,0,0,0,14,2,13,19,13,2,0,0,0,0,0,0,0,0,0
0,0,0,0,0,0,13,27,0,0,13,0,0,0,0,0,0,0,0,0
0,0,0,0,0,0,19,0,0,0,13,29,29,29,29,29,0,0,0,0
0,0,0,0,0,0,13,0,0,0,13,0,0,0,0,0,0,0,0,0
0,0,0,0,0,14,2,13,19,13,2,0,0,0,0,0,0,0,0,0
0,0,0,0,0,10,17,10,0,10,17,10,0,0,0,0,0,0,0,0
0,0,0,0,0,0,0,0,0,0,0,0,0,0,0,0,0,0,0,0
0,0,0,0,0,0,0,0,0,0,0,0,0,0,0,0,0,0,0,0
0,0,0,0,0,0,0,0,0,0,0,0,0,0,0,0,0,0,0,0
0,0,0,0,0,0,0,0,0,0,0,0,0,0,0,0,0,0,0,0
0,0,0,0,0,0,0,0,0,0,0,0,0,0,0,0,0,0,0,0
:endlayer
layer: 13
0,0,0,0,0,0,0,0,0,0,0,0,0,0,0,0,0,0,0,0
0,0,0,0,0,0,0,0,0,0,0,0,0,0,0,0,0,0,0,0
0,0,0,0,0,0,0,0,0,0,0,0,0,0,0,0,0,0,0,0
0,0,0,0,0,0,0,0,0,0,0,0,0,0,0,0,0,0,0,0
0,0,0,0,0,0,0,0,0,0,0,0,0,0,0,0,0,0,0,0
0,0,0,0,0,18,18,18,18,18,18,18,0,0,0,0,0,0,0,0
0,0,0,0,0,17,2,9,9,9,2,17,0,0,0,0,0,0,0,0
0,0,0,0,0,0,11,0,26,0,11,0,0,0,0,0,0,0,0,0
0,0,0,0,0,0,11,23,0,24,11,0,0,0,0,0,0,0,0,0
0,0,0,0,0,0,11,0,25,0,11,0,0,0,0,0,0,0,0,0
0,0,0,0,0,7,2,9,9,9,2,7,0,0,0,0,0,0,0,0
0,0,0,0,0,6,6,6,6,6,6,6,0,0,0,0,0,0,0,0
0,0,0,0,0,0,0,0,0,0,0,0,0,0,0,0,0,0,0,0
0,0,0,0,0,0,0,0,0,0,0,0,0,0,0,0,0,0,0,0
0,0,0,0,0,0,0,0,0,0,0,0,0,0,0,0,0,0,0,0
0,0,0,0,0,0,0,0,0,0,0,0,0,0,0,0,0,0,0,0
0,0,0,0,0,0,0,0,0,0,0,0,0,0,0,0,0,0,0,0
:endlayer
layer: 14
0,0,0,0,0,0,0,0,0,0,0,0,0,0,0,0,0,0,0,0
0,0,0,0,0,0,0,0,0,0,0,0,0,0,0,0,0,0,0,0
0,0,0,0,0,0,0,0,0,0,0,0,0,0,0,0,0,0,0,0
0,0,0,0,0,0,0,0,0,0,0,0,0,0,0,0,0,0,0,0
0,0,0,0,0,0,0,0,0,0,0,0,0,0,0,0,0,0,0,0
0,0,0,0,0,0,0,0,0,0,0,0,0,0,0,0,0,0,0,0
0,0,0,0,0,18,18,18,18,18,18,18,0,0,0,0,0,0,0,0
0,0,0,0,0,17,2,9,9,9,2,17,0,0,0,0,0,0,0,0
0,0,0,0,0,0,13,0,0,0,13,0,0,0,0,0,0,0,0,0
0,0,0,0,0,7,2,9,9,9,2,7,0,0,0,0,0,0,0,0
0,0,0,0,0,6,6,6,6,6,6,6,0,0,0,0,0,0,0,0
0,0,0,0,0,0,0,0,0,0,0,0,0,0,0,0,0,0,0,0
0,0,0,0,0,0,0,0,0,0,0,0,0,0,0,0,0,0,0,0
0,0,0,0,0,0,0,0,0,0,0,0,0,0,0,0,0,0,0,0
0,0,0,0,0,0,0,0,0,0,0,0,0,0,0,0,0,0,0,0
0,0,0,0,0,0,0,0,0,0,0,0,0,0,0,0,0,0,0,0
0,0,0,0,0,0,0,0,0,0,0,0,0,0,0,0,0,0,0,0
:endlayer
layer: 15
0,0,0,0,0,0,0,0,0,0,0,0,0,0,0,0,0,0,0,0
0,0,0,0,0,0,0,0,0,0,0,0,0,0,0,0,0,0,0,0
0,0,0,0,0,0,0,0,0,0,0,0,0,0,0,0,0,0,0,0
0,0,0,0,0,0,0,0,0,0,0,0,0,0,0,0,0,0,0,0
0,0,0,0,0,0,0,0,0,0,0,0,0,0,0,0,0,0,0,0
0,0,0,0,0,0,0,0,0,0,0,0,0,0,0,0,0,0,0,0
0,0,0,0,0,0,0,0,0,0,0,0,0,0,0,0,0,0,0,0
0,0,0,0,0,18,18,18,18,18,18,18,0,0,0,0,0,0,0,0
0,0,0,0,0,31,2,9,9,9,2,30,0,0,0,0,0,0,0,0
0,0,0,0,0,6,6,6,6,6,6,6,0,0,0,0,0,0,0,0
0,0,0,0,0,0,0,0,0,0,0,0,0,0,0,0,0,0,0,0
0,0,0,0,0,0,0,0,0,0,0,0,0,0,0,0,0,0,0,0
0,0,0,0,0,0,0,0,0,0,0,0,0,0,0,0,0,0,0,0
0,0,0,0,0,0,0,0,0,0,0,0,0,0,0,0,0,0,0,0
0,0,0,0,0,0,0,0,0,0,0,0,0,0,0,0,0,0,0,0
0,0,0,0,0,0,0,0,0,0,0,0,0,0,0,0,0,0,0,0
0,0,0,0,0,0,0,0,0,0,0,0,0,0,0,0,0,0,0,0
:endlayer
layer: 16
0,0,0,0,0,0,0,0,0,0,0,0,0,0,0,0,0,0,0,0
0,0,0,0,0,0,0,0,0,0,0,0,0,0,0,0,0,0,0,0
0,0,0,0,0,0,0,0,0,0,0,0,0,0,0,0,0,0,0,0
0,0,0,0,0,0,0,0,0,0,0,0,0,0,0,0,0,0,0,0
0,0,0,0,0,0,0,0,0,0,0,0,0,0,0,0,0,0,0,0
0,0,0,0,0,0,0,0,0,0,0,0,0,0,0,0,0,0,0,0
0,0,0,0,0,0,0,0,0,0,0,0,0,0,0,0,0,0,0,0
0,0,0,0,0,0,0,0,0,0,0,0,0,0,0,0,0,0,0,0
0,0,0,0,0,29,29,29,29,29,29,29,0,0,0,0,0,0,0,0
0,0,0,0,0,0,0,0,0,0,0,0,0,0,0,0,0,0,0,0
0,0,0,0,0,0,0,0,0,0,0,0,0,0,0,0,0,0,0,0
0,0,0,0,0,0,0,0,0,0,0,0,0,0,0,0,0,0,0,0
0,0,0,0,0,0,0,0,0,0,0,0,0,0,0,0,0,0,0,0
0,0,0,0,0,0,0,0,0,0,0,0,0,0,0,0,0,0,0,0
0,0,0,0,0,0,0,0,0,0,0,0,0,0,0,0,0,0,0,0
0,0,0,0,0,0,0,0,0,0,0,0,0,0,0,0,0,0,0,0
0,0,0,0,0,0,0,0,0,0,0,0,0,0,0,0,0,0,0,0
:endlayer

#### RULES ####
rule:
plugin=vanillaBlocks
number=1
data:
JSON:{blockState:{blockName:"minecraft:ladder",properties:{facing:"south"}}}
:enddata
:endrule

rule:
plugin=vanillaBlocks
number=2
data:
JSON:{blockState:{blockName:"minecraft:log",properties:{variant:"spruce",axis:"y"}}}
:enddata
:endrule

rule:
plugin=vanillaBlocks
number=3
data:
JSON:{blockState:{blockName:"minecraft:cobblestone"}}
:enddata
:endrule

rule:
plugin=vanillaBlocks
number=4
data:
JSON:{blockState:{blockName:"minecraft:ladder",properties:{facing:"west"}}}
:enddata
:endrule

rule:
plugin=vanillaBlocks
number=5
data:
JSON:{blockState:{blockName:"minecraft:dirt",properties:{variant:"dirt",snowy:"false"}}}
:enddata
:endrule

rule:
plugin=vanillaBlocks
number=6
data:
JSON:{blockState:{blockName:"minecraft:spruce_stairs",properties:{half:"bottom",shape:"straight",facing:"north"}}}
:enddata
:endrule

rule:
plugin=vanillaBlocks
number=7
data:
JSON:{blockState:{blockName:"minecraft:spruce_stairs",properties:{half:"top",shape:"straight",facing:"south"}}}
:enddata
:endrule

rule:
plugin=vanillaBlocks
number=8
data:
JSON:{blockState:{blockName:"minecraft:ladder",properties:{facing:"north"}}}
:enddata
:endrule

rule:
plugin=vanillaBlocks
number=9
data:
JSON:{blockState:{blockName:"minecraft:log",properties:{variant:"spruce",axis:"x"}}}
:enddata
:endrule

rule:
plugin=vanillaBlocks
number=10
data:
JSON:{blockState:{blockName:"minecraft:wooden_slab",properties:{half:"top",variant:"spruce"}}}
:enddata
:endrule

rule:
plugin=vanillaBlocks
number=11
data:
JSON:{blockState:{blockName:"minecraft:log",properties:{variant:"spruce",axis:"z"}}}
:enddata
:endrule

rule:
plugin=vanillaBlocks
number=12
data:
JSON:{blockState:{blockName:"minecraft:planks",properties:{variant:"spruce"}}}
:enddata
:endrule

rule:
plugin=vanillaBlocks
number=13
data:
JSON:{blockState:{blockName:"minecraft:planks",properties:{variant:"oak"}}}
:enddata
:endrule

rule:
plugin=vanillaBlocks
number=14
data:
JSON:{blockState:{blockName:"minecraft:spruce_fence",properties:{east:"false",south:"false",north:"false",west:"false"}}}
:enddata
:endrule

rule:
plugin=doors
number=15
data:
JSON:{blockState:{blockName:"minecraft:spruce_door",properties:{hinge:"left",half:"lower",powered:"false",facing:"west",open:"false"}}}
:enddata
:endrule

rule:
plugin=doors
number=16
data:
JSON:{blockState:{blockName:"minecraft:spruce_door",properties:{hinge:"left",half:"lower",powered:"false",facing:"east",open:"false"}}}
:enddata
:endrule

rule:
plugin=vanillaBlocks
number=17
data:
JSON:{blockState:{blockName:"minecraft:spruce_stairs",properties:{half:"top",shape:"straight",facing:"north"}}}
:enddata
:endrule

rule:
plugin=vanillaBlocks
number=18
data:
JSON:{blockState:{blockName:"minecraft:spruce_stairs",properties:{half:"bottom",shape:"straight",facing:"south"}}}
:enddata
:endrule

rule:
plugin=vanillaBlocks
number=19
data:
JSON:{blockState:{blockName:"minecraft:acacia_fence",properties:{east:"false",south:"false",north:"false",west:"false"}}}
:enddata
:endrule

rule:
plugin=vanillaBlocks
number=20
data:
JSON:{blockState:{blockName:"minecraft:torch",properties:{facing:"up"}}}
:enddata
:endrule

rule:
plugin=doors
number=21
data:
JSON:{blockState:{blockName:"minecraft:spruce_door",properties:{hinge:"left",half:"upper",powered:"false",facing:"south",open:"false"}}}
:enddata
:endrule

rule:
plugin=doors
number=22
data:
JSON:{blockState:{blockName:"minecraft:spruce_door",properties:{hinge:"right",half:"upper",powered:"false",facing:"south",open:"false"}}}
:enddata
:endrule

rule:
plugin=vanillaBlocks
number=23
data:
JSON:{blockState:{blockName:"minecraft:torch",properties:{facing:"east"}}}
:enddata
:endrule

rule:
plugin=vanillaBlocks
number=24
data:
JSON:{blockState:{blockName:"minecraft:torch",properties:{facing:"west"}}}
:enddata
:endrule

rule:
plugin=vanillaBlocks
number=25
data:
JSON:{blockState:{blockName:"minecraft:torch",properties:{facing:"north"}}}
:enddata
:endrule

rule:
plugin=vanillaBlocks
number=26
data:
JSON:{blockState:{blockName:"minecraft:torch",properties:{facing:"south"}}}
:enddata
:endrule

rule:
plugin=vanillaBlocks
number=27
data:
JSON:{blockState:{blockName:"minecraft:ladder",properties:{facing:"east"}}}
:enddata
:endrule

rule:
plugin=vanillaBlocks
number=28
data:
JSON:{blockState:{blockName:"minecraft:spruce_stairs",properties:{half:"bottom",shape:"straight",facing:"east"}}}
:enddata
:endrule

rule:
plugin=vanillaBlocks
number=29
data:
JSON:{blockState:{blockName:"minecraft:wooden_slab",properties:{half:"bottom",variant:"spruce"}}}
:enddata
:endrule

rule:
plugin=vanillaBlocks
number=30
data:
JSON:{blockState:{blockName:"minecraft:spruce_stairs",properties:{half:"top",shape:"straight",facing:"west"}}}
:enddata
:endrule

rule:
plugin=vanillaBlocks
number=31
data:
JSON:{blockState:{blockName:"minecraft:spruce_stairs",properties:{half:"top",shape:"straight",facing:"east"}}}
:enddata
:endrule

#### ENTITIES ####
