# Ancient Warfare Structure Template File
# Auto-generated structure template file. created on: 6/4/2021 at: 17:12:43
# Lines beginning with # denote comments

header:
version=2.11
name=SB_MinoakaCol_House_1H2R_1
mods=
size=16,11,13
offset=11,1,12
:endheader

#### VALIDATION ####
validation:
type=ground
structureAuthor=theoddlyseagull
survival=true
worldGenEnabled=false
unique=false
preserveBlocks=false
preventNaturalHostileSpawns=false
selectionWeight=1
clusterValue=1
minDuplicateDistance=1
dimensionWhiteList=true
dimensionList=
biomeGroupList=
biomeWhiteList=true
biomeList=
leveling=0
fill=0
border=0
blockSwap=false
territoryName=
biomeReplacement=minecraft:
minGenerationHeight=0
maxGenerationHeight=255
:endvalidation

#### LAYERS ####
layer: 0
1,1,1,1,1,1,1,1,1,1,1,1,1,1,1,1
1,1,1,2,2,2,2,2,2,2,2,2,1,1,1,1
1,1,1,2,2,2,2,2,2,2,2,2,1,1,1,1
1,1,1,2,2,2,2,2,2,2,2,2,1,1,1,1
1,1,1,2,2,2,2,2,2,2,2,2,2,2,2,1
1,2,2,2,2,2,2,2,2,2,2,2,2,2,2,2
2,2,2,2,2,2,2,2,2,2,2,2,2,2,2,2
2,2,2,2,2,2,2,2,2,2,2,2,2,2,2,2
2,2,2,2,2,2,2,2,2,2,2,2,2,2,2,1
1,2,2,2,2,2,2,2,2,2,2,2,2,2,2,1
1,1,1,1,1,1,1,2,2,2,2,2,2,2,2,1
1,1,1,1,1,1,1,2,2,2,2,2,2,2,2,1
1,1,1,1,1,1,1,1,1,1,2,2,1,1,1,1
:endlayer
layer: 1
0,0,0,0,0,0,0,0,0,0,0,0,0,0,0,0
0,0,0,3,5,5,5,3,5,5,5,3,0,0,0,0
0,0,0,5,0,0,0,0,0,0,0,5,0,0,0,0
0,0,0,5,0,0,0,0,0,0,0,5,0,0,0,0
0,0,0,5,0,0,0,3,5,0,5,3,5,5,3,0
0,3,5,3,5,5,5,3,0,0,0,0,0,8,2,2
2,2,6,0,0,0,0,5,0,0,0,0,0,7,4,2
2,4,7,0,0,0,0,0,0,0,0,0,0,8,2,2
2,2,6,0,0,0,0,5,0,0,0,0,0,0,3,0
0,3,5,3,5,5,5,3,0,0,0,0,0,0,5,0
0,0,0,0,0,0,0,5,0,0,0,0,0,0,5,0
0,0,0,0,0,0,0,3,5,3,0,0,3,5,3,0
0,0,0,0,0,0,0,0,0,0,0,0,0,0,0,0
:endlayer
layer: 2
0,0,0,10,0,0,0,0,0,0,0,10,0,0,0,0
0,0,0,3,5,9,5,3,5,9,5,3,0,0,0,0
0,0,0,5,0,0,0,0,0,0,0,5,0,0,0,0
0,0,0,9,0,0,0,0,0,0,0,5,0,0,0,0
0,0,0,5,0,0,0,3,5,0,5,3,5,5,3,0
0,3,5,3,5,5,5,3,0,0,0,0,0,0,2,2
2,2,0,0,0,0,0,5,0,0,0,0,0,0,0,2
2,0,0,0,0,0,0,0,0,0,0,0,0,0,2,2
2,2,0,0,0,0,0,5,0,0,0,0,0,0,3,0
0,3,5,3,5,9,5,3,0,0,0,0,0,0,9,0
0,0,0,0,0,0,0,5,0,0,0,0,0,0,9,0
0,0,0,0,0,0,0,3,5,3,0,0,3,5,3,0
0,0,0,0,0,0,0,0,0,11,0,0,11,0,0,0
:endlayer
layer: 3
0,0,15,15,15,15,15,15,15,15,15,15,15,0,0,0
0,0,15,3,18,18,18,18,18,18,18,3,15,0,0,0
0,0,0,16,0,0,0,0,0,0,0,16,0,0,0,0
0,0,0,16,0,0,0,0,0,10,0,16,0,0,0,0
0,0,0,16,17,10,19,3,5,5,5,3,5,5,3,0
0,3,5,3,5,5,5,3,20,0,0,0,0,0,2,13
13,2,0,0,0,0,0,5,0,0,0,0,0,0,21,2
2,14,0,0,0,0,0,5,0,0,0,0,0,0,2,12
12,2,0,0,0,0,0,5,0,0,0,0,0,0,3,0
0,3,5,3,5,9,5,3,0,0,0,0,0,0,9,0
0,0,0,0,0,0,0,5,0,10,0,0,10,0,9,0
0,0,0,0,0,0,0,3,5,3,5,5,3,5,3,0
0,0,0,0,0,0,0,0,0,15,0,0,15,0,0,0
:endlayer
layer: 4
0,0,0,0,0,0,0,0,0,0,0,0,0,0,0,0
0,0,27,27,27,27,27,27,27,27,27,27,27,0,0,0
0,0,26,26,26,26,26,26,26,26,26,26,26,0,0,0
0,0,15,5,26,26,26,26,26,26,26,5,15,0,31,32
25,25,26,26,26,26,26,3,18,18,18,18,18,18,3,32
24,3,18,18,18,18,18,16,0,0,0,0,0,0,16,32
0,16,14,0,0,0,0,16,0,0,0,0,0,0,16,2
2,16,14,0,0,0,29,16,0,0,0,0,0,0,16,32
0,16,14,0,0,0,0,16,0,0,0,0,0,0,16,32
23,3,18,18,18,18,18,16,0,0,0,0,0,0,16,32
22,22,22,22,22,22,22,16,0,0,0,0,0,0,16,32
0,0,0,0,0,0,28,3,18,18,18,18,18,18,3,32
0,0,0,0,0,0,28,30,0,0,27,27,0,0,31,32
:endlayer
layer: 5
0,0,0,0,0,0,0,0,0,0,0,0,0,0,0,0
0,0,0,0,0,0,0,0,0,0,0,0,0,0,0,0
0,0,0,0,0,35,0,0,0,35,0,0,0,0,0,0
0,0,27,27,27,27,27,28,26,27,27,27,27,31,32,0
0,0,0,0,0,35,0,28,5,5,5,5,5,5,32,0
25,25,25,25,25,25,25,28,17,0,0,0,0,19,32,0
24,5,2,34,34,34,34,5,17,0,0,0,0,19,32,2
2,2,2,0,0,0,0,5,17,0,0,0,0,19,32,0
23,5,2,33,33,33,33,5,17,0,0,0,0,19,32,0
22,22,22,22,22,22,22,22,17,0,0,0,0,19,32,0
0,0,0,0,0,0,0,28,17,0,0,0,0,19,32,0
0,0,0,0,0,0,0,28,5,5,5,5,5,5,32,0
0,0,0,0,0,0,0,28,30,0,0,0,0,31,32,0
:endlayer
layer: 6
0,0,0,0,0,0,0,0,0,0,0,0,0,0,0,0
0,0,0,0,0,0,0,0,0,0,0,0,0,0,0,0
0,0,0,0,0,0,0,0,0,0,0,0,0,0,0,0
0,0,0,0,0,0,0,0,28,30,15,15,31,32,0,0
0,0,0,0,0,0,0,0,28,5,5,5,5,32,0,0
0,0,0,0,0,0,0,0,28,17,0,0,19,32,0,0
28,25,25,25,25,25,25,25,28,17,0,0,19,32,0,2
2,18,18,18,18,18,18,5,5,17,0,0,19,32,0,0
28,22,22,22,22,22,22,22,22,17,0,0,19,32,0,0
0,0,0,0,0,0,0,0,28,17,0,0,19,32,0,0
0,0,0,0,0,0,0,0,28,17,0,0,19,32,0,0
0,0,0,0,0,0,0,0,28,5,5,5,5,32,0,0
0,0,0,0,0,0,0,0,28,30,15,15,31,32,0,0
:endlayer
layer: 7
0,0,0,0,0,0,0,0,0,0,0,0,0,0,0,0
0,0,0,0,0,0,0,0,0,0,0,0,0,0,0,0
0,0,0,0,0,0,0,0,0,0,0,0,0,0,0,0
0,0,0,0,0,0,0,0,0,28,25,25,32,0,0,0
0,0,0,0,0,0,0,0,0,28,5,5,32,0,0,0
0,0,0,0,0,0,0,0,0,28,17,19,32,0,0,0
0,0,0,0,0,0,0,0,0,28,17,19,32,0,0,2
2,27,27,27,27,27,27,27,27,28,17,19,32,0,0,0
0,0,0,0,0,0,0,0,0,28,17,19,32,0,0,0
0,0,0,0,0,0,0,0,0,28,17,19,32,0,0,0
0,0,0,0,0,0,0,0,0,28,17,19,32,0,0,0
0,0,0,0,0,0,0,0,0,28,5,5,32,0,0,0
0,0,0,0,0,0,0,0,0,28,22,22,32,0,0,0
:endlayer
layer: 8
0,0,0,0,0,0,0,0,0,0,0,0,0,0,0,0
0,0,0,0,0,0,0,0,0,0,0,0,0,0,0,0
0,0,0,0,0,0,0,0,0,0,0,0,0,0,0,0
0,0,0,0,0,0,0,0,0,0,0,0,0,0,0,0
0,0,0,0,0,0,0,0,0,0,25,25,0,0,0,0
0,0,0,0,0,0,0,0,0,0,28,32,0,0,0,0
0,0,0,0,0,0,0,0,0,0,28,32,0,0,0,2
36,0,0,0,0,0,0,0,0,0,28,32,0,0,0,0
0,0,0,0,0,0,0,0,0,0,28,32,0,0,0,0
0,0,0,0,0,0,0,0,0,0,28,32,0,0,0,0
0,0,0,0,0,0,0,0,0,0,28,32,0,0,0,0
0,0,0,0,0,0,0,0,0,0,22,22,0,0,0,0
0,0,0,0,0,0,0,0,0,0,0,0,0,0,0,0
:endlayer
layer: 9
0,0,0,0,0,0,0,0,0,0,0,0,0,0,0,0
0,0,0,0,0,0,0,0,0,0,0,0,0,0,0,0
0,0,0,0,0,0,0,0,0,0,0,0,0,0,0,0
0,0,0,0,0,0,0,0,0,0,0,0,0,0,0,0
0,0,0,0,0,0,0,0,0,0,0,0,0,0,0,0
0,0,0,0,0,0,0,0,0,0,0,0,0,0,0,0
0,0,0,0,0,0,0,0,0,0,0,0,0,0,0,36
7,0,0,0,0,0,0,0,0,0,0,0,0,0,0,0
0,0,0,0,0,0,0,0,0,0,0,0,0,0,0,0
0,0,0,0,0,0,0,0,0,0,0,0,0,0,0,0
0,0,0,0,0,0,0,0,0,0,0,0,0,0,0,0
0,0,0,0,0,0,0,0,0,0,0,0,0,0,0,0
0,0,0,0,0,0,0,0,0,0,0,0,0,0,0,0
:endlayer
layer: 10
0,0,0,0,0,0,0,0,0,0,0,0,0,0,0,0
0,0,0,0,0,0,0,0,0,0,0,0,0,0,0,0
0,0,0,0,0,0,0,0,0,0,0,0,0,0,0,0
0,0,0,0,0,0,0,0,0,0,0,0,0,0,0,0
0,0,0,0,0,0,0,0,0,0,0,0,0,0,0,0
0,0,0,0,0,0,0,0,0,0,0,0,0,0,0,0
0,0,0,0,0,0,0,0,0,0,0,0,0,0,0,7
0,0,0,0,0,0,0,0,0,0,0,0,0,0,0,0
0,0,0,0,0,0,0,0,0,0,0,0,0,0,0,0
0,0,0,0,0,0,0,0,0,0,0,0,0,0,0,0
0,0,0,0,0,0,0,0,0,0,0,0,0,0,0,0
0,0,0,0,0,0,0,0,0,0,0,0,0,0,0,0
0,0,0,0,0,0,0,0,0,0,0,0,0,0,0,0
:endlayer

#### RULES ####
rule:
plugin=vanillaBlocks
number=1
data:
JSON:{blockState:{blockName:"minecraft:grass",properties:{snowy:"false"}}}
:enddata
:endrule

rule:
plugin=vanillaBlocks
number=2
data:
JSON:{blockState:{blockName:"minecraft:cobblestone"}}
:enddata
:endrule

rule:
plugin=vanillaBlocks
number=3
data:
JSON:{blockState:{blockName:"minecraft:log",properties:{variant:"oak",axis:"y"}}}
:enddata
:endrule

rule:
plugin=vanillaBlocks
number=4
data:
JSON:{blockState:{blockName:"ancientwarfarestructure:fire_pit",properties:{lit:"true",variant:"log"}}}
:enddata
:endrule

rule:
plugin=vanillaBlocks
number=5
data:
JSON:{blockState:{blockName:"minecraft:planks",properties:{variant:"oak"}}}
:enddata
:endrule

rule:
plugin=vanillaBlocks
number=6
data:
JSON:{blockState:{blockName:"minecraft:stone_stairs",properties:{half:"bottom",shape:"straight",facing:"west"}}}
:enddata
:endrule

rule:
plugin=vanillaBlocks
number=7
data:
JSON:{blockState:{blockName:"minecraft:stone_slab",properties:{half:"bottom",variant:"cobblestone"}}}
:enddata
:endrule

rule:
plugin=vanillaBlocks
number=8
data:
JSON:{blockState:{blockName:"minecraft:stone_stairs",properties:{half:"bottom",shape:"straight",facing:"east"}}}
:enddata
:endrule

rule:
plugin=vanillaBlocks
number=9
data:
JSON:{blockState:{blockName:"minecraft:stained_glass_pane",properties:{east:"false",color:"green",south:"false",north:"false",west:"false"}}}
:enddata
:endrule

rule:
plugin=vanillaBlocks
number=10
data:
JSON:{blockState:{blockName:"minecraft:torch",properties:{facing:"north"}}}
:enddata
:endrule

rule:
plugin=vanillaBlocks
number=11
data:
JSON:{blockState:{blockName:"minecraft:torch",properties:{facing:"south"}}}
:enddata
:endrule

rule:
plugin=vanillaBlocks
number=12
data:
JSON:{blockState:{blockName:"minecraft:stone_stairs",properties:{half:"bottom",shape:"straight",facing:"north"}}}
:enddata
:endrule

rule:
plugin=vanillaBlocks
number=13
data:
JSON:{blockState:{blockName:"minecraft:stone_stairs",properties:{half:"bottom",shape:"straight",facing:"south"}}}
:enddata
:endrule

rule:
plugin=vanillaBlocks
number=14
data:
JSON:{blockState:{blockName:"minecraft:stone_stairs",properties:{half:"top",shape:"straight",facing:"west"}}}
:enddata
:endrule

rule:
plugin=vanillaBlocks
number=15
data:
JSON:{blockState:{blockName:"minecraft:wooden_slab",properties:{half:"top",variant:"spruce"}}}
:enddata
:endrule

rule:
plugin=vanillaBlocks
number=16
data:
JSON:{blockState:{blockName:"minecraft:log",properties:{variant:"oak",axis:"z"}}}
:enddata
:endrule

rule:
plugin=vanillaBlocks
number=17
data:
JSON:{blockState:{blockName:"minecraft:oak_stairs",properties:{half:"top",shape:"straight",facing:"west"}}}
:enddata
:endrule

rule:
plugin=vanillaBlocks
number=18
data:
JSON:{blockState:{blockName:"minecraft:log",properties:{variant:"oak",axis:"x"}}}
:enddata
:endrule

rule:
plugin=vanillaBlocks
number=19
data:
JSON:{blockState:{blockName:"minecraft:oak_stairs",properties:{half:"top",shape:"straight",facing:"east"}}}
:enddata
:endrule

rule:
plugin=vanillaBlocks
number=20
data:
JSON:{blockState:{blockName:"minecraft:torch",properties:{facing:"east"}}}
:enddata
:endrule

rule:
plugin=vanillaBlocks
number=21
data:
JSON:{blockState:{blockName:"minecraft:stone_stairs",properties:{half:"top",shape:"straight",facing:"east"}}}
:enddata
:endrule

rule:
plugin=vanillaBlocks
number=22
data:
JSON:{blockState:{blockName:"minecraft:spruce_stairs",properties:{half:"bottom",shape:"straight",facing:"north"}}}
:enddata
:endrule

rule:
plugin=vanillaBlocks
number=23
data:
JSON:{blockState:{blockName:"minecraft:spruce_stairs",properties:{half:"top",shape:"straight",facing:"south"}}}
:enddata
:endrule

rule:
plugin=vanillaBlocks
number=24
data:
JSON:{blockState:{blockName:"minecraft:spruce_stairs",properties:{half:"top",shape:"straight",facing:"north"}}}
:enddata
:endrule

rule:
plugin=vanillaBlocks
number=25
data:
JSON:{blockState:{blockName:"minecraft:spruce_stairs",properties:{half:"bottom",shape:"straight",facing:"south"}}}
:enddata
:endrule

rule:
plugin=vanillaBlocks
number=26
data:
JSON:{blockState:{blockName:"minecraft:planks",properties:{variant:"spruce"}}}
:enddata
:endrule

rule:
plugin=vanillaBlocks
number=27
data:
JSON:{blockState:{blockName:"minecraft:wooden_slab",properties:{half:"bottom",variant:"spruce"}}}
:enddata
:endrule

rule:
plugin=vanillaBlocks
number=28
data:
JSON:{blockState:{blockName:"minecraft:spruce_stairs",properties:{half:"bottom",shape:"straight",facing:"east"}}}
:enddata
:endrule

rule:
plugin=vanillaBlocks
number=29
data:
JSON:{blockState:{blockName:"minecraft:torch",properties:{facing:"west"}}}
:enddata
:endrule

rule:
plugin=vanillaBlocks
number=30
data:
JSON:{blockState:{blockName:"minecraft:spruce_stairs",properties:{half:"top",shape:"straight",facing:"west"}}}
:enddata
:endrule

rule:
plugin=vanillaBlocks
number=31
data:
JSON:{blockState:{blockName:"minecraft:spruce_stairs",properties:{half:"top",shape:"straight",facing:"east"}}}
:enddata
:endrule

rule:
plugin=vanillaBlocks
number=32
data:
JSON:{blockState:{blockName:"minecraft:spruce_stairs",properties:{half:"bottom",shape:"straight",facing:"west"}}}
:enddata
:endrule

rule:
plugin=vanillaBlocks
number=33
data:
JSON:{blockState:{blockName:"minecraft:oak_stairs",properties:{half:"top",shape:"straight",facing:"south"}}}
:enddata
:endrule

rule:
plugin=vanillaBlocks
number=34
data:
JSON:{blockState:{blockName:"minecraft:oak_stairs",properties:{half:"top",shape:"straight",facing:"north"}}}
:enddata
:endrule

rule:
plugin=vanillaBlocks
number=35
data:
JSON:{blockState:{blockName:"minecraft:torch",properties:{facing:"up"}}}
:enddata
:endrule

rule:
plugin=vanillaBlocks
number=36
data:
JSON:{blockState:{blockName:"minecraft:cobblestone_wall",properties:{east:"false",south:"false",north:"false",variant:"cobblestone",west:"false",up:"false"}}}
:enddata
:endrule

#### ENTITIES ####
