# Ancient Warfare Structure Template File
# Auto-generated structure template file. created on: 6/4/2021 at: 18:17:11
# Lines beginning with # denote comments

header:
version=2.11
name=SB_MinoakaCol_House_1H3R_1
mods=
size=21,12,17
offset=12,1,16
:endheader

#### VALIDATION ####
validation:
type=ground
structureAuthor=TheOddlySeagull
survival=true
worldGenEnabled=false
unique=false
preserveBlocks=false
preventNaturalHostileSpawns=false
selectionWeight=1
clusterValue=1
minDuplicateDistance=1
dimensionWhiteList=true
dimensionList=
biomeGroupList=
biomeWhiteList=true
biomeList=
leveling=0
fill=0
border=0
blockSwap=false
territoryName=
biomeReplacement=minecraft:
minGenerationHeight=0
maxGenerationHeight=255
:endvalidation

#### LAYERS ####
layer: 0
1,1,1,1,1,1,1,1,1,1,1,1,1,1,1,1,1,1,1,1,1
1,1,1,2,2,2,2,2,2,2,1,1,1,1,1,1,1,1,1,1,1
1,1,1,2,2,2,2,2,2,2,1,1,1,1,1,1,1,1,1,1,1
1,1,1,2,2,2,2,2,2,2,2,2,2,2,2,1,1,1,1,1,1
1,1,1,2,2,2,2,2,2,2,2,2,2,2,2,1,2,2,2,1,1
1,1,1,2,2,2,2,2,2,2,2,2,2,2,2,2,2,2,2,2,1
1,2,2,2,2,2,2,2,2,2,2,2,2,2,2,2,2,2,2,2,1
1,2,2,2,2,2,2,2,2,2,2,2,2,2,2,2,2,2,2,2,1
1,2,2,2,2,2,2,2,2,2,2,2,2,2,2,2,2,2,2,2,1
1,2,2,2,2,2,2,2,2,2,2,2,2,2,2,2,2,2,2,2,1
1,2,2,2,2,2,2,2,2,2,2,2,2,2,2,2,2,2,2,2,1
1,2,2,2,2,2,2,2,2,2,2,2,2,2,2,2,2,1,1,1,1
1,1,1,1,1,1,2,2,2,2,2,2,2,2,2,2,2,1,1,1,1
1,1,1,1,1,1,2,2,2,2,2,2,2,2,2,2,2,1,1,1,1
1,1,1,1,1,1,2,2,2,2,2,2,2,2,2,2,2,1,1,1,1
1,1,1,1,1,1,1,2,2,2,2,2,2,2,2,2,2,1,1,1,1
1,1,1,1,1,1,1,1,1,1,1,2,2,1,1,1,1,1,1,1,1
:endlayer
layer: 1
0,0,0,0,0,0,0,0,0,0,0,0,0,0,0,0,0,0,0,0,0
0,0,0,3,4,4,3,4,4,3,0,0,0,0,0,0,0,0,0,0,0
0,0,0,4,0,0,0,0,0,4,0,0,0,0,0,0,0,0,0,0,0
0,0,0,4,0,0,0,0,0,3,2,2,2,2,3,0,0,0,0,0,0
0,0,0,3,0,0,0,0,0,0,0,0,0,0,2,0,2,2,2,0,0
0,0,0,4,2,2,2,0,0,0,0,0,0,0,3,4,2,6,2,3,0
0,3,4,3,2,6,2,3,4,3,0,0,0,0,2,0,5,5,5,4,0
0,4,0,0,5,5,5,2,0,0,0,0,0,0,0,0,0,0,0,3,0
0,3,0,0,0,0,0,0,0,0,0,0,0,0,0,0,0,0,0,4,0
0,4,0,0,0,0,0,0,0,0,0,0,0,0,2,0,0,0,0,4,0
0,4,0,0,0,0,0,2,0,0,0,0,0,0,3,2,3,4,4,3,0
0,3,4,4,3,4,4,2,0,0,0,0,0,0,0,0,2,0,0,0,0
0,0,0,0,0,0,2,2,5,0,0,0,0,0,0,0,2,0,0,0,0
0,0,0,0,0,0,2,6,5,0,0,0,0,0,0,0,2,0,0,0,0
0,0,0,0,0,0,2,2,5,0,0,0,0,0,0,0,2,0,0,0,0
0,0,0,0,0,0,0,3,2,2,2,0,0,2,2,2,3,0,0,0,0
0,0,0,0,0,0,0,0,0,0,0,0,0,0,0,0,0,0,0,0,0
:endlayer
layer: 2
0,0,0,0,0,0,0,0,0,0,0,0,0,0,0,0,0,0,0,0,0
0,0,0,3,4,4,3,7,7,3,0,0,0,0,0,0,0,0,0,0,0
0,0,0,7,0,0,0,0,0,4,0,0,0,0,0,0,0,0,0,0,0
0,0,0,7,0,0,0,0,0,3,2,7,7,2,3,0,0,0,0,0,0
0,0,0,3,0,0,0,0,0,0,0,0,0,0,2,0,2,2,2,0,0
0,0,0,4,2,2,2,0,0,0,0,0,0,0,3,4,2,0,2,3,0
0,3,4,3,2,0,2,3,4,3,0,0,0,0,2,0,0,0,0,4,0
0,4,0,0,0,0,0,2,0,0,0,0,0,0,0,0,0,0,0,3,0
0,3,0,0,0,0,0,0,0,0,0,0,0,0,0,0,0,0,0,7,0
0,7,0,0,0,0,0,0,0,0,0,0,0,0,2,0,0,0,0,7,0
0,7,0,0,0,0,0,2,0,0,0,0,0,0,3,2,3,7,7,3,0
0,3,7,7,3,4,4,2,0,0,0,0,0,0,0,0,2,0,0,0,0
0,0,0,0,0,0,2,2,0,0,0,0,0,0,0,0,7,0,0,0,0
0,0,0,0,0,0,2,0,0,0,0,0,0,0,0,0,7,0,0,0,0
0,0,0,0,0,0,2,2,0,0,0,0,0,0,0,0,2,0,0,0,0
0,0,0,0,0,0,0,3,2,7,2,0,0,2,7,2,3,0,0,0,0
0,0,0,0,0,0,0,0,0,0,0,0,0,0,0,0,0,0,0,0,0
:endlayer
layer: 3
0,0,0,0,0,0,0,0,0,0,0,0,0,0,0,0,0,0,0,0,0
0,0,0,3,4,4,3,7,7,3,0,0,0,0,0,0,0,0,0,0,0
0,0,0,7,0,0,0,0,0,4,0,0,0,0,0,0,0,0,0,0,0
0,0,0,7,0,0,0,0,0,3,2,7,7,2,3,0,0,0,0,0,0
0,0,0,3,0,0,0,0,0,17,0,0,0,0,2,0,9,2,13,0,0
0,0,0,4,9,2,13,0,0,16,0,0,0,0,3,4,2,10,2,3,0
0,3,4,3,2,10,2,3,4,3,19,0,0,0,2,0,8,8,8,4,0
0,4,0,0,8,8,8,2,0,0,0,0,0,0,10,0,0,0,0,3,0
0,3,0,0,0,0,0,10,0,0,0,0,0,0,15,0,0,0,0,7,0
0,7,0,0,0,0,0,15,0,0,0,0,0,0,2,0,0,0,0,7,0
0,7,0,0,0,0,0,2,0,0,0,0,0,20,3,2,3,7,7,3,0
0,3,7,7,3,4,4,2,0,0,0,0,0,0,0,0,2,0,0,0,0
0,0,0,0,0,0,12,2,8,0,0,0,0,0,0,0,7,0,0,0,0
0,0,0,0,0,0,2,14,8,0,0,0,0,0,0,0,7,0,0,0,0
0,0,0,0,0,0,11,2,8,0,18,0,0,18,0,0,2,0,0,0,0
0,0,0,0,0,0,0,3,2,7,2,2,2,2,7,2,3,0,0,0,0
0,0,0,0,0,0,0,0,0,0,0,0,0,0,0,0,0,0,0,0,0
:endlayer
layer: 4
0,0,27,28,0,0,0,0,0,30,31,0,0,0,0,0,0,0,0,0,0
0,0,27,3,26,26,26,26,26,3,31,0,0,0,0,0,0,0,0,0,0
0,0,27,25,0,0,29,0,0,25,31,0,0,0,0,0,0,0,0,0,0
0,0,27,25,0,0,0,0,0,25,26,26,26,26,3,0,0,0,0,0,0
0,0,27,25,0,0,0,0,0,25,0,0,0,0,25,24,24,2,24,24,24
24,24,24,25,0,2,18,0,0,25,0,0,0,0,25,26,26,26,26,3,23
23,3,26,26,26,26,26,26,26,3,0,0,0,0,25,0,0,11,0,25,0
0,25,0,0,0,11,0,25,0,0,0,0,0,0,25,0,0,0,0,25,0
0,25,0,0,0,0,0,25,0,0,0,0,0,0,25,0,0,0,0,25,0
0,25,0,0,0,0,0,25,0,0,0,0,0,0,25,0,18,0,0,25,0
0,25,0,0,18,0,0,25,0,0,0,0,0,0,3,26,26,26,26,3,22
22,3,26,26,26,26,26,25,0,0,0,0,0,0,0,0,25,21,21,21,21
21,21,21,21,21,21,27,25,0,0,0,0,0,0,0,0,25,31,0,0,0
0,0,0,0,0,0,2,25,13,0,0,0,0,0,0,0,25,31,0,0,0
0,0,0,0,0,0,27,25,0,0,0,0,0,0,0,0,25,31,0,0,0
0,0,0,0,0,0,27,3,26,26,26,26,26,26,26,26,3,31,0,0,0
0,0,0,0,0,0,27,28,0,0,0,0,0,0,0,0,30,31,0,0,0
:endlayer
layer: 5
0,0,0,27,28,0,0,0,30,31,0,0,0,0,0,0,0,0,0,0,0
0,0,0,27,4,4,4,4,4,31,0,0,0,0,0,0,0,0,0,0,0
0,0,0,27,33,0,0,0,34,31,0,0,0,0,0,0,0,0,0,0,0
0,0,0,27,33,0,0,0,34,4,3,7,7,3,4,0,0,0,0,0,0
0,0,0,27,33,0,0,0,34,4,0,0,0,0,4,0,0,2,0,0,0
0,0,0,27,33,2,0,0,34,4,0,0,0,0,4,24,24,24,24,24,24
24,24,24,24,4,4,4,4,4,3,0,0,0,0,4,17,17,17,17,4,23
23,4,17,17,17,17,17,4,33,0,0,0,0,0,4,0,0,0,0,4,32
32,4,0,0,0,0,0,4,33,0,0,0,0,0,4,0,0,0,0,4,32
32,4,0,0,0,0,0,4,33,0,0,0,0,0,4,16,16,16,16,4,22
22,4,16,16,16,16,16,4,33,0,0,0,0,0,3,4,21,21,21,21,21
21,21,21,21,21,21,21,27,33,0,0,0,0,0,0,34,31,0,0,0,0
0,0,0,0,0,0,0,27,33,0,0,0,0,0,0,34,31,0,0,0,0
0,0,0,0,0,0,2,27,33,0,0,0,0,0,0,34,31,0,0,0,0
0,0,0,0,0,0,0,27,33,0,0,0,0,0,0,34,31,0,0,0,0
0,0,0,0,0,0,0,27,4,4,3,7,7,3,4,4,31,0,0,0,0
0,0,0,0,0,0,0,27,28,0,0,0,0,0,0,30,31,0,0,0,0
:endlayer
layer: 6
0,0,0,0,27,28,32,30,31,0,0,0,0,0,0,0,0,0,0,0,0
0,0,0,0,27,4,4,4,31,0,0,0,0,0,0,0,0,0,0,0,0
0,0,0,0,27,33,0,34,35,28,0,0,0,0,30,31,0,0,0,0,0
0,0,0,0,27,33,0,34,35,4,3,7,7,3,4,31,0,0,0,0,0
0,0,0,0,27,33,0,34,35,4,29,0,0,29,25,31,0,2,0,0,0
0,0,0,0,27,2,0,34,35,4,0,0,0,0,25,31,0,0,0,0,0
0,0,0,0,27,4,4,4,35,3,0,0,0,0,25,31,24,24,24,24,24
24,24,24,24,24,4,4,4,35,33,0,0,0,0,25,17,17,17,17,4,31
27,4,17,17,17,17,17,4,35,33,0,0,0,0,25,16,16,16,16,4,31
27,4,16,16,16,16,16,4,35,33,0,0,0,0,25,21,21,21,21,21,21
21,21,21,21,21,21,21,21,27,33,0,0,0,0,3,31,0,0,0,0,0
0,0,0,0,0,0,0,0,27,33,0,0,0,0,34,31,0,0,0,0,0
0,0,0,0,0,0,0,0,27,33,0,0,0,0,34,31,0,0,0,0,0
0,0,0,0,0,0,2,0,27,33,0,0,0,0,34,31,0,0,0,0,0
0,0,0,0,0,0,0,0,27,33,18,0,0,18,34,31,0,0,0,0,0
0,0,0,0,0,0,0,0,27,4,3,7,7,3,4,31,0,0,0,0,0
0,0,0,0,0,0,0,0,27,28,0,0,0,0,30,31,0,0,0,0,0
:endlayer
layer: 7
0,0,0,0,0,24,24,31,0,0,0,0,0,0,0,0,0,0,0,0,0
0,0,0,0,0,27,25,31,0,0,0,0,0,0,0,0,0,0,0,0,0
0,0,0,0,0,27,25,31,0,27,28,32,32,30,31,0,0,0,0,0,0
0,0,0,0,0,27,25,31,0,27,3,26,26,3,31,0,0,0,0,0,0
0,0,0,0,0,27,25,31,0,27,33,0,0,34,31,0,0,2,0,0,0
0,0,0,0,0,2,25,31,0,27,33,0,0,34,31,0,0,0,0,0,0
0,0,0,0,0,27,25,31,36,27,33,0,0,34,31,0,0,0,0,0,0
0,0,0,0,0,27,25,31,0,27,33,0,0,34,31,24,24,24,24,31,0
0,27,24,24,24,24,25,31,0,27,33,0,0,34,21,21,21,21,21,31,0
0,27,21,21,21,21,21,21,0,27,33,0,0,34,31,0,0,0,0,0,0
0,0,0,0,0,0,0,0,0,27,33,0,0,34,31,0,0,0,0,0,0
0,0,0,0,0,0,0,0,0,27,33,0,0,34,31,0,0,0,0,0,0
0,0,0,0,0,0,0,0,0,27,33,0,0,34,31,0,0,0,0,0,0
0,0,0,0,0,0,2,0,0,27,33,0,0,34,31,0,0,0,0,0,0
0,0,0,0,0,0,0,0,0,27,33,0,0,34,31,0,0,0,0,0,0
0,0,0,0,0,0,0,0,0,27,3,26,26,3,31,0,0,0,0,0,0
0,0,0,0,0,0,0,0,0,27,28,32,32,30,31,0,0,0,0,0,0
:endlayer
layer: 8
0,0,0,0,0,0,0,0,0,0,0,0,0,0,0,0,0,0,0,0,0
0,0,0,0,0,0,37,0,0,0,0,0,0,0,0,0,0,0,0,0,0
0,0,0,0,0,0,37,0,0,0,27,24,24,31,0,0,0,0,0,0,0
0,0,0,0,0,0,37,0,0,0,27,4,4,31,0,0,0,0,0,0,0
0,0,0,0,0,0,37,0,0,0,27,33,34,31,0,0,0,38,0,0,0
0,0,0,0,0,2,37,0,0,0,27,33,34,31,0,0,0,0,0,0,0
0,0,0,0,0,0,37,0,0,0,27,33,34,31,0,0,0,0,0,0,0
0,0,0,0,0,0,37,0,0,0,27,33,34,31,0,0,0,0,0,0,0
0,0,0,0,0,0,37,0,0,0,27,33,34,31,0,0,0,0,0,0,0
0,0,0,0,0,0,0,0,0,0,27,33,34,31,0,0,0,0,0,0,0
0,0,0,0,0,0,0,0,0,0,27,33,34,31,0,0,0,0,0,0,0
0,0,0,0,0,0,0,0,0,0,27,33,34,31,0,0,0,0,0,0,0
0,0,0,0,0,0,0,0,0,0,27,33,34,31,0,0,0,0,0,0,0
0,0,0,0,0,0,2,0,0,0,27,33,34,31,0,0,0,0,0,0,0
0,0,0,0,0,0,0,0,0,0,27,33,34,31,0,0,0,0,0,0,0
0,0,0,0,0,0,0,0,0,0,27,4,4,31,0,0,0,0,0,0,0
0,0,0,0,0,0,0,0,0,0,27,21,21,31,0,0,0,0,0,0,0
:endlayer
layer: 9
0,0,0,0,0,0,0,0,0,0,0,0,0,0,0,0,0,0,0,0,0
0,0,0,0,0,0,0,0,0,0,0,0,0,0,0,0,0,0,0,0,0
0,0,0,0,0,0,0,0,0,0,0,0,0,0,0,0,0,0,0,0,0
0,0,0,0,0,0,0,0,0,0,0,24,24,0,0,0,0,0,0,0,0
0,0,0,0,0,0,0,0,0,0,0,27,31,0,0,0,0,5,0,0,0
0,0,0,0,0,2,0,0,0,0,0,27,31,0,0,0,0,0,0,0,0
0,0,0,0,0,0,0,0,0,0,0,27,31,0,0,0,0,0,0,0,0
0,0,0,0,0,0,0,0,0,0,0,27,31,0,0,0,0,0,0,0,0
0,0,0,0,0,0,0,0,0,0,0,27,31,0,0,0,0,0,0,0,0
0,0,0,0,0,0,0,0,0,0,0,27,31,0,0,0,0,0,0,0,0
0,0,0,0,0,0,0,0,0,0,0,27,31,0,0,0,0,0,0,0,0
0,0,0,0,0,0,0,0,0,0,0,27,31,0,0,0,0,0,0,0,0
0,0,0,0,0,0,0,0,0,0,0,27,31,0,0,0,0,0,0,0,0
0,0,0,0,0,0,38,0,0,0,0,27,31,0,0,0,0,0,0,0,0
0,0,0,0,0,0,0,0,0,0,0,27,31,0,0,0,0,0,0,0,0
0,0,0,0,0,0,0,0,0,0,0,21,21,0,0,0,0,0,0,0,0
0,0,0,0,0,0,0,0,0,0,0,0,0,0,0,0,0,0,0,0,0
:endlayer
layer: 10
0,0,0,0,0,0,0,0,0,0,0,0,0,0,0,0,0,0,0,0,0
0,0,0,0,0,0,0,0,0,0,0,0,0,0,0,0,0,0,0,0,0
0,0,0,0,0,0,0,0,0,0,0,0,0,0,0,0,0,0,0,0,0
0,0,0,0,0,0,0,0,0,0,0,0,0,0,0,0,0,0,0,0,0
0,0,0,0,0,0,0,0,0,0,0,0,0,0,0,0,0,0,0,0,0
0,0,0,0,0,38,0,0,0,0,0,0,0,0,0,0,0,0,0,0,0
0,0,0,0,0,0,0,0,0,0,0,0,0,0,0,0,0,0,0,0,0
0,0,0,0,0,0,0,0,0,0,0,0,0,0,0,0,0,0,0,0,0
0,0,0,0,0,0,0,0,0,0,0,0,0,0,0,0,0,0,0,0,0
0,0,0,0,0,0,0,0,0,0,0,0,0,0,0,0,0,0,0,0,0
0,0,0,0,0,0,0,0,0,0,0,0,0,0,0,0,0,0,0,0,0
0,0,0,0,0,0,0,0,0,0,0,0,0,0,0,0,0,0,0,0,0
0,0,0,0,0,0,0,0,0,0,0,0,0,0,0,0,0,0,0,0,0
0,0,0,0,0,0,5,0,0,0,0,0,0,0,0,0,0,0,0,0,0
0,0,0,0,0,0,0,0,0,0,0,0,0,0,0,0,0,0,0,0,0
0,0,0,0,0,0,0,0,0,0,0,0,0,0,0,0,0,0,0,0,0
0,0,0,0,0,0,0,0,0,0,0,0,0,0,0,0,0,0,0,0,0
:endlayer
layer: 11
0,0,0,0,0,0,0,0,0,0,0,0,0,0,0,0,0,0,0,0,0
0,0,0,0,0,0,0,0,0,0,0,0,0,0,0,0,0,0,0,0,0
0,0,0,0,0,0,0,0,0,0,0,0,0,0,0,0,0,0,0,0,0
0,0,0,0,0,0,0,0,0,0,0,0,0,0,0,0,0,0,0,0,0
0,0,0,0,0,0,0,0,0,0,0,0,0,0,0,0,0,0,0,0,0
0,0,0,0,0,5,0,0,0,0,0,0,0,0,0,0,0,0,0,0,0
0,0,0,0,0,0,0,0,0,0,0,0,0,0,0,0,0,0,0,0,0
0,0,0,0,0,0,0,0,0,0,0,0,0,0,0,0,0,0,0,0,0
0,0,0,0,0,0,0,0,0,0,0,0,0,0,0,0,0,0,0,0,0
0,0,0,0,0,0,0,0,0,0,0,0,0,0,0,0,0,0,0,0,0
0,0,0,0,0,0,0,0,0,0,0,0,0,0,0,0,0,0,0,0,0
0,0,0,0,0,0,0,0,0,0,0,0,0,0,0,0,0,0,0,0,0
0,0,0,0,0,0,0,0,0,0,0,0,0,0,0,0,0,0,0,0,0
0,0,0,0,0,0,0,0,0,0,0,0,0,0,0,0,0,0,0,0,0
0,0,0,0,0,0,0,0,0,0,0,0,0,0,0,0,0,0,0,0,0
0,0,0,0,0,0,0,0,0,0,0,0,0,0,0,0,0,0,0,0,0
0,0,0,0,0,0,0,0,0,0,0,0,0,0,0,0,0,0,0,0,0
:endlayer

#### RULES ####
rule:
plugin=vanillaBlocks
number=1
data:
JSON:{blockState:{blockName:"minecraft:grass",properties:{snowy:"false"}}}
:enddata
:endrule

rule:
plugin=vanillaBlocks
number=2
data:
JSON:{blockState:{blockName:"minecraft:cobblestone"}}
:enddata
:endrule

rule:
plugin=vanillaBlocks
number=3
data:
JSON:{blockState:{blockName:"minecraft:log",properties:{variant:"oak",axis:"y"}}}
:enddata
:endrule

rule:
plugin=vanillaBlocks
number=4
data:
JSON:{blockState:{blockName:"minecraft:planks",properties:{variant:"oak"}}}
:enddata
:endrule

rule:
plugin=vanillaBlocks
number=5
data:
JSON:{blockState:{blockName:"minecraft:stone_slab",properties:{half:"bottom",variant:"cobblestone"}}}
:enddata
:endrule

rule:
plugin=vanillaBlocks
number=6
data:
JSON:{blockState:{blockName:"ancientwarfarestructure:fire_pit",properties:{lit:"true",variant:"log"}}}
:enddata
:endrule

rule:
plugin=vanillaBlocks
number=7
data:
JSON:{blockState:{blockName:"minecraft:stained_glass_pane",properties:{east:"false",color:"green",south:"false",north:"false",west:"false"}}}
:enddata
:endrule

rule:
plugin=vanillaBlocks
number=8
data:
JSON:{blockState:{blockName:"minecraft:stone_slab",properties:{half:"top",variant:"cobblestone"}}}
:enddata
:endrule

rule:
plugin=vanillaBlocks
number=9
data:
JSON:{blockState:{blockName:"minecraft:stone_stairs",properties:{half:"bottom",shape:"straight",facing:"east"}}}
:enddata
:endrule

rule:
plugin=vanillaBlocks
number=10
data:
JSON:{blockState:{blockName:"minecraft:stone_stairs",properties:{half:"top",shape:"straight",facing:"north"}}}
:enddata
:endrule

rule:
plugin=vanillaBlocks
number=11
data:
JSON:{blockState:{blockName:"minecraft:stone_stairs",properties:{half:"bottom",shape:"straight",facing:"north"}}}
:enddata
:endrule

rule:
plugin=vanillaBlocks
number=12
data:
JSON:{blockState:{blockName:"minecraft:stone_stairs",properties:{half:"bottom",shape:"straight",facing:"south"}}}
:enddata
:endrule

rule:
plugin=vanillaBlocks
number=13
data:
JSON:{blockState:{blockName:"minecraft:stone_stairs",properties:{half:"bottom",shape:"straight",facing:"west"}}}
:enddata
:endrule

rule:
plugin=vanillaBlocks
number=14
data:
JSON:{blockState:{blockName:"minecraft:stone_stairs",properties:{half:"top",shape:"straight",facing:"west"}}}
:enddata
:endrule

rule:
plugin=vanillaBlocks
number=15
data:
JSON:{blockState:{blockName:"minecraft:stone_stairs",properties:{half:"top",shape:"straight",facing:"south"}}}
:enddata
:endrule

rule:
plugin=vanillaBlocks
number=16
data:
JSON:{blockState:{blockName:"minecraft:oak_stairs",properties:{half:"top",shape:"straight",facing:"south"}}}
:enddata
:endrule

rule:
plugin=vanillaBlocks
number=17
data:
JSON:{blockState:{blockName:"minecraft:oak_stairs",properties:{half:"top",shape:"straight",facing:"north"}}}
:enddata
:endrule

rule:
plugin=vanillaBlocks
number=18
data:
JSON:{blockState:{blockName:"minecraft:torch",properties:{facing:"north"}}}
:enddata
:endrule

rule:
plugin=vanillaBlocks
number=19
data:
JSON:{blockState:{blockName:"minecraft:torch",properties:{facing:"east"}}}
:enddata
:endrule

rule:
plugin=vanillaBlocks
number=20
data:
JSON:{blockState:{blockName:"minecraft:torch",properties:{facing:"west"}}}
:enddata
:endrule

rule:
plugin=vanillaBlocks
number=21
data:
JSON:{blockState:{blockName:"minecraft:spruce_stairs",properties:{half:"bottom",shape:"straight",facing:"north"}}}
:enddata
:endrule

rule:
plugin=vanillaBlocks
number=22
data:
JSON:{blockState:{blockName:"minecraft:spruce_stairs",properties:{half:"top",shape:"straight",facing:"south"}}}
:enddata
:endrule

rule:
plugin=vanillaBlocks
number=23
data:
JSON:{blockState:{blockName:"minecraft:spruce_stairs",properties:{half:"top",shape:"straight",facing:"north"}}}
:enddata
:endrule

rule:
plugin=vanillaBlocks
number=24
data:
JSON:{blockState:{blockName:"minecraft:spruce_stairs",properties:{half:"bottom",shape:"straight",facing:"south"}}}
:enddata
:endrule

rule:
plugin=vanillaBlocks
number=25
data:
JSON:{blockState:{blockName:"minecraft:log",properties:{variant:"oak",axis:"z"}}}
:enddata
:endrule

rule:
plugin=vanillaBlocks
number=26
data:
JSON:{blockState:{blockName:"minecraft:log",properties:{variant:"oak",axis:"x"}}}
:enddata
:endrule

rule:
plugin=vanillaBlocks
number=27
data:
JSON:{blockState:{blockName:"minecraft:spruce_stairs",properties:{half:"bottom",shape:"straight",facing:"east"}}}
:enddata
:endrule

rule:
plugin=vanillaBlocks
number=28
data:
JSON:{blockState:{blockName:"minecraft:spruce_stairs",properties:{half:"top",shape:"straight",facing:"west"}}}
:enddata
:endrule

rule:
plugin=vanillaBlocks
number=29
data:
JSON:{blockState:{blockName:"minecraft:torch",properties:{facing:"south"}}}
:enddata
:endrule

rule:
plugin=vanillaBlocks
number=30
data:
JSON:{blockState:{blockName:"minecraft:spruce_stairs",properties:{half:"top",shape:"straight",facing:"east"}}}
:enddata
:endrule

rule:
plugin=vanillaBlocks
number=31
data:
JSON:{blockState:{blockName:"minecraft:spruce_stairs",properties:{half:"bottom",shape:"straight",facing:"west"}}}
:enddata
:endrule

rule:
plugin=vanillaBlocks
number=32
data:
JSON:{blockState:{blockName:"minecraft:wooden_slab",properties:{half:"top",variant:"spruce"}}}
:enddata
:endrule

rule:
plugin=vanillaBlocks
number=33
data:
JSON:{blockState:{blockName:"minecraft:oak_stairs",properties:{half:"top",shape:"straight",facing:"west"}}}
:enddata
:endrule

rule:
plugin=vanillaBlocks
number=34
data:
JSON:{blockState:{blockName:"minecraft:oak_stairs",properties:{half:"top",shape:"straight",facing:"east"}}}
:enddata
:endrule

rule:
plugin=vanillaBlocks
number=35
data:
JSON:{blockState:{blockName:"minecraft:planks",properties:{variant:"spruce"}}}
:enddata
:endrule

rule:
plugin=vanillaBlocks
number=36
data:
JSON:{blockState:{blockName:"minecraft:torch",properties:{facing:"up"}}}
:enddata
:endrule

rule:
plugin=vanillaBlocks
number=37
data:
JSON:{blockState:{blockName:"minecraft:wooden_slab",properties:{half:"bottom",variant:"spruce"}}}
:enddata
:endrule

rule:
plugin=vanillaBlocks
number=38
data:
JSON:{blockState:{blockName:"minecraft:cobblestone_wall",properties:{east:"false",south:"false",north:"false",variant:"cobblestone",west:"false",up:"false"}}}
:enddata
:endrule

#### ENTITIES ####
