# Ancient Warfare Structure Template File
# Auto-generated structure template file. created on: 6/4/2021 at: 18:21:34
# Lines beginning with # denote comments

header:
version=2.11
name=SB_MinoakaCol_House_1H5R_2
mods=
size=19,17,18
offset=8,1,17
:endheader

#### VALIDATION ####
validation:
type=ground
structureAuthor=theoddlyseagull
survival=true
worldGenEnabled=false
unique=false
preserveBlocks=false
preventNaturalHostileSpawns=false
selectionWeight=1
clusterValue=1
minDuplicateDistance=1
dimensionWhiteList=true
dimensionList=
biomeGroupList=
biomeWhiteList=true
biomeList=
leveling=0
fill=0
border=0
blockSwap=false
territoryName=
biomeReplacement=minecraft:
minGenerationHeight=0
maxGenerationHeight=255
:endvalidation

#### LAYERS ####
layer: 0
1,1,1,1,1,1,1,1,1,1,1,2,2,1,1,1,1,1,1
1,1,1,1,1,1,1,1,1,1,2,2,2,2,1,1,1,1,1
1,1,1,1,1,1,1,2,2,2,2,2,2,2,1,1,1,1,1
1,1,1,1,1,1,1,2,2,2,2,2,2,2,1,1,1,1,1
1,1,2,2,2,1,1,2,2,2,2,2,2,2,1,1,1,1,1
1,2,2,2,2,2,2,2,2,2,2,2,2,2,1,1,1,1,1
1,2,2,2,2,2,2,2,2,2,2,2,2,2,2,2,2,1,1
1,2,2,2,2,2,2,2,2,2,2,2,2,2,2,2,2,1,1
1,2,2,2,2,2,2,2,2,2,2,2,2,2,2,2,2,1,1
1,2,2,2,2,2,2,2,2,2,2,2,2,2,2,2,2,1,1
1,2,2,2,2,2,2,2,2,2,2,2,2,2,2,2,2,1,1
1,2,2,2,2,2,2,2,2,2,2,2,2,2,2,2,2,1,1
1,1,1,1,1,2,2,2,2,2,2,2,2,2,2,2,2,1,1
1,1,1,1,1,2,2,2,2,2,2,2,2,2,2,2,2,1,1
1,1,1,1,1,2,2,2,2,2,2,2,2,2,2,2,2,1,1
1,1,1,1,1,2,2,2,2,2,2,2,2,2,1,1,1,1,1
1,1,1,1,1,2,2,2,2,2,2,1,1,1,1,1,1,1,1
1,1,1,1,1,1,1,2,2,1,1,1,1,1,1,1,1,1,1
:endlayer
layer: 1
0,0,0,0,0,0,0,0,0,0,0,0,0,0,0,0,0,0,0
0,0,0,0,0,0,0,0,0,0,3,0,0,3,0,0,0,0,0
0,0,0,0,0,0,0,3,2,2,0,0,0,2,0,0,0,0,0
0,0,0,0,0,0,0,2,0,0,0,0,0,2,0,0,0,0,0
0,0,2,2,2,0,0,2,0,0,0,8,8,2,0,0,0,0,0
0,3,2,6,2,2,2,3,0,0,0,7,7,3,0,0,0,0,0
0,2,4,5,4,0,0,0,0,0,0,0,0,2,2,2,2,0,0
0,2,0,0,0,0,0,0,0,0,0,0,0,2,0,0,2,0,0
0,2,0,0,0,0,0,0,0,0,0,0,0,3,0,0,3,0,0
0,2,0,0,0,0,0,0,0,0,0,0,0,0,0,0,2,0,0
0,2,0,0,0,0,0,0,0,0,0,0,0,0,0,0,2,0,0
0,3,2,2,2,3,0,0,0,0,0,0,0,0,0,0,2,0,0
0,0,0,0,0,2,0,0,0,0,0,0,0,0,0,0,2,0,0
0,0,0,0,0,2,0,0,0,0,0,5,5,5,0,0,2,0,0
0,0,0,0,0,2,0,0,0,0,3,2,6,2,2,2,3,0,0
0,0,0,0,0,2,0,0,0,0,2,2,2,2,0,0,0,0,0
0,0,0,0,0,3,2,0,0,2,3,0,0,0,0,0,0,0,0
0,0,0,0,0,0,0,0,0,0,0,0,0,0,0,0,0,0,0
:endlayer
layer: 2
0,0,0,0,0,0,0,0,0,0,10,0,0,10,0,0,0,0,0
0,0,0,0,0,0,0,0,0,0,3,0,0,3,0,0,0,0,0
0,0,0,0,0,0,0,3,2,2,0,0,0,2,0,0,0,0,0
0,0,0,0,0,0,0,2,0,0,0,0,0,9,0,0,0,0,0
0,0,2,2,2,0,0,2,0,0,0,0,0,2,0,0,0,0,0
0,3,2,0,2,2,2,3,0,0,0,8,8,3,0,0,0,0,0
0,2,0,0,0,0,0,0,0,0,0,7,7,2,2,2,2,0,0
0,9,0,0,0,0,0,0,0,0,0,0,0,2,0,0,2,0,0
0,2,0,0,0,0,0,0,0,0,0,0,0,3,0,0,3,0,0
0,9,0,0,0,0,0,0,0,0,0,0,0,0,0,0,2,0,0
0,2,0,0,0,0,0,0,0,0,0,0,0,0,0,0,9,0,0
0,3,2,9,2,3,0,0,0,0,0,0,0,0,0,0,2,0,0
0,0,0,0,0,2,0,0,0,0,0,0,0,0,0,0,9,0,0
0,0,0,0,0,2,0,0,0,0,0,0,0,0,0,0,2,0,0
0,0,0,0,0,9,0,0,0,0,3,2,0,2,9,2,3,0,0
0,0,0,0,0,2,0,0,0,0,2,2,2,2,0,0,0,0,0
0,0,0,0,0,3,2,0,0,2,3,0,0,0,0,0,0,0,0
0,0,0,0,0,0,0,0,0,0,0,0,0,0,0,0,0,0,0
:endlayer
layer: 3
0,0,0,0,0,0,0,0,0,8,8,16,16,8,8,0,0,0,0
0,0,0,0,0,0,0,0,0,7,3,2,2,3,7,0,0,0,0
0,0,0,0,0,0,0,3,2,2,18,0,0,2,0,0,0,0,0
0,0,0,0,0,0,0,2,0,0,0,0,0,9,0,0,0,0,0
0,0,12,2,15,0,0,2,0,0,0,0,0,2,0,0,0,0,0
0,3,2,11,2,2,2,3,17,0,0,0,0,3,0,0,0,0,0
0,2,11,13,11,11,11,18,0,0,0,8,8,2,2,2,2,0,0
0,9,0,0,0,0,0,0,0,0,0,7,7,2,21,14,2,0,0
0,2,0,0,0,0,0,0,0,0,0,0,19,3,21,14,3,0,0
0,9,0,0,0,0,0,0,0,0,0,0,0,18,0,0,2,0,0
0,2,0,0,0,10,0,0,0,0,0,0,0,0,0,0,9,0,0
0,3,2,9,2,3,17,0,0,0,0,0,0,0,0,0,2,0,0
0,0,0,0,14,2,0,0,0,0,0,0,0,0,0,0,9,0,0
0,0,0,0,0,2,0,0,0,0,10,0,0,0,0,0,2,0,0
0,0,0,0,0,9,0,0,0,19,3,2,20,2,9,2,3,0,0
0,0,0,0,0,2,0,0,0,0,2,12,2,15,0,0,0,0,0
0,0,0,0,0,3,2,2,2,2,3,0,0,0,0,0,0,0,0
0,0,0,0,0,0,16,0,0,16,0,0,0,0,0,0,0,0,0
:endlayer
layer: 4
0,0,0,0,0,0,0,0,0,0,0,0,0,0,0,0,0,0,0
0,0,0,0,0,0,8,8,8,8,8,8,8,8,8,0,0,0,0
0,0,0,0,0,0,7,3,25,25,25,25,25,3,7,0,0,0,0
0,0,0,0,0,0,0,24,0,0,24,0,0,24,0,0,0,0,0
22,23,0,2,0,20,0,24,0,0,24,0,0,24,0,0,0,0,0
22,3,25,25,2,2,2,3,25,25,24,0,0,24,0,0,0,0,0
22,24,2,26,2,2,2,26,16,26,24,0,0,24,29,2,29,0,0
22,24,26,26,16,24,16,26,16,26,24,8,8,24,2,2,2,0,0
22,24,16,16,16,24,16,26,16,26,24,25,25,25,2,2,2,25,30
22,24,26,26,26,24,16,26,16,26,24,16,16,24,16,16,24,16,0
22,24,16,16,16,24,25,25,25,25,24,26,26,24,16,16,24,16,0
22,3,25,25,25,2,26,16,26,16,24,16,16,24,25,25,24,25,30
22,23,0,0,2,2,26,16,26,16,24,26,26,24,16,16,24,16,0
0,0,0,0,14,2,26,16,26,16,24,16,16,24,16,16,24,16,0
0,0,0,0,0,24,25,25,25,25,25,25,25,24,25,25,25,25,30
0,0,0,0,0,24,16,16,16,16,24,0,2,24,16,16,24,0,0
0,0,0,0,0,3,25,25,25,25,3,0,0,28,0,0,28,0,0
0,0,0,0,0,0,0,27,27,0,0,0,0,0,0,0,0,0,0
:endlayer
layer: 5
0,0,0,0,0,0,0,0,0,0,0,0,0,0,0,0,0,0,0
0,0,0,0,0,0,0,0,0,0,0,0,0,0,0,0,0,0,0
0,0,0,0,0,0,8,8,8,8,8,8,8,8,8,0,0,0,0
0,0,0,0,0,0,7,31,34,34,31,34,34,31,7,0,0,0,0
0,22,23,2,20,2,20,31,0,0,31,0,0,31,0,0,0,0,0
0,22,31,31,2,6,2,3,32,32,3,0,0,3,0,0,0,0,0
0,22,24,0,5,5,5,31,26,23,32,0,0,31,29,2,29,0,0
0,22,24,0,0,0,0,3,33,0,32,0,0,3,2,6,2,0,0
0,22,24,0,0,0,0,0,0,0,0,0,0,3,0,0,0,3,0
0,22,24,0,0,0,0,0,0,0,0,0,0,0,0,0,0,31,0
0,22,24,0,0,0,31,3,31,31,32,0,0,0,0,0,0,31,0
0,22,31,31,31,2,15,0,0,0,3,0,0,3,31,31,31,3,0
0,22,23,0,2,6,5,0,0,0,0,0,0,0,0,0,0,31,0
0,0,0,0,2,2,15,0,0,0,0,0,0,0,0,0,0,31,0
0,0,0,0,0,3,31,31,3,0,3,31,31,3,0,0,0,3,0
0,0,0,0,0,32,0,0,0,0,32,0,2,3,31,31,3,0,0
0,0,0,0,0,3,32,32,32,32,3,0,0,0,0,0,0,0,0
0,0,0,0,0,18,0,0,0,0,18,0,0,0,0,0,0,0,0
:endlayer
layer: 6
0,0,0,0,0,0,0,0,0,0,0,0,0,0,0,0,0,0,0
0,0,0,0,0,0,0,0,0,0,0,0,0,0,0,0,0,0,0
0,0,0,0,0,0,0,0,0,0,0,0,0,0,0,0,0,0,0
0,0,0,0,0,0,8,8,8,8,8,8,8,8,8,0,0,0,0
0,0,22,2,12,2,2,31,34,34,31,34,34,31,7,0,0,0,0
0,0,22,31,2,0,2,3,32,32,3,0,0,3,0,0,0,0,0
0,0,22,35,0,0,0,31,0,22,23,0,0,31,12,2,15,0,0
0,0,3,35,0,0,0,3,0,0,0,0,0,3,2,0,2,0,0
0,0,9,0,0,0,0,0,0,0,0,0,0,3,0,0,0,3,0
0,0,3,35,0,0,0,0,0,0,0,0,0,0,0,0,0,9,0
0,0,22,35,0,0,31,3,31,31,32,0,0,0,0,0,0,9,0
0,0,22,31,31,2,0,0,0,0,3,0,0,3,31,31,31,3,0
0,0,22,23,2,0,0,0,0,0,0,0,0,0,0,0,0,9,0
0,0,0,0,2,2,0,0,0,0,0,0,0,0,0,0,0,9,0
0,0,0,0,0,3,9,9,3,0,3,31,31,3,0,0,0,3,0
0,0,0,0,0,0,0,0,0,0,0,0,2,3,9,9,3,0,0
0,0,0,0,0,32,0,0,0,0,32,0,0,0,0,0,0,0,0
0,0,0,0,0,0,0,0,0,0,0,0,0,0,0,0,0,0,0
:endlayer
layer: 7
0,0,0,0,0,0,0,0,0,0,0,0,0,0,0,0,0,0,0
0,0,0,0,0,0,0,0,0,0,0,0,0,0,0,0,0,0,0
0,0,0,0,0,0,0,0,0,0,0,0,0,0,0,0,0,0,0
0,0,0,0,0,0,0,0,0,0,0,0,0,0,0,0,0,0,0
0,0,0,2,23,2,8,8,8,8,8,8,8,8,8,0,0,0,0
0,0,0,22,2,11,2,3,34,34,3,34,34,3,7,0,0,0,0
0,8,8,22,21,13,13,31,0,0,22,23,0,31,0,2,0,0,0
0,7,3,31,35,0,19,3,0,0,0,0,0,3,2,11,2,0,0
0,16,9,0,0,0,0,34,0,0,0,0,0,3,0,0,0,3,0
0,36,3,31,35,0,0,37,0,10,0,0,0,34,0,0,0,9,0
0,33,33,22,35,10,31,3,31,31,32,0,0,37,0,0,0,9,0
0,0,0,22,31,2,13,0,0,0,3,0,0,3,31,31,31,3,0
0,0,0,22,2,21,0,0,0,0,34,0,0,34,0,0,0,9,0
0,0,0,0,4,2,13,0,10,0,37,0,0,37,0,0,0,9,0
0,0,0,0,0,3,9,9,3,31,3,31,31,3,17,0,0,3,0
0,0,0,0,0,16,0,0,0,0,16,0,2,3,9,9,3,0,0
0,0,0,0,0,27,16,16,16,16,27,0,0,0,0,0,0,0,0
0,0,0,0,0,0,0,0,0,0,0,0,0,0,0,0,0,0,0
:endlayer
layer: 8
0,0,0,0,0,0,0,0,0,0,0,0,0,0,0,0,0,0,0
0,0,0,0,0,0,0,0,0,0,0,0,0,0,0,0,0,0,0
0,0,0,0,0,0,0,0,0,0,0,0,0,0,0,0,0,0,0
0,0,0,0,0,0,0,0,0,0,0,0,0,0,0,0,0,0,0
0,0,0,2,22,2,0,0,0,0,0,0,0,0,0,0,0,0,0
0,0,0,0,22,25,25,3,25,25,25,25,25,3,27,0,0,0,0
0,0,0,0,22,24,26,24,0,0,0,22,26,24,13,2,13,38,39
0,8,8,8,8,24,7,24,25,25,25,25,25,24,2,25,2,38,39
0,22,24,25,25,24,16,24,16,26,16,26,16,24,26,26,26,3,39
0,33,33,33,33,24,16,24,16,26,16,26,16,24,26,26,26,24,39
0,0,0,0,22,24,25,25,25,25,25,25,25,24,16,16,16,24,39
0,0,0,0,22,24,2,26,16,26,24,16,16,24,25,25,25,24,39
0,0,0,0,2,24,2,26,16,26,24,26,26,24,16,16,16,24,39
0,0,0,0,22,24,2,26,16,26,24,16,16,24,26,26,26,24,39
0,0,0,0,22,3,25,25,25,25,25,25,25,24,16,16,16,3,39
0,0,0,0,22,23,27,27,27,27,0,0,2,3,25,25,3,38,39
0,0,0,0,0,0,0,0,0,0,0,0,22,23,0,0,0,38,39
0,0,0,0,0,0,0,0,0,0,0,0,0,0,0,0,0,0,0
:endlayer
layer: 9
0,0,0,0,0,0,0,0,0,0,0,0,0,0,0,0,0,0,0
0,0,0,0,0,0,0,0,0,0,0,0,0,0,0,0,0,0,0
0,0,0,0,0,0,0,0,0,0,0,0,0,0,0,0,0,0,0
0,0,0,0,0,0,0,0,0,0,0,0,0,0,0,0,0,0,0
0,0,0,2,0,2,23,0,0,0,0,0,0,0,0,0,0,0,0
0,0,0,0,0,22,31,3,31,9,31,9,31,3,0,0,0,0,0
0,0,0,0,0,22,24,0,0,0,0,0,0,31,0,2,38,39,0
0,0,0,0,0,22,24,32,32,32,32,0,0,3,31,31,3,39,0
0,0,27,27,27,22,24,17,0,0,0,0,0,0,0,0,24,39,0
0,0,0,0,0,22,24,0,0,0,0,0,0,0,0,0,24,39,0
0,0,0,0,0,22,24,0,0,0,0,0,0,0,0,0,24,39,0
0,0,0,0,0,22,24,17,0,0,0,0,0,0,0,0,24,39,0
0,0,0,0,2,22,24,0,0,0,0,0,0,0,0,0,24,39,0
0,0,0,0,0,22,24,0,0,0,0,0,0,0,0,0,24,39,0
0,0,0,0,0,22,31,3,31,9,31,9,31,3,0,0,24,39,0
0,0,0,0,0,22,23,0,0,0,0,0,2,22,31,31,3,39,0
0,0,0,0,0,0,0,0,0,0,0,0,0,22,23,16,38,39,0
0,0,0,0,0,0,0,0,0,0,0,0,0,0,0,0,0,0,0
:endlayer
layer: 10
0,0,0,0,0,0,0,0,0,0,0,0,0,0,0,0,0,0,0
0,0,0,0,0,0,0,0,0,0,0,0,0,0,0,0,0,0,0
0,0,0,0,0,0,0,0,0,0,0,0,0,0,0,0,0,0,0
0,0,0,0,0,0,0,0,0,0,0,0,0,0,0,0,0,0,0
0,0,0,2,0,2,22,23,0,0,0,0,0,38,39,0,0,0,0
0,0,0,0,0,0,22,3,31,9,31,9,31,3,39,0,0,0,0
0,0,0,0,0,0,22,35,0,0,0,0,0,24,8,2,8,0,0
0,0,0,0,0,0,22,35,0,0,0,0,0,3,25,25,39,0,0
0,0,0,0,0,0,3,35,0,0,0,0,0,0,0,0,3,32,0
0,0,0,0,0,0,9,0,0,0,0,0,0,0,0,0,9,0,0
0,0,0,0,0,0,9,0,0,0,0,0,0,0,0,0,9,0,0
0,0,0,0,0,0,3,35,0,0,0,0,0,0,0,0,3,32,0
0,0,0,0,2,0,22,35,0,0,0,0,0,0,0,0,9,0,0
0,0,0,0,0,0,22,35,0,0,0,0,0,0,0,0,9,0,0
0,0,0,0,0,0,22,3,31,9,31,9,31,3,0,0,3,32,0
0,0,0,0,0,0,22,23,0,0,0,0,2,38,25,25,39,0,0
0,0,0,0,0,0,0,0,0,0,0,0,0,0,33,33,39,0,0
0,0,0,0,0,0,0,0,0,0,0,0,0,0,0,0,0,0,0
:endlayer
layer: 11
0,0,0,0,0,0,0,0,0,0,0,0,0,0,0,0,0,0,0
0,0,0,0,0,0,0,0,0,0,0,0,0,0,0,0,0,0,0
0,0,0,0,0,0,0,0,0,0,0,0,0,0,0,0,0,0,0
0,0,0,0,0,0,0,0,0,0,0,0,0,0,0,0,0,0,0
0,0,0,2,0,2,0,22,23,0,0,0,38,39,0,0,0,0,0
0,0,0,0,0,0,0,22,25,25,25,25,25,39,0,0,0,0,0
0,0,0,0,0,0,0,22,35,0,0,0,40,39,0,2,0,0,0
0,0,0,0,0,8,8,22,35,0,0,0,40,39,8,8,8,8,0
0,0,0,0,0,7,3,31,35,0,0,0,34,34,34,34,3,23,0
0,0,0,0,0,16,9,0,0,0,0,0,0,0,0,0,9,16,0
0,0,0,0,0,16,9,0,0,0,0,0,0,0,0,0,9,16,0
0,0,0,0,0,36,3,31,35,0,0,0,0,0,0,19,3,23,0
0,0,0,0,2,33,33,22,35,0,0,0,0,0,0,0,9,16,0
0,0,0,0,0,0,0,22,35,0,0,0,0,0,0,0,9,16,0
0,0,0,0,0,0,0,22,25,25,25,25,25,3,37,37,3,23,0
0,0,0,0,0,0,0,22,23,0,0,0,2,39,33,33,33,33,0
0,0,0,0,0,0,0,0,0,0,0,0,0,0,0,0,0,0,0
0,0,0,0,0,0,0,0,0,0,0,0,0,0,0,0,0,0,0
:endlayer
layer: 12
0,0,0,0,0,0,0,0,0,0,0,0,0,0,0,0,0,0,0
0,0,0,0,0,0,0,0,0,0,0,0,0,0,0,0,0,0,0
0,0,0,0,0,0,0,0,0,0,0,0,0,0,0,0,0,0,0
0,0,0,0,0,0,0,0,0,0,0,0,0,0,0,0,0,0,0
0,0,0,29,0,2,0,0,22,23,16,38,39,0,0,0,0,0,0
0,0,0,0,0,0,0,0,22,31,31,31,39,0,0,0,0,0,0
0,0,0,0,0,0,0,0,22,35,18,40,39,0,0,2,0,0,0
0,0,0,0,0,0,0,0,22,35,0,40,39,0,0,0,0,0,0
0,0,0,0,0,8,8,8,8,35,0,40,8,8,8,8,8,8,0
0,0,0,0,0,22,24,34,34,35,0,40,34,34,34,34,24,39,0
0,0,0,0,0,22,24,37,37,35,0,0,0,0,0,0,24,39,0
0,0,0,0,0,33,33,33,33,35,0,0,0,0,0,0,24,39,0
0,0,0,0,2,0,0,0,22,35,0,0,0,0,0,0,24,39,0
0,0,0,0,0,0,0,0,22,35,10,40,37,37,37,37,24,39,0
0,0,0,0,0,0,0,0,22,31,31,31,39,33,33,33,33,33,0
0,0,0,0,0,0,0,0,22,23,16,38,2,0,0,0,0,0,0
0,0,0,0,0,0,0,0,0,0,0,0,0,0,0,0,0,0,0
0,0,0,0,0,0,0,0,0,0,0,0,0,0,0,0,0,0,0
:endlayer
layer: 13
0,0,0,0,0,0,0,0,0,0,0,0,0,0,0,0,0,0,0
0,0,0,0,0,0,0,0,0,0,0,0,0,0,0,0,0,0,0
0,0,0,0,0,0,0,0,0,0,0,0,0,0,0,0,0,0,0
0,0,0,0,0,0,0,0,0,0,0,0,0,0,0,0,0,0,0
0,0,0,5,0,29,0,0,0,22,8,39,0,0,0,0,0,0,0
0,0,0,0,0,0,0,0,0,22,24,39,0,0,0,0,0,0,0
0,0,0,0,0,0,0,0,0,22,24,39,0,0,0,2,0,0,0
0,0,0,0,0,0,0,0,0,22,24,39,0,0,0,0,0,0,0
0,0,0,0,0,0,0,0,0,22,24,39,0,0,0,0,0,0,0
0,0,0,0,0,0,22,8,8,8,24,8,8,8,8,8,39,0,0
0,0,0,0,0,0,22,33,33,33,24,34,34,34,34,40,39,0,0
0,0,0,0,0,0,0,0,0,22,24,41,41,41,41,40,39,0,0
0,0,0,0,2,0,0,0,0,22,24,37,37,37,37,37,39,0,0
0,0,0,0,0,0,0,0,0,22,24,39,33,33,33,33,39,0,0
0,0,0,0,0,0,0,0,0,22,24,39,0,0,0,0,0,0,0
0,0,0,0,0,0,0,0,0,22,33,39,2,0,0,0,0,0,0
0,0,0,0,0,0,0,0,0,0,0,0,0,0,0,0,0,0,0
0,0,0,0,0,0,0,0,0,0,0,0,0,0,0,0,0,0,0
:endlayer
layer: 14
0,0,0,0,0,0,0,0,0,0,0,0,0,0,0,0,0,0,0
0,0,0,0,0,0,0,0,0,0,0,0,0,0,0,0,0,0,0
0,0,0,0,0,0,0,0,0,0,0,0,0,0,0,0,0,0,0
0,0,0,0,0,0,0,0,0,0,0,0,0,0,0,0,0,0,0
0,0,0,0,0,5,0,0,0,0,0,0,0,0,0,0,0,0,0
0,0,0,0,0,0,0,0,0,0,27,0,0,0,0,0,0,0,0
0,0,0,0,0,0,0,0,0,0,27,0,0,0,0,2,0,0,0
0,0,0,0,0,0,0,0,0,0,27,0,0,0,0,0,0,0,0
0,0,0,0,0,0,0,0,0,0,27,0,0,0,0,0,0,0,0
0,0,0,0,0,0,0,0,0,0,27,0,0,0,0,0,0,0,0
0,0,0,0,0,0,0,0,0,0,27,27,27,27,27,27,0,0,0
0,0,0,0,0,0,0,0,0,0,27,26,26,26,26,27,0,0,0
0,0,0,0,29,0,0,0,0,0,27,27,27,27,27,27,0,0,0
0,0,0,0,0,0,0,0,0,0,27,0,0,0,0,0,0,0,0
0,0,0,0,0,0,0,0,0,0,27,0,0,0,0,0,0,0,0
0,0,0,0,0,0,0,0,0,0,0,0,2,0,0,0,0,0,0
0,0,0,0,0,0,0,0,0,0,0,0,0,0,0,0,0,0,0
0,0,0,0,0,0,0,0,0,0,0,0,0,0,0,0,0,0,0
:endlayer
layer: 15
0,0,0,0,0,0,0,0,0,0,0,0,0,0,0,0,0,0,0
0,0,0,0,0,0,0,0,0,0,0,0,0,0,0,0,0,0,0
0,0,0,0,0,0,0,0,0,0,0,0,0,0,0,0,0,0,0
0,0,0,0,0,0,0,0,0,0,0,0,0,0,0,0,0,0,0
0,0,0,0,0,0,0,0,0,0,0,0,0,0,0,0,0,0,0
0,0,0,0,0,0,0,0,0,0,0,0,0,0,0,0,0,0,0
0,0,0,0,0,0,0,0,0,0,0,0,0,0,0,29,0,0,0
0,0,0,0,0,0,0,0,0,0,0,0,0,0,0,0,0,0,0
0,0,0,0,0,0,0,0,0,0,0,0,0,0,0,0,0,0,0
0,0,0,0,0,0,0,0,0,0,0,0,0,0,0,0,0,0,0
0,0,0,0,0,0,0,0,0,0,0,0,0,0,0,0,0,0,0
0,0,0,0,0,0,0,0,0,0,0,0,42,0,0,0,0,0,0
0,0,0,0,5,0,0,0,0,0,0,0,0,0,0,0,0,0,0
0,0,0,0,0,0,0,0,0,0,0,0,0,0,0,0,0,0,0
0,0,0,0,0,0,0,0,0,0,0,0,0,0,0,0,0,0,0
0,0,0,0,0,0,0,0,0,0,0,0,29,0,0,0,0,0,0
0,0,0,0,0,0,0,0,0,0,0,0,0,0,0,0,0,0,0
0,0,0,0,0,0,0,0,0,0,0,0,0,0,0,0,0,0,0
:endlayer
layer: 16
0,0,0,0,0,0,0,0,0,0,0,0,0,0,0,0,0,0,0
0,0,0,0,0,0,0,0,0,0,0,0,0,0,0,0,0,0,0
0,0,0,0,0,0,0,0,0,0,0,0,0,0,0,0,0,0,0
0,0,0,0,0,0,0,0,0,0,0,0,0,0,0,0,0,0,0
0,0,0,0,0,0,0,0,0,0,0,0,0,0,0,0,0,0,0
0,0,0,0,0,0,0,0,0,0,0,0,0,0,0,0,0,0,0
0,0,0,0,0,0,0,0,0,0,0,0,0,0,0,5,0,0,0
0,0,0,0,0,0,0,0,0,0,0,0,0,0,0,0,0,0,0
0,0,0,0,0,0,0,0,0,0,0,0,0,0,0,0,0,0,0
0,0,0,0,0,0,0,0,0,0,0,0,0,0,0,0,0,0,0
0,0,0,0,0,0,0,0,0,0,0,0,0,0,0,0,0,0,0
0,0,0,0,0,0,0,0,0,0,0,0,0,0,0,0,0,0,0
0,0,0,0,0,0,0,0,0,0,0,0,0,0,0,0,0,0,0
0,0,0,0,0,0,0,0,0,0,0,0,0,0,0,0,0,0,0
0,0,0,0,0,0,0,0,0,0,0,0,0,0,0,0,0,0,0
0,0,0,0,0,0,0,0,0,0,0,0,5,0,0,0,0,0,0
0,0,0,0,0,0,0,0,0,0,0,0,0,0,0,0,0,0,0
0,0,0,0,0,0,0,0,0,0,0,0,0,0,0,0,0,0,0
:endlayer

#### RULES ####
rule:
plugin=vanillaBlocks
number=1
data:
JSON:{blockState:{blockName:"minecraft:grass",properties:{snowy:"false"}}}
:enddata
:endrule

rule:
plugin=vanillaBlocks
number=2
data:
JSON:{blockState:{blockName:"minecraft:cobblestone"}}
:enddata
:endrule

rule:
plugin=vanillaBlocks
number=3
data:
JSON:{blockState:{blockName:"minecraft:log",properties:{variant:"oak",axis:"y"}}}
:enddata
:endrule

rule:
plugin=vanillaBlocks
number=4
data:
JSON:{blockState:{blockName:"minecraft:stone_stairs",properties:{half:"bottom",shape:"straight",facing:"north"}}}
:enddata
:endrule

rule:
plugin=vanillaBlocks
number=5
data:
JSON:{blockState:{blockName:"minecraft:stone_slab",properties:{half:"bottom",variant:"cobblestone"}}}
:enddata
:endrule

rule:
plugin=vanillaBlocks
number=6
data:
JSON:{blockState:{blockName:"ancientwarfarestructure:fire_pit",properties:{lit:"true",variant:"log"}}}
:enddata
:endrule

rule:
plugin=vanillaBlocks
number=7
data:
JSON:{blockState:{blockName:"minecraft:spruce_stairs",properties:{half:"top",shape:"straight",facing:"north"}}}
:enddata
:endrule

rule:
plugin=vanillaBlocks
number=8
data:
JSON:{blockState:{blockName:"minecraft:spruce_stairs",properties:{half:"bottom",shape:"straight",facing:"south"}}}
:enddata
:endrule

rule:
plugin=vanillaBlocks
number=9
data:
JSON:{blockState:{blockName:"minecraft:stained_glass_pane",properties:{east:"false",color:"green",south:"false",north:"false",west:"false"}}}
:enddata
:endrule

rule:
plugin=vanillaBlocks
number=10
data:
JSON:{blockState:{blockName:"minecraft:torch",properties:{facing:"north"}}}
:enddata
:endrule

rule:
plugin=vanillaBlocks
number=11
data:
JSON:{blockState:{blockName:"minecraft:stone_stairs",properties:{half:"top",shape:"straight",facing:"north"}}}
:enddata
:endrule

rule:
plugin=vanillaBlocks
number=12
data:
JSON:{blockState:{blockName:"minecraft:stone_stairs",properties:{half:"bottom",shape:"straight",facing:"east"}}}
:enddata
:endrule

rule:
plugin=vanillaBlocks
number=13
data:
JSON:{blockState:{blockName:"minecraft:stone_slab",properties:{half:"top",variant:"cobblestone"}}}
:enddata
:endrule

rule:
plugin=vanillaBlocks
number=14
data:
JSON:{blockState:{blockName:"minecraft:stone_stairs",properties:{half:"top",shape:"straight",facing:"east"}}}
:enddata
:endrule

rule:
plugin=vanillaBlocks
number=15
data:
JSON:{blockState:{blockName:"minecraft:stone_stairs",properties:{half:"bottom",shape:"straight",facing:"west"}}}
:enddata
:endrule

rule:
plugin=vanillaBlocks
number=16
data:
JSON:{blockState:{blockName:"minecraft:wooden_slab",properties:{half:"top",variant:"spruce"}}}
:enddata
:endrule

rule:
plugin=vanillaBlocks
number=17
data:
JSON:{blockState:{blockName:"minecraft:torch",properties:{facing:"east"}}}
:enddata
:endrule

rule:
plugin=vanillaBlocks
number=18
data:
JSON:{blockState:{blockName:"minecraft:torch",properties:{facing:"south"}}}
:enddata
:endrule

rule:
plugin=vanillaBlocks
number=19
data:
JSON:{blockState:{blockName:"minecraft:torch",properties:{facing:"west"}}}
:enddata
:endrule

rule:
plugin=vanillaBlocks
number=20
data:
JSON:{blockState:{blockName:"minecraft:stone_stairs",properties:{half:"top",shape:"straight",facing:"south"}}}
:enddata
:endrule

rule:
plugin=vanillaBlocks
number=21
data:
JSON:{blockState:{blockName:"minecraft:stone_stairs",properties:{half:"top",shape:"straight",facing:"west"}}}
:enddata
:endrule

rule:
plugin=vanillaBlocks
number=22
data:
JSON:{blockState:{blockName:"minecraft:spruce_stairs",properties:{half:"bottom",shape:"straight",facing:"east"}}}
:enddata
:endrule

rule:
plugin=vanillaBlocks
number=23
data:
JSON:{blockState:{blockName:"minecraft:spruce_stairs",properties:{half:"top",shape:"straight",facing:"west"}}}
:enddata
:endrule

rule:
plugin=vanillaBlocks
number=24
data:
JSON:{blockState:{blockName:"minecraft:log",properties:{variant:"oak",axis:"z"}}}
:enddata
:endrule

rule:
plugin=vanillaBlocks
number=25
data:
JSON:{blockState:{blockName:"minecraft:log",properties:{variant:"oak",axis:"x"}}}
:enddata
:endrule

rule:
plugin=vanillaBlocks
number=26
data:
JSON:{blockState:{blockName:"minecraft:planks",properties:{variant:"spruce"}}}
:enddata
:endrule

rule:
plugin=vanillaBlocks
number=27
data:
JSON:{blockState:{blockName:"minecraft:wooden_slab",properties:{half:"bottom",variant:"spruce"}}}
:enddata
:endrule

rule:
plugin=vanillaBlocks
number=28
data:
JSON:{blockState:{blockName:"minecraft:trapdoor",properties:{half:"top",facing:"south",open:"true"}}}
:enddata
:endrule

rule:
plugin=vanillaBlocks
number=29
data:
JSON:{blockState:{blockName:"minecraft:cobblestone_wall",properties:{east:"false",south:"false",north:"false",variant:"cobblestone",west:"false",up:"false"}}}
:enddata
:endrule

rule:
plugin=vanillaBlocks
number=30
data:
JSON:{blockState:{blockName:"minecraft:trapdoor",properties:{half:"top",facing:"east",open:"true"}}}
:enddata
:endrule

rule:
plugin=vanillaBlocks
number=31
data:
JSON:{blockState:{blockName:"minecraft:planks",properties:{variant:"oak"}}}
:enddata
:endrule

rule:
plugin=vanillaBlocks
number=32
data:
JSON:{blockState:{blockName:"minecraft:spruce_fence",properties:{east:"false",south:"false",north:"false",west:"false"}}}
:enddata
:endrule

rule:
plugin=vanillaBlocks
number=33
data:
JSON:{blockState:{blockName:"minecraft:spruce_stairs",properties:{half:"bottom",shape:"straight",facing:"north"}}}
:enddata
:endrule

rule:
plugin=vanillaBlocks
number=34
data:
JSON:{blockState:{blockName:"minecraft:oak_stairs",properties:{half:"top",shape:"straight",facing:"north"}}}
:enddata
:endrule

rule:
plugin=vanillaBlocks
number=35
data:
JSON:{blockState:{blockName:"minecraft:oak_stairs",properties:{half:"top",shape:"straight",facing:"west"}}}
:enddata
:endrule

rule:
plugin=vanillaBlocks
number=36
data:
JSON:{blockState:{blockName:"minecraft:spruce_stairs",properties:{half:"top",shape:"straight",facing:"south"}}}
:enddata
:endrule

rule:
plugin=vanillaBlocks
number=37
data:
JSON:{blockState:{blockName:"minecraft:oak_stairs",properties:{half:"top",shape:"straight",facing:"south"}}}
:enddata
:endrule

rule:
plugin=vanillaBlocks
number=38
data:
JSON:{blockState:{blockName:"minecraft:spruce_stairs",properties:{half:"top",shape:"straight",facing:"east"}}}
:enddata
:endrule

rule:
plugin=vanillaBlocks
number=39
data:
JSON:{blockState:{blockName:"minecraft:spruce_stairs",properties:{half:"bottom",shape:"straight",facing:"west"}}}
:enddata
:endrule

rule:
plugin=vanillaBlocks
number=40
data:
JSON:{blockState:{blockName:"minecraft:oak_stairs",properties:{half:"top",shape:"straight",facing:"east"}}}
:enddata
:endrule

rule:
plugin=vanillaBlocks
number=41
data:
JSON:{blockState:{blockName:"minecraft:wooden_slab",properties:{half:"top",variant:"oak"}}}
:enddata
:endrule

rule:
plugin=vanillaBlocks
number=42
data:
JSON:{blockState:{blockName:"minecraft:torch",properties:{facing:"up"}}}
:enddata
:endrule

#### ENTITIES ####
