# Ancient Warfare Structure Template File
# Auto-generated structure template file. created on: 6/4/2023 at: 23:21:50
# Lines beginning with # denote comments

header:
version=2.11
name=SB_MarenCol_House_1H2R_1_spruce
mods=
size=13,11,14
offset=5,1,13
:endheader

#### VALIDATION ####
validation:
type=ground
structureAuthor=TheOddlySeagull
survival=true
worldGenEnabled=false
unique=false
preserveBlocks=false
preventNaturalHostileSpawns=false
selectionWeight=1
clusterValue=1
minDuplicateDistance=1
dimensionWhiteList=true
dimensionList=
biomeGroupList=
biomeWhiteList=true
biomeList=
leveling=0
fill=0
border=0
blockSwap=false
territoryName=
biomeReplacement=minecraft:
minGenerationHeight=0
maxGenerationHeight=255
:endvalidation

#### LAYERS ####
layer: 0
1,1,1,1,1,1,1,1,1,1,1,1,1
1,1,1,1,1,1,1,2,3,3,3,2,1
1,1,1,4,4,4,1,5,6,6,6,5,1
1,2,4,4,4,4,4,5,6,6,6,5,1
1,5,4,4,4,4,4,5,6,6,6,5,1
1,5,4,4,4,4,4,2,3,3,3,2,1
1,5,4,4,4,4,4,5,6,6,6,5,1
1,5,4,4,4,4,4,5,6,6,6,5,1
1,5,4,4,4,4,4,5,6,6,6,5,1
1,5,4,4,4,4,4,5,6,6,6,5,1
1,2,3,2,4,4,4,5,3,3,3,2,1
1,1,1,5,4,4,4,5,1,1,1,1,1
1,1,1,2,3,3,3,2,1,1,1,1,1
1,1,1,1,4,4,4,1,1,1,1,1,1
:endlayer
layer: 1
0,0,0,0,0,0,0,0,0,0,0,0,0
0,0,0,0,0,0,0,2,6,6,6,2,0
0,0,0,4,4,4,0,6,0,0,0,6,0
0,2,4,7,7,7,4,2,0,0,0,6,0
0,6,0,8,8,8,0,0,0,0,0,6,0
0,2,0,0,0,0,0,2,6,6,6,2,0
0,6,0,0,0,0,0,0,0,0,0,6,0
0,6,0,0,0,0,0,2,0,0,0,6,0
0,2,0,0,0,0,0,6,0,0,0,2,0
0,6,0,0,0,0,0,6,0,0,0,6,0
0,2,6,2,0,0,0,2,6,6,6,2,0
0,0,0,6,0,0,0,6,0,0,0,0,0
0,0,0,2,6,9,6,2,0,0,0,0,0
0,0,0,0,0,0,0,0,0,0,0,0,0
:endlayer
layer: 2
0,0,0,0,0,0,0,0,0,0,0,0,0
0,0,0,0,0,0,0,2,6,10,6,2,0
0,0,0,4,4,4,0,6,0,0,0,6,0
0,2,4,0,0,0,4,2,0,0,0,10,0
0,6,0,0,0,0,0,0,0,0,0,6,0
0,2,0,0,0,0,0,2,6,6,6,2,0
0,10,0,0,0,0,0,0,0,0,0,10,0
0,10,0,0,0,0,0,2,0,0,0,10,0
0,2,0,0,0,0,0,6,0,0,0,2,0
0,6,0,0,0,0,0,6,0,0,0,6,0
0,2,6,2,0,0,0,2,6,10,6,2,0
0,0,0,6,0,0,0,6,0,0,0,0,0
0,0,0,2,6,11,6,2,0,0,0,0,0
0,0,0,0,0,0,0,0,0,0,0,0,0
:endlayer
layer: 3
0,0,0,0,0,0,0,12,0,0,0,12,0
0,0,0,0,0,0,13,2,6,10,6,2,14
0,12,0,15,4,16,0,6,0,0,0,6,0
13,2,4,17,0,18,4,2,0,0,0,10,0
0,6,0,0,0,0,0,6,0,12,0,6,0
0,2,14,0,0,0,13,2,6,6,6,2,0
0,10,0,0,0,0,0,6,0,0,0,10,0
0,10,0,0,0,0,13,2,14,0,0,10,0
0,2,14,0,0,0,0,6,0,0,13,2,0
0,6,0,12,0,0,0,6,0,0,0,6,0
13,2,6,2,14,0,13,2,6,10,6,2,14
0,19,0,6,0,0,0,6,0,0,0,19,0
0,0,13,2,6,6,6,2,14,0,0,0,0
0,0,0,19,0,0,0,19,0,0,0,0,0
:endlayer
layer: 4
0,0,0,0,0,0,20,21,0,0,0,22,23
0,0,0,0,0,0,20,2,3,3,3,2,23
24,24,24,24,4,24,24,5,0,0,0,5,24
25,2,3,4,4,4,3,5,0,0,0,5,25
0,5,0,0,0,0,0,5,0,0,0,5,0
0,5,0,0,0,0,0,5,3,3,3,5,0
0,5,0,0,0,0,0,5,0,19,0,5,0
0,5,0,0,0,0,0,5,0,0,0,5,0
0,5,0,0,0,0,0,5,0,0,0,5,0
0,5,0,0,0,0,0,5,0,12,0,5,0
26,2,3,2,21,0,22,5,3,3,3,2,26
27,27,20,5,0,0,0,5,27,27,27,27,27
0,0,20,2,3,3,3,2,23,0,0,0,0
0,0,20,21,0,0,0,22,23,0,0,0,0
:endlayer
layer: 5
0,0,0,0,0,0,0,20,21,0,22,23,0
0,0,0,0,0,0,0,20,2,6,2,23,0
0,0,0,0,4,0,0,20,21,0,22,23,0
24,24,24,24,24,24,24,20,21,0,22,23,24
25,2,25,25,25,25,25,2,21,0,22,2,25
0,6,0,0,0,0,0,6,6,6,6,6,0
0,6,0,0,0,0,0,6,0,0,0,6,0
0,6,0,0,0,0,0,6,0,0,0,6,0
0,6,0,0,0,0,0,6,0,0,0,6,0
26,2,26,26,26,26,26,2,26,26,26,2,26
27,27,27,20,3,3,3,23,27,27,27,27,27
0,0,0,20,21,0,22,23,0,0,0,0,0
0,0,0,20,2,6,2,23,0,0,0,0,0
0,0,0,20,21,0,22,23,0,0,0,0,0
:endlayer
layer: 6
0,0,0,0,0,0,0,0,20,26,23,0,0
0,0,0,0,0,0,0,0,20,2,23,0,0
0,0,0,0,4,0,0,0,20,5,23,0,0
0,0,0,0,0,0,0,0,20,5,23,0,0
24,24,24,24,24,24,24,24,20,5,23,24,24
25,2,25,25,25,25,25,2,3,3,3,2,25
0,6,0,0,0,0,0,6,0,0,0,6,0
0,6,0,0,0,0,0,6,0,0,0,6,0
26,2,26,26,26,26,26,2,26,26,26,2,26
27,27,27,27,20,5,23,27,27,27,27,27,27
0,0,0,0,20,5,23,0,0,0,0,0,0
0,0,0,0,20,5,23,0,0,0,0,0,0
0,0,0,0,20,2,23,0,0,0,0,0,0
0,0,0,0,20,25,23,0,0,0,0,0,0
:endlayer
layer: 7
0,0,0,0,0,0,0,0,0,28,0,0,0
0,0,0,0,0,0,0,0,0,28,0,0,0
0,0,0,0,4,0,0,0,0,28,0,0,0
0,0,0,0,0,0,0,0,0,28,0,0,0
0,0,0,0,0,0,0,0,0,28,0,0,0
24,24,24,20,10,23,24,24,24,24,24,24,24
25,5,25,29,0,29,25,5,25,25,25,5,25
26,5,26,26,26,26,26,5,26,26,26,5,26
27,27,27,27,27,27,27,27,27,27,27,27,27
0,0,0,0,0,28,0,0,0,0,0,0,0
0,0,0,0,0,28,0,0,0,0,0,0,0
0,0,0,0,0,28,0,0,0,0,0,0,0
0,0,0,0,0,28,0,0,0,0,0,0,0
0,0,0,0,0,28,0,0,0,0,0,0,0
:endlayer
layer: 8
0,0,0,0,0,0,0,0,0,0,0,0,0
0,0,0,0,0,0,0,0,0,0,0,0,0
0,0,0,0,4,0,0,0,0,0,0,0,0
0,0,0,0,0,0,0,0,0,0,0,0,0
0,0,0,0,0,0,0,0,0,0,0,0,0
0,0,0,0,28,0,0,0,0,0,0,0,0
24,24,24,24,24,24,24,24,24,24,24,24,24
27,27,27,27,27,27,27,27,27,27,27,27,27
0,0,0,0,0,0,0,0,0,0,0,0,0
0,0,0,0,0,0,0,0,0,0,0,0,0
0,0,0,0,0,0,0,0,0,0,0,0,0
0,0,0,0,0,0,0,0,0,0,0,0,0
0,0,0,0,0,0,0,0,0,0,0,0,0
0,0,0,0,0,0,0,0,0,0,0,0,0
:endlayer
layer: 9
0,0,0,0,0,0,0,0,0,0,0,0,0
0,0,0,0,0,0,0,0,0,0,0,0,0
0,0,0,0,30,0,0,0,0,0,0,0,0
0,0,0,0,0,0,0,0,0,0,0,0,0
0,0,0,0,0,0,0,0,0,0,0,0,0
0,0,0,0,0,0,0,0,0,0,0,0,0
0,0,0,0,0,0,0,0,0,0,0,0,0
0,0,0,0,0,0,0,0,0,0,0,0,0
0,0,0,0,0,0,0,0,0,0,0,0,0
0,0,0,0,0,0,0,0,0,0,0,0,0
0,0,0,0,0,0,0,0,0,0,0,0,0
0,0,0,0,0,0,0,0,0,0,0,0,0
0,0,0,0,0,0,0,0,0,0,0,0,0
0,0,0,0,0,0,0,0,0,0,0,0,0
:endlayer
layer: 10
0,0,0,0,0,0,0,0,0,0,0,0,0
0,0,0,0,0,0,0,0,0,0,0,0,0
0,0,0,0,8,0,0,0,0,0,0,0,0
0,0,0,0,0,0,0,0,0,0,0,0,0
0,0,0,0,0,0,0,0,0,0,0,0,0
0,0,0,0,0,0,0,0,0,0,0,0,0
0,0,0,0,0,0,0,0,0,0,0,0,0
0,0,0,0,0,0,0,0,0,0,0,0,0
0,0,0,0,0,0,0,0,0,0,0,0,0
0,0,0,0,0,0,0,0,0,0,0,0,0
0,0,0,0,0,0,0,0,0,0,0,0,0
0,0,0,0,0,0,0,0,0,0,0,0,0
0,0,0,0,0,0,0,0,0,0,0,0,0
0,0,0,0,0,0,0,0,0,0,0,0,0
:endlayer

#### RULES ####
rule:
plugin=vanillaBlocks
number=1
data:
JSON:{blockState:{blockName:"minecraft:grass",properties:{snowy:"false"}}}
:enddata
:endrule

rule:
plugin=vanillaBlocks
number=2
data:
JSON:{blockState:{blockName:"minecraft:log",properties:{variant:"spruce",axis:"y"}}}
:enddata
:endrule

rule:
plugin=vanillaBlocks
number=3
data:
JSON:{blockState:{blockName:"minecraft:log",properties:{variant:"spruce",axis:"x"}}}
:enddata
:endrule

rule:
plugin=vanillaBlocks
number=4
data:
JSON:{blockState:{blockName:"minecraft:cobblestone"}}
:enddata
:endrule

rule:
plugin=vanillaBlocks
number=5
data:
JSON:{blockState:{blockName:"minecraft:log",properties:{variant:"spruce",axis:"z"}}}
:enddata
:endrule

rule:
plugin=vanillaBlocks
number=6
data:
JSON:{blockState:{blockName:"minecraft:planks",properties:{variant:"spruce"}}}
:enddata
:endrule

rule:
plugin=vanillaBlocks
number=7
data:
JSON:{blockState:{blockName:"ancientwarfarestructure:fire_pit",properties:{lit:"false",variant:"log"}}}
:enddata
:endrule

rule:
plugin=vanillaBlocks
number=8
data:
JSON:{blockState:{blockName:"minecraft:stone_slab",properties:{half:"bottom",variant:"cobblestone"}}}
:enddata
:endrule

rule:
plugin=doors
number=9
data:
JSON:{blockState:{blockName:"minecraft:wooden_door",properties:{hinge:"left",half:"lower",powered:"false",facing:"north",open:"false"}}}
:enddata
:endrule

rule:
plugin=vanillaBlocks
number=10
data:
JSON:{blockState:{blockName:"minecraft:spruce_fence",properties:{east:"false",south:"false",north:"false",west:"false"}}}
:enddata
:endrule

rule:
plugin=doors
number=11
data:
JSON:{blockState:{blockName:"minecraft:wooden_door",properties:{hinge:"left",half:"upper",powered:"false",facing:"north",open:"false"}}}
:enddata
:endrule

rule:
plugin=vanillaBlocks
number=12
data:
JSON:{blockState:{blockName:"minecraft:torch",properties:{facing:"north"}}}
:enddata
:endrule

rule:
plugin=vanillaBlocks
number=13
data:
JSON:{blockState:{blockName:"minecraft:torch",properties:{facing:"west"}}}
:enddata
:endrule

rule:
plugin=vanillaBlocks
number=14
data:
JSON:{blockState:{blockName:"minecraft:torch",properties:{facing:"east"}}}
:enddata
:endrule

rule:
plugin=vanillaBlocks
number=15
data:
JSON:{blockState:{blockName:"minecraft:stone_stairs",properties:{half:"bottom",shape:"straight",facing:"east"}}}
:enddata
:endrule

rule:
plugin=vanillaBlocks
number=16
data:
JSON:{blockState:{blockName:"minecraft:stone_stairs",properties:{half:"bottom",shape:"straight",facing:"west"}}}
:enddata
:endrule

rule:
plugin=vanillaBlocks
number=17
data:
JSON:{blockState:{blockName:"minecraft:stone_stairs",properties:{half:"top",shape:"straight",facing:"west"}}}
:enddata
:endrule

rule:
plugin=vanillaBlocks
number=18
data:
JSON:{blockState:{blockName:"minecraft:stone_stairs",properties:{half:"top",shape:"straight",facing:"east"}}}
:enddata
:endrule

rule:
plugin=vanillaBlocks
number=19
data:
JSON:{blockState:{blockName:"minecraft:torch",properties:{facing:"south"}}}
:enddata
:endrule

rule:
plugin=vanillaBlocks
number=20
data:
JSON:{blockState:{blockName:"minecraft:spruce_stairs",properties:{half:"bottom",shape:"straight",facing:"east"}}}
:enddata
:endrule

rule:
plugin=vanillaBlocks
number=21
data:
JSON:{blockState:{blockName:"minecraft:spruce_stairs",properties:{half:"top",shape:"straight",facing:"west"}}}
:enddata
:endrule

rule:
plugin=vanillaBlocks
number=22
data:
JSON:{blockState:{blockName:"minecraft:spruce_stairs",properties:{half:"top",shape:"straight",facing:"east"}}}
:enddata
:endrule

rule:
plugin=vanillaBlocks
number=23
data:
JSON:{blockState:{blockName:"minecraft:spruce_stairs",properties:{half:"bottom",shape:"straight",facing:"west"}}}
:enddata
:endrule

rule:
plugin=vanillaBlocks
number=24
data:
JSON:{blockState:{blockName:"minecraft:spruce_stairs",properties:{half:"bottom",shape:"straight",facing:"south"}}}
:enddata
:endrule

rule:
plugin=vanillaBlocks
number=25
data:
JSON:{blockState:{blockName:"minecraft:spruce_stairs",properties:{half:"top",shape:"straight",facing:"north"}}}
:enddata
:endrule

rule:
plugin=vanillaBlocks
number=26
data:
JSON:{blockState:{blockName:"minecraft:spruce_stairs",properties:{half:"top",shape:"straight",facing:"south"}}}
:enddata
:endrule

rule:
plugin=vanillaBlocks
number=27
data:
JSON:{blockState:{blockName:"minecraft:spruce_stairs",properties:{half:"bottom",shape:"straight",facing:"north"}}}
:enddata
:endrule

rule:
plugin=vanillaBlocks
number=28
data:
JSON:{blockState:{blockName:"minecraft:wooden_slab",properties:{half:"bottom",variant:"spruce"}}}
:enddata
:endrule

rule:
plugin=vanillaBlocks
number=29
data:
JSON:{blockState:{blockName:"minecraft:wooden_slab",properties:{half:"top",variant:"spruce"}}}
:enddata
:endrule

rule:
plugin=vanillaBlocks
number=30
data:
JSON:{blockState:{blockName:"minecraft:cobblestone_wall",properties:{east:"false",south:"false",north:"false",variant:"cobblestone",west:"false",up:"false"}}}
:enddata
:endrule

#### ENTITIES ####
