# Ancient Warfare Structure Template File
# Auto-generated structure template file. created on: 1/9/2024 at: 0:51:3
# Lines beginning with # denote comments

header:
version=2.11
name=SB_DarokCol_LumberHouse_1H1R_1
mods=
size=18,15,15
offset=10,2,14
:endheader

#### VALIDATION ####
validation:
type=ground
structureAuthor=TheOddlySeagull
survival=true
worldGenEnabled=false
unique=false
preserveBlocks=false
preventNaturalHostileSpawns=true
selectionWeight=1
clusterValue=1
minDuplicateDistance=1
dimensionWhiteList=true
dimensionList=
biomeGroupList=
biomeWhiteList=true
biomeList=
leveling=10
fill=10
border=5
blockSwap=false
territoryName=
biomeReplacement=minecraft:
minGenerationHeight=0
maxGenerationHeight=255
:endvalidation

#### LAYERS ####
layer: 0
1,1,1,1,1,1,1,1,1,1,1,1,1,1,1,1,1,1
1,1,1,1,1,1,1,1,1,1,1,1,1,1,1,1,1,1
1,1,1,2,2,2,2,2,2,2,2,2,2,2,2,2,1,1
1,1,1,2,2,2,2,2,2,2,2,2,2,2,2,2,1,1
1,1,1,2,2,2,2,2,2,2,2,2,2,2,2,2,1,1
1,1,1,2,2,2,2,2,2,2,2,2,2,2,2,2,1,1
1,1,1,2,2,2,2,2,2,2,2,2,2,2,2,2,1,1
1,1,1,2,2,2,2,2,2,2,2,2,2,2,2,2,1,1
1,1,1,2,2,2,2,2,2,2,2,2,2,2,2,2,1,1
1,1,1,2,2,2,2,2,2,2,2,2,2,2,2,2,1,1
1,1,1,2,2,2,2,2,2,2,2,2,2,2,2,2,1,1
1,1,1,2,2,2,2,2,2,2,2,2,2,2,2,2,1,1
1,1,1,2,2,2,2,2,2,2,2,2,2,2,2,2,1,1
1,1,1,1,1,1,1,1,1,1,1,1,1,1,1,1,1,1
1,1,1,1,1,1,1,1,1,1,1,1,1,1,1,1,1,1
:endlayer
layer: 1
3,3,3,3,3,3,3,3,3,3,3,3,3,3,3,3,3,3
3,3,3,3,3,3,3,3,3,3,3,3,3,3,3,3,3,3
3,3,3,2,2,2,2,2,2,2,2,2,2,2,2,2,3,3
3,3,3,2,2,2,2,2,2,2,2,2,2,2,2,2,3,3
3,3,3,2,2,2,2,2,2,2,2,2,2,2,2,2,3,3
3,3,3,2,2,2,2,2,2,2,2,2,2,2,2,2,3,3
3,3,3,2,2,2,2,2,2,2,2,2,2,2,2,2,3,3
3,3,3,2,2,2,2,2,2,2,2,2,2,2,2,2,3,3
3,3,3,2,2,2,2,2,2,2,2,2,2,2,2,2,3,3
3,3,3,2,2,2,2,2,2,2,2,2,2,2,2,2,3,3
3,3,3,2,2,2,2,2,2,2,2,2,2,2,2,2,3,3
3,3,3,2,2,2,2,2,2,2,2,2,2,2,2,2,3,3
3,3,3,2,2,2,2,2,2,2,2,2,2,2,2,2,3,3
3,3,3,3,3,3,3,3,3,3,3,3,3,3,3,3,3,3
3,3,3,3,3,3,3,3,3,3,3,3,3,3,3,3,3,3
:endlayer
layer: 2
0,0,0,0,0,0,0,0,0,0,0,0,0,0,0,0,0,0
0,4,0,0,0,0,0,0,0,0,0,0,0,0,0,0,4,0
0,0,0,5,6,6,6,6,5,2,2,2,2,7,2,2,0,0
0,0,0,8,9,9,9,9,8,2,2,2,2,7,7,2,0,0
0,0,0,8,9,9,9,9,8,7,2,2,2,2,2,2,0,0
0,0,0,8,9,9,9,9,8,2,2,2,2,2,2,2,0,0
0,0,0,8,9,9,9,9,8,2,2,2,7,2,2,2,0,0
0,0,0,5,6,6,6,6,5,2,2,7,7,2,2,7,4,0
0,0,0,8,9,9,9,9,8,2,2,2,2,2,2,2,0,0
0,0,0,8,9,9,9,9,8,2,2,2,2,2,2,2,0,0
0,0,0,8,9,9,9,9,8,2,2,7,7,2,2,2,0,0
0,0,0,8,9,9,9,9,8,2,2,2,7,7,2,2,0,0
0,0,0,5,6,6,6,6,5,10,10,10,10,10,10,10,0,0
0,4,0,0,0,0,0,0,0,0,0,0,0,0,0,0,4,0
0,0,0,0,0,0,0,0,0,0,0,0,0,0,0,0,0,0
:endlayer
layer: 3
0,0,0,0,0,0,0,0,0,0,0,0,0,0,0,0,0,0
0,0,0,0,0,0,0,0,0,0,0,0,0,0,0,0,0,0
0,0,0,5,11,11,11,11,5,0,0,0,0,0,0,0,0,0
0,0,0,11,0,0,12,13,11,0,0,0,0,0,14,0,0,0
0,0,0,11,0,0,0,0,0,0,0,0,0,0,4,0,0,0
0,0,0,11,0,0,0,0,0,0,0,15,0,15,0,0,0,0
0,0,0,11,0,0,0,0,11,0,16,15,15,15,17,0,0,0
0,0,0,5,0,0,0,0,5,0,0,15,15,15,0,0,0,0
0,0,0,11,0,0,0,0,11,0,0,15,0,15,0,0,0,0
0,0,0,11,0,0,0,0,0,0,0,0,0,15,0,0,0,0
0,0,0,11,0,0,0,0,0,0,0,0,0,0,4,0,0,0
0,0,0,11,0,0,0,0,11,0,0,0,0,0,14,0,0,0
0,0,0,5,11,11,11,11,5,0,0,0,0,0,0,0,0,0
0,0,0,0,0,0,0,0,0,0,0,0,0,0,0,0,0,0
0,0,0,0,0,0,0,0,0,0,0,0,0,0,0,0,0,0
:endlayer
layer: 4
0,0,0,0,0,0,0,0,0,0,0,0,0,0,0,0,0,0
0,0,0,0,0,0,0,0,0,0,0,0,0,0,0,0,0,0
0,0,0,5,11,11,11,11,5,0,0,0,0,0,0,0,0,0
0,0,0,11,0,12,18,0,11,0,0,0,0,0,14,0,0,0
0,0,0,19,0,0,0,0,0,0,0,0,15,0,0,0,0,0
0,0,0,19,0,0,0,0,0,0,0,0,15,0,0,0,0,0
0,0,0,11,0,0,0,0,11,0,0,20,15,21,0,0,0,0
0,0,0,5,0,0,0,0,5,0,0,0,15,0,0,0,0,0
0,0,0,11,0,0,0,0,11,0,0,0,15,0,0,0,0,0
0,0,0,19,0,0,0,0,0,0,0,0,0,0,0,0,0,0
0,0,0,19,0,0,0,0,0,0,0,0,0,0,0,0,0,0
0,0,0,11,0,0,0,0,11,0,0,0,0,0,14,0,0,0
0,0,0,5,11,19,19,11,5,0,0,0,0,0,0,0,0,0
0,0,0,0,0,0,0,0,0,0,0,0,0,0,0,0,0,0
0,0,0,0,0,0,0,0,0,0,0,0,0,0,0,0,0,0
:endlayer
layer: 5
0,0,0,0,0,0,0,0,0,0,0,0,0,0,0,0,0,0
0,0,0,22,0,0,0,0,22,0,0,0,0,0,0,0,0,0
0,0,23,5,11,11,11,11,5,24,0,0,0,0,0,0,0,0
0,0,0,11,12,18,0,25,11,0,0,0,0,26,27,0,0,0
0,0,0,19,0,0,0,0,19,0,0,0,0,26,27,0,0,0
0,0,0,19,0,0,0,0,19,0,0,0,0,26,27,0,0,0
0,0,0,11,0,0,0,0,11,0,0,0,28,26,27,0,0,0
0,0,23,5,24,0,0,23,5,24,0,0,0,26,27,0,0,0
0,0,0,11,0,0,0,0,11,0,0,0,0,26,27,0,0,0
0,0,0,19,0,0,0,0,19,0,0,0,0,26,27,0,0,0
0,0,0,19,0,0,0,0,19,0,0,0,0,26,27,0,0,0
0,0,0,11,22,0,0,22,11,0,0,0,0,26,27,0,0,0
0,0,23,5,11,19,19,11,5,24,0,0,0,0,0,0,0,0
0,0,0,25,0,0,0,0,25,0,0,0,0,0,0,0,0,0
0,0,0,0,0,0,0,0,0,0,0,0,0,0,0,0,0,0
:endlayer
layer: 6
0,0,0,0,0,0,0,0,0,0,0,0,0,0,0,0,0,0
0,0,0,0,0,0,0,0,0,0,0,0,0,0,0,0,0,0
0,29,6,6,6,6,6,6,5,0,0,0,0,0,0,0,0,0
0,0,30,8,18,0,0,0,8,0,0,26,27,0,0,0,0,0
0,0,26,8,31,31,31,31,8,0,0,26,27,4,0,0,0,0
0,0,26,8,32,32,32,32,8,0,0,26,27,0,0,0,0,0
0,0,30,8,31,31,31,31,8,0,0,26,27,0,0,0,0,0
0,29,6,6,6,6,6,6,5,6,33,26,27,0,0,0,0,0
0,0,30,8,32,32,32,32,8,34,0,26,27,0,0,0,0,0
0,0,26,8,31,31,31,31,8,26,0,26,27,0,0,0,0,0
0,0,26,8,32,32,32,32,8,26,0,26,27,4,0,0,0,0
0,0,30,8,31,31,31,31,8,34,0,26,27,0,0,0,0,0
0,29,6,6,6,6,6,6,6,6,33,0,0,0,0,0,0,0
0,0,0,0,0,0,0,0,0,0,0,0,0,0,0,0,0,0
0,0,0,0,0,0,0,0,0,0,0,0,0,0,0,0,0,0
:endlayer
layer: 7
0,0,0,0,0,0,0,0,0,0,0,0,0,0,0,0,0,0
0,0,0,0,0,0,0,0,0,0,0,0,0,0,0,0,0,0
0,0,5,35,35,35,35,35,5,0,0,0,0,0,0,0,0,0
0,0,35,0,0,0,0,0,35,26,27,0,0,0,0,0,0,0
0,0,35,0,0,19,19,19,35,26,27,0,0,0,0,0,0,0
0,0,35,0,0,0,0,0,35,26,27,0,0,0,0,0,0,0
0,0,35,0,0,0,0,0,35,26,27,0,0,0,0,0,0,0
0,0,5,0,0,5,35,35,5,5,27,0,0,0,0,0,0,0
0,0,35,0,0,0,0,0,0,35,27,0,0,0,0,0,0,0
0,0,35,0,0,0,0,0,0,35,27,0,0,0,0,0,0,0
0,0,35,0,0,0,0,0,0,35,27,0,0,0,0,0,0,0
0,0,35,0,0,0,0,0,0,35,27,0,0,0,0,0,0,0
0,0,5,35,35,35,35,35,35,5,0,0,0,0,0,0,0,0
0,0,0,0,0,0,0,0,0,0,0,0,0,0,0,0,0,0
0,0,0,0,0,0,0,0,0,0,0,0,0,0,0,0,0,0
:endlayer
layer: 8
0,0,0,0,0,0,0,0,0,0,0,0,0,0,0,0,0,0
0,0,0,0,0,0,0,0,0,0,0,0,0,0,0,0,0,0
0,0,5,35,19,35,19,35,5,0,0,0,0,0,0,0,0,0
0,0,35,0,0,0,0,0,35,4,0,0,0,0,0,0,0,0
0,0,19,0,0,0,0,0,19,0,0,0,0,0,0,0,0,0
0,0,19,0,0,0,0,0,19,0,0,0,0,0,0,0,0,0
0,0,35,0,0,0,0,0,35,4,0,0,0,0,0,0,0,0
0,0,5,0,0,5,35,35,5,5,0,0,0,0,0,0,0,0
0,0,35,0,0,0,0,0,0,35,0,0,0,0,0,0,0,0
0,0,19,0,0,0,0,0,0,19,0,0,0,0,0,0,0,0
0,0,19,0,0,0,0,0,0,19,0,0,0,0,0,0,0,0
0,0,35,0,0,0,0,0,0,35,0,0,0,0,0,0,0,0
0,0,5,35,19,35,35,19,35,5,0,0,0,0,0,0,0,0
0,0,0,0,0,0,0,0,0,0,0,0,0,0,0,0,0,0
0,0,0,0,0,0,0,0,0,0,0,0,0,0,0,0,0,0
:endlayer
layer: 9
0,0,0,0,0,0,0,0,0,0,0,0,0,0,0,0,0,0
0,26,0,0,0,0,0,0,0,0,0,0,0,0,0,0,0,0
0,30,5,35,19,35,19,35,5,0,0,0,0,0,0,0,0,0
0,26,35,0,0,25,0,0,35,0,0,0,0,0,0,0,0,0
0,0,19,0,0,0,0,0,19,0,0,0,0,0,0,0,0,0
0,0,19,0,0,0,0,0,19,0,0,0,0,0,0,0,0,0
0,26,35,0,0,22,0,0,35,0,26,0,0,0,0,0,0,0
0,30,5,35,35,5,35,35,5,5,34,0,0,0,0,0,0,0
0,26,35,0,0,25,0,0,25,35,26,0,0,0,0,0,0,0
0,0,19,0,0,0,0,0,0,19,0,0,0,0,0,0,0,0
0,0,19,0,0,0,0,0,0,19,0,0,0,0,0,0,0,0
0,26,35,22,0,0,0,0,22,35,26,0,0,0,0,0,0,0
0,30,5,35,19,35,35,19,35,5,34,0,0,0,0,0,0,0
0,26,0,0,0,0,0,0,0,0,26,0,0,0,0,0,0,0
0,0,0,0,0,0,0,0,0,0,0,0,0,0,0,0,0,0
:endlayer
layer: 10
0,0,0,0,0,0,0,0,0,0,0,0,0,0,0,0,0,0
0,36,34,0,0,0,0,0,0,26,0,0,0,0,0,0,0,0
0,36,5,6,6,6,6,6,5,34,0,0,0,0,0,0,0,0
0,36,8,0,0,0,0,0,8,26,0,0,0,0,0,0,0,0
0,36,8,0,0,0,0,0,8,0,0,0,0,0,0,0,0,0
0,36,8,0,0,0,0,0,8,0,0,0,0,0,0,0,0,0
0,36,8,0,0,0,0,0,8,30,37,0,0,0,0,0,0,0
0,36,5,6,6,6,6,6,5,5,37,0,0,0,0,0,0,0
0,36,8,0,0,0,0,0,0,8,37,0,0,0,0,0,0,0
0,36,8,0,0,0,0,0,0,8,37,0,0,0,0,0,0,0
0,36,8,0,0,0,0,0,0,8,37,0,0,0,0,0,0,0
0,36,8,0,0,0,0,0,0,8,37,0,0,0,0,0,0,0
0,36,5,6,6,6,6,6,6,5,37,0,0,0,0,0,0,0
0,36,34,0,0,0,0,0,0,30,37,0,0,0,0,0,0,0
0,0,0,0,0,0,0,0,0,0,0,0,0,0,0,0,0,0
:endlayer
layer: 11
0,0,0,0,0,0,0,0,0,0,0,0,0,0,0,0,0,0
0,0,36,34,0,0,0,0,30,37,0,0,0,0,0,0,0,0
0,0,36,5,35,35,35,35,5,37,0,0,0,0,0,0,0,0
0,0,36,8,0,0,0,0,8,37,0,0,0,0,0,0,0,0
0,0,36,8,0,0,0,0,8,37,0,0,0,0,0,0,0,0
0,0,36,8,0,0,0,0,8,37,0,0,0,0,0,0,0,0
0,0,36,8,0,0,0,0,8,37,0,0,0,0,0,0,0,0
0,0,36,8,35,35,35,35,8,37,0,0,0,0,0,0,0,0
0,0,36,8,0,0,0,0,8,37,0,0,0,0,0,0,0,0
0,0,36,8,0,0,0,0,8,37,0,0,0,0,0,0,0,0
0,0,36,8,0,0,0,0,8,37,0,0,0,0,0,0,0,0
0,0,36,8,0,0,0,0,8,37,0,0,0,0,0,0,0,0
0,0,36,5,35,35,35,35,5,37,0,0,0,0,0,0,0,0
0,0,36,34,0,0,0,0,30,37,0,0,0,0,0,0,0,0
0,0,0,0,0,0,0,0,0,0,0,0,0,0,0,0,0,0
:endlayer
layer: 12
0,0,0,0,0,0,0,0,0,0,0,0,0,0,0,0,0,0
0,0,0,36,34,0,0,30,37,0,0,0,0,0,0,0,0,0
0,0,0,36,5,35,35,5,37,0,0,0,0,0,0,0,0,0
0,0,0,36,8,0,0,8,37,0,0,0,0,0,0,0,0,0
0,0,0,36,8,0,0,8,37,0,0,0,0,0,0,0,0,0
0,0,0,36,8,0,0,8,37,0,0,0,0,0,0,0,0,0
0,0,0,36,8,0,0,8,37,0,0,0,0,0,0,0,0,0
0,0,0,36,8,35,35,8,37,0,0,0,0,0,0,0,0,0
0,0,0,36,8,0,0,8,37,0,0,0,0,0,0,0,0,0
0,0,0,36,8,0,0,8,37,0,0,0,0,0,0,0,0,0
0,0,0,36,8,0,0,8,37,0,0,0,0,0,0,0,0,0
0,0,0,36,8,0,0,8,37,0,0,0,0,0,0,0,0,0
0,0,0,36,5,35,35,5,37,0,0,0,0,0,0,0,0,0
0,0,0,36,34,0,0,30,37,0,0,0,0,0,0,0,0,0
0,0,0,0,0,0,0,0,0,0,0,0,0,0,0,0,0,0
:endlayer
layer: 13
0,0,0,0,0,0,0,0,0,0,0,0,0,0,0,0,0,0
0,0,0,0,36,34,30,37,0,0,0,0,0,0,0,0,0,0
0,0,0,0,36,5,5,37,0,0,0,0,0,0,0,0,0,0
0,0,0,0,36,8,8,37,0,0,0,0,0,0,0,0,0,0
0,0,0,0,36,8,8,37,0,0,0,0,0,0,0,0,0,0
0,0,0,0,36,8,8,37,0,0,0,0,0,0,0,0,0,0
0,0,0,0,36,8,8,37,0,0,0,0,0,0,0,0,0,0
0,0,0,0,36,8,8,37,0,0,0,0,0,0,0,0,0,0
0,0,0,0,36,8,8,37,0,0,0,0,0,0,0,0,0,0
0,0,0,0,36,8,8,37,0,0,0,0,0,0,0,0,0,0
0,0,0,0,36,8,8,37,0,0,0,0,0,0,0,0,0,0
0,0,0,0,36,8,8,37,0,0,0,0,0,0,0,0,0,0
0,0,0,0,36,5,5,37,0,0,0,0,0,0,0,0,0,0
0,0,0,0,36,34,30,37,0,0,0,0,0,0,0,0,0,0
0,0,0,0,0,0,0,0,0,0,0,0,0,0,0,0,0,0
:endlayer
layer: 14
0,0,0,0,0,0,0,0,0,0,0,0,0,0,0,0,0,0
0,0,0,0,0,36,37,0,0,0,0,0,0,0,0,0,0,0
0,0,0,0,0,36,37,0,0,0,0,0,0,0,0,0,0,0
0,0,0,0,0,36,37,0,0,0,0,0,0,0,0,0,0,0
0,0,0,0,0,36,37,0,0,0,0,0,0,0,0,0,0,0
0,0,0,0,0,36,37,0,0,0,0,0,0,0,0,0,0,0
0,0,0,0,0,36,37,0,0,0,0,0,0,0,0,0,0,0
0,0,0,0,0,36,37,0,0,0,0,0,0,0,0,0,0,0
0,0,0,0,0,36,37,0,0,0,0,0,0,0,0,0,0,0
0,0,0,0,0,36,37,0,0,0,0,0,0,0,0,0,0,0
0,0,0,0,0,36,37,0,0,0,0,0,0,0,0,0,0,0
0,0,0,0,0,36,37,0,0,0,0,0,0,0,0,0,0,0
0,0,0,0,0,36,37,0,0,0,0,0,0,0,0,0,0,0
0,0,0,0,0,36,37,0,0,0,0,0,0,0,0,0,0,0
0,0,0,0,0,0,0,0,0,0,0,0,0,0,0,0,0,0
:endlayer

#### RULES ####
rule:
plugin=vanillaBlocks
number=1
data:
JSON:{blockState:{blockName:"minecraft:dirt",properties:{variant:"dirt",snowy:"false"}}}
:enddata
:endrule

rule:
plugin=vanillaBlocks
number=2
data:
JSON:{blockState:{blockName:"minecraft:cobblestone"}}
:enddata
:endrule

rule:
plugin=vanillaBlocks
number=3
data:
JSON:{blockState:{blockName:"minecraft:grass",properties:{snowy:"false"}}}
:enddata
:endrule

rule:
plugin=vanillaBlocks
number=4
data:
JSON:{blockState:{blockName:"minecraft:torch",properties:{facing:"up"}}}
:enddata
:endrule

rule:
plugin=vanillaBlocks
number=5
data:
JSON:{blockState:{blockName:"minecraft:log",properties:{variant:"spruce",axis:"y"}}}
:enddata
:endrule

rule:
plugin=vanillaBlocks
number=6
data:
JSON:{blockState:{blockName:"minecraft:log",properties:{variant:"spruce",axis:"x"}}}
:enddata
:endrule

rule:
plugin=vanillaBlocks
number=7
data:
JSON:{blockState:{blockName:"minecraft:mossy_cobblestone"}}
:enddata
:endrule

rule:
plugin=vanillaBlocks
number=8
data:
JSON:{blockState:{blockName:"minecraft:log",properties:{variant:"spruce",axis:"z"}}}
:enddata
:endrule

rule:
plugin=vanillaBlocks
number=9
data:
JSON:{blockState:{blockName:"minecraft:dirt",properties:{variant:"coarse_dirt",snowy:"false"}}}
:enddata
:endrule

rule:
plugin=vanillaBlocks
number=10
data:
JSON:{blockState:{blockName:"minecraft:stone_stairs",properties:{half:"bottom",shape:"straight",facing:"north"}}}
:enddata
:endrule

rule:
plugin=vanillaBlocks
number=11
data:
JSON:{blockState:{blockName:"minecraft:stonebrick",properties:{variant:"stonebrick"}}}
:enddata
:endrule

rule:
plugin=vanillaBlocks
number=12
data:
JSON:{blockState:{blockName:"minecraft:dark_oak_stairs",properties:{half:"top",shape:"straight",facing:"east"}}}
:enddata
:endrule

rule:
plugin=vanillaBlocks
number=13
data:
JSON:{blockState:{blockName:"minecraft:dark_oak_stairs",properties:{half:"bottom",shape:"straight",facing:"north"}}}
:enddata
:endrule

rule:
plugin=vanillaBlocks
number=14
data:
JSON:{blockState:{blockName:"minecraft:spruce_fence",properties:{east:"false",south:"false",north:"false",west:"false"}}}
:enddata
:endrule

rule:
plugin=vanillaBlocks
number=15
data:
JSON:{blockState:{blockName:"minecraft:log",properties:{variant:"oak",axis:"z"}}}
:enddata
:endrule

rule:
plugin=vanillaBlocks
number=16
data:
JSON:{blockState:{blockName:"minecraft:ladder",properties:{facing:"west"}}}
:enddata
:endrule

rule:
plugin=vanillaBlocks
number=17
data:
JSON:{blockState:{blockName:"minecraft:ladder",properties:{facing:"east"}}}
:enddata
:endrule

rule:
plugin=vanillaBlocks
number=18
data:
JSON:{blockState:{blockName:"minecraft:dark_oak_stairs",properties:{half:"bottom",shape:"straight",facing:"west"}}}
:enddata
:endrule

rule:
plugin=vanillaBlocks
number=19
data:
JSON:{blockState:{blockName:"minecraft:acacia_fence",properties:{east:"false",south:"false",north:"false",west:"false"}}}
:enddata
:endrule

rule:
plugin=vanillaBlocks
number=20
data:
JSON:{blockState:{blockName:"minecraft:rail",properties:{shape:"ascending_east"}}}
:enddata
:endrule

rule:
plugin=vanillaBlocks
number=21
data:
JSON:{blockState:{blockName:"minecraft:rail",properties:{shape:"ascending_west"}}}
:enddata
:endrule

rule:
plugin=vanillaBlocks
number=22
data:
JSON:{blockState:{blockName:"minecraft:torch",properties:{facing:"north"}}}
:enddata
:endrule

rule:
plugin=vanillaBlocks
number=23
data:
JSON:{blockState:{blockName:"minecraft:torch",properties:{facing:"west"}}}
:enddata
:endrule

rule:
plugin=vanillaBlocks
number=24
data:
JSON:{blockState:{blockName:"minecraft:torch",properties:{facing:"east"}}}
:enddata
:endrule

rule:
plugin=vanillaBlocks
number=25
data:
JSON:{blockState:{blockName:"minecraft:torch",properties:{facing:"south"}}}
:enddata
:endrule

rule:
plugin=vanillaBlocks
number=26
data:
JSON:{blockState:{blockName:"minecraft:wooden_slab",properties:{half:"top",variant:"spruce"}}}
:enddata
:endrule

rule:
plugin=vanillaBlocks
number=27
data:
JSON:{blockState:{blockName:"minecraft:wooden_slab",properties:{half:"bottom",variant:"spruce"}}}
:enddata
:endrule

rule:
plugin=vanillaBlocks
number=28
data:
JSON:{blockState:{blockName:"minecraft:rail",properties:{shape:"east_west"}}}
:enddata
:endrule

rule:
plugin=vanillaBlocks
number=29
data:
JSON:{blockState:{blockName:"minecraft:wooden_button",properties:{powered:"false",facing:"west"}}}
:enddata
:endrule

rule:
plugin=vanillaBlocks
number=30
data:
JSON:{blockState:{blockName:"minecraft:spruce_stairs",properties:{half:"top",shape:"straight",facing:"east"}}}
:enddata
:endrule

rule:
plugin=vanillaBlocks
number=31
data:
JSON:{blockState:{blockName:"minecraft:wooden_slab",properties:{half:"top",variant:"dark_oak"}}}
:enddata
:endrule

rule:
plugin=vanillaBlocks
number=32
data:
JSON:{blockState:{blockName:"minecraft:planks",properties:{variant:"dark_oak"}}}
:enddata
:endrule

rule:
plugin=vanillaBlocks
number=33
data:
JSON:{blockState:{blockName:"minecraft:wooden_button",properties:{powered:"false",facing:"east"}}}
:enddata
:endrule

rule:
plugin=vanillaBlocks
number=34
data:
JSON:{blockState:{blockName:"minecraft:spruce_stairs",properties:{half:"top",shape:"straight",facing:"west"}}}
:enddata
:endrule

rule:
plugin=vanillaBlocks
number=35
data:
JSON:{blockState:{blockName:"minecraft:planks",properties:{variant:"oak"}}}
:enddata
:endrule

rule:
plugin=vanillaBlocks
number=36
data:
JSON:{blockState:{blockName:"minecraft:spruce_stairs",properties:{half:"bottom",shape:"straight",facing:"east"}}}
:enddata
:endrule

rule:
plugin=vanillaBlocks
number=37
data:
JSON:{blockState:{blockName:"minecraft:spruce_stairs",properties:{half:"bottom",shape:"straight",facing:"west"}}}
:enddata
:endrule

#### ENTITIES ####
