# Ancient Warfare Structure Template File
# Auto-generated structure template file. created on: 1/9/2024 at: 0:17:51
# Lines beginning with # denote comments

header:
version=2.11
name=SB_DarokCol_SmithyWorkshop_1
mods=
size=15,12,15
offset=7,0,14
:endheader

#### VALIDATION ####
validation:
type=harbor
structureAuthor=TheOddlySeagull
survival=true
worldGenEnabled=false
unique=false
preserveBlocks=false
preventNaturalHostileSpawns=true
selectionWeight=1
clusterValue=1
minDuplicateDistance=1
dimensionWhiteList=true
dimensionList=
biomeGroupList=
biomeWhiteList=true
biomeList=
leveling=10
fill=10
border=5
blockSwap=false
territoryName=
biomeReplacement=minecraft:
:endvalidation

#### LAYERS ####
layer: 0
0,0,0,0,0,0,0,0,0,0,0,0,0,0,0
0,2,2,6,6,6,6,2,6,6,6,6,2,1,0
0,10,3,6,9,9,6,3,6,9,9,6,3,1,0
0,10,4,6,6,6,6,4,6,6,6,6,4,1,0
0,10,4,7,7,7,7,4,7,7,7,7,4,1,0
0,10,4,7,7,7,7,4,7,7,7,7,4,1,0
0,10,4,7,7,7,7,4,7,7,7,7,4,1,0
0,10,3,8,8,8,8,3,8,8,8,8,3,1,0
0,10,4,7,7,7,7,4,7,7,7,7,4,1,0
0,10,4,7,7,7,7,4,7,7,7,7,4,1,0
0,10,4,7,7,7,7,4,7,7,7,7,4,1,0
0,10,4,7,7,7,7,4,7,7,7,7,4,1,0
0,10,3,8,8,8,8,3,8,8,8,8,3,1,0
0,5,5,5,5,5,5,5,5,5,5,5,5,1,0
0,0,0,0,0,0,0,0,0,0,0,0,0,0,0
:endlayer
layer: 1
0,0,0,0,0,0,0,0,0,0,0,0,0,0,0
0,0,0,6,6,6,6,0,6,6,6,6,0,0,0
0,0,3,6,0,0,6,3,6,0,0,6,3,0,0
0,0,7,6,11,11,6,7,6,11,11,6,7,0,0
0,0,0,0,0,0,0,0,0,0,0,0,0,0,0
0,0,0,0,0,0,0,0,0,0,0,0,0,0,0
0,0,7,0,0,0,0,0,0,0,0,0,7,0,0
0,0,3,7,0,0,7,3,7,0,0,7,3,0,0
0,0,0,0,0,0,0,0,0,0,0,0,0,0,0
0,0,0,0,0,0,0,0,0,0,0,0,0,0,0
0,0,0,0,0,0,0,0,0,0,0,0,0,0,0
0,0,0,0,0,0,0,0,0,0,0,0,0,0,0
0,0,3,0,0,0,0,3,0,0,0,0,3,0,0
0,0,0,0,0,0,0,0,0,0,0,0,0,0,0
0,0,0,0,0,0,0,0,0,0,0,0,0,0,0
:endlayer
layer: 2
0,0,0,0,0,0,0,0,0,0,0,0,0,0,0
0,0,13,6,6,6,6,13,6,6,6,6,13,0,0
0,16,3,6,0,0,6,3,6,0,0,6,3,12,0
0,0,7,18,17,17,15,7,18,17,17,15,7,0,0
0,0,0,0,0,0,0,14,0,0,0,0,0,0,0
0,0,0,0,0,0,0,0,0,0,0,0,0,0,0
0,0,7,0,0,0,0,13,0,0,0,0,7,0,0
0,16,3,7,0,0,7,3,7,0,0,7,3,12,0
0,0,14,0,0,0,0,14,0,0,0,0,14,0,0
0,0,0,0,0,0,0,0,0,0,0,0,0,0,0
0,0,0,0,0,0,0,0,0,0,0,0,0,0,0
0,0,13,0,0,0,0,13,0,0,0,0,13,0,0
0,16,3,12,0,0,16,3,12,0,0,16,3,12,0
0,0,14,0,0,0,0,14,0,0,0,0,14,0,0
0,0,0,0,0,0,0,0,0,0,0,0,0,0,0
:endlayer
layer: 3
0,0,0,0,0,0,0,0,0,0,0,0,0,0,0
0,0,0,18,6,6,15,0,18,6,6,15,0,0,0
0,0,3,6,0,0,6,3,6,0,0,6,3,0,0
0,0,7,0,23,23,0,7,0,23,23,0,7,0,0
0,0,19,0,0,0,0,0,0,0,0,0,19,0,0
0,0,19,0,0,0,0,0,0,0,0,0,19,0,0
0,0,7,0,0,0,0,0,0,0,0,0,7,0,0
0,0,3,7,19,19,7,3,7,19,19,7,3,0,0
0,0,20,0,0,0,0,20,0,0,0,0,20,0,0
0,0,0,0,0,0,0,0,0,0,0,0,0,0,0
0,0,0,0,0,0,0,0,0,0,0,0,0,0,0
0,0,21,0,0,0,0,21,0,0,0,0,21,0,0
0,0,3,24,0,0,22,3,24,0,0,22,3,0,0
0,0,0,0,0,0,0,0,0,0,0,0,0,0,0
0,0,0,0,0,0,0,0,0,0,0,0,0,0,0
:endlayer
layer: 4
0,0,0,0,0,0,0,0,0,0,0,0,0,0,0
0,0,0,0,6,6,0,0,0,6,6,0,0,0,0
0,0,3,18,6,6,15,3,18,6,6,15,3,0,0
0,0,4,28,0,0,27,4,28,0,0,27,4,0,0
0,0,4,0,0,0,0,4,0,0,0,0,4,0,0
0,0,4,0,0,0,0,4,0,0,0,0,4,0,0
0,25,4,0,0,0,0,4,0,0,0,0,4,25,0
0,29,3,8,8,8,8,3,8,8,8,8,3,26,0
0,25,4,0,0,0,0,4,0,0,0,0,4,25,0
0,25,4,0,0,0,0,4,0,0,0,0,4,25,0
0,25,4,0,0,0,0,4,0,0,0,0,4,25,0
0,25,4,0,0,0,0,4,0,0,0,0,4,25,0
0,29,3,8,8,8,8,3,8,8,8,8,3,26,0
0,25,25,0,0,0,0,0,0,0,0,0,25,25,0
0,0,0,0,0,0,0,0,0,0,0,0,0,0,0
:endlayer
layer: 5
0,0,0,0,0,0,0,0,0,0,0,0,0,0,0
0,0,0,0,34,34,0,0,0,34,34,0,0,0,0
0,0,3,7,6,6,7,3,7,6,6,7,3,0,0
0,0,7,15,0,0,18,7,15,0,0,18,7,0,0
0,0,7,0,0,0,0,0,0,0,0,0,7,0,0
0,0,7,12,0,0,0,36,0,0,0,16,7,0,0
0,30,3,8,8,8,8,3,8,8,8,8,3,30,0
0,31,31,33,3,3,35,3,35,3,3,33,31,31,0
0,0,32,33,4,0,0,0,0,0,4,33,32,0,0
0,0,32,33,4,0,0,0,0,0,4,33,32,0,0
0,0,32,33,4,0,0,0,0,0,4,33,32,0,0
0,0,32,33,4,0,0,0,0,0,4,33,32,0,0
0,0,32,33,3,3,35,3,35,3,3,33,32,0,0
0,0,32,33,25,0,0,0,0,0,25,33,32,0,0
0,0,0,0,0,0,0,0,0,0,0,0,0,0,0
:endlayer
layer: 6
0,0,0,0,0,0,0,0,0,0,0,0,0,0,0
0,0,0,0,0,0,0,0,0,0,0,0,0,0,0
0,0,3,7,6,6,7,3,7,6,6,7,3,0,0
0,0,7,0,37,37,0,7,0,37,37,0,7,0,0
0,0,7,0,0,0,0,0,0,0,0,0,7,0,0
0,30,3,8,8,8,8,3,8,8,8,8,3,30,0
0,31,31,31,31,33,4,4,4,33,31,31,31,31,0
0,0,0,0,32,33,3,3,3,33,32,0,0,0,0
0,0,0,0,32,33,4,14,4,33,32,0,0,0,0
0,0,0,0,32,33,4,0,4,33,32,0,0,0,0
0,0,0,36,32,33,4,0,4,33,32,36,0,0,0
0,0,0,0,32,33,4,13,4,33,32,0,0,0,0
0,0,0,0,32,33,3,3,3,33,32,0,0,0,0
0,0,0,0,32,33,25,0,25,33,32,0,0,0,0
0,0,0,0,0,0,0,0,0,0,0,0,0,0,0
:endlayer
layer: 7
0,0,0,0,0,0,0,0,0,0,0,0,0,0,0
0,25,30,25,0,0,25,30,25,0,0,25,30,25,0
0,0,3,7,34,34,7,3,7,34,34,7,3,0,0
0,0,7,0,6,6,0,7,0,6,6,0,7,0,0
0,30,3,8,8,8,8,3,8,8,8,8,3,30,0
0,31,31,31,31,31,31,33,31,31,31,31,31,31,0
0,0,0,0,0,36,32,33,32,36,0,0,0,0,0
0,0,0,0,0,0,32,33,32,0,0,0,0,0,0
0,0,0,0,0,0,32,33,32,0,0,0,0,0,0
0,0,0,0,0,0,32,33,32,0,0,0,0,0,0
0,0,0,0,0,0,32,33,32,0,0,0,0,0,0
0,0,0,0,0,0,32,33,32,0,0,0,0,0,0
0,0,0,0,0,0,32,33,32,0,0,0,0,0,0
0,0,0,0,0,0,32,33,32,0,0,0,0,0,0
0,0,0,0,0,0,0,0,0,0,0,0,0,0,0
:endlayer
layer: 8
0,0,0,0,0,0,0,0,0,0,0,0,0,0,0
0,38,38,38,38,38,38,38,38,38,38,38,38,38,0
0,39,3,8,8,8,8,8,8,8,8,8,3,39,0
0,30,3,8,6,6,8,3,8,6,6,8,3,30,0
0,31,31,31,31,31,31,31,31,31,31,31,31,31,0
0,0,0,0,0,0,0,0,0,0,0,0,0,0,0
0,0,0,0,0,0,0,0,0,0,0,0,0,0,0
0,0,0,0,0,0,0,0,0,0,0,0,0,0,0
0,0,0,0,0,0,0,0,0,0,0,0,0,0,0
0,0,0,0,0,0,0,0,0,0,0,0,0,0,0
0,0,0,0,0,0,0,36,0,0,0,0,0,0,0
0,0,0,0,0,0,0,0,0,0,0,0,0,0,0
0,0,0,0,0,0,0,0,0,0,0,0,0,0,0
0,0,0,0,0,0,0,0,0,0,0,0,0,0,0
0,0,0,0,0,0,0,0,0,0,0,0,0,0,0
:endlayer
layer: 9
0,0,0,0,0,0,0,0,0,0,0,0,0,0,0
0,0,0,0,0,0,0,0,0,0,0,0,0,0,0
0,38,38,38,38,38,38,38,38,38,38,38,38,38,0
0,31,31,31,6,6,31,31,31,6,6,31,31,31,0
0,0,0,0,0,0,0,0,0,0,0,0,0,0,0
0,0,0,0,0,0,0,0,0,0,0,0,0,0,0
0,0,0,0,0,0,0,0,0,0,0,0,0,0,0
0,0,0,0,0,0,0,0,0,0,0,0,0,0,0
0,0,0,0,0,0,0,0,0,0,0,0,0,0,0
0,0,0,0,0,0,0,0,0,0,0,0,0,0,0
0,0,0,0,0,0,0,0,0,0,0,0,0,0,0
0,0,0,0,0,0,0,0,0,0,0,0,0,0,0
0,0,0,0,0,0,0,0,0,0,0,0,0,0,0
0,0,0,0,0,0,0,0,0,0,0,0,0,0,0
0,0,0,0,0,0,0,0,0,0,0,0,0,0,0
:endlayer
layer: 10
0,0,0,0,0,0,0,0,0,0,0,0,0,0,0
0,0,0,0,0,0,0,0,0,0,0,0,0,0,0
0,0,0,0,0,0,0,0,0,0,0,0,0,0,0
0,0,0,0,6,6,0,0,0,6,6,0,0,0,0
0,0,0,0,0,0,0,0,0,0,0,0,0,0,0
0,0,0,0,0,0,0,0,0,0,0,0,0,0,0
0,0,0,0,0,0,0,0,0,0,0,0,0,0,0
0,0,0,0,0,0,0,0,0,0,0,0,0,0,0
0,0,0,0,0,0,0,0,0,0,0,0,0,0,0
0,0,0,0,0,0,0,0,0,0,0,0,0,0,0
0,0,0,0,0,0,0,0,0,0,0,0,0,0,0
0,0,0,0,0,0,0,0,0,0,0,0,0,0,0
0,0,0,0,0,0,0,0,0,0,0,0,0,0,0
0,0,0,0,0,0,0,0,0,0,0,0,0,0,0
0,0,0,0,0,0,0,0,0,0,0,0,0,0,0
:endlayer
layer: 11
0,0,0,0,0,0,0,0,0,0,0,0,0,0,0
0,0,0,0,0,0,0,0,0,0,0,0,0,0,0
0,0,0,0,0,0,0,0,0,0,0,0,0,0,0
0,0,0,0,43,42,0,0,0,41,40,0,0,0,0
0,0,0,0,0,0,0,0,0,0,0,0,0,0,0
0,0,0,0,0,0,0,0,0,0,0,0,0,0,0
0,0,0,0,0,0,0,0,0,0,0,0,0,0,0
0,0,0,0,0,0,0,0,0,0,0,0,0,0,0
0,0,0,0,0,0,0,0,0,0,0,0,0,0,0
0,0,0,0,0,0,0,0,0,0,0,0,0,0,0
0,0,0,0,0,0,0,0,0,0,0,0,0,0,0
0,0,0,0,0,0,0,0,0,0,0,0,0,0,0
0,0,0,0,0,0,0,0,0,0,0,0,0,0,0
0,0,0,0,0,0,0,0,0,0,0,0,0,0,0
0,0,0,0,0,0,0,0,0,0,0,0,0,0,0
:endlayer

#### RULES ####
rule:
plugin=vanillaBlocks
number=1
data:
JSON:{blockState:{blockName:"minecraft:stone_brick_stairs",properties:{half:"bottom",shape:"straight",facing:"west"}}}
:enddata
:endrule

rule:
plugin=vanillaBlocks
number=2
data:
JSON:{blockState:{blockName:"minecraft:stone_brick_stairs",properties:{half:"bottom",shape:"straight",facing:"south"}}}
:enddata
:endrule

rule:
plugin=vanillaBlocks
number=3
data:
JSON:{blockState:{blockName:"minecraft:log",properties:{variant:"spruce",axis:"y"}}}
:enddata
:endrule

rule:
plugin=vanillaBlocks
number=4
data:
JSON:{blockState:{blockName:"minecraft:log",properties:{variant:"spruce",axis:"z"}}}
:enddata
:endrule

rule:
plugin=vanillaBlocks
number=5
data:
JSON:{blockState:{blockName:"minecraft:stone_brick_stairs",properties:{half:"bottom",shape:"straight",facing:"north"}}}
:enddata
:endrule

rule:
plugin=vanillaBlocks
number=6
data:
JSON:{blockState:{blockName:"minecraft:brick_block"}}
:enddata
:endrule

rule:
plugin=vanillaBlocks
number=7
data:
JSON:{blockState:{blockName:"minecraft:stone",properties:{variant:"smooth_andesite"}}}
:enddata
:endrule

rule:
plugin=vanillaBlocks
number=8
data:
JSON:{blockState:{blockName:"minecraft:log",properties:{variant:"spruce",axis:"x"}}}
:enddata
:endrule

rule:
plugin=vanillaBlocks
number=9
data:
JSON:{blockState:{blockName:"minecraft:coal_block"}}
:enddata
:endrule

rule:
plugin=vanillaBlocks
number=10
data:
JSON:{blockState:{blockName:"minecraft:stone_brick_stairs",properties:{half:"bottom",shape:"straight",facing:"east"}}}
:enddata
:endrule

rule:
plugin=vanillaBlocks
number=11
data:
JSON:{blockState:{blockName:"minecraft:stone_slab",properties:{half:"bottom",variant:"brick"}}}
:enddata
:endrule

rule:
plugin=vanillaBlocks
number=12
data:
JSON:{blockState:{blockName:"minecraft:torch",properties:{facing:"east"}}}
:enddata
:endrule

rule:
plugin=vanillaBlocks
number=13
data:
JSON:{blockState:{blockName:"minecraft:torch",properties:{facing:"north"}}}
:enddata
:endrule

rule:
plugin=vanillaBlocks
number=14
data:
JSON:{blockState:{blockName:"minecraft:torch",properties:{facing:"south"}}}
:enddata
:endrule

rule:
plugin=vanillaBlocks
number=15
data:
JSON:{blockState:{blockName:"minecraft:brick_stairs",properties:{half:"bottom",shape:"straight",facing:"west"}}}
:enddata
:endrule

rule:
plugin=vanillaBlocks
number=16
data:
JSON:{blockState:{blockName:"minecraft:torch",properties:{facing:"west"}}}
:enddata
:endrule

rule:
plugin=vanillaBlocks
number=17
data:
JSON:{blockState:{blockName:"minecraft:stone_slab",properties:{half:"top",variant:"brick"}}}
:enddata
:endrule

rule:
plugin=vanillaBlocks
number=18
data:
JSON:{blockState:{blockName:"minecraft:brick_stairs",properties:{half:"bottom",shape:"straight",facing:"east"}}}
:enddata
:endrule

rule:
plugin=vanillaBlocks
number=19
data:
JSON:{blockState:{blockName:"minecraft:acacia_fence",properties:{east:"false",south:"false",north:"false",west:"false"}}}
:enddata
:endrule

rule:
plugin=vanillaBlocks
number=20
data:
JSON:{blockState:{blockName:"minecraft:oak_stairs",properties:{half:"top",shape:"straight",facing:"north"}}}
:enddata
:endrule

rule:
plugin=vanillaBlocks
number=21
data:
JSON:{blockState:{blockName:"minecraft:oak_stairs",properties:{half:"top",shape:"straight",facing:"south"}}}
:enddata
:endrule

rule:
plugin=vanillaBlocks
number=22
data:
JSON:{blockState:{blockName:"minecraft:oak_stairs",properties:{half:"top",shape:"straight",facing:"east"}}}
:enddata
:endrule

rule:
plugin=vanillaBlocks
number=23
data:
JSON:{blockState:{blockName:"minecraft:brick_stairs",properties:{half:"bottom",shape:"straight",facing:"north"}}}
:enddata
:endrule

rule:
plugin=vanillaBlocks
number=24
data:
JSON:{blockState:{blockName:"minecraft:oak_stairs",properties:{half:"top",shape:"straight",facing:"west"}}}
:enddata
:endrule

rule:
plugin=vanillaBlocks
number=25
data:
JSON:{blockState:{blockName:"minecraft:wooden_slab",properties:{half:"top",variant:"spruce"}}}
:enddata
:endrule

rule:
plugin=vanillaBlocks
number=26
data:
JSON:{blockState:{blockName:"minecraft:spruce_stairs",properties:{half:"top",shape:"straight",facing:"west"}}}
:enddata
:endrule

rule:
plugin=vanillaBlocks
number=27
data:
JSON:{blockState:{blockName:"minecraft:brick_stairs",properties:{half:"top",shape:"straight",facing:"east"}}}
:enddata
:endrule

rule:
plugin=vanillaBlocks
number=28
data:
JSON:{blockState:{blockName:"minecraft:brick_stairs",properties:{half:"top",shape:"straight",facing:"west"}}}
:enddata
:endrule

rule:
plugin=vanillaBlocks
number=29
data:
JSON:{blockState:{blockName:"minecraft:spruce_stairs",properties:{half:"top",shape:"straight",facing:"east"}}}
:enddata
:endrule

rule:
plugin=vanillaBlocks
number=30
data:
JSON:{blockState:{blockName:"minecraft:spruce_stairs",properties:{half:"top",shape:"straight",facing:"south"}}}
:enddata
:endrule

rule:
plugin=vanillaBlocks
number=31
data:
JSON:{blockState:{blockName:"minecraft:spruce_stairs",properties:{half:"bottom",shape:"straight",facing:"north"}}}
:enddata
:endrule

rule:
plugin=vanillaBlocks
number=32
data:
JSON:{blockState:{blockName:"minecraft:wooden_slab",properties:{half:"bottom",variant:"spruce"}}}
:enddata
:endrule

rule:
plugin=vanillaBlocks
number=33
data:
JSON:{blockState:{blockName:"minecraft:planks",properties:{variant:"spruce"}}}
:enddata
:endrule

rule:
plugin=vanillaBlocks
number=34
data:
JSON:{blockState:{blockName:"minecraft:brick_stairs",properties:{half:"bottom",shape:"straight",facing:"south"}}}
:enddata
:endrule

rule:
plugin=vanillaBlocks
number=35
data:
JSON:{blockState:{blockName:"minecraft:planks",properties:{variant:"oak"}}}
:enddata
:endrule

rule:
plugin=vanillaBlocks
number=36
data:
JSON:{blockState:{blockName:"minecraft:torch",properties:{facing:"up"}}}
:enddata
:endrule

rule:
plugin=vanillaBlocks
number=37
data:
JSON:{blockState:{blockName:"minecraft:brick_stairs",properties:{half:"top",shape:"straight",facing:"north"}}}
:enddata
:endrule

rule:
plugin=vanillaBlocks
number=38
data:
JSON:{blockState:{blockName:"minecraft:spruce_stairs",properties:{half:"bottom",shape:"straight",facing:"south"}}}
:enddata
:endrule

rule:
plugin=vanillaBlocks
number=39
data:
JSON:{blockState:{blockName:"minecraft:spruce_stairs",properties:{half:"top",shape:"straight",facing:"north"}}}
:enddata
:endrule

rule:
plugin=vanillaFlowerPot
number=40
data:
JSON:{blockState:{blockName:"minecraft:flower_pot",properties:{contents:"empty",custom:"false",legacy_data:"0"}},itemMeta:0}
:enddata
:endrule

rule:
plugin=vanillaFlowerPot
number=41
data:
JSON:{blockState:{blockName:"minecraft:flower_pot",properties:{contents:"empty",custom:"false",legacy_data:"0"}},itemMeta:0}
:enddata
:endrule

rule:
plugin=vanillaFlowerPot
number=42
data:
JSON:{blockState:{blockName:"minecraft:flower_pot",properties:{contents:"empty",custom:"false",legacy_data:"0"}},itemMeta:0}
:enddata
:endrule

rule:
plugin=vanillaFlowerPot
number=43
data:
JSON:{blockState:{blockName:"minecraft:flower_pot",properties:{contents:"empty",custom:"false",legacy_data:"0"}},itemMeta:0}
:enddata
:endrule

#### ENTITIES ####
