# Ancient Warfare Structure Template File
# Auto-generated structure template file. created on: 10/10/2021 at: 17:1:33
# Lines beginning with # denote comments

header:
version=2.11
name=SurvivalBuild_WoodenWatchTower_BIRCH
mods=
size=12,27,16
offset=6,1,15
:endheader

#### VALIDATION ####
validation:
type=ground
structureAuthor=TheOddlySeagull
survival=true
worldGenEnabled=false
unique=false
preserveBlocks=false
preventNaturalHostileSpawns=false
selectionWeight=1
clusterValue=1
minDuplicateDistance=1
dimensionWhiteList=true
dimensionList=
biomeGroupList=
biomeWhiteList=true
biomeList=
leveling=0
fill=0
border=0
blockSwap=false
territoryName=
biomeReplacement=minecraft:
minGenerationHeight=0
maxGenerationHeight=255
:endvalidation

#### LAYERS ####
layer: 0
0,0,0,0,0,0,0,0,0,0,0,0
0,1,1,1,1,1,1,1,1,1,1,1
0,1,1,1,1,1,2,1,1,1,1,1
0,1,1,2,2,2,2,2,2,2,1,1
0,1,1,2,2,2,2,2,2,2,1,1
0,1,1,2,2,2,2,2,2,2,1,1
0,1,2,2,2,2,2,2,2,2,2,1
0,1,1,2,2,2,2,2,2,2,1,1
0,1,1,2,2,2,2,2,2,2,1,1
0,1,1,2,2,2,2,2,2,2,1,1
0,1,1,2,2,2,2,2,2,2,1,1
0,1,1,2,2,2,2,2,2,2,1,1
0,1,1,2,2,2,2,2,2,2,1,1
0,1,1,1,2,2,2,2,2,1,1,1
0,1,1,1,1,2,2,2,1,1,1,1
0,1,1,1,1,1,1,1,1,1,1,1
:endlayer
layer: 1
0,0,0,0,0,0,0,0,0,0,0,0
0,0,0,0,0,0,0,0,0,0,0,0
0,0,0,0,0,0,3,0,0,0,0,0
0,0,0,5,3,4,4,4,3,5,0,0
0,0,0,3,3,0,0,0,3,3,0,0
0,0,0,4,0,7,0,0,0,4,0,0
0,0,3,4,0,6,3,0,0,4,3,0
0,0,0,4,0,0,0,0,0,4,0,0
0,0,0,3,3,0,0,0,3,3,0,0
0,0,0,5,4,0,0,0,4,5,0,0
0,0,0,0,4,0,0,0,4,0,0,0
0,0,0,0,4,0,0,0,4,0,0,0
0,0,0,3,3,4,0,4,3,3,0,0
0,0,0,0,3,0,0,0,3,0,0,0
0,0,0,0,0,0,0,0,0,0,0,0
0,0,0,0,0,0,0,0,0,0,0,0
:endlayer
layer: 2
0,0,0,0,0,0,0,0,0,0,0,0
0,0,0,0,0,0,0,0,0,0,0,0
0,0,0,0,0,0,3,0,0,0,0,0
0,0,0,5,3,4,4,4,3,5,0,0
0,0,0,3,3,0,0,0,3,3,0,0
0,0,0,4,0,0,6,7,0,4,0,0
0,0,3,4,0,0,3,0,0,4,3,0
0,0,0,4,0,0,0,0,0,4,0,0
0,0,0,3,3,0,0,0,3,3,0,0
0,0,0,5,4,0,0,0,4,5,0,0
0,0,0,0,4,0,0,0,4,0,0,0
0,0,0,0,4,0,0,0,4,0,0,0
0,0,0,3,3,4,0,4,3,3,0,0
0,0,0,0,3,0,0,0,3,0,0,0
0,0,0,0,0,0,0,0,0,0,0,0
0,0,0,0,0,0,0,0,0,0,0,0
:endlayer
layer: 3
0,0,0,0,0,0,0,0,0,0,0,0
0,0,0,0,0,0,0,0,0,0,0,0
0,0,0,0,0,0,15,0,0,0,0,0
0,0,0,5,15,4,4,4,15,5,0,0
0,0,0,11,3,0,14,0,3,9,0,0
0,0,0,4,0,0,0,0,0,4,0,0
0,0,11,4,13,0,3,6,12,4,9,0
0,0,0,4,0,0,0,7,0,4,0,0
0,0,0,11,3,0,0,0,3,9,0,0
0,0,0,5,4,0,0,0,4,5,0,0
0,0,0,0,4,0,0,0,4,0,0,0
0,0,0,0,4,0,0,0,4,0,0,0
0,0,0,11,3,4,10,4,3,9,0,0
0,0,0,0,8,0,0,0,8,0,0,0
0,0,0,0,0,0,0,0,0,0,0,0
0,0,0,0,0,0,0,0,0,0,0,0
:endlayer
layer: 4
0,0,0,0,0,0,0,0,0,0,0,0
0,0,0,0,0,0,0,0,0,0,0,0
0,0,0,0,0,0,0,0,0,0,0,0
0,0,0,5,0,4,4,4,0,5,0,0
0,0,0,0,3,0,0,0,3,0,0,0
0,0,0,4,0,0,0,0,0,4,0,0
0,0,0,4,0,0,3,0,0,4,0,0
0,0,0,4,0,7,6,0,0,4,0,0
0,0,0,7,3,0,0,0,3,7,0,0
0,0,0,20,17,0,0,0,17,19,0,0
0,0,0,7,17,0,0,0,17,7,0,0
0,0,0,7,17,0,18,0,17,7,0,0
0,0,0,7,3,16,16,16,3,7,0,0
0,0,0,7,0,0,14,0,0,7,0,0
0,0,0,0,0,0,0,0,0,0,0,0
0,0,0,0,0,0,0,0,0,0,0,0
:endlayer
layer: 5
0,0,0,0,0,0,0,0,0,0,0,0
0,0,0,0,0,0,0,0,0,0,0,0
0,0,0,0,0,0,0,0,0,0,0,0
0,0,0,5,0,4,4,4,0,5,0,0
0,0,0,0,3,16,16,16,3,0,0,0
0,0,0,4,17,7,7,7,17,4,0,0
0,0,0,4,17,6,3,0,17,4,0,0
0,0,0,4,17,0,0,0,17,4,0,0
0,0,0,0,3,16,16,16,3,0,0,0
0,0,0,5,6,7,0,7,6,5,0,0
0,0,0,21,6,7,0,7,6,21,0,0
0,0,0,0,6,7,0,7,6,0,0,0
0,0,0,0,6,4,4,4,6,0,0,0
0,0,0,0,6,7,0,7,6,0,0,0
0,0,0,0,0,0,0,0,0,0,0,0
0,0,0,0,0,0,0,0,0,0,0,0
:endlayer
layer: 6
0,0,0,0,0,0,0,0,0,0,0,0
0,0,0,0,0,0,0,0,0,0,0,0
0,0,0,0,0,0,0,0,0,0,0,0
0,0,0,5,0,4,15,4,0,5,0,0
0,0,0,0,3,0,0,0,3,0,0,0
0,0,0,4,0,0,0,0,0,4,0,0
0,0,0,11,0,0,3,6,0,9,0,0
0,0,0,4,0,0,0,7,0,4,0,0
0,0,0,0,3,0,0,0,3,0,0,0
0,0,0,5,0,4,8,4,0,5,0,0
0,0,0,0,0,0,6,0,0,0,0,0
0,0,0,0,0,0,6,0,0,0,0,0
0,0,0,0,0,0,6,0,0,0,0,0
0,0,0,0,0,0,6,0,0,0,0,0
0,0,0,0,0,0,0,0,0,0,0,0
0,0,0,0,0,0,0,0,0,0,0,0
:endlayer
layer: 7
0,0,0,0,0,0,0,0,0,0,0,0
0,0,0,0,0,0,0,0,0,0,0,0
0,0,0,0,0,0,0,0,0,0,0,0
0,0,0,5,0,4,5,4,0,5,0,0
0,0,0,0,3,0,0,0,3,0,0,0
0,0,0,4,0,0,0,0,0,4,0,0
0,0,0,5,0,0,3,0,0,5,0,0
0,0,0,4,0,7,6,0,0,4,0,0
0,0,0,0,3,0,0,0,3,0,0,0
0,0,0,5,0,4,5,4,0,5,0,0
0,0,0,0,0,0,0,0,0,0,0,0
0,0,0,0,0,0,0,0,0,0,0,0
0,0,0,0,0,0,0,0,0,0,0,0
0,0,0,0,0,0,0,0,0,0,0,0
0,0,0,0,0,0,0,0,0,0,0,0
0,0,0,0,0,0,0,0,0,0,0,0
:endlayer
layer: 8
0,0,0,0,0,0,0,0,0,0,0,0
0,0,0,0,0,0,0,0,0,0,0,0
0,0,0,0,0,0,0,0,0,0,0,0
0,0,0,5,0,4,22,4,0,5,0,0
0,0,0,0,3,0,14,0,3,0,0,0
0,0,0,4,0,7,0,0,0,4,0,0
0,0,0,20,13,6,3,0,12,19,0,0
0,0,0,4,0,0,0,0,0,4,0,0
0,0,0,0,3,0,18,0,3,0,0,0
0,0,0,5,0,4,10,4,0,5,0,0
0,0,0,0,0,0,0,0,0,0,0,0
0,0,0,0,0,0,0,0,0,0,0,0
0,0,0,0,0,0,0,0,0,0,0,0
0,0,0,0,0,0,0,0,0,0,0,0
0,0,0,0,0,0,0,0,0,0,0,0
0,0,0,0,0,0,0,0,0,0,0,0
:endlayer
layer: 9
0,0,0,0,0,0,0,0,0,0,0,0
0,0,0,0,0,0,0,0,0,0,0,0
0,0,0,0,7,7,22,7,7,0,0,0
0,0,0,4,20,16,16,16,19,4,0,0
0,0,7,22,3,16,16,16,3,22,7,0
0,0,7,17,17,0,6,7,17,17,7,0
0,0,20,17,17,0,3,7,17,17,19,0
0,0,7,17,17,0,0,7,17,17,7,0
0,0,7,10,3,16,16,16,3,10,7,0
0,0,0,4,20,16,16,16,19,4,0,0
0,0,0,0,7,7,10,7,7,0,0,0
0,0,0,0,0,0,0,0,0,0,0,0
0,0,0,0,0,0,0,0,0,0,0,0
0,0,0,0,0,0,0,0,0,0,0,0
0,0,0,0,0,0,0,0,0,0,0,0
0,0,0,0,0,0,0,0,0,0,0,0
:endlayer
layer: 10
0,0,0,0,0,0,0,0,0,0,0,0
0,0,0,0,0,0,0,0,0,0,0,0
0,0,0,0,0,0,0,0,0,0,0,0
0,0,0,5,0,4,0,4,0,5,0,0
0,0,0,0,3,0,0,0,3,0,0,0
0,0,0,4,0,0,0,0,0,4,0,0
0,0,0,11,0,0,3,0,0,0,0,0
0,0,0,4,0,7,6,0,0,4,0,0
0,0,0,0,3,0,0,0,3,0,0,0
0,0,0,5,0,4,0,4,0,5,0,0
0,0,0,0,0,0,0,0,0,0,0,0
0,0,0,0,0,0,0,0,0,0,0,0
0,0,0,0,0,0,0,0,0,0,0,0
0,0,0,0,0,0,0,0,0,0,0,0
0,0,0,0,0,0,0,0,0,0,0,0
0,0,0,0,0,0,0,0,0,0,0,0
:endlayer
layer: 11
0,0,0,0,0,0,0,0,0,0,0,0
0,0,0,0,0,0,0,0,0,0,0,0
0,0,0,0,0,0,0,0,0,0,0,0
0,0,0,5,0,4,0,4,0,5,0,0
0,0,0,0,3,0,0,0,3,0,0,0
0,0,0,4,0,7,0,0,0,4,0,0
0,0,0,0,0,6,3,0,0,0,0,0
0,0,0,4,0,0,0,0,0,4,0,0
0,0,0,0,3,0,0,0,3,0,0,0
0,0,0,5,0,4,0,4,0,5,0,0
0,0,0,0,0,0,0,0,0,0,0,0
0,0,0,0,0,0,0,0,0,0,0,0
0,0,0,0,0,0,0,0,0,0,0,0
0,0,0,0,0,0,0,0,0,0,0,0
0,0,0,0,0,0,0,0,0,0,0,0
0,0,0,0,0,0,0,0,0,0,0,0
:endlayer
layer: 12
0,0,0,0,0,0,0,0,0,0,0,0
0,0,0,0,0,0,0,0,0,0,0,0
0,0,0,0,0,0,0,0,0,0,0,0
0,0,0,5,0,4,22,4,0,5,0,0
0,0,0,0,3,0,14,0,3,0,0,0
0,0,0,4,0,0,6,7,0,4,0,0
0,0,0,20,13,0,3,0,12,19,0,0
0,0,0,4,0,0,0,0,0,4,0,0
0,0,0,0,3,0,18,0,3,0,0,0
0,0,0,5,0,4,10,4,0,5,0,0
0,0,0,0,0,0,0,0,0,0,0,0
0,0,0,0,0,0,0,0,0,0,0,0
0,0,0,0,0,0,0,0,0,0,0,0
0,0,0,0,0,0,0,0,0,0,0,0
0,0,0,0,0,0,0,0,0,0,0,0
0,0,0,0,0,0,0,0,0,0,0,0
:endlayer
layer: 13
0,0,0,0,0,0,0,0,0,0,0,0
0,0,0,0,0,0,0,0,0,0,0,0
0,0,0,18,7,7,22,7,7,18,0,0
0,0,12,4,20,16,16,16,19,4,13,0
0,0,7,22,3,16,16,16,3,22,7,0
0,0,7,17,17,0,0,0,17,17,7,0
0,0,20,17,17,0,3,6,17,17,19,0
0,0,7,17,17,0,0,7,17,17,7,0
0,0,7,10,3,16,16,16,3,10,7,0
0,0,12,4,20,16,16,16,19,4,13,0
0,0,0,14,7,7,10,7,7,14,0,0
0,0,0,0,0,0,0,0,0,0,0,0
0,0,0,0,0,0,0,0,0,0,0,0
0,0,0,0,0,0,0,0,0,0,0,0
0,0,0,0,0,0,0,0,0,0,0,0
0,0,0,0,0,0,0,0,0,0,0,0
:endlayer
layer: 14
0,0,0,0,0,0,0,0,0,0,0,0
0,0,0,0,0,0,0,0,0,0,0,0
0,0,0,0,0,0,0,0,0,0,0,0
0,0,0,5,0,4,15,4,0,5,0,0
0,0,0,0,3,0,0,0,3,0,0,0
0,0,0,4,0,0,0,0,0,4,0,0
0,0,0,11,0,0,3,0,0,0,0,0
0,0,0,4,0,7,6,0,0,4,0,0
0,0,0,0,3,0,0,0,3,0,0,0
0,0,0,5,0,4,0,4,0,5,0,0
0,0,0,0,0,0,0,0,0,0,0,0
0,0,0,0,0,0,0,0,0,0,0,0
0,0,0,0,0,0,0,0,0,0,0,0
0,0,0,0,0,0,0,0,0,0,0,0
0,0,0,0,0,0,0,0,0,0,0,0
0,0,0,0,0,0,0,0,0,0,0,0
:endlayer
layer: 15
0,0,0,0,0,0,0,0,0,0,0,0
0,0,0,0,0,0,0,0,0,0,0,0
0,0,0,0,0,0,0,0,0,0,0,0
0,0,0,5,0,4,0,4,0,5,0,0
0,0,0,0,3,0,0,0,3,0,0,0
0,0,0,4,0,7,0,0,0,4,0,0
0,0,0,0,0,6,3,0,0,0,0,0
0,0,0,4,0,0,0,0,0,4,0,0
0,0,0,0,3,0,0,0,3,0,0,0
0,0,0,5,0,4,0,4,0,5,0,0
0,0,0,0,0,0,0,0,0,0,0,0
0,0,0,0,0,0,0,0,0,0,0,0
0,0,0,0,0,0,0,0,0,0,0,0
0,0,0,0,0,0,0,0,0,0,0,0
0,0,0,0,0,0,0,0,0,0,0,0
0,0,0,0,0,0,0,0,0,0,0,0
:endlayer
layer: 16
0,0,0,0,0,0,0,0,0,0,0,0
0,0,0,0,0,0,0,0,0,0,0,0
0,0,0,0,0,0,0,0,0,0,0,0
0,0,0,5,0,4,22,4,0,5,0,0
0,0,0,0,3,0,14,0,3,0,0,0
0,0,0,4,0,0,6,7,0,4,0,0
0,0,0,20,13,0,3,0,12,19,0,0
0,0,0,4,0,0,0,0,0,4,0,0
0,0,0,0,3,0,18,0,3,0,0,0
0,0,0,5,0,4,10,4,0,5,0,0
0,0,0,0,0,0,0,0,0,0,0,0
0,0,0,0,0,0,0,0,0,0,0,0
0,0,0,0,0,0,0,0,0,0,0,0
0,0,0,0,0,0,0,0,0,0,0,0
0,0,0,0,0,0,0,0,0,0,0,0
0,0,0,0,0,0,0,0,0,0,0,0
:endlayer
layer: 17
0,0,0,0,0,0,0,0,0,0,0,0
0,0,0,0,0,0,0,0,0,0,0,0
0,0,0,0,7,7,22,7,7,0,0,0
0,0,0,4,20,16,16,16,19,4,0,0
0,0,7,22,3,16,16,16,3,22,7,0
0,0,7,17,17,0,0,0,17,17,7,0
0,0,20,17,17,0,3,6,17,17,19,0
0,0,7,17,17,7,7,7,17,17,7,0
0,0,7,10,3,16,16,16,3,10,7,0
0,0,0,4,20,16,16,16,19,4,0,0
0,0,0,0,7,7,10,7,7,0,0,0
0,0,0,0,0,0,0,0,0,0,0,0
0,0,0,0,0,0,0,0,0,0,0,0
0,0,0,0,0,0,0,0,0,0,0,0
0,0,0,0,0,0,0,0,0,0,0,0
0,0,0,0,0,0,0,0,0,0,0,0
:endlayer
layer: 18
0,0,0,0,0,0,0,0,0,0,0,0
0,0,0,0,0,0,0,0,0,0,0,0
0,0,0,0,4,16,16,16,4,0,0,0
0,0,0,3,4,4,4,4,4,3,0,0
0,0,4,4,4,16,16,16,4,4,4,0
0,0,17,4,17,0,0,0,17,4,17,0
0,0,17,4,17,0,3,0,17,4,17,0
0,0,17,4,17,0,0,0,17,4,17,0
0,0,4,4,4,15,15,15,4,4,4,0
0,0,0,3,4,4,4,4,4,3,0,0
0,0,0,0,4,16,16,16,4,0,0,0
0,0,0,0,0,0,0,0,0,0,0,0
0,0,0,0,0,0,0,0,0,0,0,0
0,0,0,0,0,0,0,0,0,0,0,0
0,0,0,0,0,0,0,0,0,0,0,0
0,0,0,0,0,0,0,0,0,0,0,0
:endlayer
layer: 19
0,0,0,0,0,0,0,0,0,0,0,0
0,0,0,0,0,0,0,0,0,0,0,0
0,0,0,0,15,4,8,4,15,0,0,0
0,0,0,4,6,6,6,6,6,4,0,0
0,0,11,6,0,0,21,0,0,6,9,0
0,0,4,6,0,0,0,0,0,6,4,0
0,0,9,6,21,0,3,0,21,6,11,0
0,0,4,6,0,0,0,0,0,6,4,0
0,0,11,6,0,0,0,0,0,6,9,0
0,0,0,4,6,6,6,6,6,4,0,0
0,0,0,0,8,4,15,4,8,0,0,0
0,0,0,0,0,0,0,0,0,0,0,0
0,0,0,0,0,0,0,0,0,0,0,0
0,0,0,0,0,0,0,0,0,0,0,0
0,0,0,0,0,0,0,0,0,0,0,0
0,0,0,0,0,0,0,0,0,0,0,0
:endlayer
layer: 20
0,0,0,0,0,0,0,0,0,0,0,0
0,0,0,0,0,0,0,0,0,0,0,0
0,0,0,0,0,6,0,6,0,0,0,0
0,0,0,6,0,0,0,0,0,6,0,0
0,0,0,0,0,0,0,0,0,0,0,0
0,0,6,0,0,0,0,0,0,0,6,0
0,0,0,0,0,0,3,0,0,0,0,0
0,0,6,0,0,0,0,0,0,0,6,0
0,0,0,0,0,0,0,0,0,0,0,0
0,0,0,6,0,0,0,0,0,6,0,0
0,0,0,0,0,6,0,6,0,0,0,0
0,0,0,0,0,0,0,0,0,0,0,0
0,0,0,0,0,0,0,0,0,0,0,0
0,0,0,0,0,0,0,0,0,0,0,0
0,0,0,0,0,0,0,0,0,0,0,0
0,0,0,0,0,0,0,0,0,0,0,0
:endlayer
layer: 21
0,0,0,0,0,0,0,0,0,0,0,0
0,0,0,0,0,0,0,0,0,0,0,0
0,0,0,0,0,0,0,0,0,0,0,0
0,0,0,0,0,0,0,0,0,0,0,0
0,0,0,0,0,0,0,0,0,0,0,0
0,0,0,0,0,0,0,0,0,0,0,0
0,0,0,0,0,0,3,0,0,0,0,0
0,0,0,0,0,0,0,0,0,0,0,0
0,0,0,0,0,0,0,0,0,0,0,0
0,0,0,0,0,0,0,0,0,0,0,0
0,0,0,0,0,0,0,0,0,0,0,0
0,0,0,0,0,0,0,0,0,0,0,0
0,0,0,0,0,0,0,0,0,0,0,0
0,0,0,0,0,0,0,0,0,0,0,0
0,0,0,0,0,0,0,0,0,0,0,0
0,0,0,0,0,0,0,0,0,0,0,0
:endlayer
layer: 22
0,0,0,0,0,0,0,0,0,0,0,0
0,0,0,0,0,0,0,0,0,0,0,0
0,0,0,0,0,0,0,0,0,0,0,0
0,0,0,0,0,0,0,0,0,0,0,0
0,0,0,0,0,0,0,0,0,0,0,0
0,0,0,0,0,0,0,0,0,0,0,0
0,0,0,0,0,0,3,0,0,0,0,0
0,0,0,0,0,0,0,0,0,0,0,0
0,0,0,0,0,0,0,0,0,0,0,0
0,0,0,0,0,0,0,0,0,0,0,0
0,0,0,0,0,0,0,0,0,0,0,0
0,0,0,0,0,0,0,0,0,0,0,0
0,0,0,0,0,0,0,0,0,0,0,0
0,0,0,0,0,0,0,0,0,0,0,0
0,0,0,0,0,0,0,0,0,0,0,0
0,0,0,0,0,0,0,0,0,0,0,0
:endlayer
layer: 23
0,0,0,0,0,0,0,0,0,0,0,0
0,0,0,0,0,0,0,0,0,0,0,0
0,0,0,0,0,0,0,0,0,0,0,0
0,0,0,0,0,0,0,0,0,0,0,0
0,0,0,0,0,0,0,0,0,0,0,0
0,0,0,0,0,0,0,0,0,0,0,0
0,0,0,0,0,0,5,0,0,0,0,0
0,0,0,0,0,0,0,0,0,0,0,0
0,0,0,0,0,0,0,0,0,0,0,0
0,0,0,0,0,0,0,0,0,0,0,0
0,0,0,0,0,0,0,0,0,0,0,0
0,0,0,0,0,0,0,0,0,0,0,0
0,0,0,0,0,0,0,0,0,0,0,0
0,0,0,0,0,0,0,0,0,0,0,0
0,0,0,0,0,0,0,0,0,0,0,0
0,0,0,0,0,0,0,0,0,0,0,0
:endlayer
layer: 24
0,0,0,0,0,0,0,0,0,0,0,0
0,0,0,0,0,0,0,0,0,0,0,0
0,0,0,0,0,0,0,0,0,0,0,0
0,0,0,0,0,0,0,0,0,0,0,0
0,0,0,0,0,0,0,0,0,0,0,0
0,0,0,0,0,0,0,0,0,0,0,0
0,0,0,0,0,0,5,0,0,0,0,0
0,0,0,0,0,0,0,0,0,0,0,0
0,0,0,0,0,0,0,0,0,0,0,0
0,0,0,0,0,0,0,0,0,0,0,0
0,0,0,0,0,0,0,0,0,0,0,0
0,0,0,0,0,0,0,0,0,0,0,0
0,0,0,0,0,0,0,0,0,0,0,0
0,0,0,0,0,0,0,0,0,0,0,0
0,0,0,0,0,0,0,0,0,0,0,0
0,0,0,0,0,0,0,0,0,0,0,0
:endlayer
layer: 25
0,0,0,0,0,0,0,0,0,0,0,0
0,0,0,0,0,0,0,0,0,0,0,0
0,0,0,0,0,0,0,0,0,0,0,0
0,0,0,0,0,0,0,0,0,0,0,0
0,0,0,0,0,0,0,0,0,0,0,0
0,0,0,0,0,0,0,0,0,0,0,0
0,0,0,0,0,0,5,0,0,0,0,0
0,0,0,0,0,0,0,0,0,0,0,0
0,0,0,0,0,0,0,0,0,0,0,0
0,0,0,0,0,0,0,0,0,0,0,0
0,0,0,0,0,0,0,0,0,0,0,0
0,0,0,0,0,0,0,0,0,0,0,0
0,0,0,0,0,0,0,0,0,0,0,0
0,0,0,0,0,0,0,0,0,0,0,0
0,0,0,0,0,0,0,0,0,0,0,0
0,0,0,0,0,0,0,0,0,0,0,0
:endlayer
layer: 26
0,0,0,0,0,0,0,0,0,0,0,0
0,0,0,0,0,0,0,0,0,0,0,0
0,0,0,0,0,0,0,0,0,0,0,0
0,0,0,0,0,0,0,0,0,0,0,0
0,0,0,0,0,0,0,0,0,0,0,0
0,0,0,0,0,0,0,0,0,0,0,0
0,0,0,0,0,0,21,0,0,0,0,0
0,0,0,0,0,0,0,0,0,0,0,0
0,0,0,0,0,0,0,0,0,0,0,0
0,0,0,0,0,0,0,0,0,0,0,0
0,0,0,0,0,0,0,0,0,0,0,0
0,0,0,0,0,0,0,0,0,0,0,0
0,0,0,0,0,0,0,0,0,0,0,0
0,0,0,0,0,0,0,0,0,0,0,0
0,0,0,0,0,0,0,0,0,0,0,0
0,0,0,0,0,0,0,0,0,0,0,0
:endlayer

#### RULES ####
rule:
plugin=vanillaBlocks
number=1
data:
JSON:{blockState:{blockName:"minecraft:grass",properties:{snowy:"false"}}}
:enddata
:endrule

rule:
plugin=vanillaBlocks
number=2
data:
JSON:{blockState:{blockName:"minecraft:cobblestone"}}
:enddata
:endrule

rule:
plugin=vanillaBlocks
number=3
data:
JSON:{blockState:{blockName:"minecraft:log",properties:{variant:"birch",axis:"y"}}}
:enddata
:endrule

rule:
plugin=vanillaBlocks
number=4
data:
JSON:{blockState:{blockName:"minecraft:planks",properties:{variant:"birch"}}}
:enddata
:endrule

rule:
plugin=vanillaBlocks
number=5
data:
JSON:{blockState:{blockName:"minecraft:birch_fence",properties:{east:"false",south:"false",north:"false",west:"false"}}}
:enddata
:endrule

rule:
plugin=vanillaBlocks
number=6
data:
JSON:{blockState:{blockName:"minecraft:wooden_slab",properties:{half:"bottom",variant:"birch"}}}
:enddata
:endrule

rule:
plugin=vanillaBlocks
number=7
data:
JSON:{blockState:{blockName:"minecraft:wooden_slab",properties:{half:"top",variant:"birch"}}}
:enddata
:endrule

rule:
plugin=vanillaBlocks
number=8
data:
JSON:{blockState:{blockName:"minecraft:birch_stairs",properties:{half:"bottom",shape:"straight",facing:"north"}}}
:enddata
:endrule

rule:
plugin=vanillaBlocks
number=9
data:
JSON:{blockState:{blockName:"minecraft:birch_stairs",properties:{half:"bottom",shape:"straight",facing:"west"}}}
:enddata
:endrule

rule:
plugin=vanillaBlocks
number=10
data:
JSON:{blockState:{blockName:"minecraft:birch_stairs",properties:{half:"top",shape:"straight",facing:"north"}}}
:enddata
:endrule

rule:
plugin=vanillaBlocks
number=11
data:
JSON:{blockState:{blockName:"minecraft:birch_stairs",properties:{half:"bottom",shape:"straight",facing:"east"}}}
:enddata
:endrule

rule:
plugin=vanillaBlocks
number=12
data:
JSON:{blockState:{blockName:"minecraft:torch",properties:{facing:"west"}}}
:enddata
:endrule

rule:
plugin=vanillaBlocks
number=13
data:
JSON:{blockState:{blockName:"minecraft:torch",properties:{facing:"east"}}}
:enddata
:endrule

rule:
plugin=vanillaBlocks
number=14
data:
JSON:{blockState:{blockName:"minecraft:torch",properties:{facing:"south"}}}
:enddata
:endrule

rule:
plugin=vanillaBlocks
number=15
data:
JSON:{blockState:{blockName:"minecraft:birch_stairs",properties:{half:"bottom",shape:"straight",facing:"south"}}}
:enddata
:endrule

rule:
plugin=vanillaBlocks
number=16
data:
JSON:{blockState:{blockName:"minecraft:log",properties:{variant:"birch",axis:"x"}}}
:enddata
:endrule

rule:
plugin=vanillaBlocks
number=17
data:
JSON:{blockState:{blockName:"minecraft:log",properties:{variant:"birch",axis:"z"}}}
:enddata
:endrule

rule:
plugin=vanillaBlocks
number=18
data:
JSON:{blockState:{blockName:"minecraft:torch",properties:{facing:"north"}}}
:enddata
:endrule

rule:
plugin=vanillaBlocks
number=19
data:
JSON:{blockState:{blockName:"minecraft:birch_stairs",properties:{half:"top",shape:"straight",facing:"west"}}}
:enddata
:endrule

rule:
plugin=vanillaBlocks
number=20
data:
JSON:{blockState:{blockName:"minecraft:birch_stairs",properties:{half:"top",shape:"straight",facing:"east"}}}
:enddata
:endrule

rule:
plugin=vanillaBlocks
number=21
data:
JSON:{blockState:{blockName:"minecraft:torch",properties:{facing:"up"}}}
:enddata
:endrule

rule:
plugin=vanillaBlocks
number=22
data:
JSON:{blockState:{blockName:"minecraft:birch_stairs",properties:{half:"top",shape:"straight",facing:"south"}}}
:enddata
:endrule

#### ENTITIES ####
