# Ancient Warfare Structure Template File
# Auto-generated structure template file. created on: 9/23/2023 at: 21:27:51
# Lines beginning with # denote comments

header:
version=2.11
name=SB_KievarusCol_LargeWarehouse_1_ebony
mods=biomesoplenty
size=33,21,25
offset=9,1,24
:endheader

#### VALIDATION ####
validation:
type=ground
structureAuthor=TheOddlySeagull
survival=true
worldGenEnabled=false
unique=false
preserveBlocks=false
preventNaturalHostileSpawns=false
selectionWeight=1
clusterValue=1
minDuplicateDistance=1
dimensionWhiteList=true
dimensionList=
biomeGroupList=
biomeWhiteList=true
biomeList=
leveling=0
fill=0
border=0
blockSwap=false
territoryName=
biomeReplacement=minecraft:
minGenerationHeight=0
maxGenerationHeight=255
:endvalidation

#### LAYERS ####
layer: 0
1,1,1,1,1,1,1,1,1,1,1,1,1,1,1,1,1,1,1,1,1,1,1,1,1,1,1,1,1,1,1,1,1
1,1,2,1,1,1,1,1,1,1,2,1,1,1,1,1,1,1,2,1,1,1,1,1,1,1,1,1,1,1,1,1,1
1,2,2,2,2,2,2,2,2,2,2,2,2,2,2,2,2,2,2,1,1,1,1,1,1,1,1,1,1,1,1,1,1
1,1,2,3,2,3,2,3,3,2,3,3,2,2,2,3,3,2,2,1,1,1,1,1,2,1,1,1,1,1,2,1,1
1,1,2,2,3,2,2,3,2,3,3,2,3,2,2,2,3,2,2,2,2,2,2,2,2,2,2,2,2,2,2,2,1
1,1,2,2,2,2,3,3,2,3,2,3,3,3,2,3,2,2,2,2,2,2,3,2,2,2,3,3,2,3,2,1,1
1,1,2,3,2,3,3,3,2,2,3,2,2,2,3,3,2,2,2,3,2,3,3,3,3,2,2,2,2,2,2,1,1
1,1,2,3,3,3,3,3,2,2,2,2,2,2,3,3,2,2,2,2,2,3,2,2,3,2,3,3,3,3,2,1,1
1,2,2,3,2,2,3,2,3,2,2,2,2,2,2,3,2,2,2,2,2,2,3,2,2,3,3,3,2,3,2,2,1
1,1,2,3,2,3,2,3,3,2,3,2,3,2,3,2,3,2,2,2,3,3,2,2,2,2,3,2,3,3,2,1,1
1,1,2,3,2,3,3,2,3,3,3,3,2,2,3,2,2,2,2,3,3,2,3,3,2,3,3,3,2,2,2,1,1
1,1,2,2,3,2,3,2,3,3,2,3,3,2,3,2,2,3,2,2,3,3,3,2,3,3,3,2,2,2,2,1,1
1,1,2,3,3,3,3,3,3,3,2,3,2,3,2,2,3,2,2,2,2,2,2,2,2,2,2,2,2,2,2,2,4
1,1,2,3,3,3,3,3,3,3,3,3,2,2,2,3,2,2,2,1,1,1,1,1,1,1,1,1,1,1,2,2,2
1,2,2,2,2,2,2,2,2,2,2,2,2,2,2,2,2,2,2,1,1,1,1,1,1,1,1,1,1,1,2,2,2
1,1,2,3,3,3,3,2,2,1,1,1,1,1,1,1,1,1,1,1,1,1,1,1,1,1,1,1,1,1,2,4,4
1,1,2,2,2,3,2,2,2,1,1,1,1,1,1,1,1,1,1,1,1,1,1,1,1,1,1,1,1,1,1,1,1
1,1,2,3,3,3,3,2,2,2,2,4,1,1,2,1,1,1,2,1,1,1,2,1,1,1,2,1,1,1,2,1,1
1,1,2,2,3,2,2,2,2,2,2,4,1,1,1,1,1,1,1,1,1,1,1,1,1,1,1,1,1,1,1,1,1
1,1,2,3,3,3,2,2,2,2,2,4,1,1,1,1,1,1,1,1,1,1,1,1,1,1,1,1,1,1,1,1,1
1,1,2,2,2,3,2,2,2,2,2,4,1,1,1,1,1,1,1,1,1,1,1,1,1,1,1,1,1,1,1,1,1
1,1,2,3,2,2,2,3,2,2,2,4,1,1,1,1,1,1,1,1,1,1,1,1,1,1,1,1,1,1,1,1,1
1,1,2,2,2,2,2,2,2,2,2,4,1,1,1,1,1,1,1,1,1,1,1,1,1,1,1,1,1,1,1,1,1
1,1,1,1,1,1,1,1,4,2,2,4,1,1,1,1,1,1,1,1,1,1,1,1,1,1,1,1,1,1,1,1,1
1,1,1,1,1,1,1,1,4,2,2,4,1,1,1,1,1,1,1,1,1,1,1,1,1,1,1,1,1,1,1,1,1
:endlayer
layer: 1
0,0,0,0,0,0,0,0,0,0,0,0,0,0,0,0,0,0,0,0,0,0,0,0,0,0,0,0,0,0,0,0,0
0,0,5,0,0,0,0,0,0,0,5,0,0,0,0,0,0,0,5,0,0,0,0,0,0,0,0,0,0,0,0,0,0
0,5,5,6,6,6,5,6,6,6,5,6,6,6,5,6,6,6,5,0,0,0,0,0,0,0,0,0,0,0,0,0,0
0,0,6,2,2,3,2,3,2,3,3,3,3,2,2,2,3,2,6,0,0,0,0,0,5,0,0,0,0,0,5,0,0
0,0,6,2,3,3,2,3,3,3,2,3,3,2,2,3,2,2,5,6,6,5,6,6,5,6,6,5,6,6,5,5,0
0,0,5,3,2,3,3,3,3,2,2,2,3,2,3,2,3,2,6,2,3,3,2,3,2,2,3,2,2,3,6,0,0
0,0,6,2,2,2,2,2,3,3,3,2,2,3,3,2,2,3,6,3,2,2,2,3,3,3,2,2,3,2,6,0,0
0,0,6,2,3,2,2,2,2,3,2,3,2,3,2,2,2,2,6,3,3,2,3,2,3,2,3,3,2,2,6,0,0
0,5,5,2,2,2,3,2,3,3,3,2,2,2,2,3,3,2,5,2,2,2,2,3,2,3,2,2,3,2,5,5,0
0,0,6,2,3,2,2,2,2,2,3,3,3,3,3,2,3,2,6,3,2,2,3,2,2,3,3,2,3,3,6,0,0
0,0,6,2,3,3,2,2,3,2,2,3,3,2,2,2,3,3,6,3,3,2,3,3,3,2,3,2,3,3,6,0,0
0,0,5,3,2,2,3,3,3,2,3,2,3,3,3,2,3,3,6,2,2,2,2,3,2,3,3,2,3,3,6,0,0
0,0,6,3,3,2,3,3,3,3,2,2,3,3,2,3,3,3,5,6,6,6,5,6,6,6,5,6,6,6,5,5,0
0,0,6,2,2,2,2,2,3,3,3,2,3,2,3,2,3,3,6,0,0,0,0,0,0,0,0,0,0,0,10,11,0
0,5,5,6,6,6,6,6,5,6,5,6,6,6,5,6,6,6,5,0,0,0,0,0,0,0,0,0,0,0,10,11,0
0,0,6,3,3,2,2,3,6,0,0,0,0,0,0,0,0,0,0,0,0,0,0,0,0,0,0,0,0,0,5,0,0
0,0,5,3,2,2,3,2,5,0,0,0,0,0,0,0,0,0,0,0,0,0,0,0,0,0,0,0,0,0,0,0,0
0,0,6,2,2,2,3,3,6,8,5,0,0,0,5,0,0,0,5,0,0,0,5,0,0,0,5,0,0,0,5,0,0
0,0,6,2,3,3,3,3,6,7,7,0,0,0,0,0,0,0,0,0,0,0,0,0,0,0,0,0,0,0,0,0,0
0,0,6,2,2,2,3,2,6,0,0,0,0,0,0,0,0,0,0,0,0,0,0,0,0,0,0,0,0,0,0,0,0
0,0,5,2,2,3,3,2,5,0,0,0,0,0,0,0,0,0,0,0,0,0,0,0,0,0,0,0,0,0,0,0,0
0,0,6,3,3,2,3,2,6,0,0,0,0,0,0,0,0,0,0,0,0,0,0,0,0,0,0,0,0,0,0,0,0
0,0,5,6,6,5,6,6,5,0,0,0,0,0,9,0,0,0,0,0,0,0,9,0,0,0,0,0,0,0,9,0,0
0,0,0,0,0,0,0,0,0,0,0,0,0,0,0,0,0,0,0,0,0,0,0,0,0,0,0,0,0,0,0,0,0
0,0,0,0,0,0,0,0,0,0,0,0,0,0,0,0,0,0,0,0,0,0,0,0,0,0,0,0,0,0,0,0,0
:endlayer
layer: 2
0,0,0,0,0,0,0,0,0,0,0,0,0,0,0,0,0,0,0,0,0,0,0,0,0,0,0,0,0,0,0,0,0
0,0,5,0,0,0,0,0,0,0,5,0,0,0,0,0,0,0,5,0,0,0,0,0,0,0,0,0,0,0,0,0,0
0,5,5,8,8,8,8,8,8,8,8,8,8,8,8,8,8,8,5,0,0,0,0,0,0,0,0,0,0,0,0,0,0
0,0,10,13,12,13,13,13,2,13,13,13,12,13,12,12,12,13,10,0,0,0,0,0,5,0,0,0,0,0,5,0,0
0,0,10,12,12,12,13,13,2,13,12,12,13,13,12,13,12,13,5,8,8,8,8,8,8,8,8,8,8,8,5,5,0
0,0,10,12,13,12,13,13,2,13,13,13,12,13,13,12,13,12,10,6,6,6,10,6,6,6,10,6,6,6,10,0,0
0,0,10,12,13,12,5,13,13,12,5,13,12,13,5,13,13,12,10,6,6,6,10,6,6,6,10,6,6,6,10,0,0
0,0,10,13,12,13,13,12,13,13,13,13,12,12,13,12,13,13,10,6,6,6,10,6,6,6,10,6,6,6,10,0,0
0,5,10,12,12,12,12,13,12,12,12,12,12,13,12,13,13,12,10,6,6,6,10,6,6,6,10,6,6,6,10,5,0
0,0,10,12,12,12,12,13,12,12,13,13,13,13,12,13,12,12,10,6,6,6,10,6,6,6,10,6,6,6,10,0,0
0,0,10,12,13,13,5,12,13,13,5,13,12,13,5,12,13,12,10,6,6,6,10,6,6,6,10,6,6,6,10,0,0
0,0,10,12,13,13,12,12,12,13,13,13,13,12,13,12,12,13,10,6,6,6,10,6,6,6,10,6,6,6,10,0,0
0,0,10,13,12,13,12,13,12,12,13,13,13,13,13,12,13,12,5,8,8,8,8,8,8,8,8,8,8,8,5,5,0
0,0,10,12,12,13,13,13,13,13,12,13,12,12,13,13,13,12,10,16,16,16,10,16,16,16,10,16,16,16,11,0,0
0,5,5,8,8,8,8,8,8,8,8,8,8,8,8,8,8,8,10,14,14,14,10,14,14,14,10,14,14,14,11,0,0
0,0,10,13,12,13,12,12,10,14,10,16,16,16,10,16,16,16,10,14,14,14,10,14,14,14,10,14,14,14,5,0,0
0,0,10,13,13,13,12,12,10,14,10,14,14,14,10,14,14,14,10,14,14,14,10,14,14,14,10,14,14,14,10,0,0
0,0,10,13,12,12,12,12,10,7,5,15,14,17,5,15,14,17,5,15,14,17,5,15,14,17,5,15,14,17,5,0,0
0,0,10,12,12,13,13,13,10,0,0,0,0,0,0,0,0,0,0,0,0,0,0,0,0,0,0,0,0,0,0,0,0
0,0,10,12,12,13,13,13,10,0,0,0,0,0,0,0,0,0,0,0,0,0,0,0,0,0,0,0,0,0,0,0,0
0,0,10,12,12,13,12,13,10,0,0,0,0,0,0,0,0,0,0,0,0,0,0,0,0,0,0,0,0,0,0,0,0
0,0,10,12,12,13,12,13,10,0,0,0,0,0,0,0,0,0,0,0,0,0,0,0,0,0,0,0,0,0,0,0,0
0,0,5,8,8,8,8,8,5,0,0,0,0,0,0,0,0,0,0,0,0,0,0,0,0,0,0,0,0,0,0,0,0
0,0,0,0,0,0,0,0,0,0,0,0,0,0,0,0,0,0,0,0,0,0,0,0,0,0,0,0,0,0,0,0,0
0,0,0,0,0,0,0,0,0,0,0,0,0,0,0,0,0,0,0,0,0,0,0,0,0,0,0,0,0,0,0,0,0
:endlayer
layer: 3
0,0,0,0,0,0,0,0,0,0,0,0,0,0,0,0,0,0,0,0,0,0,0,0,0,0,0,0,0,0,0,0,0
0,0,5,21,0,0,0,0,0,18,5,21,0,0,0,0,0,18,5,0,0,0,0,0,0,0,0,0,0,0,0,0,0
0,5,5,6,6,5,6,5,6,6,5,6,6,5,6,5,6,6,5,0,0,0,0,0,0,0,0,0,0,0,0,0,0
0,20,6,0,0,0,0,17,11,0,0,0,0,0,0,0,0,0,6,21,0,0,0,18,5,21,0,0,0,18,5,0,0
0,0,6,0,0,0,0,17,11,0,0,0,0,0,0,0,0,0,5,6,5,6,5,6,5,6,5,6,5,6,5,5,0
0,0,5,0,0,0,0,17,11,0,0,0,0,0,0,0,0,0,6,0,0,0,0,0,0,0,0,0,0,0,6,0,0
0,0,6,0,0,0,5,0,0,0,5,0,0,0,5,0,0,0,5,0,0,0,0,0,0,0,0,0,0,0,6,21,0
0,19,6,0,0,0,0,0,0,0,0,0,0,0,0,0,0,0,0,0,0,0,0,0,0,0,0,0,0,0,6,0,0
0,5,5,0,0,0,0,0,0,0,0,0,0,0,0,0,0,0,0,0,0,0,9,0,0,0,9,0,23,23,5,5,0
0,20,6,0,0,0,0,0,0,0,0,0,0,0,0,0,0,0,0,0,0,0,0,0,0,0,0,0,7,7,6,0,0
0,0,6,0,0,0,5,0,0,0,5,0,0,0,5,0,0,0,5,0,0,0,0,0,0,0,0,0,0,0,6,21,0
0,0,5,0,0,0,0,0,0,0,0,0,0,0,0,0,0,0,6,0,0,0,0,0,0,0,0,0,0,0,6,0,0
0,0,6,0,0,0,0,0,0,0,0,0,0,0,0,0,0,0,5,6,0,6,5,6,6,6,5,6,0,6,5,5,0
0,19,6,0,0,0,0,0,0,0,0,0,0,0,0,0,0,0,6,0,0,0,0,0,0,0,0,0,0,0,0,0,0
0,5,5,6,0,0,0,6,5,6,5,0,0,0,5,0,0,0,5,0,0,0,0,0,0,0,0,0,0,0,0,0,0
0,0,6,0,0,0,0,0,6,0,0,0,0,0,0,0,0,0,0,0,0,0,0,0,0,0,0,0,0,0,5,0,0
0,18,5,0,0,0,0,0,0,0,0,0,0,0,0,0,0,0,0,0,0,0,0,0,0,0,0,0,0,0,22,0,0
0,0,6,0,0,0,0,0,6,0,5,22,22,22,5,22,22,22,5,22,22,22,5,22,22,22,5,22,22,22,5,21,0
0,0,6,0,0,0,0,0,5,0,20,0,0,0,20,0,0,0,20,0,0,0,20,0,0,0,20,0,0,0,20,0,0
0,0,6,0,0,0,0,0,6,0,0,0,0,0,0,0,0,0,0,0,0,0,0,0,0,0,0,0,0,0,0,0,0
0,18,5,0,0,0,0,0,6,0,0,0,0,0,0,0,0,0,0,0,0,0,0,0,0,0,0,0,0,0,0,0,0
0,0,6,0,0,0,0,0,6,0,0,0,0,0,0,0,0,0,0,0,0,0,0,0,0,0,0,0,0,0,0,0,0
0,0,5,6,6,6,6,6,5,0,0,0,0,0,0,0,0,0,0,0,0,0,0,0,0,0,0,0,0,0,0,0,0
0,0,20,0,0,0,0,0,20,0,0,0,0,0,0,0,0,0,0,0,0,0,0,0,0,0,0,0,0,0,0,0,0
0,0,0,0,0,0,0,0,0,0,0,0,0,0,0,0,0,0,0,0,0,0,0,0,0,0,0,0,0,0,0,0,0
:endlayer
layer: 4
0,0,0,0,0,0,0,0,0,0,0,0,0,0,0,0,0,0,0,0,0,0,0,0,0,0,0,0,0,0,0,0,0
0,0,5,0,0,0,0,0,0,0,5,0,0,0,0,0,0,0,5,0,0,0,0,0,0,0,0,0,0,0,0,0,0
0,5,5,6,6,5,6,5,6,6,5,6,6,5,6,5,6,6,5,0,0,0,0,0,0,0,0,0,0,0,0,0,0
0,0,6,0,0,20,17,11,0,0,0,0,0,0,0,0,0,0,6,0,0,0,0,0,5,0,0,0,0,0,5,0,0
0,0,6,0,0,0,17,11,0,0,0,0,0,0,0,0,0,0,5,6,5,6,5,6,5,6,5,6,5,6,5,5,0
0,0,5,0,0,0,17,11,0,0,0,0,0,0,0,0,0,0,6,0,0,0,0,0,0,0,0,0,0,0,6,0,0
0,0,6,0,0,0,5,0,0,0,5,0,0,0,5,0,0,0,5,0,0,0,0,0,0,0,0,0,0,0,6,0,0
0,0,6,0,0,0,0,0,0,0,0,0,0,0,0,0,0,0,0,0,0,0,0,0,0,0,0,0,23,23,6,0,0
0,5,5,0,0,0,0,0,0,0,0,0,0,0,0,0,0,0,0,0,0,0,0,0,0,0,0,0,7,7,5,5,0
0,0,6,0,0,0,0,0,0,0,0,0,0,0,0,0,0,0,0,0,0,0,0,0,0,0,0,0,0,0,6,0,0
0,0,6,0,0,0,5,0,0,0,5,0,0,0,5,0,0,0,5,0,0,0,0,0,0,0,0,0,0,0,6,0,0
0,0,5,0,0,0,0,0,0,0,0,0,0,0,0,0,0,0,6,0,0,0,0,0,0,0,0,0,0,0,6,0,0
0,0,6,0,0,0,0,0,0,0,0,0,0,0,0,0,0,0,5,6,0,6,5,6,22,6,5,6,0,6,5,5,0
0,0,6,0,0,0,0,0,0,0,0,0,0,0,0,0,0,0,6,0,0,0,0,0,0,0,0,0,0,0,0,0,0
0,5,5,6,0,0,0,6,5,6,5,0,0,0,5,0,0,0,5,0,0,0,0,0,0,0,0,0,0,0,0,0,0
0,0,6,0,0,0,0,0,6,0,0,0,0,0,0,0,0,0,0,0,0,0,0,0,0,0,0,0,0,0,22,0,0
0,0,5,0,0,0,0,0,0,0,19,0,0,0,19,0,0,0,19,0,0,0,19,0,0,0,19,0,0,0,0,0,0
0,0,6,0,0,0,0,0,6,0,5,0,0,0,5,0,0,0,5,0,0,0,5,0,0,0,5,0,0,0,5,0,0
0,0,22,0,0,0,0,0,5,0,0,0,0,0,0,0,0,0,0,0,0,0,0,0,0,0,0,0,0,0,0,0,0
0,0,6,0,0,0,0,0,6,0,0,0,0,0,0,0,0,0,0,0,0,0,0,0,0,0,0,0,0,0,0,0,0
0,0,5,0,0,0,0,0,22,0,0,0,0,0,0,0,0,0,0,0,0,0,0,0,0,0,0,0,0,0,0,0,0
0,0,6,0,0,0,0,0,6,0,0,0,0,0,0,0,0,0,0,0,0,0,0,0,0,0,0,0,0,0,0,0,0
0,0,5,6,6,22,6,6,5,0,0,0,0,0,0,0,0,0,0,0,0,0,0,0,0,0,0,0,0,0,0,0,0
0,0,0,0,0,0,0,0,0,0,0,0,0,0,0,0,0,0,0,0,0,0,0,0,0,0,0,0,0,0,0,0,0
0,0,0,0,0,0,0,0,0,0,0,0,0,0,0,0,0,0,0,0,0,0,0,0,0,0,0,0,0,0,0,0,0
:endlayer
layer: 5
0,0,0,0,0,0,0,0,0,0,0,0,0,0,0,0,0,0,0,0,0,0,0,0,0,0,0,0,0,0,0,0,0
0,0,5,0,0,0,0,0,0,0,5,0,0,0,0,0,0,0,5,0,0,0,0,0,0,0,0,0,0,0,0,0,0
0,5,5,6,6,5,6,5,6,6,5,6,6,5,6,5,6,6,5,0,0,0,0,0,0,0,0,0,0,0,0,0,0
0,0,6,0,0,17,11,0,0,0,20,0,0,0,0,20,0,0,6,0,0,0,0,0,5,0,0,0,0,0,5,0,0
0,0,6,0,0,17,11,0,0,0,0,0,0,0,0,0,0,0,5,6,5,6,5,6,5,6,5,6,5,6,5,5,0
0,0,5,21,0,17,11,0,0,0,0,0,0,0,0,0,0,0,6,0,20,0,16,0,20,0,16,0,20,0,6,0,0
0,0,6,0,0,0,5,0,0,0,5,0,0,0,5,0,0,18,5,0,0,0,14,0,0,0,14,0,23,23,6,0,0
0,0,6,0,0,0,20,0,0,0,20,0,0,0,20,0,0,0,16,0,0,0,0,0,0,0,0,0,7,7,6,0,0
0,5,5,0,0,0,0,0,0,0,0,0,0,0,0,0,0,0,14,0,0,0,0,0,0,0,0,0,0,0,5,5,0
0,0,6,0,0,0,19,0,0,0,19,0,0,0,19,0,0,0,23,0,0,0,0,0,0,0,0,0,0,0,6,0,0
0,0,6,0,0,0,5,0,0,0,5,0,0,0,5,0,0,18,5,0,0,0,14,0,0,0,14,0,0,0,6,0,0
0,0,5,21,0,0,0,0,0,0,0,0,0,0,0,0,0,0,6,0,19,0,23,0,19,0,23,0,19,0,6,0,0
0,0,6,0,0,0,0,0,0,0,0,0,0,0,0,0,0,0,5,6,6,6,5,6,6,6,5,6,6,6,5,5,0
0,0,6,0,0,0,0,0,19,0,0,0,0,0,19,0,0,0,6,0,0,0,20,0,0,0,20,0,0,0,0,0,0
0,5,5,6,15,14,17,6,5,6,5,15,14,17,5,15,14,17,5,0,0,0,0,0,0,0,0,0,0,0,0,0,0
0,0,6,0,0,0,0,0,6,0,0,0,0,0,0,0,0,0,0,0,0,0,0,0,0,0,0,0,0,0,22,0,0
0,0,5,21,0,0,0,0,6,0,14,0,0,0,14,0,0,0,14,0,0,0,14,0,0,0,14,0,0,0,23,0,0
0,0,6,0,0,0,0,0,6,0,5,0,0,0,5,0,0,0,5,0,0,0,5,0,0,0,5,0,0,0,5,0,0
0,0,6,0,0,0,0,18,5,24,24,24,24,24,24,24,24,24,24,24,24,24,24,24,24,24,24,24,24,24,24,24,0
0,0,6,0,0,0,0,0,6,0,0,0,0,0,0,0,0,0,0,0,0,0,0,0,0,0,0,0,0,0,0,0,0
0,0,5,21,0,0,0,0,6,0,0,0,0,0,0,0,0,0,0,0,0,0,0,0,0,0,0,0,0,0,0,0,0
0,0,6,0,0,0,0,0,6,0,0,0,0,0,0,0,0,0,0,0,0,0,0,0,0,0,0,0,0,0,0,0,0
0,0,5,6,6,6,6,6,5,0,0,0,0,0,0,0,0,0,0,0,0,0,0,0,0,0,0,0,0,0,0,0,0
0,0,0,0,0,0,0,0,0,0,0,0,0,0,0,0,0,0,0,0,0,0,0,0,0,0,0,0,0,0,0,0,0
0,0,0,0,0,0,0,0,0,0,0,0,0,0,0,0,0,0,0,0,0,0,0,0,0,0,0,0,0,0,0,0,0
:endlayer
layer: 6
0,0,0,0,0,0,0,0,0,0,0,0,0,0,0,0,0,0,0,0,0,0,0,0,0,0,0,0,0,0,0,0,0
0,0,5,0,0,0,0,0,0,0,5,0,0,0,0,0,0,0,5,0,0,0,0,0,0,0,0,0,0,0,0,0,0
0,5,5,8,8,8,8,8,8,8,8,8,8,8,8,8,8,8,5,0,0,0,0,0,0,0,0,0,0,0,0,0,0
0,0,10,14,6,11,0,0,0,14,6,14,6,14,6,14,6,14,10,0,0,0,0,0,5,0,0,0,0,0,5,0,0
0,0,10,14,6,11,0,0,0,14,6,14,6,14,6,14,6,14,5,8,8,8,8,8,8,8,8,8,8,8,5,5,0
0,0,10,14,6,11,0,0,0,14,6,14,6,14,6,14,6,14,10,14,14,14,10,14,14,14,10,6,6,6,10,0,0
0,0,10,8,8,8,8,8,8,8,8,8,8,8,8,8,8,8,10,6,6,6,10,6,6,6,10,6,7,7,10,0,0
0,0,10,14,6,14,6,14,6,14,6,14,6,14,6,14,6,14,10,14,14,14,10,14,14,14,10,15,0,0,10,0,0
0,5,10,14,6,14,6,14,6,14,6,14,6,14,6,14,6,14,10,6,6,6,10,6,6,6,10,15,0,0,10,5,0
0,0,10,14,6,14,6,14,6,14,6,14,6,14,6,14,6,14,10,14,14,14,10,14,14,14,10,15,0,0,10,0,0
0,0,10,8,8,8,8,8,8,8,8,8,8,8,8,8,8,8,10,6,6,6,10,6,6,6,10,15,0,0,10,0,0
0,0,10,14,6,14,6,14,6,14,6,14,6,14,6,14,6,14,10,14,14,14,10,14,14,14,10,15,0,0,10,0,0
0,0,10,14,6,14,6,14,6,14,6,14,6,14,6,14,6,14,5,8,8,8,8,8,8,8,8,8,8,8,5,5,0
0,0,10,14,6,14,6,14,6,14,6,14,6,14,6,14,6,14,10,0,0,0,0,0,0,0,0,0,0,0,10,0,0
0,5,5,8,8,8,8,8,8,8,8,8,8,8,8,8,8,8,5,0,0,0,14,0,0,0,14,0,0,0,10,0,0
0,24,10,0,0,20,0,0,10,0,23,0,0,0,23,0,0,0,23,0,0,0,23,0,0,0,23,0,0,0,10,0,0
0,24,10,0,0,0,0,0,10,24,24,24,24,24,24,24,24,24,24,24,24,24,24,24,24,24,24,24,24,24,24,24,0
0,24,10,0,0,0,0,0,10,24,24,24,24,24,24,24,24,24,24,24,24,24,24,24,24,24,24,24,24,24,24,24,0
0,24,10,0,0,0,0,0,10,24,0,0,0,0,0,0,0,0,0,0,0,0,0,0,0,0,0,0,0,0,0,0,0
0,24,10,0,0,0,0,0,10,24,0,0,0,0,0,0,0,0,0,0,0,0,0,0,0,0,0,0,0,0,0,0,0
0,24,10,0,0,0,0,0,10,24,0,0,0,0,0,0,0,0,0,0,0,0,0,0,0,0,0,0,0,0,0,0,0
0,24,10,0,0,19,0,0,10,24,0,0,0,0,0,0,0,0,0,0,0,0,0,0,0,0,0,0,0,0,0,0,0
0,24,5,8,8,8,8,8,5,24,0,0,0,0,0,0,0,0,0,0,0,0,0,0,0,0,0,0,0,0,0,0,0
0,24,0,0,0,0,0,0,0,24,0,0,0,0,0,0,0,0,0,0,0,0,0,0,0,0,0,0,0,0,0,0,0
0,0,0,0,0,0,0,0,0,0,0,0,0,0,0,0,0,0,0,0,0,0,0,0,0,0,0,0,0,0,0,0,0
:endlayer
layer: 7
0,0,0,0,0,0,0,0,0,0,0,0,0,0,0,0,0,0,0,0,0,0,0,0,0,0,0,0,0,0,0,0,0
0,0,5,0,0,0,0,0,0,0,5,0,0,0,0,0,0,0,5,0,0,0,0,0,0,0,0,0,0,0,0,0,0
0,5,5,6,5,6,6,6,5,6,5,6,5,6,6,6,5,6,5,0,0,0,0,0,0,0,0,0,0,0,0,0,0
0,0,6,0,0,0,0,0,0,22,0,0,0,0,0,0,0,0,6,0,0,0,0,0,5,0,0,0,0,0,5,0,0
0,0,6,0,0,0,0,0,0,22,0,0,0,0,0,0,0,0,5,6,6,5,6,6,5,6,6,5,6,6,5,5,0
0,0,6,0,0,0,0,0,0,22,0,0,0,0,0,0,0,0,6,0,0,0,0,0,0,0,0,0,0,0,6,0,0
0,0,6,0,0,0,5,22,22,22,5,0,0,0,5,0,0,0,5,0,0,0,0,0,0,0,0,0,0,0,6,0,0
0,0,6,0,0,0,0,0,0,0,0,0,0,0,0,0,0,0,0,0,0,0,0,0,0,0,0,22,0,0,6,0,0
0,5,5,0,0,0,0,0,0,0,0,0,0,0,0,0,0,0,0,0,0,0,0,0,0,0,0,22,0,0,5,5,0
0,0,6,0,0,0,0,0,0,0,0,0,0,0,0,0,0,0,0,0,0,0,0,0,0,0,0,22,0,0,6,0,0
0,0,6,0,0,0,5,0,0,0,5,0,0,0,5,0,0,0,5,0,0,0,0,0,0,0,0,22,0,0,6,0,0
0,0,6,0,0,0,0,0,0,0,0,0,0,0,0,0,0,0,6,0,0,0,0,0,0,0,0,22,0,0,6,0,0
0,0,6,0,0,0,0,0,0,0,0,0,0,0,0,0,0,0,5,6,6,6,5,6,6,6,5,6,6,6,5,5,0
0,0,6,0,25,15,19,0,0,0,0,0,0,0,0,0,0,0,6,0,0,0,23,0,0,0,23,0,0,0,6,0,0
0,5,5,6,6,6,5,6,6,6,5,6,6,6,5,6,6,6,5,24,24,24,24,24,24,24,24,24,24,24,24,24,0
0,0,24,0,0,0,0,0,24,24,24,24,24,24,24,24,24,24,24,24,24,24,24,24,24,24,24,24,24,24,24,24,0
0,0,24,0,0,0,0,0,24,9,0,0,0,0,9,0,0,0,0,9,0,0,0,0,9,0,0,0,0,9,0,0,0
0,0,24,0,0,0,0,0,24,0,0,0,0,0,0,0,0,0,0,0,0,0,0,0,0,0,0,0,0,0,0,0,0
0,0,24,0,0,0,0,0,24,0,0,0,0,0,0,0,0,0,0,0,0,0,0,0,0,0,0,0,0,0,0,0,0
0,0,24,0,0,0,0,0,24,0,0,0,0,0,0,0,0,0,0,0,0,0,0,0,0,0,0,0,0,0,0,0,0
0,0,24,0,0,0,0,0,24,0,0,0,0,0,0,0,0,0,0,0,0,0,0,0,0,0,0,0,0,0,0,0,0
0,0,24,0,0,0,0,0,24,0,0,0,0,0,0,0,0,0,0,0,0,0,0,0,0,0,0,0,0,0,0,0,0
0,0,24,6,6,6,6,6,24,0,0,0,0,0,0,0,0,0,0,0,0,0,0,0,0,0,0,0,0,0,0,0,0
0,0,24,15,14,26,14,17,24,0,0,0,0,0,0,0,0,0,0,0,0,0,0,0,0,0,0,0,0,0,0,0,0
0,0,0,0,0,0,0,0,0,0,0,0,0,0,0,0,0,0,0,0,0,0,0,0,0,0,0,0,0,0,0,0,0
:endlayer
layer: 8
0,0,0,0,0,0,0,0,0,0,0,0,0,0,0,0,0,0,0,0,0,0,0,0,0,0,0,0,0,0,0,0,0
0,0,5,0,0,0,0,0,0,0,5,0,0,0,0,0,0,0,5,0,0,0,0,0,0,0,0,0,0,0,0,0,0
0,5,5,6,5,6,22,6,5,6,5,6,5,6,22,6,5,6,5,0,0,0,0,0,0,0,0,0,0,0,0,0,0
0,0,6,0,0,0,0,0,0,0,0,0,0,0,0,0,0,0,6,0,0,0,0,0,5,0,0,0,0,0,5,0,0
0,0,6,0,0,0,0,0,0,0,0,0,0,0,0,0,0,0,5,6,6,5,6,6,5,6,6,5,6,6,5,5,0
0,0,22,0,0,0,0,0,0,0,0,0,0,0,0,0,0,0,6,0,0,0,0,0,0,0,0,0,0,0,6,0,0
0,0,6,0,0,0,5,0,0,0,5,0,0,0,5,0,0,0,5,0,0,0,0,0,0,0,0,0,0,0,22,0,0
0,0,6,0,0,0,0,0,0,0,0,0,0,0,0,0,0,0,0,0,0,0,0,0,0,0,0,0,0,0,6,0,0
0,5,5,0,0,0,0,0,0,0,0,0,0,0,0,0,0,0,0,0,0,0,0,0,0,0,0,0,0,0,5,5,0
0,0,6,0,0,0,0,0,0,0,0,0,0,0,0,0,0,0,0,0,0,0,0,0,0,0,0,0,0,0,6,0,0
0,0,6,0,0,0,5,0,0,0,5,0,0,0,5,0,0,0,5,0,0,0,0,0,0,0,0,0,0,0,22,0,0
0,0,22,0,0,0,0,0,0,0,0,0,0,0,0,0,0,0,6,0,0,0,0,0,0,0,0,0,0,0,6,0,0
0,0,6,0,0,0,0,0,0,0,0,0,0,0,0,0,0,0,5,6,6,6,5,6,6,6,5,6,6,6,5,5,0
0,0,6,0,0,25,15,0,0,0,0,0,0,0,0,0,0,0,6,24,24,24,24,24,24,24,24,24,24,24,24,24,0
0,5,5,6,6,6,5,6,6,6,5,6,22,6,5,6,22,6,5,0,0,0,0,0,0,0,0,0,0,0,0,0,0
0,0,0,24,0,0,0,24,0,0,0,0,0,0,0,0,0,0,0,0,0,0,0,0,0,0,0,0,0,0,0,0,0
0,0,0,24,0,0,0,24,0,0,0,0,0,0,0,0,0,0,0,0,0,0,0,0,0,0,0,0,0,0,0,0,0
0,0,0,24,0,0,0,24,0,0,0,0,0,0,0,0,0,0,0,0,0,0,0,0,0,0,0,0,0,0,0,0,0
0,0,0,24,0,0,0,24,0,0,0,0,0,0,0,0,0,0,0,0,0,0,0,0,0,0,0,0,0,0,0,0,0
0,0,0,24,0,0,0,24,0,0,0,0,0,0,0,0,0,0,0,0,0,0,0,0,0,0,0,0,0,0,0,0,0
0,0,0,24,0,0,0,24,0,0,0,0,0,0,0,0,0,0,0,0,0,0,0,0,0,0,0,0,0,0,0,0,0
0,0,0,24,0,0,0,24,0,0,0,0,0,0,0,0,0,0,0,0,0,0,0,0,0,0,0,0,0,0,0,0,0
0,0,0,24,6,6,6,24,0,0,0,0,0,0,0,0,0,0,0,0,0,0,0,0,0,0,0,0,0,0,0,0,0
0,0,0,24,15,0,17,24,0,0,0,0,0,0,0,0,0,0,0,0,0,0,0,0,0,0,0,0,0,0,0,0,0
0,0,0,0,0,0,0,0,0,0,0,0,0,0,0,0,0,0,0,0,0,0,0,0,0,0,0,0,0,0,0,0,0
:endlayer
layer: 9
0,0,0,0,0,0,0,0,0,0,0,0,0,0,0,0,0,0,0,0,0,0,0,0,0,0,0,0,0,0,0,0,0
0,0,5,0,0,0,0,0,0,0,5,0,0,0,0,0,0,0,5,0,0,0,0,0,0,0,0,0,0,0,0,0,0
0,5,5,6,5,6,6,6,5,6,5,6,5,6,6,6,5,6,5,0,0,0,0,0,0,0,0,0,0,0,0,0,0
0,0,6,0,20,0,0,0,20,0,0,0,20,0,0,0,20,0,6,15,14,26,14,17,5,15,14,26,14,17,5,0,0
0,0,6,0,0,0,0,0,0,0,0,0,0,0,0,0,0,0,5,6,6,5,6,6,5,6,6,5,6,6,5,5,0
0,0,6,0,0,0,0,0,0,0,0,0,0,0,0,0,0,0,6,0,0,20,0,0,20,0,0,20,0,0,6,16,0
0,0,6,0,0,0,5,0,0,0,5,0,0,0,5,0,0,18,5,21,0,0,0,0,0,0,0,0,0,0,6,14,0
0,0,6,0,0,0,20,0,0,0,20,0,0,0,20,0,0,0,16,0,0,0,0,0,0,0,0,0,0,0,6,23,0
0,5,5,0,0,0,0,0,0,0,0,0,0,0,0,0,0,0,14,0,0,0,0,0,0,0,0,0,0,18,5,5,0
0,0,6,0,0,0,19,0,0,0,19,0,0,0,19,0,0,0,23,0,0,0,0,0,0,0,0,0,0,0,6,16,0
0,0,6,0,0,0,5,0,0,0,5,0,0,0,5,0,0,18,5,21,0,0,0,0,0,0,0,0,0,0,6,14,0
0,0,6,0,0,0,0,0,0,0,0,0,0,0,0,0,0,0,6,0,0,0,19,0,0,0,19,0,0,0,6,23,0
0,0,6,0,0,0,0,0,0,0,0,0,0,0,0,0,0,0,5,6,6,6,5,6,6,6,5,6,6,6,5,5,0
0,0,6,0,0,0,25,15,0,0,19,0,0,0,19,0,0,0,6,9,0,0,0,0,9,0,0,0,0,9,0,0,0
0,5,5,6,6,6,5,6,6,6,5,6,6,6,5,6,6,6,5,0,0,0,0,0,0,0,0,0,0,0,0,0,0
0,0,0,0,24,0,24,0,0,0,0,0,0,0,0,0,0,0,0,0,0,0,0,0,0,0,0,0,0,0,0,0,0
0,0,0,9,24,0,24,9,0,0,0,0,0,0,0,0,0,0,0,0,0,0,0,0,0,0,0,0,0,0,0,0,0
0,0,0,0,24,0,24,0,0,0,0,0,0,0,0,0,0,0,0,0,0,0,0,0,0,0,0,0,0,0,0,0,0
0,0,0,0,24,0,24,0,0,0,0,0,0,0,0,0,0,0,0,0,0,0,0,0,0,0,0,0,0,0,0,0,0
0,0,0,0,24,0,24,0,0,0,0,0,0,0,0,0,0,0,0,0,0,0,0,0,0,0,0,0,0,0,0,0,0
0,0,0,0,24,0,24,0,0,0,0,0,0,0,0,0,0,0,0,0,0,0,0,0,0,0,0,0,0,0,0,0,0
0,0,0,9,24,0,24,9,0,0,0,0,0,0,0,0,0,0,0,0,0,0,0,0,0,0,0,0,0,0,0,0,0
0,0,0,0,24,6,24,0,0,0,0,0,0,0,0,0,0,0,0,0,0,0,0,0,0,0,0,0,0,0,0,0,0
0,0,0,0,24,16,24,0,0,0,0,0,0,0,0,0,0,0,0,0,0,0,0,0,0,0,0,0,0,0,0,0,0
0,0,0,0,0,0,0,0,0,0,0,0,0,0,0,0,0,0,0,0,0,0,0,0,0,0,0,0,0,0,0,0,0
:endlayer
layer: 10
0,0,0,0,0,0,0,0,0,0,0,0,0,0,0,0,0,0,0,0,0,0,0,0,0,0,0,0,0,0,0,0,0
0,0,5,0,0,0,0,0,0,0,5,0,0,0,0,0,0,0,5,0,0,0,0,0,0,0,0,0,0,0,0,0,0
0,5,5,8,8,8,8,8,8,8,8,8,8,8,8,8,8,8,5,0,0,0,0,0,0,0,0,0,0,0,0,0,0
0,0,10,14,6,14,6,14,6,14,6,14,6,14,6,14,6,14,10,24,24,24,24,24,24,24,24,24,24,24,24,24,0
0,0,10,14,6,14,6,14,6,14,6,14,6,14,6,14,6,14,5,8,8,8,8,8,8,8,8,8,8,8,5,5,0
0,0,10,14,6,14,6,14,6,14,6,14,6,14,6,14,6,14,10,14,6,14,6,14,6,14,0,0,0,0,10,10,0
0,0,10,8,8,8,8,8,8,8,8,8,8,8,8,8,8,8,10,14,6,14,6,14,6,14,0,0,0,0,10,10,0
0,0,10,14,6,14,6,14,6,14,6,14,6,14,6,14,6,14,10,14,6,14,6,14,6,14,0,0,0,0,10,10,0
0,5,10,14,6,14,6,14,6,14,6,14,6,14,6,14,6,14,10,14,6,14,6,14,6,14,0,0,0,0,10,10,0
0,0,10,14,6,14,6,14,6,14,6,14,6,14,6,14,6,14,10,14,6,14,6,14,6,14,0,0,0,0,10,10,0
0,0,10,8,8,8,8,8,8,8,8,8,8,8,8,8,8,8,10,14,6,14,6,14,6,14,0,0,0,0,10,10,0
0,0,10,14,6,14,6,14,6,14,6,14,6,14,6,14,6,14,10,14,6,14,6,14,6,14,0,0,0,0,10,10,0
0,0,10,6,6,6,6,6,6,14,6,14,6,14,6,14,6,14,5,8,8,8,8,8,8,8,8,8,8,8,5,5,0
0,0,10,0,0,0,0,25,6,14,6,14,6,14,6,14,6,14,10,24,24,24,24,24,24,24,24,24,24,24,24,24,0
0,5,5,8,8,8,8,8,8,8,8,8,8,8,8,8,8,8,5,0,0,0,0,0,0,0,0,0,0,0,0,0,0
0,0,0,0,0,24,0,0,0,0,0,0,0,0,0,0,0,0,0,0,0,0,0,0,0,0,0,0,0,0,0,0,0
0,0,0,0,0,24,0,0,0,0,0,0,0,0,0,0,0,0,0,0,0,0,0,0,0,0,0,0,0,0,0,0,0
0,0,0,0,0,24,0,0,0,0,0,0,0,0,0,0,0,0,0,0,0,0,0,0,0,0,0,0,0,0,0,0,0
0,0,0,0,0,24,0,0,0,0,0,0,0,0,0,0,0,0,0,0,0,0,0,0,0,0,0,0,0,0,0,0,0
0,0,0,0,0,24,0,0,0,0,0,0,0,0,0,0,0,0,0,0,0,0,0,0,0,0,0,0,0,0,0,0,0
0,0,0,0,0,24,0,0,0,0,0,0,0,0,0,0,0,0,0,0,0,0,0,0,0,0,0,0,0,0,0,0,0
0,0,0,0,0,24,0,0,0,0,0,0,0,0,0,0,0,0,0,0,0,0,0,0,0,0,0,0,0,0,0,0,0
0,0,0,0,0,24,0,0,0,0,0,0,0,0,0,0,0,0,0,0,0,0,0,0,0,0,0,0,0,0,0,0,0
0,0,0,0,0,24,0,0,0,0,0,0,0,0,0,0,0,0,0,0,0,0,0,0,0,0,0,0,0,0,0,0,0
0,0,0,0,0,0,0,0,0,0,0,0,0,0,0,0,0,0,0,0,0,0,0,0,0,0,0,0,0,0,0,0,0
:endlayer
layer: 11
0,0,0,0,0,0,0,0,0,0,0,0,0,0,0,0,0,0,0,0,0,0,0,0,0,0,0,0,0,0,0,0,0
0,0,5,0,0,0,14,0,0,0,5,0,0,0,14,0,0,0,5,0,0,0,0,0,0,0,0,0,0,0,0,0,0
0,5,5,6,6,6,5,6,6,6,5,6,6,6,5,6,6,6,5,0,0,0,0,0,0,0,0,0,0,0,0,0,0
0,0,6,0,0,0,0,0,0,0,0,0,0,0,0,0,0,0,6,0,0,0,0,0,0,0,0,0,0,0,0,0,0
0,0,6,0,0,0,0,0,0,0,0,0,0,0,0,0,0,0,5,24,24,24,24,24,24,24,24,24,24,24,24,24,0
0,0,6,0,0,0,0,0,0,0,0,0,0,0,0,0,0,0,6,0,0,0,0,0,0,22,0,0,0,0,6,14,0
0,0,6,0,0,0,0,0,0,0,0,0,0,0,0,0,0,0,5,0,0,0,0,0,0,22,0,0,0,0,6,0,0
0,0,6,0,0,0,0,0,0,0,0,0,0,0,0,0,0,0,0,0,0,0,0,0,0,22,0,0,0,0,6,0,0
0,5,5,0,0,0,0,0,9,0,0,0,9,0,0,0,0,0,0,0,0,0,0,9,0,22,0,0,0,0,6,0,0
0,0,6,0,0,0,0,0,0,0,0,0,0,0,0,0,0,0,0,0,0,0,0,0,0,22,0,0,0,0,6,0,0
0,0,6,0,0,0,0,0,0,0,0,0,0,0,0,0,0,0,5,0,0,0,0,0,0,22,0,0,0,0,6,0,0
0,0,6,0,0,0,0,0,0,0,0,0,0,0,0,0,0,0,6,0,0,0,0,0,0,22,0,0,0,0,6,14,0
0,0,6,22,22,22,22,0,0,0,0,0,0,0,0,0,0,0,5,24,24,24,24,24,24,24,24,24,24,24,24,24,0
0,0,6,0,0,0,0,0,0,0,0,0,0,0,0,0,0,0,6,0,0,0,0,0,0,0,0,0,0,0,0,0,0
0,5,5,6,6,6,5,6,6,6,5,6,6,6,5,6,6,6,5,0,0,0,0,0,0,0,0,0,0,0,0,0,0
0,0,14,0,0,0,14,0,0,0,14,0,0,0,14,0,0,0,14,0,0,0,0,0,0,0,0,0,0,0,0,0,0
0,0,0,0,0,0,0,0,0,0,0,0,0,0,0,0,0,0,0,0,0,0,0,0,0,0,0,0,0,0,0,0,0
0,0,0,0,0,0,0,0,0,0,0,0,0,0,0,0,0,0,0,0,0,0,0,0,0,0,0,0,0,0,0,0,0
0,0,0,0,0,0,0,0,0,0,0,0,0,0,0,0,0,0,0,0,0,0,0,0,0,0,0,0,0,0,0,0,0
0,0,0,0,0,0,0,0,0,0,0,0,0,0,0,0,0,0,0,0,0,0,0,0,0,0,0,0,0,0,0,0,0
0,0,0,0,0,0,0,0,0,0,0,0,0,0,0,0,0,0,0,0,0,0,0,0,0,0,0,0,0,0,0,0,0
0,0,0,0,0,0,0,0,0,0,0,0,0,0,0,0,0,0,0,0,0,0,0,0,0,0,0,0,0,0,0,0,0
0,0,0,0,0,0,0,0,0,0,0,0,0,0,0,0,0,0,0,0,0,0,0,0,0,0,0,0,0,0,0,0,0
0,0,0,0,0,0,0,0,0,0,0,0,0,0,0,0,0,0,0,0,0,0,0,0,0,0,0,0,0,0,0,0,0
0,0,0,0,0,0,0,0,0,0,0,0,0,0,0,0,0,0,0,0,0,0,0,0,0,0,0,0,0,0,0,0,0
:endlayer
layer: 12
0,0,0,0,0,0,0,0,0,0,0,0,0,0,0,0,0,0,0,0,0,0,0,0,0,0,0,0,0,0,0,0,0
0,24,24,24,24,24,24,24,24,24,24,24,24,24,24,24,24,24,24,24,0,0,0,0,0,0,0,0,0,0,0,0,0
0,5,5,8,8,8,8,8,8,8,8,8,8,8,8,8,8,8,5,0,0,0,0,0,0,0,0,0,0,0,0,0,0
0,0,6,0,0,0,20,0,0,0,20,0,0,0,20,0,0,0,10,0,0,0,0,0,0,0,0,0,0,0,0,0,0
0,0,6,0,0,0,0,0,0,0,0,0,0,0,0,0,0,0,10,0,0,0,0,9,0,0,9,0,0,0,0,0,0
0,0,22,0,0,0,0,0,0,0,0,0,0,0,0,0,0,0,10,24,24,24,24,24,24,24,24,24,24,24,24,24,0
0,0,6,0,0,0,0,0,0,0,0,0,0,0,0,0,0,18,5,21,0,0,0,0,0,0,0,0,0,0,6,14,0
0,0,6,0,0,0,0,0,0,0,0,0,0,0,0,0,0,0,0,0,0,0,0,0,0,0,0,0,0,0,6,0,0
0,5,5,21,0,0,0,0,0,0,0,0,0,0,0,0,0,0,0,0,0,0,0,0,0,0,0,0,0,0,22,0,0
0,0,6,0,0,0,0,0,0,0,0,0,0,0,0,0,0,0,0,0,0,0,0,0,0,0,0,0,0,0,6,0,0
0,0,6,0,0,0,0,0,0,0,0,0,0,0,0,0,0,18,5,21,0,0,0,0,0,0,0,0,0,0,6,14,0
0,0,22,0,0,0,0,0,0,0,0,0,0,0,0,0,0,0,10,24,24,24,24,24,24,24,24,24,24,24,24,24,0
0,0,6,0,0,0,0,0,0,0,0,0,0,0,0,0,0,0,10,0,0,0,0,9,0,0,9,0,0,0,0,0,0
0,0,6,0,0,0,19,0,0,0,19,0,0,0,19,0,0,0,10,0,0,0,0,0,0,0,0,0,0,0,0,0,0
0,5,5,8,8,8,8,8,8,8,8,8,8,8,8,8,8,8,5,0,0,0,0,0,0,0,0,0,0,0,0,0,0
0,24,24,24,24,24,24,24,24,24,24,24,24,24,24,24,24,24,24,24,0,0,0,0,0,0,0,0,0,0,0,0,0
0,0,0,0,0,0,0,0,0,0,0,0,0,0,0,0,0,0,0,0,0,0,0,0,0,0,0,0,0,0,0,0,0
0,0,0,0,0,0,0,0,0,0,0,0,0,0,0,0,0,0,0,0,0,0,0,0,0,0,0,0,0,0,0,0,0
0,0,0,0,0,0,0,0,0,0,0,0,0,0,0,0,0,0,0,0,0,0,0,0,0,0,0,0,0,0,0,0,0
0,0,0,0,0,0,0,0,0,0,0,0,0,0,0,0,0,0,0,0,0,0,0,0,0,0,0,0,0,0,0,0,0
0,0,0,0,0,0,0,0,0,0,0,0,0,0,0,0,0,0,0,0,0,0,0,0,0,0,0,0,0,0,0,0,0
0,0,0,0,0,0,0,0,0,0,0,0,0,0,0,0,0,0,0,0,0,0,0,0,0,0,0,0,0,0,0,0,0
0,0,0,0,0,0,0,0,0,0,0,0,0,0,0,0,0,0,0,0,0,0,0,0,0,0,0,0,0,0,0,0,0
0,0,0,0,0,0,0,0,0,0,0,0,0,0,0,0,0,0,0,0,0,0,0,0,0,0,0,0,0,0,0,0,0
0,0,0,0,0,0,0,0,0,0,0,0,0,0,0,0,0,0,0,0,0,0,0,0,0,0,0,0,0,0,0,0,0
:endlayer
layer: 13
0,0,0,0,0,0,0,0,0,0,0,0,0,0,0,0,0,0,0,0,0,0,0,0,0,0,0,0,0,0,0,0,0
0,0,0,0,0,0,0,0,0,0,0,0,0,0,0,0,0,0,0,0,0,0,0,0,0,0,0,0,0,0,0,0,0
0,24,24,24,24,24,24,24,24,24,24,24,24,24,24,24,24,24,24,24,0,0,0,0,0,0,0,0,0,0,0,0,0
0,6,6,0,0,0,0,0,0,0,0,0,0,0,0,0,0,0,6,0,0,0,0,0,0,0,0,0,0,0,0,0,0
0,14,6,0,0,0,0,0,0,0,0,0,0,0,0,0,0,0,6,0,0,0,0,0,0,0,0,0,0,0,0,0,0
0,0,6,0,0,0,0,0,0,0,0,0,0,0,0,0,0,0,6,0,9,0,0,0,0,0,0,0,0,9,0,0,0
0,14,6,0,0,0,0,0,0,0,0,0,0,0,0,0,0,0,5,24,24,24,24,24,24,24,24,24,24,24,24,24,0
0,6,6,0,0,0,0,0,0,0,0,0,0,0,0,0,0,0,16,0,0,0,0,0,0,0,0,0,0,0,6,16,0
0,5,5,0,0,0,0,0,0,0,0,0,0,0,0,0,0,0,14,0,0,0,0,0,0,0,0,0,0,18,6,26,0
0,6,6,0,0,0,0,0,0,0,0,0,0,0,0,0,0,0,23,0,0,0,0,0,0,0,0,0,0,0,6,23,0
0,14,6,0,0,0,0,0,0,0,0,0,0,0,0,0,0,0,5,24,24,24,24,24,24,24,24,24,24,24,24,24,0
0,0,6,0,0,0,0,0,0,0,0,0,0,0,0,0,0,0,6,0,9,0,0,0,0,0,0,0,0,9,0,0,0
0,14,6,0,0,0,0,0,0,0,0,0,0,0,0,0,0,0,6,0,0,0,0,0,0,0,0,0,0,0,0,0,0
0,6,6,0,0,0,0,0,0,0,0,0,0,0,0,0,0,0,6,0,0,0,0,0,0,0,0,0,0,0,0,0,0
0,24,24,24,24,24,24,24,24,24,24,24,24,24,24,24,24,24,24,24,0,0,0,0,0,0,0,0,0,0,0,0,0
0,0,0,0,0,0,0,0,0,0,0,0,0,0,0,0,0,0,0,0,0,0,0,0,0,0,0,0,0,0,0,0,0
0,0,0,0,0,0,0,0,0,0,0,0,0,0,0,0,0,0,0,0,0,0,0,0,0,0,0,0,0,0,0,0,0
0,0,0,0,0,0,0,0,0,0,0,0,0,0,0,0,0,0,0,0,0,0,0,0,0,0,0,0,0,0,0,0,0
0,0,0,0,0,0,0,0,0,0,0,0,0,0,0,0,0,0,0,0,0,0,0,0,0,0,0,0,0,0,0,0,0
0,0,0,0,0,0,0,0,0,0,0,0,0,0,0,0,0,0,0,0,0,0,0,0,0,0,0,0,0,0,0,0,0
0,0,0,0,0,0,0,0,0,0,0,0,0,0,0,0,0,0,0,0,0,0,0,0,0,0,0,0,0,0,0,0,0
0,0,0,0,0,0,0,0,0,0,0,0,0,0,0,0,0,0,0,0,0,0,0,0,0,0,0,0,0,0,0,0,0
0,0,0,0,0,0,0,0,0,0,0,0,0,0,0,0,0,0,0,0,0,0,0,0,0,0,0,0,0,0,0,0,0
0,0,0,0,0,0,0,0,0,0,0,0,0,0,0,0,0,0,0,0,0,0,0,0,0,0,0,0,0,0,0,0,0
0,0,0,0,0,0,0,0,0,0,0,0,0,0,0,0,0,0,0,0,0,0,0,0,0,0,0,0,0,0,0,0,0
:endlayer
layer: 14
0,0,0,0,0,0,0,0,0,0,0,0,0,0,0,0,0,0,0,0,0,0,0,0,0,0,0,0,0,0,0,0,0
0,0,0,0,0,0,0,0,0,0,0,0,0,0,0,0,0,0,0,0,0,0,0,0,0,0,0,0,0,0,0,0,0
0,0,0,0,0,0,0,0,0,0,9,0,0,0,0,0,0,0,0,0,0,0,0,0,0,0,0,0,0,0,0,0,0
0,24,24,24,24,24,24,24,24,24,24,24,24,24,24,24,24,24,24,24,0,0,0,0,0,0,0,0,0,0,0,0,0
0,10,10,0,0,0,0,0,0,0,0,0,0,0,0,0,0,0,6,0,0,0,0,0,0,0,0,0,0,0,0,0,0
0,10,10,0,0,0,0,0,0,0,0,0,0,0,0,0,0,0,6,0,0,0,0,0,0,0,0,0,0,0,0,0,0
0,10,10,0,0,0,0,0,0,0,0,0,0,0,0,0,0,0,5,0,0,0,0,0,0,0,0,0,0,0,0,0,0
0,10,10,0,0,0,0,0,0,0,0,0,0,0,0,0,0,0,10,24,24,24,24,24,24,24,24,24,24,24,24,24,0
0,5,10,0,0,0,0,0,0,0,0,0,0,0,0,0,0,0,10,0,0,0,0,0,0,0,0,0,0,0,6,15,0
0,10,10,0,0,0,0,0,0,0,0,0,0,0,0,0,0,0,10,24,24,24,24,24,24,24,24,24,24,24,24,24,0
0,10,10,0,0,0,0,0,0,0,0,0,0,0,0,0,0,0,5,0,0,0,0,0,0,0,0,0,0,0,0,0,0
0,10,10,0,0,0,0,0,0,0,0,0,0,0,0,0,0,0,6,0,0,0,0,0,0,0,0,0,0,0,0,0,0
0,10,10,0,0,0,0,0,0,0,0,0,0,0,0,0,0,0,6,0,0,0,0,0,0,0,0,0,0,0,0,0,0
0,24,24,24,24,24,24,24,24,24,24,24,24,24,24,24,24,24,24,24,0,0,0,0,0,0,0,0,0,0,0,0,0
0,0,0,0,0,0,0,0,0,0,9,0,0,0,0,0,0,0,0,0,0,0,0,0,0,0,0,0,0,0,0,0,0
0,0,0,0,0,0,0,0,0,0,0,0,0,0,0,0,0,0,0,0,0,0,0,0,0,0,0,0,0,0,0,0,0
0,0,0,0,0,0,0,0,0,0,0,0,0,0,0,0,0,0,0,0,0,0,0,0,0,0,0,0,0,0,0,0,0
0,0,0,0,0,0,0,0,0,0,0,0,0,0,0,0,0,0,0,0,0,0,0,0,0,0,0,0,0,0,0,0,0
0,0,0,0,0,0,0,0,0,0,0,0,0,0,0,0,0,0,0,0,0,0,0,0,0,0,0,0,0,0,0,0,0
0,0,0,0,0,0,0,0,0,0,0,0,0,0,0,0,0,0,0,0,0,0,0,0,0,0,0,0,0,0,0,0,0
0,0,0,0,0,0,0,0,0,0,0,0,0,0,0,0,0,0,0,0,0,0,0,0,0,0,0,0,0,0,0,0,0
0,0,0,0,0,0,0,0,0,0,0,0,0,0,0,0,0,0,0,0,0,0,0,0,0,0,0,0,0,0,0,0,0
0,0,0,0,0,0,0,0,0,0,0,0,0,0,0,0,0,0,0,0,0,0,0,0,0,0,0,0,0,0,0,0,0
0,0,0,0,0,0,0,0,0,0,0,0,0,0,0,0,0,0,0,0,0,0,0,0,0,0,0,0,0,0,0,0,0
0,0,0,0,0,0,0,0,0,0,0,0,0,0,0,0,0,0,0,0,0,0,0,0,0,0,0,0,0,0,0,0,0
:endlayer
layer: 15
0,0,0,0,0,0,0,0,0,0,0,0,0,0,0,0,0,0,0,0,0,0,0,0,0,0,0,0,0,0,0,0,0
0,0,0,0,0,0,0,0,0,0,0,0,0,0,0,0,0,0,0,0,0,0,0,0,0,0,0,0,0,0,0,0,0
0,0,0,0,0,0,0,0,0,0,0,0,0,0,0,0,0,0,0,0,0,0,0,0,0,0,0,0,0,0,0,0,0
0,0,0,9,0,0,0,9,0,0,0,0,0,9,0,0,0,9,0,0,0,0,0,0,0,0,0,0,0,0,0,0,0
0,24,24,24,24,24,24,24,24,24,24,24,24,24,24,24,24,24,24,24,0,0,0,0,0,0,0,0,0,0,0,0,0
0,7,6,0,0,0,0,0,0,0,0,0,0,0,0,0,0,0,6,0,0,0,0,0,0,0,0,0,0,0,0,0,0
0,0,6,0,0,0,0,0,0,0,0,0,0,0,0,0,0,0,5,0,0,0,0,0,0,0,0,0,0,0,0,0,0
0,0,6,0,0,0,0,0,0,0,0,0,0,0,0,0,0,0,6,0,0,0,0,0,0,0,0,0,0,0,0,0,0
0,5,5,0,0,0,0,0,0,0,0,0,0,0,0,0,0,0,6,24,24,24,24,24,24,24,24,24,24,24,24,24,0
0,0,6,0,0,0,0,0,0,0,0,0,0,0,0,0,0,0,6,0,0,0,0,0,0,0,0,0,0,0,0,0,0
0,0,6,0,0,0,0,0,0,0,0,0,0,0,0,0,0,0,5,0,0,0,0,0,0,0,0,0,0,0,0,0,0
0,27,6,0,0,0,0,0,0,0,0,0,0,0,0,0,0,0,6,0,0,0,0,0,0,0,0,0,0,0,0,0,0
0,24,24,24,24,24,24,24,24,24,24,24,24,24,24,24,24,24,24,24,0,0,0,0,0,0,0,0,0,0,0,0,0
0,0,0,9,0,0,0,9,0,0,0,0,0,9,0,0,0,9,0,0,0,0,0,0,0,0,0,0,0,0,0,0,0
0,0,0,0,0,0,0,0,0,0,0,0,0,0,0,0,0,0,0,0,0,0,0,0,0,0,0,0,0,0,0,0,0
0,0,0,0,0,0,0,0,0,0,0,0,0,0,0,0,0,0,0,0,0,0,0,0,0,0,0,0,0,0,0,0,0
0,0,0,0,0,0,0,0,0,0,0,0,0,0,0,0,0,0,0,0,0,0,0,0,0,0,0,0,0,0,0,0,0
0,0,0,0,0,0,0,0,0,0,0,0,0,0,0,0,0,0,0,0,0,0,0,0,0,0,0,0,0,0,0,0,0
0,0,0,0,0,0,0,0,0,0,0,0,0,0,0,0,0,0,0,0,0,0,0,0,0,0,0,0,0,0,0,0,0
0,0,0,0,0,0,0,0,0,0,0,0,0,0,0,0,0,0,0,0,0,0,0,0,0,0,0,0,0,0,0,0,0
0,0,0,0,0,0,0,0,0,0,0,0,0,0,0,0,0,0,0,0,0,0,0,0,0,0,0,0,0,0,0,0,0
0,0,0,0,0,0,0,0,0,0,0,0,0,0,0,0,0,0,0,0,0,0,0,0,0,0,0,0,0,0,0,0,0
0,0,0,0,0,0,0,0,0,0,0,0,0,0,0,0,0,0,0,0,0,0,0,0,0,0,0,0,0,0,0,0,0
0,0,0,0,0,0,0,0,0,0,0,0,0,0,0,0,0,0,0,0,0,0,0,0,0,0,0,0,0,0,0,0,0
0,0,0,0,0,0,0,0,0,0,0,0,0,0,0,0,0,0,0,0,0,0,0,0,0,0,0,0,0,0,0,0,0
:endlayer
layer: 16
0,0,0,0,0,0,0,0,0,0,0,0,0,0,0,0,0,0,0,0,0,0,0,0,0,0,0,0,0,0,0,0,0
0,0,0,0,0,0,0,0,0,0,0,0,0,0,0,0,0,0,0,0,0,0,0,0,0,0,0,0,0,0,0,0,0
0,0,0,0,0,0,0,0,0,0,0,0,0,0,0,0,0,0,0,0,0,0,0,0,0,0,0,0,0,0,0,0,0
0,0,0,0,0,0,0,0,0,0,0,0,0,0,0,0,0,0,0,0,0,0,0,0,0,0,0,0,0,0,0,0,0
0,0,0,0,0,0,0,0,0,0,0,0,0,0,0,0,0,0,0,0,0,0,0,0,0,0,0,0,0,0,0,0,0
0,24,24,24,24,24,24,24,24,24,24,24,24,24,24,24,24,24,24,24,0,0,0,0,0,0,0,0,0,0,0,0,0
0,14,6,0,0,0,0,0,0,0,0,0,0,0,0,0,0,0,10,0,0,0,0,0,0,0,0,0,0,0,0,0,0
0,0,6,0,0,0,0,0,0,0,0,0,0,0,0,0,0,0,10,0,0,0,0,0,0,0,0,0,0,0,0,0,0
0,5,5,21,0,0,0,0,0,0,0,0,0,0,0,0,0,18,10,0,9,0,0,0,0,0,0,0,0,9,0,0,0
0,0,6,0,0,0,0,0,0,0,0,0,0,0,0,0,0,0,10,0,0,0,0,0,0,0,0,0,0,0,0,0,0
0,14,6,0,0,0,0,0,0,0,0,0,0,0,0,0,0,0,10,0,0,0,0,0,0,0,0,0,0,0,0,0,0
0,24,24,24,24,24,24,24,24,24,24,24,24,24,24,24,24,24,24,24,0,0,0,0,0,0,0,0,0,0,0,0,0
0,0,0,0,0,0,0,0,0,0,0,0,0,0,0,0,0,0,0,0,0,0,0,0,0,0,0,0,0,0,0,0,0
0,0,0,0,0,0,0,0,0,0,0,0,0,0,0,0,0,0,0,0,0,0,0,0,0,0,0,0,0,0,0,0,0
0,0,0,0,0,0,0,0,0,0,0,0,0,0,0,0,0,0,0,0,0,0,0,0,0,0,0,0,0,0,0,0,0
0,0,0,0,0,0,0,0,0,0,0,0,0,0,0,0,0,0,0,0,0,0,0,0,0,0,0,0,0,0,0,0,0
0,0,0,0,0,0,0,0,0,0,0,0,0,0,0,0,0,0,0,0,0,0,0,0,0,0,0,0,0,0,0,0,0
0,0,0,0,0,0,0,0,0,0,0,0,0,0,0,0,0,0,0,0,0,0,0,0,0,0,0,0,0,0,0,0,0
0,0,0,0,0,0,0,0,0,0,0,0,0,0,0,0,0,0,0,0,0,0,0,0,0,0,0,0,0,0,0,0,0
0,0,0,0,0,0,0,0,0,0,0,0,0,0,0,0,0,0,0,0,0,0,0,0,0,0,0,0,0,0,0,0,0
0,0,0,0,0,0,0,0,0,0,0,0,0,0,0,0,0,0,0,0,0,0,0,0,0,0,0,0,0,0,0,0,0
0,0,0,0,0,0,0,0,0,0,0,0,0,0,0,0,0,0,0,0,0,0,0,0,0,0,0,0,0,0,0,0,0
0,0,0,0,0,0,0,0,0,0,0,0,0,0,0,0,0,0,0,0,0,0,0,0,0,0,0,0,0,0,0,0,0
0,0,0,0,0,0,0,0,0,0,0,0,0,0,0,0,0,0,0,0,0,0,0,0,0,0,0,0,0,0,0,0,0
0,0,0,0,0,0,0,0,0,0,0,0,0,0,0,0,0,0,0,0,0,0,0,0,0,0,0,0,0,0,0,0,0
:endlayer
layer: 17
0,0,0,0,0,0,0,0,0,0,0,0,0,0,0,0,0,0,0,0,0,0,0,0,0,0,0,0,0,0,0,0,0
0,0,0,0,0,0,0,0,0,0,0,0,0,0,0,0,0,0,0,0,0,0,0,0,0,0,0,0,0,0,0,0,0
0,0,0,0,0,0,0,0,0,0,0,0,0,0,0,0,0,0,0,0,0,0,0,0,0,0,0,0,0,0,0,0,0
0,0,0,0,0,0,0,0,0,0,0,0,0,0,0,0,0,0,0,0,0,0,0,0,0,0,0,0,0,0,0,0,0
0,0,0,0,0,0,0,0,0,0,0,0,0,0,0,0,0,0,0,0,0,0,0,0,0,0,0,0,0,0,0,0,0
0,0,0,0,0,0,0,0,0,0,0,0,0,0,0,0,0,0,0,0,0,0,0,0,0,0,0,0,0,0,0,0,0
0,24,24,24,24,24,24,24,24,24,24,24,24,24,24,24,24,24,24,24,0,0,0,0,0,0,0,0,0,0,0,0,0
0,16,6,0,0,0,0,0,0,0,0,0,0,0,0,0,0,0,6,0,0,0,0,0,0,0,0,0,0,0,0,0,0
0,5,5,0,0,0,0,0,0,0,0,0,0,0,0,0,0,0,6,0,0,0,0,0,0,0,0,0,0,0,0,0,0
0,23,6,0,0,0,0,0,0,0,0,0,0,0,0,0,0,0,6,0,0,0,0,0,0,0,0,0,0,0,0,0,0
0,24,24,24,24,24,24,24,24,24,24,24,24,24,24,24,24,24,24,24,0,0,0,0,0,0,0,0,0,0,0,0,0
0,0,0,0,0,0,0,0,0,0,0,0,0,0,0,0,0,0,0,0,0,0,0,0,0,0,0,0,0,0,0,0,0
0,0,0,0,0,0,0,0,0,0,0,0,0,0,0,0,0,0,0,0,0,0,0,0,0,0,0,0,0,0,0,0,0
0,0,0,0,0,0,0,0,0,0,0,0,0,0,0,0,0,0,0,0,0,0,0,0,0,0,0,0,0,0,0,0,0
0,0,0,0,0,0,0,0,0,0,0,0,0,0,0,0,0,0,0,0,0,0,0,0,0,0,0,0,0,0,0,0,0
0,0,0,0,0,0,0,0,0,0,0,0,0,0,0,0,0,0,0,0,0,0,0,0,0,0,0,0,0,0,0,0,0
0,0,0,0,0,0,0,0,0,0,0,0,0,0,0,0,0,0,0,0,0,0,0,0,0,0,0,0,0,0,0,0,0
0,0,0,0,0,0,0,0,0,0,0,0,0,0,0,0,0,0,0,0,0,0,0,0,0,0,0,0,0,0,0,0,0
0,0,0,0,0,0,0,0,0,0,0,0,0,0,0,0,0,0,0,0,0,0,0,0,0,0,0,0,0,0,0,0,0
0,0,0,0,0,0,0,0,0,0,0,0,0,0,0,0,0,0,0,0,0,0,0,0,0,0,0,0,0,0,0,0,0
0,0,0,0,0,0,0,0,0,0,0,0,0,0,0,0,0,0,0,0,0,0,0,0,0,0,0,0,0,0,0,0,0
0,0,0,0,0,0,0,0,0,0,0,0,0,0,0,0,0,0,0,0,0,0,0,0,0,0,0,0,0,0,0,0,0
0,0,0,0,0,0,0,0,0,0,0,0,0,0,0,0,0,0,0,0,0,0,0,0,0,0,0,0,0,0,0,0,0
0,0,0,0,0,0,0,0,0,0,0,0,0,0,0,0,0,0,0,0,0,0,0,0,0,0,0,0,0,0,0,0,0
0,0,0,0,0,0,0,0,0,0,0,0,0,0,0,0,0,0,0,0,0,0,0,0,0,0,0,0,0,0,0,0,0
:endlayer
layer: 18
0,0,0,0,0,0,0,0,0,0,0,0,0,0,0,0,0,0,0,0,0,0,0,0,0,0,0,0,0,0,0,0,0
0,0,0,0,0,0,0,0,0,0,0,0,0,0,0,0,0,0,0,0,0,0,0,0,0,0,0,0,0,0,0,0,0
0,0,0,0,0,0,0,0,0,0,0,0,0,0,0,0,0,0,0,0,0,0,0,0,0,0,0,0,0,0,0,0,0
0,0,0,0,0,0,0,0,0,0,0,0,0,0,0,0,0,0,0,0,0,0,0,0,0,0,0,0,0,0,0,0,0
0,0,0,0,0,0,0,0,0,0,0,0,0,0,0,0,0,0,0,0,0,0,0,0,0,0,0,0,0,0,0,0,0
0,0,0,0,0,0,0,0,0,0,0,0,0,0,0,0,0,0,0,0,0,0,0,0,0,0,0,0,0,0,0,0,0
0,0,0,9,0,0,0,9,0,0,0,0,0,9,0,0,0,9,0,0,0,0,0,0,0,0,0,0,0,0,0,0,0
0,24,24,24,24,24,24,24,24,24,24,24,24,24,24,24,24,24,24,24,0,0,0,0,0,0,0,0,0,0,0,0,0
0,5,5,0,0,0,0,0,0,0,0,0,0,0,0,0,0,0,6,0,0,0,0,0,0,0,0,0,0,0,0,0,0
0,24,24,24,24,24,24,24,24,24,24,24,24,24,24,24,24,24,24,24,0,0,0,0,0,0,0,0,0,0,0,0,0
0,0,0,9,0,0,0,9,0,0,0,0,0,9,0,0,0,9,0,0,0,0,0,0,0,0,0,0,0,0,0,0,0
0,0,0,0,0,0,0,0,0,0,0,0,0,0,0,0,0,0,0,0,0,0,0,0,0,0,0,0,0,0,0,0,0
0,0,0,0,0,0,0,0,0,0,0,0,0,0,0,0,0,0,0,0,0,0,0,0,0,0,0,0,0,0,0,0,0
0,0,0,0,0,0,0,0,0,0,0,0,0,0,0,0,0,0,0,0,0,0,0,0,0,0,0,0,0,0,0,0,0
0,0,0,0,0,0,0,0,0,0,0,0,0,0,0,0,0,0,0,0,0,0,0,0,0,0,0,0,0,0,0,0,0
0,0,0,0,0,0,0,0,0,0,0,0,0,0,0,0,0,0,0,0,0,0,0,0,0,0,0,0,0,0,0,0,0
0,0,0,0,0,0,0,0,0,0,0,0,0,0,0,0,0,0,0,0,0,0,0,0,0,0,0,0,0,0,0,0,0
0,0,0,0,0,0,0,0,0,0,0,0,0,0,0,0,0,0,0,0,0,0,0,0,0,0,0,0,0,0,0,0,0
0,0,0,0,0,0,0,0,0,0,0,0,0,0,0,0,0,0,0,0,0,0,0,0,0,0,0,0,0,0,0,0,0
0,0,0,0,0,0,0,0,0,0,0,0,0,0,0,0,0,0,0,0,0,0,0,0,0,0,0,0,0,0,0,0,0
0,0,0,0,0,0,0,0,0,0,0,0,0,0,0,0,0,0,0,0,0,0,0,0,0,0,0,0,0,0,0,0,0
0,0,0,0,0,0,0,0,0,0,0,0,0,0,0,0,0,0,0,0,0,0,0,0,0,0,0,0,0,0,0,0,0
0,0,0,0,0,0,0,0,0,0,0,0,0,0,0,0,0,0,0,0,0,0,0,0,0,0,0,0,0,0,0,0,0
0,0,0,0,0,0,0,0,0,0,0,0,0,0,0,0,0,0,0,0,0,0,0,0,0,0,0,0,0,0,0,0,0
0,0,0,0,0,0,0,0,0,0,0,0,0,0,0,0,0,0,0,0,0,0,0,0,0,0,0,0,0,0,0,0,0
:endlayer
layer: 19
0,0,0,0,0,0,0,0,0,0,0,0,0,0,0,0,0,0,0,0,0,0,0,0,0,0,0,0,0,0,0,0,0
0,0,0,0,0,0,0,0,0,0,0,0,0,0,0,0,0,0,0,0,0,0,0,0,0,0,0,0,0,0,0,0,0
0,0,0,0,0,0,0,0,0,0,0,0,0,0,0,0,0,0,0,0,0,0,0,0,0,0,0,0,0,0,0,0,0
0,0,0,0,0,0,0,0,0,0,0,0,0,0,0,0,0,0,0,0,0,0,0,0,0,0,0,0,0,0,0,0,0
0,0,0,0,0,0,0,0,0,0,0,0,0,0,0,0,0,0,0,0,0,0,0,0,0,0,0,0,0,0,0,0,0
0,0,0,0,0,0,0,0,0,0,0,0,0,0,0,0,0,0,0,0,0,0,0,0,0,0,0,0,0,0,0,0,0
0,0,0,0,0,0,0,0,0,0,0,0,0,0,0,0,0,0,0,0,0,0,0,0,0,0,0,0,0,0,0,0,0
0,0,0,0,0,0,0,0,0,0,0,0,0,0,0,0,0,0,0,0,0,0,0,0,0,0,0,0,0,0,0,0,0
0,24,24,24,24,24,24,24,24,24,24,24,24,24,24,24,24,24,24,24,0,0,0,0,0,0,0,0,0,0,0,0,0
0,0,0,0,0,0,0,0,0,0,0,0,0,0,0,0,0,0,0,0,0,0,0,0,0,0,0,0,0,0,0,0,0
0,0,0,0,0,0,0,0,0,0,0,0,0,0,0,0,0,0,0,0,0,0,0,0,0,0,0,0,0,0,0,0,0
0,0,0,0,0,0,0,0,0,0,0,0,0,0,0,0,0,0,0,0,0,0,0,0,0,0,0,0,0,0,0,0,0
0,0,0,0,0,0,0,0,0,0,0,0,0,0,0,0,0,0,0,0,0,0,0,0,0,0,0,0,0,0,0,0,0
0,0,0,0,0,0,0,0,0,0,0,0,0,0,0,0,0,0,0,0,0,0,0,0,0,0,0,0,0,0,0,0,0
0,0,0,0,0,0,0,0,0,0,0,0,0,0,0,0,0,0,0,0,0,0,0,0,0,0,0,0,0,0,0,0,0
0,0,0,0,0,0,0,0,0,0,0,0,0,0,0,0,0,0,0,0,0,0,0,0,0,0,0,0,0,0,0,0,0
0,0,0,0,0,0,0,0,0,0,0,0,0,0,0,0,0,0,0,0,0,0,0,0,0,0,0,0,0,0,0,0,0
0,0,0,0,0,0,0,0,0,0,0,0,0,0,0,0,0,0,0,0,0,0,0,0,0,0,0,0,0,0,0,0,0
0,0,0,0,0,0,0,0,0,0,0,0,0,0,0,0,0,0,0,0,0,0,0,0,0,0,0,0,0,0,0,0,0
0,0,0,0,0,0,0,0,0,0,0,0,0,0,0,0,0,0,0,0,0,0,0,0,0,0,0,0,0,0,0,0,0
0,0,0,0,0,0,0,0,0,0,0,0,0,0,0,0,0,0,0,0,0,0,0,0,0,0,0,0,0,0,0,0,0
0,0,0,0,0,0,0,0,0,0,0,0,0,0,0,0,0,0,0,0,0,0,0,0,0,0,0,0,0,0,0,0,0
0,0,0,0,0,0,0,0,0,0,0,0,0,0,0,0,0,0,0,0,0,0,0,0,0,0,0,0,0,0,0,0,0
0,0,0,0,0,0,0,0,0,0,0,0,0,0,0,0,0,0,0,0,0,0,0,0,0,0,0,0,0,0,0,0,0
0,0,0,0,0,0,0,0,0,0,0,0,0,0,0,0,0,0,0,0,0,0,0,0,0,0,0,0,0,0,0,0,0
:endlayer
layer: 20
0,0,0,0,0,0,0,0,0,0,0,0,0,0,0,0,0,0,0,0,0,0,0,0,0,0,0,0,0,0,0,0,0
0,0,0,0,0,0,0,0,0,0,0,0,0,0,0,0,0,0,0,0,0,0,0,0,0,0,0,0,0,0,0,0,0
0,0,0,0,0,0,0,0,0,0,0,0,0,0,0,0,0,0,0,0,0,0,0,0,0,0,0,0,0,0,0,0,0
0,0,0,0,0,0,0,0,0,0,0,0,0,0,0,0,0,0,0,0,0,0,0,0,0,0,0,0,0,0,0,0,0
0,0,0,0,0,0,0,0,0,0,0,0,0,0,0,0,0,0,0,0,0,0,0,0,0,0,0,0,0,0,0,0,0
0,0,0,0,0,0,0,0,0,0,0,0,0,0,0,0,0,0,0,0,0,0,0,0,0,0,0,0,0,0,0,0,0
0,0,0,0,0,0,0,0,0,0,0,0,0,0,0,0,0,0,0,0,0,0,0,0,0,0,0,0,0,0,0,0,0
0,0,0,0,0,0,0,0,0,0,0,0,0,0,0,0,0,0,0,0,0,0,0,0,0,0,0,0,0,0,0,0,0
0,0,0,0,0,0,0,0,0,0,9,0,0,0,0,0,0,0,0,0,0,0,0,0,0,0,0,0,0,0,0,0,0
0,0,0,0,0,0,0,0,0,0,0,0,0,0,0,0,0,0,0,0,0,0,0,0,0,0,0,0,0,0,0,0,0
0,0,0,0,0,0,0,0,0,0,0,0,0,0,0,0,0,0,0,0,0,0,0,0,0,0,0,0,0,0,0,0,0
0,0,0,0,0,0,0,0,0,0,0,0,0,0,0,0,0,0,0,0,0,0,0,0,0,0,0,0,0,0,0,0,0
0,0,0,0,0,0,0,0,0,0,0,0,0,0,0,0,0,0,0,0,0,0,0,0,0,0,0,0,0,0,0,0,0
0,0,0,0,0,0,0,0,0,0,0,0,0,0,0,0,0,0,0,0,0,0,0,0,0,0,0,0,0,0,0,0,0
0,0,0,0,0,0,0,0,0,0,0,0,0,0,0,0,0,0,0,0,0,0,0,0,0,0,0,0,0,0,0,0,0
0,0,0,0,0,0,0,0,0,0,0,0,0,0,0,0,0,0,0,0,0,0,0,0,0,0,0,0,0,0,0,0,0
0,0,0,0,0,0,0,0,0,0,0,0,0,0,0,0,0,0,0,0,0,0,0,0,0,0,0,0,0,0,0,0,0
0,0,0,0,0,0,0,0,0,0,0,0,0,0,0,0,0,0,0,0,0,0,0,0,0,0,0,0,0,0,0,0,0
0,0,0,0,0,0,0,0,0,0,0,0,0,0,0,0,0,0,0,0,0,0,0,0,0,0,0,0,0,0,0,0,0
0,0,0,0,0,0,0,0,0,0,0,0,0,0,0,0,0,0,0,0,0,0,0,0,0,0,0,0,0,0,0,0,0
0,0,0,0,0,0,0,0,0,0,0,0,0,0,0,0,0,0,0,0,0,0,0,0,0,0,0,0,0,0,0,0,0
0,0,0,0,0,0,0,0,0,0,0,0,0,0,0,0,0,0,0,0,0,0,0,0,0,0,0,0,0,0,0,0,0
0,0,0,0,0,0,0,0,0,0,0,0,0,0,0,0,0,0,0,0,0,0,0,0,0,0,0,0,0,0,0,0,0
0,0,0,0,0,0,0,0,0,0,0,0,0,0,0,0,0,0,0,0,0,0,0,0,0,0,0,0,0,0,0,0,0
0,0,0,0,0,0,0,0,0,0,0,0,0,0,0,0,0,0,0,0,0,0,0,0,0,0,0,0,0,0,0,0,0
:endlayer

#### RULES ####
rule:
plugin=vanillaBlocks
number=1
data:
JSON:{blockState:{blockName:"minecraft:grass",properties:{snowy:"false"}}}
:enddata
:endrule

rule:
plugin=vanillaBlocks
number=2
data:
JSON:{blockState:{blockName:"minecraft:cobblestone"}}
:enddata
:endrule

rule:
plugin=vanillaBlocks
number=3
data:
JSON:{blockState:{blockName:"minecraft:dirt",properties:{variant:"dirt",snowy:"false"}}}
:enddata
:endrule

rule:
plugin=vanillaBlocks
number=4
data:
JSON:{blockState:{blockName:"minecraft:stonebrick",properties:{variant:"stonebrick"}}}
:enddata
:endrule

rule:
plugin=vanillaBlocks
number=5
data:
JSON:{blockState:{blockName:"biomesoplenty:log_3",properties:{variant:"ebony",axis:"y"}}}
:enddata
:endrule

rule:
plugin=vanillaBlocks
number=6
data:
JSON:{blockState:{blockName:"biomesoplenty:planks_0",properties:{variant:"ebony"}}}
:enddata
:endrule

rule:
plugin=vanillaBlocks
number=7
data:
JSON:{blockState:{blockName:"biomesoplenty:ebony_stairs",properties:{half:"bottom",shape:"straight",facing:"north"}}}
:enddata
:endrule

rule:
plugin=vanillaBlocks
number=8
data:
JSON:{blockState:{blockName:"biomesoplenty:log_3",properties:{variant:"ebony",axis:"x"}}}
:enddata
:endrule

rule:
plugin=vanillaBlocks
number=9
data:
JSON:{blockState:{blockName:"minecraft:torch",properties:{facing:"up"}}}
:enddata
:endrule

rule:
plugin=vanillaBlocks
number=10
data:
JSON:{blockState:{blockName:"biomesoplenty:log_3",properties:{variant:"ebony",axis:"z"}}}
:enddata
:endrule

rule:
plugin=vanillaBlocks
number=11
data:
JSON:{blockState:{blockName:"biomesoplenty:ebony_stairs",properties:{half:"bottom",shape:"straight",facing:"west"}}}
:enddata
:endrule

rule:
plugin=vanillaBlocks
number=12
data:
JSON:{blockState:{blockName:"minecraft:gravel"}}
:enddata
:endrule

rule:
plugin=vanillaBlocks
number=13
data:
JSON:{blockState:{blockName:"minecraft:dirt",properties:{variant:"coarse_dirt",snowy:"false"}}}
:enddata
:endrule

rule:
plugin=vanillaBlocks
number=14
data:
JSON:{blockState:{blockName:"biomesoplenty:wood_slab_1",properties:{half:"top",variant:"ebony"}}}
:enddata
:endrule

rule:
plugin=vanillaBlocks
number=15
data:
JSON:{blockState:{blockName:"biomesoplenty:ebony_stairs",properties:{half:"top",shape:"straight",facing:"west"}}}
:enddata
:endrule

rule:
plugin=vanillaBlocks
number=16
data:
JSON:{blockState:{blockName:"biomesoplenty:ebony_stairs",properties:{half:"top",shape:"straight",facing:"north"}}}
:enddata
:endrule

rule:
plugin=vanillaBlocks
number=17
data:
JSON:{blockState:{blockName:"biomesoplenty:ebony_stairs",properties:{half:"top",shape:"straight",facing:"east"}}}
:enddata
:endrule

rule:
plugin=vanillaBlocks
number=18
data:
JSON:{blockState:{blockName:"minecraft:torch",properties:{facing:"west"}}}
:enddata
:endrule

rule:
plugin=vanillaBlocks
number=19
data:
JSON:{blockState:{blockName:"minecraft:torch",properties:{facing:"north"}}}
:enddata
:endrule

rule:
plugin=vanillaBlocks
number=20
data:
JSON:{blockState:{blockName:"minecraft:torch",properties:{facing:"south"}}}
:enddata
:endrule

rule:
plugin=vanillaBlocks
number=21
data:
JSON:{blockState:{blockName:"minecraft:torch",properties:{facing:"east"}}}
:enddata
:endrule

rule:
plugin=vanillaBlocks
number=22
data:
JSON:{blockState:{blockName:"biomesoplenty:ebony_fence",properties:{east:"false",south:"false",north:"false",west:"false"}}}
:enddata
:endrule

rule:
plugin=vanillaBlocks
number=23
data:
JSON:{blockState:{blockName:"biomesoplenty:ebony_stairs",properties:{half:"top",shape:"straight",facing:"south"}}}
:enddata
:endrule

rule:
plugin=vanillaBlocks
number=24
data:
JSON:{blockState:{blockName:"minecraft:wool",properties:{color:"brown"}}}
:enddata
:endrule

rule:
plugin=vanillaBlocks
number=25
data:
JSON:{blockState:{blockName:"biomesoplenty:ebony_stairs",properties:{half:"bottom",shape:"straight",facing:"east"}}}
:enddata
:endrule

rule:
plugin=vanillaBlocks
number=26
data:
JSON:{blockState:{blockName:"biomesoplenty:wood_slab_1",properties:{half:"bottom",variant:"ebony"}}}
:enddata
:endrule

rule:
plugin=vanillaBlocks
number=27
data:
JSON:{blockState:{blockName:"biomesoplenty:ebony_stairs",properties:{half:"bottom",shape:"straight",facing:"south"}}}
:enddata
:endrule

#### ENTITIES ####
