# Ancient Warfare Structure Template File
# Auto-generated structure template file. created on: 9/23/2023 at: 14:7:13
# Lines beginning with # denote comments

header:
version=2.11
name=SB_KievarusCol_GrainTower_1_umbran
mods=biomesoplenty
size=14,14,13
offset=2,1,12
:endheader

#### VALIDATION ####
validation:
type=ground
structureAuthor=TheOddlySeagull
survival=true
worldGenEnabled=false
unique=false
preserveBlocks=false
preventNaturalHostileSpawns=false
selectionWeight=1
clusterValue=1
minDuplicateDistance=1
dimensionWhiteList=true
dimensionList=
biomeGroupList=
biomeWhiteList=true
biomeList=
leveling=0
fill=0
border=0
blockSwap=false
territoryName=
biomeReplacement=minecraft:
minGenerationHeight=0
maxGenerationHeight=255
:endvalidation

#### LAYERS ####
layer: 0
1,1,1,1,1,1,1,1,1,1,1,1,1,1
1,1,1,1,1,1,1,1,1,1,1,1,1,1
2,1,1,2,2,2,2,2,2,2,2,2,1,1
1,1,1,2,2,2,2,2,3,3,3,2,1,1
1,1,1,2,3,2,2,2,2,3,3,2,1,1
1,1,1,2,2,3,3,2,3,3,3,2,1,1
2,1,1,2,3,3,2,2,2,3,3,2,1,1
1,1,1,2,3,3,2,2,2,3,2,2,1,1
1,1,1,2,3,3,2,3,2,2,3,2,1,1
1,1,1,2,2,2,3,2,2,2,2,2,1,1
2,2,2,2,2,2,2,2,2,2,2,2,1,1
4,2,2,4,1,1,1,1,1,1,1,1,1,1
4,2,2,4,1,1,1,1,1,1,1,1,1,1
:endlayer
layer: 1
0,0,0,0,0,0,0,0,0,0,0,0,0,0
0,0,0,0,0,0,0,0,0,0,0,0,0,0
5,0,0,5,6,6,6,5,6,6,6,5,0,0
0,0,0,6,3,3,2,3,2,3,3,6,0,0
0,0,0,6,2,3,2,3,2,2,2,6,0,0
0,0,0,6,2,2,2,3,2,3,2,6,0,0
5,0,0,5,3,2,2,2,3,3,2,5,0,0
0,0,0,6,3,3,2,2,3,3,3,6,0,0
0,0,0,6,2,3,2,2,2,3,3,6,0,0
0,0,0,6,3,2,2,3,3,3,3,6,0,0
5,7,7,5,6,6,6,5,6,6,6,5,0,0
0,8,8,0,0,0,0,0,0,0,0,0,0,0
0,0,0,0,0,0,0,0,0,0,0,0,0,0
:endlayer
layer: 2
0,0,0,0,0,0,0,0,0,0,0,0,0,0
0,0,0,0,0,0,0,0,0,0,0,0,0,0
5,6,6,5,7,7,7,7,7,7,7,5,0,0
0,13,12,9,10,10,10,10,10,11,10,9,0,0
0,13,12,9,10,10,11,11,11,10,10,9,0,0
0,13,12,9,11,11,11,10,10,10,11,9,0,0
5,6,6,9,10,10,10,10,10,11,11,9,0,0
0,13,12,9,10,10,10,11,10,11,10,9,0,0
0,13,12,9,11,11,10,10,11,10,11,9,0,0
0,13,12,9,11,10,11,11,10,10,11,9,0,0
5,8,8,5,7,7,7,7,7,7,7,5,0,0
0,0,0,0,0,0,0,0,0,0,0,0,0,0
0,0,0,0,0,0,0,0,0,0,0,0,0,0
:endlayer
layer: 3
0,0,0,0,0,0,0,0,0,0,0,0,0,0
0,0,0,15,0,0,0,15,0,0,0,15,0,0
5,0,17,5,6,6,6,5,6,6,6,5,14,0
0,0,0,0,0,0,0,0,0,0,0,6,0,0
0,0,0,0,0,0,0,0,0,0,0,6,0,0
0,0,0,0,0,0,0,0,0,0,0,6,0,0
5,0,17,5,0,0,0,0,0,0,0,5,14,0
0,0,0,0,0,0,0,0,0,0,0,6,0,0
0,0,0,0,0,0,0,0,0,0,0,6,0,0
0,0,0,0,0,0,0,0,0,0,0,6,0,0
5,0,17,5,6,6,6,5,6,6,6,5,14,0
0,0,0,16,0,0,0,16,0,0,0,16,0,0
0,0,0,0,0,0,0,0,0,0,0,0,0,0
:endlayer
layer: 4
0,0,0,0,0,0,0,0,0,0,0,0,0,0
0,0,0,18,0,0,0,18,0,0,0,18,0,0
19,0,18,5,6,6,6,5,6,6,6,5,18,0
0,0,0,0,0,0,0,0,0,0,0,6,0,0
0,0,0,0,0,0,0,0,0,0,0,6,0,0
0,0,0,0,0,0,0,0,0,0,0,6,0,0
19,0,18,5,0,0,0,0,0,0,0,5,18,0
0,0,0,0,0,0,0,0,0,0,0,6,0,0
0,0,0,0,0,0,0,0,0,0,0,6,0,0
0,0,0,0,0,0,0,0,0,0,0,6,0,0
19,0,18,5,6,6,6,5,6,6,6,5,18,0
0,0,0,18,0,0,0,18,0,0,0,18,0,0
0,0,0,0,0,0,0,0,0,0,0,0,0,0
:endlayer
layer: 5
0,0,0,0,0,0,0,0,0,0,0,0,0,0
0,0,0,21,0,0,0,21,0,0,0,21,0,0
0,0,12,5,6,6,6,5,6,6,6,5,20,0
0,0,0,22,0,0,0,16,0,0,0,6,0,0
0,0,0,13,0,0,0,0,0,0,0,18,0,0
0,0,0,21,0,0,0,0,0,0,0,6,0,0
0,0,12,5,14,0,0,0,0,0,17,5,20,0
0,0,0,22,0,0,0,0,0,0,0,6,0,0
0,0,0,13,0,0,0,0,0,0,0,18,0,0
0,0,0,21,0,0,0,15,0,0,0,6,0,0
0,0,12,5,6,6,6,5,6,6,6,5,20,0
0,0,0,22,0,0,0,22,0,0,0,22,0,0
0,0,0,0,0,0,0,0,0,0,0,0,0,0
:endlayer
layer: 6
0,23,23,23,23,23,23,23,23,23,23,23,23,23
0,23,13,9,13,13,13,9,13,13,13,9,13,23
0,23,7,5,7,7,7,7,7,7,7,5,7,23
0,23,13,9,0,0,0,0,0,0,0,9,13,23
0,23,13,9,0,0,0,0,0,0,0,9,13,23
0,23,13,9,0,0,0,0,0,0,0,9,13,23
0,23,7,9,0,0,0,0,0,0,0,9,7,23
0,23,13,9,0,0,0,0,0,0,0,9,13,23
0,23,13,9,0,0,0,0,0,0,0,9,13,23
0,23,13,9,0,0,0,0,0,0,0,9,13,23
0,23,7,5,7,7,7,7,7,7,7,5,7,23
0,23,13,9,13,13,13,9,13,13,13,9,13,23
0,23,23,23,23,23,23,23,23,23,23,23,23,23
:endlayer
layer: 7
0,0,0,0,0,0,0,0,0,0,0,0,0,0
0,0,23,23,23,23,23,23,23,23,23,23,23,0
0,0,23,5,6,6,6,6,6,6,6,5,23,0
0,0,23,6,18,0,0,0,0,0,18,6,23,0
0,0,23,6,0,0,0,0,0,0,0,6,23,0
0,0,23,6,0,0,0,0,0,0,0,6,23,0
0,0,23,6,0,0,0,0,0,0,0,6,23,0
0,0,23,6,0,0,0,0,0,0,0,6,23,0
0,0,23,6,0,0,0,0,0,0,0,6,23,0
0,0,23,6,18,0,0,0,0,0,18,6,23,0
0,0,23,5,6,6,6,6,6,6,6,5,23,0
0,0,23,23,23,23,23,23,23,23,23,23,23,0
0,0,0,0,0,0,0,0,0,0,0,0,0,0
:endlayer
layer: 8
0,0,0,0,0,0,0,0,0,0,0,0,0,0
0,0,0,0,0,0,0,0,0,0,0,0,0,0
0,0,0,23,23,23,23,23,23,23,23,23,0,0
0,0,0,23,20,22,22,22,22,22,12,23,0,0
0,0,0,23,20,0,0,0,0,0,12,23,0,0
0,0,0,23,20,0,0,0,0,0,12,23,0,0
0,0,0,23,20,0,0,0,0,0,12,23,0,0
0,0,0,23,20,0,0,0,0,0,12,23,0,0
0,0,0,23,20,0,0,0,0,0,12,23,0,0
0,0,0,23,20,21,21,21,21,21,21,23,0,0
0,0,0,23,23,23,23,23,23,23,23,23,0,0
0,0,0,0,0,0,0,0,0,0,0,0,0,0
0,0,0,0,0,0,0,0,0,0,0,0,0,0
:endlayer
layer: 9
0,0,0,0,0,0,0,0,0,0,0,0,0,0
0,0,0,0,0,0,0,0,0,0,0,0,0,0
0,0,0,24,0,0,0,24,0,0,0,24,0,0
0,0,0,0,23,23,23,23,23,23,23,0,0,0
0,0,0,0,23,22,22,22,22,22,23,0,0,0
0,0,0,0,23,20,0,0,0,12,23,0,0,0
0,0,0,24,23,20,0,0,0,12,23,24,0,0
0,0,0,0,23,20,0,0,0,12,23,0,0,0
0,0,0,0,23,21,21,21,21,21,23,0,0,0
0,0,0,0,23,23,23,23,23,23,23,0,0,0
0,0,0,24,0,0,0,24,0,0,0,24,0,0
0,0,0,0,0,0,0,0,0,0,0,0,0,0
0,0,0,0,0,0,0,0,0,0,0,0,0,0
:endlayer
layer: 10
0,0,0,0,0,0,0,0,0,0,0,0,0,0
0,0,0,0,0,0,0,0,0,0,0,0,0,0
0,0,0,0,0,0,0,0,0,0,0,0,0,0
0,0,0,0,0,0,0,0,0,0,0,0,0,0
0,0,0,0,0,23,23,23,23,23,0,0,0,0
0,0,0,0,0,23,20,22,12,23,0,0,0,0
0,0,0,0,0,23,20,0,12,23,0,0,0,0
0,0,0,0,0,23,20,21,21,23,0,0,0,0
0,0,0,0,0,23,23,23,23,23,0,0,0,0
0,0,0,0,0,0,0,0,0,0,0,0,0,0
0,0,0,0,0,0,0,0,0,0,0,0,0,0
0,0,0,0,0,0,0,0,0,0,0,0,0,0
0,0,0,0,0,0,0,0,0,0,0,0,0,0
:endlayer
layer: 11
0,0,0,0,0,0,0,0,0,0,0,0,0,0
0,0,0,0,0,0,0,0,0,0,0,0,0,0
0,0,0,0,0,0,0,0,0,0,0,0,0,0
0,0,0,0,0,0,0,0,0,0,0,0,0,0
0,0,0,0,0,0,0,0,0,0,0,0,0,0
0,0,0,0,0,0,23,23,23,0,0,0,0,0
0,0,0,0,0,0,23,6,23,0,0,0,0,0
0,0,0,0,0,0,23,23,23,0,0,0,0,0
0,0,0,0,0,0,0,0,0,0,0,0,0,0
0,0,0,0,0,0,0,0,0,0,0,0,0,0
0,0,0,0,0,0,0,0,0,0,0,0,0,0
0,0,0,0,0,0,0,0,0,0,0,0,0,0
0,0,0,0,0,0,0,0,0,0,0,0,0,0
:endlayer
layer: 12
0,0,0,0,0,0,0,0,0,0,0,0,0,0
0,0,0,0,0,0,0,0,0,0,0,0,0,0
0,0,0,0,0,0,0,0,0,0,0,0,0,0
0,0,0,0,0,0,0,0,0,0,0,0,0,0
0,0,0,0,0,0,0,0,0,0,0,0,0,0
0,0,0,0,0,0,0,0,0,0,0,0,0,0
0,0,0,0,0,0,0,23,0,0,0,0,0,0
0,0,0,0,0,0,0,0,0,0,0,0,0,0
0,0,0,0,0,0,0,0,0,0,0,0,0,0
0,0,0,0,0,0,0,0,0,0,0,0,0,0
0,0,0,0,0,0,0,0,0,0,0,0,0,0
0,0,0,0,0,0,0,0,0,0,0,0,0,0
0,0,0,0,0,0,0,0,0,0,0,0,0,0
:endlayer
layer: 13
0,0,0,0,0,0,0,0,0,0,0,0,0,0
0,0,0,0,0,0,0,0,0,0,0,0,0,0
0,0,0,0,0,0,0,0,0,0,0,0,0,0
0,0,0,0,0,0,0,0,0,0,0,0,0,0
0,0,0,0,0,0,0,0,0,0,0,0,0,0
0,0,0,0,0,0,0,0,0,0,0,0,0,0
0,0,0,0,0,0,0,24,0,0,0,0,0,0
0,0,0,0,0,0,0,0,0,0,0,0,0,0
0,0,0,0,0,0,0,0,0,0,0,0,0,0
0,0,0,0,0,0,0,0,0,0,0,0,0,0
0,0,0,0,0,0,0,0,0,0,0,0,0,0
0,0,0,0,0,0,0,0,0,0,0,0,0,0
0,0,0,0,0,0,0,0,0,0,0,0,0,0
:endlayer

#### RULES ####
rule:
plugin=vanillaBlocks
number=1
data:
JSON:{blockState:{blockName:"minecraft:grass",properties:{snowy:"false"}}}
:enddata
:endrule

rule:
plugin=vanillaBlocks
number=2
data:
JSON:{blockState:{blockName:"minecraft:cobblestone"}}
:enddata
:endrule

rule:
plugin=vanillaBlocks
number=3
data:
JSON:{blockState:{blockName:"minecraft:dirt",properties:{variant:"dirt",snowy:"false"}}}
:enddata
:endrule

rule:
plugin=vanillaBlocks
number=4
data:
JSON:{blockState:{blockName:"minecraft:stonebrick",properties:{variant:"stonebrick"}}}
:enddata
:endrule

rule:
plugin=vanillaBlocks
number=5
data:
JSON:{blockState:{blockName:"biomesoplenty:log_0",properties:{variant:"umbran",axis:"y"}}}
:enddata
:endrule

rule:
plugin=vanillaBlocks
number=6
data:
JSON:{blockState:{blockName:"biomesoplenty:planks_0",properties:{variant:"umbran"}}}
:enddata
:endrule

rule:
plugin=vanillaBlocks
number=7
data:
JSON:{blockState:{blockName:"biomesoplenty:log_0",properties:{variant:"umbran",axis:"x"}}}
:enddata
:endrule

rule:
plugin=vanillaBlocks
number=8
data:
JSON:{blockState:{blockName:"biomesoplenty:umbran_stairs",properties:{half:"bottom",shape:"straight",facing:"north"}}}
:enddata
:endrule

rule:
plugin=vanillaBlocks
number=9
data:
JSON:{blockState:{blockName:"biomesoplenty:log_0",properties:{variant:"umbran",axis:"z"}}}
:enddata
:endrule

rule:
plugin=vanillaBlocks
number=10
data:
JSON:{blockState:{blockName:"minecraft:dirt",properties:{variant:"coarse_dirt",snowy:"false"}}}
:enddata
:endrule

rule:
plugin=vanillaBlocks
number=11
data:
JSON:{blockState:{blockName:"minecraft:gravel"}}
:enddata
:endrule

rule:
plugin=vanillaBlocks
number=12
data:
JSON:{blockState:{blockName:"biomesoplenty:umbran_stairs",properties:{half:"top",shape:"straight",facing:"east"}}}
:enddata
:endrule

rule:
plugin=vanillaBlocks
number=13
data:
JSON:{blockState:{blockName:"biomesoplenty:wood_slab_0",properties:{half:"top",variant:"umbran"}}}
:enddata
:endrule

rule:
plugin=vanillaBlocks
number=14
data:
JSON:{blockState:{blockName:"minecraft:torch",properties:{facing:"east"}}}
:enddata
:endrule

rule:
plugin=vanillaBlocks
number=15
data:
JSON:{blockState:{blockName:"minecraft:torch",properties:{facing:"north"}}}
:enddata
:endrule

rule:
plugin=vanillaBlocks
number=16
data:
JSON:{blockState:{blockName:"minecraft:torch",properties:{facing:"south"}}}
:enddata
:endrule

rule:
plugin=vanillaBlocks
number=17
data:
JSON:{blockState:{blockName:"minecraft:torch",properties:{facing:"west"}}}
:enddata
:endrule

rule:
plugin=vanillaBlocks
number=18
data:
JSON:{blockState:{blockName:"biomesoplenty:umbran_fence",properties:{east:"false",south:"false",north:"false",west:"false"}}}
:enddata
:endrule

rule:
plugin=vanillaBlocks
number=19
data:
JSON:{blockState:{blockName:"biomesoplenty:wood_slab_0",properties:{half:"bottom",variant:"umbran"}}}
:enddata
:endrule

rule:
plugin=vanillaBlocks
number=20
data:
JSON:{blockState:{blockName:"biomesoplenty:umbran_stairs",properties:{half:"top",shape:"straight",facing:"west"}}}
:enddata
:endrule

rule:
plugin=vanillaBlocks
number=21
data:
JSON:{blockState:{blockName:"biomesoplenty:umbran_stairs",properties:{half:"top",shape:"straight",facing:"south"}}}
:enddata
:endrule

rule:
plugin=vanillaBlocks
number=22
data:
JSON:{blockState:{blockName:"biomesoplenty:umbran_stairs",properties:{half:"top",shape:"straight",facing:"north"}}}
:enddata
:endrule

rule:
plugin=vanillaBlocks
number=23
data:
JSON:{blockState:{blockName:"minecraft:wool",properties:{color:"brown"}}}
:enddata
:endrule

rule:
plugin=vanillaBlocks
number=24
data:
JSON:{blockState:{blockName:"minecraft:torch",properties:{facing:"up"}}}
:enddata
:endrule

#### ENTITIES ####
