# Ancient Warfare Structure Template File
# Auto-generated structure template file. created on: 9/23/2023 at: 13:57:33
# Lines beginning with # denote comments

header:
version=2.11
name=SB_KievarusCol_Farm_1H1R_1_ethereal
mods=biomesoplenty
size=23,16,15
offset=13,1,14
:endheader

#### VALIDATION ####
validation:
type=ground
structureAuthor=TheOddlySeagull
survival=true
worldGenEnabled=false
unique=false
preserveBlocks=false
preventNaturalHostileSpawns=false
selectionWeight=1
clusterValue=1
minDuplicateDistance=1
dimensionWhiteList=true
dimensionList=
biomeGroupList=
biomeWhiteList=true
biomeList=
leveling=0
fill=0
border=0
blockSwap=false
territoryName=
biomeReplacement=minecraft:
minGenerationHeight=0
maxGenerationHeight=255
:endvalidation

#### LAYERS ####
layer: 0
1,1,1,1,1,1,1,1,1,1,1,1,1,1,1,1,1,1,1,1,1,1,1
1,1,2,1,1,1,1,1,1,1,1,2,1,1,1,1,1,1,1,1,2,1,1
1,2,2,2,2,2,2,2,2,2,2,2,2,2,2,2,2,2,2,2,2,2,1
1,1,2,6,6,6,3,6,6,6,6,2,1,1,2,1,3,2,1,3,2,1,1
1,1,2,3,6,6,3,3,3,6,3,2,1,1,2,3,1,2,3,3,2,1,1
1,1,2,3,6,6,3,6,6,3,6,2,3,1,2,3,1,2,1,3,2,1,1
1,1,2,3,3,3,3,6,6,6,6,2,2,2,2,2,2,2,2,2,2,1,1
1,1,2,6,3,6,3,3,6,3,6,2,4,4,4,2,4,2,4,2,2,1,1
1,1,2,6,3,3,3,6,3,3,6,2,2,4,2,4,2,2,4,2,2,1,1
1,1,2,6,3,3,6,6,6,3,6,2,4,2,4,2,2,2,4,4,2,1,1
1,2,2,2,2,2,2,2,2,2,2,2,2,2,2,2,2,2,2,2,2,2,1
1,1,2,1,1,1,1,1,1,1,1,2,1,1,1,1,1,1,1,1,2,1,1
1,1,1,1,1,1,1,1,1,1,1,1,1,1,1,1,1,1,1,1,1,1,1
1,1,1,1,1,1,1,1,1,1,1,2,2,2,2,2,2,1,1,1,1,1,1
1,1,1,1,1,1,1,1,1,1,1,5,2,2,2,2,5,1,1,1,1,1,1
:endlayer
layer: 1
0,0,0,0,0,0,0,0,0,0,0,0,0,0,0,0,0,0,0,0,0,0,0
0,0,7,0,0,0,0,0,0,0,0,7,0,0,0,0,0,0,0,0,7,0,0
0,7,7,8,7,0,0,0,0,7,8,7,0,0,7,0,0,7,0,0,7,7,0
0,0,8,0,0,0,0,0,0,0,0,8,0,0,8,0,0,8,0,0,8,0,0
0,0,8,0,0,0,0,0,0,0,0,8,0,0,8,0,0,8,0,0,8,0,0
0,0,8,0,0,0,0,0,0,0,12,8,0,0,8,0,0,8,0,0,8,0,0
0,0,7,0,0,0,0,0,0,7,13,7,8,8,7,8,8,7,8,8,7,0,0
0,0,8,0,0,0,0,0,0,0,0,8,4,4,4,4,4,4,2,4,8,0,0
0,0,8,0,0,0,0,0,0,0,0,8,2,4,4,4,4,4,4,2,8,0,0
0,0,8,0,0,0,0,0,0,0,0,8,2,4,2,4,2,4,2,2,8,0,0
0,7,7,8,8,7,8,8,7,8,8,7,8,8,7,8,8,7,8,8,7,7,0
0,0,7,0,0,0,0,0,0,0,0,7,0,0,0,0,0,0,0,0,7,0,0
0,0,9,0,0,0,0,0,0,0,0,0,10,10,10,10,0,0,0,0,9,0,0
0,0,0,0,0,0,0,0,0,0,0,7,11,11,11,11,7,0,0,0,0,0,0
0,0,0,0,0,0,14,0,0,0,0,0,0,0,0,0,0,0,0,0,0,0,0
:endlayer
layer: 2
0,0,0,0,0,0,0,0,0,0,0,0,0,0,0,0,0,0,0,0,0,0,0
0,0,7,0,0,0,0,0,0,0,0,7,0,0,0,0,0,0,0,0,7,0,0
0,7,7,17,7,0,0,0,0,7,17,7,0,0,7,0,0,7,0,0,7,7,0
0,0,16,0,19,0,0,0,0,19,0,16,0,0,16,0,0,16,0,0,16,0,0
0,0,16,15,0,0,0,0,0,0,0,16,15,0,16,15,0,16,15,0,16,0,0
0,0,16,0,0,0,0,0,0,0,0,16,0,0,16,0,0,16,0,0,16,0,0
0,0,16,0,0,0,0,0,0,7,12,16,17,17,17,17,17,17,17,17,16,0,0
0,0,16,0,0,0,0,0,0,20,13,16,8,8,8,8,8,8,8,8,16,0,0
0,0,16,15,0,0,0,0,0,20,18,16,8,8,8,8,8,8,8,8,16,0,0
0,0,16,0,0,21,0,0,21,20,18,16,8,8,8,8,8,8,8,8,16,0,0
0,7,7,17,17,17,17,17,17,17,17,17,17,17,17,17,17,17,17,17,7,7,0
0,0,7,18,18,18,18,18,18,18,18,7,8,8,8,8,16,18,18,18,7,0,0
0,22,17,17,17,17,17,17,17,17,17,16,11,11,11,11,16,17,17,17,17,15,0
0,0,0,0,0,0,0,0,0,0,0,7,0,0,0,0,7,0,0,0,0,0,0
0,0,0,0,0,0,0,0,0,0,0,19,0,0,0,0,19,0,0,0,0,0,0
:endlayer
layer: 3
0,0,0,0,0,0,0,0,0,0,0,0,0,0,0,0,0,0,0,0,0,0,0
0,0,7,15,0,0,0,0,0,0,22,7,15,0,0,0,0,0,0,22,7,0,0
0,7,7,8,7,0,0,0,0,7,8,7,0,0,7,0,0,7,0,0,7,7,0
0,19,8,0,0,0,0,0,0,0,0,9,0,0,9,0,0,9,0,0,8,19,0
0,0,7,0,0,0,0,0,0,0,0,9,0,0,9,0,0,9,0,0,8,0,0
0,0,8,0,0,0,0,0,0,0,0,9,0,0,9,0,0,9,0,0,8,0,0
0,0,8,0,0,0,0,0,0,9,0,7,9,9,7,9,9,7,9,9,7,0,0
0,0,8,0,0,0,0,0,0,9,0,0,0,0,0,0,0,0,0,0,8,0,0
0,0,7,0,0,0,0,0,0,9,0,0,0,0,0,0,0,0,0,0,8,0,0
0,21,8,0,0,0,0,0,0,9,0,0,0,0,0,24,23,0,0,0,8,21,0
0,7,7,8,8,8,8,8,8,8,8,7,8,0,0,8,7,8,8,8,7,7,0
0,0,7,0,0,0,20,25,0,0,0,7,0,0,0,0,0,0,0,0,7,0,0
0,0,9,0,0,0,0,0,0,0,0,0,0,0,0,0,0,0,0,0,9,0,0
0,0,0,0,0,0,0,0,0,0,0,9,0,0,0,0,9,0,0,0,0,0,0
0,0,0,0,0,0,0,0,0,0,0,0,0,0,0,0,0,0,0,0,0,0,0
:endlayer
layer: 4
0,0,0,0,0,0,0,0,0,0,0,0,0,0,0,0,0,0,0,0,0,0,0
0,0,7,0,0,0,0,0,0,0,0,7,0,0,0,0,0,0,0,0,7,0,0
0,7,7,8,7,23,18,18,20,7,8,7,23,20,7,23,20,7,10,20,7,7,0
0,0,8,0,0,0,0,0,0,0,0,0,0,0,0,0,0,0,0,0,8,0,0
0,0,7,0,0,0,0,0,0,0,0,0,0,0,0,0,0,0,0,0,8,0,0
0,0,8,0,0,0,0,0,0,0,0,0,0,0,0,0,0,0,0,0,8,0,0
0,0,9,0,0,0,0,0,0,0,0,7,0,0,7,0,0,7,0,0,7,0,0
0,0,8,0,0,0,0,0,0,0,0,0,0,0,0,0,0,0,0,0,8,0,0
0,0,7,0,0,0,0,0,0,0,0,0,0,0,0,0,0,0,0,0,9,0,0
0,0,8,0,0,0,0,0,0,0,0,0,0,0,0,0,24,23,0,0,8,0,0
0,7,7,8,8,8,8,8,8,8,8,7,8,0,0,8,7,8,8,8,7,7,0
0,0,7,0,0,20,25,0,0,0,0,7,0,0,0,0,0,0,0,0,7,0,0
0,0,9,0,0,0,0,0,0,0,0,0,0,0,0,0,0,0,0,0,9,0,0
0,0,0,0,0,0,0,0,0,0,0,9,0,0,0,0,9,0,0,0,0,0,0
0,0,0,0,0,0,0,0,0,0,0,0,0,0,0,0,0,0,0,0,0,0,0
:endlayer
layer: 5
0,0,0,0,0,0,0,0,0,0,0,0,0,0,0,0,0,0,0,0,0,0,0
0,0,7,0,0,0,0,0,0,0,0,7,0,0,0,0,0,0,0,0,7,0,0
0,7,7,8,7,8,8,8,8,7,8,7,8,8,7,8,8,7,8,8,7,7,0
0,0,8,0,0,0,0,0,0,0,0,13,0,0,0,0,0,0,0,0,8,0,0
0,0,7,0,0,0,0,0,0,0,0,18,0,0,0,0,0,0,0,0,8,0,0
0,0,8,0,0,0,0,0,0,0,0,10,0,0,0,0,0,0,0,0,8,0,0
0,0,8,0,0,0,0,0,0,0,0,7,18,18,7,18,18,7,18,18,7,0,0
0,0,8,0,0,0,0,0,0,0,0,13,0,0,19,0,0,19,0,0,8,0,0
0,0,7,0,0,0,0,0,0,0,0,18,0,0,0,0,0,0,0,0,8,0,0
0,0,8,0,0,0,0,0,0,0,0,10,0,0,0,0,0,24,23,0,8,0,0
0,7,7,8,8,8,8,8,8,8,8,7,8,8,8,8,7,8,8,8,7,7,0
0,0,7,15,20,25,0,0,0,0,22,7,15,0,0,0,26,0,0,22,7,0,0
0,0,9,0,0,0,0,0,0,0,0,26,0,0,0,0,26,0,0,0,9,0,0
0,0,0,0,0,0,0,0,0,0,0,26,0,0,0,0,26,0,0,0,0,0,0
0,0,0,0,0,0,0,0,0,0,0,0,0,0,0,0,0,0,0,0,0,0,0
:endlayer
layer: 6
0,0,0,0,0,0,0,0,0,0,0,0,0,0,0,0,0,0,0,0,0,0,0
0,0,7,0,0,0,0,0,0,0,0,7,0,0,0,0,0,0,0,0,7,0,0
0,7,7,17,17,17,17,17,17,17,17,17,17,17,17,17,17,17,17,17,7,7,0
0,0,16,8,18,8,18,8,18,8,18,16,8,18,8,18,8,18,8,18,16,0,0
0,0,16,8,18,8,18,8,18,8,18,16,8,18,8,18,8,18,8,18,16,0,0
0,0,16,8,18,8,18,8,18,8,18,16,8,18,8,18,8,18,8,18,16,0,0
0,0,16,8,18,8,18,8,18,8,18,16,17,17,17,17,17,17,17,17,16,0,0
0,0,16,8,18,8,18,8,18,8,18,16,8,18,8,18,8,18,8,18,16,0,0
0,0,16,8,18,8,18,8,18,8,18,16,8,18,23,13,13,13,8,18,16,0,0
0,0,16,8,18,8,18,8,18,8,18,16,8,18,23,0,0,0,24,23,16,0,0
0,7,7,17,17,17,17,17,17,17,17,17,17,17,17,17,17,17,17,17,7,7,0
0,0,7,20,25,0,0,0,18,18,18,7,18,18,18,18,18,18,18,18,7,0,0
0,0,17,17,17,17,17,17,17,17,17,17,17,17,17,17,17,17,17,17,17,0,0
0,0,0,0,0,0,0,0,0,0,0,0,26,26,26,26,0,0,0,0,0,0,0
0,0,0,0,0,0,0,0,0,0,0,0,0,0,0,0,0,0,0,0,0,0,0
:endlayer
layer: 7
0,0,0,0,0,0,0,0,0,0,0,0,0,0,0,0,0,0,0,0,0,0,0
0,0,7,0,0,0,0,0,0,0,0,7,0,0,0,0,0,0,0,0,7,0,0
0,7,7,8,7,8,8,8,8,7,8,7,8,7,8,8,8,8,7,8,7,7,0
0,0,8,0,0,0,0,0,0,0,0,8,0,0,0,0,0,0,0,0,8,0,0
0,0,7,12,0,0,0,0,0,0,0,8,0,0,0,0,0,0,0,0,7,0,0
0,0,8,13,0,0,0,0,0,0,0,8,0,0,0,0,0,0,0,0,8,0,0
0,0,9,0,0,0,0,0,0,0,0,7,0,0,0,7,8,8,8,8,7,0,0
0,0,8,0,0,0,0,0,0,0,0,8,0,0,0,0,0,20,25,0,8,0,0
0,0,7,0,0,0,0,0,0,0,0,8,0,0,0,0,0,0,0,0,7,0,0
0,0,8,0,0,0,0,0,0,0,0,8,0,0,0,0,0,0,0,0,8,0,0
0,7,7,8,8,8,8,8,0,0,8,7,8,0,8,7,8,8,8,8,7,7,0
0,0,7,0,0,0,0,0,0,0,0,7,0,0,0,0,0,0,0,0,7,0,0
0,0,9,0,0,0,0,0,0,0,0,0,0,0,0,0,0,0,0,0,9,0,0
0,0,0,0,0,0,0,0,0,0,0,0,0,0,0,0,0,0,0,0,0,0,0
0,0,0,0,0,0,0,0,0,0,0,0,0,0,0,0,0,0,0,0,0,0,0
:endlayer
layer: 8
0,0,0,0,0,0,0,0,0,0,0,0,0,0,0,0,0,0,0,0,0,0,0
0,0,7,0,0,0,0,0,0,0,0,7,0,0,0,0,0,0,0,0,7,0,0
0,7,7,8,7,8,8,8,8,7,8,7,8,7,8,9,9,8,7,8,7,7,0
0,13,8,0,0,0,0,0,0,0,0,8,0,0,0,0,0,0,0,0,8,13,0
0,0,7,0,0,0,0,0,0,0,0,8,0,0,0,0,0,0,0,0,7,0,0
0,0,8,12,0,0,0,0,0,0,0,8,0,0,0,0,0,0,0,0,8,0,0
0,0,8,13,0,0,0,0,0,0,0,7,0,0,0,7,8,8,8,8,7,0,0
0,0,8,0,0,0,0,0,0,0,0,8,0,0,0,0,20,25,0,0,8,0,0
0,0,7,0,0,0,0,0,0,0,0,8,0,0,0,0,0,0,0,0,7,0,0
0,10,8,0,0,0,0,0,0,0,0,8,0,0,0,0,0,0,0,0,8,10,0
0,7,7,8,8,8,8,8,0,0,8,7,8,0,8,7,8,9,9,8,7,7,0
0,0,7,0,0,0,0,0,0,0,0,7,0,0,0,19,0,0,0,0,7,0,0
0,0,9,0,0,0,0,0,0,0,0,0,0,0,0,0,0,0,0,0,9,0,0
0,0,0,0,0,0,0,0,0,0,0,0,0,0,0,0,0,0,0,0,0,0,0
0,0,0,0,0,0,0,0,0,0,0,0,0,0,0,0,0,0,0,0,0,0,0
:endlayer
layer: 9
26,26,26,26,26,26,26,26,26,26,26,26,26,26,26,26,26,26,26,26,26,26,26
0,0,7,0,10,0,0,0,0,10,0,7,0,10,0,0,0,0,10,0,7,0,0
0,7,7,8,7,8,8,8,8,7,8,7,8,7,8,8,8,8,7,8,7,7,0
0,8,8,0,19,0,0,0,0,19,0,8,0,19,0,0,0,0,19,0,8,8,0
0,18,7,15,0,0,0,0,0,0,0,8,0,0,0,0,0,0,0,22,7,18,0
0,18,8,0,0,0,0,0,0,0,0,8,0,0,0,21,0,0,0,0,8,18,0
0,0,8,12,0,0,0,0,0,0,22,7,23,18,20,7,8,8,8,8,7,0,0
0,18,8,13,0,0,0,0,0,0,0,8,0,0,0,20,25,0,0,0,8,18,0
0,18,7,15,0,0,0,0,0,0,0,8,15,0,0,0,0,0,0,22,7,18,0
0,8,8,0,0,0,21,0,0,0,0,8,0,0,0,21,0,0,0,0,8,8,0
0,7,7,8,8,8,8,8,8,8,8,7,8,8,8,7,8,8,8,8,7,7,0
0,0,7,15,0,0,0,0,0,0,22,7,15,0,0,13,0,0,0,22,7,0,0
26,26,26,26,26,26,26,26,26,26,26,26,26,26,26,26,26,26,26,26,26,26,26
0,0,0,0,0,0,0,0,0,0,0,0,0,0,0,0,0,0,0,0,0,0,0
0,0,0,0,0,0,0,0,0,0,0,0,0,0,0,0,0,0,0,0,0,0,0
:endlayer
layer: 10
0,0,0,0,0,0,0,0,0,0,0,0,0,0,0,0,0,0,0,0,0,0,0
26,26,26,26,26,26,26,26,26,26,26,26,26,26,26,26,26,26,26,26,26,26,26
0,7,7,17,17,17,17,17,17,17,17,17,17,17,17,17,17,17,17,17,7,7,0
0,16,16,0,8,18,18,18,18,18,18,16,18,8,18,8,18,8,18,8,16,16,0
0,16,16,0,8,8,8,8,8,8,8,16,18,8,18,8,18,8,18,8,16,16,0
0,16,16,0,8,18,18,18,18,18,18,16,18,8,18,8,18,8,18,8,16,16,0
0,16,16,0,8,8,8,8,8,8,8,16,17,17,17,17,17,17,17,17,16,16,0
0,16,16,12,8,18,18,18,18,18,18,16,18,8,20,25,0,0,0,8,16,16,0
0,16,16,13,8,8,8,8,8,8,8,16,18,8,18,8,10,10,10,8,16,16,0
0,16,16,18,8,18,18,18,18,18,18,16,18,8,18,8,18,8,18,8,16,16,0
0,7,7,17,17,17,17,17,17,17,17,17,17,17,17,17,17,17,17,17,7,7,0
26,26,26,26,26,26,26,26,26,26,26,26,26,26,26,26,26,26,26,26,26,26,26
0,0,0,0,0,0,0,0,0,0,0,0,0,0,0,0,0,0,0,0,0,0,0
0,0,0,0,0,0,0,0,0,0,0,0,0,0,0,0,0,0,0,0,0,0,0
0,0,0,0,0,0,0,0,0,0,0,0,0,0,0,0,0,0,0,0,0,0,0
:endlayer
layer: 11
0,0,0,0,0,0,0,0,0,0,0,0,0,0,0,0,0,0,0,0,0,0,0
0,0,0,0,0,0,0,0,0,0,0,14,0,0,0,0,0,0,0,0,0,0,0
26,26,26,26,26,26,26,26,26,26,26,26,26,26,26,26,26,26,26,26,26,26,26
0,13,8,0,0,0,0,0,0,0,0,8,0,0,0,0,0,0,0,0,8,13,0
0,22,8,0,0,0,0,0,0,0,0,8,0,0,0,0,0,0,0,0,8,15,0
0,0,8,0,0,0,0,0,0,0,0,7,0,0,0,0,0,0,0,0,8,0,0
0,0,8,0,0,0,0,14,0,0,0,8,0,0,0,14,0,0,0,0,8,0,0
0,0,8,0,0,0,0,0,0,0,0,7,0,0,0,0,0,0,0,0,8,0,0
0,22,8,0,0,0,0,0,0,0,0,8,0,0,0,0,0,0,0,0,8,15,0
0,10,8,0,0,0,0,0,0,0,0,8,0,0,0,0,0,0,0,0,8,10,0
26,26,26,26,26,26,26,26,26,26,26,26,26,26,26,26,26,26,26,26,26,26,26
0,0,0,0,0,0,0,0,0,0,0,14,0,0,0,0,0,0,0,0,0,0,0
0,0,0,0,0,0,0,0,0,0,0,0,0,0,0,0,0,0,0,0,0,0,0
0,0,0,0,0,0,0,0,0,0,0,0,0,0,0,0,0,0,0,0,0,0,0
0,0,0,0,0,0,0,0,0,0,0,0,0,0,0,0,0,0,0,0,0,0,0
:endlayer
layer: 12
0,0,0,0,0,0,0,0,0,0,0,0,0,0,0,0,0,0,0,0,0,0,0
0,0,0,0,0,0,0,0,0,0,0,0,0,0,0,0,0,0,0,0,0,0,0
0,0,14,0,0,0,0,14,0,0,0,0,0,0,0,14,0,0,0,0,14,0,0
26,26,26,26,26,26,26,26,26,26,26,26,26,26,26,26,26,26,26,26,26,26,26
0,13,8,0,0,0,0,0,0,0,0,8,0,0,0,0,0,0,0,0,8,13,0
0,0,8,0,0,0,0,0,0,0,0,7,0,0,0,0,0,0,0,0,8,0,0
0,0,9,0,0,0,0,0,0,0,0,8,0,0,0,0,0,0,0,0,9,0,0
0,0,8,0,0,0,0,0,0,0,0,7,0,0,0,0,0,0,0,0,8,0,0
0,10,8,0,0,0,0,0,0,0,0,8,0,0,0,0,0,0,0,0,8,10,0
26,26,26,26,26,26,26,26,26,26,26,26,26,26,26,26,26,26,26,26,26,26,26
0,0,14,0,0,0,0,14,0,0,0,0,0,0,0,14,0,0,0,0,14,0,0
0,0,0,0,0,0,0,0,0,0,0,0,0,0,0,0,0,0,0,0,0,0,0
0,0,0,0,0,0,0,0,0,0,0,0,0,0,0,0,0,0,0,0,0,0,0
0,0,0,0,0,0,0,0,0,0,0,0,0,0,0,0,0,0,0,0,0,0,0
0,0,0,0,0,0,0,0,0,0,0,0,0,0,0,0,0,0,0,0,0,0,0
:endlayer
layer: 13
0,0,0,0,0,0,0,0,0,0,0,0,0,0,0,0,0,0,0,0,0,0,0
0,0,0,0,0,0,0,0,0,0,0,0,0,0,0,0,0,0,0,0,0,0,0
0,0,0,0,0,0,0,0,0,0,0,0,0,0,0,0,0,0,0,0,0,0,0
0,0,0,0,0,0,0,0,0,0,0,0,0,0,0,0,0,0,0,0,0,0,0
26,26,26,26,26,26,26,26,26,26,26,26,26,26,26,26,26,26,26,26,26,26,26
0,13,8,0,0,0,0,0,0,0,0,7,0,0,0,0,0,0,0,0,8,13,0
0,0,8,15,0,0,0,0,0,0,22,8,15,0,0,0,0,0,0,22,8,0,0
0,10,8,0,0,0,0,0,0,0,0,7,0,0,0,0,0,0,0,0,8,10,0
26,26,26,26,26,26,26,26,26,26,26,26,26,26,26,26,26,26,26,26,26,26,26
0,0,0,0,0,0,0,0,0,0,0,0,0,0,0,0,0,0,0,0,0,0,0
0,0,0,0,0,0,0,0,0,0,0,0,0,0,0,0,0,0,0,0,0,0,0
0,0,0,0,0,0,0,0,0,0,0,0,0,0,0,0,0,0,0,0,0,0,0
0,0,0,0,0,0,0,0,0,0,0,0,0,0,0,0,0,0,0,0,0,0,0
0,0,0,0,0,0,0,0,0,0,0,0,0,0,0,0,0,0,0,0,0,0,0
0,0,0,0,0,0,0,0,0,0,0,0,0,0,0,0,0,0,0,0,0,0,0
:endlayer
layer: 14
0,0,0,0,0,0,0,0,0,0,0,0,0,0,0,0,0,0,0,0,0,0,0
0,0,0,0,0,0,0,0,0,0,0,0,0,0,0,0,0,0,0,0,0,0,0
0,0,0,0,0,0,0,0,0,0,0,0,0,0,0,0,0,0,0,0,0,0,0
0,0,0,0,0,0,0,0,0,0,0,0,0,0,0,0,0,0,0,0,0,0,0
0,0,0,0,0,0,0,0,0,0,0,14,0,0,0,0,0,0,0,0,0,0,0
26,26,26,26,26,26,26,26,26,26,26,26,26,26,26,26,26,26,26,26,26,26,26
0,20,8,0,0,0,0,0,0,0,0,8,0,0,0,0,0,0,0,0,8,23,0
26,26,26,26,26,26,26,26,26,26,26,26,26,26,26,26,26,26,26,26,26,26,26
0,0,0,0,0,0,0,0,0,0,0,14,0,0,0,0,0,0,0,0,0,0,0
0,0,0,0,0,0,0,0,0,0,0,0,0,0,0,0,0,0,0,0,0,0,0
0,0,0,0,0,0,0,0,0,0,0,0,0,0,0,0,0,0,0,0,0,0,0
0,0,0,0,0,0,0,0,0,0,0,0,0,0,0,0,0,0,0,0,0,0,0
0,0,0,0,0,0,0,0,0,0,0,0,0,0,0,0,0,0,0,0,0,0,0
0,0,0,0,0,0,0,0,0,0,0,0,0,0,0,0,0,0,0,0,0,0,0
0,0,0,0,0,0,0,0,0,0,0,0,0,0,0,0,0,0,0,0,0,0,0
:endlayer
layer: 15
0,0,0,0,0,0,0,0,0,0,0,0,0,0,0,0,0,0,0,0,0,0,0
0,0,0,0,0,0,0,0,0,0,0,0,0,0,0,0,0,0,0,0,0,0,0
0,0,0,0,0,0,0,0,0,0,0,0,0,0,0,0,0,0,0,0,0,0,0
0,0,0,0,0,0,0,0,0,0,0,0,0,0,0,0,0,0,0,0,0,0,0
0,0,0,0,0,0,0,0,0,0,0,0,0,0,0,0,0,0,0,0,0,0,0
0,0,14,0,0,0,0,14,0,0,0,0,0,0,0,14,0,0,0,0,14,0,0
26,26,26,26,26,26,26,26,26,26,26,26,26,26,26,26,26,26,26,26,26,26,26
0,0,14,0,0,0,0,14,0,0,0,0,0,0,0,14,0,0,0,0,14,0,0
0,0,0,0,0,0,0,0,0,0,0,0,0,0,0,0,0,0,0,0,0,0,0
0,0,0,0,0,0,0,0,0,0,0,0,0,0,0,0,0,0,0,0,0,0,0
0,0,0,0,0,0,0,0,0,0,0,0,0,0,0,0,0,0,0,0,0,0,0
0,0,0,0,0,0,0,0,0,0,0,0,0,0,0,0,0,0,0,0,0,0,0
0,0,0,0,0,0,0,0,0,0,0,0,0,0,0,0,0,0,0,0,0,0,0
0,0,0,0,0,0,0,0,0,0,0,0,0,0,0,0,0,0,0,0,0,0,0
0,0,0,0,0,0,0,0,0,0,0,0,0,0,0,0,0,0,0,0,0,0,0
:endlayer

#### RULES ####
rule:
plugin=vanillaBlocks
number=1
data:
JSON:{blockState:{blockName:"minecraft:grass",properties:{snowy:"false"}}}
:enddata
:endrule

rule:
plugin=vanillaBlocks
number=2
data:
JSON:{blockState:{blockName:"minecraft:cobblestone"}}
:enddata
:endrule

rule:
plugin=vanillaBlocks
number=3
data:
JSON:{blockState:{blockName:"minecraft:dirt",properties:{variant:"coarse_dirt",snowy:"false"}}}
:enddata
:endrule

rule:
plugin=vanillaBlocks
number=4
data:
JSON:{blockState:{blockName:"minecraft:dirt",properties:{variant:"dirt",snowy:"false"}}}
:enddata
:endrule

rule:
plugin=vanillaBlocks
number=5
data:
JSON:{blockState:{blockName:"minecraft:stonebrick",properties:{variant:"stonebrick"}}}
:enddata
:endrule

rule:
plugin=vanillaBlocks
number=6
data:
JSON:{blockState:{blockName:"minecraft:gravel"}}
:enddata
:endrule

rule:
plugin=vanillaBlocks
number=7
data:
JSON:{blockState:{blockName:"biomesoplenty:log_1",properties:{variant:"ethereal",axis:"y"}}}
:enddata
:endrule

rule:
plugin=vanillaBlocks
number=8
data:
JSON:{blockState:{blockName:"biomesoplenty:planks_0",properties:{variant:"ethereal"}}}
:enddata
:endrule

rule:
plugin=vanillaBlocks
number=9
data:
JSON:{blockState:{blockName:"biomesoplenty:ethereal_fence",properties:{east:"false",south:"false",north:"false",west:"false"}}}
:enddata
:endrule

rule:
plugin=vanillaBlocks
number=10
data:
JSON:{blockState:{blockName:"biomesoplenty:ethereal_stairs",properties:{half:"top",shape:"straight",facing:"south"}}}
:enddata
:endrule

rule:
plugin=vanillaBlocks
number=11
data:
JSON:{blockState:{blockName:"biomesoplenty:ethereal_stairs",properties:{half:"bottom",shape:"straight",facing:"north"}}}
:enddata
:endrule

rule:
plugin=vanillaBlocks
number=12
data:
JSON:{blockState:{blockName:"biomesoplenty:ethereal_stairs",properties:{half:"bottom",shape:"straight",facing:"south"}}}
:enddata
:endrule

rule:
plugin=vanillaBlocks
number=13
data:
JSON:{blockState:{blockName:"biomesoplenty:ethereal_stairs",properties:{half:"top",shape:"straight",facing:"north"}}}
:enddata
:endrule

rule:
plugin=vanillaBlocks
number=14
data:
JSON:{blockState:{blockName:"minecraft:torch",properties:{facing:"up"}}}
:enddata
:endrule

rule:
plugin=vanillaBlocks
number=15
data:
JSON:{blockState:{blockName:"minecraft:torch",properties:{facing:"east"}}}
:enddata
:endrule

rule:
plugin=vanillaBlocks
number=16
data:
JSON:{blockState:{blockName:"biomesoplenty:log_1",properties:{variant:"ethereal",axis:"z"}}}
:enddata
:endrule

rule:
plugin=vanillaBlocks
number=17
data:
JSON:{blockState:{blockName:"biomesoplenty:log_1",properties:{variant:"ethereal",axis:"x"}}}
:enddata
:endrule

rule:
plugin=vanillaBlocks
number=18
data:
JSON:{blockState:{blockName:"biomesoplenty:wood_slab_0",properties:{half:"top",variant:"ethereal"}}}
:enddata
:endrule

rule:
plugin=vanillaBlocks
number=19
data:
JSON:{blockState:{blockName:"minecraft:torch",properties:{facing:"south"}}}
:enddata
:endrule

rule:
plugin=vanillaBlocks
number=20
data:
JSON:{blockState:{blockName:"biomesoplenty:ethereal_stairs",properties:{half:"top",shape:"straight",facing:"east"}}}
:enddata
:endrule

rule:
plugin=vanillaBlocks
number=21
data:
JSON:{blockState:{blockName:"minecraft:torch",properties:{facing:"north"}}}
:enddata
:endrule

rule:
plugin=vanillaBlocks
number=22
data:
JSON:{blockState:{blockName:"minecraft:torch",properties:{facing:"west"}}}
:enddata
:endrule

rule:
plugin=vanillaBlocks
number=23
data:
JSON:{blockState:{blockName:"biomesoplenty:ethereal_stairs",properties:{half:"top",shape:"straight",facing:"west"}}}
:enddata
:endrule

rule:
plugin=vanillaBlocks
number=24
data:
JSON:{blockState:{blockName:"biomesoplenty:ethereal_stairs",properties:{half:"bottom",shape:"straight",facing:"east"}}}
:enddata
:endrule

rule:
plugin=vanillaBlocks
number=25
data:
JSON:{blockState:{blockName:"biomesoplenty:ethereal_stairs",properties:{half:"bottom",shape:"straight",facing:"west"}}}
:enddata
:endrule

rule:
plugin=vanillaBlocks
number=26
data:
JSON:{blockState:{blockName:"minecraft:wool",properties:{color:"brown"}}}
:enddata
:endrule

#### ENTITIES ####
