# Ancient Warfare Structure Template File
# Auto-generated structure template file. created on: 1/9/2024 at: 13:18:2
# Lines beginning with # denote comments

header:
version=2.11
name=SB_DarokCol_House_1H3R_1
mods=
size=17,17,13
offset=6,1,10
:endheader

#### VALIDATION ####
validation:
type=ground
structureAuthor=TheOddlySeagull
survival=true
worldGenEnabled=false
unique=false
preserveBlocks=false
preventNaturalHostileSpawns=true
selectionWeight=1
clusterValue=1
minDuplicateDistance=1
dimensionWhiteList=true
dimensionList=
biomeGroupList=
biomeWhiteList=true
biomeList=
leveling=10
fill=10
border=5
blockSwap=false
territoryName=
biomeReplacement=minecraft:
minGenerationHeight=0
maxGenerationHeight=255
:endvalidation

#### LAYERS ####
layer: 0
1,1,1,1,1,1,1,1,1,1,1,1,1,1,1,1,1
1,1,1,1,2,3,3,3,3,3,3,3,3,3,3,2,1
1,1,1,1,4,5,5,5,5,5,5,5,5,5,5,4,1
1,1,1,1,4,5,5,5,5,5,5,5,5,5,5,4,1
1,1,1,1,4,5,5,5,5,5,5,5,5,5,5,4,1
1,1,1,1,4,5,5,5,5,5,5,5,5,5,5,4,1
1,1,1,1,4,5,5,5,5,5,5,5,5,5,5,4,1
1,1,1,1,4,5,5,5,5,5,5,5,5,5,5,4,1
1,1,1,1,2,3,3,3,3,3,3,3,3,3,3,2,1
1,1,1,1,1,1,1,1,1,1,1,1,1,1,1,1,1
1,1,1,1,1,1,1,1,1,1,1,1,1,1,1,1,1
1,1,1,1,1,1,1,1,1,1,1,1,1,1,1,1,1
1,1,1,1,1,1,1,1,1,1,1,1,1,1,1,1,1
:endlayer
layer: 1
0,0,0,0,0,0,0,0,0,0,0,0,0,0,0,0,0
0,0,0,0,2,7,7,7,7,7,7,7,7,7,7,2,0
0,0,0,0,7,0,0,0,0,0,0,0,11,10,0,7,0
0,0,0,0,9,0,0,0,0,0,0,0,0,0,0,7,0
0,0,0,0,7,0,0,0,0,0,0,0,0,0,0,7,0
0,0,0,0,7,0,0,0,0,0,0,0,0,0,0,7,0
0,0,0,0,7,0,0,0,0,0,0,0,0,0,0,7,0
0,0,0,0,7,0,0,0,0,0,0,0,0,0,0,7,0
0,0,0,0,2,7,8,7,7,7,7,7,7,7,7,2,0
0,0,0,0,0,0,0,0,0,0,0,0,0,0,0,0,0
0,0,0,0,0,0,0,0,0,0,0,0,0,0,0,0,0
0,6,0,0,0,0,0,0,0,6,0,0,0,0,0,0,0
0,0,0,0,0,0,0,0,0,0,0,0,0,0,0,0,0
:endlayer
layer: 2
0,0,0,0,0,0,0,0,0,0,0,0,0,0,0,0,0
0,0,0,0,2,7,7,7,7,7,7,7,7,7,7,2,0
0,0,0,0,7,0,17,0,0,0,0,11,10,0,16,7,0
0,0,0,0,13,0,0,0,0,0,0,0,0,0,0,7,0
0,0,0,0,7,15,0,0,0,0,0,0,0,0,0,7,0
0,0,0,0,12,0,0,0,0,0,0,0,0,0,0,7,0
0,0,0,0,12,0,0,0,0,0,0,0,0,0,0,7,0
0,0,0,0,7,15,0,14,0,0,14,14,0,0,14,7,0
0,0,0,0,2,7,13,7,12,12,7,7,12,12,7,2,0
0,0,0,0,0,0,0,0,0,0,0,0,0,0,0,0,0
0,0,0,0,0,0,0,0,0,0,0,0,0,0,0,0,0
0,0,0,0,0,0,0,0,0,0,0,0,0,0,0,0,0
0,0,0,0,0,0,0,0,0,0,0,0,0,0,0,0,0
:endlayer
layer: 3
0,0,0,0,14,0,0,0,14,0,0,14,0,0,0,14,0
0,0,0,16,2,7,7,7,7,7,7,7,7,7,7,2,15
0,0,0,0,7,0,0,0,0,0,11,10,0,0,0,7,0
0,0,0,0,7,0,0,0,0,0,0,0,0,0,0,7,0
0,0,0,0,7,0,0,0,0,0,0,0,0,0,0,7,0
0,0,0,0,7,0,0,0,0,0,0,0,0,0,0,7,0
0,0,0,0,7,0,0,0,0,0,0,0,0,0,0,7,0
0,0,0,0,7,0,0,0,0,0,0,0,0,0,0,7,0
0,0,0,16,2,7,7,7,7,7,7,7,7,7,7,2,15
0,0,0,18,17,0,0,0,0,0,0,0,0,0,0,17,0
0,0,0,0,0,0,0,0,0,0,0,0,0,0,0,0,0
0,0,0,0,0,0,0,0,0,0,0,0,0,0,0,0,0
0,0,0,0,0,0,0,0,0,0,0,0,0,0,0,0,0
:endlayer
layer: 4
0,0,0,0,0,0,0,0,0,0,0,0,0,0,0,0,0
0,0,26,3,3,3,3,3,3,3,3,3,3,3,3,2,0
0,0,0,21,4,24,5,24,5,11,10,0,0,0,0,4,0
0,0,0,18,4,24,5,24,5,24,5,25,25,25,25,4,0
0,0,0,21,4,24,5,24,5,24,5,24,5,24,5,4,0
0,0,0,18,4,24,5,24,5,24,5,24,5,24,5,4,0
0,0,0,21,4,24,5,24,5,24,5,24,5,24,5,4,0
0,0,0,18,4,24,5,24,5,24,5,24,5,24,5,4,0
0,0,21,23,2,3,3,3,3,3,3,3,3,3,3,4,0
0,0,21,2,22,18,20,18,20,18,20,18,20,18,20,4,0
0,0,21,20,20,0,0,0,18,18,18,18,0,0,0,19,0
0,0,0,0,0,0,0,0,0,0,0,0,0,0,0,0,0
0,0,0,0,0,0,0,0,0,0,0,0,0,0,0,0,0
:endlayer
layer: 5
0,0,0,0,0,0,0,0,0,0,0,0,0,0,0,0,0
0,0,0,2,27,2,27,27,2,27,27,2,27,27,2,2,0
0,0,0,27,0,0,0,0,27,0,0,0,0,0,0,27,0
0,0,0,2,0,0,0,0,0,0,0,12,12,12,12,27,0
0,0,0,27,0,0,0,0,27,0,0,0,0,0,0,27,0
0,0,0,2,27,2,27,27,2,0,0,0,0,0,0,2,0
0,0,0,27,0,0,0,0,27,0,0,0,0,0,25,27,0
0,0,0,2,0,0,0,0,0,0,0,0,0,0,29,27,0
0,0,2,0,0,0,0,0,27,0,0,0,0,0,0,27,0
0,0,27,28,2,27,27,27,2,27,27,2,27,27,27,2,0
0,0,2,27,2,0,0,0,12,12,12,12,0,0,0,0,0
0,0,0,0,0,0,0,0,0,0,0,0,0,0,0,0,0
0,0,0,0,0,0,0,0,0,0,0,0,0,0,0,0,0
:endlayer
layer: 6
0,0,0,0,0,0,0,0,0,0,0,0,0,0,0,0,0
0,0,0,2,27,2,27,27,2,27,27,2,27,27,2,2,0
0,0,0,12,0,0,0,0,27,0,0,0,0,0,0,27,0
0,0,0,2,0,0,0,0,0,0,0,0,0,0,0,27,0
0,0,0,12,0,0,0,0,27,0,0,0,0,0,0,27,0
0,0,0,2,27,2,27,27,2,0,0,0,0,0,25,2,0
0,0,0,12,0,0,0,0,27,0,0,0,0,0,29,27,0
0,0,0,2,0,0,0,0,0,0,0,0,0,0,0,27,0
0,0,2,0,0,0,0,0,27,0,0,0,0,0,0,27,0
0,0,12,28,2,27,12,27,2,12,12,2,27,12,27,2,0
0,0,2,12,2,0,0,0,0,0,0,0,0,0,0,0,0
0,0,0,0,0,0,0,0,0,0,0,0,0,0,0,0,0
0,0,0,0,0,0,0,0,0,0,0,0,0,0,0,0,0
:endlayer
layer: 7
0,0,0,23,0,0,0,0,0,0,0,0,0,0,0,23,0
0,0,0,2,27,2,27,27,2,27,27,2,27,27,2,2,0
0,0,0,12,0,17,0,0,27,0,0,17,0,0,17,27,0
0,0,0,2,15,0,0,0,27,0,0,0,0,0,0,27,0
0,0,0,12,0,14,0,0,27,0,0,0,0,0,25,27,0
0,0,0,2,27,2,27,27,2,15,0,0,0,0,29,2,0
0,0,0,12,0,17,0,0,27,0,0,0,0,0,0,27,0
0,0,0,2,15,0,0,0,27,0,0,0,0,0,0,27,0
0,0,2,0,14,0,0,0,27,0,0,14,0,0,0,27,0
0,0,12,28,2,27,12,27,2,12,12,2,27,12,27,2,0
0,0,2,12,2,0,0,0,0,0,0,0,0,0,0,20,0
0,0,0,0,0,0,0,0,0,0,0,0,0,0,0,0,0
0,0,0,0,0,0,0,0,0,0,0,0,0,0,0,0,0
:endlayer
layer: 8
0,0,31,31,31,31,31,31,31,31,31,31,31,31,31,31,31
0,0,20,2,3,3,3,3,3,3,3,3,3,3,3,2,20
0,0,0,4,24,5,24,5,4,5,24,5,24,5,24,4,0
0,0,0,4,24,5,24,5,4,5,24,5,24,5,25,4,0
0,0,0,4,24,5,24,5,4,5,24,5,24,5,29,4,0
0,0,0,4,3,3,3,3,4,5,24,5,24,5,0,4,0
0,0,0,4,24,5,24,5,4,5,24,5,24,5,0,4,0
0,0,0,4,24,5,24,5,4,5,24,5,24,5,0,4,0
0,0,2,3,2,5,24,5,4,5,24,5,24,5,0,4,0
0,0,4,28,2,3,3,3,3,3,3,3,3,3,3,2,23
0,0,2,3,2,30,30,30,30,30,30,30,30,30,30,30,30
0,0,0,0,0,0,0,0,0,0,0,0,0,0,0,0,0
0,0,0,0,0,0,0,0,0,0,0,0,0,0,0,0,0
:endlayer
layer: 9
0,0,0,0,0,0,0,0,0,0,0,0,0,0,0,0,0
0,0,31,31,31,31,31,31,31,31,31,31,31,31,31,31,31
0,0,20,2,3,3,3,3,3,3,3,3,3,3,3,2,20
0,0,0,27,0,0,0,0,0,0,0,0,0,0,0,27,0
0,0,0,27,0,0,0,0,0,0,0,0,0,0,0,27,0
0,0,0,27,0,0,0,0,0,0,0,0,0,12,0,27,0
0,0,0,27,0,0,0,0,0,0,0,0,0,12,0,27,0
0,0,0,27,0,0,0,0,0,0,0,0,0,12,0,27,0
0,0,2,2,2,3,3,3,3,3,3,3,3,3,3,2,23
0,0,27,28,2,30,30,30,30,30,30,30,30,30,30,30,30
0,0,2,27,2,0,0,0,0,0,0,0,0,0,0,0,0
0,0,0,0,0,0,0,0,0,0,0,0,0,0,0,0,0
0,0,0,0,0,0,0,0,0,0,0,0,0,0,0,0,0
:endlayer
layer: 10
0,0,0,0,0,0,0,0,0,0,0,0,0,0,0,0,0
0,0,0,0,0,0,0,0,0,0,0,0,0,0,0,0,0
0,0,31,31,31,31,31,31,31,31,31,31,31,31,31,31,31
0,0,20,2,3,3,3,3,3,3,3,3,3,3,3,2,20
0,0,0,27,0,0,0,0,0,0,0,0,0,0,0,27,0
0,0,0,12,0,0,0,0,0,0,0,0,0,0,0,27,0
0,0,0,27,0,0,0,0,14,0,0,14,0,0,0,27,0
0,0,23,2,3,3,3,3,2,0,0,2,3,3,3,2,23
0,0,2,0,2,30,30,30,2,12,12,2,30,30,30,30,30
0,0,12,28,2,0,0,0,0,0,0,0,0,0,0,0,0
0,0,2,12,2,0,0,0,0,0,0,0,0,0,0,0,0
0,0,0,0,0,0,0,0,0,0,0,0,0,0,0,0,0
0,0,0,0,0,0,0,0,0,0,0,0,0,0,0,0,0
:endlayer
layer: 11
0,0,0,0,0,0,0,0,0,0,0,0,0,0,0,0,0
0,0,0,0,0,0,0,0,0,0,0,0,0,0,0,0,0
0,0,0,0,0,0,0,0,0,0,0,0,0,0,0,0,0
0,0,31,31,31,31,31,31,31,31,31,31,31,31,31,31,31
0,0,20,2,3,3,3,3,3,3,3,3,3,3,3,2,20
0,0,21,27,15,0,0,0,0,0,0,0,0,0,16,27,22
0,0,23,2,3,3,3,3,2,0,0,2,3,3,3,2,23
0,0,34,34,34,34,30,30,4,0,0,4,30,30,30,30,30
0,21,2,0,2,22,0,33,2,12,12,2,32,0,0,0,0
0,0,12,28,2,0,0,33,22,0,0,21,32,0,0,0,0
0,21,2,12,2,22,0,0,0,0,0,0,0,0,0,0,0
0,0,20,0,20,0,0,0,0,0,0,0,0,0,0,0,0
0,0,0,0,0,0,0,0,0,0,0,0,0,0,0,0,0
:endlayer
layer: 12
0,0,0,0,0,0,0,0,0,0,0,0,0,0,0,0,0
0,0,0,0,0,0,0,0,0,0,0,0,0,0,0,0,0
0,0,0,0,0,0,0,0,0,0,0,0,0,0,0,0,0
0,0,0,0,0,0,0,0,0,0,0,0,0,0,0,0,0
0,0,31,31,31,31,31,31,31,31,31,31,31,31,31,31,31
0,0,34,2,3,3,3,3,3,2,2,3,3,3,3,2,34
0,0,30,30,30,30,30,30,30,4,4,30,30,30,30,30,30
0,33,31,31,31,31,0,0,33,4,4,32,0,0,0,0,0
0,33,2,3,2,32,0,0,33,3,3,32,0,0,0,0,0
0,33,4,28,4,32,0,0,33,22,21,32,0,0,0,0,0
0,33,2,3,2,32,0,0,0,0,0,0,0,0,0,0,0
0,30,30,30,30,30,0,0,0,0,0,0,0,0,0,0,0
0,0,0,0,0,0,0,0,0,0,0,0,0,0,0,0,0
:endlayer
layer: 13
0,0,0,0,0,0,0,0,0,0,0,0,0,0,0,0,0
0,0,0,0,0,0,0,0,0,0,0,0,0,0,0,0,0
0,0,0,0,0,0,0,0,0,0,0,0,0,0,0,0,0
0,0,0,0,0,0,0,0,0,0,0,0,0,0,0,0,0
0,0,0,0,0,0,0,0,0,0,0,0,0,0,0,0,0
0,0,35,35,35,35,35,35,35,31,31,35,35,35,35,35,35
0,0,0,0,0,0,0,0,0,33,32,0,0,0,0,0,0
0,0,0,0,0,0,0,0,0,33,32,0,0,0,0,0,0
0,0,34,34,34,0,0,0,0,33,32,0,0,0,0,0,0
0,0,34,2,34,0,0,0,0,33,32,0,0,0,0,0,0
0,0,34,34,34,0,0,0,0,0,0,0,0,0,0,0,0
0,0,0,0,0,0,0,0,0,0,0,0,0,0,0,0,0
0,0,0,0,0,0,0,0,0,0,0,0,0,0,0,0,0
:endlayer
layer: 14
0,0,0,0,0,0,0,0,0,0,0,0,0,0,0,0,0
0,0,0,0,0,0,0,0,0,0,0,0,0,0,0,0,0
0,0,0,0,0,0,0,0,0,0,0,0,0,0,0,0,0
0,0,0,0,0,0,0,0,0,0,0,0,0,0,0,0,0
0,0,0,0,0,0,0,0,0,0,0,0,0,0,0,0,0
0,0,0,0,0,0,0,0,0,0,0,0,0,0,0,0,0
0,0,0,0,0,0,0,0,0,0,0,0,0,0,0,0,0
0,0,0,0,0,0,0,0,0,0,0,0,0,0,0,0,0
0,0,33,31,31,0,0,0,0,0,0,0,0,0,0,0,0
0,0,33,2,32,0,0,0,0,0,0,0,0,0,0,0,0
0,0,30,30,30,0,0,0,0,0,0,0,0,0,0,0,0
0,0,0,0,0,0,0,0,0,0,0,0,0,0,0,0,0
0,0,0,0,0,0,0,0,0,0,0,0,0,0,0,0,0
:endlayer
layer: 15
0,0,0,0,0,0,0,0,0,0,0,0,0,0,0,0,0
0,0,0,0,0,0,0,0,0,0,0,0,0,0,0,0,0
0,0,0,0,0,0,0,0,0,0,0,0,0,0,0,0,0
0,0,0,0,0,0,0,0,0,0,0,0,0,0,0,0,0
0,0,0,0,0,0,0,0,0,0,0,0,0,0,0,0,0
0,0,0,0,0,0,0,0,0,0,0,0,0,0,0,0,0
0,0,0,0,0,0,0,0,0,0,0,0,0,0,0,0,0
0,0,0,0,0,0,0,0,0,0,0,0,0,0,0,0,0
0,0,0,0,0,0,0,0,0,0,0,0,0,0,0,0,0
0,0,0,34,0,0,0,0,0,0,0,0,0,0,0,0,0
0,0,0,0,0,0,0,0,0,0,0,0,0,0,0,0,0
0,0,0,0,0,0,0,0,0,0,0,0,0,0,0,0,0
0,0,0,0,0,0,0,0,0,0,0,0,0,0,0,0,0
:endlayer
layer: 16
0,0,0,0,0,0,0,0,0,0,0,0,0,0,0,0,0
0,0,0,0,0,0,0,0,0,0,0,0,0,0,0,0,0
0,0,0,0,0,0,0,0,0,0,0,0,0,0,0,0,0
0,0,0,0,0,0,0,0,0,0,0,0,0,0,0,0,0
0,0,0,0,0,0,0,0,0,0,0,0,0,0,0,0,0
0,0,0,0,0,0,0,0,0,0,0,0,0,0,0,0,0
0,0,0,0,0,0,0,0,0,0,0,0,0,0,0,0,0
0,0,0,0,0,0,0,0,0,0,0,0,0,0,0,0,0
0,0,0,0,0,0,0,0,0,0,0,0,0,0,0,0,0
0,0,0,35,0,0,0,0,0,0,0,0,0,0,0,0,0
0,0,0,0,0,0,0,0,0,0,0,0,0,0,0,0,0
0,0,0,0,0,0,0,0,0,0,0,0,0,0,0,0,0
0,0,0,0,0,0,0,0,0,0,0,0,0,0,0,0,0
:endlayer

#### RULES ####
rule:
plugin=vanillaBlocks
number=1
data:
JSON:{blockState:{blockName:"minecraft:grass",properties:{snowy:"false"}}}
:enddata
:endrule

rule:
plugin=vanillaBlocks
number=2
data:
JSON:{blockState:{blockName:"minecraft:log",properties:{variant:"spruce",axis:"y"}}}
:enddata
:endrule

rule:
plugin=vanillaBlocks
number=3
data:
JSON:{blockState:{blockName:"minecraft:log",properties:{variant:"spruce",axis:"x"}}}
:enddata
:endrule

rule:
plugin=vanillaBlocks
number=4
data:
JSON:{blockState:{blockName:"minecraft:log",properties:{variant:"spruce",axis:"z"}}}
:enddata
:endrule

rule:
plugin=vanillaBlocks
number=5
data:
JSON:{blockState:{blockName:"minecraft:planks",properties:{variant:"dark_oak"}}}
:enddata
:endrule

rule:
plugin=vanillaBlocks
number=6
data:
JSON:{blockState:{blockName:"minecraft:torch",properties:{facing:"up"}}}
:enddata
:endrule

rule:
plugin=vanillaBlocks
number=7
data:
JSON:{blockState:{blockName:"minecraft:cobblestone"}}
:enddata
:endrule

rule:
plugin=doors
number=8
data:
JSON:{blockState:{blockName:"minecraft:spruce_door",properties:{hinge:"left",half:"lower",powered:"false",facing:"north",open:"false"}}}
:enddata
:endrule

rule:
plugin=doors
number=9
data:
JSON:{blockState:{blockName:"minecraft:spruce_door",properties:{hinge:"left",half:"lower",powered:"false",facing:"east",open:"false"}}}
:enddata
:endrule

rule:
plugin=vanillaBlocks
number=10
data:
JSON:{blockState:{blockName:"minecraft:dark_oak_stairs",properties:{half:"bottom",shape:"straight",facing:"west"}}}
:enddata
:endrule

rule:
plugin=vanillaBlocks
number=11
data:
JSON:{blockState:{blockName:"minecraft:dark_oak_stairs",properties:{half:"top",shape:"straight",facing:"east"}}}
:enddata
:endrule

rule:
plugin=vanillaBlocks
number=12
data:
JSON:{blockState:{blockName:"minecraft:acacia_fence",properties:{east:"false",south:"false",north:"false",west:"false"}}}
:enddata
:endrule

rule:
plugin=doors
number=13
data:
JSON:{blockState:{blockName:"minecraft:spruce_door",properties:{hinge:"left",half:"upper",powered:"false",facing:"south",open:"false"}}}
:enddata
:endrule

rule:
plugin=vanillaBlocks
number=14
data:
JSON:{blockState:{blockName:"minecraft:torch",properties:{facing:"north"}}}
:enddata
:endrule

rule:
plugin=vanillaBlocks
number=15
data:
JSON:{blockState:{blockName:"minecraft:torch",properties:{facing:"east"}}}
:enddata
:endrule

rule:
plugin=vanillaBlocks
number=16
data:
JSON:{blockState:{blockName:"minecraft:torch",properties:{facing:"west"}}}
:enddata
:endrule

rule:
plugin=vanillaBlocks
number=17
data:
JSON:{blockState:{blockName:"minecraft:torch",properties:{facing:"south"}}}
:enddata
:endrule

rule:
plugin=vanillaBlocks
number=18
data:
JSON:{blockState:{blockName:"minecraft:wooden_slab",properties:{half:"top",variant:"spruce"}}}
:enddata
:endrule

rule:
plugin=vanillaBlocks
number=19
data:
JSON:{blockState:{blockName:"minecraft:wooden_button",properties:{powered:"false",facing:"south"}}}
:enddata
:endrule

rule:
plugin=vanillaBlocks
number=20
data:
JSON:{blockState:{blockName:"minecraft:spruce_stairs",properties:{half:"top",shape:"straight",facing:"north"}}}
:enddata
:endrule

rule:
plugin=vanillaBlocks
number=21
data:
JSON:{blockState:{blockName:"minecraft:spruce_stairs",properties:{half:"top",shape:"straight",facing:"east"}}}
:enddata
:endrule

rule:
plugin=vanillaBlocks
number=22
data:
JSON:{blockState:{blockName:"minecraft:spruce_stairs",properties:{half:"top",shape:"straight",facing:"west"}}}
:enddata
:endrule

rule:
plugin=vanillaBlocks
number=23
data:
JSON:{blockState:{blockName:"minecraft:spruce_stairs",properties:{half:"top",shape:"straight",facing:"south"}}}
:enddata
:endrule

rule:
plugin=vanillaBlocks
number=24
data:
JSON:{blockState:{blockName:"minecraft:wooden_slab",properties:{half:"top",variant:"dark_oak"}}}
:enddata
:endrule

rule:
plugin=vanillaBlocks
number=25
data:
JSON:{blockState:{blockName:"minecraft:dark_oak_stairs",properties:{half:"top",shape:"straight",facing:"south"}}}
:enddata
:endrule

rule:
plugin=vanillaBlocks
number=26
data:
JSON:{blockState:{blockName:"minecraft:wooden_button",properties:{powered:"false",facing:"west"}}}
:enddata
:endrule

rule:
plugin=vanillaBlocks
number=27
data:
JSON:{blockState:{blockName:"minecraft:planks",properties:{variant:"oak"}}}
:enddata
:endrule

rule:
plugin=vanillaBlocks
number=28
data:
JSON:{blockState:{blockName:"minecraft:ladder",properties:{facing:"west"}}}
:enddata
:endrule

rule:
plugin=vanillaBlocks
number=29
data:
JSON:{blockState:{blockName:"minecraft:dark_oak_stairs",properties:{half:"bottom",shape:"straight",facing:"north"}}}
:enddata
:endrule

rule:
plugin=vanillaBlocks
number=30
data:
JSON:{blockState:{blockName:"minecraft:spruce_stairs",properties:{half:"bottom",shape:"straight",facing:"north"}}}
:enddata
:endrule

rule:
plugin=vanillaBlocks
number=31
data:
JSON:{blockState:{blockName:"minecraft:spruce_stairs",properties:{half:"bottom",shape:"straight",facing:"south"}}}
:enddata
:endrule

rule:
plugin=vanillaBlocks
number=32
data:
JSON:{blockState:{blockName:"minecraft:spruce_stairs",properties:{half:"bottom",shape:"straight",facing:"west"}}}
:enddata
:endrule

rule:
plugin=vanillaBlocks
number=33
data:
JSON:{blockState:{blockName:"minecraft:spruce_stairs",properties:{half:"bottom",shape:"straight",facing:"east"}}}
:enddata
:endrule

rule:
plugin=vanillaBlocks
number=34
data:
JSON:{blockState:{blockName:"minecraft:planks",properties:{variant:"spruce"}}}
:enddata
:endrule

rule:
plugin=vanillaBlocks
number=35
data:
JSON:{blockState:{blockName:"minecraft:wooden_slab",properties:{half:"bottom",variant:"spruce"}}}
:enddata
:endrule

#### ENTITIES ####
