# Ancient Warfare Structure Template File
# Auto-generated structure template file. created on: 1/9/2024 at: 13:34:32
# Lines beginning with # denote comments

header:
version=2.11
name=SB_DarokCol_House_1H4R_2
mods=
size=18,14,17
offset=8,0,16
:endheader

#### VALIDATION ####
validation:
type=ground
structureAuthor=TheOddlySeagull
survival=true
worldGenEnabled=false
unique=false
preserveBlocks=false
preventNaturalHostileSpawns=true
selectionWeight=1
clusterValue=1
minDuplicateDistance=1
dimensionWhiteList=true
dimensionList=
biomeGroupList=
biomeWhiteList=true
biomeList=
leveling=10
fill=10
border=5
blockSwap=false
territoryName=
biomeReplacement=minecraft:
minGenerationHeight=0
maxGenerationHeight=255
:endvalidation

#### LAYERS ####
layer: 0
0,0,0,0,0,0,0,0,0,0,0,0,0,0,0,0,0,0
0,0,0,0,0,0,0,0,0,0,0,0,0,0,0,0,0,0
0,0,0,0,0,0,0,0,0,0,0,4,5,5,5,5,4,0
0,0,0,0,0,0,0,0,0,0,0,6,7,7,7,7,6,0
0,0,0,0,0,0,0,0,0,0,0,6,7,7,7,7,6,0
0,0,0,0,0,0,0,0,0,0,0,6,7,8,8,7,6,0
0,0,0,0,0,0,0,0,0,0,0,6,7,8,8,7,6,0
0,0,4,5,5,5,5,5,5,5,5,4,7,7,7,7,6,0
0,0,6,7,7,7,7,7,7,7,7,6,7,7,7,7,6,0
0,0,6,7,7,8,8,8,8,8,8,4,5,4,5,5,4,0
0,0,6,7,7,8,7,7,7,7,7,8,7,6,0,0,0,0
0,0,6,7,7,8,7,7,7,7,7,8,7,6,0,0,0,0
0,0,6,7,7,8,8,8,8,8,8,8,7,6,0,0,0,0
0,0,6,7,7,7,7,7,7,7,7,7,7,6,0,0,0,0
0,0,4,5,5,5,5,5,5,5,5,5,5,4,0,0,0,0
0,0,0,0,0,0,3,2,2,1,0,0,0,0,0,0,0,0
0,0,0,0,0,0,0,0,0,0,0,0,0,0,0,0,0,0
:endlayer
layer: 1
0,0,0,0,0,0,0,0,0,0,0,0,0,0,0,0,0,0
0,0,0,0,0,0,0,0,0,0,0,0,0,0,0,0,0,0
0,0,0,0,0,0,0,0,0,0,0,4,9,9,9,9,4,0
0,0,0,0,0,0,0,0,0,0,0,9,0,0,0,0,9,0
0,0,0,0,0,0,0,0,0,0,0,9,0,0,0,0,9,0
0,0,0,0,0,0,0,0,0,0,0,9,0,0,0,0,9,0
0,0,0,0,0,0,0,0,0,0,0,9,0,0,0,0,9,0
0,0,4,9,9,9,9,9,9,9,9,4,0,0,0,0,9,0
0,0,9,0,0,0,0,0,0,0,0,0,0,0,0,0,9,0
0,0,9,0,0,0,0,0,0,0,0,4,9,4,9,9,4,0
0,0,9,13,0,0,0,0,0,0,0,0,0,9,0,0,0,0
0,0,9,12,0,0,0,0,0,0,0,0,0,9,0,0,0,0
0,0,9,0,0,0,0,0,0,0,0,0,0,9,0,0,0,0
0,0,9,0,0,0,0,0,0,0,0,0,0,9,0,0,0,0
0,0,4,9,9,9,9,11,10,9,9,9,9,4,0,0,0,0
0,0,0,0,0,0,0,0,0,0,0,0,0,0,0,0,0,0
0,0,0,0,0,0,0,0,0,0,0,0,0,0,0,0,0,0
:endlayer
layer: 2
0,0,0,0,0,0,0,0,0,0,0,0,0,0,0,0,0,0
0,0,0,0,0,0,0,0,0,0,0,0,0,0,0,0,0,0
0,0,0,0,0,0,0,0,0,0,0,4,9,14,14,9,4,0
0,0,0,0,0,0,0,0,0,0,0,9,0,0,0,0,9,0
0,0,0,0,0,0,0,0,0,0,0,14,0,0,0,0,9,0
0,0,0,0,0,0,0,0,0,0,0,9,0,0,0,0,9,0
0,0,0,0,0,0,0,0,0,0,0,9,0,0,0,0,14,0
0,0,4,9,9,14,9,9,9,14,9,4,0,0,0,0,9,0
0,0,9,0,0,0,0,0,0,0,0,0,0,0,0,0,9,0
0,0,9,13,0,0,0,0,0,0,0,4,9,4,9,9,4,0
0,0,9,12,0,0,0,0,0,0,0,0,0,9,0,0,0,0
0,0,9,0,0,0,0,0,0,0,0,0,0,14,0,0,0,0
0,0,14,0,0,0,0,0,0,0,0,0,0,9,0,0,0,0
0,0,9,0,0,0,17,0,0,17,0,0,0,9,0,0,0,0
0,0,4,9,14,9,9,16,15,9,9,14,9,4,0,0,0,0
0,0,0,0,0,0,0,0,0,0,0,0,0,0,0,0,0,0
0,0,0,0,0,0,0,0,0,0,0,0,0,0,0,0,0,0
:endlayer
layer: 3
0,0,0,0,0,0,0,0,0,0,0,0,0,0,0,0,0,0
0,0,0,0,0,0,0,0,0,0,0,17,0,0,0,0,17,0
0,0,0,0,0,0,0,0,0,0,20,4,9,9,9,9,4,19
0,0,0,0,0,0,0,0,0,0,0,9,18,0,0,18,9,0
0,0,0,0,0,0,0,0,0,0,0,9,0,0,0,0,9,0
0,0,0,0,0,0,0,0,0,0,0,9,0,0,0,0,9,0
0,0,17,0,0,0,0,0,0,0,0,9,0,0,0,0,9,0
0,20,4,9,9,9,9,9,9,9,9,4,19,0,0,0,9,0
0,0,9,13,0,0,0,18,0,0,0,9,0,17,0,0,9,0
0,0,9,12,0,0,0,0,0,0,20,4,9,4,9,9,4,19
0,0,9,0,0,0,0,0,0,0,0,18,0,9,0,0,18,0
0,0,9,0,0,0,0,0,0,0,0,0,0,9,0,0,0,0
0,0,9,0,0,0,0,0,0,0,0,0,0,9,0,0,0,0
0,0,9,17,0,0,0,0,0,0,0,0,20,9,0,0,0,0
0,20,4,9,9,9,9,9,9,9,9,9,9,4,19,0,0,0
0,0,18,0,0,0,0,0,0,0,0,0,0,18,0,0,0,0
0,0,0,0,0,0,0,0,0,0,0,0,0,0,0,0,0,0
:endlayer
layer: 4
0,0,0,0,0,0,0,0,0,0,0,31,0,0,0,0,31,0
0,0,0,0,0,0,0,0,0,0,0,6,22,30,22,30,6,0
0,0,0,0,0,0,0,0,0,25,5,6,5,5,5,5,6,0
0,0,0,0,0,0,0,0,0,0,29,6,28,28,28,28,6,0
0,0,0,0,0,0,0,0,0,0,22,6,27,27,27,27,6,0
0,0,31,0,0,0,0,0,0,0,29,6,28,28,28,28,6,0
0,0,6,30,22,30,22,30,22,30,22,6,27,27,27,27,6,0
25,5,6,5,5,5,5,5,5,5,5,4,28,28,28,28,6,0
0,29,6,12,27,28,27,28,27,28,27,28,27,27,27,27,6,0
0,22,6,0,27,28,27,28,27,28,27,4,5,5,5,5,6,0
0,29,6,0,27,28,27,28,27,28,27,28,27,6,22,23,6,0
0,22,6,0,27,28,27,28,27,28,27,28,27,6,26,0,21,0
0,29,6,13,27,28,27,28,27,28,27,28,27,6,22,0,0,0
0,22,6,28,27,28,27,28,27,28,27,28,27,6,26,0,0,0
25,5,6,5,5,5,5,5,5,5,5,5,5,6,5,24,0,0
0,0,6,23,22,23,22,23,22,23,22,23,22,6,0,0,0,0
0,0,21,0,0,0,0,0,0,0,0,0,0,21,0,0,0,0
:endlayer
layer: 5
0,0,0,0,0,0,0,0,0,0,0,0,0,0,0,0,0,0
0,0,0,0,0,0,0,0,0,0,0,4,32,32,32,32,4,0
0,0,0,0,0,0,0,0,0,0,4,0,0,0,0,0,32,0
0,0,0,0,0,0,0,0,0,0,32,0,0,0,0,0,32,0
0,0,0,0,0,0,0,0,0,0,32,0,0,0,0,0,32,0
0,0,0,0,0,0,0,0,0,0,32,0,0,0,0,0,32,0
0,0,4,32,32,32,4,32,32,32,4,0,0,0,0,0,32,0
0,4,0,0,0,0,0,0,0,0,0,4,0,0,0,0,32,0
0,32,34,0,0,0,0,0,0,0,0,0,0,0,0,0,32,0
0,32,33,0,14,0,0,0,0,0,0,4,0,0,0,0,32,0
0,32,0,0,14,0,0,4,32,0,32,4,32,4,32,32,4,0
0,32,0,0,14,0,0,32,0,0,0,0,0,0,32,0,0,0
0,32,14,14,14,0,0,32,0,0,0,0,0,0,32,0,0,0
0,32,0,0,0,0,0,32,0,0,0,0,0,0,32,0,0,0
0,4,0,0,0,0,0,4,0,0,0,0,0,0,4,0,0,0
0,0,4,32,32,32,32,32,32,32,32,32,32,4,0,0,0,0
0,0,0,0,0,0,0,0,0,0,0,0,0,0,0,0,0,0
:endlayer
layer: 6
0,0,0,0,0,0,0,0,0,0,0,0,0,0,0,0,0,0
0,0,0,0,0,0,0,0,0,0,0,4,32,14,14,32,4,0
0,0,0,0,0,0,0,0,0,0,4,0,0,0,0,0,32,0
0,0,0,0,0,0,0,0,0,0,32,0,0,0,0,0,32,0
0,0,0,0,0,0,0,0,0,0,14,0,0,0,0,0,32,0
0,0,0,0,0,0,0,0,0,0,32,0,0,0,0,0,14,0
0,0,4,32,14,32,4,32,14,32,4,0,0,0,0,0,14,0
0,4,0,0,0,0,0,0,0,0,0,4,0,0,0,0,32,0
0,32,0,0,0,0,0,0,0,0,0,0,0,0,0,0,32,0
0,32,34,0,0,0,0,0,0,0,0,4,0,0,0,0,32,0
0,14,33,0,0,0,0,4,32,0,32,4,32,4,32,32,4,0
0,14,0,0,0,0,0,32,0,0,0,0,0,0,32,0,0,0
0,32,0,0,0,0,0,32,0,0,0,0,0,0,14,0,0,0
0,32,0,0,0,0,0,32,0,0,0,0,0,0,32,0,0,0
0,4,0,0,0,0,0,4,0,0,0,0,0,0,4,0,0,0
0,0,4,32,32,14,14,32,32,14,14,32,32,4,0,0,0,0
0,0,0,0,0,0,0,0,0,0,0,0,0,0,0,0,0,0
:endlayer
layer: 7
0,0,0,0,0,0,0,0,0,0,0,0,0,0,0,0,0,0
0,0,0,0,0,0,0,0,0,0,0,4,32,14,14,32,4,26
0,0,0,0,0,0,0,0,0,0,4,18,0,0,0,0,32,0
0,0,0,0,0,0,0,0,0,0,32,0,0,0,0,0,32,0
0,0,0,0,0,0,0,0,0,0,14,0,0,0,0,20,32,0
0,0,0,0,0,0,0,0,0,0,32,0,0,0,0,0,14,0
0,0,4,32,14,32,4,32,14,32,4,17,0,0,0,0,14,0
0,4,19,0,0,0,18,0,0,0,20,4,0,0,0,20,32,0
0,32,0,0,0,0,0,0,0,0,0,32,0,0,0,0,32,0
0,32,0,0,0,0,0,17,0,0,20,4,0,17,0,0,32,0
0,14,34,0,0,0,20,4,32,32,32,4,32,4,32,32,4,26
0,14,33,0,0,0,0,32,0,0,0,18,0,18,32,0,0,0
0,32,0,0,0,0,0,32,0,0,0,0,0,0,14,0,0,0
0,32,0,0,0,0,0,32,0,0,0,0,0,0,32,0,0,0
0,4,19,0,0,0,20,4,19,0,0,0,0,20,4,0,0,0
0,0,4,32,32,14,14,32,32,14,14,32,32,4,0,0,0,0
0,0,23,0,0,0,0,0,0,0,0,0,0,23,0,0,0,0
:endlayer
layer: 8
0,0,0,0,0,0,0,0,0,0,0,0,0,0,0,0,29,36
0,0,0,0,0,0,0,0,0,38,26,4,5,5,5,5,4,36
0,0,0,0,0,0,0,0,0,38,4,0,0,0,0,0,6,36
0,0,0,0,0,0,0,0,0,38,6,0,0,0,0,0,6,36
0,0,0,0,0,0,0,0,0,38,6,0,0,0,0,0,6,36
0,37,37,37,37,37,37,37,37,37,6,0,0,0,0,0,6,36
0,23,4,5,5,5,5,5,5,5,4,0,0,0,0,0,6,36
0,4,0,28,27,28,27,6,27,28,27,4,0,0,0,0,6,36
0,6,0,28,27,28,27,6,27,28,27,6,0,0,0,0,6,36
0,6,0,28,27,28,27,6,27,28,27,6,0,0,0,0,6,36
0,6,0,28,27,28,27,6,5,5,5,5,5,5,5,5,4,36
0,6,34,28,27,28,27,6,27,28,27,28,27,28,6,0,29,36
0,6,33,28,27,28,27,6,27,28,27,28,27,28,6,0,0,0
0,6,27,28,27,28,27,6,27,28,27,28,27,28,6,0,0,0
0,4,27,28,27,28,27,6,27,28,27,28,27,28,4,0,0,0
0,30,4,5,5,5,5,5,5,5,5,5,5,4,30,0,0,0
0,35,35,35,35,35,35,35,35,35,35,35,35,35,35,0,0,0
:endlayer
layer: 9
0,0,0,0,0,0,0,0,0,0,38,26,0,0,0,29,36,0
0,0,0,0,0,0,0,0,0,0,38,4,32,32,32,4,36,0
0,0,0,0,0,0,0,0,0,0,38,6,0,0,0,6,36,0
0,0,0,0,0,0,0,0,0,0,38,6,0,0,0,6,36,0
0,0,0,0,0,0,0,0,0,0,38,6,0,0,0,6,36,0
0,0,0,0,0,0,0,0,0,0,38,6,0,0,0,6,36,0
37,37,37,37,37,37,37,37,37,37,37,6,0,0,0,6,36,0
23,4,5,5,5,5,5,5,5,5,5,4,0,0,0,6,36,0
0,32,0,14,0,0,0,0,0,0,0,32,0,0,0,6,36,0
0,32,0,14,0,0,0,0,0,0,0,32,0,0,0,6,36,0
0,32,0,14,0,0,0,0,0,0,0,4,32,32,32,4,36,0
0,32,0,0,0,0,0,0,0,0,0,0,0,0,32,29,36,0
0,32,0,0,0,0,0,0,0,0,0,0,0,0,32,0,0,0
0,32,0,0,0,0,17,0,0,17,0,0,0,0,32,0,0,0
30,4,5,5,5,5,5,5,5,5,5,5,5,5,4,30,0,0
35,35,35,35,35,35,35,35,35,35,35,35,35,35,35,35,0,0
0,0,0,0,0,0,0,0,0,0,0,0,0,0,0,0,0,0
:endlayer
layer: 10
0,0,0,0,0,0,0,0,0,0,0,38,26,0,29,36,0,0
0,0,0,0,0,0,0,0,0,0,0,38,4,32,4,36,0,0
0,0,0,0,0,0,0,0,0,0,0,38,6,0,6,36,0,0
0,0,0,0,0,0,0,0,0,0,0,38,6,0,6,36,0,0
0,0,0,0,0,0,0,0,0,0,0,38,6,0,6,36,0,0
0,0,0,0,0,0,0,0,0,0,0,38,6,0,6,36,0,0
0,0,0,0,0,0,0,0,0,0,0,38,6,0,6,36,0,0
37,37,37,37,37,37,37,37,37,37,37,38,6,0,6,36,0,0
23,4,5,5,5,5,5,5,5,5,5,5,6,0,6,36,0,0
0,32,19,0,0,0,0,0,0,0,20,32,6,0,6,36,0,0
0,14,0,0,0,0,0,0,0,0,0,4,32,32,4,36,0,0
0,14,0,0,0,0,0,0,0,0,0,0,0,0,32,36,0,0
0,32,19,0,0,0,0,0,0,0,0,0,0,20,32,0,0,0
30,4,5,5,5,5,40,0,0,39,5,5,5,5,4,30,0,0
35,35,35,35,35,35,4,14,14,4,35,35,35,35,35,35,0,0
0,0,0,0,0,0,0,0,0,0,0,0,0,0,0,0,0,0
0,0,0,0,0,0,0,0,0,0,0,0,0,0,0,0,0,0
:endlayer
layer: 11
0,0,0,0,0,0,0,0,0,0,0,0,38,30,36,0,0,0
0,0,0,0,0,0,0,0,0,0,0,0,38,4,36,0,0,0
0,0,0,0,0,0,0,0,0,0,0,0,38,6,36,0,0,0
0,0,0,0,0,0,0,0,0,0,0,0,38,6,36,0,0,0
0,0,0,0,0,0,0,0,0,0,0,0,38,6,36,0,0,0
0,0,0,0,0,0,0,0,0,0,0,0,38,6,36,0,0,0
0,0,0,0,0,0,0,0,0,0,0,0,38,6,36,0,0,0
0,0,0,0,0,0,0,0,0,0,0,0,38,6,36,0,0,0
37,37,37,37,37,37,37,37,37,37,37,37,38,6,36,0,0,0
23,4,5,5,5,5,5,5,5,5,5,5,5,6,36,0,0,0
0,32,0,0,0,0,0,0,0,0,0,4,32,32,4,0,0,0
0,32,0,0,0,0,0,0,0,0,0,0,0,0,32,0,0,0
30,4,5,5,5,5,40,0,0,39,5,5,5,5,4,30,0,0
35,35,35,35,35,35,6,0,0,6,35,35,35,35,35,35,0,0
0,0,0,0,0,38,4,14,14,4,36,0,0,0,0,0,0,0
0,0,0,0,0,38,26,0,0,29,36,0,0,0,0,0,0,0
0,0,0,0,0,0,0,0,0,0,0,0,0,0,0,0,0,0
:endlayer
layer: 12
0,0,0,0,0,0,0,0,0,0,0,0,0,41,0,0,0,0
0,0,0,0,0,0,0,0,0,0,0,0,0,41,0,0,0,0
0,0,0,0,0,0,0,0,0,0,0,0,0,41,0,0,0,0
0,0,0,0,0,0,0,0,0,0,0,0,0,41,0,0,0,0
0,0,0,0,0,0,0,0,0,0,0,0,0,41,0,0,0,0
0,0,0,0,0,0,0,0,0,0,0,0,0,41,0,0,0,0
0,0,0,0,0,0,0,0,0,0,0,0,0,41,0,0,0,0
0,0,0,0,0,0,0,0,0,0,0,0,0,41,0,0,0,0
0,0,0,0,0,0,0,0,0,0,0,0,0,41,0,0,0,0
37,37,37,37,37,37,37,37,37,37,37,37,37,37,37,37,0,0
23,4,5,5,5,5,5,5,5,5,5,5,5,5,4,23,0,0
30,4,5,5,5,5,5,5,5,5,5,5,5,5,4,30,0,0
35,35,35,35,35,35,35,6,6,35,35,35,35,35,35,35,0,0
0,0,0,0,0,0,38,6,6,36,0,0,0,0,0,0,0,0
0,0,0,0,0,0,38,5,5,36,0,0,0,0,0,0,0,0
0,0,0,0,0,0,38,26,29,36,0,0,0,0,0,0,0,0
0,0,0,0,0,0,0,0,0,0,0,0,0,0,0,0,0,0
:endlayer
layer: 13
0,0,0,0,0,0,0,0,0,0,0,0,0,0,0,0,0,0
0,0,0,0,0,0,0,0,0,0,0,0,0,0,0,0,0,0
0,0,0,0,0,0,0,0,0,0,0,0,0,0,0,0,0,0
0,0,0,0,0,0,0,0,0,0,0,0,0,0,0,0,0,0
0,0,0,0,0,0,0,0,0,0,0,0,0,0,0,0,0,0
0,0,0,0,0,0,0,0,0,0,0,0,0,0,0,0,0,0
0,0,0,0,0,0,0,0,0,0,0,0,0,0,0,0,0,0
0,0,0,0,0,0,0,0,0,0,0,0,0,0,0,0,0,0
0,0,0,0,0,0,0,0,0,0,0,0,0,0,0,0,0,0
0,0,0,0,0,0,0,0,0,0,0,0,0,0,0,0,0,0
37,37,37,37,37,37,37,37,37,37,37,37,37,37,37,37,0,0
35,35,35,35,35,35,35,38,35,35,35,35,35,35,35,35,0,0
0,0,0,0,0,0,0,38,36,0,0,0,0,0,0,0,0,0
0,0,0,0,0,0,0,38,36,0,0,0,0,0,0,0,0,0
0,0,0,0,0,0,0,38,36,0,0,0,0,0,0,0,0,0
0,0,0,0,0,0,0,38,36,0,0,0,0,0,0,0,0,0
0,0,0,0,0,0,0,0,0,0,0,0,0,0,0,0,0,0
:endlayer

#### RULES ####
rule:
plugin=vanillaBlocks
number=1
data:
JSON:{blockState:{blockName:"minecraft:stone_brick_stairs",properties:{half:"bottom",shape:"straight",facing:"west"}}}
:enddata
:endrule

rule:
plugin=vanillaBlocks
number=2
data:
JSON:{blockState:{blockName:"minecraft:stone_brick_stairs",properties:{half:"bottom",shape:"straight",facing:"north"}}}
:enddata
:endrule

rule:
plugin=vanillaBlocks
number=3
data:
JSON:{blockState:{blockName:"minecraft:stone_brick_stairs",properties:{half:"bottom",shape:"straight",facing:"east"}}}
:enddata
:endrule

rule:
plugin=vanillaBlocks
number=4
data:
JSON:{blockState:{blockName:"minecraft:log",properties:{variant:"spruce",axis:"y"}}}
:enddata
:endrule

rule:
plugin=vanillaBlocks
number=5
data:
JSON:{blockState:{blockName:"minecraft:log",properties:{variant:"spruce",axis:"x"}}}
:enddata
:endrule

rule:
plugin=vanillaBlocks
number=6
data:
JSON:{blockState:{blockName:"minecraft:log",properties:{variant:"spruce",axis:"z"}}}
:enddata
:endrule

rule:
plugin=vanillaBlocks
number=7
data:
JSON:{blockState:{blockName:"minecraft:stone",properties:{variant:"smooth_andesite"}}}
:enddata
:endrule

rule:
plugin=vanillaBlocks
number=8
data:
JSON:{blockState:{blockName:"minecraft:stone",properties:{variant:"smooth_diorite"}}}
:enddata
:endrule

rule:
plugin=vanillaBlocks
number=9
data:
JSON:{blockState:{blockName:"minecraft:cobblestone"}}
:enddata
:endrule

rule:
plugin=doors
number=10
data:
JSON:{blockState:{blockName:"minecraft:spruce_door",properties:{hinge:"right",half:"lower",powered:"false",facing:"north",open:"false"}}}
:enddata
:endrule

rule:
plugin=doors
number=11
data:
JSON:{blockState:{blockName:"minecraft:spruce_door",properties:{hinge:"left",half:"lower",powered:"false",facing:"north",open:"false"}}}
:enddata
:endrule

rule:
plugin=vanillaBlocks
number=12
data:
JSON:{blockState:{blockName:"minecraft:dark_oak_stairs",properties:{half:"bottom",shape:"straight",facing:"north"}}}
:enddata
:endrule

rule:
plugin=vanillaBlocks
number=13
data:
JSON:{blockState:{blockName:"minecraft:dark_oak_stairs",properties:{half:"top",shape:"straight",facing:"south"}}}
:enddata
:endrule

rule:
plugin=vanillaBlocks
number=14
data:
JSON:{blockState:{blockName:"minecraft:acacia_fence",properties:{east:"false",south:"false",north:"false",west:"false"}}}
:enddata
:endrule

rule:
plugin=doors
number=15
data:
JSON:{blockState:{blockName:"minecraft:spruce_door",properties:{hinge:"right",half:"upper",powered:"false",facing:"north",open:"false"}}}
:enddata
:endrule

rule:
plugin=doors
number=16
data:
JSON:{blockState:{blockName:"minecraft:spruce_door",properties:{hinge:"left",half:"upper",powered:"false",facing:"north",open:"false"}}}
:enddata
:endrule

rule:
plugin=vanillaBlocks
number=17
data:
JSON:{blockState:{blockName:"minecraft:torch",properties:{facing:"north"}}}
:enddata
:endrule

rule:
plugin=vanillaBlocks
number=18
data:
JSON:{blockState:{blockName:"minecraft:torch",properties:{facing:"south"}}}
:enddata
:endrule

rule:
plugin=vanillaBlocks
number=19
data:
JSON:{blockState:{blockName:"minecraft:torch",properties:{facing:"east"}}}
:enddata
:endrule

rule:
plugin=vanillaBlocks
number=20
data:
JSON:{blockState:{blockName:"minecraft:torch",properties:{facing:"west"}}}
:enddata
:endrule

rule:
plugin=vanillaBlocks
number=21
data:
JSON:{blockState:{blockName:"minecraft:wooden_button",properties:{powered:"false",facing:"south"}}}
:enddata
:endrule

rule:
plugin=vanillaBlocks
number=22
data:
JSON:{blockState:{blockName:"minecraft:wooden_slab",properties:{half:"top",variant:"spruce"}}}
:enddata
:endrule

rule:
plugin=vanillaBlocks
number=23
data:
JSON:{blockState:{blockName:"minecraft:spruce_stairs",properties:{half:"top",shape:"straight",facing:"north"}}}
:enddata
:endrule

rule:
plugin=vanillaBlocks
number=24
data:
JSON:{blockState:{blockName:"minecraft:wooden_button",properties:{powered:"false",facing:"east"}}}
:enddata
:endrule

rule:
plugin=vanillaBlocks
number=25
data:
JSON:{blockState:{blockName:"minecraft:wooden_button",properties:{powered:"false",facing:"west"}}}
:enddata
:endrule

rule:
plugin=vanillaBlocks
number=26
data:
JSON:{blockState:{blockName:"minecraft:spruce_stairs",properties:{half:"top",shape:"straight",facing:"west"}}}
:enddata
:endrule

rule:
plugin=vanillaBlocks
number=27
data:
JSON:{blockState:{blockName:"minecraft:wooden_slab",properties:{half:"top",variant:"dark_oak"}}}
:enddata
:endrule

rule:
plugin=vanillaBlocks
number=28
data:
JSON:{blockState:{blockName:"minecraft:planks",properties:{variant:"dark_oak"}}}
:enddata
:endrule

rule:
plugin=vanillaBlocks
number=29
data:
JSON:{blockState:{blockName:"minecraft:spruce_stairs",properties:{half:"top",shape:"straight",facing:"east"}}}
:enddata
:endrule

rule:
plugin=vanillaBlocks
number=30
data:
JSON:{blockState:{blockName:"minecraft:spruce_stairs",properties:{half:"top",shape:"straight",facing:"south"}}}
:enddata
:endrule

rule:
plugin=vanillaBlocks
number=31
data:
JSON:{blockState:{blockName:"minecraft:wooden_button",properties:{powered:"false",facing:"north"}}}
:enddata
:endrule

rule:
plugin=vanillaBlocks
number=32
data:
JSON:{blockState:{blockName:"minecraft:planks",properties:{variant:"oak"}}}
:enddata
:endrule

rule:
plugin=vanillaBlocks
number=33
data:
JSON:{blockState:{blockName:"minecraft:dark_oak_stairs",properties:{half:"top",shape:"straight",facing:"north"}}}
:enddata
:endrule

rule:
plugin=vanillaBlocks
number=34
data:
JSON:{blockState:{blockName:"minecraft:dark_oak_stairs",properties:{half:"bottom",shape:"straight",facing:"south"}}}
:enddata
:endrule

rule:
plugin=vanillaBlocks
number=35
data:
JSON:{blockState:{blockName:"minecraft:spruce_stairs",properties:{half:"bottom",shape:"straight",facing:"north"}}}
:enddata
:endrule

rule:
plugin=vanillaBlocks
number=36
data:
JSON:{blockState:{blockName:"minecraft:spruce_stairs",properties:{half:"bottom",shape:"straight",facing:"west"}}}
:enddata
:endrule

rule:
plugin=vanillaBlocks
number=37
data:
JSON:{blockState:{blockName:"minecraft:spruce_stairs",properties:{half:"bottom",shape:"straight",facing:"south"}}}
:enddata
:endrule

rule:
plugin=vanillaBlocks
number=38
data:
JSON:{blockState:{blockName:"minecraft:spruce_stairs",properties:{half:"bottom",shape:"straight",facing:"east"}}}
:enddata
:endrule

rule:
plugin=vanillaBlocks
number=39
data:
JSON:{blockState:{blockName:"minecraft:dark_oak_stairs",properties:{half:"top",shape:"straight",facing:"east"}}}
:enddata
:endrule

rule:
plugin=vanillaBlocks
number=40
data:
JSON:{blockState:{blockName:"minecraft:dark_oak_stairs",properties:{half:"top",shape:"straight",facing:"west"}}}
:enddata
:endrule

rule:
plugin=vanillaBlocks
number=41
data:
JSON:{blockState:{blockName:"minecraft:wooden_slab",properties:{half:"bottom",variant:"spruce"}}}
:enddata
:endrule

#### ENTITIES ####
