# Ancient Warfare Structure Template File
# Auto-generated structure template file. created on: 1/9/2024 at: 0:43:48
# Lines beginning with # denote comments

header:
version=2.11
name=SB_DarokCol_House_1H4R_1
mods=
size=11,21,17
offset=5,1,16
:endheader

#### VALIDATION ####
validation:
type=ground
structureAuthor=TheOddlySeagull
survival=true
worldGenEnabled=false
unique=false
preserveBlocks=false
preventNaturalHostileSpawns=true
selectionWeight=1
clusterValue=1
minDuplicateDistance=1
dimensionWhiteList=true
dimensionList=
biomeGroupList=
biomeWhiteList=true
biomeList=
leveling=10
fill=10
border=5
blockSwap=false
territoryName=
biomeReplacement=minecraft:
minGenerationHeight=0
maxGenerationHeight=255
:endvalidation

#### LAYERS ####
layer: 0
1,1,1,1,1,1,1,1,1,1,1
1,1,1,1,1,1,1,1,1,1,1
1,1,1,1,1,1,1,1,1,1,1
2,3,3,3,3,2,3,3,3,3,2
4,5,5,5,5,4,5,5,5,5,4
4,5,5,5,5,4,5,5,5,5,4
4,5,5,5,5,4,5,5,5,5,4
4,5,5,5,5,4,5,5,5,5,4
2,3,3,3,3,3,3,3,3,3,2
4,5,5,5,5,4,5,5,5,5,4
4,5,5,5,5,4,5,5,5,5,4
4,5,5,5,5,4,5,5,5,5,4
4,5,5,5,5,4,5,5,5,5,4
2,3,3,3,3,3,3,3,3,3,2
1,1,1,1,1,1,1,1,1,1,1
1,1,1,1,1,1,1,1,1,1,1
1,1,1,1,1,1,1,1,1,1,1
:endlayer
layer: 1
0,0,0,0,0,0,0,0,0,0,0
0,0,0,0,0,0,0,0,0,0,0
0,0,0,0,0,0,0,0,0,0,0
2,6,6,6,6,2,6,7,8,6,2
6,0,0,0,0,6,0,0,0,0,6
6,0,0,0,0,0,0,0,0,0,6
6,0,0,0,0,0,0,0,0,0,6
6,0,0,0,0,6,0,0,0,0,6
2,6,6,6,6,2,0,0,0,0,2
6,0,0,0,0,0,0,0,0,9,6
6,0,0,0,0,0,0,0,0,10,6
6,0,0,0,0,0,0,0,0,0,6
6,0,0,0,0,0,0,0,0,0,6
2,6,6,6,6,2,6,11,12,6,2
0,0,0,0,0,0,0,0,0,0,0
0,0,0,0,0,0,0,0,0,0,0
0,0,0,0,0,0,0,0,0,0,0
:endlayer
layer: 2
0,0,0,0,0,0,0,0,0,0,0
0,0,0,0,0,0,0,0,0,0,0
0,0,0,0,0,0,0,0,0,0,0
2,6,13,13,6,2,6,14,15,6,2
6,0,0,0,0,6,0,0,0,0,6
6,0,0,0,0,0,0,0,0,0,6
6,0,0,0,0,0,0,0,0,0,6
6,0,0,0,0,6,0,0,0,0,6
2,6,6,6,6,2,0,0,0,0,2
6,0,0,0,0,0,0,0,0,0,6
6,0,0,0,0,0,0,0,0,9,6
6,0,0,0,0,0,0,0,0,10,6
6,0,0,0,0,0,0,0,0,0,6
2,6,13,13,6,2,6,15,14,6,2
0,0,0,0,0,0,0,0,0,0,0
0,0,0,0,0,0,0,0,0,0,0
0,0,0,0,0,0,0,0,0,0,0
:endlayer
layer: 3
0,0,0,0,0,0,0,0,0,0,0
0,0,0,0,0,0,0,0,0,0,0
16,0,0,0,0,16,0,0,0,0,16
2,6,13,13,6,2,6,6,6,6,2
6,17,0,0,18,6,0,0,0,0,6
6,0,0,0,0,6,0,0,0,0,6
6,0,0,0,0,6,0,0,0,0,6
6,17,0,0,18,6,0,0,0,0,6
2,6,6,6,6,2,17,0,0,18,2
6,17,0,0,0,19,0,0,0,0,6
6,0,0,0,0,0,0,0,0,0,6
6,0,0,0,0,0,0,0,0,9,6
6,17,0,0,0,16,0,0,0,10,6
2,6,13,13,6,2,6,6,6,6,2
19,0,0,0,0,19,0,0,0,0,19
0,0,0,0,0,0,0,0,0,0,0
0,0,0,0,0,0,0,0,0,0,0
:endlayer
layer: 4
0,0,0,0,0,0,0,0,0,0,0
20,0,0,0,0,20,0,0,0,0,20
4,21,22,21,22,4,22,21,22,21,4
4,3,3,3,3,4,3,3,3,3,4
4,23,5,23,5,4,5,23,5,23,4
4,23,5,23,5,4,5,23,5,23,4
4,23,5,23,5,4,5,23,5,23,4
4,23,5,23,5,4,5,23,5,23,4
2,3,3,3,3,2,3,3,3,3,2
4,23,5,23,5,4,5,23,5,0,4
4,23,5,23,5,4,5,23,5,0,4
4,23,5,23,5,4,5,23,5,0,4
4,23,5,23,5,4,5,23,5,9,4
4,3,3,3,3,4,3,3,3,3,4
4,21,24,21,24,4,24,21,24,21,4
25,0,0,0,0,25,0,0,0,0,25
0,0,0,0,0,0,0,0,0,0,0
:endlayer
layer: 5
0,0,0,0,0,0,0,0,0,0,0
0,0,26,26,0,0,0,26,26,0,0
2,27,27,27,27,2,27,27,27,27,2
27,0,0,0,0,27,0,28,29,0,27
27,0,0,0,0,27,0,0,0,0,27
2,0,0,0,0,2,0,0,0,0,2
27,0,0,0,0,0,0,0,0,0,27
27,0,0,0,0,0,0,0,0,0,27
2,27,27,27,27,2,0,0,13,13,2
27,0,0,0,0,0,0,0,13,0,27
27,0,0,0,0,0,0,0,13,0,27
2,0,0,0,0,2,0,0,13,0,2
27,0,0,0,0,27,0,0,0,0,27
27,0,0,0,0,27,0,0,0,0,27
2,27,27,27,27,2,27,27,27,27,2
0,0,30,30,0,0,0,30,30,0,0
0,0,0,0,0,0,0,0,0,0,0
:endlayer
layer: 6
0,0,0,0,0,0,0,0,0,0,0
0,0,0,0,0,0,0,0,0,0,0
2,27,13,13,27,2,27,13,13,27,2
27,0,0,0,0,27,28,29,0,0,27
27,0,0,0,0,27,0,0,0,0,27
2,0,0,0,0,2,0,0,0,0,2
27,0,0,0,0,0,0,0,0,0,27
27,0,0,0,0,0,0,0,0,0,27
2,27,27,27,27,2,0,0,0,0,2
27,0,0,0,0,0,0,0,0,0,27
27,0,0,0,0,0,0,0,0,0,27
2,0,0,0,0,2,0,0,0,0,2
27,0,0,0,0,27,0,0,0,0,27
27,0,0,0,0,27,0,0,0,0,27
2,27,13,13,27,2,27,13,13,27,2
0,0,0,0,0,0,0,0,0,0,0
0,0,0,0,0,0,0,0,0,0,0
:endlayer
layer: 7
0,0,0,0,0,0,0,0,0,0,0
0,0,0,0,0,0,0,0,0,0,0
2,27,13,13,27,2,27,13,13,27,2
27,0,0,0,0,27,31,0,0,0,27
27,0,0,0,0,27,10,0,0,0,27
2,17,0,0,18,2,17,0,0,18,2
27,0,0,0,0,27,0,0,0,0,27
27,0,0,0,0,27,0,0,0,0,27
2,27,27,27,27,2,17,0,0,18,2
27,0,0,0,0,27,0,0,0,0,27
27,0,0,0,0,27,0,0,0,0,27
2,17,0,0,18,2,17,0,0,18,2
27,0,0,0,0,27,0,0,0,0,27
27,0,0,0,0,27,0,0,0,0,27
2,27,13,13,27,2,27,13,13,27,2
0,0,0,0,0,0,0,0,0,0,0
0,0,0,0,0,0,0,0,0,0,0
:endlayer
layer: 8
0,0,0,0,0,0,0,0,0,0,0
22,0,0,0,0,0,0,0,0,0,22
2,3,3,3,3,2,3,3,3,3,2
4,23,5,23,5,4,0,0,0,0,4
4,23,5,23,5,4,0,10,5,10,4
4,23,5,23,5,4,9,32,5,23,4
4,23,5,23,5,4,5,23,5,23,4
4,23,5,23,5,4,5,23,5,23,4
2,3,3,3,3,2,3,3,3,3,2
4,23,5,23,5,4,5,23,5,23,4
4,23,5,23,5,4,5,23,5,23,4
4,23,5,23,5,4,5,23,5,23,4
4,23,5,23,5,4,5,23,5,23,4
4,23,5,23,5,4,5,23,5,23,4
2,3,3,3,3,2,3,3,3,3,2
24,0,0,0,0,0,0,0,0,0,24
0,0,0,0,0,0,0,0,0,0,0
:endlayer
layer: 9
0,0,0,0,0,0,0,0,0,0,0
33,0,0,26,0,0,0,26,0,0,33
33,2,27,27,27,2,27,27,27,2,33
33,0,0,0,0,13,0,0,0,0,33
33,0,0,0,0,13,0,13,13,13,33
33,0,0,0,0,13,0,13,0,0,33
33,0,0,0,0,0,0,0,0,0,33
33,0,0,0,0,0,0,0,0,0,33
33,2,0,0,0,2,0,0,0,2,33
33,0,0,0,0,0,0,0,0,0,33
33,0,0,0,0,0,0,0,0,0,33
33,0,0,0,0,0,0,0,0,0,33
33,0,0,0,0,0,0,0,0,0,33
33,0,0,0,0,0,34,0,0,0,33
33,2,27,27,27,2,27,27,27,2,33
33,0,0,30,0,0,0,30,0,0,33
0,0,0,0,0,0,0,0,0,0,0
:endlayer
layer: 10
0,0,0,0,0,0,0,0,0,0,0
35,36,0,0,0,0,0,0,0,37,38
35,2,27,13,27,2,27,13,27,2,38
35,4,0,0,0,0,0,0,0,4,38
35,4,0,0,0,0,0,0,0,4,38
35,4,0,0,0,0,0,0,0,4,38
35,4,0,0,0,0,0,0,0,4,38
35,4,0,0,0,0,0,0,0,4,38
35,2,0,0,0,2,0,0,0,2,38
35,4,0,0,0,0,0,0,0,4,38
35,4,0,0,0,0,0,0,0,4,38
35,4,0,0,0,0,0,0,0,4,38
35,4,0,0,0,0,0,0,0,4,38
35,4,0,0,0,0,34,0,0,4,38
35,2,27,13,27,2,27,13,27,2,38
35,36,0,0,0,0,0,0,0,37,38
0,0,0,0,0,0,0,0,0,0,0
:endlayer
layer: 11
0,0,0,0,0,0,0,0,0,0,0
0,33,0,0,0,0,0,0,0,33,0
0,33,2,27,27,2,27,27,2,33,0
0,33,19,0,0,19,0,0,19,33,0
0,33,0,0,0,0,0,0,0,33,0
0,33,0,0,0,0,0,0,0,33,0
0,33,0,0,0,0,0,0,0,33,0
0,33,0,0,0,16,0,0,0,33,0
0,33,2,17,18,2,17,18,2,33,0
0,33,0,0,0,19,0,0,0,33,0
0,33,0,0,0,0,0,0,0,33,0
0,33,0,0,0,0,0,0,0,33,0
0,33,0,0,0,0,0,0,0,33,0
0,33,16,0,0,16,34,0,16,33,0
0,33,2,27,27,2,27,27,2,33,0
0,33,0,0,0,0,0,0,0,33,0
0,0,0,0,0,0,0,0,0,0,0
:endlayer
layer: 12
0,0,0,0,0,0,0,0,0,0,0
0,35,36,0,0,0,0,0,37,38,0
0,35,2,3,3,2,3,3,2,38,0
0,35,4,0,0,0,0,0,4,38,0
0,35,4,0,0,0,0,0,4,38,0
0,35,4,0,0,0,0,0,4,38,0
0,35,4,0,0,0,0,0,4,38,0
0,35,4,0,0,0,0,0,4,38,0
0,35,2,3,3,2,3,3,2,38,0
0,35,4,23,23,23,23,23,4,38,0
0,35,4,5,5,5,5,5,4,38,0
0,35,4,23,23,23,23,23,4,38,0
0,35,4,5,5,5,5,5,4,38,0
0,35,4,23,23,23,34,23,4,38,0
0,35,2,3,3,2,3,3,2,38,0
0,35,36,0,0,0,0,0,37,38,0
0,0,0,0,0,0,0,0,0,0,0
:endlayer
layer: 13
0,0,0,0,0,0,0,0,0,0,0
0,0,33,0,0,0,0,0,33,0,0
0,0,33,2,27,2,27,2,33,0,0
0,0,33,0,0,0,0,0,33,0,0
0,0,33,0,0,0,0,0,33,0,0
0,0,33,0,0,0,0,0,33,0,0
0,0,33,0,0,0,0,0,33,0,0
0,0,33,0,0,0,0,0,33,0,0
0,0,33,2,13,2,13,2,33,0,0
0,0,33,0,0,0,0,0,33,0,0
0,0,33,0,0,0,0,0,33,0,0
0,0,33,0,0,0,0,0,33,0,0
0,0,33,0,0,0,0,0,33,0,0
0,0,33,0,0,0,34,0,33,0,0
0,0,33,2,27,2,27,2,33,0,0
0,0,33,0,0,0,0,0,33,0,0
0,0,0,0,0,0,0,0,0,0,0
:endlayer
layer: 14
0,0,0,0,0,0,0,0,0,0,0
0,0,35,36,0,0,0,37,38,0,0
0,0,35,2,27,2,27,2,38,0,0
0,0,35,4,0,0,0,4,38,0,0
0,0,35,4,0,0,0,4,38,0,0
0,0,35,4,0,0,0,4,38,0,0
0,0,35,4,0,0,0,4,38,0,0
0,0,35,4,0,0,0,4,38,0,0
0,0,35,2,0,2,0,2,38,0,0
0,0,35,4,0,19,0,4,38,0,0
0,0,35,4,0,0,0,4,38,0,0
0,0,35,4,0,0,0,4,38,0,0
0,0,35,4,0,0,0,4,38,0,0
0,0,35,4,0,16,34,4,38,0,0
0,0,35,2,27,2,27,2,38,0,0
0,0,35,36,0,0,0,37,38,0,0
0,0,0,0,0,0,0,0,0,0,0
:endlayer
layer: 15
0,0,0,0,0,0,0,0,0,0,0
0,0,0,33,0,0,0,33,0,0,0
0,0,0,33,2,27,2,33,0,0,0
0,0,0,33,0,0,0,33,0,0,0
0,0,0,33,0,0,0,33,0,0,0
0,0,0,33,0,0,0,33,0,0,0
0,0,0,33,0,0,0,33,0,0,0
0,0,0,33,0,0,0,33,0,0,0
0,0,0,33,2,13,2,33,0,0,0
0,0,0,33,0,0,0,33,0,0,0
0,0,0,33,0,0,0,33,0,0,0
0,0,0,33,0,0,0,33,0,0,0
0,0,0,33,0,0,0,33,0,0,0
0,0,0,33,0,0,34,33,0,0,0
0,0,0,33,2,27,2,33,0,0,0
0,0,0,33,0,0,0,33,0,0,0
0,0,0,0,0,0,0,0,0,0,0
:endlayer
layer: 16
0,0,0,0,0,0,0,0,0,0,0
0,0,0,35,36,0,37,38,0,0,0
0,0,0,35,2,27,2,38,0,0,0
0,0,0,35,4,0,4,38,0,0,0
0,0,0,35,4,0,4,38,0,0,0
0,0,0,35,4,0,4,38,0,0,0
0,0,0,35,4,0,4,38,0,0,0
0,0,0,35,4,0,4,38,0,0,0
0,0,0,35,2,13,2,38,0,0,0
0,0,0,35,4,0,4,38,0,0,0
0,0,0,35,4,0,4,38,0,0,0
0,0,0,35,4,0,4,38,0,0,0
0,0,0,35,4,0,4,38,0,0,0
0,0,0,35,4,0,4,38,0,0,0
0,0,0,35,2,27,2,38,0,0,0
0,0,0,35,36,0,37,38,0,0,0
0,0,0,0,0,0,0,0,0,0,0
:endlayer
layer: 17
0,0,0,0,0,0,0,0,0,0,0
0,0,0,0,33,22,33,0,0,0,0
0,0,0,0,33,2,33,0,0,0,0
0,0,0,0,33,0,33,0,0,0,0
0,0,0,0,33,0,33,0,0,0,0
0,0,0,0,33,0,33,0,0,0,0
0,0,0,0,33,0,33,0,0,0,0
0,0,0,0,33,0,33,0,0,0,0
0,0,0,0,33,2,33,0,0,0,0
0,0,0,0,33,0,33,0,0,0,0
0,0,0,0,33,0,33,0,0,0,0
0,0,0,0,33,0,33,0,0,0,0
0,0,0,0,33,0,33,0,0,0,0
0,0,0,0,33,0,33,0,0,0,0
0,0,0,0,33,2,33,0,0,0,0
0,0,0,0,33,24,33,0,0,0,0
0,0,0,0,0,0,0,0,0,0,0
:endlayer
layer: 18
0,0,0,0,0,0,0,0,0,0,0
0,0,0,0,35,33,38,0,0,0,0
0,0,0,0,35,2,38,0,0,0,0
0,0,0,0,35,4,38,0,0,0,0
0,0,0,0,35,4,38,0,0,0,0
0,0,0,0,35,4,38,0,0,0,0
0,0,0,0,35,4,38,0,0,0,0
0,0,0,0,35,4,38,0,0,0,0
0,0,0,0,35,2,38,0,0,0,0
0,0,0,0,35,4,38,0,0,0,0
0,0,0,0,35,4,38,0,0,0,0
0,0,0,0,35,4,38,0,0,0,0
0,0,0,0,35,4,38,0,0,0,0
0,0,0,0,35,4,38,0,0,0,0
0,0,0,0,35,2,38,0,0,0,0
0,0,0,0,35,33,38,0,0,0,0
0,0,0,0,0,0,0,0,0,0,0
:endlayer
layer: 19
0,0,0,0,0,0,0,0,0,0,0
0,0,0,0,0,39,0,0,0,0,0
0,0,0,0,0,33,0,0,0,0,0
0,0,0,0,0,33,0,0,0,0,0
0,0,0,0,0,33,0,0,0,0,0
0,0,0,0,0,33,0,0,0,0,0
0,0,0,0,0,33,0,0,0,0,0
0,0,0,0,0,33,0,0,0,0,0
0,0,0,0,0,33,0,0,0,0,0
0,0,0,0,0,33,0,0,0,0,0
0,0,0,0,0,33,0,0,0,0,0
0,0,0,0,0,33,0,0,0,0,0
0,0,0,0,0,33,0,0,0,0,0
0,0,0,0,0,33,0,0,0,0,0
0,0,0,0,0,33,0,0,0,0,0
0,0,0,0,0,40,0,0,0,0,0
0,0,0,0,0,0,0,0,0,0,0
:endlayer
layer: 20
0,0,0,0,0,0,0,0,0,0,0
0,0,0,0,0,0,0,0,0,0,0
0,0,0,0,0,0,0,0,0,0,0
0,0,0,0,0,41,0,0,0,0,0
0,0,0,0,0,0,0,0,0,0,0
0,0,0,0,0,0,0,0,0,0,0
0,0,0,0,0,0,0,0,0,0,0
0,0,0,0,0,0,0,0,0,0,0
0,0,0,0,0,0,0,0,0,0,0
0,0,0,0,0,0,0,0,0,0,0
0,0,0,0,0,0,0,0,0,0,0
0,0,0,0,0,0,0,0,0,0,0
0,0,0,0,0,0,0,0,0,0,0
0,0,0,0,0,41,0,0,0,0,0
0,0,0,0,0,0,0,0,0,0,0
0,0,0,0,0,0,0,0,0,0,0
0,0,0,0,0,0,0,0,0,0,0
:endlayer

#### RULES ####
rule:
plugin=vanillaBlocks
number=1
data:
JSON:{blockState:{blockName:"minecraft:grass",properties:{snowy:"false"}}}
:enddata
:endrule

rule:
plugin=vanillaBlocks
number=2
data:
JSON:{blockState:{blockName:"minecraft:log",properties:{variant:"spruce",axis:"y"}}}
:enddata
:endrule

rule:
plugin=vanillaBlocks
number=3
data:
JSON:{blockState:{blockName:"minecraft:log",properties:{variant:"spruce",axis:"x"}}}
:enddata
:endrule

rule:
plugin=vanillaBlocks
number=4
data:
JSON:{blockState:{blockName:"minecraft:log",properties:{variant:"spruce",axis:"z"}}}
:enddata
:endrule

rule:
plugin=vanillaBlocks
number=5
data:
JSON:{blockState:{blockName:"minecraft:planks",properties:{variant:"dark_oak"}}}
:enddata
:endrule

rule:
plugin=vanillaBlocks
number=6
data:
JSON:{blockState:{blockName:"minecraft:cobblestone"}}
:enddata
:endrule

rule:
plugin=doors
number=7
data:
JSON:{blockState:{blockName:"minecraft:spruce_door",properties:{hinge:"right",half:"lower",powered:"false",facing:"south",open:"false"}}}
:enddata
:endrule

rule:
plugin=doors
number=8
data:
JSON:{blockState:{blockName:"minecraft:spruce_door",properties:{hinge:"left",half:"lower",powered:"false",facing:"south",open:"false"}}}
:enddata
:endrule

rule:
plugin=vanillaBlocks
number=9
data:
JSON:{blockState:{blockName:"minecraft:dark_oak_stairs",properties:{half:"bottom",shape:"straight",facing:"south"}}}
:enddata
:endrule

rule:
plugin=vanillaBlocks
number=10
data:
JSON:{blockState:{blockName:"minecraft:dark_oak_stairs",properties:{half:"top",shape:"straight",facing:"north"}}}
:enddata
:endrule

rule:
plugin=doors
number=11
data:
JSON:{blockState:{blockName:"minecraft:spruce_door",properties:{hinge:"left",half:"lower",powered:"false",facing:"north",open:"false"}}}
:enddata
:endrule

rule:
plugin=doors
number=12
data:
JSON:{blockState:{blockName:"minecraft:spruce_door",properties:{hinge:"right",half:"lower",powered:"false",facing:"north",open:"false"}}}
:enddata
:endrule

rule:
plugin=vanillaBlocks
number=13
data:
JSON:{blockState:{blockName:"minecraft:acacia_fence",properties:{east:"false",south:"false",north:"false",west:"false"}}}
:enddata
:endrule

rule:
plugin=doors
number=14
data:
JSON:{blockState:{blockName:"minecraft:spruce_door",properties:{hinge:"right",half:"upper",powered:"false",facing:"north",open:"false"}}}
:enddata
:endrule

rule:
plugin=doors
number=15
data:
JSON:{blockState:{blockName:"minecraft:spruce_door",properties:{hinge:"left",half:"upper",powered:"false",facing:"north",open:"false"}}}
:enddata
:endrule

rule:
plugin=vanillaBlocks
number=16
data:
JSON:{blockState:{blockName:"minecraft:torch",properties:{facing:"north"}}}
:enddata
:endrule

rule:
plugin=vanillaBlocks
number=17
data:
JSON:{blockState:{blockName:"minecraft:torch",properties:{facing:"east"}}}
:enddata
:endrule

rule:
plugin=vanillaBlocks
number=18
data:
JSON:{blockState:{blockName:"minecraft:torch",properties:{facing:"west"}}}
:enddata
:endrule

rule:
plugin=vanillaBlocks
number=19
data:
JSON:{blockState:{blockName:"minecraft:torch",properties:{facing:"south"}}}
:enddata
:endrule

rule:
plugin=vanillaBlocks
number=20
data:
JSON:{blockState:{blockName:"minecraft:wooden_button",properties:{powered:"false",facing:"north"}}}
:enddata
:endrule

rule:
plugin=vanillaBlocks
number=21
data:
JSON:{blockState:{blockName:"minecraft:wooden_slab",properties:{half:"top",variant:"spruce"}}}
:enddata
:endrule

rule:
plugin=vanillaBlocks
number=22
data:
JSON:{blockState:{blockName:"minecraft:spruce_stairs",properties:{half:"top",shape:"straight",facing:"south"}}}
:enddata
:endrule

rule:
plugin=vanillaBlocks
number=23
data:
JSON:{blockState:{blockName:"minecraft:wooden_slab",properties:{half:"top",variant:"dark_oak"}}}
:enddata
:endrule

rule:
plugin=vanillaBlocks
number=24
data:
JSON:{blockState:{blockName:"minecraft:spruce_stairs",properties:{half:"top",shape:"straight",facing:"north"}}}
:enddata
:endrule

rule:
plugin=vanillaBlocks
number=25
data:
JSON:{blockState:{blockName:"minecraft:wooden_button",properties:{powered:"false",facing:"south"}}}
:enddata
:endrule

rule:
plugin=vanillaBlocks
number=26
data:
JSON:{blockState:{blockName:"minecraft:oak_stairs",properties:{half:"top",shape:"straight",facing:"south"}}}
:enddata
:endrule

rule:
plugin=vanillaBlocks
number=27
data:
JSON:{blockState:{blockName:"minecraft:planks",properties:{variant:"oak"}}}
:enddata
:endrule

rule:
plugin=vanillaBlocks
number=28
data:
JSON:{blockState:{blockName:"minecraft:dark_oak_stairs",properties:{half:"top",shape:"straight",facing:"east"}}}
:enddata
:endrule

rule:
plugin=vanillaBlocks
number=29
data:
JSON:{blockState:{blockName:"minecraft:dark_oak_stairs",properties:{half:"bottom",shape:"straight",facing:"west"}}}
:enddata
:endrule

rule:
plugin=vanillaBlocks
number=30
data:
JSON:{blockState:{blockName:"minecraft:oak_stairs",properties:{half:"top",shape:"straight",facing:"north"}}}
:enddata
:endrule

rule:
plugin=vanillaBlocks
number=31
data:
JSON:{blockState:{blockName:"minecraft:wooden_slab",properties:{half:"bottom",variant:"dark_oak"}}}
:enddata
:endrule

rule:
plugin=vanillaBlocks
number=32
data:
JSON:{blockState:{blockName:"minecraft:dark_oak_stairs",properties:{half:"top",shape:"straight",facing:"west"}}}
:enddata
:endrule

rule:
plugin=vanillaBlocks
number=33
data:
JSON:{blockState:{blockName:"minecraft:planks",properties:{variant:"spruce"}}}
:enddata
:endrule

rule:
plugin=vanillaBlocks
number=34
data:
JSON:{blockState:{blockName:"minecraft:ladder",properties:{facing:"north"}}}
:enddata
:endrule

rule:
plugin=vanillaBlocks
number=35
data:
JSON:{blockState:{blockName:"minecraft:spruce_stairs",properties:{half:"bottom",shape:"straight",facing:"east"}}}
:enddata
:endrule

rule:
plugin=vanillaBlocks
number=36
data:
JSON:{blockState:{blockName:"minecraft:spruce_stairs",properties:{half:"top",shape:"straight",facing:"west"}}}
:enddata
:endrule

rule:
plugin=vanillaBlocks
number=37
data:
JSON:{blockState:{blockName:"minecraft:spruce_stairs",properties:{half:"top",shape:"straight",facing:"east"}}}
:enddata
:endrule

rule:
plugin=vanillaBlocks
number=38
data:
JSON:{blockState:{blockName:"minecraft:spruce_stairs",properties:{half:"bottom",shape:"straight",facing:"west"}}}
:enddata
:endrule

rule:
plugin=vanillaBlocks
number=39
data:
JSON:{blockState:{blockName:"minecraft:spruce_stairs",properties:{half:"bottom",shape:"straight",facing:"south"}}}
:enddata
:endrule

rule:
plugin=vanillaBlocks
number=40
data:
JSON:{blockState:{blockName:"minecraft:spruce_stairs",properties:{half:"bottom",shape:"straight",facing:"north"}}}
:enddata
:endrule

rule:
plugin=vanillaBlocks
number=41
data:
JSON:{blockState:{blockName:"minecraft:torch",properties:{facing:"up"}}}
:enddata
:endrule

#### ENTITIES ####
