# Ancient Warfare Structure Template File
# Auto-generated structure template file. created on: 9/23/2023 at: 22:22:55
# Lines beginning with # denote comments

header:
version=2.11
name=SB_KievarusCol_SmithyHouse_1H4R_1_ironwood
mods=rustic
size=30,17,21
offset=14,1,20
:endheader

#### VALIDATION ####
validation:
type=ground
structureAuthor=TheOddlySeagull
survival=true
worldGenEnabled=false
unique=false
preserveBlocks=false
preventNaturalHostileSpawns=false
selectionWeight=1
clusterValue=1
minDuplicateDistance=1
dimensionWhiteList=true
dimensionList=
biomeGroupList=
biomeWhiteList=true
biomeList=
leveling=0
fill=0
border=0
blockSwap=false
territoryName=
biomeReplacement=minecraft:
minGenerationHeight=0
maxGenerationHeight=255
:endvalidation

#### LAYERS ####
layer: 0
1,1,1,1,1,1,1,1,1,4,2,2,4,1,1,1,1,1,1,1,1,1,1,1,1,1,1,1,1,1
1,1,1,1,1,1,1,1,1,4,2,2,4,1,1,1,1,1,1,2,1,1,1,1,1,1,1,2,1,1
1,1,1,2,2,2,2,2,2,2,4,4,4,4,4,2,2,2,2,2,2,2,2,2,2,2,2,2,2,1
1,1,1,2,2,3,3,2,2,2,3,3,3,2,3,2,2,3,2,2,2,2,2,2,2,3,2,2,1,1
1,1,1,2,2,2,2,3,2,2,2,3,2,2,3,2,3,3,2,2,2,2,3,2,3,2,3,2,1,1
1,1,1,2,2,3,3,3,2,2,2,2,2,3,2,2,2,3,2,2,3,2,2,3,2,2,2,2,1,1
1,1,2,2,2,2,2,2,2,2,2,2,2,2,2,2,3,3,2,2,3,3,2,3,2,2,3,2,1,1
1,2,2,2,2,2,3,3,3,2,2,2,3,2,2,2,3,3,3,2,3,2,3,2,3,3,3,2,1,1
1,2,2,2,2,2,2,2,3,2,3,2,2,2,2,2,2,2,3,2,3,3,3,2,3,3,3,2,1,1
1,2,2,2,2,2,2,2,3,2,3,2,3,3,3,2,2,3,3,2,2,3,2,3,3,2,3,2,1,1
1,1,2,2,2,3,2,2,3,2,2,3,2,2,3,2,2,2,3,2,2,2,2,2,2,2,3,2,1,1
1,1,1,2,2,2,2,3,2,2,4,4,4,4,4,2,2,2,2,2,3,3,3,3,2,2,3,2,2,1
1,1,1,2,3,2,3,2,2,2,4,2,5,5,2,2,2,5,5,2,2,2,2,3,2,2,3,2,1,1
1,1,1,2,2,3,3,2,2,2,4,5,5,5,2,2,5,2,2,2,3,2,3,3,3,3,3,2,1,1
1,1,1,2,2,2,2,2,2,2,4,2,2,5,2,2,5,2,5,2,3,2,3,2,3,3,2,2,1,1
1,1,1,1,1,1,1,1,1,1,4,2,5,5,2,5,2,2,5,2,2,2,2,2,3,3,2,2,1,1
1,1,1,1,1,2,2,2,2,1,4,5,5,5,2,2,5,2,5,2,3,2,2,3,3,3,2,2,1,1
1,1,1,1,1,2,0,0,2,1,4,5,5,5,2,5,5,2,2,2,3,2,2,2,2,3,3,2,1,1
1,1,1,1,1,2,0,0,2,1,4,4,4,4,2,2,4,4,2,2,2,2,2,2,2,2,2,2,2,1
1,1,1,1,1,2,2,2,2,1,1,1,1,4,2,2,4,1,1,2,1,1,1,1,1,1,1,2,1,1
1,1,1,1,1,1,1,1,1,1,1,1,1,4,2,2,4,1,1,1,1,1,1,1,1,1,1,1,1,1
:endlayer
layer: 1
0,0,0,0,0,0,0,0,0,0,0,0,0,0,0,0,0,0,0,0,0,0,0,0,0,0,0,0,0,0
0,0,0,0,0,0,0,0,0,0,0,0,0,0,0,0,0,0,0,6,0,0,0,0,0,0,0,6,0,0
0,0,0,6,9,9,9,9,9,6,16,16,4,4,4,6,2,2,6,6,10,6,10,10,10,6,10,6,6,0
0,0,0,7,10,10,4,5,5,7,5,2,5,5,2,2,3,2,3,10,3,3,3,3,3,3,3,10,0,0
0,0,0,7,10,10,4,2,5,7,2,2,5,5,5,2,3,3,3,6,3,2,2,3,3,2,2,6,0,0
0,0,0,7,4,4,4,2,2,7,5,2,2,5,2,2,2,3,3,10,2,3,3,2,3,2,3,10,0,0
0,0,4,4,4,2,5,2,5,7,5,2,5,2,2,2,2,2,3,10,3,2,2,3,2,3,3,10,0,0
0,4,4,4,4,5,5,5,2,7,5,5,2,2,5,2,3,3,3,10,2,3,2,3,3,2,2,10,0,0
0,4,4,4,4,2,2,2,2,7,2,5,5,5,5,2,3,3,3,10,2,2,3,3,3,2,3,10,0,0
0,4,4,4,4,2,5,5,5,7,2,5,5,5,2,2,2,2,2,6,3,2,2,3,2,2,3,6,0,0
0,0,4,4,4,2,2,5,5,7,2,2,2,2,5,2,3,2,2,10,2,2,3,2,3,3,3,10,0,0
0,0,0,7,5,5,5,2,2,7,15,15,15,15,15,6,2,2,6,6,3,2,3,2,2,2,3,6,6,0
0,0,0,7,5,5,2,2,5,7,0,0,0,0,0,0,0,0,0,10,3,3,2,3,2,2,3,10,0,0
0,0,0,7,2,2,5,2,2,7,0,0,0,0,0,0,0,0,0,6,2,3,3,2,3,2,3,10,0,0
0,0,0,6,9,9,9,9,9,6,0,0,0,0,0,0,0,0,0,10,2,2,2,2,3,2,2,10,0,0
0,0,0,0,0,0,0,0,0,0,0,0,0,0,0,0,0,0,0,10,3,2,3,2,3,2,3,10,0,0
0,0,0,0,0,2,13,13,2,0,0,0,0,0,0,0,0,0,0,6,3,3,2,3,2,2,3,6,0,0
0,0,0,0,0,11,0,0,14,0,0,0,0,0,0,0,0,0,0,10,3,3,2,2,3,2,3,10,0,0
0,0,0,0,0,11,0,0,14,0,0,0,0,17,0,0,17,0,6,6,10,6,10,10,10,6,10,6,6,0
0,0,0,0,8,2,12,12,2,0,0,0,0,0,0,0,0,0,0,6,0,0,0,0,0,0,0,6,0,0
0,0,0,0,0,0,0,0,0,0,0,0,0,0,0,0,0,0,0,0,0,0,0,0,0,0,0,0,0,0
:endlayer
layer: 2
0,0,0,0,0,0,0,0,0,0,0,0,0,0,0,0,0,0,0,0,0,0,0,0,0,0,0,0,0,0
0,0,0,0,0,0,0,0,0,0,0,0,0,0,0,0,0,0,0,6,0,0,0,0,0,0,0,6,0,0
0,0,0,6,10,10,6,10,10,6,0,0,17,17,17,6,2,2,6,6,9,9,9,9,9,9,9,6,6,0
0,0,0,10,0,0,18,0,0,0,0,0,0,0,0,19,5,5,5,7,10,10,10,10,10,10,10,7,0,0
0,0,0,10,0,0,18,0,0,0,0,0,0,0,0,19,5,2,5,7,10,10,10,10,10,10,10,7,0,0
0,0,0,6,4,15,15,0,0,0,0,0,0,0,0,19,5,2,5,7,10,10,10,10,10,10,10,7,0,0
0,0,4,4,4,0,0,0,0,6,0,0,0,0,0,6,5,5,5,7,10,10,10,10,10,10,10,7,0,0
0,4,0,0,4,0,0,0,0,0,0,0,0,0,0,2,2,5,5,7,10,10,10,10,10,10,10,7,0,0
0,4,0,0,4,0,0,0,0,0,0,0,0,0,0,2,5,2,5,7,10,10,10,10,10,10,10,7,0,0
0,4,0,0,4,0,0,0,0,0,0,0,0,0,0,2,5,2,5,7,10,10,10,10,10,10,10,7,0,0
0,0,4,4,4,0,0,0,0,6,0,0,0,0,0,2,2,2,2,7,10,10,10,10,10,10,10,7,0,0
0,0,0,6,17,0,0,0,0,10,0,0,0,0,0,6,2,2,6,7,9,9,9,9,9,9,9,7,6,0
0,0,0,10,0,0,0,0,0,10,0,0,0,0,0,0,0,0,0,7,10,10,10,7,10,10,10,7,0,0
0,0,0,10,0,0,0,0,0,10,0,0,0,0,0,0,0,0,0,7,10,10,10,7,10,10,10,7,0,0
0,0,0,6,10,10,6,10,10,6,0,0,0,0,0,0,0,0,0,7,10,10,10,7,10,10,10,7,0,0
0,0,0,0,0,0,0,0,0,0,0,0,0,0,0,0,0,0,0,7,10,10,10,7,10,10,10,7,0,0
0,0,0,0,0,17,0,0,17,0,0,0,0,0,0,0,0,0,0,7,10,10,10,7,10,10,10,7,0,0
0,0,0,0,0,0,0,0,0,0,0,0,0,0,0,0,0,0,0,7,10,10,10,7,10,10,10,7,0,0
0,0,0,0,0,0,0,0,0,0,0,0,0,8,0,0,8,0,6,6,9,9,9,9,9,9,9,6,6,0
0,0,0,0,0,17,0,0,17,0,0,0,0,0,0,0,0,0,0,6,0,0,0,0,0,0,0,6,0,0
0,0,0,0,0,0,0,0,0,0,0,0,0,0,0,0,0,0,0,0,0,0,0,0,0,0,0,0,0,0
:endlayer
layer: 3
0,0,0,0,0,0,0,0,0,0,0,0,0,0,0,0,0,0,0,0,0,0,0,0,0,0,0,0,0,0
0,0,0,22,0,0,0,0,0,22,0,0,0,0,0,22,0,0,0,6,23,0,0,0,0,0,20,6,0,0
0,0,20,6,10,10,6,10,10,6,23,0,0,0,0,6,17,17,6,6,10,6,10,10,10,6,10,6,6,0
0,0,0,10,0,0,0,0,0,0,0,0,0,0,0,0,0,0,0,10,0,0,0,0,0,0,0,10,21,0
0,0,0,10,0,0,0,0,0,0,0,0,0,0,0,0,0,0,0,6,0,0,0,0,0,0,25,10,0,0
0,0,0,6,17,0,0,0,0,0,0,0,0,0,0,0,0,0,0,10,0,0,0,0,0,0,24,10,0,0
0,0,4,4,4,23,0,0,0,6,0,0,0,0,0,6,0,0,0,0,0,0,0,0,0,0,20,6,0,0
0,4,0,0,0,0,0,0,0,0,0,0,0,0,0,17,0,0,0,0,0,0,0,0,0,0,0,10,0,0
20,4,0,0,0,0,0,0,0,0,0,0,0,0,0,17,0,0,0,10,0,0,0,0,0,0,0,10,0,0
0,4,0,0,0,0,0,0,0,0,0,0,0,0,0,17,0,0,0,6,0,0,0,0,0,0,0,10,0,0
0,0,4,4,4,23,0,0,0,6,0,0,0,0,0,17,0,0,0,10,0,0,0,0,0,0,0,10,22,0
0,0,0,6,17,0,0,0,0,10,0,0,0,0,0,6,17,17,6,6,0,0,0,6,0,0,0,6,6,0
0,0,0,10,0,0,0,0,0,17,0,0,0,0,0,21,0,0,21,10,0,0,0,10,0,0,0,10,21,0
0,0,0,10,0,0,0,0,0,10,0,0,0,0,0,0,0,0,0,10,0,0,0,6,0,0,0,10,0,0
0,0,20,6,10,10,6,10,10,6,23,0,0,0,0,0,0,0,0,10,0,0,0,10,0,0,0,10,0,0
0,0,0,21,0,0,0,0,0,21,0,0,0,0,0,0,0,0,0,10,0,0,0,10,0,0,0,10,0,0
0,0,0,0,0,17,0,0,17,0,0,0,0,0,0,0,0,0,0,10,0,0,0,6,0,0,0,6,0,0
0,0,0,0,0,0,0,0,0,0,0,0,0,0,0,0,0,0,22,10,0,0,0,10,0,0,0,10,22,0
0,0,0,0,0,0,0,0,0,0,0,0,0,0,0,0,0,0,6,6,10,10,10,6,10,10,10,6,6,0
0,0,0,0,0,17,0,0,17,0,0,0,0,0,0,0,0,0,0,6,23,0,0,0,0,0,20,6,0,0
0,0,0,0,0,0,0,0,0,0,0,0,0,0,0,0,0,0,0,0,0,0,0,0,0,0,0,0,0,0
:endlayer
layer: 4
0,0,0,0,0,0,0,0,0,0,0,0,0,0,0,0,0,0,0,0,0,0,0,0,0,0,0,0,0,0
0,0,0,0,0,0,0,0,0,0,0,0,0,0,0,0,0,0,0,6,0,0,0,0,0,0,0,6,0,0
0,0,0,6,10,10,6,10,10,6,0,0,0,0,0,6,0,0,6,6,10,6,10,17,10,6,10,6,6,0
0,0,0,10,0,0,21,0,0,24,0,0,0,0,0,0,0,0,0,10,0,0,0,0,0,0,0,10,0,0
0,0,0,10,0,0,0,0,0,32,0,0,0,0,0,0,0,0,0,6,0,0,0,0,0,0,0,10,0,0
0,0,0,6,17,0,0,0,0,31,0,0,0,0,0,0,0,0,0,10,0,0,0,0,0,0,25,10,0,0
0,0,19,4,18,0,0,0,20,6,23,0,0,0,20,6,0,0,0,0,0,0,0,0,0,0,24,6,0,0
0,19,27,0,28,0,0,0,0,24,0,0,0,0,0,0,0,0,0,0,0,0,0,0,0,0,0,10,0,0
0,4,0,0,29,0,0,0,0,32,0,0,0,0,0,0,0,0,0,10,0,0,0,0,0,0,0,17,0,0
0,19,26,0,28,0,0,0,0,31,0,0,0,0,0,0,0,0,0,6,0,0,0,0,0,0,0,17,0,0
0,0,19,4,18,0,0,0,20,6,23,0,0,0,0,0,0,0,0,10,0,0,0,0,0,0,0,10,0,0
0,0,0,6,17,0,0,0,0,10,0,0,0,0,0,6,0,0,6,6,0,0,0,6,0,0,0,6,6,0
0,0,0,10,0,0,0,0,0,10,0,0,0,0,0,0,0,0,0,10,0,0,0,10,0,0,0,10,0,0
0,0,0,10,0,0,22,0,0,10,0,0,0,0,0,0,0,0,0,17,0,0,0,6,0,0,0,17,0,0
0,0,0,6,10,10,6,10,10,6,0,0,0,0,0,0,0,0,0,10,0,0,0,10,0,0,0,17,0,0
0,0,0,0,0,0,0,0,0,0,0,0,0,0,0,0,0,0,0,10,0,0,0,10,0,0,0,10,0,0
0,0,0,0,0,30,0,0,30,0,0,0,0,0,0,0,0,0,0,17,0,0,0,6,0,0,0,6,0,0
0,0,0,0,0,30,0,0,30,0,0,0,0,0,0,0,0,0,0,10,0,0,0,10,0,0,0,10,0,0
0,0,0,0,0,30,0,0,30,0,0,0,0,0,0,0,0,0,6,6,10,17,10,6,10,17,10,6,6,0
0,0,0,0,0,30,0,0,30,0,0,0,0,0,0,0,0,0,0,6,0,0,0,0,0,0,0,6,0,0
0,0,0,0,0,0,0,0,0,0,0,0,0,0,0,0,0,0,0,0,0,0,0,0,0,0,0,0,0,0
:endlayer
layer: 5
0,0,0,0,0,0,0,0,0,0,0,0,0,0,0,0,0,0,0,0,0,0,0,0,0,0,0,0,0,0
0,0,0,0,0,0,0,0,0,0,0,0,0,0,0,0,0,0,0,6,0,0,0,0,0,0,0,6,0,0
0,0,0,6,9,9,9,9,9,6,0,0,0,0,30,6,0,0,6,6,10,6,10,10,10,6,10,6,6,0
0,0,0,7,0,0,0,0,0,7,0,0,0,0,30,0,0,0,0,10,0,21,0,0,0,21,0,10,0,0
0,0,0,7,0,0,0,0,0,7,0,0,0,0,30,0,0,0,20,6,23,0,0,0,0,0,0,10,0,0
0,0,0,6,17,0,0,0,0,7,0,0,0,0,30,0,0,0,0,10,0,0,0,0,0,0,0,10,0,0
0,0,0,4,0,0,0,0,0,7,0,0,0,0,30,6,0,0,0,10,0,0,0,0,0,0,25,6,0,0
0,0,16,4,33,0,0,0,0,7,0,0,0,0,30,0,0,0,0,10,0,0,0,0,0,0,24,10,0,0
0,19,0,4,33,0,0,0,0,7,0,0,0,0,30,0,0,0,0,10,0,0,0,0,0,0,0,10,0,0
0,0,15,4,33,0,0,0,0,7,0,0,0,0,30,0,0,0,20,6,23,0,0,0,0,0,0,10,0,0
0,0,0,4,0,0,0,0,0,7,0,0,0,0,30,0,0,0,0,10,0,0,0,22,0,0,0,10,0,0
0,0,0,6,17,0,0,0,0,7,0,0,0,0,30,6,0,0,6,6,34,32,35,6,34,32,35,6,6,0
0,0,0,7,0,0,0,0,0,7,0,0,0,0,0,0,0,0,0,10,0,0,0,10,0,0,0,10,0,0
0,0,0,7,0,0,0,0,0,7,0,0,0,0,0,0,0,0,0,10,0,0,0,6,0,0,0,10,0,0
0,0,0,6,9,9,9,9,9,6,0,0,0,0,0,0,0,0,0,10,0,0,0,10,0,0,0,10,0,0
0,0,0,0,0,0,0,0,0,0,0,0,0,0,0,0,0,0,0,10,0,0,20,10,0,0,0,10,0,0
0,0,0,0,0,0,30,30,0,0,0,0,0,0,0,0,0,0,0,10,0,0,0,6,23,0,20,6,0,0
0,0,0,0,0,8,30,30,0,0,0,0,0,0,0,0,0,0,0,10,0,0,0,10,0,0,0,10,0,0
0,0,0,0,0,0,30,30,8,0,0,0,0,0,0,0,0,0,6,6,10,10,10,6,10,10,10,6,6,0
0,0,0,0,0,0,30,30,0,0,0,0,0,0,0,0,0,0,0,6,0,0,0,0,0,0,0,6,0,0
0,0,0,0,0,0,0,0,0,0,0,0,0,0,0,0,0,0,0,0,0,0,0,0,0,0,0,0,0,0
:endlayer
layer: 6
0,0,0,0,0,0,0,0,0,0,0,0,0,0,0,0,0,0,0,0,0,0,0,0,0,0,0,0,0,0
0,0,30,17,0,0,0,0,0,17,30,0,0,0,0,0,0,0,0,6,0,0,0,0,0,0,0,6,0,0
0,0,30,6,17,17,6,17,17,6,30,0,0,0,0,30,30,0,6,6,9,9,9,9,9,9,9,6,6,0
0,0,30,10,0,0,0,0,0,10,30,0,0,0,0,30,30,0,0,7,32,32,32,32,32,34,0,7,0,0
0,0,30,10,0,0,0,0,0,10,30,0,0,0,0,30,30,0,0,7,10,10,10,10,10,34,0,7,0,0
0,0,30,6,17,0,0,0,0,10,30,0,0,0,0,30,30,0,0,7,32,32,32,32,32,34,0,7,0,0
0,0,30,4,0,0,0,0,0,6,30,0,0,0,0,30,30,0,0,7,10,10,10,10,10,34,0,7,0,0
0,0,30,4,0,0,0,0,0,10,30,0,0,0,0,30,30,0,0,7,32,32,32,32,32,10,25,7,0,0
0,0,4,4,0,0,0,0,0,10,30,0,0,0,0,30,30,0,0,7,10,10,10,10,10,10,10,7,0,0
0,0,30,4,0,0,0,0,0,10,30,0,0,0,0,30,30,0,0,7,32,32,32,32,32,32,32,7,0,0
0,0,30,4,0,0,0,0,0,6,30,0,0,0,0,30,30,0,0,7,10,10,10,10,10,10,10,7,0,0
0,0,30,6,17,0,0,0,0,10,30,0,0,0,0,30,30,0,6,7,9,9,9,9,9,9,9,6,6,0
0,0,30,10,0,0,0,0,0,10,30,0,0,0,0,0,0,0,30,7,10,10,10,7,10,10,10,7,30,0
0,0,30,10,0,0,0,0,0,10,30,0,0,0,0,0,0,0,30,7,32,32,32,7,32,32,32,7,30,0
0,0,30,6,17,17,6,17,17,6,30,0,0,0,0,0,0,0,30,7,10,10,10,7,10,10,10,7,30,0
0,0,30,17,0,0,0,0,0,17,30,0,0,0,0,0,0,0,30,7,32,32,32,7,32,32,32,7,30,0
0,0,0,0,0,0,0,0,0,0,0,0,0,0,0,0,0,0,30,7,10,10,10,7,10,10,10,7,30,0
0,0,0,0,0,0,0,0,0,0,0,0,0,0,0,0,0,0,30,7,32,32,32,7,32,32,32,7,30,0
0,0,0,0,0,0,0,0,0,0,0,0,0,0,0,0,0,0,30,6,9,9,9,9,9,9,9,6,30,0
0,0,0,0,0,0,0,0,0,0,0,0,0,0,0,0,0,0,30,6,0,0,0,0,0,0,0,6,30,0
0,0,0,0,0,0,0,0,0,0,0,0,0,0,0,0,0,0,0,0,0,0,0,0,0,0,0,0,0,0
:endlayer
layer: 7
0,0,0,0,0,0,0,0,0,0,0,0,0,0,0,0,0,0,0,0,0,0,0,0,0,0,0,0,0,0
0,0,0,30,31,0,0,0,31,30,0,0,0,0,0,0,0,0,0,6,0,0,0,0,0,0,0,6,0,0
0,0,0,30,9,9,9,9,9,30,0,0,0,0,0,0,0,30,6,6,10,6,10,10,10,6,10,6,6,0
0,0,0,30,34,0,0,0,35,30,0,0,0,0,0,0,8,30,30,10,0,36,34,0,0,17,0,10,0,0
0,0,0,30,34,0,0,0,35,30,0,0,0,0,0,0,0,30,30,6,0,0,0,0,0,17,0,6,0,0
0,0,0,30,10,0,0,0,35,30,0,0,0,0,0,0,0,30,30,10,0,0,0,0,0,17,0,10,0,0
0,0,0,30,34,0,0,0,35,30,0,0,0,0,0,0,0,30,30,10,0,0,0,0,0,17,0,10,0,0
0,0,0,30,34,0,0,0,35,30,0,0,0,0,0,0,0,30,30,10,0,0,0,0,0,6,0,10,0,0
0,0,4,30,34,0,0,0,35,30,0,0,0,0,0,0,0,30,30,10,0,0,0,0,0,0,0,10,0,0
0,0,0,30,34,0,0,0,35,30,0,0,0,0,0,0,0,30,30,6,0,0,0,0,0,0,0,6,0,0
0,0,0,30,34,0,0,0,35,30,0,0,0,0,0,0,8,30,30,10,0,0,0,0,0,0,0,10,0,0
0,0,0,30,10,0,0,0,35,30,0,0,0,0,0,0,0,30,6,6,10,6,0,0,0,6,10,6,6,0
0,0,0,30,34,0,0,0,35,30,0,0,0,0,0,0,0,0,0,30,0,0,0,0,0,0,0,30,0,0
0,0,0,30,34,0,0,0,35,30,0,0,0,0,0,0,0,0,0,30,0,0,0,0,0,0,0,30,0,0
0,0,0,30,9,9,9,9,9,30,0,0,0,0,0,0,0,0,0,30,0,0,0,0,0,0,0,30,0,0
0,0,0,30,24,0,0,0,24,30,0,0,0,0,0,0,0,0,0,30,0,0,0,0,0,0,0,30,0,0
0,0,0,0,0,0,0,0,0,0,0,0,0,0,0,0,0,0,0,30,0,0,0,0,0,0,0,30,0,0
0,0,0,0,0,0,0,0,0,0,0,0,0,0,0,0,0,0,0,30,0,0,0,0,0,0,0,30,0,0
0,0,0,0,0,0,0,0,0,0,0,0,0,0,0,0,0,0,0,30,10,10,10,10,10,10,10,30,0,0
0,0,0,0,0,0,0,0,0,0,0,0,0,0,0,0,0,0,0,30,34,0,32,32,32,0,35,30,0,0
0,0,0,0,0,0,0,0,0,0,0,0,0,0,0,0,0,0,0,0,0,0,0,0,0,0,0,0,0,0
:endlayer
layer: 8
0,0,0,0,0,0,0,0,0,0,0,0,0,0,0,0,0,0,0,0,0,0,0,0,0,0,0,0,0,0
0,0,0,0,30,32,17,32,30,0,0,0,0,0,0,0,0,0,0,6,0,0,0,0,0,0,0,6,0,0
0,0,0,0,30,10,10,10,30,0,0,0,0,0,0,0,0,0,6,6,10,6,10,10,10,6,10,6,6,0
0,0,0,0,30,0,0,0,30,0,0,0,0,0,0,0,0,0,0,10,0,0,36,34,0,0,0,10,0,0
0,0,0,0,30,0,0,0,30,0,0,0,0,0,0,0,0,0,0,6,0,0,0,0,0,0,0,6,0,0
0,0,0,0,30,0,0,0,30,0,0,0,0,0,0,0,0,0,0,10,0,0,0,0,0,0,0,10,0,0
0,0,0,0,30,0,0,0,30,0,0,0,0,0,0,0,0,0,0,17,0,0,0,0,0,0,0,17,0,0
0,0,0,0,30,0,0,0,30,0,0,0,0,0,0,0,0,0,0,17,0,0,0,0,0,6,0,17,0,0
0,0,4,0,30,0,0,0,30,0,0,0,0,0,0,0,0,0,0,10,0,0,0,0,0,0,0,10,0,0
0,0,0,0,30,0,0,0,30,0,0,0,0,0,0,0,0,0,0,6,0,0,0,0,0,0,0,6,0,0
0,0,0,0,30,0,0,0,30,0,0,0,0,0,0,0,0,0,0,10,0,22,0,0,0,22,0,10,0,0
0,0,0,0,30,0,0,0,30,0,0,0,0,0,0,0,0,0,6,6,10,6,0,0,0,6,10,6,6,0
0,0,0,0,30,0,0,0,30,0,0,0,0,0,0,0,0,0,0,0,30,0,0,0,0,0,30,0,0,0
0,0,0,0,30,0,0,0,30,0,0,0,0,0,0,0,0,0,0,0,30,0,0,0,0,0,30,0,0,0
0,0,0,0,30,10,10,10,30,0,0,0,0,0,0,0,0,0,0,0,30,23,0,0,0,20,30,0,0,0
0,0,0,0,30,32,17,32,30,0,0,0,0,0,0,0,0,0,0,0,30,0,0,0,0,0,30,0,0,0
0,0,0,0,0,0,0,0,0,0,0,0,0,0,0,0,0,0,0,0,30,0,0,0,0,0,30,0,0,0
0,0,0,0,0,0,0,0,0,0,0,0,0,0,0,0,0,0,0,0,30,0,0,0,0,0,30,0,0,0
0,0,0,0,0,0,0,0,0,0,0,0,0,0,0,0,0,0,0,0,30,10,10,17,10,10,30,0,0,0
0,0,0,0,0,0,0,0,0,0,0,0,0,0,0,0,0,0,0,0,30,37,0,0,0,36,30,0,0,0
0,0,0,0,0,0,0,0,0,0,0,0,0,0,0,0,0,0,0,0,0,0,0,0,0,0,0,0,0,0
:endlayer
layer: 9
0,0,0,0,0,0,0,0,0,0,0,0,0,0,0,0,0,0,0,0,0,0,0,0,0,0,0,0,0,0
0,0,0,0,0,30,31,30,0,0,0,0,0,0,0,0,0,0,0,6,0,0,0,0,0,0,0,6,0,0
0,0,0,0,0,30,10,30,0,0,0,0,0,0,0,0,0,0,6,6,10,6,10,10,10,6,10,6,6,0
0,0,0,0,8,30,0,30,8,0,0,0,0,0,0,0,0,0,0,10,0,0,0,36,34,24,0,10,0,0
0,0,0,0,0,30,0,30,0,0,0,0,0,0,0,0,0,0,0,6,23,0,0,0,0,32,0,6,0,0
0,0,0,0,0,30,0,30,0,0,0,0,0,0,0,0,0,0,0,10,0,0,0,0,0,32,0,10,0,0
0,0,0,0,0,30,0,30,0,0,0,0,0,0,0,0,0,0,0,10,0,0,0,0,0,31,0,10,0,0
0,0,0,0,0,30,0,30,0,0,0,0,0,0,0,0,0,0,0,10,0,0,0,0,20,6,0,10,0,0
0,0,4,0,8,30,0,30,8,0,0,0,0,0,0,0,0,0,0,10,0,0,0,0,0,24,0,10,0,0
0,0,0,0,0,30,0,30,0,0,0,0,0,0,0,0,0,0,0,6,23,0,0,0,0,32,0,6,0,0
0,0,0,0,0,30,0,30,0,0,0,0,0,0,0,0,0,0,0,10,0,0,0,0,0,31,0,10,0,0
0,0,0,0,0,30,0,30,0,0,0,0,0,0,0,0,0,0,6,6,10,6,34,32,35,6,10,6,6,0
0,0,0,0,0,30,0,30,0,0,0,0,0,0,0,0,0,0,0,0,0,30,0,0,0,30,0,0,0,0
0,0,0,0,8,30,0,30,8,0,0,0,0,0,0,0,0,0,0,0,0,30,0,0,0,30,0,0,0,0
0,0,0,0,0,30,10,30,0,0,0,0,0,0,0,0,0,0,0,0,8,30,0,0,0,30,8,0,0,0
0,0,0,0,0,30,24,30,0,0,0,0,0,0,0,0,0,0,0,0,0,30,0,0,0,30,0,0,0,0
0,0,0,0,0,0,0,0,0,0,0,0,0,0,0,0,0,0,0,0,0,30,0,0,0,30,0,0,0,0
0,0,0,0,0,0,0,0,0,0,0,0,0,0,0,0,0,0,0,0,8,30,0,22,0,30,8,0,0,0
0,0,0,0,0,0,0,0,0,0,0,0,0,0,0,0,0,0,0,0,0,30,10,10,10,30,0,0,0,0
0,0,0,0,0,0,0,0,0,0,0,0,0,0,0,0,0,0,0,0,0,30,32,0,32,30,0,0,0,0
0,0,0,0,0,0,0,0,0,0,0,0,0,0,0,0,0,0,0,0,0,0,0,0,0,0,0,0,0,0
:endlayer
layer: 10
0,0,0,0,0,0,0,0,0,0,0,0,0,0,0,0,0,0,0,0,0,0,0,0,0,0,0,0,0,0
0,0,0,0,0,0,30,0,0,0,0,0,0,0,0,0,0,0,30,6,0,0,0,0,0,0,0,6,30,0
0,0,0,0,0,0,30,0,0,0,0,0,0,0,0,0,0,0,30,6,9,9,9,9,9,9,9,6,30,0
0,0,0,0,0,0,30,0,0,0,0,0,0,0,0,0,0,0,30,7,0,0,0,0,36,7,32,7,30,0
0,0,0,0,0,0,30,0,0,0,0,0,0,0,0,0,0,0,30,7,31,31,31,31,10,7,32,7,30,0
0,0,0,0,0,0,30,0,0,0,0,0,0,0,0,0,0,0,30,7,32,10,32,10,32,7,32,7,30,0
0,0,0,0,0,0,30,0,0,0,0,0,0,0,0,0,0,0,30,7,32,10,32,10,32,7,32,7,30,0
0,0,0,0,0,0,30,0,0,0,0,0,0,0,0,0,0,0,30,7,32,10,32,10,32,7,32,7,30,0
0,0,4,0,0,0,30,0,0,0,0,0,0,0,0,0,0,0,30,7,32,10,32,10,32,7,32,7,30,0
0,0,0,0,0,0,30,0,0,0,0,0,0,0,0,0,0,0,30,7,32,10,32,10,32,7,32,7,30,0
0,0,0,0,0,0,30,0,0,0,0,0,0,0,0,0,0,0,30,7,32,10,32,10,32,7,32,7,30,0
0,0,0,0,0,0,30,0,0,0,0,0,0,0,0,0,0,0,30,6,9,9,9,9,9,9,9,6,30,0
0,0,0,0,0,0,30,0,0,0,0,0,0,0,0,0,0,0,30,0,0,0,30,21,30,0,0,0,30,0
0,0,0,0,0,0,30,0,0,0,0,0,0,0,0,0,0,0,0,0,0,0,30,0,30,0,0,0,0,0
0,0,0,0,0,0,30,0,0,0,0,0,0,0,0,0,0,0,0,0,0,0,30,0,30,0,0,0,0,0
0,0,0,0,0,0,30,0,0,0,0,0,0,0,0,0,0,0,0,0,0,0,30,0,30,0,0,0,0,0
0,0,0,0,0,0,0,0,0,0,0,0,0,0,0,0,0,0,0,0,0,0,30,0,30,0,0,0,0,0
0,0,0,0,0,0,0,0,0,0,0,0,0,0,0,0,0,0,0,0,0,0,30,0,30,0,0,0,0,0
0,0,0,0,0,0,0,0,0,0,0,0,0,0,0,0,0,0,0,0,0,0,30,10,30,0,0,0,0,0
0,0,0,0,0,0,0,0,0,0,0,0,0,0,0,0,0,0,0,0,0,0,30,24,30,0,0,0,0,0
0,0,0,0,0,0,0,0,0,0,0,0,0,0,0,0,0,0,0,0,0,0,0,0,0,0,0,0,0,0
:endlayer
layer: 11
0,0,0,0,0,0,0,0,0,0,0,0,0,0,0,0,0,0,0,0,0,0,0,0,0,0,0,0,0,0
0,0,0,0,0,0,0,0,0,0,0,0,0,0,0,0,0,0,0,30,34,0,32,32,32,0,35,30,0,0
0,0,0,0,0,0,0,0,0,0,0,0,0,0,0,0,0,0,0,30,10,10,10,10,10,10,10,30,0,0
0,0,0,0,0,0,0,0,0,0,0,0,0,0,0,0,0,0,0,30,0,0,0,0,0,0,0,30,0,0
0,0,0,0,0,0,0,0,0,0,0,0,0,0,0,0,0,0,0,30,0,0,0,0,0,0,0,30,0,0
0,0,0,0,0,0,0,0,0,0,0,0,0,0,0,0,0,0,0,30,0,0,0,0,0,0,0,30,0,0
0,0,0,0,0,0,0,0,0,0,0,0,0,0,0,0,0,0,0,30,0,0,0,8,0,0,0,30,0,0
0,0,0,0,0,0,0,0,0,0,0,0,0,0,0,0,0,0,0,30,0,0,0,0,0,0,0,30,0,0
0,0,4,0,0,0,0,0,0,0,0,0,0,0,0,0,0,0,0,30,0,0,0,0,0,0,0,30,0,0
0,0,0,0,0,0,0,0,0,0,0,0,0,0,0,0,0,0,0,30,0,0,0,0,0,0,0,30,0,0
0,0,0,0,0,0,0,0,0,0,0,0,0,0,0,0,0,0,0,30,0,0,0,0,0,0,0,30,0,0
0,0,0,0,0,0,0,0,0,0,0,0,0,0,0,0,0,0,0,30,10,10,10,10,10,10,10,30,0,0
0,0,0,0,0,0,0,0,0,0,0,0,0,0,0,0,0,0,0,30,0,0,0,30,0,0,0,30,0,0
0,0,0,0,0,0,0,0,0,0,0,0,0,0,0,0,0,0,0,0,0,0,0,30,0,0,0,0,0,0
0,0,0,0,0,0,0,0,0,0,0,0,0,0,0,0,0,0,0,0,0,0,0,30,0,0,0,0,0,0
0,0,0,0,0,0,0,0,0,0,0,0,0,0,0,0,0,0,0,0,0,0,0,30,0,0,0,0,0,0
0,0,0,0,0,0,0,0,0,0,0,0,0,0,0,0,0,0,0,0,0,0,0,30,0,0,0,0,0,0
0,0,0,0,0,0,0,0,0,0,0,0,0,0,0,0,0,0,0,0,0,0,0,30,0,0,0,0,0,0
0,0,0,0,0,0,0,0,0,0,0,0,0,0,0,0,0,0,0,0,0,0,0,30,0,0,0,0,0,0
0,0,0,0,0,0,0,0,0,0,0,0,0,0,0,0,0,0,0,0,0,0,0,30,0,0,0,0,0,0
0,0,0,0,0,0,0,0,0,0,0,0,0,0,0,0,0,0,0,0,0,0,0,0,0,0,0,0,0,0
:endlayer
layer: 12
0,0,0,0,0,0,0,0,0,0,0,0,0,0,0,0,0,0,0,0,0,0,0,0,0,0,0,0,0,0
0,0,0,0,0,0,0,0,0,0,0,0,0,0,0,0,0,0,0,0,30,37,0,0,0,36,30,0,0,0
0,0,0,0,0,0,0,0,0,0,0,0,0,0,0,0,0,0,0,0,30,10,10,17,10,10,30,0,0,0
0,0,0,0,0,0,0,0,0,0,0,0,0,0,0,0,0,0,0,0,30,0,0,0,0,0,30,0,0,0
0,0,0,0,0,0,0,0,0,0,0,0,0,0,0,0,0,0,0,0,30,0,0,0,0,0,30,0,0,0
0,0,0,0,0,0,0,0,0,0,0,0,0,0,0,0,0,0,0,8,30,0,0,0,0,0,30,8,0,0
0,0,0,0,0,0,0,0,0,0,0,0,0,0,0,0,0,0,0,0,30,0,0,0,0,0,30,0,0,0
0,0,0,0,0,0,0,0,0,0,0,0,0,0,0,0,0,0,0,0,30,0,0,0,0,0,30,0,0,0
0,0,38,0,0,0,0,0,0,0,0,0,0,0,0,0,0,0,0,8,30,0,0,0,0,0,30,8,0,0
0,0,0,0,0,0,0,0,0,0,0,0,0,0,0,0,0,0,0,0,30,0,0,0,0,0,30,0,0,0
0,0,0,0,0,0,0,0,0,0,0,0,0,0,0,0,0,0,0,0,30,0,0,0,0,0,30,0,0,0
0,0,0,0,0,0,0,0,0,0,0,0,0,0,0,0,0,0,0,0,30,10,10,17,10,10,30,0,0,0
0,0,0,0,0,0,0,0,0,0,0,0,0,0,0,0,0,0,0,0,30,32,0,0,0,32,30,0,0,0
0,0,0,0,0,0,0,0,0,0,0,0,0,0,0,0,0,0,0,0,0,0,0,0,0,0,0,0,0,0
0,0,0,0,0,0,0,0,0,0,0,0,0,0,0,0,0,0,0,0,0,0,0,8,0,0,0,0,0,0
0,0,0,0,0,0,0,0,0,0,0,0,0,0,0,0,0,0,0,0,0,0,0,0,0,0,0,0,0,0
0,0,0,0,0,0,0,0,0,0,0,0,0,0,0,0,0,0,0,0,0,0,0,0,0,0,0,0,0,0
0,0,0,0,0,0,0,0,0,0,0,0,0,0,0,0,0,0,0,0,0,0,0,8,0,0,0,0,0,0
0,0,0,0,0,0,0,0,0,0,0,0,0,0,0,0,0,0,0,0,0,0,0,0,0,0,0,0,0,0
0,0,0,0,0,0,0,0,0,0,0,0,0,0,0,0,0,0,0,0,0,0,0,0,0,0,0,0,0,0
0,0,0,0,0,0,0,0,0,0,0,0,0,0,0,0,0,0,0,0,0,0,0,0,0,0,0,0,0,0
:endlayer
layer: 13
0,0,0,0,0,0,0,0,0,0,0,0,0,0,0,0,0,0,0,0,0,0,0,0,0,0,0,0,0,0
0,0,0,0,0,0,0,0,0,0,0,0,0,0,0,0,0,0,0,0,0,30,32,0,32,30,0,0,0,0
0,0,0,0,0,0,0,0,0,0,0,0,0,0,0,0,0,0,0,0,0,30,10,10,10,30,0,0,0,0
0,0,0,0,0,0,0,0,0,0,0,0,0,0,0,0,0,0,0,0,8,30,0,21,0,30,8,0,0,0
0,0,0,0,0,0,0,0,0,0,0,0,0,0,0,0,0,0,0,0,0,30,0,0,0,30,0,0,0,0
0,0,0,0,0,0,0,0,0,0,0,0,0,0,0,0,0,0,0,0,0,30,0,0,0,30,0,0,0,0
0,0,0,0,0,0,0,0,0,0,0,0,0,0,0,0,0,0,0,0,0,30,0,0,0,30,0,0,0,0
0,0,0,0,0,0,0,0,0,0,0,0,0,0,0,0,0,0,0,0,0,30,0,0,0,30,0,0,0,0
0,0,33,0,0,0,0,0,0,0,0,0,0,0,0,0,0,0,0,0,0,30,0,0,0,30,0,0,0,0
0,0,0,0,0,0,0,0,0,0,0,0,0,0,0,0,0,0,0,0,0,30,0,0,0,30,0,0,0,0
0,0,0,0,0,0,0,0,0,0,0,0,0,0,0,0,0,0,0,0,8,30,0,22,0,30,8,0,0,0
0,0,0,0,0,0,0,0,0,0,0,0,0,0,0,0,0,0,0,0,0,30,10,10,10,30,0,0,0,0
0,0,0,0,0,0,0,0,0,0,0,0,0,0,0,0,0,0,0,0,0,30,34,0,35,30,0,0,0,0
0,0,0,0,0,0,0,0,0,0,0,0,0,0,0,0,0,0,0,0,0,0,0,0,0,0,0,0,0,0
0,0,0,0,0,0,0,0,0,0,0,0,0,0,0,0,0,0,0,0,0,0,0,0,0,0,0,0,0,0
0,0,0,0,0,0,0,0,0,0,0,0,0,0,0,0,0,0,0,0,0,0,0,0,0,0,0,0,0,0
0,0,0,0,0,0,0,0,0,0,0,0,0,0,0,0,0,0,0,0,0,0,0,0,0,0,0,0,0,0
0,0,0,0,0,0,0,0,0,0,0,0,0,0,0,0,0,0,0,0,0,0,0,0,0,0,0,0,0,0
0,0,0,0,0,0,0,0,0,0,0,0,0,0,0,0,0,0,0,0,0,0,0,0,0,0,0,0,0,0
0,0,0,0,0,0,0,0,0,0,0,0,0,0,0,0,0,0,0,0,0,0,0,0,0,0,0,0,0,0
0,0,0,0,0,0,0,0,0,0,0,0,0,0,0,0,0,0,0,0,0,0,0,0,0,0,0,0,0,0
:endlayer
layer: 14
0,0,0,0,0,0,0,0,0,0,0,0,0,0,0,0,0,0,0,0,0,0,0,0,0,0,0,0,0,0
0,0,0,0,0,0,0,0,0,0,0,0,0,0,0,0,0,0,0,0,0,0,30,31,30,0,0,0,0,0
0,0,0,0,0,0,0,0,0,0,0,0,0,0,0,0,0,0,0,0,0,0,30,10,30,0,0,0,0,0
0,0,0,0,0,0,0,0,0,0,0,0,0,0,0,0,0,0,0,0,0,0,30,0,30,0,0,0,0,0
0,0,0,0,0,0,0,0,0,0,0,0,0,0,0,0,0,0,0,0,0,0,30,0,30,0,0,0,0,0
0,0,0,0,0,0,0,0,0,0,0,0,0,0,0,0,0,0,0,0,0,8,30,0,30,8,0,0,0,0
0,0,0,0,0,0,0,0,0,0,0,0,0,0,0,0,0,0,0,0,0,0,30,0,30,0,0,0,0,0
0,0,0,0,0,0,0,0,0,0,0,0,0,0,0,0,0,0,0,0,0,0,30,0,30,0,0,0,0,0
0,0,0,0,0,0,0,0,0,0,0,0,0,0,0,0,0,0,0,0,0,8,30,0,30,8,0,0,0,0
0,0,0,0,0,0,0,0,0,0,0,0,0,0,0,0,0,0,0,0,0,0,30,0,30,0,0,0,0,0
0,0,0,0,0,0,0,0,0,0,0,0,0,0,0,0,0,0,0,0,0,0,30,0,30,0,0,0,0,0
0,0,0,0,0,0,0,0,0,0,0,0,0,0,0,0,0,0,0,0,0,0,30,10,30,0,0,0,0,0
0,0,0,0,0,0,0,0,0,0,0,0,0,0,0,0,0,0,0,0,0,0,30,24,30,0,0,0,0,0
0,0,0,0,0,0,0,0,0,0,0,0,0,0,0,0,0,0,0,0,0,0,0,0,0,0,0,0,0,0
0,0,0,0,0,0,0,0,0,0,0,0,0,0,0,0,0,0,0,0,0,0,0,0,0,0,0,0,0,0
0,0,0,0,0,0,0,0,0,0,0,0,0,0,0,0,0,0,0,0,0,0,0,0,0,0,0,0,0,0
0,0,0,0,0,0,0,0,0,0,0,0,0,0,0,0,0,0,0,0,0,0,0,0,0,0,0,0,0,0
0,0,0,0,0,0,0,0,0,0,0,0,0,0,0,0,0,0,0,0,0,0,0,0,0,0,0,0,0,0
0,0,0,0,0,0,0,0,0,0,0,0,0,0,0,0,0,0,0,0,0,0,0,0,0,0,0,0,0,0
0,0,0,0,0,0,0,0,0,0,0,0,0,0,0,0,0,0,0,0,0,0,0,0,0,0,0,0,0,0
0,0,0,0,0,0,0,0,0,0,0,0,0,0,0,0,0,0,0,0,0,0,0,0,0,0,0,0,0,0
:endlayer
layer: 15
0,0,0,0,0,0,0,0,0,0,0,0,0,0,0,0,0,0,0,0,0,0,0,0,0,0,0,0,0,0
0,0,0,0,0,0,0,0,0,0,0,0,0,0,0,0,0,0,0,0,0,0,0,30,0,0,0,0,0,0
0,0,0,0,0,0,0,0,0,0,0,0,0,0,0,0,0,0,0,0,0,0,0,30,0,0,0,0,0,0
0,0,0,0,0,0,0,0,0,0,0,0,0,0,0,0,0,0,0,0,0,0,0,30,0,0,0,0,0,0
0,0,0,0,0,0,0,0,0,0,0,0,0,0,0,0,0,0,0,0,0,0,0,30,0,0,0,0,0,0
0,0,0,0,0,0,0,0,0,0,0,0,0,0,0,0,0,0,0,0,0,0,0,30,0,0,0,0,0,0
0,0,0,0,0,0,0,0,0,0,0,0,0,0,0,0,0,0,0,0,0,0,0,30,0,0,0,0,0,0
0,0,0,0,0,0,0,0,0,0,0,0,0,0,0,0,0,0,0,0,0,0,0,30,0,0,0,0,0,0
0,0,0,0,0,0,0,0,0,0,0,0,0,0,0,0,0,0,0,0,0,0,0,30,0,0,0,0,0,0
0,0,0,0,0,0,0,0,0,0,0,0,0,0,0,0,0,0,0,0,0,0,0,30,0,0,0,0,0,0
0,0,0,0,0,0,0,0,0,0,0,0,0,0,0,0,0,0,0,0,0,0,0,30,0,0,0,0,0,0
0,0,0,0,0,0,0,0,0,0,0,0,0,0,0,0,0,0,0,0,0,0,0,30,0,0,0,0,0,0
0,0,0,0,0,0,0,0,0,0,0,0,0,0,0,0,0,0,0,0,0,0,0,30,0,0,0,0,0,0
0,0,0,0,0,0,0,0,0,0,0,0,0,0,0,0,0,0,0,0,0,0,0,0,0,0,0,0,0,0
0,0,0,0,0,0,0,0,0,0,0,0,0,0,0,0,0,0,0,0,0,0,0,0,0,0,0,0,0,0
0,0,0,0,0,0,0,0,0,0,0,0,0,0,0,0,0,0,0,0,0,0,0,0,0,0,0,0,0,0
0,0,0,0,0,0,0,0,0,0,0,0,0,0,0,0,0,0,0,0,0,0,0,0,0,0,0,0,0,0
0,0,0,0,0,0,0,0,0,0,0,0,0,0,0,0,0,0,0,0,0,0,0,0,0,0,0,0,0,0
0,0,0,0,0,0,0,0,0,0,0,0,0,0,0,0,0,0,0,0,0,0,0,0,0,0,0,0,0,0
0,0,0,0,0,0,0,0,0,0,0,0,0,0,0,0,0,0,0,0,0,0,0,0,0,0,0,0,0,0
0,0,0,0,0,0,0,0,0,0,0,0,0,0,0,0,0,0,0,0,0,0,0,0,0,0,0,0,0,0
:endlayer
layer: 16
0,0,0,0,0,0,0,0,0,0,0,0,0,0,0,0,0,0,0,0,0,0,0,0,0,0,0,0,0,0
0,0,0,0,0,0,0,0,0,0,0,0,0,0,0,0,0,0,0,0,0,0,0,0,0,0,0,0,0,0
0,0,0,0,0,0,0,0,0,0,0,0,0,0,0,0,0,0,0,0,0,0,0,0,0,0,0,0,0,0
0,0,0,0,0,0,0,0,0,0,0,0,0,0,0,0,0,0,0,0,0,0,0,8,0,0,0,0,0,0
0,0,0,0,0,0,0,0,0,0,0,0,0,0,0,0,0,0,0,0,0,0,0,0,0,0,0,0,0,0
0,0,0,0,0,0,0,0,0,0,0,0,0,0,0,0,0,0,0,0,0,0,0,0,0,0,0,0,0,0
0,0,0,0,0,0,0,0,0,0,0,0,0,0,0,0,0,0,0,0,0,0,0,0,0,0,0,0,0,0
0,0,0,0,0,0,0,0,0,0,0,0,0,0,0,0,0,0,0,0,0,0,0,0,0,0,0,0,0,0
0,0,0,0,0,0,0,0,0,0,0,0,0,0,0,0,0,0,0,0,0,0,0,0,0,0,0,0,0,0
0,0,0,0,0,0,0,0,0,0,0,0,0,0,0,0,0,0,0,0,0,0,0,0,0,0,0,0,0,0
0,0,0,0,0,0,0,0,0,0,0,0,0,0,0,0,0,0,0,0,0,0,0,8,0,0,0,0,0,0
0,0,0,0,0,0,0,0,0,0,0,0,0,0,0,0,0,0,0,0,0,0,0,0,0,0,0,0,0,0
0,0,0,0,0,0,0,0,0,0,0,0,0,0,0,0,0,0,0,0,0,0,0,0,0,0,0,0,0,0
0,0,0,0,0,0,0,0,0,0,0,0,0,0,0,0,0,0,0,0,0,0,0,0,0,0,0,0,0,0
0,0,0,0,0,0,0,0,0,0,0,0,0,0,0,0,0,0,0,0,0,0,0,0,0,0,0,0,0,0
0,0,0,0,0,0,0,0,0,0,0,0,0,0,0,0,0,0,0,0,0,0,0,0,0,0,0,0,0,0
0,0,0,0,0,0,0,0,0,0,0,0,0,0,0,0,0,0,0,0,0,0,0,0,0,0,0,0,0,0
0,0,0,0,0,0,0,0,0,0,0,0,0,0,0,0,0,0,0,0,0,0,0,0,0,0,0,0,0,0
0,0,0,0,0,0,0,0,0,0,0,0,0,0,0,0,0,0,0,0,0,0,0,0,0,0,0,0,0,0
0,0,0,0,0,0,0,0,0,0,0,0,0,0,0,0,0,0,0,0,0,0,0,0,0,0,0,0,0,0
0,0,0,0,0,0,0,0,0,0,0,0,0,0,0,0,0,0,0,0,0,0,0,0,0,0,0,0,0,0
:endlayer

#### RULES ####
rule:
plugin=vanillaBlocks
number=1
data:
JSON:{blockState:{blockName:"minecraft:grass",properties:{snowy:"false"}}}
:enddata
:endrule

rule:
plugin=vanillaBlocks
number=2
data:
JSON:{blockState:{blockName:"minecraft:cobblestone"}}
:enddata
:endrule

rule:
plugin=vanillaBlocks
number=3
data:
JSON:{blockState:{blockName:"minecraft:dirt",properties:{variant:"dirt",snowy:"false"}}}
:enddata
:endrule

rule:
plugin=vanillaBlocks
number=4
data:
JSON:{blockState:{blockName:"minecraft:stonebrick",properties:{variant:"stonebrick"}}}
:enddata
:endrule

rule:
plugin=vanillaBlocks
number=5
data:
JSON:{blockState:{blockName:"minecraft:gravel"}}
:enddata
:endrule

rule:
plugin=vanillaBlocks
number=6
data:
JSON:{blockState:{blockName:"rustic:log",properties:{variant:"ironwood",axis:"y"}}}
:enddata
:endrule

rule:
plugin=vanillaBlocks
number=7
data:
JSON:{blockState:{blockName:"rustic:log",properties:{variant:"ironwood",axis:"z"}}}
:enddata
:endrule

rule:
plugin=vanillaBlocks
number=8
data:
JSON:{blockState:{blockName:"minecraft:torch",properties:{facing:"up"}}}
:enddata
:endrule

rule:
plugin=vanillaBlocks
number=9
data:
JSON:{blockState:{blockName:"rustic:log",properties:{variant:"ironwood",axis:"x"}}}
:enddata
:endrule

rule:
plugin=vanillaBlocks
number=10
data:
JSON:{blockState:{blockName:"rustic:planks",properties:{variant:"ironwood"}}}
:enddata
:endrule

rule:
plugin=vanillaBlocks
number=11
data:
JSON:{blockState:{blockName:"minecraft:stone_stairs",properties:{half:"bottom",shape:"straight",facing:"east"}}}
:enddata
:endrule

rule:
plugin=vanillaBlocks
number=12
data:
JSON:{blockState:{blockName:"minecraft:stone_stairs",properties:{half:"bottom",shape:"straight",facing:"north"}}}
:enddata
:endrule

rule:
plugin=vanillaBlocks
number=13
data:
JSON:{blockState:{blockName:"minecraft:stone_stairs",properties:{half:"bottom",shape:"straight",facing:"south"}}}
:enddata
:endrule

rule:
plugin=vanillaBlocks
number=14
data:
JSON:{blockState:{blockName:"minecraft:stone_stairs",properties:{half:"bottom",shape:"straight",facing:"west"}}}
:enddata
:endrule

rule:
plugin=vanillaBlocks
number=15
data:
JSON:{blockState:{blockName:"minecraft:stone_brick_stairs",properties:{half:"bottom",shape:"straight",facing:"north"}}}
:enddata
:endrule

rule:
plugin=vanillaBlocks
number=16
data:
JSON:{blockState:{blockName:"minecraft:stone_brick_stairs",properties:{half:"bottom",shape:"straight",facing:"south"}}}
:enddata
:endrule

rule:
plugin=vanillaBlocks
number=17
data:
JSON:{blockState:{blockName:"rustic:fence_ironwood",properties:{east:"false",south:"false",north:"false",west:"false"}}}
:enddata
:endrule

rule:
plugin=vanillaBlocks
number=18
data:
JSON:{blockState:{blockName:"minecraft:stone_brick_stairs",properties:{half:"bottom",shape:"straight",facing:"west"}}}
:enddata
:endrule

rule:
plugin=vanillaBlocks
number=19
data:
JSON:{blockState:{blockName:"minecraft:stone_brick_stairs",properties:{half:"bottom",shape:"straight",facing:"east"}}}
:enddata
:endrule

rule:
plugin=vanillaBlocks
number=20
data:
JSON:{blockState:{blockName:"minecraft:torch",properties:{facing:"west"}}}
:enddata
:endrule

rule:
plugin=vanillaBlocks
number=21
data:
JSON:{blockState:{blockName:"minecraft:torch",properties:{facing:"south"}}}
:enddata
:endrule

rule:
plugin=vanillaBlocks
number=22
data:
JSON:{blockState:{blockName:"minecraft:torch",properties:{facing:"north"}}}
:enddata
:endrule

rule:
plugin=vanillaBlocks
number=23
data:
JSON:{blockState:{blockName:"minecraft:torch",properties:{facing:"east"}}}
:enddata
:endrule

rule:
plugin=vanillaBlocks
number=24
data:
JSON:{blockState:{blockName:"rustic:stairs_ironwood",properties:{half:"top",shape:"straight",facing:"north"}}}
:enddata
:endrule

rule:
plugin=vanillaBlocks
number=25
data:
JSON:{blockState:{blockName:"rustic:stairs_ironwood",properties:{half:"bottom",shape:"straight",facing:"south"}}}
:enddata
:endrule

rule:
plugin=vanillaBlocks
number=26
data:
JSON:{blockState:{blockName:"minecraft:stone_brick_stairs",properties:{half:"top",shape:"straight",facing:"south"}}}
:enddata
:endrule

rule:
plugin=vanillaBlocks
number=27
data:
JSON:{blockState:{blockName:"minecraft:stone_brick_stairs",properties:{half:"top",shape:"straight",facing:"north"}}}
:enddata
:endrule

rule:
plugin=vanillaBlocks
number=28
data:
JSON:{blockState:{blockName:"minecraft:stone_brick_stairs",properties:{half:"top",shape:"straight",facing:"west"}}}
:enddata
:endrule

rule:
plugin=vanillaBlocks
number=29
data:
JSON:{blockState:{blockName:"minecraft:stone_slab",properties:{half:"top",variant:"stone_brick"}}}
:enddata
:endrule

rule:
plugin=vanillaBlocks
number=30
data:
JSON:{blockState:{blockName:"minecraft:wool",properties:{color:"brown"}}}
:enddata
:endrule

rule:
plugin=vanillaBlocks
number=31
data:
JSON:{blockState:{blockName:"rustic:stairs_ironwood",properties:{half:"top",shape:"straight",facing:"south"}}}
:enddata
:endrule

rule:
plugin=vanillaBlocks
number=32
data:
JSON:{blockState:{blockName:"rustic:ironwood_slab",properties:{half:"top"}}}
:enddata
:endrule

rule:
plugin=vanillaBlocks
number=33
data:
JSON:{blockState:{blockName:"minecraft:stone_slab",properties:{half:"bottom",variant:"stone_brick"}}}
:enddata
:endrule

rule:
plugin=vanillaBlocks
number=34
data:
JSON:{blockState:{blockName:"rustic:stairs_ironwood",properties:{half:"top",shape:"straight",facing:"west"}}}
:enddata
:endrule

rule:
plugin=vanillaBlocks
number=35
data:
JSON:{blockState:{blockName:"rustic:stairs_ironwood",properties:{half:"top",shape:"straight",facing:"east"}}}
:enddata
:endrule

rule:
plugin=vanillaBlocks
number=36
data:
JSON:{blockState:{blockName:"rustic:stairs_ironwood",properties:{half:"bottom",shape:"straight",facing:"east"}}}
:enddata
:endrule

rule:
plugin=vanillaBlocks
number=37
data:
JSON:{blockState:{blockName:"rustic:stairs_ironwood",properties:{half:"bottom",shape:"straight",facing:"west"}}}
:enddata
:endrule

rule:
plugin=vanillaBlocks
number=38
data:
JSON:{blockState:{blockName:"minecraft:cobblestone_wall",properties:{east:"false",south:"false",north:"false",variant:"cobblestone",west:"false",up:"false"}}}
:enddata
:endrule

#### ENTITIES ####
