# Ancient Warfare Structure Template File
# Auto-generated structure template file. created on: 3/13/2021 at: 14:16:56
# Lines beginning with # denote comments

header:
version=2.11
name=SurvivalBuild_FortWall_medium_type1_StraightTower_birch
mods=
size=16,11,16
offset=15,0,0
:endheader

#### VALIDATION ####
validation:
type=ground
structureAuthor=TheOddlySeagull
survival=true
worldGenEnabled=false
unique=false
preserveBlocks=false
preventNaturalHostileSpawns=false
selectionWeight=1
clusterValue=1
minDuplicateDistance=1
dimensionWhiteList=true
dimensionList=
biomeGroupList=
biomeWhiteList=true
biomeList=
leveling=0
fill=0
border=0
blockSwap=false
territoryName=
biomeReplacement=minecraft:
minGenerationHeight=0
maxGenerationHeight=255
:endvalidation

#### LAYERS ####
layer: 0
0,0,0,0,0,0,1,1,1,1,0,0,0,0,0,0
0,0,0,0,0,0,0,2,2,0,0,0,0,0,0,0
0,0,0,0,0,0,1,2,2,1,0,0,0,0,0,0
0,0,0,0,0,0,0,2,2,0,0,0,0,0,0,0
0,0,0,0,0,0,1,2,2,1,0,0,0,0,0,0
0,0,0,0,0,0,0,2,2,0,0,0,0,0,0,0
0,0,0,0,0,7,1,3,3,1,1,0,0,0,0,0
0,0,0,0,0,6,2,5,5,2,0,0,0,0,0,0
0,0,0,0,0,6,2,5,5,2,0,0,0,0,0,0
0,0,0,0,0,4,1,3,3,1,1,0,0,0,0,0
0,0,0,0,0,0,0,2,2,0,0,0,0,0,0,0
0,0,0,0,0,0,1,2,2,1,0,0,0,0,0,0
0,0,0,0,0,0,0,2,2,0,0,0,0,0,0,0
0,0,0,0,0,0,1,2,2,1,0,0,0,0,0,0
0,0,0,0,0,0,0,2,2,0,0,0,0,0,0,0
0,0,0,0,0,0,1,1,1,1,0,0,0,0,0,0
:endlayer
layer: 1
0,0,0,0,0,0,1,1,1,1,0,0,0,0,0,0
0,0,0,0,0,0,0,5,5,0,0,0,0,0,0,0
0,0,0,0,0,0,6,1,1,8,0,0,0,0,0,0
0,0,0,0,0,0,0,5,5,0,0,0,0,0,0,0
0,0,0,0,0,0,6,1,1,8,0,0,0,0,0,0
0,0,0,0,0,0,0,5,5,0,0,0,0,0,0,0
0,0,0,0,0,9,1,5,5,1,8,0,0,0,0,0
0,0,0,0,0,0,0,6,5,5,0,0,0,0,0,0
0,0,0,0,0,0,0,0,0,5,0,0,0,0,0,0
0,0,0,0,0,9,1,5,5,1,8,0,0,0,0,0
0,0,0,0,0,0,0,5,5,0,0,0,0,0,0,0
0,0,0,0,0,0,6,1,1,8,0,0,0,0,0,0
0,0,0,0,0,0,0,5,5,0,0,0,0,0,0,0
0,0,0,0,0,0,6,1,1,8,0,0,0,0,0,0
0,0,0,0,0,0,0,5,5,0,0,0,0,0,0,0
0,0,0,0,0,0,1,1,1,1,0,0,0,0,0,0
:endlayer
layer: 2
0,0,0,0,0,0,4,1,1,4,0,0,0,0,0,0
0,0,0,0,0,0,0,5,5,0,0,0,0,0,0,0
0,0,0,0,0,0,0,1,1,0,0,0,0,0,0,0
0,0,0,0,0,0,0,5,5,0,0,0,0,0,0,0
0,0,0,0,0,0,0,1,1,0,0,0,0,0,0,0
0,0,0,0,0,0,9,5,5,0,0,0,0,0,0,0
0,0,0,0,0,9,1,5,5,1,0,0,0,0,0,0
0,0,0,0,0,0,0,0,6,5,0,0,0,0,0,0
0,0,0,0,0,0,0,0,10,5,0,0,0,0,0,0
0,0,0,0,0,9,1,5,5,1,0,0,0,0,0,0
0,0,0,0,0,0,9,5,5,0,0,0,0,0,0,0
0,0,0,0,0,0,0,1,1,0,0,0,0,0,0,0
0,0,0,0,0,0,0,5,5,0,0,0,0,0,0,0
0,0,0,0,0,0,0,1,1,0,0,0,0,0,0,0
0,0,0,0,0,0,0,5,5,0,0,0,0,0,0,0
0,0,0,0,0,0,7,1,1,7,0,0,0,0,0,0
:endlayer
layer: 3
0,0,0,0,0,0,9,1,1,9,0,0,0,0,0,0
0,0,0,0,0,0,0,5,5,0,0,0,0,0,0,0
0,0,0,0,0,0,11,1,1,0,0,0,0,0,0,0
0,0,0,0,0,0,0,5,5,12,0,0,0,0,0,0
0,0,0,0,0,0,11,1,1,0,0,0,0,0,0,0
0,0,0,0,0,0,10,5,5,0,0,0,0,0,0,0
0,0,0,0,0,10,1,5,5,1,12,0,0,0,0,0
0,0,0,0,0,0,0,0,0,5,0,0,0,0,0,0
0,0,0,0,0,0,13,10,7,5,0,0,0,0,0,0
0,0,0,0,0,10,1,5,5,1,12,0,0,0,0,0
0,0,0,0,0,0,10,5,5,0,0,0,0,0,0,0
0,0,0,0,0,0,11,1,1,0,0,0,0,0,0,0
0,0,0,0,0,0,0,5,5,12,0,0,0,0,0,0
0,0,0,0,0,0,11,1,1,0,0,0,0,0,0,0
0,0,0,0,0,0,0,5,5,0,0,0,0,0,0,0
0,0,0,0,0,0,9,1,1,9,0,0,0,0,0,0
:endlayer
layer: 4
0,0,0,0,0,0,10,3,3,14,0,0,0,0,0,0
0,0,0,0,0,0,15,2,2,15,0,0,0,0,0,0
0,0,0,0,0,0,10,2,2,14,0,0,0,0,0,0
0,0,0,0,0,0,15,2,2,15,0,0,0,0,0,0
0,0,0,0,15,15,10,2,2,14,0,0,0,0,0,0
0,0,0,0,15,10,5,2,2,15,0,0,0,0,0,0
0,0,0,0,15,5,1,3,3,1,0,0,0,0,0,0
0,0,0,0,15,10,2,0,0,2,0,0,0,0,0,0
0,0,0,0,15,10,2,8,0,2,0,0,0,0,0,0
0,0,0,0,15,5,1,3,3,1,0,0,0,0,0,0
0,0,0,0,15,10,5,2,2,15,0,0,0,0,0,0
0,0,0,0,15,15,10,2,2,14,0,0,0,0,0,0
0,0,0,0,0,0,15,2,2,15,0,0,0,0,0,0
0,0,0,0,0,0,10,2,2,14,0,0,0,0,0,0
0,0,0,0,0,0,15,2,2,15,0,0,0,0,0,0
0,0,0,0,0,0,10,3,3,14,0,0,0,0,0,0
:endlayer
layer: 5
0,0,0,0,0,0,9,0,0,2,0,0,0,0,0,0
0,0,0,0,0,0,9,0,0,2,0,0,0,0,0,0
0,0,0,0,0,0,9,0,0,2,0,0,0,0,0,0
0,0,0,0,0,0,9,0,0,2,0,0,0,0,0,0
0,0,0,0,9,9,9,0,0,2,0,0,0,0,0,0
0,0,0,0,9,0,0,0,0,2,0,0,0,0,0,0
0,0,0,0,9,0,1,5,5,1,0,0,0,0,0,0
0,0,0,0,9,0,0,0,0,5,0,0,0,0,0,0
0,0,0,0,9,0,0,0,0,9,0,0,0,0,0,0
0,0,0,0,9,0,1,5,5,1,0,0,0,0,0,0
0,0,0,0,9,0,0,0,0,2,0,0,0,0,0,0
0,0,0,0,9,9,9,0,0,2,0,0,0,0,0,0
0,0,0,0,0,0,9,0,0,2,0,0,0,0,0,0
0,0,0,0,0,0,9,0,0,2,0,0,0,0,0,0
0,0,0,0,0,0,9,0,0,2,0,0,0,0,0,0
0,0,0,0,0,0,9,0,0,2,0,0,0,0,0,0
:endlayer
layer: 6
0,0,0,0,0,0,0,0,0,8,0,0,0,0,0,0
0,0,0,0,0,0,0,0,0,0,0,0,0,0,0,0
0,0,0,0,0,0,16,0,0,8,0,0,0,0,0,0
0,0,0,0,0,0,0,0,0,0,0,0,0,0,0,0
0,0,0,0,16,0,0,0,0,8,0,0,0,0,0,0
0,0,0,0,0,0,0,0,0,0,0,0,0,0,0,0
0,0,0,0,0,0,1,5,5,1,0,0,0,0,0,0
0,0,0,0,0,0,0,0,0,5,0,0,0,0,0,0
0,0,0,0,0,0,0,0,0,14,0,0,0,0,0,0
0,0,0,0,0,0,1,5,5,1,0,0,0,0,0,0
0,0,0,0,0,0,0,0,0,0,0,0,0,0,0,0
0,0,0,0,16,0,0,0,0,8,0,0,0,0,0,0
0,0,0,0,0,0,0,0,0,0,0,0,0,0,0,0
0,0,0,0,0,0,16,0,0,8,0,0,0,0,0,0
0,0,0,0,0,0,0,0,0,0,0,0,0,0,0,0
0,0,0,0,0,0,0,0,0,8,0,0,0,0,0,0
:endlayer
layer: 7
0,0,0,0,0,0,0,0,0,0,0,0,0,0,0,0
0,0,0,0,0,0,0,0,0,0,0,0,0,0,0,0
0,0,0,0,0,0,0,0,0,0,0,0,0,0,0,0
0,0,0,0,0,0,0,0,0,0,0,0,0,0,0,0
0,0,0,0,0,0,0,0,0,0,0,0,0,0,0,0
0,0,0,0,0,0,9,0,0,9,0,0,0,0,0,0
0,0,0,0,0,9,1,5,5,1,9,0,0,0,0,0
0,0,0,0,0,0,18,0,0,5,0,0,0,0,0,0
0,0,0,0,0,0,17,0,0,5,0,0,0,0,0,0
0,0,0,0,0,9,1,5,5,1,9,0,0,0,0,0
0,0,0,0,0,0,9,0,0,9,0,0,0,0,0,0
0,0,0,0,0,0,0,0,0,0,0,0,0,0,0,0
0,0,0,0,0,0,0,0,0,0,0,0,0,0,0,0
0,0,0,0,0,0,0,0,0,0,0,0,0,0,0,0
0,0,0,0,0,0,0,0,0,0,0,0,0,0,0,0
0,0,0,0,0,0,0,0,0,0,0,0,0,0,0,0
:endlayer
layer: 8
0,0,0,0,0,0,0,0,0,0,0,0,0,0,0,0
0,0,0,0,0,0,0,0,0,0,0,0,0,0,0,0
0,0,0,0,0,0,0,0,0,0,0,0,0,0,0,0
0,0,0,0,0,0,0,0,0,0,0,0,0,0,0,0
0,0,0,0,0,0,0,0,0,0,0,0,0,0,0,0
0,0,0,0,0,6,7,7,7,7,7,0,0,0,0,0
0,0,0,0,0,6,1,3,3,1,8,0,0,0,0,0
0,0,0,0,0,6,2,0,0,2,8,0,0,0,0,0
0,0,0,0,0,6,2,0,0,2,8,0,0,0,0,0
0,0,0,0,0,6,1,3,3,1,8,0,0,0,0,0
0,0,0,0,0,4,4,4,4,4,4,0,0,0,0,0
0,0,0,0,0,0,0,0,0,0,0,0,0,0,0,0
0,0,0,0,0,0,0,0,0,0,0,0,0,0,0,0
0,0,0,0,0,0,0,0,0,0,0,0,0,0,0,0
0,0,0,0,0,0,0,0,0,0,0,0,0,0,0,0
0,0,0,0,0,0,0,0,0,0,0,0,0,0,0,0
:endlayer
layer: 9
0,0,0,0,0,0,0,0,0,0,0,0,0,0,0,0
0,0,0,0,0,0,0,0,0,0,0,0,0,0,0,0
0,0,0,0,0,0,0,0,0,0,0,0,0,0,0,0
0,0,0,0,0,0,0,0,0,0,0,0,0,0,0,0
0,0,0,0,0,0,0,0,0,0,0,0,0,0,0,0
0,0,0,0,0,0,0,0,0,0,0,0,0,0,0,0
0,0,0,0,0,0,19,19,19,19,0,0,0,0,0,0
0,0,0,0,0,0,19,5,5,19,0,0,0,0,0,0
0,0,0,0,0,0,19,5,5,19,0,0,0,0,0,0
0,0,0,0,0,0,19,19,19,19,0,0,0,0,0,0
0,0,0,0,0,0,0,0,0,0,0,0,0,0,0,0
0,0,0,0,0,0,0,0,0,0,0,0,0,0,0,0
0,0,0,0,0,0,0,0,0,0,0,0,0,0,0,0
0,0,0,0,0,0,0,0,0,0,0,0,0,0,0,0
0,0,0,0,0,0,0,0,0,0,0,0,0,0,0,0
0,0,0,0,0,0,0,0,0,0,0,0,0,0,0,0
:endlayer
layer: 10
0,0,0,0,0,0,0,0,0,0,0,0,0,0,0,0
0,0,0,0,0,0,0,0,0,0,0,0,0,0,0,0
0,0,0,0,0,0,0,0,0,0,0,0,0,0,0,0
0,0,0,0,0,0,0,0,0,0,0,0,0,0,0,0
0,0,0,0,0,0,0,0,0,0,0,0,0,0,0,0
0,0,0,0,0,0,0,0,0,0,0,0,0,0,0,0
0,0,0,0,0,0,0,0,0,0,0,0,0,0,0,0
0,0,0,0,0,0,0,0,0,0,0,0,0,0,0,0
0,0,0,0,0,0,0,16,0,0,0,0,0,0,0,0
0,0,0,0,0,0,0,0,0,0,0,0,0,0,0,0
0,0,0,0,0,0,0,0,0,0,0,0,0,0,0,0
0,0,0,0,0,0,0,0,0,0,0,0,0,0,0,0
0,0,0,0,0,0,0,0,0,0,0,0,0,0,0,0
0,0,0,0,0,0,0,0,0,0,0,0,0,0,0,0
0,0,0,0,0,0,0,0,0,0,0,0,0,0,0,0
0,0,0,0,0,0,0,0,0,0,0,0,0,0,0,0
:endlayer

#### RULES ####
rule:
plugin=vanillaBlocks
number=1
data:
JSON:{blockState:{blockName:"minecraft:log",properties:{variant:"birch",axis:"y"}}}
:enddata
:endrule

rule:
plugin=vanillaBlocks
number=2
data:
JSON:{blockState:{blockName:"minecraft:log",properties:{variant:"birch",axis:"z"}}}
:enddata
:endrule

rule:
plugin=vanillaBlocks
number=3
data:
JSON:{blockState:{blockName:"minecraft:log",properties:{variant:"birch",axis:"x"}}}
:enddata
:endrule

rule:
plugin=vanillaBlocks
number=4
data:
JSON:{blockState:{blockName:"minecraft:birch_stairs",properties:{half:"bottom",shape:"straight",facing:"north"}}}
:enddata
:endrule

rule:
plugin=vanillaBlocks
number=5
data:
JSON:{blockState:{blockName:"minecraft:planks",properties:{variant:"birch"}}}
:enddata
:endrule

rule:
plugin=vanillaBlocks
number=6
data:
JSON:{blockState:{blockName:"minecraft:birch_stairs",properties:{half:"bottom",shape:"straight",facing:"east"}}}
:enddata
:endrule

rule:
plugin=vanillaBlocks
number=7
data:
JSON:{blockState:{blockName:"minecraft:birch_stairs",properties:{half:"bottom",shape:"straight",facing:"south"}}}
:enddata
:endrule

rule:
plugin=vanillaBlocks
number=8
data:
JSON:{blockState:{blockName:"minecraft:birch_stairs",properties:{half:"bottom",shape:"straight",facing:"west"}}}
:enddata
:endrule

rule:
plugin=vanillaBlocks
number=9
data:
JSON:{blockState:{blockName:"minecraft:birch_fence",properties:{east:"false",south:"false",north:"false",west:"false"}}}
:enddata
:endrule

rule:
plugin=vanillaBlocks
number=10
data:
JSON:{blockState:{blockName:"minecraft:birch_stairs",properties:{half:"top",shape:"straight",facing:"east"}}}
:enddata
:endrule

rule:
plugin=vanillaBlocks
number=11
data:
JSON:{blockState:{blockName:"minecraft:torch",properties:{facing:"west"}}}
:enddata
:endrule

rule:
plugin=vanillaBlocks
number=12
data:
JSON:{blockState:{blockName:"minecraft:torch",properties:{facing:"east"}}}
:enddata
:endrule

rule:
plugin=vanillaBlocks
number=13
data:
JSON:{blockState:{blockName:"minecraft:torch",properties:{facing:"north"}}}
:enddata
:endrule

rule:
plugin=vanillaBlocks
number=14
data:
JSON:{blockState:{blockName:"minecraft:birch_stairs",properties:{half:"top",shape:"straight",facing:"west"}}}
:enddata
:endrule

rule:
plugin=vanillaBlocks
number=15
data:
JSON:{blockState:{blockName:"minecraft:wooden_slab",properties:{half:"top",variant:"birch"}}}
:enddata
:endrule

rule:
plugin=vanillaBlocks
number=16
data:
JSON:{blockState:{blockName:"minecraft:torch",properties:{facing:"up"}}}
:enddata
:endrule

rule:
plugin=vanillaBlocks
number=17
data:
JSON:{blockState:{blockName:"minecraft:birch_stairs",properties:{half:"top",shape:"straight",facing:"south"}}}
:enddata
:endrule

rule:
plugin=vanillaBlocks
number=18
data:
JSON:{blockState:{blockName:"minecraft:birch_stairs",properties:{half:"top",shape:"straight",facing:"north"}}}
:enddata
:endrule

rule:
plugin=vanillaBlocks
number=19
data:
JSON:{blockState:{blockName:"minecraft:wooden_slab",properties:{half:"bottom",variant:"birch"}}}
:enddata
:endrule

#### ENTITIES ####
