# Ancient Warfare Structure Template File
# Auto-generated structure template file. created on: 3/19/2021 at: 18:8:47
# Lines beginning with # denote comments

header:
version=2.11
name=SurvivalBuild_SiegeCampTentL_RUSTICironwood
mods=rustic
size=21,11,12
offset=10,0,11
:endheader

#### VALIDATION ####
validation:
type=ground
structureAuthor=TheOddlySeagull
survival=true
worldGenEnabled=false
unique=false
preserveBlocks=false
preventNaturalHostileSpawns=false
selectionWeight=1
clusterValue=1
minDuplicateDistance=1
dimensionWhiteList=true
dimensionList=
biomeGroupList=
biomeWhiteList=true
biomeList=
leveling=0
fill=0
border=0
blockSwap=false
territoryName=
biomeReplacement=minecraft:
minGenerationHeight=0
maxGenerationHeight=255
:endvalidation

#### LAYERS ####
layer: 0
0,0,0,0,1,2,3,2,3,2,3,2,3,2,3,2,1,0,0,0,0
0,0,1,2,3,1,0,0,0,0,1,0,0,0,0,1,3,2,1,0,0
0,1,3,0,0,0,0,0,0,0,0,0,0,0,0,0,0,0,3,1,0
0,2,1,0,0,0,0,0,0,0,0,0,0,0,0,0,0,0,1,2,0
0,3,0,0,0,0,0,0,0,0,0,0,0,0,0,0,0,0,0,3,0
0,2,0,0,0,0,4,0,0,0,0,0,0,0,4,0,0,0,0,2,0
0,3,0,0,0,0,0,0,0,0,0,0,0,0,0,0,0,0,0,3,0
0,2,1,0,0,0,0,0,0,0,0,0,0,0,0,0,0,0,1,2,0
0,1,3,0,0,0,0,0,0,0,0,0,0,0,0,0,0,0,3,1,0
0,0,1,2,3,1,0,0,0,0,0,0,0,0,0,1,3,2,1,0,0
0,0,0,0,1,2,3,2,3,0,0,0,3,2,3,2,1,0,0,0,0
0,0,0,0,0,0,0,0,1,0,0,0,1,0,0,0,0,0,0,0,0
:endlayer
layer: 1
0,0,0,0,1,2,3,2,3,2,3,2,3,2,3,2,1,0,0,0,0
0,0,1,2,3,1,0,0,0,0,1,0,0,0,0,1,3,2,1,0,0
0,1,3,0,0,0,0,0,0,0,0,0,0,0,0,0,0,0,3,1,0
0,2,1,0,0,0,0,0,0,0,0,0,0,0,0,0,0,0,1,2,0
0,3,0,0,0,0,0,0,0,0,0,0,0,0,0,0,0,0,0,3,0
0,2,0,0,0,0,4,0,0,0,0,0,0,0,4,0,0,0,0,2,0
0,3,0,0,0,0,0,0,0,0,0,0,0,0,0,0,0,0,0,3,0
0,2,1,0,0,0,0,0,0,0,0,0,0,0,0,0,0,0,1,2,0
0,1,3,0,0,0,0,0,0,0,0,0,0,0,0,0,0,0,3,1,0
0,0,1,2,3,1,0,0,0,0,0,0,0,0,0,1,3,2,1,0,0
0,0,0,0,1,2,3,2,3,0,0,0,3,2,3,2,1,0,0,0,0
0,0,0,0,0,0,0,0,1,0,0,0,1,0,0,0,0,0,0,0,0
:endlayer
layer: 2
0,0,0,0,1,2,3,2,3,2,3,2,3,2,3,2,1,0,0,0,0
0,0,1,2,3,1,0,0,6,0,1,0,6,0,0,1,3,2,1,0,0
0,1,3,6,0,0,0,0,0,0,0,0,0,0,0,0,0,6,3,1,0
0,2,1,0,0,0,0,0,0,0,0,0,0,0,0,0,0,0,1,2,0
1,3,0,0,0,0,5,0,0,0,0,0,0,0,5,0,0,0,0,3,1
0,1,0,0,0,7,4,8,0,0,0,0,0,7,4,8,0,0,0,1,0
1,3,0,0,0,0,6,0,0,0,0,0,0,0,6,0,0,0,0,3,1
0,2,1,0,0,0,0,0,0,0,0,0,0,0,0,0,0,0,1,2,0
0,1,3,5,0,0,0,0,0,0,0,0,0,0,0,0,0,0,3,1,0
0,0,1,2,3,1,0,0,0,0,0,0,0,0,0,1,3,2,1,0,0
0,0,0,0,1,2,3,2,3,2,0,2,3,2,3,2,1,0,0,0,0
0,0,0,0,0,0,0,6,1,0,0,0,1,6,0,0,0,0,0,0,0
:endlayer
layer: 3
0,0,0,0,1,2,3,2,3,2,3,2,3,2,3,2,1,0,0,0,0
0,0,1,2,3,1,0,0,0,0,1,0,0,0,0,1,3,2,1,0,0
0,1,3,0,0,0,0,0,0,0,0,0,0,0,0,0,0,0,3,1,0
0,2,1,0,0,0,0,0,0,0,0,0,0,0,0,0,0,0,1,2,0
9,3,0,0,0,0,0,0,0,0,0,0,0,0,0,0,0,0,0,3,9
10,2,0,0,0,0,4,0,0,0,0,0,0,0,4,0,0,0,0,2,10
9,3,0,0,0,0,0,0,0,0,0,0,0,0,0,0,0,0,0,3,9
0,2,1,0,0,0,0,0,0,0,0,0,0,0,0,0,0,0,1,2,0
0,1,3,0,0,0,0,0,0,0,0,0,0,0,0,0,0,0,3,1,0
0,0,1,2,3,1,0,0,0,0,5,0,0,0,0,1,3,2,1,0,0
0,0,0,0,1,2,3,2,3,2,3,2,3,2,3,2,1,0,0,0,0
0,0,0,0,0,0,0,0,9,10,10,10,9,0,0,0,0,0,0,0,0
:endlayer
layer: 4
0,0,0,0,0,0,0,0,0,0,0,0,0,0,0,0,0,0,0,0,0
0,0,0,0,0,2,2,2,2,2,2,2,2,2,2,2,0,0,0,0,0
0,0,0,2,2,1,0,0,0,0,1,0,0,0,0,1,2,2,0,0,0
0,0,2,1,0,0,0,0,0,0,0,0,0,0,0,0,0,1,2,0,0
0,0,2,0,0,0,0,0,0,0,0,0,0,0,0,0,0,0,2,0,0
0,0,2,0,0,0,4,0,0,0,0,0,0,0,4,0,0,0,2,0,0
0,0,2,0,0,0,0,0,0,0,0,0,0,0,0,0,0,0,2,0,0
0,0,2,1,0,0,0,0,0,0,0,0,0,0,0,0,0,1,2,0,0
0,0,0,2,2,1,0,0,0,0,0,0,0,0,0,1,2,2,0,0,0
0,0,0,0,0,2,2,2,2,2,2,2,2,2,2,2,0,0,0,0,0
0,0,0,0,0,0,0,0,0,0,0,0,0,0,0,0,0,0,0,0,0
0,0,0,0,0,0,0,0,0,0,0,0,0,0,0,0,0,0,0,0,0
:endlayer
layer: 5
0,0,0,0,0,0,0,0,0,0,0,0,0,0,0,0,0,0,0,0,0
0,0,0,0,0,0,0,0,0,0,0,0,0,0,0,0,0,0,0,0,0
0,0,0,0,0,3,3,3,3,3,3,3,3,3,3,3,0,0,0,0,0
0,0,0,3,3,1,0,0,0,3,3,3,0,0,0,1,3,3,0,0,0
0,0,0,3,0,0,0,0,0,0,1,0,0,0,0,0,0,3,0,0,0
0,0,0,3,0,0,4,0,0,0,0,0,0,0,4,0,0,3,0,0,0
0,0,0,3,0,0,0,0,0,0,1,0,0,0,0,0,0,3,0,0,0
0,0,0,3,3,1,0,0,0,3,3,3,0,0,0,1,3,3,0,0,0
0,0,0,0,0,3,3,3,3,3,3,3,3,3,3,3,0,0,0,0,0
0,0,0,0,0,0,0,0,0,0,0,0,0,0,0,0,0,0,0,0,0
0,0,0,0,0,0,0,0,0,0,0,0,0,0,0,0,0,0,0,0,0
0,0,0,0,0,0,0,0,0,0,0,0,0,0,0,0,0,0,0,0,0
:endlayer
layer: 6
0,0,0,0,0,0,0,0,0,0,0,0,0,0,0,0,0,0,0,0,0
0,0,0,0,0,0,0,0,0,0,0,0,0,0,0,0,0,0,0,0,0
0,0,0,0,0,0,5,0,0,0,0,0,0,0,5,0,0,0,0,0,0
0,0,0,0,0,11,11,11,11,0,5,0,11,11,11,11,0,0,0,0,0
0,0,0,0,11,11,1,11,11,11,11,11,11,11,1,11,11,0,0,0,0
0,0,0,7,11,1,4,1,0,11,11,11,0,1,4,1,11,8,0,0,0
0,0,0,0,11,11,1,11,11,11,11,11,11,11,1,11,11,0,0,0,0
0,0,0,0,0,11,11,11,11,0,6,0,11,11,11,11,0,0,0,0,0
0,0,0,0,0,0,6,0,0,0,0,0,0,0,6,0,0,0,0,0,0
0,0,0,0,0,0,0,0,0,0,0,0,0,0,0,0,0,0,0,0,0
0,0,0,0,0,0,0,0,0,0,0,0,0,0,0,0,0,0,0,0,0
0,0,0,0,0,0,0,0,0,0,0,0,0,0,0,0,0,0,0,0,0
:endlayer
layer: 7
0,0,0,0,0,0,0,0,0,0,0,0,0,0,0,0,0,0,0,0,0
0,0,0,0,0,0,0,0,0,0,0,0,0,0,0,0,0,0,0,0,0
0,0,0,0,0,0,0,0,0,0,0,0,0,0,0,0,0,0,0,0,0
0,0,0,0,0,0,0,0,0,0,0,0,0,0,0,0,0,0,0,0,0
0,0,0,0,0,0,11,0,0,0,0,0,0,0,11,0,0,0,0,0,0
0,0,0,0,0,11,4,11,11,0,0,0,11,11,4,11,0,0,0,0,0
0,0,0,0,0,0,11,0,0,0,0,0,0,0,11,0,0,0,0,0,0
0,0,0,0,0,0,0,0,0,0,0,0,0,0,0,0,0,0,0,0,0
0,0,0,0,0,0,0,0,0,0,0,0,0,0,0,0,0,0,0,0,0
0,0,0,0,0,0,0,0,0,0,0,0,0,0,0,0,0,0,0,0,0
0,0,0,0,0,0,0,0,0,0,0,0,0,0,0,0,0,0,0,0,0
0,0,0,0,0,0,0,0,0,0,0,0,0,0,0,0,0,0,0,0,0
:endlayer
layer: 8
0,0,0,0,0,0,0,0,0,0,0,0,0,0,0,0,0,0,0,0,0
0,0,0,0,0,0,0,0,0,0,0,0,0,0,0,0,0,0,0,0,0
0,0,0,0,0,0,0,0,0,0,0,0,0,0,0,0,0,0,0,0,0
0,0,0,0,0,0,0,0,0,0,0,0,0,0,0,0,0,0,0,0,0
0,0,0,0,0,0,0,0,0,0,0,0,0,0,0,0,0,0,0,0,0
0,0,0,0,0,0,3,0,0,0,0,0,0,0,3,0,0,0,0,0,0
0,0,0,0,0,0,0,0,0,0,0,0,0,0,0,0,0,0,0,0,0
0,0,0,0,0,0,0,0,0,0,0,0,0,0,0,0,0,0,0,0,0
0,0,0,0,0,0,0,0,0,0,0,0,0,0,0,0,0,0,0,0,0
0,0,0,0,0,0,0,0,0,0,0,0,0,0,0,0,0,0,0,0,0
0,0,0,0,0,0,0,0,0,0,0,0,0,0,0,0,0,0,0,0,0
0,0,0,0,0,0,0,0,0,0,0,0,0,0,0,0,0,0,0,0,0
:endlayer
layer: 9
0,0,0,0,0,0,0,0,0,0,0,0,0,0,0,0,0,0,0,0,0
0,0,0,0,0,0,0,0,0,0,0,0,0,0,0,0,0,0,0,0,0
0,0,0,0,0,0,0,0,0,0,0,0,0,0,0,0,0,0,0,0,0
0,0,0,0,0,0,0,0,0,0,0,0,0,0,0,0,0,0,0,0,0
0,0,0,0,0,0,0,0,0,0,0,0,0,0,0,0,0,0,0,0,0
0,0,0,0,0,0,1,0,0,0,0,0,0,0,1,0,0,0,0,0,0
0,0,0,0,0,0,0,0,0,0,0,0,0,0,0,0,0,0,0,0,0
0,0,0,0,0,0,0,0,0,0,0,0,0,0,0,0,0,0,0,0,0
0,0,0,0,0,0,0,0,0,0,0,0,0,0,0,0,0,0,0,0,0
0,0,0,0,0,0,0,0,0,0,0,0,0,0,0,0,0,0,0,0,0
0,0,0,0,0,0,0,0,0,0,0,0,0,0,0,0,0,0,0,0,0
0,0,0,0,0,0,0,0,0,0,0,0,0,0,0,0,0,0,0,0,0
:endlayer
layer: 10
0,0,0,0,0,0,0,0,0,0,0,0,0,0,0,0,0,0,0,0,0
0,0,0,0,0,0,0,0,0,0,0,0,0,0,0,0,0,0,0,0,0
0,0,0,0,0,0,0,0,0,0,0,0,0,0,0,0,0,0,0,0,0
0,0,0,0,0,0,0,0,0,0,0,0,0,0,0,0,0,0,0,0,0
0,0,0,0,0,0,0,0,0,0,0,0,0,0,0,0,0,0,0,0,0
0,0,0,0,0,0,1,0,0,0,0,0,0,0,1,0,0,0,0,0,0
0,0,0,0,0,0,0,0,0,0,0,0,0,0,0,0,0,0,0,0,0
0,0,0,0,0,0,0,0,0,0,0,0,0,0,0,0,0,0,0,0,0
0,0,0,0,0,0,0,0,0,0,0,0,0,0,0,0,0,0,0,0,0
0,0,0,0,0,0,0,0,0,0,0,0,0,0,0,0,0,0,0,0,0
0,0,0,0,0,0,0,0,0,0,0,0,0,0,0,0,0,0,0,0,0
0,0,0,0,0,0,0,0,0,0,0,0,0,0,0,0,0,0,0,0,0
:endlayer

#### RULES ####
rule:
plugin=vanillaBlocks
number=1
data:
JSON:{blockState:{blockName:"rustic:fence_ironwood",properties:{east:"false",south:"false",north:"false",west:"false"}}}
:enddata
:endrule

rule:
plugin=vanillaBlocks
number=2
data:
JSON:{blockState:{blockName:"minecraft:wool",properties:{color:"green"}}}
:enddata
:endrule

rule:
plugin=vanillaBlocks
number=3
data:
JSON:{blockState:{blockName:"minecraft:wool",properties:{color:"brown"}}}
:enddata
:endrule

rule:
plugin=vanillaBlocks
number=4
data:
JSON:{blockState:{blockName:"rustic:log",properties:{variant:"ironwood",axis:"y"}}}
:enddata
:endrule

rule:
plugin=vanillaBlocks
number=5
data:
JSON:{blockState:{blockName:"minecraft:torch",properties:{facing:"north"}}}
:enddata
:endrule

rule:
plugin=vanillaBlocks
number=6
data:
JSON:{blockState:{blockName:"minecraft:torch",properties:{facing:"south"}}}
:enddata
:endrule

rule:
plugin=vanillaBlocks
number=7
data:
JSON:{blockState:{blockName:"minecraft:torch",properties:{facing:"west"}}}
:enddata
:endrule

rule:
plugin=vanillaBlocks
number=8
data:
JSON:{blockState:{blockName:"minecraft:torch",properties:{facing:"east"}}}
:enddata
:endrule

rule:
plugin=vanillaBlocks
number=9
data:
JSON:{blockState:{blockName:"rustic:ironwood_slab",properties:{half:"bottom"}}}
:enddata
:endrule

rule:
plugin=vanillaBlocks
number=10
data:
JSON:{blockState:{blockName:"rustic:ironwood_slab",properties:{half:"top"}}}
:enddata
:endrule

rule:
plugin=vanillaBlocks
number=11
data:
JSON:{blockState:{blockName:"minecraft:wool",properties:{color:"silver"}}}
:enddata
:endrule

#### ENTITIES ####
