# Ancient Warfare Structure Template File
# Auto-generated structure template file. created on: 6/18/2023 at: 11:27:3
# Lines beginning with # denote comments

header:
version=2.11
name=SB_ArdminRoad_bridge_10t15s_1
mods=minefantasyreeforged
size=11,12,21
offset=5,10,21
:endheader

#### VALIDATION ####
validation:
type=ground
structureAuthor=TheOddlySeagull
survival=true
worldGenEnabled=false
unique=false
preserveBlocks=true
preventNaturalHostileSpawns=false
selectionWeight=1
clusterValue=1
minDuplicateDistance=1
dimensionWhiteList=true
dimensionList=
biomeGroupList=
biomeWhiteList=true
biomeList=
leveling=0
fill=0
border=0
blockSwap=false
territoryName=
biomeReplacement=minecraft:
minGenerationHeight=0
maxGenerationHeight=255
:endvalidation

#### LAYERS ####
layer: 0
1,1,1,0,0,0,0,0,1,1,1
1,1,1,0,0,0,0,0,1,1,1
1,1,1,0,0,0,0,0,1,1,1
0,0,0,0,0,0,0,0,0,0,0
0,0,0,0,0,0,0,0,0,0,0
0,0,0,0,0,0,0,0,0,0,0
0,0,0,0,0,0,0,0,0,0,0
0,0,0,0,0,0,0,0,0,0,0
0,0,0,0,0,0,0,0,0,0,0
0,0,0,0,0,0,0,0,0,0,0
0,0,0,0,0,0,0,0,0,0,0
0,0,0,0,0,0,0,0,0,0,0
0,0,0,0,0,0,0,0,0,0,0
0,0,0,0,0,0,0,0,0,0,0
0,0,0,0,0,0,0,0,0,0,0
0,0,0,0,0,0,0,0,0,0,0
0,0,0,0,0,0,0,0,0,0,0
0,0,0,0,0,0,0,0,0,0,0
1,1,1,0,0,0,0,0,1,1,1
1,1,1,0,0,0,0,0,1,1,1
1,1,1,0,0,0,0,0,1,1,1
:endlayer
layer: 1
1,1,1,0,0,0,0,0,1,1,1
1,1,1,0,0,0,0,0,1,1,1
1,1,1,0,0,0,0,0,1,1,1
0,0,0,0,0,0,0,0,0,0,0
0,0,0,0,0,0,0,0,0,0,0
0,0,0,0,0,0,0,0,0,0,0
0,0,0,0,0,0,0,0,0,0,0
0,0,0,0,0,0,0,0,0,0,0
0,0,0,0,0,0,0,0,0,0,0
0,0,0,0,0,0,0,0,0,0,0
0,0,0,0,0,0,0,0,0,0,0
0,0,0,0,0,0,0,0,0,0,0
0,0,0,0,0,0,0,0,0,0,0
0,0,0,0,0,0,0,0,0,0,0
0,0,0,0,0,0,0,0,0,0,0
0,0,0,0,0,0,0,0,0,0,0
0,0,0,0,0,0,0,0,0,0,0
0,0,0,0,0,0,0,0,0,0,0
1,1,1,0,0,0,0,0,1,1,1
1,1,1,0,0,0,0,0,1,1,1
1,1,1,0,0,0,0,0,1,1,1
:endlayer
layer: 2
1,1,1,0,0,0,0,0,1,1,1
1,1,1,0,0,0,0,0,1,1,1
1,1,1,0,0,0,0,0,1,1,1
0,0,0,0,0,0,0,0,0,0,0
0,0,0,0,0,0,0,0,0,0,0
0,0,0,0,0,0,0,0,0,0,0
0,0,0,0,0,0,0,0,0,0,0
0,0,0,0,0,0,0,0,0,0,0
0,0,0,0,0,0,0,0,0,0,0
0,0,0,0,0,0,0,0,0,0,0
0,0,0,0,0,0,0,0,0,0,0
0,0,0,0,0,0,0,0,0,0,0
0,0,0,0,0,0,0,0,0,0,0
0,0,0,0,0,0,0,0,0,0,0
0,0,0,0,0,0,0,0,0,0,0
0,0,0,0,0,0,0,0,0,0,0
0,0,0,0,0,0,0,0,0,0,0
0,0,0,0,0,0,0,0,0,0,0
1,1,1,0,0,0,0,0,1,1,1
1,1,1,0,0,0,0,0,1,1,1
1,1,1,0,0,0,0,0,1,1,1
:endlayer
layer: 3
1,1,1,0,0,0,0,0,1,1,1
1,1,1,0,0,0,0,0,1,1,1
1,1,1,0,0,0,0,0,1,1,1
0,0,0,0,0,0,0,0,0,0,0
0,0,0,0,0,0,0,0,0,0,0
0,0,0,0,0,0,0,0,0,0,0
0,0,0,0,0,0,0,0,0,0,0
0,0,0,0,0,0,0,0,0,0,0
0,0,0,0,0,0,0,0,0,0,0
0,0,0,0,0,0,0,0,0,0,0
0,0,0,0,0,0,0,0,0,0,0
0,0,0,0,0,0,0,0,0,0,0
0,0,0,0,0,0,0,0,0,0,0
0,0,0,0,0,0,0,0,0,0,0
0,0,0,0,0,0,0,0,0,0,0
0,0,0,0,0,0,0,0,0,0,0
0,0,0,0,0,0,0,0,0,0,0
0,0,0,0,0,0,0,0,0,0,0
1,1,1,0,0,0,0,0,1,1,1
1,1,1,0,0,0,0,0,1,1,1
1,1,1,0,0,0,0,0,1,1,1
:endlayer
layer: 4
1,1,1,0,0,0,0,0,1,1,1
1,1,1,0,0,0,0,0,1,1,1
1,1,1,0,0,0,0,0,1,1,1
0,0,0,0,0,0,0,0,0,0,0
0,0,0,0,0,0,0,0,0,0,0
0,0,0,0,0,0,0,0,0,0,0
0,0,0,0,0,0,0,0,0,0,0
0,0,0,0,0,0,0,0,0,0,0
0,0,0,0,0,0,0,0,0,0,0
0,0,0,0,0,0,0,0,0,0,0
0,0,0,0,0,0,0,0,0,0,0
0,0,0,0,0,0,0,0,0,0,0
0,0,0,0,0,0,0,0,0,0,0
0,0,0,0,0,0,0,0,0,0,0
0,0,0,0,0,0,0,0,0,0,0
0,0,0,0,0,0,0,0,0,0,0
0,0,0,0,0,0,0,0,0,0,0
0,0,0,0,0,0,0,0,0,0,0
1,1,1,0,0,0,0,0,1,1,1
1,1,1,0,0,0,0,0,1,1,1
1,1,1,0,0,0,0,0,1,1,1
:endlayer
layer: 5
1,1,1,0,0,0,0,0,1,1,1
1,1,1,3,0,0,0,2,1,1,1
1,1,1,0,0,0,0,0,1,1,1
0,5,0,0,0,0,0,0,0,5,0
0,0,0,0,0,0,0,0,0,0,0
0,0,0,0,0,0,0,0,0,0,0
0,0,0,0,0,0,0,0,0,0,0
0,0,0,0,0,0,0,0,0,0,0
0,0,0,0,0,0,0,0,0,0,0
0,0,0,0,0,0,0,0,0,0,0
0,0,0,0,0,0,0,0,0,0,0
0,0,0,0,0,0,0,0,0,0,0
0,0,0,0,0,0,0,0,0,0,0
0,0,0,0,0,0,0,0,0,0,0
0,0,0,0,0,0,0,0,0,0,0
0,0,0,0,0,0,0,0,0,0,0
0,0,0,0,0,0,0,0,0,0,0
0,4,0,0,0,0,0,0,0,4,0
1,1,1,0,0,0,0,0,1,1,1
1,1,1,3,0,0,0,2,1,1,1
1,1,1,0,0,0,0,0,1,1,1
:endlayer
layer: 6
1,1,1,3,0,0,0,2,1,1,1
1,1,1,1,6,0,6,1,1,1,1
1,1,1,3,0,0,0,2,1,1,1
0,1,0,0,0,0,0,0,0,1,0
0,1,0,0,0,0,0,0,0,1,0
0,6,0,0,0,0,0,0,0,6,0
0,0,0,0,0,0,0,0,0,0,0
0,0,0,0,0,0,0,0,0,0,0
0,0,0,0,0,0,0,0,0,0,0
0,0,0,0,0,0,0,0,0,0,0
0,0,0,0,0,0,0,0,0,0,0
0,0,0,0,0,0,0,0,0,0,0
0,0,0,0,0,0,0,0,0,0,0
0,0,0,0,0,0,0,0,0,0,0
0,0,0,0,0,0,0,0,0,0,0
0,6,0,0,0,0,0,0,0,6,0
0,1,0,0,0,0,0,0,0,1,0
0,1,0,0,0,0,0,0,0,1,0
1,1,1,3,0,0,0,2,1,1,1
1,1,1,1,6,0,6,1,1,1,1
1,1,1,3,0,0,0,2,1,1,1
:endlayer
layer: 7
1,1,1,1,1,1,1,1,1,1,1
1,1,1,1,1,1,1,1,1,1,1
1,1,1,1,1,1,1,1,1,1,1
0,1,0,0,0,0,0,0,0,1,0
0,1,0,0,0,0,0,0,0,1,0
0,1,0,0,0,0,0,0,0,1,0
0,1,0,0,0,0,0,0,0,1,0
0,6,0,0,0,0,0,0,0,6,0
0,6,0,0,0,0,0,0,0,6,0
0,0,0,0,0,0,0,0,0,0,0
0,0,0,0,0,0,0,0,0,0,0
0,0,0,0,0,0,0,0,0,0,0
0,6,0,0,0,0,0,0,0,6,0
0,6,0,0,0,0,0,0,0,6,0
0,1,0,0,0,0,0,0,0,1,0
0,1,0,0,0,0,0,0,0,1,0
0,1,0,0,0,0,0,0,0,1,0
0,1,0,0,0,0,0,0,0,1,0
1,1,1,1,1,1,1,1,1,1,1
1,1,1,1,1,1,1,1,1,1,1
1,1,1,1,1,1,1,1,1,1,1
:endlayer
layer: 8
1,1,1,1,1,1,1,1,1,1,1
1,1,1,1,1,1,1,1,1,1,1
1,1,1,1,1,1,1,1,1,1,1
0,1,3,5,5,1,5,5,2,1,0
0,1,3,6,6,1,6,6,2,1,0
0,1,3,6,6,1,6,6,2,1,0
0,1,3,6,6,1,6,6,2,1,0
0,1,1,1,1,1,1,1,1,1,0
0,1,3,6,6,1,6,6,2,1,0
0,1,3,6,6,1,6,6,2,1,0
0,1,3,6,6,1,6,6,2,1,0
0,1,3,6,6,1,6,6,2,1,0
0,1,3,6,6,1,6,6,2,1,0
0,1,1,1,1,1,1,1,1,1,0
0,1,3,6,6,1,6,6,2,1,0
0,1,3,6,6,1,6,6,2,1,0
0,1,3,6,6,1,6,6,2,1,0
0,1,3,4,4,1,4,4,2,1,0
1,1,1,1,1,1,1,1,1,1,1
1,1,1,1,1,1,1,1,1,1,1
1,1,1,1,1,1,1,1,1,1,1
:endlayer
layer: 9
10,1,1,8,8,8,8,8,1,1,10
9,1,1,8,8,8,8,8,1,1,9
7,1,1,8,8,8,8,8,1,1,7
0,1,1,8,8,8,8,8,1,1,0
0,1,1,8,8,8,8,8,1,1,0
0,1,1,8,8,8,8,8,1,1,0
0,9,1,8,8,8,8,8,1,9,0
0,1,1,8,8,8,8,8,1,1,0
0,1,1,8,8,8,8,8,1,1,0
0,1,1,8,8,8,8,8,1,1,0
0,9,1,8,8,8,8,8,1,9,0
0,1,1,8,8,8,8,8,1,1,0
0,1,1,8,8,8,8,8,1,1,0
0,1,1,8,8,8,8,8,1,1,0
0,9,1,8,8,8,8,8,1,9,0
0,1,1,8,8,8,8,8,1,1,0
0,1,1,8,8,8,8,8,1,1,0
0,1,1,8,8,8,8,8,1,1,0
10,1,1,8,8,8,8,8,1,1,10
9,1,1,8,8,8,8,8,1,1,9
7,1,1,8,8,8,8,8,1,1,7
:endlayer
layer: 10
0,1,0,0,0,0,0,0,0,1,0
12,1,0,0,0,0,0,0,0,1,11
0,1,0,0,0,0,0,0,0,1,0
0,13,0,0,0,0,0,0,0,13,0
0,13,0,0,0,0,0,0,0,13,0
0,13,0,0,0,0,0,0,0,13,0
0,1,0,0,0,0,0,0,0,1,0
0,13,0,0,0,0,0,0,0,13,0
0,13,0,0,0,0,0,0,0,13,0
0,13,0,0,0,0,0,0,0,13,0
0,13,0,0,0,0,0,0,0,13,0
0,13,0,0,0,0,0,0,0,13,0
0,13,0,0,0,0,0,0,0,13,0
0,13,0,0,0,0,0,0,0,13,0
0,1,0,0,0,0,0,0,0,1,0
0,13,0,0,0,0,0,0,0,13,0
0,13,0,0,0,0,0,0,0,13,0
0,13,0,0,0,0,0,0,0,13,0
0,1,0,0,0,0,0,0,0,1,0
12,1,0,0,0,0,0,0,0,1,11
0,1,0,0,0,0,0,0,0,1,0
:endlayer
layer: 11
0,14,0,0,0,0,0,0,0,14,0
0,14,0,0,0,0,0,0,0,14,0
0,14,0,0,0,0,0,0,0,14,0
0,0,0,0,0,0,0,0,0,0,0
0,0,0,0,0,0,0,0,0,0,0
0,0,0,0,0,0,0,0,0,0,0
0,14,0,0,0,0,0,0,0,14,0
0,0,0,0,0,0,0,0,0,0,0
0,0,0,0,0,0,0,0,0,0,0
0,0,0,0,0,0,0,0,0,0,0
0,0,0,0,0,0,0,0,0,0,0
0,0,0,0,0,0,0,0,0,0,0
0,0,0,0,0,0,0,0,0,0,0
0,0,0,0,0,0,0,0,0,0,0
0,14,0,0,0,0,0,0,0,14,0
0,0,0,0,0,0,0,0,0,0,0
0,0,0,0,0,0,0,0,0,0,0
0,0,0,0,0,0,0,0,0,0,0
0,14,0,0,0,0,0,0,0,14,0
0,14,0,0,0,0,0,0,0,14,0
0,14,0,0,0,0,0,0,0,14,0
:endlayer

#### RULES ####
rule:
plugin=vanillaBlocks
number=1
data:
JSON:{blockState:{blockName:"minecraft:stonebrick",properties:{variant:"stonebrick"}}}
:enddata
:endrule

rule:
plugin=vanillaBlocks
number=2
data:
JSON:{blockState:{blockName:"minecraft:stone_brick_stairs",properties:{half:"top",shape:"straight",facing:"east"}}}
:enddata
:endrule

rule:
plugin=vanillaBlocks
number=3
data:
JSON:{blockState:{blockName:"minecraft:stone_brick_stairs",properties:{half:"top",shape:"straight",facing:"west"}}}
:enddata
:endrule

rule:
plugin=vanillaBlocks
number=4
data:
JSON:{blockState:{blockName:"minecraft:stone_brick_stairs",properties:{half:"top",shape:"straight",facing:"south"}}}
:enddata
:endrule

rule:
plugin=vanillaBlocks
number=5
data:
JSON:{blockState:{blockName:"minecraft:stone_brick_stairs",properties:{half:"top",shape:"straight",facing:"north"}}}
:enddata
:endrule

rule:
plugin=vanillaBlocks
number=6
data:
JSON:{blockState:{blockName:"minecraft:stone_slab",properties:{half:"top",variant:"stone_brick"}}}
:enddata
:endrule

rule:
plugin=vanillaBlocks
number=7
data:
JSON:{blockState:{blockName:"minecraft:stone_brick_stairs",properties:{half:"bottom",shape:"straight",facing:"north"}}}
:enddata
:endrule

rule:
plugin=vanillaBlocks
number=8
data:
JSON:{blockState:{blockName:"minefantasyreforged:cobblestone_road"}}
:enddata
:endrule

rule:
plugin=vanillaBlocks
number=9
data:
JSON:{blockState:{blockName:"minecraft:stonebrick",properties:{variant:"chiseled_stonebrick"}}}
:enddata
:endrule

rule:
plugin=vanillaBlocks
number=10
data:
JSON:{blockState:{blockName:"minecraft:stone_brick_stairs",properties:{half:"bottom",shape:"straight",facing:"south"}}}
:enddata
:endrule

rule:
plugin=vanillaBlocks
number=11
data:
JSON:{blockState:{blockName:"minecraft:stone_brick_stairs",properties:{half:"bottom",shape:"straight",facing:"west"}}}
:enddata
:endrule

rule:
plugin=vanillaBlocks
number=12
data:
JSON:{blockState:{blockName:"minecraft:stone_brick_stairs",properties:{half:"bottom",shape:"straight",facing:"east"}}}
:enddata
:endrule

rule:
plugin=vanillaBlocks
number=13
data:
JSON:{blockState:{blockName:"minecraft:cobblestone_wall",properties:{east:"false",south:"false",north:"false",variant:"cobblestone",west:"false",up:"false"}}}
:enddata
:endrule

rule:
plugin=vanillaBlocks
number=14
data:
JSON:{blockState:{blockName:"minecraft:stone_slab",properties:{half:"bottom",variant:"stone_brick"}}}
:enddata
:endrule

#### ENTITIES ####
