# Ancient Warfare Structure Template File
# Auto-generated structure template file. created on: 7/10/2023 at: 23:24:14
# Lines beginning with # denote comments

header:
version=2.11
name=SB_ArdminRoad_bridge_stair6d_21t13s_1
mods=minefantasyreforged
size=11,23,19
offset=5,21,19
:endheader

#### VALIDATION ####
validation:
type=ground
structureAuthor=TheOddlySeagull
survival=true
worldGenEnabled=false
unique=false
preserveBlocks=true
preventNaturalHostileSpawns=false
selectionWeight=1
clusterValue=1
minDuplicateDistance=1
dimensionWhiteList=true
dimensionList=
biomeGroupList=
biomeWhiteList=true
biomeList=
leveling=0
fill=0
border=0
blockSwap=false
territoryName=
biomeReplacement=minecraft:
minGenerationHeight=0
maxGenerationHeight=255
:endvalidation

#### LAYERS ####
layer: 0
1,1,1,0,0,0,0,0,1,1,1
1,1,1,0,0,0,0,0,1,1,1
1,1,1,0,0,0,0,0,1,1,1
0,0,0,0,0,0,0,0,0,0,0
0,0,0,0,0,0,0,0,0,0,0
0,0,0,0,0,0,0,0,0,0,0
0,0,0,0,0,0,0,0,0,0,0
0,0,0,0,0,0,0,0,0,0,0
0,0,0,0,0,0,0,0,0,0,0
0,0,0,0,0,0,0,0,0,0,0
0,0,0,0,0,0,0,0,0,0,0
0,0,0,0,0,0,0,0,0,0,0
0,0,0,0,0,0,0,0,0,0,0
0,0,0,0,0,0,0,0,0,0,0
0,0,0,0,0,0,0,0,0,0,0
0,0,0,0,0,0,0,0,0,0,0
1,1,1,0,0,0,0,0,1,1,1
1,1,1,0,0,0,0,0,1,1,1
1,1,1,0,0,0,0,0,1,1,1
:endlayer
layer: 1
1,1,1,0,0,0,0,0,1,1,1
1,1,1,0,0,0,0,0,1,1,1
1,1,1,0,0,0,0,0,1,1,1
0,0,0,0,0,0,0,0,0,0,0
0,0,0,0,0,0,0,0,0,0,0
0,0,0,0,0,0,0,0,0,0,0
0,0,0,0,0,0,0,0,0,0,0
0,0,0,0,0,0,0,0,0,0,0
0,0,0,0,0,0,0,0,0,0,0
0,0,0,0,0,0,0,0,0,0,0
0,0,0,0,0,0,0,0,0,0,0
0,0,0,0,0,0,0,0,0,0,0
0,0,0,0,0,0,0,0,0,0,0
0,0,0,0,0,0,0,0,0,0,0
0,0,0,0,0,0,0,0,0,0,0
0,0,0,0,0,0,0,0,0,0,0
1,1,1,0,0,0,0,0,1,1,1
1,1,1,0,0,0,0,0,1,1,1
1,1,1,0,0,0,0,0,1,1,1
:endlayer
layer: 2
1,1,1,0,0,0,0,0,1,1,1
1,1,1,0,0,0,0,0,1,1,1
1,1,1,0,0,0,0,0,1,1,1
0,0,0,0,0,0,0,0,0,0,0
0,0,0,0,0,0,0,0,0,0,0
0,0,0,0,0,0,0,0,0,0,0
0,0,0,0,0,0,0,0,0,0,0
0,0,0,0,0,0,0,0,0,0,0
0,0,0,0,0,0,0,0,0,0,0
0,0,0,0,0,0,0,0,0,0,0
0,0,0,0,0,0,0,0,0,0,0
0,0,0,0,0,0,0,0,0,0,0
0,0,0,0,0,0,0,0,0,0,0
0,0,0,0,0,0,0,0,0,0,0
0,0,0,0,0,0,0,0,0,0,0
0,0,0,0,0,0,0,0,0,0,0
1,1,1,0,0,0,0,0,1,1,1
1,1,1,0,0,0,0,0,1,1,1
1,1,1,0,0,0,0,0,1,1,1
:endlayer
layer: 3
1,1,1,0,0,0,0,0,1,1,1
1,1,1,0,0,0,0,0,1,1,1
1,1,1,0,0,0,0,0,1,1,1
0,0,0,0,0,0,0,0,0,0,0
0,0,0,0,0,0,0,0,0,0,0
0,0,0,0,0,0,0,0,0,0,0
0,0,0,0,0,0,0,0,0,0,0
0,0,0,0,0,0,0,0,0,0,0
0,0,0,0,0,0,0,0,0,0,0
0,0,0,0,0,0,0,0,0,0,0
0,0,0,0,0,0,0,0,0,0,0
0,0,0,0,0,0,0,0,0,0,0
0,0,0,0,0,0,0,0,0,0,0
0,0,0,0,0,0,0,0,0,0,0
0,0,0,0,0,0,0,0,0,0,0
0,0,0,0,0,0,0,0,0,0,0
1,1,1,0,0,0,0,0,1,1,1
1,1,1,0,0,0,0,0,1,1,1
1,1,1,0,0,0,0,0,1,1,1
:endlayer
layer: 4
1,1,1,0,0,0,0,0,1,1,1
1,1,1,0,0,0,0,0,1,1,1
1,1,1,0,0,0,0,0,1,1,1
0,0,0,0,0,0,0,0,0,0,0
0,0,0,0,0,0,0,0,0,0,0
0,0,0,0,0,0,0,0,0,0,0
0,0,0,0,0,0,0,0,0,0,0
0,0,0,0,0,0,0,0,0,0,0
0,0,0,0,0,0,0,0,0,0,0
0,0,0,0,0,0,0,0,0,0,0
0,0,0,0,0,0,0,0,0,0,0
0,0,0,0,0,0,0,0,0,0,0
0,0,0,0,0,0,0,0,0,0,0
0,0,0,0,0,0,0,0,0,0,0
0,0,0,0,0,0,0,0,0,0,0
0,0,0,0,0,0,0,0,0,0,0
1,1,1,0,0,0,0,0,1,1,1
1,1,1,0,0,0,0,0,1,1,1
1,1,1,0,0,0,0,0,1,1,1
:endlayer
layer: 5
1,1,1,0,0,0,0,0,1,1,1
1,1,1,0,0,0,0,0,1,1,1
1,1,1,0,0,0,0,0,1,1,1
0,0,0,0,0,0,0,0,0,0,0
0,0,0,0,0,0,0,0,0,0,0
0,0,0,0,0,0,0,0,0,0,0
0,0,0,0,0,0,0,0,0,0,0
0,0,0,0,0,0,0,0,0,0,0
0,0,0,0,0,0,0,0,0,0,0
0,0,0,0,0,0,0,0,0,0,0
0,0,0,0,0,0,0,0,0,0,0
0,0,0,0,0,0,0,0,0,0,0
0,0,0,0,0,0,0,0,0,0,0
0,0,0,0,0,0,0,0,0,0,0
0,0,0,0,0,0,0,0,0,0,0
0,0,0,0,0,0,0,0,0,0,0
1,1,1,0,0,0,0,0,1,1,1
1,1,1,0,0,0,0,0,1,1,1
1,1,1,0,0,0,0,0,1,1,1
:endlayer
layer: 6
1,1,1,0,0,0,0,0,1,1,1
1,1,1,0,0,0,0,0,1,1,1
1,1,1,0,0,0,0,0,1,1,1
0,0,0,0,0,0,0,0,0,0,0
0,0,0,0,0,0,0,0,0,0,0
0,0,0,0,0,0,0,0,0,0,0
0,0,0,0,0,0,0,0,0,0,0
0,0,0,0,0,0,0,0,0,0,0
0,0,0,0,0,0,0,0,0,0,0
0,0,0,0,0,0,0,0,0,0,0
0,0,0,0,0,0,0,0,0,0,0
0,0,0,0,0,0,0,0,0,0,0
0,0,0,0,0,0,0,0,0,0,0
0,0,0,0,0,0,0,0,0,0,0
0,0,0,0,0,0,0,0,0,0,0
0,0,0,0,0,0,0,0,0,0,0
1,1,1,0,0,0,0,0,1,1,1
1,1,1,0,0,0,0,0,1,1,1
1,1,1,0,0,0,0,0,1,1,1
:endlayer
layer: 7
1,1,1,0,0,0,0,0,1,1,1
1,1,1,0,0,0,0,0,1,1,1
1,1,1,0,0,0,0,0,1,1,1
0,0,0,0,0,0,0,0,0,0,0
0,0,0,0,0,0,0,0,0,0,0
0,0,0,0,0,0,0,0,0,0,0
0,0,0,0,0,0,0,0,0,0,0
0,0,0,0,0,0,0,0,0,0,0
0,0,0,0,0,0,0,0,0,0,0
0,0,0,0,0,0,0,0,0,0,0
0,0,0,0,0,0,0,0,0,0,0
0,0,0,0,0,0,0,0,0,0,0
0,0,0,0,0,0,0,0,0,0,0
0,0,0,0,0,0,0,0,0,0,0
0,0,0,0,0,0,0,0,0,0,0
0,0,0,0,0,0,0,0,0,0,0
1,1,1,0,0,0,0,0,1,1,1
1,1,1,0,0,0,0,0,1,1,1
1,1,1,0,0,0,0,0,1,1,1
:endlayer
layer: 8
1,1,1,0,0,0,0,0,1,1,1
1,1,1,0,0,0,0,0,1,1,1
1,1,1,0,0,0,0,0,1,1,1
0,0,0,0,0,0,0,0,0,0,0
0,0,0,0,0,0,0,0,0,0,0
0,0,0,0,0,0,0,0,0,0,0
0,0,0,0,0,0,0,0,0,0,0
0,0,0,0,0,0,0,0,0,0,0
0,0,0,0,0,0,0,0,0,0,0
0,0,0,0,0,0,0,0,0,0,0
0,0,0,0,0,0,0,0,0,0,0
0,0,0,0,0,0,0,0,0,0,0
0,0,0,0,0,0,0,0,0,0,0
0,0,0,0,0,0,0,0,0,0,0
0,0,0,0,0,0,0,0,0,0,0
0,0,0,0,0,0,0,0,0,0,0
1,1,1,0,0,0,0,0,1,1,1
1,1,1,0,0,0,0,0,1,1,1
1,1,1,0,0,0,0,0,1,1,1
:endlayer
layer: 9
1,1,1,0,0,0,0,0,1,1,1
1,1,1,2,0,0,0,3,1,1,1
1,1,1,0,0,0,0,0,1,1,1
0,0,0,0,0,0,0,0,0,0,0
0,0,0,0,0,0,0,0,0,0,0
0,0,0,0,0,0,0,0,0,0,0
0,0,0,0,0,0,0,0,0,0,0
0,0,0,0,0,0,0,0,0,0,0
0,0,0,0,0,0,0,0,0,0,0
0,0,0,0,0,0,0,0,0,0,0
0,0,0,0,0,0,0,0,0,0,0
0,0,0,0,0,0,0,0,0,0,0
0,0,0,0,0,0,0,0,0,0,0
0,0,0,0,0,0,0,0,0,0,0
0,0,0,0,0,0,0,0,0,0,0
0,0,0,0,0,0,0,0,0,0,0
1,1,1,0,0,0,0,0,1,1,1
1,1,1,0,0,0,0,0,1,1,1
1,1,1,0,0,0,0,0,1,1,1
:endlayer
layer: 10
1,1,1,2,0,0,0,3,1,1,1
1,1,1,1,4,0,4,1,1,1,1
1,1,1,2,0,0,0,3,1,1,1
0,5,0,0,0,0,0,0,0,5,0
0,0,0,0,0,0,0,0,0,0,0
0,0,0,0,0,0,0,0,0,0,0
0,0,0,0,0,0,0,0,0,0,0
0,0,0,0,0,0,0,0,0,0,0
0,0,0,0,0,0,0,0,0,0,0
0,0,0,0,0,0,0,0,0,0,0
0,0,0,0,0,0,0,0,0,0,0
0,0,0,0,0,0,0,0,0,0,0
0,0,0,0,0,0,0,0,0,0,0
0,0,0,0,0,0,0,0,0,0,0
0,0,0,0,0,0,0,0,0,0,0
0,6,0,0,0,0,0,0,0,6,0
1,1,1,0,0,0,0,0,1,1,1
1,1,1,0,0,0,0,0,1,1,1
1,1,1,0,0,0,0,0,1,1,1
:endlayer
layer: 11
1,1,1,1,1,1,1,1,1,1,1
1,1,1,1,1,1,1,1,1,1,1
1,1,1,1,1,1,1,1,1,1,1
0,1,0,0,0,0,0,0,0,1,0
0,1,0,0,0,0,0,0,0,1,0
0,4,0,0,0,0,0,0,0,4,0
0,4,0,0,0,0,0,0,0,4,0
0,0,0,0,0,0,0,0,0,0,0
0,0,0,0,0,0,0,0,0,0,0
0,0,0,0,0,0,0,0,0,0,0
0,0,0,0,0,0,0,0,0,0,0
0,0,0,0,0,0,0,0,0,0,0
0,4,0,0,0,0,0,0,0,4,0
0,4,0,0,0,0,0,0,0,4,0
0,1,0,0,0,0,0,0,0,1,0
0,1,0,0,0,0,0,0,0,1,0
1,1,1,0,0,0,0,0,1,1,1
1,1,1,0,0,0,0,0,1,1,1
1,1,1,0,0,0,0,0,1,1,1
:endlayer
layer: 12
1,1,1,1,1,1,1,1,1,1,1
1,1,1,1,1,1,1,1,1,1,1
1,1,1,1,1,1,1,1,1,1,1
0,1,2,5,5,5,5,5,3,1,0
0,1,2,0,0,0,0,0,3,1,0
0,1,2,0,0,0,0,0,3,1,0
0,1,2,0,0,0,0,0,3,1,0
0,1,2,0,0,0,0,0,3,1,0
0,1,2,0,0,0,0,0,3,1,0
0,1,1,0,0,0,0,0,1,1,0
0,1,2,0,0,0,0,0,3,1,0
0,1,2,0,0,0,0,0,3,1,0
0,1,2,0,0,0,0,0,3,1,0
0,1,2,0,0,0,0,0,3,1,0
0,1,2,0,0,0,0,0,3,1,0
0,1,6,0,0,0,0,0,6,1,0
1,1,1,0,0,0,0,0,1,1,1
1,1,1,0,0,0,0,0,1,1,1
1,1,1,0,0,0,0,0,1,1,1
:endlayer
layer: 13
1,1,1,1,1,1,1,1,1,1,1
1,1,1,1,1,1,1,1,1,1,1
1,1,1,1,1,1,1,1,1,1,1
0,1,1,1,1,1,1,1,1,1,0
0,0,7,8,8,8,8,8,7,0,0
0,0,7,0,0,0,0,0,7,0,0
0,0,7,0,0,0,0,0,7,0,0
0,1,7,0,0,0,0,0,7,1,0
0,9,7,0,0,0,0,0,7,9,0
0,9,7,0,0,0,0,0,7,9,0
0,9,7,0,0,0,0,0,7,9,0
0,1,7,0,0,0,0,0,7,1,0
0,1,7,0,0,0,0,0,7,1,0
0,1,7,0,0,0,0,0,7,1,0
0,1,7,0,0,0,0,0,7,1,0
0,1,7,2,0,0,0,3,7,1,0
1,1,1,0,0,0,0,0,1,1,1
1,1,1,0,0,0,0,0,1,1,1
1,1,1,0,0,0,0,0,1,1,1
:endlayer
layer: 14
10,1,1,11,11,11,11,11,1,1,10
12,1,1,11,11,11,11,11,1,1,12
13,1,1,11,11,11,11,11,1,1,13
0,1,1,11,11,11,11,11,1,1,0
0,5,7,7,7,7,7,7,7,5,0
0,4,7,14,8,8,8,15,7,4,0
0,6,7,16,0,0,0,16,7,6,0
0,1,7,0,0,0,0,0,7,1,0
0,0,7,0,0,0,0,0,7,0,0
0,0,7,0,0,0,0,0,7,0,0
0,0,7,0,0,0,0,0,7,0,0
0,1,7,0,0,0,0,0,7,1,0
0,0,7,0,0,0,0,0,7,0,0
0,0,7,0,0,0,0,0,7,0,0
0,0,7,0,0,0,0,0,7,0,0
0,1,7,1,1,1,1,1,7,1,0
1,1,1,0,0,0,0,0,1,1,1
1,1,1,0,0,0,0,0,1,1,1
1,1,1,0,0,0,0,0,1,1,1
:endlayer
layer: 15
0,1,0,0,0,0,0,0,0,1,0
17,1,0,0,0,0,0,0,0,1,18
0,1,0,0,0,0,0,0,0,1,0
0,19,0,0,0,0,0,0,0,19,0
0,1,9,20,20,20,20,20,9,1,0
0,12,1,11,11,11,11,11,1,12,0
0,1,7,7,7,7,7,7,7,1,0
0,1,7,14,16,16,16,15,7,1,0
0,0,7,16,0,0,0,16,7,0,0
0,0,7,0,0,0,0,0,7,0,0
0,0,7,0,0,0,0,0,7,0,0
0,1,7,0,0,0,0,0,7,1,0
0,0,7,0,0,0,0,0,7,0,0
0,0,7,0,0,0,0,0,7,0,0
0,0,7,0,0,0,0,0,7,0,0
0,1,7,7,7,7,7,7,7,1,0
1,1,1,0,0,0,0,0,1,1,1
1,1,1,0,0,0,0,0,1,1,1
1,1,1,0,0,0,0,0,1,1,1
:endlayer
layer: 16
0,9,0,0,0,0,0,0,0,9,0
0,9,0,0,0,0,0,0,0,9,0
0,9,0,0,0,0,0,0,0,9,0
0,0,0,0,0,0,0,0,0,0,0
0,19,0,0,0,0,0,0,0,19,0
0,19,0,0,0,0,0,0,0,19,0
0,1,9,20,20,20,20,20,9,1,0
0,1,1,11,11,11,11,11,1,1,0
0,5,7,7,7,7,7,7,7,5,0
0,4,7,14,16,16,16,15,7,4,0
0,6,7,16,0,0,0,16,7,6,0
0,1,7,0,0,0,0,0,7,1,0
0,0,7,0,0,0,0,0,7,0,0
0,0,7,0,0,0,0,0,7,0,0
0,0,7,0,0,0,0,0,7,0,0
0,1,7,7,7,12,7,7,7,1,0
1,1,1,0,0,0,0,0,1,1,1
1,1,1,2,0,0,0,3,1,1,1
1,1,1,0,0,0,0,0,1,1,1
:endlayer
layer: 17
0,0,0,0,0,0,0,0,0,0,0
0,0,0,0,0,0,0,0,0,0,0
0,0,0,0,0,0,0,0,0,0,0
0,0,0,0,0,0,0,0,0,0,0
0,0,0,0,0,0,0,0,0,0,0
0,0,0,0,0,0,0,0,0,0,0
0,19,0,0,0,0,0,0,0,19,0
0,19,0,0,0,0,0,0,0,19,0
0,1,9,20,20,20,20,20,9,1,0
0,12,1,11,11,11,11,11,1,12,0
0,1,7,7,7,7,7,7,7,1,0
0,1,7,14,16,16,16,15,7,1,0
0,0,7,16,0,0,0,16,7,0,0
0,0,7,0,0,0,0,0,7,0,0
0,0,7,0,0,0,0,0,7,0,0
0,1,7,7,7,7,7,7,7,1,0
1,1,1,2,0,0,0,3,1,1,1
1,1,1,1,4,0,4,1,1,1,1
1,1,1,2,0,0,0,3,1,1,1
:endlayer
layer: 18
0,0,0,0,0,0,0,0,0,0,0
0,0,0,0,0,0,0,0,0,0,0
0,0,0,0,0,0,0,0,0,0,0
0,0,0,0,0,0,0,0,0,0,0
0,0,0,0,0,0,0,0,0,0,0
0,0,0,0,0,0,0,0,0,0,0
0,0,0,0,0,0,0,0,0,0,0
0,0,0,0,0,0,0,0,0,0,0
0,19,0,0,0,0,0,0,0,19,0
0,19,0,0,0,0,0,0,0,19,0
0,1,9,20,20,20,20,20,9,1,0
0,1,1,11,11,11,11,11,1,1,0
0,5,7,7,7,7,7,7,7,5,0
0,4,7,14,16,16,16,15,7,4,0
0,6,7,16,0,0,0,16,7,6,0
0,1,7,7,7,7,7,7,7,1,0
1,1,1,1,1,1,1,1,1,1,1
1,1,1,1,1,1,1,1,1,1,1
1,1,1,1,1,1,1,1,1,1,1
:endlayer
layer: 19
0,0,0,0,0,0,0,0,0,0,0
0,0,0,0,0,0,0,0,0,0,0
0,0,0,0,0,0,0,0,0,0,0
0,0,0,0,0,0,0,0,0,0,0
0,0,0,0,0,0,0,0,0,0,0
0,0,0,0,0,0,0,0,0,0,0
0,0,0,0,0,0,0,0,0,0,0
0,0,0,0,0,0,0,0,0,0,0
0,0,0,0,0,0,0,0,0,0,0
0,0,0,0,0,0,0,0,0,0,0
0,19,0,0,0,0,0,0,0,19,0
0,19,0,0,0,0,0,0,0,19,0
0,1,9,20,20,20,20,20,9,1,0
0,12,1,11,11,11,11,11,1,12,0
0,1,7,7,7,7,7,7,7,1,0
0,1,7,7,7,7,7,7,7,1,0
1,1,1,1,1,1,1,1,1,1,1
1,1,1,1,1,1,1,1,1,1,1
1,1,1,1,1,1,1,1,1,1,1
:endlayer
layer: 20
0,0,0,0,0,0,0,0,0,0,0
0,0,0,0,0,0,0,0,0,0,0
0,0,0,0,0,0,0,0,0,0,0
0,0,0,0,0,0,0,0,0,0,0
0,0,0,0,0,0,0,0,0,0,0
0,0,0,0,0,0,0,0,0,0,0
0,0,0,0,0,0,0,0,0,0,0
0,0,0,0,0,0,0,0,0,0,0
0,0,0,0,0,0,0,0,0,0,0
0,0,0,0,0,0,0,0,0,0,0
0,0,0,0,0,0,0,0,0,0,0
0,0,0,0,0,0,0,0,0,0,0
0,19,0,0,0,0,0,0,0,19,0
0,19,0,0,0,0,0,0,0,19,0
0,1,9,20,20,20,20,20,9,1,0
0,1,1,11,11,11,11,11,1,1,0
10,1,1,11,11,11,11,11,1,1,10
12,1,1,11,11,11,11,11,1,1,12
13,1,1,11,11,11,11,11,1,1,13
:endlayer
layer: 21
0,0,0,0,0,0,0,0,0,0,0
0,0,0,0,0,0,0,0,0,0,0
0,0,0,0,0,0,0,0,0,0,0
0,0,0,0,0,0,0,0,0,0,0
0,0,0,0,0,0,0,0,0,0,0
0,0,0,0,0,0,0,0,0,0,0
0,0,0,0,0,0,0,0,0,0,0
0,0,0,0,0,0,0,0,0,0,0
0,0,0,0,0,0,0,0,0,0,0
0,0,0,0,0,0,0,0,0,0,0
0,0,0,0,0,0,0,0,0,0,0
0,0,0,0,0,0,0,0,0,0,0
0,0,0,0,0,0,0,0,0,0,0
0,0,0,0,0,0,0,0,0,0,0
0,19,0,0,0,0,0,0,0,19,0
0,19,0,0,0,0,0,0,0,19,0
0,1,0,0,0,0,0,0,0,1,0
17,1,0,0,0,0,0,0,0,1,18
0,1,0,0,0,0,0,0,0,1,0
:endlayer
layer: 22
0,0,0,0,0,0,0,0,0,0,0
0,0,0,0,0,0,0,0,0,0,0
0,0,0,0,0,0,0,0,0,0,0
0,0,0,0,0,0,0,0,0,0,0
0,0,0,0,0,0,0,0,0,0,0
0,0,0,0,0,0,0,0,0,0,0
0,0,0,0,0,0,0,0,0,0,0
0,0,0,0,0,0,0,0,0,0,0
0,0,0,0,0,0,0,0,0,0,0
0,0,0,0,0,0,0,0,0,0,0
0,0,0,0,0,0,0,0,0,0,0
0,0,0,0,0,0,0,0,0,0,0
0,0,0,0,0,0,0,0,0,0,0
0,0,0,0,0,0,0,0,0,0,0
0,0,0,0,0,0,0,0,0,0,0
0,0,0,0,0,0,0,0,0,0,0
0,9,0,0,0,0,0,0,0,9,0
0,9,0,0,0,0,0,0,0,9,0
0,9,0,0,0,0,0,0,0,9,0
:endlayer

#### RULES ####
rule:
plugin=vanillaBlocks
number=1
data:
JSON:{blockState:{blockName:"minecraft:stonebrick",properties:{variant:"stonebrick"}}}
:enddata
:endrule

rule:
plugin=vanillaBlocks
number=2
data:
JSON:{blockState:{blockName:"minecraft:stone_brick_stairs",properties:{half:"top",shape:"straight",facing:"west"}}}
:enddata
:endrule

rule:
plugin=vanillaBlocks
number=3
data:
JSON:{blockState:{blockName:"minecraft:stone_brick_stairs",properties:{half:"top",shape:"straight",facing:"east"}}}
:enddata
:endrule

rule:
plugin=vanillaBlocks
number=4
data:
JSON:{blockState:{blockName:"minecraft:stone_slab",properties:{half:"top",variant:"stone_brick"}}}
:enddata
:endrule

rule:
plugin=vanillaBlocks
number=5
data:
JSON:{blockState:{blockName:"minecraft:stone_brick_stairs",properties:{half:"top",shape:"straight",facing:"north"}}}
:enddata
:endrule

rule:
plugin=vanillaBlocks
number=6
data:
JSON:{blockState:{blockName:"minecraft:stone_brick_stairs",properties:{half:"top",shape:"straight",facing:"south"}}}
:enddata
:endrule

rule:
plugin=vanillaBlocks
number=7
data:
JSON:{blockState:{blockName:"minecraft:cobblestone"}}
:enddata
:endrule

rule:
plugin=vanillaBlocks
number=8
data:
JSON:{blockState:{blockName:"minecraft:stone_stairs",properties:{half:"top",shape:"straight",facing:"north"}}}
:enddata
:endrule

rule:
plugin=vanillaBlocks
number=9
data:
JSON:{blockState:{blockName:"minecraft:stone_slab",properties:{half:"bottom",variant:"stone_brick"}}}
:enddata
:endrule

rule:
plugin=vanillaBlocks
number=10
data:
JSON:{blockState:{blockName:"minecraft:stone_brick_stairs",properties:{half:"bottom",shape:"straight",facing:"south"}}}
:enddata
:endrule

rule:
plugin=vanillaBlocks
number=11
data:
JSON:{blockState:{blockName:"minefantasyreforged:cobblestone_road"}}
:enddata
:endrule

rule:
plugin=vanillaBlocks
number=12
data:
JSON:{blockState:{blockName:"minecraft:stonebrick",properties:{variant:"chiseled_stonebrick"}}}
:enddata
:endrule

rule:
plugin=vanillaBlocks
number=13
data:
JSON:{blockState:{blockName:"minecraft:stone_brick_stairs",properties:{half:"bottom",shape:"straight",facing:"north"}}}
:enddata
:endrule

rule:
plugin=vanillaBlocks
number=14
data:
JSON:{blockState:{blockName:"minecraft:stone_stairs",properties:{half:"top",shape:"straight",facing:"west"}}}
:enddata
:endrule

rule:
plugin=vanillaBlocks
number=15
data:
JSON:{blockState:{blockName:"minecraft:stone_stairs",properties:{half:"top",shape:"straight",facing:"east"}}}
:enddata
:endrule

rule:
plugin=vanillaBlocks
number=16
data:
JSON:{blockState:{blockName:"minecraft:stone_slab",properties:{half:"top",variant:"cobblestone"}}}
:enddata
:endrule

rule:
plugin=vanillaBlocks
number=17
data:
JSON:{blockState:{blockName:"minecraft:stone_brick_stairs",properties:{half:"bottom",shape:"straight",facing:"east"}}}
:enddata
:endrule

rule:
plugin=vanillaBlocks
number=18
data:
JSON:{blockState:{blockName:"minecraft:stone_brick_stairs",properties:{half:"bottom",shape:"straight",facing:"west"}}}
:enddata
:endrule

rule:
plugin=vanillaBlocks
number=19
data:
JSON:{blockState:{blockName:"minecraft:cobblestone_wall",properties:{east:"false",south:"false",north:"false",variant:"cobblestone",west:"false",up:"false"}}}
:enddata
:endrule

rule:
plugin=vanillaBlocks
number=20
data:
JSON:{blockState:{blockName:"minecraft:stone_slab",properties:{half:"bottom",variant:"cobblestone"}}}
:enddata
:endrule

#### ENTITIES ####
