# Ancient Warfare Structure Template File
# Auto-generated structure template file. created on: 6/25/2023 at: 10:42:44
# Lines beginning with # denote comments

header:
version=2.11
name=SB_ArdminRoad_tunnel_double_1
mods=minefantasyreforged
size=11,8,9
offset=5,2,9
:endheader

#### VALIDATION ####
validation:
type=ground
structureAuthor=TheOddlySeagull
survival=true
worldGenEnabled=false
unique=false
preserveBlocks=false
preventNaturalHostileSpawns=false
selectionWeight=1
clusterValue=1
minDuplicateDistance=1
dimensionWhiteList=true
dimensionList=
biomeGroupList=
biomeWhiteList=true
biomeList=
leveling=0
fill=0
border=0
blockSwap=false
territoryName=
biomeReplacement=minecraft:
minGenerationHeight=0
maxGenerationHeight=255
:endvalidation

#### LAYERS ####
layer: 0
1,1,1,1,1,1,1,1,1,1,1
1,1,1,1,1,1,1,1,1,1,1
1,1,1,1,1,1,1,1,1,1,1
1,1,1,1,1,1,1,1,1,1,1
1,1,1,1,1,1,1,1,1,1,1
1,1,1,1,1,1,1,1,1,1,1
1,1,1,1,1,1,1,1,1,1,1
1,1,1,1,1,1,1,1,1,1,1
1,1,1,1,1,1,1,1,1,1,1
:endlayer
layer: 1
1,1,2,3,3,3,3,3,2,1,1
1,1,2,3,3,3,3,3,2,1,1
1,1,2,3,3,3,3,3,2,1,1
1,1,2,3,3,3,3,3,2,1,1
1,1,2,3,3,3,3,3,2,1,1
1,1,2,3,3,3,3,3,2,1,1
1,1,2,3,3,3,3,3,2,1,1
1,1,2,3,3,3,3,3,2,1,1
1,1,2,3,3,3,3,3,2,1,1
:endlayer
layer: 2
1,2,0,0,0,0,0,0,0,2,1
1,0,0,0,0,0,0,0,0,0,1
1,0,0,0,0,0,0,0,0,0,1
1,0,0,0,0,0,0,0,0,0,1
1,2,0,0,0,0,0,0,0,2,1
1,0,0,0,0,0,0,0,0,0,1
1,0,0,0,0,0,0,0,0,0,1
1,0,0,0,0,0,0,0,0,0,1
1,2,0,0,0,0,0,0,0,2,1
:endlayer
layer: 3
1,2,0,0,0,0,0,0,0,2,1
1,0,0,0,0,0,0,0,0,0,1
1,0,0,0,0,0,0,0,0,0,1
1,0,0,0,0,0,0,0,0,0,1
1,2,0,0,0,0,0,0,0,2,1
1,0,0,0,0,0,0,0,0,0,1
1,0,0,0,0,0,0,0,0,0,1
1,0,0,0,0,0,0,0,0,0,1
1,2,0,0,0,0,0,0,0,2,1
:endlayer
layer: 4
1,2,0,0,0,0,0,0,0,2,1
1,0,0,0,0,0,0,0,0,0,1
1,0,0,0,0,0,0,0,0,0,1
1,0,0,0,0,0,0,0,0,0,1
1,2,0,0,0,0,0,0,0,2,1
1,0,0,0,0,0,0,0,0,0,1
1,0,0,0,0,0,0,0,0,0,1
1,0,0,0,0,0,0,0,0,0,1
1,2,0,0,0,0,0,0,0,2,1
:endlayer
layer: 5
1,2,0,0,0,0,0,0,0,2,1
1,4,0,0,0,0,0,0,0,4,1
1,5,0,0,0,0,0,0,0,5,1
1,6,0,0,0,0,0,0,0,6,1
1,2,0,0,0,0,0,0,0,2,1
1,4,0,0,0,0,0,0,0,4,1
1,5,0,0,0,0,0,0,0,5,1
1,6,0,0,0,0,0,0,0,6,1
1,2,0,0,0,0,0,0,0,2,1
:endlayer
layer: 6
1,2,7,0,0,0,0,0,8,2,1
1,2,0,0,0,0,0,0,0,2,1
1,9,0,0,0,0,0,0,0,9,1
1,2,0,0,0,0,0,0,0,2,1
1,2,7,0,0,0,0,0,8,2,1
1,2,0,0,0,0,0,0,0,2,1
1,9,0,0,0,0,0,0,0,9,1
1,2,0,0,0,0,0,0,0,2,1
1,2,7,0,0,0,0,0,8,2,1
:endlayer
layer: 7
1,2,2,2,2,2,2,2,2,2,1
1,2,7,5,5,2,5,5,8,2,1
1,2,7,5,5,2,5,5,8,2,1
1,2,7,5,5,2,5,5,8,2,1
1,2,2,2,2,2,2,2,2,2,1
1,2,7,5,5,2,5,5,8,2,1
1,2,7,5,5,2,5,5,8,2,1
1,2,7,5,5,2,5,5,8,2,1
1,2,2,2,2,2,2,2,2,2,1
:endlayer

#### RULES ####
rule:
plugin=vanillaBlocks
number=1
data:
JSON:{blockState:{blockName:"minecraft:cobblestone"}}
:enddata
:endrule

rule:
plugin=vanillaBlocks
number=2
data:
JSON:{blockState:{blockName:"minecraft:stonebrick",properties:{variant:"stonebrick"}}}
:enddata
:endrule

rule:
plugin=vanillaBlocks
number=3
data:
JSON:{blockState:{blockName:"minefantasyreforged:cobblestone_road"}}
:enddata
:endrule

rule:
plugin=vanillaBlocks
number=4
data:
JSON:{blockState:{blockName:"minecraft:stone_brick_stairs",properties:{half:"top",shape:"straight",facing:"north"}}}
:enddata
:endrule

rule:
plugin=vanillaBlocks
number=5
data:
JSON:{blockState:{blockName:"minecraft:stone_slab",properties:{half:"top",variant:"stone_brick"}}}
:enddata
:endrule

rule:
plugin=vanillaBlocks
number=6
data:
JSON:{blockState:{blockName:"minecraft:stone_brick_stairs",properties:{half:"top",shape:"straight",facing:"south"}}}
:enddata
:endrule

rule:
plugin=vanillaBlocks
number=7
data:
JSON:{blockState:{blockName:"minecraft:stone_brick_stairs",properties:{half:"top",shape:"straight",facing:"west"}}}
:enddata
:endrule

rule:
plugin=vanillaBlocks
number=8
data:
JSON:{blockState:{blockName:"minecraft:stone_brick_stairs",properties:{half:"top",shape:"straight",facing:"east"}}}
:enddata
:endrule

rule:
plugin=vanillaBlocks
number=9
data:
JSON:{blockState:{blockName:"minecraft:stonebrick",properties:{variant:"chiseled_stonebrick"}}}
:enddata
:endrule

#### ENTITIES ####
