# Ancient Warfare Structure Template File
# Auto-generated structure template file. created on: 3/19/2021 at: 11:57:50
# Lines beginning with # denote comments

header:
version=2.11
name=SB_T2wall2_AngleInner_stone
mods=
size=16,11,16
offset=15,0,15
:endheader

#### VALIDATION ####
validation:
type=ground
structureAuthor=TheOddlySeagull
survival=true
worldGenEnabled=false
unique=false
preserveBlocks=false
preventNaturalHostileSpawns=false
selectionWeight=1
clusterValue=1
minDuplicateDistance=1
dimensionWhiteList=true
dimensionList=
biomeGroupList=
biomeWhiteList=true
biomeList=
leveling=0
fill=0
border=0
blockSwap=false
territoryName=
biomeReplacement=minecraft:
minGenerationHeight=0
maxGenerationHeight=255
:endvalidation

#### LAYERS ####
layer: 0
0,0,0,0,0,0,0,0,0,0,0,0,0,0,0,0
0,0,0,0,0,0,0,0,0,0,0,0,0,0,0,0
0,0,0,0,0,0,0,0,0,0,0,0,0,0,0,0
0,0,0,0,1,0,3,4,4,6,0,1,0,0,0,0
0,0,0,1,1,1,1,1,1,1,1,1,1,0,0,0
0,0,0,0,1,5,5,5,5,5,5,1,0,0,0,0
0,0,0,4,1,5,1,1,1,1,5,1,0,1,0,1
0,0,0,3,1,5,1,5,5,1,1,1,1,1,1,1
0,0,0,3,1,5,1,5,5,1,1,1,1,1,1,1
0,0,0,2,1,5,1,1,1,1,0,1,0,1,0,1
0,0,0,0,1,5,5,1,1,0,0,0,0,0,0,0
0,0,0,1,1,1,1,1,1,1,0,0,0,0,0,0
0,0,0,0,1,0,0,1,1,0,0,0,0,0,0,0
0,0,0,0,0,0,1,1,1,1,0,0,0,0,0,0
0,0,0,0,0,0,0,1,1,0,0,0,0,0,0,0
0,0,0,0,0,0,1,1,1,1,0,0,0,0,0,0
:endlayer
layer: 1
0,0,0,0,0,0,0,0,0,0,0,0,0,0,0,0
0,0,0,0,0,0,0,0,0,0,0,0,0,0,0,0
0,0,0,0,0,0,0,0,0,0,0,0,0,0,0,0
0,0,0,0,1,0,0,0,0,0,0,1,0,0,0,0
0,0,0,1,1,5,1,0,0,1,5,1,1,0,0,0
0,0,0,0,5,0,0,0,0,0,0,5,0,0,0,0
0,0,0,0,1,0,1,0,0,1,5,1,0,4,0,1
0,0,0,0,0,0,0,0,4,5,5,1,5,1,5,1
0,0,0,0,0,0,0,0,5,5,5,1,5,1,5,1
0,0,0,0,1,0,1,5,5,1,0,2,0,2,0,1
0,0,0,0,5,0,5,5,5,0,0,0,0,0,0,0
0,0,0,1,1,5,1,1,1,6,0,0,0,0,0,0
0,0,0,0,1,0,0,5,5,0,0,0,0,0,0,0
0,0,0,0,0,0,3,1,1,6,0,0,0,0,0,0
0,0,0,0,0,0,0,5,5,0,0,0,0,0,0,0
0,0,0,0,0,0,1,1,1,1,0,0,0,0,0,0
:endlayer
layer: 2
0,0,0,0,0,0,0,0,0,0,0,0,0,0,0,0
0,0,0,0,0,0,0,0,0,0,0,0,0,0,0,0
0,0,0,0,0,0,0,0,0,0,0,0,0,0,0,0
0,0,0,0,4,0,8,0,0,8,0,4,0,0,0,0
0,0,0,3,1,5,1,0,0,1,5,1,6,0,0,0
0,0,0,0,5,0,0,0,0,0,7,5,0,0,0,0
0,0,0,7,1,0,1,0,0,1,5,1,0,0,0,3
0,0,0,0,0,0,0,0,0,5,5,1,5,1,5,1
0,0,0,0,0,0,0,9,4,5,5,1,5,1,5,1
0,0,0,7,1,0,1,5,5,1,0,0,0,0,0,3
0,0,0,0,5,8,5,5,5,0,0,0,0,0,0,0
0,0,0,3,1,5,1,1,1,0,0,0,0,0,0,0
0,0,0,0,2,0,0,5,5,0,0,0,0,0,0,0
0,0,0,0,0,0,0,1,1,0,0,0,0,0,0,0
0,0,0,0,0,0,0,5,5,0,0,0,0,0,0,0
0,0,0,0,0,0,4,1,1,4,0,0,0,0,0,0
:endlayer
layer: 3
0,0,0,0,0,0,0,0,0,0,0,0,0,0,0,0
0,0,0,0,0,0,0,0,0,0,0,0,0,0,0,0
0,0,0,0,0,0,0,0,0,0,0,0,0,0,0,0
0,0,0,0,0,0,10,0,0,10,0,0,0,0,0,0
0,0,0,0,1,5,1,5,5,1,5,1,0,0,0,0
0,0,0,0,5,0,0,0,0,0,13,5,0,0,0,0
0,0,0,10,1,0,1,0,0,1,5,1,0,8,0,11
0,0,0,0,5,0,5,9,0,5,5,1,5,1,5,1
0,0,0,0,5,0,5,6,0,5,5,1,5,1,5,1
0,0,0,10,1,0,1,5,5,1,0,0,14,0,0,11
0,0,0,0,5,9,5,5,5,0,0,0,0,0,0,0
0,0,0,0,1,5,1,1,1,0,0,0,0,0,0,0
0,0,0,0,0,0,0,5,5,12,0,0,0,0,0,0
0,0,0,0,0,0,7,1,1,0,0,0,0,0,0,0
0,0,0,0,0,0,0,5,5,0,0,0,0,0,0,0
0,0,0,0,0,0,11,1,1,11,0,0,0,0,0,0
:endlayer
layer: 4
0,0,0,0,0,0,0,0,0,0,0,0,0,0,0,0
0,0,0,0,0,0,0,0,0,0,0,0,0,0,0,0
0,0,0,0,0,0,0,0,0,0,0,0,0,0,0,0
0,0,0,0,0,0,0,15,15,0,0,0,0,0,0,0
0,0,0,0,1,1,1,1,1,1,1,1,0,0,0,0
0,0,0,0,1,5,5,5,5,5,5,1,0,0,0,0
0,0,0,0,1,5,1,1,1,1,5,1,10,9,10,9
0,0,0,15,1,5,1,2,0,1,1,1,1,1,1,1
0,0,0,15,1,5,1,0,0,1,1,1,1,1,1,1
0,0,0,0,1,5,1,1,1,1,10,17,10,17,10,17
0,0,0,0,1,5,5,1,1,10,0,0,0,0,0,0
0,0,0,0,1,1,1,1,1,16,0,0,0,0,0,0
0,0,0,0,0,0,10,1,1,10,0,0,0,0,0,0
0,0,0,0,0,0,13,1,1,16,0,0,0,0,0,0
0,0,0,0,0,0,10,1,1,10,0,0,0,0,0,0
0,0,0,0,0,0,13,1,1,16,0,0,0,0,0,0
:endlayer
layer: 5
0,0,0,0,0,0,0,0,0,0,0,0,0,0,0,0
0,0,0,0,0,0,0,0,0,0,0,0,0,0,0,0
0,0,0,0,0,0,0,0,0,0,0,0,0,0,0,0
0,0,0,0,0,0,0,0,0,0,0,0,0,0,0,0
0,0,0,0,1,11,11,11,11,11,11,1,0,0,0,0
0,0,0,0,11,0,0,0,0,0,0,11,0,0,0,0
0,0,0,0,11,0,1,0,0,1,0,11,11,11,11,11
0,0,0,0,11,0,5,0,0,5,0,0,0,0,0,0
0,0,0,0,11,0,5,0,0,5,0,0,0,0,0,0
0,0,0,0,11,0,1,11,5,1,1,1,1,1,1,1
0,0,0,0,11,0,0,0,0,1,0,0,0,0,0,0
0,0,0,0,1,11,11,0,0,1,0,0,0,0,0,0
0,0,0,0,0,0,11,0,0,1,0,0,0,0,0,0
0,0,0,0,0,0,11,0,0,1,0,0,0,0,0,0
0,0,0,0,0,0,11,0,0,1,0,0,0,0,0,0
0,0,0,0,0,0,11,0,0,1,0,0,0,0,0,0
:endlayer
layer: 6
0,0,0,0,0,0,0,0,0,0,0,0,0,0,0,0
0,0,0,0,0,0,0,0,0,0,0,0,0,0,0,0
0,0,0,0,0,0,0,0,0,0,0,0,0,0,0,0
0,0,0,0,0,0,0,0,0,0,0,0,0,0,0,0
0,0,0,0,15,0,0,0,0,0,0,15,0,0,0,0
0,0,0,0,0,0,8,0,0,8,0,0,0,0,0,0
0,0,0,0,0,0,1,0,0,1,0,0,0,18,0,0
0,0,0,0,0,0,5,0,0,5,0,0,0,0,0,0
0,0,0,0,0,0,5,0,0,5,0,0,0,0,0,0
0,0,0,0,0,0,1,17,5,1,0,2,0,2,0,2
0,0,0,0,0,0,0,0,0,0,0,0,0,0,0,0
0,0,0,0,15,0,0,0,0,6,0,0,0,0,0,0
0,0,0,0,0,0,0,0,0,0,0,0,0,0,0,0
0,0,0,0,0,0,18,0,0,6,0,0,0,0,0,0
0,0,0,0,0,0,0,0,0,0,0,0,0,0,0,0
0,0,0,0,0,0,0,0,0,6,0,0,0,0,0,0
:endlayer
layer: 7
0,0,0,0,0,0,0,0,0,0,0,0,0,0,0,0
0,0,0,0,0,0,0,0,0,0,0,0,0,0,0,0
0,0,0,0,0,0,0,0,0,0,0,0,0,0,0,0
0,0,0,0,0,0,0,0,0,0,0,0,0,0,0,0
0,0,0,0,0,0,0,0,0,0,0,0,0,0,0,0
0,0,0,0,0,0,11,0,0,11,0,0,0,0,0,0
0,0,0,0,0,11,1,16,13,1,11,0,0,0,0,0
0,0,0,0,0,0,5,0,0,5,0,0,0,0,0,0
0,0,0,0,0,0,5,0,0,5,0,0,0,0,0,0
0,0,0,0,0,11,1,5,5,1,11,0,0,0,0,0
0,0,0,0,0,0,11,0,0,11,0,0,0,0,0,0
0,0,0,0,0,0,0,0,0,0,0,0,0,0,0,0
0,0,0,0,0,0,0,0,0,0,0,0,0,0,0,0
0,0,0,0,0,0,0,0,0,0,0,0,0,0,0,0
0,0,0,0,0,0,0,0,0,0,0,0,0,0,0,0
0,0,0,0,0,0,0,0,0,0,0,0,0,0,0,0
:endlayer
layer: 8
0,0,0,0,0,0,0,0,0,0,0,0,0,0,0,0
0,0,0,0,0,0,0,0,0,0,0,0,0,0,0,0
0,0,0,0,0,0,0,0,0,0,0,0,0,0,0,0
0,0,0,0,0,0,0,0,0,0,0,0,0,0,0,0
0,0,0,0,0,0,0,0,0,0,0,0,0,0,0,0
0,0,0,0,0,3,4,4,4,4,4,0,0,0,0,0
0,0,0,0,0,3,1,1,1,1,6,0,0,0,0,0
0,0,0,0,0,3,1,0,0,1,6,0,0,0,0,0
0,0,0,0,0,3,1,0,0,1,6,0,0,0,0,0
0,0,0,0,0,3,1,1,1,1,6,0,0,0,0,0
0,0,0,0,0,3,2,2,2,2,6,0,0,0,0,0
0,0,0,0,0,0,0,0,0,0,0,0,0,0,0,0
0,0,0,0,0,0,0,0,0,0,0,0,0,0,0,0
0,0,0,0,0,0,0,0,0,0,0,0,0,0,0,0
0,0,0,0,0,0,0,0,0,0,0,0,0,0,0,0
0,0,0,0,0,0,0,0,0,0,0,0,0,0,0,0
:endlayer
layer: 9
0,0,0,0,0,0,0,0,0,0,0,0,0,0,0,0
0,0,0,0,0,0,0,0,0,0,0,0,0,0,0,0
0,0,0,0,0,0,0,0,0,0,0,0,0,0,0,0
0,0,0,0,0,0,0,0,0,0,0,0,0,0,0,0
0,0,0,0,0,0,0,0,0,0,0,0,0,0,0,0
0,0,0,0,0,0,0,0,0,0,0,0,0,0,0,0
0,0,0,0,0,0,15,15,15,15,0,0,0,0,0,0
0,0,0,0,0,0,15,5,5,15,0,0,0,0,0,0
0,0,0,0,0,0,15,5,5,15,0,0,0,0,0,0
0,0,0,0,0,0,15,15,15,15,0,0,0,0,0,0
0,0,0,0,0,0,0,0,0,0,0,0,0,0,0,0
0,0,0,0,0,0,0,0,0,0,0,0,0,0,0,0
0,0,0,0,0,0,0,0,0,0,0,0,0,0,0,0
0,0,0,0,0,0,0,0,0,0,0,0,0,0,0,0
0,0,0,0,0,0,0,0,0,0,0,0,0,0,0,0
0,0,0,0,0,0,0,0,0,0,0,0,0,0,0,0
:endlayer
layer: 10
0,0,0,0,0,0,0,0,0,0,0,0,0,0,0,0
0,0,0,0,0,0,0,0,0,0,0,0,0,0,0,0
0,0,0,0,0,0,0,0,0,0,0,0,0,0,0,0
0,0,0,0,0,0,0,0,0,0,0,0,0,0,0,0
0,0,0,0,0,0,0,0,0,0,0,0,0,0,0,0
0,0,0,0,0,0,0,0,0,0,0,0,0,0,0,0
0,0,0,0,0,0,0,0,0,0,0,0,0,0,0,0
0,0,0,0,0,0,0,18,0,0,0,0,0,0,0,0
0,0,0,0,0,0,0,0,0,0,0,0,0,0,0,0
0,0,0,0,0,0,0,0,0,0,0,0,0,0,0,0
0,0,0,0,0,0,0,0,0,0,0,0,0,0,0,0
0,0,0,0,0,0,0,0,0,0,0,0,0,0,0,0
0,0,0,0,0,0,0,0,0,0,0,0,0,0,0,0
0,0,0,0,0,0,0,0,0,0,0,0,0,0,0,0
0,0,0,0,0,0,0,0,0,0,0,0,0,0,0,0
0,0,0,0,0,0,0,0,0,0,0,0,0,0,0,0
:endlayer

#### RULES ####
rule:
plugin=vanillaBlocks
number=1
data:
JSON:{blockState:{blockName:"minecraft:stonebrick",properties:{variant:"stonebrick"}}}
:enddata
:endrule

rule:
plugin=vanillaBlocks
number=2
data:
JSON:{blockState:{blockName:"minecraft:stone_stairs",properties:{half:"bottom",shape:"straight",facing:"north"}}}
:enddata
:endrule

rule:
plugin=vanillaBlocks
number=3
data:
JSON:{blockState:{blockName:"minecraft:stone_stairs",properties:{half:"bottom",shape:"straight",facing:"east"}}}
:enddata
:endrule

rule:
plugin=vanillaBlocks
number=4
data:
JSON:{blockState:{blockName:"minecraft:stone_stairs",properties:{half:"bottom",shape:"straight",facing:"south"}}}
:enddata
:endrule

rule:
plugin=vanillaBlocks
number=5
data:
JSON:{blockState:{blockName:"minecraft:cobblestone"}}
:enddata
:endrule

rule:
plugin=vanillaBlocks
number=6
data:
JSON:{blockState:{blockName:"minecraft:stone_stairs",properties:{half:"bottom",shape:"straight",facing:"west"}}}
:enddata
:endrule

rule:
plugin=vanillaBlocks
number=7
data:
JSON:{blockState:{blockName:"minecraft:torch",properties:{facing:"west"}}}
:enddata
:endrule

rule:
plugin=vanillaBlocks
number=8
data:
JSON:{blockState:{blockName:"minecraft:torch",properties:{facing:"north"}}}
:enddata
:endrule

rule:
plugin=vanillaBlocks
number=9
data:
JSON:{blockState:{blockName:"minecraft:stone_stairs",properties:{half:"top",shape:"straight",facing:"south"}}}
:enddata
:endrule

rule:
plugin=vanillaBlocks
number=10
data:
JSON:{blockState:{blockName:"minecraft:stone_slab",properties:{half:"top",variant:"cobblestone"}}}
:enddata
:endrule

rule:
plugin=vanillaBlocks
number=11
data:
JSON:{blockState:{blockName:"minecraft:cobblestone_wall",properties:{east:"false",south:"false",north:"false",variant:"cobblestone",west:"false",up:"false"}}}
:enddata
:endrule

rule:
plugin=vanillaBlocks
number=12
data:
JSON:{blockState:{blockName:"minecraft:torch",properties:{facing:"east"}}}
:enddata
:endrule

rule:
plugin=vanillaBlocks
number=13
data:
JSON:{blockState:{blockName:"minecraft:stone_stairs",properties:{half:"top",shape:"straight",facing:"east"}}}
:enddata
:endrule

rule:
plugin=vanillaBlocks
number=14
data:
JSON:{blockState:{blockName:"minecraft:torch",properties:{facing:"south"}}}
:enddata
:endrule

rule:
plugin=vanillaBlocks
number=15
data:
JSON:{blockState:{blockName:"minecraft:stone_slab",properties:{half:"bottom",variant:"cobblestone"}}}
:enddata
:endrule

rule:
plugin=vanillaBlocks
number=16
data:
JSON:{blockState:{blockName:"minecraft:stone_stairs",properties:{half:"top",shape:"straight",facing:"west"}}}
:enddata
:endrule

rule:
plugin=vanillaBlocks
number=17
data:
JSON:{blockState:{blockName:"minecraft:stone_stairs",properties:{half:"top",shape:"straight",facing:"north"}}}
:enddata
:endrule

rule:
plugin=vanillaBlocks
number=18
data:
JSON:{blockState:{blockName:"minecraft:torch",properties:{facing:"up"}}}
:enddata
:endrule

#### ENTITIES ####
