# Ancient Warfare Structure Template File
# Auto-generated structure template file. created on: 3/12/2021 at: 23:31:29
# Lines beginning with # denote comments

header:
version=2.11
name=SB_T2wall2_AngleInner_birch
mods=
size=16,11,16
offset=15,0,15
:endheader

#### VALIDATION ####
validation:
type=ground
structureAuthor=TheOddlySeagull
survival=true
worldGenEnabled=false
unique=false
preserveBlocks=false
preventNaturalHostileSpawns=false
selectionWeight=1
clusterValue=1
minDuplicateDistance=1
dimensionWhiteList=true
dimensionList=
biomeGroupList=
biomeWhiteList=true
biomeList=
leveling=0
fill=0
border=0
blockSwap=false
territoryName=
biomeReplacement=minecraft:
minGenerationHeight=0
maxGenerationHeight=255
:endvalidation

#### LAYERS ####
layer: 0
0,0,0,0,0,0,0,0,0,0,0,0,0,0,0,0
0,0,0,0,0,0,0,0,0,0,0,0,0,0,0,0
0,0,0,0,0,0,0,0,0,0,0,0,0,0,0,0
0,0,0,0,1,0,3,4,4,8,0,1,0,0,0,0
0,0,0,1,1,6,6,6,6,6,6,1,1,0,0,0
0,0,0,0,5,7,7,7,7,7,7,5,0,0,0,0
0,0,0,4,5,7,1,6,6,1,7,1,0,1,0,1
0,0,0,3,5,7,5,7,7,5,6,6,6,6,6,1
0,0,0,3,5,7,5,7,7,5,6,6,6,6,6,1
0,0,0,2,5,7,1,6,6,1,0,1,0,1,0,1
0,0,0,0,5,7,7,5,5,0,0,0,0,0,0,0
0,0,0,1,1,6,1,5,5,1,0,0,0,0,0,0
0,0,0,0,1,0,0,5,5,0,0,0,0,0,0,0
0,0,0,0,0,0,1,5,5,1,0,0,0,0,0,0
0,0,0,0,0,0,0,5,5,0,0,0,0,0,0,0
0,0,0,0,0,0,1,1,1,1,0,0,0,0,0,0
:endlayer
layer: 1
0,0,0,0,0,0,0,0,0,0,0,0,0,0,0,0
0,0,0,0,0,0,0,0,0,0,0,0,0,0,0,0
0,0,0,0,0,0,0,0,0,0,0,0,0,0,0,0
0,0,0,0,1,0,0,0,0,0,0,1,0,0,0,0
0,0,0,1,1,7,1,0,0,1,7,1,1,0,0,0
0,0,0,0,7,0,0,0,0,0,0,7,0,0,0,0
0,0,0,0,1,0,1,0,0,1,7,1,0,4,0,1
0,0,0,0,0,0,0,0,4,7,7,1,7,1,7,1
0,0,0,0,0,0,0,0,7,7,7,1,7,1,7,1
0,0,0,0,1,0,1,7,7,1,0,2,0,2,0,1
0,0,0,0,7,0,7,7,7,0,0,0,0,0,0,0
0,0,0,1,1,7,1,1,1,8,0,0,0,0,0,0
0,0,0,0,1,0,0,7,7,0,0,0,0,0,0,0
0,0,0,0,0,0,3,1,1,8,0,0,0,0,0,0
0,0,0,0,0,0,0,7,7,0,0,0,0,0,0,0
0,0,0,0,0,0,1,1,1,1,0,0,0,0,0,0
:endlayer
layer: 2
0,0,0,0,0,0,0,0,0,0,0,0,0,0,0,0
0,0,0,0,0,0,0,0,0,0,0,0,0,0,0,0
0,0,0,0,0,0,0,0,0,0,0,0,0,0,0,0
0,0,0,0,4,0,10,0,0,10,0,4,0,0,0,0
0,0,0,3,1,7,1,0,0,1,7,1,8,0,0,0
0,0,0,0,7,0,0,0,0,0,9,7,0,0,0,0
0,0,0,9,1,0,1,0,0,1,7,1,0,0,0,3
0,0,0,0,0,0,0,0,0,7,7,1,7,1,7,1
0,0,0,0,0,0,0,11,4,7,7,1,7,1,7,1
0,0,0,9,1,0,1,7,7,1,0,0,0,0,0,3
0,0,0,0,7,10,7,7,7,0,0,0,0,0,0,0
0,0,0,3,1,7,1,1,1,0,0,0,0,0,0,0
0,0,0,0,2,0,0,7,7,0,0,0,0,0,0,0
0,0,0,0,0,0,0,1,1,0,0,0,0,0,0,0
0,0,0,0,0,0,0,7,7,0,0,0,0,0,0,0
0,0,0,0,0,0,4,1,1,4,0,0,0,0,0,0
:endlayer
layer: 3
0,0,0,0,0,0,0,0,0,0,0,0,0,0,0,0
0,0,0,0,0,0,0,0,0,0,0,0,0,0,0,0
0,0,0,0,0,0,0,0,0,0,0,0,0,0,0,0
0,0,0,0,0,0,12,0,0,12,0,0,0,0,0,0
0,0,0,0,1,7,1,7,7,1,7,1,0,0,0,0
0,0,0,0,7,0,0,0,0,0,15,7,0,0,0,0
0,0,0,12,1,0,1,0,0,1,7,1,0,10,0,13
0,0,0,0,7,0,7,11,0,7,7,1,7,1,7,1
0,0,0,0,7,0,7,8,0,7,7,1,7,1,7,1
0,0,0,12,1,0,1,7,7,1,0,0,16,0,0,13
0,0,0,0,7,11,7,7,7,0,0,0,0,0,0,0
0,0,0,0,1,7,1,1,1,0,0,0,0,0,0,0
0,0,0,0,0,0,0,7,7,14,0,0,0,0,0,0
0,0,0,0,0,0,9,1,1,0,0,0,0,0,0,0
0,0,0,0,0,0,0,7,7,0,0,0,0,0,0,0
0,0,0,0,0,0,13,1,1,13,0,0,0,0,0,0
:endlayer
layer: 4
0,0,0,0,0,0,0,0,0,0,0,0,0,0,0,0
0,0,0,0,0,0,0,0,0,0,0,0,0,0,0,0
0,0,0,0,0,0,0,0,0,0,0,0,0,0,0,0
0,0,0,0,0,0,0,17,17,0,0,0,0,0,0,0
0,0,0,0,1,6,6,6,6,6,6,1,0,0,0,0
0,0,0,0,5,7,7,7,7,7,7,5,0,0,0,0
0,0,0,0,5,7,1,6,6,1,7,5,12,11,12,11
0,0,0,17,5,7,5,2,0,5,6,6,6,6,6,5
0,0,0,17,5,7,5,0,0,5,6,6,6,6,6,5
0,0,0,0,5,7,1,6,6,1,12,19,12,19,12,19
0,0,0,0,5,7,7,5,5,12,0,0,0,0,0,0
0,0,0,0,1,6,6,5,5,18,0,0,0,0,0,0
0,0,0,0,0,0,12,5,5,12,0,0,0,0,0,0
0,0,0,0,0,0,15,5,5,18,0,0,0,0,0,0
0,0,0,0,0,0,12,5,5,12,0,0,0,0,0,0
0,0,0,0,0,0,15,6,6,18,0,0,0,0,0,0
:endlayer
layer: 5
0,0,0,0,0,0,0,0,0,0,0,0,0,0,0,0
0,0,0,0,0,0,0,0,0,0,0,0,0,0,0,0
0,0,0,0,0,0,0,0,0,0,0,0,0,0,0,0
0,0,0,0,0,0,0,0,0,0,0,0,0,0,0,0
0,0,0,0,1,13,13,13,13,13,13,1,0,0,0,0
0,0,0,0,13,0,0,0,0,0,0,13,0,0,0,0
0,0,0,0,13,0,1,0,0,1,0,13,13,13,13,13
0,0,0,0,13,0,7,0,0,7,0,0,0,0,0,0
0,0,0,0,13,0,7,0,0,7,0,0,0,0,0,0
0,0,0,0,13,0,1,13,7,1,6,6,6,6,6,6
0,0,0,0,13,0,0,0,0,5,0,0,0,0,0,0
0,0,0,0,1,13,13,0,0,5,0,0,0,0,0,0
0,0,0,0,0,0,13,0,0,5,0,0,0,0,0,0
0,0,0,0,0,0,13,0,0,5,0,0,0,0,0,0
0,0,0,0,0,0,13,0,0,5,0,0,0,0,0,0
0,0,0,0,0,0,13,0,0,5,0,0,0,0,0,0
:endlayer
layer: 6
0,0,0,0,0,0,0,0,0,0,0,0,0,0,0,0
0,0,0,0,0,0,0,0,0,0,0,0,0,0,0,0
0,0,0,0,0,0,0,0,0,0,0,0,0,0,0,0
0,0,0,0,0,0,0,0,0,0,0,0,0,0,0,0
0,0,0,0,17,0,0,0,0,0,0,17,0,0,0,0
0,0,0,0,0,0,10,0,0,10,0,0,0,0,0,0
0,0,0,0,0,0,1,0,0,1,0,0,0,20,0,0
0,0,0,0,0,0,7,0,0,7,0,0,0,0,0,0
0,0,0,0,0,0,7,0,0,7,0,0,0,0,0,0
0,0,0,0,0,0,1,19,7,1,0,2,0,2,0,2
0,0,0,0,0,0,0,0,0,0,0,0,0,0,0,0
0,0,0,0,17,0,0,0,0,8,0,0,0,0,0,0
0,0,0,0,0,0,0,0,0,0,0,0,0,0,0,0
0,0,0,0,0,0,20,0,0,8,0,0,0,0,0,0
0,0,0,0,0,0,0,0,0,0,0,0,0,0,0,0
0,0,0,0,0,0,0,0,0,8,0,0,0,0,0,0
:endlayer
layer: 7
0,0,0,0,0,0,0,0,0,0,0,0,0,0,0,0
0,0,0,0,0,0,0,0,0,0,0,0,0,0,0,0
0,0,0,0,0,0,0,0,0,0,0,0,0,0,0,0
0,0,0,0,0,0,0,0,0,0,0,0,0,0,0,0
0,0,0,0,0,0,0,0,0,0,0,0,0,0,0,0
0,0,0,0,0,0,13,0,0,13,0,0,0,0,0,0
0,0,0,0,0,13,1,18,15,1,13,0,0,0,0,0
0,0,0,0,0,0,7,0,0,7,0,0,0,0,0,0
0,0,0,0,0,0,7,0,0,7,0,0,0,0,0,0
0,0,0,0,0,13,1,7,7,1,13,0,0,0,0,0
0,0,0,0,0,0,13,0,0,13,0,0,0,0,0,0
0,0,0,0,0,0,0,0,0,0,0,0,0,0,0,0
0,0,0,0,0,0,0,0,0,0,0,0,0,0,0,0
0,0,0,0,0,0,0,0,0,0,0,0,0,0,0,0
0,0,0,0,0,0,0,0,0,0,0,0,0,0,0,0
0,0,0,0,0,0,0,0,0,0,0,0,0,0,0,0
:endlayer
layer: 8
0,0,0,0,0,0,0,0,0,0,0,0,0,0,0,0
0,0,0,0,0,0,0,0,0,0,0,0,0,0,0,0
0,0,0,0,0,0,0,0,0,0,0,0,0,0,0,0
0,0,0,0,0,0,0,0,0,0,0,0,0,0,0,0
0,0,0,0,0,0,0,0,0,0,0,0,0,0,0,0
0,0,0,0,0,3,4,4,4,4,4,0,0,0,0,0
0,0,0,0,0,3,1,6,6,1,8,0,0,0,0,0
0,0,0,0,0,3,5,0,0,5,8,0,0,0,0,0
0,0,0,0,0,3,5,0,0,5,8,0,0,0,0,0
0,0,0,0,0,3,1,6,6,1,8,0,0,0,0,0
0,0,0,0,0,3,2,2,2,2,8,0,0,0,0,0
0,0,0,0,0,0,0,0,0,0,0,0,0,0,0,0
0,0,0,0,0,0,0,0,0,0,0,0,0,0,0,0
0,0,0,0,0,0,0,0,0,0,0,0,0,0,0,0
0,0,0,0,0,0,0,0,0,0,0,0,0,0,0,0
0,0,0,0,0,0,0,0,0,0,0,0,0,0,0,0
:endlayer
layer: 9
0,0,0,0,0,0,0,0,0,0,0,0,0,0,0,0
0,0,0,0,0,0,0,0,0,0,0,0,0,0,0,0
0,0,0,0,0,0,0,0,0,0,0,0,0,0,0,0
0,0,0,0,0,0,0,0,0,0,0,0,0,0,0,0
0,0,0,0,0,0,0,0,0,0,0,0,0,0,0,0
0,0,0,0,0,0,0,0,0,0,0,0,0,0,0,0
0,0,0,0,0,0,17,17,17,17,0,0,0,0,0,0
0,0,0,0,0,0,17,7,7,17,0,0,0,0,0,0
0,0,0,0,0,0,17,7,7,17,0,0,0,0,0,0
0,0,0,0,0,0,17,17,17,17,0,0,0,0,0,0
0,0,0,0,0,0,0,0,0,0,0,0,0,0,0,0
0,0,0,0,0,0,0,0,0,0,0,0,0,0,0,0
0,0,0,0,0,0,0,0,0,0,0,0,0,0,0,0
0,0,0,0,0,0,0,0,0,0,0,0,0,0,0,0
0,0,0,0,0,0,0,0,0,0,0,0,0,0,0,0
0,0,0,0,0,0,0,0,0,0,0,0,0,0,0,0
:endlayer
layer: 10
0,0,0,0,0,0,0,0,0,0,0,0,0,0,0,0
0,0,0,0,0,0,0,0,0,0,0,0,0,0,0,0
0,0,0,0,0,0,0,0,0,0,0,0,0,0,0,0
0,0,0,0,0,0,0,0,0,0,0,0,0,0,0,0
0,0,0,0,0,0,0,0,0,0,0,0,0,0,0,0
0,0,0,0,0,0,0,0,0,0,0,0,0,0,0,0
0,0,0,0,0,0,0,0,0,0,0,0,0,0,0,0
0,0,0,0,0,0,0,20,0,0,0,0,0,0,0,0
0,0,0,0,0,0,0,0,0,0,0,0,0,0,0,0
0,0,0,0,0,0,0,0,0,0,0,0,0,0,0,0
0,0,0,0,0,0,0,0,0,0,0,0,0,0,0,0
0,0,0,0,0,0,0,0,0,0,0,0,0,0,0,0
0,0,0,0,0,0,0,0,0,0,0,0,0,0,0,0
0,0,0,0,0,0,0,0,0,0,0,0,0,0,0,0
0,0,0,0,0,0,0,0,0,0,0,0,0,0,0,0
0,0,0,0,0,0,0,0,0,0,0,0,0,0,0,0
:endlayer

#### RULES ####
rule:
plugin=vanillaBlocks
number=1
data:
JSON:{blockState:{blockName:"minecraft:log",properties:{variant:"birch",axis:"y"}}}
:enddata
:endrule

rule:
plugin=vanillaBlocks
number=2
data:
JSON:{blockState:{blockName:"minecraft:birch_stairs",properties:{half:"bottom",shape:"straight",facing:"north"}}}
:enddata
:endrule

rule:
plugin=vanillaBlocks
number=3
data:
JSON:{blockState:{blockName:"minecraft:birch_stairs",properties:{half:"bottom",shape:"straight",facing:"east"}}}
:enddata
:endrule

rule:
plugin=vanillaBlocks
number=4
data:
JSON:{blockState:{blockName:"minecraft:birch_stairs",properties:{half:"bottom",shape:"straight",facing:"south"}}}
:enddata
:endrule

rule:
plugin=vanillaBlocks
number=5
data:
JSON:{blockState:{blockName:"minecraft:log",properties:{variant:"birch",axis:"z"}}}
:enddata
:endrule

rule:
plugin=vanillaBlocks
number=6
data:
JSON:{blockState:{blockName:"minecraft:log",properties:{variant:"birch",axis:"x"}}}
:enddata
:endrule

rule:
plugin=vanillaBlocks
number=7
data:
JSON:{blockState:{blockName:"minecraft:planks",properties:{variant:"birch"}}}
:enddata
:endrule

rule:
plugin=vanillaBlocks
number=8
data:
JSON:{blockState:{blockName:"minecraft:birch_stairs",properties:{half:"bottom",shape:"straight",facing:"west"}}}
:enddata
:endrule

rule:
plugin=vanillaBlocks
number=9
data:
JSON:{blockState:{blockName:"minecraft:torch",properties:{facing:"west"}}}
:enddata
:endrule

rule:
plugin=vanillaBlocks
number=10
data:
JSON:{blockState:{blockName:"minecraft:torch",properties:{facing:"north"}}}
:enddata
:endrule

rule:
plugin=vanillaBlocks
number=11
data:
JSON:{blockState:{blockName:"minecraft:birch_stairs",properties:{half:"top",shape:"straight",facing:"south"}}}
:enddata
:endrule

rule:
plugin=vanillaBlocks
number=12
data:
JSON:{blockState:{blockName:"minecraft:wooden_slab",properties:{half:"top",variant:"birch"}}}
:enddata
:endrule

rule:
plugin=vanillaBlocks
number=13
data:
JSON:{blockState:{blockName:"minecraft:birch_fence",properties:{east:"false",south:"false",north:"false",west:"false"}}}
:enddata
:endrule

rule:
plugin=vanillaBlocks
number=14
data:
JSON:{blockState:{blockName:"minecraft:torch",properties:{facing:"east"}}}
:enddata
:endrule

rule:
plugin=vanillaBlocks
number=15
data:
JSON:{blockState:{blockName:"minecraft:birch_stairs",properties:{half:"top",shape:"straight",facing:"east"}}}
:enddata
:endrule

rule:
plugin=vanillaBlocks
number=16
data:
JSON:{blockState:{blockName:"minecraft:torch",properties:{facing:"south"}}}
:enddata
:endrule

rule:
plugin=vanillaBlocks
number=17
data:
JSON:{blockState:{blockName:"minecraft:wooden_slab",properties:{half:"bottom",variant:"birch"}}}
:enddata
:endrule

rule:
plugin=vanillaBlocks
number=18
data:
JSON:{blockState:{blockName:"minecraft:birch_stairs",properties:{half:"top",shape:"straight",facing:"west"}}}
:enddata
:endrule

rule:
plugin=vanillaBlocks
number=19
data:
JSON:{blockState:{blockName:"minecraft:birch_stairs",properties:{half:"top",shape:"straight",facing:"north"}}}
:enddata
:endrule

rule:
plugin=vanillaBlocks
number=20
data:
JSON:{blockState:{blockName:"minecraft:torch",properties:{facing:"up"}}}
:enddata
:endrule

#### ENTITIES ####
