# Ancient Warfare Structure Template File
# Auto-generated structure template file. created on: 4/15/2023 at: 14:28:2
# Lines beginning with # denote comments

header:
version=2.11
name=SB_warehouse_large_birch
mods=
size=19,12,36
offset=9,1,35
:endheader

#### VALIDATION ####
validation:
type=ground
structureAuthor=TheOddlySeagull
survival=true
worldGenEnabled=false
unique=false
preserveBlocks=false
preventNaturalHostileSpawns=false
selectionWeight=1
clusterValue=1
minDuplicateDistance=1
dimensionWhiteList=true
dimensionList=
biomeGroupList=
biomeWhiteList=true
biomeList=
leveling=0
fill=0
border=0
blockSwap=false
territoryName=
biomeReplacement=minecraft:
minGenerationHeight=0
maxGenerationHeight=255
:endvalidation

#### LAYERS ####
layer: 0
1,1,1,1,1,1,1,1,2,2,2,1,1,1,1,1,1,1,1
1,2,2,2,2,2,2,2,2,2,2,2,2,2,2,2,2,2,1
1,2,2,4,4,2,4,2,4,2,4,3,4,2,3,4,3,2,1
1,2,4,2,3,4,2,4,2,2,3,3,2,4,3,3,3,2,1
1,2,4,4,3,4,3,2,4,4,3,3,2,4,2,3,2,2,1
1,2,3,2,3,3,3,3,4,2,2,4,3,3,4,4,4,2,1
1,2,4,3,3,2,2,2,3,2,3,3,2,3,4,2,3,2,1
1,2,2,3,3,2,3,2,2,2,3,2,3,3,3,2,4,2,1
1,2,4,3,4,4,2,3,4,3,2,2,3,4,4,2,2,2,1
1,2,2,2,2,2,4,2,4,3,2,4,2,3,3,4,3,2,1
1,2,3,2,2,4,3,3,3,4,4,4,2,3,4,4,3,2,1
1,2,2,2,2,2,3,4,2,3,3,3,4,4,3,3,2,2,1
1,2,2,2,4,4,4,3,3,3,3,2,3,4,4,2,2,2,1
1,2,3,4,2,2,2,2,3,2,2,2,4,4,4,2,4,2,1
1,2,2,2,4,2,4,3,4,3,3,2,3,3,4,2,2,2,1
1,2,4,2,4,2,3,2,2,4,2,4,3,4,4,2,3,2,1
2,2,3,2,3,4,2,3,2,2,2,3,2,4,2,2,3,2,2
2,2,4,3,4,2,4,2,3,4,4,3,4,3,4,3,2,2,2
2,2,2,4,2,3,3,2,3,2,2,4,3,3,2,2,4,2,2
2,2,2,4,3,2,3,3,3,2,4,2,4,4,3,3,4,2,2
1,2,2,3,3,3,4,4,3,4,2,4,4,4,3,4,2,2,1
1,2,2,4,4,4,3,3,3,2,4,4,3,4,2,4,3,2,1
1,2,2,3,3,3,2,2,2,2,3,2,4,4,4,2,4,2,1
1,2,3,3,3,2,3,2,4,2,4,3,2,4,4,3,4,2,1
1,2,3,2,3,3,2,2,3,2,3,4,2,3,4,2,2,2,1
1,2,3,3,2,3,4,4,3,4,2,3,2,2,3,4,4,2,1
1,2,3,2,2,2,3,4,4,2,2,4,3,3,2,3,2,2,1
1,2,2,3,4,4,3,2,3,3,4,4,3,2,2,2,4,2,1
1,2,3,4,2,4,2,2,4,2,4,2,4,2,3,3,4,2,1
1,2,3,4,2,4,3,2,4,4,4,3,3,2,3,4,4,2,1
1,2,2,3,4,3,2,2,2,4,4,4,3,2,3,4,2,2,1
1,2,4,4,4,3,2,2,2,2,2,4,4,2,4,3,4,2,1
1,2,2,4,2,4,4,3,3,4,2,4,2,2,3,3,2,2,1
1,2,2,4,2,3,2,2,2,3,3,2,2,4,2,2,3,2,1
1,2,2,2,2,2,2,2,2,2,2,2,2,2,2,2,2,2,1
1,1,1,1,1,1,1,2,2,2,2,2,1,1,1,1,1,1,1
:endlayer
layer: 1
0,0,0,0,0,0,0,0,0,0,0,0,0,0,0,0,0,0,0
0,5,11,11,5,11,11,5,7,0,7,5,11,11,5,11,11,5,0
0,7,0,0,0,0,0,0,0,0,0,0,0,0,0,0,0,7,0
0,7,0,0,0,0,0,0,0,0,0,0,0,0,0,0,0,7,0
0,5,0,0,0,0,0,0,0,0,0,0,0,0,0,0,0,5,0
0,9,0,0,0,0,0,0,0,0,0,0,0,0,0,0,0,8,0
0,9,0,0,0,0,0,0,0,0,0,0,0,0,0,0,0,8,0
0,5,0,0,0,0,0,0,0,5,0,0,0,0,0,0,0,5,0
0,7,0,0,0,0,0,0,0,0,0,0,0,0,0,0,0,7,0
0,7,0,0,0,0,0,0,0,0,0,0,0,0,0,0,0,7,0
0,5,0,0,0,0,0,0,0,0,0,0,0,0,0,0,0,5,0
0,9,0,0,0,0,0,0,0,0,0,0,0,0,0,0,0,8,0
0,9,0,0,0,0,0,0,0,0,0,0,0,0,0,0,0,8,0
0,5,0,0,0,0,0,0,0,5,0,0,0,0,0,0,0,5,0
0,7,0,0,0,0,0,0,0,0,0,0,0,0,0,0,0,7,0
0,7,0,0,0,0,0,0,0,0,0,0,0,0,0,0,0,7,0
0,5,0,0,0,10,0,0,0,0,0,0,10,0,0,0,0,5,0
0,0,0,0,0,0,0,0,0,0,0,0,0,0,0,0,0,0,0
0,0,0,0,0,0,0,0,0,0,0,0,0,0,0,0,0,0,0
0,5,0,0,0,10,0,0,0,0,0,0,10,0,0,0,0,5,0
0,7,0,0,0,0,0,0,0,0,0,0,0,0,0,0,0,7,0
0,7,0,0,0,0,0,0,0,0,0,0,0,0,0,0,0,7,0
0,5,0,0,0,0,0,0,0,5,0,0,0,0,0,0,0,5,0
0,9,0,0,0,0,0,0,0,0,0,0,0,0,0,0,0,8,0
0,9,0,0,0,0,0,0,0,0,0,0,0,0,0,0,0,8,0
0,5,0,0,0,0,0,0,0,0,0,0,0,0,0,0,0,5,0
0,7,0,0,0,0,0,0,0,0,0,0,0,0,0,0,0,7,0
0,7,0,0,0,0,0,0,0,0,0,0,0,0,0,0,0,7,0
0,5,0,0,0,0,0,0,0,5,0,0,0,0,0,0,0,5,0
0,9,0,0,0,0,0,0,0,0,0,0,0,0,0,0,0,8,0
0,9,0,0,0,0,0,0,0,0,0,0,0,0,0,0,0,8,0
0,5,0,0,0,0,0,0,0,0,0,0,0,0,0,0,0,5,0
0,7,0,0,0,0,0,0,0,0,0,0,0,0,0,0,0,7,0
0,7,0,0,0,0,0,0,0,0,0,0,0,0,0,0,0,7,0
0,5,6,6,5,6,6,5,0,0,0,5,6,6,5,6,6,5,0
0,0,0,0,0,0,0,0,0,0,0,0,0,0,0,0,0,0,0
:endlayer
layer: 2
0,0,0,0,0,0,0,0,0,0,0,0,0,0,0,0,0,0,0
0,5,11,11,5,11,11,5,7,0,7,5,11,11,5,11,11,5,0
0,7,0,0,0,0,0,0,0,0,0,0,0,0,0,0,0,7,0
0,7,0,0,0,0,0,0,0,0,0,0,0,0,0,0,0,7,0
0,5,0,0,0,0,0,0,0,0,0,0,0,0,0,0,0,5,0
0,9,0,0,0,0,0,0,0,0,0,0,0,0,0,0,0,8,0
0,9,0,0,0,0,0,0,0,0,0,0,0,0,0,0,0,8,0
0,5,14,0,0,0,0,0,0,5,0,0,0,0,0,0,13,5,0
0,7,0,0,0,0,0,0,0,0,0,0,0,0,0,0,0,7,0
0,7,0,0,0,0,0,0,0,0,0,0,0,0,0,0,0,7,0
0,5,0,0,0,0,0,0,0,0,0,0,0,0,0,0,0,5,0
0,9,0,0,0,0,0,0,0,0,0,0,0,0,0,0,0,8,0
0,9,0,0,0,0,0,0,0,0,0,0,0,0,0,0,0,8,0
0,5,14,0,0,0,0,0,0,5,0,0,0,0,0,0,13,5,0
0,7,0,0,0,0,0,0,0,17,0,0,0,0,0,0,0,7,0
0,7,0,0,0,0,0,0,0,0,0,0,0,0,0,0,0,7,0
0,5,0,0,0,16,0,0,0,0,0,0,16,0,0,0,0,5,0
0,0,0,0,0,0,0,0,0,0,0,0,0,0,0,0,0,0,0
0,0,0,0,0,0,0,0,0,0,0,0,0,0,0,0,0,0,0
0,5,0,0,0,16,0,0,0,0,0,0,16,0,0,0,0,5,0
0,7,0,0,0,0,0,0,0,0,0,0,0,0,0,0,0,7,0
0,7,0,0,0,0,0,0,0,15,0,0,0,0,0,0,0,7,0
0,5,14,0,0,0,0,0,0,5,0,0,0,0,0,0,13,5,0
0,9,0,0,0,0,0,0,0,0,0,0,0,0,0,0,0,8,0
0,9,0,0,0,0,0,0,0,0,0,0,0,0,0,0,0,8,0
0,5,0,0,0,0,0,0,0,0,0,0,0,0,0,0,0,5,0
0,7,0,0,0,0,0,0,0,0,0,0,0,0,0,0,0,7,0
0,7,0,0,0,0,0,0,0,0,0,0,0,0,0,0,0,7,0
0,5,14,0,0,0,0,0,0,5,0,0,0,0,0,0,13,5,0
0,9,0,0,0,0,0,0,0,0,0,0,0,0,0,0,0,8,0
0,9,0,0,0,0,0,0,0,0,0,0,0,0,0,0,0,8,0
0,5,0,0,0,0,0,0,0,0,0,0,0,0,0,0,0,5,0
0,7,0,0,0,0,0,0,0,0,0,0,0,0,0,0,0,7,0
0,7,0,0,0,0,0,0,0,0,0,0,0,0,0,0,0,7,0
0,5,12,12,5,12,12,5,0,0,0,5,12,12,5,12,12,5,0
0,0,0,0,0,0,0,0,0,0,0,0,0,0,0,0,0,0,0
:endlayer
layer: 3
0,0,0,0,0,0,0,15,0,0,0,15,0,0,0,0,0,0,0
13,5,18,18,5,18,18,5,7,7,7,5,18,18,5,18,18,5,14
0,19,0,0,17,0,0,17,0,0,0,17,0,0,17,0,0,19,0
0,19,0,0,0,0,0,0,0,0,0,0,0,0,0,0,0,19,0
0,5,14,0,0,0,0,0,0,0,0,0,0,0,0,0,13,5,0
0,9,0,0,0,0,0,0,0,0,0,0,0,0,0,0,0,8,0
0,9,0,0,0,0,0,0,0,15,0,0,0,0,0,0,0,8,0
13,5,10,0,0,0,0,0,10,5,10,0,0,0,0,0,10,5,14
0,19,0,0,0,0,0,0,0,17,0,0,0,0,0,0,0,19,0
0,19,0,0,0,0,0,0,0,0,0,0,0,0,0,0,0,19,0
0,5,14,0,0,0,0,0,0,0,0,0,0,0,0,0,13,5,0
0,9,0,0,0,0,0,0,0,0,0,0,0,0,0,0,0,8,0
0,9,0,0,0,0,0,0,0,15,0,0,0,0,0,0,0,8,0
13,5,10,0,0,0,0,0,10,5,10,0,0,0,0,0,10,5,14
0,19,0,0,0,0,0,0,0,10,0,0,0,0,0,0,0,19,0
0,19,0,0,0,0,0,0,0,0,0,0,0,0,0,0,0,19,0
0,5,14,0,0,0,0,0,0,0,0,0,0,0,0,0,13,5,0
0,7,0,0,0,0,0,0,0,0,0,0,0,0,0,0,0,7,0
0,7,0,0,0,0,0,0,0,0,0,0,0,0,0,0,0,7,0
0,5,14,0,0,0,0,0,0,0,0,0,0,0,0,0,13,5,0
0,19,0,0,0,0,0,0,0,0,0,0,0,0,0,0,0,19,0
0,19,0,0,0,0,0,0,0,10,0,0,0,0,0,0,0,19,0
13,5,10,0,0,0,0,0,10,5,10,0,0,0,0,0,10,5,14
0,9,0,0,0,0,0,0,0,17,0,0,0,0,0,0,0,8,0
0,9,0,0,0,0,0,0,0,0,0,0,0,0,0,0,0,8,0
0,5,14,0,0,0,0,0,0,0,0,0,0,0,0,0,13,5,0
0,19,0,0,0,0,0,0,0,0,0,0,0,0,0,0,0,19,0
0,19,0,0,0,0,0,0,0,15,0,0,0,0,0,0,0,19,0
13,5,10,0,0,0,0,0,10,5,10,0,0,0,0,0,10,5,14
0,9,0,0,0,0,0,0,0,17,0,0,0,0,0,0,0,8,0
0,9,0,0,0,0,0,0,0,0,0,0,0,0,0,0,0,8,0
0,5,14,0,0,0,0,0,0,0,0,0,0,0,0,0,13,5,0
0,19,0,0,0,0,0,0,0,0,0,0,0,0,0,0,0,19,0
0,19,0,0,15,0,0,15,0,0,0,15,0,0,15,0,0,19,0
13,5,18,18,5,18,18,5,0,0,0,5,18,18,5,18,18,5,14
0,0,0,0,0,0,0,10,0,0,0,10,0,0,0,0,0,0,0
:endlayer
layer: 4
0,0,0,0,0,0,0,0,0,0,0,0,0,0,0,0,0,0,0
0,5,7,7,5,7,7,5,18,18,18,5,7,7,5,7,7,5,0
0,7,0,0,0,0,0,0,0,10,0,0,0,0,0,0,0,7,0
0,7,0,0,0,0,0,0,0,0,0,0,0,0,0,0,0,7,0
0,5,0,0,0,0,0,0,0,0,0,0,0,0,0,0,0,5,0
0,19,0,0,0,0,0,0,0,0,0,0,0,0,0,0,0,19,0
0,19,0,0,0,0,0,0,0,10,0,0,0,0,0,0,0,19,0
0,5,23,0,0,0,0,0,22,5,23,0,0,0,0,0,22,5,0
0,7,0,0,0,0,0,0,0,10,0,0,0,0,0,0,0,7,0
0,7,0,0,0,0,0,0,0,0,0,0,0,0,0,0,0,7,0
0,5,0,0,0,0,0,0,0,0,0,0,0,0,0,0,0,5,0
0,19,0,0,0,0,0,0,0,0,0,0,0,0,0,0,0,19,0
0,19,0,0,0,0,0,0,0,10,0,0,0,0,0,0,0,19,0
0,5,23,0,0,0,0,0,22,5,23,0,0,0,0,0,22,5,0
0,7,0,0,0,0,0,0,0,6,0,0,0,0,0,0,0,7,0
0,7,0,0,0,0,0,0,0,0,0,0,0,0,0,0,0,7,0
0,5,0,0,0,0,0,0,0,0,0,0,0,0,0,0,0,5,0
0,19,0,0,0,0,0,0,0,0,0,0,0,0,0,0,0,19,0
0,19,0,0,0,0,0,0,0,0,0,0,0,0,0,0,0,19,0
0,5,0,0,0,0,0,0,0,0,0,0,0,0,0,0,0,5,0
0,7,0,0,0,0,0,0,0,0,0,0,0,0,0,0,0,7,0
0,7,0,0,0,0,0,0,0,24,0,0,0,0,0,0,0,7,0
0,5,23,0,0,0,0,0,22,5,23,0,0,0,0,0,22,5,0
0,19,0,0,0,0,0,0,0,10,0,0,0,0,0,0,0,19,0
0,19,0,0,0,0,0,0,0,0,0,0,0,0,0,0,0,19,0
0,5,0,0,0,0,0,0,0,0,0,0,0,0,0,0,0,5,0
0,7,0,0,0,0,0,0,0,0,0,0,0,0,0,0,0,7,0
0,7,0,0,0,0,0,0,0,10,0,0,0,0,0,0,0,7,0
0,5,23,0,0,0,0,0,22,5,23,0,0,0,0,0,22,5,0
0,19,0,0,0,0,0,0,0,10,0,0,0,0,0,0,0,19,0
0,19,0,0,0,0,0,0,0,0,0,0,0,0,0,0,0,19,0
0,5,0,0,0,0,0,0,0,0,0,0,0,0,0,0,0,5,0
0,7,0,0,0,0,0,0,0,0,0,0,0,0,0,0,0,7,0
0,7,0,0,0,0,0,0,0,0,0,0,0,0,0,0,0,7,0
0,5,6,6,5,6,6,5,18,18,18,5,6,6,5,6,6,5,0
0,0,0,0,0,0,0,20,21,21,21,20,0,0,0,0,0,0,0
:endlayer
layer: 5
0,0,0,0,0,0,0,0,0,0,0,0,0,0,0,0,0,0,0
10,5,10,10,5,10,10,5,7,7,7,5,10,10,5,10,10,5,10
0,7,0,0,0,0,0,0,0,7,0,0,0,0,0,0,0,7,0
0,7,0,0,0,0,0,0,0,21,0,0,0,0,0,0,0,7,0
0,5,0,0,0,0,0,0,0,0,0,0,0,0,0,0,0,5,0
0,10,0,0,0,0,0,0,0,21,0,0,0,0,0,0,0,10,0
0,10,0,0,0,0,0,0,0,7,0,0,0,0,0,0,0,10,0
10,5,10,7,21,0,21,7,10,5,10,7,21,0,21,7,10,5,10
0,7,0,0,0,0,0,0,0,7,0,0,0,0,0,0,0,7,0
0,7,0,0,0,0,0,0,0,21,0,0,0,0,0,0,0,7,0
0,5,0,0,0,0,0,0,0,0,0,0,0,0,0,0,0,5,0
0,10,0,0,0,0,0,0,0,21,0,0,0,0,0,0,0,10,0
0,10,0,0,0,0,0,0,0,7,0,0,0,0,0,0,0,10,0
10,5,10,7,21,0,21,7,10,5,10,7,21,0,21,7,10,5,10
0,7,0,0,0,0,0,0,0,10,0,0,0,0,0,0,0,7,0
0,7,0,0,0,0,0,0,0,7,0,0,0,0,0,0,0,7,0
0,5,0,0,0,0,0,0,0,21,0,0,0,0,0,0,0,5,0
0,10,0,0,0,0,0,0,0,0,0,0,0,0,0,0,0,10,0
0,10,0,0,0,0,0,0,0,0,0,0,0,0,0,0,0,10,0
0,5,0,0,0,0,0,0,0,21,0,0,0,0,0,0,0,5,0
0,7,0,0,0,0,0,0,0,7,0,0,0,0,0,0,0,7,0
0,7,0,0,0,0,0,0,0,10,0,0,0,0,0,0,0,7,0
10,5,10,7,21,0,21,7,10,5,10,7,21,0,21,7,10,5,10
0,10,0,0,0,0,0,0,0,7,0,0,0,0,0,0,0,10,0
0,10,0,0,0,0,0,0,0,21,0,0,0,0,0,0,0,10,0
0,5,0,0,0,0,0,0,0,0,0,0,0,0,0,0,0,5,0
0,7,0,0,0,0,0,0,0,21,0,0,0,0,0,0,0,7,0
0,7,0,0,0,0,0,0,0,7,0,0,0,0,0,0,0,7,0
10,5,10,7,21,0,21,7,10,5,10,7,21,0,21,7,10,5,10
0,10,0,0,0,0,0,0,0,7,0,0,0,0,0,0,0,10,0
0,10,0,0,0,0,0,0,0,21,0,0,0,0,0,0,0,10,0
0,5,0,0,0,0,0,0,0,0,0,0,0,0,0,0,0,5,0
0,7,0,0,0,0,0,0,0,0,0,0,0,0,0,0,0,7,0
0,7,0,0,0,0,0,0,0,0,0,0,0,0,0,0,0,7,0
10,5,10,10,5,10,10,5,7,7,7,5,10,10,5,10,10,5,10
0,0,0,0,0,0,0,0,0,0,0,0,0,0,0,0,0,0,0
:endlayer
layer: 6
21,15,0,0,0,0,0,0,0,0,0,0,0,0,0,0,0,15,21
22,5,18,18,18,18,18,18,18,18,18,18,18,18,18,18,18,5,23
21,19,0,0,0,0,0,0,0,19,0,0,0,0,0,0,0,19,21
21,19,0,0,0,0,0,0,0,19,0,0,0,0,0,0,0,19,21
21,19,0,0,0,0,0,0,0,19,0,0,0,0,0,0,0,19,21
21,19,0,0,0,0,0,0,0,19,0,0,0,0,0,0,0,19,21
21,19,0,0,0,0,0,0,0,19,0,0,0,0,0,0,0,19,21
22,19,18,18,18,18,18,18,18,18,18,18,18,18,18,18,18,19,23
21,19,0,0,0,0,0,0,0,19,0,0,0,0,0,0,0,19,21
21,19,0,0,0,0,0,0,0,19,0,0,0,0,0,0,0,19,21
21,19,0,0,0,0,0,0,0,19,0,0,0,0,0,0,0,19,21
21,19,0,0,0,0,0,0,0,19,0,0,0,0,0,0,0,19,21
21,19,0,0,0,0,0,0,0,19,0,0,0,0,0,0,0,19,21
22,19,18,18,18,18,18,18,18,18,18,18,18,18,18,18,18,19,23
21,19,0,0,0,0,0,0,0,19,0,0,0,0,0,0,0,19,21
21,19,0,0,0,0,0,0,0,19,0,0,0,0,0,0,0,19,21
21,19,0,0,0,0,0,0,0,19,0,0,0,0,0,0,0,19,21
21,19,0,0,0,0,0,0,0,19,0,0,0,0,0,0,0,19,21
21,19,0,0,0,0,0,0,0,19,0,0,0,0,0,0,0,19,21
21,19,0,0,0,0,0,0,0,19,0,0,0,0,0,0,0,19,21
21,19,0,0,0,0,0,0,0,19,0,0,0,0,0,0,0,19,21
21,19,0,0,0,0,0,0,0,19,0,0,0,0,0,0,0,19,21
22,19,18,18,18,18,18,18,18,18,18,18,18,18,18,18,18,19,23
21,19,0,0,0,0,0,0,0,19,0,0,0,0,0,0,0,19,21
21,19,0,0,0,0,0,0,0,19,0,0,0,0,0,0,0,19,21
21,19,0,0,0,0,0,0,0,19,0,0,0,0,0,0,0,19,21
21,19,0,0,0,0,0,0,0,19,0,0,0,0,0,0,0,19,21
21,19,0,0,0,0,0,0,0,19,0,0,0,0,0,0,0,19,21
22,19,18,18,18,18,18,18,18,18,18,18,18,18,18,18,18,19,23
21,19,0,0,0,0,0,0,0,19,0,0,0,0,0,0,0,19,21
21,19,0,0,0,0,0,0,0,19,0,0,0,0,0,0,0,19,21
21,19,0,0,0,0,0,0,0,19,0,0,0,0,0,0,0,19,21
21,19,0,0,0,0,0,0,0,19,0,0,0,0,0,0,0,19,21
21,19,0,0,0,0,0,0,0,19,0,0,0,0,0,0,0,19,21
22,5,18,18,18,18,18,18,18,18,18,18,18,18,18,18,18,5,23
21,17,0,0,0,0,0,0,0,0,0,0,0,0,0,0,0,17,21
:endlayer
layer: 7
0,20,21,0,0,0,0,0,0,0,0,0,0,0,0,0,21,20,0
0,20,7,7,11,11,5,11,11,11,11,11,5,11,11,7,7,20,0
0,20,21,0,0,0,0,0,0,0,0,0,0,0,0,0,21,20,0
0,20,21,0,0,0,0,0,0,0,0,0,0,0,0,0,21,20,0
0,20,21,0,0,0,0,0,0,10,0,0,0,0,0,0,21,20,0
0,20,21,0,0,0,0,0,0,0,0,0,0,0,0,0,21,20,0
0,20,21,0,0,0,0,0,0,0,0,0,0,0,0,0,21,20,0
0,20,21,10,0,5,0,0,10,5,10,0,0,5,0,10,21,20,0
0,20,21,0,0,0,0,0,0,0,0,0,0,0,0,0,21,20,0
0,20,21,0,0,0,0,0,0,0,0,0,0,0,0,0,21,20,0
0,20,21,0,0,0,0,0,0,10,0,0,0,0,0,0,21,20,0
0,20,21,0,0,0,0,0,0,0,0,0,0,0,0,0,21,20,0
0,20,21,0,0,0,0,0,0,0,0,0,0,0,0,0,21,20,0
0,20,21,10,0,5,0,0,10,5,10,0,0,5,0,10,21,20,0
0,20,21,0,0,0,0,0,0,0,0,0,0,0,0,0,21,20,0
0,20,21,0,0,0,0,0,0,0,0,0,0,0,0,0,21,20,0
0,20,21,0,0,0,0,0,0,10,0,0,0,0,0,0,21,20,0
0,20,21,0,0,0,0,0,0,0,0,0,0,0,0,0,21,20,0
0,20,21,0,0,0,0,0,0,0,0,0,0,0,0,0,21,20,0
0,20,21,0,0,0,0,0,0,10,0,0,0,0,0,0,21,20,0
0,20,21,0,0,0,0,0,0,0,0,0,0,0,0,0,21,20,0
0,20,21,0,0,0,0,0,0,0,0,0,0,0,0,0,21,20,0
0,20,21,10,0,5,0,0,10,5,10,0,0,5,0,10,21,20,0
0,20,21,0,0,0,0,0,0,0,0,0,0,0,0,0,21,20,0
0,20,21,0,0,0,0,0,0,0,0,0,0,0,0,0,21,20,0
0,20,21,0,0,0,0,0,0,10,0,0,0,0,0,0,21,20,0
0,20,21,0,0,0,0,0,0,0,0,0,0,0,0,0,21,20,0
0,20,21,0,0,0,0,0,0,0,0,0,0,0,0,0,21,20,0
0,20,21,10,0,5,0,0,10,5,10,0,0,5,0,10,21,20,0
0,20,21,0,0,0,0,0,0,0,0,0,0,0,0,0,21,20,0
0,20,21,0,0,0,0,0,0,0,0,0,0,0,0,0,21,20,0
0,20,21,0,0,0,0,0,0,10,0,0,0,0,0,0,21,20,0
0,20,21,0,0,0,0,0,0,0,0,0,0,0,0,0,21,20,0
0,20,21,0,0,0,0,0,0,0,0,0,0,0,0,0,21,20,0
0,20,7,7,12,12,5,12,12,12,12,12,5,12,12,7,7,20,0
0,20,21,0,0,0,0,0,0,0,0,0,0,0,0,0,21,20,0
:endlayer
layer: 8
0,0,0,20,21,0,15,0,0,0,0,0,15,0,21,20,0,0,0
0,0,0,20,7,7,5,11,11,11,11,11,5,7,7,20,0,0,0
0,0,0,20,21,0,0,0,0,17,0,0,0,0,21,20,0,0,0
0,0,0,20,21,0,0,0,0,0,0,0,0,0,21,20,0,0,0
0,0,16,20,21,0,0,0,0,10,0,0,0,0,21,20,16,0,0
0,0,0,20,21,0,0,0,0,0,0,0,0,0,21,20,0,0,0
0,0,0,20,21,0,0,0,0,15,0,0,0,0,21,20,0,0,0
0,0,0,20,21,5,18,23,0,5,0,22,18,5,21,20,0,0,0
0,0,0,20,21,0,0,0,0,17,0,0,0,0,21,20,0,0,0
0,0,0,20,21,0,0,0,0,0,0,0,0,0,21,20,0,0,0
0,0,16,20,21,0,0,0,0,10,0,0,0,0,21,20,16,0,0
0,0,0,20,21,0,0,0,0,0,0,0,0,0,21,20,0,0,0
0,0,0,20,21,0,0,0,0,15,0,0,0,0,21,20,0,0,0
0,0,0,20,21,5,18,23,0,5,0,22,18,5,21,20,0,0,0
0,0,0,20,21,0,0,0,0,17,0,0,0,0,21,20,0,0,0
0,0,0,20,21,0,0,0,0,0,0,0,0,0,21,20,0,0,0
0,0,16,20,21,0,0,0,0,10,0,0,0,0,21,20,16,0,0
0,0,0,20,21,0,0,0,0,0,0,0,0,0,21,20,0,0,0
0,0,0,20,21,0,0,0,0,0,0,0,0,0,21,20,0,0,0
0,0,16,20,21,0,0,0,0,10,0,0,0,0,21,20,16,0,0
0,0,0,20,21,0,0,0,0,0,0,0,0,0,21,20,0,0,0
0,0,0,20,21,0,0,0,0,15,0,0,0,0,21,20,0,0,0
0,0,0,20,21,5,18,23,0,5,0,22,18,5,21,20,0,0,0
0,0,0,20,21,0,0,0,0,17,0,0,0,0,21,20,0,0,0
0,0,0,20,21,0,0,0,0,0,0,0,0,0,21,20,0,0,0
0,0,16,20,21,0,0,0,0,10,0,0,0,0,21,20,16,0,0
0,0,0,20,21,0,0,0,0,0,0,0,0,0,21,20,0,0,0
0,0,0,20,21,0,0,0,0,15,0,0,0,0,21,20,0,0,0
0,0,0,20,21,5,18,23,0,5,0,22,18,5,21,20,0,0,0
0,0,0,20,21,0,0,0,0,17,0,0,0,0,21,20,0,0,0
0,0,0,20,21,0,0,0,0,0,0,0,0,0,21,20,0,0,0
0,0,16,20,21,0,0,0,0,10,0,0,0,0,21,20,16,0,0
0,0,0,20,21,0,0,0,0,0,0,0,0,0,21,20,0,0,0
0,0,0,20,21,0,0,0,0,15,0,0,0,0,21,20,0,0,0
0,0,0,20,7,7,5,12,12,12,12,12,5,7,7,20,0,0,0
0,0,0,20,21,0,17,0,0,0,0,0,17,0,21,20,0,0,0
:endlayer
layer: 9
0,0,0,0,0,20,21,0,0,0,0,0,21,20,0,0,0,0,0
0,0,0,0,0,20,7,18,18,18,18,18,7,20,0,0,0,0,0
0,0,0,0,0,20,21,0,0,0,0,0,21,20,0,0,0,0,0
0,0,0,0,0,20,21,0,0,10,0,0,21,20,0,0,0,0,0
0,0,0,0,0,20,21,0,0,10,0,0,21,20,0,0,0,0,0
0,0,0,0,0,20,21,0,0,10,0,0,21,20,0,0,0,0,0
0,0,0,0,0,20,21,0,0,0,0,0,21,20,0,0,0,0,0
0,0,0,0,0,20,21,18,18,10,18,18,21,20,0,0,0,0,0
0,0,0,0,0,20,21,0,0,0,0,0,21,20,0,0,0,0,0
0,0,0,0,0,20,21,0,0,10,0,0,21,20,0,0,0,0,0
0,0,0,0,0,20,21,0,0,10,0,0,21,20,0,0,0,0,0
0,0,0,0,0,20,21,0,0,10,0,0,21,20,0,0,0,0,0
0,0,0,0,0,20,21,0,0,0,0,0,21,20,0,0,0,0,0
0,0,0,0,0,20,21,18,18,10,18,18,21,20,0,0,0,0,0
0,0,0,0,0,20,21,0,0,0,0,0,21,20,0,0,0,0,0
0,0,0,0,0,20,21,0,0,10,0,0,21,20,0,0,0,0,0
0,0,0,0,0,20,21,0,0,10,0,0,21,20,0,0,0,0,0
0,0,0,0,0,20,21,0,0,10,0,0,21,20,0,0,0,0,0
0,0,0,0,0,20,21,0,0,10,0,0,21,20,0,0,0,0,0
0,0,0,0,0,20,21,0,0,10,0,0,21,20,0,0,0,0,0
0,0,0,0,0,20,21,0,0,10,0,0,21,20,0,0,0,0,0
0,0,0,0,0,20,21,0,0,0,0,0,21,20,0,0,0,0,0
0,0,0,0,0,20,21,18,18,10,18,18,21,20,0,0,0,0,0
0,0,0,0,0,20,21,0,0,0,0,0,21,20,0,0,0,0,0
0,0,0,0,0,20,21,0,0,10,0,0,21,20,0,0,0,0,0
0,0,0,0,0,20,21,0,0,10,0,0,21,20,0,0,0,0,0
0,0,0,0,0,20,21,0,0,10,0,0,21,20,0,0,0,0,0
0,0,0,0,0,20,21,0,0,0,0,0,21,20,0,0,0,0,0
0,0,0,0,0,20,21,18,18,10,18,18,21,20,0,0,0,0,0
0,0,0,0,0,20,21,0,0,0,0,0,21,20,0,0,0,0,0
0,0,0,0,0,20,21,0,0,10,0,0,21,20,0,0,0,0,0
0,0,0,0,0,20,21,0,0,10,0,0,21,20,0,0,0,0,0
0,0,0,0,0,20,21,0,0,10,0,0,21,20,0,0,0,0,0
0,0,0,0,0,20,21,0,0,0,0,0,21,20,0,0,0,0,0
0,0,0,0,0,20,7,18,18,18,18,18,7,20,0,0,0,0,0
0,0,0,0,0,20,21,0,0,0,0,0,21,20,0,0,0,0,0
:endlayer
layer: 10
0,0,0,0,0,0,0,20,21,0,21,20,0,0,0,0,0,0,0
0,0,0,0,0,0,0,20,7,7,7,20,0,0,0,0,0,0,0
0,0,0,0,0,0,0,20,21,19,21,20,0,0,0,0,0,0,0
0,0,0,0,0,0,0,20,21,19,21,20,0,0,0,0,0,0,0
0,0,0,0,0,0,0,20,21,19,21,20,0,0,0,0,0,0,0
0,0,0,0,0,0,0,20,21,19,21,20,0,0,0,0,0,0,0
0,0,0,0,0,0,0,20,21,19,21,20,0,0,0,0,0,0,0
0,0,0,0,0,0,0,20,21,19,21,20,0,0,0,0,0,0,0
0,0,0,0,0,0,0,20,21,19,21,20,0,0,0,0,0,0,0
0,0,0,0,0,0,0,20,21,19,21,20,0,0,0,0,0,0,0
0,0,0,0,0,0,0,20,21,19,21,20,0,0,0,0,0,0,0
0,0,0,0,0,0,0,20,21,19,21,20,0,0,0,0,0,0,0
0,0,0,0,0,0,0,20,21,19,21,20,0,0,0,0,0,0,0
0,0,0,0,0,0,0,20,21,19,21,20,0,0,0,0,0,0,0
0,0,0,0,0,0,0,20,21,19,21,20,0,0,0,0,0,0,0
0,0,0,0,0,0,0,20,21,19,21,20,0,0,0,0,0,0,0
0,0,0,0,0,0,0,20,21,19,21,20,0,0,0,0,0,0,0
0,0,0,0,0,0,0,20,21,19,21,20,0,0,0,0,0,0,0
0,0,0,0,0,0,0,20,21,19,21,20,0,0,0,0,0,0,0
0,0,0,0,0,0,0,20,21,19,21,20,0,0,0,0,0,0,0
0,0,0,0,0,0,0,20,21,19,21,20,0,0,0,0,0,0,0
0,0,0,0,0,0,0,20,21,19,21,20,0,0,0,0,0,0,0
0,0,0,0,0,0,0,20,21,19,21,20,0,0,0,0,0,0,0
0,0,0,0,0,0,0,20,21,19,21,20,0,0,0,0,0,0,0
0,0,0,0,0,0,0,20,21,19,21,20,0,0,0,0,0,0,0
0,0,0,0,0,0,0,20,21,19,21,20,0,0,0,0,0,0,0
0,0,0,0,0,0,0,20,21,19,21,20,0,0,0,0,0,0,0
0,0,0,0,0,0,0,20,21,19,21,20,0,0,0,0,0,0,0
0,0,0,0,0,0,0,20,21,19,21,20,0,0,0,0,0,0,0
0,0,0,0,0,0,0,20,21,19,21,20,0,0,0,0,0,0,0
0,0,0,0,0,0,0,20,21,19,21,20,0,0,0,0,0,0,0
0,0,0,0,0,0,0,20,21,19,21,20,0,0,0,0,0,0,0
0,0,0,0,0,0,0,20,21,19,21,20,0,0,0,0,0,0,0
0,0,0,0,0,0,0,20,21,19,21,20,0,0,0,0,0,0,0
0,0,0,0,0,0,0,20,7,7,7,20,0,0,0,0,0,0,0
0,0,0,0,0,0,0,20,21,0,21,20,0,0,0,0,0,0,0
:endlayer
layer: 11
0,0,0,0,0,0,0,0,0,20,0,0,0,0,0,0,0,0,0
0,0,0,0,0,0,0,0,0,20,0,0,0,0,0,0,0,0,0
0,0,0,0,0,0,0,0,0,20,0,0,0,0,0,0,0,0,0
0,0,0,0,0,0,0,0,0,20,0,0,0,0,0,0,0,0,0
0,0,0,0,0,0,0,0,16,20,16,0,0,0,0,0,0,0,0
0,0,0,0,0,0,0,0,0,20,0,0,0,0,0,0,0,0,0
0,0,0,0,0,0,0,0,0,20,0,0,0,0,0,0,0,0,0
0,0,0,0,0,0,0,0,0,20,0,0,0,0,0,0,0,0,0
0,0,0,0,0,0,0,0,0,20,0,0,0,0,0,0,0,0,0
0,0,0,0,0,0,0,0,0,20,0,0,0,0,0,0,0,0,0
0,0,0,0,0,0,0,0,16,20,16,0,0,0,0,0,0,0,0
0,0,0,0,0,0,0,0,0,20,0,0,0,0,0,0,0,0,0
0,0,0,0,0,0,0,0,0,20,0,0,0,0,0,0,0,0,0
0,0,0,0,0,0,0,0,0,20,0,0,0,0,0,0,0,0,0
0,0,0,0,0,0,0,0,0,20,0,0,0,0,0,0,0,0,0
0,0,0,0,0,0,0,0,0,20,0,0,0,0,0,0,0,0,0
0,0,0,0,0,0,0,0,16,20,16,0,0,0,0,0,0,0,0
0,0,0,0,0,0,0,0,0,20,0,0,0,0,0,0,0,0,0
0,0,0,0,0,0,0,0,0,20,0,0,0,0,0,0,0,0,0
0,0,0,0,0,0,0,0,16,20,16,0,0,0,0,0,0,0,0
0,0,0,0,0,0,0,0,0,20,0,0,0,0,0,0,0,0,0
0,0,0,0,0,0,0,0,0,20,0,0,0,0,0,0,0,0,0
0,0,0,0,0,0,0,0,0,20,0,0,0,0,0,0,0,0,0
0,0,0,0,0,0,0,0,0,20,0,0,0,0,0,0,0,0,0
0,0,0,0,0,0,0,0,0,20,0,0,0,0,0,0,0,0,0
0,0,0,0,0,0,0,0,16,20,16,0,0,0,0,0,0,0,0
0,0,0,0,0,0,0,0,0,20,0,0,0,0,0,0,0,0,0
0,0,0,0,0,0,0,0,0,20,0,0,0,0,0,0,0,0,0
0,0,0,0,0,0,0,0,0,20,0,0,0,0,0,0,0,0,0
0,0,0,0,0,0,0,0,0,20,0,0,0,0,0,0,0,0,0
0,0,0,0,0,0,0,0,0,20,0,0,0,0,0,0,0,0,0
0,0,0,0,0,0,0,0,16,20,16,0,0,0,0,0,0,0,0
0,0,0,0,0,0,0,0,0,20,0,0,0,0,0,0,0,0,0
0,0,0,0,0,0,0,0,0,20,0,0,0,0,0,0,0,0,0
0,0,0,0,0,0,0,0,0,20,0,0,0,0,0,0,0,0,0
0,0,0,0,0,0,0,0,0,20,0,0,0,0,0,0,0,0,0
:endlayer

#### RULES ####
rule:
plugin=vanillaBlocks
number=1
data:
JSON:{blockState:{blockName:"minecraft:grass",properties:{snowy:"false"}}}
:enddata
:endrule

rule:
plugin=vanillaBlocks
number=2
data:
JSON:{blockState:{blockName:"minecraft:cobblestone"}}
:enddata
:endrule

rule:
plugin=vanillaBlocks
number=3
data:
JSON:{blockState:{blockName:"minecraft:dirt",properties:{variant:"coarse_dirt",snowy:"false"}}}
:enddata
:endrule

rule:
plugin=vanillaBlocks
number=4
data:
JSON:{blockState:{blockName:"minecraft:stonebrick",properties:{variant:"stonebrick"}}}
:enddata
:endrule

rule:
plugin=vanillaBlocks
number=5
data:
JSON:{blockState:{blockName:"minecraft:log",properties:{variant:birch,axis:"y"}}}
:enddata
:endrule

rule:
plugin=vanillaBlocks
number=6
data:
JSON:{blockState:{blockName:"minecraft:birch_stairs",properties:{half:"top",shape:"straight",facing:"north"}}}
:enddata
:endrule

rule:
plugin=vanillaBlocks
number=7
data:
JSON:{blockState:{blockName:"minecraft:planks",properties:{variant:birch}}}
:enddata
:endrule

rule:
plugin=vanillaBlocks
number=8
data:
JSON:{blockState:{blockName:"minecraft:birch_stairs",properties:{half:"bottom",shape:"straight",facing:"west"}}}
:enddata
:endrule

rule:
plugin=vanillaBlocks
number=9
data:
JSON:{blockState:{blockName:"minecraft:birch_stairs",properties:{half:"bottom",shape:"straight",facing:"east"}}}
:enddata
:endrule

rule:
plugin=vanillaBlocks
number=10
data:
JSON:{blockState:{blockName:"minecraft:birch_fence",properties:{east:"false",south:"false",north:"false",west:"false"}}}
:enddata
:endrule

rule:
plugin=vanillaBlocks
number=11
data:
JSON:{blockState:{blockName:"minecraft:birch_stairs",properties:{half:"bottom",shape:"straight",facing:"south"}}}
:enddata
:endrule

rule:
plugin=vanillaBlocks
number=12
data:
JSON:{blockState:{blockName:"minecraft:birch_stairs",properties:{half:"bottom",shape:"straight",facing:"north"}}}
:enddata
:endrule

rule:
plugin=vanillaBlocks
number=13
data:
JSON:{blockState:{blockName:"minecraft:torch",properties:{facing:"west"}}}
:enddata
:endrule

rule:
plugin=vanillaBlocks
number=14
data:
JSON:{blockState:{blockName:"minecraft:torch",properties:{facing:"east"}}}
:enddata
:endrule

rule:
plugin=vanillaBlocks
number=15
data:
JSON:{blockState:{blockName:"minecraft:torch",properties:{facing:"north"}}}
:enddata
:endrule

rule:
plugin=vanillaBlocks
number=16
data:
JSON:{blockState:{blockName:"minecraft:torch",properties:{facing:"up"}}}
:enddata
:endrule

rule:
plugin=vanillaBlocks
number=17
data:
JSON:{blockState:{blockName:"minecraft:torch",properties:{facing:"south"}}}
:enddata
:endrule

rule:
plugin=vanillaBlocks
number=18
data:
JSON:{blockState:{blockName:"minecraft:log",properties:{variant:birch,axis:"x"}}}
:enddata
:endrule

rule:
plugin=vanillaBlocks
number=19
data:
JSON:{blockState:{blockName:"minecraft:log",properties:{variant:birch,axis:"z"}}}
:enddata
:endrule

rule:
plugin=vanillaBlocks
number=20
data:
JSON:{blockState:{blockName:"minecraft:wooden_slab",properties:{half:"bottom",variant:"birch"}}}
:enddata
:endrule

rule:
plugin=vanillaBlocks
number=21
data:
JSON:{blockState:{blockName:"minecraft:wooden_slab",properties:{half:"top",variant:"birch"}}}
:enddata
:endrule

rule:
plugin=vanillaBlocks
number=22
data:
JSON:{blockState:{blockName:"minecraft:birch_stairs",properties:{half:"top",shape:"straight",facing:"east"}}}
:enddata
:endrule

rule:
plugin=vanillaBlocks
number=23
data:
JSON:{blockState:{blockName:"minecraft:birch_stairs",properties:{half:"top",shape:"straight",facing:"west"}}}
:enddata
:endrule

rule:
plugin=vanillaBlocks
number=24
data:
JSON:{blockState:{blockName:"minecraft:birch_stairs",properties:{half:"top",shape:"straight",facing:"south"}}}
:enddata
:endrule

#### ENTITIES ####
