# Ancient Warfare Structure Template File
# Auto-generated structure template file. created on: 10/16/2023 at: 18:0:23
# Lines beginning with # denote comments

header:
version=2.11
name=SB_MarenCol_Farm_1H1R_1_umbran
mods=biomesoplenty
size=38,14,31
offset=26,1,30
:endheader

#### VALIDATION ####
validation:
type=ground
structureAuthor=TheOddlySeagull
survival=true
worldGenEnabled=false
unique=false
preserveBlocks=false
preventNaturalHostileSpawns=false
selectionWeight=1
clusterValue=1
minDuplicateDistance=1
dimensionWhiteList=true
dimensionList=
biomeGroupList=
biomeWhiteList=true
biomeList=
leveling=0
fill=0
border=0
blockSwap=false
territoryName=
biomeReplacement=minecraft:
minGenerationHeight=0
maxGenerationHeight=255
:endvalidation

#### LAYERS ####
layer: 0
1,1,1,1,1,1,1,1,1,2,1,1,1,1,1,1,3,1,1,1,1,1,1,1,1,1,4,5,5,4,1,1,1,1,1,1,1,1
1,1,1,1,1,1,1,1,3,2,6,1,1,6,1,3,6,6,1,1,1,1,1,1,1,1,4,5,5,4,1,1,1,1,1,1,1,1
1,1,1,6,1,1,1,6,3,6,3,1,3,3,2,2,3,2,2,1,1,1,1,1,1,1,4,5,5,4,1,1,1,1,1,1,1,1
1,6,3,6,6,3,1,1,1,1,2,6,3,3,3,3,2,3,1,1,1,1,1,1,1,1,4,5,5,4,1,1,1,1,1,1,1,1
1,1,1,3,2,1,1,3,1,2,6,1,3,6,3,1,6,1,1,1,1,5,5,5,5,5,5,5,5,5,5,5,1,1,1,1,1,1
1,1,1,1,1,1,1,2,3,3,2,2,1,1,5,5,5,5,5,5,5,5,6,6,2,2,3,3,3,3,2,5,1,1,1,1,1,1
1,1,1,1,1,1,6,2,3,6,3,3,3,1,5,6,2,2,2,3,2,5,2,6,6,2,6,6,3,2,2,5,5,5,5,5,1,1
1,1,1,1,1,1,2,1,1,3,3,2,1,1,5,2,3,2,3,2,6,5,2,2,6,6,6,3,6,3,2,5,6,2,6,5,1,1
1,1,1,1,1,1,3,3,1,1,6,1,1,1,5,3,3,3,5,5,6,5,6,2,2,3,2,6,2,3,6,5,3,6,6,5,1,1
1,1,1,1,2,6,6,6,2,5,5,5,5,5,5,5,5,5,5,5,5,5,3,3,2,2,2,3,3,3,3,5,2,2,6,5,6,1
1,1,1,1,1,3,3,1,1,5,7,7,7,7,5,5,5,5,5,5,5,5,3,6,3,2,2,3,6,6,3,5,6,2,2,5,1,2
1,1,1,1,1,1,5,5,5,5,7,7,7,7,5,5,5,5,5,5,5,5,6,2,3,2,6,2,6,6,6,5,2,3,2,5,3,3
1,1,1,1,1,1,5,5,5,5,7,7,7,7,5,5,5,5,5,5,5,5,6,6,3,6,6,6,3,2,2,5,3,2,2,5,5,3
1,1,5,5,5,5,5,5,5,5,5,5,5,5,5,5,5,5,5,5,5,5,6,3,3,2,3,6,2,6,2,5,2,6,3,5,5,1
1,1,5,3,2,2,5,3,2,5,5,5,5,5,5,5,5,5,5,5,5,5,6,3,3,2,6,2,6,2,3,5,2,3,2,5,5,2
1,1,5,2,3,3,5,3,3,5,5,5,5,5,5,5,5,5,5,5,5,5,3,3,3,3,3,2,3,3,2,5,2,6,2,5,6,1
1,1,5,8,8,8,5,3,2,5,5,5,5,5,5,5,5,5,5,5,5,5,3,3,2,6,6,3,6,6,3,5,5,5,5,5,6,2
1,1,5,3,3,3,5,3,2,5,2,2,1,2,3,1,3,1,1,1,1,5,2,6,6,2,3,3,3,6,6,5,2,1,6,3,6,6
1,1,5,3,3,2,5,2,2,5,1,2,6,3,1,6,1,2,1,1,1,5,6,6,6,6,2,3,2,2,3,5,3,6,1,6,6,2
1,1,5,8,8,8,5,3,3,5,1,2,3,1,1,2,3,1,3,1,3,5,6,2,3,3,3,6,6,2,2,5,3,3,3,1,1,1
1,1,5,2,2,2,5,2,2,5,1,2,1,1,1,1,6,6,6,6,2,5,3,3,3,6,3,3,3,3,3,5,6,1,1,1,1,1
1,1,5,2,3,2,5,2,3,5,6,1,1,1,1,1,2,1,2,2,2,5,5,5,5,5,5,5,5,5,5,5,1,1,1,1,1,1
1,1,5,8,8,8,5,3,2,5,6,3,6,2,1,1,1,1,1,3,1,1,6,4,5,5,5,6,5,4,1,1,1,1,1,1,1,1
1,1,5,2,3,3,5,2,3,5,1,6,2,1,1,1,1,1,1,1,6,3,6,4,5,6,6,5,5,4,1,1,1,1,1,1,1,1
1,1,5,3,3,3,5,2,3,5,3,1,1,1,1,5,5,5,5,5,3,1,1,4,6,6,6,6,6,4,1,1,1,1,1,1,1,1
1,1,5,8,8,8,5,3,3,5,1,2,3,1,1,5,0,0,0,5,1,2,1,4,6,5,5,5,5,4,1,1,1,1,1,1,1,1
1,1,5,2,2,2,5,2,3,5,3,6,1,1,1,5,0,9,0,5,2,6,2,4,6,6,5,5,6,4,1,1,1,1,1,1,1,1
1,1,5,2,3,2,5,2,3,5,6,2,6,1,1,5,0,0,0,5,2,3,6,4,6,6,6,5,5,4,1,1,1,1,1,1,1,1
1,1,5,5,5,5,5,5,5,5,3,2,2,3,6,5,5,5,5,5,6,1,2,4,5,6,5,5,6,4,1,1,1,1,1,1,1,1
1,1,1,1,1,1,4,6,5,4,1,6,6,3,2,1,1,1,3,1,1,6,1,4,5,6,6,5,5,4,1,1,1,1,1,1,1,1
1,1,1,1,1,1,4,5,6,4,1,2,1,3,2,1,1,3,1,3,3,3,1,4,5,6,5,5,5,4,1,1,1,1,1,1,1,1
:endlayer
layer: 1
0,0,0,0,0,0,0,0,0,0,0,0,0,0,0,0,0,0,0,0,0,0,0,0,0,0,0,0,0,0,0,0,0,0,0,0,0,0
0,10,0,0,0,0,0,0,0,0,0,0,0,0,0,0,0,0,0,0,0,0,0,0,0,0,0,0,0,0,0,0,0,0,0,10,0,0
0,0,0,0,0,0,9,0,0,0,0,0,0,0,0,0,0,9,0,0,0,0,0,0,0,0,0,0,0,0,0,0,0,0,0,0,0,0
0,0,0,0,0,0,0,0,0,0,9,0,0,0,0,0,0,0,0,0,0,0,0,0,0,0,0,0,0,0,0,0,0,0,0,0,0,0
0,0,0,0,0,0,0,0,0,0,0,0,0,0,0,0,0,0,0,0,0,11,7,11,7,7,11,0,0,11,7,11,0,0,0,0,0,0
0,0,0,0,0,0,0,0,0,0,0,0,0,0,10,0,0,10,0,0,10,7,0,12,0,0,0,0,0,12,0,7,0,0,0,0,0,0
0,0,0,0,0,0,0,0,0,0,0,0,0,0,0,0,0,0,0,0,0,11,0,0,0,0,0,0,0,0,0,11,7,11,7,11,0,0
0,0,0,9,0,0,0,0,0,0,0,0,0,0,0,0,0,0,0,0,0,7,0,0,0,0,0,0,0,0,0,7,0,0,0,7,0,0
0,0,0,0,0,0,0,0,0,0,0,0,0,0,0,0,0,0,5,5,0,7,0,0,0,0,0,0,0,0,0,7,0,0,0,11,0,0
0,0,0,0,0,0,0,0,0,11,7,11,7,7,11,0,11,5,0,0,5,11,0,0,0,0,0,0,0,0,0,11,0,0,0,7,0,0
0,0,0,0,0,0,0,0,0,7,0,0,0,0,7,0,0,0,13,13,0,7,0,0,0,9,0,0,0,0,0,7,0,0,0,11,0,0
0,0,0,0,0,0,0,0,0,11,0,0,0,0,11,0,0,0,0,0,0,11,0,0,0,0,0,0,0,0,0,11,0,0,0,7,0,0
0,0,0,0,0,0,0,0,0,7,0,0,0,0,7,0,0,0,0,0,0,0,0,0,0,0,0,0,0,0,0,7,0,0,0,11,0,0
0,0,11,7,7,7,11,0,0,7,7,11,0,0,11,0,0,0,0,0,0,0,0,0,0,0,0,0,0,0,0,7,0,0,0,0,0,0
0,0,7,0,0,0,0,0,0,11,0,0,0,0,0,0,0,0,0,0,0,11,0,0,0,0,0,0,0,0,0,11,0,0,0,11,0,0
0,0,7,0,0,0,0,0,0,0,0,0,0,0,0,0,0,0,0,0,0,7,0,0,0,0,0,0,0,0,0,0,0,0,0,7,0,0
0,0,11,10,10,10,11,0,0,11,7,11,0,0,11,7,11,7,7,11,7,11,0,0,0,0,9,0,0,0,0,11,7,11,7,11,0,0
0,0,7,0,0,0,0,0,0,7,0,0,0,0,0,0,0,0,0,0,0,7,0,0,0,0,0,0,0,0,0,7,0,0,0,0,0,0
0,0,7,0,0,0,0,0,0,11,0,0,0,0,0,0,0,0,0,0,0,7,0,0,0,0,0,0,0,0,0,7,0,0,0,0,0,0
0,0,11,10,10,10,11,0,0,0,0,0,0,0,0,0,0,0,0,0,0,11,0,0,0,0,0,0,0,0,0,11,0,0,0,0,0,0
0,0,7,0,0,0,0,0,0,0,0,0,0,0,0,0,0,0,0,0,0,0,0,0,0,0,0,0,0,0,0,0,0,0,0,0,0,0
0,0,7,0,0,0,0,0,0,0,0,0,0,0,0,0,0,0,0,0,0,11,7,11,0,0,0,0,0,11,7,11,0,0,0,0,0,0
0,0,11,10,10,10,11,0,0,11,0,0,0,0,0,0,0,0,0,0,0,0,0,0,0,0,0,0,0,0,0,0,0,0,0,0,0,0
0,0,7,0,0,0,0,0,0,0,0,0,0,0,0,0,0,0,0,0,0,0,0,0,0,0,0,0,0,0,0,0,0,0,0,0,10,0
0,0,7,0,0,0,0,0,0,0,0,0,0,0,0,13,5,5,5,13,0,0,0,0,0,0,0,0,0,0,0,0,0,0,0,0,0,0
0,0,11,10,10,10,11,0,0,0,0,0,0,0,0,5,0,0,0,5,0,0,0,0,0,0,0,0,0,0,0,0,0,0,0,0,0,0
0,0,7,0,0,0,0,0,0,11,0,0,0,0,14,5,0,0,0,5,15,0,0,0,0,0,0,0,0,0,0,0,0,0,0,0,0,0
0,0,7,0,0,0,0,0,0,7,0,0,0,0,0,5,0,0,0,5,0,0,0,0,0,0,0,0,0,0,0,0,0,0,0,0,0,0
0,0,11,7,7,7,11,0,0,11,0,0,0,0,0,13,5,5,5,13,0,0,0,0,0,0,9,0,0,0,0,0,0,0,0,0,0,0
0,0,0,0,0,0,0,0,0,0,0,0,0,0,0,0,0,0,0,0,0,0,0,0,0,0,0,0,0,0,0,10,0,0,0,0,10,0
0,0,0,0,0,0,0,0,0,0,0,0,0,0,0,0,0,0,0,0,0,0,0,0,0,0,0,0,0,0,0,0,0,0,0,0,0,0
:endlayer
layer: 2
0,0,0,0,0,0,0,0,0,0,0,0,0,0,0,0,0,0,0,0,0,0,0,0,0,0,0,0,0,0,0,0,0,0,0,0,0,0
0,9,0,0,0,0,0,0,0,0,0,0,0,0,0,0,0,0,0,0,0,0,0,0,0,0,0,0,0,0,0,0,0,0,0,9,0,0
0,0,0,0,0,0,0,0,0,0,0,0,0,0,0,0,0,0,0,0,0,0,0,0,0,0,0,0,0,0,0,0,0,0,0,0,0,0
0,0,0,0,0,0,0,0,0,0,0,0,0,0,0,0,0,0,0,0,0,0,0,0,0,0,0,0,0,0,0,0,0,0,0,0,0,0
0,0,0,0,0,0,0,0,0,0,0,0,0,0,0,0,0,0,0,0,0,11,7,11,7,7,11,0,0,11,7,11,0,0,0,0,0,0
0,0,0,0,0,0,0,0,0,0,0,0,0,0,10,0,0,10,0,0,10,7,0,12,0,0,0,0,0,12,0,7,0,0,0,0,0,0
0,0,0,0,0,0,0,0,0,0,0,0,0,0,0,0,0,0,0,0,0,11,0,0,0,0,0,0,0,0,0,11,7,11,7,11,15,0
0,0,0,0,0,0,0,0,0,0,0,0,0,0,0,0,0,0,0,0,0,7,0,0,0,0,0,0,0,0,0,7,0,0,0,7,0,0
0,0,0,0,0,0,0,0,0,0,0,0,0,0,0,0,0,0,5,5,0,7,0,0,0,0,0,0,0,0,0,7,0,0,0,11,15,0
0,0,0,0,0,0,0,0,0,11,7,11,10,10,11,0,11,5,0,0,5,11,0,0,0,0,0,0,0,0,0,11,0,0,0,10,0,0
0,0,0,0,0,0,0,0,0,7,0,0,0,0,7,0,0,0,0,0,0,7,0,0,0,0,0,0,0,0,0,7,0,0,0,11,15,0
0,0,0,0,0,0,0,0,0,11,0,0,0,0,11,0,0,0,0,0,0,11,0,0,0,0,0,0,0,0,0,11,0,0,0,7,0,0
0,0,0,0,0,0,0,0,0,7,0,0,0,0,7,0,0,0,0,0,0,0,0,0,0,0,0,0,0,0,0,7,0,0,0,11,15,0
0,0,11,7,7,7,11,0,0,7,7,11,0,0,11,0,0,0,0,0,0,0,0,0,0,0,0,0,0,0,0,7,0,0,0,0,0,0
0,0,7,0,0,0,0,0,0,11,0,0,0,0,0,0,0,0,0,0,0,11,0,0,0,0,0,0,0,0,0,11,0,0,0,11,15,0
0,0,7,0,0,0,0,0,0,0,0,0,0,0,0,0,0,0,0,0,0,7,0,0,0,0,0,0,0,0,0,0,0,0,0,7,0,0
0,0,11,0,0,0,11,0,0,11,7,11,0,0,11,7,11,10,10,11,7,11,0,0,0,0,0,0,0,0,0,11,7,11,7,11,15,0
0,0,7,0,0,0,0,0,0,7,0,0,0,0,0,0,0,0,0,0,0,7,0,0,0,0,0,0,0,0,0,7,0,0,0,0,0,0
0,0,7,0,0,0,0,0,0,11,0,0,0,0,0,0,0,0,0,0,0,7,0,0,0,0,0,0,0,0,0,7,0,0,0,0,0,0
0,0,11,0,0,0,11,0,0,0,0,0,0,0,0,0,0,0,0,0,0,11,0,0,0,0,0,0,0,0,0,11,0,0,0,0,0,0
0,0,7,0,0,0,0,0,0,0,0,0,0,0,0,0,0,0,0,0,0,0,0,0,0,0,0,0,0,0,0,0,0,0,0,0,0,0
0,0,7,0,0,0,0,0,0,0,0,0,0,0,0,0,0,0,0,0,0,11,7,11,0,0,0,0,0,11,7,11,0,0,0,0,0,0
0,0,11,0,0,0,11,0,0,11,0,0,0,0,0,0,0,0,0,0,0,0,0,0,0,0,0,0,0,0,0,0,0,0,0,0,0,0
0,0,7,0,0,0,0,0,0,0,0,0,0,0,0,0,0,0,0,0,0,0,0,0,0,0,0,0,0,0,0,0,0,0,0,0,9,0
0,0,7,0,0,0,0,0,0,0,0,0,0,0,0,0,0,0,0,0,0,0,0,0,0,0,0,0,0,0,0,0,0,0,0,0,0,0
0,0,11,0,0,0,11,0,0,0,0,0,0,0,0,0,0,0,0,0,0,0,0,0,0,0,0,0,0,0,0,0,0,0,0,0,0,0
0,0,7,0,0,0,0,0,0,11,0,0,0,0,0,10,0,0,0,10,0,0,0,0,0,0,0,0,0,0,0,0,0,0,0,0,0,0
0,0,7,0,0,0,0,0,0,7,0,0,0,0,0,0,0,0,0,0,0,0,0,0,0,0,0,0,0,0,0,0,0,0,0,0,0,0
0,0,11,7,7,7,11,0,0,11,0,0,0,0,0,0,0,0,0,0,0,0,0,0,0,0,0,0,0,0,0,0,0,0,0,0,0,0
0,0,0,0,0,0,0,0,0,0,0,0,0,0,0,0,0,0,0,0,0,0,0,0,0,0,0,0,0,0,0,9,0,0,0,0,9,0
0,0,0,0,0,0,0,0,0,0,0,0,0,0,0,0,0,0,0,0,0,0,0,0,0,0,0,0,0,0,0,0,0,0,0,0,0,0
:endlayer
layer: 3
0,0,0,0,0,0,0,0,0,0,0,0,0,0,0,0,0,0,0,0,0,0,0,0,0,0,0,0,0,0,0,0,0,0,0,0,0,0
0,0,0,0,0,0,0,0,0,0,0,0,0,0,0,0,0,0,0,0,0,0,0,0,0,0,0,0,0,0,0,0,0,0,0,0,0,0
0,0,0,0,0,0,0,0,0,0,0,0,0,0,0,0,0,0,0,0,0,0,0,0,0,0,0,0,0,0,0,0,0,0,0,0,0,0
0,0,0,0,0,0,0,0,0,0,0,0,0,0,0,0,0,0,0,0,0,16,0,16,0,0,16,0,0,16,0,16,0,0,0,0,0,0
0,0,0,0,0,0,0,0,0,0,0,0,0,17,17,17,17,17,17,17,17,11,7,11,10,10,11,8,8,11,7,11,15,0,0,0,0,0
0,0,0,0,0,0,0,0,0,0,0,0,0,0,10,0,0,10,0,0,10,7,0,12,0,0,18,0,0,12,0,7,0,16,0,16,17,0
0,0,0,0,0,0,0,0,0,0,0,0,0,0,10,0,0,0,0,0,14,11,15,0,0,0,0,0,0,0,14,11,8,11,7,11,17,0
0,0,0,0,0,0,0,0,0,0,0,0,0,0,10,0,0,0,0,0,0,7,0,0,0,0,0,0,0,0,0,10,0,0,0,19,17,0
0,0,0,0,0,0,0,0,0,16,0,16,0,0,10,0,16,0,5,5,0,7,0,0,0,0,0,0,0,0,0,10,0,0,0,19,17,0
0,0,0,0,0,0,0,0,14,11,7,11,10,10,11,7,11,5,20,21,5,11,10,0,0,0,0,0,0,0,10,11,0,0,0,19,17,0
0,0,0,0,0,0,0,0,0,7,0,18,0,0,7,0,18,0,0,0,0,7,0,0,0,0,0,0,0,0,0,7,0,0,0,19,17,0
0,0,0,0,0,0,0,0,14,11,15,0,0,14,11,15,0,0,0,0,14,11,15,0,0,0,0,0,0,0,14,11,0,0,0,19,17,0
0,0,16,0,0,0,16,0,0,7,0,16,0,0,7,0,0,0,0,0,0,22,0,0,0,0,0,0,0,0,0,10,0,0,0,19,17,0
0,14,11,10,10,10,11,7,7,7,7,11,23,24,11,15,0,0,0,0,0,25,0,0,0,0,0,0,0,0,0,10,0,0,0,19,17,0
0,0,10,0,0,0,0,0,0,11,0,18,0,0,18,0,0,0,0,0,14,11,15,0,0,0,0,0,0,0,14,11,0,0,0,19,17,0
0,0,10,0,0,0,0,0,0,7,0,16,0,0,16,0,16,0,0,16,0,7,0,0,0,0,0,0,0,0,0,7,0,0,0,19,17,0
0,14,11,0,0,0,11,15,0,11,7,11,7,7,11,7,11,10,10,11,7,11,15,0,0,0,0,0,0,0,14,11,8,11,7,11,17,0
0,0,10,0,0,0,0,0,0,7,0,18,0,0,18,0,18,0,0,18,0,10,0,0,0,0,0,0,0,0,0,10,0,18,0,18,17,0
0,0,10,0,0,0,0,0,0,11,15,0,0,0,0,0,0,0,0,0,0,10,0,0,0,0,0,0,0,0,0,10,0,0,0,0,0,0
0,14,11,0,0,0,11,15,0,22,0,0,0,0,0,0,0,0,0,0,14,11,15,0,0,0,0,0,0,0,14,11,15,0,0,0,0,0
0,0,10,0,0,0,0,0,0,0,0,0,0,0,0,0,0,0,0,0,0,7,0,16,0,0,0,0,0,16,0,7,0,0,0,0,0,0
0,0,10,0,0,0,0,0,0,25,0,0,0,0,0,0,0,0,0,0,14,11,7,11,0,0,0,0,0,11,7,11,15,0,0,0,0,0
0,14,11,0,0,0,11,15,0,11,15,0,0,0,0,0,0,0,0,0,0,18,0,18,0,0,0,0,0,18,0,18,0,0,0,0,0,0
0,0,10,0,0,0,0,0,0,22,0,0,0,0,0,0,0,0,0,0,0,0,0,0,0,0,0,0,0,0,0,0,0,0,0,0,0,0
0,0,10,0,0,0,0,0,0,0,0,0,0,0,0,0,0,0,0,0,0,0,0,0,0,0,0,0,0,0,0,0,0,0,0,0,0,0
0,14,11,0,0,0,11,15,0,25,0,0,0,0,0,0,0,0,0,0,0,0,0,0,0,0,0,0,0,0,0,0,0,0,0,0,0,0
0,0,10,0,0,0,0,0,0,11,15,0,0,0,0,10,0,0,0,10,0,0,0,0,0,0,0,0,0,0,0,0,0,0,0,0,0,0
0,0,10,0,0,0,0,0,0,7,0,0,0,0,0,0,0,0,0,0,0,0,0,0,0,0,0,0,0,0,0,0,0,0,0,0,0,0
0,14,11,10,10,10,11,7,7,11,15,0,0,0,0,0,0,0,0,0,0,0,0,0,0,0,0,0,0,0,0,0,0,0,0,0,0,0
0,0,18,0,0,0,18,0,0,18,0,0,0,0,0,0,0,0,0,0,0,0,0,0,0,0,0,0,0,0,0,0,0,0,0,0,0,0
0,0,0,0,0,0,0,0,0,0,0,0,0,0,0,0,0,0,0,0,0,0,0,0,0,0,0,0,0,0,0,0,0,0,0,0,0,0
:endlayer
layer: 4
0,0,0,0,0,0,0,0,0,0,0,0,0,0,0,0,0,0,0,0,0,0,0,0,0,0,0,0,0,0,0,0,0,0,0,0,0,0
0,0,0,0,0,0,0,0,0,0,0,0,0,0,0,0,0,0,0,0,0,0,0,0,0,0,0,0,0,0,0,0,0,0,0,0,0,0
0,0,0,0,0,0,0,0,0,0,0,0,0,0,0,0,0,0,0,0,0,0,0,0,0,0,0,0,0,0,0,0,0,0,0,0,0,0
0,0,0,0,0,0,0,0,0,0,0,0,0,0,0,0,0,0,0,0,0,0,0,0,0,0,0,0,0,0,0,0,0,0,0,0,0,0
0,0,0,0,0,0,0,0,0,0,0,0,0,0,0,0,0,0,0,0,0,11,8,11,7,7,11,7,7,11,8,11,0,0,0,0,0,0
0,0,0,0,0,0,0,0,0,0,0,0,0,26,26,26,26,26,26,26,26,19,0,12,0,0,0,0,0,12,0,19,0,0,17,26,0,0
0,0,0,0,0,0,0,0,0,0,0,0,0,17,17,17,17,17,17,17,17,11,0,0,0,0,0,0,0,0,0,11,7,11,7,26,0,0
0,0,0,0,0,0,0,0,0,0,0,0,0,0,10,0,0,0,0,0,0,19,0,0,0,0,0,0,0,0,0,19,0,0,17,26,0,0
0,0,0,0,0,0,0,0,27,27,27,27,27,27,27,27,27,27,5,5,27,19,0,0,0,0,0,0,0,0,0,19,0,0,17,26,0,0
0,0,0,0,0,0,0,0,22,11,8,8,8,8,8,8,8,8,8,8,8,11,7,17,0,0,0,0,0,17,7,11,0,0,17,26,0,0
0,0,0,0,0,0,0,0,0,19,0,0,0,0,19,0,0,0,0,0,0,19,0,0,0,0,0,0,0,0,0,19,0,0,17,26,0,0
0,0,0,0,0,0,0,0,0,19,0,0,0,0,19,0,0,0,0,0,0,11,0,0,0,0,0,0,0,0,0,11,0,0,17,26,0,0
0,28,23,0,0,0,0,0,0,19,0,0,0,0,19,0,0,0,0,0,0,19,0,0,0,0,0,0,0,0,0,19,0,0,17,26,0,0
0,28,11,8,8,8,8,8,8,19,8,8,8,8,11,0,0,0,0,0,0,19,0,0,0,0,0,0,0,0,0,19,0,0,17,26,0,0
0,28,19,0,0,0,19,0,0,19,0,0,0,0,0,0,0,0,0,0,0,11,0,0,0,0,0,0,0,0,0,11,0,0,17,26,0,0
0,28,19,0,0,0,19,0,0,19,0,0,0,0,0,0,0,0,0,0,0,19,0,0,0,0,0,0,0,0,0,19,0,0,17,26,0,0
0,28,19,10,10,10,19,0,0,19,8,8,8,8,8,8,8,8,8,8,8,11,0,0,0,0,0,0,0,0,0,11,7,11,7,26,0,0
0,28,19,0,0,0,19,0,0,19,29,29,29,29,29,29,29,29,29,29,29,19,0,0,0,0,0,0,0,0,0,19,0,0,17,26,0,0
0,28,19,0,0,0,19,0,0,19,30,0,0,0,0,0,0,0,0,0,0,19,0,0,0,0,0,0,0,0,0,19,0,0,0,0,0,0
0,28,19,10,10,10,19,0,0,19,30,0,0,0,0,0,0,0,0,0,0,11,0,0,0,0,0,0,0,0,0,11,0,0,0,0,0,0
0,28,19,0,0,0,19,0,0,19,30,0,0,0,0,0,0,0,0,0,0,19,0,0,0,0,0,0,0,0,0,19,0,0,0,0,0,0
0,28,19,0,0,0,19,0,0,19,30,0,0,0,0,0,0,0,0,0,0,11,8,11,0,0,0,0,0,11,8,11,0,0,0,0,0,0
0,28,19,10,10,10,19,0,0,19,30,0,0,0,0,0,0,0,0,0,0,0,0,0,0,0,0,0,0,0,0,0,0,0,0,0,0,0
0,28,19,0,0,0,19,0,0,19,30,0,0,0,0,0,0,0,0,0,0,0,0,0,0,0,0,0,0,0,0,0,0,0,0,0,0,0
0,28,19,0,0,0,19,0,0,19,30,0,0,0,0,0,0,0,0,0,0,0,0,0,0,0,0,0,0,0,0,0,0,0,0,0,0,0
0,28,19,10,10,10,19,0,0,19,30,0,0,0,0,17,17,17,17,17,0,0,0,0,0,0,0,0,0,0,0,0,0,0,0,0,0,0
0,28,19,0,0,0,19,0,0,19,30,0,0,0,0,10,10,10,10,10,0,0,0,0,0,0,0,0,0,0,0,0,0,0,0,0,0,0
0,28,19,0,0,0,19,0,0,19,30,0,0,0,0,17,17,17,17,17,0,0,0,0,0,0,0,0,0,0,0,0,0,0,0,0,0,0
0,28,11,8,8,8,8,8,8,11,30,0,0,0,0,0,0,0,0,0,0,0,0,0,0,0,0,0,0,0,0,0,0,0,0,0,0,0
0,28,23,0,0,0,0,0,0,24,30,0,0,0,0,0,0,0,0,0,0,0,0,0,0,0,0,0,0,0,0,0,0,0,0,0,0,0
0,0,0,0,0,0,0,0,0,0,0,0,0,0,0,0,0,0,0,0,0,0,0,0,0,0,0,0,0,0,0,0,0,0,0,0,0,0
:endlayer
layer: 5
0,0,0,0,0,0,0,0,0,0,0,0,0,0,0,0,0,0,0,0,0,0,0,0,0,0,0,0,0,0,0,0,0,0,0,0,0,0
0,0,0,0,0,0,0,0,0,0,0,0,0,0,0,0,0,0,0,0,0,0,0,0,0,0,0,0,0,0,0,0,0,0,0,0,0,0
0,0,0,0,0,0,0,0,0,0,0,0,0,0,0,0,0,0,0,0,0,0,0,0,0,0,0,0,0,0,0,0,0,0,0,0,0,0
0,0,0,0,0,0,0,0,0,0,0,0,0,0,0,0,0,0,0,0,0,0,0,0,0,25,17,25,0,0,0,0,0,0,0,0,0,0
0,0,0,0,0,0,0,0,0,0,0,0,0,0,0,0,0,0,0,0,0,11,7,11,8,8,8,8,8,11,7,11,0,0,0,0,0,0
0,0,0,0,0,0,0,0,0,0,0,0,0,0,0,0,0,0,0,0,0,7,17,12,17,7,17,7,17,12,17,7,17,26,0,0,0,0
0,0,0,0,0,0,0,0,0,0,0,0,0,0,0,0,9,0,0,0,0,11,17,7,17,7,17,7,17,7,17,11,7,26,0,0,0,0
0,0,0,0,0,0,0,0,0,0,0,0,0,26,26,26,26,26,26,26,26,7,17,7,17,7,17,7,17,7,17,7,17,26,9,0,0,0
0,0,0,0,0,0,0,0,0,0,0,0,0,17,17,17,17,17,5,5,17,7,17,7,17,7,17,7,17,7,17,7,17,26,0,0,0,0
0,0,0,0,0,0,0,0,27,27,27,27,27,27,27,27,27,27,27,27,27,11,8,8,8,8,8,8,8,8,8,11,17,26,0,0,0,0
0,0,0,0,0,0,0,0,22,11,22,22,22,22,19,22,22,22,22,22,22,7,17,17,17,17,17,17,17,17,17,7,17,26,0,0,0,0
0,0,0,0,0,0,0,0,0,7,0,0,0,0,7,0,0,0,0,0,0,11,0,0,0,0,0,0,0,0,0,11,17,26,0,0,0,0
0,0,28,23,0,0,0,0,24,7,0,0,0,0,7,0,0,0,0,0,0,7,0,0,0,0,0,0,0,0,0,7,17,26,0,0,0,0
0,0,28,11,7,7,7,7,11,7,7,7,7,7,11,0,0,0,0,0,0,7,0,0,0,0,0,0,0,0,0,7,17,26,0,0,0,0
0,0,28,23,0,0,10,0,24,7,0,0,0,0,0,0,0,0,0,0,0,11,0,0,0,0,0,0,0,0,0,11,17,26,0,0,0,0
0,0,28,23,0,0,10,0,24,11,25,25,25,25,25,25,25,25,25,25,25,7,0,0,0,0,0,0,0,0,0,7,17,26,9,0,0,0
0,0,28,23,0,0,11,0,24,30,29,29,29,29,29,29,29,29,29,29,29,11,0,0,0,0,0,0,0,0,0,11,7,26,0,0,0,0
0,0,28,23,0,0,10,0,24,30,0,0,0,0,0,0,0,0,0,0,0,7,0,0,0,0,0,0,0,0,0,7,17,26,0,0,0,0
0,0,28,23,0,0,10,0,24,30,0,0,0,0,0,0,0,0,0,0,0,7,0,0,0,0,0,0,0,0,0,7,0,0,0,0,0,0
0,0,28,23,0,0,11,0,24,30,0,0,0,0,0,0,0,0,0,0,0,11,0,0,0,0,0,0,0,0,0,11,0,0,0,0,0,0
0,0,28,23,0,0,10,0,24,30,0,0,0,0,0,0,0,0,0,0,0,7,0,0,0,0,0,0,0,0,0,7,0,0,0,0,0,0
0,0,28,23,0,0,10,0,24,30,0,0,0,0,0,0,0,0,0,0,0,11,7,11,23,0,0,0,24,11,7,11,0,0,0,0,0,0
0,0,28,23,0,0,11,0,24,30,0,0,0,0,0,0,0,0,0,0,0,0,0,0,0,0,0,0,0,0,0,0,0,0,0,0,0,0
0,0,28,23,0,0,10,0,24,30,0,0,0,0,0,0,0,0,0,0,0,0,0,0,0,0,0,0,0,0,0,0,0,0,0,0,0,0
0,0,28,23,0,0,10,0,24,30,0,0,0,0,0,0,0,0,0,0,0,0,0,0,0,0,0,0,0,0,0,0,0,0,0,0,0,0
0,0,28,23,0,0,11,0,24,30,0,0,0,0,0,0,0,9,0,0,0,0,0,0,0,0,0,0,0,0,0,0,0,0,0,0,0,0
0,0,28,23,0,0,10,0,24,30,0,0,0,0,0,26,26,26,26,26,0,0,0,0,0,0,0,0,0,0,0,0,0,0,0,0,0,0
0,0,28,23,0,0,10,0,24,30,0,0,0,0,0,0,0,9,0,0,0,0,0,0,0,0,0,0,0,0,0,0,0,0,0,0,0,0
0,0,28,11,7,7,7,7,11,30,0,0,0,0,0,0,0,0,0,0,0,0,0,0,0,0,0,0,0,0,0,0,0,0,0,0,0,0
0,0,28,23,0,0,0,0,24,30,0,0,0,0,0,0,0,0,0,0,0,0,0,0,0,0,0,0,0,0,0,0,0,0,0,0,0,0
0,0,0,0,0,0,0,0,0,0,0,0,0,0,0,0,0,0,0,0,0,0,0,0,0,0,0,0,0,0,0,0,0,0,0,0,0,0
:endlayer
layer: 6
0,0,0,0,0,0,0,0,0,0,0,0,0,0,0,0,0,0,0,0,0,0,0,0,0,0,0,0,0,0,0,0,0,0,0,0,0,0
0,0,0,0,0,0,0,0,0,0,0,0,0,0,0,0,0,0,0,0,0,0,0,0,0,0,0,0,0,0,0,0,0,0,0,0,0,0
0,0,0,0,0,0,0,0,0,0,0,0,0,0,0,0,0,0,0,0,0,0,0,0,0,0,0,0,0,0,0,0,0,0,0,0,0,0
0,0,0,0,0,0,0,0,0,0,0,0,0,0,0,0,0,0,0,0,28,23,0,0,0,0,0,0,0,0,0,24,30,0,0,0,0,0
0,0,0,0,0,0,0,0,0,0,0,0,0,0,0,0,0,0,0,0,28,11,8,11,10,0,0,0,10,11,8,11,30,0,0,0,0,0
0,0,0,0,0,0,0,0,0,0,0,0,0,0,0,0,0,0,0,0,28,19,0,12,0,0,0,0,0,12,0,19,30,0,0,0,0,0
0,0,0,0,0,0,0,0,0,0,0,0,0,0,0,0,0,0,0,0,28,19,0,0,0,0,0,0,0,0,0,19,30,0,0,0,0,0
0,0,0,0,0,0,0,0,0,0,0,0,0,0,0,0,0,0,0,0,28,19,0,0,9,0,0,0,9,0,0,19,30,0,0,0,0,0
0,0,0,0,0,0,0,0,0,0,0,0,0,0,0,0,0,0,5,5,28,19,0,0,0,0,0,0,0,0,0,19,30,0,0,0,0,0
0,0,0,0,0,0,0,0,0,0,0,0,0,26,26,26,26,26,26,26,28,19,0,0,0,0,0,0,0,0,0,19,30,0,0,0,0,0
0,0,0,0,0,0,0,0,27,27,27,27,27,27,27,27,27,27,27,27,27,19,0,0,0,0,0,0,0,0,0,19,30,0,0,0,0,0
0,0,0,0,0,0,0,0,22,11,22,22,22,22,19,22,22,22,22,22,22,19,0,0,0,0,0,0,0,0,0,19,30,0,0,0,0,0
0,0,0,28,23,0,0,24,30,7,0,0,0,0,7,0,0,0,0,0,0,19,0,0,0,0,0,0,0,0,0,19,30,0,0,0,0,0
0,0,0,28,11,7,7,11,30,7,7,7,7,7,11,0,0,0,0,0,0,19,0,0,0,0,0,0,0,0,0,19,30,0,0,0,0,0
0,0,0,28,23,0,0,24,7,11,25,25,25,25,25,25,25,25,25,25,25,19,0,0,0,0,0,0,0,0,0,19,30,0,0,0,0,0
0,0,0,28,23,0,0,24,30,29,29,29,29,29,29,29,29,29,29,29,29,19,0,0,0,0,0,0,0,0,0,19,30,0,0,0,0,0
0,0,0,28,23,0,11,24,30,0,0,0,0,0,0,0,0,0,0,0,28,19,0,0,0,0,0,0,0,0,0,19,30,0,0,0,0,0
0,0,0,28,23,0,0,24,30,0,0,0,0,0,0,0,0,0,0,0,28,19,0,0,0,0,0,0,0,0,0,19,30,0,0,0,0,0
0,0,0,28,23,0,0,24,30,0,0,0,0,0,0,0,0,0,0,0,28,19,0,0,0,0,0,0,0,0,0,19,30,0,0,0,0,0
0,0,0,28,23,0,11,24,30,0,0,0,0,0,0,0,0,0,0,0,28,19,0,0,0,0,0,0,0,0,0,19,30,0,0,0,0,0
0,0,0,28,23,0,0,24,30,0,0,0,0,0,0,0,0,0,0,0,28,19,0,0,0,0,0,0,0,0,0,19,30,0,0,0,0,0
0,0,0,28,23,0,0,24,30,0,0,0,0,0,0,0,0,0,0,0,28,11,8,8,8,8,8,8,8,8,8,11,30,0,0,0,0,0
0,0,0,28,23,0,11,24,30,0,0,0,0,0,0,0,0,0,0,0,28,23,0,0,0,0,0,0,0,0,0,24,30,0,0,0,0,0
0,0,0,28,23,0,0,24,30,0,0,0,0,0,0,0,0,0,0,0,0,0,0,0,0,0,0,0,0,0,0,0,0,0,0,0,0,0
0,0,0,28,23,0,0,24,30,0,0,0,0,0,0,0,0,0,0,0,0,0,0,0,0,0,0,0,0,0,0,0,0,0,0,0,0,0
0,0,0,28,23,0,11,24,30,0,0,0,0,0,0,0,0,0,0,0,0,0,0,0,0,0,0,0,0,0,0,0,0,0,0,0,0,0
0,0,0,28,23,0,0,24,30,0,0,0,0,0,0,0,0,0,0,0,0,0,0,0,0,0,0,0,0,0,0,0,0,0,0,0,0,0
0,0,0,28,23,0,0,24,30,0,0,0,0,0,0,0,0,0,0,0,0,0,0,0,0,0,0,0,0,0,0,0,0,0,0,0,0,0
0,0,0,28,11,7,7,11,30,0,0,0,0,0,0,0,0,0,0,0,0,0,0,0,0,0,0,0,0,0,0,0,0,0,0,0,0,0
0,0,0,28,23,0,0,24,30,0,0,0,0,0,0,0,0,0,0,0,0,0,0,0,0,0,0,0,0,0,0,0,0,0,0,0,0,0
0,0,0,0,0,0,0,0,0,0,0,0,0,0,0,0,0,0,0,0,0,0,0,0,0,0,0,0,0,0,0,0,0,0,0,0,0,0
:endlayer
layer: 7
0,0,0,0,0,0,0,0,0,0,0,0,0,0,0,0,0,0,0,0,0,0,0,0,0,0,0,0,0,0,0,0,0,0,0,0,0,0
0,0,0,0,0,0,0,0,0,0,0,0,0,0,0,0,0,0,0,0,0,0,0,0,0,0,0,0,0,0,0,0,0,0,0,0,0,0
0,0,0,0,0,0,0,0,0,0,0,0,0,0,0,0,0,0,0,0,0,0,0,0,0,0,0,0,0,0,0,0,0,0,0,0,0,0
0,0,0,0,0,0,0,0,0,0,0,0,0,0,0,0,0,0,0,0,0,28,23,0,0,0,0,0,0,0,24,30,0,0,0,0,0,0
0,0,0,0,0,0,0,0,0,0,0,0,0,0,0,0,0,0,0,0,0,28,11,11,10,0,0,0,10,11,11,30,0,0,0,0,0,0
0,0,0,0,0,0,0,0,0,0,0,0,0,0,0,0,0,0,0,0,0,28,23,12,0,0,0,0,0,12,24,30,0,0,0,0,0,0
0,0,0,0,0,0,0,0,0,0,0,0,0,0,0,0,0,0,0,0,0,28,23,0,0,0,0,0,0,0,24,30,0,0,0,0,0,0
0,0,0,0,0,0,0,0,0,0,0,0,0,0,0,0,0,0,0,0,0,28,23,0,0,0,0,0,0,0,24,30,0,0,0,0,0,0
0,0,0,0,0,0,0,0,0,0,0,0,0,0,0,0,0,0,31,5,0,28,23,0,0,0,0,0,0,0,24,30,0,0,0,0,0,0
0,0,0,0,0,0,0,0,0,0,0,0,0,0,0,0,0,0,0,0,0,28,23,0,0,0,0,0,0,0,24,30,0,0,0,0,0,0
0,0,0,0,0,0,0,0,0,0,0,0,0,0,0,0,0,0,0,0,0,28,23,0,0,0,0,0,0,0,24,30,0,0,0,0,0,0
0,0,0,0,0,0,0,0,27,27,27,27,27,27,27,27,27,27,27,27,27,27,23,0,0,0,0,0,0,0,24,30,0,0,0,0,0,0
0,0,0,0,28,23,24,30,22,19,22,22,22,22,19,22,22,22,22,22,22,7,23,0,0,0,0,0,0,0,24,30,0,0,0,0,0,0
0,0,0,0,28,8,8,30,25,19,8,8,8,8,11,25,25,25,25,25,25,7,23,0,0,0,0,0,0,0,24,30,0,0,0,0,0,0
0,0,0,0,28,23,19,30,29,29,29,29,29,29,29,29,29,29,29,29,29,28,23,0,0,0,0,0,0,0,24,30,0,0,0,0,0,0
0,0,0,0,28,23,19,30,0,0,0,0,0,0,0,0,0,0,0,0,0,28,23,0,0,0,0,0,0,0,24,30,0,0,0,0,0,0
0,0,0,0,28,23,19,30,0,0,0,0,0,0,0,0,0,0,0,0,0,28,23,0,0,0,0,0,0,0,24,30,0,0,0,0,0,0
0,0,0,0,28,23,19,30,0,0,0,0,0,0,0,0,0,0,0,0,0,28,23,0,0,0,0,0,0,0,24,30,0,0,0,0,0,0
0,0,0,0,28,23,19,30,0,0,0,0,0,0,0,0,0,0,0,0,0,28,23,0,0,0,0,0,0,0,24,30,0,0,0,0,0,0
0,0,0,0,28,23,19,30,0,0,0,0,0,0,0,0,0,0,0,0,0,28,23,0,0,0,0,0,0,0,24,30,0,0,0,0,0,0
0,0,0,0,28,23,19,30,0,0,0,0,0,0,0,0,0,0,0,0,0,28,23,0,0,0,0,0,0,0,24,30,0,0,0,0,0,0
0,0,0,0,28,23,19,30,0,0,0,0,0,0,0,0,0,0,0,0,0,28,11,7,11,7,7,7,11,7,11,30,0,0,0,0,0,0
0,0,0,0,28,23,19,30,0,0,0,0,0,0,0,0,0,0,0,0,0,28,23,0,0,0,0,0,0,0,24,30,0,0,0,0,0,0
0,0,0,0,28,23,19,30,0,0,0,0,0,0,0,0,0,0,0,0,0,0,0,0,0,0,0,0,0,0,0,0,0,0,0,0,0,0
0,0,0,0,28,23,19,30,0,0,0,0,0,0,0,0,0,0,0,0,0,0,0,0,0,0,0,0,0,0,0,0,0,0,0,0,0,0
0,0,0,0,28,23,19,30,0,0,0,0,0,0,0,0,0,0,0,0,0,0,0,0,0,0,0,0,0,0,0,0,0,0,0,0,0,0
0,0,0,0,28,23,19,30,0,0,0,0,0,0,0,0,0,0,0,0,0,0,0,0,0,0,0,0,0,0,0,0,0,0,0,0,0,0
0,0,0,0,28,23,19,30,0,0,0,0,0,0,0,0,0,0,0,0,0,0,0,0,0,0,0,0,0,0,0,0,0,0,0,0,0,0
0,0,0,0,28,8,8,30,0,0,0,0,0,0,0,0,0,0,0,0,0,0,0,0,0,0,0,0,0,0,0,0,0,0,0,0,0,0
0,0,0,0,28,23,24,30,0,0,0,0,0,0,0,0,0,0,0,0,0,0,0,0,0,0,0,0,0,0,0,0,0,0,0,0,0,0
0,0,0,0,0,0,0,0,0,0,0,0,0,0,0,0,0,0,0,0,0,0,0,0,0,0,0,0,0,0,0,0,0,0,0,0,0,0
:endlayer
layer: 8
0,0,0,0,0,0,0,0,0,0,0,0,0,0,0,0,0,0,0,0,0,0,0,0,0,0,0,0,0,0,0,0,0,0,0,0,0,0
0,0,0,0,0,0,0,0,0,0,0,0,0,0,0,0,0,0,0,0,0,0,0,0,0,0,0,0,0,0,0,0,0,0,0,0,0,0
0,0,0,0,0,0,0,0,0,0,0,0,0,0,0,0,0,0,0,0,0,0,0,0,0,0,0,0,0,0,0,0,0,0,0,0,0,0
0,0,0,0,0,0,0,0,0,0,0,0,0,0,0,0,0,0,0,0,0,0,28,23,0,0,0,0,0,24,30,0,0,0,0,0,0,0
0,0,0,0,0,0,0,0,0,0,0,0,0,0,0,0,0,0,0,0,0,0,28,11,7,17,0,17,7,11,30,0,0,0,0,0,0,0
0,0,0,0,0,0,0,0,0,0,0,0,0,0,0,0,0,0,0,0,0,0,28,23,0,0,0,0,0,24,30,0,0,0,0,0,0,0
0,0,0,0,0,0,0,0,0,0,0,0,0,0,0,0,0,0,0,0,0,0,28,23,0,0,0,0,0,24,30,0,0,0,0,0,0,0
0,0,0,0,0,0,0,0,0,0,0,0,0,0,0,0,0,0,0,0,0,0,28,23,0,0,0,0,0,24,30,0,0,0,0,0,0,0
0,0,0,0,0,0,0,0,0,0,0,0,0,0,0,0,0,0,0,5,0,0,28,23,0,0,0,0,0,24,30,0,0,0,0,0,0,0
0,0,0,0,0,0,0,0,0,0,0,0,0,0,0,0,0,0,0,0,0,0,28,23,0,0,0,0,0,24,30,0,0,0,0,0,0,0
0,0,0,0,0,0,0,0,0,0,0,0,0,0,0,0,0,0,0,0,0,0,28,23,0,0,0,0,0,24,30,0,0,0,0,0,0,0
0,0,0,0,0,0,0,0,0,0,0,0,0,0,0,0,0,0,0,0,0,0,28,23,0,0,0,0,0,24,30,0,0,0,0,0,0,0
0,0,0,0,0,28,30,0,27,27,27,27,27,27,27,27,27,27,27,27,27,27,28,23,0,0,0,0,0,24,30,0,0,0,0,0,0,0
0,0,0,0,0,28,30,0,29,29,29,29,29,29,29,29,29,29,29,29,29,29,29,23,0,0,0,0,0,24,30,0,0,0,0,0,0,0
0,0,0,0,0,28,30,0,0,0,0,0,0,0,0,0,0,0,0,0,0,0,28,23,0,0,0,0,0,24,30,0,0,0,0,0,0,0
0,0,0,0,0,28,30,0,0,0,0,0,0,0,0,0,0,0,0,0,0,0,28,23,0,0,0,0,0,24,30,0,0,0,0,0,0,0
0,0,0,0,0,28,30,0,0,0,0,0,0,0,0,0,0,0,0,0,0,0,28,23,0,0,0,0,0,24,30,0,0,0,0,0,0,0
0,0,0,0,0,28,30,0,0,0,0,0,0,0,0,0,0,0,0,0,0,0,28,23,0,0,0,0,0,24,30,0,0,0,0,0,0,0
0,0,0,0,0,28,30,0,0,0,0,0,0,0,0,0,0,0,0,0,0,0,28,23,0,0,0,0,0,24,30,0,0,0,0,0,0,0
0,0,0,0,0,28,30,0,0,0,0,0,0,0,0,0,0,0,0,0,0,0,28,23,0,0,0,0,0,24,30,0,0,0,0,0,0,0
0,0,0,0,0,28,30,0,0,0,0,0,0,0,0,0,0,0,0,0,0,0,28,23,0,0,0,0,0,24,30,0,0,0,0,0,0,0
0,0,0,0,0,28,30,0,0,0,0,0,0,0,0,0,0,0,0,0,0,0,28,11,8,8,8,8,8,11,30,0,0,0,0,0,0,0
0,0,0,0,0,28,30,0,0,0,0,0,0,0,0,0,0,0,0,0,0,0,28,23,0,0,0,0,0,24,30,0,0,0,0,0,0,0
0,0,0,0,0,28,30,0,0,0,0,0,0,0,0,0,0,0,0,0,0,0,0,0,0,0,0,0,0,0,0,0,0,0,0,0,0,0
0,0,0,0,0,28,30,0,0,0,0,0,0,0,0,0,0,0,0,0,0,0,0,0,0,0,0,0,0,0,0,0,0,0,0,0,0,0
0,0,0,0,0,28,30,0,0,0,0,0,0,0,0,0,0,0,0,0,0,0,0,0,0,0,0,0,0,0,0,0,0,0,0,0,0,0
0,0,0,0,0,28,30,0,0,0,0,0,0,0,0,0,0,0,0,0,0,0,0,0,0,0,0,0,0,0,0,0,0,0,0,0,0,0
0,0,0,0,0,28,30,0,0,0,0,0,0,0,0,0,0,0,0,0,0,0,0,0,0,0,0,0,0,0,0,0,0,0,0,0,0,0
0,0,0,0,0,28,30,0,0,0,0,0,0,0,0,0,0,0,0,0,0,0,0,0,0,0,0,0,0,0,0,0,0,0,0,0,0,0
0,0,0,0,0,28,30,0,0,0,0,0,0,0,0,0,0,0,0,0,0,0,0,0,0,0,0,0,0,0,0,0,0,0,0,0,0,0
0,0,0,0,0,0,0,0,0,0,0,0,0,0,0,0,0,0,0,0,0,0,0,0,0,0,0,0,0,0,0,0,0,0,0,0,0,0
:endlayer
layer: 9
0,0,0,0,0,0,0,0,0,0,0,0,0,0,0,0,0,0,0,0,0,0,0,0,0,0,0,0,0,0,0,0,0,0,0,0,0,0
0,0,0,0,0,0,0,0,0,0,0,0,0,0,0,0,0,0,0,0,0,0,0,0,0,0,0,0,0,0,0,0,0,0,0,0,0,0
0,0,0,0,0,0,0,0,0,0,0,0,0,0,0,0,0,0,0,0,0,0,0,0,0,0,0,0,0,0,0,0,0,0,0,0,0,0
0,0,0,0,0,0,0,0,0,0,0,0,0,0,0,0,0,0,0,0,0,0,0,28,23,0,10,0,24,30,0,0,0,0,0,0,0,0
0,0,0,0,0,0,0,0,0,0,0,0,0,0,0,0,0,0,0,0,0,0,0,28,11,8,8,8,11,30,0,0,0,0,0,0,0,0
0,0,0,0,0,0,0,0,0,0,0,0,0,0,0,0,0,0,0,0,0,0,0,27,23,0,0,0,24,27,0,0,0,0,0,0,0,0
0,0,0,0,0,0,0,0,0,0,0,0,0,0,0,0,0,0,0,0,0,0,0,10,0,0,0,0,0,10,0,0,0,0,0,0,0,0
0,0,0,0,0,0,0,0,0,0,0,0,0,0,0,0,0,0,0,0,0,0,0,29,23,0,0,0,24,29,0,0,0,0,0,0,0,0
0,0,0,0,0,0,0,0,0,0,0,0,0,0,0,0,0,0,0,5,0,0,0,28,23,0,0,0,24,30,0,0,0,0,0,0,0,0
0,0,0,0,0,0,0,0,0,0,0,0,0,0,0,0,0,0,0,0,0,0,0,27,23,0,0,0,24,27,0,0,0,0,0,0,0,0
0,0,0,0,0,0,0,0,0,0,0,0,0,0,0,0,0,0,0,0,0,0,0,10,0,0,0,0,0,10,0,0,0,0,0,0,0,0
0,0,0,0,0,0,0,0,0,0,0,0,0,0,0,0,0,0,0,0,0,0,0,29,23,0,0,0,24,29,0,0,0,0,0,0,0,0
0,0,0,0,0,0,0,0,0,0,0,0,0,0,0,0,0,0,0,0,0,0,0,28,23,0,0,0,24,30,0,0,0,0,0,0,0,0
0,0,0,0,0,0,0,0,0,0,0,0,0,0,0,0,0,0,0,0,0,0,0,28,23,0,0,0,24,30,0,0,0,0,0,0,0,0
0,0,0,0,0,0,0,0,0,0,0,0,0,0,0,0,0,0,0,0,0,0,0,27,23,0,0,0,24,27,0,0,0,0,0,0,0,0
0,0,0,0,0,0,0,0,0,0,0,0,0,0,0,0,0,0,0,0,0,0,0,10,0,0,0,0,0,10,0,0,0,0,0,0,0,0
0,0,0,0,0,0,0,0,0,0,0,0,0,0,0,0,0,0,0,0,0,0,0,29,23,0,0,0,24,29,0,0,0,0,0,0,0,0
0,0,0,0,0,0,0,0,0,0,0,0,0,0,0,0,0,0,0,0,0,0,0,28,23,0,0,0,24,30,0,0,0,0,0,0,0,0
0,0,0,0,0,0,0,0,0,0,0,0,0,0,0,0,0,0,0,0,0,0,0,27,23,0,0,0,24,27,0,0,0,0,0,0,0,0
0,0,0,0,0,0,0,0,0,0,0,0,0,0,0,0,0,0,0,0,0,0,0,10,0,0,0,0,0,10,0,0,0,0,0,0,0,0
0,0,0,0,0,0,0,0,0,0,0,0,0,0,0,0,0,0,0,0,0,0,0,29,23,0,0,0,24,29,0,0,0,0,0,0,0,0
0,0,0,0,0,0,0,0,0,0,0,0,0,0,0,0,0,0,0,0,0,0,0,28,11,7,7,7,11,30,0,0,0,0,0,0,0,0
0,0,0,0,0,0,0,0,0,0,0,0,0,0,0,0,0,0,0,0,0,0,0,28,23,0,0,0,24,30,0,0,0,0,0,0,0,0
0,0,0,0,0,0,0,0,0,0,0,0,0,0,0,0,0,0,0,0,0,0,0,0,0,0,0,0,0,0,0,0,0,0,0,0,0,0
0,0,0,0,0,0,0,0,0,0,0,0,0,0,0,0,0,0,0,0,0,0,0,0,0,0,0,0,0,0,0,0,0,0,0,0,0,0
0,0,0,0,0,0,0,0,0,0,0,0,0,0,0,0,0,0,0,0,0,0,0,0,0,0,0,0,0,0,0,0,0,0,0,0,0,0
0,0,0,0,0,0,0,0,0,0,0,0,0,0,0,0,0,0,0,0,0,0,0,0,0,0,0,0,0,0,0,0,0,0,0,0,0,0
0,0,0,0,0,0,0,0,0,0,0,0,0,0,0,0,0,0,0,0,0,0,0,0,0,0,0,0,0,0,0,0,0,0,0,0,0,0
0,0,0,0,0,0,0,0,0,0,0,0,0,0,0,0,0,0,0,0,0,0,0,0,0,0,0,0,0,0,0,0,0,0,0,0,0,0
0,0,0,0,0,0,0,0,0,0,0,0,0,0,0,0,0,0,0,0,0,0,0,0,0,0,0,0,0,0,0,0,0,0,0,0,0,0
0,0,0,0,0,0,0,0,0,0,0,0,0,0,0,0,0,0,0,0,0,0,0,0,0,0,0,0,0,0,0,0,0,0,0,0,0,0
:endlayer
layer: 10
0,0,0,0,0,0,0,0,0,0,0,0,0,0,0,0,0,0,0,0,0,0,0,0,0,0,0,0,0,0,0,0,0,0,0,0,0,0
0,0,0,0,0,0,0,0,0,0,0,0,0,0,0,0,0,0,0,0,0,0,0,0,0,0,10,0,0,0,0,0,0,0,0,0,0,0
0,0,0,0,0,0,0,0,0,0,0,0,0,0,0,0,0,0,0,0,0,0,0,0,0,0,10,0,0,0,0,0,0,0,0,0,0,0
0,0,0,0,0,0,0,0,0,0,0,0,0,0,0,0,0,0,0,0,0,0,0,0,28,23,10,24,30,0,0,0,0,0,0,0,0,0
0,0,0,0,0,0,0,0,0,0,0,0,0,0,0,0,0,0,0,0,0,0,0,0,28,11,7,11,30,0,0,0,0,0,0,0,0,0
0,0,0,0,0,0,0,0,0,0,0,0,0,0,0,0,0,0,0,0,0,0,0,0,28,23,0,24,30,0,0,0,0,0,0,0,0,0
0,0,0,0,0,0,0,0,0,0,0,0,0,0,0,0,0,0,0,0,0,0,0,26,28,23,0,24,30,26,0,0,0,0,0,0,0,0
0,0,0,0,0,0,0,0,0,0,0,0,0,0,0,0,0,0,0,0,0,0,0,0,28,23,0,24,30,0,0,0,0,0,0,0,0,0
0,0,0,0,0,0,0,0,0,0,0,0,0,0,0,0,0,0,0,5,0,0,0,0,28,23,0,24,30,0,0,0,0,0,0,0,0,0
0,0,0,0,0,0,0,0,0,0,0,0,0,0,0,0,0,0,0,0,0,0,0,0,28,23,0,24,30,0,0,0,0,0,0,0,0,0
0,0,0,0,0,0,0,0,0,0,0,0,0,0,0,0,0,0,0,0,0,0,0,26,28,23,0,24,30,26,0,0,0,0,0,0,0,0
0,0,0,0,0,0,0,0,0,0,0,0,0,0,0,0,0,0,0,0,0,0,0,0,28,23,0,24,30,0,0,0,0,0,0,0,0,0
0,0,0,0,0,0,0,0,0,0,0,0,0,0,0,0,0,0,0,0,0,0,0,0,28,23,0,24,30,0,0,0,0,0,0,0,0,0
0,0,0,0,0,0,0,0,0,0,0,0,0,0,0,0,0,0,0,0,0,0,0,0,28,23,0,24,30,0,0,0,0,0,0,0,0,0
0,0,0,0,0,0,0,0,0,0,0,0,0,0,0,0,0,0,0,0,0,0,0,0,28,23,0,24,30,0,0,0,0,0,0,0,0,0
0,0,0,0,0,0,0,0,0,0,0,0,0,0,0,0,0,0,0,0,0,0,0,26,28,23,0,24,30,26,0,0,0,0,0,0,0,0
0,0,0,0,0,0,0,0,0,0,0,0,0,0,0,0,0,0,0,0,0,0,0,0,28,23,0,24,30,0,0,0,0,0,0,0,0,0
0,0,0,0,0,0,0,0,0,0,0,0,0,0,0,0,0,0,0,0,0,0,0,0,28,23,0,24,30,0,0,0,0,0,0,0,0,0
0,0,0,0,0,0,0,0,0,0,0,0,0,0,0,0,0,0,0,0,0,0,0,0,28,23,0,24,30,0,0,0,0,0,0,0,0,0
0,0,0,0,0,0,0,0,0,0,0,0,0,0,0,0,0,0,0,0,0,0,0,26,28,23,0,24,30,26,0,0,0,0,0,0,0,0
0,0,0,0,0,0,0,0,0,0,0,0,0,0,0,0,0,0,0,0,0,0,0,0,28,23,0,24,30,0,0,0,0,0,0,0,0,0
0,0,0,0,0,0,0,0,0,0,0,0,0,0,0,0,0,0,0,0,0,0,0,0,28,11,7,11,30,0,0,0,0,0,0,0,0,0
0,0,0,0,0,0,0,0,0,0,0,0,0,0,0,0,0,0,0,0,0,0,0,0,28,23,0,24,30,0,0,0,0,0,0,0,0,0
0,0,0,0,0,0,0,0,0,0,0,0,0,0,0,0,0,0,0,0,0,0,0,0,0,0,0,0,0,0,0,0,0,0,0,0,0,0
0,0,0,0,0,0,0,0,0,0,0,0,0,0,0,0,0,0,0,0,0,0,0,0,0,0,0,0,0,0,0,0,0,0,0,0,0,0
0,0,0,0,0,0,0,0,0,0,0,0,0,0,0,0,0,0,0,0,0,0,0,0,0,0,0,0,0,0,0,0,0,0,0,0,0,0
0,0,0,0,0,0,0,0,0,0,0,0,0,0,0,0,0,0,0,0,0,0,0,0,0,0,0,0,0,0,0,0,0,0,0,0,0,0
0,0,0,0,0,0,0,0,0,0,0,0,0,0,0,0,0,0,0,0,0,0,0,0,0,0,0,0,0,0,0,0,0,0,0,0,0,0
0,0,0,0,0,0,0,0,0,0,0,0,0,0,0,0,0,0,0,0,0,0,0,0,0,0,0,0,0,0,0,0,0,0,0,0,0,0
0,0,0,0,0,0,0,0,0,0,0,0,0,0,0,0,0,0,0,0,0,0,0,0,0,0,0,0,0,0,0,0,0,0,0,0,0,0
0,0,0,0,0,0,0,0,0,0,0,0,0,0,0,0,0,0,0,0,0,0,0,0,0,0,0,0,0,0,0,0,0,0,0,0,0,0
:endlayer
layer: 11
0,0,0,0,0,0,0,0,0,0,0,0,0,0,0,0,0,0,0,0,0,0,0,0,0,0,0,0,0,0,0,0,0,0,0,0,0,0
0,0,0,0,0,0,0,0,0,0,0,0,0,0,0,0,0,0,0,0,0,0,0,0,0,0,0,0,0,0,0,0,0,0,0,0,0,0
0,0,0,0,0,0,0,0,0,0,0,0,0,0,0,0,0,0,0,0,0,0,0,0,0,0,9,0,0,0,0,0,0,0,0,0,0,0
0,0,0,0,0,0,0,0,0,0,0,0,0,0,0,0,0,0,0,0,0,0,0,0,0,28,25,30,0,0,0,0,0,0,0,0,0,0
0,0,0,0,0,0,0,0,0,0,0,0,0,0,0,0,0,0,0,0,0,0,0,0,0,28,11,30,0,0,0,0,0,0,0,0,0,0
0,0,0,0,0,0,0,0,0,0,0,0,0,0,0,0,0,0,0,0,0,0,0,0,0,28,19,30,0,0,0,0,0,0,0,0,0,0
0,0,0,0,0,0,0,0,0,0,0,0,0,0,0,0,0,0,0,0,0,0,0,0,0,28,19,30,0,0,0,0,0,0,0,0,0,0
0,0,0,0,0,0,0,0,0,0,0,0,0,0,0,0,0,0,0,0,0,0,0,0,0,28,19,30,0,0,0,0,0,0,0,0,0,0
0,0,0,0,0,0,0,0,0,0,0,0,0,0,0,0,0,0,0,5,0,0,0,0,0,28,19,30,0,0,0,0,0,0,0,0,0,0
0,0,0,0,0,0,0,0,0,0,0,0,0,0,0,0,0,0,0,0,0,0,0,0,0,28,19,30,0,0,0,0,0,0,0,0,0,0
0,0,0,0,0,0,0,0,0,0,0,0,0,0,0,0,0,0,0,0,0,0,0,0,0,28,19,30,0,0,0,0,0,0,0,0,0,0
0,0,0,0,0,0,0,0,0,0,0,0,0,0,0,0,0,0,0,0,0,0,0,0,0,28,19,30,0,0,0,0,0,0,0,0,0,0
0,0,0,0,0,0,0,0,0,0,0,0,0,0,0,0,0,0,0,0,0,0,0,0,0,28,19,30,0,0,0,0,0,0,0,0,0,0
0,0,0,0,0,0,0,0,0,0,0,0,0,0,0,0,0,0,0,0,0,0,0,0,0,28,19,30,0,0,0,0,0,0,0,0,0,0
0,0,0,0,0,0,0,0,0,0,0,0,0,0,0,0,0,0,0,0,0,0,0,0,0,28,19,30,0,0,0,0,0,0,0,0,0,0
0,0,0,0,0,0,0,0,0,0,0,0,0,0,0,0,0,0,0,0,0,0,0,0,0,28,19,30,0,0,0,0,0,0,0,0,0,0
0,0,0,0,0,0,0,0,0,0,0,0,0,0,0,0,0,0,0,0,0,0,0,0,0,28,19,30,0,0,0,0,0,0,0,0,0,0
0,0,0,0,0,0,0,0,0,0,0,0,0,0,0,0,0,0,0,0,0,0,0,0,0,28,19,30,0,0,0,0,0,0,0,0,0,0
0,0,0,0,0,0,0,0,0,0,0,0,0,0,0,0,0,0,0,0,0,0,0,0,0,28,19,30,0,0,0,0,0,0,0,0,0,0
0,0,0,0,0,0,0,0,0,0,0,0,0,0,0,0,0,0,0,0,0,0,0,0,0,28,19,30,0,0,0,0,0,0,0,0,0,0
0,0,0,0,0,0,0,0,0,0,0,0,0,0,0,0,0,0,0,0,0,0,0,0,0,28,19,30,0,0,0,0,0,0,0,0,0,0
0,0,0,0,0,0,0,0,0,0,0,0,0,0,0,0,0,0,0,0,0,0,0,0,0,28,11,30,0,0,0,0,0,0,0,0,0,0
0,0,0,0,0,0,0,0,0,0,0,0,0,0,0,0,0,0,0,0,0,0,0,0,0,28,22,30,0,0,0,0,0,0,0,0,0,0
0,0,0,0,0,0,0,0,0,0,0,0,0,0,0,0,0,0,0,0,0,0,0,0,0,0,0,0,0,0,0,0,0,0,0,0,0,0
0,0,0,0,0,0,0,0,0,0,0,0,0,0,0,0,0,0,0,0,0,0,0,0,0,0,0,0,0,0,0,0,0,0,0,0,0,0
0,0,0,0,0,0,0,0,0,0,0,0,0,0,0,0,0,0,0,0,0,0,0,0,0,0,0,0,0,0,0,0,0,0,0,0,0,0
0,0,0,0,0,0,0,0,0,0,0,0,0,0,0,0,0,0,0,0,0,0,0,0,0,0,0,0,0,0,0,0,0,0,0,0,0,0
0,0,0,0,0,0,0,0,0,0,0,0,0,0,0,0,0,0,0,0,0,0,0,0,0,0,0,0,0,0,0,0,0,0,0,0,0,0
0,0,0,0,0,0,0,0,0,0,0,0,0,0,0,0,0,0,0,0,0,0,0,0,0,0,0,0,0,0,0,0,0,0,0,0,0,0
0,0,0,0,0,0,0,0,0,0,0,0,0,0,0,0,0,0,0,0,0,0,0,0,0,0,0,0,0,0,0,0,0,0,0,0,0,0
0,0,0,0,0,0,0,0,0,0,0,0,0,0,0,0,0,0,0,0,0,0,0,0,0,0,0,0,0,0,0,0,0,0,0,0,0,0
:endlayer
layer: 12
0,0,0,0,0,0,0,0,0,0,0,0,0,0,0,0,0,0,0,0,0,0,0,0,0,0,0,0,0,0,0,0,0,0,0,0,0,0
0,0,0,0,0,0,0,0,0,0,0,0,0,0,0,0,0,0,0,0,0,0,0,0,0,0,0,0,0,0,0,0,0,0,0,0,0,0
0,0,0,0,0,0,0,0,0,0,0,0,0,0,0,0,0,0,0,0,0,0,0,0,0,0,0,0,0,0,0,0,0,0,0,0,0,0
0,0,0,0,0,0,0,0,0,0,0,0,0,0,0,0,0,0,0,0,0,0,0,0,0,0,26,0,0,0,0,0,0,0,0,0,0,0
0,0,0,0,0,0,0,0,0,0,0,0,0,0,0,0,0,0,0,0,0,0,0,0,0,0,26,0,0,0,0,0,0,0,0,0,0,0
0,0,0,0,0,0,0,0,0,0,0,0,0,0,0,0,0,0,0,0,0,0,0,0,0,0,26,0,0,0,0,0,0,0,0,0,0,0
0,0,0,0,0,0,0,0,0,0,0,0,0,0,0,0,0,0,0,0,0,0,0,0,0,0,26,0,0,0,0,0,0,0,0,0,0,0
0,0,0,0,0,0,0,0,0,0,0,0,0,0,0,0,0,0,0,0,0,0,0,0,0,0,26,0,0,0,0,0,0,0,0,0,0,0
0,0,0,0,0,0,0,0,0,0,0,0,0,0,0,0,0,0,0,32,0,0,0,0,0,0,26,0,0,0,0,0,0,0,0,0,0,0
0,0,0,0,0,0,0,0,0,0,0,0,0,0,0,0,0,0,0,0,0,0,0,0,0,0,26,0,0,0,0,0,0,0,0,0,0,0
0,0,0,0,0,0,0,0,0,0,0,0,0,0,0,0,0,0,0,0,0,0,0,0,0,0,26,0,0,0,0,0,0,0,0,0,0,0
0,0,0,0,0,0,0,0,0,0,0,0,0,0,0,0,0,0,0,0,0,0,0,0,0,0,26,0,0,0,0,0,0,0,0,0,0,0
0,0,0,0,0,0,0,0,0,0,0,0,0,0,0,0,0,0,0,0,0,0,0,0,0,0,26,0,0,0,0,0,0,0,0,0,0,0
0,0,0,0,0,0,0,0,0,0,0,0,0,0,0,0,0,0,0,0,0,0,0,0,0,0,26,0,0,0,0,0,0,0,0,0,0,0
0,0,0,0,0,0,0,0,0,0,0,0,0,0,0,0,0,0,0,0,0,0,0,0,0,0,26,0,0,0,0,0,0,0,0,0,0,0
0,0,0,0,0,0,0,0,0,0,0,0,0,0,0,0,0,0,0,0,0,0,0,0,0,0,26,0,0,0,0,0,0,0,0,0,0,0
0,0,0,0,0,0,0,0,0,0,0,0,0,0,0,0,0,0,0,0,0,0,0,0,0,0,26,0,0,0,0,0,0,0,0,0,0,0
0,0,0,0,0,0,0,0,0,0,0,0,0,0,0,0,0,0,0,0,0,0,0,0,0,0,26,0,0,0,0,0,0,0,0,0,0,0
0,0,0,0,0,0,0,0,0,0,0,0,0,0,0,0,0,0,0,0,0,0,0,0,0,0,26,0,0,0,0,0,0,0,0,0,0,0
0,0,0,0,0,0,0,0,0,0,0,0,0,0,0,0,0,0,0,0,0,0,0,0,0,0,26,0,0,0,0,0,0,0,0,0,0,0
0,0,0,0,0,0,0,0,0,0,0,0,0,0,0,0,0,0,0,0,0,0,0,0,0,0,26,0,0,0,0,0,0,0,0,0,0,0
0,0,0,0,0,0,0,0,0,0,0,0,0,0,0,0,0,0,0,0,0,0,0,0,0,0,26,0,0,0,0,0,0,0,0,0,0,0
0,0,0,0,0,0,0,0,0,0,0,0,0,0,0,0,0,0,0,0,0,0,0,0,0,0,26,0,0,0,0,0,0,0,0,0,0,0
0,0,0,0,0,0,0,0,0,0,0,0,0,0,0,0,0,0,0,0,0,0,0,0,0,0,0,0,0,0,0,0,0,0,0,0,0,0
0,0,0,0,0,0,0,0,0,0,0,0,0,0,0,0,0,0,0,0,0,0,0,0,0,0,0,0,0,0,0,0,0,0,0,0,0,0
0,0,0,0,0,0,0,0,0,0,0,0,0,0,0,0,0,0,0,0,0,0,0,0,0,0,0,0,0,0,0,0,0,0,0,0,0,0
0,0,0,0,0,0,0,0,0,0,0,0,0,0,0,0,0,0,0,0,0,0,0,0,0,0,0,0,0,0,0,0,0,0,0,0,0,0
0,0,0,0,0,0,0,0,0,0,0,0,0,0,0,0,0,0,0,0,0,0,0,0,0,0,0,0,0,0,0,0,0,0,0,0,0,0
0,0,0,0,0,0,0,0,0,0,0,0,0,0,0,0,0,0,0,0,0,0,0,0,0,0,0,0,0,0,0,0,0,0,0,0,0,0
0,0,0,0,0,0,0,0,0,0,0,0,0,0,0,0,0,0,0,0,0,0,0,0,0,0,0,0,0,0,0,0,0,0,0,0,0,0
0,0,0,0,0,0,0,0,0,0,0,0,0,0,0,0,0,0,0,0,0,0,0,0,0,0,0,0,0,0,0,0,0,0,0,0,0,0
:endlayer
layer: 13
0,0,0,0,0,0,0,0,0,0,0,0,0,0,0,0,0,0,0,0,0,0,0,0,0,0,0,0,0,0,0,0,0,0,0,0,0,0
0,0,0,0,0,0,0,0,0,0,0,0,0,0,0,0,0,0,0,0,0,0,0,0,0,0,0,0,0,0,0,0,0,0,0,0,0,0
0,0,0,0,0,0,0,0,0,0,0,0,0,0,0,0,0,0,0,0,0,0,0,0,0,0,0,0,0,0,0,0,0,0,0,0,0,0
0,0,0,0,0,0,0,0,0,0,0,0,0,0,0,0,0,0,0,0,0,0,0,0,0,0,0,0,0,0,0,0,0,0,0,0,0,0
0,0,0,0,0,0,0,0,0,0,0,0,0,0,0,0,0,0,0,0,0,0,0,0,0,0,0,0,0,0,0,0,0,0,0,0,0,0
0,0,0,0,0,0,0,0,0,0,0,0,0,0,0,0,0,0,0,0,0,0,0,0,0,0,0,0,0,0,0,0,0,0,0,0,0,0
0,0,0,0,0,0,0,0,0,0,0,0,0,0,0,0,0,0,0,0,0,0,0,0,0,0,0,0,0,0,0,0,0,0,0,0,0,0
0,0,0,0,0,0,0,0,0,0,0,0,0,0,0,0,0,0,0,0,0,0,0,0,0,0,0,0,0,0,0,0,0,0,0,0,0,0
0,0,0,0,0,0,0,0,0,0,0,0,0,0,0,0,0,0,0,13,0,0,0,0,0,0,0,0,0,0,0,0,0,0,0,0,0,0
0,0,0,0,0,0,0,0,0,0,0,0,0,0,0,0,0,0,0,0,0,0,0,0,0,0,0,0,0,0,0,0,0,0,0,0,0,0
0,0,0,0,0,0,0,0,0,0,0,0,0,0,0,0,0,0,0,0,0,0,0,0,0,0,0,0,0,0,0,0,0,0,0,0,0,0
0,0,0,0,0,0,0,0,0,0,0,0,0,0,0,0,0,0,0,0,0,0,0,0,0,0,0,0,0,0,0,0,0,0,0,0,0,0
0,0,0,0,0,0,0,0,0,0,0,0,0,0,0,0,0,0,0,0,0,0,0,0,0,0,0,0,0,0,0,0,0,0,0,0,0,0
0,0,0,0,0,0,0,0,0,0,0,0,0,0,0,0,0,0,0,0,0,0,0,0,0,0,0,0,0,0,0,0,0,0,0,0,0,0
0,0,0,0,0,0,0,0,0,0,0,0,0,0,0,0,0,0,0,0,0,0,0,0,0,0,0,0,0,0,0,0,0,0,0,0,0,0
0,0,0,0,0,0,0,0,0,0,0,0,0,0,0,0,0,0,0,0,0,0,0,0,0,0,0,0,0,0,0,0,0,0,0,0,0,0
0,0,0,0,0,0,0,0,0,0,0,0,0,0,0,0,0,0,0,0,0,0,0,0,0,0,0,0,0,0,0,0,0,0,0,0,0,0
0,0,0,0,0,0,0,0,0,0,0,0,0,0,0,0,0,0,0,0,0,0,0,0,0,0,0,0,0,0,0,0,0,0,0,0,0,0
0,0,0,0,0,0,0,0,0,0,0,0,0,0,0,0,0,0,0,0,0,0,0,0,0,0,0,0,0,0,0,0,0,0,0,0,0,0
0,0,0,0,0,0,0,0,0,0,0,0,0,0,0,0,0,0,0,0,0,0,0,0,0,0,0,0,0,0,0,0,0,0,0,0,0,0
0,0,0,0,0,0,0,0,0,0,0,0,0,0,0,0,0,0,0,0,0,0,0,0,0,0,0,0,0,0,0,0,0,0,0,0,0,0
0,0,0,0,0,0,0,0,0,0,0,0,0,0,0,0,0,0,0,0,0,0,0,0,0,0,0,0,0,0,0,0,0,0,0,0,0,0
0,0,0,0,0,0,0,0,0,0,0,0,0,0,0,0,0,0,0,0,0,0,0,0,0,0,0,0,0,0,0,0,0,0,0,0,0,0
0,0,0,0,0,0,0,0,0,0,0,0,0,0,0,0,0,0,0,0,0,0,0,0,0,0,0,0,0,0,0,0,0,0,0,0,0,0
0,0,0,0,0,0,0,0,0,0,0,0,0,0,0,0,0,0,0,0,0,0,0,0,0,0,0,0,0,0,0,0,0,0,0,0,0,0
0,0,0,0,0,0,0,0,0,0,0,0,0,0,0,0,0,0,0,0,0,0,0,0,0,0,0,0,0,0,0,0,0,0,0,0,0,0
0,0,0,0,0,0,0,0,0,0,0,0,0,0,0,0,0,0,0,0,0,0,0,0,0,0,0,0,0,0,0,0,0,0,0,0,0,0
0,0,0,0,0,0,0,0,0,0,0,0,0,0,0,0,0,0,0,0,0,0,0,0,0,0,0,0,0,0,0,0,0,0,0,0,0,0
0,0,0,0,0,0,0,0,0,0,0,0,0,0,0,0,0,0,0,0,0,0,0,0,0,0,0,0,0,0,0,0,0,0,0,0,0,0
0,0,0,0,0,0,0,0,0,0,0,0,0,0,0,0,0,0,0,0,0,0,0,0,0,0,0,0,0,0,0,0,0,0,0,0,0,0
0,0,0,0,0,0,0,0,0,0,0,0,0,0,0,0,0,0,0,0,0,0,0,0,0,0,0,0,0,0,0,0,0,0,0,0,0,0
:endlayer

#### RULES ####
rule:
plugin=vanillaBlocks
number=1
data:
JSON:{blockState:{blockName:"minecraft:grass",properties:{snowy:"false"}}}
:enddata
:endrule

rule:
plugin=vanillaBlocks
number=2
data:
JSON:{blockState:{blockName:"minecraft:dirt",properties:{variant:"coarse_dirt",snowy:"false"}}}
:enddata
:endrule

rule:
plugin=vanillaBlocks
number=3
data:
JSON:{blockState:{blockName:"minecraft:grass_path"}}
:enddata
:endrule

rule:
plugin=vanillaBlocks
number=4
data:
JSON:{blockState:{blockName:"minecraft:stonebrick",properties:{variant:"stonebrick"}}}
:enddata
:endrule

rule:
plugin=vanillaBlocks
number=5
data:
JSON:{blockState:{blockName:"minecraft:cobblestone"}}
:enddata
:endrule

rule:
plugin=vanillaBlocks
number=6
data:
JSON:{blockState:{blockName:"minecraft:gravel"}}
:enddata
:endrule

rule:
plugin=vanillaBlocks
number=7
data:
JSON:{blockState:{blockName:"biomesoplenty:planks_0",properties:{variant:"umbran"}}}
:enddata
:endrule

rule:
plugin=vanillaBlocks
number=8
data:
JSON:{blockState:{blockName:"biomesoplenty:log_0",properties:{variant:"umbran",axis:"x"}}}
:enddata
:endrule

rule:
plugin=vanillaBlocks
number=9
data:
JSON:{blockState:{blockName:"minecraft:torch",properties:{facing:"up"}}}
:enddata
:endrule

rule:
plugin=vanillaBlocks
number=10
data:
JSON:{blockState:{blockName:"biomesoplenty:umbran_fence",properties:{east:"false",south:"false",north:"false",west:"false"}}}
:enddata
:endrule

rule:
plugin=vanillaBlocks
number=11
data:
JSON:{blockState:{blockName:"biomesoplenty:log_0",properties:{variant:"umbran",axis:"y"}}}
:enddata
:endrule

rule:
plugin=vanillaBlocks
number=12
data:
JSON:{blockState:{blockName:"minecraft:ladder",properties:{facing:"south"}}}
:enddata
:endrule

rule:
plugin=vanillaBlocks
number=13
data:
JSON:{blockState:{blockName:"minecraft:stone_slab",properties:{half:"bottom",variant:"cobblestone"}}}
:enddata
:endrule

rule:
plugin=vanillaBlocks
number=14
data:
JSON:{blockState:{blockName:"minecraft:torch",properties:{facing:"west"}}}
:enddata
:endrule

rule:
plugin=vanillaBlocks
number=15
data:
JSON:{blockState:{blockName:"minecraft:torch",properties:{facing:"east"}}}
:enddata
:endrule

rule:
plugin=vanillaBlocks
number=16
data:
JSON:{blockState:{blockName:"minecraft:torch",properties:{facing:"north"}}}
:enddata
:endrule

rule:
plugin=vanillaBlocks
number=17
data:
JSON:{blockState:{blockName:"biomesoplenty:wood_slab_0",properties:{half:"top",variant:"umbran"}}}
:enddata
:endrule

rule:
plugin=vanillaBlocks
number=18
data:
JSON:{blockState:{blockName:"minecraft:torch",properties:{facing:"south"}}}
:enddata
:endrule

rule:
plugin=vanillaBlocks
number=19
data:
JSON:{blockState:{blockName:"biomesoplenty:log_0",properties:{variant:"umbran",axis:"z"}}}
:enddata
:endrule

rule:
plugin=vanillaBlocks
number=20
data:
JSON:{blockState:{blockName:"minecraft:stone_stairs",properties:{half:"top",shape:"straight",facing:"west"}}}
:enddata
:endrule

rule:
plugin=vanillaBlocks
number=21
data:
JSON:{blockState:{blockName:"minecraft:stone_stairs",properties:{half:"top",shape:"straight",facing:"east"}}}
:enddata
:endrule

rule:
plugin=vanillaBlocks
number=22
data:
JSON:{blockState:{blockName:"biomesoplenty:umbran_stairs",properties:{half:"top",shape:"straight",facing:"north"}}}
:enddata
:endrule

rule:
plugin=vanillaBlocks
number=23
data:
JSON:{blockState:{blockName:"biomesoplenty:umbran_stairs",properties:{half:"top",shape:"straight",facing:"west"}}}
:enddata
:endrule

rule:
plugin=vanillaBlocks
number=24
data:
JSON:{blockState:{blockName:"biomesoplenty:umbran_stairs",properties:{half:"top",shape:"straight",facing:"east"}}}
:enddata
:endrule

rule:
plugin=vanillaBlocks
number=25
data:
JSON:{blockState:{blockName:"biomesoplenty:umbran_stairs",properties:{half:"top",shape:"straight",facing:"south"}}}
:enddata
:endrule

rule:
plugin=vanillaBlocks
number=26
data:
JSON:{blockState:{blockName:"biomesoplenty:wood_slab_0",properties:{half:"bottom",variant:"umbran"}}}
:enddata
:endrule

rule:
plugin=vanillaBlocks
number=27
data:
JSON:{blockState:{blockName:"biomesoplenty:umbran_stairs",properties:{half:"bottom",shape:"straight",facing:"south"}}}
:enddata
:endrule

rule:
plugin=vanillaBlocks
number=28
data:
JSON:{blockState:{blockName:"biomesoplenty:umbran_stairs",properties:{half:"bottom",shape:"straight",facing:"east"}}}
:enddata
:endrule

rule:
plugin=vanillaBlocks
number=29
data:
JSON:{blockState:{blockName:"biomesoplenty:umbran_stairs",properties:{half:"bottom",shape:"straight",facing:"north"}}}
:enddata
:endrule

rule:
plugin=vanillaBlocks
number=30
data:
JSON:{blockState:{blockName:"biomesoplenty:umbran_stairs",properties:{half:"bottom",shape:"straight",facing:"west"}}}
:enddata
:endrule

rule:
plugin=vanillaBlocks
number=31
data:
JSON:{blockState:{blockName:"minecraft:stone_stairs",properties:{half:"bottom",shape:"straight",facing:"east"}}}
:enddata
:endrule

rule:
plugin=vanillaBlocks
number=32
data:
JSON:{blockState:{blockName:"minecraft:cobblestone_wall",properties:{east:"false",south:"false",north:"false",variant:"cobblestone",west:"false",up:"false"}}}
:enddata
:endrule

#### ENTITIES ####
