# Ancient Warfare Structure Template File
# Auto-generated structure template file. created on: 6/11/2023 at: 23:10:27
# Lines beginning with # denote comments

header:
version=2.11
name=SB_MarenCol_Farm_1H1R_1_ethereal
mods=biomesoplenty
size=38,14,31
offset=26,1,30
:endheader

#### VALIDATION ####
validation:
type=ground
structureAuthor=TheOddlySeagull
survival=true
worldGenEnabled=false
unique=false
preserveBlocks=false
preventNaturalHostileSpawns=false
selectionWeight=1
clusterValue=1
minDuplicateDistance=1
dimensionWhiteList=true
dimensionList=
biomeGroupList=
biomeWhiteList=true
biomeList=
leveling=0
fill=0
border=0
blockSwap=false
territoryName=
biomeReplacement=minecraft:
minGenerationHeight=0
maxGenerationHeight=255
:endvalidation

#### LAYERS ####
layer: 0
1,1,1,1,1,1,1,1,1,2,1,1,1,1,1,1,3,1,1,1,1,1,1,1,1,1,4,5,5,4,1,1,1,1,1,1,1,1
1,1,1,1,1,1,1,1,3,2,6,1,1,6,1,3,6,6,1,1,1,1,1,1,1,1,4,5,5,4,1,1,1,1,1,1,1,1
1,1,1,6,1,1,1,6,3,6,3,1,3,3,2,2,3,2,2,1,1,1,1,1,1,1,4,5,5,4,1,1,1,1,1,1,1,1
1,6,3,6,6,3,1,1,1,1,2,6,3,3,3,3,2,3,1,1,1,1,1,1,1,1,4,5,5,4,1,1,1,1,1,1,1,1
1,1,1,3,2,1,1,3,1,2,6,1,3,6,3,1,6,1,1,1,1,5,5,5,5,5,5,5,5,5,5,5,1,1,1,1,1,1
1,1,1,1,1,1,1,2,3,3,2,2,1,1,5,5,5,5,5,5,5,5,6,6,2,2,3,3,3,3,2,5,1,1,1,1,1,1
1,1,1,1,1,1,6,2,3,6,3,3,3,1,5,6,2,2,2,3,2,5,2,6,6,2,6,6,3,2,2,5,7,7,7,7,1,1
1,1,1,1,1,1,2,1,1,3,3,2,1,1,5,2,3,2,3,2,6,5,2,2,6,6,6,3,6,3,2,5,6,2,6,7,1,1
1,1,1,1,1,1,3,3,1,1,6,1,1,1,5,3,3,3,5,5,6,5,6,2,2,3,2,6,2,3,6,5,3,6,6,7,1,1
1,1,1,1,2,6,6,6,2,5,5,5,5,5,5,5,5,5,5,5,5,5,3,3,2,2,2,3,3,3,3,5,2,2,6,7,6,1
1,1,1,1,1,3,3,1,1,5,8,8,8,8,7,7,7,7,7,7,7,5,3,6,3,2,2,3,6,6,3,5,6,2,2,7,1,2
1,1,1,1,1,1,5,5,5,5,8,8,8,8,7,7,7,7,7,7,7,5,6,2,3,2,6,2,6,6,6,5,2,3,2,7,3,3
1,1,1,1,1,1,5,5,5,5,8,8,8,8,7,7,7,7,7,7,7,5,6,6,3,6,6,6,3,2,2,5,3,2,2,7,5,3
1,1,5,5,5,5,5,5,5,5,7,7,7,7,7,7,7,7,7,7,7,5,6,3,3,2,3,6,2,6,2,5,2,6,3,7,5,1
1,1,5,3,2,2,5,3,2,5,7,7,7,7,7,7,7,7,7,7,7,5,6,3,3,2,6,2,6,2,3,5,2,3,2,7,5,2
1,1,5,2,3,3,5,3,3,5,7,7,7,7,7,7,7,7,7,7,7,5,3,3,3,3,3,2,3,3,2,5,2,6,2,7,6,1
1,1,5,9,9,9,5,3,2,5,5,5,5,5,5,5,5,5,5,5,5,5,3,3,2,6,6,3,6,6,3,5,7,7,7,7,6,2
1,1,5,3,3,3,5,3,2,5,2,2,1,2,3,1,3,1,1,1,1,5,2,6,6,2,3,3,3,6,6,5,2,1,6,3,6,6
1,1,5,3,3,2,5,2,2,5,1,2,6,3,1,6,1,2,1,1,1,5,6,6,6,6,2,3,2,2,3,5,3,6,1,6,6,2
1,1,5,9,9,9,5,3,3,5,1,2,3,1,1,2,3,1,3,1,3,5,6,2,3,3,3,6,6,2,2,5,3,3,3,1,1,1
1,1,5,2,2,2,5,2,2,5,1,2,1,1,1,1,6,6,6,6,2,5,3,3,3,6,3,3,3,3,3,5,6,1,1,1,1,1
1,1,5,2,3,2,5,2,3,5,6,1,1,1,1,1,2,1,2,2,2,5,5,5,5,5,5,5,5,5,5,5,1,1,1,1,1,1
1,1,5,9,9,9,5,3,2,5,6,3,6,2,1,1,1,1,1,3,1,1,6,4,5,5,5,6,5,4,1,1,1,1,1,1,1,1
1,1,5,2,3,3,5,2,3,5,1,6,2,1,1,1,1,1,1,1,6,3,6,4,5,6,6,5,5,4,1,1,1,1,1,1,1,1
1,1,5,3,3,3,5,2,3,5,3,1,1,1,1,5,5,5,5,5,3,1,1,4,6,6,6,6,6,4,1,1,1,1,1,1,1,1
1,1,5,9,9,9,5,3,3,5,1,2,3,1,1,5,0,0,0,5,1,2,1,4,6,5,5,5,5,4,1,1,1,1,1,1,1,1
1,1,5,2,2,2,5,2,3,5,3,6,1,1,1,5,0,10,0,5,2,6,2,4,6,6,5,5,6,4,1,1,1,1,1,1,1,1
1,1,5,2,3,2,5,2,3,5,6,2,6,1,1,5,0,0,0,5,2,3,6,4,6,6,6,5,5,4,1,1,1,1,1,1,1,1
1,1,5,5,5,5,5,5,5,5,3,2,2,3,6,5,5,5,5,5,6,1,2,4,5,6,5,5,6,4,1,1,1,1,1,1,1,1
1,1,1,1,1,1,4,6,5,4,1,6,6,3,2,1,1,1,3,1,1,6,1,4,5,6,6,5,5,4,1,1,1,1,1,1,1,1
1,1,1,1,1,1,4,5,6,4,1,2,1,3,2,1,1,3,1,3,3,3,1,4,5,6,5,5,5,4,1,1,1,1,1,1,1,1
:endlayer
layer: 1
0,0,0,0,0,0,0,0,0,0,0,0,0,0,0,0,0,0,0,0,0,0,0,0,0,0,0,0,0,0,0,0,0,0,0,0,0,0
0,11,0,0,0,0,0,0,0,0,0,0,0,0,0,0,0,0,0,0,0,0,0,0,0,0,0,0,0,0,0,0,0,0,0,11,0,0
0,0,0,0,0,0,10,0,0,0,0,0,0,0,0,0,0,10,0,0,0,0,0,0,0,0,0,0,0,0,0,0,0,0,0,0,0,0
0,0,0,0,0,0,0,0,0,0,10,0,0,0,0,0,0,0,0,0,0,0,0,0,0,0,0,0,0,0,0,0,0,0,0,0,0,0
0,0,0,0,0,0,0,0,0,0,0,0,0,0,0,0,0,0,0,0,0,12,8,12,8,8,12,0,0,12,8,12,0,0,0,0,0,0
0,0,0,0,0,0,0,0,0,0,0,0,0,0,11,0,0,11,0,0,11,8,0,13,0,0,0,0,0,13,0,8,0,0,0,0,0,0
0,0,0,0,0,0,0,0,0,0,0,0,0,0,0,0,0,0,0,0,0,12,0,0,0,0,0,0,0,0,0,12,8,12,8,12,0,0
0,0,0,10,0,0,0,0,0,0,0,0,0,0,0,0,0,0,0,0,0,8,0,0,0,0,0,0,0,0,0,8,0,0,0,8,0,0
0,0,0,0,0,0,0,0,0,0,0,0,0,0,0,0,0,0,5,5,0,8,0,0,0,0,0,0,0,0,0,8,0,0,0,12,0,0
0,0,0,0,0,0,0,0,0,12,8,12,8,8,12,0,12,5,0,0,5,12,0,0,0,0,0,0,0,0,0,12,0,0,0,8,0,0
0,0,0,0,0,0,0,0,0,8,0,0,0,0,8,0,0,0,14,14,0,8,0,0,0,10,0,0,0,0,0,8,0,0,0,12,0,0
0,0,0,0,0,0,0,0,0,12,0,0,0,0,12,0,0,0,0,0,0,12,0,0,0,0,0,0,0,0,0,12,0,0,0,8,0,0
0,0,0,0,0,0,0,0,0,8,0,0,0,0,8,0,0,0,0,0,0,0,0,0,0,0,0,0,0,0,0,8,0,0,0,12,0,0
0,0,12,8,8,8,12,0,0,8,8,12,0,0,12,0,0,0,0,0,0,0,0,0,0,0,0,0,0,0,0,8,0,0,0,0,0,0
0,0,8,0,0,0,0,0,0,12,0,0,0,0,0,0,0,0,0,0,0,12,0,0,0,0,0,0,0,0,0,12,0,0,0,12,0,0
0,0,8,0,0,0,0,0,0,0,0,0,0,0,0,0,0,0,0,0,0,8,0,0,0,0,0,0,0,0,0,0,0,0,0,8,0,0
0,0,12,11,11,11,12,0,0,12,8,12,0,0,12,8,12,8,8,12,8,12,0,0,0,0,10,0,0,0,0,12,8,12,8,12,0,0
0,0,8,0,0,0,0,0,0,8,0,0,0,0,0,0,0,0,0,0,0,8,0,0,0,0,0,0,0,0,0,8,0,0,0,0,0,0
0,0,8,0,0,0,0,0,0,12,0,0,0,0,0,0,0,0,0,0,0,8,0,0,0,0,0,0,0,0,0,8,0,0,0,0,0,0
0,0,12,11,11,11,12,0,0,0,0,0,0,0,0,0,0,0,0,0,0,12,0,0,0,0,0,0,0,0,0,12,0,0,0,0,0,0
0,0,8,0,0,0,0,0,0,0,0,0,0,0,0,0,0,0,0,0,0,0,0,0,0,0,0,0,0,0,0,0,0,0,0,0,0,0
0,0,8,0,0,0,0,0,0,0,0,0,0,0,0,0,0,0,0,0,0,12,8,12,0,0,0,0,0,12,8,12,0,0,0,0,0,0
0,0,12,11,11,11,12,0,0,12,0,0,0,0,0,0,0,0,0,0,0,0,0,0,0,0,0,0,0,0,0,0,0,0,0,0,0,0
0,0,8,0,0,0,0,0,0,0,0,0,0,0,0,0,0,0,0,0,0,0,0,0,0,0,0,0,0,0,0,0,0,0,0,0,11,0
0,0,8,0,0,0,0,0,0,0,0,0,0,0,0,14,5,5,5,14,0,0,0,0,0,0,0,0,0,0,0,0,0,0,0,0,0,0
0,0,12,11,11,11,12,0,0,0,0,0,0,0,0,5,0,0,0,5,0,0,0,0,0,0,0,0,0,0,0,0,0,0,0,0,0,0
0,0,8,0,0,0,0,0,0,12,0,0,0,0,15,5,0,0,0,5,16,0,0,0,0,0,0,0,0,0,0,0,0,0,0,0,0,0
0,0,8,0,0,0,0,0,0,8,0,0,0,0,0,5,0,0,0,5,0,0,0,0,0,0,0,0,0,0,0,0,0,0,0,0,0,0
0,0,12,8,8,8,12,0,0,12,0,0,0,0,0,14,5,5,5,14,0,0,0,0,0,0,10,0,0,0,0,0,0,0,0,0,0,0
0,0,0,0,0,0,0,0,0,0,0,0,0,0,0,0,0,0,0,0,0,0,0,0,0,0,0,0,0,0,0,11,0,0,0,0,11,0
0,0,0,0,0,0,0,0,0,0,0,0,0,0,0,0,0,0,0,0,0,0,0,0,0,0,0,0,0,0,0,0,0,0,0,0,0,0
:endlayer
layer: 2
0,0,0,0,0,0,0,0,0,0,0,0,0,0,0,0,0,0,0,0,0,0,0,0,0,0,0,0,0,0,0,0,0,0,0,0,0,0
0,10,0,0,0,0,0,0,0,0,0,0,0,0,0,0,0,0,0,0,0,0,0,0,0,0,0,0,0,0,0,0,0,0,0,10,0,0
0,0,0,0,0,0,0,0,0,0,0,0,0,0,0,0,0,0,0,0,0,0,0,0,0,0,0,0,0,0,0,0,0,0,0,0,0,0
0,0,0,0,0,0,0,0,0,0,0,0,0,0,0,0,0,0,0,0,0,0,0,0,0,0,0,0,0,0,0,0,0,0,0,0,0,0
0,0,0,0,0,0,0,0,0,0,0,0,0,0,0,0,0,0,0,0,0,12,8,12,8,8,12,0,0,12,8,12,0,0,0,0,0,0
0,0,0,0,0,0,0,0,0,0,0,0,0,0,11,0,0,11,0,0,11,8,0,13,0,0,0,0,0,13,0,8,0,0,0,0,0,0
0,0,0,0,0,0,0,0,0,0,0,0,0,0,0,0,0,0,0,0,0,12,0,0,0,0,0,0,0,0,0,12,8,12,8,12,16,0
0,0,0,0,0,0,0,0,0,0,0,0,0,0,0,0,0,0,0,0,0,8,0,0,0,0,0,0,0,0,0,8,0,0,0,8,0,0
0,0,0,0,0,0,0,0,0,0,0,0,0,0,0,0,0,0,5,5,0,8,0,0,0,0,0,0,0,0,0,8,0,0,0,12,16,0
0,0,0,0,0,0,0,0,0,12,8,12,11,11,12,0,12,5,0,0,5,12,0,0,0,0,0,0,0,0,0,12,0,0,0,11,0,0
0,0,0,0,0,0,0,0,0,8,0,0,0,0,8,0,0,0,0,0,0,8,0,0,0,0,0,0,0,0,0,8,0,0,0,12,16,0
0,0,0,0,0,0,0,0,0,12,0,0,0,0,12,0,0,0,0,0,0,12,0,0,0,0,0,0,0,0,0,12,0,0,0,8,0,0
0,0,0,0,0,0,0,0,0,8,0,0,0,0,8,0,0,0,0,0,0,0,0,0,0,0,0,0,0,0,0,8,0,0,0,12,16,0
0,0,12,8,8,8,12,0,0,8,8,12,0,0,12,0,0,0,0,0,0,0,0,0,0,0,0,0,0,0,0,8,0,0,0,0,0,0
0,0,8,0,0,0,0,0,0,12,0,0,0,0,0,0,0,0,0,0,0,12,0,0,0,0,0,0,0,0,0,12,0,0,0,12,16,0
0,0,8,0,0,0,0,0,0,0,0,0,0,0,0,0,0,0,0,0,0,8,0,0,0,0,0,0,0,0,0,0,0,0,0,8,0,0
0,0,12,0,0,0,12,0,0,12,8,12,0,0,12,8,12,11,11,12,8,12,0,0,0,0,0,0,0,0,0,12,8,12,8,12,16,0
0,0,8,0,0,0,0,0,0,8,0,0,0,0,0,0,0,0,0,0,0,8,0,0,0,0,0,0,0,0,0,8,0,0,0,0,0,0
0,0,8,0,0,0,0,0,0,12,0,0,0,0,0,0,0,0,0,0,0,8,0,0,0,0,0,0,0,0,0,8,0,0,0,0,0,0
0,0,12,0,0,0,12,0,0,0,0,0,0,0,0,0,0,0,0,0,0,12,0,0,0,0,0,0,0,0,0,12,0,0,0,0,0,0
0,0,8,0,0,0,0,0,0,0,0,0,0,0,0,0,0,0,0,0,0,0,0,0,0,0,0,0,0,0,0,0,0,0,0,0,0,0
0,0,8,0,0,0,0,0,0,0,0,0,0,0,0,0,0,0,0,0,0,12,8,12,0,0,0,0,0,12,8,12,0,0,0,0,0,0
0,0,12,0,0,0,12,0,0,12,0,0,0,0,0,0,0,0,0,0,0,0,0,0,0,0,0,0,0,0,0,0,0,0,0,0,0,0
0,0,8,0,0,0,0,0,0,0,0,0,0,0,0,0,0,0,0,0,0,0,0,0,0,0,0,0,0,0,0,0,0,0,0,0,10,0
0,0,8,0,0,0,0,0,0,0,0,0,0,0,0,0,0,0,0,0,0,0,0,0,0,0,0,0,0,0,0,0,0,0,0,0,0,0
0,0,12,0,0,0,12,0,0,0,0,0,0,0,0,0,0,0,0,0,0,0,0,0,0,0,0,0,0,0,0,0,0,0,0,0,0,0
0,0,8,0,0,0,0,0,0,12,0,0,0,0,0,11,0,0,0,11,0,0,0,0,0,0,0,0,0,0,0,0,0,0,0,0,0,0
0,0,8,0,0,0,0,0,0,8,0,0,0,0,0,0,0,0,0,0,0,0,0,0,0,0,0,0,0,0,0,0,0,0,0,0,0,0
0,0,12,8,8,8,12,0,0,12,0,0,0,0,0,0,0,0,0,0,0,0,0,0,0,0,0,0,0,0,0,0,0,0,0,0,0,0
0,0,0,0,0,0,0,0,0,0,0,0,0,0,0,0,0,0,0,0,0,0,0,0,0,0,0,0,0,0,0,10,0,0,0,0,10,0
0,0,0,0,0,0,0,0,0,0,0,0,0,0,0,0,0,0,0,0,0,0,0,0,0,0,0,0,0,0,0,0,0,0,0,0,0,0
:endlayer
layer: 3
0,0,0,0,0,0,0,0,0,0,0,0,0,0,0,0,0,0,0,0,0,0,0,0,0,0,0,0,0,0,0,0,0,0,0,0,0,0
0,0,0,0,0,0,0,0,0,0,0,0,0,0,0,0,0,0,0,0,0,0,0,0,0,0,0,0,0,0,0,0,0,0,0,0,0,0
0,0,0,0,0,0,0,0,0,0,0,0,0,0,0,0,0,0,0,0,0,0,0,0,0,0,0,0,0,0,0,0,0,0,0,0,0,0
0,0,0,0,0,0,0,0,0,0,0,0,0,0,0,0,0,0,0,0,0,17,0,17,0,0,17,0,0,17,0,17,0,0,0,0,0,0
0,0,0,0,0,0,0,0,0,0,0,0,0,18,18,18,18,18,18,18,18,12,8,12,11,11,12,9,9,12,8,12,16,0,0,0,0,0
0,0,0,0,0,0,0,0,0,0,0,0,0,0,11,0,0,11,0,0,11,8,0,13,0,0,19,0,0,13,0,8,0,17,0,17,18,0
0,0,0,0,0,0,0,0,0,0,0,0,0,0,11,0,0,0,0,0,15,12,16,0,0,0,0,0,0,0,15,12,9,12,8,12,18,0
0,0,0,0,0,0,0,0,0,0,0,0,0,0,11,0,0,0,0,0,0,8,0,0,0,0,0,0,0,0,0,11,0,0,0,20,18,0
0,0,0,0,0,0,0,0,0,17,0,17,0,0,11,0,17,0,5,5,0,8,0,0,0,0,0,0,0,0,0,11,0,0,0,20,18,0
0,0,0,0,0,0,0,0,15,12,8,12,11,11,12,8,12,5,21,22,5,12,11,0,0,0,0,0,0,0,11,12,0,0,0,20,18,0
0,0,0,0,0,0,0,0,0,8,0,19,0,0,8,0,19,0,0,0,0,8,0,0,0,0,0,0,0,0,0,8,0,0,0,20,18,0
0,0,0,0,0,0,0,0,15,12,16,0,0,15,12,16,0,0,0,0,15,12,16,0,0,0,0,0,0,0,15,12,0,0,0,20,18,0
0,0,17,0,0,0,17,0,0,8,0,17,0,0,8,0,0,0,0,0,0,23,0,0,0,0,0,0,0,0,0,11,0,0,0,20,18,0
0,15,12,11,11,11,12,8,8,8,8,12,24,25,12,16,0,0,0,0,0,26,0,0,0,0,0,0,0,0,0,11,0,0,0,20,18,0
0,0,11,0,0,0,0,0,0,12,0,19,0,0,19,0,0,0,0,0,15,12,16,0,0,0,0,0,0,0,15,12,0,0,0,20,18,0
0,0,11,0,0,0,0,0,0,8,0,17,0,0,17,0,17,0,0,17,0,8,0,0,0,0,0,0,0,0,0,8,0,0,0,20,18,0
0,15,12,0,0,0,12,16,0,12,8,12,8,8,12,8,12,11,11,12,8,12,16,0,0,0,0,0,0,0,15,12,9,12,8,12,18,0
0,0,11,0,0,0,0,0,0,8,0,19,0,0,19,0,19,0,0,19,0,11,0,0,0,0,0,0,0,0,0,11,0,19,0,19,18,0
0,0,11,0,0,0,0,0,0,12,16,0,0,0,0,0,0,0,0,0,0,11,0,0,0,0,0,0,0,0,0,11,0,0,0,0,0,0
0,15,12,0,0,0,12,16,0,23,0,0,0,0,0,0,0,0,0,0,15,12,16,0,0,0,0,0,0,0,15,12,16,0,0,0,0,0
0,0,11,0,0,0,0,0,0,0,0,0,0,0,0,0,0,0,0,0,0,8,0,17,0,0,0,0,0,17,0,8,0,0,0,0,0,0
0,0,11,0,0,0,0,0,0,26,0,0,0,0,0,0,0,0,0,0,15,12,8,12,0,0,0,0,0,12,8,12,16,0,0,0,0,0
0,15,12,0,0,0,12,16,0,12,16,0,0,0,0,0,0,0,0,0,0,19,0,19,0,0,0,0,0,19,0,19,0,0,0,0,0,0
0,0,11,0,0,0,0,0,0,23,0,0,0,0,0,0,0,0,0,0,0,0,0,0,0,0,0,0,0,0,0,0,0,0,0,0,0,0
0,0,11,0,0,0,0,0,0,0,0,0,0,0,0,0,0,0,0,0,0,0,0,0,0,0,0,0,0,0,0,0,0,0,0,0,0,0
0,15,12,0,0,0,12,16,0,26,0,0,0,0,0,0,0,0,0,0,0,0,0,0,0,0,0,0,0,0,0,0,0,0,0,0,0,0
0,0,11,0,0,0,0,0,0,12,16,0,0,0,0,11,0,0,0,11,0,0,0,0,0,0,0,0,0,0,0,0,0,0,0,0,0,0
0,0,11,0,0,0,0,0,0,8,0,0,0,0,0,0,0,0,0,0,0,0,0,0,0,0,0,0,0,0,0,0,0,0,0,0,0,0
0,15,12,11,11,11,12,8,8,12,16,0,0,0,0,0,0,0,0,0,0,0,0,0,0,0,0,0,0,0,0,0,0,0,0,0,0,0
0,0,19,0,0,0,19,0,0,19,0,0,0,0,0,0,0,0,0,0,0,0,0,0,0,0,0,0,0,0,0,0,0,0,0,0,0,0
0,0,0,0,0,0,0,0,0,0,0,0,0,0,0,0,0,0,0,0,0,0,0,0,0,0,0,0,0,0,0,0,0,0,0,0,0,0
:endlayer
layer: 4
0,0,0,0,0,0,0,0,0,0,0,0,0,0,0,0,0,0,0,0,0,0,0,0,0,0,0,0,0,0,0,0,0,0,0,0,0,0
0,0,0,0,0,0,0,0,0,0,0,0,0,0,0,0,0,0,0,0,0,0,0,0,0,0,0,0,0,0,0,0,0,0,0,0,0,0
0,0,0,0,0,0,0,0,0,0,0,0,0,0,0,0,0,0,0,0,0,0,0,0,0,0,0,0,0,0,0,0,0,0,0,0,0,0
0,0,0,0,0,0,0,0,0,0,0,0,0,0,0,0,0,0,0,0,0,0,0,0,0,0,0,0,0,0,0,0,0,0,0,0,0,0
0,0,0,0,0,0,0,0,0,0,0,0,0,0,0,0,0,0,0,0,0,12,9,12,8,8,12,8,8,12,9,12,0,0,0,0,0,0
0,0,0,0,0,0,0,0,0,0,0,0,0,27,27,27,27,27,27,27,27,20,0,13,0,0,0,0,0,13,0,20,0,0,18,27,0,0
0,0,0,0,0,0,0,0,0,0,0,0,0,18,18,18,18,18,18,18,18,12,0,0,0,0,0,0,0,0,0,12,8,12,8,27,0,0
0,0,0,0,0,0,0,0,0,0,0,0,0,0,11,0,0,0,0,0,0,20,0,0,0,0,0,0,0,0,0,20,0,0,18,27,0,0
0,0,0,0,0,0,0,0,28,28,28,28,28,28,28,28,28,28,5,5,28,20,0,0,0,0,0,0,0,0,0,20,0,0,18,27,0,0
0,0,0,0,0,0,0,0,23,12,9,9,9,9,9,9,9,9,9,9,9,12,8,18,0,0,0,0,0,18,8,12,0,0,18,27,0,0
0,0,0,0,0,0,0,0,0,20,0,0,0,0,20,0,0,0,0,0,0,20,0,0,0,0,0,0,0,0,0,20,0,0,18,27,0,0
0,0,0,0,0,0,0,0,0,20,0,0,0,0,20,0,0,0,0,0,0,12,0,0,0,0,0,0,0,0,0,12,0,0,18,27,0,0
0,29,24,0,0,0,0,0,0,20,0,0,0,0,20,0,0,0,0,0,0,20,0,0,0,0,0,0,0,0,0,20,0,0,18,27,0,0
0,29,12,9,9,9,9,9,9,20,9,9,9,9,12,0,0,0,0,0,0,20,0,0,0,0,0,0,0,0,0,20,0,0,18,27,0,0
0,29,20,0,0,0,20,0,0,20,0,0,0,0,0,0,0,0,0,0,0,12,0,0,0,0,0,0,0,0,0,12,0,0,18,27,0,0
0,29,20,0,0,0,20,0,0,20,0,0,0,0,0,0,0,0,0,0,0,20,0,0,0,0,0,0,0,0,0,20,0,0,18,27,0,0
0,29,20,11,11,11,20,0,0,20,9,9,9,9,9,9,9,9,9,9,9,12,0,0,0,0,0,0,0,0,0,12,8,12,8,27,0,0
0,29,20,0,0,0,20,0,0,20,30,30,30,30,30,30,30,30,30,30,30,20,0,0,0,0,0,0,0,0,0,20,0,0,18,27,0,0
0,29,20,0,0,0,20,0,0,20,31,0,0,0,0,0,0,0,0,0,0,20,0,0,0,0,0,0,0,0,0,20,0,0,0,0,0,0
0,29,20,11,11,11,20,0,0,20,31,0,0,0,0,0,0,0,0,0,0,12,0,0,0,0,0,0,0,0,0,12,0,0,0,0,0,0
0,29,20,0,0,0,20,0,0,20,31,0,0,0,0,0,0,0,0,0,0,20,0,0,0,0,0,0,0,0,0,20,0,0,0,0,0,0
0,29,20,0,0,0,20,0,0,20,31,0,0,0,0,0,0,0,0,0,0,12,9,12,0,0,0,0,0,12,9,12,0,0,0,0,0,0
0,29,20,11,11,11,20,0,0,20,31,0,0,0,0,0,0,0,0,0,0,0,0,0,0,0,0,0,0,0,0,0,0,0,0,0,0,0
0,29,20,0,0,0,20,0,0,20,31,0,0,0,0,0,0,0,0,0,0,0,0,0,0,0,0,0,0,0,0,0,0,0,0,0,0,0
0,29,20,0,0,0,20,0,0,20,31,0,0,0,0,0,0,0,0,0,0,0,0,0,0,0,0,0,0,0,0,0,0,0,0,0,0,0
0,29,20,11,11,11,20,0,0,20,31,0,0,0,0,18,18,18,18,18,0,0,0,0,0,0,0,0,0,0,0,0,0,0,0,0,0,0
0,29,20,0,0,0,20,0,0,20,31,0,0,0,0,11,11,11,11,11,0,0,0,0,0,0,0,0,0,0,0,0,0,0,0,0,0,0
0,29,20,0,0,0,20,0,0,20,31,0,0,0,0,18,18,18,18,18,0,0,0,0,0,0,0,0,0,0,0,0,0,0,0,0,0,0
0,29,12,9,9,9,9,9,9,12,31,0,0,0,0,0,0,0,0,0,0,0,0,0,0,0,0,0,0,0,0,0,0,0,0,0,0,0
0,29,24,0,0,0,0,0,0,25,31,0,0,0,0,0,0,0,0,0,0,0,0,0,0,0,0,0,0,0,0,0,0,0,0,0,0,0
0,0,0,0,0,0,0,0,0,0,0,0,0,0,0,0,0,0,0,0,0,0,0,0,0,0,0,0,0,0,0,0,0,0,0,0,0,0
:endlayer
layer: 5
0,0,0,0,0,0,0,0,0,0,0,0,0,0,0,0,0,0,0,0,0,0,0,0,0,0,0,0,0,0,0,0,0,0,0,0,0,0
0,0,0,0,0,0,0,0,0,0,0,0,0,0,0,0,0,0,0,0,0,0,0,0,0,0,0,0,0,0,0,0,0,0,0,0,0,0
0,0,0,0,0,0,0,0,0,0,0,0,0,0,0,0,0,0,0,0,0,0,0,0,0,0,0,0,0,0,0,0,0,0,0,0,0,0
0,0,0,0,0,0,0,0,0,0,0,0,0,0,0,0,0,0,0,0,0,0,0,0,0,26,18,26,0,0,0,0,0,0,0,0,0,0
0,0,0,0,0,0,0,0,0,0,0,0,0,0,0,0,0,0,0,0,0,12,8,12,9,9,9,9,9,12,8,12,0,0,0,0,0,0
0,0,0,0,0,0,0,0,0,0,0,0,0,0,0,0,0,0,0,0,0,8,18,13,18,8,18,8,18,13,18,8,18,27,0,0,0,0
0,0,0,0,0,0,0,0,0,0,0,0,0,0,0,0,10,0,0,0,0,12,18,8,18,8,18,8,18,8,18,12,8,27,0,0,0,0
0,0,0,0,0,0,0,0,0,0,0,0,0,27,27,27,27,27,27,27,27,8,18,8,18,8,18,8,18,8,18,8,18,27,10,0,0,0
0,0,0,0,0,0,0,0,0,0,0,0,0,18,18,18,18,18,5,5,18,8,18,8,18,8,18,8,18,8,18,8,18,27,0,0,0,0
0,0,0,0,0,0,0,0,28,28,28,28,28,28,28,28,28,28,28,28,28,12,9,9,9,9,9,9,9,9,9,12,18,27,0,0,0,0
0,0,0,0,0,0,0,0,23,12,23,23,23,23,20,23,23,23,23,23,23,8,18,18,18,18,18,18,18,18,18,8,18,27,0,0,0,0
0,0,0,0,0,0,0,0,0,8,0,0,0,0,8,0,0,0,0,0,0,12,0,0,0,0,0,0,0,0,0,12,18,27,0,0,0,0
0,0,29,24,0,0,0,0,25,8,0,0,0,0,8,0,0,0,0,0,0,8,0,0,0,0,0,0,0,0,0,8,18,27,0,0,0,0
0,0,29,12,8,8,8,8,12,8,8,8,8,8,12,0,0,0,0,0,0,8,0,0,0,0,0,0,0,0,0,8,18,27,0,0,0,0
0,0,29,24,0,0,11,0,25,8,0,0,0,0,0,0,0,0,0,0,0,12,0,0,0,0,0,0,0,0,0,12,18,27,0,0,0,0
0,0,29,24,0,0,11,0,25,12,26,26,26,26,26,26,26,26,26,26,26,8,0,0,0,0,0,0,0,0,0,8,18,27,10,0,0,0
0,0,29,24,0,0,12,0,25,31,30,30,30,30,30,30,30,30,30,30,30,12,0,0,0,0,0,0,0,0,0,12,8,27,0,0,0,0
0,0,29,24,0,0,11,0,25,31,0,0,0,0,0,0,0,0,0,0,0,8,0,0,0,0,0,0,0,0,0,8,18,27,0,0,0,0
0,0,29,24,0,0,11,0,25,31,0,0,0,0,0,0,0,0,0,0,0,8,0,0,0,0,0,0,0,0,0,8,0,0,0,0,0,0
0,0,29,24,0,0,12,0,25,31,0,0,0,0,0,0,0,0,0,0,0,12,0,0,0,0,0,0,0,0,0,12,0,0,0,0,0,0
0,0,29,24,0,0,11,0,25,31,0,0,0,0,0,0,0,0,0,0,0,8,0,0,0,0,0,0,0,0,0,8,0,0,0,0,0,0
0,0,29,24,0,0,11,0,25,31,0,0,0,0,0,0,0,0,0,0,0,12,8,12,24,0,0,0,25,12,8,12,0,0,0,0,0,0
0,0,29,24,0,0,12,0,25,31,0,0,0,0,0,0,0,0,0,0,0,0,0,0,0,0,0,0,0,0,0,0,0,0,0,0,0,0
0,0,29,24,0,0,11,0,25,31,0,0,0,0,0,0,0,0,0,0,0,0,0,0,0,0,0,0,0,0,0,0,0,0,0,0,0,0
0,0,29,24,0,0,11,0,25,31,0,0,0,0,0,0,0,0,0,0,0,0,0,0,0,0,0,0,0,0,0,0,0,0,0,0,0,0
0,0,29,24,0,0,12,0,25,31,0,0,0,0,0,0,0,10,0,0,0,0,0,0,0,0,0,0,0,0,0,0,0,0,0,0,0,0
0,0,29,24,0,0,11,0,25,31,0,0,0,0,0,27,27,27,27,27,0,0,0,0,0,0,0,0,0,0,0,0,0,0,0,0,0,0
0,0,29,24,0,0,11,0,25,31,0,0,0,0,0,0,0,10,0,0,0,0,0,0,0,0,0,0,0,0,0,0,0,0,0,0,0,0
0,0,29,12,8,8,8,8,12,31,0,0,0,0,0,0,0,0,0,0,0,0,0,0,0,0,0,0,0,0,0,0,0,0,0,0,0,0
0,0,29,24,0,0,0,0,25,31,0,0,0,0,0,0,0,0,0,0,0,0,0,0,0,0,0,0,0,0,0,0,0,0,0,0,0,0
0,0,0,0,0,0,0,0,0,0,0,0,0,0,0,0,0,0,0,0,0,0,0,0,0,0,0,0,0,0,0,0,0,0,0,0,0,0
:endlayer
layer: 6
0,0,0,0,0,0,0,0,0,0,0,0,0,0,0,0,0,0,0,0,0,0,0,0,0,0,0,0,0,0,0,0,0,0,0,0,0,0
0,0,0,0,0,0,0,0,0,0,0,0,0,0,0,0,0,0,0,0,0,0,0,0,0,0,0,0,0,0,0,0,0,0,0,0,0,0
0,0,0,0,0,0,0,0,0,0,0,0,0,0,0,0,0,0,0,0,0,0,0,0,0,0,0,0,0,0,0,0,0,0,0,0,0,0
0,0,0,0,0,0,0,0,0,0,0,0,0,0,0,0,0,0,0,0,29,24,0,0,0,0,0,0,0,0,0,25,31,0,0,0,0,0
0,0,0,0,0,0,0,0,0,0,0,0,0,0,0,0,0,0,0,0,29,12,9,12,11,0,0,0,11,12,9,12,31,0,0,0,0,0
0,0,0,0,0,0,0,0,0,0,0,0,0,0,0,0,0,0,0,0,29,20,0,13,0,0,0,0,0,13,0,20,31,0,0,0,0,0
0,0,0,0,0,0,0,0,0,0,0,0,0,0,0,0,0,0,0,0,29,20,0,0,0,0,0,0,0,0,0,20,31,0,0,0,0,0
0,0,0,0,0,0,0,0,0,0,0,0,0,0,0,0,0,0,0,0,29,20,0,0,10,0,0,0,10,0,0,20,31,0,0,0,0,0
0,0,0,0,0,0,0,0,0,0,0,0,0,0,0,0,0,0,5,5,29,20,0,0,0,0,0,0,0,0,0,20,31,0,0,0,0,0
0,0,0,0,0,0,0,0,0,0,0,0,0,27,27,27,27,27,27,27,29,20,0,0,0,0,0,0,0,0,0,20,31,0,0,0,0,0
0,0,0,0,0,0,0,0,28,28,28,28,28,28,28,28,28,28,28,28,28,20,0,0,0,0,0,0,0,0,0,20,31,0,0,0,0,0
0,0,0,0,0,0,0,0,23,12,23,23,23,23,20,23,23,23,23,23,23,20,0,0,0,0,0,0,0,0,0,20,31,0,0,0,0,0
0,0,0,29,24,0,0,25,31,8,0,0,0,0,8,0,0,0,0,0,0,20,0,0,0,0,0,0,0,0,0,20,31,0,0,0,0,0
0,0,0,29,12,8,8,12,31,8,8,8,8,8,12,0,0,0,0,0,0,20,0,0,0,0,0,0,0,0,0,20,31,0,0,0,0,0
0,0,0,29,24,0,0,25,8,12,26,26,26,26,26,26,26,26,26,26,26,20,0,0,0,0,0,0,0,0,0,20,31,0,0,0,0,0
0,0,0,29,24,0,0,25,31,30,30,30,30,30,30,30,30,30,30,30,30,20,0,0,0,0,0,0,0,0,0,20,31,0,0,0,0,0
0,0,0,29,24,0,12,25,31,0,0,0,0,0,0,0,0,0,0,0,29,20,0,0,0,0,0,0,0,0,0,20,31,0,0,0,0,0
0,0,0,29,24,0,0,25,31,0,0,0,0,0,0,0,0,0,0,0,29,20,0,0,0,0,0,0,0,0,0,20,31,0,0,0,0,0
0,0,0,29,24,0,0,25,31,0,0,0,0,0,0,0,0,0,0,0,29,20,0,0,0,0,0,0,0,0,0,20,31,0,0,0,0,0
0,0,0,29,24,0,12,25,31,0,0,0,0,0,0,0,0,0,0,0,29,20,0,0,0,0,0,0,0,0,0,20,31,0,0,0,0,0
0,0,0,29,24,0,0,25,31,0,0,0,0,0,0,0,0,0,0,0,29,20,0,0,0,0,0,0,0,0,0,20,31,0,0,0,0,0
0,0,0,29,24,0,0,25,31,0,0,0,0,0,0,0,0,0,0,0,29,12,9,9,9,9,9,9,9,9,9,12,31,0,0,0,0,0
0,0,0,29,24,0,12,25,31,0,0,0,0,0,0,0,0,0,0,0,29,24,0,0,0,0,0,0,0,0,0,25,31,0,0,0,0,0
0,0,0,29,24,0,0,25,31,0,0,0,0,0,0,0,0,0,0,0,0,0,0,0,0,0,0,0,0,0,0,0,0,0,0,0,0,0
0,0,0,29,24,0,0,25,31,0,0,0,0,0,0,0,0,0,0,0,0,0,0,0,0,0,0,0,0,0,0,0,0,0,0,0,0,0
0,0,0,29,24,0,12,25,31,0,0,0,0,0,0,0,0,0,0,0,0,0,0,0,0,0,0,0,0,0,0,0,0,0,0,0,0,0
0,0,0,29,24,0,0,25,31,0,0,0,0,0,0,0,0,0,0,0,0,0,0,0,0,0,0,0,0,0,0,0,0,0,0,0,0,0
0,0,0,29,24,0,0,25,31,0,0,0,0,0,0,0,0,0,0,0,0,0,0,0,0,0,0,0,0,0,0,0,0,0,0,0,0,0
0,0,0,29,12,8,8,12,31,0,0,0,0,0,0,0,0,0,0,0,0,0,0,0,0,0,0,0,0,0,0,0,0,0,0,0,0,0
0,0,0,29,24,0,0,25,31,0,0,0,0,0,0,0,0,0,0,0,0,0,0,0,0,0,0,0,0,0,0,0,0,0,0,0,0,0
0,0,0,0,0,0,0,0,0,0,0,0,0,0,0,0,0,0,0,0,0,0,0,0,0,0,0,0,0,0,0,0,0,0,0,0,0,0
:endlayer
layer: 7
0,0,0,0,0,0,0,0,0,0,0,0,0,0,0,0,0,0,0,0,0,0,0,0,0,0,0,0,0,0,0,0,0,0,0,0,0,0
0,0,0,0,0,0,0,0,0,0,0,0,0,0,0,0,0,0,0,0,0,0,0,0,0,0,0,0,0,0,0,0,0,0,0,0,0,0
0,0,0,0,0,0,0,0,0,0,0,0,0,0,0,0,0,0,0,0,0,0,0,0,0,0,0,0,0,0,0,0,0,0,0,0,0,0
0,0,0,0,0,0,0,0,0,0,0,0,0,0,0,0,0,0,0,0,0,29,24,0,0,0,0,0,0,0,25,31,0,0,0,0,0,0
0,0,0,0,0,0,0,0,0,0,0,0,0,0,0,0,0,0,0,0,0,29,12,12,11,0,0,0,11,12,12,31,0,0,0,0,0,0
0,0,0,0,0,0,0,0,0,0,0,0,0,0,0,0,0,0,0,0,0,29,24,13,0,0,0,0,0,13,25,31,0,0,0,0,0,0
0,0,0,0,0,0,0,0,0,0,0,0,0,0,0,0,0,0,0,0,0,29,24,0,0,0,0,0,0,0,25,31,0,0,0,0,0,0
0,0,0,0,0,0,0,0,0,0,0,0,0,0,0,0,0,0,0,0,0,29,24,0,0,0,0,0,0,0,25,31,0,0,0,0,0,0
0,0,0,0,0,0,0,0,0,0,0,0,0,0,0,0,0,0,32,7,0,29,24,0,0,0,0,0,0,0,25,31,0,0,0,0,0,0
0,0,0,0,0,0,0,0,0,0,0,0,0,0,0,0,0,0,0,0,0,29,24,0,0,0,0,0,0,0,25,31,0,0,0,0,0,0
0,0,0,0,0,0,0,0,0,0,0,0,0,0,0,0,0,0,0,0,0,29,24,0,0,0,0,0,0,0,25,31,0,0,0,0,0,0
0,0,0,0,0,0,0,0,28,28,28,28,28,28,28,28,28,28,28,28,28,28,24,0,0,0,0,0,0,0,25,31,0,0,0,0,0,0
0,0,0,0,29,24,25,31,23,20,23,23,23,23,20,23,23,23,23,23,23,8,24,0,0,0,0,0,0,0,25,31,0,0,0,0,0,0
0,0,0,0,29,9,9,31,26,20,9,9,9,9,12,26,26,26,26,26,26,8,24,0,0,0,0,0,0,0,25,31,0,0,0,0,0,0
0,0,0,0,29,24,20,31,30,30,30,30,30,30,30,30,30,30,30,30,30,29,24,0,0,0,0,0,0,0,25,31,0,0,0,0,0,0
0,0,0,0,29,24,20,31,0,0,0,0,0,0,0,0,0,0,0,0,0,29,24,0,0,0,0,0,0,0,25,31,0,0,0,0,0,0
0,0,0,0,29,24,20,31,0,0,0,0,0,0,0,0,0,0,0,0,0,29,24,0,0,0,0,0,0,0,25,31,0,0,0,0,0,0
0,0,0,0,29,24,20,31,0,0,0,0,0,0,0,0,0,0,0,0,0,29,24,0,0,0,0,0,0,0,25,31,0,0,0,0,0,0
0,0,0,0,29,24,20,31,0,0,0,0,0,0,0,0,0,0,0,0,0,29,24,0,0,0,0,0,0,0,25,31,0,0,0,0,0,0
0,0,0,0,29,24,20,31,0,0,0,0,0,0,0,0,0,0,0,0,0,29,24,0,0,0,0,0,0,0,25,31,0,0,0,0,0,0
0,0,0,0,29,24,20,31,0,0,0,0,0,0,0,0,0,0,0,0,0,29,24,0,0,0,0,0,0,0,25,31,0,0,0,0,0,0
0,0,0,0,29,24,20,31,0,0,0,0,0,0,0,0,0,0,0,0,0,29,12,8,12,8,8,8,12,8,12,31,0,0,0,0,0,0
0,0,0,0,29,24,20,31,0,0,0,0,0,0,0,0,0,0,0,0,0,29,24,0,0,0,0,0,0,0,25,31,0,0,0,0,0,0
0,0,0,0,29,24,20,31,0,0,0,0,0,0,0,0,0,0,0,0,0,0,0,0,0,0,0,0,0,0,0,0,0,0,0,0,0,0
0,0,0,0,29,24,20,31,0,0,0,0,0,0,0,0,0,0,0,0,0,0,0,0,0,0,0,0,0,0,0,0,0,0,0,0,0,0
0,0,0,0,29,24,20,31,0,0,0,0,0,0,0,0,0,0,0,0,0,0,0,0,0,0,0,0,0,0,0,0,0,0,0,0,0,0
0,0,0,0,29,24,20,31,0,0,0,0,0,0,0,0,0,0,0,0,0,0,0,0,0,0,0,0,0,0,0,0,0,0,0,0,0,0
0,0,0,0,29,24,20,31,0,0,0,0,0,0,0,0,0,0,0,0,0,0,0,0,0,0,0,0,0,0,0,0,0,0,0,0,0,0
0,0,0,0,29,9,9,31,0,0,0,0,0,0,0,0,0,0,0,0,0,0,0,0,0,0,0,0,0,0,0,0,0,0,0,0,0,0
0,0,0,0,29,24,25,31,0,0,0,0,0,0,0,0,0,0,0,0,0,0,0,0,0,0,0,0,0,0,0,0,0,0,0,0,0,0
0,0,0,0,0,0,0,0,0,0,0,0,0,0,0,0,0,0,0,0,0,0,0,0,0,0,0,0,0,0,0,0,0,0,0,0,0,0
:endlayer
layer: 8
0,0,0,0,0,0,0,0,0,0,0,0,0,0,0,0,0,0,0,0,0,0,0,0,0,0,0,0,0,0,0,0,0,0,0,0,0,0
0,0,0,0,0,0,0,0,0,0,0,0,0,0,0,0,0,0,0,0,0,0,0,0,0,0,0,0,0,0,0,0,0,0,0,0,0,0
0,0,0,0,0,0,0,0,0,0,0,0,0,0,0,0,0,0,0,0,0,0,0,0,0,0,0,0,0,0,0,0,0,0,0,0,0,0
0,0,0,0,0,0,0,0,0,0,0,0,0,0,0,0,0,0,0,0,0,0,29,24,0,0,0,0,0,25,31,0,0,0,0,0,0,0
0,0,0,0,0,0,0,0,0,0,0,0,0,0,0,0,0,0,0,0,0,0,29,12,8,18,0,18,8,12,31,0,0,0,0,0,0,0
0,0,0,0,0,0,0,0,0,0,0,0,0,0,0,0,0,0,0,0,0,0,29,24,0,0,0,0,0,25,31,0,0,0,0,0,0,0
0,0,0,0,0,0,0,0,0,0,0,0,0,0,0,0,0,0,0,0,0,0,29,24,0,0,0,0,0,25,31,0,0,0,0,0,0,0
0,0,0,0,0,0,0,0,0,0,0,0,0,0,0,0,0,0,0,0,0,0,29,24,0,0,0,0,0,25,31,0,0,0,0,0,0,0
0,0,0,0,0,0,0,0,0,0,0,0,0,0,0,0,0,0,0,7,0,0,29,24,0,0,0,0,0,25,31,0,0,0,0,0,0,0
0,0,0,0,0,0,0,0,0,0,0,0,0,0,0,0,0,0,0,0,0,0,29,24,0,0,0,0,0,25,31,0,0,0,0,0,0,0
0,0,0,0,0,0,0,0,0,0,0,0,0,0,0,0,0,0,0,0,0,0,29,24,0,0,0,0,0,25,31,0,0,0,0,0,0,0
0,0,0,0,0,0,0,0,0,0,0,0,0,0,0,0,0,0,0,0,0,0,29,24,0,0,0,0,0,25,31,0,0,0,0,0,0,0
0,0,0,0,0,29,31,0,28,28,28,28,28,28,28,28,28,28,28,28,28,28,29,24,0,0,0,0,0,25,31,0,0,0,0,0,0,0
0,0,0,0,0,29,31,0,30,30,30,30,30,30,30,30,30,30,30,30,30,30,30,24,0,0,0,0,0,25,31,0,0,0,0,0,0,0
0,0,0,0,0,29,31,0,0,0,0,0,0,0,0,0,0,0,0,0,0,0,29,24,0,0,0,0,0,25,31,0,0,0,0,0,0,0
0,0,0,0,0,29,31,0,0,0,0,0,0,0,0,0,0,0,0,0,0,0,29,24,0,0,0,0,0,25,31,0,0,0,0,0,0,0
0,0,0,0,0,29,31,0,0,0,0,0,0,0,0,0,0,0,0,0,0,0,29,24,0,0,0,0,0,25,31,0,0,0,0,0,0,0
0,0,0,0,0,29,31,0,0,0,0,0,0,0,0,0,0,0,0,0,0,0,29,24,0,0,0,0,0,25,31,0,0,0,0,0,0,0
0,0,0,0,0,29,31,0,0,0,0,0,0,0,0,0,0,0,0,0,0,0,29,24,0,0,0,0,0,25,31,0,0,0,0,0,0,0
0,0,0,0,0,29,31,0,0,0,0,0,0,0,0,0,0,0,0,0,0,0,29,24,0,0,0,0,0,25,31,0,0,0,0,0,0,0
0,0,0,0,0,29,31,0,0,0,0,0,0,0,0,0,0,0,0,0,0,0,29,24,0,0,0,0,0,25,31,0,0,0,0,0,0,0
0,0,0,0,0,29,31,0,0,0,0,0,0,0,0,0,0,0,0,0,0,0,29,12,9,9,9,9,9,12,31,0,0,0,0,0,0,0
0,0,0,0,0,29,31,0,0,0,0,0,0,0,0,0,0,0,0,0,0,0,29,24,0,0,0,0,0,25,31,0,0,0,0,0,0,0
0,0,0,0,0,29,31,0,0,0,0,0,0,0,0,0,0,0,0,0,0,0,0,0,0,0,0,0,0,0,0,0,0,0,0,0,0,0
0,0,0,0,0,29,31,0,0,0,0,0,0,0,0,0,0,0,0,0,0,0,0,0,0,0,0,0,0,0,0,0,0,0,0,0,0,0
0,0,0,0,0,29,31,0,0,0,0,0,0,0,0,0,0,0,0,0,0,0,0,0,0,0,0,0,0,0,0,0,0,0,0,0,0,0
0,0,0,0,0,29,31,0,0,0,0,0,0,0,0,0,0,0,0,0,0,0,0,0,0,0,0,0,0,0,0,0,0,0,0,0,0,0
0,0,0,0,0,29,31,0,0,0,0,0,0,0,0,0,0,0,0,0,0,0,0,0,0,0,0,0,0,0,0,0,0,0,0,0,0,0
0,0,0,0,0,29,31,0,0,0,0,0,0,0,0,0,0,0,0,0,0,0,0,0,0,0,0,0,0,0,0,0,0,0,0,0,0,0
0,0,0,0,0,29,31,0,0,0,0,0,0,0,0,0,0,0,0,0,0,0,0,0,0,0,0,0,0,0,0,0,0,0,0,0,0,0
0,0,0,0,0,0,0,0,0,0,0,0,0,0,0,0,0,0,0,0,0,0,0,0,0,0,0,0,0,0,0,0,0,0,0,0,0,0
:endlayer
layer: 9
0,0,0,0,0,0,0,0,0,0,0,0,0,0,0,0,0,0,0,0,0,0,0,0,0,0,0,0,0,0,0,0,0,0,0,0,0,0
0,0,0,0,0,0,0,0,0,0,0,0,0,0,0,0,0,0,0,0,0,0,0,0,0,0,0,0,0,0,0,0,0,0,0,0,0,0
0,0,0,0,0,0,0,0,0,0,0,0,0,0,0,0,0,0,0,0,0,0,0,0,0,0,0,0,0,0,0,0,0,0,0,0,0,0
0,0,0,0,0,0,0,0,0,0,0,0,0,0,0,0,0,0,0,0,0,0,0,29,24,0,11,0,25,31,0,0,0,0,0,0,0,0
0,0,0,0,0,0,0,0,0,0,0,0,0,0,0,0,0,0,0,0,0,0,0,29,12,9,9,9,12,31,0,0,0,0,0,0,0,0
0,0,0,0,0,0,0,0,0,0,0,0,0,0,0,0,0,0,0,0,0,0,0,28,24,0,0,0,25,28,0,0,0,0,0,0,0,0
0,0,0,0,0,0,0,0,0,0,0,0,0,0,0,0,0,0,0,0,0,0,0,11,0,0,0,0,0,11,0,0,0,0,0,0,0,0
0,0,0,0,0,0,0,0,0,0,0,0,0,0,0,0,0,0,0,0,0,0,0,30,24,0,0,0,25,30,0,0,0,0,0,0,0,0
0,0,0,0,0,0,0,0,0,0,0,0,0,0,0,0,0,0,0,7,0,0,0,29,24,0,0,0,25,31,0,0,0,0,0,0,0,0
0,0,0,0,0,0,0,0,0,0,0,0,0,0,0,0,0,0,0,0,0,0,0,28,24,0,0,0,25,28,0,0,0,0,0,0,0,0
0,0,0,0,0,0,0,0,0,0,0,0,0,0,0,0,0,0,0,0,0,0,0,11,0,0,0,0,0,11,0,0,0,0,0,0,0,0
0,0,0,0,0,0,0,0,0,0,0,0,0,0,0,0,0,0,0,0,0,0,0,30,24,0,0,0,25,30,0,0,0,0,0,0,0,0
0,0,0,0,0,0,0,0,0,0,0,0,0,0,0,0,0,0,0,0,0,0,0,29,24,0,0,0,25,31,0,0,0,0,0,0,0,0
0,0,0,0,0,0,0,0,0,0,0,0,0,0,0,0,0,0,0,0,0,0,0,29,24,0,0,0,25,31,0,0,0,0,0,0,0,0
0,0,0,0,0,0,0,0,0,0,0,0,0,0,0,0,0,0,0,0,0,0,0,28,24,0,0,0,25,28,0,0,0,0,0,0,0,0
0,0,0,0,0,0,0,0,0,0,0,0,0,0,0,0,0,0,0,0,0,0,0,11,0,0,0,0,0,11,0,0,0,0,0,0,0,0
0,0,0,0,0,0,0,0,0,0,0,0,0,0,0,0,0,0,0,0,0,0,0,30,24,0,0,0,25,30,0,0,0,0,0,0,0,0
0,0,0,0,0,0,0,0,0,0,0,0,0,0,0,0,0,0,0,0,0,0,0,29,24,0,0,0,25,31,0,0,0,0,0,0,0,0
0,0,0,0,0,0,0,0,0,0,0,0,0,0,0,0,0,0,0,0,0,0,0,28,24,0,0,0,25,28,0,0,0,0,0,0,0,0
0,0,0,0,0,0,0,0,0,0,0,0,0,0,0,0,0,0,0,0,0,0,0,11,0,0,0,0,0,11,0,0,0,0,0,0,0,0
0,0,0,0,0,0,0,0,0,0,0,0,0,0,0,0,0,0,0,0,0,0,0,30,24,0,0,0,25,30,0,0,0,0,0,0,0,0
0,0,0,0,0,0,0,0,0,0,0,0,0,0,0,0,0,0,0,0,0,0,0,29,12,8,8,8,12,31,0,0,0,0,0,0,0,0
0,0,0,0,0,0,0,0,0,0,0,0,0,0,0,0,0,0,0,0,0,0,0,29,24,0,0,0,25,31,0,0,0,0,0,0,0,0
0,0,0,0,0,0,0,0,0,0,0,0,0,0,0,0,0,0,0,0,0,0,0,0,0,0,0,0,0,0,0,0,0,0,0,0,0,0
0,0,0,0,0,0,0,0,0,0,0,0,0,0,0,0,0,0,0,0,0,0,0,0,0,0,0,0,0,0,0,0,0,0,0,0,0,0
0,0,0,0,0,0,0,0,0,0,0,0,0,0,0,0,0,0,0,0,0,0,0,0,0,0,0,0,0,0,0,0,0,0,0,0,0,0
0,0,0,0,0,0,0,0,0,0,0,0,0,0,0,0,0,0,0,0,0,0,0,0,0,0,0,0,0,0,0,0,0,0,0,0,0,0
0,0,0,0,0,0,0,0,0,0,0,0,0,0,0,0,0,0,0,0,0,0,0,0,0,0,0,0,0,0,0,0,0,0,0,0,0,0
0,0,0,0,0,0,0,0,0,0,0,0,0,0,0,0,0,0,0,0,0,0,0,0,0,0,0,0,0,0,0,0,0,0,0,0,0,0
0,0,0,0,0,0,0,0,0,0,0,0,0,0,0,0,0,0,0,0,0,0,0,0,0,0,0,0,0,0,0,0,0,0,0,0,0,0
0,0,0,0,0,0,0,0,0,0,0,0,0,0,0,0,0,0,0,0,0,0,0,0,0,0,0,0,0,0,0,0,0,0,0,0,0,0
:endlayer
layer: 10
0,0,0,0,0,0,0,0,0,0,0,0,0,0,0,0,0,0,0,0,0,0,0,0,0,0,0,0,0,0,0,0,0,0,0,0,0,0
0,0,0,0,0,0,0,0,0,0,0,0,0,0,0,0,0,0,0,0,0,0,0,0,0,0,11,0,0,0,0,0,0,0,0,0,0,0
0,0,0,0,0,0,0,0,0,0,0,0,0,0,0,0,0,0,0,0,0,0,0,0,0,0,11,0,0,0,0,0,0,0,0,0,0,0
0,0,0,0,0,0,0,0,0,0,0,0,0,0,0,0,0,0,0,0,0,0,0,0,29,24,11,25,31,0,0,0,0,0,0,0,0,0
0,0,0,0,0,0,0,0,0,0,0,0,0,0,0,0,0,0,0,0,0,0,0,0,29,12,8,12,31,0,0,0,0,0,0,0,0,0
0,0,0,0,0,0,0,0,0,0,0,0,0,0,0,0,0,0,0,0,0,0,0,0,29,24,0,25,31,0,0,0,0,0,0,0,0,0
0,0,0,0,0,0,0,0,0,0,0,0,0,0,0,0,0,0,0,0,0,0,0,27,29,24,0,25,31,27,0,0,0,0,0,0,0,0
0,0,0,0,0,0,0,0,0,0,0,0,0,0,0,0,0,0,0,0,0,0,0,0,29,24,0,25,31,0,0,0,0,0,0,0,0,0
0,0,0,0,0,0,0,0,0,0,0,0,0,0,0,0,0,0,0,7,0,0,0,0,29,24,0,25,31,0,0,0,0,0,0,0,0,0
0,0,0,0,0,0,0,0,0,0,0,0,0,0,0,0,0,0,0,0,0,0,0,0,29,24,0,25,31,0,0,0,0,0,0,0,0,0
0,0,0,0,0,0,0,0,0,0,0,0,0,0,0,0,0,0,0,0,0,0,0,27,29,24,0,25,31,27,0,0,0,0,0,0,0,0
0,0,0,0,0,0,0,0,0,0,0,0,0,0,0,0,0,0,0,0,0,0,0,0,29,24,0,25,31,0,0,0,0,0,0,0,0,0
0,0,0,0,0,0,0,0,0,0,0,0,0,0,0,0,0,0,0,0,0,0,0,0,29,24,0,25,31,0,0,0,0,0,0,0,0,0
0,0,0,0,0,0,0,0,0,0,0,0,0,0,0,0,0,0,0,0,0,0,0,0,29,24,0,25,31,0,0,0,0,0,0,0,0,0
0,0,0,0,0,0,0,0,0,0,0,0,0,0,0,0,0,0,0,0,0,0,0,0,29,24,0,25,31,0,0,0,0,0,0,0,0,0
0,0,0,0,0,0,0,0,0,0,0,0,0,0,0,0,0,0,0,0,0,0,0,27,29,24,0,25,31,27,0,0,0,0,0,0,0,0
0,0,0,0,0,0,0,0,0,0,0,0,0,0,0,0,0,0,0,0,0,0,0,0,29,24,0,25,31,0,0,0,0,0,0,0,0,0
0,0,0,0,0,0,0,0,0,0,0,0,0,0,0,0,0,0,0,0,0,0,0,0,29,24,0,25,31,0,0,0,0,0,0,0,0,0
0,0,0,0,0,0,0,0,0,0,0,0,0,0,0,0,0,0,0,0,0,0,0,0,29,24,0,25,31,0,0,0,0,0,0,0,0,0
0,0,0,0,0,0,0,0,0,0,0,0,0,0,0,0,0,0,0,0,0,0,0,27,29,24,0,25,31,27,0,0,0,0,0,0,0,0
0,0,0,0,0,0,0,0,0,0,0,0,0,0,0,0,0,0,0,0,0,0,0,0,29,24,0,25,31,0,0,0,0,0,0,0,0,0
0,0,0,0,0,0,0,0,0,0,0,0,0,0,0,0,0,0,0,0,0,0,0,0,29,12,8,12,31,0,0,0,0,0,0,0,0,0
0,0,0,0,0,0,0,0,0,0,0,0,0,0,0,0,0,0,0,0,0,0,0,0,29,24,0,25,31,0,0,0,0,0,0,0,0,0
0,0,0,0,0,0,0,0,0,0,0,0,0,0,0,0,0,0,0,0,0,0,0,0,0,0,0,0,0,0,0,0,0,0,0,0,0,0
0,0,0,0,0,0,0,0,0,0,0,0,0,0,0,0,0,0,0,0,0,0,0,0,0,0,0,0,0,0,0,0,0,0,0,0,0,0
0,0,0,0,0,0,0,0,0,0,0,0,0,0,0,0,0,0,0,0,0,0,0,0,0,0,0,0,0,0,0,0,0,0,0,0,0,0
0,0,0,0,0,0,0,0,0,0,0,0,0,0,0,0,0,0,0,0,0,0,0,0,0,0,0,0,0,0,0,0,0,0,0,0,0,0
0,0,0,0,0,0,0,0,0,0,0,0,0,0,0,0,0,0,0,0,0,0,0,0,0,0,0,0,0,0,0,0,0,0,0,0,0,0
0,0,0,0,0,0,0,0,0,0,0,0,0,0,0,0,0,0,0,0,0,0,0,0,0,0,0,0,0,0,0,0,0,0,0,0,0,0
0,0,0,0,0,0,0,0,0,0,0,0,0,0,0,0,0,0,0,0,0,0,0,0,0,0,0,0,0,0,0,0,0,0,0,0,0,0
0,0,0,0,0,0,0,0,0,0,0,0,0,0,0,0,0,0,0,0,0,0,0,0,0,0,0,0,0,0,0,0,0,0,0,0,0,0
:endlayer
layer: 11
0,0,0,0,0,0,0,0,0,0,0,0,0,0,0,0,0,0,0,0,0,0,0,0,0,0,0,0,0,0,0,0,0,0,0,0,0,0
0,0,0,0,0,0,0,0,0,0,0,0,0,0,0,0,0,0,0,0,0,0,0,0,0,0,0,0,0,0,0,0,0,0,0,0,0,0
0,0,0,0,0,0,0,0,0,0,0,0,0,0,0,0,0,0,0,0,0,0,0,0,0,0,10,0,0,0,0,0,0,0,0,0,0,0
0,0,0,0,0,0,0,0,0,0,0,0,0,0,0,0,0,0,0,0,0,0,0,0,0,29,26,31,0,0,0,0,0,0,0,0,0,0
0,0,0,0,0,0,0,0,0,0,0,0,0,0,0,0,0,0,0,0,0,0,0,0,0,29,12,31,0,0,0,0,0,0,0,0,0,0
0,0,0,0,0,0,0,0,0,0,0,0,0,0,0,0,0,0,0,0,0,0,0,0,0,29,20,31,0,0,0,0,0,0,0,0,0,0
0,0,0,0,0,0,0,0,0,0,0,0,0,0,0,0,0,0,0,0,0,0,0,0,0,29,20,31,0,0,0,0,0,0,0,0,0,0
0,0,0,0,0,0,0,0,0,0,0,0,0,0,0,0,0,0,0,0,0,0,0,0,0,29,20,31,0,0,0,0,0,0,0,0,0,0
0,0,0,0,0,0,0,0,0,0,0,0,0,0,0,0,0,0,0,7,0,0,0,0,0,29,20,31,0,0,0,0,0,0,0,0,0,0
0,0,0,0,0,0,0,0,0,0,0,0,0,0,0,0,0,0,0,0,0,0,0,0,0,29,20,31,0,0,0,0,0,0,0,0,0,0
0,0,0,0,0,0,0,0,0,0,0,0,0,0,0,0,0,0,0,0,0,0,0,0,0,29,20,31,0,0,0,0,0,0,0,0,0,0
0,0,0,0,0,0,0,0,0,0,0,0,0,0,0,0,0,0,0,0,0,0,0,0,0,29,20,31,0,0,0,0,0,0,0,0,0,0
0,0,0,0,0,0,0,0,0,0,0,0,0,0,0,0,0,0,0,0,0,0,0,0,0,29,20,31,0,0,0,0,0,0,0,0,0,0
0,0,0,0,0,0,0,0,0,0,0,0,0,0,0,0,0,0,0,0,0,0,0,0,0,29,20,31,0,0,0,0,0,0,0,0,0,0
0,0,0,0,0,0,0,0,0,0,0,0,0,0,0,0,0,0,0,0,0,0,0,0,0,29,20,31,0,0,0,0,0,0,0,0,0,0
0,0,0,0,0,0,0,0,0,0,0,0,0,0,0,0,0,0,0,0,0,0,0,0,0,29,20,31,0,0,0,0,0,0,0,0,0,0
0,0,0,0,0,0,0,0,0,0,0,0,0,0,0,0,0,0,0,0,0,0,0,0,0,29,20,31,0,0,0,0,0,0,0,0,0,0
0,0,0,0,0,0,0,0,0,0,0,0,0,0,0,0,0,0,0,0,0,0,0,0,0,29,20,31,0,0,0,0,0,0,0,0,0,0
0,0,0,0,0,0,0,0,0,0,0,0,0,0,0,0,0,0,0,0,0,0,0,0,0,29,20,31,0,0,0,0,0,0,0,0,0,0
0,0,0,0,0,0,0,0,0,0,0,0,0,0,0,0,0,0,0,0,0,0,0,0,0,29,20,31,0,0,0,0,0,0,0,0,0,0
0,0,0,0,0,0,0,0,0,0,0,0,0,0,0,0,0,0,0,0,0,0,0,0,0,29,20,31,0,0,0,0,0,0,0,0,0,0
0,0,0,0,0,0,0,0,0,0,0,0,0,0,0,0,0,0,0,0,0,0,0,0,0,29,12,31,0,0,0,0,0,0,0,0,0,0
0,0,0,0,0,0,0,0,0,0,0,0,0,0,0,0,0,0,0,0,0,0,0,0,0,29,23,31,0,0,0,0,0,0,0,0,0,0
0,0,0,0,0,0,0,0,0,0,0,0,0,0,0,0,0,0,0,0,0,0,0,0,0,0,0,0,0,0,0,0,0,0,0,0,0,0
0,0,0,0,0,0,0,0,0,0,0,0,0,0,0,0,0,0,0,0,0,0,0,0,0,0,0,0,0,0,0,0,0,0,0,0,0,0
0,0,0,0,0,0,0,0,0,0,0,0,0,0,0,0,0,0,0,0,0,0,0,0,0,0,0,0,0,0,0,0,0,0,0,0,0,0
0,0,0,0,0,0,0,0,0,0,0,0,0,0,0,0,0,0,0,0,0,0,0,0,0,0,0,0,0,0,0,0,0,0,0,0,0,0
0,0,0,0,0,0,0,0,0,0,0,0,0,0,0,0,0,0,0,0,0,0,0,0,0,0,0,0,0,0,0,0,0,0,0,0,0,0
0,0,0,0,0,0,0,0,0,0,0,0,0,0,0,0,0,0,0,0,0,0,0,0,0,0,0,0,0,0,0,0,0,0,0,0,0,0
0,0,0,0,0,0,0,0,0,0,0,0,0,0,0,0,0,0,0,0,0,0,0,0,0,0,0,0,0,0,0,0,0,0,0,0,0,0
0,0,0,0,0,0,0,0,0,0,0,0,0,0,0,0,0,0,0,0,0,0,0,0,0,0,0,0,0,0,0,0,0,0,0,0,0,0
:endlayer
layer: 12
0,0,0,0,0,0,0,0,0,0,0,0,0,0,0,0,0,0,0,0,0,0,0,0,0,0,0,0,0,0,0,0,0,0,0,0,0,0
0,0,0,0,0,0,0,0,0,0,0,0,0,0,0,0,0,0,0,0,0,0,0,0,0,0,0,0,0,0,0,0,0,0,0,0,0,0
0,0,0,0,0,0,0,0,0,0,0,0,0,0,0,0,0,0,0,0,0,0,0,0,0,0,0,0,0,0,0,0,0,0,0,0,0,0
0,0,0,0,0,0,0,0,0,0,0,0,0,0,0,0,0,0,0,0,0,0,0,0,0,0,27,0,0,0,0,0,0,0,0,0,0,0
0,0,0,0,0,0,0,0,0,0,0,0,0,0,0,0,0,0,0,0,0,0,0,0,0,0,27,0,0,0,0,0,0,0,0,0,0,0
0,0,0,0,0,0,0,0,0,0,0,0,0,0,0,0,0,0,0,0,0,0,0,0,0,0,27,0,0,0,0,0,0,0,0,0,0,0
0,0,0,0,0,0,0,0,0,0,0,0,0,0,0,0,0,0,0,0,0,0,0,0,0,0,27,0,0,0,0,0,0,0,0,0,0,0
0,0,0,0,0,0,0,0,0,0,0,0,0,0,0,0,0,0,0,0,0,0,0,0,0,0,27,0,0,0,0,0,0,0,0,0,0,0
0,0,0,0,0,0,0,0,0,0,0,0,0,0,0,0,0,0,0,33,0,0,0,0,0,0,27,0,0,0,0,0,0,0,0,0,0,0
0,0,0,0,0,0,0,0,0,0,0,0,0,0,0,0,0,0,0,0,0,0,0,0,0,0,27,0,0,0,0,0,0,0,0,0,0,0
0,0,0,0,0,0,0,0,0,0,0,0,0,0,0,0,0,0,0,0,0,0,0,0,0,0,27,0,0,0,0,0,0,0,0,0,0,0
0,0,0,0,0,0,0,0,0,0,0,0,0,0,0,0,0,0,0,0,0,0,0,0,0,0,27,0,0,0,0,0,0,0,0,0,0,0
0,0,0,0,0,0,0,0,0,0,0,0,0,0,0,0,0,0,0,0,0,0,0,0,0,0,27,0,0,0,0,0,0,0,0,0,0,0
0,0,0,0,0,0,0,0,0,0,0,0,0,0,0,0,0,0,0,0,0,0,0,0,0,0,27,0,0,0,0,0,0,0,0,0,0,0
0,0,0,0,0,0,0,0,0,0,0,0,0,0,0,0,0,0,0,0,0,0,0,0,0,0,27,0,0,0,0,0,0,0,0,0,0,0
0,0,0,0,0,0,0,0,0,0,0,0,0,0,0,0,0,0,0,0,0,0,0,0,0,0,27,0,0,0,0,0,0,0,0,0,0,0
0,0,0,0,0,0,0,0,0,0,0,0,0,0,0,0,0,0,0,0,0,0,0,0,0,0,27,0,0,0,0,0,0,0,0,0,0,0
0,0,0,0,0,0,0,0,0,0,0,0,0,0,0,0,0,0,0,0,0,0,0,0,0,0,27,0,0,0,0,0,0,0,0,0,0,0
0,0,0,0,0,0,0,0,0,0,0,0,0,0,0,0,0,0,0,0,0,0,0,0,0,0,27,0,0,0,0,0,0,0,0,0,0,0
0,0,0,0,0,0,0,0,0,0,0,0,0,0,0,0,0,0,0,0,0,0,0,0,0,0,27,0,0,0,0,0,0,0,0,0,0,0
0,0,0,0,0,0,0,0,0,0,0,0,0,0,0,0,0,0,0,0,0,0,0,0,0,0,27,0,0,0,0,0,0,0,0,0,0,0
0,0,0,0,0,0,0,0,0,0,0,0,0,0,0,0,0,0,0,0,0,0,0,0,0,0,27,0,0,0,0,0,0,0,0,0,0,0
0,0,0,0,0,0,0,0,0,0,0,0,0,0,0,0,0,0,0,0,0,0,0,0,0,0,27,0,0,0,0,0,0,0,0,0,0,0
0,0,0,0,0,0,0,0,0,0,0,0,0,0,0,0,0,0,0,0,0,0,0,0,0,0,0,0,0,0,0,0,0,0,0,0,0,0
0,0,0,0,0,0,0,0,0,0,0,0,0,0,0,0,0,0,0,0,0,0,0,0,0,0,0,0,0,0,0,0,0,0,0,0,0,0
0,0,0,0,0,0,0,0,0,0,0,0,0,0,0,0,0,0,0,0,0,0,0,0,0,0,0,0,0,0,0,0,0,0,0,0,0,0
0,0,0,0,0,0,0,0,0,0,0,0,0,0,0,0,0,0,0,0,0,0,0,0,0,0,0,0,0,0,0,0,0,0,0,0,0,0
0,0,0,0,0,0,0,0,0,0,0,0,0,0,0,0,0,0,0,0,0,0,0,0,0,0,0,0,0,0,0,0,0,0,0,0,0,0
0,0,0,0,0,0,0,0,0,0,0,0,0,0,0,0,0,0,0,0,0,0,0,0,0,0,0,0,0,0,0,0,0,0,0,0,0,0
0,0,0,0,0,0,0,0,0,0,0,0,0,0,0,0,0,0,0,0,0,0,0,0,0,0,0,0,0,0,0,0,0,0,0,0,0,0
0,0,0,0,0,0,0,0,0,0,0,0,0,0,0,0,0,0,0,0,0,0,0,0,0,0,0,0,0,0,0,0,0,0,0,0,0,0
:endlayer
layer: 13
0,0,0,0,0,0,0,0,0,0,0,0,0,0,0,0,0,0,0,0,0,0,0,0,0,0,0,0,0,0,0,0,0,0,0,0,0,0
0,0,0,0,0,0,0,0,0,0,0,0,0,0,0,0,0,0,0,0,0,0,0,0,0,0,0,0,0,0,0,0,0,0,0,0,0,0
0,0,0,0,0,0,0,0,0,0,0,0,0,0,0,0,0,0,0,0,0,0,0,0,0,0,0,0,0,0,0,0,0,0,0,0,0,0
0,0,0,0,0,0,0,0,0,0,0,0,0,0,0,0,0,0,0,0,0,0,0,0,0,0,0,0,0,0,0,0,0,0,0,0,0,0
0,0,0,0,0,0,0,0,0,0,0,0,0,0,0,0,0,0,0,0,0,0,0,0,0,0,0,0,0,0,0,0,0,0,0,0,0,0
0,0,0,0,0,0,0,0,0,0,0,0,0,0,0,0,0,0,0,0,0,0,0,0,0,0,0,0,0,0,0,0,0,0,0,0,0,0
0,0,0,0,0,0,0,0,0,0,0,0,0,0,0,0,0,0,0,0,0,0,0,0,0,0,0,0,0,0,0,0,0,0,0,0,0,0
0,0,0,0,0,0,0,0,0,0,0,0,0,0,0,0,0,0,0,0,0,0,0,0,0,0,0,0,0,0,0,0,0,0,0,0,0,0
0,0,0,0,0,0,0,0,0,0,0,0,0,0,0,0,0,0,0,14,0,0,0,0,0,0,0,0,0,0,0,0,0,0,0,0,0,0
0,0,0,0,0,0,0,0,0,0,0,0,0,0,0,0,0,0,0,0,0,0,0,0,0,0,0,0,0,0,0,0,0,0,0,0,0,0
0,0,0,0,0,0,0,0,0,0,0,0,0,0,0,0,0,0,0,0,0,0,0,0,0,0,0,0,0,0,0,0,0,0,0,0,0,0
0,0,0,0,0,0,0,0,0,0,0,0,0,0,0,0,0,0,0,0,0,0,0,0,0,0,0,0,0,0,0,0,0,0,0,0,0,0
0,0,0,0,0,0,0,0,0,0,0,0,0,0,0,0,0,0,0,0,0,0,0,0,0,0,0,0,0,0,0,0,0,0,0,0,0,0
0,0,0,0,0,0,0,0,0,0,0,0,0,0,0,0,0,0,0,0,0,0,0,0,0,0,0,0,0,0,0,0,0,0,0,0,0,0
0,0,0,0,0,0,0,0,0,0,0,0,0,0,0,0,0,0,0,0,0,0,0,0,0,0,0,0,0,0,0,0,0,0,0,0,0,0
0,0,0,0,0,0,0,0,0,0,0,0,0,0,0,0,0,0,0,0,0,0,0,0,0,0,0,0,0,0,0,0,0,0,0,0,0,0
0,0,0,0,0,0,0,0,0,0,0,0,0,0,0,0,0,0,0,0,0,0,0,0,0,0,0,0,0,0,0,0,0,0,0,0,0,0
0,0,0,0,0,0,0,0,0,0,0,0,0,0,0,0,0,0,0,0,0,0,0,0,0,0,0,0,0,0,0,0,0,0,0,0,0,0
0,0,0,0,0,0,0,0,0,0,0,0,0,0,0,0,0,0,0,0,0,0,0,0,0,0,0,0,0,0,0,0,0,0,0,0,0,0
0,0,0,0,0,0,0,0,0,0,0,0,0,0,0,0,0,0,0,0,0,0,0,0,0,0,0,0,0,0,0,0,0,0,0,0,0,0
0,0,0,0,0,0,0,0,0,0,0,0,0,0,0,0,0,0,0,0,0,0,0,0,0,0,0,0,0,0,0,0,0,0,0,0,0,0
0,0,0,0,0,0,0,0,0,0,0,0,0,0,0,0,0,0,0,0,0,0,0,0,0,0,0,0,0,0,0,0,0,0,0,0,0,0
0,0,0,0,0,0,0,0,0,0,0,0,0,0,0,0,0,0,0,0,0,0,0,0,0,0,0,0,0,0,0,0,0,0,0,0,0,0
0,0,0,0,0,0,0,0,0,0,0,0,0,0,0,0,0,0,0,0,0,0,0,0,0,0,0,0,0,0,0,0,0,0,0,0,0,0
0,0,0,0,0,0,0,0,0,0,0,0,0,0,0,0,0,0,0,0,0,0,0,0,0,0,0,0,0,0,0,0,0,0,0,0,0,0
0,0,0,0,0,0,0,0,0,0,0,0,0,0,0,0,0,0,0,0,0,0,0,0,0,0,0,0,0,0,0,0,0,0,0,0,0,0
0,0,0,0,0,0,0,0,0,0,0,0,0,0,0,0,0,0,0,0,0,0,0,0,0,0,0,0,0,0,0,0,0,0,0,0,0,0
0,0,0,0,0,0,0,0,0,0,0,0,0,0,0,0,0,0,0,0,0,0,0,0,0,0,0,0,0,0,0,0,0,0,0,0,0,0
0,0,0,0,0,0,0,0,0,0,0,0,0,0,0,0,0,0,0,0,0,0,0,0,0,0,0,0,0,0,0,0,0,0,0,0,0,0
0,0,0,0,0,0,0,0,0,0,0,0,0,0,0,0,0,0,0,0,0,0,0,0,0,0,0,0,0,0,0,0,0,0,0,0,0,0
0,0,0,0,0,0,0,0,0,0,0,0,0,0,0,0,0,0,0,0,0,0,0,0,0,0,0,0,0,0,0,0,0,0,0,0,0,0
:endlayer

#### RULES ####
rule:
plugin=vanillaBlocks
number=1
data:
JSON:{blockState:{blockName:"minecraft:grass",properties:{snowy:"false"}}}
:enddata
:endrule

rule:
plugin=vanillaBlocks
number=2
data:
JSON:{blockState:{blockName:"minecraft:dirt",properties:{variant:"coarse_dirt",snowy:"false"}}}
:enddata
:endrule

rule:
plugin=vanillaBlocks
number=3
data:
JSON:{blockState:{blockName:"minecraft:grass_path"}}
:enddata
:endrule

rule:
plugin=vanillaBlocks
number=4
data:
JSON:{blockState:{blockName:"minecraft:stonebrick",properties:{variant:"stonebrick"}}}
:enddata
:endrule

rule:
plugin=vanillaBlocks
number=5
data:
JSON:{blockState:{blockName:"minecraft:cobblestone"}}
:enddata
:endrule

rule:
plugin=vanillaBlocks
number=6
data:
JSON:{blockState:{blockName:"minecraft:gravel"}}
:enddata
:endrule

rule:
plugin=vanillaBlocks
number=7
data:
JSON:{blockState:{blockName:"minecraft:monster_egg",properties:{variant:"cobblestone"}}}
:enddata
:endrule

rule:
plugin=vanillaBlocks
number=8
data:
JSON:{blockState:{blockName:"biomesoplenty:planks_0",properties:{variant:"ethereal"}}}
:enddata
:endrule

rule:
plugin=vanillaBlocks
number=9
data:
JSON:{blockState:{blockName:"biomesoplenty:log_1",properties:{variant:"ethereal",axis:"x"}}}
:enddata
:endrule

rule:
plugin=vanillaBlocks
number=10
data:
JSON:{blockState:{blockName:"minecraft:torch",properties:{facing:"up"}}}
:enddata
:endrule

rule:
plugin=vanillaBlocks
number=11
data:
JSON:{blockState:{blockName:"biomesoplenty:ethereal_fence",properties:{east:"false",south:"false",north:"false",west:"false"}}}
:enddata
:endrule

rule:
plugin=vanillaBlocks
number=12
data:
JSON:{blockState:{blockName:"biomesoplenty:log_1",properties:{variant:"ethereal",axis:"y"}}}
:enddata
:endrule

rule:
plugin=vanillaBlocks
number=13
data:
JSON:{blockState:{blockName:"minecraft:ladder",properties:{facing:"south"}}}
:enddata
:endrule

rule:
plugin=vanillaBlocks
number=14
data:
JSON:{blockState:{blockName:"minecraft:stone_slab",properties:{half:"bottom",variant:"cobblestone"}}}
:enddata
:endrule

rule:
plugin=vanillaBlocks
number=15
data:
JSON:{blockState:{blockName:"minecraft:torch",properties:{facing:"west"}}}
:enddata
:endrule

rule:
plugin=vanillaBlocks
number=16
data:
JSON:{blockState:{blockName:"minecraft:torch",properties:{facing:"east"}}}
:enddata
:endrule

rule:
plugin=vanillaBlocks
number=17
data:
JSON:{blockState:{blockName:"minecraft:torch",properties:{facing:"north"}}}
:enddata
:endrule

rule:
plugin=vanillaBlocks
number=18
data:
JSON:{blockState:{blockName:"biomesoplenty:wood_slab_0",properties:{half:"top",variant:"ethereal"}}}
:enddata
:endrule

rule:
plugin=vanillaBlocks
number=19
data:
JSON:{blockState:{blockName:"minecraft:torch",properties:{facing:"south"}}}
:enddata
:endrule

rule:
plugin=vanillaBlocks
number=20
data:
JSON:{blockState:{blockName:"biomesoplenty:log_1",properties:{variant:"ethereal",axis:"z"}}}
:enddata
:endrule

rule:
plugin=vanillaBlocks
number=21
data:
JSON:{blockState:{blockName:"minecraft:stone_stairs",properties:{half:"top",shape:"straight",facing:"west"}}}
:enddata
:endrule

rule:
plugin=vanillaBlocks
number=22
data:
JSON:{blockState:{blockName:"minecraft:stone_stairs",properties:{half:"top",shape:"straight",facing:"east"}}}
:enddata
:endrule

rule:
plugin=vanillaBlocks
number=23
data:
JSON:{blockState:{blockName:"biomesoplenty:ethereal_stairs",properties:{half:"top",shape:"straight",facing:"north"}}}
:enddata
:endrule

rule:
plugin=vanillaBlocks
number=24
data:
JSON:{blockState:{blockName:"biomesoplenty:ethereal_stairs",properties:{half:"top",shape:"straight",facing:"west"}}}
:enddata
:endrule

rule:
plugin=vanillaBlocks
number=25
data:
JSON:{blockState:{blockName:"biomesoplenty:ethereal_stairs",properties:{half:"top",shape:"straight",facing:"east"}}}
:enddata
:endrule

rule:
plugin=vanillaBlocks
number=26
data:
JSON:{blockState:{blockName:"biomesoplenty:ethereal_stairs",properties:{half:"top",shape:"straight",facing:"south"}}}
:enddata
:endrule

rule:
plugin=vanillaBlocks
number=27
data:
JSON:{blockState:{blockName:"biomesoplenty:wood_slab_0",properties:{half:"bottom",variant:"ethereal"}}}
:enddata
:endrule

rule:
plugin=vanillaBlocks
number=28
data:
JSON:{blockState:{blockName:"biomesoplenty:ethereal_stairs",properties:{half:"bottom",shape:"straight",facing:"south"}}}
:enddata
:endrule

rule:
plugin=vanillaBlocks
number=29
data:
JSON:{blockState:{blockName:"biomesoplenty:ethereal_stairs",properties:{half:"bottom",shape:"straight",facing:"east"}}}
:enddata
:endrule

rule:
plugin=vanillaBlocks
number=30
data:
JSON:{blockState:{blockName:"biomesoplenty:ethereal_stairs",properties:{half:"bottom",shape:"straight",facing:"north"}}}
:enddata
:endrule

rule:
plugin=vanillaBlocks
number=31
data:
JSON:{blockState:{blockName:"biomesoplenty:ethereal_stairs",properties:{half:"bottom",shape:"straight",facing:"west"}}}
:enddata
:endrule

rule:
plugin=vanillaBlocks
number=32
data:
JSON:{blockState:{blockName:"minecraft:stone_stairs",properties:{half:"bottom",shape:"straight",facing:"east"}}}
:enddata
:endrule

rule:
plugin=vanillaBlocks
number=33
data:
JSON:{blockState:{blockName:"minecraft:cobblestone_wall",properties:{east:"false",south:"false",north:"false",variant:"cobblestone",west:"false",up:"false"}}}
:enddata
:endrule

#### ENTITIES ####
