# Ancient Warfare Structure Template File
# Auto-generated structure template file. created on: 6/6/2023 at: 22:25:41
# Lines beginning with # denote comments

header:
version=2.11
name=SB_MarenCol_TowerHouse_1H3R_1_mangrove
mods=biomesoplenty
size=11,24,11
offset=5,1,10
:endheader

#### VALIDATION ####
validation:
type=ground
structureAuthor=TheOddlySeagull
survival=true
worldGenEnabled=false
unique=false
preserveBlocks=false
preventNaturalHostileSpawns=false
selectionWeight=1
clusterValue=1
minDuplicateDistance=1
dimensionWhiteList=true
dimensionList=
biomeGroupList=
biomeWhiteList=true
biomeList=
leveling=0
fill=0
border=0
blockSwap=false
territoryName=
biomeReplacement=minecraft:
minGenerationHeight=0
maxGenerationHeight=255
:endvalidation

#### LAYERS ####
layer: 0
1,1,1,1,1,1,1,1,1,1,1
1,1,1,1,1,1,1,1,1,1,1
1,1,2,3,2,3,2,3,2,1,1
1,1,3,3,3,3,3,3,3,1,1
1,1,2,3,3,3,3,3,2,1,1
1,1,3,3,3,3,3,3,3,3,1
1,1,2,3,3,3,3,3,3,3,1
1,1,3,3,3,3,3,3,3,3,1
1,1,2,3,2,3,2,3,2,1,1
1,1,1,1,3,3,3,1,1,1,1
1,1,1,1,3,3,3,1,1,1,1
:endlayer
layer: 1
0,0,0,0,0,0,0,0,0,0,0
0,0,0,0,0,0,0,0,0,0,0
0,0,2,3,2,3,2,3,2,0,0
0,0,3,0,0,0,0,0,3,0,0
0,0,2,0,6,0,0,0,2,0,0
0,0,3,4,5,0,0,8,9,3,0
0,0,2,0,0,0,0,8,9,3,0
0,0,3,0,0,0,0,8,9,3,0
0,0,2,3,2,7,2,3,2,0,0
0,0,0,0,0,0,0,0,0,0,0
0,0,0,0,0,0,0,0,0,0,0
:endlayer
layer: 2
0,0,0,0,0,0,0,0,0,0,0
0,0,0,0,0,0,0,0,0,0,0
0,0,2,3,2,6,2,3,2,0,0
0,0,3,4,0,0,0,0,3,0,0
0,0,2,5,6,0,0,0,2,0,0
0,0,6,0,0,0,0,0,0,3,0
0,0,2,0,0,0,0,0,0,3,0
0,0,3,0,0,0,0,0,0,3,0
0,0,2,3,2,10,2,3,2,0,0
0,0,0,0,0,0,0,0,0,0,0
0,0,0,0,0,0,0,0,0,0,0
:endlayer
layer: 3
0,0,0,0,0,0,0,0,0,0,0
0,0,13,0,0,0,0,0,13,0,0
0,11,2,3,2,6,2,3,2,14,0
0,0,3,0,5,4,12,0,3,0,0
0,0,2,14,6,0,0,11,2,0,0
0,0,6,0,0,0,0,0,16,3,0
0,0,2,14,0,0,0,0,0,3,0
0,0,3,0,13,0,13,0,15,3,0
0,11,2,3,2,3,2,3,2,14,0
0,0,12,0,0,0,0,0,12,0,0
0,0,0,0,0,0,0,0,0,0,0
:endlayer
layer: 4
0,0,0,0,0,0,0,0,0,0,0
0,0,0,0,0,0,0,0,0,0,0
0,0,2,2,2,2,2,2,2,0,0
0,0,2,0,0,0,17,4,2,0,0
0,0,2,0,6,5,17,4,2,0,0
0,0,2,0,0,4,17,3,2,3,0
0,0,2,17,17,17,17,3,2,3,0
0,0,2,4,4,4,17,3,2,3,0
0,0,2,2,2,2,2,2,2,0,0
0,0,0,0,0,0,0,0,0,0,0
0,0,0,0,0,0,0,0,0,0,0
:endlayer
layer: 5
0,0,0,0,0,0,0,0,0,0,0
0,0,0,0,0,0,0,0,0,0,0
0,0,2,3,3,3,3,3,2,0,0
0,0,3,0,0,0,0,0,3,0,0
0,0,3,0,6,0,0,0,3,0,0
0,0,3,4,5,0,0,8,9,3,0
0,0,3,0,0,0,0,8,9,3,0
0,0,3,0,0,0,0,8,9,3,0
0,0,2,3,3,3,3,3,2,0,0
0,0,0,0,0,0,0,0,0,0,0
0,0,0,0,0,0,0,0,0,0,0
:endlayer
layer: 6
0,0,0,0,0,0,0,0,0,0,0
0,0,0,0,0,0,0,0,0,0,0
0,0,2,3,6,3,6,3,2,0,0
0,0,3,4,0,0,0,0,3,0,0
0,0,6,5,6,0,0,0,3,0,0
0,0,3,0,0,0,0,0,0,3,0
0,0,6,0,0,0,0,0,0,3,0
0,0,3,0,0,0,0,0,0,3,0
0,0,2,3,6,3,6,3,2,0,0
0,0,0,0,0,0,0,0,0,0,0
0,0,0,0,0,0,0,0,0,0,0
:endlayer
layer: 7
0,0,0,0,0,0,0,0,0,0,0
0,0,0,0,0,0,0,0,0,0,0
0,0,2,3,6,3,6,3,2,0,0
0,0,3,0,5,4,0,0,3,0,0
0,0,6,0,6,0,0,11,3,0,0
0,0,3,14,0,0,0,0,16,19,0
0,0,6,0,0,0,0,0,0,3,0
0,0,3,0,0,13,0,0,15,18,0
0,0,2,3,6,3,6,3,2,0,0
0,0,0,0,0,0,0,0,0,0,0
0,0,0,0,0,0,0,0,0,0,0
:endlayer
layer: 8
0,0,0,0,0,0,0,0,0,0,0
0,0,0,0,0,0,0,0,0,0,0
0,0,2,2,2,2,2,2,2,0,0
0,0,2,0,0,0,17,4,2,0,0
0,0,2,0,6,5,17,4,2,0,0
0,0,2,0,0,4,17,4,2,0,0
0,0,2,17,17,17,17,17,2,3,0
0,0,2,4,4,4,17,4,2,0,0
0,0,2,2,2,2,2,2,2,0,0
0,0,0,0,0,0,0,0,0,0,0
0,0,0,0,0,0,0,0,0,0,0
:endlayer
layer: 9
0,0,0,0,0,0,0,0,0,0,0
0,0,0,0,0,0,0,0,0,0,0
0,0,20,17,20,17,20,17,20,0,0
0,0,17,0,0,0,0,0,17,0,0
0,0,20,0,6,0,0,0,20,0,0
0,0,17,4,5,0,0,0,17,0,0
0,0,20,0,0,0,0,0,20,3,0
0,0,17,0,0,0,0,0,17,0,0
0,0,20,17,20,17,20,17,20,0,0
0,0,0,0,0,0,0,0,0,0,0
0,0,0,0,0,0,0,0,0,0,0
:endlayer
layer: 10
0,0,0,0,0,0,0,0,0,0,0
0,0,0,0,0,0,0,0,0,0,0
0,0,20,6,20,6,20,6,20,0,0
0,0,6,4,0,0,0,0,6,0,0
0,0,20,5,6,0,0,0,20,0,0
0,0,6,0,0,0,0,0,17,0,0
0,0,20,0,0,0,0,0,20,3,0
0,0,6,0,0,0,0,0,17,0,0
0,0,20,6,20,6,20,6,20,0,0
0,0,0,0,0,0,0,0,0,0,0
0,0,0,0,0,0,0,0,0,0,0
:endlayer
layer: 11
0,0,0,0,0,0,0,0,0,0,0
0,0,0,0,0,0,0,0,0,0,0
0,0,20,6,20,6,20,6,20,0,0
0,0,6,0,5,4,12,0,6,0,0
0,0,20,14,6,0,0,11,20,0,0
0,0,6,0,0,0,0,0,17,0,0
0,0,20,14,0,0,0,11,20,3,0
0,0,6,0,13,0,13,0,17,0,0
0,0,20,6,20,6,20,6,20,0,0
0,0,0,0,0,0,0,0,0,0,0
0,0,0,0,0,0,0,0,0,0,0
:endlayer
layer: 12
0,0,0,0,0,0,0,0,0,0,0
0,0,0,0,0,0,0,0,0,0,0
0,0,20,22,22,22,22,22,20,0,0
0,0,21,0,0,0,17,4,21,0,0
0,0,21,0,6,5,17,4,21,0,0
0,0,21,4,4,4,17,4,21,0,0
0,0,21,17,17,17,17,17,21,3,0
0,0,21,4,4,4,17,4,21,0,0
0,0,20,22,22,22,22,22,20,0,0
0,0,0,0,0,0,0,0,0,0,0
0,0,0,0,0,0,0,0,0,0,0
:endlayer
layer: 13
0,0,0,0,0,0,0,0,0,0,0
0,0,0,0,0,0,0,0,0,0,0
0,0,20,17,20,17,20,17,20,0,0
0,0,17,0,0,0,0,0,17,0,0
0,0,20,0,6,0,0,0,20,0,0
0,0,17,0,0,0,0,0,17,0,0
0,0,20,0,0,0,0,0,20,3,0
0,0,17,0,0,0,0,0,17,0,0
0,0,20,17,20,17,20,17,20,0,0
0,0,0,0,0,0,0,0,0,0,0
0,0,0,0,0,0,0,0,0,0,0
:endlayer
layer: 14
0,0,0,0,0,0,0,0,0,0,0
0,0,0,0,0,0,0,0,0,0,0
0,0,20,6,20,6,20,6,20,0,0
0,0,6,0,0,0,0,0,6,0,0
0,0,20,0,6,0,0,0,20,0,0
0,0,6,0,0,0,0,0,6,0,0
0,0,20,0,0,0,0,0,20,3,0
0,0,6,0,0,0,0,0,6,0,0
0,0,20,6,20,6,20,6,20,0,0
0,0,0,0,0,0,0,0,0,0,0
0,0,0,0,0,0,0,0,0,0,0
:endlayer
layer: 15
0,0,0,0,0,0,0,0,0,0,0
0,0,6,0,6,0,6,0,6,0,0
0,6,20,6,20,6,20,6,20,6,0
0,0,6,0,12,0,12,0,6,0,0
0,6,20,14,6,0,0,11,20,6,0
0,0,6,0,0,0,0,0,6,0,0
0,6,20,14,0,0,0,11,20,3,0
0,0,6,0,13,0,13,0,6,0,0
0,6,20,6,20,6,20,6,20,6,0
0,0,6,0,6,0,6,0,6,0,0
0,0,0,0,0,0,0,0,0,0,0
:endlayer
layer: 16
0,0,0,0,0,0,0,0,0,0,0
0,25,25,25,25,25,25,25,25,26,0
0,24,20,22,22,22,22,22,20,26,0
0,24,21,0,0,0,0,0,21,26,0
0,24,21,0,6,0,0,0,21,26,0
0,24,21,0,0,0,0,0,21,26,0
0,24,21,0,0,0,0,0,21,3,0
0,24,21,0,0,0,0,0,21,26,0
0,24,20,22,22,22,22,22,20,26,0
0,23,23,23,23,23,23,23,23,23,0
0,0,0,0,0,0,0,0,0,0,0
:endlayer
layer: 17
0,0,0,0,0,0,0,0,0,0,0
0,0,0,0,0,0,0,0,0,0,0
0,0,24,25,25,25,25,25,25,0,0
0,0,24,28,29,29,29,29,26,0,0
0,0,24,28,6,0,0,30,26,0,0
0,0,24,28,0,0,0,30,26,0,0
0,0,24,28,0,0,0,30,26,3,0
0,0,24,27,27,27,27,30,26,0,0
0,0,23,23,23,23,23,23,23,0,0
0,0,0,0,0,0,0,0,0,0,0
0,0,0,0,0,0,0,0,0,0,0
:endlayer
layer: 18
0,0,0,0,0,0,0,0,0,0,0
0,0,0,0,0,0,0,0,0,0,0
0,0,0,0,0,0,0,0,0,0,0
0,0,0,25,25,25,25,26,0,0,0
0,0,0,24,29,29,30,26,0,0,0
0,0,0,24,28,0,30,26,0,0,0
0,0,0,24,28,27,27,26,0,3,0
0,0,0,24,23,23,23,23,0,0,0
0,0,0,0,0,0,0,0,0,0,0
0,0,0,0,0,0,0,0,0,0,0
0,0,0,0,0,0,0,0,0,0,0
:endlayer
layer: 19
0,0,0,0,0,0,0,0,0,0,0
0,0,0,0,0,0,0,0,0,0,0
0,0,0,0,0,0,0,0,0,0,0
0,0,0,0,0,0,0,0,0,0,0
0,0,0,0,25,25,26,0,0,0,0
0,0,0,0,24,17,26,0,0,0,0
0,0,0,0,24,23,23,0,0,3,0
0,0,0,0,0,0,0,0,0,0,0
0,0,0,0,0,0,0,0,0,0,0
0,0,0,0,0,0,0,0,0,0,0
0,0,0,0,0,0,0,0,0,0,0
:endlayer
layer: 20
0,0,0,0,0,0,0,0,0,0,0
0,0,0,0,0,0,0,0,0,0,0
0,0,0,0,0,0,0,0,0,0,0
0,0,0,0,0,0,0,0,0,0,0
0,0,0,0,0,0,0,0,0,0,0
0,0,0,0,0,6,0,0,0,0,0
0,0,0,0,0,0,0,0,0,3,0
0,0,0,0,0,0,0,0,0,0,0
0,0,0,0,0,0,0,0,0,0,0
0,0,0,0,0,0,0,0,0,0,0
0,0,0,0,0,0,0,0,0,0,0
:endlayer
layer: 21
0,0,0,0,0,0,0,0,0,0,0
0,0,0,0,0,0,0,0,0,0,0
0,0,0,0,0,0,0,0,0,0,0
0,0,0,0,0,0,0,0,0,0,0
0,0,0,0,0,0,0,0,0,0,0
0,0,0,0,0,6,0,0,0,0,0
0,0,0,0,0,0,0,0,0,31,0
0,0,0,0,0,0,0,0,0,0,0
0,0,0,0,0,0,0,0,0,0,0
0,0,0,0,0,0,0,0,0,0,0
0,0,0,0,0,0,0,0,0,0,0
:endlayer
layer: 22
0,0,0,0,0,0,0,0,0,0,0
0,0,0,0,0,0,0,0,0,0,0
0,0,0,0,0,0,0,0,0,0,0
0,0,0,0,0,0,0,0,0,0,0
0,0,0,0,0,0,0,0,0,0,0
0,0,0,0,0,6,0,0,0,0,0
0,0,0,0,0,0,0,0,0,8,0
0,0,0,0,0,0,0,0,0,0,0
0,0,0,0,0,0,0,0,0,0,0
0,0,0,0,0,0,0,0,0,0,0
0,0,0,0,0,0,0,0,0,0,0
:endlayer
layer: 23
0,0,0,0,0,0,0,0,0,0,0
0,0,0,0,0,0,0,0,0,0,0
0,0,0,0,0,0,0,0,0,0,0
0,0,0,0,0,0,0,0,0,0,0
0,0,0,0,0,0,0,0,0,0,0
0,0,0,0,0,32,0,0,0,0,0
0,0,0,0,0,0,0,0,0,0,0
0,0,0,0,0,0,0,0,0,0,0
0,0,0,0,0,0,0,0,0,0,0
0,0,0,0,0,0,0,0,0,0,0
0,0,0,0,0,0,0,0,0,0,0
:endlayer

#### RULES ####
rule:
plugin=vanillaBlocks
number=1
data:
JSON:{blockState:{blockName:"minecraft:grass",properties:{snowy:"false"}}}
:enddata
:endrule

rule:
plugin=vanillaBlocks
number=2
data:
JSON:{blockState:{blockName:"minecraft:stonebrick",properties:{variant:"stonebrick"}}}
:enddata
:endrule

rule:
plugin=vanillaBlocks
number=3
data:
JSON:{blockState:{blockName:"minecraft:cobblestone"}}
:enddata
:endrule

rule:
plugin=vanillaBlocks
number=4
data:
JSON:{blockState:{blockName:"biomesoplenty:wood_slab_0",properties:{half:"top",variant:"mangrove"}}}
:enddata
:endrule

rule:
plugin=vanillaBlocks
number=5
data:
JSON:{blockState:{blockName:"biomesoplenty:wood_slab_0",properties:{half:"bottom",variant:"mangrove"}}}
:enddata
:endrule

rule:
plugin=vanillaBlocks
number=6
data:
JSON:{blockState:{blockName:"biomesoplenty:mangrove_fence",properties:{east:"false",south:"false",north:"false",west:"false"}}}
:enddata
:endrule

rule:
plugin=doors
number=7
data:
JSON:{blockState:{blockName:"minecraft:wooden_door",properties:{hinge:"left",half:"lower",powered:"false",facing:"north",open:"false"}}}
:enddata
:endrule

rule:
plugin=vanillaBlocks
number=8
data:
JSON:{blockState:{blockName:"minecraft:stone_slab",properties:{half:"bottom",variant:"cobblestone"}}}
:enddata
:endrule

rule:
plugin=vanillaBlocks
number=9
data:
JSON:{blockState:{blockName:"ancientwarfarestructure:fire_pit",properties:{lit:"false",variant:"log"}}}
:enddata
:endrule

rule:
plugin=doors
number=10
data:
JSON:{blockState:{blockName:"minecraft:wooden_door",properties:{hinge:"left",half:"upper",powered:"false",facing:"north",open:"false"}}}
:enddata
:endrule

rule:
plugin=vanillaBlocks
number=11
data:
JSON:{blockState:{blockName:"minecraft:torch",properties:{facing:"west"}}}
:enddata
:endrule

rule:
plugin=vanillaBlocks
number=12
data:
JSON:{blockState:{blockName:"minecraft:torch",properties:{facing:"south"}}}
:enddata
:endrule

rule:
plugin=vanillaBlocks
number=13
data:
JSON:{blockState:{blockName:"minecraft:torch",properties:{facing:"north"}}}
:enddata
:endrule

rule:
plugin=vanillaBlocks
number=14
data:
JSON:{blockState:{blockName:"minecraft:torch",properties:{facing:"east"}}}
:enddata
:endrule

rule:
plugin=vanillaBlocks
number=15
data:
JSON:{blockState:{blockName:"minecraft:stone_stairs",properties:{half:"top",shape:"straight",facing:"south"}}}
:enddata
:endrule

rule:
plugin=vanillaBlocks
number=16
data:
JSON:{blockState:{blockName:"minecraft:stone_stairs",properties:{half:"top",shape:"straight",facing:"north"}}}
:enddata
:endrule

rule:
plugin=vanillaBlocks
number=17
data:
JSON:{blockState:{blockName:"biomesoplenty:planks_0",properties:{variant:"mangrove"}}}
:enddata
:endrule

rule:
plugin=vanillaBlocks
number=18
data:
JSON:{blockState:{blockName:"minecraft:stone_stairs",properties:{half:"bottom",shape:"straight",facing:"north"}}}
:enddata
:endrule

rule:
plugin=vanillaBlocks
number=19
data:
JSON:{blockState:{blockName:"minecraft:stone_stairs",properties:{half:"bottom",shape:"straight",facing:"south"}}}
:enddata
:endrule

rule:
plugin=vanillaBlocks
number=20
data:
JSON:{blockState:{blockName:"biomesoplenty:log_1",properties:{variant:"mangrove",axis:"y"}}}
:enddata
:endrule

rule:
plugin=vanillaBlocks
number=21
data:
JSON:{blockState:{blockName:"biomesoplenty:log_1",properties:{variant:"mangrove",axis:"z"}}}
:enddata
:endrule

rule:
plugin=vanillaBlocks
number=22
data:
JSON:{blockState:{blockName:"biomesoplenty:log_1",properties:{variant:"mangrove",axis:"x"}}}
:enddata
:endrule

rule:
plugin=vanillaBlocks
number=23
data:
JSON:{blockState:{blockName:"biomesoplenty:mangrove_stairs",properties:{half:"bottom",shape:"straight",facing:"north"}}}
:enddata
:endrule

rule:
plugin=vanillaBlocks
number=24
data:
JSON:{blockState:{blockName:"biomesoplenty:mangrove_stairs",properties:{half:"bottom",shape:"straight",facing:"east"}}}
:enddata
:endrule

rule:
plugin=vanillaBlocks
number=25
data:
JSON:{blockState:{blockName:"biomesoplenty:mangrove_stairs",properties:{half:"bottom",shape:"straight",facing:"south"}}}
:enddata
:endrule

rule:
plugin=vanillaBlocks
number=26
data:
JSON:{blockState:{blockName:"biomesoplenty:mangrove_stairs",properties:{half:"bottom",shape:"straight",facing:"west"}}}
:enddata
:endrule

rule:
plugin=vanillaBlocks
number=27
data:
JSON:{blockState:{blockName:"biomesoplenty:mangrove_stairs",properties:{half:"top",shape:"straight",facing:"south"}}}
:enddata
:endrule

rule:
plugin=vanillaBlocks
number=28
data:
JSON:{blockState:{blockName:"biomesoplenty:mangrove_stairs",properties:{half:"top",shape:"straight",facing:"west"}}}
:enddata
:endrule

rule:
plugin=vanillaBlocks
number=29
data:
JSON:{blockState:{blockName:"biomesoplenty:mangrove_stairs",properties:{half:"top",shape:"straight",facing:"north"}}}
:enddata
:endrule

rule:
plugin=vanillaBlocks
number=30
data:
JSON:{blockState:{blockName:"biomesoplenty:mangrove_stairs",properties:{half:"top",shape:"straight",facing:"east"}}}
:enddata
:endrule

rule:
plugin=vanillaBlocks
number=31
data:
JSON:{blockState:{blockName:"minecraft:cobblestone_wall",properties:{east:"false",south:"false",north:"false",variant:"cobblestone",west:"false",up:"false"}}}
:enddata
:endrule

rule:
plugin=vanillaBlocks
number=32
data:
JSON:{blockState:{blockName:"minecraft:torch",properties:{facing:"up"}}}
:enddata
:endrule

#### ENTITIES ####
