# Ancient Warfare Structure Template File
# Auto-generated structure template file. created on: 6/4/2023 at: 23:22:6
# Lines beginning with # denote comments

header:
version=2.11
name=SB_MarenCol_House_2H2R_1_palm
mods=biomesoplenty
size=18,14,19
offset=8,1,18
:endheader

#### VALIDATION ####
validation:
type=ground
structureAuthor=TheOddlySeagull
survival=true
worldGenEnabled=false
unique=false
preserveBlocks=false
preventNaturalHostileSpawns=false
selectionWeight=1
clusterValue=1
minDuplicateDistance=1
dimensionWhiteList=true
dimensionList=
biomeGroupList=
biomeWhiteList=true
biomeList=
leveling=0
fill=0
border=0
blockSwap=false
territoryName=
biomeReplacement=minecraft:
minGenerationHeight=0
maxGenerationHeight=255
:endvalidation

#### LAYERS ####
layer: 0
1,1,1,1,1,1,1,1,1,1,1,1,1,1,1,1,1,1
1,1,1,3,4,4,4,3,1,2,2,1,1,1,1,1,1,1
1,1,1,5,2,2,2,5,2,2,2,2,3,1,1,1,1,1
1,1,1,5,2,2,2,5,2,2,2,2,5,1,1,1,1,1
1,1,1,5,2,2,2,5,2,2,2,2,5,2,2,2,1,1
1,3,4,4,4,4,4,3,2,2,2,2,5,2,2,2,1,1
1,5,6,6,6,6,6,5,2,2,2,2,5,2,2,2,1,1
1,5,6,6,6,6,6,5,2,2,2,2,5,2,2,2,1,1
1,5,6,6,6,6,6,5,2,2,2,2,5,1,1,1,1,1
1,3,4,4,4,4,4,4,4,4,4,4,4,4,4,4,3,1
1,1,1,1,1,2,2,2,2,2,2,2,5,6,6,6,5,1
1,1,1,1,2,2,2,2,2,2,2,2,5,6,6,6,5,1
1,1,1,1,2,2,2,2,2,2,2,2,5,6,6,6,5,1
1,1,1,1,1,2,2,2,2,2,2,2,5,6,6,6,5,1
1,1,1,1,1,3,2,2,2,2,2,2,3,4,4,4,3,1
1,1,1,1,1,5,2,2,2,2,2,2,5,1,1,1,1,1
1,1,1,1,1,3,4,4,4,4,4,4,3,1,1,1,1,1
1,1,1,1,1,1,1,2,2,2,2,1,1,1,1,1,1,1
1,1,1,1,1,1,1,2,2,2,2,1,1,1,1,1,1,1
:endlayer
layer: 1
0,0,0,0,0,0,0,0,0,0,0,0,0,0,0,0,0,0
0,0,0,3,6,6,6,3,0,2,2,0,0,0,0,0,7,0
0,0,0,6,0,0,0,6,2,11,11,2,3,0,0,0,0,0
0,0,0,6,0,7,0,3,0,10,10,0,6,0,0,0,0,0
0,0,0,6,15,14,0,0,0,0,0,0,3,0,0,0,0,0
0,3,6,3,6,6,6,3,0,0,0,0,13,0,0,0,0,0
0,6,0,0,0,0,0,6,0,0,0,0,12,0,0,0,0,0
0,6,0,0,0,0,0,3,0,0,0,0,3,0,0,0,0,0
0,6,0,0,0,0,0,0,0,0,0,0,6,0,0,0,0,0
0,3,6,6,6,3,6,3,6,6,3,6,3,6,6,6,3,0
0,0,0,0,0,2,10,0,0,0,0,0,0,0,0,0,6,0
0,0,0,0,2,11,10,0,0,0,0,0,3,0,0,0,6,0
0,0,0,0,2,11,10,0,0,0,0,0,6,0,0,0,6,0
0,0,0,0,0,2,10,0,0,0,0,0,6,0,0,0,6,0
0,0,0,0,0,3,0,0,0,0,0,0,3,6,6,6,3,0
0,0,0,0,0,6,0,0,0,0,0,0,6,0,0,0,0,0
0,0,0,0,0,3,6,3,9,8,3,6,3,0,0,0,0,0
0,7,0,0,0,0,0,0,0,0,0,0,0,0,0,0,7,0
0,0,0,0,0,0,0,0,0,0,0,0,0,0,0,0,0,0
:endlayer
layer: 2
0,0,0,0,0,0,0,0,0,0,0,0,0,0,0,0,0,0
0,0,0,3,6,7,6,3,0,2,2,0,0,0,0,0,16,0
0,0,0,6,15,0,21,6,2,0,0,2,3,0,0,0,0,0
0,0,0,7,14,7,0,3,0,0,0,0,7,0,0,0,0,0
0,0,0,6,0,0,0,0,0,0,0,0,3,0,0,0,0,0
0,3,6,3,6,6,6,3,0,0,0,0,20,0,0,0,0,0
0,6,0,0,0,0,0,6,0,0,0,0,19,0,0,0,0,0
0,7,0,0,0,0,0,3,0,0,0,0,3,0,0,0,0,0
0,6,0,0,0,0,0,0,0,0,0,0,7,0,0,0,0,0
0,3,6,7,6,3,6,3,6,6,3,6,3,6,7,6,3,0
0,0,0,0,0,2,0,0,0,0,0,0,0,0,0,0,6,0
0,0,0,0,2,0,0,0,0,0,0,0,3,0,0,0,7,0
0,0,0,0,2,0,0,0,0,0,0,0,6,0,0,0,7,0
0,0,0,0,0,2,0,0,0,0,0,0,6,0,0,0,6,0
0,0,0,0,0,3,0,0,0,0,0,0,3,6,7,6,3,0
0,0,0,0,0,6,0,0,0,0,0,0,6,0,0,0,0,0
0,0,0,0,0,3,7,3,18,17,3,7,3,0,0,0,0,0
0,16,0,0,0,0,0,0,0,0,0,0,0,0,0,0,16,0
0,0,0,0,0,0,0,0,0,0,0,0,0,0,0,0,0,0
:endlayer
layer: 3
0,0,0,27,0,0,0,27,0,0,0,0,0,0,0,0,0,0
0,0,0,3,6,7,6,3,0,30,2,0,27,0,0,0,0,0
0,0,0,6,0,14,15,6,2,29,28,2,3,22,0,0,0,0
0,0,0,7,0,7,0,3,22,0,0,0,7,0,0,0,0,0
0,27,0,6,0,0,0,6,0,0,0,23,3,22,0,0,0,0
23,3,6,3,6,6,6,3,22,0,0,0,6,0,0,0,0,0
0,6,0,21,0,0,0,6,0,0,0,0,6,0,0,0,0,0
0,7,0,0,0,0,0,3,22,0,0,23,3,22,0,0,0,0
0,6,0,0,0,27,0,6,0,0,27,0,7,0,0,0,0,0
23,3,6,7,6,3,6,3,6,6,3,6,3,6,7,6,3,22
0,21,0,0,0,2,0,21,0,0,21,0,6,0,0,0,6,0
0,0,0,0,2,26,0,0,0,0,0,23,3,22,0,0,7,0
0,0,0,0,25,24,0,0,0,0,0,0,6,0,0,0,7,0
0,0,0,0,0,2,0,0,0,0,0,0,6,0,0,0,6,0
0,0,0,0,23,3,22,0,0,0,0,23,3,6,7,6,3,22
0,0,0,0,0,6,0,0,0,0,0,0,6,0,0,0,0,0
0,0,0,0,0,3,7,3,6,6,3,7,3,0,0,0,0,0
0,0,0,0,0,21,0,21,0,0,21,0,21,0,0,0,0,0
0,0,0,0,0,0,0,0,0,0,0,0,0,0,0,0,0,0
:endlayer
layer: 4
0,0,0,0,0,0,0,0,0,0,0,0,0,0,0,0,0,0
0,0,0,3,4,4,4,3,0,0,2,0,32,31,0,0,0,0
0,0,0,5,0,0,0,5,4,4,4,4,3,31,0,0,0,0
0,0,0,5,0,7,14,5,0,0,0,0,5,31,0,0,0,0
38,38,38,5,27,0,15,5,0,0,0,0,5,31,0,0,0,0
37,3,4,3,4,4,4,3,0,0,0,0,5,31,0,0,0,0
0,5,0,0,0,0,0,5,0,0,0,0,5,31,0,0,0,0
0,5,0,0,0,0,0,5,0,0,0,0,5,31,0,0,0,0
0,5,0,0,0,0,0,5,0,0,0,0,5,38,38,38,38,38
36,3,4,4,4,4,4,4,4,4,4,4,5,4,4,4,3,37
35,35,35,35,34,5,0,0,0,0,0,0,5,0,0,0,5,0
0,0,0,0,2,5,0,0,0,0,0,0,5,0,0,0,5,0
0,0,0,0,34,5,0,0,0,0,0,0,5,0,0,0,5,0
0,0,0,0,34,5,0,0,0,0,0,0,5,0,0,0,5,0
0,0,0,0,34,5,0,0,0,0,0,0,5,4,4,4,3,36
0,0,0,0,34,5,0,0,0,0,0,0,5,31,35,35,35,35
0,0,0,0,34,3,4,4,4,4,4,4,3,31,0,0,0,0
0,0,0,0,34,33,0,0,0,0,0,0,32,31,0,0,0,0
0,0,0,0,0,0,0,0,0,0,0,0,0,0,0,0,0,0
:endlayer
layer: 5
0,0,0,0,0,0,0,0,0,0,0,0,0,0,0,0,0,0
0,0,0,3,6,6,6,3,33,0,2,32,31,0,0,0,0,0
0,0,0,6,0,0,0,6,3,6,6,3,31,0,0,0,0,0
0,0,0,6,0,7,0,6,33,0,0,32,31,0,0,0,0,0
0,0,0,6,15,14,0,6,33,0,0,32,31,0,0,0,0,0
38,38,38,3,6,6,6,3,33,0,0,32,31,0,0,0,0,0
37,3,37,37,37,37,37,3,33,0,0,32,31,0,0,0,0,0
0,6,0,0,0,0,0,6,33,0,0,32,31,0,0,0,0,0
36,3,36,36,36,36,36,3,33,0,0,32,31,0,0,0,0,0
35,35,35,35,35,34,3,6,6,6,6,3,38,38,38,38,38,38
0,0,0,0,0,34,33,0,0,0,0,32,3,37,37,37,3,37
0,0,0,0,2,34,33,0,0,0,0,32,6,0,0,0,6,0
0,0,0,0,0,34,33,0,0,0,0,32,6,0,0,0,6,0
0,0,0,0,0,34,33,0,0,0,0,32,3,36,36,36,3,36
0,0,0,0,0,34,33,0,0,0,0,32,35,35,35,35,35,35
0,0,0,0,0,34,33,0,0,0,0,32,31,0,0,0,0,0
0,0,0,0,0,34,3,6,6,6,6,3,31,0,0,0,0,0
0,0,0,0,0,34,33,0,0,0,0,32,31,0,0,0,0,0
0,0,0,0,0,0,0,0,0,0,0,0,0,0,0,0,0,0
:endlayer
layer: 6
0,0,0,0,0,0,0,0,0,0,0,0,0,0,0,0,0,0
0,0,0,3,6,7,6,3,34,33,2,31,0,0,0,0,0,0
0,0,0,6,15,0,21,6,34,4,4,31,0,0,0,0,0,0
0,0,0,7,14,7,0,6,34,33,32,31,0,0,0,0,0,0
0,0,0,6,0,0,0,6,34,33,32,31,0,0,0,0,0,0
0,0,0,3,6,6,6,3,34,33,32,31,0,0,0,0,0,0
38,38,38,38,38,38,38,38,34,33,32,31,0,0,0,0,0,0
32,3,4,4,4,4,4,3,6,33,32,31,0,0,0,0,0,0
35,35,35,35,35,35,34,6,6,33,32,31,0,0,0,0,0,0
0,0,0,0,0,0,34,3,6,6,3,31,0,0,0,0,0,0
0,0,0,0,0,0,34,33,0,0,32,38,38,38,38,38,38,38
0,0,0,0,2,0,34,33,0,0,32,6,5,37,37,37,5,37
0,0,0,0,0,0,34,33,0,0,32,6,5,36,36,36,5,36
0,0,0,0,0,0,34,33,0,0,32,35,35,35,35,35,35,35
0,0,0,0,0,0,34,33,0,0,32,31,0,0,0,0,0,0
0,0,0,0,0,0,34,33,0,0,32,31,0,0,0,0,0,0
0,0,0,0,0,0,34,3,6,6,3,31,0,0,0,0,0,0
0,0,0,0,0,0,34,33,0,0,32,31,0,0,0,0,0,0
0,0,0,0,0,0,0,0,0,0,0,0,0,0,0,0,0,0
:endlayer
layer: 7
0,0,0,0,0,0,0,0,0,0,0,0,0,0,0,0,0,0
0,0,0,3,6,7,6,3,0,34,2,0,0,0,0,0,0,0
0,0,0,6,0,14,15,6,0,34,31,0,0,0,0,0,0,0
0,0,0,7,0,7,0,6,0,34,31,0,0,0,0,0,0,0
0,0,0,6,0,0,0,6,0,34,31,0,0,0,0,0,0,0
0,0,0,3,6,6,6,3,0,34,31,0,0,0,0,0,0,0
0,0,0,0,0,0,0,0,0,34,31,0,0,0,0,0,0,0
14,14,14,14,14,14,14,14,14,34,31,0,0,0,0,0,0,0
0,0,0,0,0,0,0,34,6,6,31,0,0,0,0,0,0,0
0,0,0,0,0,0,0,34,4,4,31,0,0,0,0,0,0,0
0,0,0,0,0,0,0,34,33,32,31,0,0,0,0,0,0,0
0,0,0,0,2,0,0,34,33,32,31,38,38,38,38,38,38,38
0,0,0,0,0,0,0,34,33,32,35,35,35,35,35,35,35,35
0,0,0,0,0,0,0,34,33,32,31,0,0,0,0,0,0,0
0,0,0,0,0,0,0,34,33,32,31,0,0,0,0,0,0,0
0,0,0,0,0,0,0,34,33,32,31,0,0,0,0,0,0,0
0,0,0,0,0,0,0,34,4,4,31,0,0,0,0,0,0,0
0,0,0,0,0,0,0,34,33,32,31,0,0,0,0,0,0,0
0,0,0,0,0,0,0,0,0,0,0,0,0,0,0,0,0,0
:endlayer
layer: 8
0,0,0,0,0,0,0,0,0,0,0,0,0,0,0,0,0,0
0,0,0,3,4,4,4,3,0,0,2,0,0,0,0,0,0,0
0,0,0,5,0,0,0,5,0,0,0,0,0,0,0,0,0,0
0,0,0,5,0,7,14,5,0,0,0,0,0,0,0,0,0,0
0,0,0,5,15,15,15,5,0,0,0,0,0,0,0,0,0,0
0,0,0,3,4,4,4,3,0,0,0,0,0,0,0,0,0,0
0,0,0,0,0,0,0,0,0,0,0,0,0,0,0,0,0,0
0,0,0,0,0,0,0,0,0,0,0,0,0,0,0,0,0,0
0,0,0,0,0,0,0,0,34,31,0,0,0,0,0,0,0,0
0,0,0,0,0,0,0,0,34,31,0,0,0,0,0,0,0,0
0,0,0,0,0,0,0,0,34,31,0,0,0,0,0,0,0,0
0,0,0,0,39,0,0,0,34,31,0,0,0,0,0,0,0,0
0,0,0,0,0,0,0,0,34,31,0,0,0,0,0,0,0,0
0,0,0,0,0,0,0,0,34,31,0,0,0,0,0,0,0,0
0,0,0,0,0,0,0,0,34,31,0,0,0,0,0,0,0,0
0,0,0,0,0,0,0,0,34,31,0,0,0,0,0,0,0,0
0,0,0,0,0,0,0,0,34,31,0,0,0,0,0,0,0,0
0,0,0,0,0,0,0,0,34,31,0,0,0,0,0,0,0,0
0,0,0,0,0,0,0,0,0,0,0,0,0,0,0,0,0,0
:endlayer
layer: 9
0,0,0,0,0,0,0,0,0,0,0,0,0,0,0,0,0,0
0,0,0,3,7,7,7,3,0,0,39,0,0,0,0,0,0,0
0,0,0,7,0,0,0,7,0,0,0,0,0,0,0,0,0,0
0,0,0,7,7,7,0,7,0,0,0,0,0,0,0,0,0,0
0,0,0,7,0,0,0,7,0,0,0,0,0,0,0,0,0,0
0,0,0,3,7,7,7,3,0,0,0,0,0,0,0,0,0,0
0,0,0,0,0,0,0,0,0,0,0,0,0,0,0,0,0,0
0,0,0,0,0,0,0,0,0,0,0,0,0,0,0,0,0,0
0,0,0,0,0,0,0,0,0,0,0,0,0,0,0,0,0,0
0,0,0,0,0,0,0,0,0,0,0,0,0,0,0,0,0,0
0,0,0,0,0,0,0,0,0,0,0,0,0,0,0,0,0,0
0,0,0,0,10,0,0,0,0,0,0,0,0,0,0,0,0,0
0,0,0,0,0,0,0,0,0,0,0,0,0,0,0,0,0,0
0,0,0,0,0,0,0,0,0,0,0,0,0,0,0,0,0,0
0,0,0,0,0,0,0,0,0,0,0,0,0,0,0,0,0,0
0,0,0,0,0,0,0,0,0,0,0,0,0,0,0,0,0,0
0,0,0,0,0,0,0,0,0,0,0,0,0,0,0,0,0,0
0,0,0,0,0,0,0,0,0,0,0,0,0,0,0,0,0,0
0,0,0,0,0,0,0,0,0,0,0,0,0,0,0,0,0,0
:endlayer
layer: 10
0,0,0,0,0,0,0,0,0,0,0,0,0,0,0,0,0,0
0,0,0,7,0,0,0,7,0,0,10,0,0,0,0,0,0,0
0,0,0,0,0,0,0,0,0,0,0,0,0,0,0,0,0,0
0,0,0,0,16,7,0,0,0,0,0,0,0,0,0,0,0,0
0,0,0,0,0,0,0,0,0,0,0,0,0,0,0,0,0,0
0,0,0,7,0,0,0,7,0,0,0,0,0,0,0,0,0,0
0,0,0,0,0,0,0,0,0,0,0,0,0,0,0,0,0,0
0,0,0,0,0,0,0,0,0,0,0,0,0,0,0,0,0,0
0,0,0,0,0,0,0,0,0,0,0,0,0,0,0,0,0,0
0,0,0,0,0,0,0,0,0,0,0,0,0,0,0,0,0,0
0,0,0,0,0,0,0,0,0,0,0,0,0,0,0,0,0,0
0,0,0,0,0,0,0,0,0,0,0,0,0,0,0,0,0,0
0,0,0,0,0,0,0,0,0,0,0,0,0,0,0,0,0,0
0,0,0,0,0,0,0,0,0,0,0,0,0,0,0,0,0,0
0,0,0,0,0,0,0,0,0,0,0,0,0,0,0,0,0,0
0,0,0,0,0,0,0,0,0,0,0,0,0,0,0,0,0,0
0,0,0,0,0,0,0,0,0,0,0,0,0,0,0,0,0,0
0,0,0,0,0,0,0,0,0,0,0,0,0,0,0,0,0,0
0,0,0,0,0,0,0,0,0,0,0,0,0,0,0,0,0,0
:endlayer
layer: 11
0,0,0,0,0,0,0,0,0,0,0,0,0,0,0,0,0,0
0,0,0,7,0,0,0,7,0,0,0,0,0,0,0,0,0,0
0,0,0,0,0,0,0,0,0,0,0,0,0,0,0,0,0,0
0,0,0,0,0,7,0,0,0,0,0,0,0,0,0,0,0,0
0,0,0,0,0,0,0,0,0,0,0,0,0,0,0,0,0,0
0,0,0,7,0,0,0,7,0,0,0,0,0,0,0,0,0,0
0,0,0,0,0,0,0,0,0,0,0,0,0,0,0,0,0,0
0,0,0,0,0,0,0,0,0,0,0,0,0,0,0,0,0,0
0,0,0,0,0,0,0,0,0,0,0,0,0,0,0,0,0,0
0,0,0,0,0,0,0,0,0,0,0,0,0,0,0,0,0,0
0,0,0,0,0,0,0,0,0,0,0,0,0,0,0,0,0,0
0,0,0,0,0,0,0,0,0,0,0,0,0,0,0,0,0,0
0,0,0,0,0,0,0,0,0,0,0,0,0,0,0,0,0,0
0,0,0,0,0,0,0,0,0,0,0,0,0,0,0,0,0,0
0,0,0,0,0,0,0,0,0,0,0,0,0,0,0,0,0,0
0,0,0,0,0,0,0,0,0,0,0,0,0,0,0,0,0,0
0,0,0,0,0,0,0,0,0,0,0,0,0,0,0,0,0,0
0,0,0,0,0,0,0,0,0,0,0,0,0,0,0,0,0,0
0,0,0,0,0,0,0,0,0,0,0,0,0,0,0,0,0,0
:endlayer
layer: 12
0,0,0,0,0,0,0,0,0,0,0,0,0,0,0,0,0,0
0,0,0,14,14,14,14,14,0,0,0,0,0,0,0,0,0,0
0,0,0,14,15,15,15,14,0,0,0,0,0,0,0,0,0,0
0,0,0,14,15,7,15,14,0,0,0,0,0,0,0,0,0,0
0,0,0,14,15,15,15,14,0,0,0,0,0,0,0,0,0,0
0,0,0,14,14,14,14,14,0,0,0,0,0,0,0,0,0,0
0,0,0,0,0,0,0,0,0,0,0,0,0,0,0,0,0,0
0,0,0,0,0,0,0,0,0,0,0,0,0,0,0,0,0,0
0,0,0,0,0,0,0,0,0,0,0,0,0,0,0,0,0,0
0,0,0,0,0,0,0,0,0,0,0,0,0,0,0,0,0,0
0,0,0,0,0,0,0,0,0,0,0,0,0,0,0,0,0,0
0,0,0,0,0,0,0,0,0,0,0,0,0,0,0,0,0,0
0,0,0,0,0,0,0,0,0,0,0,0,0,0,0,0,0,0
0,0,0,0,0,0,0,0,0,0,0,0,0,0,0,0,0,0
0,0,0,0,0,0,0,0,0,0,0,0,0,0,0,0,0,0
0,0,0,0,0,0,0,0,0,0,0,0,0,0,0,0,0,0
0,0,0,0,0,0,0,0,0,0,0,0,0,0,0,0,0,0
0,0,0,0,0,0,0,0,0,0,0,0,0,0,0,0,0,0
0,0,0,0,0,0,0,0,0,0,0,0,0,0,0,0,0,0
:endlayer
layer: 13
0,0,0,0,0,0,0,0,0,0,0,0,0,0,0,0,0,0
0,0,0,0,0,0,0,0,0,0,0,0,0,0,0,0,0,0
0,0,0,0,0,16,0,0,0,0,0,0,0,0,0,0,0,0
0,0,0,0,16,14,16,0,0,0,0,0,0,0,0,0,0,0
0,0,0,0,0,16,0,0,0,0,0,0,0,0,0,0,0,0
0,0,0,0,0,0,0,0,0,0,0,0,0,0,0,0,0,0
0,0,0,0,0,0,0,0,0,0,0,0,0,0,0,0,0,0
0,0,0,0,0,0,0,0,0,0,0,0,0,0,0,0,0,0
0,0,0,0,0,0,0,0,0,0,0,0,0,0,0,0,0,0
0,0,0,0,0,0,0,0,0,0,0,0,0,0,0,0,0,0
0,0,0,0,0,0,0,0,0,0,0,0,0,0,0,0,0,0
0,0,0,0,0,0,0,0,0,0,0,0,0,0,0,0,0,0
0,0,0,0,0,0,0,0,0,0,0,0,0,0,0,0,0,0
0,0,0,0,0,0,0,0,0,0,0,0,0,0,0,0,0,0
0,0,0,0,0,0,0,0,0,0,0,0,0,0,0,0,0,0
0,0,0,0,0,0,0,0,0,0,0,0,0,0,0,0,0,0
0,0,0,0,0,0,0,0,0,0,0,0,0,0,0,0,0,0
0,0,0,0,0,0,0,0,0,0,0,0,0,0,0,0,0,0
0,0,0,0,0,0,0,0,0,0,0,0,0,0,0,0,0,0
:endlayer

#### RULES ####
rule:
plugin=vanillaBlocks
number=1
data:
JSON:{blockState:{blockName:"minecraft:grass",properties:{snowy:"false"}}}
:enddata
:endrule

rule:
plugin=vanillaBlocks
number=2
data:
JSON:{blockState:{blockName:"minecraft:cobblestone"}}
:enddata
:endrule

rule:
plugin=vanillaBlocks
number=3
data:
JSON:{blockState:{blockName:"biomesoplenty:log_1",properties:{variant:"palm",axis:"y"}}}
:enddata
:endrule

rule:
plugin=vanillaBlocks
number=4
data:
JSON:{blockState:{blockName:"biomesoplenty:log_1",properties:{variant:"palm",axis:"x"}}}
:enddata
:endrule

rule:
plugin=vanillaBlocks
number=5
data:
JSON:{blockState:{blockName:"biomesoplenty:log_1",properties:{variant:"palm",axis:"z"}}}
:enddata
:endrule

rule:
plugin=vanillaBlocks
number=6
data:
JSON:{blockState:{blockName:"biomesoplenty:planks_0",properties:{variant:"palm"}}}
:enddata
:endrule

rule:
plugin=vanillaBlocks
number=7
data:
JSON:{blockState:{blockName:"biomesoplenty:palm_fence",properties:{east:"false",south:"false",north:"false",west:"false"}}}
:enddata
:endrule

rule:
plugin=doors
number=8
data:
JSON:{blockState:{blockName:"minecraft:wooden_door",properties:{hinge:"right",half:"lower",powered:"false",facing:"north",open:"false"}}}
:enddata
:endrule

rule:
plugin=doors
number=9
data:
JSON:{blockState:{blockName:"minecraft:wooden_door",properties:{hinge:"left",half:"lower",powered:"false",facing:"north",open:"false"}}}
:enddata
:endrule

rule:
plugin=vanillaBlocks
number=10
data:
JSON:{blockState:{blockName:"minecraft:stone_slab",properties:{half:"bottom",variant:"cobblestone"}}}
:enddata
:endrule

rule:
plugin=vanillaBlocks
number=11
data:
JSON:{blockState:{blockName:"ancientwarfarestructure:fire_pit",properties:{lit:"false",variant:"log"}}}
:enddata
:endrule

rule:
plugin=doors
number=12
data:
JSON:{blockState:{blockName:"minecraft:wooden_door",properties:{hinge:"left",half:"lower",powered:"false",facing:"west",open:"false"}}}
:enddata
:endrule

rule:
plugin=doors
number=13
data:
JSON:{blockState:{blockName:"minecraft:wooden_door",properties:{hinge:"right",half:"lower",powered:"false",facing:"west",open:"false"}}}
:enddata
:endrule

rule:
plugin=vanillaBlocks
number=14
data:
JSON:{blockState:{blockName:"biomesoplenty:wood_slab_0",properties:{half:"bottom",variant:"palm"}}}
:enddata
:endrule

rule:
plugin=vanillaBlocks
number=15
data:
JSON:{blockState:{blockName:"biomesoplenty:wood_slab_0",properties:{half:"top",variant:"palm"}}}
:enddata
:endrule

rule:
plugin=vanillaBlocks
number=16
data:
JSON:{blockState:{blockName:"minecraft:torch",properties:{facing:"up"}}}
:enddata
:endrule

rule:
plugin=doors
number=17
data:
JSON:{blockState:{blockName:"minecraft:wooden_door",properties:{hinge:"right",half:"upper",powered:"false",facing:"north",open:"false"}}}
:enddata
:endrule

rule:
plugin=doors
number=18
data:
JSON:{blockState:{blockName:"minecraft:wooden_door",properties:{hinge:"left",half:"upper",powered:"false",facing:"north",open:"false"}}}
:enddata
:endrule

rule:
plugin=doors
number=19
data:
JSON:{blockState:{blockName:"minecraft:wooden_door",properties:{hinge:"left",half:"upper",powered:"false",facing:"west",open:"false"}}}
:enddata
:endrule

rule:
plugin=doors
number=20
data:
JSON:{blockState:{blockName:"minecraft:wooden_door",properties:{hinge:"right",half:"upper",powered:"false",facing:"west",open:"false"}}}
:enddata
:endrule

rule:
plugin=vanillaBlocks
number=21
data:
JSON:{blockState:{blockName:"minecraft:torch",properties:{facing:"south"}}}
:enddata
:endrule

rule:
plugin=vanillaBlocks
number=22
data:
JSON:{blockState:{blockName:"minecraft:torch",properties:{facing:"east"}}}
:enddata
:endrule

rule:
plugin=vanillaBlocks
number=23
data:
JSON:{blockState:{blockName:"minecraft:torch",properties:{facing:"west"}}}
:enddata
:endrule

rule:
plugin=vanillaBlocks
number=24
data:
JSON:{blockState:{blockName:"minecraft:stone_stairs",properties:{half:"top",shape:"straight",facing:"south"}}}
:enddata
:endrule

rule:
plugin=vanillaBlocks
number=25
data:
JSON:{blockState:{blockName:"minecraft:stone_stairs",properties:{half:"bottom",shape:"straight",facing:"north"}}}
:enddata
:endrule

rule:
plugin=vanillaBlocks
number=26
data:
JSON:{blockState:{blockName:"minecraft:stone_stairs",properties:{half:"top",shape:"straight",facing:"north"}}}
:enddata
:endrule

rule:
plugin=vanillaBlocks
number=27
data:
JSON:{blockState:{blockName:"minecraft:torch",properties:{facing:"north"}}}
:enddata
:endrule

rule:
plugin=vanillaBlocks
number=28
data:
JSON:{blockState:{blockName:"minecraft:stone_stairs",properties:{half:"top",shape:"straight",facing:"east"}}}
:enddata
:endrule

rule:
plugin=vanillaBlocks
number=29
data:
JSON:{blockState:{blockName:"minecraft:stone_stairs",properties:{half:"top",shape:"straight",facing:"west"}}}
:enddata
:endrule

rule:
plugin=vanillaBlocks
number=30
data:
JSON:{blockState:{blockName:"minecraft:stone_stairs",properties:{half:"bottom",shape:"straight",facing:"east"}}}
:enddata
:endrule

rule:
plugin=vanillaBlocks
number=31
data:
JSON:{blockState:{blockName:"biomesoplenty:palm_stairs",properties:{half:"bottom",shape:"straight",facing:"west"}}}
:enddata
:endrule

rule:
plugin=vanillaBlocks
number=32
data:
JSON:{blockState:{blockName:"biomesoplenty:palm_stairs",properties:{half:"top",shape:"straight",facing:"east"}}}
:enddata
:endrule

rule:
plugin=vanillaBlocks
number=33
data:
JSON:{blockState:{blockName:"biomesoplenty:palm_stairs",properties:{half:"top",shape:"straight",facing:"west"}}}
:enddata
:endrule

rule:
plugin=vanillaBlocks
number=34
data:
JSON:{blockState:{blockName:"biomesoplenty:palm_stairs",properties:{half:"bottom",shape:"straight",facing:"east"}}}
:enddata
:endrule

rule:
plugin=vanillaBlocks
number=35
data:
JSON:{blockState:{blockName:"biomesoplenty:palm_stairs",properties:{half:"bottom",shape:"straight",facing:"north"}}}
:enddata
:endrule

rule:
plugin=vanillaBlocks
number=36
data:
JSON:{blockState:{blockName:"biomesoplenty:palm_stairs",properties:{half:"top",shape:"straight",facing:"south"}}}
:enddata
:endrule

rule:
plugin=vanillaBlocks
number=37
data:
JSON:{blockState:{blockName:"biomesoplenty:palm_stairs",properties:{half:"top",shape:"straight",facing:"north"}}}
:enddata
:endrule

rule:
plugin=vanillaBlocks
number=38
data:
JSON:{blockState:{blockName:"biomesoplenty:palm_stairs",properties:{half:"bottom",shape:"straight",facing:"south"}}}
:enddata
:endrule

rule:
plugin=vanillaBlocks
number=39
data:
JSON:{blockState:{blockName:"minecraft:cobblestone_wall",properties:{east:"false",south:"false",north:"false",variant:"cobblestone",west:"false",up:"false"}}}
:enddata
:endrule

#### ENTITIES ####
