# Ancient Warfare Structure Template File
# Auto-generated structure template file. created on: 4/15/2023 at: 14:5:14
# Lines beginning with # denote comments

header:
version=2.11
name=SB_brewery_cave
mods=
size=14,8,15
offset=2,7,14
:endheader

#### VALIDATION ####
validation:
type=ground
structureAuthor=TheOddlySeagull
survival=true
worldGenEnabled=false
unique=false
preserveBlocks=false
preventNaturalHostileSpawns=false
selectionWeight=1
clusterValue=1
minDuplicateDistance=1
dimensionWhiteList=true
dimensionList=
biomeGroupList=
biomeWhiteList=true
biomeList=
leveling=0
fill=0
border=0
blockSwap=false
territoryName=
biomeReplacement=minecraft:
minGenerationHeight=0
maxGenerationHeight=255
:endvalidation

#### LAYERS ####
layer: 0
1,1,1,2,2,2,2,2,2,2,2,2,2,2
1,1,1,2,2,2,2,2,2,2,2,2,2,2
1,1,1,2,2,3,3,3,2,3,3,3,2,2
1,1,1,2,2,3,2,3,2,3,2,3,2,2
1,1,1,2,2,3,3,3,2,3,3,3,2,2
2,2,2,2,2,2,2,2,2,2,2,2,2,2
2,2,2,2,2,3,3,3,2,3,3,3,2,2
2,2,2,2,2,3,2,3,2,3,2,3,2,2
2,2,2,2,2,3,3,3,2,3,3,3,2,2
2,2,2,2,2,2,2,2,2,2,2,2,2,2
2,2,2,2,2,3,3,3,2,3,3,3,2,2
2,2,2,2,2,3,2,3,2,3,2,3,2,2
2,2,2,2,2,3,3,3,2,3,3,3,2,2
2,2,2,2,2,2,2,2,2,2,2,2,2,2
2,2,2,2,2,2,2,2,2,2,2,2,2,2
:endlayer
layer: 1
1,1,1,2,2,3,3,3,2,3,3,3,2,2
1,1,1,2,4,0,0,0,4,0,0,0,4,2
1,1,1,3,0,0,0,0,0,0,0,0,0,3
1,1,1,3,0,0,5,0,0,0,5,0,0,3
1,1,1,3,0,0,0,0,0,0,0,0,0,3
2,3,3,2,4,0,0,0,0,0,0,0,4,2
3,0,0,0,0,0,0,0,0,0,0,0,0,3
3,0,0,0,0,0,0,0,0,0,0,0,0,3
3,0,0,0,0,0,0,0,0,0,0,0,0,3
2,6,6,2,4,0,0,0,0,0,0,0,4,2
3,2,2,3,0,0,0,0,0,0,0,0,0,3
3,2,2,3,0,0,5,0,0,0,5,0,0,3
3,2,2,3,0,0,0,0,0,0,0,0,0,3
2,2,2,2,4,0,0,0,4,0,0,0,4,2
2,2,2,2,2,3,3,3,2,3,3,3,2,2
:endlayer
layer: 2
1,1,1,2,2,3,3,3,2,3,3,3,2,2
1,1,1,2,4,0,0,0,4,0,0,0,4,2
1,1,1,3,0,0,0,0,0,0,0,0,0,3
1,1,1,3,0,0,0,0,0,0,0,0,0,3
1,1,1,3,0,0,0,0,0,0,0,0,0,3
2,3,3,2,4,0,0,0,0,0,0,0,4,2
3,0,0,0,0,0,0,0,0,0,0,0,0,3
3,0,0,0,0,0,0,0,0,0,0,0,0,3
3,0,0,0,0,0,0,0,0,0,0,0,0,3
2,0,0,2,4,0,0,0,0,0,0,0,4,2
3,6,6,3,0,0,0,0,0,0,0,0,0,3
3,2,2,3,0,0,0,0,0,0,0,0,0,3
3,2,2,3,0,0,0,0,0,0,0,0,0,3
2,2,2,2,4,0,0,0,4,0,0,0,4,2
2,2,2,2,2,3,3,3,2,3,3,3,2,2
:endlayer
layer: 3
1,1,1,2,2,3,3,3,2,3,3,3,2,2
1,1,1,2,4,0,0,0,4,0,0,0,4,2
1,1,1,3,0,0,0,0,0,0,0,0,0,3
1,1,1,3,0,0,0,0,0,0,0,0,0,3
1,1,1,3,0,0,0,0,0,0,0,0,0,3
2,3,3,2,4,0,0,0,0,0,0,0,4,2
3,0,0,0,0,0,0,0,0,0,0,0,0,3
3,7,0,0,0,0,0,0,0,0,0,0,0,3
3,0,0,0,0,0,0,0,0,0,0,0,0,3
2,0,0,2,4,0,0,0,0,0,0,0,4,2
3,0,0,3,0,0,0,0,0,0,0,0,0,3
3,6,6,3,0,0,0,0,0,0,0,0,0,3
3,2,2,3,0,0,0,0,0,0,0,0,0,3
2,2,2,2,4,0,0,0,4,0,0,0,4,2
2,2,2,2,2,3,3,3,2,3,3,3,2,2
:endlayer
layer: 4
1,1,1,2,2,3,3,3,2,3,3,3,2,2
1,1,1,2,3,8,0,9,3,8,0,9,3,2
1,1,1,3,10,0,0,0,11,0,0,0,10,3
1,1,1,3,0,0,0,0,0,0,0,0,0,3
1,1,1,3,12,0,0,0,0,0,0,0,12,3
2,3,3,2,3,7,0,0,0,0,0,13,3,2
3,0,0,0,10,0,0,0,0,0,0,0,10,3
3,0,0,0,0,0,0,0,0,0,0,0,0,3
3,0,0,0,12,0,0,0,0,0,0,0,12,3
2,0,0,2,3,7,0,0,0,0,0,13,3,2
3,0,0,3,10,0,0,0,0,0,0,0,10,3
3,0,0,3,0,0,0,0,0,0,0,0,0,3
3,6,6,3,12,0,0,0,14,0,0,0,12,3
2,2,2,2,3,8,0,9,3,8,0,9,3,2
2,2,2,2,2,3,3,3,2,3,3,3,2,2
:endlayer
layer: 5
1,1,1,2,2,2,2,2,2,2,2,2,2,2
1,1,1,2,2,3,3,3,2,3,3,3,2,2
1,1,1,2,3,15,15,15,3,15,15,15,3,2
1,1,1,2,3,15,16,15,3,15,16,15,3,2
1,1,1,2,3,15,15,15,3,15,15,15,3,2
2,2,2,2,2,3,3,3,16,3,3,3,2,2
2,17,17,2,3,15,15,15,3,15,15,15,3,2
2,17,17,2,3,15,16,15,3,15,16,15,3,2
2,17,17,2,3,15,15,15,3,15,15,15,3,2
2,10,10,2,2,3,3,3,16,3,3,3,2,2
2,0,0,2,3,15,15,15,3,15,15,15,3,2
2,0,0,2,3,15,16,15,3,15,16,15,3,2
2,0,0,2,3,15,15,15,3,15,15,15,3,2
2,6,6,2,2,3,3,3,2,3,3,3,2,2
2,2,2,2,2,2,2,2,2,2,2,2,2,2
:endlayer
layer: 6
18,18,18,18,18,18,18,18,18,18,18,18,18,18
18,18,18,18,18,18,18,18,18,18,18,18,18,18
18,18,18,18,18,18,18,18,18,18,18,18,18,18
18,18,18,18,18,18,18,18,18,18,18,18,18,18
18,18,18,18,18,18,18,18,18,18,18,18,18,18
18,18,18,18,18,18,18,18,18,18,18,18,18,18
18,18,18,18,18,18,18,18,18,18,18,18,18,18
18,18,18,18,18,18,18,18,18,18,18,18,18,18
18,18,18,18,18,18,18,18,18,18,18,18,18,18
18,18,18,18,18,18,18,18,18,18,18,18,18,18
3,10,10,3,18,18,18,18,18,18,18,18,18,18
3,0,0,3,18,18,18,18,18,18,18,18,18,18
3,0,0,3,18,18,18,18,18,18,18,18,18,18
3,0,0,3,18,18,18,18,18,18,18,18,18,18
3,6,6,3,18,18,18,18,18,18,18,18,18,18
:endlayer
layer: 7
5,0,0,0,0,0,5,0,0,0,0,0,0,5
0,0,0,0,0,0,0,0,0,0,0,0,0,0
0,0,0,0,0,0,0,0,0,0,0,0,0,0
0,0,0,0,0,0,0,0,0,0,0,0,0,0
0,0,0,0,0,0,0,0,0,0,0,0,0,0
0,0,0,0,0,0,0,0,0,0,0,0,0,0
0,0,0,0,0,0,0,0,0,0,0,0,0,0
5,0,0,0,0,0,5,0,0,0,0,0,0,5
0,0,0,0,0,0,0,0,0,0,0,0,0,0
0,0,0,0,0,0,0,0,0,0,0,0,0,0
19,19,19,19,0,0,0,0,0,0,0,0,0,0
19,0,0,19,0,0,0,0,0,0,0,0,0,0
19,0,0,19,0,0,0,0,0,0,0,0,0,0
19,0,0,19,0,0,0,0,0,0,0,0,0,0
19,0,0,19,0,0,5,0,0,0,0,0,0,5
:endlayer

#### RULES ####
rule:
plugin=vanillaBlocks
number=1
data:
JSON:{blockState:{blockName:"minecraft:dirt",properties:{variant:"dirt",snowy:"false"}}}
:enddata
:endrule

rule:
plugin=vanillaBlocks
number=2
data:
JSON:{blockState:{blockName:"minecraft:cobblestone"}}
:enddata
:endrule

rule:
plugin=vanillaBlocks
number=3
data:
JSON:{blockState:{blockName:"minecraft:stonebrick",properties:{variant:"stonebrick"}}}
:enddata
:endrule

rule:
plugin=vanillaBlocks
number=4
data:
JSON:{blockState:{blockName:"minecraft:cobblestone_wall",properties:{east:"false",south:"false",north:"false",variant:"cobblestone",west:"false",up:"false"}}}
:enddata
:endrule

rule:
plugin=vanillaBlocks
number=5
data:
JSON:{blockState:{blockName:"minecraft:torch",properties:{facing:"up"}}}
:enddata
:endrule

rule:
plugin=vanillaBlocks
number=6
data:
JSON:{blockState:{blockName:"minecraft:stone_brick_stairs",properties:{half:"bottom",shape:"straight",facing:"south"}}}
:enddata
:endrule

rule:
plugin=vanillaBlocks
number=7
data:
JSON:{blockState:{blockName:"minecraft:torch",properties:{facing:"east"}}}
:enddata
:endrule

rule:
plugin=vanillaBlocks
number=8
data:
JSON:{blockState:{blockName:"minecraft:stone_stairs",properties:{half:"top",shape:"straight",facing:"west"}}}
:enddata
:endrule

rule:
plugin=vanillaBlocks
number=9
data:
JSON:{blockState:{blockName:"minecraft:stone_stairs",properties:{half:"top",shape:"straight",facing:"east"}}}
:enddata
:endrule

rule:
plugin=vanillaBlocks
number=10
data:
JSON:{blockState:{blockName:"minecraft:stone_stairs",properties:{half:"top",shape:"straight",facing:"north"}}}
:enddata
:endrule

rule:
plugin=vanillaBlocks
number=11
data:
JSON:{blockState:{blockName:"minecraft:torch",properties:{facing:"south"}}}
:enddata
:endrule

rule:
plugin=vanillaBlocks
number=12
data:
JSON:{blockState:{blockName:"minecraft:stone_stairs",properties:{half:"top",shape:"straight",facing:"south"}}}
:enddata
:endrule

rule:
plugin=vanillaBlocks
number=13
data:
JSON:{blockState:{blockName:"minecraft:torch",properties:{facing:"west"}}}
:enddata
:endrule

rule:
plugin=vanillaBlocks
number=14
data:
JSON:{blockState:{blockName:"minecraft:torch",properties:{facing:"north"}}}
:enddata
:endrule

rule:
plugin=vanillaBlocks
number=15
data:
JSON:{blockState:{blockName:"minecraft:stone_slab",properties:{half:"top",variant:"cobblestone"}}}
:enddata
:endrule

rule:
plugin=vanillaBlocks
number=16
data:
JSON:{blockState:{blockName:"minecraft:stone_slab",properties:{half:"top",variant:"stone"}}}
:enddata
:endrule

rule:
plugin=vanillaBlocks
number=17
data:
JSON:{blockState:{blockName:"minecraft:stone_slab",properties:{half:"top",variant:"stone_brick"}}}
:enddata
:endrule

rule:
plugin=vanillaBlocks
number=18
data:
JSON:{blockState:{blockName:"minecraft:grass",properties:{snowy:"false"}}}
:enddata
:endrule

rule:
plugin=vanillaBlocks
number=19
data:
JSON:{blockState:{blockName:"minecraft:stone_slab",properties:{half:"bottom",variant:"stone"}}}
:enddata
:endrule

#### ENTITIES ####
