# Ancient Warfare Structure Template File
# Auto-generated structure template file. created on: 4/23/2023 at: 14:16:13
# Lines beginning with # denote comments

header:
version=2.11
name=SB_T1wall_Angle_Tower_hellbark
mods=biomesoplenty
size=11,13,11
offset=2,1,10
:endheader

#### VALIDATION ####
validation:
type=ground
structureAuthor=TheOddlySeagull
survival=true
worldGenEnabled=false
unique=false
preserveBlocks=false
preventNaturalHostileSpawns=false
selectionWeight=1
clusterValue=1
minDuplicateDistance=1
dimensionWhiteList=true
dimensionList=
biomeGroupList=
biomeWhiteList=true
biomeList=
leveling=0
fill=0
border=0
blockSwap=false
territoryName=
biomeReplacement=minecraft:
minGenerationHeight=0
maxGenerationHeight=255
:endvalidation

#### LAYERS ####
layer: 0
1,1,1,1,1,1,1,1,1,2,1
1,1,1,1,1,1,1,1,1,2,1
1,1,1,1,1,1,1,1,1,2,1
1,1,1,1,1,1,1,1,1,2,1
1,1,1,1,1,1,1,1,1,2,1
1,1,3,1,1,2,2,2,2,2,1
1,1,1,1,1,2,2,2,2,2,1
1,1,1,1,1,2,2,2,2,2,1
1,1,1,1,1,2,2,2,2,2,1
2,2,2,2,2,2,2,2,2,2,1
1,1,1,1,1,1,1,1,1,1,1
:endlayer
layer: 1
0,0,0,0,0,0,0,0,0,6,5
0,11,0,0,0,0,0,0,0,7,0
0,0,0,0,0,0,0,0,0,7,0
0,0,0,0,0,0,0,0,0,7,0
0,0,0,0,0,14,13,0,0,6,5
0,0,6,0,0,6,7,7,7,6,5
0,0,0,0,0,7,0,0,12,8,0
0,0,0,0,0,0,0,11,10,8,0
0,0,0,0,0,7,0,0,9,8,0
6,7,7,7,6,6,7,7,7,6,5
4,0,0,0,4,4,0,0,0,4,0
:endlayer
layer: 2
0,0,0,0,0,0,0,0,0,6,0
0,19,0,0,0,0,0,0,0,7,0
0,0,0,0,0,0,0,0,9,7,18
0,0,0,0,0,0,0,0,0,7,0
0,0,17,0,0,0,14,13,0,6,0
0,0,6,0,0,6,7,7,7,6,0
0,0,0,0,0,7,0,0,0,7,0
0,0,0,0,0,0,0,11,0,7,18
0,0,17,0,0,7,17,10,12,7,0
6,7,7,7,6,6,16,16,16,6,0
0,0,15,0,0,0,0,15,0,0,0
:endlayer
layer: 3
0,0,0,0,0,0,0,0,10,6,0
0,0,0,0,0,0,0,0,10,7,0
0,0,0,0,0,0,0,0,10,7,0
0,0,0,0,0,0,0,0,10,7,0
0,0,0,0,0,0,0,14,13,6,0
0,0,6,10,10,6,7,7,7,6,0
0,0,10,10,10,8,18,0,0,7,0
0,0,10,10,21,8,10,11,0,7,0
10,10,10,20,10,8,12,0,0,7,0
6,7,7,7,6,6,7,12,7,6,0
0,0,0,0,0,0,0,0,0,0,0
:endlayer
layer: 4
0,0,0,0,0,0,0,0,9,6,0
0,0,0,0,0,0,0,0,0,12,0
0,0,0,0,0,0,0,0,0,14,0
0,0,0,0,0,0,0,0,0,12,0
0,0,0,0,0,0,0,0,9,6,0
0,0,6,11,11,6,16,16,16,6,0
0,0,11,0,0,0,12,10,15,7,0
0,0,11,0,0,0,0,11,0,7,0
17,0,0,0,17,0,0,0,0,7,0
6,12,22,12,6,6,7,0,7,6,0
0,0,0,0,0,0,0,0,0,0,0
:endlayer
layer: 5
0,0,0,0,0,0,0,0,0,12,0
0,0,0,0,0,0,0,0,0,0,0
0,0,0,0,0,0,0,0,0,0,0
0,0,0,0,0,0,0,0,0,0,0
0,0,0,0,0,0,0,0,0,12,0
0,0,12,0,0,6,7,12,7,6,0
0,0,0,0,0,0,0,0,12,8,0
0,0,0,0,0,0,0,11,10,8,0
0,0,0,0,0,0,0,0,9,8,0
12,0,0,0,12,6,7,10,7,6,0
0,0,0,0,0,0,0,0,0,0,0
:endlayer
layer: 6
0,0,0,0,0,0,0,0,0,0,0
0,0,0,0,0,0,0,0,0,0,0
0,0,0,0,0,0,0,0,0,0,0
0,0,0,0,0,0,0,0,0,0,0
0,0,0,0,0,0,0,0,0,0,0
0,0,0,0,0,6,7,0,7,6,0
0,0,0,0,0,23,0,0,0,7,0
0,0,0,0,0,0,0,11,0,12,0
0,0,0,0,0,20,17,10,12,7,0
0,0,0,0,0,6,16,16,16,6,0
0,0,0,0,0,0,0,0,0,0,0
:endlayer
layer: 7
0,0,0,0,0,0,0,0,0,0,0
0,0,0,0,0,0,0,0,0,0,0
0,0,0,0,0,0,0,0,0,0,0
0,0,0,0,0,0,0,0,0,0,0
0,0,0,0,0,0,0,0,0,0,0
0,0,0,0,0,6,7,10,7,6,0
0,0,0,0,0,8,18,0,0,7,0
0,0,0,0,0,8,10,11,0,0,0
0,0,0,0,0,8,12,0,0,7,0
0,0,0,0,0,6,7,12,7,6,0
0,0,0,0,0,0,0,0,0,0,0
:endlayer
layer: 8
0,0,0,0,0,0,0,0,0,0,0
0,0,0,0,0,0,0,0,0,0,0
0,0,0,0,0,0,0,0,0,0,0
0,0,0,0,0,0,0,0,0,0,0
0,0,0,0,0,0,0,0,0,0,0
0,0,0,0,0,6,16,16,16,6,0
0,0,0,0,0,7,12,10,15,7,0
0,0,0,0,0,7,0,11,0,10,0
0,0,0,0,0,7,0,0,0,7,0
0,0,0,0,0,6,7,0,7,6,0
0,0,0,0,0,0,0,0,0,0,0
:endlayer
layer: 9
0,0,0,0,0,0,0,0,0,0,0
0,0,0,0,0,0,0,0,0,0,0
0,0,0,0,0,0,0,0,0,0,0
0,0,0,0,0,0,0,0,0,0,0
0,0,0,0,0,0,0,0,0,0,0
0,0,0,0,0,6,7,7,7,6,0
0,0,0,0,0,7,0,0,12,8,0
0,0,0,0,0,7,0,11,10,8,0
0,0,0,0,0,7,0,0,9,8,0
0,0,0,0,0,6,7,10,7,6,0
0,0,0,0,0,0,0,0,0,0,0
:endlayer
layer: 10
0,0,0,0,0,0,0,0,0,0,0
0,0,0,0,0,0,0,0,0,0,0
0,0,0,0,0,0,0,0,0,0,0
0,0,0,0,0,0,0,0,0,0,0
0,0,0,0,0,20,10,10,10,20,0
0,0,0,0,21,6,16,16,16,6,13
0,0,0,0,10,8,0,0,0,8,10
0,0,0,0,10,8,0,11,0,8,10
0,0,0,0,10,8,10,10,12,8,10
0,0,0,0,21,6,16,16,16,6,13
0,0,0,0,0,23,10,10,10,23,0
:endlayer
layer: 11
0,0,0,0,0,0,0,0,0,0,0
0,0,0,0,0,0,0,0,0,0,0
0,0,0,0,0,0,0,0,0,0,0
0,0,0,0,0,0,0,0,0,0,0
0,0,0,0,0,4,12,4,12,4,0
0,0,0,0,5,12,0,0,0,12,14
0,0,0,0,12,0,0,0,0,0,12
0,0,0,0,5,0,0,11,0,0,14
0,0,0,0,12,0,0,0,0,0,12
0,0,0,0,5,12,0,0,0,12,14
0,0,0,0,0,22,12,22,12,22,0
:endlayer
layer: 12
0,0,0,0,0,0,0,0,0,0,0
0,0,0,0,0,0,0,0,0,0,0
0,0,0,0,0,0,0,0,0,0,0
0,0,0,0,0,0,0,0,0,0,0
0,0,0,0,0,0,0,0,0,0,0
0,0,0,0,0,0,0,0,0,0,0
0,0,0,0,0,0,0,0,0,0,0
0,0,0,0,0,0,0,19,0,0,0
0,0,0,0,0,0,0,0,0,0,0
0,0,0,0,0,0,0,0,0,0,0
0,0,0,0,0,0,0,0,0,0,0
:endlayer

#### RULES ####
rule:
plugin=vanillaBlocks
number=1
data:
JSON:{blockState:{blockName:"minecraft:grass",properties:{snowy:"false"}}}
:enddata
:endrule

rule:
plugin=vanillaBlocks
number=2
data:
JSON:{blockState:{blockName:"minecraft:cobblestone"}}
:enddata
:endrule

rule:
plugin=vanillaBlocks
number=3
data:
JSON:{blockState:{blockName:"minecraft:dirt",properties:{variant:"dirt",snowy:"false"}}}
:enddata
:endrule

rule:
plugin=vanillaBlocks
number=4
data:
JSON:{blockState:{blockName:"biomesoplenty:hellbark_stairs",properties:{half:"bottom",shape:"straight",facing:"north"}}}
:enddata
:endrule

rule:
plugin=vanillaBlocks
number=5
data:
JSON:{blockState:{blockName:"biomesoplenty:hellbark_stairs",properties:{half:"bottom",shape:"straight",facing:"west"}}}
:enddata
:endrule

rule:
plugin=vanillaBlocks
number=6
data:
JSON:{blockState:{blockName:"biomesoplenty:log_2",properties:{variant:"hellbark",axis:"y"}}}
:enddata
:endrule

rule:
plugin=vanillaBlocks
number=7
data:
JSON:{blockState:{blockName:"biomesoplenty:planks_0",properties:{variant:"hellbark"}}}
:enddata
:endrule

rule:
plugin=vanillaBlocks
number=8
data:
JSON:{blockState:{blockName:"biomesoplenty:log_2",properties:{variant:"hellbark",axis:"z"}}}
:enddata
:endrule

rule:
plugin=vanillaBlocks
number=9
data:
JSON:{blockState:{blockName:"minecraft:torch",properties:{facing:"west"}}}
:enddata
:endrule

rule:
plugin=vanillaBlocks
number=10
data:
JSON:{blockState:{blockName:"biomesoplenty:wood_slab_1",properties:{half:"top",variant:"hellbark"}}}
:enddata
:endrule

rule:
plugin=vanillaBlocks
number=11
data:
JSON:{blockState:{blockName:"biomesoplenty:hellbark_fence",properties:{east:"false",south:"false",north:"false",west:"false"}}}
:enddata
:endrule

rule:
plugin=vanillaBlocks
number=12
data:
JSON:{blockState:{blockName:"biomesoplenty:wood_slab_1",properties:{half:"bottom",variant:"hellbark"}}}
:enddata
:endrule

rule:
plugin=vanillaBlocks
number=13
data:
JSON:{blockState:{blockName:"biomesoplenty:hellbark_stairs",properties:{half:"top",shape:"straight",facing:"west"}}}
:enddata
:endrule

rule:
plugin=vanillaBlocks
number=14
data:
JSON:{blockState:{blockName:"biomesoplenty:hellbark_stairs",properties:{half:"bottom",shape:"straight",facing:"east"}}}
:enddata
:endrule

rule:
plugin=vanillaBlocks
number=15
data:
JSON:{blockState:{blockName:"minecraft:torch",properties:{facing:"south"}}}
:enddata
:endrule

rule:
plugin=vanillaBlocks
number=16
data:
JSON:{blockState:{blockName:"biomesoplenty:log_2",properties:{variant:"hellbark",axis:"x"}}}
:enddata
:endrule

rule:
plugin=vanillaBlocks
number=17
data:
JSON:{blockState:{blockName:"minecraft:torch",properties:{facing:"north"}}}
:enddata
:endrule

rule:
plugin=vanillaBlocks
number=18
data:
JSON:{blockState:{blockName:"minecraft:torch",properties:{facing:"east"}}}
:enddata
:endrule

rule:
plugin=vanillaBlocks
number=19
data:
JSON:{blockState:{blockName:"minecraft:torch",properties:{facing:"up"}}}
:enddata
:endrule

rule:
plugin=vanillaBlocks
number=20
data:
JSON:{blockState:{blockName:"biomesoplenty:hellbark_stairs",properties:{half:"top",shape:"straight",facing:"south"}}}
:enddata
:endrule

rule:
plugin=vanillaBlocks
number=21
data:
JSON:{blockState:{blockName:"biomesoplenty:hellbark_stairs",properties:{half:"top",shape:"straight",facing:"east"}}}
:enddata
:endrule

rule:
plugin=vanillaBlocks
number=22
data:
JSON:{blockState:{blockName:"biomesoplenty:hellbark_stairs",properties:{half:"bottom",shape:"straight",facing:"south"}}}
:enddata
:endrule

rule:
plugin=vanillaBlocks
number=23
data:
JSON:{blockState:{blockName:"biomesoplenty:hellbark_stairs",properties:{half:"top",shape:"straight",facing:"north"}}}
:enddata
:endrule

#### ENTITIES ####
