# Ancient Warfare Structure Template File
# Auto-generated structure template file. created on: 9/23/2023 at: 12:4:22
# Lines beginning with # denote comments

header:
version=2.11
name=SB_KieavarusCol_GuardTower_1_mahogany
mods=biomesoplenty
size=12,24,11
offset=2,1,10
:endheader

#### VALIDATION ####
validation:
type=ground
structureAuthor=TheOddlySeagull
survival=true
worldGenEnabled=false
unique=false
preserveBlocks=false
preventNaturalHostileSpawns=false
selectionWeight=1
clusterValue=1
minDuplicateDistance=1
dimensionWhiteList=true
dimensionList=
biomeGroupList=
biomeWhiteList=true
biomeList=
leveling=0
fill=0
border=0
blockSwap=false
territoryName=
biomeReplacement=minecraft:
minGenerationHeight=0
maxGenerationHeight=255
:endvalidation

#### LAYERS ####
layer: 0
1,1,1,1,1,1,1,1,1,1,1,1
1,1,1,1,2,1,1,1,1,1,2,1
1,2,1,2,2,2,2,2,2,2,2,2
1,1,1,1,2,3,2,3,2,2,2,1
1,1,1,1,2,2,3,2,3,3,2,1
1,1,1,1,2,2,3,3,2,3,2,1
1,1,1,1,2,2,2,3,2,3,2,1
1,1,2,2,2,2,2,3,3,3,2,1
1,2,2,2,2,2,2,2,2,2,2,2
1,4,2,4,2,1,1,1,1,1,2,1
1,4,2,4,1,1,1,1,1,1,1,1
:endlayer
layer: 1
0,0,0,0,0,0,0,0,0,0,0,0
0,0,0,0,5,0,0,0,0,0,5,0
0,5,0,5,5,6,6,6,6,6,5,5
0,0,0,0,6,3,3,2,3,3,6,0
0,0,0,0,6,3,2,2,2,2,6,0
0,0,0,0,6,2,2,2,2,3,6,0
0,0,0,0,6,2,2,2,2,2,6,0
0,0,7,7,6,2,2,2,2,3,6,0
0,5,8,5,5,6,6,6,6,6,5,5
0,0,0,0,5,0,0,0,0,0,5,0
0,0,0,0,0,0,0,0,0,0,0,0
:endlayer
layer: 2
0,0,0,0,0,0,0,0,0,0,0,0
0,0,0,0,5,0,0,0,0,0,5,0
0,5,7,5,5,9,9,9,9,9,5,5
0,10,10,11,12,2,2,2,2,2,12,0
0,13,13,11,12,2,2,2,2,2,12,0
0,13,13,11,12,2,2,2,2,2,12,0
0,11,7,7,12,2,2,2,2,2,12,0
0,7,8,6,12,2,2,2,2,2,12,0
0,5,0,5,5,9,9,9,9,9,5,5
0,0,0,0,5,0,0,0,0,0,5,0
0,0,0,0,0,0,0,0,0,0,0,0
:endlayer
layer: 3
0,0,0,0,0,0,0,0,0,0,0,0
0,0,0,0,5,14,0,0,0,15,5,0
15,5,16,5,5,6,6,6,6,6,5,5
0,16,0,0,6,6,17,0,0,0,6,18
0,16,0,0,6,8,0,0,0,0,6,0
0,16,0,0,0,0,0,0,0,0,6,0
0,16,0,0,6,0,0,0,0,0,6,0
0,16,0,0,6,0,0,0,0,0,6,19
15,5,0,5,5,6,6,6,6,6,5,5
0,0,0,0,5,14,0,0,0,15,5,0
0,0,0,0,0,0,0,0,0,0,0,0
:endlayer
layer: 4
0,0,0,0,0,0,0,0,0,0,0,0
0,0,0,0,5,0,0,0,0,0,5,0
0,16,0,5,5,6,6,6,6,6,5,5
0,0,0,0,6,0,20,17,0,0,6,0
0,0,0,0,6,0,0,0,0,0,6,0
0,0,0,0,0,0,0,0,0,0,6,0
0,0,0,0,6,0,0,0,0,0,6,0
0,0,0,0,6,0,0,0,0,0,6,0
0,16,0,5,5,6,6,6,6,6,5,5
0,0,0,0,5,0,0,0,0,0,5,0
0,0,0,0,0,0,0,0,0,0,0,0
:endlayer
layer: 5
0,0,0,0,0,0,0,0,0,0,0,0
0,0,0,0,5,0,0,0,0,0,5,0
0,16,0,5,5,6,6,6,6,6,5,5
0,0,0,15,6,0,0,20,17,0,6,0
0,0,0,0,6,0,0,0,0,0,6,0
0,0,0,0,6,14,0,0,0,15,6,0
0,0,0,0,6,0,0,0,0,0,6,0
0,0,0,15,6,0,0,19,0,0,6,0
0,16,0,5,5,6,6,6,6,6,5,5
0,0,0,0,5,0,0,0,0,0,5,0
0,0,0,0,0,0,0,0,0,0,0,0
:endlayer
layer: 6
0,0,0,0,0,0,0,0,0,0,0,0
0,0,0,0,5,0,0,0,0,0,5,0
0,21,21,5,5,9,9,9,9,9,5,5
0,21,0,0,12,0,0,0,20,17,12,0
0,21,0,0,12,6,6,6,6,6,12,0
0,21,0,0,12,13,13,13,13,13,12,0
0,21,0,0,12,6,6,6,6,6,12,0
0,21,0,0,12,13,13,13,13,13,12,0
0,21,21,5,5,9,9,9,9,9,5,5
0,0,0,0,5,0,0,0,0,0,5,0
0,0,0,0,0,0,0,0,0,0,0,0
:endlayer
layer: 7
0,0,0,0,0,0,0,0,0,0,0,0
0,0,0,0,5,0,0,0,0,0,5,0
0,0,0,5,5,6,6,6,6,6,5,5
0,0,21,21,6,7,0,0,0,0,6,0
0,0,21,0,6,8,0,0,0,0,6,0
0,0,21,0,6,0,0,0,0,0,6,0
0,0,21,0,6,0,0,0,0,0,6,0
0,0,21,21,6,0,0,0,0,0,6,0
0,0,0,5,5,6,6,6,6,6,5,5
0,0,0,0,5,0,0,0,0,0,5,0
0,0,0,0,0,0,0,0,0,0,0,0
:endlayer
layer: 8
0,0,0,0,0,0,0,0,0,0,0,0
0,0,0,0,5,0,0,0,0,0,5,0
0,0,0,5,5,6,6,16,6,6,5,5
0,0,0,0,6,0,20,0,0,0,6,0
0,0,0,21,6,0,0,0,0,0,6,0
0,0,22,21,6,0,0,0,0,0,16,0
0,0,0,21,6,0,0,0,0,0,6,0
0,0,0,0,6,0,0,0,0,0,6,0
0,0,0,5,5,6,6,16,6,6,5,5
0,0,0,0,5,0,0,0,0,0,5,0
0,0,0,0,0,0,0,0,0,0,0,0
:endlayer
layer: 9
0,0,0,0,0,0,0,0,0,0,0,0
0,0,0,0,5,0,0,0,0,0,5,0
0,0,0,5,5,6,6,6,6,6,5,5
0,0,0,0,6,0,0,20,0,0,6,0
0,0,0,0,6,0,0,0,0,0,6,0
0,0,0,0,6,14,0,0,0,15,6,0
0,0,0,0,6,0,0,0,0,0,6,0
0,0,0,0,6,0,0,19,0,0,6,0
0,0,0,5,5,6,6,6,6,6,5,5
0,0,0,0,5,0,0,0,0,0,5,0
0,0,0,0,0,0,0,0,0,0,0,0
:endlayer
layer: 10
0,0,0,0,0,0,0,0,0,0,0,0
0,0,0,0,5,0,0,0,0,0,5,0
0,0,0,5,5,9,9,9,9,9,5,5
0,0,0,0,12,0,0,0,20,13,12,0
0,0,0,0,12,6,6,6,6,6,12,0
0,0,0,0,12,13,13,13,13,13,12,0
0,0,0,0,12,6,6,6,6,6,12,0
0,0,0,0,12,13,13,13,13,13,12,0
0,0,0,5,5,9,9,9,9,9,5,5
0,0,0,0,5,0,0,0,0,0,5,0
0,0,0,0,0,0,0,0,0,0,0,0
:endlayer
layer: 11
0,0,0,0,0,0,0,0,0,0,0,0
0,0,0,0,5,0,0,0,0,0,5,0
0,0,0,5,5,6,23,6,23,6,5,5
0,0,0,0,6,0,0,0,0,0,6,0
0,0,0,0,23,0,0,0,0,0,23,0
0,0,0,0,6,0,0,0,0,0,6,0
0,0,0,0,6,7,0,0,0,0,23,0
0,0,0,0,6,6,24,0,0,0,6,0
0,0,0,5,5,6,6,6,23,6,5,5
0,0,0,0,5,0,0,0,0,0,5,0
0,0,0,0,0,0,0,0,0,0,0,0
:endlayer
layer: 12
0,0,0,0,0,0,0,0,0,0,0,0
0,0,0,0,5,0,0,0,0,0,5,0
0,0,0,5,5,6,0,6,0,6,5,5
0,0,0,0,6,0,0,0,0,0,6,0
0,0,0,0,0,0,0,0,0,0,0,0
0,0,0,0,6,7,0,0,0,0,6,0
0,0,0,0,6,8,0,0,0,0,0,0
0,0,0,0,6,0,0,0,0,0,6,0
0,0,0,5,5,6,6,6,0,6,5,5
0,0,0,0,5,0,0,0,0,0,5,0
0,0,0,0,0,0,0,0,0,0,0,0
:endlayer
layer: 13
0,0,0,0,0,0,0,0,0,0,0,0
0,0,0,0,5,0,0,0,0,0,5,0
0,0,0,5,5,6,6,6,6,6,5,5
0,0,0,0,6,0,0,18,0,0,6,0
0,0,0,0,6,7,0,0,0,0,6,0
0,0,0,0,6,8,0,0,0,15,6,0
0,0,0,0,6,0,0,0,0,0,6,0
0,0,0,0,6,0,0,19,0,0,6,0
0,0,0,5,5,6,6,6,6,6,5,5
0,0,0,0,5,0,0,0,0,0,5,0
0,0,0,0,0,0,0,0,0,0,0,0
:endlayer
layer: 14
0,0,0,0,0,0,0,0,0,0,0,0
0,0,0,13,6,13,7,13,7,13,6,13
0,0,0,6,5,9,9,9,9,9,5,6
0,0,0,13,12,17,6,13,6,13,12,13
0,0,0,11,12,8,6,13,6,13,12,17
0,0,0,13,12,0,6,13,6,13,12,13
0,0,0,11,12,0,6,13,6,13,12,17
0,0,0,13,12,0,6,13,6,13,12,13
0,0,0,6,5,9,9,9,9,9,5,6
0,0,0,13,6,13,10,13,10,13,6,13
0,0,0,0,0,0,0,0,0,0,0,0
:endlayer
layer: 15
0,0,0,0,0,0,0,0,0,0,0,0
0,0,0,5,23,23,23,5,23,23,23,5
0,0,0,23,0,0,0,0,0,0,0,23
0,0,0,23,0,0,0,0,0,0,0,23
0,0,0,23,0,0,0,0,0,0,0,23
0,0,0,5,0,0,0,22,0,0,0,5
0,0,0,23,0,0,0,0,0,0,0,23
0,0,0,23,0,0,0,0,0,0,0,23
0,0,0,23,0,0,0,0,0,0,0,23
0,0,0,5,23,23,23,5,23,23,23,5
0,0,0,0,0,0,0,0,0,0,0,0
:endlayer
layer: 16
0,0,0,0,0,0,0,0,0,0,0,0
0,0,0,5,0,0,0,5,0,0,0,5
0,0,0,0,0,0,0,0,0,0,0,0
0,0,0,0,0,0,0,0,0,0,0,0
0,0,0,0,0,0,0,0,0,0,0,0
0,0,0,5,0,0,0,0,0,0,0,5
0,0,0,0,0,0,0,0,0,0,0,0
0,0,0,0,0,0,0,0,0,0,0,0
0,0,0,0,0,0,0,0,0,0,0,0
0,0,0,5,0,0,0,5,0,0,0,5
0,0,0,0,0,0,0,0,0,0,0,0
:endlayer
layer: 17
0,0,0,0,0,0,0,0,0,0,0,0
0,0,0,5,17,0,11,5,17,0,11,5
0,0,0,10,0,0,0,0,0,0,0,10
0,0,0,0,0,0,0,0,0,0,0,0
0,0,0,7,0,0,0,0,0,0,0,7
0,0,0,5,0,0,0,0,0,0,0,5
0,0,0,10,0,0,0,0,0,0,0,10
0,0,0,0,0,0,0,0,0,0,0,0
0,0,0,7,0,0,0,0,0,0,0,7
0,0,0,5,17,0,11,5,17,0,11,5
0,0,0,0,0,0,0,0,0,0,0,0
:endlayer
layer: 18
0,0,21,21,21,21,21,21,21,21,21,21
0,0,21,5,9,9,9,9,9,9,9,5
0,0,21,12,0,0,0,18,0,0,0,12
0,0,21,12,0,0,0,0,0,0,0,12
0,0,21,12,0,0,0,0,0,0,0,12
0,0,21,12,14,0,0,0,0,0,15,12
0,0,21,12,0,0,0,0,0,0,0,12
0,0,21,12,0,0,0,0,0,0,0,12
0,0,21,12,0,0,0,19,0,0,0,12
0,0,21,5,9,9,9,9,9,9,9,5
0,0,21,21,21,21,21,21,21,21,21,21
:endlayer
layer: 19
0,0,0,0,0,0,0,0,0,0,0,0
0,0,0,21,21,21,21,21,21,21,21,21
0,0,0,21,0,0,0,0,0,0,0,21
0,0,0,21,0,0,0,0,0,0,0,21
0,0,0,21,0,0,0,0,0,0,0,21
0,0,0,21,0,0,0,0,0,0,0,21
0,0,0,21,0,0,0,0,0,0,0,21
0,0,0,21,0,0,0,0,0,0,0,21
0,0,0,21,0,0,0,0,0,0,0,21
0,0,0,21,21,21,21,21,21,21,21,21
0,0,0,0,0,0,0,0,0,0,0,0
:endlayer
layer: 20
0,0,0,0,0,0,0,0,0,0,0,0
0,0,0,22,0,0,0,0,0,0,0,22
0,0,0,0,21,21,21,21,21,21,21,0
0,0,0,0,21,0,0,0,0,0,21,0
0,0,0,0,21,0,0,0,0,0,21,0
0,0,0,0,21,0,0,0,0,0,21,0
0,0,0,0,21,0,0,0,0,0,21,0
0,0,0,0,21,0,0,0,0,0,21,0
0,0,0,0,21,21,21,21,21,21,21,0
0,0,0,22,0,0,0,0,0,0,0,22
0,0,0,0,0,0,0,0,0,0,0,0
:endlayer
layer: 21
0,0,0,0,0,0,0,0,0,0,0,0
0,0,0,0,0,0,0,0,0,0,0,0
0,0,0,0,0,0,0,22,0,0,0,0
0,0,0,0,0,21,21,21,21,21,0,0
0,0,0,0,0,21,0,0,0,21,0,0
0,0,0,0,22,21,0,0,0,21,22,0
0,0,0,0,0,21,0,0,0,21,0,0
0,0,0,0,0,21,21,21,21,21,0,0
0,0,0,0,0,0,0,22,0,0,0,0
0,0,0,0,0,0,0,0,0,0,0,0
0,0,0,0,0,0,0,0,0,0,0,0
:endlayer
layer: 22
0,0,0,0,0,0,0,0,0,0,0,0
0,0,0,0,0,0,0,0,0,0,0,0
0,0,0,0,0,0,0,0,0,0,0,0
0,0,0,0,0,0,0,0,0,0,0,0
0,0,0,0,0,0,21,21,21,0,0,0
0,0,0,0,0,0,21,0,21,0,0,0
0,0,0,0,0,0,21,21,21,0,0,0
0,0,0,0,0,0,0,0,0,0,0,0
0,0,0,0,0,0,0,0,0,0,0,0
0,0,0,0,0,0,0,0,0,0,0,0
0,0,0,0,0,0,0,0,0,0,0,0
:endlayer
layer: 23
0,0,0,0,0,0,0,0,0,0,0,0
0,0,0,0,0,0,0,0,0,0,0,0
0,0,0,0,0,0,0,0,0,0,0,0
0,0,0,0,0,0,0,0,0,0,0,0
0,0,0,0,0,0,0,0,0,0,0,0
0,0,0,0,0,0,0,21,0,0,0,0
0,0,0,0,0,0,0,0,0,0,0,0
0,0,0,0,0,0,0,0,0,0,0,0
0,0,0,0,0,0,0,0,0,0,0,0
0,0,0,0,0,0,0,0,0,0,0,0
0,0,0,0,0,0,0,0,0,0,0,0
:endlayer

#### RULES ####
rule:
plugin=vanillaBlocks
number=1
data:
JSON:{blockState:{blockName:"minecraft:grass",properties:{snowy:"false"}}}
:enddata
:endrule

rule:
plugin=vanillaBlocks
number=2
data:
JSON:{blockState:{blockName:"minecraft:cobblestone"}}
:enddata
:endrule

rule:
plugin=vanillaBlocks
number=3
data:
JSON:{blockState:{blockName:"minecraft:dirt",properties:{variant:"dirt",snowy:"false"}}}
:enddata
:endrule

rule:
plugin=vanillaBlocks
number=4
data:
JSON:{blockState:{blockName:"minecraft:stonebrick",properties:{variant:"stonebrick"}}}
:enddata
:endrule

rule:
plugin=vanillaBlocks
number=5
data:
JSON:{blockState:{blockName:"biomesoplenty:log_3",properties:{variant:"mahogany",axis:"y"}}}
:enddata
:endrule

rule:
plugin=vanillaBlocks
number=6
data:
JSON:{blockState:{blockName:"biomesoplenty:planks_0",properties:{variant:"mahogany"}}}
:enddata
:endrule

rule:
plugin=vanillaBlocks
number=7
data:
JSON:{blockState:{blockName:"biomesoplenty:mahogany_stairs",properties:{half:"top",shape:"straight",facing:"south"}}}
:enddata
:endrule

rule:
plugin=vanillaBlocks
number=8
data:
JSON:{blockState:{blockName:"biomesoplenty:mahogany_stairs",properties:{half:"bottom",shape:"straight",facing:"north"}}}
:enddata
:endrule

rule:
plugin=vanillaBlocks
number=9
data:
JSON:{blockState:{blockName:"biomesoplenty:log_3",properties:{variant:"mahogany",axis:"x"}}}
:enddata
:endrule

rule:
plugin=vanillaBlocks
number=10
data:
JSON:{blockState:{blockName:"biomesoplenty:mahogany_stairs",properties:{half:"top",shape:"straight",facing:"north"}}}
:enddata
:endrule

rule:
plugin=vanillaBlocks
number=11
data:
JSON:{blockState:{blockName:"biomesoplenty:mahogany_stairs",properties:{half:"top",shape:"straight",facing:"east"}}}
:enddata
:endrule

rule:
plugin=vanillaBlocks
number=12
data:
JSON:{blockState:{blockName:"biomesoplenty:log_3",properties:{variant:"mahogany",axis:"z"}}}
:enddata
:endrule

rule:
plugin=vanillaBlocks
number=13
data:
JSON:{blockState:{blockName:"biomesoplenty:wood_slab_1",properties:{half:"top",variant:"mahogany"}}}
:enddata
:endrule

rule:
plugin=vanillaBlocks
number=14
data:
JSON:{blockState:{blockName:"minecraft:torch",properties:{facing:"east"}}}
:enddata
:endrule

rule:
plugin=vanillaBlocks
number=15
data:
JSON:{blockState:{blockName:"minecraft:torch",properties:{facing:"west"}}}
:enddata
:endrule

rule:
plugin=vanillaBlocks
number=16
data:
JSON:{blockState:{blockName:"biomesoplenty:mahogany_fence",properties:{east:"false",south:"false",north:"false",west:"false"}}}
:enddata
:endrule

rule:
plugin=vanillaBlocks
number=17
data:
JSON:{blockState:{blockName:"biomesoplenty:mahogany_stairs",properties:{half:"top",shape:"straight",facing:"west"}}}
:enddata
:endrule

rule:
plugin=vanillaBlocks
number=18
data:
JSON:{blockState:{blockName:"minecraft:torch",properties:{facing:"south"}}}
:enddata
:endrule

rule:
plugin=vanillaBlocks
number=19
data:
JSON:{blockState:{blockName:"minecraft:torch",properties:{facing:"north"}}}
:enddata
:endrule

rule:
plugin=vanillaBlocks
number=20
data:
JSON:{blockState:{blockName:"biomesoplenty:mahogany_stairs",properties:{half:"bottom",shape:"straight",facing:"east"}}}
:enddata
:endrule

rule:
plugin=vanillaBlocks
number=21
data:
JSON:{blockState:{blockName:"minecraft:wool",properties:{color:"brown"}}}
:enddata
:endrule

rule:
plugin=vanillaBlocks
number=22
data:
JSON:{blockState:{blockName:"minecraft:torch",properties:{facing:"up"}}}
:enddata
:endrule

rule:
plugin=vanillaBlocks
number=23
data:
JSON:{blockState:{blockName:"biomesoplenty:wood_slab_1",properties:{half:"bottom",variant:"mahogany"}}}
:enddata
:endrule

rule:
plugin=vanillaBlocks
number=24
data:
JSON:{blockState:{blockName:"biomesoplenty:mahogany_stairs",properties:{half:"bottom",shape:"straight",facing:"west"}}}
:enddata
:endrule

#### ENTITIES ####
