# Ancient Warfare Structure Template File
# Auto-generated structure template file. created on: 3/19/2021 at: 17:58:59
# Lines beginning with # denote comments

header:
version=2.11
name=SB_BesiegedCol_Tent_Small_fir
mods=biomesoplenty
size=11,11,11
offset=5,0,10
:endheader

#### VALIDATION ####
validation:
type=ground
structureAuthor=TheOddlySeagull
survival=true
worldGenEnabled=false
unique=false
preserveBlocks=false
preventNaturalHostileSpawns=false
selectionWeight=1
clusterValue=1
minDuplicateDistance=1
dimensionWhiteList=true
dimensionList=
biomeGroupList=
biomeWhiteList=true
biomeList=
leveling=0
fill=0
border=0
blockSwap=false
territoryName=
biomeReplacement=minecraft:
minGenerationHeight=0
maxGenerationHeight=255
:endvalidation

#### LAYERS ####
layer: 0
0,0,0,0,0,0,0,0,0,0,0
0,0,1,2,3,2,3,2,1,0,0
0,1,3,1,0,0,0,1,3,1,0
0,2,1,0,0,0,0,0,1,2,0
0,3,0,0,0,0,0,0,0,3,0
0,2,0,0,0,4,0,0,0,2,0
0,3,0,0,0,0,0,0,0,3,0
0,2,1,0,0,0,0,0,1,2,0
0,1,3,1,0,0,0,1,3,1,0
0,0,1,2,0,0,0,2,1,0,0
0,0,0,1,0,0,0,1,0,0,0
:endlayer
layer: 1
0,0,0,0,0,0,0,0,0,0,0
0,0,1,2,3,2,3,2,1,0,0
0,1,3,1,0,0,0,1,3,1,0
0,2,1,0,0,0,0,0,1,2,0
0,3,0,0,0,0,0,0,0,3,0
0,2,0,0,0,4,0,0,0,2,0
0,3,0,0,0,0,0,0,0,3,0
0,2,1,0,0,0,0,0,1,2,0
0,1,3,1,0,0,0,1,3,1,0
0,0,1,2,0,0,0,2,1,0,0
0,0,0,1,0,0,0,1,0,0,0
:endlayer
layer: 2
0,0,0,0,1,0,1,0,0,0,0
0,0,1,2,3,1,3,2,1,0,0
0,1,3,1,0,0,0,1,3,1,0
0,2,1,0,0,0,0,0,1,2,0
1,3,0,0,0,0,0,0,0,3,1
0,1,0,0,0,4,0,0,0,1,0
1,3,0,0,0,0,0,0,0,3,1
0,2,1,0,0,0,0,0,1,2,0
0,1,3,1,0,0,0,1,3,1,0
0,0,1,2,3,0,3,2,1,0,0
0,0,0,1,0,0,0,1,0,0,0
:endlayer
layer: 3
0,0,0,0,5,6,5,0,0,0,0
0,0,1,2,3,2,3,2,1,0,0
0,1,3,1,0,0,0,1,3,1,0
0,2,1,0,0,0,0,0,1,2,0
5,3,0,0,0,0,0,0,0,3,5
6,2,0,0,0,4,0,0,0,2,6
5,3,0,0,0,0,0,0,0,3,5
0,2,1,0,0,0,0,0,1,2,0
0,1,3,1,0,0,0,1,3,1,0
0,0,1,2,3,2,3,2,1,0,0
0,0,0,5,6,6,6,5,0,0,0
:endlayer
layer: 4
0,0,0,0,0,0,0,0,0,0,0
0,0,0,0,0,2,0,0,0,0,0
0,0,0,2,3,2,3,2,0,0,0
0,0,2,1,0,0,0,1,2,0,0
0,0,3,0,0,0,0,0,3,0,0
0,2,2,0,0,4,0,0,2,2,0
0,0,3,0,0,0,0,0,3,0,0
0,0,2,1,0,0,0,1,2,0,0
0,0,0,2,3,2,3,2,0,0,0
0,0,0,0,0,2,0,0,0,0,0
0,0,0,0,0,0,0,0,0,0,0
:endlayer
layer: 5
0,0,0,0,0,0,0,0,0,0,0
0,0,0,0,0,0,0,0,0,0,0
0,0,0,0,0,7,0,0,0,0,0
0,0,0,2,3,2,3,2,0,0,0
0,0,0,3,1,0,1,3,0,0,0
0,0,7,2,0,4,0,2,7,0,0
0,0,0,3,1,0,1,3,0,0,0
0,0,0,2,3,2,3,2,0,0,0
0,0,0,0,0,7,0,0,0,0,0
0,0,0,0,0,0,0,0,0,0,0
0,0,0,0,0,0,0,0,0,0,0
:endlayer
layer: 6
0,0,0,0,0,0,0,0,0,0,0
0,0,0,0,0,0,0,0,0,0,0
0,0,0,0,0,10,0,0,0,0,0
0,0,0,0,0,2,0,0,0,0,0
0,0,0,0,3,3,3,0,0,0,0
0,0,8,2,3,4,3,2,11,0,0
0,0,0,0,3,3,3,0,0,0,0
0,0,0,0,0,2,0,0,0,0,0
0,0,0,0,0,9,0,0,0,0,0
0,0,0,0,0,0,0,0,0,0,0
0,0,0,0,0,0,0,0,0,0,0
:endlayer
layer: 7
0,0,0,0,0,0,0,0,0,0,0
0,0,0,0,0,0,0,0,0,0,0
0,0,0,0,0,0,0,0,0,0,0
0,0,0,0,0,0,0,0,0,0,0
0,0,0,0,0,3,0,0,0,0,0
0,0,0,0,3,4,3,0,0,0,0
0,0,0,0,0,3,0,0,0,0,0
0,0,0,0,0,0,0,0,0,0,0
0,0,0,0,0,0,0,0,0,0,0
0,0,0,0,0,0,0,0,0,0,0
0,0,0,0,0,0,0,0,0,0,0
:endlayer
layer: 8
0,0,0,0,0,0,0,0,0,0,0
0,0,0,0,0,0,0,0,0,0,0
0,0,0,0,0,0,0,0,0,0,0
0,0,0,0,0,0,0,0,0,0,0
0,0,0,0,0,0,0,0,0,0,0
0,0,0,0,0,7,0,0,0,0,0
0,0,0,0,0,0,0,0,0,0,0
0,0,0,0,0,0,0,0,0,0,0
0,0,0,0,0,0,0,0,0,0,0
0,0,0,0,0,0,0,0,0,0,0
0,0,0,0,0,0,0,0,0,0,0
:endlayer
layer: 9
0,0,0,0,0,0,0,0,0,0,0
0,0,0,0,0,0,0,0,0,0,0
0,0,0,0,0,0,0,0,0,0,0
0,0,0,0,0,0,0,0,0,0,0
0,0,0,0,0,0,0,0,0,0,0
0,0,0,0,0,1,0,0,0,0,0
0,0,0,0,0,0,0,0,0,0,0
0,0,0,0,0,0,0,0,0,0,0
0,0,0,0,0,0,0,0,0,0,0
0,0,0,0,0,0,0,0,0,0,0
0,0,0,0,0,0,0,0,0,0,0
:endlayer
layer: 10
0,0,0,0,0,0,0,0,0,0,0
0,0,0,0,0,0,0,0,0,0,0
0,0,0,0,0,0,0,0,0,0,0
0,0,0,0,0,0,0,0,0,0,0
0,0,0,0,0,0,0,0,0,0,0
0,0,0,0,0,1,0,0,0,0,0
0,0,0,0,0,0,0,0,0,0,0
0,0,0,0,0,0,0,0,0,0,0
0,0,0,0,0,0,0,0,0,0,0
0,0,0,0,0,0,0,0,0,0,0
0,0,0,0,0,0,0,0,0,0,0
:endlayer

#### RULES ####
rule:
plugin=vanillaBlocks
number=1
data:
JSON:{blockState:{blockName:"biomesoplenty:fir_fence",properties:{east:"false",south:"false",north:"false",west:"false"}}}
:enddata
:endrule

rule:
plugin=vanillaBlocks
number=2
data:
JSON:{blockState:{blockName:"minecraft:wool",properties:{color:"red"}}}
:enddata
:endrule

rule:
plugin=vanillaBlocks
number=3
data:
JSON:{blockState:{blockName:"minecraft:wool",properties:{color:"blue"}}}
:enddata
:endrule

rule:
plugin=vanillaBlocks
number=4
data:
JSON:{blockState:{blockName:"biomesoplenty:log_0",properties:{variant:"fir",axis:"y"}}}
:enddata
:endrule

rule:
plugin=vanillaBlocks
number=5
data:
JSON:{blockState:{blockName:"biomesoplenty:wood_slab_0",properties:{half:"bottom",variant:"fir"}}}
:enddata
:endrule

rule:
plugin=vanillaBlocks
number=6
data:
JSON:{blockState:{blockName:"biomesoplenty:wood_slab_0",properties:{half:"top",variant:"fir"}}}
:enddata
:endrule

rule:
plugin=vanillaBlocks
number=7
data:
JSON:{blockState:{blockName:"minecraft:wool",properties:{color:"black"}}}
:enddata
:endrule

rule:
plugin=vanillaBlocks
number=8
data:
JSON:{blockState:{blockName:"minecraft:torch",properties:{facing:"west"}}}
:enddata
:endrule

rule:
plugin=vanillaBlocks
number=9
data:
JSON:{blockState:{blockName:"minecraft:torch",properties:{facing:"south"}}}
:enddata
:endrule

rule:
plugin=vanillaBlocks
number=10
data:
JSON:{blockState:{blockName:"minecraft:torch",properties:{facing:"north"}}}
:enddata
:endrule

rule:
plugin=vanillaBlocks
number=11
data:
JSON:{blockState:{blockName:"minecraft:torch",properties:{facing:"east"}}}
:enddata
:endrule

#### ENTITIES ####
