# Ancient Warfare Structure Template File
# Auto-generated structure template file. created on: 3/19/2021 at: 18:4:15
# Lines beginning with # denote comments

header:
version=2.11
name=SB_BesiegedCol_Tent_Small_redwood
mods=biomesoplenty
size=11,11,11
offset=5,0,10
:endheader

#### VALIDATION ####
validation:
type=ground
structureAuthor=TheOddlySeagull
survival=true
worldGenEnabled=false
unique=false
preserveBlocks=false
preventNaturalHostileSpawns=false
selectionWeight=1
clusterValue=1
minDuplicateDistance=1
dimensionWhiteList=true
dimensionList=
biomeGroupList=
biomeWhiteList=true
biomeList=
leveling=0
fill=0
border=0
blockSwap=false
territoryName=
biomeReplacement=minecraft:
minGenerationHeight=0
maxGenerationHeight=255
:endvalidation

#### LAYERS ####
layer: 0
0,0,0,0,0,0,0,0,0,0,0
0,0,1,2,2,3,2,2,1,0,0
0,1,3,1,0,0,0,1,3,1,0
0,2,1,0,0,0,0,0,1,2,0
0,2,0,0,0,0,0,0,0,2,0
0,3,0,0,0,4,0,0,0,3,0
0,2,0,0,0,0,0,0,0,2,0
0,2,1,0,0,0,0,0,1,2,0
0,1,3,1,0,0,0,1,3,1,0
0,0,1,2,0,0,0,2,1,0,0
0,0,0,1,0,0,0,1,0,0,0
:endlayer
layer: 1
0,0,0,0,0,0,0,0,0,0,0
0,0,1,2,2,3,2,2,1,0,0
0,1,3,1,0,0,0,1,3,1,0
0,2,1,0,0,0,0,0,1,2,0
0,2,0,0,0,0,0,0,0,2,0
0,3,0,0,0,4,0,0,0,3,0
0,2,0,0,0,0,0,0,0,2,0
0,2,1,0,0,0,0,0,1,2,0
0,1,3,1,0,0,0,1,3,1,0
0,0,1,2,0,0,0,2,1,0,0
0,0,0,1,0,0,0,1,0,0,0
:endlayer
layer: 2
0,0,0,0,1,0,1,0,0,0,0
0,0,1,3,2,1,2,3,1,0,0
0,1,5,1,0,0,0,1,5,1,0
0,3,1,0,0,0,0,0,1,3,0
1,2,0,0,0,0,0,0,0,2,1
0,1,0,0,0,4,0,0,0,1,0
1,2,0,0,0,0,0,0,0,2,1
0,3,1,0,0,0,0,0,1,3,0
0,1,5,1,0,0,0,1,5,1,0
0,0,1,3,2,0,2,3,1,0,0
0,0,0,1,0,0,0,1,0,0,0
:endlayer
layer: 3
0,0,0,0,6,7,6,0,0,0,0
0,0,1,3,2,2,2,3,1,0,0
0,1,5,1,0,0,0,1,5,1,0
0,3,1,0,0,0,0,0,1,3,0
6,2,0,0,0,0,0,0,0,2,6
7,2,0,0,0,4,0,0,0,2,7
6,2,0,0,0,0,0,0,0,2,6
0,3,1,0,0,0,0,0,1,3,0
0,1,5,1,0,0,0,1,5,1,0
0,0,1,3,2,2,2,3,1,0,0
0,0,0,6,7,7,7,6,0,0,0
:endlayer
layer: 4
0,0,0,0,0,0,0,0,0,0,0
0,0,0,0,0,3,0,0,0,0,0
0,0,0,5,3,3,3,5,0,0,0
0,0,5,1,0,0,0,1,5,0,0
0,0,3,0,0,0,0,0,3,0,0
0,3,3,0,0,4,0,0,3,3,0
0,0,3,0,0,0,0,0,3,0,0
0,0,5,1,0,0,0,1,5,0,0
0,0,0,5,3,3,3,5,0,0,0
0,0,0,0,0,3,0,0,0,0,0
0,0,0,0,0,0,0,0,0,0,0
:endlayer
layer: 5
0,0,0,0,0,0,0,0,0,0,0
0,0,0,0,0,0,0,0,0,0,0
0,0,0,0,0,3,0,0,0,0,0
0,0,0,5,5,5,5,5,0,0,0
0,0,0,5,1,0,1,5,0,0,0
0,0,3,5,0,4,0,5,3,0,0
0,0,0,5,1,0,1,5,0,0,0
0,0,0,5,5,5,5,5,0,0,0
0,0,0,0,0,3,0,0,0,0,0
0,0,0,0,0,0,0,0,0,0,0
0,0,0,0,0,0,0,0,0,0,0
:endlayer
layer: 6
0,0,0,0,0,0,0,0,0,0,0
0,0,0,0,0,0,0,0,0,0,0
0,0,0,0,0,0,0,0,0,0,0
0,0,0,0,0,3,0,0,0,0,0
0,0,0,0,3,5,3,0,0,0,0
0,0,0,3,5,4,5,3,0,0,0
0,0,0,0,3,5,3,0,0,0,0
0,0,0,0,0,3,0,0,0,0,0
0,0,0,0,0,0,0,0,0,0,0
0,0,0,0,0,0,0,0,0,0,0
0,0,0,0,0,0,0,0,0,0,0
:endlayer
layer: 7
0,0,0,0,0,0,0,0,0,0,0
0,0,0,0,0,0,0,0,0,0,0
0,0,0,0,0,0,0,0,0,0,0
0,0,0,0,0,0,0,0,0,0,0
0,0,0,0,0,2,0,0,0,0,0
0,0,0,0,2,4,2,0,0,0,0
0,0,0,0,0,2,0,0,0,0,0
0,0,0,0,0,0,0,0,0,0,0
0,0,0,0,0,0,0,0,0,0,0
0,0,0,0,0,0,0,0,0,0,0
0,0,0,0,0,0,0,0,0,0,0
:endlayer
layer: 8
0,0,0,0,0,0,0,0,0,0,0
0,0,0,0,0,0,0,0,0,0,0
0,0,0,0,0,0,0,0,0,0,0
0,0,0,0,0,0,0,0,0,0,0
0,0,0,0,0,0,0,0,0,0,0
0,0,0,0,0,3,0,0,0,0,0
0,0,0,0,0,0,0,0,0,0,0
0,0,0,0,0,0,0,0,0,0,0
0,0,0,0,0,0,0,0,0,0,0
0,0,0,0,0,0,0,0,0,0,0
0,0,0,0,0,0,0,0,0,0,0
:endlayer
layer: 9
0,0,0,0,0,0,0,0,0,0,0
0,0,0,0,0,0,0,0,0,0,0
0,0,0,0,0,0,0,0,0,0,0
0,0,0,0,0,0,0,0,0,0,0
0,0,0,0,0,0,0,0,0,0,0
0,0,0,0,0,1,0,0,0,0,0
0,0,0,0,0,0,0,0,0,0,0
0,0,0,0,0,0,0,0,0,0,0
0,0,0,0,0,0,0,0,0,0,0
0,0,0,0,0,0,0,0,0,0,0
0,0,0,0,0,0,0,0,0,0,0
:endlayer
layer: 10
0,0,0,0,0,0,0,0,0,0,0
0,0,0,0,0,0,0,0,0,0,0
0,0,0,0,0,0,0,0,0,0,0
0,0,0,0,0,0,0,0,0,0,0
0,0,0,0,0,0,0,0,0,0,0
0,0,0,0,0,1,0,0,0,0,0
0,0,0,0,0,0,0,0,0,0,0
0,0,0,0,0,0,0,0,0,0,0
0,0,0,0,0,0,0,0,0,0,0
0,0,0,0,0,0,0,0,0,0,0
0,0,0,0,0,0,0,0,0,0,0
:endlayer

#### RULES ####
rule:
plugin=vanillaBlocks
number=1
data:
JSON:{blockState:{blockName:"biomesoplenty:redwood_fence",properties:{east:"false",south:"false",north:"false",west:"false"}}}
:enddata
:endrule

rule:
plugin=vanillaBlocks
number=2
data:
JSON:{blockState:{blockName:"minecraft:wool",properties:{color:"red"}}}
:enddata
:endrule

rule:
plugin=vanillaBlocks
number=3
data:
JSON:{blockState:{blockName:"minecraft:wool",properties:{color:"black"}}}
:enddata
:endrule

rule:
plugin=vanillaBlocks
number=4
data:
JSON:{blockState:{blockName:"biomesoplenty:log_2",properties:{variant:"redwood",axis:"y"}}}
:enddata
:endrule

rule:
plugin=vanillaBlocks
number=5
data:
JSON:{blockState:{blockName:"minecraft:wool",properties:{color:"orange"}}}
:enddata
:endrule

rule:
plugin=vanillaBlocks
number=6
data:
JSON:{blockState:{blockName:"biomesoplenty:wood_slab_1",properties:{half:"bottom",variant:"redwood"}}}
:enddata
:endrule

rule:
plugin=vanillaBlocks
number=7
data:
JSON:{blockState:{blockName:"biomesoplenty:wood_slab_1",properties:{half:"top",variant:"redwood"}}}
:enddata
:endrule

#### ENTITIES ####
