# Ancient Warfare Structure Template File
# Auto-generated structure template file. created on: 3/19/2021 at: 17:51:10
# Lines beginning with # denote comments

header:
version=2.11
name=SB_BesiegedCol_Tent_Small_acacia
mods=
size=11,11,11
offset=5,0,10
:endheader

#### VALIDATION ####
validation:
type=ground
structureAuthor=TheOddlySeagull
survival=true
worldGenEnabled=false
unique=false
preserveBlocks=false
preventNaturalHostileSpawns=false
selectionWeight=1
clusterValue=1
minDuplicateDistance=1
dimensionWhiteList=true
dimensionList=
biomeGroupList=
biomeWhiteList=true
biomeList=
leveling=0
fill=0
border=0
blockSwap=false
territoryName=
biomeReplacement=minecraft:
minGenerationHeight=0
maxGenerationHeight=255
:endvalidation

#### LAYERS ####
layer: 0
0,0,0,0,0,0,0,0,0,0,0
0,0,1,2,2,2,2,2,1,0,0
0,1,2,1,0,0,0,1,2,1,0
0,2,1,0,0,0,0,0,1,2,0
0,2,0,0,0,0,0,0,0,2,0
0,2,0,0,0,3,0,0,0,2,0
0,2,0,0,0,0,0,0,0,2,0
0,2,1,0,0,0,0,0,1,2,0
0,1,2,1,0,0,0,1,2,1,0
0,0,1,2,0,0,0,2,1,0,0
0,0,0,1,0,0,0,1,0,0,0
:endlayer
layer: 1
0,0,0,0,0,0,0,0,0,0,0
0,0,1,4,4,4,4,4,1,0,0
0,1,4,1,0,0,0,1,4,1,0
0,4,1,0,0,0,0,0,1,4,0
0,4,0,0,0,0,0,0,0,4,0
0,4,0,0,0,3,0,0,0,4,0
0,4,0,0,0,0,0,0,0,4,0
0,4,1,0,0,0,0,0,1,4,0
0,1,4,1,0,0,0,1,4,1,0
0,0,1,4,0,0,0,4,1,0,0
0,0,0,1,0,0,0,1,0,0,0
:endlayer
layer: 2
0,0,0,0,1,0,1,0,0,0,0
0,0,1,4,4,1,4,4,1,0,0
0,1,4,1,0,0,0,1,4,1,0
0,4,1,0,0,0,0,0,1,4,0
1,4,0,0,0,0,0,0,0,4,1
0,1,0,0,0,3,0,0,0,1,0
1,4,0,0,0,0,0,0,0,4,1
0,4,1,0,0,0,0,0,1,4,0
0,1,4,1,0,0,0,1,4,1,0
0,0,1,4,4,0,4,4,1,0,0
0,0,0,1,0,0,0,1,0,0,0
:endlayer
layer: 3
0,0,0,0,5,6,5,0,0,0,0
0,0,1,7,4,7,4,7,1,0,0
0,1,7,1,0,0,0,1,7,1,0
0,7,1,0,0,0,0,0,1,7,0
5,4,0,0,0,0,0,0,0,4,5
6,7,0,0,0,3,0,0,0,7,6
5,4,0,0,0,0,0,0,0,4,5
0,7,1,0,0,0,0,0,1,7,0
0,1,7,1,0,0,0,1,7,1,0
0,0,1,7,4,7,4,7,1,0,0
0,0,0,5,6,6,6,5,0,0,0
:endlayer
layer: 4
0,0,0,0,0,0,0,0,0,0,0
0,0,0,0,0,8,0,0,0,0,0
0,0,0,8,7,8,7,8,0,0,0
0,0,8,1,0,0,0,1,8,0,0
0,0,7,0,0,0,0,0,7,0,0
0,8,8,0,0,3,0,0,8,8,0
0,0,7,0,0,0,0,0,7,0,0
0,0,8,1,0,0,0,1,8,0,0
0,0,0,8,7,8,7,8,0,0,0
0,0,0,0,0,8,0,0,0,0,0
0,0,0,0,0,0,0,0,0,0,0
:endlayer
layer: 5
0,0,0,0,0,0,0,0,0,0,0
0,0,0,0,0,0,0,0,0,0,0
0,0,0,0,0,8,0,0,0,0,0
0,0,0,8,8,8,8,8,0,0,0
0,0,0,8,1,0,1,8,0,0,0
0,0,8,8,0,3,0,8,8,0,0
0,0,0,8,1,0,1,8,0,0,0
0,0,0,8,8,8,8,8,0,0,0
0,0,0,0,0,8,0,0,0,0,0
0,0,0,0,0,0,0,0,0,0,0
0,0,0,0,0,0,0,0,0,0,0
:endlayer
layer: 6
0,0,0,0,0,0,0,0,0,0,0
0,0,0,0,0,0,0,0,0,0,0
0,0,0,0,0,11,0,0,0,0,0
0,0,0,0,0,7,0,0,0,0,0
0,0,0,0,7,7,7,0,0,0,0
0,0,9,7,7,3,7,7,12,0,0
0,0,0,0,7,7,7,0,0,0,0
0,0,0,0,0,7,0,0,0,0,0
0,0,0,0,0,10,0,0,0,0,0
0,0,0,0,0,0,0,0,0,0,0
0,0,0,0,0,0,0,0,0,0,0
:endlayer
layer: 7
0,0,0,0,0,0,0,0,0,0,0
0,0,0,0,0,0,0,0,0,0,0
0,0,0,0,0,0,0,0,0,0,0
0,0,0,0,0,0,0,0,0,0,0
0,0,0,0,0,4,0,0,0,0,0
0,0,0,0,4,3,4,0,0,0,0
0,0,0,0,0,4,0,0,0,0,0
0,0,0,0,0,0,0,0,0,0,0
0,0,0,0,0,0,0,0,0,0,0
0,0,0,0,0,0,0,0,0,0,0
0,0,0,0,0,0,0,0,0,0,0
:endlayer
layer: 8
0,0,0,0,0,0,0,0,0,0,0
0,0,0,0,0,0,0,0,0,0,0
0,0,0,0,0,0,0,0,0,0,0
0,0,0,0,0,0,0,0,0,0,0
0,0,0,0,0,0,0,0,0,0,0
0,0,0,0,0,2,0,0,0,0,0
0,0,0,0,0,0,0,0,0,0,0
0,0,0,0,0,0,0,0,0,0,0
0,0,0,0,0,0,0,0,0,0,0
0,0,0,0,0,0,0,0,0,0,0
0,0,0,0,0,0,0,0,0,0,0
:endlayer
layer: 9
0,0,0,0,0,0,0,0,0,0,0
0,0,0,0,0,0,0,0,0,0,0
0,0,0,0,0,0,0,0,0,0,0
0,0,0,0,0,0,0,0,0,0,0
0,0,0,0,0,0,0,0,0,0,0
0,0,0,0,0,1,0,0,0,0,0
0,0,0,0,0,0,0,0,0,0,0
0,0,0,0,0,0,0,0,0,0,0
0,0,0,0,0,0,0,0,0,0,0
0,0,0,0,0,0,0,0,0,0,0
0,0,0,0,0,0,0,0,0,0,0
:endlayer
layer: 10
0,0,0,0,0,0,0,0,0,0,0
0,0,0,0,0,0,0,0,0,0,0
0,0,0,0,0,0,0,0,0,0,0
0,0,0,0,0,0,0,0,0,0,0
0,0,0,0,0,0,0,0,0,0,0
0,0,0,0,0,1,0,0,0,0,0
0,0,0,0,0,0,0,0,0,0,0
0,0,0,0,0,0,0,0,0,0,0
0,0,0,0,0,0,0,0,0,0,0
0,0,0,0,0,0,0,0,0,0,0
0,0,0,0,0,0,0,0,0,0,0
:endlayer

#### RULES ####
rule:
plugin=vanillaBlocks
number=1
data:
JSON:{blockState:{blockName:"minecraft:acacia_fence",properties:{east:"false",south:"false",north:"false",west:"false"}}}
:enddata
:endrule

rule:
plugin=vanillaBlocks
number=2
data:
JSON:{blockState:{blockName:"minecraft:wool",properties:{color:"lime"}}}
:enddata
:endrule

rule:
plugin=vanillaBlocks
number=3
data:
JSON:{blockState:{blockName:"minecraft:log2",properties:{variant:"acacia",axis:"y"}}}
:enddata
:endrule

rule:
plugin=vanillaBlocks
number=4
data:
JSON:{blockState:{blockName:"minecraft:wool",properties:{color:"yellow"}}}
:enddata
:endrule

rule:
plugin=vanillaBlocks
number=5
data:
JSON:{blockState:{blockName:"minecraft:wooden_slab",properties:{half:"bottom",variant:"acacia"}}}
:enddata
:endrule

rule:
plugin=vanillaBlocks
number=6
data:
JSON:{blockState:{blockName:"minecraft:wooden_slab",properties:{half:"top",variant:"acacia"}}}
:enddata
:endrule

rule:
plugin=vanillaBlocks
number=7
data:
JSON:{blockState:{blockName:"minecraft:wool",properties:{color:"gray"}}}
:enddata
:endrule

rule:
plugin=vanillaBlocks
number=8
data:
JSON:{blockState:{blockName:"minecraft:wool",properties:{color:"red"}}}
:enddata
:endrule

rule:
plugin=vanillaBlocks
number=9
data:
JSON:{blockState:{blockName:"minecraft:torch",properties:{facing:"west"}}}
:enddata
:endrule

rule:
plugin=vanillaBlocks
number=10
data:
JSON:{blockState:{blockName:"minecraft:torch",properties:{facing:"south"}}}
:enddata
:endrule

rule:
plugin=vanillaBlocks
number=11
data:
JSON:{blockState:{blockName:"minecraft:torch",properties:{facing:"north"}}}
:enddata
:endrule

rule:
plugin=vanillaBlocks
number=12
data:
JSON:{blockState:{blockName:"minecraft:torch",properties:{facing:"east"}}}
:enddata
:endrule

#### ENTITIES ####
