# Ancient Warfare Structure Template File
# Auto-generated structure template file. created on: 9/23/2023 at: 11:37:10
# Lines beginning with # denote comments

header:
version=2.11
name=SB_KieavarusCol_TownHall_1_redwood
mods=biomesoplenty
size=31,39,21
offset=22,1,20
:endheader

#### VALIDATION ####
validation:
type=ground
structureAuthor=TheOddlySeagull
survival=true
worldGenEnabled=false
unique=false
preserveBlocks=false
preventNaturalHostileSpawns=false
selectionWeight=1
clusterValue=1
minDuplicateDistance=1
dimensionWhiteList=true
dimensionList=
biomeGroupList=
biomeWhiteList=true
biomeList=
leveling=0
fill=0
border=0
blockSwap=false
territoryName=
biomeReplacement=minecraft:
minGenerationHeight=0
maxGenerationHeight=255
:endvalidation

#### LAYERS ####
layer: 0
1,3,1,1,1,1,1,1,1,1,3,1,1,1,1,1,3,1,1,1,1,1,1,3,1,1,1,1,1,1,1
3,3,3,3,3,3,3,3,3,3,3,3,3,3,3,3,3,3,3,3,3,3,3,3,3,1,1,1,1,1,1
1,3,3,3,3,3,3,3,4,3,4,4,3,3,4,3,4,3,4,4,4,3,3,3,1,1,1,1,1,1,1
1,3,4,4,3,3,3,3,3,4,3,3,4,4,3,3,4,3,3,4,4,3,4,3,1,1,1,1,1,1,1
3,3,4,4,3,3,3,3,3,4,4,3,4,3,4,3,3,3,4,3,3,3,4,3,3,3,3,3,3,3,1
1,3,3,3,3,4,3,4,4,4,3,3,3,3,4,3,3,4,4,4,3,3,3,3,1,3,1,1,1,3,1
1,3,3,4,3,3,3,4,3,3,4,3,3,4,3,3,3,3,3,4,3,4,3,3,1,3,1,1,1,3,1
1,3,3,4,4,4,3,4,3,4,4,4,3,3,3,3,3,4,3,3,3,4,3,3,1,3,1,1,1,3,1
3,3,4,4,4,4,3,4,3,3,4,4,3,4,3,4,4,3,4,3,3,3,3,3,1,3,1,1,1,3,1
1,3,4,3,3,4,3,3,4,3,3,3,3,4,4,4,3,3,4,4,3,3,3,3,1,3,1,1,1,3,1
1,3,4,4,3,3,3,3,3,3,3,3,4,4,4,4,4,4,4,3,3,3,3,3,1,3,1,1,1,3,1
1,3,4,4,4,4,3,3,3,3,4,3,4,4,3,3,4,4,4,3,3,3,3,3,1,3,1,1,1,3,1
3,3,3,3,3,3,4,3,4,4,3,4,4,4,3,4,4,4,4,3,3,4,3,3,3,3,3,3,3,3,1
1,3,3,4,3,3,3,3,3,3,3,3,3,3,4,4,3,3,3,4,3,4,4,3,1,1,1,1,1,1,1
1,3,3,3,4,4,3,3,3,3,3,4,3,3,3,4,4,3,3,4,3,3,4,3,1,1,1,1,1,1,1
3,3,3,3,3,3,3,3,3,3,3,3,3,3,3,3,3,3,3,3,3,3,3,3,3,1,1,1,1,1,1
1,3,1,1,1,1,1,1,1,1,3,1,1,1,1,1,3,1,1,3,3,3,3,3,2,1,1,1,1,1,1
1,1,1,1,1,1,1,1,1,1,1,1,1,1,1,1,1,1,1,3,3,3,3,3,2,1,1,1,1,1,1
1,1,1,1,1,1,1,1,1,1,1,1,1,1,1,1,1,1,1,3,3,3,3,3,2,1,1,1,1,1,1
1,1,1,1,1,1,1,1,1,1,3,1,1,1,1,1,3,1,1,1,3,3,3,3,2,1,1,1,1,1,1
1,1,1,1,1,1,1,1,1,1,1,1,1,1,1,1,1,1,1,1,2,3,3,3,2,1,1,1,1,1,1
:endlayer
layer: 1
0,5,0,0,0,0,0,0,0,0,5,0,0,0,0,0,5,0,0,0,0,0,0,5,0,0,0,0,0,0,0
5,5,9,9,5,9,9,5,9,9,5,9,9,9,9,9,5,9,9,9,9,9,9,5,5,0,0,0,0,0,0
0,9,3,3,3,4,4,3,4,3,4,3,4,4,3,4,3,4,3,3,3,4,3,9,0,0,0,0,0,0,0
0,9,3,3,4,3,4,4,4,3,4,3,4,4,3,3,4,3,4,4,4,3,4,9,0,0,0,0,0,0,0
5,5,4,4,3,4,4,4,4,3,3,4,3,3,3,4,3,4,4,3,4,3,4,5,9,5,0,0,0,5,0
0,9,3,3,4,3,5,4,3,4,4,3,3,3,4,4,4,4,3,3,5,4,3,9,0,9,0,0,0,0,0
0,9,3,3,3,4,4,3,3,3,3,3,3,3,4,3,4,3,4,3,4,3,4,9,0,9,0,0,0,0,0
0,9,4,3,4,3,3,3,3,4,3,3,3,4,4,3,3,3,3,4,3,4,3,9,0,9,0,0,0,0,0
5,5,4,3,4,3,4,4,3,3,3,4,3,4,4,3,4,3,4,3,4,4,4,5,0,5,0,0,0,5,0
0,9,3,4,3,3,3,3,3,4,4,4,4,3,3,3,4,3,4,3,3,4,3,9,0,9,0,0,0,0,0
0,9,4,4,3,3,3,4,4,4,4,3,4,4,4,3,4,3,3,3,3,3,4,9,0,9,0,0,0,0,0
0,9,4,3,3,4,5,3,3,4,3,3,3,4,4,4,4,4,4,4,5,3,4,9,0,9,0,0,0,0,0
5,5,4,4,3,3,4,3,4,4,3,4,3,3,3,3,3,4,3,4,4,3,3,5,9,5,0,0,0,5,0
0,9,3,4,4,3,3,4,4,3,4,3,3,4,4,4,3,4,4,3,3,3,4,9,0,0,0,0,0,0,0
0,9,4,4,3,4,4,3,4,3,3,4,3,4,3,3,4,4,3,4,4,3,3,9,0,0,0,0,0,0,0
5,5,9,9,5,9,9,5,9,9,5,9,9,9,9,9,5,9,9,9,9,9,9,5,5,0,0,0,0,0,0
0,5,0,0,0,0,0,0,0,0,5,0,0,0,0,0,5,0,0,8,7,0,0,5,0,0,0,0,0,0,0
0,0,0,0,0,0,0,0,0,0,0,0,0,0,0,0,0,0,0,8,7,0,0,0,0,0,0,0,0,0,0
0,0,0,0,0,0,0,0,0,0,0,0,0,0,0,0,0,0,0,8,7,0,0,0,0,0,0,6,0,0,0
0,0,0,0,0,6,0,0,0,0,5,0,0,0,0,0,5,0,0,0,5,0,0,0,0,0,0,0,0,0,0
0,0,0,0,0,0,0,0,0,0,0,0,0,0,0,0,0,0,0,0,0,0,0,0,0,0,0,0,0,0,0
:endlayer
layer: 2
0,5,0,0,0,0,0,0,0,0,5,0,0,0,0,0,5,0,0,0,0,0,0,5,0,0,0,0,0,0,0
5,5,14,14,14,14,14,14,14,14,5,14,14,14,14,14,5,14,14,14,14,14,14,5,5,0,0,0,0,0,0
0,12,9,9,9,9,9,9,9,12,9,9,9,9,9,9,9,12,9,9,9,9,9,12,0,0,0,0,0,0,0
0,12,9,9,9,9,9,9,12,9,9,9,9,9,9,9,9,9,12,9,9,9,9,12,0,0,0,0,0,0,0
5,12,14,14,14,14,14,12,9,9,9,9,9,9,9,9,9,9,9,12,14,14,14,5,14,5,14,14,14,5,0
0,12,9,9,9,9,5,9,9,9,9,9,9,9,9,9,9,9,9,9,5,9,9,12,9,12,10,10,10,12,0
0,12,9,9,9,9,12,9,9,9,9,5,9,9,9,5,9,9,9,9,12,9,9,12,9,12,9,9,9,12,0
0,12,9,9,9,9,12,9,9,9,9,9,9,9,9,9,9,9,9,9,12,9,9,12,9,12,10,10,10,12,0
5,12,9,9,9,9,12,9,9,9,9,9,9,9,9,9,9,9,9,9,12,9,9,12,9,12,9,9,9,5,0
0,12,9,9,9,9,12,9,9,9,9,9,9,9,9,9,9,9,9,9,12,9,9,12,9,12,10,10,10,12,0
0,12,9,9,9,9,12,9,9,9,9,5,9,9,9,5,9,9,9,9,12,9,9,12,9,12,9,9,9,12,0
0,12,9,9,9,9,5,9,9,9,9,9,9,9,9,9,9,9,9,9,5,9,9,12,9,12,10,10,10,12,0
5,12,14,14,14,14,14,12,9,9,9,9,9,9,9,9,9,9,9,12,14,14,14,5,14,5,14,14,14,5,0
0,12,9,9,9,9,9,9,12,9,9,9,9,9,9,9,9,9,12,9,9,9,9,12,0,0,0,0,0,0,0
0,12,9,9,9,9,9,9,9,12,9,9,9,9,9,9,9,12,9,9,9,9,9,12,0,0,0,0,0,0,0
5,5,14,14,14,14,14,14,14,14,5,14,14,14,14,14,5,14,14,14,14,14,14,5,5,0,0,0,0,0,0
0,5,0,0,0,0,0,0,0,0,5,13,13,13,13,13,5,13,13,7,0,0,0,5,0,0,0,0,0,0,0
0,0,0,0,0,0,0,0,0,0,12,10,10,10,10,10,12,10,8,7,0,0,0,0,0,0,0,0,0,0,0
0,0,0,0,0,0,0,0,0,0,12,10,10,10,10,10,12,10,8,7,0,0,0,0,0,0,0,0,0,0,0
0,0,0,0,0,0,0,0,0,0,5,11,10,9,10,8,5,11,10,8,5,0,0,0,0,0,0,0,0,0,0
0,0,0,0,0,0,0,0,0,0,0,0,0,0,0,0,0,0,0,0,0,0,0,0,0,0,0,0,0,0,0
:endlayer
layer: 3
0,5,18,0,0,0,0,0,0,17,5,18,0,0,0,17,5,18,0,0,0,0,17,5,0,0,0,0,0,0,0
5,5,9,9,9,9,9,9,9,9,5,9,9,9,9,9,5,9,9,9,9,9,9,5,5,0,0,0,0,0,0
0,9,0,0,0,0,0,0,0,0,0,0,0,0,8,7,0,0,0,0,0,0,0,9,15,0,0,0,0,0,0
19,9,0,0,0,0,0,0,0,0,0,0,0,0,8,7,0,0,0,0,0,0,0,9,0,0,0,0,0,19,0
5,5,0,0,0,0,0,0,0,0,0,0,0,0,0,0,0,0,0,0,0,0,0,5,9,5,16,16,16,5,18
15,9,0,0,0,0,5,0,0,0,0,0,0,0,0,0,0,0,0,0,5,0,0,0,0,9,0,0,0,16,0
0,9,0,0,0,0,0,0,0,0,0,5,0,0,0,5,0,0,0,0,0,0,0,0,0,5,0,0,0,16,0
19,9,0,0,0,0,0,0,0,0,0,0,0,0,0,0,0,0,0,0,0,0,0,0,0,0,0,0,0,16,0
5,5,0,0,0,0,0,0,0,0,0,0,0,0,0,0,0,0,0,0,0,0,6,0,0,0,0,0,0,5,18
15,9,0,0,0,0,0,0,0,0,0,0,0,0,0,0,0,0,0,0,0,0,0,0,0,0,0,0,0,16,0
0,9,0,0,0,0,0,0,0,0,0,5,0,0,0,5,0,0,0,0,0,0,0,0,0,5,0,0,0,16,0
19,9,0,0,0,0,5,0,0,0,0,0,0,0,0,0,0,0,0,0,5,0,0,0,0,9,0,0,0,16,0
5,5,0,0,0,0,0,0,0,0,0,0,0,0,0,0,0,0,0,0,0,0,0,5,9,5,16,16,16,5,18
15,9,0,0,0,0,0,0,0,0,0,0,0,0,0,0,0,0,0,0,0,0,0,9,0,0,0,0,0,15,0
0,9,0,0,0,0,0,0,0,0,0,0,0,0,0,0,0,0,0,0,0,0,0,9,0,0,0,0,0,0,0
5,5,9,9,9,9,9,9,9,9,5,0,0,0,0,0,5,9,9,9,9,9,9,5,5,0,0,0,0,0,0
0,5,18,0,0,0,0,0,0,17,5,0,0,0,0,0,5,0,0,0,0,0,0,5,0,0,0,0,0,0,0
0,0,0,0,0,0,0,0,0,0,16,0,0,0,0,0,0,0,0,0,0,0,0,0,0,0,0,0,0,0,0
0,0,0,0,0,0,0,0,0,0,16,0,0,0,0,0,0,0,0,0,0,0,0,0,0,0,0,0,0,0,0
0,0,0,0,0,0,0,0,0,0,5,16,16,16,16,16,5,16,16,16,5,0,0,0,0,0,0,0,0,0,0
0,0,0,0,0,0,0,0,0,0,15,0,0,0,0,0,15,0,0,0,15,0,0,0,0,0,0,0,0,0,0
:endlayer
layer: 4
0,5,0,0,0,0,0,0,0,0,5,0,0,0,0,0,5,0,0,0,0,0,0,5,0,0,0,0,0,0,0
5,5,9,9,16,9,9,16,9,9,5,9,16,9,16,9,5,9,9,16,16,9,9,5,5,0,0,0,0,0,0
0,9,0,0,0,0,0,0,0,0,0,0,0,8,7,0,0,0,0,0,0,0,0,9,0,0,0,0,0,0,0
0,9,0,0,0,0,0,0,0,0,0,0,0,8,7,0,0,0,0,0,0,0,0,9,0,0,0,0,0,0,0
5,5,0,0,0,0,0,0,0,0,0,0,0,0,0,0,0,0,0,0,0,0,0,5,9,5,0,0,0,5,0
0,9,0,0,0,0,5,0,0,0,0,0,0,0,0,0,0,0,0,0,5,0,0,0,0,9,0,0,0,0,0
0,16,0,0,0,0,0,0,0,0,0,5,0,0,0,5,0,0,0,0,0,0,0,0,0,5,0,0,0,0,0
0,9,0,0,0,0,0,0,0,0,0,0,0,0,0,0,0,0,0,0,0,0,0,0,0,0,0,0,0,0,0
5,5,0,0,0,0,0,0,0,0,0,0,0,0,0,0,0,0,0,0,0,0,0,0,0,0,0,0,0,5,0
0,9,0,0,0,0,0,0,0,0,0,0,0,0,0,0,0,0,0,0,0,0,0,0,0,0,0,0,0,0,0
0,16,0,0,0,0,0,0,0,0,0,5,0,0,0,5,0,0,0,0,0,0,0,0,0,5,0,0,0,0,0
0,9,0,0,0,0,5,0,0,0,0,0,0,0,0,0,0,0,0,0,5,0,0,0,0,9,0,0,0,0,0
5,5,0,0,0,0,0,0,0,0,0,0,0,0,0,0,0,0,0,0,0,0,0,5,9,5,0,0,0,5,0
0,9,0,0,0,0,0,0,0,0,0,0,0,0,0,0,0,0,0,0,0,0,0,9,0,0,0,0,0,0,0
0,9,0,0,0,0,0,0,0,0,0,0,0,0,0,0,0,0,0,0,0,0,0,9,19,0,0,0,0,0,0
5,5,9,9,16,9,9,16,9,9,5,0,0,0,0,0,5,9,9,16,16,9,9,5,5,0,0,0,0,0,0
0,5,0,0,0,0,0,0,0,0,5,0,0,0,0,0,5,0,0,0,0,0,0,5,0,0,0,0,0,0,0
0,0,0,0,0,0,0,0,0,0,0,0,0,0,0,0,0,0,0,0,0,0,0,0,0,0,0,0,0,0,0
0,0,0,0,0,0,0,0,0,0,0,0,0,0,0,0,0,0,0,0,0,0,0,0,0,0,0,0,0,0,0
0,0,0,0,0,0,0,0,0,0,16,0,0,0,0,0,16,0,0,0,16,0,0,0,0,0,0,0,0,0,0
0,0,0,0,0,0,0,0,0,0,0,0,0,0,0,0,0,0,0,0,0,0,0,0,0,0,0,0,0,0,0
:endlayer
layer: 5
0,5,0,0,0,0,0,0,0,0,5,0,0,0,0,0,5,0,0,0,0,0,0,5,0,0,0,0,0,0,0
5,5,9,9,9,9,9,9,9,9,5,9,9,9,9,9,5,9,9,9,9,9,9,5,5,0,0,0,0,0,0
0,9,0,0,0,15,0,0,0,10,15,0,8,7,0,0,15,10,0,0,0,0,0,9,0,0,0,0,0,0,0
0,9,0,0,0,0,0,0,10,0,0,0,8,7,0,0,0,0,10,0,0,0,0,9,0,0,0,0,0,0,0
5,5,18,0,0,0,0,10,0,0,0,0,0,0,0,0,0,0,0,10,0,0,17,5,9,5,11,10,8,5,0
0,9,0,0,0,0,5,18,0,0,0,19,0,0,0,19,0,0,0,17,5,0,0,9,0,9,0,0,0,13,0
0,9,0,0,0,0,13,0,0,0,17,5,0,0,0,5,18,0,0,0,13,0,0,10,17,5,0,0,0,10,0
0,9,0,0,0,0,10,0,0,0,0,0,0,0,0,0,0,0,0,0,10,0,0,0,0,13,0,0,0,20,0
5,5,18,0,0,0,10,0,0,0,0,0,0,0,0,0,0,0,0,0,10,0,0,0,0,10,0,0,17,5,0
0,9,0,0,0,0,10,0,0,0,0,0,0,0,0,0,0,0,0,0,10,0,0,0,0,20,0,0,0,13,0
0,9,0,0,0,0,20,0,0,0,17,5,0,0,0,5,18,0,0,0,20,0,0,10,17,5,0,0,0,10,0
0,9,0,0,0,0,5,18,0,0,0,15,0,0,0,15,0,0,0,17,5,0,0,9,0,9,0,0,0,20,0
5,5,18,0,0,0,0,10,0,0,0,0,0,0,0,0,0,0,0,10,0,0,17,5,9,5,11,10,8,5,0
0,9,0,0,0,0,0,0,10,0,0,0,0,0,0,0,0,0,10,0,0,0,0,9,0,0,0,0,0,0,0
0,9,0,0,0,19,0,0,0,10,19,0,0,0,0,0,19,10,0,0,0,0,0,9,0,0,0,0,0,0,0
5,5,9,9,9,9,9,9,9,9,5,11,10,10,10,8,5,9,9,9,9,9,9,5,5,0,0,0,0,0,0
0,5,0,0,0,0,0,0,0,0,5,18,0,0,0,17,5,18,0,0,0,0,17,5,0,0,0,0,0,0,0
0,0,0,0,0,0,0,0,0,0,0,0,0,0,0,0,0,0,0,0,0,0,0,0,0,0,0,0,0,0,0
0,0,0,0,0,0,0,0,0,0,0,0,0,0,0,0,0,0,0,0,0,0,0,0,0,0,0,0,0,0,0
0,0,0,0,0,0,0,0,0,0,16,0,0,0,0,0,16,0,0,0,16,0,0,0,0,0,0,0,0,0,0
0,0,0,0,0,0,0,0,0,0,0,0,0,0,0,0,0,0,0,0,0,0,0,0,0,0,0,0,0,0,0
:endlayer
layer: 6
21,21,21,21,21,21,21,21,21,21,5,0,0,0,0,0,5,0,0,0,0,0,0,5,0,0,0,0,0,0,0
5,5,14,14,14,14,14,14,14,14,5,14,14,14,14,14,5,14,14,14,14,14,14,5,5,0,0,0,0,0,0
0,12,10,9,10,9,10,9,10,5,10,9,7,0,0,0,0,5,10,10,10,9,10,12,0,0,0,0,0,0,0
0,12,10,9,10,9,10,9,5,10,10,9,7,0,0,0,0,8,5,10,10,9,10,12,21,21,21,21,21,21,21
5,12,10,9,10,9,10,5,10,9,10,9,9,20,20,20,20,20,10,5,10,9,10,12,14,14,14,14,14,5,0
0,12,14,14,14,14,5,10,10,10,9,9,9,9,9,9,9,10,10,10,5,14,14,12,10,12,10,10,10,12,0
0,12,10,10,10,10,12,9,9,9,9,5,0,15,0,5,9,9,9,9,12,10,10,12,9,12,9,9,9,12,0
0,12,9,9,9,9,12,10,10,10,9,0,0,0,0,0,9,10,10,10,12,9,9,12,10,12,10,10,10,12,0
5,12,10,10,10,10,12,9,9,9,9,18,0,0,0,17,9,9,9,9,12,10,10,12,9,12,9,9,9,12,0
0,12,9,9,9,9,12,10,10,10,9,0,0,0,0,0,9,10,10,10,12,9,9,12,10,12,10,10,10,12,0
0,12,10,10,10,10,12,9,9,9,9,5,0,19,0,5,9,9,9,9,12,10,10,12,9,12,9,9,9,12,0
0,12,14,14,14,14,5,10,10,10,9,9,9,9,9,9,9,10,10,10,5,14,14,12,10,12,10,10,10,12,0
5,12,10,9,10,9,10,5,10,9,10,9,10,9,10,9,10,9,10,5,10,9,10,12,14,14,14,14,14,5,0
0,12,10,9,10,9,10,9,5,10,10,9,10,9,10,9,10,10,5,10,10,9,10,12,21,21,21,21,21,21,21
0,12,10,9,10,9,10,9,10,5,10,9,10,9,10,9,10,5,10,10,10,9,10,12,0,0,0,0,0,0,0
5,5,14,14,14,14,14,14,14,14,5,14,14,14,14,14,5,14,14,14,14,14,14,5,5,0,0,0,0,0,0
21,21,21,21,21,21,21,21,21,21,5,0,0,0,0,0,5,0,0,0,0,0,0,5,0,0,0,0,0,0,0
0,0,0,0,0,0,0,0,0,0,0,0,0,0,0,0,0,0,0,0,0,0,0,0,0,0,0,0,0,0,0
0,0,0,0,0,0,0,0,0,0,21,21,21,21,21,21,21,21,21,21,21,0,0,0,0,0,0,0,0,0,0
0,0,0,0,0,0,0,0,0,0,21,21,21,21,21,21,21,21,21,21,21,0,0,0,0,0,0,0,0,0,0
0,0,0,0,0,0,0,0,0,0,0,0,0,0,0,0,0,0,0,0,0,0,0,0,0,0,0,0,0,0,0
:endlayer
layer: 7
0,0,0,0,0,0,0,0,0,0,5,0,0,0,0,0,5,0,0,0,0,0,0,5,0,0,0,0,0,0,0
21,21,21,21,21,21,21,21,21,21,5,9,9,9,9,9,5,9,9,9,9,9,9,5,5,0,0,0,0,0,0
0,9,0,0,0,0,0,0,0,9,0,0,0,0,0,0,0,0,0,0,0,0,0,9,0,0,0,0,0,0,0
0,9,0,0,0,0,0,0,9,0,0,0,0,0,0,0,0,0,0,0,0,0,0,9,0,0,0,0,0,0,0
5,5,0,0,0,0,0,9,0,0,0,0,0,0,0,0,0,0,0,0,0,0,0,9,21,21,21,21,21,21,21
0,9,0,0,0,0,5,0,0,0,0,16,16,16,16,16,0,0,0,0,5,0,0,5,5,0,0,0,0,9,0
0,9,0,0,0,0,0,0,0,0,16,5,0,0,0,5,16,0,0,0,0,0,0,0,0,0,0,0,0,9,0
0,9,0,0,0,0,0,0,0,0,16,0,0,0,0,0,16,0,0,0,0,0,0,0,0,0,0,0,0,9,0
5,5,0,0,0,0,0,0,0,0,16,0,0,0,0,0,16,0,0,0,0,0,0,0,0,0,0,0,0,9,0
0,9,0,0,0,0,0,0,0,0,16,0,0,0,0,0,16,0,0,0,0,0,0,0,0,0,0,0,0,9,0
0,9,0,0,0,0,0,0,0,0,16,5,0,0,0,5,16,0,0,0,0,0,0,0,0,0,0,0,0,9,0
0,9,0,0,0,0,5,0,0,0,0,16,16,16,16,16,0,0,0,0,5,0,0,5,5,0,0,0,0,9,0
5,5,0,0,0,0,0,9,0,0,0,0,0,0,0,0,0,0,0,0,0,0,0,9,21,21,21,21,21,21,21
0,9,0,0,0,0,0,0,9,0,0,0,0,0,8,7,0,0,0,0,0,0,0,9,0,0,0,0,0,0,0
0,9,0,0,0,0,0,0,0,9,0,0,0,0,8,7,0,0,0,0,0,0,0,9,0,0,0,0,0,0,0
21,21,21,21,21,21,21,21,21,21,5,9,9,9,9,9,5,9,9,9,9,9,9,5,5,0,0,0,0,0,0
0,0,0,0,0,0,0,0,0,0,5,21,21,21,21,21,5,21,21,21,21,0,0,5,0,0,0,0,0,0,0
0,0,0,0,0,0,0,0,0,0,21,21,21,21,21,21,21,21,21,21,21,0,0,0,0,0,0,0,0,0,0
0,0,0,0,0,0,0,0,0,0,0,0,0,0,0,0,0,0,0,0,0,0,0,0,0,0,0,0,0,0,0
0,0,0,0,0,0,0,0,0,0,0,0,0,0,0,0,0,0,0,0,0,0,0,0,0,0,0,0,0,0,0
0,0,0,0,0,0,0,0,0,0,0,0,0,0,0,0,0,0,0,0,0,0,0,0,0,0,0,0,0,0,0
:endlayer
layer: 8
0,0,0,0,0,0,0,0,0,0,5,0,0,0,0,0,5,0,0,0,0,0,0,5,0,0,0,0,0,0,0
0,0,0,0,0,0,0,0,0,0,5,9,16,9,16,9,5,9,9,16,16,9,9,5,5,0,0,0,0,0,0
21,21,21,21,21,21,21,21,21,9,0,0,0,0,0,0,0,0,0,0,0,0,0,9,0,0,0,0,0,0,0
0,9,0,0,0,0,0,0,9,0,0,0,0,0,0,0,0,0,0,0,0,0,0,16,0,0,0,0,0,0,0
5,5,0,0,0,0,17,9,0,0,0,0,0,0,0,0,0,0,0,0,0,0,0,9,0,0,0,0,0,0,0
0,9,0,0,0,0,5,0,0,0,0,0,0,0,0,0,0,0,0,0,5,0,0,5,5,21,21,21,21,21,21
0,16,0,0,0,0,0,0,0,0,0,5,0,0,0,5,0,0,0,0,0,0,0,13,0,0,0,0,0,9,10
0,9,0,0,0,0,0,0,0,0,0,0,0,0,0,0,0,0,0,0,0,0,0,0,0,0,0,0,0,9,0
5,5,0,0,0,0,0,0,0,0,0,0,0,0,0,0,0,0,0,0,0,0,0,0,0,0,0,0,0,16,0
0,9,0,0,0,0,0,0,0,0,0,0,0,0,0,0,0,0,0,0,0,0,0,0,0,0,0,0,0,9,0
0,16,0,0,0,0,0,0,0,0,0,5,0,0,0,5,0,0,0,0,0,0,0,20,0,0,0,0,0,9,10
0,9,0,0,0,0,5,0,0,0,0,0,0,0,0,0,0,0,0,0,5,0,0,5,5,21,21,21,21,21,21
5,5,0,0,0,0,17,9,0,0,0,0,0,0,0,0,0,0,0,0,0,0,0,9,0,0,0,0,0,0,0
0,9,0,0,0,0,0,0,9,0,0,0,0,8,7,0,0,0,0,0,0,0,0,16,0,0,0,0,0,0,0
21,21,21,21,21,21,21,21,21,9,0,0,0,8,7,0,0,0,0,0,0,0,0,9,0,0,0,0,0,0,0
0,0,0,0,0,0,0,0,0,0,5,9,9,9,9,9,5,9,9,9,9,9,9,5,5,0,0,0,0,0,0
0,0,0,0,0,0,0,0,0,0,5,0,0,0,0,0,5,0,0,0,0,0,0,5,0,0,0,0,0,0,0
0,0,0,0,0,0,0,0,0,0,0,0,6,0,0,0,0,0,6,0,0,0,0,0,0,0,0,0,0,0,0
0,0,0,0,0,0,0,0,0,0,0,0,0,0,0,0,0,0,0,0,0,0,0,0,0,0,0,0,0,0,0
0,0,0,0,0,0,0,0,0,0,0,0,0,0,0,0,0,0,0,0,0,0,0,0,0,0,0,0,0,0,0
0,0,0,0,0,0,0,0,0,0,0,0,0,0,0,0,0,0,0,0,0,0,0,0,0,0,0,0,0,0,0
:endlayer
layer: 9
0,0,0,0,0,0,0,0,0,0,5,0,0,0,0,0,5,0,0,0,0,0,0,5,0,0,0,0,0,0,0
0,0,0,0,0,0,0,0,0,0,5,9,9,9,9,9,5,9,9,9,9,9,9,5,5,0,0,0,0,0,0
0,0,6,0,0,0,6,0,0,9,15,0,0,0,0,0,15,10,0,0,0,0,0,9,0,0,0,0,0,0,0
21,21,21,21,21,21,21,21,9,0,0,0,0,0,0,0,0,0,10,0,0,0,0,9,0,0,0,0,0,0,0
5,5,18,0,0,0,10,9,0,0,0,0,0,0,0,0,0,0,0,10,0,0,0,9,0,0,0,0,0,0,0
16,9,11,10,10,8,5,18,0,0,0,0,0,0,0,0,0,0,0,17,5,0,17,5,5,0,0,0,6,0,0
0,9,0,0,0,0,13,0,0,0,0,5,0,0,0,5,0,0,0,0,0,0,0,9,21,21,21,21,21,21,21
0,9,0,0,0,0,10,0,0,0,0,0,0,0,0,0,0,0,0,0,0,0,0,13,0,0,0,0,0,9,10
5,5,18,0,0,0,10,0,0,0,0,0,0,0,0,0,0,0,0,0,0,0,0,0,0,0,0,0,17,9,0
0,9,0,0,0,0,10,0,0,0,0,0,0,0,0,0,0,0,0,0,0,0,0,20,0,0,0,0,0,9,10
0,9,0,0,0,0,20,0,0,0,0,5,0,0,0,5,0,0,0,0,0,0,0,9,21,21,21,21,21,21,21
16,9,11,10,10,8,5,18,0,0,0,0,0,0,0,0,0,0,0,17,5,0,17,5,5,0,0,0,6,0,0
5,5,18,0,0,0,10,9,0,0,0,0,0,0,0,0,0,0,0,10,0,0,0,9,0,0,0,0,0,0,0
21,21,21,21,21,21,21,21,9,0,0,0,8,7,0,0,0,0,10,0,0,0,0,9,0,0,0,0,0,0,0
0,0,6,0,0,0,6,0,0,9,19,0,8,7,0,0,19,10,0,0,0,0,0,9,0,0,0,0,0,0,0
0,0,0,0,0,0,0,0,0,0,5,9,9,9,9,9,5,9,9,9,9,9,9,5,5,0,0,0,0,0,0
0,0,0,0,0,0,0,0,0,0,5,0,0,0,0,0,5,0,0,0,0,0,0,5,0,0,0,0,0,0,0
0,0,0,0,0,0,0,0,0,0,0,0,0,0,0,0,0,0,0,0,0,0,0,0,0,0,0,0,0,0,0
0,0,0,0,0,0,0,0,0,0,0,0,0,0,0,0,0,0,0,0,0,0,0,0,0,0,0,0,0,0,0
0,0,0,0,0,0,0,0,0,0,0,0,0,0,0,0,0,0,0,0,0,0,0,0,0,0,0,0,0,0,0
0,0,0,0,0,0,0,0,0,0,0,0,0,0,0,0,0,0,0,0,0,0,0,0,0,0,0,0,0,0,0
:endlayer
layer: 10
0,0,0,0,0,0,0,0,0,0,5,0,0,0,0,0,5,21,21,21,21,21,21,21,21,0,0,0,0,0,0
0,0,0,0,0,0,0,0,0,0,5,14,14,14,14,14,5,14,14,14,14,14,14,5,5,0,0,0,0,0,0
0,0,0,0,0,0,0,0,0,5,10,9,10,9,10,9,10,5,0,0,0,0,0,12,0,0,0,0,0,0,0
0,0,0,0,0,0,0,0,5,10,10,9,10,9,10,9,10,10,5,0,0,0,0,12,0,0,0,0,0,0,0
21,21,21,21,21,21,21,5,10,9,10,9,10,9,10,9,10,9,10,5,0,0,0,12,0,0,0,0,0,0,0
13,12,14,14,14,14,5,10,10,10,9,9,9,9,9,9,9,10,10,10,5,14,14,12,5,0,0,0,0,0,0
0,12,10,10,10,10,12,9,9,9,9,5,0,15,0,5,9,9,9,9,12,10,10,12,0,0,0,0,0,0,0
0,12,9,9,9,9,12,10,10,10,9,0,0,0,0,0,9,10,10,10,12,9,9,12,21,21,21,21,21,21,21
5,12,10,10,10,10,12,9,9,9,9,18,0,0,0,17,9,9,9,9,12,10,10,12,0,0,0,0,0,9,11
0,12,9,9,9,9,12,10,10,10,9,0,0,0,0,0,9,10,10,10,12,9,9,12,21,21,21,21,21,21,21
0,12,10,10,10,10,12,9,9,9,9,5,0,19,0,5,9,9,9,9,12,10,10,12,0,0,0,0,0,0,0
20,12,14,14,14,14,5,10,10,10,9,9,9,9,9,9,9,10,10,10,5,14,14,12,5,0,0,0,0,0,0
21,21,21,21,21,21,21,5,10,9,10,9,9,13,13,13,13,8,10,5,0,0,0,12,0,0,0,0,0,0,0
0,0,0,0,0,0,0,0,5,10,10,9,7,0,0,0,0,8,5,0,0,0,0,12,0,0,0,0,0,0,0
0,0,0,0,0,0,0,0,0,5,10,9,7,0,0,0,0,5,0,0,0,0,0,12,0,0,0,0,0,0,0
0,0,0,0,0,0,0,0,0,0,5,14,14,14,14,14,5,14,14,14,14,14,14,5,5,0,0,0,0,0,0
0,0,0,0,0,0,0,0,0,0,5,0,0,0,0,0,5,21,21,21,21,21,21,21,21,0,0,0,0,0,0
0,0,0,0,0,0,0,0,0,0,0,0,0,0,0,0,0,0,0,0,0,0,0,0,0,0,0,0,0,0,0
0,0,0,0,0,0,0,0,0,0,0,0,0,0,0,0,0,0,0,0,0,0,0,0,0,0,0,0,0,0,0
0,0,0,0,0,0,0,0,0,0,0,0,0,0,0,0,0,0,0,0,0,0,0,0,0,0,0,0,0,0,0
0,0,0,0,0,0,0,0,0,0,0,0,0,0,0,0,0,0,0,0,0,0,0,0,0,0,0,0,0,0,0
:endlayer
layer: 11
0,0,0,0,0,0,0,0,0,0,5,0,0,0,0,0,5,0,0,0,0,0,0,0,0,0,0,0,0,0,0
0,0,0,0,0,0,0,0,0,0,5,9,9,9,9,9,5,21,21,21,21,21,21,21,21,0,0,0,0,0,0
0,0,0,0,0,0,0,0,0,9,0,0,0,0,8,7,0,9,0,0,0,0,0,9,0,0,0,0,0,0,0
0,0,0,0,0,0,0,0,9,0,0,0,0,0,8,7,0,0,9,0,0,0,0,9,0,0,0,0,0,0,0
0,0,0,0,0,0,0,9,0,0,0,0,0,0,0,0,0,0,0,9,0,0,0,9,0,0,0,0,0,0,0
21,21,21,21,21,5,5,0,0,0,0,16,16,16,16,16,0,0,0,0,5,16,16,5,5,0,0,0,0,0,0
13,9,0,0,0,0,13,0,0,0,16,5,0,0,0,5,16,0,0,0,0,0,0,9,0,0,0,0,0,0,0
0,16,0,0,0,0,0,0,0,0,16,0,0,0,0,0,16,0,0,0,0,0,0,9,0,0,0,0,0,0,0
5,9,0,0,0,0,0,0,0,0,16,0,0,0,0,0,16,0,0,0,0,0,0,9,21,21,21,21,21,21,21
0,16,0,0,0,0,0,0,0,0,16,0,0,0,0,0,16,0,0,0,0,0,0,9,0,0,0,0,0,0,0
20,9,0,0,0,0,20,0,0,0,16,5,0,0,0,5,16,0,0,0,0,0,0,9,0,0,0,0,0,0,0
21,21,21,21,21,5,5,0,0,0,0,16,16,16,16,16,0,0,0,0,5,16,16,5,5,0,0,0,0,0,0
0,0,0,0,0,0,0,9,0,0,0,0,0,0,0,0,0,0,0,9,0,0,0,9,0,0,0,0,0,0,0
0,0,0,0,0,0,0,0,9,0,0,0,0,0,0,0,0,0,9,0,0,0,0,9,0,0,0,0,0,0,0
0,0,0,0,0,0,0,0,0,9,0,0,0,0,0,0,0,9,0,0,0,0,0,9,0,0,0,0,0,0,0
0,0,0,0,0,0,0,0,0,0,5,9,9,9,9,9,5,21,21,21,21,21,21,21,21,0,0,0,0,0,0
0,0,0,0,0,0,0,0,0,0,5,0,0,0,0,0,5,0,0,0,0,0,0,0,0,0,0,0,0,0,0
0,0,0,0,0,0,0,0,0,0,0,0,0,0,0,0,0,0,0,0,0,0,0,0,0,0,0,0,0,0,0
0,0,0,0,0,0,0,0,0,0,0,0,0,0,0,0,0,0,0,0,0,0,0,0,0,0,0,0,0,0,0
0,0,0,0,0,0,0,0,0,0,0,0,0,0,0,0,0,0,0,0,0,0,0,0,0,0,0,0,0,0,0
0,0,0,0,0,0,0,0,0,0,0,0,0,0,0,0,0,0,0,0,0,0,0,0,0,0,0,0,0,0,0
:endlayer
layer: 12
0,0,0,0,0,0,0,0,0,0,5,0,0,0,0,0,5,0,0,0,0,0,0,0,0,0,0,0,0,0,0
0,0,0,0,0,0,0,0,0,0,5,9,16,9,16,9,5,0,0,0,0,0,0,0,0,0,0,0,0,0,0
0,0,0,0,0,0,0,0,0,9,0,0,0,8,7,0,0,9,21,21,21,21,21,21,21,0,0,0,0,0,0
0,0,0,0,0,0,0,0,9,0,0,0,0,8,7,0,0,0,9,0,0,0,0,9,0,0,0,0,0,0,0
0,0,0,0,0,0,0,9,0,0,0,0,0,0,0,0,0,0,0,9,0,0,0,9,0,0,0,0,0,0,0
0,0,6,0,0,5,5,0,0,0,0,0,0,0,0,0,0,0,0,0,5,0,0,5,5,0,0,0,0,0,0
21,21,21,21,21,21,9,0,0,0,0,5,0,0,0,5,0,0,0,0,0,0,0,9,0,0,0,0,0,0,0
8,9,0,0,0,0,13,0,0,0,0,0,0,0,0,0,0,0,0,0,0,0,0,16,0,0,0,0,0,0,0
5,9,0,0,0,0,0,0,0,0,0,0,0,0,0,0,0,0,0,0,0,0,0,9,0,0,0,0,6,0,0
8,9,0,0,0,0,20,0,0,0,0,0,0,0,0,0,0,0,0,0,0,0,0,16,0,0,0,0,0,0,0
21,21,21,21,21,21,9,0,0,0,0,5,0,0,0,5,0,0,0,0,0,0,0,9,0,0,0,0,0,0,0
0,0,6,0,0,5,5,0,0,0,0,0,0,0,0,0,0,0,0,0,5,0,0,5,5,0,0,0,0,0,0
0,0,0,0,0,0,0,9,0,0,0,0,0,0,0,0,0,0,0,9,0,0,0,9,0,0,0,0,0,0,0
0,0,0,0,0,0,0,0,9,0,0,0,0,0,0,0,0,0,9,0,0,0,0,9,0,0,0,0,0,0,0
0,0,0,0,0,0,0,0,0,9,0,0,0,0,0,0,0,9,21,21,21,21,21,21,21,0,0,0,0,0,0
0,0,0,0,0,0,0,0,0,0,5,9,16,9,16,9,5,0,0,0,0,0,0,0,0,0,0,0,0,0,0
0,0,0,0,0,0,0,0,0,0,5,0,0,0,0,0,5,0,0,0,0,0,0,0,0,0,0,0,0,0,0
0,0,0,0,0,0,0,0,0,0,0,0,0,0,0,0,0,0,0,0,0,0,0,0,0,0,0,0,0,0,0
0,0,0,0,0,0,0,0,0,0,0,0,0,0,0,0,0,0,0,0,0,0,0,0,0,0,0,0,0,0,0
0,0,0,0,0,0,0,0,0,0,0,0,0,0,0,0,0,0,0,0,0,0,0,0,0,0,0,0,0,0,0
0,0,0,0,0,0,0,0,0,0,0,0,0,0,0,0,0,0,0,0,0,0,0,0,0,0,0,0,0,0,0
:endlayer
layer: 13
0,0,0,0,0,0,0,0,0,0,5,0,0,0,0,0,5,0,0,0,0,0,0,0,0,0,0,0,0,0,0
0,0,0,0,0,0,0,0,0,0,5,9,9,9,9,9,5,0,0,0,0,0,0,0,0,0,0,0,0,0,0
0,0,0,0,0,0,0,0,0,9,15,0,8,7,0,0,15,9,6,0,0,0,6,0,0,0,0,0,0,0,0
0,0,0,0,0,0,0,0,9,0,0,0,8,7,0,0,0,0,9,21,21,21,21,21,21,0,0,0,0,0,0
0,0,0,0,0,0,0,9,0,0,0,0,0,0,0,0,0,0,0,9,0,0,0,9,0,0,0,0,0,0,0
0,0,0,0,0,5,5,18,0,0,0,0,0,0,0,0,0,0,0,17,5,0,17,5,5,0,0,0,0,0,0
0,0,0,0,0,0,9,0,0,0,0,5,0,0,0,5,0,0,0,0,13,0,0,9,0,0,0,0,0,0,0
21,21,21,21,21,21,9,0,0,0,0,0,0,0,0,0,0,0,0,0,10,0,0,9,0,0,0,0,0,0,0
5,9,18,0,0,0,9,0,0,0,0,0,0,0,0,0,0,0,0,0,10,0,0,9,0,0,0,0,0,0,0
21,21,21,21,21,21,9,0,0,0,0,0,0,0,0,0,0,0,0,0,10,0,0,9,0,0,0,0,0,0,0
0,0,0,0,0,0,9,0,0,0,0,5,0,0,0,5,0,0,0,0,20,0,0,9,0,0,0,0,0,0,0
0,0,0,0,0,5,5,18,0,0,0,0,0,0,0,0,0,0,0,17,5,0,17,5,5,0,0,0,0,0,0
0,0,0,0,0,0,0,9,0,0,0,0,0,0,0,0,0,0,0,9,0,0,0,9,0,0,0,0,0,0,0
0,0,0,0,0,0,0,0,9,0,0,0,0,0,0,0,0,0,9,21,21,21,21,21,21,0,0,0,0,0,0
0,0,0,0,0,0,0,0,0,9,19,0,0,0,0,0,19,9,6,0,0,0,6,0,0,0,0,0,0,0,0
0,0,0,0,0,0,0,0,0,0,5,9,9,9,9,9,5,0,0,0,0,0,0,0,0,0,0,0,0,0,0
0,0,0,0,0,0,0,0,0,0,5,0,0,0,0,0,5,0,0,0,0,0,0,0,0,0,0,0,0,0,0
0,0,0,0,0,0,0,0,0,0,0,0,0,0,0,0,0,0,0,0,0,0,0,0,0,0,0,0,0,0,0
0,0,0,0,0,0,0,0,0,0,0,0,0,0,0,0,0,0,0,0,0,0,0,0,0,0,0,0,0,0,0
0,0,0,0,0,0,0,0,0,0,0,0,0,0,0,0,0,0,0,0,0,0,0,0,0,0,0,0,0,0,0
0,0,0,0,0,0,0,0,0,0,0,0,0,0,0,0,0,0,0,0,0,0,0,0,0,0,0,0,0,0,0
:endlayer
layer: 14
0,0,0,0,0,0,0,0,0,0,5,0,0,0,0,0,5,0,0,0,0,0,0,0,0,0,0,0,0,0,0
0,0,0,0,0,0,0,0,0,0,5,14,14,14,14,14,5,0,0,0,0,0,0,0,0,0,0,0,0,0,0
0,0,0,0,0,0,0,0,0,5,10,9,7,0,0,0,0,5,0,0,0,0,0,0,0,0,0,0,0,0,0
0,0,0,0,0,0,0,0,5,10,10,9,7,0,0,0,0,8,5,0,0,0,0,0,0,0,0,0,0,0,0
0,0,0,0,0,0,0,5,10,9,10,9,9,20,20,20,20,8,10,5,21,21,21,21,21,0,0,0,0,0,0
0,0,0,0,0,5,5,10,10,10,9,9,9,9,9,9,9,10,10,10,5,14,14,5,5,0,0,0,0,0,0
0,0,0,0,0,0,12,9,9,9,9,5,0,15,0,5,9,9,9,9,12,10,10,12,0,0,0,0,0,0,0
0,0,0,0,0,0,12,10,10,10,9,0,0,0,0,0,9,10,10,10,12,9,9,12,0,0,0,0,0,0,0
21,21,21,21,21,21,12,9,9,9,9,18,0,0,0,17,9,9,9,9,12,10,10,12,0,0,0,0,0,0,0
0,0,0,0,0,0,12,10,10,10,9,0,0,0,0,0,9,10,10,10,12,9,9,12,0,0,0,0,0,0,0
0,0,0,0,0,0,12,9,9,9,9,5,0,19,0,5,9,9,9,9,12,10,10,12,0,0,0,0,0,0,0
0,0,0,0,0,5,5,10,10,10,9,9,9,9,9,9,9,10,10,10,5,14,14,5,5,0,0,0,0,0,0
0,0,0,0,0,0,0,5,10,9,10,9,10,9,10,9,10,9,10,5,21,21,21,21,21,0,0,0,0,0,0
0,0,0,0,0,0,0,0,5,10,10,9,10,9,10,9,10,10,5,0,0,0,0,0,0,0,0,0,0,0,0
0,0,0,0,0,0,0,0,0,5,10,9,10,9,10,9,10,5,0,0,0,0,0,0,0,0,0,0,0,0,0
0,0,0,0,0,0,0,0,0,0,5,14,14,14,14,14,5,0,0,0,0,0,0,0,0,0,0,0,0,0,0
0,0,0,0,0,0,0,0,0,0,5,0,0,0,0,0,5,0,0,0,0,0,0,0,0,0,0,0,0,0,0
0,0,0,0,0,0,0,0,0,0,0,0,0,0,0,0,0,0,0,0,0,0,0,0,0,0,0,0,0,0,0
0,0,0,0,0,0,0,0,0,0,0,0,0,0,0,0,0,0,0,0,0,0,0,0,0,0,0,0,0,0,0
0,0,0,0,0,0,0,0,0,0,0,0,0,0,0,0,0,0,0,0,0,0,0,0,0,0,0,0,0,0,0
0,0,0,0,0,0,0,0,0,0,0,0,0,0,0,0,0,0,0,0,0,0,0,0,0,0,0,0,0,0,0
:endlayer
layer: 15
0,0,0,0,0,0,0,0,0,0,5,0,0,0,0,0,5,0,0,0,0,0,0,0,0,0,0,0,0,0,0
0,0,0,0,0,0,0,0,0,0,5,9,9,9,9,9,5,0,0,0,0,0,0,0,0,0,0,0,0,0,0
0,0,0,0,0,0,0,0,0,9,0,0,0,0,0,0,0,9,0,0,0,0,0,0,0,0,0,0,0,0,0
0,0,0,0,0,0,0,0,9,0,0,0,0,0,0,0,0,0,9,0,0,0,0,0,0,0,0,0,0,0,0
0,0,0,0,0,0,0,9,0,0,0,0,0,0,0,0,0,0,0,9,0,0,0,0,0,0,0,0,0,0,0
0,0,0,0,0,5,5,0,0,0,0,16,16,16,16,16,0,0,0,0,5,5,21,21,21,0,0,0,0,0,0
0,0,0,0,0,0,9,0,0,0,16,5,0,0,0,5,16,0,0,0,13,0,0,9,13,0,0,0,0,0,0
0,0,0,0,0,0,9,0,0,0,16,0,0,0,0,0,16,0,0,0,0,0,0,9,0,0,0,0,0,0,0
0,0,6,0,0,0,9,0,0,0,16,0,0,0,0,0,16,0,0,0,0,0,0,16,0,0,0,0,0,0,0
0,0,0,0,0,0,9,0,0,0,16,0,0,0,0,0,16,0,0,0,0,0,0,9,0,0,0,0,0,0,0
0,0,0,0,0,0,9,0,0,0,16,5,0,0,0,5,16,0,0,0,20,0,0,9,20,0,0,0,0,0,0
0,0,0,0,0,5,5,0,0,0,0,16,16,16,16,16,0,0,0,0,5,5,21,21,21,0,0,0,0,0,0
0,0,0,0,0,0,0,9,0,0,0,0,0,0,0,0,0,0,0,9,0,0,0,0,0,0,0,0,0,0,0
0,0,0,0,0,0,0,0,9,0,0,0,0,0,0,0,0,0,9,0,0,0,0,0,0,0,0,0,0,0,0
0,0,0,0,0,0,0,0,0,9,0,0,0,0,0,0,0,9,0,0,0,0,0,0,0,0,0,0,0,0,0
0,0,0,0,0,0,0,0,0,0,5,9,9,9,9,9,5,0,0,0,0,0,0,0,0,0,0,0,0,0,0
0,0,0,0,0,0,0,0,0,0,5,0,0,0,0,0,5,0,0,0,0,0,0,0,0,0,0,0,0,0,0
0,0,0,0,0,0,0,0,0,0,0,0,0,0,0,0,0,0,0,0,0,0,0,0,0,0,0,0,0,0,0
0,0,0,0,0,0,0,0,0,0,0,0,0,0,0,0,0,0,0,0,0,0,0,0,0,0,0,0,0,0,0
0,0,0,0,0,0,0,0,0,0,0,0,0,0,0,0,0,0,0,0,0,0,0,0,0,0,0,0,0,0,0
0,0,0,0,0,0,0,0,0,0,0,0,0,0,0,0,0,0,0,0,0,0,0,0,0,0,0,0,0,0,0
:endlayer
layer: 16
0,0,0,0,0,0,0,0,0,0,5,0,0,0,0,0,5,0,0,0,0,0,0,0,0,0,0,0,0,0,0
0,0,0,0,0,0,0,0,0,0,5,9,16,9,16,9,5,0,0,0,0,0,0,0,0,0,0,0,0,0,0
0,0,0,0,0,0,0,0,0,9,0,0,0,0,0,0,0,9,0,0,0,0,0,0,0,0,0,0,0,0,0
0,0,0,0,0,0,0,0,9,0,0,0,0,0,0,0,0,0,9,0,0,0,0,0,0,0,0,0,0,0,0
0,0,0,0,0,0,0,9,0,0,0,0,0,0,0,0,0,0,0,9,0,0,0,0,0,0,0,0,0,0,0
0,0,0,0,0,5,5,0,0,0,0,16,0,0,0,16,0,0,0,0,5,5,6,0,0,0,0,0,0,0,0
0,0,0,0,0,0,9,0,0,0,16,5,0,0,0,5,16,0,0,0,9,21,21,21,21,0,0,0,0,0,0
0,0,0,0,0,0,16,0,0,0,0,0,0,0,0,0,0,0,0,0,13,0,0,9,13,0,0,0,0,0,0
0,0,0,0,0,0,9,0,0,0,0,0,0,0,0,0,0,0,0,0,0,0,0,9,0,0,0,0,0,0,0
0,0,0,0,0,0,16,0,0,0,0,0,0,0,0,0,0,0,0,0,20,0,0,9,20,0,0,0,0,0,0
0,0,0,0,0,0,9,0,0,0,16,5,0,0,0,5,16,0,0,0,9,21,21,21,21,0,0,0,0,0,0
0,0,0,0,0,5,5,0,0,0,0,16,0,0,0,16,0,0,0,0,5,5,6,0,0,0,0,0,0,0,0
0,0,0,0,0,0,0,9,0,0,0,0,0,0,0,0,0,0,0,9,0,0,0,0,0,0,0,0,0,0,0
0,0,0,0,0,0,0,0,9,0,0,0,0,0,0,0,0,0,9,0,0,0,0,0,0,0,0,0,0,0,0
0,0,0,0,0,0,0,0,0,9,0,0,0,0,0,0,0,9,0,0,0,0,0,0,0,0,0,0,0,0,0
0,0,0,0,0,0,0,0,0,0,5,9,16,9,16,9,5,0,0,0,0,0,0,0,0,0,0,0,0,0,0
0,0,0,0,0,0,0,0,0,0,5,0,0,0,0,0,5,0,0,0,0,0,0,0,0,0,0,0,0,0,0
0,0,0,0,0,0,0,0,0,0,0,0,0,0,0,0,0,0,0,0,0,0,0,0,0,0,0,0,0,0,0
0,0,0,0,0,0,0,0,0,0,0,0,0,0,0,0,0,0,0,0,0,0,0,0,0,0,0,0,0,0,0
0,0,0,0,0,0,0,0,0,0,0,0,0,0,0,0,0,0,0,0,0,0,0,0,0,0,0,0,0,0,0
0,0,0,0,0,0,0,0,0,0,0,0,0,0,0,0,0,0,0,0,0,0,0,0,0,0,0,0,0,0,0
:endlayer
layer: 17
0,0,0,0,0,0,0,0,0,0,5,20,20,20,20,20,5,0,0,0,0,0,0,0,0,0,0,0,0,0,0
0,0,0,0,0,0,0,0,0,20,5,9,9,9,9,9,5,20,0,0,0,0,0,0,0,0,0,0,0,0,0
0,0,0,0,0,0,0,0,20,9,15,0,0,0,0,0,15,9,20,0,0,0,0,0,0,0,0,0,0,0,0
0,0,0,0,0,0,0,8,9,0,0,0,0,0,0,0,0,0,9,11,0,0,0,0,0,0,0,0,0,0,0
0,0,0,0,0,0,8,9,0,0,0,0,0,0,0,0,0,0,0,9,11,0,0,0,0,0,0,0,0,0,0
0,0,0,0,0,5,5,18,0,0,0,16,0,0,0,16,0,0,0,17,5,5,0,0,0,0,0,0,0,0,0
0,0,0,0,0,8,9,0,0,0,16,5,0,0,0,5,16,0,0,0,9,11,0,0,0,0,0,0,0,0,0
0,0,0,0,0,8,9,0,0,0,0,0,0,0,0,0,0,0,0,0,9,21,21,21,21,0,0,0,0,0,0
0,0,0,0,0,8,9,0,0,0,0,0,0,0,0,0,0,0,0,0,9,0,17,9,11,0,0,0,0,0,0
0,0,0,0,0,8,9,0,0,0,0,0,0,0,0,0,0,0,0,0,9,21,21,21,21,0,0,0,0,0,0
0,0,0,0,0,8,9,0,0,0,16,5,0,0,0,5,16,0,0,0,9,11,0,0,0,0,0,0,0,0,0
0,0,0,0,0,5,5,18,0,0,0,16,0,0,0,16,0,0,0,17,5,5,0,0,0,0,0,0,0,0,0
0,0,0,0,0,0,8,9,0,0,0,0,0,0,0,0,0,0,0,9,11,0,0,0,0,0,0,0,0,0,0
0,0,0,0,0,0,0,8,9,0,0,0,0,0,0,0,0,0,9,11,0,0,0,0,0,0,0,0,0,0,0
0,0,0,0,0,0,0,0,13,9,19,0,0,0,0,0,19,9,13,0,0,0,0,0,0,0,0,0,0,0,0
0,0,0,0,0,0,0,0,0,13,5,9,9,9,9,9,5,13,0,0,0,0,0,0,0,0,0,0,0,0,0
0,0,0,0,0,0,0,0,0,0,5,13,13,13,13,13,5,0,0,0,0,0,0,0,0,0,0,0,0,0,0
0,0,0,0,0,0,0,0,0,0,0,0,0,0,0,0,0,0,0,0,0,0,0,0,0,0,0,0,0,0,0
0,0,0,0,0,0,0,0,0,0,0,0,0,0,0,0,0,0,0,0,0,0,0,0,0,0,0,0,0,0,0
0,0,0,0,0,0,0,0,0,0,0,0,0,0,0,0,0,0,0,0,0,0,0,0,0,0,0,0,0,0,0
0,0,0,0,0,0,0,0,0,0,0,0,0,0,0,0,0,0,0,0,0,0,0,0,0,0,0,0,0,0,0
:endlayer
layer: 18
0,0,0,0,0,0,0,0,0,0,21,21,21,21,21,21,21,0,0,0,0,0,0,0,0,0,0,0,0,0,0
0,0,0,0,0,0,0,0,0,21,5,14,14,14,14,14,5,21,0,0,0,0,0,0,0,0,0,0,0,0,0
0,0,0,0,0,0,0,0,21,5,0,0,0,0,0,0,0,5,21,0,0,0,0,0,0,0,0,0,0,0,0
0,0,0,0,0,0,0,21,5,0,0,0,0,0,0,0,0,0,5,21,0,0,0,0,0,0,0,0,0,0,0
0,0,0,0,0,0,21,5,0,0,0,0,0,0,0,0,0,0,0,5,21,0,0,0,0,0,0,0,0,0,0
0,0,0,0,0,21,5,0,0,0,0,9,9,9,9,9,0,0,0,0,5,21,0,0,0,0,0,0,0,0,0
0,0,0,0,0,21,12,0,0,0,9,5,0,15,0,5,9,0,0,0,12,21,0,0,0,0,0,0,0,0,0
0,0,0,0,0,21,12,0,0,0,9,0,0,0,0,0,9,0,0,0,12,21,0,0,0,0,0,0,0,0,0
0,0,0,0,0,21,12,0,0,0,9,18,0,0,0,17,9,0,0,0,12,21,21,21,21,0,0,0,0,0,0
0,0,0,0,0,21,12,0,0,0,9,0,0,0,0,0,9,0,0,0,12,21,0,0,0,0,0,0,0,0,0
0,0,0,0,0,21,12,0,0,0,9,5,0,19,0,5,9,0,0,0,12,21,0,0,0,0,0,0,0,0,0
0,0,0,0,0,21,5,0,0,0,0,9,9,9,9,9,0,0,0,0,5,21,0,0,0,0,0,0,0,0,0
0,0,0,0,0,0,21,5,0,0,0,0,0,0,0,0,0,0,0,5,21,0,0,0,0,0,0,0,0,0,0
0,0,0,0,0,0,0,21,5,0,0,0,0,0,0,0,0,0,5,21,0,0,0,0,0,0,0,0,0,0,0
0,0,0,0,0,0,0,0,21,5,0,0,0,0,0,0,0,5,21,0,0,0,0,0,0,0,0,0,0,0,0
0,0,0,0,0,0,0,0,0,21,5,14,14,14,14,14,5,21,0,0,0,0,0,0,0,0,0,0,0,0,0
0,0,0,0,0,0,0,0,0,0,21,21,21,21,21,21,21,0,0,0,0,0,0,0,0,0,0,0,0,0,0
0,0,0,0,0,0,0,0,0,0,0,0,0,0,0,0,0,0,0,0,0,0,0,0,0,0,0,0,0,0,0
0,0,0,0,0,0,0,0,0,0,0,0,0,0,0,0,0,0,0,0,0,0,0,0,0,0,0,0,0,0,0
0,0,0,0,0,0,0,0,0,0,0,0,0,0,0,0,0,0,0,0,0,0,0,0,0,0,0,0,0,0,0
0,0,0,0,0,0,0,0,0,0,0,0,0,0,0,0,0,0,0,0,0,0,0,0,0,0,0,0,0,0,0
:endlayer
layer: 19
0,0,0,0,0,0,0,0,0,0,0,0,0,0,0,0,0,0,0,0,0,0,0,0,0,0,0,0,0,0,0
0,0,0,0,0,0,0,0,0,0,21,21,21,21,21,21,21,0,0,0,0,0,0,0,0,0,0,0,0,0,0
0,0,0,0,0,0,0,0,0,21,12,0,0,0,0,0,12,21,0,0,0,0,0,0,0,0,0,0,0,0,0
0,0,0,0,0,0,0,0,21,0,12,0,0,0,0,0,12,0,21,0,0,0,0,0,0,0,0,0,0,0,0
0,0,0,0,0,0,0,21,0,0,12,0,0,0,0,0,12,0,0,21,0,0,0,0,0,0,0,0,0,0,0
0,0,0,0,0,0,21,14,14,14,12,14,14,14,14,14,12,14,14,14,21,0,0,0,0,0,0,0,0,0,0
0,0,0,0,0,0,21,0,0,0,12,5,0,0,0,5,12,0,0,0,21,0,0,0,0,0,0,0,0,0,0
0,0,0,0,0,0,21,0,0,0,12,0,0,0,0,0,12,0,0,0,21,0,0,0,0,0,0,0,0,0,0
0,0,0,0,0,0,21,0,0,0,12,0,0,0,0,0,12,0,0,0,21,0,6,0,0,0,0,0,0,0,0
0,0,0,0,0,0,21,0,0,0,12,0,0,0,0,0,12,0,0,0,21,0,0,0,0,0,0,0,0,0,0
0,0,0,0,0,0,21,0,0,0,12,5,0,0,0,5,12,0,0,0,21,0,0,0,0,0,0,0,0,0,0
0,0,0,0,0,0,21,14,14,14,12,14,14,14,14,14,12,14,14,14,21,0,0,0,0,0,0,0,0,0,0
0,0,0,0,0,0,0,21,0,0,12,0,0,0,0,0,12,0,0,21,0,0,0,0,0,0,0,0,0,0,0
0,0,0,0,0,0,0,0,21,0,12,0,0,0,0,0,12,0,21,0,0,0,0,0,0,0,0,0,0,0,0
0,0,0,0,0,0,0,0,0,21,12,0,0,0,0,0,12,21,0,0,0,0,0,0,0,0,0,0,0,0,0
0,0,0,0,0,0,0,0,0,0,21,21,21,21,21,21,21,0,0,0,0,0,0,0,0,0,0,0,0,0,0
0,0,0,0,0,0,0,0,0,0,0,0,0,0,0,0,0,0,0,0,0,0,0,0,0,0,0,0,0,0,0
0,0,0,0,0,0,0,0,0,0,0,0,0,0,0,0,0,0,0,0,0,0,0,0,0,0,0,0,0,0,0
0,0,0,0,0,0,0,0,0,0,0,0,0,0,0,0,0,0,0,0,0,0,0,0,0,0,0,0,0,0,0
0,0,0,0,0,0,0,0,0,0,0,0,0,0,0,0,0,0,0,0,0,0,0,0,0,0,0,0,0,0,0
0,0,0,0,0,0,0,0,0,0,0,0,0,0,0,0,0,0,0,0,0,0,0,0,0,0,0,0,0,0,0
:endlayer
layer: 20
0,0,0,0,0,0,0,0,0,0,0,0,0,0,0,0,0,0,0,0,0,0,0,0,0,0,0,0,0,0,0
0,0,0,0,0,0,0,0,0,0,0,0,0,6,0,0,0,0,0,0,0,0,0,0,0,0,0,0,0,0,0
0,0,0,0,0,0,0,0,0,0,21,21,21,21,21,21,21,0,0,0,0,0,0,0,0,0,0,0,0,0,0
0,0,0,0,0,0,0,0,6,21,21,0,0,0,0,0,21,21,6,0,0,0,0,0,0,0,0,0,0,0,0
0,0,0,0,0,0,0,0,21,21,0,0,0,0,0,0,0,21,21,0,0,0,0,0,0,0,0,0,0,0,0
0,0,0,0,0,0,0,21,21,0,6,16,16,16,16,16,6,0,21,21,0,0,0,0,0,0,0,0,0,0,0
0,0,0,0,0,0,0,21,0,0,16,5,0,0,0,5,16,0,0,21,0,0,0,0,0,0,0,0,0,0,0
0,0,0,0,0,0,0,21,0,0,16,0,0,0,0,0,16,0,0,21,0,0,0,0,0,0,0,0,0,0,0
0,0,0,0,0,0,6,21,0,0,16,0,0,0,0,0,16,0,0,21,6,0,0,0,0,0,0,0,0,0,0
0,0,0,0,0,0,0,21,0,0,16,0,0,0,0,0,16,0,0,21,0,0,0,0,0,0,0,0,0,0,0
0,0,0,0,0,0,0,21,0,0,16,5,0,0,0,5,16,0,0,21,0,0,0,0,0,0,0,0,0,0,0
0,0,0,0,0,0,0,21,21,0,6,16,16,16,16,16,6,0,21,21,0,0,0,0,0,0,0,0,0,0,0
0,0,0,0,0,0,0,0,21,21,0,0,0,0,0,0,0,21,21,0,0,0,0,0,0,0,0,0,0,0,0
0,0,0,0,0,0,0,0,6,21,21,0,0,0,0,0,21,21,6,0,0,0,0,0,0,0,0,0,0,0,0
0,0,0,0,0,0,0,0,0,0,21,21,21,21,21,21,21,0,0,0,0,0,0,0,0,0,0,0,0,0,0
0,0,0,0,0,0,0,0,0,0,0,0,0,6,0,0,0,0,0,0,0,0,0,0,0,0,0,0,0,0,0
0,0,0,0,0,0,0,0,0,0,0,0,0,0,0,0,0,0,0,0,0,0,0,0,0,0,0,0,0,0,0
0,0,0,0,0,0,0,0,0,0,0,0,0,0,0,0,0,0,0,0,0,0,0,0,0,0,0,0,0,0,0
0,0,0,0,0,0,0,0,0,0,0,0,0,0,0,0,0,0,0,0,0,0,0,0,0,0,0,0,0,0,0
0,0,0,0,0,0,0,0,0,0,0,0,0,0,0,0,0,0,0,0,0,0,0,0,0,0,0,0,0,0,0
0,0,0,0,0,0,0,0,0,0,0,0,0,0,0,0,0,0,0,0,0,0,0,0,0,0,0,0,0,0,0
:endlayer
layer: 21
0,0,0,0,0,0,0,0,0,0,0,0,0,0,0,0,0,0,0,0,0,0,0,0,0,0,0,0,0,0,0
0,0,0,0,0,0,0,0,0,0,0,0,0,0,0,0,0,0,0,0,0,0,0,0,0,0,0,0,0,0,0
0,0,0,0,0,0,0,0,0,0,0,0,0,21,0,0,0,0,0,0,0,0,0,0,0,0,0,0,0,0,0
0,0,0,0,0,0,0,0,0,0,0,21,21,21,21,21,0,0,0,0,0,0,0,0,0,0,0,0,0,0,0
0,0,0,0,0,0,0,0,0,21,21,0,0,0,0,0,21,21,0,0,0,0,0,0,0,0,0,0,0,0,0
0,0,0,0,0,0,0,0,0,21,0,0,0,0,0,0,0,21,0,0,0,0,0,0,0,0,0,0,0,0,0
0,0,0,0,0,0,0,0,21,0,0,5,0,0,0,5,0,0,21,0,0,0,0,0,0,0,0,0,0,0,0
0,0,0,0,0,0,0,0,21,0,0,0,0,0,0,0,0,0,21,0,0,0,0,0,0,0,0,0,0,0,0
0,0,0,0,0,0,0,21,21,0,0,0,0,0,0,0,0,0,21,21,0,0,0,0,0,0,0,0,0,0,0
0,0,0,0,0,0,0,0,21,0,0,0,0,0,0,0,0,0,21,0,0,0,0,0,0,0,0,0,0,0,0
0,0,0,0,0,0,0,0,21,0,0,5,0,0,0,5,0,0,21,0,0,0,0,0,0,0,0,0,0,0,0
0,0,0,0,0,0,0,0,0,21,0,0,0,0,0,0,0,21,0,0,0,0,0,0,0,0,0,0,0,0,0
0,0,0,0,0,0,0,0,0,21,21,0,0,0,0,0,21,21,0,0,0,0,0,0,0,0,0,0,0,0,0
0,0,0,0,0,0,0,0,0,0,0,21,21,21,21,21,0,0,0,0,0,0,0,0,0,0,0,0,0,0,0
0,0,0,0,0,0,0,0,0,0,0,0,0,21,0,0,0,0,0,0,0,0,0,0,0,0,0,0,0,0,0
0,0,0,0,0,0,0,0,0,0,0,0,0,0,0,0,0,0,0,0,0,0,0,0,0,0,0,0,0,0,0
0,0,0,0,0,0,0,0,0,0,0,0,0,0,0,0,0,0,0,0,0,0,0,0,0,0,0,0,0,0,0
0,0,0,0,0,0,0,0,0,0,0,0,0,0,0,0,0,0,0,0,0,0,0,0,0,0,0,0,0,0,0
0,0,0,0,0,0,0,0,0,0,0,0,0,0,0,0,0,0,0,0,0,0,0,0,0,0,0,0,0,0,0
0,0,0,0,0,0,0,0,0,0,0,0,0,0,0,0,0,0,0,0,0,0,0,0,0,0,0,0,0,0,0
0,0,0,0,0,0,0,0,0,0,0,0,0,0,0,0,0,0,0,0,0,0,0,0,0,0,0,0,0,0,0
:endlayer
layer: 22
0,0,0,0,0,0,0,0,0,0,0,0,0,0,0,0,0,0,0,0,0,0,0,0,0,0,0,0,0,0,0
0,0,0,0,0,0,0,0,0,0,0,0,0,0,0,0,0,0,0,0,0,0,0,0,0,0,0,0,0,0,0
0,0,0,0,0,0,0,0,0,0,0,0,0,0,0,0,0,0,0,0,0,0,0,0,0,0,0,0,0,0,0
0,0,0,0,0,0,0,0,0,0,0,0,21,21,21,0,0,0,0,0,0,0,0,0,0,0,0,0,0,0,0
0,0,0,0,0,0,0,0,0,0,21,21,0,0,0,21,21,0,0,0,0,0,0,0,0,0,0,0,0,0,0
0,0,0,0,0,0,0,0,0,21,0,0,0,0,0,0,0,21,0,0,0,0,0,0,0,0,0,0,0,0,0
0,0,0,0,0,0,0,0,0,21,0,5,0,0,0,5,0,21,0,0,0,0,0,0,0,0,0,0,0,0,0
0,0,0,0,0,0,0,0,21,0,0,0,0,0,0,0,0,0,21,0,0,0,0,0,0,0,0,0,0,0,0
0,0,0,0,0,0,0,0,21,0,0,0,0,0,0,0,0,0,21,0,0,0,0,0,0,0,0,0,0,0,0
0,0,0,0,0,0,0,0,21,0,0,0,0,0,0,0,0,0,21,0,0,0,0,0,0,0,0,0,0,0,0
0,0,0,0,0,0,0,0,0,21,0,5,0,0,0,5,0,21,0,0,0,0,0,0,0,0,0,0,0,0,0
0,0,0,0,0,0,0,0,0,21,0,0,0,0,0,0,0,21,0,0,0,0,0,0,0,0,0,0,0,0,0
0,0,0,0,0,0,0,0,0,0,21,21,0,0,0,21,21,0,0,0,0,0,0,0,0,0,0,0,0,0,0
0,0,0,0,0,0,0,0,0,0,0,0,21,21,21,0,0,0,0,0,0,0,0,0,0,0,0,0,0,0,0
0,0,0,0,0,0,0,0,0,0,0,0,0,0,0,0,0,0,0,0,0,0,0,0,0,0,0,0,0,0,0
0,0,0,0,0,0,0,0,0,0,0,0,0,0,0,0,0,0,0,0,0,0,0,0,0,0,0,0,0,0,0
0,0,0,0,0,0,0,0,0,0,0,0,0,0,0,0,0,0,0,0,0,0,0,0,0,0,0,0,0,0,0
0,0,0,0,0,0,0,0,0,0,0,0,0,0,0,0,0,0,0,0,0,0,0,0,0,0,0,0,0,0,0
0,0,0,0,0,0,0,0,0,0,0,0,0,0,0,0,0,0,0,0,0,0,0,0,0,0,0,0,0,0,0
0,0,0,0,0,0,0,0,0,0,0,0,0,0,0,0,0,0,0,0,0,0,0,0,0,0,0,0,0,0,0
0,0,0,0,0,0,0,0,0,0,0,0,0,0,0,0,0,0,0,0,0,0,0,0,0,0,0,0,0,0,0
:endlayer
layer: 23
0,0,0,0,0,0,0,0,0,0,0,0,0,0,0,0,0,0,0,0,0,0,0,0,0,0,0,0,0,0,0
0,0,0,0,0,0,0,0,0,0,0,0,0,0,0,0,0,0,0,0,0,0,0,0,0,0,0,0,0,0,0
0,0,0,0,0,0,0,0,0,0,0,0,0,0,0,0,0,0,0,0,0,0,0,0,0,0,0,0,0,0,0
0,0,0,0,0,0,0,0,0,0,0,0,0,21,0,0,0,0,0,0,0,0,0,0,0,0,0,0,0,0,0
0,0,0,0,0,0,0,0,0,0,0,0,21,21,21,0,0,0,0,0,0,0,0,0,0,0,0,0,0,0,0
0,0,0,0,0,0,0,0,0,0,21,21,13,13,13,21,21,0,0,0,0,0,0,0,0,0,0,0,0,0,0
0,0,0,0,0,0,0,0,0,0,21,5,0,0,0,5,21,0,0,0,0,0,0,0,0,0,0,0,0,0,0
0,0,0,0,0,0,0,0,0,21,11,0,0,0,0,0,8,21,0,0,0,0,0,0,0,0,0,0,0,0,0
0,0,0,0,0,0,0,0,21,21,11,0,0,0,0,0,8,21,21,0,0,0,0,0,0,0,0,0,0,0,0
0,0,0,0,0,0,0,0,0,21,11,0,0,0,0,0,8,21,0,0,0,0,0,0,0,0,0,0,0,0,0
0,0,0,0,0,0,0,0,0,0,21,5,0,0,0,5,21,0,0,0,0,0,0,0,0,0,0,0,0,0,0
0,0,0,0,0,0,0,0,0,0,21,21,20,20,20,21,21,0,0,0,0,0,0,0,0,0,0,0,0,0,0
0,0,0,0,0,0,0,0,0,0,0,0,21,21,21,0,0,0,0,0,0,0,0,0,0,0,0,0,0,0,0
0,0,0,0,0,0,0,0,0,0,0,0,0,21,0,0,0,0,0,0,0,0,0,0,0,0,0,0,0,0,0
0,0,0,0,0,0,0,0,0,0,0,0,0,0,0,0,0,0,0,0,0,0,0,0,0,0,0,0,0,0,0
0,0,0,0,0,0,0,0,0,0,0,0,0,0,0,0,0,0,0,0,0,0,0,0,0,0,0,0,0,0,0
0,0,0,0,0,0,0,0,0,0,0,0,0,0,0,0,0,0,0,0,0,0,0,0,0,0,0,0,0,0,0
0,0,0,0,0,0,0,0,0,0,0,0,0,0,0,0,0,0,0,0,0,0,0,0,0,0,0,0,0,0,0
0,0,0,0,0,0,0,0,0,0,0,0,0,0,0,0,0,0,0,0,0,0,0,0,0,0,0,0,0,0,0
0,0,0,0,0,0,0,0,0,0,0,0,0,0,0,0,0,0,0,0,0,0,0,0,0,0,0,0,0,0,0
0,0,0,0,0,0,0,0,0,0,0,0,0,0,0,0,0,0,0,0,0,0,0,0,0,0,0,0,0,0,0
:endlayer
layer: 24
0,0,0,0,0,0,0,0,0,0,0,0,0,0,0,0,0,0,0,0,0,0,0,0,0,0,0,0,0,0,0
0,0,0,0,0,0,0,0,0,0,0,0,0,0,0,0,0,0,0,0,0,0,0,0,0,0,0,0,0,0,0
0,0,0,0,0,0,0,0,0,0,0,0,0,0,0,0,0,0,0,0,0,0,0,0,0,0,0,0,0,0,0
0,0,0,0,0,0,0,0,0,0,0,0,0,0,0,0,0,0,0,0,0,0,0,0,0,0,0,0,0,0,0
0,0,0,0,0,0,0,0,0,0,0,0,21,21,21,0,0,0,0,0,0,0,0,0,0,0,0,0,0,0,0
0,0,0,0,0,0,0,0,0,0,6,21,14,14,14,21,6,0,0,0,0,0,0,0,0,0,0,0,0,0,0
0,0,0,0,0,0,0,0,0,0,21,5,0,15,0,5,21,0,0,0,0,0,0,0,0,0,0,0,0,0,0
0,0,0,0,0,0,0,0,0,21,12,0,0,0,0,0,12,21,0,0,0,0,0,0,0,0,0,0,0,0,0
0,0,0,0,0,0,0,0,0,21,12,18,0,0,0,17,12,21,0,0,0,0,0,0,0,0,0,0,0,0,0
0,0,0,0,0,0,0,0,0,21,12,0,0,0,0,0,12,21,0,0,0,0,0,0,0,0,0,0,0,0,0
0,0,0,0,0,0,0,0,0,0,21,5,0,19,0,5,21,0,0,0,0,0,0,0,0,0,0,0,0,0,0
0,0,0,0,0,0,0,0,0,0,6,21,14,14,14,21,6,0,0,0,0,0,0,0,0,0,0,0,0,0,0
0,0,0,0,0,0,0,0,0,0,0,0,21,21,21,0,0,0,0,0,0,0,0,0,0,0,0,0,0,0,0
0,0,0,0,0,0,0,0,0,0,0,0,0,0,0,0,0,0,0,0,0,0,0,0,0,0,0,0,0,0,0
0,0,0,0,0,0,0,0,0,0,0,0,0,0,0,0,0,0,0,0,0,0,0,0,0,0,0,0,0,0,0
0,0,0,0,0,0,0,0,0,0,0,0,0,0,0,0,0,0,0,0,0,0,0,0,0,0,0,0,0,0,0
0,0,0,0,0,0,0,0,0,0,0,0,0,0,0,0,0,0,0,0,0,0,0,0,0,0,0,0,0,0,0
0,0,0,0,0,0,0,0,0,0,0,0,0,0,0,0,0,0,0,0,0,0,0,0,0,0,0,0,0,0,0
0,0,0,0,0,0,0,0,0,0,0,0,0,0,0,0,0,0,0,0,0,0,0,0,0,0,0,0,0,0,0
0,0,0,0,0,0,0,0,0,0,0,0,0,0,0,0,0,0,0,0,0,0,0,0,0,0,0,0,0,0,0
0,0,0,0,0,0,0,0,0,0,0,0,0,0,0,0,0,0,0,0,0,0,0,0,0,0,0,0,0,0,0
:endlayer
layer: 25
0,0,0,0,0,0,0,0,0,0,0,0,0,0,0,0,0,0,0,0,0,0,0,0,0,0,0,0,0,0,0
0,0,0,0,0,0,0,0,0,0,0,0,0,0,0,0,0,0,0,0,0,0,0,0,0,0,0,0,0,0,0
0,0,0,0,0,0,0,0,0,0,0,0,0,0,0,0,0,0,0,0,0,0,0,0,0,0,0,0,0,0,0
0,0,0,0,0,0,0,0,0,0,0,0,0,0,0,0,0,0,0,0,0,0,0,0,0,0,0,0,0,0,0
0,0,0,0,0,0,0,0,0,0,0,0,22,22,22,0,0,0,0,0,0,0,0,0,0,0,0,0,0,0,0
0,0,0,0,0,0,0,0,0,0,0,22,9,9,9,22,0,0,0,0,0,0,0,0,0,0,0,0,0,0,0
0,0,0,0,0,0,0,0,0,0,22,5,0,0,0,5,22,0,0,0,0,0,0,0,0,0,0,0,0,0,0
0,0,0,0,0,0,0,0,0,22,9,0,0,0,0,0,9,22,0,0,0,0,0,0,0,0,0,0,0,0,0
0,0,0,0,0,0,0,0,0,22,9,0,0,0,0,0,9,22,0,0,0,0,0,0,0,0,0,0,0,0,0
0,0,0,0,0,0,0,0,0,22,9,0,0,0,0,0,9,22,0,0,0,0,0,0,0,0,0,0,0,0,0
0,0,0,0,0,0,0,0,0,0,22,5,0,0,0,5,22,0,0,0,0,0,0,0,0,0,0,0,0,0,0
0,0,0,0,0,0,0,0,0,0,0,22,9,9,9,22,0,0,0,0,0,0,0,0,0,0,0,0,0,0,0
0,0,0,0,0,0,0,0,0,0,0,0,22,22,22,0,0,0,0,0,0,0,0,0,0,0,0,0,0,0,0
0,0,0,0,0,0,0,0,0,0,0,0,0,0,0,0,0,0,0,0,0,0,0,0,0,0,0,0,0,0,0
0,0,0,0,0,0,0,0,0,0,0,0,0,0,0,0,0,0,0,0,0,0,0,0,0,0,0,0,0,0,0
0,0,0,0,0,0,0,0,0,0,0,0,0,0,0,0,0,0,0,0,0,0,0,0,0,0,0,0,0,0,0
0,0,0,0,0,0,0,0,0,0,0,0,0,0,0,0,0,0,0,0,0,0,0,0,0,0,0,0,0,0,0
0,0,0,0,0,0,0,0,0,0,0,0,0,0,0,0,0,0,0,0,0,0,0,0,0,0,0,0,0,0,0
0,0,0,0,0,0,0,0,0,0,0,0,0,0,0,0,0,0,0,0,0,0,0,0,0,0,0,0,0,0,0
0,0,0,0,0,0,0,0,0,0,0,0,0,0,0,0,0,0,0,0,0,0,0,0,0,0,0,0,0,0,0
0,0,0,0,0,0,0,0,0,0,0,0,0,0,0,0,0,0,0,0,0,0,0,0,0,0,0,0,0,0,0
:endlayer
layer: 26
0,0,0,0,0,0,0,0,0,0,0,0,0,0,0,0,0,0,0,0,0,0,0,0,0,0,0,0,0,0,0
0,0,0,0,0,0,0,0,0,0,0,0,0,0,0,0,0,0,0,0,0,0,0,0,0,0,0,0,0,0,0
0,0,0,0,0,0,0,0,0,0,0,0,0,0,0,0,0,0,0,0,0,0,0,0,0,0,0,0,0,0,0
0,0,0,0,0,0,0,0,0,0,0,0,0,0,0,0,0,0,0,0,0,0,0,0,0,0,0,0,0,0,0
0,0,0,0,0,0,0,0,0,0,0,0,0,0,0,0,0,0,0,0,0,0,0,0,0,0,0,0,0,0,0
0,0,0,0,0,0,0,0,0,0,0,0,9,16,9,0,0,0,0,0,0,0,0,0,0,0,0,0,0,0,0
0,0,0,0,0,0,0,0,0,0,0,5,0,0,0,5,0,0,0,0,0,0,0,0,0,0,0,0,0,0,0
0,0,0,0,0,0,0,0,0,0,9,0,0,0,0,0,9,0,0,0,0,0,0,0,0,0,0,0,0,0,0
0,0,0,0,0,0,0,0,0,0,16,0,0,0,0,0,16,0,0,0,0,0,0,0,0,0,0,0,0,0,0
0,0,0,0,0,0,0,0,0,0,9,0,0,0,0,0,9,0,0,0,0,0,0,0,0,0,0,0,0,0,0
0,0,0,0,0,0,0,0,0,0,0,5,0,0,0,5,0,0,0,0,0,0,0,0,0,0,0,0,0,0,0
0,0,0,0,0,0,0,0,0,0,0,0,9,16,9,0,0,0,0,0,0,0,0,0,0,0,0,0,0,0,0
0,0,0,0,0,0,0,0,0,0,0,0,0,0,0,0,0,0,0,0,0,0,0,0,0,0,0,0,0,0,0
0,0,0,0,0,0,0,0,0,0,0,0,0,0,0,0,0,0,0,0,0,0,0,0,0,0,0,0,0,0,0
0,0,0,0,0,0,0,0,0,0,0,0,0,0,0,0,0,0,0,0,0,0,0,0,0,0,0,0,0,0,0
0,0,0,0,0,0,0,0,0,0,0,0,0,0,0,0,0,0,0,0,0,0,0,0,0,0,0,0,0,0,0
0,0,0,0,0,0,0,0,0,0,0,0,0,0,0,0,0,0,0,0,0,0,0,0,0,0,0,0,0,0,0
0,0,0,0,0,0,0,0,0,0,0,0,0,0,0,0,0,0,0,0,0,0,0,0,0,0,0,0,0,0,0
0,0,0,0,0,0,0,0,0,0,0,0,0,0,0,0,0,0,0,0,0,0,0,0,0,0,0,0,0,0,0
0,0,0,0,0,0,0,0,0,0,0,0,0,0,0,0,0,0,0,0,0,0,0,0,0,0,0,0,0,0,0
0,0,0,0,0,0,0,0,0,0,0,0,0,0,0,0,0,0,0,0,0,0,0,0,0,0,0,0,0,0,0
:endlayer
layer: 27
0,0,0,0,0,0,0,0,0,0,0,0,0,0,0,0,0,0,0,0,0,0,0,0,0,0,0,0,0,0,0
0,0,0,0,0,0,0,0,0,0,0,0,0,0,0,0,0,0,0,0,0,0,0,0,0,0,0,0,0,0,0
0,0,0,0,0,0,0,0,0,0,0,0,0,0,0,0,0,0,0,0,0,0,0,0,0,0,0,0,0,0,0
0,0,0,0,0,0,0,0,0,0,0,0,0,0,0,0,0,0,0,0,0,0,0,0,0,0,0,0,0,0,0
0,0,0,0,0,0,0,0,0,0,0,0,0,0,0,0,0,0,0,0,0,0,0,0,0,0,0,0,0,0,0
0,0,0,0,0,0,0,0,0,0,0,0,9,9,9,0,0,0,0,0,0,0,0,0,0,0,0,0,0,0,0
0,0,0,0,0,0,0,0,0,0,0,5,0,0,0,5,0,0,0,0,0,0,0,0,0,0,0,0,0,0,0
0,0,0,0,0,0,0,0,0,0,9,0,0,0,0,0,9,0,0,0,0,0,0,0,0,0,0,0,0,0,0
0,0,0,0,0,0,0,0,0,0,9,0,0,0,0,0,9,0,0,0,0,0,0,0,0,0,0,0,0,0,0
0,0,0,0,0,0,0,0,0,0,9,0,0,0,0,0,9,0,0,0,0,0,0,0,0,0,0,0,0,0,0
0,0,0,0,0,0,0,0,0,0,0,5,0,0,0,5,0,0,0,0,0,0,0,0,0,0,0,0,0,0,0
0,0,0,0,0,0,0,0,0,0,0,0,9,9,9,0,0,0,0,0,0,0,0,0,0,0,0,0,0,0,0
0,0,0,0,0,0,0,0,0,0,0,0,0,0,0,0,0,0,0,0,0,0,0,0,0,0,0,0,0,0,0
0,0,0,0,0,0,0,0,0,0,0,0,0,0,0,0,0,0,0,0,0,0,0,0,0,0,0,0,0,0,0
0,0,0,0,0,0,0,0,0,0,0,0,0,0,0,0,0,0,0,0,0,0,0,0,0,0,0,0,0,0,0
0,0,0,0,0,0,0,0,0,0,0,0,0,0,0,0,0,0,0,0,0,0,0,0,0,0,0,0,0,0,0
0,0,0,0,0,0,0,0,0,0,0,0,0,0,0,0,0,0,0,0,0,0,0,0,0,0,0,0,0,0,0
0,0,0,0,0,0,0,0,0,0,0,0,0,0,0,0,0,0,0,0,0,0,0,0,0,0,0,0,0,0,0
0,0,0,0,0,0,0,0,0,0,0,0,0,0,0,0,0,0,0,0,0,0,0,0,0,0,0,0,0,0,0
0,0,0,0,0,0,0,0,0,0,0,0,0,0,0,0,0,0,0,0,0,0,0,0,0,0,0,0,0,0,0
0,0,0,0,0,0,0,0,0,0,0,0,0,0,0,0,0,0,0,0,0,0,0,0,0,0,0,0,0,0,0
:endlayer
layer: 28
0,0,0,0,0,0,0,0,0,0,0,0,0,0,0,0,0,0,0,0,0,0,0,0,0,0,0,0,0,0,0
0,0,0,0,0,0,0,0,0,0,0,0,0,0,0,0,0,0,0,0,0,0,0,0,0,0,0,0,0,0,0
0,0,0,0,0,0,0,0,0,0,0,0,0,0,0,0,0,0,0,0,0,0,0,0,0,0,0,0,0,0,0
0,0,0,0,0,0,0,0,0,0,0,0,0,0,0,0,0,0,0,0,0,0,0,0,0,0,0,0,0,0,0
0,0,0,0,0,0,0,0,0,0,0,0,21,21,21,0,0,0,0,0,0,0,0,0,0,0,0,0,0,0,0
0,0,0,0,0,0,0,0,0,0,0,21,14,14,14,21,0,0,0,0,0,0,0,0,0,0,0,0,0,0,0
0,0,0,0,0,0,0,0,0,0,21,5,0,0,0,5,21,0,0,0,0,0,0,0,0,0,0,0,0,0,0
0,0,0,0,0,0,0,0,0,21,12,0,0,0,0,0,12,21,0,0,0,0,0,0,0,0,0,0,0,0,0
0,0,0,0,0,0,0,0,0,21,12,0,0,0,0,0,12,21,0,0,0,0,0,0,0,0,0,0,0,0,0
0,0,0,0,0,0,0,0,0,21,12,0,0,0,0,0,12,21,0,0,0,0,0,0,0,0,0,0,0,0,0
0,0,0,0,0,0,0,0,0,0,21,5,0,0,0,5,21,0,0,0,0,0,0,0,0,0,0,0,0,0,0
0,0,0,0,0,0,0,0,0,0,0,21,14,14,14,21,0,0,0,0,0,0,0,0,0,0,0,0,0,0,0
0,0,0,0,0,0,0,0,0,0,0,0,21,21,21,0,0,0,0,0,0,0,0,0,0,0,0,0,0,0,0
0,0,0,0,0,0,0,0,0,0,0,0,0,0,0,0,0,0,0,0,0,0,0,0,0,0,0,0,0,0,0
0,0,0,0,0,0,0,0,0,0,0,0,0,0,0,0,0,0,0,0,0,0,0,0,0,0,0,0,0,0,0
0,0,0,0,0,0,0,0,0,0,0,0,0,0,0,0,0,0,0,0,0,0,0,0,0,0,0,0,0,0,0
0,0,0,0,0,0,0,0,0,0,0,0,0,0,0,0,0,0,0,0,0,0,0,0,0,0,0,0,0,0,0
0,0,0,0,0,0,0,0,0,0,0,0,0,0,0,0,0,0,0,0,0,0,0,0,0,0,0,0,0,0,0
0,0,0,0,0,0,0,0,0,0,0,0,0,0,0,0,0,0,0,0,0,0,0,0,0,0,0,0,0,0,0
0,0,0,0,0,0,0,0,0,0,0,0,0,0,0,0,0,0,0,0,0,0,0,0,0,0,0,0,0,0,0
0,0,0,0,0,0,0,0,0,0,0,0,0,0,0,0,0,0,0,0,0,0,0,0,0,0,0,0,0,0,0
:endlayer
layer: 29
0,0,0,0,0,0,0,0,0,0,0,0,0,0,0,0,0,0,0,0,0,0,0,0,0,0,0,0,0,0,0
0,0,0,0,0,0,0,0,0,0,0,0,0,0,0,0,0,0,0,0,0,0,0,0,0,0,0,0,0,0,0
0,0,0,0,0,0,0,0,0,0,0,0,0,0,0,0,0,0,0,0,0,0,0,0,0,0,0,0,0,0,0
0,0,0,0,0,0,0,0,0,0,0,0,0,0,0,0,0,0,0,0,0,0,0,0,0,0,0,0,0,0,0
0,0,0,0,0,0,0,0,0,0,0,0,0,0,0,0,0,0,0,0,0,0,0,0,0,0,0,0,0,0,0
0,0,0,0,0,0,0,0,0,0,0,0,21,21,21,0,0,0,0,0,0,0,0,0,0,0,0,0,0,0,0
0,0,0,0,0,0,0,0,0,0,0,21,11,13,8,21,0,0,0,0,0,0,0,0,0,0,0,0,0,0,0
0,0,0,0,0,0,0,0,0,0,21,13,16,0,16,13,21,0,0,0,0,0,0,0,0,0,0,0,0,0,0
0,0,0,0,0,0,0,0,0,0,21,11,0,0,0,8,21,0,0,0,0,0,0,0,0,0,0,0,0,0,0
0,0,0,0,0,0,0,0,0,0,21,20,16,0,16,20,21,0,0,0,0,0,0,0,0,0,0,0,0,0,0
0,0,0,0,0,0,0,0,0,0,0,21,11,20,8,21,0,0,0,0,0,0,0,0,0,0,0,0,0,0,0
0,0,0,0,0,0,0,0,0,0,0,0,21,21,21,0,0,0,0,0,0,0,0,0,0,0,0,0,0,0,0
0,0,0,0,0,0,0,0,0,0,0,0,0,0,0,0,0,0,0,0,0,0,0,0,0,0,0,0,0,0,0
0,0,0,0,0,0,0,0,0,0,0,0,0,0,0,0,0,0,0,0,0,0,0,0,0,0,0,0,0,0,0
0,0,0,0,0,0,0,0,0,0,0,0,0,0,0,0,0,0,0,0,0,0,0,0,0,0,0,0,0,0,0
0,0,0,0,0,0,0,0,0,0,0,0,0,0,0,0,0,0,0,0,0,0,0,0,0,0,0,0,0,0,0
0,0,0,0,0,0,0,0,0,0,0,0,0,0,0,0,0,0,0,0,0,0,0,0,0,0,0,0,0,0,0
0,0,0,0,0,0,0,0,0,0,0,0,0,0,0,0,0,0,0,0,0,0,0,0,0,0,0,0,0,0,0
0,0,0,0,0,0,0,0,0,0,0,0,0,0,0,0,0,0,0,0,0,0,0,0,0,0,0,0,0,0,0
0,0,0,0,0,0,0,0,0,0,0,0,0,0,0,0,0,0,0,0,0,0,0,0,0,0,0,0,0,0,0
0,0,0,0,0,0,0,0,0,0,0,0,0,0,0,0,0,0,0,0,0,0,0,0,0,0,0,0,0,0,0
:endlayer
layer: 30
0,0,0,0,0,0,0,0,0,0,0,0,0,0,0,0,0,0,0,0,0,0,0,0,0,0,0,0,0,0,0
0,0,0,0,0,0,0,0,0,0,0,0,0,0,0,0,0,0,0,0,0,0,0,0,0,0,0,0,0,0,0
0,0,0,0,0,0,0,0,0,0,0,0,0,0,0,0,0,0,0,0,0,0,0,0,0,0,0,0,0,0,0
0,0,0,0,0,0,0,0,0,0,0,0,0,0,0,0,0,0,0,0,0,0,0,0,0,0,0,0,0,0,0
0,0,0,0,0,0,0,0,0,0,0,0,0,0,0,0,0,0,0,0,0,0,0,0,0,0,0,0,0,0,0
0,0,0,0,0,0,0,0,0,0,0,0,0,21,0,0,0,0,0,0,0,0,0,0,0,0,0,0,0,0,0
0,0,0,0,0,0,0,0,0,0,0,0,21,9,21,0,0,0,0,0,0,0,0,0,0,0,0,0,0,0,0
0,0,0,0,0,0,0,0,0,0,0,21,9,15,9,21,0,0,0,0,0,0,0,0,0,0,0,0,0,0,0
0,0,0,0,0,0,0,0,0,0,21,9,18,0,15,9,21,0,0,0,0,0,0,0,0,0,0,0,0,0,0
0,0,0,0,0,0,0,0,0,0,0,21,9,19,9,21,0,0,0,0,0,0,0,0,0,0,0,0,0,0,0
0,0,0,0,0,0,0,0,0,0,0,0,21,9,21,0,0,0,0,0,0,0,0,0,0,0,0,0,0,0,0
0,0,0,0,0,0,0,0,0,0,0,0,0,21,0,0,0,0,0,0,0,0,0,0,0,0,0,0,0,0,0
0,0,0,0,0,0,0,0,0,0,0,0,0,0,0,0,0,0,0,0,0,0,0,0,0,0,0,0,0,0,0
0,0,0,0,0,0,0,0,0,0,0,0,0,0,0,0,0,0,0,0,0,0,0,0,0,0,0,0,0,0,0
0,0,0,0,0,0,0,0,0,0,0,0,0,0,0,0,0,0,0,0,0,0,0,0,0,0,0,0,0,0,0
0,0,0,0,0,0,0,0,0,0,0,0,0,0,0,0,0,0,0,0,0,0,0,0,0,0,0,0,0,0,0
0,0,0,0,0,0,0,0,0,0,0,0,0,0,0,0,0,0,0,0,0,0,0,0,0,0,0,0,0,0,0
0,0,0,0,0,0,0,0,0,0,0,0,0,0,0,0,0,0,0,0,0,0,0,0,0,0,0,0,0,0,0
0,0,0,0,0,0,0,0,0,0,0,0,0,0,0,0,0,0,0,0,0,0,0,0,0,0,0,0,0,0,0
0,0,0,0,0,0,0,0,0,0,0,0,0,0,0,0,0,0,0,0,0,0,0,0,0,0,0,0,0,0,0
0,0,0,0,0,0,0,0,0,0,0,0,0,0,0,0,0,0,0,0,0,0,0,0,0,0,0,0,0,0,0
:endlayer
layer: 31
0,0,0,0,0,0,0,0,0,0,0,0,0,0,0,0,0,0,0,0,0,0,0,0,0,0,0,0,0,0,0
0,0,0,0,0,0,0,0,0,0,0,0,0,0,0,0,0,0,0,0,0,0,0,0,0,0,0,0,0,0,0
0,0,0,0,0,0,0,0,0,0,0,0,0,0,0,0,0,0,0,0,0,0,0,0,0,0,0,0,0,0,0
0,0,0,0,0,0,0,0,0,0,0,0,0,0,0,0,0,0,0,0,0,0,0,0,0,0,0,0,0,0,0
0,0,0,0,0,0,0,0,0,0,0,0,0,0,0,0,0,0,0,0,0,0,0,0,0,0,0,0,0,0,0
0,0,0,0,0,0,0,0,0,0,0,0,0,6,0,0,0,0,0,0,0,0,0,0,0,0,0,0,0,0,0
0,0,0,0,0,0,0,0,0,0,0,0,21,21,21,0,0,0,0,0,0,0,0,0,0,0,0,0,0,0,0
0,0,0,0,0,0,0,0,0,0,0,21,9,13,9,21,0,0,0,0,0,0,0,0,0,0,0,0,0,0,0
0,0,0,0,0,0,0,0,0,0,6,21,11,0,8,21,6,0,0,0,0,0,0,0,0,0,0,0,0,0,0
0,0,0,0,0,0,0,0,0,0,0,21,9,20,9,21,0,0,0,0,0,0,0,0,0,0,0,0,0,0,0
0,0,0,0,0,0,0,0,0,0,0,0,21,21,21,0,0,0,0,0,0,0,0,0,0,0,0,0,0,0,0
0,0,0,0,0,0,0,0,0,0,0,0,0,6,0,0,0,0,0,0,0,0,0,0,0,0,0,0,0,0,0
0,0,0,0,0,0,0,0,0,0,0,0,0,0,0,0,0,0,0,0,0,0,0,0,0,0,0,0,0,0,0
0,0,0,0,0,0,0,0,0,0,0,0,0,0,0,0,0,0,0,0,0,0,0,0,0,0,0,0,0,0,0
0,0,0,0,0,0,0,0,0,0,0,0,0,0,0,0,0,0,0,0,0,0,0,0,0,0,0,0,0,0,0
0,0,0,0,0,0,0,0,0,0,0,0,0,0,0,0,0,0,0,0,0,0,0,0,0,0,0,0,0,0,0
0,0,0,0,0,0,0,0,0,0,0,0,0,0,0,0,0,0,0,0,0,0,0,0,0,0,0,0,0,0,0
0,0,0,0,0,0,0,0,0,0,0,0,0,0,0,0,0,0,0,0,0,0,0,0,0,0,0,0,0,0,0
0,0,0,0,0,0,0,0,0,0,0,0,0,0,0,0,0,0,0,0,0,0,0,0,0,0,0,0,0,0,0
0,0,0,0,0,0,0,0,0,0,0,0,0,0,0,0,0,0,0,0,0,0,0,0,0,0,0,0,0,0,0
0,0,0,0,0,0,0,0,0,0,0,0,0,0,0,0,0,0,0,0,0,0,0,0,0,0,0,0,0,0,0
:endlayer
layer: 32
0,0,0,0,0,0,0,0,0,0,0,0,0,0,0,0,0,0,0,0,0,0,0,0,0,0,0,0,0,0,0
0,0,0,0,0,0,0,0,0,0,0,0,0,0,0,0,0,0,0,0,0,0,0,0,0,0,0,0,0,0,0
0,0,0,0,0,0,0,0,0,0,0,0,0,0,0,0,0,0,0,0,0,0,0,0,0,0,0,0,0,0,0
0,0,0,0,0,0,0,0,0,0,0,0,0,0,0,0,0,0,0,0,0,0,0,0,0,0,0,0,0,0,0
0,0,0,0,0,0,0,0,0,0,0,0,0,0,0,0,0,0,0,0,0,0,0,0,0,0,0,0,0,0,0
0,0,0,0,0,0,0,0,0,0,0,0,0,0,0,0,0,0,0,0,0,0,0,0,0,0,0,0,0,0,0
0,0,0,0,0,0,0,0,0,0,0,0,0,21,0,0,0,0,0,0,0,0,0,0,0,0,0,0,0,0,0
0,0,0,0,0,0,0,0,0,0,0,0,21,21,21,0,0,0,0,0,0,0,0,0,0,0,0,0,0,0,0
0,0,0,0,0,0,0,0,0,0,0,21,21,9,21,21,0,0,0,0,0,0,0,0,0,0,0,0,0,0,0
0,0,0,0,0,0,0,0,0,0,0,0,21,21,21,0,0,0,0,0,0,0,0,0,0,0,0,0,0,0,0
0,0,0,0,0,0,0,0,0,0,0,0,0,21,0,0,0,0,0,0,0,0,0,0,0,0,0,0,0,0,0
0,0,0,0,0,0,0,0,0,0,0,0,0,0,0,0,0,0,0,0,0,0,0,0,0,0,0,0,0,0,0
0,0,0,0,0,0,0,0,0,0,0,0,0,0,0,0,0,0,0,0,0,0,0,0,0,0,0,0,0,0,0
0,0,0,0,0,0,0,0,0,0,0,0,0,0,0,0,0,0,0,0,0,0,0,0,0,0,0,0,0,0,0
0,0,0,0,0,0,0,0,0,0,0,0,0,0,0,0,0,0,0,0,0,0,0,0,0,0,0,0,0,0,0
0,0,0,0,0,0,0,0,0,0,0,0,0,0,0,0,0,0,0,0,0,0,0,0,0,0,0,0,0,0,0
0,0,0,0,0,0,0,0,0,0,0,0,0,0,0,0,0,0,0,0,0,0,0,0,0,0,0,0,0,0,0
0,0,0,0,0,0,0,0,0,0,0,0,0,0,0,0,0,0,0,0,0,0,0,0,0,0,0,0,0,0,0
0,0,0,0,0,0,0,0,0,0,0,0,0,0,0,0,0,0,0,0,0,0,0,0,0,0,0,0,0,0,0
0,0,0,0,0,0,0,0,0,0,0,0,0,0,0,0,0,0,0,0,0,0,0,0,0,0,0,0,0,0,0
0,0,0,0,0,0,0,0,0,0,0,0,0,0,0,0,0,0,0,0,0,0,0,0,0,0,0,0,0,0,0
:endlayer
layer: 33
0,0,0,0,0,0,0,0,0,0,0,0,0,0,0,0,0,0,0,0,0,0,0,0,0,0,0,0,0,0,0
0,0,0,0,0,0,0,0,0,0,0,0,0,0,0,0,0,0,0,0,0,0,0,0,0,0,0,0,0,0,0
0,0,0,0,0,0,0,0,0,0,0,0,0,0,0,0,0,0,0,0,0,0,0,0,0,0,0,0,0,0,0
0,0,0,0,0,0,0,0,0,0,0,0,0,0,0,0,0,0,0,0,0,0,0,0,0,0,0,0,0,0,0
0,0,0,0,0,0,0,0,0,0,0,0,0,0,0,0,0,0,0,0,0,0,0,0,0,0,0,0,0,0,0
0,0,0,0,0,0,0,0,0,0,0,0,0,0,0,0,0,0,0,0,0,0,0,0,0,0,0,0,0,0,0
0,0,0,0,0,0,0,0,0,0,0,0,0,0,0,0,0,0,0,0,0,0,0,0,0,0,0,0,0,0,0
0,0,0,0,0,0,0,0,0,0,0,0,21,21,21,0,0,0,0,0,0,0,0,0,0,0,0,0,0,0,0
0,0,0,0,0,0,0,0,0,0,0,0,21,9,21,0,0,0,0,0,0,0,0,0,0,0,0,0,0,0,0
0,0,0,0,0,0,0,0,0,0,0,0,21,21,21,0,0,0,0,0,0,0,0,0,0,0,0,0,0,0,0
0,0,0,0,0,0,0,0,0,0,0,0,0,0,0,0,0,0,0,0,0,0,0,0,0,0,0,0,0,0,0
0,0,0,0,0,0,0,0,0,0,0,0,0,0,0,0,0,0,0,0,0,0,0,0,0,0,0,0,0,0,0
0,0,0,0,0,0,0,0,0,0,0,0,0,0,0,0,0,0,0,0,0,0,0,0,0,0,0,0,0,0,0
0,0,0,0,0,0,0,0,0,0,0,0,0,0,0,0,0,0,0,0,0,0,0,0,0,0,0,0,0,0,0
0,0,0,0,0,0,0,0,0,0,0,0,0,0,0,0,0,0,0,0,0,0,0,0,0,0,0,0,0,0,0
0,0,0,0,0,0,0,0,0,0,0,0,0,0,0,0,0,0,0,0,0,0,0,0,0,0,0,0,0,0,0
0,0,0,0,0,0,0,0,0,0,0,0,0,0,0,0,0,0,0,0,0,0,0,0,0,0,0,0,0,0,0
0,0,0,0,0,0,0,0,0,0,0,0,0,0,0,0,0,0,0,0,0,0,0,0,0,0,0,0,0,0,0
0,0,0,0,0,0,0,0,0,0,0,0,0,0,0,0,0,0,0,0,0,0,0,0,0,0,0,0,0,0,0
0,0,0,0,0,0,0,0,0,0,0,0,0,0,0,0,0,0,0,0,0,0,0,0,0,0,0,0,0,0,0
0,0,0,0,0,0,0,0,0,0,0,0,0,0,0,0,0,0,0,0,0,0,0,0,0,0,0,0,0,0,0
:endlayer
layer: 34
0,0,0,0,0,0,0,0,0,0,0,0,0,0,0,0,0,0,0,0,0,0,0,0,0,0,0,0,0,0,0
0,0,0,0,0,0,0,0,0,0,0,0,0,0,0,0,0,0,0,0,0,0,0,0,0,0,0,0,0,0,0
0,0,0,0,0,0,0,0,0,0,0,0,0,0,0,0,0,0,0,0,0,0,0,0,0,0,0,0,0,0,0
0,0,0,0,0,0,0,0,0,0,0,0,0,0,0,0,0,0,0,0,0,0,0,0,0,0,0,0,0,0,0
0,0,0,0,0,0,0,0,0,0,0,0,0,0,0,0,0,0,0,0,0,0,0,0,0,0,0,0,0,0,0
0,0,0,0,0,0,0,0,0,0,0,0,0,0,0,0,0,0,0,0,0,0,0,0,0,0,0,0,0,0,0
0,0,0,0,0,0,0,0,0,0,0,0,0,0,0,0,0,0,0,0,0,0,0,0,0,0,0,0,0,0,0
0,0,0,0,0,0,0,0,0,0,0,0,0,21,0,0,0,0,0,0,0,0,0,0,0,0,0,0,0,0,0
0,0,0,0,0,0,0,0,0,0,0,0,21,9,21,0,0,0,0,0,0,0,0,0,0,0,0,0,0,0,0
0,0,0,0,0,0,0,0,0,0,0,0,0,21,0,0,0,0,0,0,0,0,0,0,0,0,0,0,0,0,0
0,0,0,0,0,0,0,0,0,0,0,0,0,0,0,0,0,0,0,0,0,0,0,0,0,0,0,0,0,0,0
0,0,0,0,0,0,0,0,0,0,0,0,0,0,0,0,0,0,0,0,0,0,0,0,0,0,0,0,0,0,0
0,0,0,0,0,0,0,0,0,0,0,0,0,0,0,0,0,0,0,0,0,0,0,0,0,0,0,0,0,0,0
0,0,0,0,0,0,0,0,0,0,0,0,0,0,0,0,0,0,0,0,0,0,0,0,0,0,0,0,0,0,0
0,0,0,0,0,0,0,0,0,0,0,0,0,0,0,0,0,0,0,0,0,0,0,0,0,0,0,0,0,0,0
0,0,0,0,0,0,0,0,0,0,0,0,0,0,0,0,0,0,0,0,0,0,0,0,0,0,0,0,0,0,0
0,0,0,0,0,0,0,0,0,0,0,0,0,0,0,0,0,0,0,0,0,0,0,0,0,0,0,0,0,0,0
0,0,0,0,0,0,0,0,0,0,0,0,0,0,0,0,0,0,0,0,0,0,0,0,0,0,0,0,0,0,0
0,0,0,0,0,0,0,0,0,0,0,0,0,0,0,0,0,0,0,0,0,0,0,0,0,0,0,0,0,0,0
0,0,0,0,0,0,0,0,0,0,0,0,0,0,0,0,0,0,0,0,0,0,0,0,0,0,0,0,0,0,0
0,0,0,0,0,0,0,0,0,0,0,0,0,0,0,0,0,0,0,0,0,0,0,0,0,0,0,0,0,0,0
:endlayer
layer: 35
0,0,0,0,0,0,0,0,0,0,0,0,0,0,0,0,0,0,0,0,0,0,0,0,0,0,0,0,0,0,0
0,0,0,0,0,0,0,0,0,0,0,0,0,0,0,0,0,0,0,0,0,0,0,0,0,0,0,0,0,0,0
0,0,0,0,0,0,0,0,0,0,0,0,0,0,0,0,0,0,0,0,0,0,0,0,0,0,0,0,0,0,0
0,0,0,0,0,0,0,0,0,0,0,0,0,0,0,0,0,0,0,0,0,0,0,0,0,0,0,0,0,0,0
0,0,0,0,0,0,0,0,0,0,0,0,0,0,0,0,0,0,0,0,0,0,0,0,0,0,0,0,0,0,0
0,0,0,0,0,0,0,0,0,0,0,0,0,0,0,0,0,0,0,0,0,0,0,0,0,0,0,0,0,0,0
0,0,0,0,0,0,0,0,0,0,0,0,0,0,0,0,0,0,0,0,0,0,0,0,0,0,0,0,0,0,0
0,0,0,0,0,0,0,0,0,0,0,0,0,21,0,0,0,0,0,0,0,0,0,0,0,0,0,0,0,0,0
0,0,0,0,0,0,0,0,0,0,0,0,21,21,21,0,0,0,0,0,0,0,0,0,0,0,0,0,0,0,0
0,0,0,0,0,0,0,0,0,0,0,0,0,21,0,0,0,0,0,0,0,0,0,0,0,0,0,0,0,0,0
0,0,0,0,0,0,0,0,0,0,0,0,0,0,0,0,0,0,0,0,0,0,0,0,0,0,0,0,0,0,0
0,0,0,0,0,0,0,0,0,0,0,0,0,0,0,0,0,0,0,0,0,0,0,0,0,0,0,0,0,0,0
0,0,0,0,0,0,0,0,0,0,0,0,0,0,0,0,0,0,0,0,0,0,0,0,0,0,0,0,0,0,0
0,0,0,0,0,0,0,0,0,0,0,0,0,0,0,0,0,0,0,0,0,0,0,0,0,0,0,0,0,0,0
0,0,0,0,0,0,0,0,0,0,0,0,0,0,0,0,0,0,0,0,0,0,0,0,0,0,0,0,0,0,0
0,0,0,0,0,0,0,0,0,0,0,0,0,0,0,0,0,0,0,0,0,0,0,0,0,0,0,0,0,0,0
0,0,0,0,0,0,0,0,0,0,0,0,0,0,0,0,0,0,0,0,0,0,0,0,0,0,0,0,0,0,0
0,0,0,0,0,0,0,0,0,0,0,0,0,0,0,0,0,0,0,0,0,0,0,0,0,0,0,0,0,0,0
0,0,0,0,0,0,0,0,0,0,0,0,0,0,0,0,0,0,0,0,0,0,0,0,0,0,0,0,0,0,0
0,0,0,0,0,0,0,0,0,0,0,0,0,0,0,0,0,0,0,0,0,0,0,0,0,0,0,0,0,0,0
0,0,0,0,0,0,0,0,0,0,0,0,0,0,0,0,0,0,0,0,0,0,0,0,0,0,0,0,0,0,0
:endlayer
layer: 36
0,0,0,0,0,0,0,0,0,0,0,0,0,0,0,0,0,0,0,0,0,0,0,0,0,0,0,0,0,0,0
0,0,0,0,0,0,0,0,0,0,0,0,0,0,0,0,0,0,0,0,0,0,0,0,0,0,0,0,0,0,0
0,0,0,0,0,0,0,0,0,0,0,0,0,0,0,0,0,0,0,0,0,0,0,0,0,0,0,0,0,0,0
0,0,0,0,0,0,0,0,0,0,0,0,0,0,0,0,0,0,0,0,0,0,0,0,0,0,0,0,0,0,0
0,0,0,0,0,0,0,0,0,0,0,0,0,0,0,0,0,0,0,0,0,0,0,0,0,0,0,0,0,0,0
0,0,0,0,0,0,0,0,0,0,0,0,0,0,0,0,0,0,0,0,0,0,0,0,0,0,0,0,0,0,0
0,0,0,0,0,0,0,0,0,0,0,0,0,0,0,0,0,0,0,0,0,0,0,0,0,0,0,0,0,0,0
0,0,0,0,0,0,0,0,0,0,0,0,0,6,0,0,0,0,0,0,0,0,0,0,0,0,0,0,0,0,0
0,0,0,0,0,0,0,0,0,0,0,0,6,21,6,0,0,0,0,0,0,0,0,0,0,0,0,0,0,0,0
0,0,0,0,0,0,0,0,0,0,0,0,0,6,0,0,0,0,0,0,0,0,0,0,0,0,0,0,0,0,0
0,0,0,0,0,0,0,0,0,0,0,0,0,0,0,0,0,0,0,0,0,0,0,0,0,0,0,0,0,0,0
0,0,0,0,0,0,0,0,0,0,0,0,0,0,0,0,0,0,0,0,0,0,0,0,0,0,0,0,0,0,0
0,0,0,0,0,0,0,0,0,0,0,0,0,0,0,0,0,0,0,0,0,0,0,0,0,0,0,0,0,0,0
0,0,0,0,0,0,0,0,0,0,0,0,0,0,0,0,0,0,0,0,0,0,0,0,0,0,0,0,0,0,0
0,0,0,0,0,0,0,0,0,0,0,0,0,0,0,0,0,0,0,0,0,0,0,0,0,0,0,0,0,0,0
0,0,0,0,0,0,0,0,0,0,0,0,0,0,0,0,0,0,0,0,0,0,0,0,0,0,0,0,0,0,0
0,0,0,0,0,0,0,0,0,0,0,0,0,0,0,0,0,0,0,0,0,0,0,0,0,0,0,0,0,0,0
0,0,0,0,0,0,0,0,0,0,0,0,0,0,0,0,0,0,0,0,0,0,0,0,0,0,0,0,0,0,0
0,0,0,0,0,0,0,0,0,0,0,0,0,0,0,0,0,0,0,0,0,0,0,0,0,0,0,0,0,0,0
0,0,0,0,0,0,0,0,0,0,0,0,0,0,0,0,0,0,0,0,0,0,0,0,0,0,0,0,0,0,0
0,0,0,0,0,0,0,0,0,0,0,0,0,0,0,0,0,0,0,0,0,0,0,0,0,0,0,0,0,0,0
:endlayer
layer: 37
0,0,0,0,0,0,0,0,0,0,0,0,0,0,0,0,0,0,0,0,0,0,0,0,0,0,0,0,0,0,0
0,0,0,0,0,0,0,0,0,0,0,0,0,0,0,0,0,0,0,0,0,0,0,0,0,0,0,0,0,0,0
0,0,0,0,0,0,0,0,0,0,0,0,0,0,0,0,0,0,0,0,0,0,0,0,0,0,0,0,0,0,0
0,0,0,0,0,0,0,0,0,0,0,0,0,0,0,0,0,0,0,0,0,0,0,0,0,0,0,0,0,0,0
0,0,0,0,0,0,0,0,0,0,0,0,0,0,0,0,0,0,0,0,0,0,0,0,0,0,0,0,0,0,0
0,0,0,0,0,0,0,0,0,0,0,0,0,0,0,0,0,0,0,0,0,0,0,0,0,0,0,0,0,0,0
0,0,0,0,0,0,0,0,0,0,0,0,0,0,0,0,0,0,0,0,0,0,0,0,0,0,0,0,0,0,0
0,0,0,0,0,0,0,0,0,0,0,0,0,0,0,0,0,0,0,0,0,0,0,0,0,0,0,0,0,0,0
0,0,0,0,0,0,0,0,0,0,0,0,0,21,0,0,0,0,0,0,0,0,0,0,0,0,0,0,0,0,0
0,0,0,0,0,0,0,0,0,0,0,0,0,0,0,0,0,0,0,0,0,0,0,0,0,0,0,0,0,0,0
0,0,0,0,0,0,0,0,0,0,0,0,0,0,0,0,0,0,0,0,0,0,0,0,0,0,0,0,0,0,0
0,0,0,0,0,0,0,0,0,0,0,0,0,0,0,0,0,0,0,0,0,0,0,0,0,0,0,0,0,0,0
0,0,0,0,0,0,0,0,0,0,0,0,0,0,0,0,0,0,0,0,0,0,0,0,0,0,0,0,0,0,0
0,0,0,0,0,0,0,0,0,0,0,0,0,0,0,0,0,0,0,0,0,0,0,0,0,0,0,0,0,0,0
0,0,0,0,0,0,0,0,0,0,0,0,0,0,0,0,0,0,0,0,0,0,0,0,0,0,0,0,0,0,0
0,0,0,0,0,0,0,0,0,0,0,0,0,0,0,0,0,0,0,0,0,0,0,0,0,0,0,0,0,0,0
0,0,0,0,0,0,0,0,0,0,0,0,0,0,0,0,0,0,0,0,0,0,0,0,0,0,0,0,0,0,0
0,0,0,0,0,0,0,0,0,0,0,0,0,0,0,0,0,0,0,0,0,0,0,0,0,0,0,0,0,0,0
0,0,0,0,0,0,0,0,0,0,0,0,0,0,0,0,0,0,0,0,0,0,0,0,0,0,0,0,0,0,0
0,0,0,0,0,0,0,0,0,0,0,0,0,0,0,0,0,0,0,0,0,0,0,0,0,0,0,0,0,0,0
0,0,0,0,0,0,0,0,0,0,0,0,0,0,0,0,0,0,0,0,0,0,0,0,0,0,0,0,0,0,0
:endlayer
layer: 38
0,0,0,0,0,0,0,0,0,0,0,0,0,0,0,0,0,0,0,0,0,0,0,0,0,0,0,0,0,0,0
0,0,0,0,0,0,0,0,0,0,0,0,0,0,0,0,0,0,0,0,0,0,0,0,0,0,0,0,0,0,0
0,0,0,0,0,0,0,0,0,0,0,0,0,0,0,0,0,0,0,0,0,0,0,0,0,0,0,0,0,0,0
0,0,0,0,0,0,0,0,0,0,0,0,0,0,0,0,0,0,0,0,0,0,0,0,0,0,0,0,0,0,0
0,0,0,0,0,0,0,0,0,0,0,0,0,0,0,0,0,0,0,0,0,0,0,0,0,0,0,0,0,0,0
0,0,0,0,0,0,0,0,0,0,0,0,0,0,0,0,0,0,0,0,0,0,0,0,0,0,0,0,0,0,0
0,0,0,0,0,0,0,0,0,0,0,0,0,0,0,0,0,0,0,0,0,0,0,0,0,0,0,0,0,0,0
0,0,0,0,0,0,0,0,0,0,0,0,0,0,0,0,0,0,0,0,0,0,0,0,0,0,0,0,0,0,0
0,0,0,0,0,0,0,0,0,0,0,0,0,16,0,0,0,0,0,0,0,0,0,0,0,0,0,0,0,0,0
0,0,0,0,0,0,0,0,0,0,0,0,0,0,0,0,0,0,0,0,0,0,0,0,0,0,0,0,0,0,0
0,0,0,0,0,0,0,0,0,0,0,0,0,0,0,0,0,0,0,0,0,0,0,0,0,0,0,0,0,0,0
0,0,0,0,0,0,0,0,0,0,0,0,0,0,0,0,0,0,0,0,0,0,0,0,0,0,0,0,0,0,0
0,0,0,0,0,0,0,0,0,0,0,0,0,0,0,0,0,0,0,0,0,0,0,0,0,0,0,0,0,0,0
0,0,0,0,0,0,0,0,0,0,0,0,0,0,0,0,0,0,0,0,0,0,0,0,0,0,0,0,0,0,0
0,0,0,0,0,0,0,0,0,0,0,0,0,0,0,0,0,0,0,0,0,0,0,0,0,0,0,0,0,0,0
0,0,0,0,0,0,0,0,0,0,0,0,0,0,0,0,0,0,0,0,0,0,0,0,0,0,0,0,0,0,0
0,0,0,0,0,0,0,0,0,0,0,0,0,0,0,0,0,0,0,0,0,0,0,0,0,0,0,0,0,0,0
0,0,0,0,0,0,0,0,0,0,0,0,0,0,0,0,0,0,0,0,0,0,0,0,0,0,0,0,0,0,0
0,0,0,0,0,0,0,0,0,0,0,0,0,0,0,0,0,0,0,0,0,0,0,0,0,0,0,0,0,0,0
0,0,0,0,0,0,0,0,0,0,0,0,0,0,0,0,0,0,0,0,0,0,0,0,0,0,0,0,0,0,0
0,0,0,0,0,0,0,0,0,0,0,0,0,0,0,0,0,0,0,0,0,0,0,0,0,0,0,0,0,0,0
:endlayer

#### RULES ####
rule:
plugin=vanillaBlocks
number=1
data:
JSON:{blockState:{blockName:"minecraft:grass",properties:{snowy:"false"}}}
:enddata
:endrule

rule:
plugin=vanillaBlocks
number=2
data:
JSON:{blockState:{blockName:"minecraft:stonebrick",properties:{variant:"stonebrick"}}}
:enddata
:endrule

rule:
plugin=vanillaBlocks
number=3
data:
JSON:{blockState:{blockName:"minecraft:cobblestone"}}
:enddata
:endrule

rule:
plugin=vanillaBlocks
number=4
data:
JSON:{blockState:{blockName:"minecraft:dirt",properties:{variant:"dirt",snowy:"false"}}}
:enddata
:endrule

rule:
plugin=vanillaBlocks
number=5
data:
JSON:{blockState:{blockName:"biomesoplenty:log_2",properties:{variant:"redwood",axis:"y"}}}
:enddata
:endrule

rule:
plugin=vanillaBlocks
number=6
data:
JSON:{blockState:{blockName:"minecraft:torch",properties:{facing:"up"}}}
:enddata
:endrule

rule:
plugin=vanillaBlocks
number=7
data:
JSON:{blockState:{blockName:"biomesoplenty:redwood_stairs",properties:{half:"bottom",shape:"straight",facing:"west"}}}
:enddata
:endrule

rule:
plugin=vanillaBlocks
number=8
data:
JSON:{blockState:{blockName:"biomesoplenty:redwood_stairs",properties:{half:"top",shape:"straight",facing:"east"}}}
:enddata
:endrule

rule:
plugin=vanillaBlocks
number=9
data:
JSON:{blockState:{blockName:"biomesoplenty:planks_0",properties:{variant:"redwood"}}}
:enddata
:endrule

rule:
plugin=vanillaBlocks
number=10
data:
JSON:{blockState:{blockName:"biomesoplenty:wood_slab_1",properties:{half:"top",variant:"redwood"}}}
:enddata
:endrule

rule:
plugin=vanillaBlocks
number=11
data:
JSON:{blockState:{blockName:"biomesoplenty:redwood_stairs",properties:{half:"top",shape:"straight",facing:"west"}}}
:enddata
:endrule

rule:
plugin=vanillaBlocks
number=12
data:
JSON:{blockState:{blockName:"biomesoplenty:log_2",properties:{variant:"redwood",axis:"z"}}}
:enddata
:endrule

rule:
plugin=vanillaBlocks
number=13
data:
JSON:{blockState:{blockName:"biomesoplenty:redwood_stairs",properties:{half:"top",shape:"straight",facing:"north"}}}
:enddata
:endrule

rule:
plugin=vanillaBlocks
number=14
data:
JSON:{blockState:{blockName:"biomesoplenty:log_2",properties:{variant:"redwood",axis:"x"}}}
:enddata
:endrule

rule:
plugin=vanillaBlocks
number=15
data:
JSON:{blockState:{blockName:"minecraft:torch",properties:{facing:"south"}}}
:enddata
:endrule

rule:
plugin=vanillaBlocks
number=16
data:
JSON:{blockState:{blockName:"biomesoplenty:redwood_fence",properties:{east:"false",south:"false",north:"false",west:"false"}}}
:enddata
:endrule

rule:
plugin=vanillaBlocks
number=17
data:
JSON:{blockState:{blockName:"minecraft:torch",properties:{facing:"west"}}}
:enddata
:endrule

rule:
plugin=vanillaBlocks
number=18
data:
JSON:{blockState:{blockName:"minecraft:torch",properties:{facing:"east"}}}
:enddata
:endrule

rule:
plugin=vanillaBlocks
number=19
data:
JSON:{blockState:{blockName:"minecraft:torch",properties:{facing:"north"}}}
:enddata
:endrule

rule:
plugin=vanillaBlocks
number=20
data:
JSON:{blockState:{blockName:"biomesoplenty:redwood_stairs",properties:{half:"top",shape:"straight",facing:"south"}}}
:enddata
:endrule

rule:
plugin=vanillaBlocks
number=21
data:
JSON:{blockState:{blockName:"minecraft:wool",properties:{color:"brown"}}}
:enddata
:endrule

rule:
plugin=vanillaBlocks
number=22
data:
JSON:{blockState:{blockName:"biomesoplenty:wood_slab_1",properties:{half:"bottom",variant:"redwood"}}}
:enddata
:endrule

#### ENTITIES ####
