# Ancient Warfare Structure Template File
# Auto-generated structure template file. created on: 9/23/2023 at: 0:41:57
# Lines beginning with # denote comments

header:
version=2.11
name=SB_KieavarusCol_Church_1_hellbark
mods=biomesoplenty
size=19,37,34
offset=9,2,33
:endheader

#### VALIDATION ####
validation:
type=ground
structureAuthor=TheOddlySeagull
survival=true
worldGenEnabled=false
unique=false
preserveBlocks=false
preventNaturalHostileSpawns=false
selectionWeight=1
clusterValue=1
minDuplicateDistance=1
dimensionWhiteList=true
dimensionList=
biomeGroupList=
biomeWhiteList=true
biomeList=
leveling=0
fill=0
border=0
blockSwap=false
territoryName=
biomeReplacement=minecraft:
minGenerationHeight=0
maxGenerationHeight=255
:endvalidation

#### LAYERS ####
layer: 0
1,1,1,1,1,1,1,1,1,1,1,1,1,1,1,1,1,1,1
1,1,1,1,1,1,2,2,2,2,2,2,2,1,1,1,1,1,1
1,1,1,1,1,1,2,2,2,2,2,2,2,1,1,1,1,1,1
1,1,1,1,1,1,2,2,2,2,2,2,2,1,1,1,1,1,1
1,1,1,1,2,2,2,2,2,2,2,2,2,2,2,1,1,1,1
1,1,1,1,2,2,2,2,2,2,2,2,2,2,2,1,1,1,1
1,1,1,2,2,2,2,2,2,2,2,2,2,2,2,2,1,1,1
1,1,1,1,2,2,2,2,2,2,2,2,2,2,2,1,1,1,1
1,1,1,1,2,2,2,2,2,2,2,2,2,2,2,1,1,1,1
1,1,1,1,2,2,2,2,2,2,2,2,2,2,2,1,1,1,1
1,1,1,1,2,2,2,2,2,2,2,2,2,2,2,1,1,1,1
1,1,1,2,2,2,2,2,2,2,2,2,2,2,2,2,1,1,1
1,1,1,1,2,2,2,2,2,2,2,2,2,2,2,1,1,1,1
1,2,2,2,2,2,2,2,2,2,2,2,2,2,2,2,2,2,1
1,2,2,2,2,2,2,2,2,2,2,2,2,2,2,2,2,2,1
2,2,2,2,2,2,2,2,2,2,2,2,2,2,2,2,2,2,2
1,2,2,2,2,2,2,2,2,2,2,2,2,2,2,2,2,2,1
1,2,2,2,2,2,2,2,2,2,2,2,2,2,2,2,2,2,1
1,2,2,2,2,2,2,2,2,2,2,2,2,2,2,2,2,2,1
1,2,2,2,2,2,2,2,2,2,2,2,2,2,2,2,2,2,1
2,2,2,2,2,2,2,2,2,2,2,2,2,2,2,2,2,2,2
1,2,2,2,2,2,2,2,2,2,2,2,2,2,2,2,2,2,1
2,2,2,2,2,2,2,2,2,2,2,2,2,2,2,2,2,2,2
1,2,2,2,2,2,2,2,2,2,2,2,2,2,2,2,2,2,1
1,2,2,2,2,2,2,2,2,2,2,2,2,2,2,2,2,2,1
1,2,2,2,2,2,2,2,2,2,2,2,2,2,2,2,2,2,1
1,2,2,2,2,2,2,2,2,2,2,2,2,2,2,2,2,2,1
2,2,2,2,2,2,2,2,2,2,2,2,2,2,2,2,2,2,2
1,2,2,2,2,2,2,2,2,2,2,2,2,2,2,2,2,2,1
1,2,2,2,2,2,2,2,2,2,2,2,2,2,2,2,2,2,1
1,1,2,2,2,2,2,2,2,2,2,2,2,2,2,2,2,1,1
1,1,2,2,2,2,2,2,2,2,2,2,2,2,2,2,2,1,1
1,1,1,1,2,1,1,2,1,1,1,2,1,1,2,1,1,1,1
1,1,1,1,1,1,1,1,1,1,1,1,1,1,1,1,1,1,1
:endlayer
layer: 1
3,3,3,3,3,3,3,3,3,3,3,3,3,3,3,3,3,3,3
3,3,3,3,3,3,2,2,2,2,2,2,2,3,3,3,3,3,3
3,3,3,3,3,3,2,2,2,2,2,2,2,3,3,3,3,3,3
3,3,3,3,3,3,2,2,2,2,2,2,2,3,3,3,3,3,3
3,3,3,3,2,2,2,2,2,2,2,2,2,2,2,3,3,3,3
3,3,3,3,2,4,0,0,0,0,0,0,0,0,2,3,3,3,3
3,3,3,2,2,4,0,0,0,0,0,0,0,0,2,2,3,3,3
3,3,3,3,2,5,0,0,0,0,0,0,0,0,2,3,3,3,3
3,3,3,3,2,0,0,0,0,0,0,0,0,0,2,3,3,3,3
3,3,3,3,2,0,0,0,0,6,0,0,0,0,2,3,3,3,3
3,3,3,3,2,0,0,0,0,0,0,0,0,0,2,3,3,3,3
3,3,3,2,2,0,0,0,0,0,0,0,0,0,2,2,3,3,3
3,3,3,3,2,0,0,0,0,0,0,0,0,0,2,3,3,3,3
3,2,2,2,2,0,0,0,0,0,0,0,0,0,2,2,2,2,3
3,2,5,0,0,0,0,0,0,0,0,0,0,0,0,0,5,2,3
2,2,0,0,0,0,0,0,0,0,0,0,0,0,0,0,0,2,2
3,2,0,0,0,0,0,0,0,0,0,0,0,0,0,0,0,2,3
3,2,0,0,0,0,0,0,0,6,0,0,0,0,0,0,0,2,3
3,2,0,0,0,0,0,0,0,0,0,0,0,0,0,0,0,2,3
3,2,0,0,0,0,0,0,0,0,0,0,0,0,0,0,0,2,3
2,2,0,0,0,0,0,0,0,0,0,0,0,0,0,0,0,2,2
3,2,0,0,0,0,0,0,0,0,0,0,0,0,0,0,0,2,3
2,2,0,0,0,0,0,0,0,0,0,0,0,0,0,0,0,2,2
3,2,0,0,0,0,0,0,0,0,0,0,0,0,0,0,0,2,3
3,2,0,0,0,0,0,0,0,6,0,0,0,0,0,0,0,2,3
3,2,0,0,0,0,0,0,0,0,0,0,0,0,0,0,0,2,3
3,2,0,0,0,0,0,0,0,0,0,0,0,0,0,0,0,2,3
2,2,0,0,0,0,0,0,0,0,0,0,0,0,0,0,0,2,2
3,2,5,0,0,0,0,0,0,0,0,0,0,0,0,0,5,2,3
3,2,2,2,2,2,2,2,2,2,2,2,2,2,2,2,2,2,3
3,7,2,2,2,2,2,2,2,2,2,2,2,2,2,2,2,7,3
3,7,2,2,2,2,2,2,2,2,2,2,2,2,2,2,2,7,3
3,7,2,2,2,3,3,2,3,3,3,2,3,3,2,2,2,7,3
3,7,2,2,7,3,3,3,3,3,3,3,3,3,7,2,2,7,3
:endlayer
layer: 2
0,0,0,0,0,0,0,0,0,0,0,0,0,0,0,0,0,0,0
0,0,0,0,0,0,5,8,8,8,8,8,5,0,0,0,0,0,0
0,0,0,0,0,0,8,8,8,8,8,8,8,0,0,0,0,0,0
0,0,0,0,0,0,8,8,8,8,8,8,8,0,0,0,0,0,0
0,0,0,0,5,8,5,8,8,8,8,8,5,8,5,0,0,0,0
0,0,0,0,8,4,0,0,0,0,0,0,0,0,8,0,0,0,0
0,0,0,5,5,4,0,0,0,0,0,0,0,0,5,5,0,0,0
0,0,0,0,8,5,0,0,0,0,0,0,0,0,8,0,0,0,0
0,0,0,0,8,0,0,0,0,0,0,0,0,0,8,0,0,0,0
0,0,0,0,8,0,0,0,0,0,0,0,0,0,8,0,0,0,0
0,0,0,0,8,0,0,0,0,0,0,0,0,0,8,0,0,0,0
0,0,0,5,5,0,0,0,0,0,0,0,0,0,5,5,0,0,0
0,0,0,0,8,0,0,0,0,0,0,0,0,0,8,0,0,0,0
0,5,8,8,5,0,0,0,0,0,0,0,0,0,5,8,8,5,0
0,8,5,0,0,0,0,0,0,0,0,0,0,0,0,0,5,8,0
5,5,0,0,0,0,0,0,0,0,0,0,0,0,0,0,0,5,5
0,8,0,0,0,0,0,0,0,0,0,0,0,0,0,0,0,8,0
0,8,0,0,0,0,0,0,0,0,0,0,0,0,0,0,0,8,0
0,8,0,0,0,0,0,0,0,0,0,0,0,0,0,0,0,8,0
0,8,0,0,0,0,0,0,0,0,0,0,0,0,0,0,0,8,0
5,5,0,0,0,0,0,0,0,0,0,0,0,0,0,0,0,5,5
0,8,0,0,0,0,0,0,0,0,0,0,0,0,0,0,0,8,0
5,5,0,0,0,0,0,0,0,0,0,0,0,0,0,0,0,5,5
0,8,0,0,0,0,0,0,0,0,0,0,0,0,0,0,0,8,0
0,8,0,0,0,0,0,0,0,0,0,0,0,0,0,0,0,8,0
0,8,0,0,0,0,0,0,0,0,0,0,0,0,0,0,0,8,0
0,8,0,0,0,0,0,0,0,0,0,0,0,0,0,0,0,8,0
5,5,0,0,0,0,0,0,0,0,0,0,0,0,0,0,0,5,5
0,8,5,0,0,0,0,0,0,0,0,0,0,0,0,0,5,8,0
0,5,8,8,8,5,8,8,8,8,8,8,8,5,8,8,8,5,0
0,0,0,0,9,8,8,8,8,8,8,8,8,8,10,0,0,0,0
0,0,0,0,9,11,8,5,8,8,8,5,8,11,10,0,0,0,0
0,0,0,0,5,0,0,5,0,0,0,5,0,0,5,0,0,0,0
0,0,0,0,0,0,0,0,0,0,0,0,0,0,0,0,0,0,0
:endlayer
layer: 3
0,0,0,0,0,0,0,0,0,0,0,0,0,0,0,0,0,0,0
0,0,0,0,0,0,5,8,8,8,8,8,5,0,0,0,0,0,0
0,0,0,0,0,0,8,8,8,8,8,8,8,0,0,0,0,0,0
0,0,0,0,0,0,8,8,8,8,8,8,8,0,0,0,0,0,0
0,0,0,0,5,8,5,8,8,8,8,8,5,8,5,0,0,0,0
0,0,0,0,8,4,12,0,0,0,0,0,12,0,8,0,0,0,0
0,0,0,5,5,4,0,0,0,0,0,0,0,13,5,5,0,0,0
0,0,0,0,8,5,0,0,0,0,0,0,0,0,8,0,0,0,0
0,0,0,0,8,0,0,0,0,0,0,0,0,0,8,0,0,0,0
0,0,0,0,8,0,0,0,0,0,0,0,0,0,8,0,0,0,0
0,0,0,0,8,0,0,0,0,0,0,0,0,0,8,0,0,0,0
0,0,0,5,5,14,0,0,0,0,0,0,0,13,5,5,0,0,0
0,0,0,0,8,0,0,0,0,0,0,0,0,0,8,0,0,0,0
0,5,8,8,5,14,0,0,0,0,0,0,0,13,5,8,8,5,0
0,8,5,0,12,0,0,0,0,0,0,0,0,0,12,0,5,8,0
5,5,14,0,0,0,0,0,0,0,0,0,0,0,0,0,13,5,5
0,8,0,0,0,0,0,0,0,0,0,0,0,0,0,0,0,8,0
0,8,0,0,0,0,0,0,0,0,0,0,0,0,0,0,0,8,0
0,8,0,0,0,0,0,0,0,0,0,0,0,0,0,0,0,8,0
0,8,0,0,0,0,0,0,0,0,0,0,0,0,0,0,0,8,0
5,5,14,0,0,0,0,0,0,0,0,0,0,0,0,0,13,5,5
0,8,0,0,0,0,0,0,0,0,0,0,0,0,0,0,0,8,0
5,5,14,0,0,0,0,0,0,0,0,0,0,0,0,0,13,5,5
0,8,0,0,0,0,0,0,0,0,0,0,0,0,0,0,0,8,0
0,8,0,0,0,0,0,0,0,0,0,0,0,0,0,0,0,8,0
0,8,0,0,0,0,0,0,0,0,0,0,0,0,0,0,0,8,0
0,8,0,0,0,0,0,0,0,0,0,0,0,0,0,0,0,8,0
5,5,14,0,0,0,0,0,0,0,0,0,0,0,0,0,13,5,5
0,8,5,0,0,15,0,0,0,0,0,0,0,15,0,0,5,8,0
0,5,8,8,8,5,8,8,8,8,8,8,8,5,8,8,8,5,0
0,0,0,0,0,9,8,8,8,8,8,8,8,10,0,0,0,0,0
0,0,0,0,0,9,11,5,8,8,8,5,11,10,0,0,0,0,0
0,0,0,0,5,16,0,5,0,0,0,5,0,16,5,0,0,0,0
0,0,0,0,0,0,0,0,0,0,0,0,0,0,0,0,0,0,0
:endlayer
layer: 4
0,0,0,0,0,0,15,0,0,0,0,0,15,0,0,0,0,0,0
0,0,0,0,0,13,5,11,11,11,11,11,5,14,0,0,0,0,0
0,0,0,0,0,0,17,8,8,8,8,8,17,0,0,0,0,0,0
0,0,0,0,15,0,17,8,8,8,8,8,17,0,15,0,0,0,0
0,0,0,13,5,11,11,11,11,11,11,11,11,11,5,14,0,0,0
0,0,0,0,17,4,18,18,18,18,18,18,18,18,17,0,0,0,0
0,0,0,5,17,4,18,18,18,18,18,18,18,18,17,5,0,0,0
0,0,0,12,17,5,18,18,18,18,18,18,18,18,17,12,0,0,0
0,0,0,0,17,0,18,18,18,18,18,18,18,18,17,0,0,0,0
0,0,0,0,17,0,18,18,18,18,18,18,18,18,17,0,0,0,0
0,0,0,15,17,11,11,11,11,11,11,11,11,11,17,15,0,0,0
0,0,0,5,17,17,8,18,8,18,8,18,8,17,17,5,0,0,0
0,15,0,0,17,17,8,18,8,18,8,18,8,17,17,0,0,15,0
13,5,11,11,5,17,8,18,8,18,8,18,8,17,5,11,11,5,14
0,17,17,11,11,11,11,11,11,11,11,11,11,11,11,11,17,17,0
5,17,17,18,18,18,18,18,18,18,18,18,18,18,18,18,17,17,5
12,17,17,8,8,8,8,8,8,8,8,8,8,8,8,8,17,17,12
0,17,17,18,18,18,18,18,18,18,18,18,18,18,18,18,17,17,0
0,17,17,8,8,8,8,8,8,8,8,8,8,8,8,8,17,17,0
15,17,17,18,18,18,18,18,18,18,18,18,18,18,18,18,17,17,15
5,17,17,8,8,8,8,8,8,8,8,8,8,8,8,8,17,17,5
0,17,17,18,18,18,18,18,18,18,18,18,18,18,18,18,17,17,0
5,17,17,8,8,8,8,8,8,8,8,8,8,8,8,8,17,17,5
12,17,17,18,18,18,18,18,18,18,18,18,18,18,18,18,17,17,12
0,17,17,8,8,8,8,8,8,8,8,8,8,8,8,8,17,17,0
0,17,17,18,18,18,18,18,18,18,18,18,18,18,18,18,17,17,0
15,17,17,8,8,8,8,8,8,8,8,8,8,8,8,8,17,17,15
5,17,17,18,18,18,18,18,18,18,18,18,18,18,18,18,17,17,5
0,17,17,11,11,11,11,11,11,11,11,11,11,11,11,11,17,17,0
13,5,11,11,11,11,11,11,11,11,11,11,11,11,11,11,11,5,14
0,12,0,0,0,0,9,8,8,8,8,8,10,0,0,0,0,12,0
0,0,0,0,0,0,9,11,11,11,11,11,10,0,0,0,0,0,0
0,0,0,0,5,19,20,5,16,16,16,5,21,19,5,0,0,0,0
0,0,0,0,0,0,0,12,0,0,0,12,0,0,0,0,0,0,0
:endlayer
layer: 5
0,0,0,0,0,0,0,0,0,0,0,0,0,0,0,0,0,0,0
0,0,0,0,0,0,5,19,19,19,19,19,5,0,0,0,0,0,0
0,0,0,0,0,0,19,0,0,0,0,0,19,0,0,0,0,0,0
0,0,0,0,0,0,19,0,9,22,10,0,19,0,0,0,0,0,0
0,0,0,0,5,8,5,8,8,8,8,8,5,8,5,0,0,0,0
0,0,0,0,8,4,23,23,23,23,23,23,23,17,8,0,0,0,0
0,0,0,5,5,4,23,23,23,23,23,23,23,17,5,5,0,0,0
0,0,0,0,8,5,23,23,23,23,23,23,23,17,8,0,0,0,0
0,0,0,0,8,17,23,23,23,23,23,23,23,17,8,0,0,0,0
0,0,0,0,8,17,23,23,23,23,23,23,23,17,8,0,0,0,0
0,0,0,0,8,5,11,5,24,24,24,5,11,5,8,0,0,0,0
0,0,0,5,5,0,0,0,0,0,0,0,0,0,5,5,0,0,0
0,0,0,0,8,0,0,0,0,0,0,0,0,0,8,0,0,0,0
0,5,8,8,5,0,0,0,0,0,0,0,0,0,5,8,8,5,0
0,8,0,0,0,5,0,5,0,0,0,5,0,5,0,0,0,8,0
5,5,0,0,0,0,0,25,0,0,0,25,0,0,0,0,0,5,5
0,8,5,0,0,0,0,0,0,0,0,0,0,0,0,0,5,8,0
0,8,0,0,0,0,0,0,0,0,0,0,0,0,0,0,0,8,0
0,8,0,0,0,0,0,0,0,0,0,0,0,0,0,0,0,8,0
0,8,5,0,0,0,0,0,0,6,0,0,0,0,0,0,5,8,0
5,5,0,0,0,0,0,0,0,0,0,0,0,0,0,0,0,5,5
0,8,0,0,0,0,0,0,0,0,0,0,0,0,0,0,0,8,0
5,5,0,0,0,0,0,0,0,0,0,0,0,0,0,0,0,5,5
0,8,5,0,0,0,0,0,0,6,0,0,0,0,0,0,5,8,0
0,8,0,0,0,0,0,0,0,0,0,0,0,0,0,0,0,8,0
0,8,0,0,0,0,0,0,0,0,0,0,0,0,0,0,0,8,0
0,8,5,0,0,0,0,0,0,0,0,0,0,0,0,0,5,8,0
5,5,0,0,0,0,0,26,0,0,0,26,0,0,0,0,0,5,5
0,8,0,0,0,5,0,5,0,0,0,5,0,5,0,0,0,8,0
0,5,8,8,8,5,8,5,0,0,0,5,8,5,8,8,8,5,0
0,0,0,0,0,0,0,0,0,0,0,0,0,0,0,0,0,0,0
0,0,0,0,0,0,0,0,0,0,0,0,0,0,0,0,0,0,0
0,0,0,0,5,19,19,5,19,19,19,5,19,19,5,0,0,0,0
0,0,0,0,0,0,0,0,0,0,0,0,0,0,0,0,0,0,0
:endlayer
layer: 6
0,0,0,0,0,0,0,0,0,0,0,0,0,0,0,0,0,0,0
0,0,0,0,0,0,5,0,0,0,0,0,5,0,0,0,0,0,0
0,0,0,0,0,0,0,0,0,0,0,0,0,0,0,0,0,0,0
0,0,0,0,0,0,0,0,0,0,0,0,0,0,0,0,0,0,0
0,0,0,0,5,8,5,8,8,0,8,8,5,8,5,0,0,0,0
0,0,0,0,8,4,0,0,0,0,0,0,0,0,8,0,0,0,0
0,0,0,5,5,4,0,0,0,0,0,0,0,0,5,5,0,0,0
0,0,0,0,8,5,0,0,0,15,0,0,0,5,8,0,0,0,0
0,0,0,0,8,0,0,5,23,23,23,5,0,0,8,0,0,0,0
0,0,0,0,8,0,0,12,0,0,0,12,0,0,8,0,0,0,0
0,0,0,0,8,5,19,19,0,0,0,19,19,5,8,0,0,0,0
0,0,0,5,5,0,0,0,0,0,0,0,0,0,5,5,0,0,0
0,0,0,0,8,0,0,0,0,0,0,0,0,0,8,0,0,0,0
0,5,8,8,5,0,0,0,0,0,0,0,0,0,5,8,8,5,0
0,8,0,0,0,5,20,5,0,0,0,5,21,5,0,0,0,8,0
5,5,0,0,0,0,0,25,0,0,0,25,0,0,0,0,0,5,5
0,8,5,0,0,0,0,0,0,0,0,0,0,0,0,0,5,8,0
0,19,0,0,0,0,0,0,0,0,0,0,0,0,0,0,0,19,0
0,19,0,0,0,0,0,0,0,0,0,0,0,0,0,0,0,19,0
0,8,5,0,0,0,0,0,0,0,0,0,0,0,0,0,5,8,0
5,5,0,0,0,0,0,0,0,0,0,0,0,0,0,0,0,5,5
0,8,0,0,0,0,0,0,0,0,0,0,0,0,0,0,0,8,0
5,5,0,0,0,0,0,0,0,0,0,0,0,0,0,0,0,5,5
0,8,5,0,0,0,0,0,0,0,0,0,0,0,0,0,5,8,0
0,19,0,0,0,0,0,0,0,0,0,0,0,0,0,0,0,19,0
0,19,0,0,0,0,0,0,0,0,0,0,0,0,0,0,0,19,0
0,8,5,0,0,0,0,0,0,0,0,0,0,0,0,0,5,8,0
5,5,0,0,0,0,0,26,0,0,0,26,0,0,0,0,0,5,5
0,8,0,0,0,5,0,5,0,0,0,5,0,5,0,0,0,8,0
0,5,8,8,8,5,8,5,0,0,0,5,8,5,8,8,8,5,0
0,0,0,27,0,0,0,0,0,0,0,0,0,0,0,27,0,0,0
0,0,0,27,0,0,0,0,0,0,0,0,0,0,0,27,0,0,0
0,0,0,27,5,0,0,5,0,0,0,5,0,0,5,27,0,0,0
0,0,0,27,0,0,0,0,0,0,0,0,0,0,0,27,0,0,0
:endlayer
layer: 7
0,0,0,0,0,27,27,27,27,27,27,27,27,27,0,0,0,0,0
0,0,0,0,0,0,5,0,0,0,0,0,5,0,0,0,0,0,0
0,0,0,0,0,0,0,0,0,0,0,0,0,0,0,0,0,0,0
0,0,0,0,0,0,0,0,0,0,0,0,0,0,0,0,0,0,0
0,0,0,0,5,8,5,8,8,0,8,8,5,8,5,0,0,0,0
0,0,0,0,8,0,0,0,0,0,0,0,0,0,8,0,0,0,0
0,0,0,5,5,0,0,0,0,0,0,0,0,0,5,5,0,0,0
0,0,0,0,8,5,0,0,0,0,0,0,0,5,8,0,0,0,0
0,0,0,0,8,0,0,24,28,28,28,24,0,0,8,0,0,0,0
0,0,0,0,8,0,0,0,0,0,0,0,0,0,8,0,0,0,0
0,0,0,0,8,5,0,0,0,0,0,0,0,5,8,0,0,0,0
0,0,0,5,5,0,0,0,0,0,0,0,0,0,5,5,0,0,0
0,0,0,0,8,14,0,0,0,0,0,0,0,13,8,0,0,0,0
0,5,8,8,5,0,0,0,0,0,0,0,0,0,5,8,8,5,0
0,8,0,0,0,5,9,5,0,0,0,5,10,5,0,0,0,8,0
5,5,0,0,0,0,0,25,0,0,0,25,0,0,0,0,0,5,5
0,8,5,0,0,0,0,0,0,0,0,0,0,0,0,0,5,8,0
0,8,0,0,0,0,0,0,0,0,0,0,0,0,0,0,0,8,0
0,8,0,0,0,0,0,0,0,0,0,0,0,0,0,0,0,8,0
0,8,5,0,0,0,0,0,0,0,0,0,0,0,0,0,5,8,0
5,5,0,0,0,0,0,0,0,0,0,0,0,0,0,0,0,5,5
0,8,0,0,0,0,0,0,0,0,0,0,0,0,0,0,0,8,0
5,5,0,0,0,0,0,0,0,0,0,0,0,0,0,0,0,5,5
0,8,5,0,0,0,0,0,0,0,0,0,0,0,0,0,5,8,0
0,8,0,0,0,0,0,0,0,0,0,0,0,0,0,0,0,8,0
0,8,0,0,0,0,0,0,0,0,0,0,0,0,0,0,0,8,0
0,8,5,0,0,0,0,0,0,0,0,0,0,0,0,0,5,8,0
5,5,0,0,0,0,0,26,0,0,0,26,0,0,0,0,0,5,5
0,8,0,0,0,5,0,5,0,0,0,5,0,5,0,0,0,8,0
0,5,8,8,8,5,8,5,0,0,0,5,8,5,8,8,8,5,0
0,0,0,0,27,0,0,0,0,0,0,0,0,0,27,0,0,0,0
0,0,0,0,27,0,0,15,0,0,0,15,0,0,27,0,0,0,0
0,0,0,0,27,20,0,5,0,0,0,5,0,21,27,0,0,0,0
0,0,0,0,27,0,0,0,0,0,0,0,0,0,27,0,0,0,0
:endlayer
layer: 8
0,0,0,0,0,0,0,0,0,0,0,0,0,0,0,0,0,0,0
0,0,0,0,0,27,27,27,27,27,27,27,27,27,0,0,0,0,0
0,0,0,0,0,0,0,0,0,0,0,0,0,0,0,0,0,0,0
0,0,0,0,0,0,0,15,0,0,0,15,0,0,0,0,0,0,0
0,0,0,0,5,11,5,11,11,11,11,11,5,11,5,0,0,0,0
0,0,0,0,17,0,0,0,0,0,0,0,0,0,17,0,0,0,0
0,0,0,5,5,0,0,0,0,0,0,0,0,0,5,5,0,0,0
0,0,0,0,17,5,0,0,0,0,0,0,0,5,17,0,0,0,0
0,0,0,0,17,0,0,0,0,0,0,0,0,0,17,0,0,0,0
0,0,0,0,17,0,0,0,0,0,0,0,0,0,17,0,0,0,0
0,0,0,0,17,5,0,0,0,0,0,0,0,5,17,0,0,0,0
0,0,0,5,5,0,0,0,0,0,0,0,0,0,5,5,0,0,0
0,0,0,0,17,0,0,0,0,0,0,0,0,0,17,0,0,0,0
0,5,11,11,5,0,0,0,0,0,0,0,0,0,5,11,11,5,0
0,17,16,0,0,5,0,5,20,0,21,5,0,5,0,0,16,17,0
5,5,29,0,0,0,0,25,0,0,0,25,0,0,0,0,29,5,5
0,17,5,14,0,0,0,0,0,0,0,0,0,0,0,13,5,17,0
0,17,16,0,0,0,0,0,0,0,0,0,0,0,0,0,16,17,0
0,17,29,0,0,0,0,0,0,0,0,0,0,0,0,0,29,17,0
0,17,5,14,0,0,0,0,0,0,0,0,0,0,0,13,5,17,0
5,5,16,0,0,0,0,0,0,0,0,0,0,0,0,0,16,5,5
0,17,18,0,0,0,0,0,0,0,0,0,0,0,0,0,18,17,0
5,5,29,0,0,0,0,0,0,0,0,0,0,0,0,0,29,5,5
0,17,5,14,0,0,0,0,0,0,0,0,0,0,0,13,5,17,0
0,17,16,0,0,0,0,0,0,0,0,0,0,0,0,0,16,17,0
0,17,29,0,0,0,0,0,0,0,0,0,0,0,0,0,29,17,0
0,17,5,14,0,0,0,0,0,0,0,0,0,0,0,13,5,17,0
5,5,16,0,0,15,0,26,0,0,0,26,0,15,0,0,16,5,5
0,17,29,0,0,5,18,5,20,18,21,5,18,5,0,0,29,17,0
0,5,11,11,11,5,11,11,11,11,11,11,11,5,11,11,11,5,0
0,0,0,0,0,27,0,0,0,0,0,0,0,27,0,0,0,0,0
0,0,0,0,0,27,0,0,0,0,0,0,0,27,0,0,0,0,0
0,0,0,0,0,27,20,5,20,0,21,5,21,27,0,0,0,0,0
0,0,0,0,0,27,0,0,0,0,0,0,0,27,0,0,0,0,0
:endlayer
layer: 9
0,0,0,0,0,0,0,0,0,0,0,0,0,0,0,0,0,0,0
0,0,0,0,0,0,0,0,0,0,0,0,0,0,0,0,0,0,0
0,0,0,0,0,27,27,27,27,27,27,27,27,27,0,0,0,0,0
0,0,0,0,0,0,0,0,0,0,0,0,0,0,0,0,0,0,0
0,0,0,0,5,8,5,8,8,8,8,8,5,8,5,0,0,0,0
0,0,0,0,8,0,12,0,0,0,0,0,12,0,8,0,0,0,0
0,0,0,5,5,0,0,0,0,0,0,0,0,0,5,5,0,0,0
0,0,0,0,8,5,14,0,0,0,0,0,13,5,8,0,0,0,0
0,0,0,0,8,0,0,0,0,0,0,0,0,0,8,0,0,0,0
0,0,0,0,8,0,0,0,0,0,0,0,0,0,8,0,0,0,0
0,0,0,0,8,5,14,0,0,0,0,0,13,5,8,0,0,0,0
0,0,0,5,5,0,0,0,0,0,0,0,0,0,5,5,0,0,0
0,0,0,0,8,0,0,0,0,0,0,0,0,0,8,0,0,0,0
0,5,8,8,5,0,0,15,0,0,0,15,0,0,5,8,8,5,0
0,8,0,0,0,5,0,5,8,0,8,5,0,5,0,0,0,8,0
5,5,0,0,0,12,0,25,0,0,0,25,0,12,0,0,0,5,5
0,8,5,0,0,0,0,0,0,0,0,0,0,0,0,0,5,8,0
0,8,0,0,0,0,0,0,0,0,0,0,0,0,0,0,0,8,0
0,8,0,0,0,0,0,0,0,0,0,0,0,0,0,0,0,8,0
0,8,5,0,0,0,0,0,0,0,0,0,0,0,0,0,5,8,0
5,5,0,0,0,0,0,0,0,0,0,0,0,0,0,0,0,5,5
0,8,0,0,0,0,0,0,0,0,0,0,0,0,0,0,0,8,0
5,5,0,0,0,0,0,0,0,0,0,0,0,0,0,0,0,5,5
0,8,5,0,0,0,0,0,0,0,0,0,0,0,0,0,5,8,0
0,8,0,0,0,0,0,0,0,0,0,0,0,0,0,0,0,8,0
0,8,0,0,0,0,0,0,0,0,0,0,0,0,0,0,0,8,0
0,8,5,0,0,0,0,0,0,0,0,0,0,0,0,0,5,8,0
5,5,0,0,0,0,0,26,0,0,0,26,0,0,0,0,0,5,5
0,8,0,0,0,5,0,5,0,0,0,5,0,5,0,0,0,8,0
0,5,8,8,8,5,8,8,5,8,5,8,8,5,8,8,8,5,0
0,0,0,0,0,0,27,0,0,0,0,0,27,0,0,0,0,0,0
0,0,0,0,0,6,27,0,0,0,0,0,27,6,0,0,0,0,0
0,0,0,0,0,0,27,11,11,11,11,11,27,0,0,0,0,0,0
0,0,0,0,0,0,27,0,0,0,0,0,27,0,0,0,0,0,0
:endlayer
layer: 10
0,0,0,0,0,0,0,0,0,0,0,0,0,0,0,0,0,0,0
0,0,0,0,0,0,0,0,0,0,0,0,0,0,0,0,0,0,0
0,0,0,0,0,0,0,6,0,0,0,6,0,0,0,0,0,0,0
0,0,0,27,0,27,27,27,27,27,27,27,27,27,0,27,0,0,0
0,0,0,27,5,8,5,8,8,8,8,8,5,8,5,27,0,0,0
0,0,0,27,17,0,0,0,0,0,0,0,0,0,17,27,0,0,0
0,0,0,27,17,0,0,0,0,0,0,0,0,0,17,27,0,0,0
0,0,0,27,17,5,0,0,0,0,0,0,0,5,17,27,0,0,0
0,0,0,27,17,0,0,0,0,0,0,0,0,0,17,27,0,0,0
0,0,0,27,17,0,0,0,0,0,0,0,0,0,17,27,0,0,0
0,0,0,27,17,5,0,0,0,0,0,0,0,5,17,27,0,0,0
0,0,0,27,17,0,0,0,0,0,0,0,0,0,17,27,0,0,0
27,0,0,27,17,0,0,0,0,0,0,0,0,0,17,27,0,0,27
27,5,8,8,5,0,0,0,0,0,0,0,0,0,5,8,8,5,27
27,17,0,0,0,5,20,5,9,16,10,5,21,5,0,0,0,17,27
27,17,0,0,0,0,0,25,0,0,0,25,0,0,0,0,0,17,27
27,17,5,0,0,0,0,0,0,0,0,0,0,0,0,0,5,17,27
27,17,0,0,0,0,0,0,0,0,0,0,0,0,0,0,0,17,27
27,17,0,0,0,0,0,0,0,0,0,0,0,0,0,0,0,17,27
27,17,5,0,0,0,0,0,0,0,0,0,0,0,0,0,5,17,27
27,17,0,0,0,0,0,0,0,0,0,0,0,0,0,0,0,17,27
27,17,0,0,0,0,0,0,0,0,0,0,0,0,0,0,0,17,27
27,17,0,0,0,0,0,0,0,0,0,0,0,0,0,0,0,17,27
27,17,5,0,0,0,0,0,0,0,0,0,0,0,0,0,5,17,27
27,17,0,0,0,0,0,0,0,0,0,0,0,0,0,0,0,17,27
27,17,0,0,0,0,0,0,0,0,0,0,0,0,0,0,0,17,27
27,17,5,0,0,0,0,0,0,0,0,0,0,0,0,0,5,17,27
27,17,0,0,0,0,0,26,0,0,0,26,0,0,0,0,0,17,27
27,17,0,0,0,5,0,5,0,0,0,5,0,5,0,0,0,17,27
27,5,11,11,11,11,11,11,11,11,11,11,11,11,11,11,11,5,27
27,0,0,0,0,0,0,27,0,0,0,27,0,0,0,0,0,0,27
0,0,0,0,0,0,0,27,0,0,0,27,0,0,0,0,0,0,0
0,0,0,0,0,0,0,27,8,8,8,27,0,0,0,0,0,0,0
0,0,0,0,0,0,0,27,0,0,0,27,0,0,0,0,0,0,0
:endlayer
layer: 11
0,0,0,0,0,0,0,0,0,0,0,0,0,0,0,0,0,0,0
0,0,0,0,0,0,0,0,0,0,0,0,0,0,0,0,0,0,0
0,0,0,0,0,0,0,0,0,0,0,0,0,0,0,0,0,0,0
0,0,0,0,27,0,0,0,0,0,0,0,0,0,27,0,0,0,0
0,0,0,0,27,11,11,11,11,11,11,11,11,11,27,0,0,0,0
0,0,0,0,27,20,0,0,0,0,0,0,0,21,27,0,0,0,0
0,0,0,0,27,20,0,0,0,0,0,0,0,21,27,0,0,0,0
0,0,0,0,27,5,20,0,0,0,0,0,21,5,27,0,0,0,0
0,0,0,0,27,20,0,0,0,0,0,0,0,21,27,0,0,0,0
0,0,0,0,27,20,0,0,0,0,0,0,0,21,27,0,0,0,0
0,0,0,0,27,5,20,0,0,0,0,0,21,5,27,0,0,0,0
0,0,0,0,27,20,0,0,0,0,0,0,0,21,27,0,0,0,0
0,27,0,0,27,20,0,0,0,0,0,0,0,21,27,0,0,27,0
0,27,8,8,5,20,0,0,0,0,0,0,0,21,5,8,8,27,0
0,27,20,16,16,5,8,5,0,8,0,5,8,5,16,16,21,27,0
0,27,20,0,0,0,0,25,0,12,0,25,0,0,0,0,21,27,0
0,27,5,0,0,0,0,0,0,0,0,0,0,0,0,0,5,27,0
0,27,20,0,0,0,0,0,0,0,0,0,0,0,0,0,21,27,0
0,27,20,0,0,0,0,0,0,0,0,0,0,0,0,0,21,27,0
0,27,5,0,0,0,0,0,0,0,0,0,0,0,0,0,5,27,0
0,27,20,0,0,0,0,0,0,0,0,0,0,0,0,0,21,27,0
0,27,20,0,0,0,0,0,0,0,0,0,0,0,0,0,21,27,0
0,27,20,0,0,0,0,0,0,0,0,0,0,0,0,0,21,27,0
0,27,5,0,0,0,0,0,0,0,0,0,0,0,0,0,5,27,0
0,27,20,0,0,0,0,0,0,0,0,0,0,0,0,0,21,27,0
0,27,20,0,0,0,0,0,0,0,0,0,0,0,0,0,21,27,0
0,27,5,0,0,0,0,0,0,0,0,0,0,0,0,0,5,27,0
0,27,20,0,0,0,0,26,0,0,0,26,0,0,0,0,21,27,0
0,27,20,29,29,5,29,5,29,29,29,5,29,5,29,29,21,27,0
0,27,8,8,5,8,5,8,8,5,8,8,5,8,5,8,8,27,0
0,27,0,0,0,0,0,0,27,0,27,0,0,0,0,0,0,27,0
0,0,0,0,0,0,0,0,27,0,27,0,0,0,0,0,0,0,0
0,0,0,0,0,0,0,0,27,8,27,0,0,0,0,0,0,0,0
0,0,0,0,0,0,0,0,27,0,27,0,0,0,0,0,0,0,0
:endlayer
layer: 12
0,0,0,0,0,0,0,0,0,0,0,0,0,0,0,0,0,0,0
0,0,0,0,0,0,0,0,0,0,0,0,0,0,0,0,0,0,0
0,0,0,0,0,0,0,0,0,0,0,0,0,0,0,0,0,0,0
0,0,0,0,0,27,0,0,0,0,0,0,0,27,0,0,0,0,0
0,0,0,0,0,27,8,8,8,8,8,8,8,27,0,0,0,0,0
0,0,0,0,0,27,8,18,8,18,8,18,8,27,0,0,0,0,0
0,0,0,0,0,27,8,18,8,18,8,18,8,27,0,0,0,0,0
0,0,0,0,0,27,11,11,11,11,11,11,11,27,0,0,0,0,0
0,0,0,0,0,27,8,18,8,18,8,18,8,27,0,0,0,0,0
0,0,0,0,0,27,8,18,8,18,8,18,8,27,0,0,0,0,0
0,0,0,0,0,27,11,11,11,11,11,11,11,27,0,0,0,0,0
0,0,0,0,0,27,8,18,8,18,8,18,8,27,0,0,0,0,0
0,0,27,0,0,27,8,18,8,18,8,18,8,27,0,0,27,0,0
0,0,27,11,11,11,11,11,11,11,11,11,11,11,11,11,27,0,0
0,0,27,8,8,5,8,5,21,8,20,5,8,5,8,8,27,0,0
0,0,27,11,11,11,17,25,17,11,17,25,17,11,11,11,27,0,0
0,0,27,20,16,16,16,16,16,16,16,16,16,16,16,16,27,0,0
0,0,27,20,0,0,0,0,0,0,0,0,0,0,0,21,27,0,0
0,0,27,20,0,0,0,0,0,0,0,0,0,0,0,21,27,0,0
0,0,27,20,0,0,0,0,0,0,0,0,0,0,0,21,27,0,0
0,0,27,20,0,0,0,0,0,0,0,0,0,0,0,21,27,0,0
0,0,27,20,0,0,0,0,0,0,0,0,0,0,0,21,27,0,0
0,0,27,20,0,0,0,0,0,0,0,0,0,0,0,21,27,0,0
0,0,27,20,0,0,0,0,0,0,0,0,0,0,0,21,27,0,0
0,0,27,20,0,0,0,0,0,0,0,0,0,0,0,21,27,0,0
0,0,27,20,0,0,0,0,0,0,0,0,0,0,0,21,27,0,0
0,0,27,29,29,29,29,29,29,29,29,29,29,29,29,21,27,0,0
0,0,27,11,11,11,17,26,17,11,17,26,17,11,11,11,27,0,0
0,0,27,8,8,5,8,5,8,8,8,5,8,5,8,8,27,0,0
0,0,27,8,5,8,5,8,8,5,8,8,5,8,5,8,27,0,0
0,0,27,0,0,0,0,0,0,27,0,0,0,0,0,0,27,0,0
0,0,0,0,0,0,0,0,6,27,6,0,0,0,0,0,0,0,0
0,0,0,0,0,0,0,0,0,27,0,0,0,0,0,0,0,0,0
0,0,0,0,0,0,0,0,0,27,0,0,0,0,0,0,0,0,0
:endlayer
layer: 13
0,0,0,0,0,0,0,0,0,0,0,0,0,0,0,0,0,0,0
0,0,0,0,0,0,0,0,0,0,0,0,0,0,0,0,0,0,0
0,0,0,0,0,0,0,0,0,0,0,0,0,0,0,0,0,0,0
0,0,0,0,0,0,27,0,0,0,0,0,27,0,0,0,0,0,0
0,0,0,0,0,0,27,8,8,19,8,8,27,0,0,0,0,0,0
0,0,0,0,0,6,27,0,0,0,0,0,27,6,0,0,0,0,0
0,0,0,0,0,0,27,0,0,0,0,0,27,0,0,0,0,0,0
0,0,0,0,0,0,27,0,0,6,0,0,27,0,0,0,0,0,0
0,0,0,0,0,0,27,0,0,0,0,0,27,0,0,0,0,0,0
0,0,0,0,0,0,27,0,0,0,0,0,27,0,0,0,0,0,0
0,0,0,0,0,6,27,0,0,6,0,0,27,6,0,0,0,0,0
0,0,0,0,0,0,27,0,0,0,0,0,27,0,0,0,0,0,0
0,0,0,27,0,0,27,0,0,0,0,0,27,0,0,27,0,0,0
0,0,0,27,8,8,8,8,5,0,5,8,8,8,8,27,0,0,0
0,0,6,27,8,8,8,8,10,0,9,8,8,8,8,27,6,0,0
0,0,0,27,8,8,8,25,22,22,22,25,8,8,8,27,0,0,0
0,0,0,27,8,8,8,8,8,8,8,8,8,8,8,27,0,0,0
0,0,0,27,16,16,16,16,16,16,16,16,16,16,21,27,0,0,0
0,0,0,27,20,18,0,0,0,0,0,0,0,18,21,27,6,0,0
0,0,6,27,20,0,0,0,0,0,0,0,0,0,21,27,0,0,0
0,0,0,27,20,0,0,0,0,0,0,0,0,0,21,27,0,0,0
0,0,0,27,20,0,0,0,0,0,0,0,0,0,21,27,0,0,0
0,0,0,27,20,0,0,0,0,0,0,0,0,0,21,27,0,0,0
0,0,0,27,20,0,0,0,0,0,0,0,0,0,21,27,6,0,0
0,0,6,27,20,18,0,0,0,0,0,0,0,18,21,27,0,0,0
0,0,0,27,29,29,29,29,29,29,29,29,29,29,29,27,0,0,0
0,0,0,27,8,8,8,8,8,8,8,8,8,8,8,27,0,0,0
0,0,0,27,8,8,8,26,8,8,8,26,8,8,8,27,0,0,0
0,0,6,27,8,8,8,8,8,8,8,8,8,8,8,27,6,0,0
0,0,0,27,5,8,5,8,8,5,8,8,5,8,5,27,0,0,0
0,0,0,27,0,0,0,0,0,0,0,0,0,0,0,27,0,0,0
0,0,0,0,0,0,0,0,0,0,0,0,0,0,0,0,0,0,0
0,0,0,0,0,0,0,0,0,0,0,0,0,0,0,0,0,0,0
0,0,0,0,0,0,0,0,0,0,0,0,0,0,0,0,0,0,0
:endlayer
layer: 14
0,0,0,0,0,0,0,0,0,0,0,0,0,0,0,0,0,0,0
0,0,0,0,0,0,0,0,0,0,0,0,0,0,0,0,0,0,0
0,0,0,0,0,0,0,0,0,0,0,0,0,0,0,0,0,0,0
0,0,0,0,0,0,0,27,0,0,0,27,0,0,0,0,0,0,0
0,0,0,0,0,0,0,27,8,8,8,27,0,0,0,0,0,0,0
0,0,0,0,0,0,0,27,0,0,0,27,0,0,0,0,0,0,0
0,0,0,0,0,0,0,27,0,0,0,27,0,0,0,0,0,0,0
0,0,0,0,0,0,0,27,0,0,0,27,0,0,0,0,0,0,0
0,0,0,0,0,0,0,27,0,0,0,27,0,0,0,0,0,0,0
0,0,0,0,0,0,0,27,0,0,0,27,0,0,0,0,0,0,0
0,0,0,0,0,0,0,27,0,0,0,27,0,0,0,0,0,0,0
0,0,0,0,0,0,0,27,0,0,0,27,0,0,0,0,0,0,0
0,0,0,0,27,0,0,27,0,0,0,27,0,0,27,0,0,0,0
0,0,0,0,27,11,11,11,5,0,5,11,11,11,27,0,0,0,0
0,0,0,0,27,17,0,0,0,0,0,0,0,17,27,0,0,0,0
0,0,0,0,27,17,0,0,0,0,0,0,0,17,27,0,0,0,0
0,0,0,0,27,17,0,0,0,6,0,0,0,17,27,0,0,0,0
0,0,0,0,27,17,0,0,0,0,0,0,0,17,27,0,0,0,0
0,0,0,0,27,17,11,11,11,11,11,11,11,17,27,0,0,0,0
0,0,0,0,27,17,20,0,0,0,0,0,21,17,27,0,0,0,0
0,0,0,0,27,17,20,0,0,0,0,0,21,17,27,0,0,0,0
0,0,0,0,27,17,20,0,0,0,0,0,21,17,27,0,0,0,0
0,0,0,0,27,17,20,0,0,0,0,0,21,17,27,0,0,0,0
0,0,0,0,27,17,20,0,0,0,0,0,21,17,27,0,0,0,0
0,0,0,0,27,17,11,11,11,11,11,11,11,17,27,0,0,0,0
0,0,0,0,27,17,0,0,0,0,0,0,0,17,27,0,0,0,0
0,0,0,0,27,17,0,0,0,0,0,0,0,17,27,0,0,0,0
0,0,0,0,27,17,0,0,0,6,0,0,0,17,27,0,0,0,0
0,0,0,0,27,17,0,0,0,0,0,0,0,17,27,0,0,0,0
0,0,0,0,27,11,11,11,11,11,11,11,11,11,27,0,0,0,0
0,0,0,0,27,0,0,0,0,0,0,0,0,0,27,0,0,0,0
0,0,0,0,0,0,0,0,0,0,0,0,0,0,0,0,0,0,0
0,0,0,0,0,0,0,0,0,0,0,0,0,0,0,0,0,0,0
0,0,0,0,0,0,0,0,0,0,0,0,0,0,0,0,0,0,0
:endlayer
layer: 15
0,0,0,0,0,0,0,0,0,0,0,0,0,0,0,0,0,0,0
0,0,0,0,0,0,0,0,0,0,0,0,0,0,0,0,0,0,0
0,0,0,0,0,0,0,0,0,0,0,0,0,0,0,0,0,0,0
0,0,0,0,0,0,0,0,27,0,27,0,0,0,0,0,0,0,0
0,0,0,0,0,0,0,0,27,8,27,0,0,0,0,0,0,0,0
0,0,0,0,0,0,0,0,27,0,27,0,0,0,0,0,0,0,0
0,0,0,0,0,0,0,0,27,0,27,0,0,0,0,0,0,0,0
0,0,0,0,0,0,0,0,27,0,27,0,0,0,0,0,0,0,0
0,0,0,0,0,0,0,0,27,0,27,0,0,0,0,0,0,0,0
0,0,0,0,0,0,0,0,27,0,27,0,0,0,0,0,0,0,0
0,0,0,0,0,0,0,0,27,0,27,0,0,0,0,0,0,0,0
0,0,0,0,0,0,0,0,27,0,27,0,0,0,0,0,0,0,0
0,0,0,0,0,27,0,0,27,0,27,0,0,27,0,0,0,0,0
0,0,0,0,0,27,8,8,5,0,5,8,8,27,0,0,0,0,0
0,0,0,0,0,27,0,0,0,0,0,0,0,27,0,0,0,0,0
0,0,0,0,0,27,0,0,0,0,0,0,0,27,0,0,0,0,0
0,0,0,0,0,27,0,0,0,0,0,0,0,27,0,0,0,0,0
0,0,0,0,0,27,0,0,0,0,0,0,0,27,0,0,0,0,0
0,0,0,0,0,27,5,8,8,5,8,8,5,27,0,0,0,0,0
0,0,0,0,0,27,17,0,0,0,0,0,17,27,0,0,0,0,0
0,0,0,0,0,27,17,0,0,0,0,0,17,27,0,0,0,0,0
0,0,0,0,0,27,17,0,0,0,0,0,17,27,0,0,0,0,0
0,0,0,0,0,27,17,0,0,0,0,0,17,27,0,0,0,0,0
0,0,0,0,0,27,17,0,0,0,0,0,17,27,0,0,0,0,0
0,0,0,0,0,27,5,8,8,5,8,8,5,27,0,0,0,0,0
0,0,0,0,0,27,0,0,0,0,0,0,0,27,0,0,0,0,0
0,0,0,0,0,27,0,0,0,0,0,0,0,27,0,0,0,0,0
0,0,0,0,0,27,0,0,0,0,0,0,0,27,0,0,0,0,0
0,0,0,0,0,27,0,0,0,0,0,0,0,27,0,0,0,0,0
0,0,0,0,0,27,8,8,8,8,8,8,8,27,0,0,0,0,0
0,0,0,0,0,27,0,0,0,0,0,0,0,27,0,0,0,0,0
0,0,0,0,0,0,0,0,0,0,0,0,0,0,0,0,0,0,0
0,0,0,0,0,0,0,0,0,0,0,0,0,0,0,0,0,0,0
0,0,0,0,0,0,0,0,0,0,0,0,0,0,0,0,0,0,0
:endlayer
layer: 16
0,0,0,0,0,0,0,0,0,0,0,0,0,0,0,0,0,0,0
0,0,0,0,0,0,0,0,0,0,0,0,0,0,0,0,0,0,0
0,0,0,0,0,0,0,0,0,0,0,0,0,0,0,0,0,0,0
0,0,0,0,0,0,0,0,0,27,0,0,0,0,0,0,0,0,0
0,0,0,0,0,0,0,0,0,27,0,0,0,0,0,0,0,0,0
0,0,0,0,0,0,0,0,6,27,6,0,0,0,0,0,0,0,0
0,0,0,0,0,0,0,0,0,27,0,0,0,0,0,0,0,0,0
0,0,0,0,0,0,0,0,0,27,0,0,0,0,0,0,0,0,0
0,0,0,0,0,0,0,0,0,27,0,0,0,0,0,0,0,0,0
0,0,0,0,0,0,0,0,0,27,0,0,0,0,0,0,0,0,0
0,0,0,0,0,0,0,0,6,27,6,0,0,0,0,0,0,0,0
0,0,0,0,0,0,0,0,0,27,0,0,0,0,0,0,0,0,0
0,0,0,0,0,0,27,0,0,27,0,0,27,0,0,0,0,0,0
0,0,0,0,0,0,27,8,8,11,8,8,27,0,0,0,0,0,0
0,0,0,0,0,6,27,0,0,0,0,0,27,6,0,0,0,0,0
0,0,0,0,0,0,27,0,0,0,0,0,27,0,0,0,0,0,0
0,0,0,0,0,0,27,0,0,0,0,0,27,0,0,0,0,0,0
0,0,0,0,0,0,27,0,0,0,0,0,27,0,0,0,0,0,0
0,0,0,0,0,0,5,8,8,5,8,8,5,6,0,0,0,0,0
0,0,0,0,0,6,8,0,0,0,0,0,8,0,0,0,0,0,0
0,0,0,0,0,0,5,0,0,0,0,0,5,0,0,0,0,0,0
0,0,0,0,0,0,8,0,0,0,0,0,8,0,0,0,0,0,0
0,0,0,0,0,0,5,0,0,0,0,0,5,0,0,0,0,0,0
0,0,0,0,0,0,8,0,0,0,0,0,8,6,0,0,0,0,0
0,0,0,0,0,6,5,8,8,5,8,8,5,0,0,0,0,0,0
0,0,0,0,0,0,27,0,0,0,0,0,27,0,0,0,0,0,0
0,0,0,0,0,0,27,0,0,0,0,0,27,0,0,0,0,0,0
0,0,0,0,0,0,27,0,0,0,0,0,27,0,0,0,0,0,0
0,0,0,0,0,6,27,0,0,0,0,0,27,6,0,0,0,0,0
0,0,0,0,0,0,27,8,8,19,8,8,27,0,0,0,0,0,0
0,0,0,0,0,0,27,0,0,0,0,0,27,0,0,0,0,0,0
0,0,0,0,0,0,0,0,0,0,0,0,0,0,0,0,0,0,0
0,0,0,0,0,0,0,0,0,0,0,0,0,0,0,0,0,0,0
0,0,0,0,0,0,0,0,0,0,0,0,0,0,0,0,0,0,0
:endlayer
layer: 17
0,0,0,0,0,0,0,0,0,0,0,0,0,0,0,0,0,0,0
0,0,0,0,0,0,0,0,0,0,0,0,0,0,0,0,0,0,0
0,0,0,0,0,0,0,0,0,0,0,0,0,0,0,0,0,0,0
0,0,0,0,0,0,0,0,0,0,0,0,0,0,0,0,0,0,0
0,0,0,0,0,0,0,0,0,0,0,0,0,0,0,0,0,0,0
0,0,0,0,0,0,0,0,0,0,0,0,0,0,0,0,0,0,0
0,0,0,0,0,0,0,0,0,0,0,0,0,0,0,0,0,0,0
0,0,0,0,0,0,0,0,0,0,0,0,0,0,0,0,0,0,0
0,0,0,0,0,0,0,0,0,0,0,0,0,0,0,0,0,0,0
0,0,0,0,0,0,0,0,0,0,0,0,0,0,0,0,0,0,0
0,0,0,0,0,0,0,0,0,0,0,0,0,0,0,0,0,0,0
0,0,0,0,0,0,0,0,0,0,0,0,0,0,0,0,0,0,0
0,0,0,0,0,0,0,27,0,0,0,27,0,0,0,0,0,0,0
0,0,0,0,0,0,0,27,8,8,8,27,0,0,0,0,0,0,0
0,0,0,0,0,0,0,27,0,0,0,27,0,0,0,0,0,0,0
0,0,0,0,0,0,0,27,0,0,0,27,0,0,0,0,0,0,0
0,0,0,0,0,0,0,27,0,0,0,27,0,0,0,0,0,0,0
0,0,0,0,0,0,0,27,0,0,0,27,0,0,0,0,0,0,0
0,0,0,0,0,0,5,8,8,5,8,8,5,0,0,0,0,0,0
0,0,0,0,0,0,19,0,0,0,0,0,19,0,0,0,0,0,0
0,0,0,0,0,0,5,0,0,0,0,0,5,0,0,0,0,0,0
0,0,0,0,0,0,19,0,0,0,0,0,19,0,0,0,0,0,0
0,0,0,0,0,0,5,0,0,0,0,0,5,0,0,0,0,0,0
0,0,0,0,0,0,19,0,0,0,0,0,19,0,0,0,0,0,0
0,0,0,0,0,0,5,8,8,5,8,8,5,0,0,0,0,0,0
0,0,0,0,0,0,0,27,0,0,0,27,0,0,0,0,0,0,0
0,0,0,0,0,0,0,27,0,0,0,27,0,0,0,0,0,0,0
0,0,0,0,0,0,0,27,0,0,0,27,0,0,0,0,0,0,0
0,0,0,0,0,0,0,27,0,0,0,27,0,0,0,0,0,0,0
0,0,0,0,0,0,0,27,8,8,8,27,0,0,0,0,0,0,0
0,0,0,0,0,0,0,27,0,0,0,27,0,0,0,0,0,0,0
0,0,0,0,0,0,0,0,0,0,0,0,0,0,0,0,0,0,0
0,0,0,0,0,0,0,0,0,0,0,0,0,0,0,0,0,0,0
0,0,0,0,0,0,0,0,0,0,0,0,0,0,0,0,0,0,0
:endlayer
layer: 18
0,0,0,0,0,0,0,0,0,0,0,0,0,0,0,0,0,0,0
0,0,0,0,0,0,0,0,0,0,0,0,0,0,0,0,0,0,0
0,0,0,0,0,0,0,0,0,0,0,0,0,0,0,0,0,0,0
0,0,0,0,0,0,0,0,0,0,0,0,0,0,0,0,0,0,0
0,0,0,0,0,0,0,0,0,0,0,0,0,0,0,0,0,0,0
0,0,0,0,0,0,0,0,0,0,0,0,0,0,0,0,0,0,0
0,0,0,0,0,0,0,0,0,0,0,0,0,0,0,0,0,0,0
0,0,0,0,0,0,0,0,0,0,0,0,0,0,0,0,0,0,0
0,0,0,0,0,0,0,0,0,0,0,0,0,0,0,0,0,0,0
0,0,0,0,0,0,0,0,0,0,0,0,0,0,0,0,0,0,0
0,0,0,0,0,0,0,0,0,0,0,0,0,0,0,0,0,0,0
0,0,0,0,0,0,0,0,0,0,0,0,0,0,0,0,0,0,0
0,0,0,0,0,0,0,0,27,0,27,0,0,0,0,0,0,0,0
0,0,0,0,0,0,0,0,27,8,27,0,0,0,0,0,0,0,0
0,0,0,0,0,0,0,0,27,0,27,0,0,0,0,0,0,0,0
0,0,0,0,0,0,0,0,27,0,27,0,0,0,0,0,0,0,0
0,0,0,0,0,0,0,0,27,0,27,0,0,0,0,0,0,0,0
0,0,0,0,0,0,0,0,27,0,27,0,0,0,0,0,0,0,0
0,0,0,0,0,0,5,8,8,5,8,8,5,0,0,0,0,0,0
0,0,0,0,0,0,19,0,0,0,0,0,19,0,0,0,0,0,0
0,0,0,0,0,0,5,0,0,0,0,0,5,0,0,0,0,0,0
0,0,0,0,0,0,19,0,0,0,0,0,19,0,0,0,0,0,0
0,0,0,0,0,0,5,0,0,0,0,0,5,0,0,0,0,0,0
0,0,0,0,0,0,19,0,0,0,0,0,19,0,0,0,0,0,0
0,0,0,0,0,0,5,8,8,5,8,8,5,0,0,0,0,0,0
0,0,0,0,0,0,0,0,27,0,27,0,0,0,0,0,0,0,0
0,0,0,0,0,0,0,0,27,0,27,0,0,0,0,0,0,0,0
0,0,0,0,0,0,0,0,27,0,27,0,0,0,0,0,0,0,0
0,0,0,0,0,0,0,0,27,0,27,0,0,0,0,0,0,0,0
0,0,0,0,0,0,0,0,27,8,27,0,0,0,0,0,0,0,0
0,0,0,0,0,0,0,0,27,0,27,0,0,0,0,0,0,0,0
0,0,0,0,0,0,0,0,0,0,0,0,0,0,0,0,0,0,0
0,0,0,0,0,0,0,0,0,0,0,0,0,0,0,0,0,0,0
0,0,0,0,0,0,0,0,0,0,0,0,0,0,0,0,0,0,0
:endlayer
layer: 19
0,0,0,0,0,0,0,0,0,0,0,0,0,0,0,0,0,0,0
0,0,0,0,0,0,0,0,0,0,0,0,0,0,0,0,0,0,0
0,0,0,0,0,0,0,0,0,0,0,0,0,0,0,0,0,0,0
0,0,0,0,0,0,0,0,0,0,0,0,0,0,0,0,0,0,0
0,0,0,0,0,0,0,0,0,0,0,0,0,0,0,0,0,0,0
0,0,0,0,0,0,0,0,0,0,0,0,0,0,0,0,0,0,0
0,0,0,0,0,0,0,0,0,0,0,0,0,0,0,0,0,0,0
0,0,0,0,0,0,0,0,0,0,0,0,0,0,0,0,0,0,0
0,0,0,0,0,0,0,0,0,0,0,0,0,0,0,0,0,0,0
0,0,0,0,0,0,0,0,0,0,0,0,0,0,0,0,0,0,0
0,0,0,0,0,0,0,0,0,0,0,0,0,0,0,0,0,0,0
0,0,0,0,0,0,0,0,0,0,0,0,0,0,0,0,0,0,0
0,0,0,0,0,0,0,0,0,27,0,0,0,0,0,0,0,0,0
0,0,0,0,0,0,0,0,0,27,0,0,0,0,0,0,0,0,0
0,0,0,0,0,0,0,0,6,27,6,0,0,0,0,0,0,0,0
0,0,0,0,0,0,0,0,0,27,0,0,0,0,0,0,0,0,0
0,0,0,0,0,0,0,0,0,27,0,0,0,0,0,0,0,0,0
0,0,0,0,0,0,0,0,0,27,0,0,0,0,0,0,0,0,0
0,0,0,0,0,0,5,8,8,5,8,8,5,0,0,0,0,0,0
0,0,0,0,0,0,8,19,0,12,0,19,8,0,0,0,0,0,0
0,0,0,0,0,0,5,0,0,0,0,0,5,0,0,0,0,0,0
0,0,0,0,0,0,8,14,0,0,0,13,8,0,0,0,0,0,0
0,0,0,0,0,0,5,0,0,0,0,0,5,0,0,0,0,0,0
0,0,0,0,0,0,8,19,0,15,0,19,8,0,0,0,0,0,0
0,0,0,0,0,0,5,8,8,5,8,8,5,0,0,0,0,0,0
0,0,0,0,0,0,0,0,0,27,0,0,0,0,0,0,0,0,0
0,0,0,0,0,0,0,0,0,27,0,0,0,0,0,0,0,0,0
0,0,0,0,0,0,0,0,0,27,0,0,0,0,0,0,0,0,0
0,0,0,0,0,0,0,0,6,27,6,0,0,0,0,0,0,0,0
0,0,0,0,0,0,0,0,0,27,0,0,0,0,0,0,0,0,0
0,0,0,0,0,0,0,0,0,27,0,0,0,0,0,0,0,0,0
0,0,0,0,0,0,0,0,0,0,0,0,0,0,0,0,0,0,0
0,0,0,0,0,0,0,0,0,0,0,0,0,0,0,0,0,0,0
0,0,0,0,0,0,0,0,0,0,0,0,0,0,0,0,0,0,0
:endlayer
layer: 20
0,0,0,0,0,0,0,0,0,0,0,0,0,0,0,0,0,0,0
0,0,0,0,0,0,0,0,0,0,0,0,0,0,0,0,0,0,0
0,0,0,0,0,0,0,0,0,0,0,0,0,0,0,0,0,0,0
0,0,0,0,0,0,0,0,0,0,0,0,0,0,0,0,0,0,0
0,0,0,0,0,0,0,0,0,0,0,0,0,0,0,0,0,0,0
0,0,0,0,0,0,0,0,0,0,0,0,0,0,0,0,0,0,0
0,0,0,0,0,0,0,0,0,0,0,0,0,0,0,0,0,0,0
0,0,0,0,0,0,0,0,0,0,0,0,0,0,0,0,0,0,0
0,0,0,0,0,0,0,0,0,0,0,0,0,0,0,0,0,0,0
0,0,0,0,0,0,0,0,0,0,0,0,0,0,0,0,0,0,0
0,0,0,0,0,0,0,0,0,0,0,0,0,0,0,0,0,0,0
0,0,0,0,0,0,0,0,0,0,0,0,0,0,0,0,0,0,0
0,0,0,0,0,0,0,0,0,0,0,0,0,0,0,0,0,0,0
0,0,0,0,0,0,0,0,0,0,0,0,0,0,0,0,0,0,0
0,0,0,0,0,0,0,0,0,0,0,0,0,0,0,0,0,0,0
0,0,0,0,0,0,0,0,0,0,0,0,0,0,0,0,0,0,0
0,0,0,0,0,0,0,0,0,0,0,0,0,0,0,0,0,0,0
0,0,0,0,0,27,27,27,27,27,27,27,27,27,0,0,0,0,0
0,0,0,0,0,27,5,11,11,11,11,11,5,27,0,0,0,0,0
0,0,0,0,0,27,17,8,16,16,16,8,17,27,0,0,0,0,0
0,0,0,0,0,27,17,20,0,0,0,21,17,27,0,0,0,0,0
0,0,0,0,0,27,17,20,0,0,0,21,17,27,0,0,0,0,0
0,0,0,0,0,27,17,20,0,0,0,21,17,27,0,0,0,0,0
0,0,0,0,0,27,17,8,29,29,29,8,17,27,0,0,0,0,0
0,0,0,0,0,27,5,11,11,11,11,11,5,27,0,0,0,0,0
0,0,0,0,0,27,27,27,27,27,27,27,27,27,0,0,0,0,0
0,0,0,0,0,0,0,0,0,0,0,0,0,0,0,0,0,0,0
0,0,0,0,0,0,0,0,0,0,0,0,0,0,0,0,0,0,0
0,0,0,0,0,0,0,0,0,0,0,0,0,0,0,0,0,0,0
0,0,0,0,0,0,0,0,0,0,0,0,0,0,0,0,0,0,0
0,0,0,0,0,0,0,0,0,0,0,0,0,0,0,0,0,0,0
0,0,0,0,0,0,0,0,0,0,0,0,0,0,0,0,0,0,0
0,0,0,0,0,0,0,0,0,0,0,0,0,0,0,0,0,0,0
0,0,0,0,0,0,0,0,0,0,0,0,0,0,0,0,0,0,0
:endlayer
layer: 21
0,0,0,0,0,0,0,0,0,0,0,0,0,0,0,0,0,0,0
0,0,0,0,0,0,0,0,0,0,0,0,0,0,0,0,0,0,0
0,0,0,0,0,0,0,0,0,0,0,0,0,0,0,0,0,0,0
0,0,0,0,0,0,0,0,0,0,0,0,0,0,0,0,0,0,0
0,0,0,0,0,0,0,0,0,0,0,0,0,0,0,0,0,0,0
0,0,0,0,0,0,0,0,0,0,0,0,0,0,0,0,0,0,0
0,0,0,0,0,0,0,0,0,0,0,0,0,0,0,0,0,0,0
0,0,0,0,0,0,0,0,0,0,0,0,0,0,0,0,0,0,0
0,0,0,0,0,0,0,0,0,0,0,0,0,0,0,0,0,0,0
0,0,0,0,0,0,0,0,0,0,0,0,0,0,0,0,0,0,0
0,0,0,0,0,0,0,0,0,0,0,0,0,0,0,0,0,0,0
0,0,0,0,0,0,0,0,0,0,0,0,0,0,0,0,0,0,0
0,0,0,0,0,0,0,0,0,0,0,0,0,0,0,0,0,0,0
0,0,0,0,0,0,0,0,0,0,0,0,0,0,0,0,0,0,0
0,0,0,0,0,0,0,0,0,0,0,0,0,0,0,0,0,0,0
0,0,0,0,0,0,0,0,0,0,0,0,0,0,0,0,0,0,0
0,0,0,0,0,0,0,0,0,0,0,0,0,0,0,0,0,0,0
0,0,0,0,0,0,0,0,0,0,0,0,0,0,0,0,0,0,0
0,0,0,0,0,0,27,27,27,27,27,27,27,0,0,0,0,0,0
0,0,0,0,0,0,27,27,11,11,11,27,27,0,0,0,0,0,0
0,0,0,0,0,0,27,17,0,0,0,17,27,0,0,0,0,0,0
0,0,0,0,0,0,27,17,0,0,0,17,27,0,0,0,0,0,0
0,0,0,0,0,0,27,17,0,0,0,17,27,0,0,0,0,0,0
0,0,0,0,0,0,27,27,11,11,11,27,27,0,0,0,0,0,0
0,0,0,0,0,0,27,27,27,27,27,27,27,0,0,0,0,0,0
0,0,0,0,0,0,0,0,0,0,0,0,0,0,0,0,0,0,0
0,0,0,0,0,0,0,0,0,0,0,0,0,0,0,0,0,0,0
0,0,0,0,0,0,0,0,0,0,0,0,0,0,0,0,0,0,0
0,0,0,0,0,0,0,0,0,0,0,0,0,0,0,0,0,0,0
0,0,0,0,0,0,0,0,0,0,0,0,0,0,0,0,0,0,0
0,0,0,0,0,0,0,0,0,0,0,0,0,0,0,0,0,0,0
0,0,0,0,0,0,0,0,0,0,0,0,0,0,0,0,0,0,0
0,0,0,0,0,0,0,0,0,0,0,0,0,0,0,0,0,0,0
0,0,0,0,0,0,0,0,0,0,0,0,0,0,0,0,0,0,0
:endlayer
layer: 22
0,0,0,0,0,0,0,0,0,0,0,0,0,0,0,0,0,0,0
0,0,0,0,0,0,0,0,0,0,0,0,0,0,0,0,0,0,0
0,0,0,0,0,0,0,0,0,0,0,0,0,0,0,0,0,0,0
0,0,0,0,0,0,0,0,0,0,0,0,0,0,0,0,0,0,0
0,0,0,0,0,0,0,0,0,0,0,0,0,0,0,0,0,0,0
0,0,0,0,0,0,0,0,0,0,0,0,0,0,0,0,0,0,0
0,0,0,0,0,0,0,0,0,0,0,0,0,0,0,0,0,0,0
0,0,0,0,0,0,0,0,0,0,0,0,0,0,0,0,0,0,0
0,0,0,0,0,0,0,0,0,0,0,0,0,0,0,0,0,0,0
0,0,0,0,0,0,0,0,0,0,0,0,0,0,0,0,0,0,0
0,0,0,0,0,0,0,0,0,0,0,0,0,0,0,0,0,0,0
0,0,0,0,0,0,0,0,0,0,0,0,0,0,0,0,0,0,0
0,0,0,0,0,0,0,0,0,0,0,0,0,0,0,0,0,0,0
0,0,0,0,0,0,0,0,0,0,0,0,0,0,0,0,0,0,0
0,0,0,0,0,0,0,0,0,0,0,0,0,0,0,0,0,0,0
0,0,0,0,0,0,0,0,0,0,0,0,0,0,0,0,0,0,0
0,0,0,0,0,0,0,0,0,0,0,0,0,0,0,0,0,0,0
0,0,0,0,0,0,0,0,0,0,0,0,0,0,0,0,0,0,0
0,0,0,0,0,0,6,0,0,0,0,0,6,0,0,0,0,0,0
0,0,0,0,0,0,0,0,8,5,8,0,0,0,0,0,0,0,0
0,0,0,0,0,0,0,5,0,0,0,5,0,0,0,0,0,0,0
0,0,0,0,0,0,0,8,0,0,0,8,0,0,0,0,0,0,0
0,0,0,0,0,0,0,5,0,0,0,5,0,0,0,0,0,0,0
0,0,0,0,0,0,0,0,8,5,8,0,0,0,0,0,0,0,0
0,0,0,0,0,0,6,0,0,0,0,0,6,0,0,0,0,0,0
0,0,0,0,0,0,0,0,0,0,0,0,0,0,0,0,0,0,0
0,0,0,0,0,0,0,0,0,0,0,0,0,0,0,0,0,0,0
0,0,0,0,0,0,0,0,0,0,0,0,0,0,0,0,0,0,0
0,0,0,0,0,0,0,0,0,0,0,0,0,0,0,0,0,0,0
0,0,0,0,0,0,0,0,0,0,0,0,0,0,0,0,0,0,0
0,0,0,0,0,0,0,0,0,0,0,0,0,0,0,0,0,0,0
0,0,0,0,0,0,0,0,0,0,0,0,0,0,0,0,0,0,0
0,0,0,0,0,0,0,0,0,0,0,0,0,0,0,0,0,0,0
0,0,0,0,0,0,0,0,0,0,0,0,0,0,0,0,0,0,0
:endlayer
layer: 23
0,0,0,0,0,0,0,0,0,0,0,0,0,0,0,0,0,0,0
0,0,0,0,0,0,0,0,0,0,0,0,0,0,0,0,0,0,0
0,0,0,0,0,0,0,0,0,0,0,0,0,0,0,0,0,0,0
0,0,0,0,0,0,0,0,0,0,0,0,0,0,0,0,0,0,0
0,0,0,0,0,0,0,0,0,0,0,0,0,0,0,0,0,0,0
0,0,0,0,0,0,0,0,0,0,0,0,0,0,0,0,0,0,0
0,0,0,0,0,0,0,0,0,0,0,0,0,0,0,0,0,0,0
0,0,0,0,0,0,0,0,0,0,0,0,0,0,0,0,0,0,0
0,0,0,0,0,0,0,0,0,0,0,0,0,0,0,0,0,0,0
0,0,0,0,0,0,0,0,0,0,0,0,0,0,0,0,0,0,0
0,0,0,0,0,0,0,0,0,0,0,0,0,0,0,0,0,0,0
0,0,0,0,0,0,0,0,0,0,0,0,0,0,0,0,0,0,0
0,0,0,0,0,0,0,0,0,0,0,0,0,0,0,0,0,0,0
0,0,0,0,0,0,0,0,0,0,0,0,0,0,0,0,0,0,0
0,0,0,0,0,0,0,0,0,0,0,0,0,0,0,0,0,0,0
0,0,0,0,0,0,0,0,0,0,0,0,0,0,0,0,0,0,0
0,0,0,0,0,0,0,0,0,0,0,0,0,0,0,0,0,0,0
0,0,0,0,0,0,0,0,0,0,0,0,0,0,0,0,0,0,0
0,0,0,0,0,0,0,0,0,0,0,0,0,0,0,0,0,0,0
0,0,0,0,0,0,0,0,8,5,8,0,0,0,0,0,0,0,0
0,0,0,0,0,0,0,5,0,0,0,5,0,0,0,0,0,0,0
0,0,0,0,0,0,0,19,0,0,0,19,0,0,0,0,0,0,0
0,0,0,0,0,0,0,5,0,0,0,5,0,0,0,0,0,0,0
0,0,0,0,0,0,0,0,8,5,8,0,0,0,0,0,0,0,0
0,0,0,0,0,0,0,0,0,0,0,0,0,0,0,0,0,0,0
0,0,0,0,0,0,0,0,0,0,0,0,0,0,0,0,0,0,0
0,0,0,0,0,0,0,0,0,0,0,0,0,0,0,0,0,0,0
0,0,0,0,0,0,0,0,0,0,0,0,0,0,0,0,0,0,0
0,0,0,0,0,0,0,0,0,0,0,0,0,0,0,0,0,0,0
0,0,0,0,0,0,0,0,0,0,0,0,0,0,0,0,0,0,0
0,0,0,0,0,0,0,0,0,0,0,0,0,0,0,0,0,0,0
0,0,0,0,0,0,0,0,0,0,0,0,0,0,0,0,0,0,0
0,0,0,0,0,0,0,0,0,0,0,0,0,0,0,0,0,0,0
0,0,0,0,0,0,0,0,0,0,0,0,0,0,0,0,0,0,0
:endlayer
layer: 24
0,0,0,0,0,0,0,0,0,0,0,0,0,0,0,0,0,0,0
0,0,0,0,0,0,0,0,0,0,0,0,0,0,0,0,0,0,0
0,0,0,0,0,0,0,0,0,0,0,0,0,0,0,0,0,0,0
0,0,0,0,0,0,0,0,0,0,0,0,0,0,0,0,0,0,0
0,0,0,0,0,0,0,0,0,0,0,0,0,0,0,0,0,0,0
0,0,0,0,0,0,0,0,0,0,0,0,0,0,0,0,0,0,0
0,0,0,0,0,0,0,0,0,0,0,0,0,0,0,0,0,0,0
0,0,0,0,0,0,0,0,0,0,0,0,0,0,0,0,0,0,0
0,0,0,0,0,0,0,0,0,0,0,0,0,0,0,0,0,0,0
0,0,0,0,0,0,0,0,0,0,0,0,0,0,0,0,0,0,0
0,0,0,0,0,0,0,0,0,0,0,0,0,0,0,0,0,0,0
0,0,0,0,0,0,0,0,0,0,0,0,0,0,0,0,0,0,0
0,0,0,0,0,0,0,0,0,0,0,0,0,0,0,0,0,0,0
0,0,0,0,0,0,0,0,0,0,0,0,0,0,0,0,0,0,0
0,0,0,0,0,0,0,0,0,0,0,0,0,0,0,0,0,0,0
0,0,0,0,0,0,0,0,0,0,0,0,0,0,0,0,0,0,0
0,0,0,0,0,0,0,0,0,0,0,0,0,0,0,0,0,0,0
0,0,0,0,0,0,0,0,0,0,0,0,0,0,0,0,0,0,0
0,0,0,0,0,0,0,0,0,0,0,0,0,0,0,0,0,0,0
0,0,0,0,0,0,0,0,8,5,8,0,0,0,0,0,0,0,0
0,0,0,0,0,0,0,5,19,12,19,5,0,0,0,0,0,0,0
0,0,0,0,0,0,0,8,14,0,13,8,0,0,0,0,0,0,0
0,0,0,0,0,0,0,5,19,15,19,5,0,0,0,0,0,0,0
0,0,0,0,0,0,0,0,8,5,8,0,0,0,0,0,0,0,0
0,0,0,0,0,0,0,0,0,0,0,0,0,0,0,0,0,0,0
0,0,0,0,0,0,0,0,0,0,0,0,0,0,0,0,0,0,0
0,0,0,0,0,0,0,0,0,0,0,0,0,0,0,0,0,0,0
0,0,0,0,0,0,0,0,0,0,0,0,0,0,0,0,0,0,0
0,0,0,0,0,0,0,0,0,0,0,0,0,0,0,0,0,0,0
0,0,0,0,0,0,0,0,0,0,0,0,0,0,0,0,0,0,0
0,0,0,0,0,0,0,0,0,0,0,0,0,0,0,0,0,0,0
0,0,0,0,0,0,0,0,0,0,0,0,0,0,0,0,0,0,0
0,0,0,0,0,0,0,0,0,0,0,0,0,0,0,0,0,0,0
0,0,0,0,0,0,0,0,0,0,0,0,0,0,0,0,0,0,0
:endlayer
layer: 25
0,0,0,0,0,0,0,0,0,0,0,0,0,0,0,0,0,0,0
0,0,0,0,0,0,0,0,0,0,0,0,0,0,0,0,0,0,0
0,0,0,0,0,0,0,0,0,0,0,0,0,0,0,0,0,0,0
0,0,0,0,0,0,0,0,0,0,0,0,0,0,0,0,0,0,0
0,0,0,0,0,0,0,0,0,0,0,0,0,0,0,0,0,0,0
0,0,0,0,0,0,0,0,0,0,0,0,0,0,0,0,0,0,0
0,0,0,0,0,0,0,0,0,0,0,0,0,0,0,0,0,0,0
0,0,0,0,0,0,0,0,0,0,0,0,0,0,0,0,0,0,0
0,0,0,0,0,0,0,0,0,0,0,0,0,0,0,0,0,0,0
0,0,0,0,0,0,0,0,0,0,0,0,0,0,0,0,0,0,0
0,0,0,0,0,0,0,0,0,0,0,0,0,0,0,0,0,0,0
0,0,0,0,0,0,0,0,0,0,0,0,0,0,0,0,0,0,0
0,0,0,0,0,0,0,0,0,0,0,0,0,0,0,0,0,0,0
0,0,0,0,0,0,0,0,0,0,0,0,0,0,0,0,0,0,0
0,0,0,0,0,0,0,0,0,0,0,0,0,0,0,0,0,0,0
0,0,0,0,0,0,0,0,0,0,0,0,0,0,0,0,0,0,0
0,0,0,0,0,0,0,0,0,0,0,0,0,0,0,0,0,0,0
0,0,0,0,0,0,0,0,0,0,0,0,0,0,0,0,0,0,0
0,0,0,0,0,0,0,0,27,27,27,0,0,0,0,0,0,0,0
0,0,0,0,0,0,0,27,8,5,8,27,0,0,0,0,0,0,0
0,0,0,0,0,0,27,5,8,16,8,5,27,0,0,0,0,0,0
0,0,0,0,0,0,27,8,20,0,21,8,27,0,0,0,0,0,0
0,0,0,0,0,0,27,5,8,29,8,5,27,0,0,0,0,0,0
0,0,0,0,0,0,0,27,8,5,8,27,0,0,0,0,0,0,0
0,0,0,0,0,0,0,0,27,27,27,0,0,0,0,0,0,0,0
0,0,0,0,0,0,0,0,0,0,0,0,0,0,0,0,0,0,0
0,0,0,0,0,0,0,0,0,0,0,0,0,0,0,0,0,0,0
0,0,0,0,0,0,0,0,0,0,0,0,0,0,0,0,0,0,0
0,0,0,0,0,0,0,0,0,0,0,0,0,0,0,0,0,0,0
0,0,0,0,0,0,0,0,0,0,0,0,0,0,0,0,0,0,0
0,0,0,0,0,0,0,0,0,0,0,0,0,0,0,0,0,0,0
0,0,0,0,0,0,0,0,0,0,0,0,0,0,0,0,0,0,0
0,0,0,0,0,0,0,0,0,0,0,0,0,0,0,0,0,0,0
0,0,0,0,0,0,0,0,0,0,0,0,0,0,0,0,0,0,0
:endlayer
layer: 26
0,0,0,0,0,0,0,0,0,0,0,0,0,0,0,0,0,0,0
0,0,0,0,0,0,0,0,0,0,0,0,0,0,0,0,0,0,0
0,0,0,0,0,0,0,0,0,0,0,0,0,0,0,0,0,0,0
0,0,0,0,0,0,0,0,0,0,0,0,0,0,0,0,0,0,0
0,0,0,0,0,0,0,0,0,0,0,0,0,0,0,0,0,0,0
0,0,0,0,0,0,0,0,0,0,0,0,0,0,0,0,0,0,0
0,0,0,0,0,0,0,0,0,0,0,0,0,0,0,0,0,0,0
0,0,0,0,0,0,0,0,0,0,0,0,0,0,0,0,0,0,0
0,0,0,0,0,0,0,0,0,0,0,0,0,0,0,0,0,0,0
0,0,0,0,0,0,0,0,0,0,0,0,0,0,0,0,0,0,0
0,0,0,0,0,0,0,0,0,0,0,0,0,0,0,0,0,0,0
0,0,0,0,0,0,0,0,0,0,0,0,0,0,0,0,0,0,0
0,0,0,0,0,0,0,0,0,0,0,0,0,0,0,0,0,0,0
0,0,0,0,0,0,0,0,0,0,0,0,0,0,0,0,0,0,0
0,0,0,0,0,0,0,0,0,0,0,0,0,0,0,0,0,0,0
0,0,0,0,0,0,0,0,0,0,0,0,0,0,0,0,0,0,0
0,0,0,0,0,0,0,0,0,0,0,0,0,0,0,0,0,0,0
0,0,0,0,0,0,0,0,0,0,0,0,0,0,0,0,0,0,0
0,0,0,0,0,0,0,0,0,0,0,0,0,0,0,0,0,0,0
0,0,0,0,0,0,0,0,27,27,27,0,0,0,0,0,0,0,0
0,0,0,0,0,0,0,27,27,8,27,27,0,0,0,0,0,0,0
0,0,0,0,0,0,0,27,8,18,8,27,0,0,0,0,0,0,0
0,0,0,0,0,0,0,27,27,8,27,27,0,0,0,0,0,0,0
0,0,0,0,0,0,0,0,27,27,27,0,0,0,0,0,0,0,0
0,0,0,0,0,0,0,0,0,0,0,0,0,0,0,0,0,0,0
0,0,0,0,0,0,0,0,0,0,0,0,0,0,0,0,0,0,0
0,0,0,0,0,0,0,0,0,0,0,0,0,0,0,0,0,0,0
0,0,0,0,0,0,0,0,0,0,0,0,0,0,0,0,0,0,0
0,0,0,0,0,0,0,0,0,0,0,0,0,0,0,0,0,0,0
0,0,0,0,0,0,0,0,0,0,0,0,0,0,0,0,0,0,0
0,0,0,0,0,0,0,0,0,0,0,0,0,0,0,0,0,0,0
0,0,0,0,0,0,0,0,0,0,0,0,0,0,0,0,0,0,0
0,0,0,0,0,0,0,0,0,0,0,0,0,0,0,0,0,0,0
0,0,0,0,0,0,0,0,0,0,0,0,0,0,0,0,0,0,0
:endlayer
layer: 27
0,0,0,0,0,0,0,0,0,0,0,0,0,0,0,0,0,0,0
0,0,0,0,0,0,0,0,0,0,0,0,0,0,0,0,0,0,0
0,0,0,0,0,0,0,0,0,0,0,0,0,0,0,0,0,0,0
0,0,0,0,0,0,0,0,0,0,0,0,0,0,0,0,0,0,0
0,0,0,0,0,0,0,0,0,0,0,0,0,0,0,0,0,0,0
0,0,0,0,0,0,0,0,0,0,0,0,0,0,0,0,0,0,0
0,0,0,0,0,0,0,0,0,0,0,0,0,0,0,0,0,0,0
0,0,0,0,0,0,0,0,0,0,0,0,0,0,0,0,0,0,0
0,0,0,0,0,0,0,0,0,0,0,0,0,0,0,0,0,0,0
0,0,0,0,0,0,0,0,0,0,0,0,0,0,0,0,0,0,0
0,0,0,0,0,0,0,0,0,0,0,0,0,0,0,0,0,0,0
0,0,0,0,0,0,0,0,0,0,0,0,0,0,0,0,0,0,0
0,0,0,0,0,0,0,0,0,0,0,0,0,0,0,0,0,0,0
0,0,0,0,0,0,0,0,0,0,0,0,0,0,0,0,0,0,0
0,0,0,0,0,0,0,0,0,0,0,0,0,0,0,0,0,0,0
0,0,0,0,0,0,0,0,0,0,0,0,0,0,0,0,0,0,0
0,0,0,0,0,0,0,0,0,0,0,0,0,0,0,0,0,0,0
0,0,0,0,0,0,0,0,0,0,0,0,0,0,0,0,0,0,0
0,0,0,0,0,0,0,0,0,0,0,0,0,0,0,0,0,0,0
0,0,0,0,0,0,0,0,0,15,0,0,0,0,0,0,0,0,0
0,0,0,0,0,0,0,0,19,8,19,0,0,0,0,0,0,0,0
0,0,0,0,0,0,0,13,8,8,8,14,0,0,0,0,0,0,0
0,0,0,0,0,0,0,0,19,8,19,0,0,0,0,0,0,0,0
0,0,0,0,0,0,0,0,0,12,0,0,0,0,0,0,0,0,0
0,0,0,0,0,0,0,0,0,0,0,0,0,0,0,0,0,0,0
0,0,0,0,0,0,0,0,0,0,0,0,0,0,0,0,0,0,0
0,0,0,0,0,0,0,0,0,0,0,0,0,0,0,0,0,0,0
0,0,0,0,0,0,0,0,0,0,0,0,0,0,0,0,0,0,0
0,0,0,0,0,0,0,0,0,0,0,0,0,0,0,0,0,0,0
0,0,0,0,0,0,0,0,0,0,0,0,0,0,0,0,0,0,0
0,0,0,0,0,0,0,0,0,0,0,0,0,0,0,0,0,0,0
0,0,0,0,0,0,0,0,0,0,0,0,0,0,0,0,0,0,0
0,0,0,0,0,0,0,0,0,0,0,0,0,0,0,0,0,0,0
0,0,0,0,0,0,0,0,0,0,0,0,0,0,0,0,0,0,0
:endlayer
layer: 28
0,0,0,0,0,0,0,0,0,0,0,0,0,0,0,0,0,0,0
0,0,0,0,0,0,0,0,0,0,0,0,0,0,0,0,0,0,0
0,0,0,0,0,0,0,0,0,0,0,0,0,0,0,0,0,0,0
0,0,0,0,0,0,0,0,0,0,0,0,0,0,0,0,0,0,0
0,0,0,0,0,0,0,0,0,0,0,0,0,0,0,0,0,0,0
0,0,0,0,0,0,0,0,0,0,0,0,0,0,0,0,0,0,0
0,0,0,0,0,0,0,0,0,0,0,0,0,0,0,0,0,0,0
0,0,0,0,0,0,0,0,0,0,0,0,0,0,0,0,0,0,0
0,0,0,0,0,0,0,0,0,0,0,0,0,0,0,0,0,0,0
0,0,0,0,0,0,0,0,0,0,0,0,0,0,0,0,0,0,0
0,0,0,0,0,0,0,0,0,0,0,0,0,0,0,0,0,0,0
0,0,0,0,0,0,0,0,0,0,0,0,0,0,0,0,0,0,0
0,0,0,0,0,0,0,0,0,0,0,0,0,0,0,0,0,0,0
0,0,0,0,0,0,0,0,0,0,0,0,0,0,0,0,0,0,0
0,0,0,0,0,0,0,0,0,0,0,0,0,0,0,0,0,0,0
0,0,0,0,0,0,0,0,0,0,0,0,0,0,0,0,0,0,0
0,0,0,0,0,0,0,0,0,0,0,0,0,0,0,0,0,0,0
0,0,0,0,0,0,0,0,0,0,0,0,0,0,0,0,0,0,0
0,0,0,0,0,0,0,0,0,0,0,0,0,0,0,0,0,0,0
0,0,0,0,0,0,0,0,0,0,0,0,0,0,0,0,0,0,0
0,0,0,0,0,0,0,0,19,8,19,0,0,0,0,0,0,0,0
0,0,0,0,0,0,0,0,8,8,8,0,0,0,0,0,0,0,0
0,0,0,0,0,0,0,0,19,8,19,0,0,0,0,0,0,0,0
0,0,0,0,0,0,0,0,0,0,0,0,0,0,0,0,0,0,0
0,0,0,0,0,0,0,0,0,0,0,0,0,0,0,0,0,0,0
0,0,0,0,0,0,0,0,0,0,0,0,0,0,0,0,0,0,0
0,0,0,0,0,0,0,0,0,0,0,0,0,0,0,0,0,0,0
0,0,0,0,0,0,0,0,0,0,0,0,0,0,0,0,0,0,0
0,0,0,0,0,0,0,0,0,0,0,0,0,0,0,0,0,0,0
0,0,0,0,0,0,0,0,0,0,0,0,0,0,0,0,0,0,0
0,0,0,0,0,0,0,0,0,0,0,0,0,0,0,0,0,0,0
0,0,0,0,0,0,0,0,0,0,0,0,0,0,0,0,0,0,0
0,0,0,0,0,0,0,0,0,0,0,0,0,0,0,0,0,0,0
0,0,0,0,0,0,0,0,0,0,0,0,0,0,0,0,0,0,0
:endlayer
layer: 29
0,0,0,0,0,0,0,0,0,0,0,0,0,0,0,0,0,0,0
0,0,0,0,0,0,0,0,0,0,0,0,0,0,0,0,0,0,0
0,0,0,0,0,0,0,0,0,0,0,0,0,0,0,0,0,0,0
0,0,0,0,0,0,0,0,0,0,0,0,0,0,0,0,0,0,0
0,0,0,0,0,0,0,0,0,0,0,0,0,0,0,0,0,0,0
0,0,0,0,0,0,0,0,0,0,0,0,0,0,0,0,0,0,0
0,0,0,0,0,0,0,0,0,0,0,0,0,0,0,0,0,0,0
0,0,0,0,0,0,0,0,0,0,0,0,0,0,0,0,0,0,0
0,0,0,0,0,0,0,0,0,0,0,0,0,0,0,0,0,0,0
0,0,0,0,0,0,0,0,0,0,0,0,0,0,0,0,0,0,0
0,0,0,0,0,0,0,0,0,0,0,0,0,0,0,0,0,0,0
0,0,0,0,0,0,0,0,0,0,0,0,0,0,0,0,0,0,0
0,0,0,0,0,0,0,0,0,0,0,0,0,0,0,0,0,0,0
0,0,0,0,0,0,0,0,0,0,0,0,0,0,0,0,0,0,0
0,0,0,0,0,0,0,0,0,0,0,0,0,0,0,0,0,0,0
0,0,0,0,0,0,0,0,0,0,0,0,0,0,0,0,0,0,0
0,0,0,0,0,0,0,0,0,0,0,0,0,0,0,0,0,0,0
0,0,0,0,0,0,0,0,0,0,0,0,0,0,0,0,0,0,0
0,0,0,0,0,0,0,0,0,0,0,0,0,0,0,0,0,0,0
0,0,0,0,0,0,0,0,0,0,0,0,0,0,0,0,0,0,0
0,0,0,0,0,0,0,0,19,8,19,0,0,0,0,0,0,0,0
0,0,0,0,0,0,0,0,8,8,8,0,0,0,0,0,0,0,0
0,0,0,0,0,0,0,0,19,8,19,0,0,0,0,0,0,0,0
0,0,0,0,0,0,0,0,0,0,0,0,0,0,0,0,0,0,0
0,0,0,0,0,0,0,0,0,0,0,0,0,0,0,0,0,0,0
0,0,0,0,0,0,0,0,0,0,0,0,0,0,0,0,0,0,0
0,0,0,0,0,0,0,0,0,0,0,0,0,0,0,0,0,0,0
0,0,0,0,0,0,0,0,0,0,0,0,0,0,0,0,0,0,0
0,0,0,0,0,0,0,0,0,0,0,0,0,0,0,0,0,0,0
0,0,0,0,0,0,0,0,0,0,0,0,0,0,0,0,0,0,0
0,0,0,0,0,0,0,0,0,0,0,0,0,0,0,0,0,0,0
0,0,0,0,0,0,0,0,0,0,0,0,0,0,0,0,0,0,0
0,0,0,0,0,0,0,0,0,0,0,0,0,0,0,0,0,0,0
0,0,0,0,0,0,0,0,0,0,0,0,0,0,0,0,0,0,0
:endlayer
layer: 30
0,0,0,0,0,0,0,0,0,0,0,0,0,0,0,0,0,0,0
0,0,0,0,0,0,0,0,0,0,0,0,0,0,0,0,0,0,0
0,0,0,0,0,0,0,0,0,0,0,0,0,0,0,0,0,0,0
0,0,0,0,0,0,0,0,0,0,0,0,0,0,0,0,0,0,0
0,0,0,0,0,0,0,0,0,0,0,0,0,0,0,0,0,0,0
0,0,0,0,0,0,0,0,0,0,0,0,0,0,0,0,0,0,0
0,0,0,0,0,0,0,0,0,0,0,0,0,0,0,0,0,0,0
0,0,0,0,0,0,0,0,0,0,0,0,0,0,0,0,0,0,0
0,0,0,0,0,0,0,0,0,0,0,0,0,0,0,0,0,0,0
0,0,0,0,0,0,0,0,0,0,0,0,0,0,0,0,0,0,0
0,0,0,0,0,0,0,0,0,0,0,0,0,0,0,0,0,0,0
0,0,0,0,0,0,0,0,0,0,0,0,0,0,0,0,0,0,0
0,0,0,0,0,0,0,0,0,0,0,0,0,0,0,0,0,0,0
0,0,0,0,0,0,0,0,0,0,0,0,0,0,0,0,0,0,0
0,0,0,0,0,0,0,0,0,0,0,0,0,0,0,0,0,0,0
0,0,0,0,0,0,0,0,0,0,0,0,0,0,0,0,0,0,0
0,0,0,0,0,0,0,0,0,0,0,0,0,0,0,0,0,0,0
0,0,0,0,0,0,0,0,0,0,0,0,0,0,0,0,0,0,0
0,0,0,0,0,0,0,0,0,0,0,0,0,0,0,0,0,0,0
0,0,0,0,0,0,0,0,0,27,0,0,0,0,0,0,0,0,0
0,0,0,0,0,0,0,0,27,8,27,0,0,0,0,0,0,0,0
0,0,0,0,0,0,0,27,8,8,8,27,0,0,0,0,0,0,0
0,0,0,0,0,0,0,0,27,8,27,0,0,0,0,0,0,0,0
0,0,0,0,0,0,0,0,0,27,0,0,0,0,0,0,0,0,0
0,0,0,0,0,0,0,0,0,0,0,0,0,0,0,0,0,0,0
0,0,0,0,0,0,0,0,0,0,0,0,0,0,0,0,0,0,0
0,0,0,0,0,0,0,0,0,0,0,0,0,0,0,0,0,0,0
0,0,0,0,0,0,0,0,0,0,0,0,0,0,0,0,0,0,0
0,0,0,0,0,0,0,0,0,0,0,0,0,0,0,0,0,0,0
0,0,0,0,0,0,0,0,0,0,0,0,0,0,0,0,0,0,0
0,0,0,0,0,0,0,0,0,0,0,0,0,0,0,0,0,0,0
0,0,0,0,0,0,0,0,0,0,0,0,0,0,0,0,0,0,0
0,0,0,0,0,0,0,0,0,0,0,0,0,0,0,0,0,0,0
0,0,0,0,0,0,0,0,0,0,0,0,0,0,0,0,0,0,0
:endlayer
layer: 31
0,0,0,0,0,0,0,0,0,0,0,0,0,0,0,0,0,0,0
0,0,0,0,0,0,0,0,0,0,0,0,0,0,0,0,0,0,0
0,0,0,0,0,0,0,0,0,0,0,0,0,0,0,0,0,0,0
0,0,0,0,0,0,0,0,0,0,0,0,0,0,0,0,0,0,0
0,0,0,0,0,0,0,0,0,0,0,0,0,0,0,0,0,0,0
0,0,0,0,0,0,0,0,0,0,0,0,0,0,0,0,0,0,0
0,0,0,0,0,0,0,0,0,0,0,0,0,0,0,0,0,0,0
0,0,0,0,0,0,0,0,0,0,0,0,0,0,0,0,0,0,0
0,0,0,0,0,0,0,0,0,0,0,0,0,0,0,0,0,0,0
0,0,0,0,0,0,0,0,0,0,0,0,0,0,0,0,0,0,0
0,0,0,0,0,0,0,0,0,0,0,0,0,0,0,0,0,0,0
0,0,0,0,0,0,0,0,0,0,0,0,0,0,0,0,0,0,0
0,0,0,0,0,0,0,0,0,0,0,0,0,0,0,0,0,0,0
0,0,0,0,0,0,0,0,0,0,0,0,0,0,0,0,0,0,0
0,0,0,0,0,0,0,0,0,0,0,0,0,0,0,0,0,0,0
0,0,0,0,0,0,0,0,0,0,0,0,0,0,0,0,0,0,0
0,0,0,0,0,0,0,0,0,0,0,0,0,0,0,0,0,0,0
0,0,0,0,0,0,0,0,0,0,0,0,0,0,0,0,0,0,0
0,0,0,0,0,0,0,0,0,0,0,0,0,0,0,0,0,0,0
0,0,0,0,0,0,0,0,27,27,27,0,0,0,0,0,0,0,0
0,0,0,0,0,0,0,27,27,8,27,27,0,0,0,0,0,0,0
0,0,0,0,0,0,0,27,8,8,8,27,0,0,0,0,0,0,0
0,0,0,0,0,0,0,27,27,8,27,27,0,0,0,0,0,0,0
0,0,0,0,0,0,0,0,27,27,27,0,0,0,0,0,0,0,0
0,0,0,0,0,0,0,0,0,0,0,0,0,0,0,0,0,0,0
0,0,0,0,0,0,0,0,0,0,0,0,0,0,0,0,0,0,0
0,0,0,0,0,0,0,0,0,0,0,0,0,0,0,0,0,0,0
0,0,0,0,0,0,0,0,0,0,0,0,0,0,0,0,0,0,0
0,0,0,0,0,0,0,0,0,0,0,0,0,0,0,0,0,0,0
0,0,0,0,0,0,0,0,0,0,0,0,0,0,0,0,0,0,0
0,0,0,0,0,0,0,0,0,0,0,0,0,0,0,0,0,0,0
0,0,0,0,0,0,0,0,0,0,0,0,0,0,0,0,0,0,0
0,0,0,0,0,0,0,0,0,0,0,0,0,0,0,0,0,0,0
0,0,0,0,0,0,0,0,0,0,0,0,0,0,0,0,0,0,0
:endlayer
layer: 32
0,0,0,0,0,0,0,0,0,0,0,0,0,0,0,0,0,0,0
0,0,0,0,0,0,0,0,0,0,0,0,0,0,0,0,0,0,0
0,0,0,0,0,0,0,0,0,0,0,0,0,0,0,0,0,0,0
0,0,0,0,0,0,0,0,0,0,0,0,0,0,0,0,0,0,0
0,0,0,0,0,0,0,0,0,0,0,0,0,0,0,0,0,0,0
0,0,0,0,0,0,0,0,0,0,0,0,0,0,0,0,0,0,0
0,0,0,0,0,0,0,0,0,0,0,0,0,0,0,0,0,0,0
0,0,0,0,0,0,0,0,0,0,0,0,0,0,0,0,0,0,0
0,0,0,0,0,0,0,0,0,0,0,0,0,0,0,0,0,0,0
0,0,0,0,0,0,0,0,0,0,0,0,0,0,0,0,0,0,0
0,0,0,0,0,0,0,0,0,0,0,0,0,0,0,0,0,0,0
0,0,0,0,0,0,0,0,0,0,0,0,0,0,0,0,0,0,0
0,0,0,0,0,0,0,0,0,0,0,0,0,0,0,0,0,0,0
0,0,0,0,0,0,0,0,0,0,0,0,0,0,0,0,0,0,0
0,0,0,0,0,0,0,0,0,0,0,0,0,0,0,0,0,0,0
0,0,0,0,0,0,0,0,0,0,0,0,0,0,0,0,0,0,0
0,0,0,0,0,0,0,0,0,0,0,0,0,0,0,0,0,0,0
0,0,0,0,0,0,0,0,0,0,0,0,0,0,0,0,0,0,0
0,0,0,0,0,0,0,0,0,0,0,0,0,0,0,0,0,0,0
0,0,0,0,0,0,0,0,0,27,0,0,0,0,0,0,0,0,0
0,0,0,0,0,0,0,0,27,8,27,0,0,0,0,0,0,0,0
0,0,0,0,0,0,0,27,8,8,8,27,0,0,0,0,0,0,0
0,0,0,0,0,0,0,0,27,8,27,0,0,0,0,0,0,0,0
0,0,0,0,0,0,0,0,0,27,0,0,0,0,0,0,0,0,0
0,0,0,0,0,0,0,0,0,0,0,0,0,0,0,0,0,0,0
0,0,0,0,0,0,0,0,0,0,0,0,0,0,0,0,0,0,0
0,0,0,0,0,0,0,0,0,0,0,0,0,0,0,0,0,0,0
0,0,0,0,0,0,0,0,0,0,0,0,0,0,0,0,0,0,0
0,0,0,0,0,0,0,0,0,0,0,0,0,0,0,0,0,0,0
0,0,0,0,0,0,0,0,0,0,0,0,0,0,0,0,0,0,0
0,0,0,0,0,0,0,0,0,0,0,0,0,0,0,0,0,0,0
0,0,0,0,0,0,0,0,0,0,0,0,0,0,0,0,0,0,0
0,0,0,0,0,0,0,0,0,0,0,0,0,0,0,0,0,0,0
0,0,0,0,0,0,0,0,0,0,0,0,0,0,0,0,0,0,0
:endlayer
layer: 33
0,0,0,0,0,0,0,0,0,0,0,0,0,0,0,0,0,0,0
0,0,0,0,0,0,0,0,0,0,0,0,0,0,0,0,0,0,0
0,0,0,0,0,0,0,0,0,0,0,0,0,0,0,0,0,0,0
0,0,0,0,0,0,0,0,0,0,0,0,0,0,0,0,0,0,0
0,0,0,0,0,0,0,0,0,0,0,0,0,0,0,0,0,0,0
0,0,0,0,0,0,0,0,0,0,0,0,0,0,0,0,0,0,0
0,0,0,0,0,0,0,0,0,0,0,0,0,0,0,0,0,0,0
0,0,0,0,0,0,0,0,0,0,0,0,0,0,0,0,0,0,0
0,0,0,0,0,0,0,0,0,0,0,0,0,0,0,0,0,0,0
0,0,0,0,0,0,0,0,0,0,0,0,0,0,0,0,0,0,0
0,0,0,0,0,0,0,0,0,0,0,0,0,0,0,0,0,0,0
0,0,0,0,0,0,0,0,0,0,0,0,0,0,0,0,0,0,0
0,0,0,0,0,0,0,0,0,0,0,0,0,0,0,0,0,0,0
0,0,0,0,0,0,0,0,0,0,0,0,0,0,0,0,0,0,0
0,0,0,0,0,0,0,0,0,0,0,0,0,0,0,0,0,0,0
0,0,0,0,0,0,0,0,0,0,0,0,0,0,0,0,0,0,0
0,0,0,0,0,0,0,0,0,0,0,0,0,0,0,0,0,0,0
0,0,0,0,0,0,0,0,0,0,0,0,0,0,0,0,0,0,0
0,0,0,0,0,0,0,0,0,0,0,0,0,0,0,0,0,0,0
0,0,0,0,0,0,0,0,0,27,0,0,0,0,0,0,0,0,0
0,0,0,0,0,0,0,0,27,27,27,0,0,0,0,0,0,0,0
0,0,0,0,0,0,0,27,27,8,27,27,0,0,0,0,0,0,0
0,0,0,0,0,0,0,0,27,27,27,0,0,0,0,0,0,0,0
0,0,0,0,0,0,0,0,0,27,0,0,0,0,0,0,0,0,0
0,0,0,0,0,0,0,0,0,0,0,0,0,0,0,0,0,0,0
0,0,0,0,0,0,0,0,0,0,0,0,0,0,0,0,0,0,0
0,0,0,0,0,0,0,0,0,0,0,0,0,0,0,0,0,0,0
0,0,0,0,0,0,0,0,0,0,0,0,0,0,0,0,0,0,0
0,0,0,0,0,0,0,0,0,0,0,0,0,0,0,0,0,0,0
0,0,0,0,0,0,0,0,0,0,0,0,0,0,0,0,0,0,0
0,0,0,0,0,0,0,0,0,0,0,0,0,0,0,0,0,0,0
0,0,0,0,0,0,0,0,0,0,0,0,0,0,0,0,0,0,0
0,0,0,0,0,0,0,0,0,0,0,0,0,0,0,0,0,0,0
0,0,0,0,0,0,0,0,0,0,0,0,0,0,0,0,0,0,0
:endlayer
layer: 34
0,0,0,0,0,0,0,0,0,0,0,0,0,0,0,0,0,0,0
0,0,0,0,0,0,0,0,0,0,0,0,0,0,0,0,0,0,0
0,0,0,0,0,0,0,0,0,0,0,0,0,0,0,0,0,0,0
0,0,0,0,0,0,0,0,0,0,0,0,0,0,0,0,0,0,0
0,0,0,0,0,0,0,0,0,0,0,0,0,0,0,0,0,0,0
0,0,0,0,0,0,0,0,0,0,0,0,0,0,0,0,0,0,0
0,0,0,0,0,0,0,0,0,0,0,0,0,0,0,0,0,0,0
0,0,0,0,0,0,0,0,0,0,0,0,0,0,0,0,0,0,0
0,0,0,0,0,0,0,0,0,0,0,0,0,0,0,0,0,0,0
0,0,0,0,0,0,0,0,0,0,0,0,0,0,0,0,0,0,0
0,0,0,0,0,0,0,0,0,0,0,0,0,0,0,0,0,0,0
0,0,0,0,0,0,0,0,0,0,0,0,0,0,0,0,0,0,0
0,0,0,0,0,0,0,0,0,0,0,0,0,0,0,0,0,0,0
0,0,0,0,0,0,0,0,0,0,0,0,0,0,0,0,0,0,0
0,0,0,0,0,0,0,0,0,0,0,0,0,0,0,0,0,0,0
0,0,0,0,0,0,0,0,0,0,0,0,0,0,0,0,0,0,0
0,0,0,0,0,0,0,0,0,0,0,0,0,0,0,0,0,0,0
0,0,0,0,0,0,0,0,0,0,0,0,0,0,0,0,0,0,0
0,0,0,0,0,0,0,0,0,0,0,0,0,0,0,0,0,0,0
0,0,0,0,0,0,0,0,0,0,0,0,0,0,0,0,0,0,0
0,0,0,0,0,0,0,0,6,27,14,0,0,0,0,0,0,0,0
0,0,0,0,0,0,0,0,27,0,27,0,0,0,0,0,0,0,0
0,0,0,0,0,0,0,0,6,27,6,0,0,0,0,0,0,0,0
0,0,0,0,0,0,0,0,0,0,0,0,0,0,0,0,0,0,0
0,0,0,0,0,0,0,0,0,0,0,0,0,0,0,0,0,0,0
0,0,0,0,0,0,0,0,0,0,0,0,0,0,0,0,0,0,0
0,0,0,0,0,0,0,0,0,0,0,0,0,0,0,0,0,0,0
0,0,0,0,0,0,0,0,0,0,0,0,0,0,0,0,0,0,0
0,0,0,0,0,0,0,0,0,0,0,0,0,0,0,0,0,0,0
0,0,0,0,0,0,0,0,0,0,0,0,0,0,0,0,0,0,0
0,0,0,0,0,0,0,0,0,0,0,0,0,0,0,0,0,0,0
0,0,0,0,0,0,0,0,0,0,0,0,0,0,0,0,0,0,0
0,0,0,0,0,0,0,0,0,0,0,0,0,0,0,0,0,0,0
0,0,0,0,0,0,0,0,0,0,0,0,0,0,0,0,0,0,0
:endlayer
layer: 35
0,0,0,0,0,0,0,0,0,0,0,0,0,0,0,0,0,0,0
0,0,0,0,0,0,0,0,0,0,0,0,0,0,0,0,0,0,0
0,0,0,0,0,0,0,0,0,0,0,0,0,0,0,0,0,0,0
0,0,0,0,0,0,0,0,0,0,0,0,0,0,0,0,0,0,0
0,0,0,0,0,0,0,0,0,0,0,0,0,0,0,0,0,0,0
0,0,0,0,0,0,0,0,0,0,0,0,0,0,0,0,0,0,0
0,0,0,0,0,0,0,0,0,0,0,0,0,0,0,0,0,0,0
0,0,0,0,0,0,0,0,0,0,0,0,0,0,0,0,0,0,0
0,0,0,0,0,0,0,0,0,0,0,0,0,0,0,0,0,0,0
0,0,0,0,0,0,0,0,0,0,0,0,0,0,0,0,0,0,0
0,0,0,0,0,0,0,0,0,0,0,0,0,0,0,0,0,0,0
0,0,0,0,0,0,0,0,0,0,0,0,0,0,0,0,0,0,0
0,0,0,0,0,0,0,0,0,0,0,0,0,0,0,0,0,0,0
0,0,0,0,0,0,0,0,0,0,0,0,0,0,0,0,0,0,0
0,0,0,0,0,0,0,0,0,0,0,0,0,0,0,0,0,0,0
0,0,0,0,0,0,0,0,0,0,0,0,0,0,0,0,0,0,0
0,0,0,0,0,0,0,0,0,0,0,0,0,0,0,0,0,0,0
0,0,0,0,0,0,0,0,0,0,0,0,0,0,0,0,0,0,0
0,0,0,0,0,0,0,0,0,0,0,0,0,0,0,0,0,0,0
0,0,0,0,0,0,0,0,0,0,0,0,0,0,0,0,0,0,0
0,0,0,0,0,0,0,0,0,0,0,0,0,0,0,0,0,0,0
0,0,0,0,0,0,0,0,0,27,0,0,0,0,0,0,0,0,0
0,0,0,0,0,0,0,0,0,0,0,0,0,0,0,0,0,0,0
0,0,0,0,0,0,0,0,0,0,0,0,0,0,0,0,0,0,0
0,0,0,0,0,0,0,0,0,0,0,0,0,0,0,0,0,0,0
0,0,0,0,0,0,0,0,0,0,0,0,0,0,0,0,0,0,0
0,0,0,0,0,0,0,0,0,0,0,0,0,0,0,0,0,0,0
0,0,0,0,0,0,0,0,0,0,0,0,0,0,0,0,0,0,0
0,0,0,0,0,0,0,0,0,0,0,0,0,0,0,0,0,0,0
0,0,0,0,0,0,0,0,0,0,0,0,0,0,0,0,0,0,0
0,0,0,0,0,0,0,0,0,0,0,0,0,0,0,0,0,0,0
0,0,0,0,0,0,0,0,0,0,0,0,0,0,0,0,0,0,0
0,0,0,0,0,0,0,0,0,0,0,0,0,0,0,0,0,0,0
0,0,0,0,0,0,0,0,0,0,0,0,0,0,0,0,0,0,0
:endlayer
layer: 36
0,0,0,0,0,0,0,0,0,0,0,0,0,0,0,0,0,0,0
0,0,0,0,0,0,0,0,0,0,0,0,0,0,0,0,0,0,0
0,0,0,0,0,0,0,0,0,0,0,0,0,0,0,0,0,0,0
0,0,0,0,0,0,0,0,0,0,0,0,0,0,0,0,0,0,0
0,0,0,0,0,0,0,0,0,0,0,0,0,0,0,0,0,0,0
0,0,0,0,0,0,0,0,0,0,0,0,0,0,0,0,0,0,0
0,0,0,0,0,0,0,0,0,0,0,0,0,0,0,0,0,0,0
0,0,0,0,0,0,0,0,0,0,0,0,0,0,0,0,0,0,0
0,0,0,0,0,0,0,0,0,0,0,0,0,0,0,0,0,0,0
0,0,0,0,0,0,0,0,0,0,0,0,0,0,0,0,0,0,0
0,0,0,0,0,0,0,0,0,0,0,0,0,0,0,0,0,0,0
0,0,0,0,0,0,0,0,0,0,0,0,0,0,0,0,0,0,0
0,0,0,0,0,0,0,0,0,0,0,0,0,0,0,0,0,0,0
0,0,0,0,0,0,0,0,0,0,0,0,0,0,0,0,0,0,0
0,0,0,0,0,0,0,0,0,0,0,0,0,0,0,0,0,0,0
0,0,0,0,0,0,0,0,0,0,0,0,0,0,0,0,0,0,0
0,0,0,0,0,0,0,0,0,0,0,0,0,0,0,0,0,0,0
0,0,0,0,0,0,0,0,0,0,0,0,0,0,0,0,0,0,0
0,0,0,0,0,0,0,0,0,0,0,0,0,0,0,0,0,0,0
0,0,0,0,0,0,0,0,0,0,0,0,0,0,0,0,0,0,0
0,0,0,0,0,0,0,0,0,0,0,0,0,0,0,0,0,0,0
0,0,0,0,0,0,0,0,0,27,0,0,0,0,0,0,0,0,0
0,0,0,0,0,0,0,0,0,0,0,0,0,0,0,0,0,0,0
0,0,0,0,0,0,0,0,0,0,0,0,0,0,0,0,0,0,0
0,0,0,0,0,0,0,0,0,0,0,0,0,0,0,0,0,0,0
0,0,0,0,0,0,0,0,0,0,0,0,0,0,0,0,0,0,0
0,0,0,0,0,0,0,0,0,0,0,0,0,0,0,0,0,0,0
0,0,0,0,0,0,0,0,0,0,0,0,0,0,0,0,0,0,0
0,0,0,0,0,0,0,0,0,0,0,0,0,0,0,0,0,0,0
0,0,0,0,0,0,0,0,0,0,0,0,0,0,0,0,0,0,0
0,0,0,0,0,0,0,0,0,0,0,0,0,0,0,0,0,0,0
0,0,0,0,0,0,0,0,0,0,0,0,0,0,0,0,0,0,0
0,0,0,0,0,0,0,0,0,0,0,0,0,0,0,0,0,0,0
0,0,0,0,0,0,0,0,0,0,0,0,0,0,0,0,0,0,0
:endlayer

#### RULES ####
rule:
plugin=vanillaBlocks
number=1
data:
JSON:{blockState:{blockName:"minecraft:dirt",properties:{variant:"dirt",snowy:"false"}}}
:enddata
:endrule

rule:
plugin=vanillaBlocks
number=2
data:
JSON:{blockState:{blockName:"minecraft:cobblestone"}}
:enddata
:endrule

rule:
plugin=vanillaBlocks
number=3
data:
JSON:{blockState:{blockName:"minecraft:grass",properties:{snowy:"false"}}}
:enddata
:endrule

rule:
plugin=vanillaBlocks
number=4
data:
JSON:{blockState:{blockName:"minecraft:ladder",properties:{facing:"east"}}}
:enddata
:endrule

rule:
plugin=vanillaBlocks
number=5
data:
JSON:{blockState:{blockName:"biomesoplenty:log_2",properties:{variant:"hellbark",axis:"y"}}}
:enddata
:endrule

rule:
plugin=vanillaBlocks
number=6
data:
JSON:{blockState:{blockName:"minecraft:torch",properties:{facing:"up"}}}
:enddata
:endrule

rule:
plugin=vanillaBlocks
number=7
data:
JSON:{blockState:{blockName:"minecraft:stonebrick",properties:{variant:"stonebrick"}}}
:enddata
:endrule

rule:
plugin=vanillaBlocks
number=8
data:
JSON:{blockState:{blockName:"biomesoplenty:planks_0",properties:{variant:"hellbark"}}}
:enddata
:endrule

rule:
plugin=vanillaBlocks
number=9
data:
JSON:{blockState:{blockName:"biomesoplenty:hellbark_stairs",properties:{half:"bottom",shape:"straight",facing:"east"}}}
:enddata
:endrule

rule:
plugin=vanillaBlocks
number=10
data:
JSON:{blockState:{blockName:"biomesoplenty:hellbark_stairs",properties:{half:"bottom",shape:"straight",facing:"west"}}}
:enddata
:endrule

rule:
plugin=vanillaBlocks
number=11
data:
JSON:{blockState:{blockName:"biomesoplenty:log_2",properties:{variant:"hellbark",axis:"x"}}}
:enddata
:endrule

rule:
plugin=vanillaBlocks
number=12
data:
JSON:{blockState:{blockName:"minecraft:torch",properties:{facing:"south"}}}
:enddata
:endrule

rule:
plugin=vanillaBlocks
number=13
data:
JSON:{blockState:{blockName:"minecraft:torch",properties:{facing:"west"}}}
:enddata
:endrule

rule:
plugin=vanillaBlocks
number=14
data:
JSON:{blockState:{blockName:"minecraft:torch",properties:{facing:"east"}}}
:enddata
:endrule

rule:
plugin=vanillaBlocks
number=15
data:
JSON:{blockState:{blockName:"minecraft:torch",properties:{facing:"north"}}}
:enddata
:endrule

rule:
plugin=vanillaBlocks
number=16
data:
JSON:{blockState:{blockName:"biomesoplenty:hellbark_stairs",properties:{half:"top",shape:"straight",facing:"north"}}}
:enddata
:endrule

rule:
plugin=vanillaBlocks
number=17
data:
JSON:{blockState:{blockName:"biomesoplenty:log_2",properties:{variant:"hellbark",axis:"z"}}}
:enddata
:endrule

rule:
plugin=vanillaBlocks
number=18
data:
JSON:{blockState:{blockName:"biomesoplenty:wood_slab_1",properties:{half:"top",variant:"hellbark"}}}
:enddata
:endrule

rule:
plugin=vanillaBlocks
number=19
data:
JSON:{blockState:{blockName:"biomesoplenty:hellbark_fence",properties:{east:"false",south:"false",north:"false",west:"false"}}}
:enddata
:endrule

rule:
plugin=vanillaBlocks
number=20
data:
JSON:{blockState:{blockName:"biomesoplenty:hellbark_stairs",properties:{half:"top",shape:"straight",facing:"west"}}}
:enddata
:endrule

rule:
plugin=vanillaBlocks
number=21
data:
JSON:{blockState:{blockName:"biomesoplenty:hellbark_stairs",properties:{half:"top",shape:"straight",facing:"east"}}}
:enddata
:endrule

rule:
plugin=vanillaBlocks
number=22
data:
JSON:{blockState:{blockName:"biomesoplenty:hellbark_stairs",properties:{half:"bottom",shape:"straight",facing:"south"}}}
:enddata
:endrule

rule:
plugin=vanillaBlocks
number=23
data:
JSON:{blockState:{blockName:"minecraft:wool",properties:{color:"blue"}}}
:enddata
:endrule

rule:
plugin=vanillaBlocks
number=24
data:
JSON:{blockState:{blockName:"biomesoplenty:hellbark_stairs",properties:{half:"bottom",shape:"straight",facing:"north"}}}
:enddata
:endrule

rule:
plugin=vanillaBlocks
number=25
data:
JSON:{blockState:{blockName:"minecraft:ladder",properties:{facing:"south"}}}
:enddata
:endrule

rule:
plugin=vanillaBlocks
number=26
data:
JSON:{blockState:{blockName:"minecraft:ladder",properties:{facing:"north"}}}
:enddata
:endrule

rule:
plugin=vanillaBlocks
number=27
data:
JSON:{blockState:{blockName:"minecraft:wool",properties:{color:"brown"}}}
:enddata
:endrule

rule:
plugin=vanillaBlocks
number=28
data:
JSON:{blockState:{blockName:"biomesoplenty:wood_slab_1",properties:{half:"bottom",variant:"hellbark"}}}
:enddata
:endrule

rule:
plugin=vanillaBlocks
number=29
data:
JSON:{blockState:{blockName:"biomesoplenty:hellbark_stairs",properties:{half:"top",shape:"straight",facing:"south"}}}
:enddata
:endrule

#### ENTITIES ####
