# Ancient Warfare Structure Template File
# Auto-generated structure template file. created on: 10/15/2023 at: 13:24:4
# Lines beginning with # denote comments

header:
version=2.11
name=SB_KievarusCol_Cathedral_1_ethereal
mods=biomesoplenty
size=36,51,47
offset=17,1,46
:endheader

#### VALIDATION ####
validation:
type=ground
structureAuthor=TheOddlySeagull
survival=true
worldGenEnabled=false
unique=false
preserveBlocks=false
preventNaturalHostileSpawns=false
selectionWeight=1
clusterValue=1
minDuplicateDistance=1
dimensionWhiteList=true
dimensionList=
biomeGroupList=
biomeWhiteList=true
biomeList=
leveling=0
fill=0
border=0
blockSwap=false
territoryName=
biomeReplacement=minecraft:
minGenerationHeight=0
maxGenerationHeight=255
:endvalidation

#### LAYERS ####
layer: 0
1,1,1,1,1,1,1,1,1,1,1,1,1,1,1,1,1,1,1,1,1,1,1,1,1,1,1,1,1,1,1,1,1,1,1,1
1,1,1,1,1,1,1,1,1,1,1,1,1,1,1,1,1,1,1,1,1,1,1,1,1,1,1,1,1,1,1,1,1,1,1,1
1,1,1,1,1,1,1,1,1,1,1,1,1,1,1,2,2,2,2,2,2,1,1,1,1,1,1,1,1,1,1,1,1,1,1,1
1,1,1,1,1,1,1,1,1,1,1,1,1,1,2,2,2,2,2,2,2,2,1,1,1,1,1,1,1,1,1,1,1,1,1,1
1,1,1,1,1,1,1,1,1,1,1,1,1,2,2,3,3,3,3,3,3,2,2,1,1,1,1,1,1,1,1,1,1,1,1,1
1,1,1,1,1,1,1,1,1,1,1,1,1,2,2,3,3,3,3,3,3,2,2,1,1,1,1,1,1,1,1,1,1,1,1,1
1,1,1,1,1,1,1,1,1,1,1,1,1,2,2,3,3,3,3,3,3,2,2,1,1,1,1,1,1,1,1,1,1,1,1,1
1,1,1,1,1,1,1,1,1,1,1,1,2,2,2,3,3,3,3,3,3,2,2,2,1,1,1,1,1,1,1,1,1,1,1,1
1,1,1,1,1,1,1,1,1,1,1,1,2,2,3,3,3,3,3,3,3,3,2,2,1,1,1,1,1,1,1,1,1,1,1,1
1,1,1,1,2,2,1,2,2,2,2,1,2,2,3,3,3,3,3,3,3,3,2,2,1,2,2,2,2,1,2,2,1,1,1,1
1,1,1,1,2,2,2,2,2,2,2,2,2,2,2,2,2,2,2,2,2,2,2,2,2,2,2,2,2,2,2,2,1,1,1,1
1,1,1,1,2,2,2,2,2,2,2,2,2,2,2,2,2,2,2,2,2,2,2,2,2,2,2,2,2,2,2,2,1,1,1,1
1,1,1,1,1,2,2,3,3,3,3,2,2,3,3,3,3,3,3,3,3,3,3,2,2,3,3,3,3,2,2,1,1,1,1,1
1,1,1,1,1,2,2,3,3,3,3,2,2,3,3,3,3,3,3,3,3,3,3,2,2,3,3,3,3,2,2,1,1,1,1,1
1,1,1,1,1,2,2,3,3,3,3,2,2,3,3,3,3,3,3,3,3,3,3,2,2,3,3,3,3,2,2,1,1,1,1,1
1,1,1,1,1,2,2,3,3,3,3,2,2,3,3,3,3,3,3,3,3,3,3,2,2,3,3,3,3,2,2,1,1,1,1,1
1,1,1,1,2,2,2,2,2,2,2,2,2,2,2,2,2,2,2,2,2,2,2,2,2,2,2,2,2,2,2,2,1,1,1,1
1,1,1,1,2,2,2,2,2,2,2,2,2,2,2,2,2,2,2,2,2,2,2,2,2,2,2,2,2,2,2,2,1,1,1,1
1,2,2,2,2,2,2,3,3,3,3,2,2,3,3,3,3,3,3,3,3,3,3,2,2,3,3,3,3,2,2,2,2,2,2,1
1,2,2,2,2,2,2,3,3,3,3,2,2,3,3,3,3,3,3,3,3,3,3,2,2,3,3,3,3,2,2,2,2,2,2,1
1,2,2,2,2,2,2,3,3,3,3,2,2,3,3,3,3,3,3,3,3,3,3,2,2,3,3,3,3,2,2,2,2,2,2,1
1,2,2,2,2,2,2,3,3,3,3,2,2,3,3,3,3,3,3,3,3,3,3,2,2,3,3,3,3,2,2,2,2,2,2,1
1,2,2,2,2,2,2,3,3,3,3,2,2,3,3,3,3,3,3,3,3,3,3,2,2,3,3,3,3,2,2,2,2,2,2,1
1,2,2,2,2,2,2,3,3,3,3,2,2,3,3,3,3,3,3,3,3,3,3,2,2,3,3,3,3,2,2,2,2,2,2,1
1,2,2,2,2,2,2,3,3,3,3,2,2,3,3,3,3,3,3,3,3,3,3,2,2,3,3,3,3,2,2,2,2,2,2,1
1,2,2,2,2,2,2,3,3,3,3,2,2,3,3,3,3,3,3,3,3,3,3,2,2,3,3,3,3,2,2,2,2,2,2,1
1,2,2,2,2,2,2,3,3,3,3,2,2,3,3,3,3,3,3,3,3,3,3,2,2,3,3,3,3,2,2,2,2,2,2,1
1,2,2,2,2,2,2,3,3,3,3,2,2,3,3,3,3,3,3,3,3,3,3,2,2,3,3,3,3,2,2,2,2,2,2,1
1,1,1,1,2,2,2,2,2,2,2,2,2,2,2,2,2,2,2,2,2,2,2,2,2,2,2,2,2,2,2,2,1,1,1,1
1,1,1,1,2,2,2,2,2,2,2,2,2,2,2,2,2,2,2,2,2,2,2,2,2,2,2,2,2,2,2,2,1,1,1,1
1,1,1,1,1,2,2,3,3,3,3,2,2,3,3,3,3,3,3,3,3,3,3,2,2,3,3,3,3,2,2,1,1,1,1,1
1,1,1,1,1,2,2,3,3,3,3,2,2,3,3,3,3,3,3,3,3,3,3,2,2,3,3,3,3,2,2,1,1,1,1,1
1,1,1,1,1,2,2,3,3,3,3,2,2,3,3,3,3,3,3,3,3,3,3,2,2,3,3,3,3,2,2,1,1,1,1,1
1,1,1,1,1,2,2,3,3,3,3,2,2,3,3,3,3,3,3,3,3,3,3,2,2,3,3,3,3,2,2,1,1,1,1,1
1,1,1,1,2,2,2,2,2,2,2,2,2,2,2,2,2,2,2,2,2,2,2,2,2,2,2,2,2,2,2,2,1,1,1,1
1,1,1,1,2,2,2,2,2,2,2,2,2,2,2,2,2,2,2,2,2,2,2,2,2,2,2,2,2,2,2,2,1,1,1,1
1,1,1,1,1,2,2,3,3,3,3,2,2,3,3,3,3,3,3,3,3,3,3,2,2,3,3,3,3,2,2,1,1,1,1,1
1,1,1,1,1,2,2,3,3,3,3,2,2,3,3,3,3,3,3,3,3,3,3,2,2,3,3,3,3,2,2,1,1,1,1,1
1,1,1,1,1,2,2,3,3,3,3,2,2,3,3,3,3,3,3,3,3,3,3,2,2,3,3,3,3,2,2,1,1,1,1,1
1,1,1,1,1,2,2,3,3,3,3,2,2,3,3,3,3,3,3,3,3,3,3,2,2,3,3,3,3,2,2,1,1,1,1,1
1,1,1,1,2,2,2,2,2,2,2,2,2,2,2,2,2,2,2,2,2,2,2,2,2,2,2,2,2,2,2,2,1,1,1,1
1,1,1,1,2,2,2,2,2,2,2,2,2,2,2,2,2,2,2,2,2,2,2,2,2,2,2,2,2,2,2,2,1,1,1,1
1,1,1,1,2,2,2,1,1,1,1,2,2,2,2,2,2,2,2,2,2,2,2,2,2,1,1,1,1,2,2,2,1,1,1,1
1,1,1,1,1,1,1,1,1,1,1,1,1,2,2,2,2,2,2,2,2,2,2,1,1,1,1,1,1,1,1,1,1,1,1,1
1,1,1,1,1,1,1,1,1,1,1,1,1,2,2,2,2,2,2,2,2,2,2,1,1,1,1,1,1,1,1,1,1,1,1,1
1,1,1,1,1,1,1,1,1,1,1,1,1,2,2,2,2,2,2,2,2,2,2,1,1,1,1,1,1,1,1,1,1,1,1,1
1,1,1,1,1,1,1,1,1,1,1,1,1,1,1,1,1,1,1,1,1,1,1,1,1,1,1,1,1,1,1,1,1,1,1,1
:endlayer
layer: 1
0,0,0,0,0,0,0,0,0,0,0,0,0,0,0,0,0,0,0,0,4,0,0,0,0,0,0,0,0,0,0,0,0,0,0,0
0,4,0,0,0,0,0,0,0,0,0,0,4,0,0,0,0,0,0,0,0,0,0,0,0,0,0,0,0,0,0,0,4,0,0,0
0,0,0,0,0,0,0,0,0,0,0,0,0,0,0,8,8,8,8,8,8,0,0,0,0,0,0,0,0,0,0,0,0,0,0,0
0,0,0,0,0,0,4,0,0,0,0,0,0,0,8,8,8,8,8,8,8,8,0,0,0,0,0,0,0,0,0,0,0,0,0,0
0,0,0,0,0,0,0,0,0,0,0,0,0,8,8,3,3,3,3,3,3,8,8,0,0,4,0,0,0,0,0,0,0,0,0,0
0,0,0,0,0,0,0,0,0,0,0,0,0,8,8,3,3,3,3,3,3,8,8,0,0,0,0,0,0,0,0,0,0,0,0,0
0,0,4,0,0,0,0,0,0,0,0,0,0,8,8,3,3,3,3,3,3,8,8,0,0,0,0,0,0,0,4,0,0,0,0,0
0,0,0,0,0,0,0,0,0,0,4,0,8,8,8,3,3,3,3,3,3,8,8,8,0,0,0,0,0,0,0,0,0,0,0,0
0,0,0,0,0,0,0,0,0,0,0,0,8,8,3,3,3,3,3,3,3,3,8,8,0,0,0,0,0,0,0,0,0,0,0,0
0,0,0,0,8,8,0,8,8,8,8,0,8,8,3,3,3,3,3,3,3,3,8,8,0,8,8,8,8,0,8,8,0,0,0,0
0,0,0,0,8,8,8,8,8,8,8,8,8,8,2,2,2,2,2,2,2,2,8,8,8,8,8,8,8,8,8,8,0,0,4,0
0,0,0,0,8,8,8,2,2,2,2,8,8,2,2,2,2,2,2,2,2,2,2,8,8,2,2,2,2,8,8,8,0,0,0,0
0,0,0,0,0,8,8,3,3,3,3,2,2,3,3,3,3,3,3,3,3,3,3,2,2,3,3,3,3,8,8,0,0,0,0,0
0,0,0,0,0,8,8,3,3,3,3,2,2,3,3,3,3,3,3,3,3,3,3,2,2,3,3,3,3,8,8,0,0,0,0,0
0,4,0,0,0,8,8,3,3,3,3,2,2,3,3,3,3,3,3,3,3,3,3,2,2,3,3,3,3,8,8,0,0,0,0,0
0,0,0,0,0,8,8,3,3,3,3,2,2,3,3,3,3,3,3,3,3,3,3,2,2,3,3,3,3,8,8,0,0,0,0,0
0,0,0,0,8,8,8,2,2,2,2,8,8,2,2,2,2,2,2,2,2,2,2,8,8,2,2,2,2,8,8,8,0,4,0,0
0,0,0,0,8,8,8,2,2,2,2,8,8,2,2,2,2,2,2,2,2,2,2,8,8,2,2,2,2,8,8,8,0,0,0,0
0,7,9,9,9,8,8,3,3,3,3,2,2,3,3,3,3,3,3,3,3,3,3,2,2,3,3,3,3,8,8,9,9,9,5,0
0,7,2,2,2,8,8,3,3,3,3,2,2,3,3,3,3,3,3,3,3,3,3,2,2,3,3,3,3,8,8,2,2,2,5,0
0,7,2,2,2,8,8,3,3,3,3,2,2,3,3,3,3,3,3,3,3,3,3,2,2,3,3,3,3,8,8,2,2,2,5,0
0,7,2,2,2,8,8,3,3,3,3,2,2,3,3,3,3,3,3,3,3,3,3,2,2,3,3,3,3,8,8,2,2,2,5,0
4,7,2,2,2,8,8,3,3,3,3,2,2,3,3,3,3,3,3,3,3,3,3,2,2,3,3,3,3,8,8,2,2,2,5,0
0,7,2,2,2,8,8,3,3,3,3,2,2,3,3,3,3,3,3,3,3,3,3,2,2,3,3,3,3,8,8,2,2,2,5,4
0,7,2,2,2,8,8,3,3,3,3,2,2,3,3,3,3,3,3,3,3,3,3,2,2,3,3,3,3,8,8,2,2,2,5,0
0,7,2,2,2,8,8,3,3,3,3,2,2,3,3,3,3,3,3,3,3,3,3,2,2,3,3,3,3,8,8,2,2,2,5,0
0,7,2,2,2,8,8,3,3,3,3,2,2,3,3,3,3,3,3,3,3,3,3,2,2,3,3,3,3,8,8,2,2,2,5,0
0,6,6,6,6,8,8,3,3,3,3,2,2,3,3,3,3,3,3,3,3,3,3,2,2,3,3,3,3,8,8,6,6,6,6,0
0,0,0,0,8,8,8,2,2,2,2,8,8,2,2,2,2,2,2,2,2,2,2,8,8,2,2,2,2,8,8,8,0,0,0,0
0,0,0,0,8,8,8,2,2,2,2,8,8,2,2,2,2,2,2,2,2,2,2,8,8,2,2,2,2,8,8,8,0,0,0,0
0,0,0,0,0,8,8,3,3,3,3,2,2,3,3,3,3,3,3,3,3,3,3,2,2,3,3,3,3,8,8,0,0,0,0,0
0,0,0,0,0,8,8,3,3,3,3,2,2,3,3,3,3,3,3,3,3,3,3,2,2,3,3,3,3,8,8,0,0,0,4,0
0,0,4,0,0,8,8,3,3,3,3,2,2,3,3,3,3,3,3,3,3,3,3,2,2,3,3,3,3,8,8,0,0,0,0,0
0,0,0,0,0,8,8,3,3,3,3,2,2,3,3,3,3,3,3,3,3,3,3,2,2,3,3,3,3,8,8,0,0,0,0,0
0,0,0,0,8,8,8,2,2,2,2,2,2,2,2,2,2,2,2,2,2,2,2,2,2,2,2,2,2,8,8,8,0,0,0,0
0,0,0,0,8,8,8,2,2,2,2,2,2,2,2,2,2,2,2,2,2,2,2,2,2,2,2,2,2,8,8,8,0,0,0,0
0,0,0,0,0,8,8,3,3,3,3,2,2,3,3,3,3,3,3,3,3,3,3,2,2,3,3,3,3,8,8,0,0,0,0,0
0,0,0,0,0,8,8,3,3,3,3,2,2,3,3,3,3,3,3,3,3,3,3,2,2,3,3,3,3,8,8,0,0,0,0,0
0,0,0,0,0,8,8,3,3,3,3,2,2,3,3,3,3,3,3,3,3,3,3,2,2,3,3,3,3,8,8,0,0,4,0,0
0,4,0,0,0,8,8,3,3,3,3,2,2,3,3,3,3,3,3,3,3,3,3,2,2,3,3,3,3,8,8,0,0,0,0,0
0,0,0,0,8,8,8,8,8,8,8,8,8,8,8,8,8,8,8,8,8,8,8,8,8,8,8,8,8,8,8,8,0,0,0,0
0,0,0,0,8,8,8,8,8,8,8,8,8,8,8,8,8,8,8,8,8,8,8,8,8,8,8,8,8,8,8,8,0,0,0,0
0,0,0,0,8,8,8,0,0,0,0,8,8,7,2,2,2,2,2,2,2,2,5,8,8,0,0,0,0,8,8,8,0,0,0,0
0,0,0,0,0,0,0,0,0,0,0,0,0,7,2,2,2,2,2,2,2,2,5,0,0,0,0,0,0,0,0,0,0,0,0,0
0,0,0,0,0,0,0,0,0,0,0,0,0,7,2,2,2,2,2,2,2,2,5,0,0,0,4,0,0,0,0,0,0,0,0,0
0,0,0,4,0,0,0,0,0,4,0,0,0,7,6,6,6,6,6,6,6,6,5,0,0,0,0,0,0,0,0,0,0,4,0,0
0,0,0,0,0,0,0,0,0,0,0,0,0,0,0,0,0,0,4,0,0,0,0,0,0,0,0,0,0,0,0,0,0,0,0,0
:endlayer
layer: 2
0,0,0,0,0,0,0,0,0,0,0,0,0,0,0,0,0,0,0,0,0,0,0,0,0,0,0,0,0,0,0,0,0,0,0,0
0,0,0,0,0,0,0,0,0,0,0,0,0,0,0,0,0,0,0,0,0,0,0,0,0,0,0,0,0,0,0,0,0,0,0,0
0,0,0,0,0,0,0,0,0,0,0,0,0,0,0,8,8,8,8,8,8,0,0,0,0,0,0,0,0,0,0,0,0,0,0,0
0,0,0,0,0,0,0,0,0,0,0,0,0,0,8,8,8,8,8,8,8,8,0,0,0,0,0,0,0,0,0,0,0,0,0,0
0,0,0,0,0,0,0,0,0,0,0,0,0,8,8,8,8,8,8,8,8,8,8,0,0,0,0,0,0,0,0,0,0,0,0,0
0,0,0,0,0,0,0,0,0,0,0,0,0,8,8,8,3,3,3,3,8,8,8,0,0,0,0,0,0,0,0,0,0,0,0,0
0,0,0,0,0,0,0,0,0,0,0,0,0,8,8,8,3,3,3,3,8,8,8,0,0,0,0,0,0,0,0,0,0,0,0,0
0,0,0,0,0,0,0,0,0,0,0,0,8,8,8,8,3,3,3,3,8,8,8,8,0,0,0,0,0,0,0,0,0,0,0,0
0,0,0,0,0,0,0,0,0,0,0,0,8,8,8,3,3,3,3,3,3,8,8,8,0,0,0,0,0,0,0,0,0,0,0,0
0,0,0,0,8,8,0,8,8,8,8,0,8,8,8,3,3,3,3,3,3,8,8,8,0,8,8,8,8,0,8,8,0,0,0,0
0,0,0,0,8,8,8,8,8,8,8,8,8,8,8,3,3,3,3,3,3,8,8,8,8,8,8,8,8,8,8,8,0,0,0,0
0,0,0,0,8,8,8,8,8,8,8,8,8,8,8,8,8,8,8,8,8,8,8,8,8,8,8,8,8,8,8,8,0,0,0,0
0,0,0,0,0,8,8,8,11,11,11,11,11,10,11,11,11,12,12,11,11,11,10,11,11,11,11,11,8,8,8,0,0,0,0,0
0,0,0,0,0,8,8,8,11,11,11,11,11,11,10,11,12,11,11,12,11,10,11,11,11,11,11,11,8,8,8,0,0,0,0,0
0,0,0,0,0,8,8,8,11,11,11,11,11,11,11,10,12,11,11,12,10,11,11,11,11,11,11,11,8,8,8,0,0,0,0,0
0,0,0,0,0,8,8,8,11,11,11,11,11,11,11,10,11,12,12,11,10,11,11,11,11,11,11,11,8,8,8,0,0,0,0,0
0,0,0,0,8,8,8,8,11,11,11,8,8,11,10,11,12,11,11,12,11,10,11,8,8,11,11,11,8,8,8,8,0,0,0,0
0,0,0,0,8,8,8,8,11,11,11,8,8,11,10,11,12,11,11,12,11,10,11,8,8,11,11,11,8,8,8,8,0,0,0,0
0,0,0,0,0,8,8,8,11,11,11,11,11,10,12,12,11,12,12,11,12,12,10,11,11,11,11,11,8,8,8,0,0,0,0,0
0,0,7,9,9,8,8,8,11,11,11,10,10,12,11,11,12,10,10,12,11,11,12,10,10,11,11,11,8,8,8,9,9,5,0,0
0,0,7,2,2,8,8,10,10,10,10,11,11,12,11,11,12,10,10,12,11,11,12,11,11,10,10,10,10,8,8,2,2,5,0,0
0,0,7,2,2,8,8,11,12,12,11,12,12,11,12,12,10,12,12,10,12,12,11,12,12,11,12,12,11,8,8,2,2,5,0,0
0,0,7,2,2,8,8,12,11,11,12,11,11,12,10,10,12,10,10,12,10,10,12,11,11,12,11,11,12,8,8,2,2,5,0,0
0,0,7,2,2,8,8,12,11,11,12,11,11,12,10,10,12,10,10,12,10,10,12,11,11,12,11,11,12,8,8,2,2,5,0,0
0,0,7,2,2,8,8,11,12,12,11,12,12,11,12,12,10,12,12,10,12,12,11,12,12,11,12,12,11,8,8,2,2,5,0,0
0,0,7,2,2,8,8,10,10,10,10,11,11,12,11,11,12,10,10,12,11,11,12,11,11,10,10,10,10,8,8,2,2,5,0,0
0,0,6,6,6,8,8,8,11,11,11,10,10,12,11,11,12,10,10,12,11,11,12,10,10,11,11,11,8,8,8,6,6,6,0,0
0,0,0,0,0,8,8,8,11,11,11,11,11,10,12,12,11,12,12,11,12,12,10,11,11,11,11,11,8,8,8,0,0,0,0,0
0,0,0,0,8,8,8,8,11,11,11,8,8,11,10,11,12,11,11,12,11,10,11,8,8,11,11,11,8,8,8,8,0,0,0,0
0,0,0,0,8,8,8,8,11,11,11,8,8,11,10,11,12,11,11,12,11,10,11,8,8,11,11,11,8,8,8,8,0,0,0,0
0,0,0,0,0,8,8,8,11,11,11,11,11,11,11,10,11,12,12,11,10,11,11,11,11,11,11,11,8,8,8,0,0,0,0,0
0,0,0,0,0,8,8,8,11,11,11,11,11,11,11,10,12,11,11,12,10,11,11,11,11,11,11,11,8,8,8,0,0,0,0,0
0,0,0,0,0,8,8,8,11,11,11,11,11,11,11,10,12,11,11,12,10,11,11,11,11,11,11,11,8,8,8,0,0,0,0,0
0,0,0,0,0,8,8,8,11,11,11,11,11,11,11,10,11,12,12,11,10,11,11,11,11,11,11,11,8,8,8,0,0,0,0,0
0,0,0,0,8,8,8,8,11,11,11,11,11,11,11,10,12,11,11,12,10,11,11,11,11,11,11,11,8,8,8,8,0,0,0,0
0,0,0,0,8,8,8,8,11,11,11,11,11,11,11,10,12,11,11,12,10,11,11,11,11,11,11,11,8,8,8,8,0,0,0,0
0,0,0,0,0,8,8,8,8,8,8,11,11,11,11,10,11,12,12,11,10,11,11,11,11,8,8,8,8,8,8,0,0,0,0,0
0,0,0,0,0,8,8,8,8,8,8,11,11,11,11,10,12,11,11,12,10,11,11,11,11,8,8,8,8,8,8,0,0,0,0,0
0,0,0,0,0,8,8,8,8,8,8,11,11,11,11,10,12,11,11,12,10,11,11,11,11,8,8,8,8,8,8,0,0,0,0,0
0,0,0,0,0,8,8,8,8,8,8,8,8,8,8,10,11,12,12,11,10,8,8,8,8,8,8,8,8,8,8,0,0,0,0,0
0,0,0,0,8,8,8,8,8,8,8,8,8,8,8,8,8,8,8,8,8,8,8,8,8,8,8,8,8,8,8,8,0,0,0,0
0,0,0,0,8,8,8,8,8,8,8,8,8,8,8,8,8,8,8,8,8,8,8,8,8,8,8,8,8,8,8,8,0,0,0,0
0,0,0,0,8,8,8,0,0,0,0,8,8,0,7,2,2,2,2,2,2,5,0,8,8,0,0,0,0,8,8,8,0,0,0,0
0,0,0,0,0,0,0,0,0,0,0,0,0,0,7,2,2,2,2,2,2,5,0,0,0,0,0,0,0,0,0,0,0,0,0,0
0,0,0,0,0,0,0,0,0,0,0,0,0,0,7,6,6,6,6,6,6,5,0,0,0,0,0,0,0,0,0,0,0,0,0,0
0,0,0,0,0,0,0,0,0,0,0,0,0,0,0,0,0,0,0,0,0,0,0,0,0,0,0,0,0,0,0,0,0,0,0,0
0,0,0,0,0,0,0,0,0,0,0,0,0,0,0,0,0,0,0,0,0,0,0,0,0,0,0,0,0,0,0,0,0,0,0,0
:endlayer
layer: 3
0,0,0,0,0,0,0,0,0,0,0,0,0,0,0,0,0,0,0,0,0,0,0,0,0,0,0,0,0,0,0,0,0,0,0,0
0,0,0,0,0,0,0,0,0,0,0,0,0,0,0,0,0,0,0,0,0,0,0,0,0,0,0,0,0,0,0,0,0,0,0,0
0,0,0,0,0,0,0,0,0,0,0,0,0,0,0,8,8,8,8,8,8,0,0,0,0,0,0,0,0,0,0,0,0,0,0,0
0,0,0,0,0,0,0,0,0,0,0,0,0,0,8,8,8,8,8,8,8,8,0,0,0,0,0,0,0,0,0,0,0,0,0,0
0,0,0,0,0,0,0,0,0,0,0,0,0,8,8,13,20,20,20,20,13,8,8,0,0,0,0,0,0,0,0,0,0,0,0,0
0,0,0,0,0,0,0,0,0,0,0,0,0,8,8,18,19,19,19,19,18,8,8,0,0,0,0,0,0,0,0,0,0,0,0,0
0,0,0,0,0,0,0,0,0,0,0,0,0,8,8,18,19,13,13,19,18,8,8,0,0,0,0,0,0,0,0,0,0,0,0,0
0,0,0,0,0,0,0,0,0,0,0,0,8,8,8,18,13,20,20,13,18,8,8,8,0,0,0,0,0,0,0,0,0,0,0,0
0,0,0,0,0,0,0,0,0,0,0,0,8,8,13,19,18,19,19,18,19,13,8,8,0,0,0,0,0,0,0,0,0,0,0,0
0,0,0,0,8,8,0,8,8,8,8,0,8,8,18,19,13,20,20,13,19,18,8,8,0,8,8,8,8,0,8,8,0,0,0,0
0,0,0,0,8,8,8,8,8,8,8,8,8,8,18,19,19,13,13,19,19,18,8,8,8,8,8,8,8,8,8,8,0,0,0,0
0,0,0,0,8,8,8,0,0,0,0,8,8,13,17,17,17,17,17,17,17,17,13,8,8,0,0,0,0,8,8,8,0,0,0,0
0,0,0,0,0,8,8,13,0,0,0,0,0,0,0,0,0,0,0,0,0,0,0,0,0,0,0,0,13,8,8,0,0,0,0,0
0,0,0,0,0,8,8,0,0,0,0,0,0,0,0,0,0,0,0,0,0,0,0,0,0,0,0,0,0,8,8,0,0,0,0,0
0,0,0,0,0,8,8,0,0,0,0,0,0,0,0,0,0,0,0,0,0,0,0,0,0,0,0,0,0,8,8,0,0,0,0,0
0,0,0,0,0,8,8,13,0,0,0,0,0,0,0,0,4,0,0,4,0,0,0,0,0,0,0,0,13,8,8,0,0,0,0,0
0,0,0,0,8,8,8,0,0,0,0,8,8,0,0,0,0,0,0,0,0,0,0,8,8,0,0,0,0,8,8,8,0,0,0,0
0,0,0,0,8,8,8,0,0,0,0,8,8,0,0,0,0,0,0,0,0,0,0,8,8,0,0,0,0,8,8,8,0,0,0,0
0,0,0,0,0,8,8,13,0,0,0,0,0,0,0,0,0,0,0,0,0,0,0,0,0,0,0,0,13,8,8,0,0,0,0,0
0,0,0,0,0,8,8,16,0,0,0,0,0,0,0,0,0,0,0,0,0,0,0,0,0,0,0,0,15,8,8,0,0,0,0,0
0,0,0,4,0,0,8,0,0,0,0,0,0,0,0,0,0,0,0,0,0,0,0,0,0,0,0,0,0,8,0,0,4,0,0,0
0,0,0,0,0,0,0,0,0,0,4,0,0,0,0,0,4,0,0,4,0,0,0,0,0,4,0,0,0,0,0,0,0,0,0,0
0,0,0,0,0,0,0,0,0,0,0,0,0,0,0,0,0,0,0,0,0,0,0,0,0,0,0,0,0,0,0,0,0,0,0,0
0,0,0,0,0,0,0,0,0,0,0,0,0,0,0,0,0,0,0,0,0,0,0,0,0,0,0,0,0,0,0,0,0,0,0,0
0,0,0,0,0,0,0,0,0,0,4,0,0,0,0,0,4,0,0,4,0,0,0,0,0,4,0,0,0,0,0,0,0,0,0,0
0,0,0,4,0,0,8,0,0,0,0,0,0,0,0,0,0,0,0,0,0,0,0,0,0,0,0,0,0,8,0,0,4,0,0,0
0,0,0,0,0,8,8,16,0,0,0,0,0,0,0,0,0,0,0,0,0,0,0,0,0,0,0,0,15,8,8,0,0,0,0,0
0,0,0,0,0,8,8,13,0,0,0,0,0,0,0,0,0,0,0,0,0,0,0,0,0,0,0,0,13,8,8,0,0,0,0,0
0,0,0,0,8,8,8,0,0,0,0,8,8,0,0,0,0,0,0,0,0,0,0,8,8,0,0,0,0,8,8,8,0,0,0,0
0,0,0,0,8,8,8,0,0,0,0,8,8,0,0,0,0,0,0,0,0,0,0,8,8,0,0,0,0,8,8,8,0,0,0,0
0,0,0,0,0,8,8,13,0,0,0,0,0,0,0,0,4,0,0,4,0,0,0,0,0,0,0,0,13,8,8,0,0,0,0,0
0,0,0,0,0,8,8,0,0,0,0,0,0,0,0,0,0,0,0,0,0,0,0,0,0,0,0,0,0,8,8,0,0,0,0,0
0,0,0,0,0,8,8,0,0,0,0,0,0,0,0,0,0,0,0,0,0,0,0,0,0,0,0,0,0,8,8,0,0,0,0,0
0,0,0,0,0,8,8,13,0,0,0,0,0,0,0,0,0,0,0,0,0,0,0,0,0,0,0,0,13,8,8,0,0,0,0,0
0,0,0,0,8,8,8,0,0,0,0,0,0,0,0,0,0,0,0,0,0,0,0,0,0,0,0,0,0,8,8,8,0,0,0,0
0,0,0,0,8,8,8,0,0,0,0,0,0,0,0,0,0,0,0,0,0,0,0,0,0,0,0,0,0,8,8,8,0,0,0,0
0,0,0,0,0,8,8,13,0,0,13,0,0,0,0,0,4,0,0,4,0,0,0,0,0,13,0,0,13,8,8,0,0,0,0,0
0,0,0,0,0,8,8,0,0,0,0,0,0,0,0,0,0,0,0,0,0,0,0,0,0,0,0,0,0,8,8,0,0,0,0,0
0,0,0,0,0,8,8,0,0,5,0,0,0,0,0,0,0,0,0,0,0,0,0,0,0,0,7,0,0,8,8,0,0,0,0,0
0,0,0,0,0,8,8,13,0,0,13,0,0,13,14,0,0,0,0,0,0,14,13,0,0,13,0,0,13,8,8,0,0,0,0,0
0,0,0,0,8,8,8,8,8,8,8,8,8,8,8,8,0,0,0,0,8,8,8,8,8,8,8,8,8,8,8,8,0,0,0,0
0,0,0,0,8,8,8,8,8,8,8,8,8,8,8,0,0,0,0,0,0,8,8,8,8,8,8,8,8,8,8,8,0,0,0,0
0,0,0,0,8,8,8,0,0,0,0,8,8,0,0,0,0,0,0,0,0,0,0,8,8,0,0,0,0,8,8,8,0,0,0,0
0,0,0,0,0,0,0,0,0,0,0,0,0,0,0,4,0,0,0,0,4,0,0,0,0,0,0,0,0,0,0,0,0,0,0,0
0,0,0,0,0,0,0,0,0,0,0,0,0,0,0,0,0,0,0,0,0,0,0,0,0,0,0,0,0,0,0,0,0,0,0,0
0,0,0,0,0,0,0,0,0,0,0,0,0,0,0,0,0,0,0,0,0,0,0,0,0,0,0,0,0,0,0,0,0,0,0,0
0,0,0,0,0,0,0,0,0,0,0,0,0,0,0,0,0,0,0,0,0,0,0,0,0,0,0,0,0,0,0,0,0,0,0,0
:endlayer
layer: 4
0,0,0,0,0,0,0,0,0,0,0,0,0,0,0,0,0,0,0,0,0,0,0,0,0,0,0,0,0,0,0,0,0,0,0,0
0,0,0,0,0,0,0,0,0,0,0,0,0,0,0,0,0,0,0,0,0,0,0,0,0,0,0,0,0,0,0,0,0,0,0,0
0,0,0,0,0,0,0,0,0,0,0,0,0,0,0,8,8,8,8,8,8,0,0,0,0,0,0,0,0,0,0,0,0,0,0,0
0,0,0,0,0,0,0,0,0,0,0,0,0,0,8,8,8,8,8,8,8,8,0,0,0,0,0,0,0,0,0,0,0,0,0,0
0,0,0,0,0,0,0,0,0,0,0,0,0,8,8,13,0,0,0,0,13,8,8,0,0,0,0,0,0,0,0,0,0,0,0,0
0,0,0,0,0,0,0,0,0,0,0,0,0,8,8,0,0,0,0,0,0,8,8,0,0,0,0,0,0,0,0,0,0,0,0,0
0,0,0,0,0,0,0,0,0,0,0,0,0,8,8,0,0,0,0,0,0,8,8,0,0,0,0,0,0,0,0,0,0,0,0,0
0,0,0,0,0,0,0,0,0,0,0,0,8,8,8,0,0,0,0,0,0,8,8,8,0,0,0,0,0,0,0,0,0,0,0,0
0,0,0,0,0,0,0,0,0,0,0,0,8,8,13,0,0,0,0,0,0,13,8,8,0,0,0,0,0,0,0,0,0,0,0,0
0,0,0,0,8,8,0,8,8,8,8,0,8,8,0,0,0,0,0,0,0,0,8,8,0,8,8,8,8,0,8,8,0,0,0,0
0,0,0,0,8,8,8,8,8,8,8,8,8,8,0,0,0,0,0,0,0,0,8,8,8,8,8,8,8,8,8,8,0,0,0,0
0,0,0,0,8,8,8,0,0,0,0,8,8,13,0,0,0,0,0,0,0,0,13,8,8,0,0,0,0,8,8,8,0,0,0,0
0,0,0,0,0,8,8,13,0,0,0,0,0,0,0,0,0,0,0,0,0,0,0,0,0,0,0,0,13,8,8,0,0,0,0,0
0,0,0,0,0,8,8,0,0,0,0,0,0,0,0,0,0,0,0,0,0,0,0,0,0,0,0,0,0,8,8,0,0,0,0,0
0,0,0,0,0,8,8,0,0,0,0,0,0,0,0,0,0,0,0,0,0,0,0,0,0,0,0,0,0,8,8,0,0,0,0,0
0,0,0,0,0,8,8,13,0,0,0,0,0,0,0,0,0,0,0,0,0,0,0,0,0,0,0,0,13,8,8,0,0,0,0,0
0,0,0,0,8,8,8,0,0,0,0,8,8,0,0,0,0,0,0,0,0,0,0,8,8,0,0,0,0,8,8,8,0,0,0,0
0,0,0,0,8,8,8,0,0,0,0,8,8,0,0,0,0,0,0,0,0,0,0,8,8,0,0,0,0,8,8,8,0,0,0,0
0,0,0,0,0,8,8,13,0,0,0,0,0,0,0,0,0,0,0,0,0,0,0,0,0,0,0,0,13,8,8,0,0,0,0,0
0,0,0,0,0,8,8,21,0,0,0,0,0,0,0,0,0,0,0,0,0,0,0,0,0,0,0,0,21,8,8,0,0,0,0,0
0,0,0,0,0,0,8,0,0,0,0,0,0,0,0,0,0,0,0,0,0,0,0,0,0,0,0,0,0,8,0,0,0,0,0,0
0,0,0,0,0,0,0,0,0,0,0,0,0,0,0,0,0,0,0,0,0,0,0,0,0,0,0,0,0,0,0,0,0,0,0,0
0,0,0,0,0,0,0,0,0,0,0,0,0,0,0,0,0,0,0,0,0,0,0,0,0,0,0,0,0,0,0,0,0,0,0,0
0,0,0,0,0,0,0,0,0,0,0,0,0,0,0,0,0,0,0,0,0,0,0,0,0,0,0,0,0,0,0,0,0,0,0,0
0,0,0,0,0,0,0,0,0,0,0,0,0,0,0,0,0,0,0,0,0,0,0,0,0,0,0,0,0,0,0,0,0,0,0,0
0,0,0,0,0,0,8,0,0,0,0,0,0,0,0,0,0,0,0,0,0,0,0,0,0,0,0,0,0,8,0,0,0,0,0,0
0,0,0,0,0,8,8,21,0,0,0,0,0,0,0,0,0,0,0,0,0,0,0,0,0,0,0,0,21,8,8,0,0,0,0,0
0,0,0,0,0,8,8,13,0,0,0,0,0,0,0,0,0,0,0,0,0,0,0,0,0,0,0,0,13,8,8,0,0,0,0,0
0,0,0,0,8,8,8,0,0,0,0,8,8,0,0,0,0,0,0,0,0,0,0,8,8,0,0,0,0,8,8,8,0,0,0,0
0,0,0,0,8,8,8,0,0,0,0,8,8,0,0,0,0,0,0,0,0,0,0,8,8,0,0,0,0,8,8,8,0,0,0,0
0,0,0,0,0,8,8,13,0,0,0,0,0,0,0,0,0,0,0,0,0,0,0,0,0,0,0,0,13,8,8,0,0,0,0,0
0,0,0,0,0,8,8,0,0,0,0,0,0,0,0,0,0,0,0,0,0,0,0,0,0,0,0,0,0,8,8,0,0,0,0,0
0,0,0,0,0,8,8,0,0,0,0,0,0,0,0,0,0,0,0,0,0,0,0,0,0,0,0,0,0,8,8,0,0,0,0,0
0,0,0,0,0,8,8,13,0,0,0,0,0,0,0,0,0,0,0,0,0,0,0,0,0,0,0,0,13,8,8,0,0,0,0,0
0,0,0,0,8,8,8,0,0,0,0,0,0,0,0,0,0,0,0,0,0,0,0,0,0,0,0,0,0,8,8,8,0,0,0,0
0,0,0,0,8,8,8,0,0,0,0,0,0,0,0,0,0,0,0,0,0,0,0,0,0,0,0,0,0,8,8,8,0,0,0,0
0,0,0,0,0,8,8,13,0,0,13,0,0,0,0,0,0,0,0,0,0,0,0,0,0,13,0,0,13,8,8,0,0,0,0,0
0,0,0,0,0,8,8,0,0,0,0,0,0,0,0,0,0,0,0,0,0,0,0,0,0,0,0,0,0,8,8,0,0,0,0,0
0,0,0,0,0,8,8,0,5,0,0,0,0,0,0,0,0,0,0,0,0,0,0,0,0,0,0,7,0,8,8,0,0,0,0,0
0,0,0,0,0,8,8,13,0,0,13,0,0,13,21,0,0,0,0,0,0,21,13,0,0,13,0,0,13,8,8,0,0,0,0,0
0,0,0,0,8,8,8,8,8,8,8,8,8,8,8,8,0,0,0,0,8,8,8,8,8,8,8,8,8,8,8,8,0,0,0,0
0,0,0,0,8,8,8,8,8,8,8,8,8,8,8,0,0,0,0,0,0,8,8,8,8,8,8,8,8,8,8,8,0,0,0,0
0,0,0,0,8,8,8,0,0,0,0,8,8,0,0,0,0,0,0,0,0,0,0,8,8,0,0,0,0,8,8,8,0,0,0,0
0,0,0,0,0,0,0,0,0,0,0,0,0,0,0,0,0,0,0,0,0,0,0,0,0,0,0,0,0,0,0,0,0,0,0,0
0,0,0,0,0,0,0,0,0,0,0,0,0,0,0,0,0,0,0,0,0,0,0,0,0,0,0,0,0,0,0,0,0,0,0,0
0,0,0,0,0,0,0,0,0,0,0,0,0,0,0,0,0,0,0,0,0,0,0,0,0,0,0,0,0,0,0,0,0,0,0,0
0,0,0,0,0,0,0,0,0,0,0,0,0,0,0,0,0,0,0,0,0,0,0,0,0,0,0,0,0,0,0,0,0,0,0,0
:endlayer
layer: 5
0,0,0,0,0,0,0,0,0,0,0,0,0,0,0,0,0,0,0,0,0,0,0,0,0,0,0,0,0,0,0,0,0,0,0,0
0,0,0,0,0,0,0,0,0,0,0,0,0,0,0,0,0,0,0,0,0,0,0,0,0,0,0,0,0,0,0,0,0,0,0,0
0,0,0,0,0,0,0,0,0,0,0,0,0,0,0,8,8,8,8,8,8,0,0,0,0,0,0,0,0,0,0,0,0,0,0,0
0,0,0,0,0,0,0,0,0,0,0,0,0,0,8,8,8,8,8,8,8,8,0,0,0,0,0,0,0,0,0,0,0,0,0,0
0,0,0,0,0,0,0,0,0,0,0,0,0,8,8,13,0,0,0,0,13,8,8,0,0,0,0,0,0,0,0,0,0,0,0,0
0,0,0,0,0,0,0,0,0,0,0,0,0,8,8,0,0,0,0,0,0,8,8,0,0,0,0,0,0,0,0,0,0,0,0,0
0,0,0,0,0,0,0,0,0,0,0,0,0,8,8,0,0,0,0,0,0,8,8,0,0,0,0,0,0,0,0,0,0,0,0,0
0,0,0,0,0,0,0,0,0,0,0,0,8,8,8,0,0,0,0,0,0,8,8,8,0,0,0,0,0,0,0,0,0,0,0,0
0,0,0,0,0,0,0,0,0,0,0,0,8,8,13,0,0,0,0,0,0,13,8,8,0,0,0,0,0,0,0,0,0,0,0,0
0,0,0,0,8,8,0,8,8,8,8,0,8,8,0,0,0,0,0,0,0,0,8,8,0,8,8,8,8,0,8,8,0,0,0,0
0,0,0,0,8,8,8,8,8,8,8,8,8,8,0,0,0,0,0,0,0,0,8,8,8,8,8,8,8,8,8,8,0,0,0,0
0,0,0,0,8,8,8,0,0,0,0,8,8,13,0,0,0,0,0,0,0,0,13,8,8,0,0,0,0,8,8,8,0,0,0,0
0,0,0,0,0,8,8,13,23,0,0,0,0,25,0,0,0,0,0,0,0,0,25,0,0,0,0,22,13,8,8,0,0,0,0,0
0,0,0,0,0,8,8,0,0,0,0,0,0,0,0,0,0,0,0,0,0,0,0,0,0,0,0,0,0,8,8,0,0,0,0,0
0,0,0,0,0,8,8,0,0,0,0,0,0,0,0,0,0,0,0,0,0,0,0,0,0,0,0,0,0,8,8,0,0,0,0,0
0,0,0,0,0,8,8,13,23,0,0,0,0,0,0,0,0,0,0,0,0,0,0,0,0,0,0,22,13,8,8,0,0,0,0,0
0,0,0,0,8,8,8,0,0,0,0,8,8,0,0,0,0,0,0,0,0,0,0,8,8,0,0,0,0,8,8,8,0,0,0,0
0,0,0,0,8,8,8,0,0,0,0,8,8,23,0,0,0,0,0,0,0,0,22,8,8,0,0,0,0,8,8,8,0,0,0,0
0,0,0,0,0,8,8,13,23,0,0,0,25,0,0,0,0,0,0,0,0,0,0,25,0,0,0,22,13,8,8,0,0,0,0,0
0,0,0,0,0,8,8,21,0,0,0,0,0,0,0,0,0,0,0,0,0,0,0,0,0,0,0,0,21,8,8,0,0,0,0,0
0,0,0,0,0,0,8,0,0,0,0,0,0,0,0,0,0,0,0,0,0,0,0,0,0,0,0,0,0,8,0,0,0,0,0,0
0,0,0,0,0,0,0,0,0,0,0,0,0,0,0,0,0,0,0,0,0,0,0,0,0,0,0,0,0,0,0,0,0,0,0,0
0,0,0,0,0,0,0,0,0,0,0,0,0,0,0,0,0,0,0,0,0,0,0,0,0,0,0,0,0,0,0,0,0,0,0,0
0,0,0,0,0,0,0,0,0,0,0,0,0,0,0,0,0,0,0,0,0,0,0,0,0,0,0,0,0,0,0,0,0,0,0,0
0,0,0,0,0,0,0,0,0,0,0,0,0,0,0,0,0,0,0,0,0,0,0,0,0,0,0,0,0,0,0,0,0,0,0,0
0,0,0,0,0,0,8,0,0,0,0,0,0,0,0,0,0,0,0,0,0,0,0,0,0,0,0,0,0,8,0,0,0,0,0,0
0,0,0,0,0,8,8,21,0,0,0,0,0,0,0,0,0,0,0,0,0,0,0,0,0,0,0,0,21,8,8,0,0,0,0,0
0,0,0,0,0,8,8,13,23,0,0,0,24,0,0,0,0,0,0,0,0,0,0,24,0,0,0,22,13,8,8,0,0,0,0,0
0,0,0,0,8,8,8,0,0,0,0,8,8,23,0,0,0,0,0,0,0,0,22,8,8,0,0,0,0,8,8,8,0,0,0,0
0,0,0,0,8,8,8,0,0,0,0,8,8,0,0,0,0,0,0,0,0,0,0,8,8,0,0,0,0,8,8,8,0,0,0,0
0,0,0,0,0,8,8,13,23,0,0,0,0,0,0,0,0,0,0,0,0,0,0,0,0,0,0,22,13,8,8,0,0,0,0,0
0,0,0,0,0,8,8,0,0,0,0,0,0,0,0,0,0,0,0,0,0,0,0,0,0,0,0,0,0,8,8,0,0,0,0,0
0,0,0,0,0,8,8,0,0,0,0,0,0,0,0,0,0,0,0,0,0,0,0,0,0,0,0,0,0,8,8,0,0,0,0,0
0,0,0,0,0,8,8,13,23,0,0,0,0,0,0,0,0,0,0,0,0,0,0,0,0,0,0,22,13,8,8,0,0,0,0,0
0,0,0,0,8,8,8,0,0,0,0,0,0,0,0,0,0,0,0,0,0,0,0,0,0,0,0,0,0,8,8,8,0,0,0,0
0,0,0,0,8,8,8,0,0,0,24,0,0,0,0,0,0,0,0,0,0,0,0,0,0,24,0,0,0,8,8,8,0,0,0,0
0,0,0,0,0,8,8,13,0,0,13,23,0,0,0,0,0,0,0,0,0,0,0,0,22,13,0,0,13,8,8,0,0,0,0,0
0,0,0,0,0,8,8,0,6,0,0,0,0,0,0,0,0,0,0,0,0,0,0,0,0,0,0,6,0,8,8,0,0,0,0,0
0,0,0,0,0,8,8,24,0,0,0,0,0,24,0,0,0,0,0,0,0,0,24,0,0,0,0,0,24,8,8,0,0,0,0,0
0,0,0,0,0,8,8,13,23,0,13,0,0,13,21,0,0,0,0,0,0,21,13,0,0,13,0,22,13,8,8,0,0,0,0,0
0,0,0,0,8,8,8,8,8,8,8,8,8,8,8,8,0,0,0,0,8,8,8,8,8,8,8,8,8,8,8,8,0,0,0,0
0,0,0,0,8,8,8,8,8,8,8,8,8,8,8,0,0,0,0,0,0,8,8,8,8,8,8,8,8,8,8,8,0,0,0,0
0,0,0,0,8,8,8,0,0,0,0,8,8,0,0,0,0,0,0,0,0,0,0,8,8,0,0,0,0,8,8,8,0,0,0,0
0,0,0,0,0,0,0,0,0,0,0,0,0,0,0,0,0,0,0,0,0,0,0,0,0,0,0,0,0,0,0,0,0,0,0,0
0,0,0,0,0,0,0,0,0,0,0,0,0,0,0,0,0,0,0,0,0,0,0,0,0,0,0,0,0,0,0,0,0,0,0,0
0,0,0,0,0,0,0,0,0,0,0,0,0,0,0,0,0,0,0,0,0,0,0,0,0,0,0,0,0,0,0,0,0,0,0,0
0,0,0,0,0,0,0,0,0,0,0,0,0,0,0,0,0,0,0,0,0,0,0,0,0,0,0,0,0,0,0,0,0,0,0,0
:endlayer
layer: 6
0,0,0,0,0,0,0,0,0,0,0,0,0,0,0,0,0,0,0,0,0,0,0,0,0,0,0,0,0,0,0,0,0,0,0,0
0,0,0,0,0,0,0,0,0,0,0,0,0,0,0,0,0,0,0,0,0,0,0,0,0,0,0,0,0,0,0,0,0,0,0,0
0,0,0,0,0,0,0,0,0,0,0,0,0,0,0,8,8,8,8,8,8,0,0,0,0,0,0,0,0,0,0,0,0,0,0,0
0,0,0,0,0,0,0,0,0,0,0,0,0,0,8,8,8,8,8,8,8,8,0,0,0,0,0,0,0,0,0,0,0,0,0,0
0,0,0,0,0,0,0,0,0,0,0,0,0,8,8,13,0,0,0,0,13,8,8,0,0,0,0,0,0,0,0,0,0,0,0,0
0,0,0,0,0,0,0,0,0,0,0,0,0,8,8,25,0,0,0,0,25,8,8,0,0,0,0,0,0,0,0,0,0,0,0,0
0,0,0,0,0,0,0,0,0,0,0,0,0,8,8,0,0,0,0,0,0,8,8,0,0,0,0,0,0,0,0,0,0,0,0,0
0,0,0,0,0,0,0,0,0,0,0,0,8,8,8,0,0,0,0,0,0,8,8,8,0,0,0,0,0,0,0,0,0,0,0,0
0,0,0,0,0,0,0,0,0,0,0,0,8,8,13,0,0,0,0,0,0,13,8,8,0,0,0,0,0,0,0,0,0,0,0,0
0,0,0,0,8,8,0,8,8,8,8,0,8,8,25,0,0,0,0,0,0,25,8,8,0,8,8,8,8,0,8,8,0,0,0,0
0,0,0,0,8,8,8,8,8,8,8,8,8,8,0,0,0,0,0,0,0,0,8,8,8,8,8,8,8,8,8,8,0,0,0,0
0,0,0,0,8,8,8,0,0,0,0,8,8,13,0,0,0,0,0,0,0,0,13,8,8,0,0,0,0,8,8,8,0,0,0,0
0,0,0,0,0,8,8,13,0,0,0,0,0,0,0,0,0,0,0,0,0,0,0,0,0,0,0,0,13,8,8,0,0,0,0,0
0,0,0,0,0,8,8,0,0,0,0,0,0,0,0,0,0,0,0,0,0,0,0,0,0,0,0,0,0,8,8,0,0,0,0,0
0,0,0,0,0,8,8,0,0,0,0,0,0,0,0,0,0,0,0,0,0,0,0,0,0,0,0,0,0,8,8,0,0,0,0,0
0,0,0,0,0,8,8,13,0,0,0,0,0,0,0,0,0,0,0,0,0,0,0,0,0,0,0,0,13,8,8,0,0,0,0,0
0,0,0,0,8,8,8,0,0,0,0,8,8,0,0,0,0,0,0,0,0,0,0,8,8,0,0,0,0,8,8,8,0,0,0,0
0,0,0,0,8,8,8,0,0,0,0,8,8,0,0,0,0,0,0,0,0,0,0,8,8,0,0,0,0,8,8,8,0,0,0,0
0,0,0,0,0,8,8,13,0,0,0,0,0,0,0,0,0,0,0,0,0,0,0,0,0,0,0,0,13,8,8,0,0,0,0,0
0,0,0,0,0,8,8,21,0,0,0,0,0,0,0,0,0,0,0,0,0,0,0,0,0,0,0,0,21,8,8,0,0,0,0,0
0,0,0,0,0,0,8,0,0,0,0,0,0,0,0,0,0,0,0,0,0,0,0,0,0,0,0,0,0,8,0,0,0,0,0,0
0,0,0,0,0,0,0,0,0,0,0,0,0,0,0,0,0,0,0,0,0,0,0,0,0,0,0,0,0,0,0,0,0,0,0,0
0,0,0,0,0,0,0,0,0,0,0,0,0,0,0,0,0,0,0,0,0,0,0,0,0,0,0,0,0,0,0,0,0,0,0,0
0,0,0,0,0,0,0,0,0,0,0,0,0,0,0,0,0,0,0,0,0,0,0,0,0,0,0,0,0,0,0,0,0,0,0,0
0,0,0,0,0,0,0,0,0,0,0,0,0,0,0,0,0,0,0,0,0,0,0,0,0,0,0,0,0,0,0,0,0,0,0,0
0,0,0,0,0,0,8,0,0,0,0,0,0,0,0,0,0,0,0,0,0,0,0,0,0,0,0,0,0,8,0,0,0,0,0,0
0,0,0,0,0,8,8,21,0,0,0,0,0,0,0,0,0,0,0,0,0,0,0,0,0,0,0,0,21,8,8,0,0,0,0,0
0,0,0,0,0,8,8,13,0,0,0,0,0,0,0,0,0,0,0,0,0,0,0,0,0,0,0,0,13,8,8,0,0,0,0,0
0,0,0,0,8,8,8,0,0,0,0,8,8,0,0,0,0,0,0,0,0,0,0,8,8,0,0,0,0,8,8,8,0,0,0,0
0,0,0,0,8,8,8,0,0,0,0,8,8,0,0,0,0,0,0,0,0,0,0,8,8,0,0,0,0,8,8,8,0,0,0,0
0,0,0,0,0,8,8,13,0,0,0,0,0,0,0,0,0,0,0,0,0,0,0,0,0,0,0,0,13,8,8,0,0,0,0,0
0,0,0,0,0,8,8,0,0,0,0,0,0,0,0,0,0,0,0,0,0,0,0,0,0,0,0,0,0,8,8,0,0,0,0,0
0,0,0,0,0,8,8,0,0,0,0,0,0,0,0,0,0,0,0,0,0,0,0,0,0,0,0,0,0,8,8,0,0,0,0,0
0,0,0,0,0,8,8,13,0,0,0,0,0,0,0,0,0,0,0,0,0,0,0,0,0,0,0,0,13,8,8,0,0,0,0,0
0,0,0,0,8,8,8,0,0,0,0,0,0,0,0,0,0,0,0,0,0,0,0,0,0,0,0,0,0,8,8,8,0,0,0,0
0,0,0,0,8,8,8,0,0,0,0,0,0,0,0,0,0,0,0,0,0,0,0,0,0,0,0,0,0,8,8,8,0,0,0,0
0,0,0,0,0,8,8,13,0,0,13,0,0,0,0,0,0,0,0,0,0,0,0,0,0,13,0,0,13,8,8,0,0,0,0,0
0,0,0,0,0,8,8,0,0,7,0,0,0,0,0,0,0,0,0,0,0,0,0,0,0,0,5,0,0,8,8,0,0,0,0,0
0,0,0,0,0,8,8,0,0,0,0,0,0,0,0,0,0,0,0,0,0,0,0,0,0,0,0,0,0,8,8,0,0,0,0,0
0,0,0,0,0,8,8,13,0,0,13,0,0,13,21,0,0,0,0,0,0,21,13,0,0,13,0,0,13,8,8,0,0,0,0,0
0,0,0,0,8,8,8,8,8,8,8,8,8,8,8,8,0,0,0,0,8,8,8,8,8,8,8,8,8,8,8,8,0,0,0,0
0,0,0,0,8,8,8,8,8,8,8,8,8,8,8,0,0,0,0,0,0,8,8,8,8,8,8,8,8,8,8,8,0,0,0,0
0,0,0,0,8,8,8,0,0,0,0,8,8,0,0,0,0,0,0,0,0,0,0,8,8,0,0,0,0,8,8,8,0,0,0,0
0,0,0,0,0,0,0,0,0,0,0,0,0,0,0,0,0,0,0,0,0,0,0,0,0,0,0,0,0,0,0,0,0,0,0,0
0,0,0,0,0,0,0,0,0,0,0,0,0,0,0,0,0,0,0,0,0,0,0,0,0,0,0,0,0,0,0,0,0,0,0,0
0,0,0,0,0,0,0,0,0,0,0,0,0,0,0,0,0,0,0,0,0,0,0,0,0,0,0,0,0,0,0,0,0,0,0,0
0,0,0,0,0,0,0,0,0,0,0,0,0,0,0,0,0,0,0,0,0,0,0,0,0,0,0,0,0,0,0,0,0,0,0,0
:endlayer
layer: 7
0,0,0,0,0,0,0,0,0,0,0,0,0,0,0,0,0,0,0,0,0,0,0,0,0,0,0,0,0,0,0,0,0,0,0,0
0,0,0,0,0,0,0,0,0,0,0,0,0,0,0,0,0,0,0,0,0,0,0,0,0,0,0,0,0,0,0,0,0,0,0,0
0,0,0,0,0,0,0,0,0,0,0,0,0,0,0,8,8,8,8,8,8,0,0,0,0,0,0,0,0,0,0,0,0,0,0,0
0,0,0,0,0,0,0,0,0,0,0,0,0,0,8,8,8,8,8,8,8,8,0,0,0,0,0,0,0,0,0,0,0,0,0,0
0,0,0,0,0,0,0,0,0,0,0,0,0,8,8,13,29,34,34,28,13,8,8,0,0,0,0,0,0,0,0,0,0,0,0,0
0,0,0,0,0,0,0,0,0,0,0,0,0,8,8,34,0,0,0,0,34,8,8,0,0,0,0,0,0,0,0,0,0,0,0,0
0,0,0,0,0,0,0,0,0,0,0,0,0,8,8,34,0,0,0,0,34,8,8,0,0,0,0,0,0,0,0,0,0,0,0,0
0,0,0,0,0,0,0,0,0,0,0,0,8,8,8,29,0,0,0,0,28,8,8,8,0,0,0,0,0,0,0,0,0,0,0,0
0,0,0,0,0,0,0,0,0,0,0,0,8,8,13,0,0,0,0,0,0,13,8,8,0,0,0,0,0,0,0,0,0,0,0,0
0,0,0,0,8,8,0,8,8,8,8,0,8,8,31,0,0,0,0,0,0,31,8,8,0,8,8,8,8,0,8,8,0,0,0,0
0,0,0,0,8,8,8,8,8,8,8,8,8,8,34,0,0,0,0,0,0,34,8,8,8,8,8,8,8,8,8,8,0,0,0,0
0,0,0,0,8,8,8,29,0,0,0,8,8,13,0,0,0,0,0,0,0,0,13,8,8,0,0,0,28,8,8,8,0,0,0,0
0,0,0,0,0,8,8,13,0,0,0,0,0,0,0,0,0,0,0,0,0,0,0,0,0,0,0,0,13,8,8,0,0,0,0,0
0,0,0,0,0,8,8,31,0,0,0,0,0,0,0,0,0,0,0,0,0,0,0,0,0,0,0,0,31,8,8,0,0,0,0,0
0,0,0,0,0,8,8,30,0,0,0,0,0,0,0,0,0,0,0,0,0,0,0,0,0,0,0,0,30,8,8,0,0,0,0,0
0,0,0,0,0,8,8,13,0,0,0,0,0,0,0,0,0,0,0,0,0,0,0,0,0,0,0,0,13,8,8,0,0,0,0,0
0,0,0,0,8,8,8,31,0,0,0,8,8,0,0,0,0,0,0,0,0,0,0,8,8,0,0,0,31,8,8,8,0,0,0,0
0,0,0,0,8,8,8,30,0,0,0,8,8,0,0,0,0,0,0,0,0,0,0,8,8,0,0,0,30,8,8,8,0,0,0,0
0,0,0,0,0,8,8,13,0,0,0,0,0,0,0,0,0,0,0,0,0,0,0,0,0,0,0,0,13,8,8,0,0,0,0,0
0,0,0,0,0,8,8,21,0,0,0,0,0,0,0,0,0,0,0,0,0,0,0,0,0,0,0,0,21,8,8,0,0,0,0,0
0,0,0,0,0,0,8,0,0,0,0,0,0,0,0,0,0,0,0,0,0,0,0,0,0,0,0,0,0,8,0,0,0,0,0,0
0,0,0,0,0,0,33,0,0,0,0,0,0,0,0,0,0,0,0,0,0,0,0,0,0,0,0,0,0,33,0,0,0,0,0,0
0,0,0,0,0,0,0,0,0,0,0,0,0,0,0,0,0,0,0,0,0,0,0,0,0,0,0,0,0,0,0,0,0,0,0,0
0,0,0,0,0,0,0,0,0,0,0,0,0,0,0,0,0,0,0,0,0,0,0,0,0,0,0,0,0,0,0,0,0,0,0,0
0,0,0,0,0,0,32,0,0,0,0,0,0,0,0,0,0,0,0,0,0,0,0,0,0,0,0,0,0,32,0,0,0,0,0,0
0,0,0,0,0,0,8,0,0,0,0,0,0,0,0,0,0,0,0,0,0,0,0,0,0,0,0,0,0,8,0,0,0,0,0,0
0,0,0,0,0,8,8,21,0,0,0,0,0,0,0,0,0,0,0,0,0,0,0,0,0,0,0,0,21,8,8,0,0,0,0,0
0,0,0,0,0,8,8,13,0,0,0,0,0,0,0,0,0,0,0,0,0,0,0,0,0,0,0,0,13,8,8,0,0,0,0,0
0,0,0,0,8,8,8,31,0,0,0,8,8,0,0,0,0,0,0,0,0,0,0,8,8,0,0,0,31,8,8,8,0,0,0,0
0,0,0,0,8,8,8,30,0,0,0,8,8,0,0,0,0,0,0,0,0,0,0,8,8,0,0,0,30,8,8,8,0,0,0,0
0,0,0,0,0,8,8,13,0,0,0,0,0,0,0,0,0,0,0,0,0,0,0,0,0,0,0,0,13,8,8,0,0,0,0,0
0,0,0,0,0,8,8,31,0,0,0,0,0,0,0,0,0,0,0,0,0,0,0,0,0,0,0,0,31,8,8,0,0,0,0,0
0,0,0,0,0,8,8,30,0,0,0,0,0,0,0,0,0,0,0,0,0,0,0,0,0,0,0,0,30,8,8,0,0,0,0,0
0,0,0,0,0,8,8,13,0,0,0,0,0,0,0,0,0,0,0,0,0,0,0,0,0,0,0,0,13,8,8,0,0,0,0,0
0,0,0,0,8,8,8,31,0,0,0,0,0,0,0,0,0,0,0,0,0,0,0,0,0,0,0,0,31,8,8,8,0,0,0,0
0,0,0,0,8,8,8,30,0,0,0,0,0,0,0,0,0,0,0,0,0,0,0,0,0,0,0,0,30,8,8,8,0,0,0,0
0,0,0,0,0,8,8,13,29,28,13,0,0,0,0,0,0,0,0,0,0,0,0,0,0,13,29,28,13,8,8,0,0,0,0,0
0,0,0,0,0,8,8,31,0,0,31,0,0,0,0,0,0,0,0,0,0,0,0,0,0,31,0,0,31,8,8,0,0,0,0,0
0,0,0,0,0,8,8,30,0,9,30,0,0,0,0,0,0,0,0,0,0,0,0,0,0,30,9,0,30,8,8,0,0,0,0,0
0,0,0,0,0,8,8,13,29,28,13,29,28,13,21,0,0,0,0,0,0,21,13,29,28,13,29,28,13,8,8,0,0,0,0,0
0,0,0,0,8,8,8,8,8,8,8,8,8,8,8,8,27,0,0,26,8,8,8,8,8,8,8,8,8,8,8,8,0,0,0,0
0,0,0,0,8,8,8,8,8,8,8,8,8,8,8,0,0,0,0,0,0,8,8,8,8,8,8,8,8,8,8,8,0,0,0,0
0,0,0,0,8,8,8,0,0,0,0,8,8,0,0,0,0,0,0,0,0,0,0,8,8,0,0,0,0,8,8,8,0,0,0,0
0,0,0,0,0,0,0,0,0,0,0,0,0,0,0,0,0,0,0,0,0,0,0,0,0,0,0,0,0,0,0,0,0,0,0,0
0,0,0,0,0,0,0,0,0,0,0,0,0,0,0,0,0,0,0,0,0,0,0,0,0,0,0,0,0,0,0,0,0,0,0,0
0,0,0,0,0,0,0,0,0,0,0,0,0,0,0,0,0,0,0,0,0,0,0,0,0,0,0,0,0,0,0,0,0,0,0,0
0,0,0,0,0,0,0,0,0,0,0,0,0,0,0,0,0,0,0,0,0,0,0,0,0,0,0,0,0,0,0,0,0,0,0,0
:endlayer
layer: 8
0,0,0,0,0,0,0,0,0,0,0,0,0,0,0,0,0,0,0,0,0,0,0,0,0,0,0,0,0,0,0,0,0,0,0,0
0,0,0,0,0,0,0,0,0,0,0,0,0,0,0,0,0,0,0,0,0,0,0,0,0,0,0,0,0,0,0,0,0,0,0,0
0,0,0,0,0,0,0,0,0,0,0,0,0,0,0,8,8,0,0,8,8,0,0,0,0,0,0,0,0,0,0,0,0,0,0,0
0,0,0,0,0,0,0,0,0,0,0,0,0,0,8,8,8,35,35,8,8,8,0,0,0,0,0,0,0,0,0,0,0,0,0,0
0,0,0,0,0,0,0,0,0,0,0,0,0,8,8,13,25,0,0,25,13,8,8,0,0,0,0,0,0,0,0,0,0,0,0,0
0,0,0,0,0,0,0,0,0,0,0,0,0,0,35,0,0,0,0,0,0,35,0,0,0,0,0,0,0,0,0,0,0,0,0,0
0,0,0,0,0,0,0,0,0,0,0,0,0,0,35,0,0,0,0,0,0,35,0,0,0,0,0,0,0,0,0,0,0,0,0,0
0,0,0,0,0,0,0,0,0,0,0,0,8,8,8,21,0,0,0,0,21,8,8,8,0,0,0,0,0,0,0,0,0,0,0,0
0,0,0,0,0,0,0,0,0,0,0,0,8,8,13,0,0,0,0,0,0,13,8,8,0,0,0,0,0,0,0,0,0,0,0,0
0,0,0,0,8,8,0,8,0,0,8,0,8,8,4,0,0,0,0,0,0,4,8,8,0,8,0,0,8,0,8,8,0,0,0,0
0,0,0,0,8,8,8,8,35,35,8,8,8,8,0,0,0,0,0,0,0,0,8,8,8,8,35,35,8,8,8,8,0,0,0,0
0,0,0,0,8,8,8,0,0,0,0,8,8,13,0,0,0,0,0,0,0,0,13,8,8,0,0,0,0,8,8,8,0,0,0,0
0,0,0,0,0,8,8,13,0,0,0,0,0,0,0,0,0,0,0,0,0,0,0,0,0,0,0,0,13,8,8,0,0,0,0,0
0,0,0,0,0,0,35,0,0,0,0,0,0,0,0,0,0,0,0,0,0,0,0,0,0,0,0,0,0,35,0,0,0,0,0,0
0,0,0,0,0,0,35,0,0,0,0,0,0,0,0,0,0,0,0,0,0,0,0,0,0,0,0,0,0,35,0,0,0,0,0,0
0,0,0,0,0,8,8,13,0,0,0,0,0,0,0,0,0,0,0,0,0,0,0,0,0,0,0,0,13,8,8,0,0,0,0,0
0,0,0,0,8,8,8,0,0,0,0,8,8,0,0,0,0,0,0,0,0,0,0,8,8,0,0,0,0,8,8,8,0,0,0,0
0,0,0,0,8,8,8,0,0,0,0,8,8,0,0,0,0,0,0,0,0,0,0,8,8,0,0,0,0,8,8,8,0,0,0,0
0,0,0,0,0,8,8,13,0,0,0,0,0,0,0,0,0,0,0,0,0,0,0,0,0,0,0,0,13,8,8,0,0,0,0,0
0,0,0,0,0,8,8,21,0,0,0,0,0,0,0,0,0,0,0,0,0,0,0,0,0,0,0,0,21,8,8,0,0,0,0,0
0,0,0,0,0,33,8,0,0,0,0,0,0,0,0,0,0,0,0,0,0,0,0,0,0,0,0,0,0,8,33,0,0,0,0,0
0,0,0,0,0,0,8,0,0,0,0,0,0,0,0,0,0,0,0,0,0,0,0,0,0,0,0,0,0,8,0,0,0,0,0,0
0,0,0,0,0,0,8,0,0,0,0,0,0,0,0,0,0,0,0,0,0,0,0,0,0,0,0,0,0,8,0,0,0,0,0,0
0,0,0,0,0,0,8,0,0,0,0,0,0,0,0,0,0,0,0,0,0,0,0,0,0,0,0,0,0,8,0,0,0,0,0,0
0,0,0,0,0,0,8,0,0,0,0,0,0,0,0,0,0,0,0,0,0,0,0,0,0,0,0,0,0,8,0,0,0,0,0,0
0,0,0,0,0,32,8,0,0,0,0,0,0,0,0,0,0,0,0,0,0,0,0,0,0,0,0,0,0,8,32,0,0,0,0,0
0,0,0,0,0,8,8,21,0,0,0,0,0,0,0,0,0,0,0,0,0,0,0,0,0,0,0,0,21,8,8,0,0,0,0,0
0,0,0,0,0,8,8,13,0,0,0,0,0,0,0,0,0,0,0,0,0,0,0,0,0,0,0,0,13,8,8,0,0,0,0,0
0,0,0,0,8,8,8,0,0,0,0,8,8,0,0,0,0,0,0,0,0,0,0,8,8,0,0,0,0,8,8,8,0,0,0,0
0,0,0,0,8,8,8,0,0,0,0,8,8,0,0,0,0,0,0,0,0,0,0,8,8,0,0,0,0,8,8,8,0,0,0,0
0,0,0,0,0,8,8,13,0,0,0,0,0,0,0,0,0,0,0,0,0,0,0,0,0,0,0,0,13,8,8,0,0,0,0,0
0,0,0,0,0,0,35,0,0,0,0,0,0,0,0,0,0,0,0,0,0,0,0,0,0,0,0,0,0,35,0,0,0,0,0,0
0,0,0,0,0,0,35,0,0,0,0,0,0,0,0,0,0,0,0,0,0,0,0,0,0,0,0,0,0,35,0,0,0,0,0,0
0,0,0,0,0,8,8,13,0,0,0,0,0,0,0,0,0,0,0,0,0,0,0,0,0,0,0,0,13,8,8,0,0,0,0,0
0,0,0,0,8,8,8,0,0,0,0,0,0,0,0,0,0,0,0,0,0,0,0,0,0,0,0,0,0,8,8,8,0,0,0,0
0,0,0,0,8,8,8,0,0,0,0,0,0,0,0,0,0,0,0,0,0,0,0,0,0,0,0,0,0,8,8,8,0,0,0,0
0,0,0,0,0,8,8,13,21,21,13,0,0,0,0,0,0,0,0,0,0,0,0,0,0,13,21,21,13,8,8,0,0,0,0,0
0,0,0,0,0,0,35,0,0,0,21,0,0,0,0,0,0,0,0,0,0,0,0,0,0,21,0,0,0,35,0,0,0,0,0,0
0,0,0,0,0,0,35,0,5,0,21,0,0,0,0,0,0,0,0,0,0,0,0,0,0,21,0,7,0,35,0,0,0,0,0,0
0,0,0,0,0,8,8,13,0,0,13,0,0,13,21,0,0,0,0,0,0,21,13,0,0,13,0,0,13,8,8,0,0,0,0,0
0,0,0,0,8,8,8,8,35,35,8,8,8,8,8,8,8,8,8,8,8,8,8,8,8,8,35,35,8,8,8,8,0,0,0,0
0,0,0,0,8,8,8,8,0,0,8,8,8,8,8,27,0,0,0,0,26,8,8,8,8,8,0,0,8,8,8,8,0,0,0,0
0,0,0,0,8,8,8,0,0,0,0,8,8,0,0,0,0,0,0,0,0,0,0,8,8,0,0,0,0,8,8,8,0,0,0,0
0,0,0,0,0,0,0,0,0,0,0,0,0,0,0,0,0,0,0,0,0,0,0,0,0,0,0,0,0,0,0,0,0,0,0,0
0,0,0,0,0,0,0,0,0,0,0,0,0,0,0,0,0,0,0,0,0,0,0,0,0,0,0,0,0,0,0,0,0,0,0,0
0,0,0,0,0,0,0,0,0,0,0,0,0,0,0,0,0,0,0,0,0,0,0,0,0,0,0,0,0,0,0,0,0,0,0,0
0,0,0,0,0,0,0,0,0,0,0,0,0,0,0,0,0,0,0,0,0,0,0,0,0,0,0,0,0,0,0,0,0,0,0,0
:endlayer
layer: 9
0,0,0,0,0,0,0,0,0,0,0,0,0,0,0,0,0,0,0,0,0,0,0,0,0,0,0,0,0,0,0,0,0,0,0,0
0,0,0,0,0,0,0,0,0,0,0,0,0,0,0,0,24,0,0,24,0,0,0,0,0,0,0,0,0,0,0,0,0,0,0,0
0,0,0,0,0,0,0,0,0,0,0,0,0,0,0,8,8,0,0,8,8,0,0,0,0,0,0,0,0,0,0,0,0,0,0,0
0,0,0,0,0,0,0,0,0,0,0,0,0,0,8,8,8,35,35,8,8,8,0,0,0,0,0,0,0,0,0,0,0,0,0,0
0,0,0,0,0,0,0,0,0,0,0,0,22,8,8,13,0,0,0,0,13,8,8,23,0,0,0,0,0,0,0,0,0,0,0,0
0,0,0,0,0,0,0,0,0,0,0,0,0,0,35,0,0,0,0,0,0,35,0,0,0,0,0,0,0,0,0,0,0,0,0,0
0,0,0,0,0,0,0,0,0,0,0,0,0,0,35,0,0,0,0,0,0,35,0,0,0,0,0,0,0,0,0,0,0,0,0,0
0,0,0,0,0,0,0,0,0,0,0,0,8,8,8,21,0,0,0,0,21,8,8,8,0,0,0,0,0,0,0,0,0,0,0,0
0,0,0,0,0,0,0,24,0,0,24,0,8,8,13,0,0,0,0,0,0,13,8,8,0,24,0,0,24,0,0,0,0,0,0,0
0,0,0,0,8,8,0,8,0,0,8,0,8,8,0,0,0,0,0,0,0,0,8,8,0,8,0,0,8,0,8,8,0,0,0,0
0,0,0,0,8,8,8,8,35,35,8,8,8,8,0,0,0,0,0,0,0,0,8,8,8,8,35,35,8,8,8,8,0,0,0,0
0,0,0,0,8,8,8,25,0,0,25,8,8,13,0,0,0,0,0,0,0,0,13,8,8,25,0,0,25,8,8,8,0,0,0,0
0,0,0,0,22,8,8,13,23,0,0,0,0,25,0,0,0,0,0,0,0,0,25,0,0,0,0,22,13,8,8,23,0,0,0,0
0,0,0,0,0,0,35,0,0,0,0,0,0,0,0,0,0,0,0,0,0,0,0,0,0,0,0,0,0,35,0,0,0,0,0,0
0,0,0,0,0,0,35,0,0,0,0,0,0,0,0,0,0,0,0,0,0,0,0,0,0,0,0,0,0,35,0,0,0,0,0,0
0,0,0,0,22,8,8,13,23,0,0,0,0,0,0,0,0,0,0,0,0,0,0,0,0,0,0,22,13,8,8,23,0,0,0,0
0,0,0,0,8,8,8,0,0,0,0,8,8,0,0,0,0,0,0,0,0,0,0,8,8,0,0,0,0,8,8,8,0,0,0,0
0,0,0,0,8,8,8,0,0,0,0,8,8,0,0,0,0,0,0,0,0,0,0,8,8,0,0,0,0,8,8,8,0,0,0,0
0,0,0,0,0,8,8,13,23,0,0,0,0,0,0,0,0,0,0,0,0,0,0,0,0,0,0,22,13,8,8,0,0,0,0,0
0,0,0,0,0,8,8,31,0,0,0,0,0,0,0,0,0,0,0,0,0,0,0,0,0,0,0,0,31,8,8,0,0,0,0,0
0,0,0,0,0,8,8,0,0,0,0,0,0,0,0,0,0,0,0,0,0,0,0,0,0,0,0,0,0,8,8,0,0,0,0,0
0,0,0,0,0,8,8,0,0,0,0,0,0,0,0,0,0,0,0,0,0,0,0,0,0,0,0,0,0,8,8,0,0,0,0,0
0,0,0,0,0,8,8,0,0,0,0,0,0,0,0,0,0,0,0,0,0,0,0,0,0,0,0,0,0,8,8,0,0,0,0,0
0,0,0,0,0,8,8,0,0,0,0,0,0,0,0,0,0,0,0,0,0,0,0,0,0,0,0,0,0,8,8,0,0,0,0,0
0,0,0,0,0,8,8,0,0,0,0,0,0,0,0,0,0,0,0,0,0,0,0,0,0,0,0,0,0,8,8,0,0,0,0,0
0,0,0,0,0,8,8,0,0,0,0,0,0,0,0,0,0,0,0,0,0,0,0,0,0,0,0,0,0,8,8,0,0,0,0,0
0,0,0,0,0,8,8,30,0,0,0,0,0,0,0,0,0,0,0,0,0,0,0,0,0,0,0,0,30,8,8,0,0,0,0,0
0,0,0,0,0,8,8,13,23,0,0,0,0,0,0,0,0,0,0,0,0,0,0,0,0,0,0,22,13,8,8,0,0,0,0,0
0,0,0,0,8,8,8,0,0,0,0,8,8,0,0,0,0,0,0,0,0,0,0,8,8,0,0,0,0,8,8,8,0,0,0,0
0,0,0,0,8,8,8,0,0,0,0,8,8,0,0,0,0,0,0,0,0,0,0,8,8,0,0,0,0,8,8,8,0,0,0,0
0,0,0,0,22,8,8,13,23,0,0,0,0,0,0,0,0,0,0,0,0,0,0,0,0,0,0,22,13,8,8,23,0,0,0,0
0,0,0,0,0,0,35,0,0,0,0,0,0,0,0,0,0,0,0,0,0,0,0,0,0,0,0,0,0,35,0,0,0,0,0,0
0,0,0,0,0,0,35,0,0,0,0,0,0,0,0,0,0,0,0,0,0,0,0,0,0,0,0,0,0,35,0,0,0,0,0,0
0,0,0,0,22,8,8,13,23,0,0,0,0,0,0,0,0,0,0,0,0,0,0,0,0,0,0,22,13,8,8,23,0,0,0,0
0,0,0,0,8,8,8,0,0,0,0,0,0,0,0,0,0,0,0,0,0,0,0,0,0,0,0,0,0,8,8,8,0,0,0,0
0,0,0,0,8,8,8,0,0,0,24,0,0,0,0,0,0,0,0,0,0,0,0,0,0,24,0,0,0,8,8,8,0,0,0,0
0,0,0,0,22,8,8,13,21,21,13,23,0,0,0,0,0,0,0,0,0,0,0,0,22,13,21,21,13,8,8,23,0,0,0,0
0,0,0,0,0,0,35,0,6,0,21,0,0,0,0,0,0,0,0,0,0,0,0,0,0,21,0,6,0,35,0,0,0,0,0,0
0,0,0,0,0,0,35,0,0,0,21,0,0,24,0,0,0,0,0,0,0,0,24,0,0,21,0,0,0,35,0,0,0,0,0,0
0,0,0,0,22,8,8,13,0,0,13,0,0,13,29,0,0,0,0,0,0,28,13,0,0,13,0,0,13,8,8,23,0,0,0,0
0,0,0,0,8,8,8,8,35,35,8,8,8,8,8,8,8,8,8,8,8,8,8,8,8,8,35,35,8,8,8,8,0,0,0,0
0,0,0,0,8,8,8,8,0,0,8,8,8,8,8,8,8,8,8,8,8,8,8,8,8,8,0,0,8,8,8,8,0,0,0,0
0,0,0,0,8,8,8,25,0,0,25,8,8,0,0,0,0,0,0,0,0,0,0,8,8,25,0,0,25,8,8,8,0,0,0,0
0,0,0,0,0,0,0,0,0,0,0,0,0,0,0,0,0,0,0,0,0,0,0,0,0,0,0,0,0,0,0,0,0,0,0,0
0,0,0,0,0,0,0,0,0,0,0,0,0,0,0,0,0,0,0,0,0,0,0,0,0,0,0,0,0,0,0,0,0,0,0,0
0,0,0,0,0,0,0,0,0,0,0,0,0,0,0,0,0,0,0,0,0,0,0,0,0,0,0,0,0,0,0,0,0,0,0,0
0,0,0,0,0,0,0,0,0,0,0,0,0,0,0,0,0,0,0,0,0,0,0,0,0,0,0,0,0,0,0,0,0,0,0,0
:endlayer
layer: 10
0,0,0,0,0,0,0,0,0,0,0,0,0,0,0,0,0,0,0,0,0,0,0,0,0,0,0,0,0,0,0,0,0,0,0,0
0,0,0,0,0,0,0,0,0,0,0,0,0,0,0,0,0,0,0,0,0,0,0,0,0,0,0,0,0,0,0,0,0,0,0,0
0,0,0,0,0,0,0,0,0,0,0,0,0,0,0,8,8,0,0,8,8,0,0,0,0,0,0,0,0,0,0,0,0,0,0,0
0,0,0,0,0,0,0,0,0,0,0,0,0,0,8,8,8,35,35,8,8,8,0,0,0,0,0,0,0,0,0,0,0,0,0,0
0,0,0,0,0,0,0,0,0,0,0,0,0,8,8,13,0,0,0,0,13,8,8,0,0,0,0,0,0,0,0,0,0,0,0,0
0,0,0,0,0,0,0,0,0,0,0,0,0,0,35,0,0,0,0,0,0,35,0,0,0,0,0,0,0,0,0,0,0,0,0,0
0,0,0,0,0,0,0,0,0,0,0,0,0,0,35,0,0,0,0,0,0,35,0,0,0,0,0,0,0,0,0,0,0,0,0,0
0,0,0,0,0,0,0,0,0,0,0,0,8,8,8,21,0,0,0,0,21,8,8,8,0,0,0,0,0,0,0,0,0,0,0,0
0,0,0,0,0,0,0,0,0,0,0,0,8,8,13,0,0,0,0,0,0,13,8,8,0,0,0,0,0,0,0,0,0,0,0,0
0,0,0,0,8,8,0,8,0,0,8,0,8,8,0,0,0,0,0,0,0,0,8,8,0,8,0,0,8,0,8,8,0,0,0,0
0,0,0,0,8,8,8,8,35,35,8,8,8,8,0,0,0,0,0,0,0,0,8,8,8,8,35,35,8,8,8,8,0,0,0,0
0,0,0,0,8,8,8,0,0,0,0,8,8,13,0,0,0,0,0,0,0,0,13,8,8,0,0,0,0,8,8,8,0,0,0,0
0,0,0,0,0,8,8,13,0,0,0,0,0,0,0,0,0,0,0,0,0,0,0,0,0,0,0,0,13,8,8,0,0,0,0,0
0,0,0,0,0,0,35,0,0,0,0,0,0,0,0,0,0,0,0,0,0,0,0,0,0,0,0,0,0,35,0,0,0,0,0,0
0,0,0,0,0,0,35,0,0,0,0,0,0,0,0,0,0,0,0,0,0,0,0,0,0,0,0,0,0,35,0,0,0,0,0,0
0,0,0,0,0,8,8,13,0,0,0,0,0,0,0,0,0,0,0,0,0,0,0,0,0,0,0,0,13,8,8,0,0,0,0,0
0,0,0,0,8,8,8,0,0,0,0,8,8,0,0,0,0,0,0,0,0,0,0,8,8,0,0,0,0,8,8,8,0,0,0,0
0,0,0,0,8,8,8,0,0,0,0,8,8,0,0,0,0,0,0,0,0,0,0,8,8,0,0,0,0,8,8,8,0,0,0,0
0,0,0,0,0,8,8,13,0,0,0,33,0,0,0,0,0,0,0,0,0,0,0,0,33,0,0,0,13,8,8,0,0,0,0,0
0,0,0,0,0,8,8,21,0,0,0,0,0,0,0,0,0,0,0,0,0,0,0,0,0,0,0,0,21,8,8,0,0,0,0,0
0,0,0,0,0,8,8,36,0,0,0,0,0,0,0,0,0,0,0,0,0,0,0,0,0,0,0,0,36,8,8,0,0,0,0,0
0,0,0,0,0,8,8,36,0,0,0,0,0,0,0,0,0,0,0,0,0,0,0,0,0,0,0,0,36,8,8,0,0,0,0,0
0,0,0,0,0,8,8,34,0,0,0,0,0,0,0,0,0,0,0,0,0,0,0,0,0,0,0,0,34,8,8,0,0,0,0,0
0,0,0,0,0,8,8,34,0,0,0,0,0,0,0,0,0,0,0,0,0,0,0,0,0,0,0,0,34,8,8,0,0,0,0,0
0,0,0,0,0,8,8,36,0,0,0,0,0,0,0,0,0,0,0,0,0,0,0,0,0,0,0,0,36,8,8,0,0,0,0,0
0,0,0,0,0,8,8,36,0,0,0,0,0,0,0,0,0,0,0,0,0,0,0,0,0,0,0,0,36,8,8,0,0,0,0,0
0,0,0,0,0,8,8,21,0,0,0,0,0,0,0,0,0,0,0,0,0,0,0,0,0,0,0,0,21,8,8,0,0,0,0,0
0,0,0,0,0,8,8,13,0,0,0,32,0,0,0,0,0,0,0,0,0,0,0,0,32,0,0,0,13,8,8,0,0,0,0,0
0,0,0,0,8,8,8,0,0,0,0,8,8,0,0,0,0,0,0,0,0,0,0,8,8,0,0,0,0,8,8,8,0,0,0,0
0,0,0,0,8,8,8,0,0,0,0,8,8,27,0,0,0,0,0,0,0,0,26,8,8,0,0,0,0,8,8,8,0,0,0,0
0,0,0,0,0,8,8,13,0,0,0,33,33,0,0,0,0,0,0,0,0,0,0,33,33,0,0,0,13,8,8,0,0,0,0,0
0,0,0,0,0,0,35,0,0,0,0,0,0,0,0,0,0,0,0,0,0,0,0,0,0,0,0,0,0,35,0,0,0,0,0,0
0,0,0,0,0,0,35,0,0,0,0,0,0,0,0,0,0,0,0,0,0,0,0,0,0,0,0,0,0,35,0,0,0,0,0,0
0,0,0,0,0,8,8,13,0,0,0,0,0,0,0,0,0,0,0,0,0,0,0,0,0,0,0,0,13,8,8,0,0,0,0,0
0,0,0,0,8,8,8,0,0,0,0,0,0,0,0,0,0,0,0,0,0,0,0,0,0,0,0,0,0,8,8,8,0,0,0,0
0,0,0,0,8,8,8,0,0,0,0,0,0,0,0,0,0,0,0,0,0,0,0,0,0,0,0,0,0,8,8,8,0,0,0,0
0,0,0,0,0,8,8,13,21,21,13,0,0,0,0,0,0,0,0,0,0,0,0,0,0,13,21,21,13,8,8,0,0,0,0,0
0,0,0,0,0,0,35,0,0,7,21,0,0,0,0,0,0,0,0,0,0,0,0,0,0,21,5,0,0,35,0,0,0,0,0,0
0,0,0,0,0,0,35,0,0,0,21,0,0,0,0,0,0,0,0,0,0,0,0,0,0,21,0,0,0,35,0,0,0,0,0,0
0,0,0,0,0,8,8,13,0,0,13,32,32,13,0,36,36,34,34,36,36,0,13,32,32,13,0,0,13,8,8,0,0,0,0,0
0,0,0,0,8,8,8,8,35,35,8,8,8,8,8,8,8,8,8,8,8,8,8,8,8,8,35,35,8,8,8,8,0,0,0,0
0,0,0,0,8,8,8,8,0,0,8,8,8,8,8,8,8,8,8,8,8,8,8,8,8,8,0,0,8,8,8,8,0,0,0,0
0,0,0,0,8,8,8,0,0,0,0,8,8,0,0,0,0,0,0,0,0,0,0,8,8,0,0,0,0,8,8,8,0,0,0,0
0,0,0,0,0,0,0,0,0,0,0,0,0,0,0,0,0,0,0,0,0,0,0,0,0,0,0,0,0,0,0,0,0,0,0,0
0,0,0,0,0,0,0,0,0,0,0,0,0,0,0,0,0,0,0,0,0,0,0,0,0,0,0,0,0,0,0,0,0,0,0,0
0,0,0,0,0,0,0,0,0,0,0,0,0,0,0,0,0,0,0,0,0,0,0,0,0,0,0,0,0,0,0,0,0,0,0,0
0,0,0,0,0,0,0,0,0,0,0,0,0,0,0,0,0,0,0,0,0,0,0,0,0,0,0,0,0,0,0,0,0,0,0,0
:endlayer
layer: 11
0,0,0,0,0,0,0,0,0,0,0,0,0,0,0,0,0,0,0,0,0,0,0,0,0,0,0,0,0,0,0,0,0,0,0,0
0,0,0,0,0,0,0,0,0,0,0,0,0,0,0,0,0,0,0,0,0,0,0,0,0,0,0,0,0,0,0,0,0,0,0,0
0,0,0,0,0,0,0,0,0,0,0,0,0,0,0,8,8,27,26,8,8,0,0,0,0,0,0,0,0,0,0,0,0,0,0,0
0,0,0,0,0,0,0,0,0,0,0,0,0,0,8,8,8,35,35,8,8,8,0,0,0,0,0,0,0,0,0,0,0,0,0,0
0,0,0,0,0,0,0,0,0,0,0,0,0,8,8,13,0,0,0,0,13,8,8,0,0,0,0,0,0,0,0,0,0,0,0,0
0,0,0,0,0,0,0,0,0,0,0,0,0,33,35,0,0,0,0,0,0,35,33,0,0,0,0,0,0,0,0,0,0,0,0,0
0,0,0,0,0,0,0,0,0,0,0,0,0,32,35,0,0,0,0,0,0,35,32,0,0,0,0,0,0,0,0,0,0,0,0,0
0,0,0,0,0,0,0,0,0,0,0,0,8,8,8,21,0,0,0,0,21,8,8,8,0,0,0,0,0,0,0,0,0,0,0,0
0,0,0,0,0,0,0,0,0,0,0,0,8,8,13,0,0,0,0,0,0,13,8,8,0,0,0,0,0,0,0,0,0,0,0,0
0,0,0,0,8,8,0,8,27,26,8,0,8,8,0,0,0,0,0,0,0,0,8,8,0,8,27,26,8,0,8,8,0,0,0,0
0,0,0,0,8,8,8,8,35,35,8,8,8,8,0,0,0,0,0,0,0,0,8,8,8,8,35,35,8,8,8,8,0,0,0,0
0,0,0,0,8,8,8,0,0,0,0,8,8,13,0,0,0,0,0,0,0,0,13,8,8,0,0,0,0,8,8,8,0,0,0,0
0,0,0,0,0,8,8,13,0,0,0,0,0,0,0,0,0,0,0,0,0,0,0,0,0,0,0,0,13,8,8,0,0,0,0,0
0,0,0,0,0,33,35,0,0,0,0,0,0,0,0,0,0,0,0,0,0,0,0,0,0,0,0,0,0,35,33,0,0,0,0,0
0,0,0,0,0,32,35,0,0,0,0,0,0,0,0,0,0,0,0,0,0,0,0,0,0,0,0,0,0,35,32,0,0,0,0,0
0,0,0,0,0,8,8,13,0,0,0,0,0,0,0,0,0,0,0,0,0,0,0,0,0,0,0,0,13,8,8,0,0,0,0,0
0,0,0,0,8,8,8,0,0,0,0,8,8,0,0,0,0,0,0,0,0,0,0,8,8,0,0,0,0,8,8,8,0,0,0,0
0,0,0,0,8,8,8,27,0,0,26,8,8,0,0,0,0,0,0,0,0,0,0,8,8,27,0,0,26,8,8,8,0,0,0,0
0,0,0,0,0,8,8,13,0,0,0,8,31,0,0,0,0,0,0,0,0,0,0,31,8,0,0,0,13,8,8,0,0,0,0,0
0,0,0,0,0,8,8,31,0,0,0,8,0,0,0,0,0,0,0,0,0,0,0,0,8,0,0,0,31,8,8,0,0,0,0,0
0,0,0,0,0,8,8,0,0,0,0,37,0,0,0,0,0,0,0,0,0,0,0,0,37,0,0,0,0,8,8,0,0,0,0,0
0,0,0,0,0,8,8,34,0,0,0,37,0,0,0,0,0,0,0,0,0,0,0,0,37,0,0,0,34,8,8,0,0,0,0,0
0,0,0,0,0,8,8,0,0,0,0,0,0,0,0,0,0,0,0,0,0,0,0,0,0,0,0,0,0,8,8,0,0,0,0,0
0,0,0,0,0,8,8,0,0,0,0,0,0,0,0,0,0,0,0,0,0,0,0,0,0,0,0,0,0,8,8,0,0,0,0,0
0,0,0,0,0,8,8,34,0,0,0,37,0,0,0,0,0,0,0,0,0,0,0,0,37,0,0,0,34,8,8,0,0,0,0,0
0,0,0,0,0,8,8,0,0,0,0,37,0,0,0,0,0,0,0,0,0,0,0,0,37,0,0,0,0,8,8,0,0,0,0,0
0,0,0,0,0,8,8,30,0,0,0,8,0,0,0,0,0,0,0,0,0,0,0,0,8,0,0,0,30,8,8,0,0,0,0,0
0,0,0,0,0,8,8,13,0,0,0,8,30,0,0,0,0,0,0,0,0,0,0,30,8,0,0,0,13,8,8,0,0,0,0,0
0,0,0,0,8,8,8,27,0,0,26,8,8,29,0,0,0,0,0,0,0,0,28,8,8,27,0,0,26,8,8,8,0,0,0,0
0,0,0,0,8,8,8,27,0,0,26,8,8,8,8,37,37,0,0,37,37,8,8,8,8,27,0,0,26,8,8,8,0,0,0,0
0,0,0,0,0,8,8,13,0,0,0,8,8,0,25,0,0,0,0,0,0,25,0,8,8,0,0,0,13,8,8,0,0,0,0,0
0,0,0,0,0,33,35,31,0,0,0,8,8,23,0,0,0,0,0,0,0,0,22,8,8,0,0,0,31,35,33,0,0,0,0,0
0,0,0,0,0,32,35,30,0,0,0,37,37,0,0,0,0,0,0,0,0,0,0,37,37,0,0,0,30,35,32,0,0,0,0,0
0,0,0,0,0,8,8,13,0,0,0,37,37,0,0,0,0,0,0,0,0,0,0,37,37,0,0,0,13,8,8,0,0,0,0,0
0,0,0,0,8,8,8,31,0,0,0,0,0,0,0,0,0,0,0,0,0,0,0,0,0,0,0,0,31,8,8,8,0,0,0,0
0,0,0,0,8,8,8,30,0,0,0,0,0,0,0,0,0,0,0,0,0,0,0,0,0,0,0,0,30,8,8,8,0,0,0,0
0,0,0,0,0,8,8,13,29,28,13,37,37,0,0,0,0,0,0,0,0,0,0,37,37,13,29,28,13,8,8,0,0,0,0,0
0,0,0,0,0,33,35,31,0,0,31,37,37,0,0,0,0,0,0,0,0,0,0,37,37,31,0,0,31,35,33,0,0,0,0,0
0,0,0,0,0,32,35,30,0,9,30,8,8,0,0,0,0,0,0,0,0,0,0,8,8,30,9,0,30,35,32,0,0,0,0,0
0,0,0,0,0,8,8,13,29,28,13,8,8,13,29,24,34,0,0,34,24,28,13,8,8,13,29,28,13,8,8,0,0,0,0,0
0,0,0,0,8,8,8,8,35,35,8,8,8,8,8,8,8,8,8,8,8,8,8,8,8,8,35,35,8,8,8,8,0,0,0,0
0,0,0,0,8,8,8,8,27,26,8,8,8,8,8,8,8,8,8,8,8,8,8,8,8,8,27,26,8,8,8,8,0,0,0,0
0,0,0,0,8,8,8,0,0,0,0,8,8,0,0,0,0,0,0,0,0,0,0,8,8,0,0,0,0,8,8,8,0,0,0,0
0,0,0,0,0,0,0,0,0,0,0,0,0,0,0,0,0,0,0,0,0,0,0,0,0,0,0,0,0,0,0,0,0,0,0,0
0,0,0,0,0,0,0,0,0,0,0,0,0,0,0,0,0,0,0,0,0,0,0,0,0,0,0,0,0,0,0,0,0,0,0,0
0,0,0,0,0,0,0,0,0,0,0,0,0,0,0,0,0,0,0,0,0,0,0,0,0,0,0,0,0,0,0,0,0,0,0,0
0,0,0,0,0,0,0,0,0,0,0,0,0,0,0,0,0,0,0,0,0,0,0,0,0,0,0,0,0,0,0,0,0,0,0,0
:endlayer
layer: 12
0,0,0,0,0,0,0,0,0,0,0,0,0,0,0,0,0,0,0,0,0,0,0,0,0,0,0,0,0,0,0,0,0,0,0,0
0,0,0,0,0,0,0,0,0,0,0,0,0,0,0,0,0,0,0,0,0,0,0,0,0,0,0,0,0,0,0,0,0,0,0,0
0,0,0,0,0,0,0,0,0,0,0,0,0,0,0,8,8,8,8,8,8,0,0,0,0,0,0,0,0,0,0,0,0,0,0,0
0,0,0,0,0,0,0,0,0,0,0,0,0,0,8,8,8,8,8,8,8,8,0,0,0,0,0,0,0,0,0,0,0,0,0,0
0,0,0,0,0,0,0,0,0,0,0,0,0,8,8,13,0,0,0,0,13,8,8,0,0,0,0,0,0,0,0,0,0,0,0,0
0,0,0,0,0,0,0,0,0,0,0,0,0,8,8,0,0,0,0,0,0,8,8,0,0,0,0,0,0,0,0,0,0,0,0,0
0,0,0,0,0,0,0,0,0,0,0,0,0,8,8,0,0,0,0,0,0,8,8,0,0,0,0,0,0,0,0,0,0,0,0,0
0,0,0,0,0,0,0,0,0,0,0,0,8,8,8,21,0,0,0,0,21,8,8,8,0,0,0,0,0,0,0,0,0,0,0,0
0,0,0,0,0,0,0,0,0,0,0,0,8,8,13,0,0,0,0,0,0,13,8,8,0,0,0,0,0,0,0,0,0,0,0,0
0,0,0,0,8,8,0,8,8,8,8,0,8,8,0,0,0,0,0,0,0,0,8,8,0,8,8,8,8,0,8,8,0,0,0,0
0,0,0,0,8,8,8,8,8,8,8,8,8,8,0,0,0,0,0,0,0,0,8,8,8,8,8,8,8,8,8,8,0,0,0,0
0,0,0,0,8,8,8,0,0,0,0,8,8,13,0,0,0,0,0,0,0,0,13,8,8,0,0,0,0,8,8,8,0,0,0,0
0,0,0,0,0,8,8,13,0,0,0,0,0,0,0,0,0,0,0,0,0,0,0,0,0,0,0,0,13,8,8,0,0,0,0,0
0,0,0,0,0,8,8,0,0,0,0,0,0,0,0,0,0,0,0,0,0,0,0,0,0,0,0,0,0,8,8,0,0,0,0,0
0,0,0,0,0,8,8,0,0,0,0,0,0,0,0,0,0,0,0,0,0,0,0,0,0,0,0,0,0,8,8,0,0,0,0,0
0,0,0,0,0,8,8,13,0,0,0,0,0,0,0,0,0,0,0,0,0,0,0,0,0,0,0,0,13,8,8,0,0,0,0,0
0,0,0,0,8,8,8,29,0,0,28,8,8,0,0,0,0,0,0,0,0,0,0,8,8,29,0,0,28,8,8,8,0,0,0,0
0,0,0,0,8,8,8,8,8,8,8,8,8,0,0,0,0,0,0,0,0,0,0,8,8,8,8,8,8,8,8,8,0,0,0,0
0,0,0,0,0,8,8,13,29,34,34,8,23,0,0,0,0,0,0,0,0,0,0,22,8,34,34,28,13,8,8,0,0,0,0,0
0,0,0,0,0,8,8,18,0,0,34,8,36,0,0,0,0,0,0,0,0,0,0,36,8,34,0,0,18,8,8,0,0,0,0,0
0,0,0,0,0,8,8,18,0,0,34,8,36,0,0,0,0,0,0,0,0,0,0,36,8,34,0,0,18,8,8,0,0,0,0,0
0,0,0,0,0,8,8,18,29,34,34,8,34,0,0,0,0,0,0,0,0,0,0,34,8,34,34,28,18,8,8,0,0,0,0,0
0,0,0,0,0,8,8,18,0,0,34,8,34,0,0,0,0,0,0,0,0,0,0,34,8,34,0,0,18,8,8,0,0,0,0,0
0,0,0,0,0,8,8,18,0,0,34,8,34,0,0,0,0,0,0,0,0,0,0,34,8,34,0,0,18,8,8,0,0,0,0,0
0,0,0,0,0,8,8,18,29,34,34,8,34,0,0,0,0,0,0,0,0,0,0,34,8,34,34,28,18,8,8,0,0,0,0,0
0,0,0,0,0,8,8,18,0,0,34,8,36,0,0,0,0,0,0,0,0,0,0,36,8,34,0,0,18,8,8,0,0,0,0,0
0,0,0,0,0,8,8,18,0,0,34,8,36,0,0,0,0,0,0,0,0,0,0,36,8,34,0,0,18,8,8,0,0,0,0,0
0,0,0,0,0,8,8,13,29,34,34,8,23,0,0,0,0,0,0,0,0,0,0,22,8,34,34,28,13,8,8,0,0,0,0,0
0,0,0,0,8,8,8,8,8,8,8,8,8,24,36,36,34,34,34,34,36,36,24,8,8,8,8,8,8,8,8,8,0,0,0,0
0,0,0,0,8,8,8,8,8,8,8,8,8,8,8,8,8,8,8,8,8,8,8,8,8,8,8,8,8,8,8,8,0,0,0,0
0,0,0,0,0,8,8,13,29,34,34,8,8,31,34,34,31,34,34,31,34,34,31,8,8,34,34,28,13,8,8,0,0,0,0,0
0,0,0,0,0,8,8,18,0,0,34,8,8,34,0,0,34,0,0,34,0,0,34,8,8,34,0,0,18,8,8,0,0,0,0,0
0,0,0,0,0,8,8,18,0,0,34,8,8,34,0,0,34,0,0,34,0,0,34,8,8,34,0,0,18,8,8,0,0,0,0,0
0,0,0,0,0,8,8,13,29,34,34,8,8,29,34,34,34,34,34,34,34,34,28,8,8,34,34,28,13,8,8,0,0,0,0,0
0,0,0,0,8,8,8,18,0,0,34,8,8,34,0,0,34,0,0,34,0,0,34,8,8,34,0,0,18,8,8,8,0,0,0,0
0,0,0,0,8,8,8,18,0,0,34,8,8,34,0,0,34,0,0,34,0,0,34,8,8,34,0,0,18,8,8,8,0,0,0,0
0,0,0,0,0,8,8,13,20,20,13,8,8,29,34,34,34,34,34,34,34,34,28,8,8,13,20,20,13,8,8,0,0,0,0,0
0,0,0,0,0,8,8,18,0,0,18,8,8,34,0,0,34,0,0,34,0,0,34,8,8,18,0,0,18,8,8,0,0,0,0,0
0,0,0,0,0,8,8,18,5,0,18,8,8,30,34,34,30,34,34,30,34,34,30,8,8,18,0,7,18,8,8,0,0,0,0,0
0,0,0,0,0,8,8,13,20,20,13,8,8,13,20,20,20,20,20,20,20,20,13,8,8,13,20,20,13,8,8,0,0,0,0,0
0,0,0,0,8,8,8,8,8,8,8,8,8,8,8,8,8,8,8,8,8,8,8,8,8,8,8,8,8,8,8,8,0,0,0,0
0,0,0,0,8,8,8,8,8,8,8,8,8,8,8,8,8,8,8,8,8,8,8,8,8,8,8,8,8,8,8,8,0,0,0,0
0,0,0,0,8,8,8,0,0,0,0,8,8,0,0,0,0,0,0,0,0,0,0,8,8,0,0,0,0,8,8,8,0,0,0,0
0,0,0,0,0,0,0,0,0,0,0,0,0,0,0,0,0,0,0,0,0,0,0,0,0,0,0,0,0,0,0,0,0,0,0,0
0,0,0,0,0,0,0,0,0,0,0,0,0,0,0,0,0,0,0,0,0,0,0,0,0,0,0,0,0,0,0,0,0,0,0,0
0,0,0,0,0,0,0,0,0,0,0,0,0,0,0,0,0,0,0,0,0,0,0,0,0,0,0,0,0,0,0,0,0,0,0,0
0,0,0,0,0,0,0,0,0,0,0,0,0,0,0,0,0,0,0,0,0,0,0,0,0,0,0,0,0,0,0,0,0,0,0,0
:endlayer
layer: 13
0,0,0,0,0,0,0,0,0,0,0,0,0,0,0,0,0,0,0,0,0,0,0,0,0,0,0,0,0,0,0,0,0,0,0,0
0,0,0,0,0,0,0,0,0,0,0,0,0,0,0,0,0,0,0,0,0,0,0,0,0,0,0,0,0,0,0,0,0,0,0,0
0,0,0,0,0,0,0,0,0,0,0,0,0,0,0,8,8,8,8,8,8,0,0,0,0,0,0,0,0,0,0,0,0,0,0,0
0,0,0,0,0,0,0,0,0,0,0,0,0,0,8,8,8,8,8,8,8,8,0,0,0,0,0,0,0,0,0,0,0,0,0,0
0,0,0,0,0,0,0,0,0,0,0,0,0,8,8,13,29,0,0,28,13,8,8,0,0,0,0,0,0,0,0,0,0,0,0,0
0,0,0,0,0,0,0,0,0,0,0,0,0,8,8,0,0,0,0,0,0,8,8,0,0,0,0,0,0,0,0,0,0,0,0,0
0,0,0,0,0,0,0,0,0,0,0,0,0,8,8,0,0,0,0,0,0,8,8,0,0,0,0,0,0,0,0,0,0,0,0,0
0,0,0,0,0,0,0,0,0,0,0,0,8,8,8,21,0,0,0,0,21,8,8,8,0,0,0,0,0,0,0,0,0,0,0,0
0,0,0,0,0,0,0,0,0,0,0,0,8,8,13,0,0,0,0,0,0,13,8,8,0,0,0,0,0,0,0,0,0,0,0,0
0,0,0,0,8,8,0,8,8,8,8,0,8,8,0,0,0,0,0,0,0,0,8,8,0,8,8,8,8,0,8,8,0,0,0,0
0,0,0,0,8,8,8,8,8,8,8,8,8,8,0,0,0,0,0,0,0,0,8,8,8,8,8,8,8,8,8,8,0,0,0,0
0,0,0,0,8,8,8,0,0,0,0,8,8,13,0,0,0,0,0,0,0,0,13,8,8,0,0,0,0,8,8,8,0,0,0,0
0,0,0,0,0,8,8,13,0,0,0,0,0,0,0,0,0,0,0,0,0,0,0,0,0,0,0,0,13,8,8,0,0,0,0,0
0,0,0,0,0,8,8,0,0,0,0,0,0,0,0,0,0,0,0,0,0,0,0,0,0,0,0,0,0,8,8,0,0,0,0,0
0,0,0,0,0,8,8,0,0,0,0,0,0,0,0,0,0,0,0,0,0,0,0,0,0,0,0,0,0,8,8,0,0,0,0,0
0,0,0,0,0,8,8,13,0,0,0,0,0,0,0,0,0,0,0,0,0,0,0,0,0,0,0,0,13,8,8,0,0,0,0,0
0,0,0,0,8,8,8,24,36,36,24,8,8,0,0,0,0,0,0,0,0,0,0,8,8,24,36,36,24,8,8,8,0,0,0,0
0,0,0,0,8,8,8,8,8,8,8,8,8,0,0,0,0,0,0,0,0,0,0,8,8,8,8,8,8,8,8,8,0,0,0,0
0,0,0,0,0,8,8,19,19,19,19,8,0,0,0,0,0,0,0,0,0,0,0,0,8,19,19,19,19,8,8,0,0,0,0,0
0,0,0,0,0,8,8,19,19,19,19,8,0,0,0,0,0,0,0,0,0,0,0,0,8,19,19,19,19,8,8,0,0,0,0,0
0,0,0,0,0,8,8,19,19,19,19,8,0,0,0,0,0,0,0,0,0,0,0,0,8,19,19,19,19,8,8,0,0,0,0,0
0,0,0,0,0,8,8,19,19,19,19,8,0,0,0,0,0,0,0,0,0,0,0,0,8,19,19,19,19,8,8,0,0,0,0,0
0,0,0,0,0,8,8,19,19,19,19,8,0,0,0,0,0,0,0,0,0,0,0,0,8,19,19,19,19,8,8,0,0,0,0,0
0,0,0,0,0,8,8,19,19,19,19,8,0,0,0,0,0,0,0,0,0,0,0,0,8,19,19,19,19,8,8,0,0,0,0,0
0,0,0,0,0,8,8,19,19,19,19,8,0,0,0,0,0,0,0,0,0,0,0,0,8,19,19,19,19,8,8,0,0,0,0,0
0,0,0,0,0,8,8,19,19,19,19,8,0,0,0,0,0,0,0,0,0,0,0,0,8,19,19,19,19,8,8,0,0,0,0,0
0,0,0,0,0,8,8,19,19,19,19,8,0,0,0,0,0,0,0,0,0,0,0,0,8,19,19,19,19,8,8,0,0,0,0,0
0,0,0,0,0,8,8,19,19,19,19,8,0,0,0,0,0,0,0,0,0,0,0,0,8,19,19,19,19,8,8,0,0,0,0,0
0,0,0,0,8,8,8,8,8,8,8,8,8,0,0,0,0,0,0,0,0,0,0,8,8,8,8,8,8,8,8,8,0,0,0,0
0,0,0,0,8,8,8,8,8,8,8,8,8,8,8,8,8,8,8,8,8,8,8,8,8,8,8,8,8,8,8,8,0,0,0,0
0,0,0,0,0,8,8,19,19,19,19,8,8,19,19,19,19,19,19,19,19,19,19,8,8,19,19,19,19,8,8,0,0,0,0,0
0,0,0,0,0,8,8,19,19,19,19,8,8,19,19,19,19,19,19,19,19,19,19,8,8,19,19,19,19,8,8,0,0,0,0,0
0,0,0,0,0,8,8,19,19,19,19,8,8,19,19,19,19,19,19,19,19,19,19,8,8,19,19,19,19,8,8,0,0,0,0,0
0,0,0,0,0,8,8,19,19,19,19,8,8,19,19,19,19,19,19,19,19,19,19,8,8,19,19,19,19,8,8,0,0,0,0,0
0,0,0,0,8,8,8,19,19,19,19,8,8,19,19,19,19,19,19,19,19,19,19,8,8,19,19,19,19,8,8,8,0,0,0,0
0,0,0,0,8,8,8,19,19,19,19,8,8,19,19,19,19,19,19,19,19,19,19,8,8,19,19,19,19,8,8,8,0,0,0,0
0,0,0,0,0,8,8,13,19,19,13,8,8,19,19,19,19,19,19,19,19,19,19,8,8,13,19,19,13,8,8,0,0,0,0,0
0,0,0,0,0,8,8,19,6,0,19,8,8,19,19,19,19,19,19,19,19,19,19,8,8,19,0,6,19,8,8,0,0,0,0,0
0,0,0,0,0,8,8,19,0,0,19,8,8,19,19,19,19,19,19,19,19,19,19,8,8,19,0,0,19,8,8,0,0,0,0,0
0,0,0,0,0,8,8,13,19,19,13,8,8,19,19,19,19,19,19,19,19,19,19,8,8,13,19,19,13,8,8,0,0,0,0,0
0,0,0,0,8,8,8,8,8,8,8,8,8,8,8,8,8,8,8,8,8,8,8,8,8,8,8,8,8,8,8,8,0,0,0,0
0,0,0,0,8,8,8,8,8,8,8,8,8,8,8,8,8,8,8,8,8,8,8,8,8,8,8,8,8,8,8,8,0,0,0,0
0,0,0,0,8,8,8,0,0,0,0,8,8,0,0,0,0,0,0,0,0,0,0,8,8,0,0,0,0,8,8,8,0,0,0,0
0,0,0,0,0,0,0,0,0,0,0,0,0,0,0,0,0,0,0,0,0,0,0,0,0,0,0,0,0,0,0,0,0,0,0,0
0,0,0,0,0,0,0,0,0,0,0,0,0,0,0,0,0,0,0,0,0,0,0,0,0,0,0,0,0,0,0,0,0,0,0,0
0,0,0,0,0,0,0,0,0,0,0,0,0,0,0,0,0,0,0,0,0,0,0,0,0,0,0,0,0,0,0,0,0,0,0,0
0,0,0,0,0,0,0,0,0,0,0,0,0,0,0,0,0,0,0,0,0,0,0,0,0,0,0,0,0,0,0,0,0,0,0,0
:endlayer
layer: 14
0,0,0,0,0,0,0,0,0,0,0,0,0,0,0,0,0,0,0,0,0,0,0,0,0,0,0,0,0,0,0,0,0,0,0,0
0,0,0,0,0,0,0,0,0,0,0,0,0,0,0,0,0,0,0,0,0,0,0,0,0,0,0,0,0,0,0,0,0,0,0,0
0,0,0,0,0,0,0,0,0,0,0,0,0,0,0,8,8,8,8,8,8,0,0,0,0,0,0,0,0,0,0,0,0,0,0,0
0,0,0,0,0,0,0,0,0,0,0,0,0,0,8,8,8,8,8,8,8,8,0,0,0,0,0,0,0,0,0,0,0,0,0,0
0,0,0,0,0,0,0,0,0,0,0,0,0,8,8,13,0,36,36,0,13,8,8,0,0,0,0,0,0,0,0,0,0,0,0,0
0,0,0,0,0,0,0,0,0,0,0,0,0,8,8,34,0,0,0,0,34,8,8,0,0,0,0,0,0,0,0,0,0,0,0,0
0,0,0,0,0,0,0,0,0,0,0,0,0,8,8,34,0,0,0,0,34,8,8,0,0,0,0,0,0,0,0,0,0,0,0,0
0,0,0,0,0,0,0,0,0,0,0,0,8,8,8,29,0,0,0,0,28,8,8,8,0,0,0,0,0,0,0,0,0,0,0,0
0,0,0,0,0,0,0,0,0,0,0,0,8,8,13,0,0,0,0,0,0,13,8,8,0,0,0,0,0,0,0,0,0,0,0,0
0,0,0,0,8,8,0,8,8,8,8,0,8,8,31,0,0,0,0,0,0,31,8,8,0,8,8,8,8,0,8,8,0,0,0,0
0,0,0,0,8,8,8,8,8,8,8,8,8,8,34,0,0,0,0,0,0,34,8,8,8,8,8,8,8,8,8,8,0,0,0,0
0,0,0,0,8,8,8,29,0,0,0,8,8,13,0,0,0,0,0,0,0,0,13,8,8,0,0,0,28,8,8,8,0,0,0,0
0,0,0,0,0,8,8,13,0,0,0,0,0,0,0,0,0,0,0,0,0,0,0,0,0,0,0,0,13,8,8,0,0,0,0,0
0,0,0,0,0,8,8,31,0,0,0,0,0,0,0,0,0,0,0,0,0,0,0,0,0,0,0,0,31,8,8,0,0,0,0,0
0,0,0,0,0,8,8,30,0,0,0,0,0,0,0,0,0,0,0,0,0,0,0,0,0,0,0,0,30,8,8,0,0,0,0,0
0,0,0,0,0,8,8,13,0,0,0,0,0,0,0,0,0,0,0,0,0,0,0,0,0,0,0,0,13,8,8,0,0,0,0,0
0,0,0,0,8,8,8,29,0,0,30,8,8,0,0,0,0,0,0,0,0,0,0,8,8,30,0,0,28,8,8,8,0,0,0,0
0,0,0,0,8,8,8,13,21,21,13,8,8,0,0,0,0,0,0,0,0,0,0,8,8,13,21,21,13,8,8,8,0,0,0,0
0,0,0,0,0,8,8,13,0,0,0,13,29,0,0,0,0,0,0,0,0,0,0,28,13,0,0,0,13,8,8,0,0,0,0,0
0,0,0,0,0,8,8,0,0,0,0,21,0,0,0,0,0,0,0,0,0,0,0,0,21,0,0,0,0,8,8,0,0,0,0,0
0,0,0,0,0,8,8,0,0,0,0,21,0,0,0,0,0,0,0,0,0,0,0,0,21,0,0,0,0,8,8,0,0,0,0,0
0,0,0,0,0,8,8,0,0,0,0,13,29,0,0,0,0,0,0,0,0,0,0,28,13,0,0,0,0,8,8,0,0,0,0,0
0,0,0,0,0,8,8,0,0,0,0,21,0,0,0,0,0,0,0,0,0,0,0,0,21,0,0,0,0,8,8,0,0,0,0,0
0,0,0,0,0,8,8,0,0,0,0,21,0,0,0,0,0,0,0,0,0,0,0,0,21,0,0,0,0,8,8,0,0,0,0,0
0,0,0,0,0,8,8,0,0,0,0,13,29,0,0,0,0,0,0,0,0,0,0,28,13,0,0,0,0,8,8,0,0,0,0,0
0,0,0,0,0,8,8,0,0,0,0,21,0,0,0,0,0,0,0,0,0,0,0,0,21,0,0,0,0,8,8,0,0,0,0,0
0,0,0,0,0,8,8,0,0,0,0,21,0,0,0,0,0,0,0,0,0,0,0,0,21,0,0,0,0,8,8,0,0,0,0,0
0,0,0,0,0,8,8,13,0,0,0,13,29,0,0,0,0,0,0,0,0,0,0,28,13,0,0,0,13,8,8,0,0,0,0,0
0,0,0,0,8,8,8,0,0,0,0,8,8,30,0,0,30,0,0,30,0,0,30,8,8,0,0,0,0,8,8,8,0,0,0,0
0,0,0,0,8,8,8,0,0,0,0,8,8,13,21,21,13,21,21,13,21,21,13,8,8,0,0,0,0,8,8,8,0,0,0,0
0,0,0,0,0,8,8,13,0,0,0,0,0,0,0,0,0,0,0,0,0,0,0,0,0,0,0,0,13,8,8,0,0,0,0,0
0,0,0,0,0,8,8,0,0,0,0,0,0,0,0,0,0,0,0,0,0,0,0,0,0,0,0,0,0,8,8,0,0,0,0,0
0,0,0,0,0,8,8,0,0,0,0,0,0,0,0,0,4,0,0,4,0,0,0,0,0,0,0,0,0,8,8,0,0,0,0,0
0,0,0,0,0,8,8,13,0,0,0,0,0,0,0,0,0,0,0,0,0,0,0,0,0,0,0,0,13,8,8,0,0,0,0,0
0,0,0,0,8,8,8,0,0,0,0,13,13,0,0,0,0,0,0,0,0,0,0,13,13,0,0,0,0,8,8,8,0,0,0,0
0,0,0,0,8,8,8,0,0,0,0,13,13,0,0,0,4,0,0,4,0,0,0,13,13,0,0,0,0,8,8,8,0,0,0,0
0,0,0,0,0,8,8,13,0,0,13,0,0,0,0,0,0,0,0,0,0,0,0,0,0,13,0,0,13,8,8,0,0,0,0,0
0,0,0,0,0,8,8,0,0,0,21,0,0,0,0,0,0,0,0,0,0,0,0,0,0,21,0,0,0,8,8,0,0,0,0,0
0,0,0,0,0,8,8,0,0,0,21,0,0,0,0,0,4,0,0,4,0,0,0,0,0,21,0,0,0,8,8,0,0,0,0,0
0,0,0,0,0,8,8,13,0,0,13,0,0,13,0,0,0,0,0,0,0,0,13,0,0,13,0,0,13,8,8,0,0,0,0,0
0,0,0,0,8,8,8,8,8,8,8,8,8,8,8,8,8,8,8,8,8,8,8,8,8,8,8,8,8,8,8,8,0,0,0,0
0,0,0,0,8,8,8,8,8,8,8,8,8,8,8,8,8,8,8,8,8,8,8,8,8,8,8,8,8,8,8,8,0,0,0,0
0,0,0,0,8,8,8,0,0,0,0,8,8,0,0,0,0,0,0,0,0,0,0,8,8,0,0,0,0,8,8,8,0,0,0,0
0,0,0,0,0,0,0,0,0,0,0,0,0,0,0,0,0,0,0,0,0,0,0,0,0,0,0,0,0,0,0,0,0,0,0,0
0,0,0,0,0,0,0,0,0,0,0,0,0,0,0,0,0,0,0,0,0,0,0,0,0,0,0,0,0,0,0,0,0,0,0,0
0,0,0,0,0,0,0,0,0,0,0,0,0,0,0,0,0,0,0,0,0,0,0,0,0,0,0,0,0,0,0,0,0,0,0,0
0,0,0,0,0,0,0,0,0,0,0,0,0,0,0,0,0,0,0,0,0,0,0,0,0,0,0,0,0,0,0,0,0,0,0,0
:endlayer
layer: 15
0,0,0,0,0,0,0,0,0,0,0,0,0,0,0,0,0,0,0,0,0,0,0,0,0,0,0,0,0,0,0,0,0,0,0,0
0,0,0,0,0,0,0,0,0,0,0,0,0,0,0,0,0,0,0,0,0,0,0,0,0,0,0,0,0,0,0,0,0,0,0,0
0,0,0,0,0,0,0,0,0,0,0,0,0,0,0,8,8,0,0,8,8,0,0,0,0,0,0,0,0,0,0,0,0,0,0,0
0,0,0,0,0,0,0,0,0,0,0,0,0,0,8,8,8,35,35,8,8,8,0,0,0,0,0,0,0,0,0,0,0,0,0,0
0,0,0,0,0,0,0,0,0,0,0,0,0,8,8,13,25,0,0,25,13,8,8,0,0,0,0,0,0,0,0,0,0,0,0,0
0,0,0,0,0,0,0,0,0,0,0,0,0,0,35,0,0,0,0,0,0,35,0,0,0,0,0,0,0,0,0,0,0,0,0,0
0,0,0,0,0,0,0,0,0,0,0,0,0,0,35,0,0,0,0,0,0,35,0,0,0,0,0,0,0,0,0,0,0,0,0,0
0,0,0,0,0,0,0,0,0,0,0,0,8,8,8,21,0,0,0,0,21,8,8,8,0,0,0,0,0,0,0,0,0,0,0,0
0,0,0,0,0,0,0,0,0,0,0,0,8,8,13,0,0,0,0,0,0,13,8,8,0,0,0,0,0,0,0,0,0,0,0,0
0,0,0,0,8,8,0,8,0,0,8,0,8,8,4,0,0,0,0,0,0,4,8,8,0,8,0,0,8,0,8,8,0,0,0,0
0,0,0,0,8,8,8,8,35,35,8,8,8,8,0,0,0,0,0,0,0,0,8,8,8,8,35,35,8,8,8,8,0,0,0,0
0,0,0,0,8,8,8,0,0,0,0,8,8,13,0,0,0,0,0,0,0,0,13,8,8,0,0,0,0,8,8,8,0,0,0,0
0,0,0,0,0,8,8,13,0,0,0,0,0,0,0,0,0,0,0,0,0,0,0,0,0,0,0,0,13,8,8,0,0,0,0,0
0,0,0,0,0,0,35,0,0,0,0,0,0,0,0,0,0,0,0,0,0,0,0,0,0,0,0,0,0,35,0,0,0,0,0,0
0,0,0,0,0,0,35,0,0,0,0,0,0,0,0,0,0,0,0,0,0,0,0,0,0,0,0,0,0,35,0,0,0,0,0,0
0,0,0,0,0,8,8,13,0,0,0,0,0,0,0,0,0,0,0,0,0,0,0,0,0,0,0,0,13,8,8,0,0,0,0,0
0,0,0,0,8,8,8,0,0,0,0,8,8,0,0,0,0,0,0,0,0,0,0,8,8,0,0,0,0,8,8,8,0,0,0,0
0,0,0,0,8,8,8,13,36,36,13,8,8,0,0,0,0,0,0,0,0,0,0,8,8,13,36,36,13,8,8,8,0,0,0,0
0,0,0,0,0,8,8,13,0,0,0,13,4,0,0,0,0,0,0,0,0,0,0,4,13,0,0,0,13,8,8,0,0,0,0,0
0,0,0,0,0,0,35,0,0,0,0,36,0,0,0,0,0,0,0,0,0,0,0,0,36,0,0,0,0,35,0,0,0,0,0,0
0,0,0,0,0,0,35,0,0,0,0,36,0,0,0,0,0,0,0,0,0,0,0,0,36,0,0,0,0,35,0,0,0,0,0,0
0,0,0,0,0,8,8,0,0,0,0,13,4,0,0,0,0,0,0,0,0,0,0,4,13,0,0,0,0,8,8,0,0,0,0,0
0,0,0,0,0,0,35,0,0,0,0,36,0,0,0,0,0,0,0,0,0,0,0,0,36,0,0,0,0,35,0,0,0,0,0,0
0,0,0,0,0,0,35,0,0,0,0,36,0,0,0,0,0,0,0,0,0,0,0,0,36,0,0,0,0,35,0,0,0,0,0,0
0,0,0,0,0,8,8,0,0,0,0,13,4,0,0,0,0,0,0,0,0,0,0,4,13,0,0,0,0,8,8,0,0,0,0,0
0,0,0,0,0,0,35,0,0,0,0,36,0,0,0,0,0,0,0,0,0,0,0,0,36,0,0,0,0,35,0,0,0,0,0,0
0,0,0,0,0,0,35,0,0,0,0,36,0,0,0,0,0,0,0,0,0,0,0,0,36,0,0,0,0,35,0,0,0,0,0,0
0,0,0,0,0,8,8,13,0,0,0,13,4,0,0,0,0,0,0,0,0,0,0,4,13,0,0,0,13,8,8,0,0,0,0,0
0,0,0,0,8,8,8,0,0,0,0,8,8,4,0,0,4,0,0,4,0,0,4,8,8,0,0,0,0,8,8,8,0,0,0,0
0,0,0,0,8,8,8,0,0,0,0,8,8,13,36,36,13,36,36,13,36,36,13,8,8,0,0,0,0,8,8,8,0,0,0,0
0,0,0,0,0,8,8,13,0,0,0,0,0,0,0,0,0,0,0,0,0,0,0,0,0,0,0,0,13,8,8,0,0,0,0,0
0,0,0,0,0,0,35,0,0,0,0,0,0,0,0,0,0,0,0,0,0,0,0,0,0,0,0,0,0,35,0,0,0,0,0,0
0,0,0,0,0,0,35,0,0,0,0,0,0,0,0,0,0,0,0,0,0,0,0,0,0,0,0,0,0,35,0,0,0,0,0,0
0,0,0,0,0,8,8,13,0,0,0,0,0,0,0,0,0,0,0,0,0,0,0,0,0,0,0,0,13,8,8,0,0,0,0,0
0,0,0,0,8,8,8,0,0,0,0,13,13,0,0,0,0,0,0,0,0,0,0,13,13,0,0,0,0,8,8,8,0,0,0,0
0,0,0,0,8,8,8,0,0,0,0,13,13,0,0,0,0,0,0,0,0,0,0,13,13,0,0,0,0,8,8,8,0,0,0,0
0,0,0,0,0,8,8,13,0,0,13,0,0,0,0,0,0,0,0,0,0,0,0,0,0,13,0,0,13,8,8,0,0,0,0,0
0,0,0,0,0,0,35,0,0,0,21,0,0,0,0,0,0,0,0,0,0,0,0,0,0,21,0,0,0,35,0,0,0,0,0,0
0,0,0,0,0,0,35,0,0,0,21,0,0,0,0,0,0,0,0,0,0,0,0,0,0,21,0,0,0,35,0,0,0,0,0,0
0,0,0,0,0,8,8,13,0,0,13,0,0,13,0,0,0,0,0,0,0,0,13,0,0,13,0,0,13,8,8,0,0,0,0,0
0,0,0,0,8,8,8,8,35,35,8,8,8,8,35,35,8,35,35,8,35,35,8,8,8,8,35,35,8,8,8,8,0,0,0,0
0,0,0,0,8,8,8,8,0,0,8,8,8,8,0,0,8,0,0,8,0,0,8,8,8,8,0,0,8,8,8,8,0,0,0,0
0,0,0,0,8,8,8,0,0,0,0,8,8,0,0,0,0,0,0,0,0,0,0,8,8,0,0,0,0,8,8,8,0,0,0,0
0,0,0,0,0,0,0,0,0,0,0,0,0,0,0,0,0,0,0,0,0,0,0,0,0,0,0,0,0,0,0,0,0,0,0,0
0,0,0,0,0,0,0,0,0,0,0,0,0,0,0,0,0,0,0,0,0,0,0,0,0,0,0,0,0,0,0,0,0,0,0,0
0,0,0,0,0,0,0,0,0,0,0,0,0,0,0,0,0,0,0,0,0,0,0,0,0,0,0,0,0,0,0,0,0,0,0,0
0,0,0,0,0,0,0,0,0,0,0,0,0,0,0,0,0,0,0,0,0,0,0,0,0,0,0,0,0,0,0,0,0,0,0,0
:endlayer
layer: 16
0,0,0,0,0,0,0,0,0,0,0,0,0,0,0,0,0,0,0,0,0,0,0,0,0,0,0,0,0,0,0,0,0,0,0,0
0,0,0,0,0,0,0,0,0,0,0,0,0,0,0,0,0,0,0,0,0,0,0,0,0,0,0,0,0,0,0,0,0,0,0,0
0,0,0,0,0,0,0,0,0,0,0,0,0,0,0,8,8,0,0,8,8,0,0,0,0,0,0,0,0,0,0,0,0,0,0,0
0,0,0,0,0,0,0,0,0,0,0,0,0,0,8,8,8,35,35,8,8,8,0,0,0,0,0,0,0,0,0,0,0,0,0,0
0,0,0,0,0,0,0,0,0,0,0,0,0,8,8,13,0,0,0,0,13,8,8,0,0,0,0,0,0,0,0,0,0,0,0,0
0,0,0,0,0,0,0,0,0,0,0,0,0,0,35,0,0,0,0,0,0,35,0,0,0,0,0,0,0,0,0,0,0,0,0,0
0,0,0,0,0,0,0,0,0,0,0,0,0,0,35,0,0,0,0,0,0,35,0,0,0,0,0,0,0,0,0,0,0,0,0,0
0,0,0,0,0,0,0,0,0,0,0,0,8,8,8,21,0,0,0,0,21,8,8,8,0,0,0,0,0,0,0,0,0,0,0,0
0,0,0,0,0,0,0,0,0,0,0,0,8,8,13,0,0,0,0,0,0,13,8,8,0,0,0,0,0,0,0,0,0,0,0,0
0,0,0,0,8,8,0,8,0,0,8,0,8,8,0,0,0,0,0,0,0,0,8,8,0,8,0,0,8,0,8,8,0,0,0,0
0,0,0,0,8,8,8,8,35,35,8,8,8,8,0,0,0,0,0,0,0,0,8,8,8,8,35,35,8,8,8,8,0,0,0,0
0,0,0,0,8,8,8,25,0,0,25,8,8,13,0,0,0,0,0,0,0,0,13,8,8,25,0,0,25,8,8,8,0,0,0,0
0,0,0,0,0,8,8,13,23,0,0,0,0,0,0,0,0,0,0,0,0,0,0,0,0,0,0,22,13,8,8,0,0,0,0,0
0,0,0,0,0,0,35,0,0,0,0,0,0,0,0,0,0,0,0,0,0,0,0,0,0,0,0,0,0,35,0,0,0,0,0,0
0,0,0,0,0,0,35,0,0,0,0,0,0,0,0,0,0,0,0,0,0,0,0,0,0,0,0,0,0,35,0,0,0,0,0,0
0,0,0,0,0,8,8,13,23,0,0,0,0,0,0,0,0,0,0,0,0,0,0,0,0,0,0,22,13,8,8,0,0,0,0,0
0,0,0,0,8,8,8,0,0,0,0,8,8,0,0,0,0,0,0,0,0,0,0,8,8,0,0,0,0,8,8,8,0,0,0,0
0,0,0,0,8,8,8,13,0,0,13,8,8,0,0,0,0,0,0,0,0,0,0,8,8,13,0,0,13,8,8,8,0,0,0,0
0,0,0,0,0,8,8,13,23,0,0,13,0,0,0,0,0,0,0,0,0,0,0,0,13,0,0,0,13,8,8,0,0,0,0,0
0,0,0,0,0,0,35,0,0,0,0,0,0,0,0,0,0,0,0,0,0,0,0,0,0,0,0,0,0,35,0,0,0,0,0,0
0,0,0,0,0,0,35,0,0,0,0,0,0,0,0,0,0,0,0,0,0,0,0,0,0,0,0,0,0,35,0,0,0,0,0,0
0,0,0,0,22,8,8,23,0,0,0,13,0,0,0,0,0,0,0,0,0,0,0,0,13,0,0,0,22,8,8,23,0,0,0,0
0,0,0,0,0,0,35,0,0,0,0,0,0,0,0,0,0,0,0,0,0,0,0,0,0,0,0,0,0,35,0,0,0,0,0,0
0,0,0,0,0,0,35,0,0,0,0,0,0,0,0,0,0,0,0,0,0,0,0,0,0,0,0,0,0,35,0,0,0,0,0,0
0,0,0,0,22,8,8,23,0,0,0,13,0,0,0,0,0,0,0,0,0,0,0,0,13,0,0,0,22,8,8,23,0,0,0,0
0,0,0,0,0,0,35,0,0,0,0,0,0,0,0,0,0,0,0,0,0,0,0,0,0,0,0,0,0,35,0,0,0,0,0,0
0,0,0,0,0,0,35,0,0,0,0,0,0,0,0,0,0,0,0,0,0,0,0,0,0,0,0,0,0,35,0,0,0,0,0,0
0,0,0,0,0,8,8,13,23,0,0,13,0,0,0,0,0,0,0,0,0,0,0,0,13,0,0,22,13,8,8,0,0,0,0,0
0,0,0,0,8,8,8,0,0,0,0,8,8,0,0,0,0,0,0,0,0,0,0,8,8,0,0,0,0,8,8,8,0,0,0,0
0,0,0,0,8,8,8,0,0,0,0,8,8,13,0,0,13,0,0,13,0,0,13,8,8,0,0,0,0,8,8,8,0,0,0,0
0,0,0,0,0,8,8,13,23,0,0,0,0,0,0,0,0,0,0,0,0,0,0,0,0,0,0,22,13,8,8,0,0,0,0,0
0,0,0,0,0,0,35,0,0,0,0,0,0,0,0,0,0,0,0,0,0,0,0,0,0,0,0,0,0,35,0,0,0,0,0,0
0,0,0,0,0,0,35,0,0,0,0,0,0,0,0,0,0,0,0,0,0,0,0,0,0,0,0,0,0,35,0,0,0,0,0,0
0,0,0,0,0,8,8,13,23,0,0,0,0,0,0,0,0,0,0,0,0,0,0,0,0,0,0,22,13,8,8,0,0,0,0,0
0,0,0,0,8,8,8,0,0,0,0,13,13,0,0,0,0,0,0,0,0,0,0,13,13,0,0,0,0,8,8,8,0,0,0,0
0,0,0,0,8,8,8,0,0,0,24,13,13,0,0,0,0,0,0,0,0,0,0,13,13,24,0,0,0,8,8,8,0,0,0,0
0,0,0,0,0,8,8,13,0,0,13,23,0,0,0,0,0,0,0,0,0,0,0,0,22,13,0,0,13,8,8,0,0,0,0,0
0,0,0,0,0,0,35,0,0,0,21,0,0,0,0,0,0,0,0,0,0,0,0,0,0,21,0,0,0,35,0,0,0,0,0,0
0,0,0,0,0,0,35,24,0,0,21,0,0,24,0,0,0,0,0,0,0,0,24,0,0,21,0,0,24,35,0,0,0,0,0,0
0,0,0,0,0,8,8,13,23,0,13,0,0,13,0,0,24,0,0,24,0,0,13,0,0,13,0,22,13,8,8,0,0,0,0,0
0,0,0,0,8,8,8,8,35,35,8,8,8,8,35,35,8,35,35,8,35,35,8,8,8,8,35,35,8,8,8,8,0,0,0,0
0,0,0,0,8,8,8,8,0,0,8,8,8,8,0,0,8,0,0,8,0,0,8,8,8,8,0,0,8,8,8,8,0,0,0,0
0,0,0,0,8,8,8,0,0,0,0,8,8,0,0,0,25,0,0,25,0,0,0,8,8,0,0,0,0,8,8,8,0,0,0,0
0,0,0,0,0,0,0,0,0,0,0,0,0,0,0,0,0,0,0,0,0,0,0,0,0,0,0,0,0,0,0,0,0,0,0,0
0,0,0,0,0,0,0,0,0,0,0,0,0,0,0,0,0,0,0,0,0,0,0,0,0,0,0,0,0,0,0,0,0,0,0,0
0,0,0,0,0,0,0,0,0,0,0,0,0,0,0,0,0,0,0,0,0,0,0,0,0,0,0,0,0,0,0,0,0,0,0,0
0,0,0,0,0,0,0,0,0,0,0,0,0,0,0,0,0,0,0,0,0,0,0,0,0,0,0,0,0,0,0,0,0,0,0,0
:endlayer
layer: 17
0,0,0,0,0,0,0,0,0,0,0,0,0,0,0,0,0,0,0,0,0,0,0,0,0,0,0,0,0,0,0,0,0,0,0,0
0,0,0,0,0,0,0,0,0,0,0,0,0,0,0,0,0,0,0,0,0,0,0,0,0,0,0,0,0,0,0,0,0,0,0,0
0,0,0,0,0,0,0,0,0,0,0,0,0,0,0,8,8,0,0,8,8,0,0,0,0,0,0,0,0,0,0,0,0,0,0,0
0,0,0,0,0,0,0,0,0,0,0,0,0,0,8,8,8,35,35,8,8,8,0,0,0,0,0,0,0,0,0,0,0,0,0,0
0,0,0,0,0,0,0,0,0,0,0,0,0,8,8,13,0,0,0,0,13,8,8,0,0,0,0,0,0,0,0,0,0,0,0,0
0,0,0,0,0,0,0,0,0,0,0,0,0,0,35,0,0,0,0,0,0,35,0,0,0,0,0,0,0,0,0,0,0,0,0,0
0,0,0,0,0,0,0,0,0,0,0,0,0,0,35,0,0,0,0,0,0,35,0,0,0,0,0,0,0,0,0,0,0,0,0,0
0,0,0,0,0,0,0,0,0,0,0,0,8,8,8,21,0,0,0,0,21,8,8,8,0,0,0,0,0,0,0,0,0,0,0,0
0,0,0,0,0,0,0,0,0,0,0,0,8,8,13,0,0,0,0,0,0,13,8,8,0,0,0,0,0,0,0,0,0,0,0,0
0,0,0,0,8,8,0,8,0,0,8,0,8,8,0,0,0,0,0,0,0,0,8,8,0,8,0,0,8,0,8,8,0,0,0,0
0,0,0,0,8,8,8,8,35,35,8,8,8,8,0,0,0,0,0,0,0,0,8,8,8,8,35,35,8,8,8,8,0,0,0,0
0,0,0,0,8,8,8,0,0,0,0,8,8,13,0,0,0,0,0,0,0,0,13,8,8,0,0,0,0,8,8,8,0,0,0,0
0,0,0,0,0,8,8,13,0,0,0,0,0,0,0,0,0,0,0,0,0,0,0,0,0,0,0,0,13,8,8,0,0,0,0,0
0,0,0,0,0,0,35,0,0,0,0,0,0,0,0,0,0,0,0,0,0,0,0,0,0,0,0,0,0,35,0,0,0,0,0,0
0,0,0,0,0,0,35,0,0,0,0,0,0,0,0,0,0,0,0,0,0,0,0,0,0,0,0,0,0,35,0,0,0,0,0,0
0,0,0,0,0,8,8,13,0,0,0,0,0,0,0,0,0,0,0,0,0,0,0,0,0,0,0,0,13,8,8,0,0,0,0,0
0,0,0,0,8,8,8,0,0,0,0,8,8,0,0,0,0,0,0,0,0,0,0,8,8,0,0,0,0,8,8,8,0,0,0,0
0,0,0,0,8,8,8,13,0,0,13,8,8,0,0,0,0,0,0,0,0,0,0,8,8,13,0,0,13,8,8,8,0,0,0,0
0,0,0,0,0,8,8,13,0,0,0,13,0,0,0,0,0,0,0,0,0,0,0,0,13,0,0,0,13,8,8,0,0,0,0,0
0,0,0,0,0,0,35,0,0,0,0,0,0,0,0,0,0,0,0,0,0,0,0,0,0,0,0,0,0,35,0,0,0,0,0,0
0,0,0,0,0,0,35,0,0,0,0,0,0,0,0,0,0,0,0,0,0,0,0,0,0,0,0,0,0,35,0,0,0,0,0,0
0,0,0,0,0,8,8,0,0,0,0,13,0,0,0,0,0,0,0,0,0,0,0,0,13,0,0,0,0,8,8,0,0,0,0,0
0,0,0,0,0,0,35,0,0,0,0,0,0,0,0,0,0,0,0,0,0,0,0,0,0,0,0,0,0,35,0,0,0,0,0,0
0,0,0,0,0,0,35,0,0,0,0,0,0,0,0,0,0,0,0,0,0,0,0,0,0,0,0,0,0,35,0,0,0,0,0,0
0,0,0,0,0,8,8,0,0,0,0,13,0,0,0,0,0,0,0,0,0,0,0,0,13,0,0,0,0,8,8,0,0,0,0,0
0,0,0,0,0,0,35,0,0,0,0,0,0,0,0,0,0,0,0,0,0,0,0,0,0,0,0,0,0,35,0,0,0,0,0,0
0,0,0,0,0,0,35,0,0,0,0,0,0,0,0,0,0,0,0,0,0,0,0,0,0,0,0,0,0,35,0,0,0,0,0,0
0,0,0,0,0,8,8,13,0,0,0,13,0,0,0,0,0,0,0,0,0,0,0,0,13,0,0,0,13,8,8,0,0,0,0,0
0,0,0,0,8,8,8,0,0,0,0,8,8,0,0,0,0,0,0,0,0,0,0,8,8,0,0,0,0,8,8,8,0,0,0,0
0,0,0,0,8,8,8,0,0,0,0,8,8,13,0,0,13,0,0,13,0,0,13,8,8,0,0,0,0,8,8,8,0,0,0,0
0,0,0,0,0,8,8,13,0,0,0,0,0,0,0,0,0,0,0,0,0,0,0,0,0,0,0,0,13,8,8,0,0,0,0,0
0,0,0,0,0,0,35,0,0,0,0,0,0,0,0,0,0,0,0,0,0,0,0,0,0,0,0,0,0,35,0,0,0,0,0,0
0,0,0,0,0,0,35,0,0,0,0,0,0,0,0,0,0,0,0,0,0,0,0,0,0,0,0,0,0,35,0,0,0,0,0,0
0,0,0,0,0,8,8,13,0,0,0,0,0,0,0,0,0,0,0,0,0,0,0,0,0,0,0,0,13,8,8,0,0,0,0,0
0,0,0,0,8,8,8,0,0,0,0,13,13,0,0,0,0,0,0,0,0,0,0,13,13,0,0,0,0,8,8,8,0,0,0,0
0,0,0,0,8,8,8,0,0,0,0,13,13,0,0,0,0,0,0,0,0,0,0,13,13,0,0,0,0,8,8,8,0,0,0,0
0,0,0,0,0,8,8,13,0,0,13,0,0,0,0,0,0,0,0,0,0,0,0,0,0,13,0,0,13,8,8,0,0,0,0,0
0,0,0,0,0,0,35,0,0,0,21,0,0,0,0,0,0,0,0,0,0,0,0,0,0,21,0,0,0,35,0,0,0,0,0,0
0,0,0,0,0,0,35,0,0,0,21,0,0,0,0,0,0,0,0,0,0,0,0,0,0,21,0,0,0,35,0,0,0,0,0,0
0,0,0,0,0,8,8,13,0,0,13,0,0,13,0,0,0,0,0,0,0,0,13,0,0,13,0,0,13,8,8,0,0,0,0,0
0,0,0,0,8,8,8,8,35,35,8,8,8,8,35,35,8,35,35,8,35,35,8,8,8,8,35,35,8,8,8,8,0,0,0,0
0,0,0,0,8,8,8,8,0,0,8,8,8,8,0,0,8,0,0,8,0,0,8,8,8,8,0,0,8,8,8,8,0,0,0,0
0,0,0,0,8,8,8,0,0,0,0,8,8,0,0,0,0,0,0,0,0,0,0,8,8,0,0,0,0,8,8,8,0,0,0,0
0,0,0,0,0,0,0,0,0,0,0,0,0,0,0,0,0,0,0,0,0,0,0,0,0,0,0,0,0,0,0,0,0,0,0,0
0,0,0,0,0,0,0,0,0,0,0,0,0,0,0,0,0,0,0,0,0,0,0,0,0,0,0,0,0,0,0,0,0,0,0,0
0,0,0,0,0,0,0,0,0,0,0,0,0,0,0,0,0,0,0,0,0,0,0,0,0,0,0,0,0,0,0,0,0,0,0,0
0,0,0,0,0,0,0,0,0,0,0,0,0,0,0,0,0,0,0,0,0,0,0,0,0,0,0,0,0,0,0,0,0,0,0,0
:endlayer
layer: 18
0,0,0,0,0,0,0,0,0,0,0,0,0,0,0,0,0,0,0,0,0,0,0,0,0,0,0,0,0,0,0,0,0,0,0,0
0,0,0,0,0,0,0,0,0,0,0,0,0,0,0,0,0,0,0,0,0,0,0,0,0,0,0,0,0,0,0,0,0,0,0,0
0,0,0,0,0,0,0,0,0,0,0,0,0,0,0,8,8,27,26,8,8,0,0,0,0,0,0,0,0,0,0,0,0,0,0,0
0,0,0,0,0,0,0,0,0,0,0,0,0,0,8,8,8,35,35,8,8,8,0,0,0,0,0,0,0,0,0,0,0,0,0,0
0,0,0,0,0,0,0,0,0,0,0,0,0,8,8,13,0,0,0,0,13,8,8,0,0,0,0,0,0,0,0,0,0,0,0,0
0,0,0,0,0,0,0,0,0,0,0,0,0,33,35,0,0,0,0,0,0,35,33,0,0,0,0,0,0,0,0,0,0,0,0,0
0,0,0,0,0,0,0,0,0,0,0,0,0,32,35,0,0,0,0,0,0,35,32,0,0,0,0,0,0,0,0,0,0,0,0,0
0,0,0,0,0,0,0,0,0,0,0,0,8,8,8,21,0,0,0,0,21,8,8,8,0,0,0,0,0,0,0,0,0,0,0,0
0,0,0,0,0,0,0,0,0,0,0,0,8,8,13,0,0,0,0,0,0,13,8,8,0,0,0,0,0,0,0,0,0,0,0,0
0,0,0,0,8,8,0,8,27,26,8,0,8,8,0,0,0,0,0,0,0,0,8,8,0,8,27,26,8,0,8,8,0,0,0,0
0,0,0,0,8,8,8,8,35,35,8,8,8,8,0,0,0,0,0,0,0,0,8,8,8,8,35,35,8,8,8,8,0,0,0,0
0,0,0,0,8,8,8,0,0,0,0,8,8,13,0,0,0,0,0,0,0,0,13,8,8,0,0,0,0,8,8,8,0,0,0,0
0,0,0,0,0,8,8,13,0,0,0,0,0,0,0,0,0,0,0,0,0,0,0,0,0,0,0,0,13,8,8,0,0,0,0,0
0,0,0,0,0,33,35,0,0,0,0,0,0,0,0,0,0,0,0,0,0,0,0,0,0,0,0,0,0,35,33,0,0,0,0,0
0,0,0,0,0,32,35,0,0,0,0,0,0,0,0,0,0,0,0,0,0,0,0,0,0,0,0,0,0,35,32,0,0,0,0,0
0,0,0,0,0,8,8,13,0,0,0,0,0,0,0,0,0,0,0,0,0,0,0,0,0,0,0,0,13,8,8,0,0,0,0,0
0,0,0,0,8,8,8,0,0,0,0,8,8,0,0,0,0,0,0,0,0,0,0,8,8,0,0,0,0,8,8,8,0,0,0,0
0,0,0,0,8,8,8,13,0,0,13,8,8,0,0,0,0,0,0,0,0,0,0,8,8,13,0,0,13,8,8,8,0,0,0,0
0,0,0,0,0,8,8,13,0,0,0,13,0,0,0,0,0,0,0,0,0,0,0,0,13,0,0,0,13,8,8,0,0,0,0,0
0,0,0,0,0,33,35,0,0,0,0,0,0,0,0,0,0,0,0,0,0,0,0,0,0,0,0,0,0,35,33,0,0,0,0,0
0,0,0,0,0,32,35,0,0,0,0,0,0,0,0,0,0,0,0,0,0,0,0,0,0,0,0,0,0,35,32,0,0,0,0,0
0,0,0,0,0,8,8,0,0,0,0,13,0,0,0,0,0,0,0,0,0,0,0,0,13,0,0,0,0,8,8,0,0,0,0,0
0,0,0,0,0,33,35,0,0,0,0,0,0,0,0,0,0,0,0,0,0,0,0,0,0,0,0,0,0,35,33,0,0,0,0,0
0,0,0,0,0,32,35,0,0,0,0,0,0,0,0,0,0,0,0,0,0,0,0,0,0,0,0,0,0,35,32,0,0,0,0,0
0,0,0,0,0,8,8,0,0,0,0,13,0,0,0,0,0,0,0,0,0,0,0,0,13,0,0,0,0,8,8,0,0,0,0,0
0,0,0,0,0,33,35,0,0,0,0,0,0,0,0,0,0,0,0,0,0,0,0,0,0,0,0,0,0,35,33,0,0,0,0,0
0,0,0,0,0,32,35,0,0,0,0,0,0,0,0,0,0,0,0,0,0,0,0,0,0,0,0,0,0,35,32,0,0,0,0,0
0,0,0,0,0,8,8,13,0,0,0,13,0,0,0,0,0,0,0,0,0,0,0,0,13,0,0,0,13,8,8,0,0,0,0,0
0,0,0,0,8,8,8,0,0,0,0,8,8,0,0,0,0,0,0,0,0,0,0,8,8,0,0,0,0,8,8,8,0,0,0,0
0,0,0,0,8,8,8,0,0,0,0,8,8,13,0,0,13,0,0,13,0,0,13,8,8,0,0,0,0,8,8,8,0,0,0,0
0,0,0,0,0,8,8,13,0,0,0,0,0,0,0,0,0,0,0,0,0,0,0,0,0,0,0,0,13,8,8,0,0,0,0,0
0,0,0,0,0,33,35,0,0,0,0,0,0,0,0,0,0,0,0,0,0,0,0,0,0,0,0,0,0,35,33,0,0,0,0,0
0,0,0,0,0,32,35,0,0,0,0,0,0,0,0,0,0,0,0,0,0,0,0,0,0,0,0,0,0,35,32,0,0,0,0,0
0,0,0,0,0,8,8,13,0,0,0,0,0,0,0,0,0,0,0,0,0,0,0,0,0,0,0,0,13,8,8,0,0,0,0,0
0,0,0,0,8,8,8,0,0,0,0,13,13,0,0,0,0,0,0,0,0,0,0,13,13,0,0,0,0,8,8,8,0,0,0,0
0,0,0,0,8,8,8,0,0,0,0,13,13,0,0,0,0,0,0,0,0,0,0,13,13,0,0,0,0,8,8,8,0,0,0,0
0,0,0,0,0,8,8,13,0,0,13,0,0,0,0,0,0,0,0,0,0,0,0,0,0,13,0,0,13,8,8,0,0,0,0,0
0,0,0,0,0,33,35,0,0,0,21,0,0,0,0,0,0,0,0,0,0,0,0,0,0,21,0,0,0,35,33,0,0,0,0,0
0,0,0,0,0,32,35,0,0,0,21,0,0,0,0,0,0,0,0,0,0,0,0,0,0,21,0,0,0,35,32,0,0,0,0,0
0,0,0,0,0,8,8,13,0,0,13,0,0,13,0,0,0,0,0,0,0,0,13,0,0,13,0,0,13,8,8,0,0,0,0,0
0,0,0,0,8,8,8,8,35,35,8,8,8,8,35,35,8,35,35,8,35,35,8,8,8,8,35,35,8,8,8,8,0,0,0,0
0,0,0,0,8,8,8,8,27,26,8,8,8,8,27,26,8,27,26,8,27,26,8,8,8,8,27,26,8,8,8,8,0,0,0,0
0,0,0,0,8,8,8,0,0,0,0,8,8,0,0,0,0,0,0,0,0,0,0,8,8,0,0,0,0,8,8,8,0,0,0,0
0,0,0,0,0,0,0,0,0,0,0,0,0,0,0,0,0,0,0,0,0,0,0,0,0,0,0,0,0,0,0,0,0,0,0,0
0,0,0,0,0,0,0,0,0,0,0,0,0,0,0,0,0,0,0,0,0,0,0,0,0,0,0,0,0,0,0,0,0,0,0,0
0,0,0,0,0,0,0,0,0,0,0,0,0,0,0,0,0,0,0,0,0,0,0,0,0,0,0,0,0,0,0,0,0,0,0,0
0,0,0,0,0,0,0,0,0,0,0,0,0,0,0,0,0,0,0,0,0,0,0,0,0,0,0,0,0,0,0,0,0,0,0,0
:endlayer
layer: 19
0,0,0,0,0,0,0,0,0,0,0,0,0,0,0,0,0,0,0,0,0,0,0,0,0,0,0,0,0,0,0,0,0,0,0,0
0,0,0,0,0,0,0,0,0,0,0,0,0,0,0,0,0,0,0,0,0,0,0,0,0,0,0,0,0,0,0,0,0,0,0,0
0,0,0,0,0,0,0,0,0,0,0,0,0,0,0,8,8,8,8,8,8,0,0,0,0,0,0,0,0,0,0,0,0,0,0,0
0,0,0,0,0,0,0,0,0,0,0,0,0,0,8,8,8,8,8,8,8,8,0,0,0,0,0,0,0,0,0,0,0,0,0,0
0,0,0,0,0,0,0,0,0,0,0,0,0,8,8,13,29,0,0,28,13,8,8,0,0,0,0,0,0,0,0,0,0,0,0,0
0,0,0,0,0,0,0,0,0,0,0,0,0,8,8,0,0,0,0,0,0,8,8,0,0,0,0,0,0,0,0,0,0,0,0,0
0,0,0,0,0,0,0,0,0,0,0,0,0,8,8,0,0,0,0,0,0,8,8,0,0,0,0,0,0,0,0,0,0,0,0,0
0,0,0,0,0,0,0,0,0,0,0,0,8,8,8,21,0,0,0,0,21,8,8,8,0,0,0,0,0,0,0,0,0,0,0,0
0,0,0,0,0,0,0,0,0,0,0,0,8,8,13,0,0,0,0,0,0,13,8,8,0,0,0,0,0,0,0,0,0,0,0,0
0,0,0,0,8,8,0,8,8,8,8,0,8,8,0,0,0,0,0,0,0,0,8,8,0,8,8,8,8,0,8,8,0,0,0,0
0,0,0,0,8,8,8,8,8,8,8,8,8,8,0,0,0,0,0,0,0,0,8,8,8,8,8,8,8,8,8,8,0,0,0,0
0,0,0,0,8,8,8,0,0,0,0,8,8,13,0,0,0,0,0,0,0,0,13,8,8,0,0,0,0,8,8,8,0,0,0,0
0,0,0,0,0,8,8,13,0,0,0,0,0,0,0,0,0,0,0,0,0,0,0,0,0,0,0,0,13,8,8,0,0,0,0,0
0,0,0,0,0,8,8,0,0,0,0,0,0,0,0,0,0,0,0,0,0,0,0,0,0,0,0,0,0,8,8,0,0,0,0,0
0,0,0,0,0,8,8,0,0,0,0,0,0,0,0,0,0,0,0,0,0,0,0,0,0,0,0,0,0,8,8,0,0,0,0,0
0,0,0,0,0,8,8,13,0,0,0,0,0,0,0,0,0,0,0,0,0,0,0,0,0,0,0,0,13,8,8,0,0,0,0,0
0,0,0,0,8,8,8,21,0,0,21,8,8,0,0,0,0,0,0,0,0,0,0,8,8,21,0,0,21,8,8,8,0,0,0,0
0,0,0,0,8,8,8,13,29,28,13,8,8,0,0,0,0,0,0,0,0,0,0,8,8,13,29,28,13,8,8,8,0,0,0,0
0,0,0,0,0,8,8,13,0,0,0,13,21,0,0,0,0,0,0,0,0,0,0,21,13,0,0,0,13,8,8,0,0,0,0,0
0,0,0,0,0,8,8,0,0,0,0,31,0,0,0,0,0,0,0,0,0,0,0,0,31,0,0,0,0,8,8,0,0,0,0,0
0,0,0,0,0,8,8,0,0,0,0,30,0,0,0,0,0,0,0,0,0,0,0,0,30,0,0,0,0,8,8,0,0,0,0,0
0,0,0,0,0,8,8,0,0,0,0,13,21,0,0,0,0,0,0,0,0,0,0,21,13,0,0,0,0,8,8,0,0,0,0,0
0,0,0,0,0,8,8,0,0,0,0,31,0,0,0,0,0,0,0,0,0,0,0,0,31,0,0,0,0,8,8,0,0,0,0,0
0,0,0,0,0,8,8,0,0,0,0,30,0,0,0,0,0,0,0,0,0,0,0,0,30,0,0,0,0,8,8,0,0,0,0,0
0,0,0,0,0,8,8,0,0,0,0,13,21,0,0,0,0,0,0,0,0,0,0,21,13,0,0,0,0,8,8,0,0,0,0,0
0,0,0,0,0,8,8,0,0,0,0,31,0,0,0,0,0,0,0,0,0,0,0,0,31,0,0,0,0,8,8,0,0,0,0,0
0,0,0,0,0,8,8,0,0,0,0,30,0,0,0,0,0,0,0,0,0,0,0,0,30,0,0,0,0,8,8,0,0,0,0,0
0,0,0,0,0,8,8,13,0,0,0,13,21,0,0,0,0,0,0,0,0,0,0,21,13,0,0,0,13,8,8,0,0,0,0,0
0,0,0,0,8,8,8,0,0,0,0,8,8,21,0,0,21,0,0,21,0,0,21,8,8,0,0,0,0,8,8,8,0,0,0,0
0,0,0,0,8,8,8,0,0,0,0,8,8,13,29,28,13,29,28,13,29,28,13,8,8,0,0,0,0,8,8,8,0,0,0,0
0,0,0,0,0,8,8,13,0,0,0,0,0,0,0,0,0,0,0,0,0,0,0,0,0,0,0,0,13,8,8,0,0,0,0,0
0,0,0,0,0,8,8,0,0,0,0,0,0,0,0,0,0,0,0,0,0,0,0,0,0,0,0,0,0,8,8,0,0,0,0,0
0,0,0,0,0,8,8,0,0,0,0,0,0,0,0,0,0,0,0,0,0,0,0,0,0,0,0,0,0,8,8,0,0,0,0,0
0,0,0,0,0,8,8,13,0,0,0,0,0,0,0,0,0,0,0,0,0,0,0,0,0,0,0,0,13,8,8,0,0,0,0,0
0,0,0,0,8,8,8,0,0,0,0,13,13,0,0,0,0,0,0,0,0,0,0,13,13,0,0,0,0,8,8,8,0,0,0,0
0,0,0,0,8,8,8,0,0,0,0,13,13,0,0,0,0,0,0,0,0,0,0,13,13,0,0,0,0,8,8,8,0,0,0,0
0,0,0,0,0,8,8,13,0,0,13,0,0,0,0,0,0,0,0,0,0,0,0,0,0,13,0,0,13,8,8,0,0,0,0,0
0,0,0,0,0,8,8,0,0,0,21,0,0,0,0,0,0,0,0,0,0,0,0,0,0,21,0,0,0,8,8,0,0,0,0,0
0,0,0,0,0,8,8,0,0,0,21,0,0,0,0,0,0,0,0,0,0,0,0,0,0,21,0,0,0,8,8,0,0,0,0,0
0,0,0,0,0,8,8,13,0,0,13,0,0,13,0,0,0,0,0,0,0,0,13,0,0,13,0,0,13,8,8,0,0,0,0,0
0,0,0,0,8,8,8,8,8,8,8,8,8,8,8,8,8,8,8,8,8,8,8,8,8,8,8,8,8,8,8,8,0,0,0,0
0,0,0,0,8,8,8,8,8,8,8,8,8,8,8,8,8,8,8,8,8,8,8,8,8,8,8,8,8,8,8,8,0,0,0,0
0,0,0,0,8,8,8,0,0,0,0,8,8,0,0,0,0,0,0,0,0,0,0,8,8,0,0,0,0,8,8,8,0,0,0,0
0,0,0,0,0,0,0,0,0,0,0,0,0,0,0,0,0,0,0,0,0,0,0,0,0,0,0,0,0,0,0,0,0,0,0,0
0,0,0,0,0,0,0,0,0,0,0,0,0,0,0,0,0,0,0,0,0,0,0,0,0,0,0,0,0,0,0,0,0,0,0,0
0,0,0,0,0,0,0,0,0,0,0,0,0,0,0,0,0,0,0,0,0,0,0,0,0,0,0,0,0,0,0,0,0,0,0,0
0,0,0,0,0,0,0,0,0,0,0,0,0,0,0,0,0,0,0,0,0,0,0,0,0,0,0,0,0,0,0,0,0,0,0,0
:endlayer
layer: 20
0,0,0,0,0,0,0,0,0,0,0,0,0,0,0,0,0,0,0,0,0,0,0,0,0,0,0,0,0,0,0,0,0,0,0,0
0,0,0,0,0,0,0,0,0,0,0,0,0,0,0,0,0,0,0,0,0,0,0,0,0,0,0,0,0,0,0,0,0,0,0,0
0,0,0,0,0,0,0,0,0,0,0,0,0,0,0,8,8,8,8,8,8,0,0,0,0,0,0,0,0,0,0,0,0,0,0,0
0,0,0,0,0,0,0,0,0,0,0,0,0,0,8,8,8,8,8,8,8,8,0,0,0,0,0,0,0,0,0,0,0,0,0,0
0,0,0,0,0,0,0,0,0,0,0,0,0,8,8,13,0,36,36,0,13,8,8,0,0,0,0,0,0,0,0,0,0,0,0,0
0,0,0,0,0,0,0,0,0,0,0,0,0,8,8,0,0,0,0,0,0,8,8,0,0,0,0,0,0,0,0,0,0,0,0,0
0,0,0,0,0,0,0,0,0,0,0,0,0,8,8,0,0,0,0,0,0,8,8,0,0,0,0,0,0,0,0,0,0,0,0,0
0,0,0,0,0,0,0,0,0,0,0,0,8,8,8,21,0,0,0,0,21,8,8,8,0,0,0,0,0,0,0,0,0,0,0,0
0,0,0,0,0,0,0,0,0,0,0,0,8,8,13,0,0,0,0,0,0,13,8,8,0,0,0,0,0,0,0,0,0,0,0,0
0,0,0,0,8,8,0,8,8,8,8,0,8,8,31,0,0,0,0,0,0,31,8,8,0,8,8,8,8,0,8,8,0,0,0,0
0,0,0,0,8,8,8,8,8,8,8,8,8,8,34,0,0,0,0,0,0,34,8,8,8,8,8,8,8,8,8,8,0,0,0,0
0,0,0,0,8,8,8,27,0,0,26,8,8,13,0,0,0,0,0,0,0,0,13,8,8,27,0,0,26,8,8,8,0,0,0,0
0,0,0,0,0,8,8,13,0,0,0,0,0,0,0,0,0,0,0,0,0,0,0,0,0,0,0,0,13,8,8,0,0,0,0,0
0,0,0,0,0,8,8,0,0,0,0,0,0,0,0,0,0,0,0,0,0,0,0,0,0,0,0,0,0,8,8,0,0,0,0,0
0,0,0,0,0,8,8,0,0,0,0,0,0,0,0,0,0,0,0,0,0,0,0,0,0,0,0,0,0,8,8,0,0,0,0,0
0,0,0,0,0,8,8,13,0,0,0,0,0,0,0,0,0,0,0,0,0,0,0,0,0,0,0,0,13,8,8,0,0,0,0,0
0,0,0,0,8,8,8,30,34,34,30,8,8,0,0,0,0,0,0,0,0,0,0,8,8,30,34,34,30,8,8,8,0,0,0,0
0,0,0,0,8,8,8,20,20,20,20,8,8,0,0,0,0,0,0,0,0,0,0,8,8,20,20,20,20,8,8,8,0,0,0,0
0,0,0,0,0,8,8,13,0,0,25,18,29,0,0,0,0,0,0,0,0,0,0,28,18,25,0,0,13,8,8,0,0,0,0,0
0,0,0,0,0,8,8,31,0,0,0,18,34,0,0,0,0,0,0,0,0,0,0,34,18,0,0,0,31,8,8,0,0,0,0,0
0,0,0,0,0,8,8,0,0,0,0,18,34,0,0,0,0,0,0,0,0,0,0,34,18,0,0,0,0,8,8,0,0,0,0,0
0,0,0,0,0,8,8,0,0,0,22,18,29,0,0,0,0,0,0,0,0,0,0,28,18,23,0,0,0,8,8,0,0,0,0,0
0,0,0,0,0,8,8,0,0,0,0,18,34,0,0,0,0,0,0,0,0,0,0,34,18,0,0,0,0,8,8,0,0,0,0,0
0,0,0,0,0,8,8,0,0,0,0,18,34,0,0,0,0,0,0,0,0,0,0,34,18,0,0,0,0,8,8,0,0,0,0,0
0,0,0,0,0,8,8,0,0,0,22,18,29,0,0,0,0,0,0,0,0,0,0,28,18,23,0,0,0,8,8,0,0,0,0,0
0,0,0,0,0,8,8,0,0,0,0,18,34,0,0,0,0,0,0,0,0,0,0,34,18,0,0,0,0,8,8,0,0,0,0,0
0,0,0,0,0,8,8,30,0,0,0,18,34,0,0,0,0,0,0,0,0,0,0,34,18,0,0,0,30,8,8,0,0,0,0,0
0,0,0,0,0,8,8,13,0,0,22,18,29,0,0,0,0,0,0,0,0,0,0,28,18,23,0,0,13,8,8,0,0,0,0,0
0,0,0,0,8,8,8,31,0,0,0,8,8,30,34,34,30,34,34,30,34,34,30,8,8,0,0,0,31,8,8,8,0,0,0,0
0,0,0,0,8,8,8,30,0,0,0,8,8,20,20,20,20,20,20,20,20,20,20,8,8,0,0,0,30,8,8,8,0,0,0,0
0,0,0,0,0,8,8,13,0,0,0,0,0,25,0,0,25,0,0,25,0,0,25,0,0,0,0,0,13,8,8,0,0,0,0,0
0,0,0,0,0,8,8,31,0,0,0,0,0,0,0,0,0,0,0,0,0,0,0,0,0,0,0,0,31,8,8,0,0,0,0,0
0,0,0,0,0,8,8,30,0,0,0,0,0,0,0,0,0,0,0,0,0,0,0,0,0,0,0,0,30,8,8,0,0,0,0,0
0,0,0,0,0,8,8,13,0,0,0,0,0,0,0,0,0,0,0,0,0,0,0,0,0,0,0,0,13,8,8,0,0,0,0,0
0,0,0,0,8,8,8,31,0,0,0,13,13,0,0,0,0,0,0,0,0,0,0,13,13,0,0,0,31,8,8,8,0,0,0,0
0,0,0,0,8,8,8,30,0,0,0,13,13,0,0,0,0,0,0,0,0,0,0,13,13,0,0,0,30,8,8,8,0,0,0,0
0,0,0,0,0,8,8,13,29,28,13,0,0,0,0,0,0,0,0,0,0,0,0,0,0,13,29,28,13,8,8,0,0,0,0,0
0,0,0,0,0,8,8,31,0,0,31,0,0,0,0,0,0,0,0,0,0,0,0,0,0,31,0,0,31,8,8,0,0,0,0,0
0,0,0,0,0,8,8,30,0,0,30,0,0,0,0,0,0,0,0,0,0,0,0,0,0,30,0,0,30,8,8,0,0,0,0,0
0,0,0,0,0,8,8,13,29,28,13,29,28,13,29,0,0,0,0,0,0,28,13,29,28,13,29,28,13,8,8,0,0,0,0,0
0,0,0,0,8,8,8,8,8,8,8,8,8,8,8,8,8,8,8,8,8,8,8,8,8,8,8,8,8,8,8,8,0,0,0,0
0,0,0,0,8,8,8,8,8,8,8,8,8,8,8,8,8,8,8,8,8,8,8,8,8,8,8,8,8,8,8,8,0,0,0,0
0,0,0,0,8,8,8,0,0,0,0,8,8,0,0,0,0,0,0,0,0,0,0,8,8,0,0,0,0,8,8,8,0,0,0,0
0,0,0,0,0,0,0,0,0,0,0,0,0,0,0,0,0,0,0,0,0,0,0,0,0,0,0,0,0,0,0,0,0,0,0,0
0,0,0,0,0,0,0,0,0,0,0,0,0,0,0,0,0,0,0,0,0,0,0,0,0,0,0,0,0,0,0,0,0,0,0,0
0,0,0,0,0,0,0,0,0,0,0,0,0,0,0,0,0,0,0,0,0,0,0,0,0,0,0,0,0,0,0,0,0,0,0,0
0,0,0,0,0,0,0,0,0,0,0,0,0,0,0,0,0,0,0,0,0,0,0,0,0,0,0,0,0,0,0,0,0,0,0,0
:endlayer
layer: 21
0,0,0,0,0,0,0,0,0,0,0,0,0,0,0,0,0,0,0,0,0,0,0,0,0,0,0,0,0,0,0,0,0,0,0,0
0,0,0,0,0,0,0,0,0,0,0,0,0,0,0,37,32,37,37,32,37,0,0,0,0,0,0,0,0,0,0,0,0,0,0,0
0,0,0,0,0,0,0,0,0,0,0,0,0,0,32,8,8,8,8,8,8,32,0,0,0,0,0,0,0,0,0,0,0,0,0,0
0,0,0,0,0,0,0,0,0,0,0,0,0,26,8,8,8,8,8,8,8,8,27,0,0,0,0,0,0,0,0,0,0,0,0,0
0,0,0,0,0,0,0,0,0,0,0,0,37,8,8,13,0,0,0,0,13,8,8,37,0,0,0,0,0,0,0,0,0,0,0,0
0,0,0,0,0,0,0,0,0,0,0,0,37,8,8,0,0,0,0,0,0,8,8,37,0,0,0,0,0,0,0,0,0,0,0,0
0,0,0,0,0,0,0,0,0,0,0,0,26,8,8,0,0,0,0,0,0,8,8,27,0,0,0,0,0,0,0,0,0,0,0,0
0,0,0,0,0,0,0,0,0,0,0,37,8,8,8,21,0,0,0,0,21,8,8,8,37,0,0,0,0,0,0,0,0,0,0,0
0,0,0,0,0,0,0,32,37,37,32,37,8,8,13,0,0,0,0,0,0,13,8,8,37,32,37,37,32,0,0,0,0,0,0,0
0,0,0,0,8,8,32,8,8,8,8,32,8,8,4,0,0,0,0,0,0,4,8,8,32,8,8,8,8,32,8,8,0,0,0,0
0,0,0,0,8,8,8,8,8,8,8,8,8,8,0,0,0,0,0,0,0,0,8,8,8,8,8,8,8,8,8,8,0,0,0,0
0,0,0,0,8,8,8,8,8,8,8,8,8,13,0,0,0,0,0,0,0,0,13,8,8,8,8,8,8,8,8,8,0,0,0,0
0,0,0,0,26,8,8,13,0,0,0,0,0,31,0,0,0,0,0,0,0,0,31,0,0,0,0,0,13,8,8,27,0,0,0,0
0,0,0,0,37,8,8,31,0,0,0,0,0,0,0,0,0,0,0,0,0,0,0,0,0,0,0,0,31,8,8,37,0,0,0,0
0,0,0,0,37,8,8,30,0,0,0,0,0,0,0,0,0,0,0,0,0,0,0,0,0,0,0,0,30,8,8,37,0,0,0,0
0,0,0,0,26,8,8,13,0,0,24,0,0,0,0,0,0,0,0,0,0,0,0,0,0,24,0,0,13,8,8,27,0,0,0,0
0,0,0,0,8,8,8,13,21,21,13,8,8,0,0,0,0,0,0,0,0,0,0,8,8,13,21,21,13,8,8,8,0,0,0,0
0,0,0,0,8,8,8,17,17,17,17,8,8,0,0,0,0,0,0,0,0,0,0,8,8,17,17,17,17,8,8,8,0,0,0,0
0,0,0,0,26,8,8,13,0,0,0,15,13,23,0,0,0,0,0,0,0,0,22,13,16,0,0,0,13,8,8,27,0,0,0,0
0,0,0,0,37,8,8,0,0,0,0,15,21,0,0,0,0,0,0,0,0,0,0,21,16,0,0,0,0,8,8,37,0,0,0,0
0,0,0,0,37,8,8,36,0,0,0,15,21,0,0,0,0,0,0,0,0,0,0,21,16,0,0,0,36,8,8,37,0,0,0,0
0,0,0,0,26,8,8,36,0,0,0,15,13,23,0,0,0,0,0,0,0,0,22,13,16,0,0,0,36,8,8,27,0,0,0,0
0,0,0,0,37,8,8,34,0,0,0,15,21,0,0,0,0,0,0,0,0,0,0,21,16,0,0,0,34,8,8,37,0,0,0,0
0,0,0,0,37,8,8,34,0,0,0,15,21,0,0,0,0,0,0,0,0,0,0,21,16,0,0,0,34,8,8,37,0,0,0,0
0,0,0,0,26,8,8,36,0,0,0,15,13,23,0,0,0,0,0,0,0,0,22,13,16,0,0,0,36,8,8,27,0,0,0,0
0,0,0,0,37,8,8,36,0,0,0,15,21,0,0,0,0,0,0,0,0,0,0,21,16,0,0,0,36,8,8,37,0,0,0,0
0,0,0,0,37,8,8,0,0,0,0,15,21,0,0,0,0,0,0,0,0,0,0,21,16,0,0,0,0,8,8,37,0,0,0,0
0,0,0,0,26,8,8,13,0,0,0,15,13,23,0,0,24,0,0,24,0,0,22,13,16,0,0,0,13,8,8,27,0,0,0,0
0,0,0,0,8,8,8,0,0,0,0,8,8,13,21,21,13,21,21,13,21,21,13,8,8,0,0,0,0,8,8,8,0,0,0,0
0,0,0,0,8,8,8,0,0,0,0,8,8,17,17,17,17,17,17,17,17,17,17,8,8,0,0,0,0,8,8,8,0,0,0,0
0,0,0,0,26,8,8,13,0,0,0,0,0,0,0,0,0,0,0,0,0,0,0,0,0,0,0,0,13,8,8,27,0,0,0,0
0,0,0,0,37,8,8,0,0,0,0,0,0,0,0,0,0,0,0,0,0,0,0,0,0,0,0,0,0,8,8,37,0,0,0,0
0,0,0,0,37,8,8,0,0,0,0,0,0,0,0,0,0,0,0,0,0,0,0,0,0,0,0,0,0,8,8,37,0,0,0,0
0,0,0,0,26,8,8,13,0,0,0,0,0,0,0,0,0,0,0,0,0,0,0,0,0,0,0,0,13,8,8,27,0,0,0,0
0,0,0,0,8,8,8,0,0,0,0,13,13,0,0,0,0,0,0,0,0,0,0,13,13,0,0,0,0,8,8,8,0,0,0,0
0,0,0,0,8,8,8,0,0,0,0,13,13,0,0,0,0,0,0,0,0,0,0,13,13,0,0,0,0,8,8,8,0,0,0,0
0,0,0,0,26,8,8,13,36,36,13,0,0,0,0,0,0,0,0,0,0,0,0,0,0,13,36,36,13,8,8,27,0,0,0,0
0,0,0,0,37,8,8,36,19,19,36,0,0,0,0,0,0,0,0,0,0,0,0,0,0,36,19,19,36,8,8,37,0,0,0,0
0,0,0,0,37,8,8,36,19,19,36,0,0,0,0,0,0,0,0,0,0,0,0,0,0,36,19,19,36,8,8,37,0,0,0,0
0,0,0,0,26,8,8,13,36,36,13,0,0,13,0,36,36,34,34,36,36,0,13,0,0,13,36,36,13,8,8,27,0,0,0,0
0,0,0,0,8,8,8,8,8,8,8,8,8,8,8,8,8,8,8,8,8,8,8,8,8,8,8,8,8,8,8,8,0,0,0,0
0,0,0,0,8,8,8,8,8,8,8,8,8,8,8,8,8,8,8,8,8,8,8,8,8,8,8,8,8,8,8,8,0,0,0,0
0,0,0,0,8,8,8,33,37,37,33,8,8,33,37,37,33,37,37,33,37,37,33,8,8,33,37,37,33,8,8,8,0,0,0,0
0,0,0,0,0,0,0,0,0,0,0,0,0,0,0,0,0,0,0,0,0,0,0,0,0,0,0,0,0,0,0,0,0,0,0,0
0,0,0,0,0,0,0,0,0,0,0,0,0,0,0,0,0,0,0,0,0,0,0,0,0,0,0,0,0,0,0,0,0,0,0,0
0,0,0,0,0,0,0,0,0,0,0,0,0,0,0,0,0,0,0,0,0,0,0,0,0,0,0,0,0,0,0,0,0,0,0,0
0,0,0,0,0,0,0,0,0,0,0,0,0,0,0,0,0,0,0,0,0,0,0,0,0,0,0,0,0,0,0,0,0,0,0,0
:endlayer
layer: 22
0,0,0,0,0,0,0,0,0,0,0,0,0,0,0,0,0,0,0,0,0,0,0,0,0,0,0,0,0,0,0,0,0,0,0,0
0,0,0,0,0,0,0,0,0,0,0,0,0,0,0,38,38,38,38,38,38,0,0,0,0,0,0,0,0,0,0,0,0,0,0,0
0,0,0,0,0,0,0,0,0,0,0,0,0,0,38,8,8,8,8,8,8,38,0,0,0,0,0,0,0,0,0,0,0,0,0,0
0,0,0,0,0,0,0,0,0,0,0,0,0,38,8,8,8,8,8,8,8,8,38,0,0,0,0,0,0,0,0,0,0,0,0,0
0,0,0,0,0,0,0,0,0,0,0,0,38,8,8,13,21,0,0,21,13,8,8,38,0,0,0,0,0,0,0,0,0,0,0,0
0,0,0,0,0,0,0,0,0,0,0,0,38,8,8,21,0,0,0,0,21,8,8,38,0,0,0,0,0,0,0,0,0,0,0,0
0,0,0,0,0,0,0,0,0,0,0,0,38,8,8,0,0,0,0,0,0,8,8,38,0,0,0,0,0,0,0,0,0,0,0,0
0,0,0,0,0,0,0,0,0,0,0,38,8,8,8,21,0,0,0,0,21,8,8,8,38,0,0,0,0,0,0,0,0,0,0,0
0,0,0,0,0,0,0,38,38,38,38,38,8,8,13,0,0,0,0,0,0,13,8,8,38,38,38,38,38,0,0,0,0,0,0,0
0,0,0,0,8,8,8,8,8,8,8,8,8,8,21,0,0,0,0,0,0,21,8,8,8,8,8,8,8,8,8,8,0,0,0,0
0,0,0,0,8,8,8,8,8,8,8,8,8,8,27,0,0,0,0,0,0,26,8,8,8,8,8,8,8,8,8,8,0,0,0,0
0,0,0,0,8,8,8,8,8,8,8,8,8,8,27,0,0,0,0,0,0,26,8,8,8,8,8,8,8,8,8,8,0,0,0,0
0,0,0,0,0,8,8,13,36,34,34,34,36,21,0,0,0,0,0,0,0,0,21,36,34,34,34,36,13,8,8,0,0,0,0,0
0,0,0,0,0,0,35,0,0,0,0,0,0,0,0,0,0,0,0,0,0,0,0,0,0,0,0,0,0,35,0,0,0,0,0,0
0,0,0,0,0,0,35,0,0,0,0,0,0,0,0,0,0,0,0,0,0,0,0,0,0,0,0,0,0,35,0,0,0,0,0,0
0,0,0,0,0,8,8,13,0,0,0,0,0,0,0,0,0,0,0,0,0,0,0,0,0,0,0,0,13,8,8,0,0,0,0,0
0,0,0,0,8,8,8,36,36,36,36,8,8,0,0,0,0,0,0,0,0,0,0,8,8,36,36,36,36,8,8,8,0,0,0,0
0,0,0,0,8,8,8,0,0,0,0,8,8,0,0,0,0,0,0,0,0,0,0,8,8,0,0,0,0,8,8,8,0,0,0,0
0,0,0,0,0,8,8,13,0,0,0,0,36,0,0,0,0,0,0,0,0,0,0,36,0,0,0,0,13,8,8,0,0,0,0,0
0,0,0,0,0,0,35,0,0,0,0,0,36,0,0,0,0,0,0,0,0,0,0,36,0,0,0,0,0,35,0,0,0,0,0,0
0,0,0,0,0,0,35,0,0,0,0,0,36,0,0,0,0,0,0,0,0,0,0,36,0,0,0,0,0,35,0,0,0,0,0,0
0,0,0,0,0,8,8,0,0,0,0,0,36,0,0,0,0,0,0,0,0,0,0,36,0,0,0,0,0,8,8,0,0,0,0,0
0,0,0,0,0,0,35,0,0,0,0,0,36,0,0,0,0,0,0,0,0,0,0,36,0,0,0,0,0,35,0,0,0,0,0,0
0,0,0,0,0,0,35,0,0,0,0,0,36,0,0,0,0,0,0,0,0,0,0,36,0,0,0,0,0,35,0,0,0,0,0,0
0,0,0,0,0,8,8,0,0,0,0,0,36,0,0,0,0,0,0,0,0,0,0,36,0,0,0,0,0,8,8,0,0,0,0,0
0,0,0,0,0,0,35,0,0,0,0,0,36,0,0,0,0,0,0,0,0,0,0,36,0,0,0,0,0,35,0,0,0,0,0,0
0,0,0,0,0,0,35,0,0,0,0,0,36,0,0,0,0,0,0,0,0,0,0,36,0,0,0,0,0,35,0,0,0,0,0,0
0,0,0,0,0,8,8,13,0,0,0,0,36,0,0,0,0,0,0,0,0,0,0,36,0,0,0,0,13,8,8,0,0,0,0,0
0,0,0,0,8,8,8,0,0,0,0,8,8,36,36,36,36,36,36,36,36,36,36,8,8,0,0,0,0,8,8,8,0,0,0,0
0,0,0,0,8,8,8,0,0,0,0,8,8,0,0,0,0,0,0,0,0,0,0,8,8,0,0,0,0,8,8,8,0,0,0,0
0,0,0,0,0,8,8,13,0,0,0,0,0,0,0,0,0,0,0,0,0,0,0,0,0,0,0,0,13,8,8,0,0,0,0,0
0,0,0,0,0,0,35,0,0,0,0,0,0,0,0,0,0,0,0,0,0,0,0,0,0,0,0,0,0,35,0,0,0,0,0,0
0,0,0,0,0,0,35,0,0,0,0,0,0,0,0,0,0,0,0,0,0,0,0,0,0,0,0,0,0,35,0,0,0,0,0,0
0,0,0,0,0,8,8,13,0,0,0,0,0,0,0,0,0,0,0,0,0,0,0,0,0,0,0,0,13,8,8,0,0,0,0,0
0,0,0,0,8,8,8,0,0,0,0,13,13,0,0,0,0,0,0,0,0,0,0,13,13,0,0,0,0,8,8,8,0,0,0,0
0,0,0,0,8,8,8,0,0,0,0,13,13,0,0,0,0,0,0,0,0,0,0,13,13,0,0,0,0,8,8,8,0,0,0,0
0,0,0,0,0,8,8,13,0,0,36,0,0,0,0,0,0,0,0,0,0,0,0,0,0,36,0,0,13,8,8,0,0,0,0,0
0,0,0,0,0,0,35,0,0,0,0,0,0,0,0,0,0,0,0,0,0,0,0,0,0,0,0,0,0,35,0,0,0,0,0,0
0,0,0,0,0,0,35,0,0,0,0,0,0,0,0,0,0,0,0,0,0,0,0,0,0,0,0,0,0,35,0,0,0,0,0,0
0,0,0,0,0,8,8,13,0,0,13,0,0,13,0,0,0,0,0,0,0,0,13,0,0,13,0,0,13,8,8,0,0,0,0,0
0,0,0,0,8,8,8,8,35,35,8,8,8,8,35,35,8,35,35,8,35,35,8,8,8,8,35,35,8,8,8,8,0,0,0,0
0,0,0,0,8,8,8,8,0,0,8,8,8,8,0,0,8,0,0,8,0,0,8,8,8,8,0,0,8,8,8,8,0,0,0,0
0,0,0,0,8,8,8,0,0,0,0,8,8,0,0,0,0,0,0,0,0,0,0,8,8,0,0,0,0,8,8,8,0,0,0,0
0,0,0,0,0,0,0,0,0,0,0,0,0,0,0,0,0,0,0,0,0,0,0,0,0,0,0,0,0,0,0,0,0,0,0,0
0,0,0,0,0,0,0,0,0,0,0,0,0,0,0,0,0,0,0,0,0,0,0,0,0,0,0,0,0,0,0,0,0,0,0,0
0,0,0,0,0,0,0,0,0,0,0,0,0,0,0,0,0,0,0,0,0,0,0,0,0,0,0,0,0,0,0,0,0,0,0,0
0,0,0,0,0,0,0,0,0,0,0,0,0,0,0,0,0,0,0,0,0,0,0,0,0,0,0,0,0,0,0,0,0,0,0,0
:endlayer
layer: 23
0,0,0,0,0,0,0,0,0,0,0,0,0,0,0,0,0,0,0,0,0,0,0,0,0,0,0,0,0,0,0,0,0,0,0,0
0,0,0,0,0,0,0,0,0,0,0,0,0,0,0,0,0,0,0,0,0,0,0,0,0,0,0,0,0,0,0,0,0,0,0,0
0,0,0,0,0,0,0,0,0,0,0,0,0,0,4,38,38,38,38,38,38,4,0,0,0,0,0,0,0,0,0,0,0,0,0,0
0,0,0,0,0,0,0,0,0,0,0,0,0,0,38,38,8,8,8,8,38,38,0,0,0,0,0,0,0,0,0,0,0,0,0,0
0,0,0,0,0,0,0,0,0,0,0,0,0,38,38,19,29,0,0,28,19,38,38,0,0,0,0,0,0,0,0,0,0,0,0,0
0,0,0,0,0,0,0,0,0,0,0,0,0,38,8,31,21,0,0,21,31,8,38,0,0,0,0,0,0,0,0,0,0,0,0,0
0,0,0,0,0,0,0,0,0,0,0,0,0,38,8,23,0,0,0,0,22,8,38,0,0,0,0,0,0,0,0,0,0,0,0,0
0,0,0,0,0,0,0,0,0,0,0,0,38,8,8,21,0,0,0,0,21,8,8,38,0,0,0,0,0,0,0,0,0,0,0,0
0,0,0,0,38,0,0,24,38,38,24,0,38,8,18,29,0,0,0,0,28,18,8,38,0,24,38,38,24,0,0,38,0,0,0,0
0,0,0,38,38,8,8,38,38,38,38,8,8,8,18,0,0,0,0,0,0,18,8,8,8,38,38,38,38,8,8,38,38,0,0,0
0,0,0,0,8,8,8,8,8,8,8,8,8,8,8,8,37,0,0,37,8,8,8,8,8,8,8,8,8,8,8,8,0,0,0,0
0,0,0,0,8,8,8,8,8,8,8,8,8,8,8,8,37,0,0,37,8,8,8,8,8,8,8,8,8,8,8,8,0,0,0,0
0,0,0,0,22,8,8,13,23,0,0,0,0,31,0,0,0,0,0,0,0,0,31,0,0,0,0,22,13,8,8,23,0,0,0,0
0,0,0,0,0,0,35,0,0,0,0,0,0,0,0,0,0,0,0,0,0,0,0,0,0,0,0,0,0,35,0,0,0,0,0,0
0,0,0,0,0,0,35,0,0,0,0,0,0,0,0,0,0,0,0,0,0,0,0,0,0,0,0,0,0,35,0,0,0,0,0,0
0,0,0,0,22,8,8,13,23,0,0,0,0,0,0,0,0,0,0,0,0,0,0,0,0,0,0,22,13,8,8,23,0,0,0,0
0,0,0,0,8,8,8,0,0,0,0,8,8,0,0,0,0,0,0,0,0,0,0,8,8,0,0,0,0,8,8,8,0,0,0,0
0,0,0,0,8,8,8,0,0,0,0,8,8,0,0,0,0,0,0,0,0,0,0,8,8,0,0,0,0,8,8,8,0,0,0,0
0,0,0,0,22,8,8,13,23,0,0,0,0,0,0,0,0,0,0,0,0,0,0,0,0,0,0,22,13,8,8,23,0,0,0,0
0,0,0,0,0,0,35,0,0,0,0,0,0,0,0,0,0,0,0,0,0,0,0,0,0,0,0,0,0,35,0,0,0,0,0,0
0,0,0,0,0,0,35,0,0,0,0,0,0,0,0,0,0,0,0,0,0,0,0,0,0,0,0,0,0,35,0,0,0,0,0,0
0,0,0,0,22,8,8,23,0,0,0,0,0,0,0,0,0,0,0,0,0,0,0,0,0,0,0,0,22,8,8,23,0,0,0,0
0,0,0,0,0,0,35,0,0,0,0,0,0,0,0,0,0,0,0,0,0,0,0,0,0,0,0,0,0,35,0,0,0,0,0,0
0,0,0,0,0,0,35,0,0,0,0,0,0,0,0,0,0,0,0,0,0,0,0,0,0,0,0,0,0,35,0,0,0,0,0,0
0,0,0,0,22,8,8,23,0,0,0,0,0,0,0,0,0,0,0,0,0,0,0,0,0,0,0,0,22,8,8,23,0,0,0,0
0,0,0,0,0,0,35,0,0,0,0,0,0,0,0,0,0,0,0,0,0,0,0,0,0,0,0,0,0,35,0,0,0,0,0,0
0,0,0,0,0,0,35,0,0,0,0,0,0,0,0,0,0,0,0,0,0,0,0,0,0,0,0,0,0,35,0,0,0,0,0,0
0,0,0,0,22,8,8,13,23,0,0,0,0,0,0,0,0,0,0,0,0,0,0,0,0,0,0,22,13,8,8,23,0,0,0,0
0,0,0,0,8,8,8,0,0,0,0,8,8,0,0,0,0,0,0,0,0,0,0,8,8,0,0,0,0,8,8,8,0,0,0,0
0,0,0,0,8,8,8,0,0,0,0,8,8,0,0,0,0,0,0,0,0,0,0,8,8,0,0,0,0,8,8,8,0,0,0,0
0,0,0,0,22,8,8,13,23,0,0,0,0,0,0,0,0,0,0,0,0,0,0,0,0,0,0,22,13,8,8,23,0,0,0,0
0,0,0,0,0,0,35,0,0,0,0,0,0,0,0,0,0,0,0,0,0,0,0,0,0,0,0,0,0,35,0,0,0,0,0,0
0,0,0,0,0,0,35,0,0,0,0,0,0,0,0,0,0,0,0,0,0,0,0,0,0,0,0,0,0,35,0,0,0,0,0,0
0,0,0,0,22,8,8,13,23,0,0,0,0,0,0,0,0,0,0,0,0,0,0,0,0,0,0,22,13,8,8,23,0,0,0,0
0,0,0,0,8,8,8,0,0,0,0,13,13,0,0,0,0,0,0,0,0,0,0,13,13,0,0,0,0,8,8,8,0,0,0,0
0,0,0,0,8,8,8,0,0,0,0,13,13,0,0,0,0,0,0,0,0,0,0,13,13,0,0,0,0,8,8,8,0,0,0,0
0,0,0,0,22,8,8,13,23,0,0,0,0,0,0,0,0,0,0,0,0,0,0,0,0,0,0,22,13,8,8,23,0,0,0,0
0,0,0,0,0,0,35,0,0,0,0,0,0,0,0,0,0,0,0,0,0,0,0,0,0,0,0,0,0,35,0,0,0,0,0,0
0,0,0,0,0,0,35,0,0,0,24,0,0,24,0,0,0,0,0,0,0,0,24,0,0,24,0,0,0,35,0,0,0,0,0,0
0,0,0,0,22,8,8,13,0,0,13,0,0,13,0,0,24,0,0,24,0,0,13,0,0,13,0,0,13,8,8,23,0,0,0,0
0,0,0,0,8,8,8,8,35,35,8,8,8,8,35,35,8,35,35,8,35,35,8,8,8,8,35,35,8,8,8,8,0,0,0,0
0,0,0,0,8,8,8,8,0,0,8,8,8,8,0,0,8,0,0,8,0,0,8,8,8,8,0,0,8,8,8,8,0,0,0,0
0,0,0,38,38,8,8,25,0,0,25,8,8,25,0,0,25,0,0,25,0,0,25,8,8,25,0,0,25,8,8,38,38,0,0,0
0,0,0,0,38,0,0,0,0,0,0,0,0,0,0,0,0,0,0,0,0,0,0,0,0,0,0,0,0,0,0,38,0,0,0,0
0,0,0,0,0,0,0,0,0,0,0,0,0,0,0,0,0,0,0,0,0,0,0,0,0,0,0,0,0,0,0,0,0,0,0,0
0,0,0,0,0,0,0,0,0,0,0,0,0,0,0,0,0,0,0,0,0,0,0,0,0,0,0,0,0,0,0,0,0,0,0,0
0,0,0,0,0,0,0,0,0,0,0,0,0,0,0,0,0,0,0,0,0,0,0,0,0,0,0,0,0,0,0,0,0,0,0,0
:endlayer
layer: 24
0,0,0,0,0,0,0,0,0,0,0,0,0,0,0,0,0,0,0,0,0,0,0,0,0,0,0,0,0,0,0,0,0,0,0,0
0,0,0,0,0,0,0,0,0,0,0,0,0,0,0,0,0,0,0,0,0,0,0,0,0,0,0,0,0,0,0,0,0,0,0,0
0,0,0,0,0,0,0,0,0,0,0,0,0,0,0,0,0,0,0,0,0,0,0,0,0,0,0,0,0,0,0,0,0,0,0,0
0,0,0,0,0,0,0,0,0,0,0,0,0,0,0,0,38,38,38,38,0,0,0,0,0,0,0,0,0,0,0,0,0,0,0,0
0,0,0,0,0,0,0,0,0,0,0,0,0,0,0,38,38,20,20,38,38,0,0,0,0,0,0,0,0,0,0,0,0,0,0,0
0,0,0,0,0,0,0,0,0,0,0,0,0,0,38,38,19,31,31,19,38,38,0,0,0,0,0,0,0,0,0,0,0,0,0,0
0,0,0,0,0,0,0,0,0,0,0,0,0,0,38,18,34,34,34,34,18,38,0,0,0,0,0,0,0,0,0,0,0,0,0,0
0,0,0,0,0,0,0,0,0,0,0,0,0,38,38,18,34,0,0,34,18,38,38,0,0,0,0,0,0,0,0,0,0,0,0,0
0,0,0,0,38,0,0,0,0,0,0,0,0,38,38,18,29,34,34,28,18,38,38,0,0,0,0,0,0,0,0,38,0,0,0,0
0,0,0,38,38,8,8,0,38,38,0,8,8,38,38,18,34,0,0,34,18,38,38,8,8,0,38,38,0,8,8,38,38,0,0,0
0,0,0,0,8,8,8,8,8,8,8,8,8,8,8,8,8,8,8,8,8,8,8,8,8,8,8,8,8,8,8,8,0,0,0,0
0,0,0,0,8,8,8,8,8,8,8,8,8,8,8,8,8,8,8,8,8,8,8,8,8,8,8,8,8,8,8,8,0,0,0,0
0,0,0,0,0,8,8,13,0,0,0,31,31,0,36,36,34,34,34,34,36,36,0,31,31,0,0,0,13,8,8,0,0,0,0,0
0,0,0,0,0,33,35,0,0,0,0,0,0,0,0,0,0,0,0,0,0,0,0,0,0,0,0,0,0,35,33,0,0,0,0,0
0,0,0,0,0,32,35,0,0,0,0,0,0,0,0,0,0,0,0,0,0,0,0,0,0,0,0,0,0,35,32,0,0,0,0,0
0,0,0,0,0,8,8,13,0,0,0,30,30,0,0,0,0,0,0,0,0,0,0,30,30,0,0,0,13,8,8,0,0,0,0,0
0,0,0,0,8,8,8,29,0,0,28,8,8,27,0,0,0,0,0,0,0,0,26,8,8,29,0,0,28,8,8,8,0,0,0,0
0,0,0,0,8,8,8,29,0,0,28,8,8,27,0,0,0,0,0,0,0,0,26,8,8,29,0,0,28,8,8,8,0,0,0,0
0,0,0,0,0,8,8,13,0,0,0,33,33,0,0,0,0,0,0,0,0,0,0,33,33,0,0,0,13,8,8,0,0,0,0,0
0,0,0,0,0,0,35,0,0,0,0,0,0,0,0,0,0,0,0,0,0,0,0,0,0,0,0,0,0,35,0,0,0,0,0,0
0,0,0,0,0,0,35,0,0,0,0,0,0,0,0,0,0,0,0,0,0,0,0,0,0,0,0,0,0,35,0,0,0,0,0,0
0,0,0,0,0,8,8,0,0,0,0,0,0,0,0,0,0,0,0,0,0,0,0,0,0,0,0,0,0,8,8,0,0,0,0,0
0,0,0,0,0,0,35,0,0,0,0,0,0,0,0,0,0,0,0,0,0,0,0,0,0,0,0,0,0,35,0,0,0,0,0,0
0,0,0,0,0,0,35,0,0,0,0,0,0,0,0,0,0,0,0,0,0,0,0,0,0,0,0,0,0,35,0,0,0,0,0,0
0,0,0,0,0,8,8,0,0,0,0,0,0,0,0,0,0,0,0,0,0,0,0,0,0,0,0,0,0,8,8,0,0,0,0,0
0,0,0,0,0,0,35,0,0,0,0,0,0,0,0,0,0,0,0,0,0,0,0,0,0,0,0,0,0,35,0,0,0,0,0,0
0,0,0,0,0,0,35,0,0,0,0,0,0,0,0,0,0,0,0,0,0,0,0,0,0,0,0,0,0,35,0,0,0,0,0,0
0,0,0,0,0,8,8,13,0,0,0,32,32,0,0,0,0,0,0,0,0,0,0,32,32,0,0,0,13,8,8,0,0,0,0,0
0,0,0,0,8,8,8,29,0,0,28,8,8,27,0,0,0,0,0,0,0,0,26,8,8,29,0,0,28,8,8,8,0,0,0,0
0,0,0,0,8,8,8,29,0,0,28,8,8,27,0,0,0,0,0,0,0,0,26,8,8,29,0,0,28,8,8,8,0,0,0,0
0,0,0,0,0,8,8,13,0,0,0,31,31,0,0,0,0,0,0,0,0,0,0,31,31,0,0,0,13,8,8,0,0,0,0,0
0,0,0,0,0,33,35,0,0,0,0,0,0,0,0,0,0,0,0,0,0,0,0,0,0,0,0,0,0,35,33,0,0,0,0,0
0,0,0,0,0,32,35,0,0,0,0,0,0,0,0,0,0,0,0,0,0,0,0,0,0,0,0,0,0,35,32,0,0,0,0,0
0,0,0,0,0,8,8,13,0,0,0,30,30,0,0,0,0,0,0,0,0,0,0,30,30,0,0,0,13,8,8,0,0,0,0,0
0,0,0,0,8,8,8,29,0,0,28,13,13,0,0,0,0,0,0,0,0,0,0,13,13,29,0,0,28,8,8,8,0,0,0,0
0,0,0,0,8,8,8,29,0,0,28,13,13,0,0,0,0,0,0,0,0,0,0,13,13,29,0,0,28,8,8,8,0,0,0,0
0,0,0,0,0,8,8,13,0,0,0,31,31,0,0,0,0,0,0,0,0,0,0,31,31,0,0,0,13,8,8,0,0,0,0,0
0,0,0,0,0,33,35,0,0,0,0,0,0,0,0,0,0,0,0,0,0,0,0,0,0,0,0,0,0,35,33,0,0,0,0,0
0,0,0,0,0,32,35,0,0,0,0,0,0,0,0,0,0,0,0,0,0,0,0,0,0,0,0,0,0,35,32,0,0,0,0,0
0,0,0,0,0,8,8,13,0,0,13,30,30,13,0,0,0,0,0,0,0,0,13,30,30,13,0,0,13,8,8,0,0,0,0,0
0,0,0,0,8,8,8,8,35,35,8,8,8,8,35,35,8,35,35,8,35,35,8,8,8,8,35,35,8,8,8,8,0,0,0,0
0,0,0,0,8,8,8,8,27,26,8,8,8,8,0,0,8,0,0,8,0,0,8,8,8,8,27,26,8,8,8,8,0,0,0,0
0,0,0,38,38,8,8,0,0,0,0,8,8,0,0,0,0,0,0,0,0,0,0,8,8,0,0,0,0,8,8,38,38,0,0,0
0,0,0,0,38,0,0,0,0,0,0,0,0,0,0,0,0,0,0,0,0,0,0,0,0,0,0,0,0,0,0,38,0,0,0,0
0,0,0,0,0,0,0,0,0,0,0,0,0,0,0,0,0,0,0,0,0,0,0,0,0,0,0,0,0,0,0,0,0,0,0,0
0,0,0,0,0,0,0,0,0,0,0,0,0,0,0,0,0,0,0,0,0,0,0,0,0,0,0,0,0,0,0,0,0,0,0,0
0,0,0,0,0,0,0,0,0,0,0,0,0,0,0,0,0,0,0,0,0,0,0,0,0,0,0,0,0,0,0,0,0,0,0,0
:endlayer
layer: 25
0,0,0,0,0,0,0,0,0,0,0,0,0,0,0,0,0,0,0,0,0,0,0,0,0,0,0,0,0,0,0,0,0,0,0,0
0,0,0,0,0,0,0,0,0,0,0,0,0,0,0,0,0,0,0,0,0,0,0,0,0,0,0,0,0,0,0,0,0,0,0,0
0,0,0,0,0,0,0,0,0,0,0,0,0,0,0,0,0,0,0,0,0,0,0,0,0,0,0,0,0,0,0,0,0,0,0,0
0,0,0,0,0,0,0,0,0,0,0,0,0,0,0,0,0,0,0,0,0,0,0,0,0,0,0,0,0,0,0,0,0,0,0,0
0,0,0,0,0,0,0,0,0,0,0,0,0,0,0,0,0,38,38,0,0,0,0,0,0,0,0,0,0,0,0,0,0,0,0,0
0,0,0,0,0,0,0,0,0,0,0,0,0,0,0,4,38,38,38,38,4,0,0,0,0,0,0,0,0,0,0,0,0,0,0,0
0,0,0,0,0,0,0,0,0,0,0,0,0,0,0,38,38,38,38,38,38,0,0,0,0,0,0,0,0,0,0,0,0,0,0,0
0,0,0,0,0,0,0,0,0,0,0,0,0,0,0,38,38,19,19,38,38,0,0,0,0,0,0,0,0,0,0,0,0,0,0,0
0,0,0,0,0,38,0,0,0,0,0,0,0,0,0,38,38,19,19,38,38,0,0,0,0,0,0,0,0,0,38,0,0,0,0,0
0,0,0,0,4,38,8,27,0,0,26,8,8,27,0,38,38,19,19,38,38,0,26,8,8,27,0,0,26,8,38,4,0,0,0,0
0,0,0,38,38,38,8,8,8,8,8,8,8,8,8,8,8,8,8,8,8,8,8,8,8,8,8,8,8,8,38,38,38,0,0,0
0,0,0,0,8,8,8,8,8,8,8,8,8,8,8,8,8,8,8,8,8,8,8,8,8,8,8,8,8,8,8,8,0,0,0,0
0,0,0,0,33,8,8,13,0,0,0,18,18,34,34,25,0,0,0,0,25,34,34,18,18,0,0,0,13,8,8,33,0,0,0,0
0,0,0,0,0,8,8,0,0,0,0,18,18,0,0,0,0,0,0,0,0,0,0,18,18,0,0,0,0,8,8,0,0,0,0,0
0,0,0,0,0,8,8,0,0,0,0,18,18,0,0,0,0,0,0,0,0,0,0,18,18,0,0,0,0,8,8,0,0,0,0,0
0,0,0,0,32,8,8,13,0,0,0,18,18,0,0,0,0,0,0,0,0,0,0,18,18,0,0,0,13,8,8,32,0,0,0,0
0,0,0,0,8,8,8,20,20,20,20,8,8,8,8,37,37,0,0,37,37,8,8,8,8,20,20,20,20,8,8,8,0,0,0,0
0,0,0,0,8,8,8,20,20,20,20,8,8,8,8,37,37,0,0,37,37,8,8,8,8,20,20,20,20,8,8,8,0,0,0,0
0,0,0,0,33,8,8,13,0,0,0,8,8,21,0,0,0,0,0,0,0,0,21,8,8,0,0,0,13,8,8,33,0,0,0,0
0,0,0,0,0,33,35,0,0,0,0,8,8,0,0,0,0,0,0,0,0,0,0,8,8,0,0,0,0,35,33,0,0,0,0,0
0,0,0,0,0,32,35,0,0,0,0,37,37,0,0,0,0,0,0,0,0,0,0,37,37,0,0,0,0,35,32,0,0,0,0,0
0,0,0,0,0,8,8,0,0,0,0,37,37,0,0,0,0,0,0,0,0,0,0,37,37,0,0,0,0,8,8,0,0,0,0,0
0,0,0,0,0,0,35,0,0,0,0,0,0,0,0,0,0,0,0,0,0,0,0,0,0,0,0,0,0,35,0,0,0,0,0,0
0,0,0,0,0,0,35,0,0,0,0,0,0,0,0,0,0,0,0,0,0,0,0,0,0,0,0,0,0,35,0,0,0,0,0,0
0,0,0,0,0,8,8,0,0,0,0,37,37,0,0,0,0,0,0,0,0,0,0,37,37,0,0,0,0,8,8,0,0,0,0,0
0,0,0,0,0,33,35,0,0,0,0,37,37,0,0,0,0,0,0,0,0,0,0,37,37,0,0,0,0,35,33,0,0,0,0,0
0,0,0,0,0,32,35,0,0,0,0,8,8,0,0,0,0,0,0,0,0,0,0,8,8,0,0,0,0,35,32,0,0,0,0,0
0,0,0,0,32,8,8,13,0,0,0,8,8,21,0,0,0,0,0,0,0,0,21,8,8,0,0,0,13,8,8,32,0,0,0,0
0,0,0,0,8,8,8,20,20,20,20,8,8,8,8,37,37,0,0,37,37,8,8,8,8,20,20,20,20,8,8,8,0,0,0,0
0,0,0,0,8,8,8,20,20,20,20,8,8,8,8,37,37,0,0,37,37,8,8,8,8,20,20,20,20,8,8,8,0,0,0,0
0,0,0,0,33,8,8,13,0,0,0,18,18,0,0,0,0,0,0,0,0,0,0,18,18,0,0,0,13,8,8,33,0,0,0,0
0,0,0,0,0,8,8,0,0,0,0,18,18,0,0,0,0,0,0,0,0,0,0,18,18,0,0,0,0,8,8,0,0,0,0,0
0,0,0,0,0,8,8,0,0,0,0,18,18,0,0,0,0,0,0,0,0,0,0,18,18,0,0,0,0,8,8,0,0,0,0,0
0,0,0,0,32,8,8,13,0,0,0,18,18,0,0,0,0,0,0,0,0,0,0,18,18,0,0,0,13,8,8,32,0,0,0,0
0,0,0,0,8,8,8,20,20,20,20,18,18,0,0,0,0,0,0,0,0,0,0,18,18,20,20,20,20,8,8,8,0,0,0,0
0,0,0,0,8,8,8,20,20,20,20,18,18,0,0,0,0,0,0,0,0,0,0,18,18,20,20,20,20,8,8,8,0,0,0,0
0,0,0,0,33,8,8,13,0,0,0,18,18,0,0,0,0,0,0,0,0,0,0,18,18,0,0,0,13,8,8,33,0,0,0,0
0,0,0,0,0,8,8,0,0,0,0,18,18,0,0,0,0,0,0,0,0,0,0,18,18,0,0,0,0,8,8,0,0,0,0,0
0,0,0,0,0,8,8,0,0,0,0,18,18,0,0,0,0,0,0,0,0,0,0,18,18,0,0,0,0,8,8,0,0,0,0,0
0,0,0,0,32,8,8,13,0,0,13,18,18,13,0,0,0,0,0,0,0,0,13,18,18,13,0,0,13,8,8,32,0,0,0,0
0,0,0,0,8,8,8,8,8,8,8,8,8,8,35,35,8,35,35,8,35,35,8,8,8,8,8,8,8,8,8,8,0,0,0,0
0,0,0,38,38,38,8,8,8,8,8,8,8,8,27,26,8,0,0,8,27,26,8,8,8,8,8,8,8,8,38,38,38,0,0,0
0,0,0,0,4,38,8,27,0,0,26,8,8,27,0,0,0,0,0,0,0,0,26,8,8,27,0,0,26,8,38,4,0,0,0,0
0,0,0,0,0,38,0,0,0,0,0,0,0,0,0,0,0,0,0,0,0,0,0,0,0,0,0,0,0,0,38,0,0,0,0,0
0,0,0,0,0,0,0,0,0,0,0,0,0,0,0,0,0,0,0,0,0,0,0,0,0,0,0,0,0,0,0,0,0,0,0,0
0,0,0,0,0,0,0,0,0,0,0,0,0,0,0,0,0,0,0,0,0,0,0,0,0,0,0,0,0,0,0,0,0,0,0,0
0,0,0,0,0,0,0,0,0,0,0,0,0,0,0,0,0,0,0,0,0,0,0,0,0,0,0,0,0,0,0,0,0,0,0,0
:endlayer
layer: 26
0,0,0,0,0,0,0,0,0,0,0,0,0,0,0,0,0,0,0,0,0,0,0,0,0,0,0,0,0,0,0,0,0,0,0,0
0,0,0,0,0,0,0,0,0,0,0,0,0,0,0,0,0,0,0,0,0,0,0,0,0,0,0,0,0,0,0,0,0,0,0,0
0,0,0,0,0,0,0,0,0,0,0,0,0,0,0,0,0,0,0,0,0,0,0,0,0,0,0,0,0,0,0,0,0,0,0,0
0,0,0,0,0,0,0,0,0,0,0,0,0,0,0,0,0,0,0,0,0,0,0,0,0,0,0,0,0,0,0,0,0,0,0,0
0,0,0,0,0,0,0,0,0,0,0,0,0,0,0,0,0,0,0,0,0,0,0,0,0,0,0,0,0,0,0,0,0,0,0,0
0,0,0,0,0,0,0,0,0,0,0,0,0,0,0,0,0,0,0,0,0,0,0,0,0,0,0,0,0,0,0,0,0,0,0,0
0,0,0,0,0,0,0,0,0,0,0,0,0,0,0,0,0,0,0,0,0,0,0,0,0,0,0,0,0,0,0,0,0,0,0,0
0,0,0,0,0,0,0,0,0,0,0,0,0,0,0,0,0,38,38,0,0,0,0,0,0,0,0,0,0,0,0,0,0,0,0,0
0,0,0,0,0,0,38,0,0,0,0,38,38,0,0,0,0,38,38,0,0,0,0,38,38,0,0,0,0,38,0,0,0,0,0,0
0,0,0,0,0,0,38,8,8,8,8,38,38,8,8,37,37,38,38,37,37,8,8,38,38,8,8,8,8,38,0,0,0,0,0,0
0,0,0,0,0,0,38,8,8,8,8,38,38,8,8,8,8,8,8,8,8,8,8,38,38,8,8,8,8,38,0,0,0,0,0,0
0,0,0,38,38,38,38,8,8,8,8,38,38,8,8,8,8,8,8,8,8,8,8,38,38,8,8,8,8,38,38,38,38,0,0,0
0,0,0,0,8,8,8,13,31,31,31,38,38,29,34,36,34,34,34,34,36,34,28,38,38,31,31,31,13,8,8,8,0,0,0,0
0,0,0,0,8,8,8,29,34,34,28,38,38,29,34,0,0,0,0,0,0,34,28,38,38,29,34,34,28,8,8,8,0,0,0,0
0,0,0,0,8,8,8,29,34,34,28,38,38,29,34,0,0,0,0,0,0,34,28,38,38,29,34,34,28,8,8,8,0,0,0,0
0,0,0,0,8,8,8,13,30,30,28,38,38,29,34,24,0,0,0,0,24,34,28,38,38,29,30,30,13,8,8,8,0,0,0,0
0,0,0,38,38,38,38,38,38,38,38,8,8,8,8,8,8,8,8,8,8,8,8,8,8,38,38,38,38,38,38,38,38,0,0,0
0,0,0,38,38,38,38,38,38,38,38,8,8,8,8,8,8,8,8,8,8,8,8,8,8,38,38,38,38,38,38,38,38,0,0,0
0,0,0,0,8,8,8,13,31,31,31,8,8,8,25,0,0,0,0,0,0,25,8,8,8,31,31,31,13,8,8,8,0,0,0,0
0,0,0,0,8,8,8,34,34,34,34,8,8,23,0,0,0,0,0,0,0,0,22,8,8,34,34,34,34,8,8,8,0,0,0,0
0,0,0,0,37,8,8,0,0,0,0,8,8,0,0,0,0,0,0,0,0,0,0,8,8,0,0,0,0,8,8,37,0,0,0,0
0,0,0,0,37,8,8,0,0,0,0,8,8,0,0,0,0,0,0,0,0,0,0,8,8,0,0,0,0,8,8,37,0,0,0,0
0,0,0,0,0,33,35,0,0,0,0,8,8,0,0,0,0,0,0,0,0,0,0,8,8,0,0,0,0,35,33,0,0,0,0,0
0,0,0,0,0,32,35,0,0,0,0,8,8,0,0,0,0,0,0,0,0,0,0,8,8,0,0,0,0,35,32,0,0,0,0,0
0,0,0,0,37,8,8,0,0,0,0,8,8,0,0,0,0,0,0,0,0,0,0,8,8,0,0,0,0,8,8,37,0,0,0,0
0,0,0,0,37,8,8,0,0,0,0,8,8,0,0,0,0,0,0,0,0,0,0,8,8,0,0,0,0,8,8,37,0,0,0,0
0,0,0,0,8,8,8,34,34,34,34,8,8,23,0,0,0,0,0,0,0,0,22,8,8,34,34,34,34,8,8,8,0,0,0,0
0,0,0,0,8,8,8,13,30,30,30,8,8,8,24,0,0,0,0,0,0,24,8,8,8,30,30,30,13,8,8,8,0,0,0,0
0,0,0,38,38,38,38,38,38,38,38,8,8,8,8,8,8,8,8,8,8,8,8,8,8,38,38,38,38,38,38,38,38,0,0,0
0,0,0,38,38,38,38,38,38,38,38,8,8,8,8,8,8,8,8,8,8,8,8,8,8,38,38,38,38,38,38,38,38,0,0,0
0,0,0,0,8,8,8,13,31,31,31,38,38,29,34,0,0,0,0,0,0,34,28,38,38,31,31,31,13,8,8,8,0,0,0,0
0,0,0,0,8,8,8,34,34,34,28,38,38,29,34,0,0,0,0,0,0,34,28,38,38,29,34,34,34,8,8,8,0,0,0,0
0,0,0,0,8,8,8,34,34,34,28,38,38,29,34,0,0,0,0,0,0,34,28,38,38,29,34,34,34,8,8,8,0,0,0,0
0,0,0,0,8,8,8,13,30,30,28,38,38,29,34,0,0,0,0,0,0,34,28,38,38,29,30,30,13,8,8,8,0,0,0,0
0,0,0,38,38,38,38,38,38,38,38,38,38,29,34,0,0,0,0,0,0,34,28,38,38,38,38,38,38,38,38,38,38,0,0,0
0,0,0,38,38,38,38,38,38,38,38,38,38,29,34,0,0,0,0,0,0,34,28,38,38,38,38,38,38,38,38,38,38,0,0,0
0,0,0,0,8,8,8,13,31,31,28,38,38,29,34,0,0,0,0,0,0,34,28,38,38,29,31,31,13,8,8,8,0,0,0,0
0,0,0,0,8,8,8,34,34,34,28,38,38,29,34,0,0,0,0,0,0,34,28,38,38,29,34,34,34,8,8,8,0,0,0,0
0,0,0,0,8,8,8,34,34,34,28,38,38,29,34,0,0,0,0,0,0,34,28,38,38,29,34,34,34,8,8,8,0,0,0,0
0,0,0,0,8,8,8,13,30,30,13,38,38,13,34,0,0,0,0,0,0,34,13,38,38,13,30,30,13,8,8,8,0,0,0,0
0,0,0,38,38,38,38,8,8,8,8,38,38,8,8,8,8,35,35,8,8,8,8,38,38,8,8,8,8,38,38,38,38,0,0,0
0,0,0,0,0,0,38,8,8,8,8,38,38,8,8,8,8,27,26,8,8,8,8,38,38,8,8,8,8,38,0,0,0,0,0,0
0,0,0,0,0,0,38,8,8,8,8,38,38,8,8,37,37,0,0,37,37,8,8,38,38,8,8,8,8,38,0,0,0,0,0,0
0,0,0,0,0,0,38,0,0,0,0,38,38,0,0,0,0,0,0,0,0,0,0,38,38,0,0,0,0,38,0,0,0,0,0,0
0,0,0,0,0,0,0,0,0,0,0,0,0,0,0,0,0,0,0,0,0,0,0,0,0,0,0,0,0,0,0,0,0,0,0,0
0,0,0,0,0,0,0,0,0,0,0,0,0,0,0,0,0,0,0,0,0,0,0,0,0,0,0,0,0,0,0,0,0,0,0,0
0,0,0,0,0,0,0,0,0,0,0,0,0,0,0,0,0,0,0,0,0,0,0,0,0,0,0,0,0,0,0,0,0,0,0,0
:endlayer
layer: 27
0,0,0,0,0,0,0,0,0,0,0,0,0,0,0,0,0,0,0,0,0,0,0,0,0,0,0,0,0,0,0,0,0,0,0,0
0,0,0,0,0,0,0,0,0,0,0,0,0,0,0,0,0,0,0,0,0,0,0,0,0,0,0,0,0,0,0,0,0,0,0,0
0,0,0,0,0,0,0,0,0,0,0,0,0,0,0,0,0,0,0,0,0,0,0,0,0,0,0,0,0,0,0,0,0,0,0,0
0,0,0,0,0,0,0,0,0,0,0,0,0,0,0,0,0,0,0,0,0,0,0,0,0,0,0,0,0,0,0,0,0,0,0,0
0,0,0,0,0,0,0,0,0,0,0,0,0,0,0,0,0,0,0,0,0,0,0,0,0,0,0,0,0,0,0,0,0,0,0,0
0,0,0,0,0,0,0,0,0,0,0,0,0,0,0,0,0,0,0,0,0,0,0,0,0,0,0,0,0,0,0,0,0,0,0,0
0,0,0,0,0,0,0,0,0,0,0,0,0,0,0,0,0,0,0,0,0,0,0,0,0,0,0,0,0,0,0,0,0,0,0,0
0,0,0,0,0,0,0,0,0,0,0,0,0,0,0,0,0,0,0,0,0,0,0,0,0,0,0,0,0,0,0,0,0,0,0,0
0,0,0,0,0,0,0,38,38,38,38,0,0,38,38,0,0,0,0,0,0,38,38,0,0,38,38,38,38,0,0,0,0,0,0,0
0,0,0,0,0,0,0,38,38,38,38,0,0,38,38,8,8,8,8,8,8,38,38,0,0,38,38,38,38,0,0,0,0,0,0,0
0,0,0,0,0,0,0,38,38,38,38,0,0,38,38,8,8,8,8,8,8,38,38,0,0,38,38,38,38,0,0,0,0,0,0,0
0,0,0,0,0,0,0,38,38,38,38,0,0,38,38,8,8,8,8,8,8,38,38,0,0,38,38,38,38,0,0,0,0,0,0,0
0,0,0,38,38,38,38,38,38,38,38,38,38,38,38,29,34,34,34,34,28,38,38,38,38,38,38,38,38,38,38,38,38,0,0,0
0,0,0,38,38,38,38,38,38,38,38,38,38,38,38,29,34,34,34,34,28,38,38,38,38,38,38,38,38,38,38,38,38,0,0,0
0,0,0,38,38,38,38,38,38,38,38,38,38,38,38,29,34,34,34,34,28,38,38,38,38,38,38,38,38,38,38,38,38,0,0,0
0,0,0,38,38,38,38,38,38,38,38,38,38,38,38,29,34,34,34,34,28,38,38,38,38,38,38,38,38,38,38,38,38,0,0,0
0,0,0,0,0,0,0,0,0,0,0,8,8,8,8,8,8,8,8,8,8,8,8,8,8,0,0,0,0,0,0,0,0,0,0,0
0,0,0,0,4,0,0,0,0,0,0,8,8,8,8,8,8,8,8,8,8,8,8,8,8,0,0,0,0,0,0,4,0,0,0,0
0,0,0,38,38,38,38,38,38,38,38,8,8,8,27,0,0,0,0,0,0,26,8,8,8,38,38,38,38,38,38,38,38,0,0,0
0,0,0,38,38,38,38,38,38,38,38,8,8,33,0,0,0,0,0,0,0,0,33,8,8,38,38,38,38,38,38,38,38,0,0,0
0,0,0,0,8,8,8,31,31,31,31,8,8,0,0,0,0,0,0,0,0,0,0,8,8,31,31,31,31,8,8,8,0,0,0,0
0,0,0,0,8,8,8,34,34,34,34,8,8,0,0,0,0,0,0,0,0,0,0,8,8,34,34,34,34,8,8,8,0,0,0,0
0,0,0,0,8,8,8,34,34,34,34,8,8,0,0,0,0,0,0,0,0,0,0,8,8,34,34,34,34,8,8,8,0,0,0,0
0,0,0,0,8,8,8,34,34,34,34,8,8,0,0,0,0,0,0,0,0,0,0,8,8,34,34,34,34,8,8,8,0,0,0,0
0,0,0,0,8,8,8,34,34,34,34,8,8,0,0,0,0,0,0,0,0,0,0,8,8,34,34,34,34,8,8,8,0,0,0,0
0,0,0,0,8,8,8,30,30,30,30,8,8,0,0,0,0,0,0,0,0,0,0,8,8,30,30,30,30,8,8,8,0,0,0,0
0,0,0,38,38,38,38,38,38,38,38,8,8,32,0,0,0,0,0,0,0,0,32,8,8,38,38,38,38,38,38,38,38,0,0,0
0,0,0,38,38,38,38,38,38,38,38,8,8,8,27,0,0,0,0,0,0,26,8,8,8,38,38,38,38,38,38,38,38,0,0,0
0,0,0,0,4,0,0,0,0,0,0,8,8,8,8,8,8,8,8,8,8,8,8,8,8,0,0,0,0,0,0,4,0,0,0,0
0,0,0,0,0,0,0,0,0,0,0,8,8,8,8,8,8,8,8,8,8,8,8,8,8,0,0,0,0,0,0,0,0,0,0,0
0,0,0,38,38,38,38,38,38,38,38,38,38,38,38,29,34,34,34,34,28,38,38,38,38,38,38,38,38,38,38,38,38,0,0,0
0,0,0,38,38,38,38,38,38,38,38,38,38,38,38,29,34,34,34,34,28,38,38,38,38,38,38,38,38,38,38,38,38,0,0,0
0,0,0,38,38,38,38,38,38,38,38,38,38,38,38,29,34,34,34,34,28,38,38,38,38,38,38,38,38,38,38,38,38,0,0,0
0,0,0,38,38,38,38,38,38,38,38,38,38,38,38,29,34,34,34,34,28,38,38,38,38,38,38,38,38,38,38,38,38,0,0,0
0,0,0,0,0,0,0,0,0,0,0,0,4,38,38,29,34,34,34,34,28,38,38,4,0,0,0,0,0,0,0,0,0,0,0,0
0,0,0,0,0,0,0,0,0,0,0,0,0,38,38,29,34,34,34,34,28,38,38,0,0,0,0,0,0,0,0,0,0,0,0,0
