# Ancient Warfare Structure Template File
# Auto-generated structure template file. created on: 4/23/2023 at: 14:49:33
# Lines beginning with # denote comments

header:
version=2.11
name=SB_T2wall_Stair_Tower_olive
mods=rustic
size=18,12,8
offset=0,1,7
:endheader

#### VALIDATION ####
validation:
type=ground
structureAuthor=TheOddlySeagull
survival=true
worldGenEnabled=false
unique=false
preserveBlocks=false
preventNaturalHostileSpawns=false
selectionWeight=1
clusterValue=1
minDuplicateDistance=1
dimensionWhiteList=true
dimensionList=
biomeGroupList=
biomeWhiteList=true
biomeList=
leveling=0
fill=0
border=0
blockSwap=false
territoryName=
biomeReplacement=minecraft:
minGenerationHeight=0
maxGenerationHeight=255
:endvalidation

#### LAYERS ####
layer: 0
1,1,1,1,1,1,1,1,1,1,1,1,1,1,1,1,1,1
1,1,1,1,1,1,2,2,2,2,2,2,1,1,1,1,1,1
1,1,1,1,1,1,2,2,2,2,2,2,1,1,1,1,1,1
2,1,1,1,1,2,2,2,2,2,2,2,2,1,1,1,1,2
2,2,2,2,2,2,2,2,2,2,2,2,2,2,2,2,2,2
2,2,2,2,2,2,2,2,2,2,2,2,2,2,2,2,2,2
2,1,1,1,1,2,2,2,2,2,2,2,2,1,1,1,1,2
1,1,1,1,1,1,2,1,1,1,1,2,1,1,1,1,1,1
:endlayer
layer: 1
0,0,0,0,0,0,0,0,0,0,0,0,0,0,0,0,0,0
0,0,0,0,0,0,8,2,0,0,2,8,0,0,0,0,0,0
0,0,0,0,0,0,2,0,0,0,0,2,0,0,0,0,0,0
3,0,0,0,0,3,2,0,7,7,0,2,3,0,0,0,0,3
2,2,2,2,2,2,2,6,0,5,4,2,2,2,2,2,2,2
2,2,2,2,2,2,2,2,2,2,2,2,2,2,2,2,2,2
3,0,0,0,0,3,2,2,2,2,2,2,3,0,0,0,0,3
0,0,0,0,0,0,3,0,0,0,0,3,0,0,0,0,0,0
:endlayer
layer: 2
0,0,0,0,0,0,0,0,0,0,0,0,0,0,0,0,0,0
0,0,0,0,0,0,8,2,0,0,2,8,0,0,0,0,0,0
0,0,0,0,0,0,2,10,0,0,0,2,0,0,0,0,0,0
3,10,0,0,9,3,2,0,7,7,0,2,3,10,0,0,9,3
2,2,2,2,2,2,2,5,4,0,0,2,2,2,2,2,2,2
2,2,2,2,2,2,2,2,2,2,2,2,2,2,2,2,2,2
3,10,0,0,9,3,2,2,2,2,2,2,3,10,0,0,9,3
0,0,0,0,0,0,3,10,0,0,9,3,0,0,0,0,0,0
:endlayer
layer: 3
0,0,0,0,0,0,0,6,0,0,6,0,0,0,0,0,0,0
0,0,0,0,0,0,8,2,12,11,2,8,0,0,0,0,0,0
0,0,0,0,0,0,2,5,0,0,0,2,0,0,0,0,0,0
3,0,0,0,0,3,2,4,7,7,0,2,3,0,0,0,0,3
2,2,2,2,2,2,2,0,0,0,0,2,2,2,2,2,2,2
2,2,2,2,2,2,2,2,2,2,2,2,2,2,2,2,2,2
3,0,0,0,0,3,2,2,2,2,2,2,3,0,0,0,0,3
0,0,0,0,0,0,3,0,0,0,0,3,0,0,0,0,0,0
:endlayer
layer: 4
0,0,0,0,0,0,0,0,0,0,0,0,0,0,0,0,0,0
0,0,0,0,0,0,8,2,2,2,2,8,0,0,0,0,0,0
0,0,0,0,0,0,2,0,4,5,15,2,0,0,0,0,0,0
3,14,0,0,13,3,2,0,7,7,0,2,3,14,0,0,13,3
2,2,2,2,2,2,2,0,0,0,0,2,2,2,2,2,2,2
2,2,2,2,2,2,2,2,2,2,2,2,2,2,2,2,2,2
3,14,0,0,13,3,2,2,2,2,2,2,3,14,0,0,13,3
0,0,0,0,0,0,3,14,0,0,13,3,0,0,0,0,0,0
:endlayer
layer: 5
0,0,0,0,0,0,0,0,0,0,0,0,0,0,0,0,0,0
0,0,0,0,0,0,8,2,17,17,2,8,0,0,0,0,0,0
0,0,0,0,0,0,2,0,0,0,4,2,0,0,0,0,0,0
3,16,16,16,16,3,2,0,7,7,5,2,3,16,16,16,16,3
2,2,2,2,2,2,2,6,0,0,9,2,2,2,2,2,2,2
2,2,2,2,2,2,2,2,2,2,2,2,2,2,2,2,2,2
3,16,16,16,16,3,2,2,2,2,2,2,3,16,16,16,16,3
0,0,0,0,0,0,3,16,16,16,16,3,0,0,0,0,0,0
:endlayer
layer: 6
0,0,0,0,0,0,0,0,0,0,0,0,0,0,0,0,0,0
0,0,0,0,0,0,8,2,0,0,2,8,0,0,0,0,0,0
6,0,0,0,0,0,2,10,0,0,0,2,6,0,0,0,0,6
3,20,19,19,20,3,2,5,7,7,0,2,3,20,19,19,20,3
17,17,17,17,17,17,17,4,4,4,4,17,17,17,17,17,17,17
17,17,17,17,17,17,17,17,17,17,17,17,17,17,17,17,17,17
3,18,19,19,18,3,8,2,2,2,2,8,3,18,19,19,18,3
15,0,0,0,0,15,3,4,4,4,4,3,15,0,0,0,0,15
:endlayer
layer: 7
0,0,0,0,0,0,0,0,0,0,0,0,0,0,0,0,0,0
0,0,0,0,0,0,8,2,12,11,2,8,0,0,0,0,0,0
0,0,0,0,0,0,0,4,5,0,0,0,0,0,0,0,0,0
4,0,4,4,0,4,2,0,7,7,0,2,4,0,4,4,0,4
0,0,0,0,0,0,0,0,0,0,0,0,0,0,0,0,0,0
0,0,0,0,0,0,0,0,0,0,0,0,0,0,0,0,0,0
4,0,4,4,0,4,8,0,2,2,0,8,4,0,4,4,0,4
0,0,0,0,0,0,4,0,0,0,0,4,0,0,0,0,0,0
:endlayer
layer: 8
0,0,0,0,0,0,0,0,0,0,0,0,0,0,0,0,0,0
0,0,0,0,0,0,8,2,2,2,2,8,0,0,0,0,0,0
0,0,0,0,0,0,21,0,0,4,5,21,0,0,0,0,0,0
0,0,0,0,0,0,2,0,7,7,0,2,0,0,0,0,0,0
0,0,0,0,0,0,0,0,0,0,0,0,0,0,0,0,0,0
0,0,0,0,0,0,0,0,0,0,0,0,0,0,0,0,0,0
0,0,0,0,0,0,8,21,2,2,21,8,0,0,0,0,0,0
0,0,0,0,0,0,0,0,0,0,0,0,0,0,0,0,0,0
:endlayer
layer: 9
0,0,0,0,0,0,23,5,5,5,5,23,0,0,0,0,0,0
0,0,0,0,0,13,8,2,2,2,2,8,14,0,0,0,0,0
0,0,0,0,0,5,2,0,0,0,0,2,5,0,0,0,0,0
0,0,0,0,0,5,2,0,7,7,4,2,5,0,0,0,0,0
0,0,0,0,0,5,2,5,5,5,5,2,5,0,0,0,0,0
0,0,0,0,0,5,2,5,5,5,5,2,5,0,0,0,0,0
0,0,0,0,0,13,8,2,2,2,2,8,14,0,0,0,0,0
0,0,0,0,0,0,22,5,5,5,5,22,0,0,0,0,0,0
:endlayer
layer: 10
0,0,0,0,0,0,3,20,19,19,20,3,0,0,0,0,0,0
0,0,0,0,0,3,4,4,4,4,4,4,3,0,0,0,0,0
0,0,0,0,0,25,4,0,0,0,0,4,24,0,0,0,0,0
0,0,0,0,0,19,4,0,7,7,0,4,19,0,0,0,0,0
0,0,0,0,0,19,4,26,7,7,26,4,19,0,0,0,0,0
0,0,0,0,0,25,4,0,0,0,0,4,24,0,0,0,0,0
0,0,0,0,0,3,4,4,4,4,4,4,3,0,0,0,0,0
0,0,0,0,0,0,3,18,19,19,18,3,0,0,0,0,0,0
:endlayer
layer: 11
0,0,0,0,0,0,4,0,4,4,0,4,0,0,0,0,0,0
0,0,0,0,0,4,0,0,0,0,0,0,4,0,0,0,0,0
0,0,0,0,0,0,0,0,0,0,0,0,0,0,0,0,0,0
0,0,0,0,0,4,0,0,0,0,0,0,4,0,0,0,0,0
0,0,0,0,0,4,0,0,0,0,0,0,4,0,0,0,0,0
0,0,0,0,0,0,0,0,0,0,0,0,0,0,0,0,0,0
0,0,0,0,0,4,0,0,0,0,0,0,4,0,0,0,0,0
0,0,0,0,0,0,4,0,4,4,0,4,0,0,0,0,0,0
:endlayer

#### RULES ####
rule:
plugin=vanillaBlocks
number=1
data:
JSON:{blockState:{blockName:"minecraft:grass",properties:{snowy:"false"}}}
:enddata
:endrule

rule:
plugin=vanillaBlocks
number=2
data:
JSON:{blockState:{blockName:"minecraft:cobblestone"}}
:enddata
:endrule

rule:
plugin=vanillaBlocks
number=3
data:
JSON:{blockState:{blockName:"rustic:log",properties:{variant:"olive",axis:"y"}}}
:enddata
:endrule

rule:
plugin=vanillaBlocks
number=4
data:
JSON:{blockState:{blockName:"rustic:olive_slab",properties:{half:"bottom"}}}
:enddata
:endrule

rule:
plugin=vanillaBlocks
number=5
data:
JSON:{blockState:{blockName:"rustic:olive_slab",properties:{half:"top"}}}
:enddata
:endrule

rule:
plugin=vanillaBlocks
number=6
data:
JSON:{blockState:{blockName:"minecraft:torch",properties:{facing:"north"}}}
:enddata
:endrule

rule:
plugin=vanillaBlocks
number=7
data:
JSON:{blockState:{blockName:"rustic:fence_olive",properties:{east:"false",south:"false",north:"false",west:"false"}}}
:enddata
:endrule

rule:
plugin=vanillaBlocks
number=8
data:
JSON:{blockState:{blockName:"minecraft:stonebrick",properties:{variant:"stonebrick"}}}
:enddata
:endrule

rule:
plugin=vanillaBlocks
number=9
data:
JSON:{blockState:{blockName:"minecraft:torch",properties:{facing:"west"}}}
:enddata
:endrule

rule:
plugin=vanillaBlocks
number=10
data:
JSON:{blockState:{blockName:"minecraft:torch",properties:{facing:"east"}}}
:enddata
:endrule

rule:
plugin=vanillaBlocks
number=11
data:
JSON:{blockState:{blockName:"minecraft:stone_stairs",properties:{half:"top",shape:"straight",facing:"east"}}}
:enddata
:endrule

rule:
plugin=vanillaBlocks
number=12
data:
JSON:{blockState:{blockName:"minecraft:stone_stairs",properties:{half:"top",shape:"straight",facing:"west"}}}
:enddata
:endrule

rule:
plugin=vanillaBlocks
number=13
data:
JSON:{blockState:{blockName:"rustic:stairs_olive",properties:{half:"top",shape:"straight",facing:"east"}}}
:enddata
:endrule

rule:
plugin=vanillaBlocks
number=14
data:
JSON:{blockState:{blockName:"rustic:stairs_olive",properties:{half:"top",shape:"straight",facing:"west"}}}
:enddata
:endrule

rule:
plugin=vanillaBlocks
number=15
data:
JSON:{blockState:{blockName:"minecraft:torch",properties:{facing:"south"}}}
:enddata
:endrule

rule:
plugin=vanillaBlocks
number=16
data:
JSON:{blockState:{blockName:"rustic:log",properties:{variant:"olive",axis:"x"}}}
:enddata
:endrule

rule:
plugin=vanillaBlocks
number=17
data:
JSON:{blockState:{blockName:"minecraft:stone_slab",properties:{half:"bottom",variant:"cobblestone"}}}
:enddata
:endrule

rule:
plugin=vanillaBlocks
number=18
data:
JSON:{blockState:{blockName:"rustic:stairs_olive",properties:{half:"bottom",shape:"straight",facing:"north"}}}
:enddata
:endrule

rule:
plugin=vanillaBlocks
number=19
data:
JSON:{blockState:{blockName:"rustic:planks",properties:{variant:"olive"}}}
:enddata
:endrule

rule:
plugin=vanillaBlocks
number=20
data:
JSON:{blockState:{blockName:"rustic:stairs_olive",properties:{half:"bottom",shape:"straight",facing:"south"}}}
:enddata
:endrule

rule:
plugin=vanillaBlocks
number=21
data:
JSON:{blockState:{blockName:"minecraft:stone_slab",properties:{half:"top",variant:"cobblestone"}}}
:enddata
:endrule

rule:
plugin=vanillaBlocks
number=22
data:
JSON:{blockState:{blockName:"rustic:stairs_olive",properties:{half:"top",shape:"straight",facing:"north"}}}
:enddata
:endrule

rule:
plugin=vanillaBlocks
number=23
data:
JSON:{blockState:{blockName:"rustic:stairs_olive",properties:{half:"top",shape:"straight",facing:"south"}}}
:enddata
:endrule

rule:
plugin=vanillaBlocks
number=24
data:
JSON:{blockState:{blockName:"rustic:stairs_olive",properties:{half:"bottom",shape:"straight",facing:"west"}}}
:enddata
:endrule

rule:
plugin=vanillaBlocks
number=25
data:
JSON:{blockState:{blockName:"rustic:stairs_olive",properties:{half:"bottom",shape:"straight",facing:"east"}}}
:enddata
:endrule

rule:
plugin=vanillaBlocks
number=26
data:
JSON:{blockState:{blockName:"minecraft:torch",properties:{facing:"up"}}}
:enddata
:endrule

#### ENTITIES ####
