# Ancient Warfare Structure Template File
# Auto-generated structure template file. created on: 5/6/2021 at: 13:11:31
# Lines beginning with # denote comments

header:
version=2.11
name=SurvivalBuild_FortWall_extreme_type1_protection1_InnerAngle_EXPLORERCRAFTbasalt
mods=explorercraft
size=16,41,16
offset=0,5,15
:endheader

#### VALIDATION ####
validation:
type=ground
structureAuthor=TheOddlySeagull
survival=true
worldGenEnabled=false
unique=false
preserveBlocks=false
preventNaturalHostileSpawns=false
selectionWeight=1
clusterValue=1
minDuplicateDistance=1
dimensionWhiteList=true
dimensionList=
biomeGroupList=
biomeWhiteList=true
biomeList=
leveling=0
fill=0
border=0
blockSwap=false
territoryName=
biomeReplacement=minecraft:
minGenerationHeight=0
maxGenerationHeight=255
:endvalidation

#### LAYERS ####
layer: 0
1,1,1,1,1,1,1,1,2,2,2,2,1,1,1,1
1,1,1,1,1,1,1,2,2,2,2,2,2,1,1,1
1,1,1,1,1,1,2,2,2,2,2,2,2,2,1,1
2,2,2,2,2,2,2,2,2,2,2,2,2,2,2,1
2,2,2,2,2,2,2,2,2,2,2,2,2,2,2,2
2,2,2,2,2,2,2,2,2,2,2,2,2,2,2,2
2,2,2,2,2,2,2,2,2,2,2,2,2,2,2,2
2,2,2,2,2,2,2,2,2,2,2,2,2,2,2,2
2,2,2,2,2,2,2,2,2,2,2,2,2,2,2,1
2,2,2,2,2,2,2,2,2,2,2,2,2,2,1,1
2,2,2,2,2,2,2,2,2,2,2,2,2,1,1,1
2,2,2,2,2,2,2,2,2,2,2,2,2,1,1,1
2,2,2,2,2,2,2,2,2,2,2,2,2,1,1,1
1,1,1,2,2,2,2,2,2,2,2,2,2,1,1,1
1,1,1,2,2,2,2,2,2,2,2,2,2,1,1,1
1,1,1,2,2,2,2,2,2,2,2,2,2,1,1,1
:endlayer
layer: 1
1,1,1,1,1,1,1,1,2,2,2,2,1,1,1,1
1,1,1,1,1,1,1,2,2,2,2,2,2,1,1,1
1,1,1,1,1,1,2,2,2,2,2,2,2,2,1,1
2,2,2,2,2,2,2,2,2,2,2,2,2,2,2,1
2,2,2,2,2,2,2,2,2,2,2,2,2,2,2,2
2,2,2,2,2,2,2,2,2,2,2,2,2,2,2,2
2,2,2,2,2,2,2,2,2,2,2,2,2,2,2,2
2,2,2,2,2,2,2,2,2,2,2,2,2,2,2,2
2,2,2,2,2,2,2,2,2,2,2,2,2,2,2,1
2,2,2,2,2,2,2,2,2,2,2,2,2,2,1,1
2,2,2,2,2,2,2,2,2,2,2,2,2,1,1,1
2,2,2,2,2,2,2,2,2,2,2,2,2,1,1,1
2,2,2,2,2,2,2,2,2,2,2,2,2,1,1,1
1,1,1,2,2,2,2,2,2,2,2,2,2,1,1,1
1,1,1,2,2,2,2,2,2,2,2,2,2,1,1,1
1,1,1,2,2,2,2,2,2,2,2,2,2,1,1,1
:endlayer
layer: 2
1,1,1,1,1,1,1,1,2,2,2,2,1,1,1,1
1,1,1,1,1,1,1,2,2,2,2,2,2,1,1,1
1,1,1,1,1,1,2,2,2,2,2,2,2,2,1,1
2,1,1,1,1,2,2,2,2,2,2,2,2,2,2,1
2,2,2,2,2,2,2,2,2,2,2,2,2,2,2,2
2,2,2,2,2,2,2,2,2,2,2,2,2,2,2,2
2,2,2,2,2,2,2,2,2,2,2,2,2,2,2,2
2,2,2,2,2,2,2,2,2,2,2,2,2,2,2,2
2,2,2,2,2,2,2,2,2,2,2,2,2,2,2,1
2,2,2,2,2,2,2,2,2,2,2,2,2,2,1,1
2,2,2,2,2,2,2,2,2,2,2,2,2,1,1,1
2,2,2,2,2,2,2,2,2,2,2,2,1,1,1,1
2,2,2,2,2,2,2,2,2,2,2,2,1,1,1,1
3,3,3,2,2,2,2,2,2,2,2,2,1,1,1,1
3,3,3,2,2,2,2,2,2,2,2,2,1,1,1,1
3,3,3,2,2,2,2,2,2,2,2,2,2,1,1,1
:endlayer
layer: 3
1,1,1,1,1,1,1,1,2,2,2,2,1,1,1,1
1,1,1,1,1,1,1,2,2,2,2,2,2,1,1,1
1,1,1,1,1,1,2,2,2,2,2,2,2,2,1,1
2,1,1,1,1,2,2,2,2,2,2,2,2,2,2,1
2,2,2,2,2,2,2,2,2,2,2,2,2,2,2,2
2,2,2,2,2,2,2,2,2,2,2,2,2,2,2,2
2,2,2,2,2,2,2,2,2,2,2,2,2,2,2,2
2,2,2,2,2,2,2,2,2,2,2,2,2,2,2,2
2,2,2,2,2,2,2,2,2,2,2,2,2,2,2,1
2,2,2,2,2,2,2,2,2,2,2,2,2,2,1,1
2,2,2,2,2,2,2,2,2,2,2,2,2,1,1,1
2,2,2,2,2,2,2,2,2,2,2,2,1,1,1,1
2,2,2,2,2,2,2,2,2,2,2,2,1,1,1,1
3,3,3,2,2,2,2,2,2,2,2,2,1,1,1,1
3,3,3,2,2,2,2,2,2,2,2,2,1,1,1,1
3,3,3,2,2,2,2,2,2,2,2,2,2,1,1,1
:endlayer
layer: 4
4,4,4,4,4,4,4,4,2,2,2,2,4,4,4,4
4,4,4,4,4,4,4,2,2,2,2,2,2,4,4,4
4,4,4,4,4,4,2,2,2,2,2,2,2,2,4,4
2,4,4,4,4,2,2,2,2,2,2,2,2,2,2,4
2,2,2,2,2,2,2,2,2,2,2,2,2,2,2,2
2,2,2,2,2,2,2,2,2,2,2,2,2,2,2,2
2,2,2,2,2,2,2,2,2,2,2,2,2,2,2,2
2,2,2,2,2,2,2,2,2,2,2,2,2,2,2,2
2,2,2,2,2,2,2,2,2,2,2,2,2,2,2,4
2,2,2,2,2,2,2,2,2,2,2,2,2,2,4,4
2,2,2,2,2,2,2,2,2,2,2,2,2,4,4,4
2,2,2,2,2,2,2,2,2,2,2,2,4,4,4,4
2,5,5,5,2,2,2,2,2,2,2,2,4,4,4,4
5,5,5,5,2,2,2,2,2,2,2,2,4,4,4,4
5,5,5,5,2,2,2,2,2,2,2,2,4,4,4,4
5,5,5,2,2,2,2,2,2,2,2,2,2,4,4,4
:endlayer
layer: 5
0,0,0,0,0,0,0,0,2,2,2,2,0,0,0,0
0,0,0,0,0,0,0,2,2,2,2,2,2,0,0,0
0,0,0,0,0,0,2,2,2,2,2,2,2,2,0,0
2,0,0,0,0,2,2,2,2,2,2,2,2,2,2,0
2,2,2,2,2,2,2,2,2,2,2,2,2,2,2,2
2,2,2,2,2,2,2,2,2,2,2,2,2,2,2,2
2,2,2,2,2,2,2,2,2,2,2,2,2,2,2,2
2,2,2,2,2,2,2,2,2,2,2,2,2,2,2,2
2,2,2,2,2,2,2,2,2,2,2,2,2,2,2,0
2,2,2,2,2,2,2,2,2,2,2,2,2,2,0,0
2,2,2,2,2,2,2,2,2,2,2,2,2,0,0,0
2,2,2,2,2,2,2,2,2,2,2,2,0,0,0,0
2,0,0,0,2,2,2,2,2,2,2,2,0,0,0,0
0,0,0,0,2,2,2,2,2,2,2,2,0,0,0,0
0,0,0,0,2,2,2,2,2,2,2,2,0,0,0,0
0,0,0,2,2,2,2,2,2,2,2,2,2,0,0,0
:endlayer
layer: 6
0,0,0,0,0,0,0,0,2,2,2,2,0,0,0,0
0,0,0,0,0,0,0,2,2,2,2,2,2,0,0,0
0,0,0,0,0,0,2,2,2,2,2,2,2,2,0,0
2,0,0,0,0,2,2,2,2,2,2,2,2,2,2,0
2,2,2,2,2,2,2,2,2,2,2,2,2,2,2,2
2,2,2,2,2,2,2,2,2,2,2,2,2,2,2,2
2,2,2,2,2,2,2,2,2,2,2,2,2,2,2,2
2,2,2,2,2,2,2,2,2,2,2,2,2,2,2,2
2,2,2,2,2,2,2,2,2,2,2,2,2,2,2,0
2,2,2,2,2,2,2,2,2,2,2,2,2,2,0,0
2,2,2,2,2,2,2,2,2,2,2,2,2,0,0,0
2,2,2,2,2,2,2,2,2,2,2,2,0,0,0,0
2,6,7,7,2,2,2,2,2,2,2,2,0,0,0,0
7,0,0,8,2,2,2,2,2,2,2,2,0,0,0,0
0,0,0,6,2,2,2,2,2,2,2,2,0,0,0,0
0,0,8,2,2,2,2,2,2,2,2,2,2,0,0,0
:endlayer
layer: 7
0,0,0,0,0,0,0,0,2,2,2,2,0,0,0,0
0,0,0,0,0,0,0,2,2,2,2,2,2,0,0,0
0,0,0,0,0,0,2,2,2,2,2,2,2,2,0,0
2,0,0,0,0,2,2,2,2,2,2,2,2,2,2,0
2,2,2,2,2,2,2,2,2,2,2,2,2,2,2,2
2,2,2,2,2,2,2,2,2,2,2,2,2,2,2,2
2,2,2,2,2,2,2,2,2,2,2,2,2,2,2,2
2,2,2,2,2,2,2,2,2,2,2,2,2,2,2,2
2,2,2,2,2,2,2,2,2,2,2,2,2,2,2,0
2,2,2,2,2,2,2,2,2,2,2,2,2,2,0,0
2,2,2,2,2,2,2,2,2,2,2,2,2,0,0,0
2,2,2,2,2,2,2,2,2,2,2,2,0,0,0,0
2,0,9,9,2,2,2,2,2,2,2,2,0,0,0,0
9,0,0,9,2,2,2,2,2,2,2,2,0,0,0,0
0,0,0,0,2,2,2,2,2,2,2,2,0,0,0,0
0,0,9,2,2,2,2,2,2,2,2,2,2,0,0,0
:endlayer
layer: 8
0,0,0,0,0,0,0,0,10,2,2,10,0,0,0,0
0,0,0,0,0,0,0,11,2,2,2,2,12,0,0,0
0,0,0,0,0,0,13,2,2,2,2,2,2,13,0,0
2,0,0,0,0,2,2,2,2,2,2,2,2,2,10,0
2,2,2,2,2,2,2,2,2,2,2,2,2,2,2,12
2,2,2,2,2,2,2,2,2,2,2,2,2,2,2,2
2,2,2,2,2,2,2,2,2,2,2,2,2,2,2,2
2,2,2,2,2,2,2,2,2,2,2,2,2,2,2,12
2,2,2,2,2,2,2,2,2,2,2,2,2,2,14,0
2,2,2,2,2,2,2,2,2,2,2,2,2,13,0,0
2,2,2,2,2,2,2,2,2,2,2,2,2,0,0,0
2,13,2,2,2,2,2,2,2,2,2,2,0,0,0,0
2,0,0,0,2,2,2,2,2,2,2,2,0,0,0,0
0,0,0,0,2,2,2,2,2,2,2,2,0,0,0,0
0,0,0,0,13,2,2,2,2,2,2,2,0,0,0,0
0,0,0,2,2,2,2,2,2,2,2,2,2,0,0,0
:endlayer
layer: 9
0,0,0,0,0,0,0,0,0,10,10,0,0,0,0,0
0,0,0,0,0,0,0,0,2,2,2,2,0,0,0,0
0,0,0,0,0,0,15,2,2,2,2,2,2,15,0,0
2,0,0,0,0,2,2,2,2,2,2,2,2,2,0,0
2,2,2,2,2,2,2,2,2,2,2,2,2,2,2,0
2,2,2,2,2,2,2,2,2,2,2,2,2,2,2,12
2,2,2,2,2,2,2,2,2,2,2,2,2,2,2,12
2,2,2,2,2,2,2,2,2,2,2,2,2,2,2,0
2,2,2,2,2,2,2,2,2,2,2,2,2,2,0,0
2,2,2,2,2,2,2,2,2,2,2,2,2,15,0,0
2,2,2,2,2,2,2,2,2,2,2,2,2,0,0,0
2,2,2,2,2,2,2,2,2,2,2,2,0,0,0,0
2,0,0,0,2,2,2,2,2,2,2,2,0,0,0,0
0,0,0,0,2,2,2,2,2,2,2,2,0,0,0,0
0,0,0,0,2,2,2,2,2,2,2,2,0,0,0,0
0,0,0,2,2,2,2,2,2,2,2,2,2,0,0,0
:endlayer
layer: 10
0,0,0,0,0,0,0,0,0,0,0,0,0,0,0,0
0,0,0,0,0,0,0,0,2,2,2,2,0,0,0,0
0,0,0,0,0,0,15,2,2,2,2,2,2,15,0,0
2,0,0,0,0,2,2,2,2,2,2,2,2,2,0,0
2,2,10,10,2,2,2,2,2,2,2,2,2,2,2,0
2,2,2,2,2,2,2,2,2,2,2,2,2,2,2,0
2,2,2,2,2,2,2,2,2,2,2,2,2,2,2,0
2,2,2,2,2,2,2,2,2,2,2,2,2,2,2,0
2,2,2,2,2,2,2,2,2,2,2,2,2,2,0,0
2,2,2,2,2,2,2,2,2,2,2,2,2,15,0,0
2,2,2,2,2,2,2,2,2,2,2,2,2,0,0,0
2,14,14,14,14,2,2,2,2,2,2,2,0,0,0,0
2,0,0,0,11,2,2,2,2,2,2,12,0,0,0,0
0,0,0,0,11,2,2,2,2,2,2,12,0,0,0,0
0,0,0,0,11,2,2,2,2,2,2,2,0,0,0,0
0,0,0,2,2,2,2,2,2,2,2,2,2,0,0,0
:endlayer
layer: 11
0,0,0,0,0,0,0,0,0,0,0,0,0,0,0,0
0,0,0,0,0,0,0,0,2,2,2,2,0,0,0,0
0,0,0,0,0,0,15,2,2,2,2,2,2,15,0,0
10,0,0,0,0,10,2,2,2,2,2,2,2,2,0,0
2,10,0,0,10,2,2,2,2,2,2,2,2,2,2,0
2,2,2,2,2,2,2,2,2,2,2,2,2,2,2,0
2,2,2,2,2,2,2,2,2,2,2,2,2,2,2,0
2,2,2,2,2,2,2,2,2,2,2,2,2,2,2,0
2,2,2,2,2,2,2,2,2,2,2,2,2,2,0,0
2,2,2,2,2,2,2,2,2,2,2,2,2,15,0,0
2,2,2,2,2,2,2,2,2,2,2,2,12,0,0,0
2,0,0,0,0,2,2,2,2,2,2,12,0,0,0,0
14,0,0,0,0,2,2,2,2,2,2,0,0,0,0,0
0,0,0,0,0,2,2,2,2,2,2,0,0,0,0,0
0,0,0,0,0,2,2,2,2,2,2,12,0,0,0,0
0,0,0,11,2,2,2,2,2,2,2,2,12,0,0,0
:endlayer
layer: 12
0,0,0,0,0,0,0,0,0,0,0,0,0,0,0,0
0,0,0,0,0,0,0,0,2,2,2,2,0,0,0,0
0,0,0,0,0,0,15,2,2,2,2,2,2,15,0,0
0,0,0,0,0,0,2,2,2,2,2,2,2,2,0,0
2,0,0,0,0,2,2,2,2,2,2,2,2,2,2,0
2,2,2,2,2,2,2,2,2,2,2,2,2,2,2,0
2,2,2,2,2,2,2,2,2,2,2,2,2,2,2,0
2,2,2,2,2,2,2,2,2,2,2,2,2,2,2,0
2,2,2,2,2,2,2,2,2,2,2,2,2,2,0,0
2,2,2,2,2,2,2,2,2,2,2,2,2,15,0,0
2,2,2,2,2,2,2,2,2,2,2,2,0,0,0,0
2,0,0,0,0,2,2,2,2,2,2,0,0,0,0,0
0,0,0,0,0,2,2,2,2,2,2,0,0,0,0,0
0,0,0,0,0,2,2,2,2,2,2,0,0,0,0,0
0,0,0,0,0,2,2,2,2,2,2,0,0,0,0,0
0,0,0,0,2,2,2,2,2,2,2,2,0,0,0,0
:endlayer
layer: 13
0,0,0,0,0,0,0,0,0,0,0,0,0,0,0,0
0,0,0,0,0,0,0,0,2,2,2,2,0,0,0,0
0,0,0,0,0,0,15,2,2,2,2,2,2,15,0,0
0,0,0,0,0,0,2,2,2,2,2,2,2,2,0,0
2,0,0,0,0,2,2,2,2,2,2,2,2,2,2,0
2,2,2,2,2,2,2,2,2,2,2,2,2,2,2,0
2,2,2,2,2,2,2,2,2,2,2,2,2,2,2,0
2,2,2,2,2,2,2,2,2,2,2,2,2,2,2,0
2,2,2,2,2,2,2,2,2,2,2,2,2,2,0,0
2,2,2,2,2,2,2,2,2,2,2,2,2,15,0,0
2,2,2,2,2,2,2,2,2,2,2,2,0,0,0,0
2,0,0,0,0,2,2,2,2,2,2,0,0,0,0,0
0,0,0,0,0,2,2,2,2,2,2,0,0,0,0,0
0,0,0,0,0,2,2,2,2,2,2,0,0,0,0,0
0,0,0,0,0,2,2,2,2,2,2,0,0,0,0,0
0,0,0,0,2,2,2,2,2,2,2,2,0,0,0,0
:endlayer
layer: 14
0,0,0,0,0,0,0,0,0,0,0,0,0,0,0,0
0,0,0,0,0,0,0,0,2,2,2,2,0,0,0,0
0,0,0,0,0,0,15,2,2,2,2,2,2,15,0,0
0,0,0,0,0,0,2,2,2,2,2,2,2,2,0,0
2,0,0,0,0,2,2,2,2,2,2,2,2,2,2,0
2,2,2,2,2,2,2,2,2,2,2,2,2,2,2,0
2,2,2,2,2,2,2,2,2,2,2,2,2,2,2,0
2,2,2,2,2,2,2,2,2,2,2,2,2,2,2,0
2,2,2,2,2,2,2,2,2,2,2,2,2,2,0,0
2,2,2,2,2,2,2,2,2,2,2,2,2,15,0,0
2,2,2,2,2,2,2,2,2,2,2,2,0,0,0,0
2,0,0,0,0,2,2,2,2,2,2,0,0,0,0,0
0,0,0,0,0,2,2,2,2,2,2,0,0,0,0,0
0,0,0,0,0,2,2,2,2,2,2,0,0,0,0,0
0,0,0,0,0,2,2,2,2,2,2,0,0,0,0,0
0,0,0,0,2,2,2,2,2,2,2,2,0,0,0,0
:endlayer
layer: 15
0,0,0,0,0,0,0,0,6,16,16,6,0,0,0,0
0,0,0,0,0,0,6,16,2,2,2,2,16,6,0,0
0,0,0,0,0,6,2,2,2,2,2,2,2,2,6,0
0,0,0,0,0,8,2,2,2,2,2,2,2,2,17,0
2,0,0,0,0,2,2,2,2,2,2,2,2,2,2,6
2,2,2,2,2,2,2,2,2,2,2,2,2,2,2,17
2,2,2,2,2,2,2,2,2,2,2,2,2,2,2,17
2,2,2,2,2,2,2,2,2,2,2,2,2,2,2,6
2,2,2,2,2,2,2,2,2,2,2,2,2,2,17,0
2,2,2,2,2,2,2,2,2,2,2,2,2,2,6,0
2,2,2,2,2,2,2,2,2,2,2,2,7,6,0,0
2,0,0,0,0,2,2,2,2,2,2,0,0,0,0,0
0,0,0,0,0,2,2,2,2,2,2,0,0,0,0,0
0,0,0,0,0,2,2,2,2,2,2,0,0,0,0,0
0,0,0,0,0,2,2,2,2,2,2,0,0,0,0,0
0,0,0,0,2,2,2,2,2,2,2,2,0,0,0,0
:endlayer
layer: 16
0,0,0,0,0,0,0,0,0,9,9,0,0,0,0,0
0,0,0,0,0,0,0,9,2,2,10,2,9,0,0,0
0,0,0,0,0,0,15,2,2,2,2,2,2,15,0,0
0,0,0,0,0,9,2,2,2,2,2,2,2,2,9,0
2,0,0,0,0,2,2,2,2,2,2,2,2,2,2,0
2,2,2,2,2,2,2,2,2,2,2,2,2,2,2,9
2,2,2,2,2,2,2,2,2,2,2,2,2,2,12,9
2,2,2,2,2,2,2,2,2,2,2,2,2,2,2,0
2,2,2,2,2,2,2,2,2,2,2,2,2,2,9,0
2,2,2,2,2,2,2,2,2,2,2,2,2,15,0,0
2,2,2,2,2,2,2,2,2,2,2,2,9,0,0,0
2,0,0,0,0,2,2,2,2,2,2,0,0,0,0,0
0,0,0,0,0,2,2,2,2,2,2,0,0,0,0,0
0,0,0,0,0,2,2,2,2,2,2,0,0,0,0,0
0,0,0,0,0,2,2,2,2,2,2,0,0,0,0,0
0,0,0,0,2,2,2,2,2,2,2,2,0,0,0,0
:endlayer
layer: 17
0,0,0,0,0,0,0,0,0,0,0,0,0,0,0,0
0,0,0,0,0,0,0,0,2,2,0,2,0,0,0,0
0,0,0,0,0,0,15,2,2,2,13,2,2,15,0,0
0,0,0,0,0,0,2,2,2,2,2,2,2,2,0,0
13,17,0,0,8,13,2,2,2,2,2,2,2,2,2,0
2,2,2,2,2,2,2,2,2,2,2,2,2,2,2,0
2,2,2,2,2,2,2,2,2,2,2,2,2,13,0,0
2,2,2,2,2,2,2,2,2,2,2,2,2,2,2,0
2,2,2,2,2,2,2,2,2,2,2,2,2,2,0,0
2,2,2,2,2,2,2,2,2,2,2,2,2,15,0,0
2,2,2,2,2,2,2,2,2,2,2,13,0,0,0,0
13,17,0,0,0,2,2,2,2,2,2,7,0,0,0,0
0,0,0,0,0,2,2,2,2,2,2,0,0,0,0,0
0,0,0,0,0,2,2,2,2,2,2,0,0,0,0,0
0,0,0,0,16,2,2,2,2,2,2,16,0,0,0,0
0,0,0,0,13,2,2,2,2,2,2,13,0,0,0,0
:endlayer
layer: 18
0,0,0,0,0,0,0,0,0,0,0,0,0,0,0,0
0,0,0,0,0,0,0,0,2,2,16,2,0,0,0,0
0,0,0,0,0,0,15,2,2,2,2,2,2,15,0,0
16,0,0,0,0,16,2,2,2,2,2,2,2,2,0,0
2,2,2,2,2,2,2,2,2,2,2,2,2,2,2,0
2,2,2,2,2,2,2,2,2,2,2,2,2,2,2,0
2,2,2,2,2,2,2,2,2,2,2,2,2,2,17,0
2,2,2,2,2,2,2,2,2,2,2,2,2,2,2,0
2,2,2,2,2,2,2,2,2,2,2,2,2,2,0,0
2,2,2,2,2,2,2,2,2,2,2,2,2,15,0,0
2,2,2,2,2,2,2,2,2,2,2,2,17,0,0,0
2,2,2,2,2,2,2,2,2,2,2,2,0,0,0,0
0,0,0,0,2,2,2,2,2,2,2,2,0,0,0,0
0,0,0,0,2,2,2,2,2,2,2,2,0,0,0,0
0,0,0,0,2,2,2,2,2,2,2,2,0,0,0,0
0,0,0,0,2,2,2,2,2,2,2,2,17,0,0,0
:endlayer
layer: 19
0,0,0,0,0,0,0,0,0,0,0,0,0,0,0,0
0,0,0,0,0,0,0,0,2,2,2,2,0,0,0,0
0,0,0,0,0,0,15,2,2,2,2,2,2,15,0,0
13,0,0,0,0,13,13,2,2,2,2,2,2,2,0,0
2,2,2,2,2,2,2,2,2,2,2,2,2,2,2,0
2,2,2,2,2,2,2,2,2,2,2,2,2,2,2,0
2,2,2,2,2,2,2,2,2,2,2,2,2,2,2,0
2,2,2,2,2,2,2,2,2,2,2,2,2,2,2,0
2,2,2,2,2,2,2,2,2,2,2,2,2,2,0,0
2,2,2,2,2,2,2,2,2,2,2,2,13,15,0,0
2,2,2,2,2,2,2,2,2,2,2,2,13,0,0,0
2,2,2,2,2,2,2,2,2,2,2,2,0,0,0,0
7,0,7,0,2,2,2,2,2,2,2,2,0,0,0,0
0,0,0,8,2,2,2,2,2,2,2,2,0,0,0,0
0,0,0,0,2,2,2,2,2,2,2,2,0,0,0,0
0,0,0,8,2,2,2,2,2,2,2,2,13,0,0,0
:endlayer
layer: 20
0,0,0,0,0,0,0,0,0,0,0,0,0,0,0,0
0,0,0,0,0,0,0,0,2,10,2,2,0,0,0,0
0,0,0,0,0,0,15,2,2,2,2,2,2,15,0,0
2,17,6,6,8,2,2,2,2,2,2,2,2,2,0,0
2,2,2,2,2,2,2,2,2,2,2,2,2,2,2,0
2,2,2,2,2,2,2,2,2,2,2,2,2,2,12,0
2,2,2,2,2,2,2,2,2,2,2,2,2,2,2,0
2,2,2,2,2,2,2,2,2,2,2,2,2,2,2,0
2,2,2,2,2,2,2,2,2,2,2,2,2,2,0,0
2,2,2,2,2,2,2,2,2,2,2,2,2,15,0,0
2,2,2,6,2,2,2,2,2,2,2,2,2,0,0,0
2,2,2,2,2,2,2,2,2,2,2,2,7,0,0,0
2,7,2,2,2,2,2,2,2,2,2,2,6,0,0,0
0,0,0,2,2,2,2,2,2,2,2,2,6,0,0,0
0,0,0,8,2,2,2,2,2,2,2,2,16,0,0,0
0,0,0,2,2,2,2,2,2,2,2,2,2,0,0,0
:endlayer
layer: 21
0,0,0,0,0,0,0,0,0,0,0,0,0,0,0,0
0,0,0,0,0,0,0,0,2,0,2,2,0,0,0,0
16,16,6,6,16,16,2,2,2,13,2,2,2,15,0,0
2,2,2,2,2,2,2,2,2,2,2,2,2,2,0,0
2,2,2,2,2,2,2,2,2,2,2,2,2,2,2,0
2,2,2,2,2,2,2,2,2,2,2,2,2,13,0,0
2,2,2,2,2,2,2,2,2,2,2,2,2,2,2,0
2,2,2,2,2,2,2,2,2,2,2,2,2,2,2,0
2,2,2,2,2,2,2,2,2,2,2,2,2,2,0,0
2,2,2,2,2,2,2,2,2,2,2,2,2,2,0,0
2,2,2,2,2,2,2,2,2,2,2,2,2,17,0,0
2,2,2,2,2,2,2,2,2,2,2,2,2,17,0,0
2,2,2,2,2,2,2,2,2,2,2,2,2,6,0,0
0,0,0,2,2,2,2,2,2,2,2,2,2,6,0,0
0,0,0,2,2,2,2,2,2,2,2,2,2,17,0,0
0,0,0,2,2,2,2,2,2,2,2,2,2,17,0,0
:endlayer
layer: 22
0,0,0,0,0,0,0,0,0,0,0,0,0,0,0,0
0,0,0,0,0,0,0,0,2,16,2,2,0,0,0,0
2,10,2,2,2,13,13,2,2,2,2,2,2,15,0,0
9,9,2,2,2,2,2,2,2,2,2,2,2,2,0,0
0,9,2,2,2,2,2,2,2,2,2,2,2,2,2,0
0,9,2,2,2,2,2,2,2,2,2,2,2,2,17,0
0,9,2,2,2,2,2,2,2,2,2,2,2,2,2,0
0,9,2,2,2,2,2,2,18,0,0,9,2,2,2,0
0,9,2,2,2,2,2,2,19,0,0,9,2,2,0,0
9,9,2,2,2,2,2,2,2,0,0,2,2,13,0,0
2,2,2,2,2,2,2,2,2,9,9,2,2,13,0,0
2,2,2,2,2,2,2,2,2,2,2,2,2,2,0,0
2,14,2,2,2,2,2,2,2,2,2,2,2,2,0,0
0,0,0,2,2,2,2,2,2,2,2,2,2,2,0,0
0,0,0,11,2,2,9,9,9,9,9,9,9,12,0,0
0,0,0,2,2,2,9,0,0,0,0,0,9,2,0,0
:endlayer
layer: 23
0,0,0,0,0,0,0,0,0,0,0,0,0,0,0,0
0,0,0,0,0,0,0,0,2,2,2,2,0,0,0,0
9,0,2,10,2,10,10,2,2,2,14,2,2,15,0,0
0,0,0,0,0,0,2,2,0,0,0,0,2,2,0,0
0,0,0,0,0,2,2,0,0,0,0,0,0,2,2,0
0,0,0,0,0,20,2,9,9,2,2,0,0,2,2,0
0,0,0,0,0,21,2,2,2,2,2,0,0,11,2,0
0,0,0,0,0,2,2,2,17,0,0,0,0,2,2,0
0,0,0,0,0,0,2,2,17,0,0,0,2,2,0,0
0,0,0,0,0,0,15,2,2,0,0,2,2,12,0,0
0,0,0,0,0,0,0,0,2,0,0,2,0,12,0,0
0,0,0,0,0,0,0,0,0,0,0,0,0,2,0,0
2,0,14,9,0,0,0,0,0,0,0,0,0,12,0,0
0,0,0,11,0,0,0,0,0,0,0,0,0,2,0,0
0,0,0,0,0,0,0,0,0,0,0,0,0,0,0,0
0,0,0,2,0,0,0,0,0,0,0,0,0,9,0,0
:endlayer
layer: 24
0,0,0,0,0,0,0,0,0,0,0,0,0,0,0,0
0,0,0,0,0,0,0,0,2,2,9,2,0,0,0,0
0,0,9,0,9,0,15,2,2,2,0,2,2,15,0,0
0,0,0,0,0,0,2,2,0,0,0,0,2,2,0,0
0,0,0,0,0,2,2,0,0,0,0,0,0,2,2,0
0,0,0,0,0,8,2,0,0,2,2,0,0,2,2,0
0,0,0,0,0,8,2,0,0,2,2,0,0,0,9,0
0,0,0,0,0,2,2,9,9,6,0,0,0,2,2,0
0,0,0,0,0,0,2,2,9,6,0,0,2,2,0,0
0,0,0,0,0,0,15,2,2,6,6,2,2,15,0,0
0,0,0,0,0,0,0,0,2,0,0,2,0,0,0,0
0,0,0,0,0,0,0,0,0,0,0,0,0,9,0,0
14,0,0,0,0,0,0,0,0,0,0,0,0,0,0,0
0,0,0,0,0,0,0,0,0,0,0,0,0,9,0,0
0,0,0,0,0,0,0,0,0,0,0,0,0,0,0,0
0,0,0,11,0,0,0,0,0,0,0,0,0,0,0,0
:endlayer
layer: 25
0,0,0,0,0,0,0,0,0,0,0,0,0,0,0,0
0,0,0,0,0,0,0,0,2,2,0,2,0,0,0,0
0,0,0,0,0,0,15,2,2,2,0,2,2,15,0,0
0,0,0,0,0,0,2,2,0,0,0,0,2,2,0,0
0,0,0,0,0,2,2,0,0,0,0,0,0,2,2,0
0,0,0,0,0,2,2,0,0,2,2,0,0,2,2,0
0,0,0,0,0,2,12,0,0,2,2,0,0,0,0,0
0,0,0,0,0,2,2,0,0,0,9,6,6,2,2,0
0,0,0,0,0,0,2,2,0,0,9,6,2,2,0,0
0,0,0,0,0,0,15,2,2,2,2,2,2,15,0,0
0,0,0,0,0,0,0,0,2,7,7,2,0,0,0,0
0,0,0,0,0,0,0,0,0,0,0,0,0,0,0,0
0,0,0,0,0,0,0,0,0,0,0,0,0,0,0,0
0,0,0,0,0,0,0,0,0,0,0,0,0,0,0,0
0,0,0,0,0,0,0,0,0,0,0,0,0,0,0,0
0,0,0,0,0,0,0,0,0,0,0,0,0,0,0,0
:endlayer
layer: 26
0,0,0,0,0,0,0,0,0,0,0,0,0,0,0,0
0,0,0,0,0,0,0,0,2,2,16,2,0,0,0,0
0,0,0,0,0,0,15,2,2,2,7,2,2,15,0,0
0,0,0,0,0,0,2,2,0,0,0,0,2,2,0,0
0,0,0,0,0,2,2,0,0,0,0,0,0,2,2,0
0,0,0,0,0,2,2,0,0,2,2,6,6,2,2,0
0,0,0,0,0,9,0,0,0,2,2,9,9,8,17,0
0,0,0,0,0,2,2,0,0,0,0,0,0,2,2,0
0,0,0,0,0,0,2,2,0,0,0,0,2,2,0,0
0,0,0,0,0,0,15,2,2,2,2,2,2,15,0,0
0,0,0,0,0,0,0,0,2,2,2,2,0,0,0,0
0,0,0,0,0,0,0,0,0,0,0,0,0,0,0,0
0,0,0,0,0,0,0,0,0,0,0,0,0,0,0,0
0,0,0,0,0,0,0,0,0,0,0,0,0,0,0,0
0,0,0,0,0,0,0,0,0,0,0,0,0,0,0,0
0,0,0,0,0,0,0,0,0,0,0,0,0,0,0,0
:endlayer
layer: 27
0,0,0,0,0,0,0,0,0,0,0,0,0,0,0,0
0,0,0,0,0,0,0,0,2,2,2,2,0,0,0,0
0,0,0,0,0,0,15,2,2,2,2,2,2,15,0,0
0,0,0,0,0,0,2,2,0,0,6,9,2,2,0,0
0,0,0,0,0,2,2,0,0,0,6,9,9,2,2,0
0,0,0,0,0,2,2,0,0,2,2,0,0,11,2,0
0,0,0,0,0,0,0,0,0,2,2,0,0,2,2,0
0,0,0,0,0,2,2,0,0,0,0,0,0,2,2,0
0,0,0,0,0,0,2,2,0,0,0,0,2,2,0,0
0,0,0,0,0,0,15,2,2,10,2,2,2,15,0,0
0,0,0,0,0,0,0,0,2,2,2,2,0,0,0,0
0,0,0,0,0,0,0,0,0,0,0,0,0,0,0,0
0,0,0,0,0,0,0,0,0,0,0,0,0,0,0,0
0,0,0,0,0,0,0,0,0,0,0,0,0,0,0,0
0,0,0,0,0,0,0,0,0,0,0,0,0,0,0,0
0,0,0,0,0,0,0,0,0,0,0,0,0,0,0,0
:endlayer
layer: 28
0,0,0,0,0,0,0,0,0,0,0,0,0,0,0,0
0,0,0,0,0,0,0,0,2,9,2,2,0,0,0,0
0,0,0,0,0,0,15,2,2,0,2,2,2,15,0,0
0,0,0,0,0,0,2,2,6,9,0,0,2,2,0,0
0,0,0,0,0,2,2,6,6,9,0,0,0,2,2,0
0,0,0,0,0,2,2,0,0,2,2,0,0,0,9,0
0,0,0,0,0,8,17,0,0,2,2,0,0,2,2,0
0,0,0,0,0,2,2,0,0,0,0,0,0,2,2,0
0,0,0,0,0,0,2,2,0,0,0,0,2,2,0,0
0,0,0,0,0,0,15,2,2,0,2,2,2,15,0,0
0,0,0,0,0,0,0,0,2,9,2,2,0,0,0,0
0,0,0,0,0,0,0,0,0,0,0,0,0,0,0,0
0,0,0,0,0,0,0,0,0,0,0,0,0,0,0,0
0,0,0,0,0,0,0,0,0,0,0,0,0,0,0,0
0,0,0,0,0,0,0,0,0,0,0,0,0,0,0,0
0,0,0,0,0,0,0,0,0,0,0,0,0,0,0,0
:endlayer
layer: 29
0,0,0,0,0,0,0,0,0,0,0,0,0,0,0,0
0,0,0,0,0,0,0,0,2,0,2,2,0,0,0,0
0,0,0,0,0,0,15,2,2,0,2,2,2,15,0,0
0,0,0,0,0,0,2,2,0,0,0,0,2,2,0,0
0,0,0,0,0,2,2,0,0,0,0,0,0,2,2,0
0,0,0,0,0,2,12,9,9,2,2,0,0,0,0,0
0,0,0,0,0,2,2,6,6,2,2,0,0,2,2,0
0,0,0,0,0,2,2,0,0,0,0,0,0,2,2,0
0,0,0,0,0,0,2,2,0,0,0,0,2,2,0,0
0,0,0,0,0,0,15,2,2,0,2,2,2,15,0,0
0,0,0,0,0,0,0,0,2,0,2,2,0,0,0,0
0,0,0,0,0,0,0,0,0,0,0,0,0,0,0,0
0,0,0,0,0,0,0,0,0,0,0,0,0,0,0,0
0,0,0,0,0,0,0,0,0,0,0,0,0,0,0,0
0,0,0,0,0,0,0,0,0,0,0,0,0,0,0,0
0,0,0,0,0,0,0,0,0,0,0,0,0,0,0,0
:endlayer
layer: 30
0,0,0,0,0,0,0,0,0,0,0,0,0,0,0,0
0,0,0,0,0,0,0,0,2,16,2,2,0,0,0,0
0,0,0,0,0,0,15,2,2,7,2,2,2,15,0,0
0,0,0,0,0,0,2,2,0,0,0,0,2,2,0,0
0,0,0,0,0,2,2,0,0,0,0,0,0,2,2,0
0,0,0,0,0,9,0,0,0,2,2,0,0,8,17,0
0,0,0,0,0,2,2,0,0,2,2,0,0,2,2,0
0,0,0,0,0,2,2,9,9,6,0,0,0,2,2,0
0,0,0,0,0,0,2,2,9,6,0,0,2,2,0,0
0,0,0,0,0,0,15,2,2,16,2,2,2,15,0,0
0,0,0,0,0,0,0,0,2,7,2,2,0,0,0,0
0,0,0,0,0,0,0,0,0,0,0,0,0,0,0,0
0,0,0,0,0,0,0,0,0,0,0,0,0,0,0,0
0,0,0,0,0,0,0,0,0,0,0,0,0,0,0,0
0,0,0,0,0,0,0,0,0,0,0,0,0,0,0,0
0,0,0,0,0,0,0,0,0,0,0,0,0,0,0,0
:endlayer
layer: 31
0,0,0,0,0,0,0,0,0,0,0,0,0,0,0,0
0,0,0,0,0,0,0,0,2,2,2,2,0,0,0,0
0,0,0,0,0,0,15,2,2,2,14,2,2,15,0,0
0,0,0,0,0,0,2,2,0,0,0,0,2,2,0,0
0,0,0,0,0,2,2,0,0,0,0,0,0,2,2,0
0,0,0,0,0,0,0,0,0,2,2,0,0,2,2,0
0,0,0,0,0,2,2,0,0,2,2,0,0,2,2,0
0,0,0,0,0,2,2,0,0,0,9,6,6,2,2,0
0,0,0,0,0,0,2,2,0,0,9,6,2,2,0,0
0,0,0,0,0,0,15,2,2,2,10,2,2,15,0,0
0,0,0,0,0,0,0,0,2,2,2,2,0,0,0,0
0,0,0,0,0,0,0,0,0,0,0,0,0,0,0,0
0,0,0,0,0,0,0,0,0,0,0,0,0,0,0,0
0,0,0,0,0,0,0,0,0,0,0,0,0,0,0,0
0,0,0,0,0,0,0,0,0,0,0,0,0,0,0,0
0,0,0,0,0,0,0,0,0,0,0,0,0,0,0,0
:endlayer
layer: 32
0,0,0,0,0,0,0,0,0,0,0,0,0,0,0,0
0,0,0,0,0,0,0,0,2,2,9,2,0,0,0,0
0,0,0,0,0,0,15,2,2,2,0,2,2,15,0,0
0,0,0,0,0,0,2,2,0,0,0,0,2,2,0,0
0,0,0,0,0,2,2,0,0,0,0,0,0,2,2,0
0,0,0,0,0,8,17,0,0,2,2,6,6,2,2,0
0,0,0,0,0,2,2,0,0,2,2,9,9,0,9,0
0,0,0,0,0,2,2,0,0,0,0,0,0,2,2,0
0,0,0,0,0,0,2,2,0,0,0,0,2,2,0,0
0,0,0,0,0,0,15,2,2,2,0,2,2,15,0,0
0,0,0,0,0,0,0,0,2,2,9,2,0,0,0,0
0,0,0,0,0,0,0,0,0,0,0,0,0,0,0,0
0,0,0,0,0,0,0,0,0,0,0,0,0,0,0,0
0,0,0,0,0,0,0,0,0,0,0,0,0,0,0,0
0,0,0,0,0,0,0,0,0,0,0,0,0,0,0,0
0,0,0,0,0,0,0,0,0,0,0,0,0,0,0,0
:endlayer
layer: 33
0,0,0,0,0,0,0,0,0,0,0,0,0,0,0,0
0,0,0,0,0,0,0,0,2,2,0,2,0,0,0,0
0,0,0,0,0,0,15,2,2,2,0,2,2,15,0,0
0,0,0,0,0,0,2,2,0,0,6,9,2,2,0,0
0,0,0,0,0,2,2,0,0,0,6,9,9,2,2,0
0,0,0,0,0,2,2,0,0,2,2,0,0,2,2,0
0,0,0,0,0,2,2,0,0,2,2,0,0,0,0,0
0,0,0,0,0,2,2,0,0,0,0,0,0,2,2,0
0,0,0,0,0,0,2,2,0,0,0,0,2,2,0,0
0,0,0,0,0,0,15,2,2,2,0,2,2,15,0,0
0,0,0,0,0,0,0,0,2,2,0,2,0,0,0,0
0,0,0,0,0,0,0,0,0,0,0,0,0,0,0,0
0,0,0,0,0,0,0,0,0,0,0,0,0,0,0,0
0,0,0,0,0,0,0,0,0,0,0,0,0,0,0,0
0,0,0,0,0,0,0,0,0,0,0,0,0,0,0,0
0,0,0,0,0,0,0,0,0,0,0,0,0,0,0,0
:endlayer
layer: 34
0,0,0,0,0,0,0,0,0,0,0,0,0,0,0,0
0,0,0,0,0,0,0,0,2,2,16,2,0,0,0,0
0,0,0,0,0,0,15,2,2,2,7,2,2,15,0,0
0,0,0,0,0,0,2,2,6,9,0,0,2,2,0,0
0,0,0,0,0,2,2,6,6,9,0,0,0,2,2,0
0,0,0,0,0,2,2,0,0,2,2,0,0,2,2,0
0,0,0,0,0,2,2,0,0,2,2,0,0,0,17,0
0,0,0,0,0,2,2,0,0,0,0,0,0,2,2,0
0,0,0,0,0,0,2,2,0,0,0,0,2,2,0,0
0,0,0,0,0,0,15,2,2,2,16,2,2,15,0,0
0,0,0,0,0,0,0,0,2,2,7,2,0,0,0,0
0,0,0,0,0,0,0,0,0,0,0,0,0,0,0,0
0,0,0,0,0,0,0,0,0,0,0,0,0,0,0,0
0,0,0,0,0,0,0,0,0,0,0,0,0,0,0,0
0,0,0,0,0,0,0,0,0,0,0,0,0,0,0,0
0,0,0,0,0,0,0,0,0,0,0,0,0,0,0,0
:endlayer
layer: 35
0,0,0,0,0,0,0,0,0,16,16,0,0,0,0,0
0,0,0,0,0,0,0,0,2,2,2,2,0,0,0,0
0,0,0,0,0,0,15,2,2,2,2,2,2,15,0,0
0,0,0,0,0,0,2,2,0,0,0,0,2,2,0,0
0,0,0,0,0,2,2,0,0,0,0,0,0,2,2,0
0,0,0,0,8,2,2,9,9,2,2,0,0,2,2,17
0,0,0,0,8,2,2,6,6,2,2,0,0,8,2,17
0,0,0,0,0,2,2,0,0,0,0,0,0,2,2,0
0,0,0,0,0,0,2,2,0,0,0,0,2,2,0,0
0,0,0,0,0,0,15,2,2,2,2,2,2,15,0,0
0,0,0,0,0,0,0,0,2,2,2,2,0,0,0,0
0,0,0,0,0,0,0,0,0,7,7,0,0,0,0,0
0,0,0,0,0,0,0,0,0,0,0,0,0,0,0,0
0,0,0,0,0,0,0,0,0,0,0,0,0,0,0,0
0,0,0,0,0,0,0,0,0,0,0,0,0,0,0,0
0,0,0,0,0,0,0,0,0,0,0,0,0,0,0,0
:endlayer
layer: 36
0,0,0,0,0,0,0,0,16,2,2,16,0,0,0,0
0,0,0,0,0,0,6,8,2,2,2,2,17,6,0,0
0,0,0,0,0,6,13,2,2,2,2,2,2,13,6,0
0,0,0,0,0,16,2,2,0,0,0,0,2,2,16,0
0,0,0,0,8,2,2,0,0,0,0,0,0,2,2,17
0,0,0,0,2,2,2,0,0,2,2,0,0,2,2,2
0,0,0,0,2,2,2,0,0,2,2,0,0,2,2,2
0,0,0,0,8,2,2,9,9,6,0,0,0,2,2,17
0,0,0,0,0,7,2,2,9,6,0,0,2,2,7,0
0,0,0,0,0,6,13,2,2,2,2,2,2,13,6,0
0,0,0,0,0,0,6,8,2,2,2,2,17,6,0,0
0,0,0,0,0,0,0,0,7,2,2,7,0,0,0,0
0,0,0,0,0,0,0,0,0,0,0,0,0,0,0,0
0,0,0,0,0,0,0,0,0,0,0,0,0,0,0,0
0,0,0,0,0,0,0,0,0,0,0,0,0,0,0,0
0,0,0,0,0,0,0,0,0,0,0,0,0,0,0,0
:endlayer
layer: 37
0,0,0,0,0,0,0,8,13,17,8,13,17,0,0,0
0,0,0,0,0,6,2,2,2,2,2,2,2,2,6,0
0,0,0,0,0,2,2,2,2,2,2,2,2,2,2,0
0,0,0,0,16,2,2,2,6,6,6,6,2,2,2,16
0,0,0,0,13,2,2,6,6,6,6,6,6,2,2,13
0,0,0,0,7,2,2,0,0,2,2,6,6,2,2,7
0,0,0,0,16,2,2,0,0,2,2,6,6,2,2,16
0,0,0,0,13,2,2,0,0,0,9,6,6,2,2,13
0,0,0,0,7,2,2,2,0,0,9,6,2,2,2,7
0,0,0,0,0,2,2,2,2,2,2,2,2,2,2,0
0,0,0,0,0,6,2,2,2,2,2,2,2,2,6,0
0,0,0,0,0,0,0,8,13,17,8,13,17,0,0,0
0,0,0,0,0,0,0,0,0,0,0,0,0,0,0,0
0,0,0,0,0,0,0,0,0,0,0,0,0,0,0,0
0,0,0,0,0,0,0,0,0,0,0,0,0,0,0,0
0,0,0,0,0,0,0,0,0,0,0,0,0,0,0,0
:endlayer
layer: 38
0,0,0,0,0,0,0,2,10,2,2,10,2,0,0,0
0,0,0,0,0,2,10,14,0,0,0,0,14,10,2,0
0,0,0,0,0,11,0,0,0,0,0,0,0,0,12,0
0,0,0,0,2,12,0,0,0,0,0,0,0,0,11,2
0,0,0,0,11,0,0,0,11,22,23,12,0,0,0,12
0,0,0,0,2,0,0,9,14,2,2,14,0,0,0,2
0,0,0,0,2,0,0,0,0,2,2,0,0,0,0,2
0,0,0,0,11,0,0,0,0,0,0,0,0,0,0,12
0,0,0,0,2,12,0,9,0,0,0,0,0,0,11,2
0,0,0,0,0,11,0,0,0,0,0,0,0,0,12,0
0,0,0,0,0,2,14,10,0,0,0,0,10,14,2,0
0,0,0,0,0,0,0,2,14,2,2,14,2,0,0,0
0,0,0,0,0,0,0,0,0,0,0,0,0,0,0,0
0,0,0,0,0,0,0,0,0,0,0,0,0,0,0,0
0,0,0,0,0,0,0,0,0,0,0,0,0,0,0,0
0,0,0,0,0,0,0,0,0,0,0,0,0,0,0,0
:endlayer
layer: 39
0,0,0,0,0,0,0,9,0,9,9,0,9,0,0,0
0,0,0,0,0,9,0,0,0,0,0,0,0,0,9,0
0,0,0,0,0,0,0,0,0,0,0,0,0,0,0,0
0,0,0,0,9,0,0,0,0,0,0,0,0,0,0,9
0,0,0,0,0,0,0,0,0,9,9,0,0,0,0,0
0,0,0,0,9,0,0,0,0,2,2,0,0,0,0,9
0,0,0,0,9,0,0,0,0,2,2,0,0,0,0,9
0,0,0,0,0,0,0,0,0,0,0,0,0,0,0,0
0,0,0,0,9,0,0,0,0,0,0,0,0,0,0,9
0,0,0,0,0,0,0,0,0,0,0,0,0,0,0,0
0,0,0,0,0,9,0,0,0,0,0,0,0,0,9,0
0,0,0,0,0,0,0,9,0,9,9,0,9,0,0,0
0,0,0,0,0,0,0,0,0,0,0,0,0,0,0,0
0,0,0,0,0,0,0,0,0,0,0,0,0,0,0,0
0,0,0,0,0,0,0,0,0,0,0,0,0,0,0,0
0,0,0,0,0,0,0,0,0,0,0,0,0,0,0,0
:endlayer
layer: 40
0,0,0,0,0,0,0,0,0,0,0,0,0,0,0,0
0,0,0,0,0,0,0,0,0,0,0,0,0,0,0,0
0,0,0,0,0,0,0,0,0,0,0,0,0,0,0,0
0,0,0,0,0,0,0,0,0,0,0,0,0,0,0,0
0,0,0,0,0,0,0,0,0,0,0,0,0,0,0,0
0,0,0,0,0,0,0,0,0,10,12,0,0,0,0,0
0,0,0,0,0,0,0,0,0,11,14,0,0,0,0,0
0,0,0,0,0,0,0,0,0,0,0,0,0,0,0,0
0,0,0,0,0,0,0,0,0,0,0,0,0,0,0,0
0,0,0,0,0,0,0,0,0,0,0,0,0,0,0,0
0,0,0,0,0,0,0,0,0,0,0,0,0,0,0,0
0,0,0,0,0,0,0,0,0,0,0,0,0,0,0,0
0,0,0,0,0,0,0,0,0,0,0,0,0,0,0,0
0,0,0,0,0,0,0,0,0,0,0,0,0,0,0,0
0,0,0,0,0,0,0,0,0,0,0,0,0,0,0,0
0,0,0,0,0,0,0,0,0,0,0,0,0,0,0,0
:endlayer

#### RULES ####
rule:
plugin=vanillaBlocks
number=1
data:
JSON:{blockState:{blockName:"minecraft:cobblestone"}}
:enddata
:endrule

rule:
plugin=vanillaBlocks
number=2
data:
JSON:{blockState:{blockName:"explorercraft:basalt_bricks"}}
:enddata
:endrule

rule:
plugin=vanillaBlocks
number=3
data:
JSON:{blockState:{blockName:"minecraft:dirt",properties:{variant:"dirt",snowy:"false"}}}
:enddata
:endrule

rule:
plugin=vanillaBlocks
number=4
data:
JSON:{blockState:{blockName:"minecraft:gravel"}}
:enddata
:endrule

rule:
plugin=vanillaBlocks
number=5
data:
JSON:{blockState:{blockName:"minecraft:grass",properties:{snowy:"false"}}}
:enddata
:endrule

rule:
plugin=vanillaBlocks
number=6
data:
JSON:{blockState:{blockName:"explorercraft:basalt_brick_slab",properties:{half:"top",variant:"default"}}}
:enddata
:endrule

rule:
plugin=vanillaBlocks
number=7
data:
JSON:{blockState:{blockName:"explorercraft:basalt_brick_stairs",properties:{half:"top",shape:"straight",facing:"north"}}}
:enddata
:endrule

rule:
plugin=vanillaBlocks
number=8
data:
JSON:{blockState:{blockName:"explorercraft:basalt_brick_stairs",properties:{half:"top",shape:"straight",facing:"east"}}}
:enddata
:endrule

rule:
plugin=vanillaBlocks
number=9
data:
JSON:{blockState:{blockName:"explorercraft:basalt_brick_slab",properties:{half:"bottom",variant:"default"}}}
:enddata
:endrule

rule:
plugin=vanillaBlocks
number=10
data:
JSON:{blockState:{blockName:"explorercraft:basalt_brick_stairs",properties:{half:"bottom",shape:"straight",facing:"south"}}}
:enddata
:endrule

rule:
plugin=vanillaBlocks
number=11
data:
JSON:{blockState:{blockName:"explorercraft:basalt_brick_stairs",properties:{half:"bottom",shape:"straight",facing:"east"}}}
:enddata
:endrule

rule:
plugin=vanillaBlocks
number=12
data:
JSON:{blockState:{blockName:"explorercraft:basalt_brick_stairs",properties:{half:"bottom",shape:"straight",facing:"west"}}}
:enddata
:endrule

rule:
plugin=vanillaBlocks
number=13
data:
JSON:{blockState:{blockName:"explorercraft:basalt_chiseled"}}
:enddata
:endrule

rule:
plugin=vanillaBlocks
number=14
data:
JSON:{blockState:{blockName:"explorercraft:basalt_brick_stairs",properties:{half:"bottom",shape:"straight",facing:"north"}}}
:enddata
:endrule

rule:
plugin=vanillaBlocks
number=15
data:
JSON:{blockState:{blockName:"explorercraft:basalt_brick_wall",properties:{east:"false",south:"false",north:"false",west:"false",up:"false"}}}
:enddata
:endrule

rule:
plugin=vanillaBlocks
number=16
data:
JSON:{blockState:{blockName:"explorercraft:basalt_brick_stairs",properties:{half:"top",shape:"straight",facing:"south"}}}
:enddata
:endrule

rule:
plugin=vanillaBlocks
number=17
data:
JSON:{blockState:{blockName:"explorercraft:basalt_brick_stairs",properties:{half:"top",shape:"straight",facing:"west"}}}
:enddata
:endrule

rule:
plugin=inventory
number=18
data:
JSON:{blockState:{blockName:"minecraft:chest",properties:{facing:"east"}},lootLevel:0,teData:{Items:[],id:"minecraft:chest",Lock:""},inventoryData:{length:0,inventoryContents:[]},legacyFeatures:1b}
:enddata
:endrule

rule:
plugin=inventory
number=19
data:
JSON:{blockState:{blockName:"minecraft:chest",properties:{facing:"east"}},lootLevel:0,teData:{Items:[],id:"minecraft:chest",Lock:""},inventoryData:{length:0,inventoryContents:[]},legacyFeatures:1b}
:enddata
:endrule

rule:
plugin=inventory
number=20
data:
JSON:{blockState:{blockName:"minecraft:chest",properties:{facing:"west"}},lootLevel:0,teData:{Items:[],id:"minecraft:chest",Lock:""},inventoryData:{length:0,inventoryContents:[]},legacyFeatures:1b}
:enddata
:endrule

rule:
plugin=inventory
number=21
data:
JSON:{blockState:{blockName:"minecraft:chest",properties:{facing:"west"}},lootLevel:0,teData:{Items:[],id:"minecraft:chest",Lock:""},inventoryData:{length:0,inventoryContents:[]},legacyFeatures:1b}
:enddata
:endrule

rule:
plugin=inventory
number=22
data:
JSON:{blockState:{blockName:"minecraft:chest",properties:{facing:"north"}},lootLevel:0,teData:{Items:[],id:"minecraft:chest",Lock:""},inventoryData:{length:0,inventoryContents:[]},legacyFeatures:1b}
:enddata
:endrule

rule:
plugin=inventory
number=23
data:
JSON:{blockState:{blockName:"minecraft:chest",properties:{facing:"north"}},lootLevel:0,teData:{Items:[],id:"minecraft:chest",Lock:""},inventoryData:{length:0,inventoryContents:[]},legacyFeatures:1b}
:enddata
:endrule

#### ENTITIES ####
