# Ancient Warfare Structure Template File
# Auto-generated structure template file. created on: 6/11/2023 at: 17:6:43
# Lines beginning with # denote comments

header:
version=2.11
name=SB_MarenCol_Warehouse_Small_1_redwood
mods=biomesoplenty
size=22,9,14
offset=10,1,13
:endheader

#### VALIDATION ####
validation:
type=ground
structureAuthor=TheOddlySeagull
survival=true
worldGenEnabled=false
unique=false
preserveBlocks=false
preventNaturalHostileSpawns=false
selectionWeight=1
clusterValue=1
minDuplicateDistance=1
dimensionWhiteList=true
dimensionList=
biomeGroupList=
biomeWhiteList=true
biomeList=
leveling=0
fill=0
border=0
blockSwap=false
territoryName=
biomeReplacement=minecraft:
minGenerationHeight=0
maxGenerationHeight=255
:endvalidation

#### LAYERS ####
layer: 0
1,1,1,1,1,1,1,1,1,1,1,1,1,1,1,1,1,1,1,1,1,1
1,1,1,1,1,1,1,1,1,1,1,1,1,1,1,1,1,1,1,1,1,1
1,1,3,3,3,3,3,3,3,3,3,3,3,3,3,3,3,3,3,3,1,1
1,1,3,5,5,4,4,4,5,4,5,5,4,4,4,5,4,5,5,3,1,1
1,1,3,4,4,5,5,4,4,5,4,4,4,4,5,5,4,4,4,3,1,1
1,1,3,5,4,4,4,5,4,4,5,5,4,5,4,4,5,4,4,3,1,1
1,1,3,4,4,5,5,5,5,5,4,4,5,5,5,5,5,4,4,3,1,1
1,1,3,5,4,5,5,5,4,4,4,4,4,4,5,4,5,4,4,3,1,1
1,1,3,5,4,5,5,5,4,4,4,5,5,5,5,4,5,4,5,3,1,1
1,1,3,3,3,3,3,3,5,4,5,5,5,4,3,3,3,3,3,3,1,1
1,1,1,1,1,1,1,3,4,4,5,5,4,4,3,1,1,1,1,1,1,1
1,1,1,1,1,1,1,3,3,3,3,3,3,3,3,1,1,1,1,1,1,1
1,1,1,1,1,1,1,1,1,2,3,3,2,1,1,1,1,1,1,1,1,1
1,1,1,1,1,1,1,1,1,2,3,3,2,1,1,1,1,1,1,1,1,1
:endlayer
layer: 1
0,0,0,0,0,0,0,0,0,0,0,0,0,0,0,0,0,0,0,0,0,0
0,0,0,0,0,0,0,0,0,0,0,0,0,0,0,0,0,0,0,0,0,0
0,0,7,8,7,8,8,7,8,7,8,8,7,8,7,8,8,7,8,7,0,0
0,0,8,0,0,0,0,0,0,0,0,0,0,0,0,0,0,0,0,8,0,0
0,0,7,0,0,0,0,0,0,0,0,0,0,0,0,0,0,0,0,7,0,0
0,0,8,0,0,0,0,0,0,0,0,0,0,0,0,0,0,0,0,8,0,0
0,0,8,0,0,0,0,0,0,0,0,0,0,0,0,0,0,0,0,8,0,0
0,0,7,0,0,0,0,0,0,0,0,0,0,0,0,0,0,0,0,7,0,0
0,0,8,0,0,0,0,0,0,0,0,0,0,0,0,0,0,0,0,8,0,0
0,0,7,8,7,8,8,7,0,0,0,0,0,0,7,8,8,7,8,7,0,0
0,0,0,0,0,0,0,8,0,0,0,0,0,0,8,0,0,0,0,0,0,0
0,0,0,0,0,0,0,7,8,7,0,0,7,8,7,0,0,0,0,0,0,0
0,6,0,0,0,0,0,0,0,0,0,0,0,0,0,0,0,0,0,0,6,0
0,0,0,0,0,0,0,0,0,0,0,0,0,0,0,0,0,0,0,0,0,0
:endlayer
layer: 2
0,0,0,0,0,0,0,0,0,0,0,0,0,0,0,0,0,0,0,0,0,0
0,0,0,0,0,0,0,0,0,0,0,0,0,0,0,0,0,0,0,0,0,0
0,0,7,8,7,8,8,7,8,7,8,8,7,8,7,8,8,7,8,7,0,0
0,0,8,0,0,0,0,0,0,0,0,0,0,0,0,0,0,0,0,8,0,0
0,0,7,0,0,0,0,0,0,0,0,0,0,0,0,0,0,0,0,7,0,0
0,0,8,0,0,0,0,0,0,0,0,0,0,0,0,0,0,0,0,8,0,0
0,0,8,0,0,0,0,0,0,0,0,0,0,0,0,0,0,0,0,8,0,0
0,0,7,0,0,0,0,0,0,0,0,0,0,0,0,0,0,0,0,7,0,0
0,0,8,0,0,0,0,0,0,0,0,0,0,0,0,0,0,0,0,8,0,0
0,0,7,8,7,8,8,7,0,0,0,0,0,0,7,8,8,7,8,7,0,0
0,0,0,0,0,0,0,8,0,0,0,0,0,0,8,0,0,0,0,0,0,0
0,0,0,0,0,0,0,7,8,7,0,0,7,8,7,0,0,0,0,0,0,0
0,9,0,0,0,0,0,10,0,0,0,0,0,0,10,0,0,0,0,0,9,0
0,0,0,0,0,0,0,0,0,0,0,0,0,0,0,0,0,0,0,0,0,0
:endlayer
layer: 3
0,0,0,0,0,0,0,0,0,0,0,0,0,0,0,0,0,0,0,0,0,0
0,0,14,0,0,0,0,14,0,14,0,0,14,0,14,0,0,0,0,14,0,0
0,13,7,8,7,6,6,7,8,7,6,6,7,8,7,6,6,7,8,7,12,0
0,0,8,0,10,0,0,10,0,10,0,0,10,0,10,0,0,10,0,8,0,0
0,0,7,12,0,0,0,0,0,0,0,0,0,0,0,0,0,0,13,7,0,0
0,0,6,0,0,0,0,0,0,0,0,0,0,0,0,0,0,0,0,6,0,0
0,0,6,0,0,0,0,0,0,0,0,0,0,0,0,0,0,0,0,6,0,0
0,0,7,12,0,0,0,0,0,0,0,0,0,0,0,0,0,0,13,7,0,0
0,0,8,0,14,0,0,14,0,0,0,0,0,0,14,0,0,14,0,8,0,0
0,13,7,8,7,6,6,7,12,0,0,0,0,13,7,6,6,7,8,7,12,0
0,0,10,0,0,0,0,8,0,14,0,0,14,0,8,0,0,0,0,10,0,0
0,0,0,0,0,0,13,7,8,7,8,8,7,8,7,12,0,0,0,0,0,0
0,0,0,0,0,0,11,11,11,11,11,11,11,11,11,11,0,0,0,0,0,0
0,0,0,0,0,0,0,0,0,0,0,0,0,0,0,0,0,0,0,0,0,0
:endlayer
layer: 4
0,0,0,0,0,0,0,0,0,0,0,0,0,0,0,0,0,0,0,0,0,0
0,21,21,21,21,21,21,21,21,21,21,21,21,21,21,21,21,21,21,21,21,0
0,20,7,18,18,18,18,18,18,18,18,18,18,18,18,18,18,18,18,7,20,0
0,0,19,0,0,0,0,0,0,0,0,0,0,0,0,0,0,0,0,19,0,0
0,0,19,0,0,0,0,0,0,0,0,0,0,0,0,0,0,0,0,19,0,0
0,0,19,0,0,0,0,0,0,0,0,0,0,0,0,0,0,0,0,19,0,0
0,0,19,0,0,0,0,0,0,0,0,0,0,0,0,0,0,0,0,19,0,0
0,0,19,0,0,0,0,0,0,0,0,0,0,0,0,0,0,0,0,19,0,0
0,0,19,0,0,0,0,0,0,0,0,0,0,0,0,0,0,0,0,19,0,0
0,17,7,18,18,18,18,18,18,18,18,18,18,18,18,18,18,18,18,7,17,0
0,16,16,16,16,16,8,8,11,11,11,11,11,11,8,8,16,16,16,16,16,0
0,0,0,0,0,0,15,15,15,15,15,15,15,15,15,15,0,0,0,0,0,0
0,0,0,0,0,0,0,0,0,0,0,0,0,0,0,0,0,0,0,0,0,0
0,0,0,0,0,0,0,0,0,0,0,0,0,0,0,0,0,0,0,0,0,0
:endlayer
layer: 5
0,0,0,0,0,0,0,0,0,0,0,0,0,0,0,0,0,0,0,0,0,0
0,0,0,0,0,0,0,0,0,0,0,0,0,0,0,0,0,0,0,0,0,0
0,21,21,21,21,21,21,21,21,21,21,21,21,21,21,21,21,21,21,21,21,0
0,20,7,20,20,20,20,20,20,20,20,20,20,20,20,20,20,20,20,7,20,0
0,0,8,0,0,0,0,0,0,0,0,0,0,0,0,0,0,0,0,8,0,0
0,0,8,0,0,0,0,0,0,0,0,0,0,0,0,0,0,0,0,8,0,0
0,0,8,0,0,0,0,0,0,0,0,0,0,0,0,0,0,0,0,8,0,0
0,0,8,0,0,0,0,0,0,0,0,0,0,0,0,0,0,0,0,8,0,0
0,17,7,17,17,17,17,17,17,17,17,17,17,17,17,17,17,17,17,7,17,0
0,16,16,16,16,16,16,16,16,16,16,16,16,16,16,16,16,16,16,16,16,0
0,0,0,0,0,0,0,0,9,0,0,0,0,9,0,0,0,0,0,0,0,0
0,0,0,0,0,0,0,0,0,0,0,0,0,0,0,0,0,0,0,0,0,0
0,0,0,0,0,0,0,0,0,0,0,0,0,0,0,0,0,0,0,0,0,0
0,0,0,0,0,0,0,0,0,0,0,0,0,0,0,0,0,0,0,0,0,0
:endlayer
layer: 6
0,0,0,0,0,0,0,0,0,0,0,0,0,0,0,0,0,0,0,0,0,0
0,0,0,0,0,0,0,0,0,0,0,0,0,0,0,0,0,0,0,0,0,0
0,0,0,0,0,0,0,0,0,0,0,0,0,0,0,0,0,0,0,0,0,0
0,21,23,6,22,21,21,23,6,22,21,21,23,6,22,21,21,23,6,22,21,0
0,20,7,0,20,20,20,20,0,20,20,20,20,0,20,20,20,20,0,7,20,0
0,0,8,0,0,0,0,0,0,0,0,0,0,0,0,0,0,0,0,8,0,0
0,0,8,0,0,0,0,0,0,0,0,0,0,0,0,0,0,0,0,8,0,0
0,17,7,0,17,17,17,17,0,17,17,17,17,0,17,17,17,17,0,7,17,0
0,16,23,6,22,16,16,23,6,22,16,16,23,6,22,16,16,23,6,22,16,0
0,0,0,0,0,0,0,0,0,0,0,0,0,0,0,0,0,0,0,0,0,0
0,0,0,0,0,0,0,0,0,0,0,0,0,0,0,0,0,0,0,0,0,0
0,0,0,0,0,0,0,0,0,0,0,0,0,0,0,0,0,0,0,0,0,0
0,0,0,0,0,0,0,0,0,0,0,0,0,0,0,0,0,0,0,0,0,0
0,0,0,0,0,0,0,0,0,0,0,0,0,0,0,0,0,0,0,0,0,0
:endlayer
layer: 7
0,0,0,0,0,0,0,0,0,0,0,0,0,0,0,0,0,0,0,0,0,0
0,0,0,0,0,0,0,0,0,0,0,0,0,0,0,0,0,0,0,0,0,0
0,0,0,0,0,0,0,0,0,0,0,0,0,0,0,0,0,0,0,0,0,0
0,0,0,15,0,0,0,0,15,0,0,0,0,15,0,0,0,0,15,0,0,0
0,21,21,21,21,21,21,21,21,21,21,21,21,21,21,21,21,21,21,21,21,0
0,20,19,20,20,20,20,20,20,20,20,20,20,20,20,20,20,20,20,19,20,0
0,17,19,17,17,17,17,17,17,17,17,17,17,17,17,17,17,17,17,19,17,0
0,16,16,16,16,16,16,16,16,16,16,16,16,16,16,16,16,16,16,16,16,0
0,0,0,15,0,0,0,0,15,0,0,0,0,15,0,0,0,0,15,0,0,0
0,0,0,0,0,0,0,0,0,0,0,0,0,0,0,0,0,0,0,0,0,0
0,0,0,0,0,0,0,0,0,0,0,0,0,0,0,0,0,0,0,0,0,0
0,0,0,0,0,0,0,0,0,0,0,0,0,0,0,0,0,0,0,0,0,0
0,0,0,0,0,0,0,0,0,0,0,0,0,0,0,0,0,0,0,0,0,0
0,0,0,0,0,0,0,0,0,0,0,0,0,0,0,0,0,0,0,0,0,0
:endlayer
layer: 8
0,0,0,0,0,0,0,0,0,0,0,0,0,0,0,0,0,0,0,0,0,0
0,0,0,0,0,0,0,0,0,0,0,0,0,0,0,0,0,0,0,0,0,0
0,0,0,0,0,0,0,0,0,0,0,0,0,0,0,0,0,0,0,0,0,0
0,0,0,0,0,0,0,0,0,0,0,0,0,0,0,0,0,0,0,0,0,0
0,0,0,0,0,0,0,0,0,0,0,0,0,0,0,0,0,0,0,0,0,0
0,21,21,21,21,21,21,21,21,21,21,21,21,21,21,21,21,21,21,21,21,0
0,16,16,16,16,16,16,16,16,16,16,16,16,16,16,16,16,16,16,16,16,0
0,0,0,0,0,0,0,0,0,0,0,0,0,0,0,0,0,0,0,0,0,0
0,0,0,0,0,0,0,0,0,0,0,0,0,0,0,0,0,0,0,0,0,0
0,0,0,0,0,0,0,0,0,0,0,0,0,0,0,0,0,0,0,0,0,0
0,0,0,0,0,0,0,0,0,0,0,0,0,0,0,0,0,0,0,0,0,0
0,0,0,0,0,0,0,0,0,0,0,0,0,0,0,0,0,0,0,0,0,0
0,0,0,0,0,0,0,0,0,0,0,0,0,0,0,0,0,0,0,0,0,0
0,0,0,0,0,0,0,0,0,0,0,0,0,0,0,0,0,0,0,0,0,0
:endlayer

#### RULES ####
rule:
plugin=vanillaBlocks
number=1
data:
JSON:{blockState:{blockName:"minecraft:grass",properties:{snowy:"false"}}}
:enddata
:endrule

rule:
plugin=vanillaBlocks
number=2
data:
JSON:{blockState:{blockName:"minecraft:stonebrick",properties:{variant:"stonebrick"}}}
:enddata
:endrule

rule:
plugin=vanillaBlocks
number=3
data:
JSON:{blockState:{blockName:"minecraft:cobblestone"}}
:enddata
:endrule

rule:
plugin=vanillaBlocks
number=4
data:
JSON:{blockState:{blockName:"minecraft:dirt",properties:{variant:"coarse_dirt",snowy:"false"}}}
:enddata
:endrule

rule:
plugin=vanillaBlocks
number=5
data:
JSON:{blockState:{blockName:"minecraft:gravel"}}
:enddata
:endrule

rule:
plugin=vanillaBlocks
number=6
data:
JSON:{blockState:{blockName:"biomesoplenty:redwood_fence",properties:{east:"false",south:"false",north:"false",west:"false"}}}
:enddata
:endrule

rule:
plugin=vanillaBlocks
number=7
data:
JSON:{blockState:{blockName:"biomesoplenty:log_2",properties:{variant:"redwood",axis:"y"}}}
:enddata
:endrule

rule:
plugin=vanillaBlocks
number=8
data:
JSON:{blockState:{blockName:"biomesoplenty:planks_0",properties:{variant:"redwood"}}}
:enddata
:endrule

rule:
plugin=vanillaBlocks
number=9
data:
JSON:{blockState:{blockName:"minecraft:torch",properties:{facing:"up"}}}
:enddata
:endrule

rule:
plugin=vanillaBlocks
number=10
data:
JSON:{blockState:{blockName:"minecraft:torch",properties:{facing:"south"}}}
:enddata
:endrule

rule:
plugin=vanillaBlocks
number=11
data:
JSON:{blockState:{blockName:"biomesoplenty:wood_slab_1",properties:{half:"top",variant:"redwood"}}}
:enddata
:endrule

rule:
plugin=vanillaBlocks
number=12
data:
JSON:{blockState:{blockName:"minecraft:torch",properties:{facing:"east"}}}
:enddata
:endrule

rule:
plugin=vanillaBlocks
number=13
data:
JSON:{blockState:{blockName:"minecraft:torch",properties:{facing:"west"}}}
:enddata
:endrule

rule:
plugin=vanillaBlocks
number=14
data:
JSON:{blockState:{blockName:"minecraft:torch",properties:{facing:"north"}}}
:enddata
:endrule

rule:
plugin=vanillaBlocks
number=15
data:
JSON:{blockState:{blockName:"biomesoplenty:wood_slab_1",properties:{half:"bottom",variant:"redwood"}}}
:enddata
:endrule

rule:
plugin=vanillaBlocks
number=16
data:
JSON:{blockState:{blockName:"biomesoplenty:redwood_stairs",properties:{half:"bottom",shape:"straight",facing:"north"}}}
:enddata
:endrule

rule:
plugin=vanillaBlocks
number=17
data:
JSON:{blockState:{blockName:"biomesoplenty:redwood_stairs",properties:{half:"top",shape:"straight",facing:"south"}}}
:enddata
:endrule

rule:
plugin=vanillaBlocks
number=18
data:
JSON:{blockState:{blockName:"biomesoplenty:log_2",properties:{variant:"redwood",axis:"x"}}}
:enddata
:endrule

rule:
plugin=vanillaBlocks
number=19
data:
JSON:{blockState:{blockName:"biomesoplenty:log_2",properties:{variant:"redwood",axis:"z"}}}
:enddata
:endrule

rule:
plugin=vanillaBlocks
number=20
data:
JSON:{blockState:{blockName:"biomesoplenty:redwood_stairs",properties:{half:"top",shape:"straight",facing:"north"}}}
:enddata
:endrule

rule:
plugin=vanillaBlocks
number=21
data:
JSON:{blockState:{blockName:"biomesoplenty:redwood_stairs",properties:{half:"bottom",shape:"straight",facing:"south"}}}
:enddata
:endrule

rule:
plugin=vanillaBlocks
number=22
data:
JSON:{blockState:{blockName:"biomesoplenty:redwood_stairs",properties:{half:"bottom",shape:"straight",facing:"west"}}}
:enddata
:endrule

rule:
plugin=vanillaBlocks
number=23
data:
JSON:{blockState:{blockName:"biomesoplenty:redwood_stairs",properties:{half:"bottom",shape:"straight",facing:"east"}}}
:enddata
:endrule

#### ENTITIES ####
