# Ancient Warfare Structure Template File
# Auto-generated structure template file. created on: 6/11/2023 at: 16:54:7
# Lines beginning with # denote comments

header:
version=2.11
name=SB_MarenCol_Tower_1_ebony
mods=biomesoplenty
size=9,22,9
offset=4,1,8
:endheader

#### VALIDATION ####
validation:
type=ground
structureAuthor=TheOddlySeagull
survival=true
worldGenEnabled=false
unique=false
preserveBlocks=false
preventNaturalHostileSpawns=false
selectionWeight=1
clusterValue=1
minDuplicateDistance=1
dimensionWhiteList=true
dimensionList=
biomeGroupList=
biomeWhiteList=true
biomeList=
leveling=0
fill=0
border=0
blockSwap=false
territoryName=
biomeReplacement=minecraft:
minGenerationHeight=0
maxGenerationHeight=255
:endvalidation

#### LAYERS ####
layer: 0
1,1,1,1,1,1,1,1,1
1,1,1,1,1,1,1,1,1
1,1,2,3,3,3,2,1,1
1,1,3,3,3,3,3,1,1
1,1,3,3,3,3,3,1,1
1,1,3,3,3,3,3,1,1
1,1,2,3,3,3,2,1,1
1,1,1,2,3,2,1,1,1
1,1,1,2,3,2,1,1,1
:endlayer
layer: 1
0,0,0,0,0,0,0,0,0
0,0,0,0,0,0,0,0,0
0,0,2,3,3,3,2,0,0
0,0,3,6,0,4,3,0,0
0,0,3,7,5,0,3,0,0
0,0,3,0,0,0,3,0,0
0,0,2,3,0,3,2,0,0
0,0,0,0,0,0,0,0,0
0,0,0,0,0,0,0,0,0
:endlayer
layer: 2
0,0,0,0,0,0,0,0,0
0,0,0,0,0,0,0,0,0
0,0,2,3,3,3,2,0,0
0,0,3,0,7,6,3,0,0
0,0,3,0,5,0,3,0,0
0,0,3,0,0,8,3,0,0
0,0,2,3,0,3,2,0,0
0,0,0,0,0,0,0,0,0
0,0,0,0,0,0,0,0,0
:endlayer
layer: 3
0,0,0,0,0,0,0,0,0
0,0,10,0,0,0,10,0,0
0,8,2,3,0,3,2,9,0
0,0,3,0,0,0,3,0,0
0,0,3,0,5,7,3,0,0
0,0,3,10,0,6,3,0,0
0,8,2,3,3,3,2,9,0
0,0,4,0,0,0,4,0,0
0,0,0,0,0,0,0,0,0
:endlayer
layer: 4
0,0,0,0,0,0,0,0,0
0,0,0,0,0,0,0,0,0
0,0,2,3,11,3,2,0,0
0,0,3,9,0,0,3,0,0
0,0,3,0,5,0,0,0,0
0,0,3,6,7,0,3,0,0
0,0,2,3,3,3,2,0,0
0,0,0,0,0,0,0,0,0
0,0,0,0,0,0,0,0,0
:endlayer
layer: 5
0,0,0,0,0,0,0,0,0
0,0,0,0,0,0,0,0,0
0,0,2,3,3,3,2,0,0
0,0,3,6,0,4,3,0,0
0,0,3,7,5,0,11,0,0
0,0,3,0,0,0,3,0,0
0,0,2,3,0,3,2,0,0
0,0,0,0,0,0,0,0,0
0,0,0,0,0,0,0,0,0
:endlayer
layer: 6
0,0,0,0,0,0,0,0,0
0,0,0,0,0,0,0,0,0
0,0,2,3,3,3,2,0,0
0,0,3,0,7,6,3,0,0
0,0,3,0,5,0,3,0,0
0,0,3,0,0,8,3,0,0
0,0,2,3,11,3,2,0,0
0,0,0,0,0,0,0,0,0
0,0,0,0,0,0,0,0,0
:endlayer
layer: 7
0,0,0,0,0,0,0,0,0
0,0,0,0,0,0,0,0,0
0,0,2,2,2,2,2,0,0
0,0,2,0,0,0,2,0,0
0,0,2,0,5,7,2,0,0
0,0,2,10,0,6,2,0,0
0,0,2,2,2,2,2,0,0
0,0,0,0,0,0,0,0,0
0,0,0,0,0,0,0,0,0
:endlayer
layer: 8
0,0,0,0,0,0,0,0,0
0,0,0,0,0,0,0,0,0
0,0,12,14,14,14,12,0,0
0,0,13,9,0,0,13,0,0
0,0,13,0,5,0,13,0,0
0,0,13,6,7,0,13,0,0
0,0,12,14,14,14,12,0,0
0,0,0,0,0,0,0,0,0
0,0,0,0,0,0,0,0,0
:endlayer
layer: 9
0,0,0,0,0,0,0,0,0
0,0,0,0,0,0,0,0,0
0,0,12,15,12,15,12,0,0
0,0,15,6,0,4,15,0,0
0,0,12,7,5,0,12,0,0
0,0,7,0,0,0,15,0,0
0,0,12,7,12,15,12,0,0
0,0,0,0,0,0,0,0,0
0,0,0,0,0,0,0,0,0
:endlayer
layer: 10
0,0,0,0,0,0,0,0,0
0,0,0,0,0,0,0,0,0
0,0,12,7,12,14,12,0,0
0,0,7,0,7,6,13,0,0
0,0,12,0,5,0,12,0,0
0,0,0,0,0,8,15,0,0
0,0,12,0,12,15,12,0,0
0,0,0,0,0,0,0,0,0
0,0,0,0,0,0,0,0,0
:endlayer
layer: 11
0,0,0,0,0,0,0,0,0
0,0,0,0,0,0,0,0,0
0,0,12,0,12,7,12,0,0
0,0,0,0,0,0,7,0,0
0,0,12,0,5,7,12,0,0
0,0,17,10,0,6,13,0,0
0,0,12,16,12,14,12,0,0
0,0,0,0,0,0,0,0,0
0,0,0,0,0,0,0,0,0
:endlayer
layer: 12
0,0,0,0,0,0,0,0,0
0,0,0,0,0,0,0,0,0
0,0,12,18,12,0,12,0,0
0,0,17,6,0,0,0,0,0
0,0,12,6,5,0,12,0,0
0,0,13,6,7,0,7,0,0
0,0,12,14,12,7,12,0,0
0,0,0,0,0,0,0,0,0
0,0,0,0,0,0,0,0,0
:endlayer
layer: 13
0,0,0,0,0,0,0,0,0
0,0,0,0,0,0,0,0,0
0,0,12,14,12,18,12,0,0
0,0,13,0,0,0,19,0,0
0,0,12,0,5,0,12,0,0
0,0,7,0,0,0,0,0,0
0,0,12,7,12,0,12,0,0
0,0,0,0,0,0,0,0,0
0,0,0,0,0,0,0,0,0
:endlayer
layer: 14
0,0,0,0,0,0,0,0,0
0,0,0,0,0,0,0,0,0
0,0,12,15,12,14,12,0,0
0,0,15,0,0,0,13,0,0
0,0,12,0,5,0,12,0,0
0,0,0,0,0,0,19,0,0
0,0,12,0,12,16,12,0,0
0,0,0,0,0,0,0,0,0
0,0,0,0,0,0,0,0,0
:endlayer
layer: 15
0,0,0,0,0,0,0,0,0
0,0,5,0,5,0,5,0,0
0,5,12,15,12,15,12,5,0
0,0,15,0,4,0,15,0,0
0,5,12,9,5,8,12,5,0
0,0,17,0,10,0,15,0,0
0,5,12,16,12,15,12,5,0
0,0,5,0,5,0,5,0,0
0,0,0,0,0,0,0,0,0
:endlayer
layer: 16
0,0,0,0,0,0,0,0,0
0,23,20,20,20,20,20,20,0
0,23,12,14,14,14,12,21,0
0,23,13,0,0,0,13,21,0
0,23,13,0,5,0,13,21,0
0,23,13,0,0,0,13,21,0
0,23,12,14,14,14,12,21,0
0,23,22,22,22,22,22,21,0
0,0,0,0,0,0,0,0,0
:endlayer
layer: 17
0,0,0,0,0,0,0,0,0
0,0,0,0,0,0,0,0,0
0,0,23,20,20,20,20,0,0
0,0,23,19,16,16,21,0,0
0,0,23,19,5,17,21,0,0
0,0,23,18,18,17,21,0,0
0,0,22,22,22,22,21,0,0
0,0,0,0,0,0,0,0,0
0,0,0,0,0,0,0,0,0
:endlayer
layer: 18
0,0,0,0,0,0,0,0,0
0,0,0,0,0,0,0,0,0
0,0,0,0,0,0,0,0,0
0,0,0,23,20,20,0,0,0
0,0,0,23,15,21,0,0,0
0,0,0,22,22,21,0,0,0
0,0,0,0,0,0,0,0,0
0,0,0,0,0,0,0,0,0
0,0,0,0,0,0,0,0,0
:endlayer
layer: 19
0,0,0,0,0,0,0,0,0
0,0,0,0,0,0,0,0,0
0,0,0,0,0,0,0,0,0
0,0,0,0,0,0,0,0,0
0,0,0,0,5,0,0,0,0
0,0,0,0,0,0,0,0,0
0,0,0,0,0,0,0,0,0
0,0,0,0,0,0,0,0,0
0,0,0,0,0,0,0,0,0
:endlayer
layer: 20
0,0,0,0,0,0,0,0,0
0,0,0,0,0,0,0,0,0
0,0,0,0,0,0,0,0,0
0,0,0,0,0,0,0,0,0
0,0,0,0,5,0,0,0,0
0,0,0,0,0,0,0,0,0
0,0,0,0,0,0,0,0,0
0,0,0,0,0,0,0,0,0
0,0,0,0,0,0,0,0,0
:endlayer
layer: 21
0,0,0,0,0,0,0,0,0
0,0,0,0,0,0,0,0,0
0,0,0,0,0,0,0,0,0
0,0,0,0,0,0,0,0,0
0,0,0,0,24,0,0,0,0
0,0,0,0,0,0,0,0,0
0,0,0,0,0,0,0,0,0
0,0,0,0,0,0,0,0,0
0,0,0,0,0,0,0,0,0
:endlayer

#### RULES ####
rule:
plugin=vanillaBlocks
number=1
data:
JSON:{blockState:{blockName:"minecraft:grass",properties:{snowy:"false"}}}
:enddata
:endrule

rule:
plugin=vanillaBlocks
number=2
data:
JSON:{blockState:{blockName:"minecraft:stonebrick",properties:{variant:"stonebrick"}}}
:enddata
:endrule

rule:
plugin=vanillaBlocks
number=3
data:
JSON:{blockState:{blockName:"minecraft:cobblestone"}}
:enddata
:endrule

rule:
plugin=vanillaBlocks
number=4
data:
JSON:{blockState:{blockName:"minecraft:torch",properties:{facing:"south"}}}
:enddata
:endrule

rule:
plugin=vanillaBlocks
number=5
data:
JSON:{blockState:{blockName:"biomesoplenty:ebony_fence",properties:{east:"false",south:"false",north:"false",west:"false"}}}
:enddata
:endrule

rule:
plugin=vanillaBlocks
number=6
data:
JSON:{blockState:{blockName:"biomesoplenty:wood_slab_1",properties:{half:"top",variant:"ebony"}}}
:enddata
:endrule

rule:
plugin=vanillaBlocks
number=7
data:
JSON:{blockState:{blockName:"biomesoplenty:wood_slab_1",properties:{half:"bottom",variant:"ebony"}}}
:enddata
:endrule

rule:
plugin=vanillaBlocks
number=8
data:
JSON:{blockState:{blockName:"minecraft:torch",properties:{facing:"west"}}}
:enddata
:endrule

rule:
plugin=vanillaBlocks
number=9
data:
JSON:{blockState:{blockName:"minecraft:torch",properties:{facing:"east"}}}
:enddata
:endrule

rule:
plugin=vanillaBlocks
number=10
data:
JSON:{blockState:{blockName:"minecraft:torch",properties:{facing:"north"}}}
:enddata
:endrule

rule:
plugin=vanillaBlocks
number=11
data:
JSON:{blockState:{blockName:"minecraft:stone_slab",properties:{half:"top",variant:"stone_brick"}}}
:enddata
:endrule

rule:
plugin=vanillaBlocks
number=12
data:
JSON:{blockState:{blockName:"biomesoplenty:log_3",properties:{variant:"ebony",axis:"y"}}}
:enddata
:endrule

rule:
plugin=vanillaBlocks
number=13
data:
JSON:{blockState:{blockName:"biomesoplenty:log_3",properties:{variant:"ebony",axis:"z"}}}
:enddata
:endrule

rule:
plugin=vanillaBlocks
number=14
data:
JSON:{blockState:{blockName:"biomesoplenty:log_3",properties:{variant:"ebony",axis:"x"}}}
:enddata
:endrule

rule:
plugin=vanillaBlocks
number=15
data:
JSON:{blockState:{blockName:"biomesoplenty:planks_0",properties:{variant:"ebony"}}}
:enddata
:endrule

rule:
plugin=vanillaBlocks
number=16
data:
JSON:{blockState:{blockName:"biomesoplenty:ebony_stairs",properties:{half:"top",shape:"straight",facing:"north"}}}
:enddata
:endrule

rule:
plugin=vanillaBlocks
number=17
data:
JSON:{blockState:{blockName:"biomesoplenty:ebony_stairs",properties:{half:"top",shape:"straight",facing:"east"}}}
:enddata
:endrule

rule:
plugin=vanillaBlocks
number=18
data:
JSON:{blockState:{blockName:"biomesoplenty:ebony_stairs",properties:{half:"top",shape:"straight",facing:"south"}}}
:enddata
:endrule

rule:
plugin=vanillaBlocks
number=19
data:
JSON:{blockState:{blockName:"biomesoplenty:ebony_stairs",properties:{half:"top",shape:"straight",facing:"west"}}}
:enddata
:endrule

rule:
plugin=vanillaBlocks
number=20
data:
JSON:{blockState:{blockName:"biomesoplenty:ebony_stairs",properties:{half:"bottom",shape:"straight",facing:"south"}}}
:enddata
:endrule

rule:
plugin=vanillaBlocks
number=21
data:
JSON:{blockState:{blockName:"biomesoplenty:ebony_stairs",properties:{half:"bottom",shape:"straight",facing:"west"}}}
:enddata
:endrule

rule:
plugin=vanillaBlocks
number=22
data:
JSON:{blockState:{blockName:"biomesoplenty:ebony_stairs",properties:{half:"bottom",shape:"straight",facing:"north"}}}
:enddata
:endrule

rule:
plugin=vanillaBlocks
number=23
data:
JSON:{blockState:{blockName:"biomesoplenty:ebony_stairs",properties:{half:"bottom",shape:"straight",facing:"east"}}}
:enddata
:endrule

rule:
plugin=vanillaBlocks
number=24
data:
JSON:{blockState:{blockName:"minecraft:torch",properties:{facing:"up"}}}
:enddata
:endrule

#### ENTITIES ####
