# Ancient Warfare Structure Template File
# Auto-generated structure template file. created on: 3/12/2021 at: 23:24:21
# Lines beginning with # denote comments

header:
version=2.11
name=SB_T2wall2_Angle_ethereal
mods=biomesoplenty
size=16,11,16
offset=15,0,15
:endheader

#### VALIDATION ####
validation:
type=ground
structureAuthor=TheOddlySeagull
survival=true
worldGenEnabled=false
unique=false
preserveBlocks=false
preventNaturalHostileSpawns=false
selectionWeight=1
clusterValue=1
minDuplicateDistance=1
dimensionWhiteList=true
dimensionList=
biomeGroupList=
biomeWhiteList=true
biomeList=
leveling=0
fill=0
border=0
blockSwap=false
territoryName=
biomeReplacement=minecraft:
minGenerationHeight=0
maxGenerationHeight=255
:endvalidation

#### LAYERS ####
layer: 0
0,0,0,0,0,0,1,1,1,1,0,0,0,0,0,0
0,0,0,0,0,0,0,3,3,0,0,0,0,0,0,0
0,0,0,0,0,0,1,3,3,1,0,0,0,0,0,0
0,0,0,0,5,6,6,3,3,0,0,0,0,0,0,0
0,0,0,6,6,2,1,3,3,1,0,0,0,0,0,0
0,0,0,5,3,4,4,3,3,0,0,0,0,0,0,0
1,0,1,5,1,4,4,3,2,1,1,0,0,0,0,0
1,2,2,2,2,2,2,4,4,3,0,0,0,0,0,0
1,2,2,2,2,2,4,4,4,3,0,0,0,0,0,0
1,0,1,0,1,0,1,2,2,1,1,0,0,0,0,0
0,0,0,0,0,0,1,0,0,1,0,0,0,0,0,0
0,0,0,0,0,0,0,0,0,0,0,0,0,0,0,0
0,0,0,0,0,0,0,0,0,0,0,0,0,0,0,0
0,0,0,0,0,0,0,0,0,0,0,0,0,0,0,0
0,0,0,0,0,0,0,0,0,0,0,0,0,0,0,0
0,0,0,0,0,0,0,0,0,0,0,0,0,0,0,0
:endlayer
layer: 1
0,0,0,0,0,0,1,1,1,1,0,0,0,0,0,0
0,0,0,0,0,0,0,4,4,0,0,0,0,0,0,0
0,0,0,0,0,0,5,1,1,8,0,0,0,0,0,0
0,0,0,0,0,0,0,4,4,0,0,0,0,0,0,0
0,0,0,0,0,0,1,1,1,8,0,0,0,0,0,0
0,0,0,0,0,0,0,9,4,0,0,0,0,0,0,0
1,0,6,0,1,0,0,0,4,1,8,0,0,0,0,0
1,4,1,4,1,9,0,5,4,4,0,0,0,0,0,0
1,4,1,4,1,4,0,4,4,4,0,0,0,0,0,0
1,0,7,0,7,0,1,4,4,1,8,0,0,0,0,0
0,0,0,0,0,0,7,0,0,7,0,0,0,0,0,0
0,0,0,0,0,0,0,0,0,0,0,0,0,0,0,0
0,0,0,0,0,0,0,0,0,0,0,0,0,0,0,0
0,0,0,0,0,0,0,0,0,0,0,0,0,0,0,0
0,0,0,0,0,0,0,0,0,0,0,0,0,0,0,0
0,0,0,0,0,0,0,0,0,0,0,0,0,0,0,0
:endlayer
layer: 2
0,0,0,0,0,0,7,1,1,7,0,0,0,0,0,0
0,0,0,0,0,0,0,4,4,0,0,0,0,0,0,0
0,0,0,0,0,0,0,1,1,0,0,0,0,0,0,0
0,0,0,0,0,0,0,4,4,0,0,0,0,0,0,0
0,0,0,0,0,0,1,1,1,0,0,0,0,0,0,0
0,0,0,0,0,0,0,9,4,0,0,0,0,0,0,0
8,0,0,0,1,0,0,0,4,1,0,0,0,0,0,0
1,4,1,4,1,9,0,0,5,4,0,0,0,0,0,0
1,4,1,4,1,4,10,4,4,4,0,0,0,0,0,0
8,0,0,0,0,0,1,4,4,1,0,0,0,0,0,0
0,0,0,0,0,0,0,0,0,0,0,0,0,0,0,0
0,0,0,0,0,0,0,0,0,0,0,0,0,0,0,0
0,0,0,0,0,0,0,0,0,0,0,0,0,0,0,0
0,0,0,0,0,0,0,0,0,0,0,0,0,0,0,0
0,0,0,0,0,0,0,0,0,0,0,0,0,0,0,0
0,0,0,0,0,0,0,0,0,0,0,0,0,0,0,0
:endlayer
layer: 3
0,0,0,0,0,0,9,1,1,9,0,0,0,0,0,0
0,0,0,0,0,0,0,4,4,0,0,0,0,0,0,0
0,0,0,0,0,0,15,1,1,0,0,0,0,0,0,0
0,0,0,0,0,0,0,4,4,12,0,0,0,0,0,0
0,0,0,0,0,14,1,1,1,0,0,0,0,0,0,0
0,0,0,0,10,0,11,14,4,0,0,0,0,0,0,0
9,0,13,0,1,12,0,0,4,1,12,0,0,0,0,0
1,4,1,4,1,10,0,0,0,4,0,0,0,0,0,0
1,4,1,4,1,4,4,4,6,4,0,0,0,0,0,0
9,0,0,11,0,0,1,4,4,1,12,0,0,0,0,0
0,0,0,0,0,0,11,0,0,11,0,0,0,0,0,0
0,0,0,0,0,0,0,0,0,0,0,0,0,0,0,0
0,0,0,0,0,0,0,0,0,0,0,0,0,0,0,0
0,0,0,0,0,0,0,0,0,0,0,0,0,0,0,0
0,0,0,0,0,0,0,0,0,0,0,0,0,0,0,0
0,0,0,0,0,0,0,0,0,0,0,0,0,0,0,0
:endlayer
layer: 4
0,0,0,0,0,0,14,2,2,18,0,0,0,0,0,0
0,0,0,0,0,0,16,3,3,16,0,0,0,0,0,0
0,0,0,0,0,0,14,3,3,18,0,0,0,0,0,0
0,0,0,0,0,0,16,3,3,16,0,0,0,0,0,0
0,0,0,0,1,2,2,3,3,18,0,0,0,0,0,0
0,0,0,0,3,4,4,3,3,16,0,0,0,0,0,0
10,16,10,16,3,4,4,2,2,1,0,0,0,0,0,0
3,2,2,2,2,2,3,0,0,3,0,0,0,0,0,0
3,2,2,2,2,2,3,8,0,3,0,0,0,0,0,0
17,16,17,16,17,16,1,2,2,1,0,0,0,0,0,0
0,0,0,0,0,0,0,0,0,0,0,0,0,0,0,0
0,0,0,0,0,0,0,0,0,0,0,0,0,0,0,0
0,0,0,0,0,0,0,0,0,0,0,0,0,0,0,0
0,0,0,0,0,0,0,0,0,0,0,0,0,0,0,0
0,0,0,0,0,0,0,0,0,0,0,0,0,0,0,0
0,0,0,0,0,0,0,0,0,0,0,0,0,0,0,0
:endlayer
layer: 5
0,0,0,0,0,0,9,0,0,3,0,0,0,0,0,0
0,0,0,0,0,0,9,0,0,3,0,0,0,0,0,0
0,0,0,0,0,0,9,0,0,3,0,0,0,0,0,0
0,0,0,0,0,0,9,0,0,3,0,0,0,0,0,0
0,0,0,0,1,9,9,0,0,3,0,0,0,0,0,0
0,0,0,0,9,0,0,0,0,3,0,0,0,0,0,0
9,9,9,9,9,0,1,4,4,1,0,0,0,0,0,0
0,0,0,0,0,0,0,0,0,4,0,0,0,0,0,0
0,0,0,0,0,0,0,0,0,9,0,0,0,0,0,0
2,2,2,2,2,2,1,4,4,1,0,0,0,0,0,0
0,0,0,0,0,0,0,0,0,0,0,0,0,0,0,0
0,0,0,0,0,0,0,0,0,0,0,0,0,0,0,0
0,0,0,0,0,0,0,0,0,0,0,0,0,0,0,0
0,0,0,0,0,0,0,0,0,0,0,0,0,0,0,0
0,0,0,0,0,0,0,0,0,0,0,0,0,0,0,0
0,0,0,0,0,0,0,0,0,0,0,0,0,0,0,0
:endlayer
layer: 6
0,0,0,0,0,0,0,0,0,8,0,0,0,0,0,0
0,0,0,0,0,0,0,0,0,0,0,0,0,0,0,0
0,0,0,0,0,0,19,0,0,8,0,0,0,0,0,0
0,0,0,0,0,0,0,0,0,0,0,0,0,0,0,0
0,0,0,0,20,0,0,0,0,8,0,0,0,0,0,0
0,0,0,0,0,0,0,0,0,0,0,0,0,0,0,0
0,0,19,0,0,0,1,4,4,1,0,0,0,0,0,0
0,0,0,0,0,0,0,0,0,4,0,0,0,0,0,0
0,0,0,0,0,0,0,0,0,18,0,0,0,0,0,0
7,0,7,0,7,0,1,4,4,1,0,0,0,0,0,0
0,0,0,0,0,0,0,0,0,0,0,0,0,0,0,0
0,0,0,0,0,0,0,0,0,0,0,0,0,0,0,0
0,0,0,0,0,0,0,0,0,0,0,0,0,0,0,0
0,0,0,0,0,0,0,0,0,0,0,0,0,0,0,0
0,0,0,0,0,0,0,0,0,0,0,0,0,0,0,0
0,0,0,0,0,0,0,0,0,0,0,0,0,0,0,0
:endlayer
layer: 7
0,0,0,0,0,0,0,0,0,0,0,0,0,0,0,0
0,0,0,0,0,0,0,0,0,0,0,0,0,0,0,0
0,0,0,0,0,0,0,0,0,0,0,0,0,0,0,0
0,0,0,0,0,0,0,0,0,0,0,0,0,0,0,0
0,0,0,0,0,0,0,0,0,0,0,0,0,0,0,0
0,0,0,0,0,0,9,0,0,9,0,0,0,0,0,0
0,0,0,0,0,9,1,4,4,1,9,0,0,0,0,0
0,0,0,0,0,0,17,0,15,4,0,0,0,0,0,0
0,0,0,0,0,0,10,0,0,4,0,0,0,0,0,0
0,0,0,0,0,9,1,4,4,1,9,0,0,0,0,0
0,0,0,0,0,0,9,0,0,9,0,0,0,0,0,0
0,0,0,0,0,0,0,0,0,0,0,0,0,0,0,0
0,0,0,0,0,0,0,0,0,0,0,0,0,0,0,0
0,0,0,0,0,0,0,0,0,0,0,0,0,0,0,0
0,0,0,0,0,0,0,0,0,0,0,0,0,0,0,0
0,0,0,0,0,0,0,0,0,0,0,0,0,0,0,0
:endlayer
layer: 8
0,0,0,0,0,0,0,0,0,0,0,0,0,0,0,0
0,0,0,0,0,0,0,0,0,0,0,0,0,0,0,0
0,0,0,0,0,0,0,0,0,0,0,0,0,0,0,0
0,0,0,0,0,0,0,0,0,0,0,0,0,0,0,0
0,0,0,0,0,0,0,0,0,0,0,0,0,0,0,0
0,0,0,0,0,5,6,6,6,6,6,0,0,0,0,0
0,0,0,0,0,5,1,2,2,1,8,0,0,0,0,0
0,0,0,0,0,5,3,0,0,3,8,0,0,0,0,0
0,0,0,0,0,5,3,0,0,3,8,0,0,0,0,0
0,0,0,0,0,5,1,2,2,1,8,0,0,0,0,0
0,0,0,0,0,7,7,7,7,7,7,0,0,0,0,0
0,0,0,0,0,0,0,0,0,0,0,0,0,0,0,0
0,0,0,0,0,0,0,0,0,0,0,0,0,0,0,0
0,0,0,0,0,0,0,0,0,0,0,0,0,0,0,0
0,0,0,0,0,0,0,0,0,0,0,0,0,0,0,0
0,0,0,0,0,0,0,0,0,0,0,0,0,0,0,0
:endlayer
layer: 9
0,0,0,0,0,0,0,0,0,0,0,0,0,0,0,0
0,0,0,0,0,0,0,0,0,0,0,0,0,0,0,0
0,0,0,0,0,0,0,0,0,0,0,0,0,0,0,0
0,0,0,0,0,0,0,0,0,0,0,0,0,0,0,0
0,0,0,0,0,0,0,0,0,0,0,0,0,0,0,0
0,0,0,0,0,0,0,0,0,0,0,0,0,0,0,0
0,0,0,0,0,0,20,20,20,20,0,0,0,0,0,0
0,0,0,0,0,0,20,4,4,20,0,0,0,0,0,0
0,0,0,0,0,0,20,4,4,20,0,0,0,0,0,0
0,0,0,0,0,0,20,20,20,20,0,0,0,0,0,0
0,0,0,0,0,0,0,0,0,0,0,0,0,0,0,0
0,0,0,0,0,0,0,0,0,0,0,0,0,0,0,0
0,0,0,0,0,0,0,0,0,0,0,0,0,0,0,0
0,0,0,0,0,0,0,0,0,0,0,0,0,0,0,0
0,0,0,0,0,0,0,0,0,0,0,0,0,0,0,0
0,0,0,0,0,0,0,0,0,0,0,0,0,0,0,0
:endlayer
layer: 10
0,0,0,0,0,0,0,0,0,0,0,0,0,0,0,0
0,0,0,0,0,0,0,0,0,0,0,0,0,0,0,0
0,0,0,0,0,0,0,0,0,0,0,0,0,0,0,0
0,0,0,0,0,0,0,0,0,0,0,0,0,0,0,0
0,0,0,0,0,0,0,0,0,0,0,0,0,0,0,0
0,0,0,0,0,0,0,0,0,0,0,0,0,0,0,0
0,0,0,0,0,0,0,0,0,0,0,0,0,0,0,0
0,0,0,0,0,0,0,19,0,0,0,0,0,0,0,0
0,0,0,0,0,0,0,0,0,0,0,0,0,0,0,0
0,0,0,0,0,0,0,0,0,0,0,0,0,0,0,0
0,0,0,0,0,0,0,0,0,0,0,0,0,0,0,0
0,0,0,0,0,0,0,0,0,0,0,0,0,0,0,0
0,0,0,0,0,0,0,0,0,0,0,0,0,0,0,0
0,0,0,0,0,0,0,0,0,0,0,0,0,0,0,0
0,0,0,0,0,0,0,0,0,0,0,0,0,0,0,0
0,0,0,0,0,0,0,0,0,0,0,0,0,0,0,0
:endlayer

#### RULES ####
rule:
plugin=vanillaBlocks
number=1
data:
JSON:{blockState:{blockName:"biomesoplenty:log_1",properties:{variant:"ethereal",axis:"y"}}}
:enddata
:endrule

rule:
plugin=vanillaBlocks
number=2
data:
JSON:{blockState:{blockName:"biomesoplenty:log_1",properties:{variant:"ethereal",axis:"x"}}}
:enddata
:endrule

rule:
plugin=vanillaBlocks
number=3
data:
JSON:{blockState:{blockName:"biomesoplenty:log_1",properties:{variant:"ethereal",axis:"z"}}}
:enddata
:endrule

rule:
plugin=vanillaBlocks
number=4
data:
JSON:{blockState:{blockName:"biomesoplenty:planks_0",properties:{variant:"ethereal"}}}
:enddata
:endrule

rule:
plugin=vanillaBlocks
number=5
data:
JSON:{blockState:{blockName:"biomesoplenty:ethereal_stairs",properties:{half:"bottom",shape:"straight",facing:"east"}}}
:enddata
:endrule

rule:
plugin=vanillaBlocks
number=6
data:
JSON:{blockState:{blockName:"biomesoplenty:ethereal_stairs",properties:{half:"bottom",shape:"straight",facing:"south"}}}
:enddata
:endrule

rule:
plugin=vanillaBlocks
number=7
data:
JSON:{blockState:{blockName:"biomesoplenty:ethereal_stairs",properties:{half:"bottom",shape:"straight",facing:"north"}}}
:enddata
:endrule

rule:
plugin=vanillaBlocks
number=8
data:
JSON:{blockState:{blockName:"biomesoplenty:ethereal_stairs",properties:{half:"bottom",shape:"straight",facing:"west"}}}
:enddata
:endrule

rule:
plugin=vanillaBlocks
number=9
data:
JSON:{blockState:{blockName:"biomesoplenty:ethereal_fence",properties:{east:"false",south:"false",north:"false",west:"false"}}}
:enddata
:endrule

rule:
plugin=vanillaBlocks
number=10
data:
JSON:{blockState:{blockName:"biomesoplenty:ethereal_stairs",properties:{half:"top",shape:"straight",facing:"south"}}}
:enddata
:endrule

rule:
plugin=vanillaBlocks
number=11
data:
JSON:{blockState:{blockName:"minecraft:torch",properties:{facing:"south"}}}
:enddata
:endrule

rule:
plugin=vanillaBlocks
number=12
data:
JSON:{blockState:{blockName:"minecraft:torch",properties:{facing:"east"}}}
:enddata
:endrule

rule:
plugin=vanillaBlocks
number=13
data:
JSON:{blockState:{blockName:"minecraft:torch",properties:{facing:"north"}}}
:enddata
:endrule

rule:
plugin=vanillaBlocks
number=14
data:
JSON:{blockState:{blockName:"biomesoplenty:ethereal_stairs",properties:{half:"top",shape:"straight",facing:"east"}}}
:enddata
:endrule

rule:
plugin=vanillaBlocks
number=15
data:
JSON:{blockState:{blockName:"minecraft:torch",properties:{facing:"west"}}}
:enddata
:endrule

rule:
plugin=vanillaBlocks
number=16
data:
JSON:{blockState:{blockName:"biomesoplenty:wood_slab_0",properties:{half:"top",variant:"ethereal"}}}
:enddata
:endrule

rule:
plugin=vanillaBlocks
number=17
data:
JSON:{blockState:{blockName:"biomesoplenty:ethereal_stairs",properties:{half:"top",shape:"straight",facing:"north"}}}
:enddata
:endrule

rule:
plugin=vanillaBlocks
number=18
data:
JSON:{blockState:{blockName:"biomesoplenty:ethereal_stairs",properties:{half:"top",shape:"straight",facing:"west"}}}
:enddata
:endrule

rule:
plugin=vanillaBlocks
number=19
data:
JSON:{blockState:{blockName:"minecraft:torch",properties:{facing:"up"}}}
:enddata
:endrule

rule:
plugin=vanillaBlocks
number=20
data:
JSON:{blockState:{blockName:"biomesoplenty:wood_slab_0",properties:{half:"bottom",variant:"ethereal"}}}
:enddata
:endrule

#### ENTITIES ####
