# Ancient Warfare Structure Template File
# Auto-generated structure template file. created on: 2/4/2022 at: 15:11:33
# Lines beginning with # denote comments

header:
version=2.11
name=SB_T0Keep_mahogany
mods=biomesoplenty
size=15,11,12
offset=7,1,11
:endheader

#### VALIDATION ####
validation:
type=ground
structureAuthor=TheOddlySeagull
survival=true
worldGenEnabled=false
unique=false
preserveBlocks=false
preventNaturalHostileSpawns=false
selectionWeight=1
clusterValue=1
minDuplicateDistance=1
dimensionWhiteList=true
dimensionList=
biomeGroupList=
biomeWhiteList=true
biomeList=
leveling=0
fill=0
border=0
blockSwap=false
territoryName=
biomeReplacement=minecraft:
minGenerationHeight=0
maxGenerationHeight=255
:endvalidation

#### LAYERS ####
layer: 0
1,1,1,1,1,1,1,1,1,1,1,1,1,1,1
1,2,1,1,1,2,3,3,3,2,1,1,1,2,1
2,2,4,4,4,4,4,4,4,4,4,4,4,2,2
1,5,3,3,3,3,3,3,3,3,3,3,3,5,1
1,5,3,3,3,3,3,3,3,3,3,3,3,5,1
1,5,3,3,3,3,3,3,3,3,3,3,3,5,1
2,5,3,3,3,3,3,3,3,3,3,3,3,5,2
1,5,3,3,3,3,3,3,3,3,3,3,3,5,1
1,5,3,3,3,3,3,3,3,3,3,3,3,5,1
1,5,3,3,3,3,3,3,3,3,3,3,3,5,1
2,2,4,4,4,4,4,4,4,4,4,4,4,2,2
1,2,1,1,1,2,1,1,1,2,1,1,1,2,1
:endlayer
layer: 1
0,0,0,0,0,0,0,0,0,0,0,0,0,0,0
0,2,0,0,0,2,3,3,3,2,0,0,0,2,0
2,2,3,3,3,2,3,3,3,2,3,3,3,2,2
0,3,0,0,0,0,0,0,0,0,0,0,0,3,0
0,3,0,0,0,0,0,0,0,0,0,0,0,3,0
0,3,0,0,0,0,0,0,0,0,0,0,0,3,0
2,2,0,0,0,0,0,0,0,2,3,3,3,2,2
0,3,0,0,0,0,0,0,0,0,6,7,0,3,0
0,3,0,0,0,2,0,0,0,0,0,8,0,3,0
0,3,0,0,0,3,0,0,0,0,0,0,0,3,0
2,2,3,3,3,2,3,0,3,2,3,3,3,2,2
0,2,0,0,0,2,0,0,0,2,0,0,0,2,0
:endlayer
layer: 2
0,0,0,0,0,0,0,0,0,0,0,0,0,0,0
0,2,0,0,0,2,3,3,3,2,0,0,0,2,0
2,2,3,3,3,2,3,3,3,2,3,3,3,2,2
0,3,0,0,0,0,0,0,0,0,0,0,0,3,0
0,3,0,0,0,0,0,0,0,0,0,0,0,3,0
0,3,0,0,0,0,0,0,0,0,0,0,0,3,0
2,2,0,0,0,0,0,0,0,2,3,3,3,2,2
0,3,0,0,0,0,0,0,0,0,0,0,6,3,0
0,3,0,0,0,2,0,0,0,0,0,8,7,3,0
0,3,0,0,0,3,0,0,0,0,0,9,0,3,0
2,2,3,3,3,2,3,0,3,2,3,3,3,2,2
0,2,0,0,0,2,0,0,0,2,0,0,0,2,0
:endlayer
layer: 3
0,0,0,0,0,0,0,0,0,0,0,0,0,0,0
0,10,0,9,0,10,3,3,3,10,0,9,0,10,0
11,2,3,3,3,2,3,3,3,2,3,3,3,2,12
0,3,0,0,0,0,0,13,0,0,0,0,0,3,0
14,3,15,0,0,0,0,0,0,0,0,0,14,3,15
0,3,0,0,0,0,0,0,0,0,0,0,0,3,0
11,2,0,0,0,0,0,0,0,2,8,8,8,2,12
0,3,0,0,0,9,0,0,0,0,0,0,0,3,0
14,3,15,0,0,2,0,0,0,0,0,8,0,3,15
0,3,0,0,0,3,0,0,0,0,0,7,6,3,0
11,2,3,3,3,2,3,16,3,2,3,3,3,2,12
0,17,0,13,0,17,0,0,0,17,0,13,0,17,0
:endlayer
layer: 4
0,0,0,0,0,0,18,7,18,0,0,0,0,0,0
0,0,0,0,0,19,3,3,3,20,0,0,0,0,0
0,2,4,4,4,4,4,4,4,4,4,4,4,2,0
0,5,7,7,7,5,7,7,7,5,0,0,0,5,0
0,5,7,7,7,5,7,7,7,5,0,0,0,5,0
0,5,7,7,7,5,7,7,7,5,0,0,0,5,0
0,5,7,7,7,5,7,7,7,5,8,0,0,5,0
0,5,7,7,7,5,7,7,7,5,7,0,0,5,0
0,5,7,7,7,5,7,7,7,5,7,8,0,5,0
0,5,7,7,7,5,7,7,7,5,6,0,0,5,0
0,2,4,4,4,4,4,4,4,4,4,4,4,2,0
0,0,0,0,0,0,0,13,0,0,0,0,0,0,0
:endlayer
layer: 5
0,0,0,0,0,0,10,3,10,0,0,0,0,0,0
0,0,0,0,0,3,0,0,0,3,0,0,0,0,0
0,3,10,3,10,2,3,0,3,2,3,8,3,2,0
0,11,0,0,0,3,0,0,0,8,0,0,0,3,0
0,3,0,0,0,0,0,0,0,8,0,0,0,8,0
0,11,0,0,0,3,0,0,0,8,0,0,0,3,0
0,3,0,0,0,2,0,0,0,8,8,0,0,2,0
0,11,0,0,0,3,0,0,0,0,0,0,0,3,0
0,3,0,0,0,0,0,0,0,0,0,8,0,8,0
0,11,0,0,0,3,0,0,0,0,0,0,0,3,0
0,3,17,3,17,2,3,8,3,2,3,8,3,2,0
0,0,0,0,0,0,0,0,0,0,0,0,0,0,0
:endlayer
layer: 6
0,0,0,0,0,0,0,6,0,0,0,0,0,0,0
0,0,0,0,0,6,0,0,0,6,0,0,0,0,0
0,6,0,6,0,2,3,0,3,2,3,8,3,2,0
0,0,0,0,0,3,0,0,0,0,0,0,0,3,0
0,6,0,0,0,0,0,0,0,0,0,0,0,8,0
0,0,0,0,0,3,0,0,0,0,0,0,0,3,0
0,6,0,0,14,2,0,0,0,0,0,0,0,2,0
0,0,0,0,0,3,0,0,0,0,0,0,0,3,0
0,6,0,0,0,0,0,0,0,0,0,8,0,8,0
0,0,0,0,0,3,0,0,0,0,0,0,0,3,0
0,6,0,6,0,2,3,8,3,2,3,8,3,2,0
0,0,0,0,0,0,0,0,0,0,0,0,0,0,0
:endlayer
layer: 7
0,0,0,0,0,0,0,0,0,0,0,0,0,0,0
0,0,0,0,7,0,0,9,0,0,0,0,0,0,7
0,0,0,0,7,2,4,4,4,4,4,4,4,2,7
0,0,0,0,7,5,0,13,0,0,0,0,0,5,7
0,0,0,0,7,5,0,0,0,0,0,0,0,5,7
0,0,0,0,7,5,0,0,0,0,0,0,0,5,7
0,0,0,0,7,5,0,0,0,0,0,0,0,5,7
0,0,0,0,7,5,0,0,0,0,0,0,0,5,7
0,0,0,0,7,5,0,0,0,0,0,8,0,5,7
0,0,0,0,7,5,0,9,0,0,0,0,0,5,7
0,0,0,0,7,2,4,4,4,4,4,4,4,2,7
0,0,0,0,7,0,0,0,0,0,0,0,0,0,7
:endlayer
layer: 8
0,0,0,0,0,0,0,0,0,0,0,0,0,0,0
0,0,0,0,0,6,7,0,0,0,0,0,7,6,0
0,0,0,0,0,6,3,3,3,3,3,3,3,6,0
0,0,0,0,0,6,7,0,0,0,0,0,7,6,0
0,0,0,0,0,6,7,0,0,0,0,0,7,6,0
0,0,0,0,0,6,7,0,0,0,0,0,7,6,0
0,0,0,0,21,6,7,0,0,0,0,0,7,6,21
0,0,0,0,0,6,7,0,0,0,0,0,7,6,0
0,0,0,0,0,6,7,0,0,0,0,8,7,6,0
0,0,0,0,0,6,7,0,0,0,0,0,7,6,0
0,0,0,0,0,6,3,3,3,3,3,3,3,6,0
0,0,0,0,0,6,7,0,0,0,0,0,7,6,0
:endlayer
layer: 9
0,0,0,0,0,0,0,0,0,0,0,0,0,0,0
0,0,0,0,0,0,0,6,7,0,7,6,0,0,0
0,0,0,0,0,0,0,6,3,3,3,6,0,0,0
0,0,0,0,0,0,0,6,7,0,7,6,0,0,0
0,0,0,0,0,0,0,6,7,0,7,6,0,0,0
0,0,0,0,0,0,0,6,7,0,7,6,0,0,0
0,0,0,0,0,0,21,6,7,0,7,6,21,0,0
0,0,0,0,0,0,0,6,7,0,7,6,0,0,0
0,0,0,0,0,0,0,6,7,0,7,6,0,0,0
0,0,0,0,0,0,0,6,7,0,7,6,0,0,0
0,0,0,0,0,0,0,6,3,3,3,6,0,0,0
0,0,0,0,0,0,0,6,7,0,7,6,0,0,0
:endlayer
layer: 10
0,0,0,0,0,0,0,0,0,0,0,0,0,0,0
0,0,0,0,0,0,0,0,0,6,0,0,0,0,0
0,0,0,0,0,0,0,0,0,6,0,0,0,0,0
0,0,0,0,0,0,0,0,0,6,0,0,0,0,0
0,0,0,0,0,0,0,0,0,6,0,0,0,0,0
0,0,0,0,0,0,0,0,0,6,0,0,0,0,0
0,0,0,0,0,0,0,0,21,6,21,0,0,0,0
0,0,0,0,0,0,0,0,0,6,0,0,0,0,0
0,0,0,0,0,0,0,0,0,6,0,0,0,0,0
0,0,0,0,0,0,0,0,0,6,0,0,0,0,0
0,0,0,0,0,0,0,0,0,6,0,0,0,0,0
0,0,0,0,0,0,0,0,0,6,0,0,0,0,0
:endlayer

#### RULES ####
rule:
plugin=vanillaBlocks
number=1
data:
JSON:{blockState:{blockName:"minecraft:dirt",properties:{variant:"dirt",snowy:"false"}}}
:enddata
:endrule

rule:
plugin=vanillaBlocks
number=2
data:
JSON:{blockState:{blockName:"biomesoplenty:log_3",properties:{variant:"mahogany",axis:"y"}}}
:enddata
:endrule

rule:
plugin=vanillaBlocks
number=3
data:
JSON:{blockState:{blockName:"biomesoplenty:planks_0",properties:{variant:"mahogany"}}}
:enddata
:endrule

rule:
plugin=vanillaBlocks
number=4
data:
JSON:{blockState:{blockName:"biomesoplenty:log_3",properties:{variant:"mahogany",axis:"x"}}}
:enddata
:endrule

rule:
plugin=vanillaBlocks
number=5
data:
JSON:{blockState:{blockName:"biomesoplenty:log_3",properties:{variant:"mahogany",axis:"z"}}}
:enddata
:endrule

rule:
plugin=vanillaBlocks
number=6
data:
JSON:{blockState:{blockName:"biomesoplenty:wood_slab_1",properties:{half:"bottom",variant:"mahogany"}}}
:enddata
:endrule

rule:
plugin=vanillaBlocks
number=7
data:
JSON:{blockState:{blockName:"biomesoplenty:wood_slab_1",properties:{half:"top",variant:"mahogany"}}}
:enddata
:endrule

rule:
plugin=vanillaBlocks
number=8
data:
JSON:{blockState:{blockName:"biomesoplenty:mahogany_fence",properties:{east:"false",south:"false",north:"false",west:"false"}}}
:enddata
:endrule

rule:
plugin=vanillaBlocks
number=9
data:
JSON:{blockState:{blockName:"minecraft:torch",properties:{facing:"north"}}}
:enddata
:endrule

rule:
plugin=vanillaBlocks
number=10
data:
JSON:{blockState:{blockName:"biomesoplenty:mahogany_stairs",properties:{half:"bottom",shape:"straight",facing:"south"}}}
:enddata
:endrule

rule:
plugin=vanillaBlocks
number=11
data:
JSON:{blockState:{blockName:"biomesoplenty:mahogany_stairs",properties:{half:"bottom",shape:"straight",facing:"east"}}}
:enddata
:endrule

rule:
plugin=vanillaBlocks
number=12
data:
JSON:{blockState:{blockName:"biomesoplenty:mahogany_stairs",properties:{half:"bottom",shape:"straight",facing:"west"}}}
:enddata
:endrule

rule:
plugin=vanillaBlocks
number=13
data:
JSON:{blockState:{blockName:"minecraft:torch",properties:{facing:"south"}}}
:enddata
:endrule

rule:
plugin=vanillaBlocks
number=14
data:
JSON:{blockState:{blockName:"minecraft:torch",properties:{facing:"west"}}}
:enddata
:endrule

rule:
plugin=vanillaBlocks
number=15
data:
JSON:{blockState:{blockName:"minecraft:torch",properties:{facing:"east"}}}
:enddata
:endrule

rule:
plugin=vanillaBlocks
number=16
data:
JSON:{blockState:{blockName:"biomesoplenty:mahogany_stairs",properties:{half:"top",shape:"straight",facing:"north"}}}
:enddata
:endrule

rule:
plugin=vanillaBlocks
number=17
data:
JSON:{blockState:{blockName:"biomesoplenty:mahogany_stairs",properties:{half:"bottom",shape:"straight",facing:"north"}}}
:enddata
:endrule

rule:
plugin=vanillaBlocks
number=18
data:
JSON:{blockState:{blockName:"biomesoplenty:mahogany_stairs",properties:{half:"top",shape:"straight",facing:"south"}}}
:enddata
:endrule

rule:
plugin=vanillaBlocks
number=19
data:
JSON:{blockState:{blockName:"biomesoplenty:mahogany_stairs",properties:{half:"top",shape:"straight",facing:"east"}}}
:enddata
:endrule

rule:
plugin=vanillaBlocks
number=20
data:
JSON:{blockState:{blockName:"biomesoplenty:mahogany_stairs",properties:{half:"top",shape:"straight",facing:"west"}}}
:enddata
:endrule

rule:
plugin=vanillaBlocks
number=21
data:
JSON:{blockState:{blockName:"minecraft:torch",properties:{facing:"up"}}}
:enddata
:endrule

#### ENTITIES ####
