# Ancient Warfare Structure Template File
# Auto-generated structure template file. created on: 9/5/2023 at: 22:58:48
# Lines beginning with # denote comments

header:
version=2.12
name=SB_MarenCol_Farm_1H1R_1_acacia_Test3
mods=
size=38,14,32
offset=18,1,32
:endheader

#### VALIDATION ####
validation:
type=ground
structureAuthor=
survival=true
worldGenEnabled=false
unique=false
preserveBlocks=false
preventNaturalHostileSpawns=false
selectionWeight=1
clusterValue=1
minDuplicateDistance=1
dimensionWhiteList=true
dimensionList=
biomeGroupList=
biomeWhiteList=true
biomeList=
leveling=0
fill=0
border=0
blockSwap=false
territoryName=
biomeReplacement=minecraft:
minGenerationHeight=0
maxGenerationHeight=255
:endvalidation

#### LAYERS ####
layer: 0
1,1,1,1,1,1,1,1,1,6,1,1,1,1,1,1,5,1,1,1,1,1,1,1,1,1,2,3,3,2,1,1,1,1,1,1,1,1
1,1,1,1,1,1,1,1,5,6,4,1,1,4,1,5,4,4,1,1,1,1,1,1,1,1,2,3,3,2,1,1,1,1,1,1,1,1
1,1,1,4,1,1,1,4,5,4,5,1,5,5,6,6,5,6,6,1,1,1,1,1,1,1,2,3,3,2,1,1,1,1,1,1,1,1
1,4,5,4,4,5,1,1,1,1,6,4,5,5,5,5,6,5,1,1,1,1,1,1,1,1,2,3,3,2,1,1,1,1,1,1,1,1
1,1,1,5,6,1,1,5,1,6,4,1,5,4,5,1,4,1,1,1,1,3,3,3,3,3,3,3,3,3,3,3,1,1,1,1,1,1
1,1,1,1,1,1,1,6,5,5,6,6,1,1,3,3,3,3,3,3,3,3,4,4,6,6,5,5,5,5,6,3,1,1,1,1,1,1
1,1,1,1,1,1,4,6,5,4,5,5,5,1,3,4,6,6,6,5,6,3,6,4,4,6,4,4,5,6,6,3,3,3,3,3,1,1
1,1,1,1,1,1,6,1,1,5,5,6,1,1,3,6,5,6,5,6,4,3,6,6,4,4,4,5,4,5,6,3,4,6,4,3,1,1
1,1,1,1,1,1,5,5,1,1,4,1,1,1,3,5,5,5,3,3,4,3,4,6,6,5,6,4,6,5,4,3,5,4,4,3,1,1
1,1,1,1,6,4,4,4,6,3,3,3,3,3,3,3,3,3,3,3,3,3,5,5,6,6,6,5,5,5,5,3,6,6,4,3,4,1
1,1,1,1,1,5,5,1,1,3,9,9,9,9,3,3,3,3,3,3,3,3,5,4,5,6,6,5,4,4,5,3,4,6,6,3,1,6
1,1,1,1,1,1,3,3,3,3,9,9,9,9,3,3,3,3,3,3,3,3,4,6,5,6,4,6,4,4,4,3,6,5,6,3,5,5
1,1,1,1,1,1,3,3,3,3,9,9,9,9,3,3,3,3,3,3,3,3,4,4,5,4,4,4,5,6,6,3,5,6,6,3,3,5
1,1,3,3,3,3,3,3,3,3,3,3,3,3,3,3,3,3,3,3,3,3,4,5,5,6,5,4,6,4,6,3,6,4,5,3,3,1
1,1,3,5,6,6,3,5,6,3,3,3,3,3,3,3,3,3,3,3,3,3,4,5,5,6,4,6,4,6,5,3,6,5,6,3,3,6
1,1,3,6,5,5,3,5,5,3,3,3,3,3,3,3,3,3,3,3,3,3,5,5,5,5,5,6,5,5,6,3,6,4,6,3,4,1
1,1,3,8,8,8,3,5,6,3,3,3,3,3,3,3,3,3,3,3,3,3,5,5,6,4,4,5,4,4,5,3,3,3,3,3,4,6
1,1,3,5,5,5,3,5,6,3,6,6,1,6,5,1,5,1,1,1,1,3,6,4,4,6,5,5,5,4,4,3,1,6,4,5,4,4
1,1,3,5,5,6,3,6,6,3,1,6,4,5,1,4,1,6,1,1,1,3,4,4,4,4,6,5,6,6,5,3,5,4,1,4,4,6
1,1,3,8,8,8,3,5,5,3,1,6,5,1,1,6,5,1,5,1,5,3,4,6,5,5,5,4,4,6,6,3,5,5,5,1,1,1
1,1,3,6,6,6,3,6,6,3,1,6,1,1,1,1,4,4,4,4,6,3,5,5,5,4,5,5,5,5,5,3,4,1,1,1,1,1
1,1,3,6,5,6,3,6,5,3,4,1,1,1,1,1,6,1,6,6,6,3,3,3,3,3,3,3,3,3,3,3,1,1,1,1,1,1
1,1,3,8,8,8,3,5,6,3,4,5,4,6,1,1,1,1,1,5,1,1,4,2,3,3,3,4,3,2,1,1,1,1,1,1,1,1
1,1,3,6,5,5,3,6,5,3,1,4,6,1,1,1,1,1,1,1,4,5,4,2,3,4,4,3,3,2,1,1,1,1,1,1,1,1
1,1,3,5,5,5,3,6,5,3,5,1,1,1,1,3,3,3,3,3,5,1,1,2,4,4,4,4,4,2,1,1,1,1,1,1,1,1
1,1,3,8,8,8,3,5,5,3,1,6,5,1,1,3,0,0,0,3,1,6,1,2,4,3,3,3,3,2,1,1,1,1,1,1,1,1
1,1,3,6,6,6,3,6,5,3,5,4,1,1,1,3,0,7,0,3,6,4,6,2,4,4,3,3,4,2,1,1,1,1,1,1,1,1
1,1,3,6,5,6,3,6,5,3,4,6,4,1,1,3,0,0,0,3,6,5,4,2,4,4,4,3,3,2,1,1,1,1,1,1,1,1
1,1,3,3,3,3,3,3,3,3,5,6,6,5,4,3,3,3,3,3,4,1,6,2,3,4,3,3,4,2,1,1,1,1,1,1,1,1
1,1,1,1,1,1,2,4,3,2,1,4,4,5,6,1,1,1,5,1,1,4,1,2,3,4,4,3,3,2,1,1,1,1,1,1,1,1
1,1,1,1,1,1,2,3,4,2,1,6,1,5,6,1,1,5,1,5,5,5,1,2,3,4,3,3,3,2,1,1,1,1,1,1,1,1
1,1,1,1,1,1,1,1,1,1,1,1,1,1,1,1,1,1,1,1,1,1,1,1,1,1,1,1,1,1,1,1,1,1,1,1,1,1
:endlayer
layer: 1
0,0,0,0,0,0,0,0,0,0,0,0,0,0,0,0,0,0,0,0,0,0,0,0,0,0,0,0,0,0,0,0,0,0,0,0,0,0
0,10,0,0,0,0,0,0,0,0,0,0,0,0,0,0,0,0,0,0,0,0,0,0,0,0,0,0,0,0,0,0,0,0,0,10,0,0
0,0,0,0,0,0,7,0,0,0,0,0,0,0,0,0,0,7,0,0,0,0,0,0,0,0,0,0,0,0,0,0,0,0,0,0,0,0
0,0,0,0,0,0,0,0,0,0,7,0,0,0,0,0,0,0,0,0,0,0,0,0,0,0,0,0,0,0,0,0,0,0,0,0,0,0
0,0,0,0,0,0,0,0,0,0,0,0,0,0,0,0,0,0,0,0,0,12,9,12,9,9,12,0,0,12,9,12,0,0,0,0,0,0
0,0,0,0,0,0,0,0,0,0,0,0,0,0,10,0,0,10,0,0,10,9,0,15,0,0,0,0,0,15,0,9,0,0,0,0,0,0
0,0,0,0,0,0,0,0,0,0,0,0,0,0,0,0,0,0,0,0,0,12,0,0,0,0,0,0,0,0,0,12,9,12,9,12,0,0
0,0,0,7,0,0,0,0,0,0,0,0,0,0,0,0,0,0,0,0,0,9,0,0,0,0,0,0,0,0,0,9,0,0,0,9,0,0
0,0,0,0,0,0,0,0,0,0,0,0,0,0,0,0,0,0,3,3,0,9,0,0,0,0,0,0,0,0,0,9,0,0,0,12,0,0
0,0,0,0,0,0,0,0,0,12,9,12,9,9,12,0,12,3,0,0,3,12,0,0,0,0,0,0,0,0,0,12,0,0,0,9,0,0
0,0,0,0,0,0,0,0,0,9,0,0,0,0,9,0,0,0,11,11,0,9,0,0,0,7,0,0,0,0,0,9,0,0,0,12,0,0
0,0,0,0,0,0,0,0,0,12,0,0,0,0,12,0,0,0,0,0,0,12,0,0,0,0,0,0,0,0,0,12,0,0,0,9,0,0
0,0,0,0,0,0,0,0,0,9,0,0,0,0,9,0,0,0,0,0,0,0,0,0,0,0,0,0,0,0,0,9,0,0,0,12,0,0
0,0,12,9,9,9,12,0,0,9,9,12,0,0,12,0,0,0,0,0,0,0,0,0,0,0,0,0,0,0,0,9,0,0,0,0,0,0
0,0,9,0,0,0,0,0,0,12,0,0,0,0,0,0,0,0,0,0,0,12,0,0,0,0,0,0,0,0,0,12,0,0,0,12,0,0
0,0,9,0,0,0,0,0,0,0,0,0,0,0,0,0,0,0,0,0,0,9,0,0,0,0,0,0,0,0,0,0,0,0,0,9,0,0
0,0,12,10,10,10,12,0,0,12,9,12,0,0,12,9,12,9,9,12,9,12,0,0,0,0,7,0,0,0,0,12,9,12,9,12,0,0
0,0,9,0,0,0,0,0,0,9,0,0,0,0,0,0,0,0,0,0,0,9,0,0,0,0,0,0,0,0,0,9,0,0,0,0,0,0
0,0,9,0,0,0,0,0,0,12,0,0,0,0,0,0,0,0,0,0,0,9,0,0,0,0,0,0,0,0,0,9,0,0,0,0,0,0
0,0,12,10,10,10,12,0,0,0,0,0,0,0,0,0,0,0,0,0,0,12,0,0,0,0,0,0,0,0,0,12,0,0,0,0,0,0
0,0,9,0,0,0,0,0,0,0,0,0,0,0,0,0,0,0,0,0,0,0,0,0,0,0,0,0,0,0,0,0,0,0,0,0,0,0
0,0,9,0,0,0,0,0,0,0,0,0,0,0,0,0,0,0,0,0,0,12,9,12,0,0,0,0,0,12,9,12,0,0,0,0,0,0
0,0,12,10,10,10,12,0,0,12,0,0,0,0,0,0,0,0,0,0,0,0,0,0,0,0,0,0,0,0,0,0,0,0,0,0,0,0
0,0,9,0,0,0,0,0,0,0,0,0,0,0,0,0,0,0,0,0,0,0,0,0,0,0,0,0,0,0,0,0,0,0,0,0,10,0
0,0,9,0,0,0,0,0,0,0,0,0,0,0,0,11,3,3,3,11,0,0,0,0,0,0,0,0,0,0,0,0,0,0,0,0,0,0
0,0,12,10,10,10,12,0,0,0,0,0,0,0,0,3,0,0,0,3,0,0,0,0,0,0,0,0,0,0,0,0,0,0,0,0,0,0
0,0,9,0,0,0,0,0,0,12,0,0,0,0,14,3,0,0,0,3,13,0,0,0,0,0,0,0,0,0,0,0,0,0,0,0,0,0
0,0,9,0,0,0,0,0,0,9,0,0,0,0,0,3,0,0,0,3,0,0,0,0,0,0,0,0,0,0,0,0,0,0,0,0,0,0
0,0,12,9,9,9,12,0,0,12,0,0,0,0,0,11,3,3,3,11,0,0,0,0,0,0,7,0,0,0,0,0,0,0,0,0,0,0
0,0,0,0,0,0,0,0,0,0,0,0,0,0,0,0,0,0,0,0,0,0,0,0,0,0,0,0,0,0,0,10,0,0,0,0,10,0
0,0,0,0,0,0,0,0,0,0,0,0,0,0,0,0,0,0,0,0,0,0,0,0,0,0,0,0,0,0,0,0,0,0,0,0,0,0
0,0,0,0,0,0,0,0,0,0,0,0,0,0,0,0,0,0,0,0,0,0,0,0,0,0,0,0,0,0,0,0,0,0,0,0,0,0
:endlayer
layer: 2
0,0,0,0,0,0,0,0,0,0,0,0,0,0,0,0,0,0,0,0,0,0,0,0,0,0,0,0,0,0,0,0,0,0,0,0,0,0
0,7,0,0,0,0,0,0,0,0,0,0,0,0,0,0,0,0,0,0,0,0,0,0,0,0,0,0,0,0,0,0,0,0,0,7,0,0
0,0,0,0,0,0,0,0,0,0,0,0,0,0,0,0,0,0,0,0,0,0,0,0,0,0,0,0,0,0,0,0,0,0,0,0,0,0
0,0,0,0,0,0,0,0,0,0,0,0,0,0,0,0,0,0,0,0,0,0,0,0,0,0,0,0,0,0,0,0,0,0,0,0,0,0
0,0,0,0,0,0,0,0,0,0,0,0,0,0,0,0,0,0,0,0,0,12,9,12,9,9,12,0,0,12,9,12,0,0,0,0,0,0
0,0,0,0,0,0,0,0,0,0,0,0,0,0,10,0,0,10,0,0,10,9,0,15,0,0,0,0,0,15,0,9,0,0,0,0,0,0
0,0,0,0,0,0,0,0,0,0,0,0,0,0,0,0,0,0,0,0,0,12,0,0,0,0,0,0,0,0,0,12,9,12,9,12,13,0
0,0,0,0,0,0,0,0,0,0,0,0,0,0,0,0,0,0,0,0,0,9,0,0,0,0,0,0,0,0,0,9,0,0,0,9,0,0
0,0,0,0,0,0,0,0,0,0,0,0,0,0,0,0,0,0,3,3,0,9,0,0,0,0,0,0,0,0,0,9,0,0,0,12,13,0
0,0,0,0,0,0,0,0,0,12,9,12,10,10,12,0,12,3,0,0,3,12,0,0,0,0,0,0,0,0,0,12,0,0,0,10,0,0
0,0,0,0,0,0,0,0,0,9,0,0,0,0,9,0,0,0,0,0,0,9,0,0,0,0,0,0,0,0,0,9,0,0,0,12,13,0
0,0,0,0,0,0,0,0,0,12,0,0,0,0,12,0,0,0,0,0,0,12,0,0,0,0,0,0,0,0,0,12,0,0,0,9,0,0
0,0,0,0,0,0,0,0,0,9,0,0,0,0,9,0,0,0,0,0,0,0,0,0,0,0,0,0,0,0,0,9,0,0,0,12,13,0
0,0,12,9,9,9,12,0,0,9,9,12,0,0,12,0,0,0,0,0,0,0,0,0,0,0,0,0,0,0,0,9,0,0,0,0,0,0
0,0,9,0,0,0,0,0,0,12,0,0,0,0,0,0,0,0,0,0,0,12,0,0,0,0,0,0,0,0,0,12,0,0,0,12,13,0
0,0,9,0,0,0,0,0,0,0,0,0,0,0,0,0,0,0,0,0,0,9,0,0,0,0,0,0,0,0,0,0,0,0,0,9,0,0
0,0,12,0,0,0,12,0,0,12,9,12,0,0,12,9,12,10,10,12,9,12,0,0,0,0,0,0,0,0,0,12,9,12,9,12,13,0
0,0,9,0,0,0,0,0,0,9,0,0,0,0,0,0,0,0,0,0,0,9,0,0,0,0,0,0,0,0,0,9,0,0,0,0,0,0
0,0,9,0,0,0,0,0,0,12,0,0,0,0,0,0,0,0,0,0,0,9,0,0,0,0,0,0,0,0,0,9,0,0,0,0,0,0
0,0,12,0,0,0,12,0,0,0,0,0,0,0,0,0,0,0,0,0,0,12,0,0,0,0,0,0,0,0,0,12,0,0,0,0,0,0
0,0,9,0,0,0,0,0,0,0,0,0,0,0,0,0,0,0,0,0,0,0,0,0,0,0,0,0,0,0,0,0,0,0,0,0,0,0
0,0,9,0,0,0,0,0,0,0,0,0,0,0,0,0,0,0,0,0,0,12,9,12,0,0,0,0,0,12,9,12,0,0,0,0,0,0
0,0,12,0,0,0,12,0,0,12,0,0,0,0,0,0,0,0,0,0,0,0,0,0,0,0,0,0,0,0,0,0,0,0,0,0,0,0
0,0,9,0,0,0,0,0,0,0,0,0,0,0,0,0,0,0,0,0,0,0,0,0,0,0,0,0,0,0,0,0,0,0,0,0,7,0
0,0,9,0,0,0,0,0,0,0,0,0,0,0,0,0,0,0,0,0,0,0,0,0,0,0,0,0,0,0,0,0,0,0,0,0,0,0
0,0,12,0,0,0,12,0,0,0,0,0,0,0,0,0,0,0,0,0,0,0,0,0,0,0,0,0,0,0,0,0,0,0,0,0,0,0
0,0,9,0,0,0,0,0,0,12,0,0,0,0,0,10,0,0,0,10,0,0,0,0,0,0,0,0,0,0,0,0,0,0,0,0,0,0
0,0,9,0,0,0,0,0,0,9,0,0,0,0,0,0,0,0,0,0,0,0,0,0,0,0,0,0,0,0,0,0,0,0,0,0,0,0
0,0,12,9,9,9,12,0,0,12,0,0,0,0,0,0,0,0,0,0,0,0,0,0,0,0,0,0,0,0,0,0,0,0,0,0,0,0
0,0,0,0,0,0,0,0,0,0,0,0,0,0,0,0,0,0,0,0,0,0,0,0,0,0,0,0,0,0,0,7,0,0,0,0,7,0
0,0,0,0,0,0,0,0,0,0,0,0,0,0,0,0,0,0,0,0,0,0,0,0,0,0,0,0,0,0,0,0,0,0,0,0,0,0
0,0,0,0,0,0,0,0,0,0,0,0,0,0,0,0,0,0,0,0,0,0,0,0,0,0,0,0,0,0,0,0,0,0,0,0,0,0
:endlayer
layer: 3
0,0,0,0,0,0,0,0,0,0,0,0,0,0,0,0,0,0,0,0,0,0,0,0,0,0,0,0,0,0,0,0,0,0,0,0,0,0
0,0,0,0,0,0,0,0,0,0,0,0,0,0,0,0,0,0,0,0,0,0,0,0,0,0,0,0,0,0,0,0,0,0,0,0,0,0
0,0,0,0,0,0,0,0,0,0,0,0,0,0,0,0,0,0,0,0,0,0,0,0,0,0,0,0,0,0,0,0,0,0,0,0,0,0
0,0,0,0,0,0,0,0,0,0,0,0,0,0,0,0,0,0,0,0,0,19,0,19,0,0,19,0,0,19,0,19,0,0,0,0,0,0
0,0,0,0,0,0,0,0,0,0,0,0,0,20,20,20,20,20,20,20,20,12,9,12,10,10,12,8,8,12,9,12,13,0,0,0,0,0
0,0,0,0,0,0,0,0,0,0,0,0,0,0,10,0,0,10,0,0,10,9,0,15,0,0,16,0,0,15,0,9,0,19,0,19,20,0
0,0,0,0,0,0,0,0,0,0,0,0,0,0,10,0,0,0,0,0,14,12,13,0,0,0,0,0,0,0,14,12,8,12,9,12,20,0
0,0,0,0,0,0,0,0,0,0,0,0,0,0,10,0,0,0,0,0,0,9,0,0,0,0,0,0,0,0,0,10,0,0,0,21,20,0
0,0,0,0,0,0,0,0,0,19,0,19,0,0,10,0,19,0,3,3,0,9,0,0,0,0,0,0,0,0,0,10,0,0,0,21,20,0
0,0,0,0,0,0,0,0,14,12,9,12,10,10,12,9,12,3,25,24,3,12,10,0,0,0,0,0,0,0,10,12,0,0,0,21,20,0
0,0,0,0,0,0,0,0,0,9,0,16,0,0,9,0,16,0,0,0,0,9,0,0,0,0,0,0,0,0,0,9,0,0,0,21,20,0
0,0,0,0,0,0,0,0,14,12,13,0,0,14,12,13,0,0,0,0,14,12,13,0,0,0,0,0,0,0,14,12,0,0,0,21,20,0
0,0,19,0,0,0,19,0,0,9,0,19,0,0,9,0,0,0,0,0,0,18,0,0,0,0,0,0,0,0,0,10,0,0,0,21,20,0
0,14,12,10,10,10,12,9,9,9,9,12,23,22,12,13,0,0,0,0,0,17,0,0,0,0,0,0,0,0,0,10,0,0,0,21,20,0
0,0,10,0,0,0,0,0,0,12,0,16,0,0,16,0,0,0,0,0,14,12,13,0,0,0,0,0,0,0,14,12,0,0,0,21,20,0
0,0,10,0,0,0,0,0,0,9,0,19,0,0,19,0,19,0,0,19,0,9,0,0,0,0,0,0,0,0,0,9,0,0,0,21,20,0
0,14,12,0,0,0,12,13,0,12,9,12,9,9,12,9,12,10,10,12,9,12,13,0,0,0,0,0,0,0,14,12,8,12,9,12,20,0
0,0,10,0,0,0,0,0,0,9,0,16,0,0,16,0,16,0,0,16,0,10,0,0,0,0,0,0,0,0,0,10,0,16,0,16,20,0
0,0,10,0,0,0,0,0,0,12,13,0,0,0,0,0,0,0,0,0,0,10,0,0,0,0,0,0,0,0,0,10,0,0,0,0,0,0
0,14,12,0,0,0,12,13,0,18,0,0,0,0,0,0,0,0,0,0,14,12,13,0,0,0,0,0,0,0,14,12,13,0,0,0,0,0
0,0,10,0,0,0,0,0,0,0,0,0,0,0,0,0,0,0,0,0,0,9,0,19,0,0,0,0,0,19,0,9,0,0,0,0,0,0
0,0,10,0,0,0,0,0,0,17,0,0,0,0,0,0,0,0,0,0,14,12,9,12,0,0,0,0,0,12,9,12,13,0,0,0,0,0
0,14,12,0,0,0,12,13,0,12,13,0,0,0,0,0,0,0,0,0,0,16,0,16,0,0,0,0,0,16,0,16,0,0,0,0,0,0
0,0,10,0,0,0,0,0,0,18,0,0,0,0,0,0,0,0,0,0,0,0,0,0,0,0,0,0,0,0,0,0,0,0,0,0,0,0
0,0,10,0,0,0,0,0,0,0,0,0,0,0,0,0,0,0,0,0,0,0,0,0,0,0,0,0,0,0,0,0,0,0,0,0,0,0
0,14,12,0,0,0,12,13,0,17,0,0,0,0,0,0,0,0,0,0,0,0,0,0,0,0,0,0,0,0,0,0,0,0,0,0,0,0
0,0,10,0,0,0,0,0,0,12,13,0,0,0,0,10,0,0,0,10,0,0,0,0,0,0,0,0,0,0,0,0,0,0,0,0,0,0
0,0,10,0,0,0,0,0,0,9,0,0,0,0,0,0,0,0,0,0,0,0,0,0,0,0,0,0,0,0,0,0,0,0,0,0,0,0
0,14,12,10,10,10,12,9,9,12,13,0,0,0,0,0,0,0,0,0,0,0,0,0,0,0,0,0,0,0,0,0,0,0,0,0,0,0
0,0,16,0,0,0,16,0,0,16,0,0,0,0,0,0,0,0,0,0,0,0,0,0,0,0,0,0,0,0,0,0,0,0,0,0,0,0
0,0,0,0,0,0,0,0,0,0,0,0,0,0,0,0,0,0,0,0,0,0,0,0,0,0,0,0,0,0,0,0,0,0,0,0,0,0
0,0,0,0,0,0,0,0,0,0,0,0,0,0,0,0,0,0,0,0,0,0,0,0,0,0,0,0,0,0,0,0,0,0,0,0,0,0
:endlayer
layer: 4
0,0,0,0,0,0,0,0,0,0,0,0,0,0,0,0,0,0,0,0,0,0,0,0,0,0,0,0,0,0,0,0,0,0,0,0,0,0
0,0,0,0,0,0,0,0,0,0,0,0,0,0,0,0,0,0,0,0,0,0,0,0,0,0,0,0,0,0,0,0,0,0,0,0,0,0
0,0,0,0,0,0,0,0,0,0,0,0,0,0,0,0,0,0,0,0,0,0,0,0,0,0,0,0,0,0,0,0,0,0,0,0,0,0
0,0,0,0,0,0,0,0,0,0,0,0,0,0,0,0,0,0,0,0,0,0,0,0,0,0,0,0,0,0,0,0,0,0,0,0,0,0
0,0,0,0,0,0,0,0,0,0,0,0,0,0,0,0,0,0,0,0,0,12,8,12,9,9,12,9,9,12,8,12,0,0,0,0,0,0
0,0,0,0,0,0,0,0,0,0,0,0,0,28,28,28,28,28,28,28,28,21,0,15,0,0,0,0,0,15,0,21,0,0,20,28,0,0
0,0,0,0,0,0,0,0,0,0,0,0,0,20,20,20,20,20,20,20,20,12,0,0,0,0,0,0,0,0,0,12,9,12,9,28,0,0
0,0,0,0,0,0,0,0,0,0,0,0,0,0,10,0,0,0,0,0,0,21,0,0,0,0,0,0,0,0,0,21,0,0,20,28,0,0
0,0,0,0,0,0,0,0,30,30,30,30,30,30,30,30,30,30,3,3,30,21,0,0,0,0,0,0,0,0,0,21,0,0,20,28,0,0
0,0,0,0,0,0,0,0,18,12,8,8,8,8,8,8,8,8,8,8,8,12,9,20,0,0,0,0,0,20,9,12,0,0,20,28,0,0
0,0,0,0,0,0,0,0,0,21,0,0,0,0,21,0,0,0,0,0,0,21,0,0,0,0,0,0,0,0,0,21,0,0,20,28,0,0
0,0,0,0,0,0,0,0,0,21,0,0,0,0,21,0,0,0,0,0,0,12,0,0,0,0,0,0,0,0,0,12,0,0,20,28,0,0
0,27,23,0,0,0,0,0,0,21,0,0,0,0,21,0,0,0,0,0,0,21,0,0,0,0,0,0,0,0,0,21,0,0,20,28,0,0
0,27,12,8,8,8,8,8,8,21,8,8,8,8,12,0,0,0,0,0,0,21,0,0,0,0,0,0,0,0,0,21,0,0,20,28,0,0
0,27,21,0,0,0,21,0,0,21,0,0,0,0,0,0,0,0,0,0,0,12,0,0,0,0,0,0,0,0,0,12,0,0,20,28,0,0
0,27,21,0,0,0,21,0,0,21,0,0,0,0,0,0,0,0,0,0,0,21,0,0,0,0,0,0,0,0,0,21,0,0,20,28,0,0
0,27,21,10,10,10,21,0,0,21,8,8,8,8,8,8,8,8,8,8,8,12,0,0,0,0,0,0,0,0,0,12,9,12,9,28,0,0
0,27,21,0,0,0,21,0,0,21,29,29,29,29,29,29,29,29,29,29,29,21,0,0,0,0,0,0,0,0,0,21,0,0,20,28,0,0
0,27,21,0,0,0,21,0,0,21,26,0,0,0,0,0,0,0,0,0,0,21,0,0,0,0,0,0,0,0,0,21,0,0,0,0,0,0
0,27,21,10,10,10,21,0,0,21,26,0,0,0,0,0,0,0,0,0,0,12,0,0,0,0,0,0,0,0,0,12,0,0,0,0,0,0
0,27,21,0,0,0,21,0,0,21,26,0,0,0,0,0,0,0,0,0,0,21,0,0,0,0,0,0,0,0,0,21,0,0,0,0,0,0
0,27,21,0,0,0,21,0,0,21,26,0,0,0,0,0,0,0,0,0,0,12,8,12,0,0,0,0,0,12,8,12,0,0,0,0,0,0
0,27,21,10,10,10,21,0,0,21,26,0,0,0,0,0,0,0,0,0,0,0,0,0,0,0,0,0,0,0,0,0,0,0,0,0,0,0
0,27,21,0,0,0,21,0,0,21,26,0,0,0,0,0,0,0,0,0,0,0,0,0,0,0,0,0,0,0,0,0,0,0,0,0,0,0
0,27,21,0,0,0,21,0,0,21,26,0,0,0,0,0,0,0,0,0,0,0,0,0,0,0,0,0,0,0,0,0,0,0,0,0,0,0
0,27,21,10,10,10,21,0,0,21,26,0,0,0,0,20,20,20,20,20,0,0,0,0,0,0,0,0,0,0,0,0,0,0,0,0,0,0
0,27,21,0,0,0,21,0,0,21,26,0,0,0,0,10,10,10,10,10,0,0,0,0,0,0,0,0,0,0,0,0,0,0,0,0,0,0
0,27,21,0,0,0,21,0,0,21,26,0,0,0,0,20,20,20,20,20,0,0,0,0,0,0,0,0,0,0,0,0,0,0,0,0,0,0
0,27,12,8,8,8,8,8,8,12,26,0,0,0,0,0,0,0,0,0,0,0,0,0,0,0,0,0,0,0,0,0,0,0,0,0,0,0
0,27,23,0,0,0,0,0,0,22,26,0,0,0,0,0,0,0,0,0,0,0,0,0,0,0,0,0,0,0,0,0,0,0,0,0,0,0
0,0,0,0,0,0,0,0,0,0,0,0,0,0,0,0,0,0,0,0,0,0,0,0,0,0,0,0,0,0,0,0,0,0,0,0,0,0
0,0,0,0,0,0,0,0,0,0,0,0,0,0,0,0,0,0,0,0,0,0,0,0,0,0,0,0,0,0,0,0,0,0,0,0,0,0
:endlayer
layer: 5
0,0,0,0,0,0,0,0,0,0,0,0,0,0,0,0,0,0,0,0,0,0,0,0,0,0,0,0,0,0,0,0,0,0,0,0,0,0
0,0,0,0,0,0,0,0,0,0,0,0,0,0,0,0,0,0,0,0,0,0,0,0,0,0,0,0,0,0,0,0,0,0,0,0,0,0
0,0,0,0,0,0,0,0,0,0,0,0,0,0,0,0,0,0,0,0,0,0,0,0,0,0,0,0,0,0,0,0,0,0,0,0,0,0
0,0,0,0,0,0,0,0,0,0,0,0,0,0,0,0,0,0,0,0,0,0,0,0,0,17,20,17,0,0,0,0,0,0,0,0,0,0
0,0,0,0,0,0,0,0,0,0,0,0,0,0,0,0,0,0,0,0,0,12,9,12,8,8,8,8,8,12,9,12,0,0,0,0,0,0
0,0,0,0,0,0,0,0,0,0,0,0,0,0,0,0,0,0,0,0,0,9,20,15,20,9,20,9,20,15,20,9,20,28,0,0,0,0
0,0,0,0,0,0,0,0,0,0,0,0,0,0,0,0,7,0,0,0,0,12,20,9,20,9,20,9,20,9,20,12,9,28,0,0,0,0
0,0,0,0,0,0,0,0,0,0,0,0,0,28,28,28,28,28,28,28,28,9,20,9,20,9,20,9,20,9,20,9,20,28,7,0,0,0
0,0,0,0,0,0,0,0,0,0,0,0,0,20,20,20,20,20,3,3,20,9,20,9,20,9,20,9,20,9,20,9,20,28,0,0,0,0
0,0,0,0,0,0,0,0,30,30,30,30,30,30,30,30,30,30,30,30,30,12,8,8,8,8,8,8,8,8,8,12,20,28,0,0,0,0
0,0,0,0,0,0,0,0,18,12,18,18,18,18,21,18,18,18,18,18,18,9,20,20,20,20,20,20,20,20,20,9,20,28,0,0,0,0
0,0,0,0,0,0,0,0,0,9,0,0,0,0,9,0,0,0,0,0,0,12,0,0,0,0,0,0,0,0,0,12,20,28,0,0,0,0
0,0,27,23,0,0,0,0,22,9,0,0,0,0,9,0,0,0,0,0,0,9,0,0,0,0,0,0,0,0,0,9,20,28,0,0,0,0
0,0,27,12,9,9,9,9,12,9,9,9,9,9,12,0,0,0,0,0,0,9,0,0,0,0,0,0,0,0,0,9,20,28,0,0,0,0
0,0,27,23,0,0,10,0,22,9,0,0,0,0,0,0,0,0,0,0,0,12,0,0,0,0,0,0,0,0,0,12,20,28,0,0,0,0
0,0,27,23,0,0,10,0,22,12,17,17,17,17,17,17,17,17,17,17,17,9,0,0,0,0,0,0,0,0,0,9,20,28,7,0,0,0
0,0,27,23,0,0,12,0,22,26,29,29,29,29,29,29,29,29,29,29,29,12,0,0,0,0,0,0,0,0,0,12,9,28,0,0,0,0
0,0,27,23,0,0,10,0,22,26,0,0,0,0,0,0,0,0,0,0,0,9,0,0,0,0,0,0,0,0,0,9,20,28,0,0,0,0
0,0,27,23,0,0,10,0,22,26,0,0,0,0,0,0,0,0,0,0,0,9,0,0,0,0,0,0,0,0,0,9,0,0,0,0,0,0
0,0,27,23,0,0,12,0,22,26,0,0,0,0,0,0,0,0,0,0,0,12,0,0,0,0,0,0,0,0,0,12,0,0,0,0,0,0
0,0,27,23,0,0,10,0,22,26,0,0,0,0,0,0,0,0,0,0,0,9,0,0,0,0,0,0,0,0,0,9,0,0,0,0,0,0
0,0,27,23,0,0,10,0,22,26,0,0,0,0,0,0,0,0,0,0,0,12,9,12,23,0,0,0,22,12,9,12,0,0,0,0,0,0
0,0,27,23,0,0,12,0,22,26,0,0,0,0,0,0,0,0,0,0,0,0,0,0,0,0,0,0,0,0,0,0,0,0,0,0,0,0
0,0,27,23,0,0,10,0,22,26,0,0,0,0,0,0,0,0,0,0,0,0,0,0,0,0,0,0,0,0,0,0,0,0,0,0,0,0
0,0,27,23,0,0,10,0,22,26,0,0,0,0,0,0,0,0,0,0,0,0,0,0,0,0,0,0,0,0,0,0,0,0,0,0,0,0
0,0,27,23,0,0,12,0,22,26,0,0,0,0,0,0,0,7,0,0,0,0,0,0,0,0,0,0,0,0,0,0,0,0,0,0,0,0
0,0,27,23,0,0,10,0,22,26,0,0,0,0,0,28,28,28,28,28,0,0,0,0,0,0,0,0,0,0,0,0,0,0,0,0,0,0
0,0,27,23,0,0,10,0,22,26,0,0,0,0,0,0,0,7,0,0,0,0,0,0,0,0,0,0,0,0,0,0,0,0,0,0,0,0
0,0,27,12,9,9,9,9,12,26,0,0,0,0,0,0,0,0,0,0,0,0,0,0,0,0,0,0,0,0,0,0,0,0,0,0,0,0
0,0,27,23,0,0,0,0,22,26,0,0,0,0,0,0,0,0,0,0,0,0,0,0,0,0,0,0,0,0,0,0,0,0,0,0,0,0
0,0,0,0,0,0,0,0,0,0,0,0,0,0,0,0,0,0,0,0,0,0,0,0,0,0,0,0,0,0,0,0,0,0,0,0,0,0
0,0,0,0,0,0,0,0,0,0,0,0,0,0,0,0,0,0,0,0,0,0,0,0,0,0,0,0,0,0,0,0,0,0,0,0,0,0
:endlayer
layer: 6
0,0,0,0,0,0,0,0,0,0,0,0,0,0,0,0,0,0,0,0,0,0,0,0,0,0,0,0,0,0,0,0,0,0,0,0,0,0
0,0,0,0,0,0,0,0,0,0,0,0,0,0,0,0,0,0,0,0,0,0,0,0,0,0,0,0,0,0,0,0,0,0,0,0,0,0
0,0,0,0,0,0,0,0,0,0,0,0,0,0,0,0,0,0,0,0,0,0,0,0,0,0,0,0,0,0,0,0,0,0,0,0,0,0
0,0,0,0,0,0,0,0,0,0,0,0,0,0,0,0,0,0,0,0,27,23,0,0,0,0,0,0,0,0,0,22,26,0,0,0,0,0
0,0,0,0,0,0,0,0,0,0,0,0,0,0,0,0,0,0,0,0,27,12,8,12,10,0,0,0,10,12,8,12,26,0,0,0,0,0
0,0,0,0,0,0,0,0,0,0,0,0,0,0,0,0,0,0,0,0,27,21,0,15,0,0,0,0,0,15,0,21,26,0,0,0,0,0
0,0,0,0,0,0,0,0,0,0,0,0,0,0,0,0,0,0,0,0,27,21,0,0,0,0,0,0,0,0,0,21,26,0,0,0,0,0
0,0,0,0,0,0,0,0,0,0,0,0,0,0,0,0,0,0,0,0,27,21,0,0,7,0,0,0,7,0,0,21,26,0,0,0,0,0
0,0,0,0,0,0,0,0,0,0,0,0,0,0,0,0,0,0,3,3,27,21,0,0,0,0,0,0,0,0,0,21,26,0,0,0,0,0
0,0,0,0,0,0,0,0,0,0,0,0,0,28,28,28,28,28,28,28,27,21,0,0,0,0,0,0,0,0,0,21,26,0,0,0,0,0
0,0,0,0,0,0,0,0,30,30,30,30,30,30,30,30,30,30,30,30,30,21,0,0,0,0,0,0,0,0,0,21,26,0,0,0,0,0
0,0,0,0,0,0,0,0,18,12,18,18,18,18,21,18,18,18,18,18,18,21,0,0,0,0,0,0,0,0,0,21,26,0,0,0,0,0
0,0,0,27,23,0,0,22,26,9,0,0,0,0,9,0,0,0,0,0,0,21,0,0,0,0,0,0,0,0,0,21,26,0,0,0,0,0
0,0,0,27,12,9,9,12,26,9,9,9,9,9,12,0,0,0,0,0,0,21,0,0,0,0,0,0,0,0,0,21,26,0,0,0,0,0
0,0,0,27,23,0,0,22,9,12,17,17,17,17,17,17,17,17,17,17,17,21,0,0,0,0,0,0,0,0,0,21,26,0,0,0,0,0
0,0,0,27,23,0,0,22,26,29,29,29,29,29,29,29,29,29,29,29,29,21,0,0,0,0,0,0,0,0,0,21,26,0,0,0,0,0
0,0,0,27,23,0,12,22,26,0,0,0,0,0,0,0,0,0,0,0,27,21,0,0,0,0,0,0,0,0,0,21,26,0,0,0,0,0
0,0,0,27,23,0,0,22,26,0,0,0,0,0,0,0,0,0,0,0,27,21,0,0,0,0,0,0,0,0,0,21,26,0,0,0,0,0
0,0,0,27,23,0,0,22,26,0,0,0,0,0,0,0,0,0,0,0,27,21,0,0,0,0,0,0,0,0,0,21,26,0,0,0,0,0
0,0,0,27,23,0,12,22,26,0,0,0,0,0,0,0,0,0,0,0,27,21,0,0,0,0,0,0,0,0,0,21,26,0,0,0,0,0
0,0,0,27,23,0,0,22,26,0,0,0,0,0,0,0,0,0,0,0,27,21,0,0,0,0,0,0,0,0,0,21,26,0,0,0,0,0
0,0,0,27,23,0,0,22,26,0,0,0,0,0,0,0,0,0,0,0,27,12,8,8,8,8,8,8,8,8,8,12,26,0,0,0,0,0
0,0,0,27,23,0,12,22,26,0,0,0,0,0,0,0,0,0,0,0,27,23,0,0,0,0,0,0,0,0,0,22,26,0,0,0,0,0
0,0,0,27,23,0,0,22,26,0,0,0,0,0,0,0,0,0,0,0,0,0,0,0,0,0,0,0,0,0,0,0,0,0,0,0,0,0
0,0,0,27,23,0,0,22,26,0,0,0,0,0,0,0,0,0,0,0,0,0,0,0,0,0,0,0,0,0,0,0,0,0,0,0,0,0
0,0,0,27,23,0,12,22,26,0,0,0,0,0,0,0,0,0,0,0,0,0,0,0,0,0,0,0,0,0,0,0,0,0,0,0,0,0
0,0,0,27,23,0,0,22,26,0,0,0,0,0,0,0,0,0,0,0,0,0,0,0,0,0,0,0,0,0,0,0,0,0,0,0,0,0
0,0,0,27,23,0,0,22,26,0,0,0,0,0,0,0,0,0,0,0,0,0,0,0,0,0,0,0,0,0,0,0,0,0,0,0,0,0
0,0,0,27,12,9,9,12,26,0,0,0,0,0,0,0,0,0,0,0,0,0,0,0,0,0,0,0,0,0,0,0,0,0,0,0,0,0
0,0,0,27,23,0,0,22,26,0,0,0,0,0,0,0,0,0,0,0,0,0,0,0,0,0,0,0,0,0,0,0,0,0,0,0,0,0
0,0,0,0,0,0,0,0,0,0,0,0,0,0,0,0,0,0,0,0,0,0,0,0,0,0,0,0,0,0,0,0,0,0,0,0,0,0
0,0,0,0,0,0,0,0,0,0,0,0,0,0,0,0,0,0,0,0,0,0,0,0,0,0,0,0,0,0,0,0,0,0,0,0,0,0
:endlayer
layer: 7
0,0,0,0,0,0,0,0,0,0,0,0,0,0,0,0,0,0,0,0,0,0,0,0,0,0,0,0,0,0,0,0,0,0,0,0,0,0
0,0,0,0,0,0,0,0,0,0,0,0,0,0,0,0,0,0,0,0,0,0,0,0,0,0,0,0,0,0,0,0,0,0,0,0,0,0
0,0,0,0,0,0,0,0,0,0,0,0,0,0,0,0,0,0,0,0,0,0,0,0,0,0,0,0,0,0,0,0,0,0,0,0,0,0
0,0,0,0,0,0,0,0,0,0,0,0,0,0,0,0,0,0,0,0,0,27,23,0,0,0,0,0,0,0,22,26,0,0,0,0,0,0
0,0,0,0,0,0,0,0,0,0,0,0,0,0,0,0,0,0,0,0,0,27,12,12,10,0,0,0,10,12,12,26,0,0,0,0,0,0
0,0,0,0,0,0,0,0,0,0,0,0,0,0,0,0,0,0,0,0,0,27,23,15,0,0,0,0,0,15,22,26,0,0,0,0,0,0
0,0,0,0,0,0,0,0,0,0,0,0,0,0,0,0,0,0,0,0,0,27,23,0,0,0,0,0,0,0,22,26,0,0,0,0,0,0
0,0,0,0,0,0,0,0,0,0,0,0,0,0,0,0,0,0,0,0,0,27,23,0,0,0,0,0,0,0,22,26,0,0,0,0,0,0
0,0,0,0,0,0,0,0,0,0,0,0,0,0,0,0,0,0,31,3,0,27,23,0,0,0,0,0,0,0,22,26,0,0,0,0,0,0
0,0,0,0,0,0,0,0,0,0,0,0,0,0,0,0,0,0,0,0,0,27,23,0,0,0,0,0,0,0,22,26,0,0,0,0,0,0
0,0,0,0,0,0,0,0,0,0,0,0,0,0,0,0,0,0,0,0,0,27,23,0,0,0,0,0,0,0,22,26,0,0,0,0,0,0
0,0,0,0,0,0,0,0,30,30,30,30,30,30,30,30,30,30,30,30,30,30,23,0,0,0,0,0,0,0,22,26,0,0,0,0,0,0
0,0,0,0,27,23,22,26,18,21,18,18,18,18,21,18,18,18,18,18,18,9,23,0,0,0,0,0,0,0,22,26,0,0,0,0,0,0
0,0,0,0,27,8,8,26,17,21,8,8,8,8,12,17,17,17,17,17,17,9,23,0,0,0,0,0,0,0,22,26,0,0,0,0,0,0
0,0,0,0,27,23,21,26,29,29,29,29,29,29,29,29,29,29,29,29,29,27,23,0,0,0,0,0,0,0,22,26,0,0,0,0,0,0
0,0,0,0,27,23,21,26,0,0,0,0,0,0,0,0,0,0,0,0,0,27,23,0,0,0,0,0,0,0,22,26,0,0,0,0,0,0
0,0,0,0,27,23,21,26,0,0,0,0,0,0,0,0,0,0,0,0,0,27,23,0,0,0,0,0,0,0,22,26,0,0,0,0,0,0
0,0,0,0,27,23,21,26,0,0,0,0,0,0,0,0,0,0,0,0,0,27,23,0,0,0,0,0,0,0,22,26,0,0,0,0,0,0
0,0,0,0,27,23,21,26,0,0,0,0,0,0,0,0,0,0,0,0,0,27,23,0,0,0,0,0,0,0,22,26,0,0,0,0,0,0
0,0,0,0,27,23,21,26,0,0,0,0,0,0,0,0,0,0,0,0,0,27,23,0,0,0,0,0,0,0,22,26,0,0,0,0,0,0
0,0,0,0,27,23,21,26,0,0,0,0,0,0,0,0,0,0,0,0,0,27,23,0,0,0,0,0,0,0,22,26,0,0,0,0,0,0
0,0,0,0,27,23,21,26,0,0,0,0,0,0,0,0,0,0,0,0,0,27,12,9,12,9,9,9,12,9,12,26,0,0,0,0,0,0
0,0,0,0,27,23,21,26,0,0,0,0,0,0,0,0,0,0,0,0,0,27,23,0,0,0,0,0,0,0,22,26,0,0,0,0,0,0
0,0,0,0,27,23,21,26,0,0,0,0,0,0,0,0,0,0,0,0,0,0,0,0,0,0,0,0,0,0,0,0,0,0,0,0,0,0
0,0,0,0,27,23,21,26,0,0,0,0,0,0,0,0,0,0,0,0,0,0,0,0,0,0,0,0,0,0,0,0,0,0,0,0,0,0
0,0,0,0,27,23,21,26,0,0,0,0,0,0,0,0,0,0,0,0,0,0,0,0,0,0,0,0,0,0,0,0,0,0,0,0,0,0
0,0,0,0,27,23,21,26,0,0,0,0,0,0,0,0,0,0,0,0,0,0,0,0,0,0,0,0,0,0,0,0,0,0,0,0,0,0
0,0,0,0,27,23,21,26,0,0,0,0,0,0,0,0,0,0,0,0,0,0,0,0,0,0,0,0,0,0,0,0,0,0,0,0,0,0
0,0,0,0,27,8,8,26,0,0,0,0,0,0,0,0,0,0,0,0,0,0,0,0,0,0,0,0,0,0,0,0,0,0,0,0,0,0
0,0,0,0,27,23,22,26,0,0,0,0,0,0,0,0,0,0,0,0,0,0,0,0,0,0,0,0,0,0,0,0,0,0,0,0,0,0
0,0,0,0,0,0,0,0,0,0,0,0,0,0,0,0,0,0,0,0,0,0,0,0,0,0,0,0,0,0,0,0,0,0,0,0,0,0
0,0,0,0,0,0,0,0,0,0,0,0,0,0,0,0,0,0,0,0,0,0,0,0,0,0,0,0,0,0,0,0,0,0,0,0,0,0
:endlayer
layer: 8
0,0,0,0,0,0,0,0,0,0,0,0,0,0,0,0,0,0,0,0,0,0,0,0,0,0,0,0,0,0,0,0,0,0,0,0,0,0
0,0,0,0,0,0,0,0,0,0,0,0,0,0,0,0,0,0,0,0,0,0,0,0,0,0,0,0,0,0,0,0,0,0,0,0,0,0
0,0,0,0,0,0,0,0,0,0,0,0,0,0,0,0,0,0,0,0,0,0,0,0,0,0,0,0,0,0,0,0,0,0,0,0,0,0
0,0,0,0,0,0,0,0,0,0,0,0,0,0,0,0,0,0,0,0,0,0,27,23,0,0,0,0,0,22,26,0,0,0,0,0,0,0
0,0,0,0,0,0,0,0,0,0,0,0,0,0,0,0,0,0,0,0,0,0,27,12,9,20,0,20,9,12,26,0,0,0,0,0,0,0
0,0,0,0,0,0,0,0,0,0,0,0,0,0,0,0,0,0,0,0,0,0,27,23,0,0,0,0,0,22,26,0,0,0,0,0,0,0
0,0,0,0,0,0,0,0,0,0,0,0,0,0,0,0,0,0,0,0,0,0,27,23,0,0,0,0,0,22,26,0,0,0,0,0,0,0
0,0,0,0,0,0,0,0,0,0,0,0,0,0,0,0,0,0,0,0,0,0,27,23,0,0,0,0,0,22,26,0,0,0,0,0,0,0
0,0,0,0,0,0,0,0,0,0,0,0,0,0,0,0,0,0,0,3,0,0,27,23,0,0,0,0,0,22,26,0,0,0,0,0,0,0
0,0,0,0,0,0,0,0,0,0,0,0,0,0,0,0,0,0,0,0,0,0,27,23,0,0,0,0,0,22,26,0,0,0,0,0,0,0
0,0,0,0,0,0,0,0,0,0,0,0,0,0,0,0,0,0,0,0,0,0,27,23,0,0,0,0,0,22,26,0,0,0,0,0,0,0
0,0,0,0,0,0,0,0,0,0,0,0,0,0,0,0,0,0,0,0,0,0,27,23,0,0,0,0,0,22,26,0,0,0,0,0,0,0
0,0,0,0,0,27,26,0,30,30,30,30,30,30,30,30,30,30,30,30,30,30,27,23,0,0,0,0,0,22,26,0,0,0,0,0,0,0
0,0,0,0,0,27,26,0,29,29,29,29,29,29,29,29,29,29,29,29,29,29,29,23,0,0,0,0,0,22,26,0,0,0,0,0,0,0
0,0,0,0,0,27,26,0,0,0,0,0,0,0,0,0,0,0,0,0,0,0,27,23,0,0,0,0,0,22,26,0,0,0,0,0,0,0
0,0,0,0,0,27,26,0,0,0,0,0,0,0,0,0,0,0,0,0,0,0,27,23,0,0,0,0,0,22,26,0,0,0,0,0,0,0
0,0,0,0,0,27,26,0,0,0,0,0,0,0,0,0,0,0,0,0,0,0,27,23,0,0,0,0,0,22,26,0,0,0,0,0,0,0
0,0,0,0,0,27,26,0,0,0,0,0,0,0,0,0,0,0,0,0,0,0,27,23,0,0,0,0,0,22,26,0,0,0,0,0,0,0
0,0,0,0,0,27,26,0,0,0,0,0,0,0,0,0,0,0,0,0,0,0,27,23,0,0,0,0,0,22,26,0,0,0,0,0,0,0
0,0,0,0,0,27,26,0,0,0,0,0,0,0,0,0,0,0,0,0,0,0,27,23,0,0,0,0,0,22,26,0,0,0,0,0,0,0
0,0,0,0,0,27,26,0,0,0,0,0,0,0,0,0,0,0,0,0,0,0,27,23,0,0,0,0,0,22,26,0,0,0,0,0,0,0
0,0,0,0,0,27,26,0,0,0,0,0,0,0,0,0,0,0,0,0,0,0,27,12,8,8,8,8,8,12,26,0,0,0,0,0,0,0
0,0,0,0,0,27,26,0,0,0,0,0,0,0,0,0,0,0,0,0,0,0,27,23,0,0,0,0,0,22,26,0,0,0,0,0,0,0
0,0,0,0,0,27,26,0,0,0,0,0,0,0,0,0,0,0,0,0,0,0,0,0,0,0,0,0,0,0,0,0,0,0,0,0,0,0
0,0,0,0,0,27,26,0,0,0,0,0,0,0,0,0,0,0,0,0,0,0,0,0,0,0,0,0,0,0,0,0,0,0,0,0,0,0
0,0,0,0,0,27,26,0,0,0,0,0,0,0,0,0,0,0,0,0,0,0,0,0,0,0,0,0,0,0,0,0,0,0,0,0,0,0
0,0,0,0,0,27,26,0,0,0,0,0,0,0,0,0,0,0,0,0,0,0,0,0,0,0,0,0,0,0,0,0,0,0,0,0,0,0
0,0,0,0,0,27,26,0,0,0,0,0,0,0,0,0,0,0,0,0,0,0,0,0,0,0,0,0,0,0,0,0,0,0,0,0,0,0
0,0,0,0,0,27,26,0,0,0,0,0,0,0,0,0,0,0,0,0,0,0,0,0,0,0,0,0,0,0,0,0,0,0,0,0,0,0
0,0,0,0,0,27,26,0,0,0,0,0,0,0,0,0,0,0,0,0,0,0,0,0,0,0,0,0,0,0,0,0,0,0,0,0,0,0
0,0,0,0,0,0,0,0,0,0,0,0,0,0,0,0,0,0,0,0,0,0,0,0,0,0,0,0,0,0,0,0,0,0,0,0,0,0
0,0,0,0,0,0,0,0,0,0,0,0,0,0,0,0,0,0,0,0,0,0,0,0,0,0,0,0,0,0,0,0,0,0,0,0,0,0
:endlayer
layer: 9
0,0,0,0,0,0,0,0,0,0,0,0,0,0,0,0,0,0,0,0,0,0,0,0,0,0,0,0,0,0,0,0,0,0,0,0,0,0
0,0,0,0,0,0,0,0,0,0,0,0,0,0,0,0,0,0,0,0,0,0,0,0,0,0,0,0,0,0,0,0,0,0,0,0,0,0
0,0,0,0,0,0,0,0,0,0,0,0,0,0,0,0,0,0,0,0,0,0,0,0,0,0,0,0,0,0,0,0,0,0,0,0,0,0
0,0,0,0,0,0,0,0,0,0,0,0,0,0,0,0,0,0,0,0,0,0,0,27,23,0,10,0,22,26,0,0,0,0,0,0,0,0
0,0,0,0,0,0,0,0,0,0,0,0,0,0,0,0,0,0,0,0,0,0,0,27,12,8,8,8,12,26,0,0,0,0,0,0,0,0
0,0,0,0,0,0,0,0,0,0,0,0,0,0,0,0,0,0,0,0,0,0,0,30,23,0,0,0,22,30,0,0,0,0,0,0,0,0
0,0,0,0,0,0,0,0,0,0,0,0,0,0,0,0,0,0,0,0,0,0,0,10,0,0,0,0,0,10,0,0,0,0,0,0,0,0
0,0,0,0,0,0,0,0,0,0,0,0,0,0,0,0,0,0,0,0,0,0,0,29,23,0,0,0,22,29,0,0,0,0,0,0,0,0
0,0,0,0,0,0,0,0,0,0,0,0,0,0,0,0,0,0,0,3,0,0,0,27,23,0,0,0,22,26,0,0,0,0,0,0,0,0
0,0,0,0,0,0,0,0,0,0,0,0,0,0,0,0,0,0,0,0,0,0,0,30,23,0,0,0,22,30,0,0,0,0,0,0,0,0
0,0,0,0,0,0,0,0,0,0,0,0,0,0,0,0,0,0,0,0,0,0,0,10,0,0,0,0,0,10,0,0,0,0,0,0,0,0
0,0,0,0,0,0,0,0,0,0,0,0,0,0,0,0,0,0,0,0,0,0,0,29,23,0,0,0,22,29,0,0,0,0,0,0,0,0
0,0,0,0,0,0,0,0,0,0,0,0,0,0,0,0,0,0,0,0,0,0,0,27,23,0,0,0,22,26,0,0,0,0,0,0,0,0
0,0,0,0,0,0,0,0,0,0,0,0,0,0,0,0,0,0,0,0,0,0,0,27,23,0,0,0,22,26,0,0,0,0,0,0,0,0
0,0,0,0,0,0,0,0,0,0,0,0,0,0,0,0,0,0,0,0,0,0,0,30,23,0,0,0,22,30,0,0,0,0,0,0,0,0
0,0,0,0,0,0,0,0,0,0,0,0,0,0,0,0,0,0,0,0,0,0,0,10,0,0,0,0,0,10,0,0,0,0,0,0,0,0
0,0,0,0,0,0,0,0,0,0,0,0,0,0,0,0,0,0,0,0,0,0,0,29,23,0,0,0,22,29,0,0,0,0,0,0,0,0
0,0,0,0,0,0,0,0,0,0,0,0,0,0,0,0,0,0,0,0,0,0,0,27,23,0,0,0,22,26,0,0,0,0,0,0,0,0
0,0,0,0,0,0,0,0,0,0,0,0,0,0,0,0,0,0,0,0,0,0,0,30,23,0,0,0,22,30,0,0,0,0,0,0,0,0
0,0,0,0,0,0,0,0,0,0,0,0,0,0,0,0,0,0,0,0,0,0,0,10,0,0,0,0,0,10,0,0,0,0,0,0,0,0
0,0,0,0,0,0,0,0,0,0,0,0,0,0,0,0,0,0,0,0,0,0,0,29,23,0,0,0,22,29,0,0,0,0,0,0,0,0
0,0,0,0,0,0,0,0,0,0,0,0,0,0,0,0,0,0,0,0,0,0,0,27,12,9,9,9,12,26,0,0,0,0,0,0,0,0
0,0,0,0,0,0,0,0,0,0,0,0,0,0,0,0,0,0,0,0,0,0,0,27,23,0,0,0,22,26,0,0,0,0,0,0,0,0
0,0,0,0,0,0,0,0,0,0,0,0,0,0,0,0,0,0,0,0,0,0,0,0,0,0,0,0,0,0,0,0,0,0,0,0,0,0
0,0,0,0,0,0,0,0,0,0,0,0,0,0,0,0,0,0,0,0,0,0,0,0,0,0,0,0,0,0,0,0,0,0,0,0,0,0
0,0,0,0,0,0,0,0,0,0,0,0,0,0,0,0,0,0,0,0,0,0,0,0,0,0,0,0,0,0,0,0,0,0,0,0,0,0
0,0,0,0,0,0,0,0,0,0,0,0,0,0,0,0,0,0,0,0,0,0,0,0,0,0,0,0,0,0,0,0,0,0,0,0,0,0
0,0,0,0,0,0,0,0,0,0,0,0,0,0,0,0,0,0,0,0,0,0,0,0,0,0,0,0,0,0,0,0,0,0,0,0,0,0
0,0,0,0,0,0,0,0,0,0,0,0,0,0,0,0,0,0,0,0,0,0,0,0,0,0,0,0,0,0,0,0,0,0,0,0,0,0
0,0,0,0,0,0,0,0,0,0,0,0,0,0,0,0,0,0,0,0,0,0,0,0,0,0,0,0,0,0,0,0,0,0,0,0,0,0
0,0,0,0,0,0,0,0,0,0,0,0,0,0,0,0,0,0,0,0,0,0,0,0,0,0,0,0,0,0,0,0,0,0,0,0,0,0
0,0,0,0,0,0,0,0,0,0,0,0,0,0,0,0,0,0,0,0,0,0,0,0,0,0,0,0,0,0,0,0,0,0,0,0,0,0
:endlayer
layer: 10
0,0,0,0,0,0,0,0,0,0,0,0,0,0,0,0,0,0,0,0,0,0,0,0,0,0,0,0,0,0,0,0,0,0,0,0,0,0
0,0,0,0,0,0,0,0,0,0,0,0,0,0,0,0,0,0,0,0,0,0,0,0,0,0,10,0,0,0,0,0,0,0,0,0,0,0
0,0,0,0,0,0,0,0,0,0,0,0,0,0,0,0,0,0,0,0,0,0,0,0,0,0,10,0,0,0,0,0,0,0,0,0,0,0
0,0,0,0,0,0,0,0,0,0,0,0,0,0,0,0,0,0,0,0,0,0,0,0,27,23,10,22,26,0,0,0,0,0,0,0,0,0
0,0,0,0,0,0,0,0,0,0,0,0,0,0,0,0,0,0,0,0,0,0,0,0,27,12,9,12,26,0,0,0,0,0,0,0,0,0
0,0,0,0,0,0,0,0,0,0,0,0,0,0,0,0,0,0,0,0,0,0,0,0,27,23,0,22,26,0,0,0,0,0,0,0,0,0
0,0,0,0,0,0,0,0,0,0,0,0,0,0,0,0,0,0,0,0,0,0,0,28,27,23,0,22,26,28,0,0,0,0,0,0,0,0
0,0,0,0,0,0,0,0,0,0,0,0,0,0,0,0,0,0,0,0,0,0,0,0,27,23,0,22,26,0,0,0,0,0,0,0,0,0
0,0,0,0,0,0,0,0,0,0,0,0,0,0,0,0,0,0,0,3,0,0,0,0,27,23,0,22,26,0,0,0,0,0,0,0,0,0
0,0,0,0,0,0,0,0,0,0,0,0,0,0,0,0,0,0,0,0,0,0,0,0,27,23,0,22,26,0,0,0,0,0,0,0,0,0
0,0,0,0,0,0,0,0,0,0,0,0,0,0,0,0,0,0,0,0,0,0,0,28,27,23,0,22,26,28,0,0,0,0,0,0,0,0
0,0,0,0,0,0,0,0,0,0,0,0,0,0,0,0,0,0,0,0,0,0,0,0,27,23,0,22,26,0,0,0,0,0,0,0,0,0
0,0,0,0,0,0,0,0,0,0,0,0,0,0,0,0,0,0,0,0,0,0,0,0,27,23,0,22,26,0,0,0,0,0,0,0,0,0
0,0,0,0,0,0,0,0,0,0,0,0,0,0,0,0,0,0,0,0,0,0,0,0,27,23,0,22,26,0,0,0,0,0,0,0,0,0
0,0,0,0,0,0,0,0,0,0,0,0,0,0,0,0,0,0,0,0,0,0,0,0,27,23,0,22,26,0,0,0,0,0,0,0,0,0
0,0,0,0,0,0,0,0,0,0,0,0,0,0,0,0,0,0,0,0,0,0,0,28,27,23,0,22,26,28,0,0,0,0,0,0,0,0
0,0,0,0,0,0,0,0,0,0,0,0,0,0,0,0,0,0,0,0,0,0,0,0,27,23,0,22,26,0,0,0,0,0,0,0,0,0
0,0,0,0,0,0,0,0,0,0,0,0,0,0,0,0,0,0,0,0,0,0,0,0,27,23,0,22,26,0,0,0,0,0,0,0,0,0
0,0,0,0,0,0,0,0,0,0,0,0,0,0,0,0,0,0,0,0,0,0,0,0,27,23,0,22,26,0,0,0,0,0,0,0,0,0
0,0,0,0,0,0,0,0,0,0,0,0,0,0,0,0,0,0,0,0,0,0,0,28,27,23,0,22,26,28,0,0,0,0,0,0,0,0
0,0,0,0,0,0,0,0,0,0,0,0,0,0,0,0,0,0,0,0,0,0,0,0,27,23,0,22,26,0,0,0,0,0,0,0,0,0
0,0,0,0,0,0,0,0,0,0,0,0,0,0,0,0,0,0,0,0,0,0,0,0,27,12,9,12,26,0,0,0,0,0,0,0,0,0
0,0,0,0,0,0,0,0,0,0,0,0,0,0,0,0,0,0,0,0,0,0,0,0,27,23,0,22,26,0,0,0,0,0,0,0,0,0
0,0,0,0,0,0,0,0,0,0,0,0,0,0,0,0,0,0,0,0,0,0,0,0,0,0,0,0,0,0,0,0,0,0,0,0,0,0
0,0,0,0,0,0,0,0,0,0,0,0,0,0,0,0,0,0,0,0,0,0,0,0,0,0,0,0,0,0,0,0,0,0,0,0,0,0
0,0,0,0,0,0,0,0,0,0,0,0,0,0,0,0,0,0,0,0,0,0,0,0,0,0,0,0,0,0,0,0,0,0,0,0,0,0
0,0,0,0,0,0,0,0,0,0,0,0,0,0,0,0,0,0,0,0,0,0,0,0,0,0,0,0,0,0,0,0,0,0,0,0,0,0
0,0,0,0,0,0,0,0,0,0,0,0,0,0,0,0,0,0,0,0,0,0,0,0,0,0,0,0,0,0,0,0,0,0,0,0,0,0
0,0,0,0,0,0,0,0,0,0,0,0,0,0,0,0,0,0,0,0,0,0,0,0,0,0,0,0,0,0,0,0,0,0,0,0,0,0
0,0,0,0,0,0,0,0,0,0,0,0,0,0,0,0,0,0,0,0,0,0,0,0,0,0,0,0,0,0,0,0,0,0,0,0,0,0
0,0,0,0,0,0,0,0,0,0,0,0,0,0,0,0,0,0,0,0,0,0,0,0,0,0,0,0,0,0,0,0,0,0,0,0,0,0
0,0,0,0,0,0,0,0,0,0,0,0,0,0,0,0,0,0,0,0,0,0,0,0,0,0,0,0,0,0,0,0,0,0,0,0,0,0
:endlayer
layer: 11
0,0,0,0,0,0,0,0,0,0,0,0,0,0,0,0,0,0,0,0,0,0,0,0,0,0,0,0,0,0,0,0,0,0,0,0,0,0
0,0,0,0,0,0,0,0,0,0,0,0,0,0,0,0,0,0,0,0,0,0,0,0,0,0,0,0,0,0,0,0,0,0,0,0,0,0
0,0,0,0,0,0,0,0,0,0,0,0,0,0,0,0,0,0,0,0,0,0,0,0,0,0,7,0,0,0,0,0,0,0,0,0,0,0
0,0,0,0,0,0,0,0,0,0,0,0,0,0,0,0,0,0,0,0,0,0,0,0,0,27,17,26,0,0,0,0,0,0,0,0,0,0
0,0,0,0,0,0,0,0,0,0,0,0,0,0,0,0,0,0,0,0,0,0,0,0,0,27,12,26,0,0,0,0,0,0,0,0,0,0
0,0,0,0,0,0,0,0,0,0,0,0,0,0,0,0,0,0,0,0,0,0,0,0,0,27,21,26,0,0,0,0,0,0,0,0,0,0
0,0,0,0,0,0,0,0,0,0,0,0,0,0,0,0,0,0,0,0,0,0,0,0,0,27,21,26,0,0,0,0,0,0,0,0,0,0
0,0,0,0,0,0,0,0,0,0,0,0,0,0,0,0,0,0,0,0,0,0,0,0,0,27,21,26,0,0,0,0,0,0,0,0,0,0
0,0,0,0,0,0,0,0,0,0,0,0,0,0,0,0,0,0,0,3,0,0,0,0,0,27,21,26,0,0,0,0,0,0,0,0,0,0
0,0,0,0,0,0,0,0,0,0,0,0,0,0,0,0,0,0,0,0,0,0,0,0,0,27,21,26,0,0,0,0,0,0,0,0,0,0
0,0,0,0,0,0,0,0,0,0,0,0,0,0,0,0,0,0,0,0,0,0,0,0,0,27,21,26,0,0,0,0,0,0,0,0,0,0
0,0,0,0,0,0,0,0,0,0,0,0,0,0,0,0,0,0,0,0,0,0,0,0,0,27,21,26,0,0,0,0,0,0,0,0,0,0
0,0,0,0,0,0,0,0,0,0,0,0,0,0,0,0,0,0,0,0,0,0,0,0,0,27,21,26,0,0,0,0,0,0,0,0,0,0
0,0,0,0,0,0,0,0,0,0,0,0,0,0,0,0,0,0,0,0,0,0,0,0,0,27,21,26,0,0,0,0,0,0,0,0,0,0
0,0,0,0,0,0,0,0,0,0,0,0,0,0,0,0,0,0,0,0,0,0,0,0,0,27,21,26,0,0,0,0,0,0,0,0,0,0
0,0,0,0,0,0,0,0,0,0,0,0,0,0,0,0,0,0,0,0,0,0,0,0,0,27,21,26,0,0,0,0,0,0,0,0,0,0
0,0,0,0,0,0,0,0,0,0,0,0,0,0,0,0,0,0,0,0,0,0,0,0,0,27,21,26,0,0,0,0,0,0,0,0,0,0
0,0,0,0,0,0,0,0,0,0,0,0,0,0,0,0,0,0,0,0,0,0,0,0,0,27,21,26,0,0,0,0,0,0,0,0,0,0
0,0,0,0,0,0,0,0,0,0,0,0,0,0,0,0,0,0,0,0,0,0,0,0,0,27,21,26,0,0,0,0,0,0,0,0,0,0
0,0,0,0,0,0,0,0,0,0,0,0,0,0,0,0,0,0,0,0,0,0,0,0,0,27,21,26,0,0,0,0,0,0,0,0,0,0
0,0,0,0,0,0,0,0,0,0,0,0,0,0,0,0,0,0,0,0,0,0,0,0,0,27,21,26,0,0,0,0,0,0,0,0,0,0
0,0,0,0,0,0,0,0,0,0,0,0,0,0,0,0,0,0,0,0,0,0,0,0,0,27,12,26,0,0,0,0,0,0,0,0,0,0
0,0,0,0,0,0,0,0,0,0,0,0,0,0,0,0,0,0,0,0,0,0,0,0,0,27,18,26,0,0,0,0,0,0,0,0,0,0
0,0,0,0,0,0,0,0,0,0,0,0,0,0,0,0,0,0,0,0,0,0,0,0,0,0,0,0,0,0,0,0,0,0,0,0,0,0
0,0,0,0,0,0,0,0,0,0,0,0,0,0,0,0,0,0,0,0,0,0,0,0,0,0,0,0,0,0,0,0,0,0,0,0,0,0
0,0,0,0,0,0,0,0,0,0,0,0,0,0,0,0,0,0,0,0,0,0,0,0,0,0,0,0,0,0,0,0,0,0,0,0,0,0
0,0,0,0,0,0,0,0,0,0,0,0,0,0,0,0,0,0,0,0,0,0,0,0,0,0,0,0,0,0,0,0,0,0,0,0,0,0
0,0,0,0,0,0,0,0,0,0,0,0,0,0,0,0,0,0,0,0,0,0,0,0,0,0,0,0,0,0,0,0,0,0,0,0,0,0
0,0,0,0,0,0,0,0,0,0,0,0,0,0,0,0,0,0,0,0,0,0,0,0,0,0,0,0,0,0,0,0,0,0,0,0,0,0
0,0,0,0,0,0,0,0,0,0,0,0,0,0,0,0,0,0,0,0,0,0,0,0,0,0,0,0,0,0,0,0,0,0,0,0,0,0
0,0,0,0,0,0,0,0,0,0,0,0,0,0,0,0,0,0,0,0,0,0,0,0,0,0,0,0,0,0,0,0,0,0,0,0,0,0
0,0,0,0,0,0,0,0,0,0,0,0,0,0,0,0,0,0,0,0,0,0,0,0,0,0,0,0,0,0,0,0,0,0,0,0,0,0
:endlayer
layer: 12
0,0,0,0,0,0,0,0,0,0,0,0,0,0,0,0,0,0,0,0,0,0,0,0,0,0,0,0,0,0,0,0,0,0,0,0,0,0
0,0,0,0,0,0,0,0,0,0,0,0,0,0,0,0,0,0,0,0,0,0,0,0,0,0,0,0,0,0,0,0,0,0,0,0,0,0
0,0,0,0,0,0,0,0,0,0,0,0,0,0,0,0,0,0,0,0,0,0,0,0,0,0,0,0,0,0,0,0,0,0,0,0,0,0
0,0,0,0,0,0,0,0,0,0,0,0,0,0,0,0,0,0,0,0,0,0,0,0,0,0,28,0,0,0,0,0,0,0,0,0,0,0
0,0,0,0,0,0,0,0,0,0,0,0,0,0,0,0,0,0,0,0,0,0,0,0,0,0,28,0,0,0,0,0,0,0,0,0,0,0
0,0,0,0,0,0,0,0,0,0,0,0,0,0,0,0,0,0,0,0,0,0,0,0,0,0,28,0,0,0,0,0,0,0,0,0,0,0
0,0,0,0,0,0,0,0,0,0,0,0,0,0,0,0,0,0,0,0,0,0,0,0,0,0,28,0,0,0,0,0,0,0,0,0,0,0
0,0,0,0,0,0,0,0,0,0,0,0,0,0,0,0,0,0,0,0,0,0,0,0,0,0,28,0,0,0,0,0,0,0,0,0,0,0
0,0,0,0,0,0,0,0,0,0,0,0,0,0,0,0,0,0,0,32,0,0,0,0,0,0,28,0,0,0,0,0,0,0,0,0,0,0
0,0,0,0,0,0,0,0,0,0,0,0,0,0,0,0,0,0,0,0,0,0,0,0,0,0,28,0,0,0,0,0,0,0,0,0,0,0
0,0,0,0,0,0,0,0,0,0,0,0,0,0,0,0,0,0,0,0,0,0,0,0,0,0,28,0,0,0,0,0,0,0,0,0,0,0
0,0,0,0,0,0,0,0,0,0,0,0,0,0,0,0,0,0,0,0,0,0,0,0,0,0,28,0,0,0,0,0,0,0,0,0,0,0
0,0,0,0,0,0,0,0,0,0,0,0,0,0,0,0,0,0,0,0,0,0,0,0,0,0,28,0,0,0,0,0,0,0,0,0,0,0
0,0,0,0,0,0,0,0,0,0,0,0,0,0,0,0,0,0,0,0,0,0,0,0,0,0,28,0,0,0,0,0,0,0,0,0,0,0
0,0,0,0,0,0,0,0,0,0,0,0,0,0,0,0,0,0,0,0,0,0,0,0,0,0,28,0,0,0,0,0,0,0,0,0,0,0
0,0,0,0,0,0,0,0,0,0,0,0,0,0,0,0,0,0,0,0,0,0,0,0,0,0,28,0,0,0,0,0,0,0,0,0,0,0
0,0,0,0,0,0,0,0,0,0,0,0,0,0,0,0,0,0,0,0,0,0,0,0,0,0,28,0,0,0,0,0,0,0,0,0,0,0
0,0,0,0,0,0,0,0,0,0,0,0,0,0,0,0,0,0,0,0,0,0,0,0,0,0,28,0,0,0,0,0,0,0,0,0,0,0
0,0,0,0,0,0,0,0,0,0,0,0,0,0,0,0,0,0,0,0,0,0,0,0,0,0,28,0,0,0,0,0,0,0,0,0,0,0
0,0,0,0,0,0,0,0,0,0,0,0,0,0,0,0,0,0,0,0,0,0,0,0,0,0,28,0,0,0,0,0,0,0,0,0,0,0
0,0,0,0,0,0,0,0,0,0,0,0,0,0,0,0,0,0,0,0,0,0,0,0,0,0,28,0,0,0,0,0,0,0,0,0,0,0
0,0,0,0,0,0,0,0,0,0,0,0,0,0,0,0,0,0,0,0,0,0,0,0,0,0,28,0,0,0,0,0,0,0,0,0,0,0
0,0,0,0,0,0,0,0,0,0,0,0,0,0,0,0,0,0,0,0,0,0,0,0,0,0,28,0,0,0,0,0,0,0,0,0,0,0
0,0,0,0,0,0,0,0,0,0,0,0,0,0,0,0,0,0,0,0,0,0,0,0,0,0,0,0,0,0,0,0,0,0,0,0,0,0
0,0,0,0,0,0,0,0,0,0,0,0,0,0,0,0,0,0,0,0,0,0,0,0,0,0,0,0,0,0,0,0,0,0,0,0,0,0
0,0,0,0,0,0,0,0,0,0,0,0,0,0,0,0,0,0,0,0,0,0,0,0,0,0,0,0,0,0,0,0,0,0,0,0,0,0
0,0,0,0,0,0,0,0,0,0,0,0,0,0,0,0,0,0,0,0,0,0,0,0,0,0,0,0,0,0,0,0,0,0,0,0,0,0
0,0,0,0,0,0,0,0,0,0,0,0,0,0,0,0,0,0,0,0,0,0,0,0,0,0,0,0,0,0,0,0,0,0,0,0,0,0
0,0,0,0,0,0,0,0,0,0,0,0,0,0,0,0,0,0,0,0,0,0,0,0,0,0,0,0,0,0,0,0,0,0,0,0,0,0
0,0,0,0,0,0,0,0,0,0,0,0,0,0,0,0,0,0,0,0,0,0,0,0,0,0,0,0,0,0,0,0,0,0,0,0,0,0
0,0,0,0,0,0,0,0,0,0,0,0,0,0,0,0,0,0,0,0,0,0,0,0,0,0,0,0,0,0,0,0,0,0,0,0,0,0
0,0,0,0,0,0,0,0,0,0,0,0,0,0,0,0,0,0,0,0,0,0,0,0,0,0,0,0,0,0,0,0,0,0,0,0,0,0
:endlayer
layer: 13
0,0,0,0,0,0,0,0,0,0,0,0,0,0,0,0,0,0,0,0,0,0,0,0,0,0,0,0,0,0,0,0,0,0,0,0,0,0
0,0,0,0,0,0,0,0,0,0,0,0,0,0,0,0,0,0,0,0,0,0,0,0,0,0,0,0,0,0,0,0,0,0,0,0,0,0
0,0,0,0,0,0,0,0,0,0,0,0,0,0,0,0,0,0,0,0,0,0,0,0,0,0,0,0,0,0,0,0,0,0,0,0,0,0
0,0,0,0,0,0,0,0,0,0,0,0,0,0,0,0,0,0,0,0,0,0,0,0,0,0,0,0,0,0,0,0,0,0,0,0,0,0
0,0,0,0,0,0,0,0,0,0,0,0,0,0,0,0,0,0,0,0,0,0,0,0,0,0,0,0,0,0,0,0,0,0,0,0,0,0
0,0,0,0,0,0,0,0,0,0,0,0,0,0,0,0,0,0,0,0,0,0,0,0,0,0,0,0,0,0,0,0,0,0,0,0,0,0
0,0,0,0,0,0,0,0,0,0,0,0,0,0,0,0,0,0,0,0,0,0,0,0,0,0,0,0,0,0,0,0,0,0,0,0,0,0
0,0,0,0,0,0,0,0,0,0,0,0,0,0,0,0,0,0,0,0,0,0,0,0,0,0,0,0,0,0,0,0,0,0,0,0,0,0
0,0,0,0,0,0,0,0,0,0,0,0,0,0,0,0,0,0,0,11,0,0,0,0,0,0,0,0,0,0,0,0,0,0,0,0,0,0
0,0,0,0,0,0,0,0,0,0,0,0,0,0,0,0,0,0,0,0,0,0,0,0,0,0,0,0,0,0,0,0,0,0,0,0,0,0
0,0,0,0,0,0,0,0,0,0,0,0,0,0,0,0,0,0,0,0,0,0,0,0,0,0,0,0,0,0,0,0,0,0,0,0,0,0
0,0,0,0,0,0,0,0,0,0,0,0,0,0,0,0,0,0,0,0,0,0,0,0,0,0,0,0,0,0,0,0,0,0,0,0,0,0
0,0,0,0,0,0,0,0,0,0,0,0,0,0,0,0,0,0,0,0,0,0,0,0,0,0,0,0,0,0,0,0,0,0,0,0,0,0
0,0,0,0,0,0,0,0,0,0,0,0,0,0,0,0,0,0,0,0,0,0,0,0,0,0,0,0,0,0,0,0,0,0,0,0,0,0
0,0,0,0,0,0,0,0,0,0,0,0,0,0,0,0,0,0,0,0,0,0,0,0,0,0,0,0,0,0,0,0,0,0,0,0,0,0
0,0,0,0,0,0,0,0,0,0,0,0,0,0,0,0,0,0,0,0,0,0,0,0,0,0,0,0,0,0,0,0,0,0,0,0,0,0
0,0,0,0,0,0,0,0,0,0,0,0,0,0,0,0,0,0,0,0,0,0,0,0,0,0,0,0,0,0,0,0,0,0,0,0,0,0
0,0,0,0,0,0,0,0,0,0,0,0,0,0,0,0,0,0,0,0,0,0,0,0,0,0,0,0,0,0,0,0,0,0,0,0,0,0
0,0,0,0,0,0,0,0,0,0,0,0,0,0,0,0,0,0,0,0,0,0,0,0,0,0,0,0,0,0,0,0,0,0,0,0,0,0
0,0,0,0,0,0,0,0,0,0,0,0,0,0,0,0,0,0,0,0,0,0,0,0,0,0,0,0,0,0,0,0,0,0,0,0,0,0
0,0,0,0,0,0,0,0,0,0,0,0,0,0,0,0,0,0,0,0,0,0,0,0,0,0,0,0,0,0,0,0,0,0,0,0,0,0
0,0,0,0,0,0,0,0,0,0,0,0,0,0,0,0,0,0,0,0,0,0,0,0,0,0,0,0,0,0,0,0,0,0,0,0,0,0
0,0,0,0,0,0,0,0,0,0,0,0,0,0,0,0,0,0,0,0,0,0,0,0,0,0,0,0,0,0,0,0,0,0,0,0,0,0
0,0,0,0,0,0,0,0,0,0,0,0,0,0,0,0,0,0,0,0,0,0,0,0,0,0,0,0,0,0,0,0,0,0,0,0,0,0
0,0,0,0,0,0,0,0,0,0,0,0,0,0,0,0,0,0,0,0,0,0,0,0,0,0,0,0,0,0,0,0,0,0,0,0,0,0
0,0,0,0,0,0,0,0,0,0,0,0,0,0,0,0,0,0,0,0,0,0,0,0,0,0,0,0,0,0,0,0,0,0,0,0,0,0
0,0,0,0,0,0,0,0,0,0,0,0,0,0,0,0,0,0,0,0,0,0,0,0,0,0,0,0,0,0,0,0,0,0,0,0,0,0
0,0,0,0,0,0,0,0,0,0,0,0,0,0,0,0,0,0,0,0,0,0,0,0,0,0,0,0,0,0,0,0,0,0,0,0,0,0
0,0,0,0,0,0,0,0,0,0,0,0,0,0,0,0,0,0,0,0,0,0,0,0,0,0,0,0,0,0,0,0,0,0,0,0,0,0
0,0,0,0,0,0,0,0,0,0,0,0,0,0,0,0,0,0,0,0,0,0,0,0,0,0,0,0,0,0,0,0,0,0,0,0,0,0
0,0,0,0,0,0,0,0,0,0,0,0,0,0,0,0,0,0,0,0,0,0,0,0,0,0,0,0,0,0,0,0,0,0,0,0,0,0
0,0,0,0,0,0,0,0,0,0,0,0,0,0,0,0,0,0,0,0,0,0,0,0,0,0,0,0,0,0,0,0,0,0,0,0,0,0
:endlayer

#### RULES ####
rule:
plugin=vanillaBlocks
number=1
data:
JSON:{blockState:{blockName:"minecraft:grass",properties:{snowy:"false"}}}
:enddata
:endrule

rule:
plugin=vanillaBlocks
number=2
data:
JSON:{blockState:{blockName:"minecraft:stonebrick",properties:{variant:"stonebrick"}}}
:enddata
:endrule

rule:
plugin=vanillaBlocks
number=3
data:
JSON:{blockState:{blockName:"minecraft:cobblestone"}}
:enddata
:endrule

rule:
plugin=vanillaBlocks
number=4
data:
JSON:{blockState:{blockName:"minecraft:gravel"}}
:enddata
:endrule

rule:
plugin=vanillaBlocks
number=5
data:
JSON:{blockState:{blockName:"minecraft:grass_path"}}
:enddata
:endrule

rule:
plugin=vanillaBlocks
number=6
data:
JSON:{blockState:{blockName:"minecraft:dirt",properties:{variant:"coarse_dirt",snowy:"false"}}}
:enddata
:endrule

rule:
plugin=vanillaBlocks
number=7
data:
JSON:{blockState:{blockName:"minecraft:torch",properties:{facing:"up"}}}
:enddata
:endrule

rule:
plugin=vanillaBlocks
number=8
data:
JSON:{blockState:{blockName:"minecraft:log2",properties:{variant:"acacia",axis:"x"}}}
:enddata
:endrule

rule:
plugin=vanillaBlocks
number=9
data:
JSON:{blockState:{blockName:"minecraft:planks",properties:{variant:"acacia"}}}
:enddata
:endrule

rule:
plugin=vanillaBlocks
number=10
data:
JSON:{blockState:{blockName:"minecraft:acacia_fence",properties:{east:"false",south:"false",north:"false",west:"false"}}}
:enddata
:endrule

rule:
plugin=vanillaBlocks
number=11
data:
JSON:{blockState:{blockName:"minecraft:stone_slab",properties:{half:"bottom",variant:"cobblestone"}}}
:enddata
:endrule

rule:
plugin=vanillaBlocks
number=12
data:
JSON:{blockState:{blockName:"minecraft:log2",properties:{variant:"acacia",axis:"y"}}}
:enddata
:endrule

rule:
plugin=vanillaBlocks
number=13
data:
JSON:{blockState:{blockName:"minecraft:torch",properties:{facing:"east"}}}
:enddata
:endrule

rule:
plugin=vanillaBlocks
number=14
data:
JSON:{blockState:{blockName:"minecraft:torch",properties:{facing:"west"}}}
:enddata
:endrule

rule:
plugin=vanillaBlocks
number=15
data:
JSON:{blockState:{blockName:"minecraft:ladder",properties:{facing:"south"}}}
:enddata
:endrule

rule:
plugin=vanillaBlocks
number=16
data:
JSON:{blockState:{blockName:"minecraft:torch",properties:{facing:"south"}}}
:enddata
:endrule

rule:
plugin=vanillaBlocks
number=17
data:
JSON:{blockState:{blockName:"minecraft:acacia_stairs",properties:{half:"top",shape:"straight",facing:"south"}}}
:enddata
:endrule

rule:
plugin=vanillaBlocks
number=18
data:
JSON:{blockState:{blockName:"minecraft:acacia_stairs",properties:{half:"top",shape:"straight",facing:"north"}}}
:enddata
:endrule

rule:
plugin=vanillaBlocks
number=19
data:
JSON:{blockState:{blockName:"minecraft:torch",properties:{facing:"north"}}}
:enddata
:endrule

rule:
plugin=vanillaBlocks
number=20
data:
JSON:{blockState:{blockName:"minecraft:wooden_slab",properties:{half:"top",variant:"acacia"}}}
:enddata
:endrule

rule:
plugin=vanillaBlocks
number=21
data:
JSON:{blockState:{blockName:"minecraft:log2",properties:{variant:"acacia",axis:"z"}}}
:enddata
:endrule

rule:
plugin=vanillaBlocks
number=22
data:
JSON:{blockState:{blockName:"minecraft:acacia_stairs",properties:{half:"top",shape:"straight",facing:"east"}}}
:enddata
:endrule

rule:
plugin=vanillaBlocks
number=23
data:
JSON:{blockState:{blockName:"minecraft:acacia_stairs",properties:{half:"top",shape:"straight",facing:"west"}}}
:enddata
:endrule

rule:
plugin=vanillaBlocks
number=24
data:
JSON:{blockState:{blockName:"minecraft:stone_stairs",properties:{half:"top",shape:"straight",facing:"east"}}}
:enddata
:endrule

rule:
plugin=vanillaBlocks
number=25
data:
JSON:{blockState:{blockName:"minecraft:stone_stairs",properties:{half:"top",shape:"straight",facing:"west"}}}
:enddata
:endrule

rule:
plugin=vanillaBlocks
number=26
data:
JSON:{blockState:{blockName:"minecraft:acacia_stairs",properties:{half:"bottom",shape:"straight",facing:"west"}}}
:enddata
:endrule

rule:
plugin=vanillaBlocks
number=27
data:
JSON:{blockState:{blockName:"minecraft:acacia_stairs",properties:{half:"bottom",shape:"straight",facing:"east"}}}
:enddata
:endrule

rule:
plugin=vanillaBlocks
number=28
data:
JSON:{blockState:{blockName:"minecraft:wooden_slab",properties:{half:"bottom",variant:"acacia"}}}
:enddata
:endrule

rule:
plugin=vanillaBlocks
number=29
data:
JSON:{blockState:{blockName:"minecraft:acacia_stairs",properties:{half:"bottom",shape:"straight",facing:"north"}}}
:enddata
:endrule

rule:
plugin=vanillaBlocks
number=30
data:
JSON:{blockState:{blockName:"minecraft:acacia_stairs",properties:{half:"bottom",shape:"straight",facing:"south"}}}
:enddata
:endrule

rule:
plugin=vanillaBlocks
number=31
data:
JSON:{blockState:{blockName:"minecraft:stone_stairs",properties:{half:"bottom",shape:"straight",facing:"east"}}}
:enddata
:endrule

rule:
plugin=vanillaBlocks
number=32
data:
JSON:{blockState:{blockName:"minecraft:cobblestone_wall",properties:{east:"false",south:"false",north:"false",variant:"cobblestone",west:"false",up:"false"}}}
:enddata
:endrule

#### ENTITIES ####
