# Ancient Warfare Structure Template File
# Auto-generated structure template file. created on: 5/7/2021 at: 0:13:11
# Lines beginning with # denote comments

header:
version=2.11
name=SB_SilkosiaCol_House_1H4R_1
mods=
size=22,17,27
offset=13,1,26
:endheader

#### VALIDATION ####
validation:
type=ground
structureAuthor=TheOddlySeagull
survival=true
worldGenEnabled=false
unique=false
preserveBlocks=false
preventNaturalHostileSpawns=false
selectionWeight=1
clusterValue=1
minDuplicateDistance=1
dimensionWhiteList=true
dimensionList=
biomeGroupList=
biomeWhiteList=true
biomeList=
leveling=0
fill=0
border=0
blockSwap=false
territoryName=
biomeReplacement=minecraft:
minGenerationHeight=0
maxGenerationHeight=255
:endvalidation

#### LAYERS ####
layer: 0
1,2,2,2,2,2,2,1,3,3,1,2,2,2,2,2,2,2,2,2,2,1
4,5,5,5,5,5,5,5,3,3,5,5,5,5,5,5,5,5,5,5,5,4
4,5,5,5,5,5,5,5,3,3,5,5,5,5,5,5,5,5,5,5,5,4
4,5,5,5,5,5,5,5,3,3,5,5,5,5,5,5,5,5,5,5,5,4
4,5,5,5,5,5,5,5,3,3,5,5,5,5,5,5,5,5,5,5,5,4
4,5,5,5,5,5,5,5,3,3,5,5,5,5,5,5,5,5,5,5,5,4
4,5,5,5,5,5,1,2,2,2,2,2,2,2,2,1,5,5,5,5,5,4
4,5,5,5,5,5,4,8,8,8,8,4,8,8,8,4,5,5,5,5,5,4
4,5,5,5,5,5,4,8,8,8,8,4,8,8,8,4,5,5,5,5,5,4
4,5,5,5,5,7,7,7,8,8,8,4,8,8,8,4,5,5,5,5,5,4
4,5,5,5,5,7,7,7,8,8,8,4,8,8,8,4,5,5,5,5,5,4
4,5,5,5,5,7,7,7,8,8,8,4,8,8,8,4,5,5,5,5,5,4
4,5,5,1,2,2,2,2,2,2,2,2,2,2,2,1,2,2,1,5,5,4
4,5,5,4,6,6,6,6,6,4,8,8,8,4,8,8,8,8,4,5,5,4
4,5,5,4,6,6,6,6,6,4,8,8,8,4,2,2,2,2,4,5,5,4
4,5,5,4,6,6,6,6,6,4,2,2,2,4,8,8,4,7,7,7,5,4
4,5,5,4,6,6,6,6,6,4,8,8,8,4,8,8,4,7,7,7,5,4
4,5,5,4,2,2,2,2,2,4,8,8,8,4,8,8,4,7,7,7,5,4
1,5,5,4,6,6,6,6,6,4,2,2,2,2,2,2,2,2,1,5,5,4
3,3,3,4,6,6,6,6,6,4,5,5,5,3,3,5,5,5,5,5,5,4
1,5,5,4,6,6,6,6,6,4,5,5,5,3,3,5,5,5,5,5,5,4
4,5,5,1,2,2,2,2,2,1,5,5,5,3,3,5,5,5,5,5,5,4
4,5,5,5,5,5,5,5,5,5,5,5,5,3,3,5,5,5,5,5,5,4
4,5,5,5,5,5,5,5,5,5,5,5,5,3,3,5,5,5,5,5,5,4
4,5,5,5,5,5,5,5,5,5,5,5,5,3,3,5,5,5,5,5,5,4
4,5,5,5,5,5,5,5,5,5,5,5,5,3,3,5,5,5,5,5,5,4
1,2,2,2,2,2,2,2,2,2,2,2,1,3,3,1,2,2,2,2,2,1
:endlayer
layer: 1
1,9,9,9,9,9,9,1,0,0,1,9,9,9,9,9,9,9,9,9,9,1
9,0,0,0,0,0,0,0,0,0,0,0,0,0,0,0,0,0,0,0,0,9
9,0,0,0,0,0,0,0,0,0,0,0,0,0,0,0,0,0,0,0,0,9
9,0,0,0,0,0,0,0,0,0,0,0,0,0,0,0,0,0,0,0,0,9
9,0,0,0,0,0,0,0,0,0,0,0,0,0,0,0,0,0,0,0,0,9
9,0,0,0,0,0,0,0,0,0,0,0,0,0,0,0,0,0,0,0,0,9
9,0,0,0,0,0,1,7,22,21,7,14,7,14,7,1,0,0,0,0,0,9
9,0,0,0,0,0,7,0,0,0,0,0,0,0,0,7,0,0,0,0,0,9
9,0,0,0,0,0,7,0,0,0,0,0,0,0,0,19,0,0,0,0,0,9
9,0,0,0,0,7,10,0,0,0,0,0,0,0,0,7,0,0,0,0,0,9
9,0,0,0,0,7,17,0,0,0,0,0,0,0,20,19,0,0,0,0,0,9
9,0,0,0,0,7,14,0,0,0,0,0,0,0,18,7,0,0,0,0,0,9
9,0,0,1,7,7,1,15,15,1,0,0,0,0,0,1,7,7,1,0,0,9
9,0,0,7,0,0,0,0,0,0,0,0,0,0,0,0,0,0,7,0,0,9
9,0,0,16,0,0,0,0,0,0,0,0,0,0,0,0,0,0,7,0,0,9
9,0,0,7,0,0,0,0,0,0,0,0,0,0,0,0,0,0,10,7,0,9
9,0,0,7,0,0,0,0,0,1,0,0,0,0,0,0,0,0,17,7,0,9
9,0,0,16,0,0,0,0,0,15,0,0,0,0,0,0,0,0,14,7,0,9
1,0,0,7,0,0,0,0,0,1,7,10,7,13,12,7,10,7,1,0,0,9
0,0,0,11,0,0,0,0,0,7,0,0,0,0,0,0,0,0,0,0,0,9
1,0,0,7,0,0,0,0,0,7,0,0,0,0,0,0,0,0,0,0,0,9
9,0,0,1,7,10,7,10,7,1,0,0,0,0,0,0,0,0,0,0,0,9
9,0,0,0,0,0,0,0,0,0,0,0,0,0,0,0,0,0,0,0,0,9
9,0,0,0,0,0,0,0,0,0,0,0,0,0,0,0,0,0,0,0,0,9
9,0,0,0,0,0,0,0,0,0,0,0,0,0,0,0,0,0,0,0,0,9
9,0,0,0,0,0,0,0,0,0,0,0,0,0,0,0,0,0,0,0,0,9
1,9,9,9,9,9,9,9,9,9,9,9,1,0,0,1,9,9,9,9,9,1
:endlayer
layer: 2
23,0,0,0,0,0,0,23,0,0,23,0,0,0,0,0,0,0,0,0,0,23
0,0,0,0,0,0,0,0,0,0,0,0,0,0,0,0,0,0,0,0,0,0
0,0,0,0,0,0,0,0,0,0,0,0,0,0,0,0,0,0,0,0,0,0
0,0,0,0,0,0,0,0,0,0,0,0,0,0,0,0,0,0,0,0,0,0
0,0,0,0,0,0,0,0,0,0,0,0,0,0,0,0,0,0,0,0,0,0
0,0,0,0,0,0,0,0,0,0,0,0,0,0,0,0,0,0,0,0,0,0
0,0,0,0,0,0,1,7,31,30,7,24,7,24,7,1,0,0,0,0,0,0
0,0,0,0,0,0,7,0,0,0,0,0,0,0,0,7,0,0,0,0,0,0
0,0,0,0,0,0,7,0,0,0,0,0,0,0,0,24,0,0,0,0,0,0
0,0,0,0,0,7,29,0,0,0,0,0,0,0,20,7,0,0,0,0,0,0
0,0,0,0,0,7,0,0,0,0,0,0,0,0,18,24,0,0,0,0,0,0
0,0,0,0,0,7,28,0,0,0,0,0,0,0,0,7,0,0,0,0,0,0
0,0,0,1,7,7,1,15,15,1,0,0,0,0,0,1,7,7,1,0,0,0
0,0,0,7,0,0,0,0,0,0,0,0,0,0,0,0,0,0,7,0,0,0
0,0,0,24,0,0,0,0,0,0,0,0,0,0,0,0,0,0,7,0,0,0
0,0,0,7,0,0,0,0,0,0,0,0,0,0,0,0,0,0,29,7,0,0
0,0,0,7,0,0,0,0,0,1,0,0,0,0,0,0,0,0,0,7,0,0
0,0,0,24,0,0,0,0,0,15,0,0,0,0,0,0,0,0,28,7,0,0
23,0,0,7,0,0,0,0,0,1,7,24,7,27,26,7,24,7,1,0,0,0
0,0,0,25,0,0,0,0,0,7,0,0,0,0,0,0,0,0,0,0,0,0
23,0,0,7,0,0,0,0,0,7,0,0,0,0,0,0,0,0,0,0,0,0
0,0,0,1,7,24,7,24,7,1,0,0,0,0,0,0,0,0,0,0,0,0
0,0,0,0,0,0,0,0,0,0,0,0,0,0,0,0,0,0,0,0,0,0
0,0,0,0,0,0,0,0,0,0,0,0,0,0,0,0,0,0,0,0,0,0
0,0,0,0,0,0,0,0,0,0,0,0,0,0,0,0,0,0,0,0,0,0
0,0,0,0,0,0,0,0,0,0,0,0,0,0,0,0,0,0,0,0,0,0
23,0,0,0,0,0,0,0,0,0,0,0,23,0,0,23,0,0,0,0,0,23
:endlayer
layer: 3
0,0,0,0,0,0,0,0,0,0,0,0,0,0,0,0,0,0,0,0,0,0
0,0,0,0,0,0,0,0,0,0,0,0,0,0,0,0,0,0,0,0,0,0
0,0,0,0,0,0,0,0,0,0,0,0,0,0,0,0,0,0,0,0,0,0
0,0,0,0,0,0,0,0,0,0,0,0,0,0,0,0,0,0,0,0,0,0
0,0,0,0,0,0,0,0,0,0,0,0,0,0,0,0,0,0,0,0,0,0
0,0,0,0,0,0,0,0,0,0,0,0,0,0,0,0,0,0,0,0,0,0
0,0,0,0,0,0,1,7,28,28,7,24,7,24,7,1,0,0,0,0,0,0
0,0,0,0,0,0,7,0,0,0,0,0,0,0,0,7,0,0,0,0,0,0
0,0,0,0,0,0,7,0,0,0,0,0,0,0,20,24,0,0,0,0,0,0
0,0,0,0,0,7,7,0,0,0,0,0,0,0,18,7,0,0,0,0,0,0
0,0,0,0,0,7,34,0,0,0,0,0,0,0,0,24,0,0,0,0,0,0
0,0,0,0,0,7,7,0,0,0,0,0,0,0,0,7,0,0,0,0,0,0
0,0,0,1,7,7,1,15,15,1,0,0,0,0,0,1,7,7,1,0,0,0
0,0,0,7,0,0,0,0,0,33,0,0,0,0,0,0,0,0,7,0,0,0
0,0,0,24,0,0,0,0,0,0,0,0,0,0,0,0,0,0,7,0,0,0
0,0,0,7,0,0,0,0,0,20,0,0,0,0,0,0,0,0,7,7,0,0
0,0,0,7,0,0,0,0,0,1,0,0,0,0,0,0,0,0,32,7,0,0
0,0,0,24,0,0,0,0,0,15,0,0,0,0,0,0,0,0,7,7,0,0
0,0,0,7,0,0,0,0,0,1,7,24,7,29,29,7,24,7,1,0,0,0
0,0,0,32,0,0,0,0,0,7,0,0,0,0,0,0,0,0,0,0,0,0
0,0,0,7,0,0,0,0,0,7,0,0,0,0,0,0,0,0,0,0,0,0
0,0,0,1,7,24,7,24,7,1,0,0,0,0,0,0,0,0,0,0,0,0
0,0,0,0,0,0,0,0,0,0,0,0,0,0,0,0,0,0,0,0,0,0
0,0,0,0,0,0,0,0,0,0,0,0,0,0,0,0,0,0,0,0,0,0
0,0,0,0,0,0,0,0,0,0,0,0,0,0,0,0,0,0,0,0,0,0
0,0,0,0,0,0,0,0,0,0,0,0,0,0,0,0,0,0,0,0,0,0
0,0,0,0,0,0,0,0,0,0,0,0,0,0,0,0,0,0,0,0,0,0
:endlayer
layer: 4
0,0,0,0,0,0,0,0,0,0,0,0,0,0,0,0,0,0,0,0,0,0
0,0,0,0,0,0,0,0,0,0,0,0,0,0,0,0,0,0,0,0,0,0
0,0,0,0,0,0,0,0,0,0,0,0,0,0,0,0,0,0,0,0,0,0
0,0,0,0,0,0,0,0,0,0,0,0,0,0,0,0,0,0,0,0,0,0
0,0,0,0,0,0,39,0,0,39,0,0,39,0,0,39,0,0,0,0,0,0
0,0,0,0,0,0,4,36,36,4,36,36,4,36,36,4,0,0,0,0,0,0
0,0,0,0,0,0,4,2,2,2,2,2,2,2,2,4,0,0,0,0,0,0
0,0,0,0,0,0,4,37,37,37,4,37,37,4,20,4,0,0,0,0,0,0
0,0,0,0,0,0,4,37,37,37,4,37,37,4,18,4,0,0,0,0,0,0
0,0,0,0,0,7,7,37,37,37,4,37,37,4,0,4,0,0,0,0,0,0
0,0,0,0,0,7,7,37,37,37,4,37,37,4,0,4,0,0,39,0,0,0
0,0,0,0,0,7,7,37,37,37,4,37,37,4,0,4,36,36,4,0,0,0
0,0,0,1,2,2,2,2,2,2,2,2,2,2,2,2,2,2,4,0,0,0
0,0,0,4,37,37,4,37,37,4,37,37,37,37,4,37,37,37,4,0,0,0
0,0,0,4,37,37,4,37,37,4,37,37,37,37,4,2,2,2,4,0,0,0
0,0,0,4,37,37,4,37,37,4,37,37,37,37,4,37,37,7,7,7,0,0
0,0,38,4,37,37,4,37,37,4,2,2,2,2,4,37,37,7,7,7,0,0
0,0,37,4,37,37,4,37,37,4,37,37,37,37,4,37,37,7,7,7,0,0
0,0,38,4,2,2,2,2,2,2,2,2,2,2,2,2,2,2,4,0,0,0
0,0,0,4,37,37,37,37,37,4,36,36,4,36,36,4,36,36,4,0,0,0
0,0,0,4,37,37,37,37,37,4,0,0,35,0,0,35,0,0,35,0,0,0
0,0,0,4,2,2,2,2,2,4,0,0,0,0,0,0,0,0,0,0,0,0
0,0,0,4,36,36,4,36,36,4,0,0,0,0,0,0,0,0,0,0,0,0
0,0,0,35,0,0,35,0,0,35,0,0,0,0,0,0,0,0,0,0,0,0
0,0,0,0,0,0,0,0,0,0,0,0,0,0,0,0,0,0,0,0,0,0
0,0,0,0,0,0,0,0,0,0,0,0,0,0,0,0,0,0,0,0,0,0
0,0,0,0,0,0,0,0,0,0,0,0,0,0,0,0,0,0,0,0,0,0
:endlayer
layer: 5
0,0,0,0,0,0,0,0,0,0,0,0,0,0,0,0,0,0,0,0,0,0
0,0,0,0,0,0,0,0,0,0,0,0,0,0,0,0,0,0,0,0,0,0
0,0,0,0,0,0,0,0,0,0,0,0,0,0,0,0,0,0,0,0,0,0
0,0,0,0,0,0,0,0,0,0,0,0,0,0,0,0,0,0,0,0,0,0
0,0,0,0,0,0,0,0,0,0,0,0,0,0,0,0,0,0,0,0,0,0
0,0,0,0,0,0,1,15,15,1,15,15,1,15,15,1,0,0,0,0,0,0
0,0,0,0,0,0,15,0,0,0,0,0,0,0,0,15,0,0,0,0,0,0
0,0,0,0,0,0,15,0,0,0,0,0,0,0,0,15,0,0,0,0,0,0
0,0,0,0,0,0,1,0,0,0,0,0,0,0,0,1,0,0,0,0,0,0
0,0,0,0,0,7,7,0,0,0,0,0,0,9,0,15,0,0,0,0,0,0
0,0,0,0,0,7,17,0,0,0,0,0,0,9,0,15,0,0,0,0,0,0
0,0,0,0,0,7,7,0,0,0,0,0,0,9,0,1,15,15,1,0,0,0
0,0,0,1,15,15,1,15,15,1,15,1,0,9,9,9,0,0,15,0,0,0
0,0,0,15,0,0,0,0,0,0,0,0,0,0,0,0,0,0,15,0,0,0
0,0,0,15,0,0,0,0,0,0,0,0,0,0,0,0,0,0,1,0,0,0
0,0,0,1,0,0,0,0,0,0,0,0,0,0,0,0,0,0,10,7,0,0
0,0,9,15,0,0,0,0,0,1,0,0,0,0,0,0,0,0,17,7,0,0
0,0,9,40,0,0,0,0,0,15,0,0,0,0,0,0,0,0,14,7,0,0
0,0,9,15,0,0,0,0,0,15,0,0,0,0,0,0,0,0,15,0,0,0
0,0,0,1,0,0,0,0,20,1,15,15,1,15,15,1,15,15,1,0,0,0
0,0,0,15,0,0,0,0,18,15,0,0,0,0,0,0,0,0,0,0,0,0
0,0,0,15,0,0,0,0,0,15,0,0,0,0,0,0,0,0,0,0,0,0
0,0,0,1,15,15,1,15,15,1,0,0,0,0,0,0,0,0,0,0,0,0
0,0,0,0,0,0,0,0,0,0,0,0,0,0,0,0,0,0,0,0,0,0
0,0,0,0,0,0,0,0,0,0,0,0,0,0,0,0,0,0,0,0,0,0
0,0,0,0,0,0,0,0,0,0,0,0,0,0,0,0,0,0,0,0,0,0
0,0,0,0,0,0,0,0,0,0,0,0,0,0,0,0,0,0,0,0,0,0
:endlayer
layer: 6
0,0,0,0,0,0,0,0,0,0,0,0,0,0,0,0,0,0,0,0,0,0
0,0,0,0,0,0,0,0,0,0,0,0,0,0,0,0,0,0,0,0,0,0
0,0,0,0,0,0,0,0,0,0,0,0,0,0,0,0,0,0,0,0,0,0
0,0,0,0,0,0,0,0,0,0,0,0,0,0,0,0,0,0,0,0,0,0
0,0,0,0,0,0,0,0,0,0,0,0,0,0,0,0,0,0,0,0,0,0
0,0,0,0,0,0,1,24,24,1,24,24,1,24,24,1,0,0,0,0,0,0
0,0,0,0,0,0,15,0,0,0,0,0,0,0,0,24,0,0,0,0,0,0
0,0,0,0,0,0,15,0,0,0,0,0,0,0,0,24,0,0,0,0,0,0
0,0,0,0,0,0,1,0,0,0,0,0,0,0,0,1,0,0,0,0,0,0
0,0,0,0,0,14,7,0,0,0,0,0,0,0,0,24,0,0,0,0,0,0
0,0,0,0,0,7,0,0,0,0,0,0,0,0,0,24,0,0,0,0,0,0
0,0,0,0,0,10,7,0,0,0,0,0,0,0,0,1,24,24,1,0,0,0
0,0,0,1,15,15,1,15,15,1,15,1,0,0,0,0,0,0,24,0,0,0
0,0,0,24,0,0,0,0,0,0,0,0,0,0,0,0,0,0,24,0,0,0
0,0,0,24,0,0,0,0,0,0,0,0,0,0,0,0,0,0,1,0,0,0
0,0,0,1,0,0,0,0,0,0,0,0,0,0,0,0,0,0,29,7,0,0
0,0,0,15,0,0,0,0,0,1,0,0,0,0,0,0,0,0,0,7,0,0
0,0,0,41,0,0,0,0,0,15,0,0,0,0,0,0,0,0,28,7,0,0
0,0,0,15,0,0,0,0,20,15,0,0,0,0,0,0,0,0,15,0,0,0
0,0,0,1,0,0,0,0,18,1,24,24,1,24,24,1,24,24,1,0,0,0
0,0,0,15,0,0,0,0,0,15,0,0,0,0,0,0,0,0,0,0,0,0
0,0,0,15,0,0,0,0,0,15,0,0,0,0,0,0,0,0,0,0,0,0
0,0,0,1,24,24,1,24,24,1,0,0,0,0,0,0,0,0,0,0,0,0
0,0,0,0,0,0,0,0,0,0,0,0,0,0,0,0,0,0,0,0,0,0
0,0,0,0,0,0,0,0,0,0,0,0,0,0,0,0,0,0,0,0,0,0
0,0,0,0,0,0,0,0,0,0,0,0,0,0,0,0,0,0,0,0,0,0
0,0,0,0,0,0,0,0,0,0,0,0,0,0,0,0,0,0,0,0,0,0
:endlayer
layer: 7
0,0,0,0,0,0,0,0,0,0,0,0,0,0,0,0,0,0,0,0,0,0
0,0,0,0,0,0,0,0,0,0,0,0,0,0,0,0,0,0,0,0,0,0
0,0,0,0,0,0,0,0,0,0,0,0,0,0,0,0,0,0,0,0,0,0
0,0,0,0,0,0,0,0,0,0,0,0,0,0,0,0,0,0,0,0,0,0
0,0,0,0,0,0,9,0,0,0,0,0,0,0,0,9,0,0,0,0,0,0
0,0,0,0,0,9,1,24,24,1,24,24,1,24,24,1,9,0,0,0,0,0
0,0,0,0,0,0,15,0,0,0,0,0,0,0,0,24,0,0,0,0,0,0
0,0,0,0,0,0,15,0,0,0,0,0,0,0,0,24,0,0,0,0,0,0
0,0,0,0,0,9,1,0,0,0,0,0,0,0,0,1,9,0,0,0,0,0
0,0,0,0,0,0,7,0,0,0,0,0,0,0,0,24,0,0,0,0,0,0
0,0,0,0,0,7,34,0,0,0,0,0,0,0,0,24,0,0,9,0,0,0
0,0,0,0,0,0,7,0,0,0,0,0,0,0,0,1,24,24,1,9,0,0
0,0,0,1,15,15,1,15,15,1,15,1,42,0,0,0,0,0,24,0,0,0
0,0,0,24,0,0,0,0,0,33,0,0,0,0,0,0,0,0,24,0,0,0
0,0,0,24,0,0,0,0,0,0,0,0,0,0,0,0,0,0,1,0,0,0
0,0,0,1,0,0,0,0,0,20,0,0,0,0,0,0,0,0,7,14,0,0
0,0,0,15,0,0,0,0,0,1,0,0,0,0,0,0,0,0,32,7,0,0
0,0,0,15,0,0,0,0,20,15,0,0,0,0,0,0,0,0,7,10,0,0
0,0,0,15,0,0,0,0,18,15,0,0,0,0,0,0,0,0,15,0,0,0
0,0,9,1,0,0,0,0,0,1,24,24,1,24,24,1,24,24,1,9,0,0
0,0,0,15,0,0,0,0,0,15,0,0,9,0,0,9,0,0,9,0,0,0
0,0,0,15,0,0,0,0,0,15,0,0,0,0,0,0,0,0,0,0,0,0
0,0,9,1,24,24,1,24,24,1,9,0,0,0,0,0,0,0,0,0,0,0
0,0,0,9,0,0,0,0,0,9,0,0,0,0,0,0,0,0,0,0,0,0
0,0,0,0,0,0,0,0,0,0,0,0,0,0,0,0,0,0,0,0,0,0
0,0,0,0,0,0,0,0,0,0,0,0,0,0,0,0,0,0,0,0,0,0
0,0,0,0,0,0,0,0,0,0,0,0,0,0,0,0,0,0,0,0,0,0
:endlayer
layer: 8
0,0,0,0,0,0,0,0,0,0,0,0,0,0,0,0,0,0,0,0,0,0
0,0,0,0,0,0,0,0,0,0,0,0,0,0,0,0,0,0,0,0,0,0
0,0,0,0,0,0,0,0,0,0,0,0,0,0,0,0,0,0,0,0,0,0
0,0,0,0,0,0,0,0,0,0,0,0,0,0,0,0,0,0,0,0,0,0
0,0,0,0,0,44,42,0,0,0,0,0,0,0,0,38,43,0,0,0,0,0
0,0,0,0,0,44,1,2,2,2,2,2,2,2,2,1,43,0,0,0,0,0
0,0,0,0,0,44,4,37,37,4,37,37,37,37,37,4,43,0,0,0,0,0
0,0,0,0,0,44,4,37,37,4,37,37,37,37,37,4,43,0,0,0,0,0
0,0,0,0,0,44,4,37,37,4,2,2,2,2,2,4,43,0,0,0,0,0
0,0,0,0,0,44,4,37,37,4,37,37,37,37,37,4,43,0,0,0,0,0
0,0,0,0,0,7,4,37,37,4,37,37,37,37,37,4,43,45,45,45,0,0
0,0,0,9,0,33,4,37,37,4,37,37,37,37,37,4,2,2,1,33,0,0
0,0,9,1,2,2,4,2,2,4,2,2,2,2,2,2,2,2,4,0,0,0
0,0,0,4,37,37,4,37,37,4,37,37,37,37,4,37,37,37,4,0,0,0
0,0,0,4,37,37,4,37,37,4,37,37,37,37,4,37,37,37,4,0,0,0
0,0,0,4,37,37,4,37,37,4,37,37,37,37,4,2,2,2,4,0,0,0
0,0,0,4,2,2,2,2,2,4,2,2,2,2,4,37,37,37,4,7,0,0
0,0,0,4,33,37,37,33,18,4,37,37,37,37,4,37,37,37,4,0,0,0
0,0,0,4,0,0,0,0,0,4,37,37,37,37,4,37,37,37,4,0,0,0
0,0,20,4,0,0,0,0,0,4,2,2,2,2,2,2,2,2,1,20,0,0
0,0,18,4,0,0,0,0,0,4,18,18,18,18,18,18,18,18,18,18,0,0
0,0,44,4,0,0,0,0,0,4,43,0,0,0,0,0,0,0,0,0,0,0
0,0,44,1,2,2,2,2,2,1,43,0,0,0,0,0,0,0,0,0,0,0
0,0,44,42,0,0,0,0,0,38,43,0,0,0,0,0,0,0,0,0,0,0
0,0,0,0,0,0,0,0,0,0,0,0,0,0,0,0,0,0,0,0,0,0
0,0,0,0,0,0,0,0,0,0,0,0,0,0,0,0,0,0,0,0,0,0
0,0,0,0,0,0,0,0,0,0,0,0,0,0,0,0,0,0,0,0,0,0
:endlayer
layer: 9
0,0,0,0,0,0,0,0,0,0,0,0,0,0,0,0,0,0,0,0,0,0
0,0,0,0,0,0,0,0,0,0,0,0,0,0,0,0,0,0,0,0,0,0
0,0,0,0,0,0,0,0,0,0,0,0,0,0,0,0,0,0,0,0,0,0
0,0,0,0,0,0,0,0,0,0,0,0,0,0,0,0,0,0,0,0,0,0
0,0,0,0,0,0,44,42,0,0,0,0,0,0,38,43,0,0,0,0,0,0
0,0,0,0,0,0,44,1,15,1,15,15,1,15,1,43,0,0,0,0,0,0
0,0,0,0,0,0,44,47,0,0,0,0,0,0,46,43,0,0,0,0,0,0
0,0,0,0,0,0,44,47,0,0,0,0,0,0,46,43,0,0,0,0,0,0
0,0,0,0,0,0,44,47,0,0,0,0,0,0,46,43,0,0,0,0,0,0
0,0,0,0,0,0,44,47,0,0,0,0,0,0,46,43,0,0,0,0,0,0
0,0,0,0,0,7,44,47,0,0,0,0,0,0,46,43,0,0,0,0,0,0
0,0,45,45,45,45,44,47,0,0,0,0,0,0,46,45,45,45,45,45,0,0
0,0,33,1,49,49,49,49,0,0,0,0,0,0,49,49,49,49,1,33,0,0
0,0,0,15,0,0,0,0,0,0,0,0,0,0,0,0,0,0,15,0,0,0
0,0,0,15,0,0,0,0,0,0,0,0,0,0,0,0,0,0,15,0,0,0
0,0,0,15,0,0,0,0,0,0,0,0,0,0,0,0,0,0,15,0,0,0
0,0,0,15,0,0,0,0,0,0,0,0,0,0,0,0,0,0,15,7,0,0
0,0,0,15,9,9,9,9,0,1,0,0,0,0,0,0,0,0,15,0,0,0
0,0,20,1,48,0,0,0,0,15,48,48,48,48,48,48,48,48,1,20,0,0
0,0,18,18,47,0,0,0,0,15,18,18,18,18,18,18,18,18,18,18,0,0
0,0,0,44,47,0,0,0,48,1,20,0,0,0,0,0,0,0,0,0,0,0
0,0,0,44,47,0,0,0,46,43,18,0,0,0,0,0,0,0,0,0,0,0
0,0,0,44,1,15,15,15,1,43,0,0,0,0,0,0,0,0,0,0,0,0
0,0,0,44,42,0,0,0,38,43,0,0,0,0,0,0,0,0,0,0,0,0
0,0,0,0,0,0,0,0,0,0,0,0,0,0,0,0,0,0,0,0,0,0
0,0,0,0,0,0,0,0,0,0,0,0,0,0,0,0,0,0,0,0,0,0
0,0,0,0,0,0,0,0,0,0,0,0,0,0,0,0,0,0,0,0,0,0
:endlayer
layer: 10
0,0,0,0,0,0,0,0,0,0,0,0,0,0,0,0,0,0,0,0,0,0
0,0,0,0,0,0,0,0,0,0,0,0,0,0,0,0,0,0,0,0,0,0
0,0,0,0,0,0,0,0,0,0,0,0,0,0,0,0,0,0,0,0,0,0
0,0,0,0,0,0,0,0,0,0,0,0,0,0,0,0,0,0,0,0,0,0
0,0,0,0,0,0,0,44,42,0,0,0,0,38,43,0,0,0,0,0,0,0
0,0,0,0,0,0,0,44,1,1,24,24,1,1,43,0,0,0,0,0,0,0
0,0,0,0,0,0,0,44,47,0,0,0,0,46,43,0,0,0,0,0,0,0
0,0,0,0,0,0,0,44,47,0,0,0,0,46,43,0,0,0,0,0,0,0
0,0,0,0,0,0,0,44,47,0,0,0,0,46,43,0,0,0,0,0,0,0
0,0,0,0,0,0,0,44,47,0,0,0,0,46,43,0,0,0,0,0,0,0
0,0,0,0,0,7,0,44,47,0,0,0,0,46,43,0,0,0,0,0,0,0
0,0,0,0,0,0,0,44,47,0,0,0,0,46,43,0,0,0,0,0,0,0
0,0,45,45,45,45,45,44,47,0,0,0,0,46,45,45,45,45,45,45,0,0
0,0,33,1,49,49,49,49,47,0,0,0,0,49,49,49,49,49,1,33,0,0
0,0,0,15,0,0,0,0,0,0,0,0,0,0,0,0,0,0,15,0,0,0
0,0,0,15,0,0,0,0,0,0,0,0,0,0,0,0,0,0,15,0,0,0
0,0,0,15,0,0,0,0,0,0,0,0,0,0,0,0,0,0,15,7,0,0
0,0,20,1,48,47,0,0,0,1,48,48,48,48,48,48,48,48,1,20,0,0
0,0,18,18,44,47,0,0,0,15,18,18,18,18,18,18,18,18,18,18,0,0
0,0,0,0,44,47,0,48,48,1,20,0,0,0,0,0,0,0,0,0,0,0
0,0,0,0,44,47,0,46,43,18,18,0,0,0,0,0,0,0,0,0,0,0
0,0,0,0,44,47,0,46,43,0,0,0,0,0,0,0,0,0,0,0,0,0
0,0,0,0,44,1,15,1,43,0,0,0,0,0,0,0,0,0,0,0,0,0
0,0,0,0,44,42,0,38,43,0,0,0,0,0,0,0,0,0,0,0,0,0
0,0,0,0,0,0,0,0,0,0,0,0,0,0,0,0,0,0,0,0,0,0
0,0,0,0,0,0,0,0,0,0,0,0,0,0,0,0,0,0,0,0,0,0
0,0,0,0,0,0,0,0,0,0,0,0,0,0,0,0,0,0,0,0,0,0
:endlayer
layer: 11
0,0,0,0,0,0,0,0,0,0,0,0,0,0,0,0,0,0,0,0,0,0
0,0,0,0,0,0,0,0,0,0,0,0,0,0,0,0,0,0,0,0,0,0
0,0,0,0,0,0,0,0,0,0,0,0,0,0,0,0,0,0,0,0,0,0
0,0,0,0,0,0,0,0,0,0,0,0,0,0,0,0,0,0,0,0,0,0
0,0,0,0,0,0,0,0,44,42,0,0,38,43,0,0,0,0,0,0,0,0
0,0,0,0,0,0,0,0,44,1,24,24,1,43,0,0,0,0,0,0,0,0
0,0,0,0,0,0,0,0,44,47,0,0,46,43,0,0,0,0,0,0,0,0
0,0,0,0,0,0,0,0,44,47,0,0,46,43,0,0,0,0,0,0,0,0
0,0,0,0,0,0,0,0,44,47,0,0,46,43,0,0,0,0,0,0,0,0
0,0,0,0,0,0,0,0,44,47,0,0,46,43,0,0,0,0,0,0,0,0
0,0,0,0,0,7,0,0,44,47,0,0,46,43,0,0,0,0,0,0,0,0
0,0,0,0,0,0,0,0,44,47,0,0,46,43,0,0,0,0,0,0,0,0
0,0,0,0,0,0,0,0,44,47,0,0,46,43,0,0,0,0,0,0,0,0
0,0,45,45,45,45,45,45,45,47,0,0,46,45,45,45,45,45,45,45,0,0
0,0,33,1,49,49,49,49,49,47,0,0,49,49,49,49,49,49,1,33,0,0
0,0,0,15,0,0,0,0,0,0,0,0,0,0,0,0,0,0,15,0,0,0
0,0,20,1,48,48,20,0,0,20,48,48,48,48,48,48,48,48,1,7,0,0
0,0,18,18,18,44,4,0,0,4,18,18,18,18,18,18,18,18,18,18,0,0
0,0,0,0,0,44,4,48,48,1,20,0,0,0,0,0,0,0,0,0,0,0
0,0,0,0,0,44,4,43,18,18,18,0,0,0,0,0,0,0,0,0,0,0
0,0,0,0,0,44,4,43,0,0,0,0,0,0,0,0,0,0,0,0,0,0
0,0,0,0,0,44,4,43,0,0,0,0,0,0,0,0,0,0,0,0,0,0
0,0,0,0,0,44,1,43,0,0,0,0,0,0,0,0,0,0,0,0,0,0
0,0,0,0,0,44,18,43,0,0,0,0,0,0,0,0,0,0,0,0,0,0
0,0,0,0,0,0,0,0,0,0,0,0,0,0,0,0,0,0,0,0,0,0
0,0,0,0,0,0,0,0,0,0,0,0,0,0,0,0,0,0,0,0,0,0
0,0,0,0,0,0,0,0,0,0,0,0,0,0,0,0,0,0,0,0,0,0
:endlayer
layer: 12
0,0,0,0,0,0,0,0,0,0,0,0,0,0,0,0,0,0,0,0,0,0
0,0,0,0,0,0,0,0,0,0,0,0,0,0,0,0,0,0,0,0,0,0
0,0,0,0,0,0,0,0,0,0,0,0,0,0,0,0,0,0,0,0,0,0
0,0,0,0,0,0,0,0,0,0,0,0,0,0,0,0,0,0,0,0,0,0
0,0,0,0,0,0,0,0,0,44,45,45,43,0,0,0,0,0,0,0,0,0
0,0,0,0,0,0,0,0,0,44,2,2,43,0,0,0,0,0,0,0,0,0
0,0,0,0,0,0,0,0,0,44,47,46,43,0,0,0,0,0,0,0,0,0
0,0,0,0,0,0,0,0,0,44,47,46,43,0,0,0,0,0,0,0,0,0
0,0,0,0,0,0,0,0,0,44,47,46,43,0,0,0,0,0,0,0,0,0
0,0,0,0,0,0,0,0,0,44,47,46,43,0,0,0,0,0,0,0,0,0
0,0,0,0,0,50,0,0,0,44,47,46,43,0,0,0,0,0,0,0,0,0
0,0,0,0,0,0,0,0,0,44,47,46,43,0,0,0,0,0,0,0,0,0
0,0,0,0,0,0,0,0,0,44,47,46,43,0,0,0,0,0,0,0,0,0
0,0,0,0,0,0,0,0,0,44,47,46,43,0,0,0,0,0,0,0,0,0
0,0,45,45,45,45,45,45,45,45,47,46,43,45,45,45,45,45,45,45,0,0
0,0,44,1,2,2,2,2,2,2,2,2,2,2,2,2,2,2,1,43,0,0
0,0,18,18,18,18,44,15,15,15,18,18,18,18,18,18,18,18,18,7,0,0
0,0,0,0,0,0,44,15,15,15,43,0,0,0,0,0,0,0,0,0,0,0
0,0,0,0,0,0,44,18,18,18,18,0,0,0,0,0,0,0,0,0,0,0
0,0,0,0,0,0,23,0,0,0,0,0,0,0,0,0,0,0,0,0,0,0
0,0,0,0,0,0,23,0,0,0,0,0,0,0,0,0,0,0,0,0,0,0
0,0,0,0,0,0,23,0,0,0,0,0,0,0,0,0,0,0,0,0,0,0
0,0,0,0,0,0,23,0,0,0,0,0,0,0,0,0,0,0,0,0,0,0
0,0,0,0,0,0,0,0,0,0,0,0,0,0,0,0,0,0,0,0,0,0
0,0,0,0,0,0,0,0,0,0,0,0,0,0,0,0,0,0,0,0,0,0
0,0,0,0,0,0,0,0,0,0,0,0,0,0,0,0,0,0,0,0,0,0
0,0,0,0,0,0,0,0,0,0,0,0,0,0,0,0,0,0,0,0,0,0
:endlayer
layer: 13
0,0,0,0,0,0,0,0,0,0,0,0,0,0,0,0,0,0,0,0,0,0
0,0,0,0,0,0,0,0,0,0,0,0,0,0,0,0,0,0,0,0,0,0
0,0,0,0,0,0,0,0,0,0,0,0,0,0,0,0,0,0,0,0,0,0
0,0,0,0,0,0,0,0,0,0,0,0,0,0,0,0,0,0,0,0,0,0
0,0,0,0,0,0,0,0,0,0,0,0,0,0,0,0,0,0,0,0,0,0
0,0,0,0,0,0,0,0,0,0,45,45,0,0,0,0,0,0,0,0,0,0
0,0,0,0,0,0,0,0,0,0,44,43,0,0,0,0,0,0,0,0,0,0
0,0,0,0,0,0,0,0,0,0,44,43,0,0,0,0,0,0,0,0,0,0
0,0,0,0,0,0,0,0,0,0,44,43,0,0,0,0,0,0,0,0,0,0
0,0,0,0,0,0,0,0,0,0,44,43,0,0,0,0,0,0,0,0,0,0
0,0,0,0,0,23,0,0,0,0,44,43,0,0,0,0,0,0,0,0,0,0
0,0,0,0,0,0,0,0,0,0,44,43,0,0,0,0,0,0,0,0,0,0
0,0,0,0,0,0,0,0,0,0,44,43,0,0,0,0,0,0,0,0,0,0
0,0,0,0,0,0,0,0,0,0,44,43,0,0,0,0,0,0,0,0,0,0
0,0,0,0,0,0,0,0,0,0,44,43,0,0,0,0,0,0,0,0,0,0
0,0,0,23,23,23,23,44,45,45,18,43,23,23,23,23,23,23,23,0,0,0
0,0,0,0,0,0,0,44,15,43,0,0,0,0,0,0,0,0,0,7,0,0
0,0,0,0,0,0,0,18,18,43,0,0,0,0,0,0,0,0,0,0,0,0
0,0,0,0,0,0,0,0,0,0,0,0,0,0,0,0,0,0,0,0,0,0
0,0,0,0,0,0,0,0,0,0,0,0,0,0,0,0,0,0,0,0,0,0
0,0,0,0,0,0,0,0,0,0,0,0,0,0,0,0,0,0,0,0,0,0
0,0,0,0,0,0,0,0,0,0,0,0,0,0,0,0,0,0,0,0,0,0
0,0,0,0,0,0,0,0,0,0,0,0,0,0,0,0,0,0,0,0,0,0
0,0,0,0,0,0,0,0,0,0,0,0,0,0,0,0,0,0,0,0,0,0
0,0,0,0,0,0,0,0,0,0,0,0,0,0,0,0,0,0,0,0,0,0
0,0,0,0,0,0,0,0,0,0,0,0,0,0,0,0,0,0,0,0,0,0
0,0,0,0,0,0,0,0,0,0,0,0,0,0,0,0,0,0,0,0,0,0
:endlayer
layer: 14
0,0,0,0,0,0,0,0,0,0,0,0,0,0,0,0,0,0,0,0,0,0
0,0,0,0,0,0,0,0,0,0,0,0,0,0,0,0,0,0,0,0,0,0
0,0,0,0,0,0,0,0,0,0,0,0,0,0,0,0,0,0,0,0,0,0
0,0,0,0,0,0,0,0,0,0,0,0,0,0,0,0,0,0,0,0,0,0
0,0,0,0,0,0,0,0,0,0,0,0,0,0,0,0,0,0,0,0,0,0
0,0,0,0,0,0,0,0,0,0,0,0,0,0,0,0,0,0,0,0,0,0
0,0,0,0,0,0,0,0,0,0,0,0,0,0,0,0,0,0,0,0,0,0
0,0,0,0,0,0,0,0,0,0,0,0,0,0,0,0,0,0,0,0,0,0
0,0,0,0,0,0,0,0,0,0,0,0,0,0,0,0,0,0,0,0,0,0
0,0,0,0,0,0,0,0,0,0,0,0,0,0,0,0,0,0,0,0,0,0
0,0,0,0,0,0,0,0,0,0,0,0,0,0,0,0,0,0,0,0,0,0
0,0,0,0,0,0,0,0,0,0,0,0,0,0,0,0,0,0,0,0,0,0
0,0,0,0,0,0,0,0,0,0,0,0,0,0,0,0,0,0,0,0,0,0
0,0,0,0,0,0,0,0,0,0,0,0,0,0,0,0,0,0,0,0,0,0
0,0,0,0,0,0,0,0,0,0,0,0,0,0,0,0,0,0,0,0,0,0
0,0,0,0,0,0,0,0,0,0,0,0,0,0,0,0,0,0,0,0,0,0
0,0,0,0,0,0,0,0,23,0,0,0,0,0,0,0,0,0,0,7,0,0
0,0,0,0,0,0,0,0,0,0,0,0,0,0,0,0,0,0,0,0,0,0
0,0,0,0,0,0,0,0,0,0,0,0,0,0,0,0,0,0,0,0,0,0
0,0,0,0,0,0,0,0,0,0,0,0,0,0,0,0,0,0,0,0,0,0
0,0,0,0,0,0,0,0,0,0,0,0,0,0,0,0,0,0,0,0,0,0
0,0,0,0,0,0,0,0,0,0,0,0,0,0,0,0,0,0,0,0,0,0
0,0,0,0,0,0,0,0,0,0,0,0,0,0,0,0,0,0,0,0,0,0
0,0,0,0,0,0,0,0,0,0,0,0,0,0,0,0,0,0,0,0,0,0
0,0,0,0,0,0,0,0,0,0,0,0,0,0,0,0,0,0,0,0,0,0
0,0,0,0,0,0,0,0,0,0,0,0,0,0,0,0,0,0,0,0,0,0
0,0,0,0,0,0,0,0,0,0,0,0,0,0,0,0,0,0,0,0,0,0
:endlayer
layer: 15
0,0,0,0,0,0,0,0,0,0,0,0,0,0,0,0,0,0,0,0,0,0
0,0,0,0,0,0,0,0,0,0,0,0,0,0,0,0,0,0,0,0,0,0
0,0,0,0,0,0,0,0,0,0,0,0,0,0,0,0,0,0,0,0,0,0
0,0,0,0,0,0,0,0,0,0,0,0,0,0,0,0,0,0,0,0,0,0
0,0,0,0,0,0,0,0,0,0,0,0,0,0,0,0,0,0,0,0,0,0
0,0,0,0,0,0,0,0,0,0,0,0,0,0,0,0,0,0,0,0,0,0
0,0,0,0,0,0,0,0,0,0,0,0,0,0,0,0,0,0,0,0,0,0
0,0,0,0,0,0,0,0,0,0,0,0,0,0,0,0,0,0,0,0,0,0
0,0,0,0,0,0,0,0,0,0,0,0,0,0,0,0,0,0,0,0,0,0
0,0,0,0,0,0,0,0,0,0,0,0,0,0,0,0,0,0,0,0,0,0
0,0,0,0,0,0,0,0,0,0,0,0,0,0,0,0,0,0,0,0,0,0
0,0,0,0,0,0,0,0,0,0,0,0,0,0,0,0,0,0,0,0,0,0
0,0,0,0,0,0,0,0,0,0,0,0,0,0,0,0,0,0,0,0,0,0
0,0,0,0,0,0,0,0,0,0,0,0,0,0,0,0,0,0,0,0,0,0
0,0,0,0,0,0,0,0,0,0,0,0,0,0,0,0,0,0,0,0,0,0
0,0,0,0,0,0,0,0,0,0,0,0,0,0,0,0,0,0,0,0,0,0
0,0,0,0,0,0,0,0,0,0,0,0,0,0,0,0,0,0,0,50,0,0
0,0,0,0,0,0,0,0,0,0,0,0,0,0,0,0,0,0,0,0,0,0
0,0,0,0,0,0,0,0,0,0,0,0,0,0,0,0,0,0,0,0,0,0
0,0,0,0,0,0,0,0,0,0,0,0,0,0,0,0,0,0,0,0,0,0
0,0,0,0,0,0,0,0,0,0,0,0,0,0,0,0,0,0,0,0,0,0
0,0,0,0,0,0,0,0,0,0,0,0,0,0,0,0,0,0,0,0,0,0
0,0,0,0,0,0,0,0,0,0,0,0,0,0,0,0,0,0,0,0,0,0
0,0,0,0,0,0,0,0,0,0,0,0,0,0,0,0,0,0,0,0,0,0
0,0,0,0,0,0,0,0,0,0,0,0,0,0,0,0,0,0,0,0,0,0
0,0,0,0,0,0,0,0,0,0,0,0,0,0,0,0,0,0,0,0,0,0
0,0,0,0,0,0,0,0,0,0,0,0,0,0,0,0,0,0,0,0,0,0
:endlayer
layer: 16
0,0,0,0,0,0,0,0,0,0,0,0,0,0,0,0,0,0,0,0,0,0
0,0,0,0,0,0,0,0,0,0,0,0,0,0,0,0,0,0,0,0,0,0
0,0,0,0,0,0,0,0,0,0,0,0,0,0,0,0,0,0,0,0,0,0
0,0,0,0,0,0,0,0,0,0,0,0,0,0,0,0,0,0,0,0,0,0
0,0,0,0,0,0,0,0,0,0,0,0,0,0,0,0,0,0,0,0,0,0
0,0,0,0,0,0,0,0,0,0,0,0,0,0,0,0,0,0,0,0,0,0
0,0,0,0,0,0,0,0,0,0,0,0,0,0,0,0,0,0,0,0,0,0
0,0,0,0,0,0,0,0,0,0,0,0,0,0,0,0,0,0,0,0,0,0
0,0,0,0,0,0,0,0,0,0,0,0,0,0,0,0,0,0,0,0,0,0
0,0,0,0,0,0,0,0,0,0,0,0,0,0,0,0,0,0,0,0,0,0
0,0,0,0,0,0,0,0,0,0,0,0,0,0,0,0,0,0,0,0,0,0
0,0,0,0,0,0,0,0,0,0,0,0,0,0,0,0,0,0,0,0,0,0
0,0,0,0,0,0,0,0,0,0,0,0,0,0,0,0,0,0,0,0,0,0
0,0,0,0,0,0,0,0,0,0,0,0,0,0,0,0,0,0,0,0,0,0
0,0,0,0,0,0,0,0,0,0,0,0,0,0,0,0,0,0,0,0,0,0
0,0,0,0,0,0,0,0,0,0,0,0,0,0,0,0,0,0,0,0,0,0
0,0,0,0,0,0,0,0,0,0,0,0,0,0,0,0,0,0,0,23,0,0
0,0,0,0,0,0,0,0,0,0,0,0,0,0,0,0,0,0,0,0,0,0
0,0,0,0,0,0,0,0,0,0,0,0,0,0,0,0,0,0,0,0,0,0
0,0,0,0,0,0,0,0,0,0,0,0,0,0,0,0,0,0,0,0,0,0
0,0,0,0,0,0,0,0,0,0,0,0,0,0,0,0,0,0,0,0,0,0
0,0,0,0,0,0,0,0,0,0,0,0,0,0,0,0,0,0,0,0,0,0
0,0,0,0,0,0,0,0,0,0,0,0,0,0,0,0,0,0,0,0,0,0
0,0,0,0,0,0,0,0,0,0,0,0,0,0,0,0,0,0,0,0,0,0
0,0,0,0,0,0,0,0,0,0,0,0,0,0,0,0,0,0,0,0,0,0
0,0,0,0,0,0,0,0,0,0,0,0,0,0,0,0,0,0,0,0,0,0
0,0,0,0,0,0,0,0,0,0,0,0,0,0,0,0,0,0,0,0,0,0
:endlayer

#### RULES ####
rule:
plugin=vanillaBlocks
number=1
data:
JSON:{blockState:{blockName:"minecraft:log",properties:{variant:"oak",axis:"y"}}}
:enddata
:endrule

rule:
plugin=vanillaBlocks
number=2
data:
JSON:{blockState:{blockName:"minecraft:log",properties:{variant:"oak",axis:"x"}}}
:enddata
:endrule

rule:
plugin=vanillaBlocks
number=3
data:
JSON:{blockState:{blockName:"minecraft:cobblestone"}}
:enddata
:endrule

rule:
plugin=vanillaBlocks
number=4
data:
JSON:{blockState:{blockName:"minecraft:log",properties:{variant:"oak",axis:"z"}}}
:enddata
:endrule

rule:
plugin=vanillaBlocks
number=5
data:
JSON:{blockState:{blockName:"minecraft:grass",properties:{snowy:"false"}}}
:enddata
:endrule

rule:
plugin=vanillaBlocks
number=6
data:
JSON:{blockState:{blockName:"minecraft:stone",properties:{variant:"smooth_andesite"}}}
:enddata
:endrule

rule:
plugin=vanillaBlocks
number=7
data:
JSON:{blockState:{blockName:"minecraft:stonebrick",properties:{variant:"stonebrick"}}}
:enddata
:endrule

rule:
plugin=vanillaBlocks
number=8
data:
JSON:{blockState:{blockName:"minecraft:planks",properties:{variant:"spruce"}}}
:enddata
:endrule

rule:
plugin=vanillaBlocks
number=9
data:
JSON:{blockState:{blockName:"minecraft:spruce_fence",properties:{east:"false",south:"false",north:"false",west:"false"}}}
:enddata
:endrule

rule:
plugin=vanillaBlocks
number=10
data:
JSON:{blockState:{blockName:"minecraft:stone_brick_stairs",properties:{half:"bottom",shape:"straight",facing:"north"}}}
:enddata
:endrule

rule:
plugin=doors
number=11
data:
JSON:{blockState:{blockName:"minecraft:spruce_door",properties:{hinge:"right",half:"lower",powered:"false",facing:"west",open:"false"}}}
:enddata
:endrule

rule:
plugin=doors
number=12
data:
JSON:{blockState:{blockName:"minecraft:spruce_door",properties:{hinge:"left",half:"lower",powered:"false",facing:"south",open:"false"}}}
:enddata
:endrule

rule:
plugin=doors
number=13
data:
JSON:{blockState:{blockName:"minecraft:spruce_door",properties:{hinge:"right",half:"lower",powered:"false",facing:"south",open:"false"}}}
:enddata
:endrule

rule:
plugin=vanillaBlocks
number=14
data:
JSON:{blockState:{blockName:"minecraft:stone_brick_stairs",properties:{half:"bottom",shape:"straight",facing:"south"}}}
:enddata
:endrule

rule:
plugin=vanillaBlocks
number=15
data:
JSON:{blockState:{blockName:"minecraft:stained_hardened_clay",properties:{color:"white"}}}
:enddata
:endrule

rule:
plugin=vanillaBlocks
number=16
data:
JSON:{blockState:{blockName:"minecraft:stone_brick_stairs",properties:{half:"bottom",shape:"straight",facing:"east"}}}
:enddata
:endrule

rule:
plugin=vanillaBlocks
number=17
data:
JSON:{blockState:{blockName:"ancientwarfarestructure:fire_pit",properties:{lit:"true",variant:"log"}}}
:enddata
:endrule

rule:
plugin=vanillaBlocks
number=18
data:
JSON:{blockState:{blockName:"minecraft:spruce_stairs",properties:{half:"bottom",shape:"straight",facing:"north"}}}
:enddata
:endrule

rule:
plugin=vanillaBlocks
number=19
data:
JSON:{blockState:{blockName:"minecraft:stone_brick_stairs",properties:{half:"bottom",shape:"straight",facing:"west"}}}
:enddata
:endrule

rule:
plugin=vanillaBlocks
number=20
data:
JSON:{blockState:{blockName:"minecraft:spruce_stairs",properties:{half:"top",shape:"straight",facing:"south"}}}
:enddata
:endrule

rule:
plugin=doors
number=21
data:
JSON:{blockState:{blockName:"minecraft:spruce_door",properties:{hinge:"right",half:"lower",powered:"false",facing:"north",open:"false"}}}
:enddata
:endrule

rule:
plugin=doors
number=22
data:
JSON:{blockState:{blockName:"minecraft:spruce_door",properties:{hinge:"left",half:"lower",powered:"false",facing:"north",open:"false"}}}
:enddata
:endrule

rule:
plugin=vanillaBlocks
number=23
data:
JSON:{blockState:{blockName:"minecraft:wooden_slab",properties:{half:"bottom",variant:"spruce"}}}
:enddata
:endrule

rule:
plugin=vanillaBlocks
number=24
data:
JSON:{blockState:{blockName:"minecraft:glass_pane",properties:{east:"false",south:"false",north:"false",west:"false"}}}
:enddata
:endrule

rule:
plugin=doors
number=25
data:
JSON:{blockState:{blockName:"minecraft:spruce_door",properties:{hinge:"right",half:"upper",powered:"false",facing:"west",open:"false"}}}
:enddata
:endrule

rule:
plugin=doors
number=26
data:
JSON:{blockState:{blockName:"minecraft:spruce_door",properties:{hinge:"left",half:"upper",powered:"false",facing:"south",open:"false"}}}
:enddata
:endrule

rule:
plugin=doors
number=27
data:
JSON:{blockState:{blockName:"minecraft:spruce_door",properties:{hinge:"right",half:"upper",powered:"false",facing:"south",open:"false"}}}
:enddata
:endrule

rule:
plugin=vanillaBlocks
number=28
data:
JSON:{blockState:{blockName:"minecraft:stone_brick_stairs",properties:{half:"top",shape:"straight",facing:"south"}}}
:enddata
:endrule

rule:
plugin=vanillaBlocks
number=29
data:
JSON:{blockState:{blockName:"minecraft:stone_brick_stairs",properties:{half:"top",shape:"straight",facing:"north"}}}
:enddata
:endrule

rule:
plugin=doors
number=30
data:
JSON:{blockState:{blockName:"minecraft:spruce_door",properties:{hinge:"right",half:"upper",powered:"false",facing:"north",open:"false"}}}
:enddata
:endrule

rule:
plugin=doors
number=31
data:
JSON:{blockState:{blockName:"minecraft:spruce_door",properties:{hinge:"left",half:"upper",powered:"false",facing:"north",open:"false"}}}
:enddata
:endrule

rule:
plugin=vanillaBlocks
number=32
data:
JSON:{blockState:{blockName:"minecraft:stone_brick_stairs",properties:{half:"top",shape:"straight",facing:"east"}}}
:enddata
:endrule

rule:
plugin=vanillaBlocks
number=33
data:
JSON:{blockState:{blockName:"minecraft:spruce_stairs",properties:{half:"top",shape:"straight",facing:"north"}}}
:enddata
:endrule

rule:
plugin=vanillaBlocks
number=34
data:
JSON:{blockState:{blockName:"minecraft:stone_brick_stairs",properties:{half:"top",shape:"straight",facing:"west"}}}
:enddata
:endrule

rule:
plugin=vanillaBlocks
number=35
data:
JSON:{blockState:{blockName:"minecraft:stone_button",properties:{powered:"false",facing:"south"}}}
:enddata
:endrule

rule:
plugin=vanillaBlocks
number=36
data:
JSON:{blockState:{blockName:"minecraft:wooden_slab",properties:{half:"top",variant:"oak"}}}
:enddata
:endrule

rule:
plugin=vanillaBlocks
number=37
data:
JSON:{blockState:{blockName:"minecraft:wooden_slab",properties:{half:"top",variant:"spruce"}}}
:enddata
:endrule

rule:
plugin=vanillaBlocks
number=38
data:
JSON:{blockState:{blockName:"minecraft:spruce_stairs",properties:{half:"top",shape:"straight",facing:"east"}}}
:enddata
:endrule

rule:
plugin=vanillaBlocks
number=39
data:
JSON:{blockState:{blockName:"minecraft:stone_button",properties:{powered:"false",facing:"north"}}}
:enddata
:endrule

rule:
plugin=doors
number=40
data:
JSON:{blockState:{blockName:"minecraft:wooden_door",properties:{hinge:"left",half:"lower",powered:"false",facing:"east",open:"false"}}}
:enddata
:endrule

rule:
plugin=doors
number=41
data:
JSON:{blockState:{blockName:"minecraft:wooden_door",properties:{hinge:"left",half:"upper",powered:"false",facing:"east",open:"false"}}}
:enddata
:endrule

rule:
plugin=vanillaBlocks
number=42
data:
JSON:{blockState:{blockName:"minecraft:spruce_stairs",properties:{half:"top",shape:"straight",facing:"west"}}}
:enddata
:endrule

rule:
plugin=vanillaBlocks
number=43
data:
JSON:{blockState:{blockName:"minecraft:spruce_stairs",properties:{half:"bottom",shape:"straight",facing:"west"}}}
:enddata
:endrule

rule:
plugin=vanillaBlocks
number=44
data:
JSON:{blockState:{blockName:"minecraft:spruce_stairs",properties:{half:"bottom",shape:"straight",facing:"east"}}}
:enddata
:endrule

rule:
plugin=vanillaBlocks
number=45
data:
JSON:{blockState:{blockName:"minecraft:spruce_stairs",properties:{half:"bottom",shape:"straight",facing:"south"}}}
:enddata
:endrule

rule:
plugin=vanillaBlocks
number=46
data:
JSON:{blockState:{blockName:"minecraft:oak_stairs",properties:{half:"top",shape:"straight",facing:"east"}}}
:enddata
:endrule

rule:
plugin=vanillaBlocks
number=47
data:
JSON:{blockState:{blockName:"minecraft:oak_stairs",properties:{half:"top",shape:"straight",facing:"west"}}}
:enddata
:endrule

rule:
plugin=vanillaBlocks
number=48
data:
JSON:{blockState:{blockName:"minecraft:oak_stairs",properties:{half:"top",shape:"straight",facing:"south"}}}
:enddata
:endrule

rule:
plugin=vanillaBlocks
number=49
data:
JSON:{blockState:{blockName:"minecraft:oak_stairs",properties:{half:"top",shape:"straight",facing:"north"}}}
:enddata
:endrule

rule:
plugin=vanillaBlocks
number=50
data:
JSON:{blockState:{blockName:"minecraft:cobblestone_wall",properties:{east:"false",south:"false",north:"false",variant:"cobblestone",west:"false",up:"false"}}}
:enddata
:endrule

#### ENTITIES ####
