# Ancient Warfare Structure Template File
# Auto-generated structure template file. created on: 5/7/2021 at: 0:12:41
# Lines beginning with # denote comments

header:
version=2.11
name=SB_SilkosiaCol_House_1H2R_1
mods=
size=16,15,20
offset=5,1,19
:endheader

#### VALIDATION ####
validation:
type=ground
structureAuthor=TheOddlySeagull
survival=true
worldGenEnabled=false
unique=false
preserveBlocks=false
preventNaturalHostileSpawns=false
selectionWeight=1
clusterValue=1
minDuplicateDistance=1
dimensionWhiteList=true
dimensionList=
biomeGroupList=
biomeWhiteList=true
biomeList=
leveling=0
fill=0
border=0
blockSwap=false
territoryName=
biomeReplacement=minecraft:
minGenerationHeight=0
maxGenerationHeight=255
:endvalidation

#### LAYERS ####
layer: 0
1,2,2,2,2,1,3,1,2,2,2,2,2,2,2,1
4,5,5,5,5,5,3,5,5,5,5,5,5,5,5,4
4,5,5,5,5,5,3,5,5,5,5,5,5,5,5,4
4,5,5,5,5,5,3,5,5,5,5,5,5,5,5,4
4,5,5,5,5,5,3,5,5,5,5,5,5,5,5,4
4,5,5,5,5,5,3,5,1,2,2,2,2,1,5,4
4,5,5,6,6,6,3,5,4,8,8,8,8,4,5,4
4,5,1,6,6,6,2,2,4,8,8,8,8,4,5,4
4,5,4,6,6,6,7,7,4,2,2,2,2,4,5,1
4,5,4,7,7,7,7,7,4,8,8,8,8,4,3,3
4,5,4,7,7,7,7,7,4,8,8,8,8,4,3,3
4,5,4,2,2,2,2,2,4,8,8,8,8,4,5,1
4,5,4,7,7,7,7,7,4,2,2,2,2,1,5,4
4,5,6,7,7,7,7,7,4,5,5,5,5,5,5,4
4,5,6,7,7,7,7,7,4,5,5,5,5,5,5,4
4,5,6,2,2,2,2,2,1,5,5,5,5,5,5,4
4,5,5,5,3,3,3,5,5,5,5,5,5,5,5,4
4,5,5,5,3,3,3,5,5,5,5,5,5,5,5,4
4,5,5,5,3,3,3,5,5,5,5,5,5,5,5,4
1,2,2,1,3,3,3,1,2,2,2,2,2,2,2,1
:endlayer
layer: 1
1,9,9,9,9,1,0,1,9,9,9,9,9,9,9,1
9,0,0,0,0,0,0,0,0,0,0,0,0,0,0,9
9,0,0,0,0,0,0,0,0,0,0,0,0,0,0,9
9,0,0,0,0,0,0,0,0,0,0,0,0,0,0,9
9,0,0,0,0,0,0,0,0,0,0,0,0,0,0,9
9,0,0,0,0,0,0,0,1,6,19,19,6,1,0,9
9,0,0,6,6,6,0,0,6,0,0,0,0,6,0,9
9,0,1,16,18,14,17,6,1,0,0,0,0,16,0,9
9,0,6,0,0,0,0,0,6,0,0,0,0,6,0,1
9,0,14,0,0,0,0,0,0,0,0,0,0,15,0,0
9,0,6,0,0,0,0,0,0,0,0,0,0,15,0,0
9,0,14,0,0,0,0,13,6,0,0,0,0,6,0,1
9,0,6,0,0,0,0,12,1,6,11,11,6,1,0,9
9,0,6,0,0,0,0,0,6,0,0,0,0,0,0,9
9,0,6,0,0,0,0,0,6,0,0,0,0,0,0,9
9,0,6,6,6,10,6,6,6,0,0,0,0,0,0,9
9,0,0,0,0,0,0,0,0,0,0,0,0,0,0,9
9,0,0,0,0,0,0,0,0,0,0,0,0,0,0,9
9,0,0,0,0,0,0,0,0,0,0,0,0,0,0,9
1,9,9,1,0,0,0,1,9,9,9,9,9,9,9,1
:endlayer
layer: 2
20,0,0,0,0,20,0,20,0,0,0,0,0,0,0,20
0,0,0,0,0,0,0,0,0,0,0,0,0,0,0,0
0,0,0,0,0,0,0,0,0,0,0,0,0,0,0,0
0,0,0,0,0,0,0,0,0,0,0,0,0,0,0,0
0,0,0,0,0,0,0,0,0,0,0,0,0,0,0,0
0,0,0,0,0,0,0,0,1,6,22,22,6,1,0,0
0,0,0,6,6,6,0,0,6,0,0,0,0,6,0,0
0,0,1,25,0,24,23,6,1,0,0,0,0,22,0,0
0,0,6,0,0,0,0,0,6,0,0,0,0,6,0,20
0,0,22,0,0,0,0,0,0,0,0,0,0,23,0,0
0,0,6,0,0,0,0,0,0,0,0,0,0,21,0,0
0,0,22,0,0,0,0,0,6,0,0,0,0,6,0,20
0,0,6,0,0,0,0,13,1,6,22,22,6,1,0,0
0,0,6,0,0,0,0,12,6,0,0,0,0,0,0,0
0,0,6,0,0,0,0,0,6,0,0,0,0,0,0,0
0,0,6,6,6,21,6,6,6,0,0,0,0,0,0,0
0,0,0,0,0,0,0,0,0,0,0,0,0,0,0,0
0,0,0,0,0,0,0,0,0,0,0,0,0,0,0,0
0,0,0,0,0,0,0,0,0,0,0,0,0,0,0,0
20,0,0,20,0,0,0,20,0,0,0,0,0,0,0,20
:endlayer
layer: 3
0,0,0,0,0,0,0,0,0,0,0,0,0,0,0,0
0,0,0,0,0,0,0,0,0,0,0,0,0,0,0,0
0,0,0,0,0,0,0,0,0,0,0,0,0,0,0,0
0,0,0,0,0,0,0,0,0,0,0,0,0,0,0,0
0,0,0,0,0,0,0,0,9,0,0,0,0,9,0,0
0,0,0,0,0,0,0,0,1,6,22,22,6,1,0,0
0,0,9,14,6,16,0,0,6,0,0,0,0,6,0,0
0,0,1,6,26,6,27,6,1,0,0,0,0,22,0,0
0,0,6,0,0,0,0,0,6,0,0,0,0,6,0,0
0,0,22,0,0,0,0,0,26,0,0,0,0,25,0,0
0,0,6,0,0,0,0,0,27,0,0,0,0,25,0,0
0,0,22,0,0,0,0,0,6,0,0,0,0,6,0,0
0,0,6,0,0,0,0,0,1,6,22,22,6,1,0,0
0,0,6,0,0,0,0,13,6,0,0,0,0,9,0,0
0,24,6,0,0,0,0,12,6,0,0,0,0,0,0,0
0,0,6,6,6,26,6,6,6,0,0,0,0,0,0,0
0,0,9,0,0,0,0,0,9,0,0,0,0,0,0,0
0,0,0,0,0,0,0,0,0,0,0,0,0,0,0,0
0,0,0,0,0,0,0,0,0,0,0,0,0,0,0,0
0,0,0,0,0,0,0,0,0,0,0,0,0,0,0,0
:endlayer
layer: 4
0,0,0,0,0,0,0,0,0,0,0,0,0,0,0,0
0,0,0,0,0,0,0,0,0,0,0,0,0,0,0,0
0,0,0,0,0,0,0,0,0,0,0,0,0,0,0,0
0,0,0,0,0,0,0,0,33,0,33,0,0,33,0,0
0,0,0,0,0,0,0,0,4,29,4,29,29,4,0,0
0,0,33,0,0,33,0,0,4,2,2,2,2,4,0,0
0,0,4,29,6,4,29,29,4,30,30,30,30,4,0,0
0,0,4,2,2,2,2,2,4,30,30,30,30,4,32,0
0,0,4,30,30,30,30,30,4,30,30,30,30,4,29,0
0,31,4,30,30,30,30,30,4,2,2,2,2,4,29,0
0,29,4,2,2,2,2,2,4,30,30,30,30,4,32,0
0,29,4,30,30,30,4,0,4,30,30,30,30,4,0,0
0,31,4,2,2,2,4,0,4,2,2,2,2,4,0,0
0,24,6,4,30,30,4,0,4,29,4,29,29,4,0,0
0,6,6,4,30,30,4,13,4,0,28,0,0,28,0,0
0,24,6,2,2,2,2,2,4,0,0,0,0,0,0,0
0,0,4,29,29,4,29,29,4,0,0,0,0,0,0,0
0,0,28,0,0,28,0,0,28,0,0,0,0,0,0,0
0,0,0,0,0,0,0,0,0,0,0,0,0,0,0,0
0,0,0,0,0,0,0,0,0,0,0,0,0,0,0,0
:endlayer
layer: 5
0,0,0,0,0,0,0,0,0,0,0,0,0,0,0,0
0,0,0,0,0,0,0,0,0,0,0,0,0,0,0,0
0,0,0,0,0,0,0,0,0,0,0,0,0,0,0,0
0,0,0,0,0,0,0,0,0,0,0,0,0,0,0,0
0,0,0,0,0,0,0,0,1,34,1,34,34,1,0,0
0,0,0,0,0,0,0,0,34,0,0,0,0,34,0,0
0,0,1,34,6,1,34,34,1,0,0,0,0,34,0,0
0,0,34,0,0,0,0,0,0,0,0,0,0,1,9,0
0,0,34,0,0,0,0,0,0,0,0,0,0,36,9,0
0,9,1,0,0,0,0,0,0,0,0,0,0,36,9,0
0,9,35,0,0,0,9,9,1,0,0,0,0,1,9,0
0,9,35,0,0,0,9,0,34,0,0,0,0,34,0,0
0,9,1,0,0,0,9,0,34,0,0,0,0,34,0,0
0,6,11,0,0,0,9,0,1,34,1,34,34,1,0,0
0,6,18,0,0,0,0,0,34,0,0,0,0,0,0,0
0,6,19,0,0,0,0,0,34,0,0,0,0,0,0,0
0,0,1,34,34,1,34,34,1,0,0,0,0,0,0,0
0,0,0,0,0,0,0,0,0,0,0,0,0,0,0,0
0,0,0,0,0,0,0,0,0,0,0,0,0,0,0,0
0,0,0,0,0,0,0,0,0,0,0,0,0,0,0,0
:endlayer
layer: 6
0,0,0,0,0,0,0,0,0,0,0,0,0,0,0,0
0,0,0,0,0,0,0,0,0,0,0,0,0,0,0,0
0,0,0,0,0,0,0,0,0,0,0,0,0,0,0,0
0,0,0,0,0,0,0,0,0,0,0,0,0,0,0,0
0,0,0,0,0,0,0,0,1,34,1,22,22,1,0,0
0,0,0,0,0,0,0,0,34,0,0,0,0,34,0,0
0,0,1,34,6,1,22,22,1,0,0,0,0,34,0,0
0,0,34,0,0,0,0,0,0,0,0,0,0,1,0,0
0,0,34,0,0,0,0,0,0,0,0,0,0,37,0,0
0,0,1,0,0,0,0,0,0,0,0,0,0,38,0,0
0,0,38,0,0,0,0,0,1,0,0,0,0,1,0,0
0,0,37,0,0,0,0,0,34,0,0,0,0,34,0,0
0,0,1,0,0,0,0,0,34,0,0,0,0,34,0,0
0,6,26,0,0,0,0,0,1,34,1,22,22,1,0,0
0,6,0,0,0,0,0,0,34,0,0,0,0,0,0,0
0,6,27,0,0,0,0,0,34,0,0,0,0,0,0,0
0,0,1,22,22,1,22,22,1,0,0,0,0,0,0,0
0,0,0,0,0,0,0,0,0,0,0,0,0,0,0,0
0,0,0,0,0,0,0,0,0,0,0,0,0,0,0,0
0,0,0,0,0,0,0,0,0,0,0,0,0,0,0,0
:endlayer
layer: 7
0,0,0,0,0,0,0,0,0,0,0,0,0,0,0,0
0,0,0,0,0,0,0,0,0,0,0,0,0,0,0,0
0,0,0,0,0,0,0,0,0,0,0,0,0,0,0,0
0,0,0,0,0,0,0,0,9,0,0,0,0,9,0,0
0,0,0,0,0,0,0,9,1,34,1,22,22,1,9,0
0,0,9,0,0,9,0,0,34,0,0,0,0,34,0,0
0,9,1,34,6,1,22,22,1,0,0,0,0,34,0,0
0,0,34,0,0,0,0,0,40,0,0,0,0,1,30,0
0,0,34,0,0,0,0,0,0,0,0,0,0,34,30,0
0,30,1,0,0,0,0,0,39,0,0,0,0,34,30,0
0,30,34,0,0,0,0,0,1,0,0,0,0,1,30,0
0,30,34,0,0,0,0,0,34,0,0,0,0,34,0,0
0,30,1,0,0,0,0,0,34,0,0,0,0,34,0,0
0,19,6,0,0,0,0,0,1,34,1,22,22,1,9,0
0,6,25,0,0,0,0,0,34,0,9,0,0,9,0,0
0,11,6,0,0,0,0,0,34,0,0,0,0,0,0,0
0,9,1,22,22,1,22,22,1,9,0,0,0,0,0,0
0,0,9,0,0,0,0,0,9,0,0,0,0,0,0,0
0,0,0,0,0,0,0,0,0,0,0,0,0,0,0,0
0,0,0,0,0,0,0,0,0,0,0,0,0,0,0,0
:endlayer
layer: 8
0,0,0,0,0,0,0,0,0,0,0,0,0,0,0,0
0,0,0,0,0,0,0,0,0,0,0,0,0,0,0,0
0,0,0,0,0,0,0,0,0,0,0,0,0,0,0,0
0,0,0,0,0,0,0,44,43,0,0,0,0,42,41,0
0,0,0,0,0,0,0,44,1,2,2,2,2,1,41,0
0,46,46,46,46,46,46,44,4,0,0,0,0,4,46,0
0,40,1,2,6,2,2,2,4,0,0,0,0,4,40,0
0,0,4,0,0,0,0,0,4,0,0,0,0,4,0,0
0,0,4,0,0,0,0,0,4,0,0,0,0,4,0,0
0,0,4,0,0,0,0,0,4,0,0,0,0,4,0,0
0,0,4,0,0,0,0,0,4,0,0,0,0,4,0,0
0,0,4,0,0,0,0,0,4,0,0,0,0,4,0,0
0,0,4,0,0,0,0,0,4,0,0,0,0,4,0,0
0,39,4,2,2,2,2,2,2,2,2,2,2,1,39,0
0,6,4,0,0,0,0,0,4,41,45,45,45,45,45,0
0,44,4,0,0,0,0,0,4,41,0,0,0,0,0,0
0,44,1,2,2,2,2,2,1,41,0,0,0,0,0,0
0,44,43,0,0,0,0,0,42,41,0,0,0,0,0,0
0,0,0,0,0,0,0,0,0,0,0,0,0,0,0,0
0,0,0,0,0,0,0,0,0,0,0,0,0,0,0,0
:endlayer
layer: 9
0,0,0,0,0,0,0,0,0,0,0,0,0,0,0,0
0,0,0,0,0,0,0,0,0,0,0,0,0,0,0,0
0,0,0,0,0,0,0,0,0,0,0,0,0,0,0,0
0,0,0,0,0,0,0,0,44,43,0,0,42,41,0,0
0,0,0,0,0,0,0,0,44,1,34,34,1,41,0,0
0,0,0,0,0,0,0,0,44,32,0,0,31,41,0,0
0,46,46,46,6,46,46,46,46,32,0,0,31,46,46,0
0,40,1,12,12,12,12,12,1,12,0,0,12,1,40,0
0,0,34,0,0,0,0,0,34,0,0,0,0,34,0,0
0,0,34,0,0,0,0,0,34,0,0,0,0,34,0,0
0,0,34,0,0,0,0,0,34,0,0,0,0,34,0,0
0,0,34,0,0,0,0,0,34,0,0,0,0,34,0,0
0,39,1,29,0,0,0,29,1,47,47,47,47,1,39,0
0,45,45,43,0,0,0,42,41,45,45,45,45,45,45,0
0,6,44,32,0,0,0,31,41,0,0,0,0,0,0,0
0,0,44,32,0,0,0,31,41,0,0,0,0,0,0,0
0,0,44,1,34,34,34,1,41,0,0,0,0,0,0,0
0,0,44,43,0,0,0,42,41,0,0,0,0,0,0,0
0,0,0,0,0,0,0,0,0,0,0,0,0,0,0,0
0,0,0,0,0,0,0,0,0,0,0,0,0,0,0,0
:endlayer
layer: 10
0,0,0,0,0,0,0,0,0,0,0,0,0,0,0,0
0,0,0,0,0,0,0,0,0,0,0,0,0,0,0,0
0,0,0,0,0,0,0,0,0,0,0,0,0,0,0,0
0,0,0,0,0,0,0,0,0,44,46,46,41,0,0,0
0,0,0,0,0,0,0,0,0,44,2,2,41,0,0,0
0,0,0,0,0,0,0,0,0,44,32,31,41,0,0,0
0,0,0,0,6,0,0,0,0,44,32,31,41,0,0,0
0,46,46,46,46,46,46,46,46,44,32,31,41,46,46,0
0,40,1,12,12,12,12,12,1,12,12,31,12,1,40,0
0,0,34,0,0,0,0,0,34,0,0,0,0,34,0,0
0,0,34,0,0,0,0,0,34,0,0,0,0,34,0,0
0,39,1,47,32,0,31,47,1,47,47,47,47,1,39,0
0,45,45,44,32,0,31,45,45,45,45,45,45,45,45,0
0,0,0,44,43,0,42,41,0,0,0,0,0,0,0,0
0,6,0,44,32,0,31,41,0,0,0,0,0,0,0,0
0,0,0,44,32,0,31,41,0,0,0,0,0,0,0,0
0,0,0,44,1,34,1,41,0,0,0,0,0,0,0,0
0,0,0,44,43,0,42,41,0,0,0,0,0,0,0,0
0,0,0,0,0,0,0,0,0,0,0,0,0,0,0,0
0,0,0,0,0,0,0,0,0,0,0,0,0,0,0,0
:endlayer
layer: 11
0,0,0,0,0,0,0,0,0,0,0,0,0,0,0,0
0,0,0,0,0,0,0,0,0,0,0,0,0,0,0,0
0,0,0,0,0,0,0,0,0,0,0,0,0,0,0,0
0,0,0,0,0,0,0,0,0,0,0,0,0,0,0,0
0,0,0,0,0,0,0,0,0,0,44,46,0,0,0,0
0,0,0,0,0,0,0,0,0,0,44,41,0,0,0,0
0,0,0,0,6,0,0,0,0,0,44,41,0,0,0,0
0,0,0,0,0,0,0,0,0,0,44,41,0,0,0,0
0,46,46,46,46,46,46,46,46,46,44,46,46,46,46,0
0,44,4,40,40,40,40,40,4,40,40,40,40,4,41,0
0,44,4,39,39,39,39,39,4,39,39,39,39,4,41,0
0,45,45,45,45,4,45,45,45,45,45,45,45,45,45,0
0,0,0,0,44,4,41,0,0,0,0,0,0,0,0,0
0,33,0,0,44,4,41,0,0,0,0,0,0,0,0,0
49,6,48,0,44,4,41,0,0,0,0,0,0,0,0,0
0,28,0,0,44,4,41,0,0,0,0,0,0,0,0,0
0,0,0,0,44,1,41,0,0,0,0,0,0,0,0,0
0,0,0,0,44,45,41,0,0,0,0,0,0,0,0,0
0,0,0,0,0,0,0,0,0,0,0,0,0,0,0,0
0,0,0,0,0,0,0,0,0,0,0,0,0,0,0,0
:endlayer
layer: 12
0,0,0,0,0,0,0,0,0,0,0,0,0,0,0,0
0,0,0,0,0,0,0,0,0,0,0,0,0,0,0,0
0,0,0,0,0,0,0,0,0,0,0,0,0,0,0,0
0,0,0,0,0,0,0,0,0,0,0,0,0,0,0,0
0,0,0,0,0,0,0,0,0,0,0,0,0,0,0,0
0,0,0,0,33,0,0,0,0,0,0,0,0,0,0,0
0,0,0,49,6,48,0,0,0,0,0,0,0,0,0,0
0,0,0,0,28,0,0,0,0,0,0,0,0,0,0,0
0,0,0,0,0,0,0,0,0,0,0,0,0,0,0,0
0,0,44,46,46,46,46,46,46,46,46,46,46,41,0,0
0,0,44,45,45,45,45,45,45,45,45,45,45,41,0,0
0,0,0,0,0,20,0,0,0,0,0,0,0,0,0,0
0,0,0,0,0,20,0,0,0,0,0,0,0,0,0,0
0,0,0,0,0,20,0,0,0,0,0,0,0,0,0,0
0,50,0,0,0,20,0,0,0,0,0,0,0,0,0,0
0,0,0,0,0,20,0,0,0,0,0,0,0,0,0,0
0,0,0,0,0,20,0,0,0,0,0,0,0,0,0,0
0,0,0,0,0,0,0,0,0,0,0,0,0,0,0,0
0,0,0,0,0,0,0,0,0,0,0,0,0,0,0,0
0,0,0,0,0,0,0,0,0,0,0,0,0,0,0,0
:endlayer
layer: 13
0,0,0,0,0,0,0,0,0,0,0,0,0,0,0,0
0,0,0,0,0,0,0,0,0,0,0,0,0,0,0,0
0,0,0,0,0,0,0,0,0,0,0,0,0,0,0,0
0,0,0,0,0,0,0,0,0,0,0,0,0,0,0,0
0,0,0,0,0,0,0,0,0,0,0,0,0,0,0,0
0,0,0,0,0,0,0,0,0,0,0,0,0,0,0,0
0,0,0,0,50,0,0,0,0,0,0,0,0,0,0,0
0,0,0,0,0,0,0,0,0,0,0,0,0,0,0,0
0,0,0,0,0,0,0,0,0,0,0,0,0,0,0,0
0,0,0,0,0,0,0,0,0,0,0,0,0,0,0,0
0,0,0,0,0,0,0,0,0,0,0,0,0,0,0,0
0,0,0,0,0,0,0,0,0,0,0,0,0,0,0,0
0,0,0,0,0,0,0,0,0,0,0,0,0,0,0,0
0,0,0,0,0,0,0,0,0,0,0,0,0,0,0,0
0,20,0,0,0,0,0,0,0,0,0,0,0,0,0,0
0,0,0,0,0,0,0,0,0,0,0,0,0,0,0,0
0,0,0,0,0,0,0,0,0,0,0,0,0,0,0,0
0,0,0,0,0,0,0,0,0,0,0,0,0,0,0,0
0,0,0,0,0,0,0,0,0,0,0,0,0,0,0,0
0,0,0,0,0,0,0,0,0,0,0,0,0,0,0,0
:endlayer
layer: 14
0,0,0,0,0,0,0,0,0,0,0,0,0,0,0,0
0,0,0,0,0,0,0,0,0,0,0,0,0,0,0,0
0,0,0,0,0,0,0,0,0,0,0,0,0,0,0,0
0,0,0,0,0,0,0,0,0,0,0,0,0,0,0,0
0,0,0,0,0,0,0,0,0,0,0,0,0,0,0,0
0,0,0,0,0,0,0,0,0,0,0,0,0,0,0,0
0,0,0,0,20,0,0,0,0,0,0,0,0,0,0,0
0,0,0,0,0,0,0,0,0,0,0,0,0,0,0,0
0,0,0,0,0,0,0,0,0,0,0,0,0,0,0,0
0,0,0,0,0,0,0,0,0,0,0,0,0,0,0,0
0,0,0,0,0,0,0,0,0,0,0,0,0,0,0,0
0,0,0,0,0,0,0,0,0,0,0,0,0,0,0,0
0,0,0,0,0,0,0,0,0,0,0,0,0,0,0,0
0,0,0,0,0,0,0,0,0,0,0,0,0,0,0,0
0,0,0,0,0,0,0,0,0,0,0,0,0,0,0,0
0,0,0,0,0,0,0,0,0,0,0,0,0,0,0,0
0,0,0,0,0,0,0,0,0,0,0,0,0,0,0,0
0,0,0,0,0,0,0,0,0,0,0,0,0,0,0,0
0,0,0,0,0,0,0,0,0,0,0,0,0,0,0,0
0,0,0,0,0,0,0,0,0,0,0,0,0,0,0,0
:endlayer

#### RULES ####
rule:
plugin=vanillaBlocks
number=1
data:
JSON:{blockState:{blockName:"minecraft:log",properties:{variant:"oak",axis:"y"}}}
:enddata
:endrule

rule:
plugin=vanillaBlocks
number=2
data:
JSON:{blockState:{blockName:"minecraft:log",properties:{variant:"oak",axis:"x"}}}
:enddata
:endrule

rule:
plugin=vanillaBlocks
number=3
data:
JSON:{blockState:{blockName:"minecraft:cobblestone"}}
:enddata
:endrule

rule:
plugin=vanillaBlocks
number=4
data:
JSON:{blockState:{blockName:"minecraft:log",properties:{variant:"oak",axis:"z"}}}
:enddata
:endrule

rule:
plugin=vanillaBlocks
number=5
data:
JSON:{blockState:{blockName:"minecraft:grass",properties:{snowy:"false"}}}
:enddata
:endrule

rule:
plugin=vanillaBlocks
number=6
data:
JSON:{blockState:{blockName:"minecraft:stonebrick",properties:{variant:"stonebrick"}}}
:enddata
:endrule

rule:
plugin=vanillaBlocks
number=7
data:
JSON:{blockState:{blockName:"minecraft:planks",properties:{variant:"spruce"}}}
:enddata
:endrule

rule:
plugin=vanillaBlocks
number=8
data:
JSON:{blockState:{blockName:"minecraft:stone",properties:{variant:"smooth_andesite"}}}
:enddata
:endrule

rule:
plugin=vanillaBlocks
number=9
data:
JSON:{blockState:{blockName:"minecraft:spruce_fence",properties:{east:"false",south:"false",north:"false",west:"false"}}}
:enddata
:endrule

rule:
plugin=doors
number=10
data:
JSON:{blockState:{blockName:"minecraft:spruce_door",properties:{hinge:"left",half:"lower",powered:"false",facing:"south",open:"false"}}}
:enddata
:endrule

rule:
plugin=vanillaBlocks
number=11
data:
JSON:{blockState:{blockName:"minecraft:stone_brick_stairs",properties:{half:"bottom",shape:"straight",facing:"north"}}}
:enddata
:endrule

rule:
plugin=vanillaBlocks
number=12
data:
JSON:{blockState:{blockName:"minecraft:oak_stairs",properties:{half:"top",shape:"straight",facing:"north"}}}
:enddata
:endrule

rule:
plugin=vanillaBlocks
number=13
data:
JSON:{blockState:{blockName:"minecraft:oak_stairs",properties:{half:"bottom",shape:"straight",facing:"south"}}}
:enddata
:endrule

rule:
plugin=vanillaBlocks
number=14
data:
JSON:{blockState:{blockName:"minecraft:stone_brick_stairs",properties:{half:"bottom",shape:"straight",facing:"east"}}}
:enddata
:endrule

rule:
plugin=doors
number=15
data:
JSON:{blockState:{blockName:"minecraft:spruce_door",properties:{hinge:"left",half:"lower",powered:"false",facing:"east",open:"false"}}}
:enddata
:endrule

rule:
plugin=vanillaBlocks
number=16
data:
JSON:{blockState:{blockName:"minecraft:stone_brick_stairs",properties:{half:"bottom",shape:"straight",facing:"west"}}}
:enddata
:endrule

rule:
plugin=doors
number=17
data:
JSON:{blockState:{blockName:"minecraft:spruce_door",properties:{hinge:"left",half:"lower",powered:"false",facing:"north",open:"false"}}}
:enddata
:endrule

rule:
plugin=vanillaBlocks
number=18
data:
JSON:{blockState:{blockName:"ancientwarfarestructure:fire_pit",properties:{lit:"true",variant:"log"}}}
:enddata
:endrule

rule:
plugin=vanillaBlocks
number=19
data:
JSON:{blockState:{blockName:"minecraft:stone_brick_stairs",properties:{half:"bottom",shape:"straight",facing:"south"}}}
:enddata
:endrule

rule:
plugin=vanillaBlocks
number=20
data:
JSON:{blockState:{blockName:"minecraft:wooden_slab",properties:{half:"bottom",variant:"spruce"}}}
:enddata
:endrule

rule:
plugin=doors
number=21
data:
JSON:{blockState:{blockName:"minecraft:spruce_door",properties:{hinge:"right",half:"upper",powered:"false",facing:"south",open:"false"}}}
:enddata
:endrule

rule:
plugin=vanillaBlocks
number=22
data:
JSON:{blockState:{blockName:"minecraft:glass_pane",properties:{east:"false",south:"false",north:"false",west:"false"}}}
:enddata
:endrule

rule:
plugin=doors
number=23
data:
JSON:{blockState:{blockName:"minecraft:spruce_door",properties:{hinge:"left",half:"upper",powered:"false",facing:"south",open:"false"}}}
:enddata
:endrule

rule:
plugin=vanillaBlocks
number=24
data:
JSON:{blockState:{blockName:"minecraft:stone_brick_stairs",properties:{half:"top",shape:"straight",facing:"east"}}}
:enddata
:endrule

rule:
plugin=vanillaBlocks
number=25
data:
JSON:{blockState:{blockName:"minecraft:stone_brick_stairs",properties:{half:"top",shape:"straight",facing:"west"}}}
:enddata
:endrule

rule:
plugin=vanillaBlocks
number=26
data:
JSON:{blockState:{blockName:"minecraft:stone_brick_stairs",properties:{half:"top",shape:"straight",facing:"north"}}}
:enddata
:endrule

rule:
plugin=vanillaBlocks
number=27
data:
JSON:{blockState:{blockName:"minecraft:stone_brick_stairs",properties:{half:"top",shape:"straight",facing:"south"}}}
:enddata
:endrule

rule:
plugin=vanillaBlocks
number=28
data:
JSON:{blockState:{blockName:"minecraft:stone_button",properties:{powered:"false",facing:"south"}}}
:enddata
:endrule

rule:
plugin=vanillaBlocks
number=29
data:
JSON:{blockState:{blockName:"minecraft:wooden_slab",properties:{half:"top",variant:"oak"}}}
:enddata
:endrule

rule:
plugin=vanillaBlocks
number=30
data:
JSON:{blockState:{blockName:"minecraft:wooden_slab",properties:{half:"top",variant:"spruce"}}}
:enddata
:endrule

rule:
plugin=vanillaBlocks
number=31
data:
JSON:{blockState:{blockName:"minecraft:oak_stairs",properties:{half:"top",shape:"straight",facing:"east"}}}
:enddata
:endrule

rule:
plugin=vanillaBlocks
number=32
data:
JSON:{blockState:{blockName:"minecraft:oak_stairs",properties:{half:"top",shape:"straight",facing:"west"}}}
:enddata
:endrule

rule:
plugin=vanillaBlocks
number=33
data:
JSON:{blockState:{blockName:"minecraft:stone_button",properties:{powered:"false",facing:"north"}}}
:enddata
:endrule

rule:
plugin=vanillaBlocks
number=34
data:
JSON:{blockState:{blockName:"minecraft:stained_hardened_clay",properties:{color:"magenta"}}}
:enddata
:endrule

rule:
plugin=doors
number=35
data:
JSON:{blockState:{blockName:"minecraft:wooden_door",properties:{hinge:"left",half:"lower",powered:"false",facing:"east",open:"false"}}}
:enddata
:endrule

rule:
plugin=doors
number=36
data:
JSON:{blockState:{blockName:"minecraft:wooden_door",properties:{hinge:"left",half:"lower",powered:"false",facing:"west",open:"false"}}}
:enddata
:endrule

rule:
plugin=doors
number=37
data:
JSON:{blockState:{blockName:"minecraft:wooden_door",properties:{hinge:"right",half:"upper",powered:"false",facing:"south",open:"false"}}}
:enddata
:endrule

rule:
plugin=doors
number=38
data:
JSON:{blockState:{blockName:"minecraft:wooden_door",properties:{hinge:"left",half:"upper",powered:"false",facing:"south",open:"false"}}}
:enddata
:endrule

rule:
plugin=vanillaBlocks
number=39
data:
JSON:{blockState:{blockName:"minecraft:spruce_stairs",properties:{half:"top",shape:"straight",facing:"south"}}}
:enddata
:endrule

rule:
plugin=vanillaBlocks
number=40
data:
JSON:{blockState:{blockName:"minecraft:spruce_stairs",properties:{half:"top",shape:"straight",facing:"north"}}}
:enddata
:endrule

rule:
plugin=vanillaBlocks
number=41
data:
JSON:{blockState:{blockName:"minecraft:spruce_stairs",properties:{half:"bottom",shape:"straight",facing:"west"}}}
:enddata
:endrule

rule:
plugin=vanillaBlocks
number=42
data:
JSON:{blockState:{blockName:"minecraft:spruce_stairs",properties:{half:"top",shape:"straight",facing:"east"}}}
:enddata
:endrule

rule:
plugin=vanillaBlocks
number=43
data:
JSON:{blockState:{blockName:"minecraft:spruce_stairs",properties:{half:"top",shape:"straight",facing:"west"}}}
:enddata
:endrule

rule:
plugin=vanillaBlocks
number=44
data:
JSON:{blockState:{blockName:"minecraft:spruce_stairs",properties:{half:"bottom",shape:"straight",facing:"east"}}}
:enddata
:endrule

rule:
plugin=vanillaBlocks
number=45
data:
JSON:{blockState:{blockName:"minecraft:spruce_stairs",properties:{half:"bottom",shape:"straight",facing:"north"}}}
:enddata
:endrule

rule:
plugin=vanillaBlocks
number=46
data:
JSON:{blockState:{blockName:"minecraft:spruce_stairs",properties:{half:"bottom",shape:"straight",facing:"south"}}}
:enddata
:endrule

rule:
plugin=vanillaBlocks
number=47
data:
JSON:{blockState:{blockName:"minecraft:oak_stairs",properties:{half:"top",shape:"straight",facing:"south"}}}
:enddata
:endrule

rule:
plugin=vanillaBlocks
number=48
data:
JSON:{blockState:{blockName:"minecraft:stone_button",properties:{powered:"false",facing:"east"}}}
:enddata
:endrule

rule:
plugin=vanillaBlocks
number=49
data:
JSON:{blockState:{blockName:"minecraft:stone_button",properties:{powered:"false",facing:"west"}}}
:enddata
:endrule

rule:
plugin=vanillaBlocks
number=50
data:
JSON:{blockState:{blockName:"minecraft:cobblestone_wall",properties:{east:"false",south:"false",north:"false",variant:"cobblestone",west:"false",up:"false"}}}
:enddata
:endrule

#### ENTITIES ####
