# Ancient Warfare Structure Template File
# Auto-generated structure template file. created on: 6/5/2021 at: 11:40:49
# Lines beginning with # denote comments

header:
version=2.11
name=SurvivalBuild_house_type1_9r_1
mods=
size=22,17,19
offset=10,1,18
:endheader

#### VALIDATION ####
validation:
type=ground
structureAuthor=theoddlyseagull
survival=true
worldGenEnabled=false
unique=false
preserveBlocks=false
preventNaturalHostileSpawns=false
selectionWeight=1
clusterValue=1
minDuplicateDistance=1
dimensionWhiteList=true
dimensionList=
biomeGroupList=
biomeWhiteList=true
biomeList=
leveling=0
fill=0
border=0
blockSwap=false
territoryName=
biomeReplacement=minecraft:
minGenerationHeight=0
maxGenerationHeight=255
:endvalidation

#### LAYERS ####
layer: 0
1,1,1,1,1,1,1,1,1,1,1,1,1,1,1,1,1,1,1,1,1,1
1,1,1,1,1,1,1,1,1,1,1,1,1,1,1,1,1,1,1,1,1,1
1,1,1,1,1,1,1,1,1,1,1,2,2,2,2,2,2,2,1,1,1,1
1,1,1,1,1,1,1,1,2,2,2,2,2,2,2,2,2,2,2,1,1,1
1,1,1,1,1,2,2,2,2,2,2,2,2,2,2,2,2,2,2,1,1,1
1,1,1,1,1,2,2,2,2,2,2,2,2,2,2,2,2,2,2,1,1,1
1,1,1,1,1,2,2,2,2,2,2,2,2,2,2,2,2,2,2,2,1,1
1,1,1,1,1,2,2,2,2,2,2,2,2,2,2,2,2,2,2,2,1,1
1,1,1,1,1,2,2,2,2,2,2,2,2,2,2,2,2,2,2,2,1,1
1,1,1,1,1,2,2,2,2,2,2,2,2,2,2,2,2,2,2,2,1,1
1,1,2,2,2,2,2,2,2,2,2,2,2,2,2,2,2,2,2,2,1,1
1,1,2,2,2,2,2,2,2,2,2,2,2,2,2,2,2,2,2,2,1,1
1,1,2,2,2,2,2,2,2,2,2,2,2,2,2,2,2,2,2,2,1,1
1,2,2,2,2,2,2,2,2,2,2,2,2,2,2,2,2,2,2,1,1,1
1,2,2,2,2,2,2,2,2,2,2,2,2,2,2,2,2,2,2,1,1,1
1,2,2,2,2,2,2,2,1,2,2,1,2,2,2,2,2,2,1,1,1,1
1,1,2,2,2,2,2,2,1,2,2,1,2,2,2,2,2,1,1,1,1,1
1,1,1,1,1,1,1,1,1,2,2,1,2,2,2,2,2,1,1,1,1,1
1,1,1,1,1,1,1,1,1,2,2,1,1,1,1,1,1,1,1,1,1,1
:endlayer
layer: 1
0,0,0,0,0,0,0,0,0,0,0,0,0,0,0,0,0,0,0,0,0,0
0,0,0,0,0,0,0,0,0,0,0,0,0,0,0,0,0,0,0,0,0,0
0,0,0,0,0,0,0,0,0,0,0,3,2,2,2,2,2,3,0,0,0,0
0,0,0,0,0,0,0,0,2,2,2,2,5,0,0,0,0,0,2,0,0,0
0,0,0,0,0,3,2,3,2,4,2,4,5,0,0,0,0,0,2,0,0,0
0,0,0,0,0,2,0,0,5,5,5,2,5,0,0,0,0,0,2,0,0,0
0,0,0,0,0,2,0,0,0,0,0,3,2,0,0,2,3,2,2,3,0,0
0,0,0,0,0,2,0,0,0,0,0,0,0,0,0,2,0,0,0,2,0,0
0,0,0,0,0,2,7,0,0,0,0,0,0,0,0,0,0,0,0,2,0,0
0,0,0,0,0,2,6,8,0,0,0,0,0,0,0,0,0,0,0,2,0,0
0,0,3,2,2,2,2,3,0,0,0,0,0,0,0,2,0,0,0,2,0,0
0,0,2,0,0,0,0,2,0,0,0,0,0,0,0,2,5,5,5,2,0,0
0,0,2,0,0,0,0,0,0,0,0,0,3,0,0,3,2,4,2,3,0,0
0,2,2,5,0,0,0,0,0,0,0,0,2,0,0,5,2,2,2,0,0,0
0,2,4,5,0,0,0,2,2,0,0,2,3,0,0,5,4,2,2,0,0,0
0,2,2,5,0,0,0,2,0,0,0,0,2,0,0,5,2,2,0,0,0,0
0,0,3,2,2,2,2,3,0,0,0,0,2,0,0,0,2,0,0,0,0,0
0,0,0,0,0,0,0,0,0,0,0,0,3,2,2,2,3,0,0,0,0,0
0,0,0,0,0,0,0,0,0,0,0,0,0,0,0,0,0,0,0,0,0,0
:endlayer
layer: 2
0,0,0,0,0,0,0,0,0,0,0,0,0,0,0,0,0,0,0,0,0,0
0,0,0,0,0,0,0,0,0,0,0,0,0,0,0,0,0,0,0,0,0,0
0,0,0,0,0,0,0,0,0,0,0,3,2,9,2,9,2,3,0,0,0,0
0,0,0,0,0,0,0,0,2,2,2,2,0,0,0,0,0,0,2,0,0,0
0,0,0,0,0,3,2,3,2,0,2,0,0,0,0,0,0,0,2,0,0,0
0,0,0,0,0,2,0,0,0,0,0,2,0,0,0,0,0,0,2,0,0,0
0,0,0,0,0,9,0,0,0,0,0,3,2,0,0,2,3,2,2,3,0,0
0,0,0,0,0,2,7,0,0,0,0,0,0,0,0,2,0,0,0,2,0,0
0,0,0,0,0,9,10,0,0,0,0,0,0,0,0,0,0,0,0,9,0,0
0,0,0,0,0,2,0,0,0,0,0,0,0,0,0,0,0,0,0,2,0,0
0,0,3,2,2,2,2,3,0,0,0,0,0,0,0,2,0,0,0,9,0,0
0,0,2,0,0,0,0,2,0,0,0,0,0,0,0,2,0,0,0,2,0,0
0,0,2,0,0,0,0,0,0,0,0,0,3,0,0,3,2,0,2,3,0,0
0,2,2,0,0,0,0,0,0,0,0,0,2,0,0,0,2,2,2,0,0,0
0,2,0,0,0,0,0,2,2,0,0,2,3,0,0,0,0,2,11,0,0,0
0,2,2,0,0,0,0,2,0,0,0,0,2,0,0,0,2,2,0,0,0,0
0,0,3,2,9,9,2,3,0,0,0,0,2,0,0,0,2,0,0,0,0,0
0,0,0,0,0,0,0,0,0,0,0,0,3,2,9,2,3,0,0,0,0,0
0,0,0,0,0,0,0,0,0,0,0,0,0,0,0,0,0,0,0,0,0,0
:endlayer
layer: 3
0,0,0,0,0,0,0,0,0,0,0,0,0,0,0,0,0,0,0,0,0,0
0,0,0,0,0,0,0,0,0,0,0,23,0,0,23,0,0,23,0,0,0,0
0,0,0,0,0,0,0,0,0,0,0,3,2,9,2,9,2,3,23,0,0,0
0,0,0,0,0,0,0,0,20,2,11,2,0,0,0,0,0,0,2,0,0,0
0,0,0,0,0,3,2,3,2,16,2,14,0,0,0,0,0,0,2,14,0,0
0,0,0,0,0,2,0,18,0,0,0,2,0,0,0,17,0,0,2,0,0,0
0,0,0,0,0,9,7,0,0,0,21,3,2,14,24,2,3,2,2,3,23,0
0,0,0,0,0,2,10,0,0,0,0,18,0,0,0,2,0,25,0,2,0,0
0,0,0,0,0,9,0,0,0,0,0,0,0,0,0,16,0,0,0,9,0,0
0,0,0,0,0,2,0,17,0,0,0,0,0,0,0,15,0,0,0,2,23,0
0,0,3,2,2,2,2,3,19,0,0,0,0,0,0,2,0,0,0,9,0,0
0,0,2,0,0,0,0,2,0,0,0,0,17,0,0,2,0,0,0,2,0,0
0,0,2,0,0,0,0,16,0,0,0,22,3,14,24,3,2,0,2,3,23,0
0,13,2,0,0,0,0,15,17,0,0,17,2,0,0,0,2,2,11,0,0,0
0,2,14,0,0,0,0,2,2,2,2,2,3,0,0,0,24,2,0,0,0,0
0,12,2,0,0,0,0,2,0,0,0,0,2,0,0,0,2,12,0,0,0,0
0,0,3,2,9,9,2,3,0,0,0,0,2,0,0,0,2,0,0,0,0,0
0,0,0,0,0,0,0,0,0,0,0,0,3,2,9,2,3,0,0,0,0,0
0,0,0,0,0,0,0,0,0,0,0,0,0,0,0,0,0,0,0,0,0,0
:endlayer
layer: 4
0,0,0,0,0,0,0,0,0,0,0,30,0,0,30,0,0,30,0,0,0,0
0,0,0,0,0,0,0,0,0,0,0,27,29,29,27,29,29,27,0,0,0,0
0,0,0,0,0,0,0,0,0,0,0,27,28,28,28,28,28,27,28,31,0,0
0,0,0,0,0,0,0,0,0,2,0,27,29,6,29,6,29,27,2,14,0,0
0,0,0,0,0,3,28,28,28,28,28,27,29,6,29,6,29,27,2,2,0,0
0,0,0,0,0,27,6,6,29,29,29,27,29,6,29,6,29,27,2,14,0,0
0,0,0,0,0,27,10,6,6,6,6,27,28,28,28,28,28,2,2,3,28,31
0,0,0,0,0,27,0,6,29,29,29,27,29,29,29,27,6,6,6,27,29,0
0,0,0,0,0,27,0,6,6,6,6,27,6,6,6,27,29,29,29,27,29,0
0,26,19,0,0,27,0,6,29,29,29,27,29,29,29,27,6,6,6,27,28,31
0,26,3,28,28,28,28,3,6,6,6,27,6,6,6,27,29,29,29,27,29,0
0,26,27,0,0,0,24,2,29,29,29,27,29,29,29,27,6,6,6,27,29,0
0,26,27,0,0,0,24,2,28,28,28,28,28,28,28,28,28,28,28,28,28,31
0,26,27,0,0,0,24,2,29,29,29,29,27,29,29,29,27,2,0,0,0,0
0,2,27,0,0,0,0,3,28,28,28,28,27,6,6,6,27,2,0,0,0,0
0,26,27,0,0,0,0,27,8,0,0,26,27,29,29,29,27,8,0,0,0,0
0,26,3,28,28,28,28,3,8,0,0,26,27,6,6,6,27,8,0,0,0,0
0,26,19,0,0,0,0,22,8,0,0,26,3,28,28,28,3,8,0,0,0,0
0,0,0,0,0,0,0,0,0,0,0,26,19,0,0,0,22,8,0,0,0,0
:endlayer
layer: 5
0,0,0,0,0,0,0,0,0,0,0,0,0,0,0,0,0,0,0,0,0,0
0,0,0,0,0,0,0,0,0,0,0,3,32,32,3,32,32,3,0,0,0,0
0,0,0,0,0,0,0,0,0,0,0,32,0,0,0,0,0,0,3,0,0,0
0,0,0,0,0,0,0,0,0,2,0,32,0,0,0,0,0,5,2,2,0,0
0,0,0,0,0,3,32,32,3,32,32,3,0,0,0,0,0,5,4,2,0,0
0,0,0,0,0,32,0,0,0,26,6,32,0,0,0,0,0,5,2,2,0,0
0,0,0,0,0,3,0,0,0,0,18,3,0,0,3,32,3,2,4,2,3,0
0,0,0,0,0,32,0,35,0,0,0,32,0,0,0,0,32,5,5,5,32,0
0,0,0,0,0,3,0,35,0,0,0,0,0,0,0,0,32,0,0,0,32,0
0,0,26,19,0,32,0,35,0,0,0,0,0,0,0,0,3,0,0,0,3,0
0,0,26,32,32,3,32,3,0,0,0,0,0,0,0,0,0,0,0,0,32,0
0,0,26,33,0,0,2,2,5,0,0,0,0,0,0,0,0,0,0,0,32,0
0,0,26,33,0,21,2,4,5,0,0,0,0,0,0,0,3,32,3,32,3,0
0,0,26,33,0,0,2,2,5,0,0,0,0,0,0,0,32,2,0,0,0,0
0,2,26,33,0,0,34,3,32,32,3,32,32,3,32,32,3,2,0,0,0,0
0,0,26,33,0,0,34,8,0,0,0,0,26,32,32,32,8,0,0,0,0,0
0,0,26,32,32,32,32,8,0,0,0,0,26,32,32,32,8,0,0,0,0,0
0,0,26,19,29,29,22,8,0,0,0,0,26,32,32,32,8,0,0,0,0,0
0,0,0,0,0,0,0,0,0,0,0,0,26,19,29,22,8,0,0,0,0,0
:endlayer
layer: 6
0,0,0,0,0,0,0,0,0,0,0,0,0,0,0,0,0,0,0,0,0,0
0,0,0,0,0,0,0,0,0,0,0,3,9,9,3,9,9,3,0,0,0,0
0,0,0,0,0,0,0,0,0,0,0,9,0,0,0,0,0,0,3,0,0,0
0,0,0,0,0,0,0,0,0,2,0,9,0,0,0,0,0,0,2,2,0,0
0,0,0,0,0,3,9,9,3,32,32,3,0,0,0,0,0,0,0,2,0,0
0,0,0,0,0,32,0,0,0,0,0,32,0,0,0,0,0,0,2,2,0,0
0,0,0,0,0,3,0,0,0,0,36,3,0,0,3,32,3,2,0,2,3,0
0,0,0,0,0,9,0,0,0,0,18,32,0,0,0,0,32,0,0,0,9,0
0,0,0,0,0,3,0,0,0,0,0,25,0,0,0,0,32,0,0,0,9,0
0,0,0,26,19,32,0,0,0,0,0,0,0,0,0,0,3,0,0,0,3,0
0,0,0,26,32,3,32,3,0,0,0,0,0,0,0,0,0,0,0,0,9,0
0,0,0,26,33,34,2,2,0,0,0,0,0,0,0,0,0,0,0,0,9,0
0,0,0,26,33,34,2,0,0,0,0,0,0,0,0,0,3,32,3,9,3,0
0,0,0,26,33,34,2,2,0,0,0,0,0,0,0,0,32,2,0,0,0,0
0,2,0,26,33,34,8,3,9,9,3,9,9,3,32,32,3,12,0,0,0,0
0,0,0,26,33,34,8,0,0,0,0,0,0,26,32,8,0,0,0,0,0,0
0,0,0,26,32,32,8,0,0,0,0,0,0,26,32,8,0,0,0,0,0,0
0,0,0,26,10,10,8,0,0,0,0,0,0,26,32,8,0,0,0,0,0,0
0,0,0,0,0,0,0,0,0,0,0,0,0,26,10,8,0,0,0,0,0,0
:endlayer
layer: 7
0,0,0,0,0,0,0,0,0,0,0,0,0,0,0,0,0,0,0,0,0,0
0,0,0,0,0,0,0,0,0,0,0,3,9,9,3,9,9,3,0,0,0,0
0,0,0,0,0,0,0,0,0,0,0,9,0,0,0,0,0,0,3,0,0,0
0,0,0,0,0,0,0,0,0,2,0,9,0,0,0,0,0,40,2,13,0,0
0,0,0,0,0,3,9,9,3,32,32,3,0,0,0,0,0,0,24,2,0,0
0,0,0,0,0,32,0,0,25,0,0,32,0,0,0,0,0,40,2,12,0,0
0,0,0,0,0,3,0,0,0,0,0,3,33,34,3,32,3,2,16,2,3,0
0,0,0,0,0,9,0,0,0,0,36,32,0,0,0,0,32,0,0,0,9,0
0,0,0,0,0,3,0,0,0,0,18,37,0,0,0,0,32,0,0,0,9,0
0,0,0,0,26,32,0,0,0,0,0,0,0,0,0,21,3,0,0,21,3,0
0,0,0,0,26,3,32,3,0,0,0,0,0,0,0,0,37,0,0,0,9,0
0,0,0,0,26,8,2,2,0,0,0,0,0,0,0,0,39,0,0,0,9,0
0,0,0,0,26,8,2,14,0,0,0,0,0,0,0,0,3,32,3,9,3,0
0,0,0,0,26,8,2,2,0,0,0,0,0,17,0,0,32,2,0,0,0,0
0,2,0,0,26,8,0,3,9,9,3,9,9,3,32,32,3,0,0,0,0,0
0,0,0,0,26,8,0,0,0,0,0,0,0,0,38,0,0,0,0,0,0,0
0,0,0,0,10,10,0,0,0,0,0,0,0,0,38,0,0,0,0,0,0,0
0,0,0,0,0,0,0,0,0,0,0,0,0,0,38,0,0,0,0,0,0,0
0,0,0,0,0,0,0,0,0,0,0,0,0,0,0,0,0,0,0,0,0,0
:endlayer
layer: 8
0,0,0,0,0,0,0,0,0,0,36,36,36,36,36,36,36,36,36,36,0,0
0,0,0,0,0,0,0,0,0,0,18,3,28,28,28,28,28,3,18,18,0,0
0,0,0,0,0,0,0,0,0,0,0,27,0,0,25,0,0,0,3,0,0,0
0,0,0,0,36,36,36,36,36,2,36,27,0,0,0,0,0,2,27,0,0,0
0,0,0,0,18,3,28,28,28,28,28,27,0,0,0,0,0,24,27,2,0,0
0,0,0,0,0,27,0,0,0,0,0,27,0,0,0,0,0,2,27,36,36,36
0,0,0,0,0,27,0,0,0,0,0,27,28,28,28,28,28,28,28,28,3,18
0,0,0,0,0,27,0,0,0,0,0,27,29,29,29,29,27,16,16,16,27,0
0,0,0,0,0,27,7,7,7,7,36,27,6,6,6,6,27,0,0,0,27,0
0,0,0,0,0,27,28,28,28,28,28,27,29,29,29,29,27,0,0,0,27,0
0,0,0,0,7,3,28,3,29,6,29,27,6,6,6,6,27,0,0,0,27,0
0,0,0,0,10,10,2,27,29,6,29,27,29,29,29,29,27,0,0,0,27,0
0,0,0,0,0,0,2,27,29,6,29,27,6,6,6,6,27,28,28,28,3,7
0,0,0,0,0,0,2,27,29,6,29,27,29,29,29,29,27,2,10,10,10,10
0,41,0,0,0,0,7,3,28,28,28,28,28,28,28,28,3,7,0,0,0,0
0,0,0,0,0,0,10,10,10,10,10,10,10,10,10,10,10,10,0,0,0,0
0,0,0,0,0,0,0,0,0,0,0,0,0,0,0,0,0,0,0,0,0,0
0,0,0,0,0,0,0,0,0,0,0,0,0,0,0,0,0,0,0,0,0,0
0,0,0,0,0,0,0,0,0,0,0,0,0,0,0,0,0,0,0,0,0,0
:endlayer
layer: 9
0,0,0,0,0,0,0,0,0,0,0,0,0,0,0,0,0,0,0,0,0,0
0,0,0,0,0,0,0,0,0,0,36,36,36,36,36,36,36,36,36,36,0,0
0,0,0,0,0,0,0,0,0,0,18,32,37,37,37,37,37,37,3,18,0,0
0,0,0,0,0,0,0,0,0,2,0,32,0,0,0,0,0,20,32,0,0,0
0,0,0,0,36,36,36,36,36,36,36,3,0,0,0,0,0,20,3,2,0,0
0,0,0,0,18,32,37,37,37,37,37,32,0,0,0,0,0,20,32,0,0,0
0,0,0,0,0,32,0,0,0,0,0,32,32,32,32,32,32,32,32,6,36,36
0,0,0,0,0,3,0,0,0,0,0,3,0,0,0,0,32,2,2,2,32,18
0,0,0,0,0,32,35,35,35,35,0,35,0,0,0,0,32,0,0,0,32,0
0,0,0,0,7,32,39,39,0,0,0,0,0,0,0,0,32,0,0,0,32,0
0,0,0,0,10,10,10,32,0,0,0,0,0,0,0,0,32,0,0,0,32,0
0,0,0,0,0,0,2,32,0,0,0,0,0,0,0,0,32,39,39,39,32,7
0,0,0,0,0,0,2,32,0,0,17,0,0,17,0,0,32,6,10,10,10,10
0,0,0,0,0,0,2,32,28,28,28,28,28,28,28,28,32,2,0,0,0,0
0,5,0,0,0,0,10,10,10,10,10,10,10,10,10,10,10,10,0,0,0,0
0,0,0,0,0,0,0,0,0,0,0,0,0,0,0,0,0,0,0,0,0,0
0,0,0,0,0,0,0,0,0,0,0,0,0,0,0,0,0,0,0,0,0,0
0,0,0,0,0,0,0,0,0,0,0,0,0,0,0,0,0,0,0,0,0,0
0,0,0,0,0,0,0,0,0,0,0,0,0,0,0,0,0,0,0,0,0,0
:endlayer
layer: 10
0,0,0,0,0,0,0,0,0,0,0,0,0,0,0,0,0,0,0,0,0,0
0,0,0,0,0,0,0,0,0,0,0,0,0,0,0,0,0,0,0,0,0,0
0,0,0,0,0,0,0,0,0,0,36,36,36,36,36,36,36,36,36,36,0,0
0,0,0,0,0,0,0,0,0,2,18,32,37,37,37,37,37,37,32,18,0,0
0,0,0,0,0,0,0,0,0,0,0,3,0,0,0,0,0,24,3,2,0,0
0,0,0,0,36,36,36,36,36,36,6,32,39,39,39,39,39,39,32,7,0,0
0,0,0,0,18,27,37,37,37,37,37,32,28,28,28,28,32,6,10,10,0,0
0,0,0,0,29,32,0,0,0,0,0,3,0,0,0,0,32,6,36,36,36,36
0,0,0,0,7,27,39,39,0,0,0,0,0,0,0,0,32,37,37,37,32,18
0,0,0,0,10,10,10,32,0,0,0,0,0,0,0,0,32,0,0,0,32,0
0,0,0,0,0,0,0,32,0,0,0,0,0,0,0,0,32,39,39,39,32,7
0,0,0,0,0,0,13,32,0,0,0,0,0,0,0,0,32,6,10,10,10,10
0,0,0,0,0,0,2,32,39,39,39,0,0,39,39,39,32,6,0,0,0,0
0,0,0,0,0,0,12,10,10,10,3,9,9,3,10,10,10,2,0,0,0,0
0,0,0,0,0,0,0,0,0,0,23,0,0,23,0,0,0,0,0,0,0,0
0,0,0,0,0,0,0,0,0,0,0,0,0,0,0,0,0,0,0,0,0,0
0,0,0,0,0,0,0,0,0,0,0,0,0,0,0,0,0,0,0,0,0,0
0,0,0,0,0,0,0,0,0,0,0,0,0,0,0,0,0,0,0,0,0,0
0,0,0,0,0,0,0,0,0,0,0,0,0,0,0,0,0,0,0,0,0,0
:endlayer
layer: 11
0,0,0,0,0,0,0,0,0,0,0,0,0,0,0,0,0,0,0,0,0,0
0,0,0,0,0,0,0,0,0,0,0,0,0,0,0,0,0,0,0,0,0,0
0,0,0,0,0,0,0,0,0,0,0,0,0,0,0,0,0,0,0,0,0,0
0,0,0,0,0,0,0,0,0,2,36,36,36,36,36,36,36,36,36,8,0,0
0,0,0,0,0,0,0,0,0,0,26,28,28,28,28,28,28,28,28,2,0,0
0,0,0,0,0,0,0,0,0,0,10,10,10,10,10,10,10,10,10,8,0,0
0,0,0,0,36,36,36,36,36,36,36,36,36,36,36,36,36,36,0,0,0,0
0,0,0,0,26,32,28,28,28,28,28,3,37,37,37,37,32,6,0,0,0,0
0,0,0,0,10,10,10,32,0,0,0,0,0,0,0,0,32,6,36,36,36,8
0,0,0,0,0,0,0,32,42,0,0,0,0,0,0,21,32,28,28,28,28,8
0,0,0,0,0,0,0,32,0,0,0,0,0,0,0,0,32,6,10,10,10,8
0,0,0,0,0,0,7,32,39,39,39,0,0,39,39,39,32,6,0,0,0,0
0,0,0,0,0,0,2,10,10,10,32,0,0,32,10,10,10,10,0,0,0,0
0,0,0,0,0,0,0,0,0,26,3,9,9,3,8,0,0,2,0,0,0,0
0,0,0,0,0,0,0,0,0,26,19,29,29,22,8,0,0,0,0,0,0,0
0,0,0,0,0,0,0,0,0,0,0,0,0,0,0,0,0,0,0,0,0,0
0,0,0,0,0,0,0,0,0,0,0,0,0,0,0,0,0,0,0,0,0,0
0,0,0,0,0,0,0,0,0,0,0,0,0,0,0,0,0,0,0,0,0,0
0,0,0,0,0,0,0,0,0,0,0,0,0,0,0,0,0,0,0,0,0,0
:endlayer
layer: 12
0,0,0,0,0,0,0,0,0,0,0,0,0,0,0,0,0,0,0,0,0,0
0,0,0,0,0,0,0,0,0,0,0,0,0,0,0,0,0,0,0,0,0,0
0,0,0,0,0,0,0,0,0,0,0,0,0,0,0,0,0,0,0,0,0,0
0,0,0,0,0,0,0,0,0,2,0,0,0,0,0,0,0,0,0,0,0,0
0,0,0,0,0,0,0,0,0,0,0,38,38,38,38,38,38,38,38,2,0,0
0,0,0,0,0,0,0,0,0,0,0,0,0,0,0,0,0,0,0,0,0,0
0,0,0,0,0,0,0,0,0,0,0,0,0,0,0,0,0,0,0,0,0,0
0,0,0,0,0,38,36,36,36,36,36,36,36,36,36,36,36,36,0,0,0,0
0,0,0,0,0,0,18,32,37,37,37,37,37,37,37,37,32,6,0,0,0,0
0,0,0,0,0,0,29,32,0,0,0,0,0,0,0,0,32,6,38,38,38,0
0,0,0,0,0,0,7,32,39,39,39,39,39,39,39,39,32,6,0,0,0,0
0,0,0,0,0,0,10,10,10,10,26,33,34,10,10,10,10,10,0,0,0,0
0,0,0,0,0,0,2,0,0,0,26,33,34,8,0,0,0,0,0,0,0,0
0,0,0,0,0,0,0,0,0,0,26,28,28,8,0,0,0,2,0,0,0,0
0,0,0,0,0,0,0,0,0,0,26,10,10,8,0,0,0,0,0,0,0,0
0,0,0,0,0,0,0,0,0,0,0,0,0,0,0,0,0,0,0,0,0,0
0,0,0,0,0,0,0,0,0,0,0,0,0,0,0,0,0,0,0,0,0,0
0,0,0,0,0,0,0,0,0,0,0,0,0,0,0,0,0,0,0,0,0,0
0,0,0,0,0,0,0,0,0,0,0,0,0,0,0,0,0,0,0,0,0,0
:endlayer
layer: 13
0,0,0,0,0,0,0,0,0,0,0,0,0,0,0,0,0,0,0,0,0,0
0,0,0,0,0,0,0,0,0,0,0,0,0,0,0,0,0,0,0,0,0,0
0,0,0,0,0,0,0,0,0,0,0,0,0,0,0,0,0,0,0,0,0,0
0,0,0,0,0,0,0,0,0,41,0,0,0,0,0,0,0,0,0,0,0,0
0,0,0,0,0,0,0,0,0,0,0,0,0,0,0,0,0,0,0,2,0,0
0,0,0,0,0,0,0,0,0,0,0,0,0,0,0,0,0,0,0,0,0,0
0,0,0,0,0,0,0,0,0,0,0,0,0,0,0,0,0,0,0,0,0,0
0,0,0,0,0,0,0,0,0,0,0,0,0,0,0,0,0,0,0,0,0,0
0,0,0,0,0,0,36,36,36,36,36,36,36,36,36,36,36,36,0,0,0,0
0,0,0,0,0,0,26,28,28,28,28,28,28,28,28,28,28,8,0,0,0,0
0,0,0,0,0,0,10,10,10,10,10,26,10,10,10,10,10,10,0,0,0,0
0,0,0,0,0,0,0,0,0,0,0,26,8,0,0,0,0,0,0,0,0,0
0,0,0,0,0,0,2,0,0,0,0,26,8,0,0,0,0,0,0,0,0,0
0,0,0,0,0,0,0,0,0,0,0,10,10,0,0,0,0,2,0,0,0,0
0,0,0,0,0,0,0,0,0,0,0,0,0,0,0,0,0,0,0,0,0,0
0,0,0,0,0,0,0,0,0,0,0,0,0,0,0,0,0,0,0,0,0,0
0,0,0,0,0,0,0,0,0,0,0,0,0,0,0,0,0,0,0,0,0,0
0,0,0,0,0,0,0,0,0,0,0,0,0,0,0,0,0,0,0,0,0,0
0,0,0,0,0,0,0,0,0,0,0,0,0,0,0,0,0,0,0,0,0,0
:endlayer
layer: 14
0,0,0,0,0,0,0,0,0,0,0,0,0,0,0,0,0,0,0,0,0,0
0,0,0,0,0,0,0,0,0,0,0,0,0,0,0,0,0,0,0,0,0,0
0,0,0,0,0,0,0,0,0,0,0,0,0,0,0,0,0,0,0,0,0,0
0,0,0,0,0,0,0,0,0,5,0,0,0,0,0,0,0,0,0,0,0,0
0,0,0,0,0,0,0,0,0,0,0,0,0,0,0,0,0,0,0,41,0,0
0,0,0,0,0,0,0,0,0,0,0,0,0,0,0,0,0,0,0,0,0,0
0,0,0,0,0,0,0,0,0,0,0,0,0,0,0,0,0,0,0,0,0,0
0,0,0,0,0,0,0,0,0,0,0,0,0,0,0,0,0,0,0,0,0,0
0,0,0,0,0,0,0,0,0,0,0,0,0,0,0,0,0,0,0,0,0,0
0,0,0,0,0,0,0,38,38,38,38,38,38,38,38,38,38,0,0,0,0,0
0,0,0,0,0,0,0,0,0,0,0,0,0,0,0,0,0,0,0,0,0,0
0,0,0,0,0,0,0,0,0,0,0,0,0,0,0,0,0,0,0,0,0,0
0,0,0,0,0,0,2,0,0,0,0,0,0,0,0,0,0,0,0,0,0,0
0,0,0,0,0,0,0,0,0,0,0,0,0,0,0,0,0,41,0,0,0,0
0,0,0,0,0,0,0,0,0,0,0,0,0,0,0,0,0,0,0,0,0,0
0,0,0,0,0,0,0,0,0,0,0,0,0,0,0,0,0,0,0,0,0,0
0,0,0,0,0,0,0,0,0,0,0,0,0,0,0,0,0,0,0,0,0,0
0,0,0,0,0,0,0,0,0,0,0,0,0,0,0,0,0,0,0,0,0,0
0,0,0,0,0,0,0,0,0,0,0,0,0,0,0,0,0,0,0,0,0,0
:endlayer
layer: 15
0,0,0,0,0,0,0,0,0,0,0,0,0,0,0,0,0,0,0,0,0,0
0,0,0,0,0,0,0,0,0,0,0,0,0,0,0,0,0,0,0,0,0,0
0,0,0,0,0,0,0,0,0,0,0,0,0,0,0,0,0,0,0,0,0,0
0,0,0,0,0,0,0,0,0,0,0,0,0,0,0,0,0,0,0,0,0,0
0,0,0,0,0,0,0,0,0,0,0,0,0,0,0,0,0,0,0,5,0,0
0,0,0,0,0,0,0,0,0,0,0,0,0,0,0,0,0,0,0,0,0,0
0,0,0,0,0,0,0,0,0,0,0,0,0,0,0,0,0,0,0,0,0,0
0,0,0,0,0,0,0,0,0,0,0,0,0,0,0,0,0,0,0,0,0,0
0,0,0,0,0,0,0,0,0,0,0,0,0,0,0,0,0,0,0,0,0,0
0,0,0,0,0,0,0,0,0,0,0,0,0,0,0,0,0,0,0,0,0,0
0,0,0,0,0,0,0,0,0,0,0,0,0,0,0,0,0,0,0,0,0,0
0,0,0,0,0,0,0,0,0,0,0,0,0,0,0,0,0,0,0,0,0,0
0,0,0,0,0,0,41,0,0,0,0,0,0,0,0,0,0,0,0,0,0,0
0,0,0,0,0,0,0,0,0,0,0,0,0,0,0,0,0,5,0,0,0,0
0,0,0,0,0,0,0,0,0,0,0,0,0,0,0,0,0,0,0,0,0,0
0,0,0,0,0,0,0,0,0,0,0,0,0,0,0,0,0,0,0,0,0,0
0,0,0,0,0,0,0,0,0,0,0,0,0,0,0,0,0,0,0,0,0,0
0,0,0,0,0,0,0,0,0,0,0,0,0,0,0,0,0,0,0,0,0,0
0,0,0,0,0,0,0,0,0,0,0,0,0,0,0,0,0,0,0,0,0,0
:endlayer
layer: 16
0,0,0,0,0,0,0,0,0,0,0,0,0,0,0,0,0,0,0,0,0,0
0,0,0,0,0,0,0,0,0,0,0,0,0,0,0,0,0,0,0,0,0,0
0,0,0,0,0,0,0,0,0,0,0,0,0,0,0,0,0,0,0,0,0,0
0,0,0,0,0,0,0,0,0,0,0,0,0,0,0,0,0,0,0,0,0,0
0,0,0,0,0,0,0,0,0,0,0,0,0,0,0,0,0,0,0,0,0,0
0,0,0,0,0,0,0,0,0,0,0,0,0,0,0,0,0,0,0,0,0,0
0,0,0,0,0,0,0,0,0,0,0,0,0,0,0,0,0,0,0,0,0,0
0,0,0,0,0,0,0,0,0,0,0,0,0,0,0,0,0,0,0,0,0,0
0,0,0,0,0,0,0,0,0,0,0,0,0,0,0,0,0,0,0,0,0,0
0,0,0,0,0,0,0,0,0,0,0,0,0,0,0,0,0,0,0,0,0,0
0,0,0,0,0,0,0,0,0,0,0,0,0,0,0,0,0,0,0,0,0,0
0,0,0,0,0,0,0,0,0,0,0,0,0,0,0,0,0,0,0,0,0,0
0,0,0,0,0,0,5,0,0,0,0,0,0,0,0,0,0,0,0,0,0,0
0,0,0,0,0,0,0,0,0,0,0,0,0,0,0,0,0,0,0,0,0,0
0,0,0,0,0,0,0,0,0,0,0,0,0,0,0,0,0,0,0,0,0,0
0,0,0,0,0,0,0,0,0,0,0,0,0,0,0,0,0,0,0,0,0,0
0,0,0,0,0,0,0,0,0,0,0,0,0,0,0,0,0,0,0,0,0,0
0,0,0,0,0,0,0,0,0,0,0,0,0,0,0,0,0,0,0,0,0,0
0,0,0,0,0,0,0,0,0,0,0,0,0,0,0,0,0,0,0,0,0,0
:endlayer

#### RULES ####
rule:
plugin=vanillaBlocks
number=1
data:
JSON:{blockState:{blockName:"minecraft:grass",properties:{snowy:"false"}}}
:enddata
:endrule

rule:
plugin=vanillaBlocks
number=2
data:
JSON:{blockState:{blockName:"minecraft:cobblestone"}}
:enddata
:endrule

rule:
plugin=vanillaBlocks
number=3
data:
JSON:{blockState:{blockName:"minecraft:log",properties:{variant:"oak",axis:"y"}}}
:enddata
:endrule

rule:
plugin=vanillaBlocks
number=4
data:
JSON:{blockState:{blockName:"ancientwarfarestructure:fire_pit",properties:{lit:"true",variant:"log"}}}
:enddata
:endrule

rule:
plugin=vanillaBlocks
number=5
data:
JSON:{blockState:{blockName:"minecraft:stone_slab",properties:{half:"bottom",variant:"cobblestone"}}}
:enddata
:endrule

rule:
plugin=vanillaBlocks
number=6
data:
JSON:{blockState:{blockName:"minecraft:planks",properties:{variant:"spruce"}}}
:enddata
:endrule

rule:
plugin=vanillaBlocks
number=7
data:
JSON:{blockState:{blockName:"minecraft:spruce_stairs",properties:{half:"top",shape:"straight",facing:"south"}}}
:enddata
:endrule

rule:
plugin=vanillaBlocks
number=8
data:
JSON:{blockState:{blockName:"minecraft:spruce_stairs",properties:{half:"bottom",shape:"straight",facing:"west"}}}
:enddata
:endrule

rule:
plugin=vanillaBlocks
number=9
data:
JSON:{blockState:{blockName:"minecraft:stained_glass_pane",properties:{east:"false",color:"green",south:"false",north:"false",west:"false"}}}
:enddata
:endrule

rule:
plugin=vanillaBlocks
number=10
data:
JSON:{blockState:{blockName:"minecraft:spruce_stairs",properties:{half:"bottom",shape:"straight",facing:"north"}}}
:enddata
:endrule

rule:
plugin=vanillaBlocks
number=11
data:
JSON:{blockState:{blockName:"minecraft:stone_stairs",properties:{half:"bottom",shape:"straight",facing:"west"}}}
:enddata
:endrule

rule:
plugin=vanillaBlocks
number=12
data:
JSON:{blockState:{blockName:"minecraft:stone_stairs",properties:{half:"bottom",shape:"straight",facing:"north"}}}
:enddata
:endrule

rule:
plugin=vanillaBlocks
number=13
data:
JSON:{blockState:{blockName:"minecraft:stone_stairs",properties:{half:"bottom",shape:"straight",facing:"south"}}}
:enddata
:endrule

rule:
plugin=vanillaBlocks
number=14
data:
JSON:{blockState:{blockName:"minecraft:stone_stairs",properties:{half:"top",shape:"straight",facing:"west"}}}
:enddata
:endrule

rule:
plugin=vanillaBlocks
number=15
data:
JSON:{blockState:{blockName:"minecraft:stone_stairs",properties:{half:"top",shape:"straight",facing:"south"}}}
:enddata
:endrule

rule:
plugin=vanillaBlocks
number=16
data:
JSON:{blockState:{blockName:"minecraft:stone_stairs",properties:{half:"top",shape:"straight",facing:"north"}}}
:enddata
:endrule

rule:
plugin=vanillaBlocks
number=17
data:
JSON:{blockState:{blockName:"minecraft:torch",properties:{facing:"north"}}}
:enddata
:endrule

rule:
plugin=vanillaBlocks
number=18
data:
JSON:{blockState:{blockName:"minecraft:spruce_stairs",properties:{half:"top",shape:"straight",facing:"north"}}}
:enddata
:endrule

rule:
plugin=vanillaBlocks
number=19
data:
JSON:{blockState:{blockName:"minecraft:spruce_stairs",properties:{half:"top",shape:"straight",facing:"west"}}}
:enddata
:endrule

rule:
plugin=vanillaBlocks
number=20
data:
JSON:{blockState:{blockName:"minecraft:stone_stairs",properties:{half:"bottom",shape:"straight",facing:"east"}}}
:enddata
:endrule

rule:
plugin=vanillaBlocks
number=21
data:
JSON:{blockState:{blockName:"minecraft:torch",properties:{facing:"west"}}}
:enddata
:endrule

rule:
plugin=vanillaBlocks
number=22
data:
JSON:{blockState:{blockName:"minecraft:spruce_stairs",properties:{half:"top",shape:"straight",facing:"east"}}}
:enddata
:endrule

rule:
plugin=vanillaBlocks
number=23
data:
JSON:{blockState:{blockName:"minecraft:fence",properties:{east:"false",south:"false",north:"false",west:"false"}}}
:enddata
:endrule

rule:
plugin=vanillaBlocks
number=24
data:
JSON:{blockState:{blockName:"minecraft:stone_stairs",properties:{half:"top",shape:"straight",facing:"east"}}}
:enddata
:endrule

rule:
plugin=vanillaBlocks
number=25
data:
JSON:{blockState:{blockName:"minecraft:torch",properties:{facing:"south"}}}
:enddata
:endrule

rule:
plugin=vanillaBlocks
number=26
data:
JSON:{blockState:{blockName:"minecraft:spruce_stairs",properties:{half:"bottom",shape:"straight",facing:"east"}}}
:enddata
:endrule

rule:
plugin=vanillaBlocks
number=27
data:
JSON:{blockState:{blockName:"minecraft:log",properties:{variant:"oak",axis:"z"}}}
:enddata
:endrule

rule:
plugin=vanillaBlocks
number=28
data:
JSON:{blockState:{blockName:"minecraft:log",properties:{variant:"oak",axis:"x"}}}
:enddata
:endrule

rule:
plugin=vanillaBlocks
number=29
data:
JSON:{blockState:{blockName:"minecraft:wooden_slab",properties:{half:"top",variant:"spruce"}}}
:enddata
:endrule

rule:
plugin=vanillaBlocks
number=30
data:
JSON:{blockState:{blockName:"minecraft:trapdoor",properties:{half:"bottom",facing:"north",open:"true"}}}
:enddata
:endrule

rule:
plugin=vanillaBlocks
number=31
data:
JSON:{blockState:{blockName:"minecraft:trapdoor",properties:{half:"bottom",facing:"east",open:"true"}}}
:enddata
:endrule

rule:
plugin=vanillaBlocks
number=32
data:
JSON:{blockState:{blockName:"minecraft:planks",properties:{variant:"oak"}}}
:enddata
:endrule

rule:
plugin=vanillaBlocks
number=33
data:
JSON:{blockState:{blockName:"minecraft:oak_stairs",properties:{half:"top",shape:"straight",facing:"west"}}}
:enddata
:endrule

rule:
plugin=vanillaBlocks
number=34
data:
JSON:{blockState:{blockName:"minecraft:oak_stairs",properties:{half:"top",shape:"straight",facing:"east"}}}
:enddata
:endrule

rule:
plugin=vanillaBlocks
number=35
data:
JSON:{blockState:{blockName:"minecraft:spruce_fence",properties:{east:"false",south:"false",north:"false",west:"false"}}}
:enddata
:endrule

rule:
plugin=vanillaBlocks
number=36
data:
JSON:{blockState:{blockName:"minecraft:spruce_stairs",properties:{half:"bottom",shape:"straight",facing:"south"}}}
:enddata
:endrule

rule:
plugin=vanillaBlocks
number=37
data:
JSON:{blockState:{blockName:"minecraft:oak_stairs",properties:{half:"top",shape:"straight",facing:"north"}}}
:enddata
:endrule

rule:
plugin=vanillaBlocks
number=38
data:
JSON:{blockState:{blockName:"minecraft:wooden_slab",properties:{half:"bottom",variant:"spruce"}}}
:enddata
:endrule

rule:
plugin=vanillaBlocks
number=39
data:
JSON:{blockState:{blockName:"minecraft:oak_stairs",properties:{half:"top",shape:"straight",facing:"south"}}}
:enddata
:endrule

rule:
plugin=vanillaBlocks
number=40
data:
JSON:{blockState:{blockName:"minecraft:stone_slab",properties:{half:"top",variant:"cobblestone"}}}
:enddata
:endrule

rule:
plugin=vanillaBlocks
number=41
data:
JSON:{blockState:{blockName:"minecraft:cobblestone_wall",properties:{east:"false",south:"false",north:"false",variant:"cobblestone",west:"false",up:"false"}}}
:enddata
:endrule

rule:
plugin=vanillaBlocks
number=42
data:
JSON:{blockState:{blockName:"minecraft:torch",properties:{facing:"east"}}}
:enddata
:endrule

#### ENTITIES ####
