# Ancient Warfare Structure Template File
# Auto-generated structure template file. created on: 6/4/2021 at: 18:19:48
# Lines beginning with # denote comments

header:
version=2.11
name=SurvivalBuild_house_type1_6r_1
mods=
size=22,19,16
offset=11,1,15
:endheader

#### VALIDATION ####
validation:
type=ground
structureAuthor=theoddlyseagull
survival=true
worldGenEnabled=false
unique=false
preserveBlocks=false
preventNaturalHostileSpawns=false
selectionWeight=1
clusterValue=1
minDuplicateDistance=1
dimensionWhiteList=true
dimensionList=
biomeGroupList=
biomeWhiteList=true
biomeList=
leveling=0
fill=0
border=0
blockSwap=false
territoryName=
biomeReplacement=minecraft:
minGenerationHeight=0
maxGenerationHeight=255
:endvalidation

#### LAYERS ####
layer: 0
1,1,1,1,1,1,1,1,1,2,2,1,1,1,1,1,1,1,1,1,1,1
1,1,1,1,1,1,1,1,1,2,2,1,1,1,2,2,2,2,2,2,2,1
1,1,1,1,1,1,1,1,1,2,2,1,1,1,2,2,2,2,2,2,2,2
1,1,1,1,1,2,2,2,2,2,2,2,2,2,2,2,2,2,2,2,2,2
1,1,1,1,1,2,2,2,2,2,2,2,2,2,2,2,2,2,2,2,2,2
1,2,2,2,2,2,2,2,2,2,2,2,2,2,2,2,2,2,2,2,2,1
1,2,2,2,2,2,2,2,2,2,2,2,2,2,2,2,2,2,2,1,1,1
1,2,2,2,2,2,2,2,2,2,2,2,2,2,2,2,2,2,2,1,1,1
1,2,2,2,2,2,2,2,2,2,2,2,2,2,2,2,2,2,2,1,1,1
1,2,2,2,2,2,2,2,2,2,2,2,2,2,2,2,2,2,2,1,1,1
1,2,2,2,2,2,2,2,2,2,2,2,2,2,2,2,2,2,2,2,1,1
1,2,2,2,2,2,2,2,2,2,2,2,2,2,2,2,2,2,2,2,2,1
1,2,2,2,2,2,2,2,2,2,2,2,2,2,2,2,2,2,2,2,2,1
1,1,2,2,2,2,2,2,2,2,2,2,2,2,2,2,2,2,2,2,2,1
1,1,1,1,1,1,1,2,2,2,2,2,2,2,2,1,1,1,2,2,1,1
1,1,1,1,1,1,1,1,1,1,2,2,1,1,1,1,1,1,1,1,1,1
:endlayer
layer: 1
0,0,0,0,0,0,0,0,0,0,0,0,0,0,0,0,0,0,0,0,0,0
0,0,0,0,0,0,0,0,0,0,0,0,0,0,3,8,3,8,3,8,3,0
0,0,0,0,0,0,0,0,0,0,0,0,0,0,8,0,0,0,0,6,2,2
0,0,0,0,0,3,8,8,3,0,0,3,8,8,3,0,0,0,0,6,4,2
0,0,0,0,0,8,0,0,0,0,0,0,0,0,8,0,0,0,0,6,2,2
0,3,2,2,2,3,2,0,0,0,0,0,0,2,3,8,0,8,3,8,3,0
0,2,0,0,0,0,0,0,0,0,0,0,0,0,2,0,0,0,2,0,0,0
0,2,0,3,0,0,0,0,0,0,0,0,0,0,0,0,0,0,3,0,0,0
0,2,0,5,7,0,0,0,0,0,9,0,0,0,0,0,0,0,2,0,0,0
0,3,2,2,2,3,0,0,0,0,0,0,0,0,0,0,0,0,2,0,0,0
0,2,2,2,6,0,0,0,0,0,0,0,0,0,0,0,0,0,2,2,0,0
0,2,2,4,6,0,0,0,0,0,0,0,0,0,0,0,0,0,3,2,2,0
0,2,2,2,6,0,0,2,0,0,0,0,0,0,2,0,0,0,2,2,2,0
0,0,2,3,2,2,2,3,0,0,0,0,0,0,3,2,2,2,3,2,2,0
0,0,0,0,0,0,0,3,2,3,0,0,3,2,3,0,0,0,2,2,0,0
0,0,0,0,0,0,0,0,0,0,0,0,0,0,0,0,0,0,0,0,0,0
:endlayer
layer: 2
0,0,0,0,0,0,0,0,0,0,0,0,0,0,0,0,0,0,0,0,0,0
0,0,0,0,0,0,0,0,0,0,0,0,0,0,3,8,3,10,3,8,3,0
0,0,0,0,0,0,0,0,0,0,0,0,0,0,8,0,0,0,0,0,2,2
0,0,0,0,0,3,10,10,3,0,0,3,10,10,3,0,0,0,0,0,0,2
0,0,0,0,0,8,0,0,0,0,0,0,0,0,8,0,0,0,0,0,2,2
0,3,2,10,2,3,2,0,0,0,0,0,0,2,3,8,0,8,3,8,3,0
0,2,0,0,0,0,0,0,0,0,0,0,0,0,2,0,0,0,2,0,0,0
0,10,5,3,0,0,0,0,0,0,0,0,0,0,0,0,0,0,3,0,0,0
0,2,7,0,0,0,0,0,0,0,0,0,0,0,0,0,0,0,2,0,0,0
0,3,2,2,2,3,0,0,0,0,0,0,0,0,0,0,0,0,10,0,0,0
0,2,2,2,0,0,0,0,0,0,0,0,0,0,0,0,0,0,2,2,0,0
0,2,2,0,0,0,0,0,0,0,0,0,0,0,0,0,0,0,3,2,2,0
0,2,2,2,0,0,0,2,0,0,0,0,0,0,2,0,0,0,2,2,2,0
0,0,2,3,2,10,2,3,0,0,0,0,0,0,3,2,10,2,3,2,2,0
0,0,0,0,0,0,0,3,2,3,0,0,3,2,3,0,0,0,2,2,0,0
0,0,0,0,0,0,0,0,0,0,0,0,0,0,0,0,0,0,0,0,0,0
:endlayer
layer: 3
0,0,0,0,0,0,0,0,0,0,0,0,0,0,0,0,0,0,0,0,0,0
0,0,0,0,0,0,0,0,0,0,0,0,0,0,3,8,3,10,3,8,3,0
0,0,0,0,0,0,0,0,16,0,0,16,0,0,8,0,0,0,0,0,2,21
0,0,0,0,0,3,10,10,3,8,8,3,10,10,3,0,0,0,0,0,18,2
0,0,0,0,0,8,16,0,0,0,0,0,0,0,8,0,0,0,0,0,2,13
0,3,2,10,2,3,2,14,0,0,0,0,18,2,3,8,8,8,3,8,3,0
11,2,7,5,0,0,0,0,0,0,0,0,0,19,2,0,0,0,2,0,0,0
0,10,0,3,15,0,0,0,0,0,0,0,0,0,20,0,0,19,3,11,0,0
11,2,0,0,0,0,0,0,0,0,0,0,0,0,0,0,0,0,2,0,0,0
0,3,2,2,2,3,0,0,0,0,0,0,0,0,0,0,0,0,10,0,0,0
0,12,2,2,0,0,0,0,0,0,0,0,0,0,0,0,0,0,2,21,0,0
0,12,2,14,0,0,0,17,0,0,0,0,0,0,17,0,0,19,3,2,22,0
0,12,2,2,0,0,0,2,15,0,0,0,0,19,2,0,0,0,2,2,22,0
0,0,13,3,2,10,2,3,0,0,0,0,0,0,3,2,10,2,3,2,22,0
0,0,0,11,0,0,0,3,2,3,2,2,3,2,3,0,0,0,13,13,0,0
0,0,0,0,0,0,0,0,0,11,0,0,11,0,0,0,0,0,0,0,0,0
:endlayer
layer: 4
0,0,0,0,0,0,0,0,0,0,0,0,0,29,29,29,29,29,29,29,29,29
0,0,0,0,0,0,0,0,0,0,0,0,0,28,3,24,24,24,24,24,3,28
0,0,0,0,5,27,5,5,27,5,5,27,5,5,23,0,0,0,0,0,23,0
0,0,0,0,5,3,24,24,24,24,24,24,24,24,23,0,0,0,0,0,23,2
0,0,0,0,0,23,0,0,0,0,0,0,0,0,23,0,0,0,0,0,23,0
0,3,24,24,24,3,24,24,24,24,24,24,24,24,23,24,24,24,3,24,3,27
7,23,0,0,7,23,5,26,5,26,5,26,5,26,23,5,5,5,23,31,31,31
5,23,0,3,5,23,5,26,5,26,5,26,5,26,23,26,26,26,23,30,0,0
7,23,0,0,0,23,5,26,5,26,5,26,5,26,23,5,5,5,23,5,0,0
0,3,24,24,24,3,24,24,24,24,24,24,24,24,23,26,26,26,23,5,0,0
0,0,2,2,2,5,5,23,5,23,5,26,5,26,23,5,5,5,23,30,0,0
0,0,2,2,2,26,26,23,5,23,5,26,5,26,23,26,26,26,2,2,0,0
0,0,2,2,2,5,5,23,5,23,5,26,5,26,23,5,5,5,2,2,0,0
0,0,0,23,24,24,24,23,5,23,5,26,5,26,23,24,24,24,23,2,0,0
0,0,0,23,5,5,5,3,24,24,24,24,24,24,3,5,5,5,23,0,0,0
0,0,0,25,0,0,0,0,0,28,5,5,28,0,0,0,0,0,25,0,0,0
:endlayer
layer: 5
0,0,0,0,0,0,0,0,0,0,0,0,0,0,0,0,0,0,0,0,0,0
0,0,0,0,0,0,0,0,0,0,0,0,0,29,29,29,29,29,29,29,29,29
0,0,0,0,0,0,0,0,0,0,0,0,0,28,8,33,33,33,33,33,8,28
0,0,0,0,7,7,7,7,7,7,7,7,7,26,8,0,0,0,0,0,8,2
0,0,0,0,26,26,26,26,26,26,26,26,26,26,8,32,32,32,32,32,8,27
0,3,8,8,8,3,8,8,3,8,3,8,8,3,8,3,8,8,3,31,31,31
0,8,0,0,0,0,0,0,0,0,0,0,0,0,8,0,0,0,8,0,0,0
0,8,0,3,0,0,0,0,0,0,0,0,0,0,3,0,0,0,3,11,0,0
0,8,0,5,7,0,0,0,0,0,0,0,0,0,0,0,0,0,0,11,0,0
0,3,8,8,8,3,8,3,0,3,0,3,8,8,3,0,0,0,0,11,0,0
0,0,2,2,6,0,0,0,0,8,0,0,0,0,8,0,0,0,3,11,0,0
0,0,2,4,6,0,0,0,0,8,0,0,0,0,8,0,0,6,2,2,0,0
0,0,2,2,6,0,0,0,0,8,0,0,0,0,8,0,0,6,4,2,0,0
0,0,0,8,0,0,0,0,0,8,0,0,0,0,8,0,0,6,2,2,0,0
0,0,0,3,8,8,8,3,8,3,0,0,3,8,3,8,8,8,3,0,0,0
0,0,0,0,0,0,0,0,0,11,11,11,11,0,0,0,0,0,0,0,0,0
:endlayer
layer: 6
0,0,0,0,0,0,0,0,0,0,0,0,0,0,0,0,0,0,0,0,0,0
0,0,0,0,0,0,0,0,0,0,0,0,0,0,0,0,0,0,0,0,0,0
0,0,0,0,0,0,0,0,0,0,0,0,0,29,29,29,29,29,29,29,29,35
0,0,0,0,0,0,0,0,0,0,0,0,0,34,24,24,24,24,24,24,24,2
0,0,0,0,0,16,0,0,16,0,16,0,0,31,31,31,31,31,31,31,31,35
0,3,8,10,8,3,10,10,3,8,3,10,10,3,8,3,8,8,3,0,0,0
0,8,0,0,0,0,0,0,0,0,0,0,0,0,8,0,0,0,10,0,0,0
0,10,5,3,0,0,0,0,0,0,0,0,0,0,3,0,0,0,3,0,0,0
0,8,7,0,0,0,0,0,0,0,0,0,0,0,0,0,0,0,0,0,0,0
0,3,8,8,8,3,8,3,0,3,0,3,8,8,3,0,0,0,0,0,0,0
0,0,2,2,0,0,0,0,0,8,0,0,0,0,8,0,0,0,3,0,0,0
0,0,2,0,0,0,0,0,0,8,0,0,0,0,8,0,0,0,2,2,0,0
0,0,2,2,0,0,0,0,0,8,0,0,0,0,8,0,0,0,0,2,0,0
0,0,0,8,0,0,0,0,0,8,0,0,0,0,8,0,0,0,2,2,0,0
0,0,0,3,8,10,8,3,10,3,0,0,3,10,3,8,10,8,3,0,0,0
0,0,0,0,0,0,0,0,0,0,0,0,0,0,0,0,0,0,0,0,0,0
:endlayer
layer: 7
0,0,0,0,0,0,0,0,0,0,0,0,0,0,0,0,0,0,0,0,0,0
0,0,0,0,0,0,0,0,0,0,0,0,0,0,0,0,0,0,0,0,0,0
0,0,0,0,0,0,0,0,0,0,0,0,0,0,0,0,0,0,0,0,0,0
0,0,0,0,0,0,0,0,0,0,0,0,0,0,7,7,7,7,7,7,7,2
0,0,11,0,11,0,0,0,0,0,0,0,0,0,0,0,0,0,0,0,0,0
0,3,8,10,8,3,10,10,3,8,3,10,10,3,8,3,8,8,3,0,0,0
11,8,7,5,0,0,0,0,0,0,0,0,0,0,8,0,0,0,10,0,0,0
0,10,0,3,0,0,0,0,0,0,0,0,0,0,3,0,0,19,3,0,0,0
11,8,0,0,0,0,0,16,0,0,0,16,0,0,8,0,0,0,8,0,0,0
0,3,8,8,8,3,8,3,8,3,8,3,8,8,3,0,0,0,8,0,0,0
0,0,21,2,0,0,0,36,0,8,0,0,0,0,8,0,0,0,3,0,0,0
0,0,2,14,0,0,0,0,0,8,0,0,0,0,8,0,0,0,2,21,0,0
0,0,13,2,0,0,0,0,0,8,0,0,0,0,8,0,0,0,0,2,0,0
0,0,0,8,0,0,0,0,0,8,0,0,16,0,8,0,0,0,2,13,0,0
0,0,0,3,8,10,8,3,10,3,8,8,3,10,3,8,10,8,3,0,0,0
0,0,0,0,0,0,0,0,0,0,0,0,0,0,0,0,0,0,0,0,0,0
:endlayer
layer: 8
0,0,0,0,0,0,0,0,0,0,0,0,0,0,0,0,0,0,0,0,0,0
0,0,0,0,0,0,0,0,0,0,0,0,0,0,0,0,0,0,0,0,0,0
0,0,0,0,0,0,0,0,0,0,0,0,0,0,0,0,0,0,0,0,0,0
0,0,0,0,0,0,0,0,0,0,0,0,0,0,0,0,0,0,0,0,0,2
0,0,7,5,7,29,29,29,29,29,29,29,29,29,29,29,29,29,29,29,0,0
0,3,24,24,24,3,24,24,24,24,24,24,24,24,24,24,24,24,3,28,0,0
7,23,0,0,7,23,5,26,5,26,5,26,5,26,23,5,5,5,23,0,0,0
5,23,0,3,5,23,5,26,5,26,5,26,5,26,23,26,26,26,23,0,0,0
7,23,0,5,5,23,5,26,5,26,5,26,5,26,23,5,5,5,23,0,0,0
0,3,24,24,24,24,24,24,24,24,24,24,24,24,23,26,26,26,23,0,0,0
0,0,0,23,5,26,5,26,5,23,26,26,26,26,23,5,5,5,23,0,0,0
0,0,2,23,5,26,5,26,5,23,5,5,5,5,23,26,26,26,23,0,0,0
0,0,0,23,5,26,5,26,5,23,26,26,26,26,23,5,5,5,23,2,0,0
0,0,0,23,5,26,5,26,5,23,5,5,5,5,23,26,26,26,23,0,0,0
0,0,27,3,24,24,24,24,24,24,24,24,24,24,24,24,24,24,3,27,0,0
0,0,31,31,31,31,31,34,30,0,0,0,0,37,35,31,31,31,31,31,0,0
:endlayer
layer: 9
0,0,0,0,0,0,0,0,0,0,0,0,0,0,0,0,0,0,0,0,0,0
0,0,0,0,0,0,0,0,0,0,0,0,0,0,0,0,0,0,0,0,0,0
0,0,0,0,0,0,0,0,0,0,0,0,0,0,0,0,0,0,0,0,0,0
0,0,0,0,0,0,0,0,0,0,0,0,0,0,0,0,0,0,0,0,0,2
0,0,0,9,0,0,0,0,0,0,0,0,0,0,0,0,0,0,0,0,0,0
0,3,8,8,8,3,29,29,29,29,29,29,29,29,29,29,29,29,29,29,0,0
0,8,0,0,0,8,8,3,8,8,3,8,8,8,3,8,8,3,8,28,0,0
9,8,0,3,0,0,0,0,0,0,0,0,0,0,0,0,0,0,8,0,0,0
0,8,0,11,0,0,0,0,0,0,0,0,0,0,0,0,0,0,3,0,0,0
0,3,8,8,8,3,0,0,0,0,9,0,0,0,0,0,0,0,8,0,0,0
0,0,0,8,0,0,0,0,0,0,0,0,0,0,0,0,0,0,8,0,0,0
0,0,2,3,0,0,0,0,0,0,0,0,0,0,0,0,0,0,3,0,0,0
0,0,0,8,0,0,0,0,0,0,0,0,0,0,0,0,0,0,8,2,0,0
0,0,27,8,8,3,8,8,3,8,8,8,8,3,8,8,3,8,8,27,0,0
0,0,31,31,31,31,31,31,34,8,8,8,8,35,31,31,31,31,31,31,0,0
0,0,0,0,0,0,0,0,34,30,5,5,37,35,0,0,0,0,0,0,0,0
:endlayer
layer: 10
0,0,0,0,0,0,0,0,0,0,0,0,0,0,0,0,0,0,0,0,0,0
0,0,0,0,0,0,0,0,0,0,0,0,0,0,0,0,0,0,0,0,0,0
0,0,0,0,0,0,0,0,0,0,0,0,0,0,0,0,0,0,0,0,0,0
0,0,0,0,0,0,0,0,0,0,0,0,0,0,0,0,0,0,0,0,0,38
0,0,0,0,0,0,0,0,0,0,0,0,0,0,0,0,0,0,0,0,0,0
0,3,8,10,8,3,0,0,0,0,0,0,0,0,0,0,0,0,0,0,0,0
0,8,0,0,0,8,29,3,10,10,3,29,29,29,3,10,10,3,29,29,0,0
0,10,0,3,0,33,33,33,0,0,33,33,33,33,33,0,0,33,8,28,0,0
0,8,0,0,0,0,0,0,0,0,0,0,0,0,0,0,0,19,3,0,0,0
0,3,8,8,8,3,0,0,0,0,0,0,0,0,0,0,0,0,10,0,0,0
0,0,0,8,0,0,0,0,0,0,0,0,0,0,0,0,0,0,10,0,0,0
0,0,2,3,15,0,0,0,0,0,0,0,0,0,0,0,0,19,3,0,0,0
0,0,27,8,32,32,0,0,32,32,32,32,32,32,0,0,32,32,8,2,0,0
0,0,31,31,31,3,10,10,3,31,8,8,31,3,10,10,3,31,31,31,0,0
0,0,0,0,0,0,0,0,0,34,8,8,35,0,0,0,0,0,0,0,0,0
0,0,0,0,0,0,0,0,0,34,31,31,35,0,0,0,0,0,0,0,0,0
:endlayer
layer: 11
0,0,0,0,0,0,0,0,0,0,0,0,0,0,0,0,0,0,0,0,0,0
0,0,0,0,0,0,0,0,0,0,0,0,0,0,0,0,0,0,0,0,0,0
0,0,0,0,0,0,0,0,0,0,0,0,0,0,0,0,0,0,0,0,0,0
0,0,0,0,0,0,0,0,0,0,0,0,0,0,0,0,0,0,0,0,0,6
0,0,11,0,11,0,0,0,0,0,0,0,0,0,0,0,0,0,0,0,0,0
0,3,8,10,8,3,34,30,0,0,37,35,0,34,30,0,0,37,35,0,0,0
11,8,0,0,0,8,34,3,10,10,3,35,0,34,3,10,10,3,35,0,0,0
0,10,0,3,0,8,29,8,0,0,8,29,29,29,8,0,0,8,29,29,0,0
11,8,0,0,0,33,33,33,0,0,33,33,33,33,33,0,0,33,3,28,0,0
0,3,8,8,8,3,0,0,0,0,0,0,0,0,0,0,0,0,10,5,0,0
0,0,0,8,0,0,0,0,0,0,0,0,0,0,0,0,0,0,10,5,0,0
0,0,2,3,32,32,0,0,32,32,32,32,32,32,0,0,32,32,3,27,0,0
0,0,31,31,31,8,0,0,8,31,34,31,31,8,0,0,8,31,31,2,0,0
0,0,0,0,34,3,10,10,3,35,34,35,34,3,10,10,3,35,0,0,0,0
0,0,0,0,34,30,0,0,37,35,31,35,34,30,0,0,37,35,0,0,0,0
0,0,0,0,0,0,0,0,0,0,0,0,0,0,0,0,0,0,0,0,0,0
:endlayer
layer: 12
0,0,0,0,0,0,0,0,0,0,0,0,0,0,0,0,0,0,0,0,0,0
0,0,0,0,0,0,0,0,0,0,0,0,0,0,0,0,0,0,0,0,0,0
0,0,0,0,0,0,0,0,0,0,0,0,0,0,0,0,0,0,0,0,0,0
0,0,0,0,0,0,0,0,0,0,0,0,0,0,0,0,0,0,0,0,0,0
0,0,7,5,7,0,0,0,0,0,0,0,0,0,0,0,0,0,0,0,0,0
0,3,24,24,24,3,0,34,29,29,29,0,0,0,34,29,29,35,0,0,0,0
7,23,0,0,0,23,0,34,24,24,35,0,0,0,34,24,24,35,0,0,0,0
5,23,0,3,0,23,0,34,39,40,35,0,0,0,34,39,40,35,0,0,0,0
7,23,0,0,0,23,29,29,39,40,35,29,29,29,29,39,40,35,29,29,0,0
0,3,24,24,24,3,33,33,33,33,33,33,33,33,33,33,33,33,23,35,0,0
0,0,27,8,32,32,32,32,32,32,32,32,32,32,32,32,32,32,23,35,0,0
0,0,2,31,31,34,39,40,35,31,31,31,31,31,39,40,31,31,31,31,0,0
0,0,0,0,0,34,39,40,35,0,0,0,0,34,39,40,35,0,0,2,0,0
0,0,0,0,0,34,24,24,35,0,0,0,0,34,24,24,35,0,0,0,0,0
0,0,0,0,0,34,31,31,35,0,0,0,0,34,31,31,35,0,0,0,0,0
0,0,0,0,0,0,0,0,0,0,0,0,0,0,0,0,0,0,0,0,0,0
:endlayer
layer: 13
0,0,0,0,0,0,0,0,0,0,0,0,0,0,0,0,0,0,0,0,0,0
0,0,0,0,0,0,0,0,0,0,0,0,0,0,0,0,0,0,0,0,0,0
0,0,0,0,0,0,0,0,0,0,0,0,0,0,0,0,0,0,0,0,0,0
0,0,0,0,0,0,0,0,0,0,0,0,0,0,0,0,0,0,0,0,0,0
5,27,5,0,5,27,5,0,0,0,0,0,0,0,0,0,0,0,0,0,0,0
37,3,8,8,8,3,30,0,0,0,0,0,0,0,0,0,0,0,0,0,0,0
5,8,0,16,0,8,5,0,29,29,0,0,0,0,0,29,29,0,0,0,0,0
0,8,19,3,15,8,0,0,34,35,0,0,0,0,0,34,35,0,0,0,0,0
5,8,0,36,0,8,5,0,34,35,0,0,0,0,0,34,35,0,0,0,0,0
37,3,8,8,8,3,26,29,29,35,29,29,29,29,29,34,35,29,35,0,0,0
5,28,26,31,26,26,26,35,31,31,31,31,31,31,34,35,31,31,35,0,0,0
0,0,2,0,0,0,34,35,0,0,0,0,0,0,34,35,0,0,0,0,0,0
0,0,0,0,0,0,34,35,0,0,0,0,0,0,34,35,0,0,0,2,0,0
0,0,0,0,0,0,31,31,0,0,0,0,0,0,31,31,0,0,0,0,0,0
0,0,0,0,0,0,0,0,0,0,0,0,0,0,0,0,0,0,0,0,0,0
0,0,0,0,0,0,0,0,0,0,0,0,0,0,0,0,0,0,0,0,0,0
:endlayer
layer: 14
0,0,0,0,0,0,0,0,0,0,0,0,0,0,0,0,0,0,0,0,0,0
0,0,0,0,0,0,0,0,0,0,0,0,0,0,0,0,0,0,0,0,0,0
0,0,0,0,0,0,0,0,0,0,0,0,0,0,0,0,0,0,0,0,0,0
0,0,0,0,0,0,0,0,0,0,0,0,0,0,0,0,0,0,0,0,0,0
34,29,29,29,29,29,29,0,0,0,0,0,0,0,0,0,0,0,0,0,0,0
34,3,24,24,24,3,35,0,0,0,0,0,0,0,0,0,0,0,0,0,0,0
34,23,0,23,0,23,35,0,0,0,0,0,0,0,0,0,0,0,0,0,0,0
34,23,24,3,24,23,35,0,0,0,0,0,0,0,0,0,0,0,0,0,0,0
34,23,0,23,0,23,35,0,0,0,0,0,0,0,0,0,0,0,0,0,0,0
34,3,24,24,24,3,35,0,0,0,0,0,0,0,0,0,0,0,0,0,0,0
31,31,31,31,31,31,35,0,0,0,0,0,0,0,0,0,0,0,0,0,0,0
0,0,2,0,0,0,0,0,0,0,0,0,0,0,0,0,0,0,0,0,0,0
0,0,0,0,0,0,0,0,0,0,0,0,0,0,0,0,0,0,0,2,0,0
0,0,0,0,0,0,0,0,0,0,0,0,0,0,0,0,0,0,0,0,0,0
0,0,0,0,0,0,0,0,0,0,0,0,0,0,0,0,0,0,0,0,0,0
0,0,0,0,0,0,0,0,0,0,0,0,0,0,0,0,0,0,0,0,0,0
:endlayer
layer: 15
0,0,0,0,0,0,0,0,0,0,0,0,0,0,0,0,0,0,0,0,0,0
0,0,0,0,0,0,0,0,0,0,0,0,0,0,0,0,0,0,0,0,0,0
0,0,0,0,0,0,0,0,0,0,0,0,0,0,0,0,0,0,0,0,0,0
0,0,0,0,0,0,0,0,0,0,0,0,0,0,0,0,0,0,0,0,0,0
0,0,0,0,0,0,0,0,0,0,0,0,0,0,0,0,0,0,0,0,0,0
0,34,29,29,29,29,0,0,0,0,0,0,0,0,0,0,0,0,0,0,0,0
0,34,39,33,33,35,0,0,0,0,0,0,0,0,0,0,0,0,0,0,0,0
0,34,39,3,40,35,0,0,0,0,0,0,0,0,0,0,0,0,0,0,0,0
0,34,32,32,40,35,0,0,0,0,0,0,0,0,0,0,0,0,0,0,0,0
0,31,31,31,31,35,0,0,0,0,0,0,0,0,0,0,0,0,0,0,0,0
0,0,0,0,0,0,0,0,0,0,0,0,0,0,0,0,0,0,0,0,0,0
0,0,2,0,0,0,0,0,0,0,0,0,0,0,0,0,0,0,0,0,0,0
0,0,0,0,0,0,0,0,0,0,0,0,0,0,0,0,0,0,0,38,0,0
0,0,0,0,0,0,0,0,0,0,0,0,0,0,0,0,0,0,0,0,0,0
0,0,0,0,0,0,0,0,0,0,0,0,0,0,0,0,0,0,0,0,0,0
0,0,0,0,0,0,0,0,0,0,0,0,0,0,0,0,0,0,0,0,0,0
:endlayer
layer: 16
0,0,0,0,0,0,0,0,0,0,0,0,0,0,0,0,0,0,0,0,0,0
0,0,0,0,0,0,0,0,0,0,0,0,0,0,0,0,0,0,0,0,0,0
0,0,0,0,0,0,0,0,0,0,0,0,0,0,0,0,0,0,0,0,0,0
0,0,0,0,0,0,0,0,0,0,0,0,0,0,0,0,0,0,0,0,0,0
0,0,0,0,0,0,0,0,0,0,0,0,0,0,0,0,0,0,0,0,0,0
0,0,0,0,0,0,0,0,0,0,0,0,0,0,0,0,0,0,0,0,0,0
0,0,29,29,35,0,0,0,0,0,0,0,0,0,0,0,0,0,0,0,0,0
0,0,34,3,35,0,0,0,0,0,0,0,0,0,0,0,0,0,0,0,0,0
0,0,34,31,31,0,0,0,0,0,0,0,0,0,0,0,0,0,0,0,0,0
0,0,0,0,0,0,0,0,0,0,0,0,0,0,0,0,0,0,0,0,0,0
0,0,0,0,0,0,0,0,0,0,0,0,0,0,0,0,0,0,0,0,0,0
0,0,2,0,0,0,0,0,0,0,0,0,0,0,0,0,0,0,0,0,0,0
0,0,0,0,0,0,0,0,0,0,0,0,0,0,0,0,0,0,0,6,0,0
0,0,0,0,0,0,0,0,0,0,0,0,0,0,0,0,0,0,0,0,0,0
0,0,0,0,0,0,0,0,0,0,0,0,0,0,0,0,0,0,0,0,0,0
0,0,0,0,0,0,0,0,0,0,0,0,0,0,0,0,0,0,0,0,0,0
:endlayer
layer: 17
0,0,0,0,0,0,0,0,0,0,0,0,0,0,0,0,0,0,0,0,0,0
0,0,0,0,0,0,0,0,0,0,0,0,0,0,0,0,0,0,0,0,0,0
0,0,0,0,0,0,0,0,0,0,0,0,0,0,0,0,0,0,0,0,0,0
0,0,0,0,0,0,0,0,0,0,0,0,0,0,0,0,0,0,0,0,0,0
0,0,0,0,0,0,0,0,0,0,0,0,0,0,0,0,0,0,0,0,0,0
0,0,0,0,0,0,0,0,0,0,0,0,0,0,0,0,0,0,0,0,0,0
0,0,0,0,0,0,0,0,0,0,0,0,0,0,0,0,0,0,0,0,0,0
0,0,0,7,0,0,0,0,0,0,0,0,0,0,0,0,0,0,0,0,0,0
0,0,0,0,0,0,0,0,0,0,0,0,0,0,0,0,0,0,0,0,0,0
0,0,0,0,0,0,0,0,0,0,0,0,0,0,0,0,0,0,0,0,0,0
0,0,0,0,0,0,0,0,0,0,0,0,0,0,0,0,0,0,0,0,0,0
0,0,38,0,0,0,0,0,0,0,0,0,0,0,0,0,0,0,0,0,0,0
0,0,0,0,0,0,0,0,0,0,0,0,0,0,0,0,0,0,0,0,0,0
0,0,0,0,0,0,0,0,0,0,0,0,0,0,0,0,0,0,0,0,0,0
0,0,0,0,0,0,0,0,0,0,0,0,0,0,0,0,0,0,0,0,0,0
0,0,0,0,0,0,0,0,0,0,0,0,0,0,0,0,0,0,0,0,0,0
:endlayer
layer: 18
0,0,0,0,0,0,0,0,0,0,0,0,0,0,0,0,0,0,0,0,0,0
0,0,0,0,0,0,0,0,0,0,0,0,0,0,0,0,0,0,0,0,0,0
0,0,0,0,0,0,0,0,0,0,0,0,0,0,0,0,0,0,0,0,0,0
0,0,0,0,0,0,0,0,0,0,0,0,0,0,0,0,0,0,0,0,0,0
0,0,0,0,0,0,0,0,0,0,0,0,0,0,0,0,0,0,0,0,0,0
0,0,0,0,0,0,0,0,0,0,0,0,0,0,0,0,0,0,0,0,0,0
0,0,0,0,0,0,0,0,0,0,0,0,0,0,0,0,0,0,0,0,0,0
0,0,0,0,0,0,0,0,0,0,0,0,0,0,0,0,0,0,0,0,0,0
0,0,0,0,0,0,0,0,0,0,0,0,0,0,0,0,0,0,0,0,0,0
0,0,0,0,0,0,0,0,0,0,0,0,0,0,0,0,0,0,0,0,0,0
0,0,0,0,0,0,0,0,0,0,0,0,0,0,0,0,0,0,0,0,0,0
0,0,6,0,0,0,0,0,0,0,0,0,0,0,0,0,0,0,0,0,0,0
0,0,0,0,0,0,0,0,0,0,0,0,0,0,0,0,0,0,0,0,0,0
0,0,0,0,0,0,0,0,0,0,0,0,0,0,0,0,0,0,0,0,0,0
0,0,0,0,0,0,0,0,0,0,0,0,0,0,0,0,0,0,0,0,0,0
0,0,0,0,0,0,0,0,0,0,0,0,0,0,0,0,0,0,0,0,0,0
:endlayer

#### RULES ####
rule:
plugin=vanillaBlocks
number=1
data:
JSON:{blockState:{blockName:"minecraft:grass",properties:{snowy:"false"}}}
:enddata
:endrule

rule:
plugin=vanillaBlocks
number=2
data:
JSON:{blockState:{blockName:"minecraft:cobblestone"}}
:enddata
:endrule

rule:
plugin=vanillaBlocks
number=3
data:
JSON:{blockState:{blockName:"minecraft:log",properties:{variant:"oak",axis:"y"}}}
:enddata
:endrule

rule:
plugin=vanillaBlocks
number=4
data:
JSON:{blockState:{blockName:"ancientwarfarestructure:fire_pit",properties:{lit:"true",variant:"log"}}}
:enddata
:endrule

rule:
plugin=vanillaBlocks
number=5
data:
JSON:{blockState:{blockName:"minecraft:wooden_slab",properties:{half:"top",variant:"spruce"}}}
:enddata
:endrule

rule:
plugin=vanillaBlocks
number=6
data:
JSON:{blockState:{blockName:"minecraft:stone_slab",properties:{half:"bottom",variant:"cobblestone"}}}
:enddata
:endrule

rule:
plugin=vanillaBlocks
number=7
data:
JSON:{blockState:{blockName:"minecraft:wooden_slab",properties:{half:"bottom",variant:"spruce"}}}
:enddata
:endrule

rule:
plugin=vanillaBlocks
number=8
data:
JSON:{blockState:{blockName:"minecraft:planks",properties:{variant:"oak"}}}
:enddata
:endrule

rule:
plugin=vanillaBlocks
number=9
data:
JSON:{blockState:{blockName:"minecraft:torch",properties:{facing:"up"}}}
:enddata
:endrule

rule:
plugin=vanillaBlocks
number=10
data:
JSON:{blockState:{blockName:"minecraft:stained_glass_pane",properties:{east:"false",color:"green",south:"false",north:"false",west:"false"}}}
:enddata
:endrule

rule:
plugin=vanillaBlocks
number=11
data:
JSON:{blockState:{blockName:"minecraft:spruce_fence",properties:{east:"false",south:"false",north:"false",west:"false"}}}
:enddata
:endrule

rule:
plugin=vanillaBlocks
number=12
data:
JSON:{blockState:{blockName:"minecraft:stone_stairs",properties:{half:"bottom",shape:"straight",facing:"east"}}}
:enddata
:endrule

rule:
plugin=vanillaBlocks
number=13
data:
JSON:{blockState:{blockName:"minecraft:stone_stairs",properties:{half:"bottom",shape:"straight",facing:"north"}}}
:enddata
:endrule

rule:
plugin=vanillaBlocks
number=14
data:
JSON:{blockState:{blockName:"minecraft:stone_stairs",properties:{half:"top",shape:"straight",facing:"west"}}}
:enddata
:endrule

rule:
plugin=vanillaBlocks
number=15
data:
JSON:{blockState:{blockName:"minecraft:torch",properties:{facing:"east"}}}
:enddata
:endrule

rule:
plugin=vanillaBlocks
number=16
data:
JSON:{blockState:{blockName:"minecraft:torch",properties:{facing:"north"}}}
:enddata
:endrule

rule:
plugin=vanillaBlocks
number=17
data:
JSON:{blockState:{blockName:"minecraft:stone_stairs",properties:{half:"top",shape:"straight",facing:"south"}}}
:enddata
:endrule

rule:
plugin=vanillaBlocks
number=18
data:
JSON:{blockState:{blockName:"minecraft:stone_stairs",properties:{half:"top",shape:"straight",facing:"east"}}}
:enddata
:endrule

rule:
plugin=vanillaBlocks
number=19
data:
JSON:{blockState:{blockName:"minecraft:torch",properties:{facing:"west"}}}
:enddata
:endrule

rule:
plugin=vanillaBlocks
number=20
data:
JSON:{blockState:{blockName:"minecraft:stone_stairs",properties:{half:"top",shape:"straight",facing:"north"}}}
:enddata
:endrule

rule:
plugin=vanillaBlocks
number=21
data:
JSON:{blockState:{blockName:"minecraft:stone_stairs",properties:{half:"bottom",shape:"straight",facing:"south"}}}
:enddata
:endrule

rule:
plugin=vanillaBlocks
number=22
data:
JSON:{blockState:{blockName:"minecraft:stone_stairs",properties:{half:"bottom",shape:"straight",facing:"west"}}}
:enddata
:endrule

rule:
plugin=vanillaBlocks
number=23
data:
JSON:{blockState:{blockName:"minecraft:log",properties:{variant:"oak",axis:"z"}}}
:enddata
:endrule

rule:
plugin=vanillaBlocks
number=24
data:
JSON:{blockState:{blockName:"minecraft:log",properties:{variant:"oak",axis:"x"}}}
:enddata
:endrule

rule:
plugin=vanillaBlocks
number=25
data:
JSON:{blockState:{blockName:"minecraft:trapdoor",properties:{half:"bottom",facing:"south",open:"true"}}}
:enddata
:endrule

rule:
plugin=vanillaBlocks
number=26
data:
JSON:{blockState:{blockName:"minecraft:planks",properties:{variant:"spruce"}}}
:enddata
:endrule

rule:
plugin=vanillaBlocks
number=27
data:
JSON:{blockState:{blockName:"minecraft:spruce_stairs",properties:{half:"top",shape:"straight",facing:"south"}}}
:enddata
:endrule

rule:
plugin=vanillaBlocks
number=28
data:
JSON:{blockState:{blockName:"minecraft:spruce_stairs",properties:{half:"top",shape:"straight",facing:"north"}}}
:enddata
:endrule

rule:
plugin=vanillaBlocks
number=29
data:
JSON:{blockState:{blockName:"minecraft:spruce_stairs",properties:{half:"bottom",shape:"straight",facing:"south"}}}
:enddata
:endrule

rule:
plugin=vanillaBlocks
number=30
data:
JSON:{blockState:{blockName:"minecraft:spruce_stairs",properties:{half:"top",shape:"straight",facing:"west"}}}
:enddata
:endrule

rule:
plugin=vanillaBlocks
number=31
data:
JSON:{blockState:{blockName:"minecraft:spruce_stairs",properties:{half:"bottom",shape:"straight",facing:"north"}}}
:enddata
:endrule

rule:
plugin=vanillaBlocks
number=32
data:
JSON:{blockState:{blockName:"minecraft:oak_stairs",properties:{half:"top",shape:"straight",facing:"south"}}}
:enddata
:endrule

rule:
plugin=vanillaBlocks
number=33
data:
JSON:{blockState:{blockName:"minecraft:oak_stairs",properties:{half:"top",shape:"straight",facing:"north"}}}
:enddata
:endrule

rule:
plugin=vanillaBlocks
number=34
data:
JSON:{blockState:{blockName:"minecraft:spruce_stairs",properties:{half:"bottom",shape:"straight",facing:"east"}}}
:enddata
:endrule

rule:
plugin=vanillaBlocks
number=35
data:
JSON:{blockState:{blockName:"minecraft:spruce_stairs",properties:{half:"bottom",shape:"straight",facing:"west"}}}
:enddata
:endrule

rule:
plugin=vanillaBlocks
number=36
data:
JSON:{blockState:{blockName:"minecraft:torch",properties:{facing:"south"}}}
:enddata
:endrule

rule:
plugin=vanillaBlocks
number=37
data:
JSON:{blockState:{blockName:"minecraft:spruce_stairs",properties:{half:"top",shape:"straight",facing:"east"}}}
:enddata
:endrule

rule:
plugin=vanillaBlocks
number=38
data:
JSON:{blockState:{blockName:"minecraft:cobblestone_wall",properties:{east:"false",south:"false",north:"false",variant:"cobblestone",west:"false",up:"false"}}}
:enddata
:endrule

rule:
plugin=vanillaBlocks
number=39
data:
JSON:{blockState:{blockName:"minecraft:oak_stairs",properties:{half:"top",shape:"straight",facing:"west"}}}
:enddata
:endrule

rule:
plugin=vanillaBlocks
number=40
data:
JSON:{blockState:{blockName:"minecraft:oak_stairs",properties:{half:"top",shape:"straight",facing:"east"}}}
:enddata
:endrule

#### ENTITIES ####
