# Ancient Warfare Structure Template File
# Auto-generated structure template file. created on: 5/7/2021 at: 0:13:36
# Lines beginning with # denote comments

header:
version=2.11
name=SurvivalBuild_CityLife_Res_BourgeoihouseC
mods=
size=20,17,19
offset=7,1,18
:endheader

#### VALIDATION ####
validation:
type=ground
structureAuthor=TheOddlySeagull
survival=true
worldGenEnabled=false
unique=false
preserveBlocks=false
preventNaturalHostileSpawns=false
selectionWeight=1
clusterValue=1
minDuplicateDistance=1
dimensionWhiteList=true
dimensionList=
biomeGroupList=
biomeWhiteList=true
biomeList=
leveling=0
fill=0
border=0
blockSwap=false
territoryName=
biomeReplacement=minecraft:
minGenerationHeight=0
maxGenerationHeight=255
:endvalidation

#### LAYERS ####
layer: 0
1,2,2,1,3,3,1,2,2,2,2,2,2,2,2,2,2,2,2,1
4,5,5,5,3,3,5,5,5,5,5,5,5,5,5,5,5,5,5,4
4,5,5,5,3,3,5,5,5,5,5,5,5,5,5,5,5,5,5,4
4,5,5,5,3,3,5,7,7,7,5,5,5,5,5,5,5,5,5,4
4,5,5,5,3,3,1,7,7,7,2,2,2,2,2,2,1,5,5,4
4,5,5,5,3,3,4,7,7,7,6,6,4,8,8,8,4,5,5,4
4,5,5,5,3,3,4,6,6,6,6,6,4,8,8,8,4,5,5,4
4,5,5,1,2,2,1,2,2,2,2,2,4,8,8,8,4,5,5,4
4,5,5,4,6,6,4,6,6,4,6,6,4,8,8,8,4,5,5,4
4,5,5,4,6,6,4,6,6,4,6,6,4,7,7,7,4,5,5,4
4,5,5,4,6,6,4,6,6,4,6,6,4,7,7,7,1,5,5,4
4,5,5,4,6,6,4,6,6,4,6,6,4,7,7,7,5,5,5,4
4,5,5,4,6,6,4,6,6,4,6,6,4,5,5,5,5,5,5,4
4,5,5,1,2,2,2,2,2,2,2,2,1,5,5,5,5,5,5,4
4,5,5,5,5,5,5,3,3,5,5,5,5,5,5,5,5,5,5,4
4,5,5,5,5,5,5,3,3,5,5,5,5,5,5,5,5,5,5,4
4,5,5,5,5,5,5,3,3,5,5,5,5,5,5,5,5,5,5,4
4,5,5,5,5,5,5,3,3,5,5,5,5,5,5,5,5,5,5,4
1,2,2,2,2,2,1,3,3,1,2,2,2,2,2,2,2,2,2,1
:endlayer
layer: 1
1,9,9,1,0,0,1,9,9,9,9,9,9,9,9,9,9,9,9,1
9,0,0,0,0,0,0,0,0,0,0,0,0,0,0,0,0,0,0,9
9,0,0,0,0,0,0,0,0,0,0,0,0,0,0,0,0,0,0,9
9,0,0,0,0,0,0,7,7,7,0,0,0,0,0,0,0,0,0,9
9,0,0,0,0,0,1,7,13,7,1,7,7,7,18,7,1,0,0,9
9,0,0,0,0,0,7,0,0,0,0,0,7,0,0,0,7,0,0,9
9,0,0,0,0,0,7,0,0,0,0,0,0,0,0,0,15,0,0,9
9,0,0,1,17,17,1,0,0,0,0,0,0,0,0,0,7,0,0,9
9,0,0,7,0,0,0,16,0,0,0,0,0,0,0,0,15,0,0,9
9,0,0,12,0,0,0,14,0,0,0,0,7,0,0,0,7,0,0,9
9,0,0,7,0,0,7,0,0,0,0,0,1,7,13,7,1,0,0,9
9,0,0,12,0,0,0,0,0,0,0,0,7,7,7,7,0,0,0,9
9,0,0,7,0,0,0,0,0,0,0,0,7,0,0,0,0,0,0,9
9,0,0,1,7,10,7,11,11,7,10,7,1,0,0,0,0,0,0,9
9,0,0,0,0,0,0,0,0,0,0,0,0,0,0,0,0,0,0,9
9,0,0,0,0,0,0,0,0,0,0,0,0,0,0,0,0,0,0,9
9,0,0,0,0,0,0,0,0,0,0,0,0,0,0,0,0,0,0,9
9,0,0,0,0,0,0,0,0,0,0,0,0,0,0,0,0,0,0,9
1,9,9,9,9,9,1,0,0,1,9,9,9,9,9,9,9,9,9,1
:endlayer
layer: 2
19,0,0,19,0,0,19,0,0,0,0,0,0,0,0,0,0,0,0,19
0,0,0,0,0,0,0,0,0,0,0,0,0,0,0,0,0,0,0,0
0,0,0,0,0,0,0,0,0,0,0,0,0,0,0,0,0,0,0,0
0,0,0,0,0,0,0,7,7,7,0,0,0,0,0,0,0,0,0,0
0,0,0,0,0,0,1,7,0,7,1,7,7,7,20,7,1,0,0,0
0,0,0,0,0,0,7,0,0,0,0,0,7,0,0,0,7,0,0,0
0,0,0,0,0,0,7,0,0,0,0,0,0,0,0,0,20,0,0,0
0,0,0,1,21,22,1,16,0,0,0,0,0,0,0,0,7,0,0,0
0,0,0,7,0,0,0,14,0,0,0,0,0,0,0,0,20,0,0,0
0,0,0,20,0,0,0,0,0,0,0,0,7,0,0,0,7,0,0,0
0,0,0,7,0,0,7,0,0,0,0,0,1,7,0,7,1,0,0,0
0,0,0,20,0,0,0,0,0,0,0,0,7,7,7,7,0,0,0,0
0,0,0,7,0,0,0,0,0,0,0,0,7,0,0,0,0,0,0,0
0,0,0,1,7,20,7,22,21,7,20,7,1,0,0,0,0,0,0,0
0,0,0,0,0,0,0,0,0,0,0,0,0,0,0,0,0,0,0,0
0,0,0,0,0,0,0,0,0,0,0,0,0,0,0,0,0,0,0,0
0,0,0,0,0,0,0,0,0,0,0,0,0,0,0,0,0,0,0,0
0,0,0,0,0,0,0,0,0,0,0,0,0,0,0,0,0,0,0,0
19,0,0,0,0,0,19,0,0,19,0,0,0,0,0,0,0,0,0,19
:endlayer
layer: 3
0,0,0,0,0,0,0,0,0,0,0,0,0,0,0,0,0,0,0,0
0,0,0,0,0,0,0,0,0,0,0,0,0,0,0,0,0,0,0,0
0,0,0,0,0,0,0,0,24,0,0,0,0,0,0,0,0,0,0,0
0,0,0,0,0,0,9,7,7,7,9,0,0,0,0,0,9,0,0,0
0,0,0,0,0,0,1,7,23,7,1,7,7,7,20,7,1,9,0,0
0,0,0,0,0,0,7,0,0,0,0,0,7,0,0,0,7,0,0,0
0,0,0,9,0,0,7,16,0,0,0,0,23,0,0,0,20,0,0,0
0,0,9,1,24,24,1,14,0,0,0,0,0,0,0,0,7,0,0,0
0,0,0,7,0,0,23,0,0,0,0,0,24,0,0,0,20,0,0,0
0,0,0,20,0,0,24,0,0,0,0,0,7,0,0,0,7,0,0,0
0,0,0,7,0,0,7,0,0,0,0,0,1,7,24,7,1,9,0,0
0,0,0,20,0,0,23,0,0,0,0,0,7,12,7,15,9,0,0,0
0,0,0,7,0,0,24,0,0,0,0,0,7,0,0,0,0,0,0,0
0,0,9,1,7,20,7,23,23,7,20,7,1,9,0,0,0,0,0,0
0,0,0,9,0,0,0,0,0,0,0,0,9,0,0,0,0,0,0,0
0,0,0,0,0,0,0,0,0,0,0,0,0,0,0,0,0,0,0,0
0,0,0,0,0,0,0,0,0,0,0,0,0,0,0,0,0,0,0,0
0,0,0,0,0,0,0,0,0,0,0,0,0,0,0,0,0,0,0,0
0,0,0,0,0,0,0,0,0,0,0,0,0,0,0,0,0,0,0,0
:endlayer
layer: 4
0,0,0,0,0,0,0,0,0,0,0,0,0,0,0,0,0,0,0,0
0,0,0,0,0,0,0,0,0,0,0,0,0,0,0,0,0,0,0,0
0,0,0,0,0,0,30,24,7,24,30,0,0,30,0,0,30,0,0,0
0,0,0,0,0,0,4,7,7,7,4,26,26,4,26,26,4,0,0,0
0,0,0,0,0,0,4,2,2,2,2,2,2,2,2,2,4,2,27,0
0,0,0,30,0,0,4,16,4,29,29,29,4,29,29,29,4,26,0,0
0,0,0,4,26,26,4,14,4,29,29,29,4,29,29,29,4,26,0,0
0,28,2,4,2,2,4,0,4,2,2,2,4,2,2,2,4,2,27,0
0,0,26,4,29,29,4,0,4,29,29,29,4,29,29,29,4,26,0,0
0,0,26,4,29,29,4,0,4,29,29,29,4,29,29,29,4,26,0,0
0,28,2,4,29,29,4,2,2,2,2,2,4,2,2,2,2,2,27,0
0,0,26,4,29,29,4,29,29,4,29,29,4,26,7,26,4,0,0,0
0,0,26,4,29,29,4,29,29,4,29,29,4,26,0,0,25,0,0,0
0,28,2,4,2,2,2,2,2,2,2,2,2,2,27,0,0,0,0,0
0,0,0,4,26,26,4,26,26,4,26,26,4,0,0,0,0,0,0,0
0,0,0,25,0,0,25,0,0,25,0,0,25,0,0,0,0,0,0,0
0,0,0,0,0,0,0,0,0,0,0,0,0,0,0,0,0,0,0,0
0,0,0,0,0,0,0,0,0,0,0,0,0,0,0,0,0,0,0,0
0,0,0,0,0,0,0,0,0,0,0,0,0,0,0,0,0,0,0,0
:endlayer
layer: 5
0,0,0,0,0,0,0,0,0,0,0,0,0,0,0,0,0,0,0,0
0,0,0,0,0,0,0,0,0,0,0,0,0,0,0,0,0,0,0,0
0,0,0,0,0,0,0,7,7,7,0,0,0,0,0,0,0,0,0,0
0,0,0,0,0,0,1,7,13,7,1,31,31,1,31,31,1,0,0,0
0,0,0,0,0,0,31,0,0,0,0,0,0,0,0,0,0,1,0,0
0,0,0,0,0,0,31,0,0,0,0,0,0,0,0,0,0,31,0,0
0,0,0,1,31,31,1,0,0,0,0,0,0,0,0,0,0,31,0,0
0,0,1,0,0,0,9,0,33,0,0,0,0,1,0,0,0,1,0,0
0,0,31,0,0,0,9,0,32,0,0,0,0,31,0,0,0,31,0,0
0,0,31,0,0,0,9,0,0,0,0,0,0,31,0,0,0,31,0,0
0,0,1,0,0,0,1,31,31,1,0,0,0,1,0,0,0,1,0,0
0,0,31,0,0,0,0,0,0,0,0,0,0,31,7,31,1,0,0,0
0,0,31,0,0,0,0,0,0,0,0,0,0,31,0,0,0,0,0,0
0,0,1,0,0,0,0,0,0,0,0,0,0,1,0,0,0,0,0,0
0,0,0,1,31,31,1,31,31,1,31,31,1,0,0,0,0,0,0,0
0,0,0,0,0,0,0,0,0,0,0,0,0,0,0,0,0,0,0,0
0,0,0,0,0,0,0,0,0,0,0,0,0,0,0,0,0,0,0,0
0,0,0,0,0,0,0,0,0,0,0,0,0,0,0,0,0,0,0,0
0,0,0,0,0,0,0,0,0,0,0,0,0,0,0,0,0,0,0,0
:endlayer
layer: 6
0,0,0,0,0,0,0,0,0,0,0,0,0,0,0,0,0,0,0,0
0,0,0,0,0,0,0,0,0,0,0,0,0,0,0,0,0,0,0,0
0,0,0,0,0,0,0,7,7,7,0,0,0,0,0,0,0,0,0,0
0,0,0,0,0,0,1,7,0,7,1,31,31,1,20,20,1,0,0,0
0,0,0,0,0,0,31,0,0,0,0,0,0,0,0,0,0,1,0,0
0,0,0,0,0,0,31,0,0,0,0,0,0,0,0,0,0,20,0,0
0,0,0,1,20,20,1,0,0,0,0,0,0,0,0,0,0,20,0,0
0,0,1,0,0,0,0,0,0,0,0,0,0,1,0,0,0,1,0,0
0,0,20,0,0,0,0,0,33,0,0,0,0,31,0,0,0,20,0,0
0,0,20,0,0,0,0,0,32,0,0,0,0,31,0,0,0,20,0,0
0,0,1,0,0,0,1,31,31,1,0,0,0,1,0,0,0,1,0,0
0,0,20,0,0,0,0,0,0,0,0,0,0,31,7,31,1,0,0,0
0,0,20,0,0,0,0,0,0,0,0,0,0,31,0,0,0,0,0,0
0,0,1,0,0,0,0,0,0,0,0,0,0,1,0,0,0,0,0,0
0,0,0,1,20,20,1,20,20,1,20,20,1,0,0,0,0,0,0,0
0,0,0,0,0,0,0,0,0,0,0,0,0,0,0,0,0,0,0,0
0,0,0,0,0,0,0,0,0,0,0,0,0,0,0,0,0,0,0,0
0,0,0,0,0,0,0,0,0,0,0,0,0,0,0,0,0,0,0,0
0,0,0,0,0,0,0,0,0,0,0,0,0,0,0,0,0,0,0,0
:endlayer
layer: 7
0,0,0,0,0,0,0,0,0,0,0,0,0,0,0,0,0,0,0,0
0,0,0,0,0,0,0,0,0,0,0,0,0,0,0,0,0,0,0,0
0,0,0,0,0,0,9,12,7,15,0,0,0,9,0,0,9,0,0,0
0,0,0,0,0,9,1,7,23,7,1,31,31,1,20,20,1,9,0,0
0,0,0,0,0,0,31,0,0,0,0,0,0,32,0,0,0,1,0,0
0,0,0,9,0,0,31,0,0,0,0,0,0,0,0,0,0,20,0,0
0,0,9,1,20,20,1,0,0,0,0,0,0,16,0,0,0,20,0,0
0,0,1,0,0,0,32,0,0,0,0,0,0,1,0,0,0,1,0,0
0,0,20,0,0,0,0,0,0,0,0,0,0,31,0,0,0,20,0,0
0,0,20,0,0,0,16,0,33,0,0,0,0,31,0,0,0,20,0,0
0,0,1,0,0,0,1,31,31,1,35,0,34,1,0,0,0,1,0,0
0,0,20,0,0,0,32,0,0,0,0,0,0,31,7,31,1,9,0,0
0,0,20,0,0,0,0,0,0,0,0,0,0,31,0,0,9,0,0,0
0,0,1,0,0,0,16,0,0,0,0,0,0,1,0,0,0,0,0,0
0,0,9,1,20,20,1,20,20,1,20,20,1,9,0,0,0,0,0,0
0,0,0,9,0,0,9,0,0,9,0,0,9,0,0,0,0,0,0,0
0,0,0,0,0,0,0,0,0,0,0,0,0,0,0,0,0,0,0,0
0,0,0,0,0,0,0,0,0,0,0,0,0,0,0,0,0,0,0,0
0,0,0,0,0,0,0,0,0,0,0,0,0,0,0,0,0,0,0,0
:endlayer
layer: 8
0,0,0,0,0,0,0,0,0,0,0,0,0,0,0,0,0,0,0,0
0,0,0,0,0,0,0,0,0,0,0,0,0,0,0,0,0,0,0,0
0,0,0,0,0,38,35,0,7,0,0,0,0,34,39,33,33,33,0,0
0,0,0,0,0,38,1,2,2,2,2,2,2,1,2,2,1,32,29,0
0,0,0,0,0,38,4,0,0,4,29,29,29,4,29,29,29,1,9,0
0,0,33,33,33,33,4,0,0,4,29,29,29,4,29,29,29,4,0,0
0,29,32,1,2,2,4,0,0,4,29,29,29,4,29,29,29,4,37,0
0,9,1,29,29,29,4,0,0,4,2,2,2,4,2,2,2,4,26,0
0,0,4,29,29,29,4,0,0,4,29,29,29,4,29,29,29,4,37,0
0,36,4,29,29,29,4,0,0,4,29,29,29,4,29,29,29,4,0,0
0,26,4,2,2,2,4,1,33,4,2,2,2,1,29,29,29,1,9,0
0,36,4,29,29,29,4,29,29,4,29,29,29,4,7,2,1,16,29,0
0,0,4,29,29,29,4,29,29,4,29,29,29,4,14,14,14,14,0,0
0,9,1,29,29,29,4,29,29,4,29,29,29,1,0,0,0,0,0,0
0,29,16,1,2,2,2,2,2,2,2,2,1,16,0,0,0,0,0,0
0,0,14,14,14,14,14,14,14,14,14,14,14,14,0,0,0,0,0,0
0,0,0,0,0,0,0,0,0,0,0,0,0,0,0,0,0,0,0,0
0,0,0,0,0,0,0,0,0,0,0,0,0,0,0,0,0,0,0,0
0,0,0,0,0,0,0,0,0,0,0,0,0,0,0,0,0,0,0,0
:endlayer
layer: 9
0,0,0,0,0,0,0,0,0,0,0,0,0,0,0,0,0,0,0,0
0,0,0,0,0,0,0,0,0,0,0,0,0,0,0,0,0,0,0,0
0,0,0,0,0,0,38,35,7,0,0,0,34,39,0,0,0,0,0,0
0,0,0,0,0,0,38,1,31,31,31,31,1,39,33,33,33,33,33,0
0,0,0,0,0,0,38,37,0,9,0,0,26,1,43,43,43,1,32,0
0,0,0,0,0,0,38,37,0,9,0,0,0,0,0,0,0,31,0,0
0,33,33,33,33,33,33,37,0,9,0,0,0,0,0,0,0,31,9,0
0,32,1,43,43,43,1,43,0,9,0,0,0,0,0,0,0,42,9,0
0,0,31,0,0,0,9,0,0,9,0,0,0,0,0,0,0,31,9,0
0,9,31,0,0,0,9,0,0,9,0,0,0,0,0,0,0,31,0,0
0,9,41,0,0,0,9,9,0,0,0,0,0,1,40,40,40,1,16,0
0,9,31,0,0,0,0,0,0,0,0,0,0,31,7,14,14,14,14,0
0,0,31,0,0,0,0,0,0,0,0,0,0,31,0,0,0,0,0,0
0,16,1,40,40,40,1,31,31,1,40,40,40,1,16,0,0,0,0,0
0,14,14,14,14,14,14,14,14,14,14,14,14,14,14,0,0,0,0,0
0,0,0,0,0,0,0,0,0,0,0,0,0,0,0,0,0,0,0,0
0,0,0,0,0,0,0,0,0,0,0,0,0,0,0,0,0,0,0,0
0,0,0,0,0,0,0,0,0,0,0,0,0,0,0,0,0,0,0,0
0,0,0,0,0,0,0,0,0,0,0,0,0,0,0,0,0,0,0,0
:endlayer
layer: 10
0,0,0,0,0,0,0,0,0,0,0,0,0,0,0,0,0,0,0,0
0,0,0,0,0,0,0,0,0,0,0,0,0,0,0,0,0,0,0,0
0,0,0,0,0,0,0,38,7,0,0,34,39,0,0,0,0,0,0,0
0,0,0,0,0,0,0,38,1,31,31,1,39,0,0,0,0,0,0,0
0,0,0,0,0,0,0,38,37,0,0,36,39,33,33,33,33,33,33,0
0,0,0,0,0,0,0,38,37,0,0,36,43,32,43,43,43,1,32,0
0,0,0,0,0,0,0,38,37,0,0,0,0,0,0,0,0,31,0,0
0,33,33,33,33,33,33,38,37,0,0,0,0,0,0,0,0,44,0,0
0,32,1,43,43,43,32,43,37,0,0,0,0,0,0,0,0,31,0,0
0,0,31,0,0,0,0,0,0,0,0,0,0,16,40,40,40,1,16,0
0,0,44,0,0,0,0,0,0,0,0,0,0,1,14,14,14,14,14,0
0,0,31,0,0,0,0,0,0,0,0,0,0,31,7,0,0,0,0,0
0,16,1,40,40,40,0,0,0,0,40,40,40,1,16,0,0,0,0,0
0,14,14,14,14,14,1,20,20,1,14,14,14,14,14,0,0,0,0,0
0,0,0,0,0,0,9,0,0,9,0,0,0,0,0,0,0,0,0,0
0,0,0,0,0,0,0,0,0,0,0,0,0,0,0,0,0,0,0,0
0,0,0,0,0,0,0,0,0,0,0,0,0,0,0,0,0,0,0,0
0,0,0,0,0,0,0,0,0,0,0,0,0,0,0,0,0,0,0,0
0,0,0,0,0,0,0,0,0,0,0,0,0,0,0,0,0,0,0,0
:endlayer
layer: 11
0,0,0,0,0,0,0,0,0,0,0,0,0,0,0,0,0,0,0,0
0,0,0,0,0,0,0,0,0,0,0,0,0,0,0,0,0,0,0,0
0,0,0,0,0,0,0,0,7,33,33,39,0,0,0,0,0,0,0,0
0,0,0,0,0,0,0,0,38,2,2,39,0,0,0,0,0,0,0,0
0,0,0,0,0,0,0,0,38,37,36,39,0,0,0,0,0,0,0,0
0,0,0,0,0,0,0,0,38,37,36,33,33,33,33,33,33,33,33,0
0,0,0,0,0,0,0,0,38,37,36,43,43,32,43,43,43,1,32,0
0,0,0,0,0,0,0,0,38,37,0,0,0,0,0,0,0,31,0,0
0,33,33,33,33,33,33,33,33,37,0,0,0,16,40,40,40,1,16,0
0,32,1,43,43,43,32,43,43,43,0,0,0,31,14,14,14,14,14,0
0,0,31,0,0,0,0,0,0,0,0,0,0,1,0,0,0,0,0,0
0,16,1,40,40,40,37,0,0,36,40,40,40,1,7,0,0,0,0,0
0,14,14,14,14,14,37,0,0,36,14,14,14,14,14,0,0,0,0,0
0,0,0,0,0,38,1,20,20,1,39,0,0,0,0,0,0,0,0,0
0,0,0,0,0,38,35,0,0,34,39,0,0,0,0,0,0,0,0,0
0,0,0,0,0,0,0,0,0,0,0,0,0,0,0,0,0,0,0,0
0,0,0,0,0,0,0,0,0,0,0,0,0,0,0,0,0,0,0,0
0,0,0,0,0,0,0,0,0,0,0,0,0,0,0,0,0,0,0,0
0,0,0,0,0,0,0,0,0,0,0,0,0,0,0,0,0,0,0,0
:endlayer
layer: 12
0,0,0,0,0,0,0,0,0,0,0,0,0,0,0,0,0,0,0,0
0,0,0,0,0,0,0,0,0,0,0,0,0,0,0,0,0,0,0,0
0,0,0,0,0,0,0,0,7,0,0,0,0,0,0,0,0,0,0,0
0,0,0,0,0,0,0,0,0,38,33,0,0,0,0,0,0,0,0,0
0,0,0,0,0,0,0,0,0,38,39,0,0,0,0,0,0,0,0,0
0,0,0,0,0,0,0,0,0,38,39,0,0,0,0,0,0,0,0,0
0,0,0,0,0,0,0,0,0,38,39,33,33,33,33,33,33,33,33,0
0,0,0,0,0,0,0,0,0,38,4,2,2,2,2,2,2,1,39,0
0,0,0,0,0,0,0,0,0,38,4,0,0,4,14,14,14,14,14,0
0,33,33,33,33,33,33,33,33,33,4,0,0,4,0,0,0,0,0,0
0,38,1,2,2,2,2,2,2,2,2,2,2,1,16,0,0,0,0,0
0,14,14,14,14,14,14,37,36,14,14,14,14,14,7,0,0,0,0,0
0,0,0,0,0,0,38,37,36,39,0,0,0,0,0,0,0,0,0,0
0,0,0,0,0,0,38,2,2,39,0,0,0,0,0,0,0,0,0,0
0,0,0,0,0,0,38,14,14,39,0,0,0,0,0,0,0,0,0,0
0,0,0,0,0,0,0,0,0,0,0,0,0,0,0,0,0,0,0,0
0,0,0,0,0,0,0,0,0,0,0,0,0,0,0,0,0,0,0,0
0,0,0,0,0,0,0,0,0,0,0,0,0,0,0,0,0,0,0,0
0,0,0,0,0,0,0,0,0,0,0,0,0,0,0,0,0,0,0,0
:endlayer
layer: 13
0,0,0,0,0,0,0,0,0,0,0,0,0,0,0,0,0,0,0,0
0,0,0,0,0,0,0,0,0,0,0,0,0,0,0,0,0,0,0,0
0,0,0,0,0,0,0,0,7,0,0,0,0,0,0,0,0,0,0,0
0,0,0,0,0,0,0,0,0,0,0,0,0,0,0,0,0,0,0,0
0,0,0,0,0,0,0,0,0,0,0,0,0,0,0,0,0,0,0,0
0,0,0,0,0,0,0,0,0,0,0,0,0,0,0,0,0,0,0,0
0,0,0,0,0,0,0,0,0,0,0,0,0,0,0,0,0,0,0,0
0,0,0,0,0,0,0,0,0,0,38,33,33,33,39,19,19,19,0,0
0,0,0,0,0,0,0,0,0,0,38,37,43,31,39,0,0,0,0,0
0,0,0,0,0,0,0,0,0,0,38,40,36,31,39,0,0,0,0,0
0,0,19,19,19,19,19,33,33,19,14,14,14,14,14,0,0,0,0,0
0,0,0,0,0,0,0,38,39,0,0,0,0,0,7,0,0,0,0,0
0,0,0,0,0,0,0,38,39,0,0,0,0,0,0,0,0,0,0,0
0,0,0,0,0,0,0,38,14,0,0,0,0,0,0,0,0,0,0,0
0,0,0,0,0,0,0,0,0,0,0,0,0,0,0,0,0,0,0,0
0,0,0,0,0,0,0,0,0,0,0,0,0,0,0,0,0,0,0,0
0,0,0,0,0,0,0,0,0,0,0,0,0,0,0,0,0,0,0,0
0,0,0,0,0,0,0,0,0,0,0,0,0,0,0,0,0,0,0,0
0,0,0,0,0,0,0,0,0,0,0,0,0,0,0,0,0,0,0,0
:endlayer
layer: 14
0,0,0,0,0,0,0,0,0,0,0,0,0,0,0,0,0,0,0,0
0,0,0,0,0,0,0,0,0,0,0,0,0,0,0,0,0,0,0,0
0,0,0,0,0,0,0,0,45,0,0,0,0,0,0,0,0,0,0,0
0,0,0,0,0,0,0,0,0,0,0,0,0,0,0,0,0,0,0,0
0,0,0,0,0,0,0,0,0,0,0,0,0,0,0,0,0,0,0,0
0,0,0,0,0,0,0,0,0,0,0,0,0,0,0,0,0,0,0,0
0,0,0,0,0,0,0,0,0,0,0,0,0,0,0,0,0,0,0,0
0,0,0,0,0,0,0,0,0,0,0,0,0,0,0,0,0,0,0,0
0,0,0,0,0,0,0,0,0,0,0,38,33,39,0,0,0,0,0,0
0,0,0,0,0,0,0,0,0,0,0,14,14,39,0,0,0,0,0,0
0,0,0,0,0,0,0,0,0,0,0,0,0,0,0,0,0,0,0,0
0,0,0,0,0,0,0,0,0,0,0,0,0,0,7,0,0,0,0,0
0,0,0,0,0,0,0,0,0,0,0,0,0,0,0,0,0,0,0,0
0,0,0,0,0,0,0,0,0,0,0,0,0,0,0,0,0,0,0,0
0,0,0,0,0,0,0,0,0,0,0,0,0,0,0,0,0,0,0,0
0,0,0,0,0,0,0,0,0,0,0,0,0,0,0,0,0,0,0,0
0,0,0,0,0,0,0,0,0,0,0,0,0,0,0,0,0,0,0,0
0,0,0,0,0,0,0,0,0,0,0,0,0,0,0,0,0,0,0,0
0,0,0,0,0,0,0,0,0,0,0,0,0,0,0,0,0,0,0,0
:endlayer
layer: 15
0,0,0,0,0,0,0,0,0,0,0,0,0,0,0,0,0,0,0,0
0,0,0,0,0,0,0,0,0,0,0,0,0,0,0,0,0,0,0,0
0,0,0,0,0,0,0,0,19,0,0,0,0,0,0,0,0,0,0,0
0,0,0,0,0,0,0,0,0,0,0,0,0,0,0,0,0,0,0,0
0,0,0,0,0,0,0,0,0,0,0,0,0,0,0,0,0,0,0,0
0,0,0,0,0,0,0,0,0,0,0,0,0,0,0,0,0,0,0,0
0,0,0,0,0,0,0,0,0,0,0,0,0,0,0,0,0,0,0,0
0,0,0,0,0,0,0,0,0,0,0,0,0,0,0,0,0,0,0,0
0,0,0,0,0,0,0,0,0,0,0,0,0,0,0,0,0,0,0,0
0,0,0,0,0,0,0,0,0,0,0,0,0,0,0,0,0,0,0,0
0,0,0,0,0,0,0,0,0,0,0,0,0,0,0,0,0,0,0,0
0,0,0,0,0,0,0,0,0,0,0,0,0,0,45,0,0,0,0,0
0,0,0,0,0,0,0,0,0,0,0,0,0,0,0,0,0,0,0,0
0,0,0,0,0,0,0,0,0,0,0,0,0,0,0,0,0,0,0,0
0,0,0,0,0,0,0,0,0,0,0,0,0,0,0,0,0,0,0,0
0,0,0,0,0,0,0,0,0,0,0,0,0,0,0,0,0,0,0,0
0,0,0,0,0,0,0,0,0,0,0,0,0,0,0,0,0,0,0,0
0,0,0,0,0,0,0,0,0,0,0,0,0,0,0,0,0,0,0,0
0,0,0,0,0,0,0,0,0,0,0,0,0,0,0,0,0,0,0,0
:endlayer
layer: 16
0,0,0,0,0,0,0,0,0,0,0,0,0,0,0,0,0,0,0,0
0,0,0,0,0,0,0,0,0,0,0,0,0,0,0,0,0,0,0,0
0,0,0,0,0,0,0,0,0,0,0,0,0,0,0,0,0,0,0,0
0,0,0,0,0,0,0,0,0,0,0,0,0,0,0,0,0,0,0,0
0,0,0,0,0,0,0,0,0,0,0,0,0,0,0,0,0,0,0,0
0,0,0,0,0,0,0,0,0,0,0,0,0,0,0,0,0,0,0,0
0,0,0,0,0,0,0,0,0,0,0,0,0,0,0,0,0,0,0,0
0,0,0,0,0,0,0,0,0,0,0,0,0,0,0,0,0,0,0,0
0,0,0,0,0,0,0,0,0,0,0,0,0,0,0,0,0,0,0,0
0,0,0,0,0,0,0,0,0,0,0,0,0,0,0,0,0,0,0,0
0,0,0,0,0,0,0,0,0,0,0,0,0,0,0,0,0,0,0,0
0,0,0,0,0,0,0,0,0,0,0,0,0,0,19,0,0,0,0,0
0,0,0,0,0,0,0,0,0,0,0,0,0,0,0,0,0,0,0,0
0,0,0,0,0,0,0,0,0,0,0,0,0,0,0,0,0,0,0,0
0,0,0,0,0,0,0,0,0,0,0,0,0,0,0,0,0,0,0,0
0,0,0,0,0,0,0,0,0,0,0,0,0,0,0,0,0,0,0,0
0,0,0,0,0,0,0,0,0,0,0,0,0,0,0,0,0,0,0,0
0,0,0,0,0,0,0,0,0,0,0,0,0,0,0,0,0,0,0,0
0,0,0,0,0,0,0,0,0,0,0,0,0,0,0,0,0,0,0,0
:endlayer

#### RULES ####
rule:
plugin=vanillaBlocks
number=1
data:
JSON:{blockState:{blockName:"minecraft:log",properties:{variant:"oak",axis:"y"}}}
:enddata
:endrule

rule:
plugin=vanillaBlocks
number=2
data:
JSON:{blockState:{blockName:"minecraft:log",properties:{variant:"oak",axis:"x"}}}
:enddata
:endrule

rule:
plugin=vanillaBlocks
number=3
data:
JSON:{blockState:{blockName:"minecraft:cobblestone"}}
:enddata
:endrule

rule:
plugin=vanillaBlocks
number=4
data:
JSON:{blockState:{blockName:"minecraft:log",properties:{variant:"oak",axis:"z"}}}
:enddata
:endrule

rule:
plugin=vanillaBlocks
number=5
data:
JSON:{blockState:{blockName:"minecraft:grass",properties:{snowy:"false"}}}
:enddata
:endrule

rule:
plugin=vanillaBlocks
number=6
data:
JSON:{blockState:{blockName:"minecraft:planks",properties:{variant:"spruce"}}}
:enddata
:endrule

rule:
plugin=vanillaBlocks
number=7
data:
JSON:{blockState:{blockName:"minecraft:stonebrick",properties:{variant:"stonebrick"}}}
:enddata
:endrule

rule:
plugin=vanillaBlocks
number=8
data:
JSON:{blockState:{blockName:"minecraft:stone",properties:{variant:"smooth_andesite"}}}
:enddata
:endrule

rule:
plugin=vanillaBlocks
number=9
data:
JSON:{blockState:{blockName:"minecraft:spruce_fence",properties:{east:"false",south:"false",north:"false",west:"false"}}}
:enddata
:endrule

rule:
plugin=vanillaBlocks
number=10
data:
JSON:{blockState:{blockName:"minecraft:stone_brick_stairs",properties:{half:"bottom",shape:"straight",facing:"north"}}}
:enddata
:endrule

rule:
plugin=doors
number=11
data:
JSON:{blockState:{blockName:"minecraft:spruce_door",properties:{hinge:"left",half:"lower",powered:"false",facing:"south",open:"false"}}}
:enddata
:endrule

rule:
plugin=vanillaBlocks
number=12
data:
JSON:{blockState:{blockName:"minecraft:stone_brick_stairs",properties:{half:"bottom",shape:"straight",facing:"east"}}}
:enddata
:endrule

rule:
plugin=vanillaBlocks
number=13
data:
JSON:{blockState:{blockName:"ancientwarfarestructure:fire_pit",properties:{lit:"true",variant:"log"}}}
:enddata
:endrule

rule:
plugin=vanillaBlocks
number=14
data:
JSON:{blockState:{blockName:"minecraft:spruce_stairs",properties:{half:"bottom",shape:"straight",facing:"north"}}}
:enddata
:endrule

rule:
plugin=vanillaBlocks
number=15
data:
JSON:{blockState:{blockName:"minecraft:stone_brick_stairs",properties:{half:"bottom",shape:"straight",facing:"west"}}}
:enddata
:endrule

rule:
plugin=vanillaBlocks
number=16
data:
JSON:{blockState:{blockName:"minecraft:spruce_stairs",properties:{half:"top",shape:"straight",facing:"south"}}}
:enddata
:endrule

rule:
plugin=doors
number=17
data:
JSON:{blockState:{blockName:"minecraft:spruce_door",properties:{hinge:"left",half:"lower",powered:"false",facing:"north",open:"false"}}}
:enddata
:endrule

rule:
plugin=vanillaBlocks
number=18
data:
JSON:{blockState:{blockName:"minecraft:stone_brick_stairs",properties:{half:"bottom",shape:"straight",facing:"south"}}}
:enddata
:endrule

rule:
plugin=vanillaBlocks
number=19
data:
JSON:{blockState:{blockName:"minecraft:wooden_slab",properties:{half:"bottom",variant:"spruce"}}}
:enddata
:endrule

rule:
plugin=vanillaBlocks
number=20
data:
JSON:{blockState:{blockName:"minecraft:glass_pane",properties:{east:"false",south:"false",north:"false",west:"false"}}}
:enddata
:endrule

rule:
plugin=doors
number=21
data:
JSON:{blockState:{blockName:"minecraft:spruce_door",properties:{hinge:"left",half:"upper",powered:"false",facing:"south",open:"false"}}}
:enddata
:endrule

rule:
plugin=doors
number=22
data:
JSON:{blockState:{blockName:"minecraft:spruce_door",properties:{hinge:"right",half:"upper",powered:"false",facing:"south",open:"false"}}}
:enddata
:endrule

rule:
plugin=vanillaBlocks
number=23
data:
JSON:{blockState:{blockName:"minecraft:stone_brick_stairs",properties:{half:"top",shape:"straight",facing:"north"}}}
:enddata
:endrule

rule:
plugin=vanillaBlocks
number=24
data:
JSON:{blockState:{blockName:"minecraft:stone_brick_stairs",properties:{half:"top",shape:"straight",facing:"south"}}}
:enddata
:endrule

rule:
plugin=vanillaBlocks
number=25
data:
JSON:{blockState:{blockName:"minecraft:stone_button",properties:{powered:"false",facing:"south"}}}
:enddata
:endrule

rule:
plugin=vanillaBlocks
number=26
data:
JSON:{blockState:{blockName:"minecraft:wooden_slab",properties:{half:"top",variant:"oak"}}}
:enddata
:endrule

rule:
plugin=vanillaBlocks
number=27
data:
JSON:{blockState:{blockName:"minecraft:stone_button",properties:{powered:"false",facing:"east"}}}
:enddata
:endrule

rule:
plugin=vanillaBlocks
number=28
data:
JSON:{blockState:{blockName:"minecraft:stone_button",properties:{powered:"false",facing:"west"}}}
:enddata
:endrule

rule:
plugin=vanillaBlocks
number=29
data:
JSON:{blockState:{blockName:"minecraft:wooden_slab",properties:{half:"top",variant:"spruce"}}}
:enddata
:endrule

rule:
plugin=vanillaBlocks
number=30
data:
JSON:{blockState:{blockName:"minecraft:stone_button",properties:{powered:"false",facing:"north"}}}
:enddata
:endrule

rule:
plugin=vanillaBlocks
number=31
data:
JSON:{blockState:{blockName:"minecraft:stained_hardened_clay",properties:{color:"pink"}}}
:enddata
:endrule

rule:
plugin=vanillaBlocks
number=32
data:
JSON:{blockState:{blockName:"minecraft:spruce_stairs",properties:{half:"top",shape:"straight",facing:"north"}}}
:enddata
:endrule

rule:
plugin=vanillaBlocks
number=33
data:
JSON:{blockState:{blockName:"minecraft:spruce_stairs",properties:{half:"bottom",shape:"straight",facing:"south"}}}
:enddata
:endrule

rule:
plugin=vanillaBlocks
number=34
data:
JSON:{blockState:{blockName:"minecraft:spruce_stairs",properties:{half:"top",shape:"straight",facing:"east"}}}
:enddata
:endrule

rule:
plugin=vanillaBlocks
number=35
data:
JSON:{blockState:{blockName:"minecraft:spruce_stairs",properties:{half:"top",shape:"straight",facing:"west"}}}
:enddata
:endrule

rule:
plugin=vanillaBlocks
number=36
data:
JSON:{blockState:{blockName:"minecraft:oak_stairs",properties:{half:"top",shape:"straight",facing:"east"}}}
:enddata
:endrule

rule:
plugin=vanillaBlocks
number=37
data:
JSON:{blockState:{blockName:"minecraft:oak_stairs",properties:{half:"top",shape:"straight",facing:"west"}}}
:enddata
:endrule

rule:
plugin=vanillaBlocks
number=38
data:
JSON:{blockState:{blockName:"minecraft:spruce_stairs",properties:{half:"bottom",shape:"straight",facing:"east"}}}
:enddata
:endrule

rule:
plugin=vanillaBlocks
number=39
data:
JSON:{blockState:{blockName:"minecraft:spruce_stairs",properties:{half:"bottom",shape:"straight",facing:"west"}}}
:enddata
:endrule

rule:
plugin=vanillaBlocks
number=40
data:
JSON:{blockState:{blockName:"minecraft:oak_stairs",properties:{half:"top",shape:"straight",facing:"south"}}}
:enddata
:endrule

rule:
plugin=doors
number=41
data:
JSON:{blockState:{blockName:"minecraft:wooden_door",properties:{hinge:"left",half:"lower",powered:"false",facing:"east",open:"false"}}}
:enddata
:endrule

rule:
plugin=doors
number=42
data:
JSON:{blockState:{blockName:"minecraft:wooden_door",properties:{hinge:"left",half:"lower",powered:"false",facing:"west",open:"false"}}}
:enddata
:endrule

rule:
plugin=vanillaBlocks
number=43
data:
JSON:{blockState:{blockName:"minecraft:oak_stairs",properties:{half:"top",shape:"straight",facing:"north"}}}
:enddata
:endrule

rule:
plugin=doors
number=44
data:
JSON:{blockState:{blockName:"minecraft:wooden_door",properties:{hinge:"left",half:"upper",powered:"false",facing:"south",open:"false"}}}
:enddata
:endrule

rule:
plugin=vanillaBlocks
number=45
data:
JSON:{blockState:{blockName:"minecraft:cobblestone_wall",properties:{east:"false",south:"false",north:"false",variant:"cobblestone",west:"false",up:"false"}}}
:enddata
:endrule

#### ENTITIES ####
