# Ancient Warfare Structure Template File
# Auto-generated structure template file. created on: 6/4/2021 at: 17:27:50
# Lines beginning with # denote comments

header:
version=2.11
name=SurvivalBuild_house_type1_3r_3
mods=
size=14,11,13
offset=7,1,12
:endheader

#### VALIDATION ####
validation:
type=ground
structureAuthor=theoddlyseagull
survival=true
worldGenEnabled=false
unique=false
preserveBlocks=false
preventNaturalHostileSpawns=false
selectionWeight=1
clusterValue=1
minDuplicateDistance=1
dimensionWhiteList=true
dimensionList=
biomeGroupList=
biomeWhiteList=true
biomeList=
leveling=0
fill=0
border=0
blockSwap=false
territoryName=
biomeReplacement=minecraft:
minGenerationHeight=0
maxGenerationHeight=255
:endvalidation

#### LAYERS ####
layer: 0
1,1,1,1,1,1,1,1,1,1,1,1,1,1
1,1,1,1,2,2,2,2,2,2,2,1,1,1
1,1,1,1,2,2,2,2,2,2,2,2,1,1
1,2,2,2,2,2,2,2,2,2,2,2,1,1
1,2,2,2,2,2,2,2,2,2,2,2,1,1
1,2,2,2,2,2,2,2,2,2,2,1,1,1
1,2,2,2,2,2,2,2,2,2,2,1,1,1
1,2,2,2,2,2,2,2,2,2,2,2,2,1
1,2,2,2,2,2,2,2,2,2,2,2,2,1
1,2,2,2,2,2,2,2,2,2,2,2,2,1
1,2,2,2,2,2,2,2,2,2,2,2,2,1
1,2,2,2,2,2,2,2,2,2,2,2,2,1
1,1,2,2,2,1,2,2,1,1,1,1,1,1
:endlayer
layer: 1
0,0,0,0,0,0,0,0,0,0,0,0,0,0
0,0,0,0,3,4,4,3,4,4,3,0,0,0
0,0,0,0,4,0,0,0,0,5,2,2,0,0
0,3,4,4,3,0,0,0,0,5,6,2,0,0
0,4,0,0,0,0,0,0,0,5,2,2,0,0
0,3,0,0,0,0,0,0,0,0,3,0,0,0
0,4,4,4,4,3,0,0,0,0,4,0,0,0
0,3,0,0,0,4,0,0,3,4,4,4,3,0
0,4,0,0,0,0,0,0,4,0,0,0,4,0
0,4,0,0,0,0,0,0,0,0,0,0,4,0
0,4,5,5,5,4,0,0,4,0,0,0,4,0
0,3,2,6,2,3,0,0,3,4,4,4,3,0
0,0,2,2,2,0,0,0,0,0,0,0,0,0
:endlayer
layer: 2
0,0,0,0,0,0,0,0,0,0,0,0,0,0
0,0,0,0,3,7,7,3,7,7,3,0,0,0
0,0,0,0,4,0,0,0,0,0,2,2,0,0
0,3,4,4,3,0,0,0,0,0,0,2,0,0
0,7,0,0,0,0,0,0,0,0,2,2,0,0
0,3,0,0,0,0,0,0,0,0,3,0,0,0
0,4,4,4,4,3,0,0,0,0,7,0,0,0
0,3,0,0,0,4,0,0,3,4,4,4,3,0
0,4,0,0,0,0,0,0,4,0,0,0,4,0
0,7,0,0,0,0,0,0,0,0,0,0,7,0
0,4,0,0,0,4,0,0,4,0,0,0,4,0
0,3,2,0,2,3,0,0,3,4,7,4,3,0
0,0,2,2,2,0,0,0,0,0,0,0,0,0
:endlayer
layer: 3
0,0,0,0,0,0,0,0,0,0,0,0,0,0
0,0,0,0,3,7,7,3,7,7,3,0,0,0
0,0,0,0,4,0,0,0,0,0,2,11,0,0
0,3,4,4,3,0,0,0,0,0,14,2,0,0
0,7,0,0,12,0,0,0,0,0,2,11,0,0
0,3,0,0,0,0,0,0,0,0,3,0,0,0
0,4,4,4,4,3,0,0,0,0,7,0,0,0
0,3,0,0,0,4,0,13,3,4,4,4,3,0
0,4,0,0,0,4,0,0,4,0,0,0,4,0
0,7,0,0,0,4,0,0,4,0,0,0,7,0
0,4,9,0,9,4,0,0,4,0,0,0,4,0
0,3,2,10,2,3,4,4,3,4,7,4,3,0
0,0,8,2,11,12,0,0,12,0,0,0,0,0
:endlayer
layer: 4
0,0,0,18,19,0,0,0,0,0,22,23,0,0
0,0,0,18,3,17,17,17,17,17,3,23,0,0
15,15,0,18,16,0,0,0,0,14,16,23,0,0
15,3,17,17,16,0,0,0,0,14,16,2,0,0
15,16,0,0,16,0,0,0,0,14,16,23,0,0
15,16,0,0,16,0,0,0,0,0,16,23,0,0
15,16,17,17,17,3,0,0,0,0,16,23,0,0
15,16,0,12,0,16,0,0,3,17,17,17,3,0
15,16,0,0,0,16,0,0,16,0,12,0,16,0
15,16,0,0,0,16,0,0,16,0,0,0,16,0
15,16,0,5,0,16,21,0,16,0,0,0,16,0
15,3,2,2,2,3,17,17,3,17,17,17,3,0
15,15,0,2,0,20,15,15,20,0,0,0,0,0
:endlayer
layer: 5
0,0,0,0,18,19,0,0,0,22,23,0,0,0
0,0,0,0,18,4,4,3,4,4,23,0,0,0
0,20,24,15,18,25,0,0,0,2,23,0,0,0
0,20,24,4,4,25,0,0,0,2,23,2,0,0
0,20,24,24,4,25,0,0,0,2,23,0,0,0
0,20,24,24,4,25,0,0,0,26,23,0,0,0
0,20,24,4,4,3,0,0,0,26,23,0,0,0
0,20,24,15,0,4,0,0,3,4,4,4,3,0
0,20,24,15,0,4,0,0,4,0,0,0,4,0
0,20,24,15,0,4,0,0,4,0,0,0,7,0
0,20,24,15,0,4,0,0,4,0,0,0,4,0
0,20,24,17,17,3,4,4,3,4,7,4,3,0
0,20,24,2,0,0,0,0,0,0,0,0,0,0
:endlayer
layer: 6
0,0,0,0,0,18,19,15,22,23,0,0,0,0
0,0,0,0,0,18,17,4,17,23,0,0,0,0
0,0,0,20,24,24,25,0,26,23,0,0,0,0
0,0,0,20,24,4,25,0,26,23,0,2,0,0
0,0,0,20,24,4,25,0,26,23,0,0,0,0
0,0,27,20,24,4,25,0,26,23,0,0,0,0
0,0,0,20,24,4,25,0,26,23,0,0,15,0
0,0,0,20,24,4,25,0,3,4,4,4,3,15
0,0,0,20,24,4,25,0,4,0,0,0,4,0
0,0,27,20,24,4,25,0,4,0,0,0,7,0
0,0,0,20,24,4,25,0,4,0,0,0,4,0
0,0,0,20,24,17,17,17,3,4,7,4,3,15
0,0,0,2,24,15,0,0,15,0,0,0,15,0
:endlayer
layer: 7
0,0,0,0,0,0,18,29,23,0,0,0,0,0
0,0,0,0,0,0,18,16,23,0,0,0,0,0
0,0,0,0,0,20,24,16,23,0,0,0,0,0
0,0,0,0,0,20,24,16,23,0,0,2,0,0
0,0,0,0,0,20,24,16,23,0,0,0,0,0
0,0,0,0,0,20,24,16,23,0,0,0,0,0
0,0,0,0,0,20,24,16,29,29,29,29,29,29
0,0,0,0,0,20,24,16,3,17,17,17,3,23
0,0,0,0,0,20,24,16,16,0,0,0,16,23
0,0,0,0,0,20,24,16,16,0,0,0,16,23
0,0,0,0,0,20,24,16,16,0,0,0,16,23
0,0,0,0,0,20,24,16,3,17,17,17,3,23
0,0,0,2,0,20,28,28,28,28,28,28,28,23
:endlayer
layer: 8
0,0,0,0,0,0,0,0,0,0,0,0,0,0
0,0,0,0,0,0,0,20,0,0,0,0,0,0
0,0,0,0,0,0,0,20,0,0,0,0,0,0
0,0,0,0,0,0,0,20,0,0,0,32,0,0
0,0,0,0,0,0,0,20,0,0,0,0,0,0
0,0,0,0,0,0,27,20,0,0,0,0,0,0
0,0,0,0,0,0,0,20,0,0,0,0,0,0
0,0,0,0,0,0,0,20,29,29,29,29,29,0
0,0,0,0,0,0,0,20,18,30,30,26,23,0
0,0,0,0,0,0,27,20,18,25,0,26,23,0
0,0,0,0,0,0,0,20,18,25,31,31,23,0
0,0,0,0,0,0,0,20,18,28,28,28,23,0
0,0,0,2,0,0,0,0,0,0,0,0,0,0
:endlayer
layer: 9
0,0,0,0,0,0,0,0,0,0,0,0,0,0
0,0,0,0,0,0,0,0,0,0,0,0,0,0
0,0,0,0,0,0,0,0,0,0,0,0,0,0
0,0,0,0,0,0,0,0,0,0,0,5,0,0
0,0,0,0,0,0,0,0,0,0,0,0,0,0
0,0,0,0,0,0,0,0,0,0,0,0,0,0
0,0,0,0,0,0,0,0,0,0,0,0,0,0
0,0,0,0,0,0,0,0,0,0,0,0,0,0
0,0,0,0,0,0,0,0,0,29,29,23,0,0
0,0,0,0,0,0,0,0,0,18,4,23,0,0
0,0,0,0,0,0,0,0,0,18,28,28,0,0
0,0,0,0,0,0,0,0,0,0,0,0,0,0
0,0,0,32,0,0,0,0,0,0,0,0,0,0
:endlayer
layer: 10
0,0,0,0,0,0,0,0,0,0,0,0,0,0
0,0,0,0,0,0,0,0,0,0,0,0,0,0
0,0,0,0,0,0,0,0,0,0,0,0,0,0
0,0,0,0,0,0,0,0,0,0,0,0,0,0
0,0,0,0,0,0,0,0,0,0,0,0,0,0
0,0,0,0,0,0,0,0,0,0,0,0,0,0
0,0,0,0,0,0,0,0,0,0,0,0,0,0
0,0,0,0,0,0,0,0,0,0,0,0,0,0
0,0,0,0,0,0,0,0,0,0,0,0,0,0
0,0,0,0,0,0,0,0,0,0,20,0,0,0
0,0,0,0,0,0,0,0,0,0,0,0,0,0
0,0,0,0,0,0,0,0,0,0,0,0,0,0
0,0,0,5,0,0,0,0,0,0,0,0,0,0
:endlayer

#### RULES ####
rule:
plugin=vanillaBlocks
number=1
data:
JSON:{blockState:{blockName:"minecraft:grass",properties:{snowy:"false"}}}
:enddata
:endrule

rule:
plugin=vanillaBlocks
number=2
data:
JSON:{blockState:{blockName:"minecraft:cobblestone"}}
:enddata
:endrule

rule:
plugin=vanillaBlocks
number=3
data:
JSON:{blockState:{blockName:"minecraft:log",properties:{variant:"oak",axis:"y"}}}
:enddata
:endrule

rule:
plugin=vanillaBlocks
number=4
data:
JSON:{blockState:{blockName:"minecraft:planks",properties:{variant:"oak"}}}
:enddata
:endrule

rule:
plugin=vanillaBlocks
number=5
data:
JSON:{blockState:{blockName:"minecraft:stone_slab",properties:{half:"bottom",variant:"cobblestone"}}}
:enddata
:endrule

rule:
plugin=vanillaBlocks
number=6
data:
JSON:{blockState:{blockName:"ancientwarfarestructure:fire_pit",properties:{lit:"true",variant:"log"}}}
:enddata
:endrule

rule:
plugin=vanillaBlocks
number=7
data:
JSON:{blockState:{blockName:"minecraft:fence",properties:{east:"false",south:"false",north:"false",west:"false"}}}
:enddata
:endrule

rule:
plugin=vanillaBlocks
number=8
data:
JSON:{blockState:{blockName:"minecraft:stone_stairs",properties:{half:"bottom",shape:"straight",facing:"east"}}}
:enddata
:endrule

rule:
plugin=vanillaBlocks
number=9
data:
JSON:{blockState:{blockName:"minecraft:stone_slab",properties:{half:"top",variant:"cobblestone"}}}
:enddata
:endrule

rule:
plugin=vanillaBlocks
number=10
data:
JSON:{blockState:{blockName:"minecraft:stone_stairs",properties:{half:"top",shape:"straight",facing:"south"}}}
:enddata
:endrule

rule:
plugin=vanillaBlocks
number=11
data:
JSON:{blockState:{blockName:"minecraft:stone_stairs",properties:{half:"bottom",shape:"straight",facing:"west"}}}
:enddata
:endrule

rule:
plugin=vanillaBlocks
number=12
data:
JSON:{blockState:{blockName:"minecraft:torch",properties:{facing:"south"}}}
:enddata
:endrule

rule:
plugin=vanillaBlocks
number=13
data:
JSON:{blockState:{blockName:"minecraft:torch",properties:{facing:"west"}}}
:enddata
:endrule

rule:
plugin=vanillaBlocks
number=14
data:
JSON:{blockState:{blockName:"minecraft:stone_stairs",properties:{half:"top",shape:"straight",facing:"east"}}}
:enddata
:endrule

rule:
plugin=vanillaBlocks
number=15
data:
JSON:{blockState:{blockName:"minecraft:wooden_slab",properties:{half:"top",variant:"spruce"}}}
:enddata
:endrule

rule:
plugin=vanillaBlocks
number=16
data:
JSON:{blockState:{blockName:"minecraft:log",properties:{variant:"oak",axis:"z"}}}
:enddata
:endrule

rule:
plugin=vanillaBlocks
number=17
data:
JSON:{blockState:{blockName:"minecraft:log",properties:{variant:"oak",axis:"x"}}}
:enddata
:endrule

rule:
plugin=vanillaBlocks
number=18
data:
JSON:{blockState:{blockName:"minecraft:spruce_stairs",properties:{half:"bottom",shape:"straight",facing:"east"}}}
:enddata
:endrule

rule:
plugin=vanillaBlocks
number=19
data:
JSON:{blockState:{blockName:"minecraft:spruce_stairs",properties:{half:"top",shape:"straight",facing:"west"}}}
:enddata
:endrule

rule:
plugin=vanillaBlocks
number=20
data:
JSON:{blockState:{blockName:"minecraft:wooden_slab",properties:{half:"bottom",variant:"spruce"}}}
:enddata
:endrule

rule:
plugin=vanillaBlocks
number=21
data:
JSON:{blockState:{blockName:"minecraft:torch",properties:{facing:"north"}}}
:enddata
:endrule

rule:
plugin=vanillaBlocks
number=22
data:
JSON:{blockState:{blockName:"minecraft:spruce_stairs",properties:{half:"top",shape:"straight",facing:"east"}}}
:enddata
:endrule

rule:
plugin=vanillaBlocks
number=23
data:
JSON:{blockState:{blockName:"minecraft:spruce_stairs",properties:{half:"bottom",shape:"straight",facing:"west"}}}
:enddata
:endrule

rule:
plugin=vanillaBlocks
number=24
data:
JSON:{blockState:{blockName:"minecraft:planks",properties:{variant:"spruce"}}}
:enddata
:endrule

rule:
plugin=vanillaBlocks
number=25
data:
JSON:{blockState:{blockName:"minecraft:oak_stairs",properties:{half:"top",shape:"straight",facing:"west"}}}
:enddata
:endrule

rule:
plugin=vanillaBlocks
number=26
data:
JSON:{blockState:{blockName:"minecraft:oak_stairs",properties:{half:"top",shape:"straight",facing:"east"}}}
:enddata
:endrule

rule:
plugin=vanillaBlocks
number=27
data:
JSON:{blockState:{blockName:"minecraft:torch",properties:{facing:"up"}}}
:enddata
:endrule

rule:
plugin=vanillaBlocks
number=28
data:
JSON:{blockState:{blockName:"minecraft:spruce_stairs",properties:{half:"bottom",shape:"straight",facing:"north"}}}
:enddata
:endrule

rule:
plugin=vanillaBlocks
number=29
data:
JSON:{blockState:{blockName:"minecraft:spruce_stairs",properties:{half:"bottom",shape:"straight",facing:"south"}}}
:enddata
:endrule

rule:
plugin=vanillaBlocks
number=30
data:
JSON:{blockState:{blockName:"minecraft:oak_stairs",properties:{half:"top",shape:"straight",facing:"north"}}}
:enddata
:endrule

rule:
plugin=vanillaBlocks
number=31
data:
JSON:{blockState:{blockName:"minecraft:oak_stairs",properties:{half:"top",shape:"straight",facing:"south"}}}
:enddata
:endrule

rule:
plugin=vanillaBlocks
number=32
data:
JSON:{blockState:{blockName:"minecraft:cobblestone_wall",properties:{east:"false",south:"false",north:"false",variant:"cobblestone",west:"false",up:"false"}}}
:enddata
:endrule

#### ENTITIES ####
