# Ancient Warfare Structure Template File
# Auto-generated structure template file. created on: 6/11/2023 at: 12:47:9
# Lines beginning with # denote comments

header:
version=2.11
name=SB_MarenCol_House_1H6R_1_mahogany
mods=biomesoplenty
size=27,22,21
offset=13,1,20
:endheader

#### VALIDATION ####
validation:
type=ground
structureAuthor=TheOddlySeagull
survival=true
worldGenEnabled=false
unique=false
preserveBlocks=false
preventNaturalHostileSpawns=false
selectionWeight=1
clusterValue=1
minDuplicateDistance=1
dimensionWhiteList=true
dimensionList=
biomeGroupList=
biomeWhiteList=true
biomeList=
leveling=0
fill=0
border=0
blockSwap=false
territoryName=
biomeReplacement=minecraft:
minGenerationHeight=0
maxGenerationHeight=255
:endvalidation

#### LAYERS ####
layer: 0
1,1,1,1,1,1,1,1,1,1,1,1,1,2,2,2,2,2,1,1,1,1,1,1,1,1,1
1,1,1,1,1,1,1,1,1,1,1,1,1,2,2,2,2,2,1,1,1,1,1,1,1,1,1
1,1,1,1,1,1,1,1,1,1,1,1,1,2,2,2,2,2,1,1,1,1,1,1,1,1,1
1,1,1,1,1,1,1,1,2,2,2,1,1,2,2,2,2,2,1,1,1,1,1,1,1,1,1
1,1,1,1,1,1,1,3,2,2,2,2,2,3,2,2,2,2,2,2,1,1,1,1,1,1,1
1,2,2,2,2,2,3,2,2,4,4,4,4,2,2,2,2,2,2,2,1,1,1,1,1,1,1
1,2,2,3,2,2,3,2,2,4,4,4,4,2,2,2,2,2,2,2,1,1,1,1,1,1,1
1,2,4,4,2,2,4,3,4,4,4,4,4,2,2,2,2,2,2,2,1,1,1,1,1,1,1
1,2,4,4,4,4,4,2,4,4,4,4,4,2,2,2,2,2,2,2,1,1,1,1,1,1,1
1,2,4,4,4,4,4,2,4,4,4,4,4,2,2,2,2,3,2,3,2,2,2,2,2,1,1
1,2,4,4,4,4,4,2,4,4,4,4,4,2,2,2,2,2,4,4,4,4,4,4,2,1,1
1,2,4,4,4,4,4,2,2,2,2,2,2,2,2,2,2,3,4,4,4,4,4,4,2,2,2
1,2,4,4,4,4,4,2,2,2,2,2,2,2,2,2,2,2,2,4,4,4,4,4,2,2,2
1,2,2,2,2,2,2,3,2,2,2,2,2,2,2,2,2,2,2,4,4,4,4,4,2,2,2
1,1,1,1,1,1,1,2,2,2,2,2,2,2,2,2,2,2,2,4,4,4,4,4,2,1,1
1,1,1,1,1,1,1,2,2,2,2,2,2,2,2,2,2,3,2,2,2,2,2,2,2,1,1
1,1,1,1,1,1,1,2,2,2,2,2,2,2,2,2,2,2,1,1,1,1,1,1,1,1,1
1,1,1,1,1,1,1,3,2,2,2,2,2,2,2,2,2,3,1,1,1,1,1,1,1,1,1
1,1,1,1,1,1,1,1,1,1,1,1,2,2,2,1,1,1,1,1,1,1,1,1,1,1,1
1,1,1,1,1,1,1,1,1,1,1,1,2,2,2,1,1,1,1,1,1,1,1,1,1,1,1
1,1,1,1,1,1,1,1,1,1,1,1,2,2,2,1,1,1,1,1,1,1,1,1,1,1,1
:endlayer
layer: 1
0,0,0,0,0,0,0,0,0,0,0,0,0,0,0,0,0,0,0,0,0,0,0,0,0,0,0
0,5,0,0,0,0,0,0,0,0,0,0,0,0,0,0,0,0,0,0,0,0,0,0,0,5,0
0,0,0,0,0,0,0,0,0,0,0,0,0,6,4,6,0,6,0,0,0,0,0,0,0,0,0
0,0,0,0,0,0,0,0,0,0,0,0,0,4,0,0,0,4,0,0,0,0,0,0,0,0,0
0,0,0,0,0,0,0,3,2,0,2,2,2,3,0,0,0,6,4,6,0,0,0,0,0,0,0
0,0,0,0,2,2,3,0,7,0,0,0,0,4,0,0,0,0,0,4,0,0,0,0,0,0,0
0,6,0,3,0,0,3,0,7,0,0,0,0,6,0,0,0,0,0,6,0,0,0,0,0,0,0
0,4,0,0,7,7,0,3,0,0,0,0,0,0,0,0,0,0,0,4,0,0,0,0,0,0,0
0,6,0,0,0,0,0,6,0,0,0,0,0,0,0,0,0,0,0,6,0,0,0,0,0,0,0
0,4,0,0,0,0,0,4,0,0,0,0,0,6,0,0,0,3,0,3,6,4,6,4,6,0,0
0,4,0,0,0,0,0,4,0,0,0,0,0,4,0,0,0,2,0,0,0,0,0,0,4,0,0
0,6,0,0,0,0,0,6,4,6,4,6,4,6,0,0,0,3,0,0,0,0,0,0,6,0,0
0,4,0,0,0,0,0,0,0,8,9,0,0,0,0,0,7,0,2,0,0,0,0,0,0,0,0
0,6,4,6,4,6,4,3,0,0,0,0,0,0,0,0,7,0,2,0,0,0,0,0,6,0,0
0,0,0,0,0,0,0,2,0,0,0,0,0,0,0,0,7,0,2,0,0,0,0,0,4,0,0
0,0,0,0,0,0,0,2,0,0,0,0,0,0,0,0,0,3,4,6,4,4,6,4,6,0,0
0,0,0,0,0,0,0,2,0,0,0,0,0,0,0,0,0,2,0,0,0,0,0,0,0,0,0
0,0,0,0,0,0,0,3,2,2,2,2,2,0,2,2,2,3,0,0,0,0,0,0,0,0,0
0,0,0,0,0,0,0,0,0,0,0,0,0,0,0,0,0,0,0,0,0,0,0,0,0,0,0
0,5,0,0,0,0,0,0,0,0,0,0,0,0,0,0,0,0,0,0,5,0,0,0,0,5,0
0,0,0,0,0,0,0,0,0,0,0,0,0,0,0,0,0,0,0,0,0,0,0,0,0,0,0
:endlayer
layer: 2
0,0,0,0,0,0,0,0,0,0,0,0,0,0,0,0,0,0,0,0,0,0,0,0,0,0,0
0,10,0,0,0,0,0,0,0,0,0,0,0,0,0,0,0,0,0,0,0,0,0,0,0,10,0
0,0,0,0,0,0,0,0,0,0,0,0,0,6,5,6,0,6,0,0,0,0,0,0,0,0,0
0,0,0,0,0,0,0,0,0,0,0,0,0,4,0,0,0,4,0,0,0,0,0,0,0,0,0
0,0,0,0,0,0,0,3,2,0,2,5,2,3,0,0,0,6,5,6,0,0,0,0,0,0,0
0,0,0,0,2,2,3,0,0,0,0,0,0,4,0,0,0,0,0,5,0,0,0,0,0,0,0
0,6,0,3,0,0,3,0,0,0,0,0,0,6,0,0,0,0,0,6,0,0,0,0,0,0,0
0,4,0,0,0,0,0,3,0,0,0,0,0,0,0,0,0,0,0,5,0,0,0,0,0,0,0
0,6,0,0,0,0,0,6,0,0,0,0,0,0,0,0,0,0,0,6,0,0,0,0,0,0,0
0,5,0,0,0,0,0,4,0,0,0,0,0,6,0,0,0,3,0,3,6,5,6,5,6,0,0
0,5,0,0,0,0,0,4,0,0,0,0,0,4,0,0,0,2,0,0,0,0,0,0,4,0,0
0,6,0,0,0,0,0,6,4,6,4,6,4,6,0,0,0,3,0,0,0,0,0,0,6,0,0
0,4,0,0,0,0,0,0,0,0,8,9,0,0,0,0,0,0,2,0,0,0,0,0,0,0,0
0,6,4,6,5,6,4,3,0,0,0,0,0,0,0,0,0,0,2,0,0,0,0,0,6,0,0
0,0,0,0,0,0,0,2,0,0,0,0,0,0,0,0,0,0,2,0,0,0,0,0,4,0,0
0,0,0,0,0,0,0,5,0,0,0,0,0,0,0,0,0,3,4,6,5,5,6,4,6,0,0
0,0,0,0,0,0,0,2,0,0,0,0,0,0,0,0,0,2,0,0,0,0,0,0,0,0,0
0,0,0,0,0,0,0,3,2,5,2,5,2,0,2,5,2,3,0,0,0,0,0,0,0,0,0
0,0,0,0,0,0,0,0,0,0,0,0,0,0,0,0,0,0,0,0,0,0,0,0,0,0,0
0,10,0,0,0,0,0,0,0,0,0,0,0,0,0,0,0,0,0,0,10,0,0,0,0,10,0
0,0,0,0,0,0,0,0,0,0,0,0,0,0,0,0,0,0,0,0,0,0,0,0,0,0,0
:endlayer
layer: 3
0,0,0,0,0,0,0,0,0,0,0,0,0,0,0,0,0,0,0,0,0,0,0,0,0,0,0
0,0,0,0,0,0,0,0,0,0,0,0,0,11,0,0,0,11,0,0,0,0,0,0,0,0,0
0,0,0,0,0,0,0,0,0,0,0,0,12,6,5,6,4,6,13,0,0,0,0,0,0,0,0
0,0,0,0,0,0,0,11,0,0,11,0,0,4,0,0,0,4,0,11,0,0,0,0,0,0,0
0,0,0,0,0,0,12,3,2,2,2,5,2,3,0,0,0,6,5,6,13,0,0,0,0,0,0
0,11,0,0,14,2,3,15,16,0,0,0,0,4,0,0,0,17,0,5,0,0,0,0,0,0,0
12,6,4,3,18,19,3,20,16,0,0,0,12,6,13,0,0,0,12,6,0,0,0,0,0,0,0
0,4,0,0,0,0,0,3,0,0,0,0,0,21,0,0,0,0,0,5,0,0,0,0,0,0,0
0,6,13,0,0,0,12,6,13,0,0,0,0,22,0,0,0,0,12,6,0,0,0,0,11,0,0
0,5,0,0,0,0,0,4,0,0,0,0,12,6,13,0,0,3,2,3,6,5,6,5,6,13,0
0,5,0,0,0,0,0,4,0,11,0,11,0,4,0,0,0,2,0,0,17,0,17,0,4,0,0
0,6,13,0,0,0,12,6,4,6,4,6,4,6,13,0,12,3,0,0,0,0,0,12,6,0,0
0,4,0,11,0,11,0,4,0,0,0,8,9,17,0,0,16,15,2,0,0,0,0,0,4,0,0
12,6,4,6,5,6,4,3,13,0,0,0,0,0,0,0,16,0,2,0,0,0,0,12,6,0,0
0,17,0,0,0,0,0,2,0,0,0,0,0,0,0,0,16,20,2,11,0,0,11,0,4,0,0
0,0,0,0,0,0,0,5,0,0,0,0,0,0,0,0,12,3,4,6,5,5,6,4,6,13,0
0,0,0,0,0,0,0,2,0,0,0,0,0,0,0,0,0,2,0,0,0,0,0,0,17,0,0
0,0,0,0,0,0,12,3,2,5,2,5,2,2,2,5,2,3,13,0,0,0,0,0,0,0,0
0,0,0,0,0,0,0,17,0,0,17,0,17,0,17,0,0,17,0,0,0,0,0,0,0,0,0
0,0,0,0,0,0,0,0,0,0,0,0,0,0,0,0,0,0,0,0,0,0,0,0,0,0,0
0,0,0,0,0,0,0,0,0,0,0,0,0,0,0,0,0,0,0,0,0,0,0,0,0,0,0
:endlayer
layer: 4
0,0,0,0,0,0,0,0,0,0,0,0,0,0,0,0,0,0,0,0,0,0,0,0,0,0,0
0,0,0,0,0,0,0,0,0,0,0,0,8,9,0,0,0,23,24,0,0,0,0,0,0,0,0
0,0,0,0,0,0,0,0,0,0,0,0,8,6,25,25,25,6,24,0,0,0,0,0,0,0,0
0,0,0,0,0,0,0,26,27,26,27,26,4,26,27,27,27,26,24,0,0,0,0,0,0,0,0
0,0,0,0,0,0,0,26,25,25,25,25,25,25,25,25,25,25,25,6,0,0,0,0,0,0,0
28,28,28,28,28,2,2,2,2,4,27,4,27,26,27,27,27,26,27,26,0,0,0,0,0,0,0
21,6,25,25,25,25,25,2,2,4,27,4,27,26,4,4,4,26,27,26,0,0,0,0,0,0,0
0,26,0,0,0,0,0,26,27,4,27,4,27,26,27,27,27,26,27,26,0,0,0,0,0,0,0
0,26,0,0,0,0,0,26,27,4,27,4,27,26,25,25,25,26,27,6,28,28,28,28,28,28,0
0,26,0,0,0,0,0,26,27,4,27,4,27,26,27,4,27,26,25,25,25,25,25,25,6,21,0
0,26,0,0,0,0,0,26,27,4,27,4,27,26,27,4,27,26,0,0,0,0,0,0,26,0,0
0,26,0,0,0,0,0,26,25,25,25,25,25,25,25,25,25,3,0,0,0,0,0,0,26,0,0
0,26,0,0,0,0,0,26,0,0,0,0,8,4,27,4,2,2,2,0,0,0,0,0,26,0,0
22,6,25,25,25,25,25,26,4,4,4,4,4,4,27,4,2,2,2,0,0,0,0,0,26,0,0
29,29,29,29,29,29,29,26,27,4,27,4,27,4,27,4,2,2,2,0,0,0,0,0,26,0,0
0,0,0,0,0,0,0,26,27,4,27,4,27,4,27,4,27,3,25,25,25,25,25,25,6,22,0
0,0,0,0,0,0,0,26,27,4,27,4,27,4,27,4,27,26,29,29,29,29,29,29,29,29,0
0,0,0,0,0,0,0,26,25,25,25,25,25,25,25,25,25,26,0,0,0,0,0,0,0,0,0
0,0,0,0,0,0,0,26,27,26,27,27,26,27,27,26,27,26,0,0,0,0,0,0,0,0,0
0,0,0,0,0,0,0,0,0,0,0,0,0,0,0,0,0,0,0,0,0,0,0,0,0,0,0
0,0,0,0,0,0,0,0,0,0,0,0,0,0,0,0,0,0,0,0,0,0,0,0,0,0,0
:endlayer
layer: 5
0,0,0,0,0,0,0,0,0,0,0,0,0,0,0,0,0,0,0,0,0,0,0,0,0,0,0
0,0,0,0,0,0,0,0,0,0,0,0,0,8,9,0,23,24,0,0,0,0,0,0,0,0,0
0,0,0,0,0,0,0,0,0,0,0,0,0,8,4,4,4,24,0,0,0,0,0,0,0,0,0
0,0,0,0,0,0,0,6,4,6,4,6,4,6,4,6,4,24,0,0,0,0,0,0,0,0,0
0,0,0,0,0,0,0,2,0,0,0,0,0,4,0,6,4,6,4,6,0,0,0,0,0,0,0
0,0,0,0,0,2,2,0,7,0,0,0,0,6,0,0,0,0,0,4,0,0,0,0,0,0,0
28,28,28,28,28,28,2,0,7,0,0,0,0,4,0,0,0,0,30,6,0,0,0,0,0,0,0
21,26,21,21,21,21,21,2,0,0,0,0,0,4,0,0,0,0,0,4,0,0,0,0,0,0,0
0,4,0,0,0,0,0,6,0,0,0,0,0,6,4,6,0,6,4,6,0,0,0,0,0,0,0
0,4,0,0,0,0,0,5,0,0,0,0,0,0,0,0,0,4,28,28,28,28,28,28,28,28,0
0,4,0,0,0,0,0,5,0,0,0,0,0,0,0,0,0,6,21,21,21,21,21,21,6,21,0
0,4,0,0,0,0,0,6,4,6,4,6,4,6,0,0,0,3,0,0,0,0,0,0,4,0,0
22,26,22,22,22,22,22,4,0,0,0,0,0,0,0,0,7,0,2,0,0,0,0,0,4,0,0
29,29,29,29,29,29,29,6,5,5,5,5,0,0,0,0,7,0,2,0,0,0,0,0,4,0,0
0,0,0,0,0,0,0,4,0,0,0,0,0,0,0,0,7,0,2,22,22,22,22,22,6,22,0
0,0,0,0,0,0,0,4,0,0,0,0,0,0,0,0,0,3,29,29,29,29,29,29,29,29,0
0,0,0,0,0,0,0,6,0,0,0,0,0,0,0,0,0,6,0,0,0,0,0,0,0,0,0
0,0,0,0,0,0,0,4,0,0,0,0,0,0,0,0,0,4,0,0,0,0,0,0,0,0,0
0,0,0,0,0,0,0,6,4,6,4,4,6,4,4,6,4,6,0,0,0,0,0,0,0,0,0
0,0,0,0,0,0,0,0,0,0,0,0,0,0,0,0,0,0,0,0,0,0,0,0,0,0,0
0,0,0,0,0,0,0,0,0,0,0,0,0,0,0,0,0,0,0,0,0,0,0,0,0,0,0
:endlayer
layer: 6
0,0,0,0,0,0,0,0,0,0,0,0,0,0,0,0,0,0,0,0,0,0,0,0,0,0,0
0,0,0,0,0,0,0,0,0,0,0,0,0,0,8,22,24,0,0,0,0,0,0,0,0,0,0
0,0,0,0,0,0,0,0,0,0,0,0,0,0,8,4,24,0,0,0,0,0,0,0,0,0,0
0,0,0,0,0,0,0,6,5,6,5,6,5,6,4,6,24,0,0,0,0,0,0,0,0,0,0
0,0,0,0,0,0,0,2,0,0,0,0,0,4,0,6,4,6,5,6,0,0,0,0,0,0,0
0,0,0,0,0,2,2,0,0,0,0,0,0,6,0,0,0,0,0,5,0,0,0,0,0,0,0
0,0,0,0,0,0,2,0,0,0,0,0,0,4,0,0,0,0,30,6,0,0,0,0,0,0,0
28,28,28,28,28,28,28,2,0,0,0,0,0,4,0,0,0,0,0,5,0,0,0,0,0,0,0
21,26,21,21,21,21,21,6,0,0,0,0,0,6,4,6,0,6,4,6,0,0,0,0,0,0,0
0,4,0,0,0,0,0,0,0,0,0,0,0,0,0,0,0,4,0,0,0,0,0,0,0,0,0
0,4,0,0,0,0,0,0,0,0,0,0,0,0,0,0,0,6,28,28,28,28,28,28,28,28,0
22,26,22,22,22,22,22,6,4,6,4,6,4,6,0,0,0,3,21,21,21,21,21,21,6,21,0
29,29,29,29,29,29,29,4,0,0,0,0,0,0,0,0,0,0,2,0,0,0,0,0,4,0,0
0,0,0,0,0,0,0,6,0,0,0,0,0,0,0,0,0,0,2,22,22,22,22,22,6,22,0
0,0,0,0,0,0,0,5,0,0,0,0,0,0,0,0,0,0,2,29,29,29,29,29,29,29,0
0,0,0,0,0,0,0,5,0,0,0,0,0,0,0,0,0,3,0,0,0,0,0,0,0,0,0
0,0,0,0,0,0,0,6,0,0,0,0,0,0,0,0,0,6,0,0,0,0,0,0,0,0,0
0,0,0,0,0,0,0,4,0,0,0,0,0,0,0,0,0,5,0,0,0,0,0,0,0,0,0
0,0,0,0,0,0,0,6,5,6,5,5,6,5,5,6,5,6,0,0,0,0,0,0,0,0,0
0,0,0,0,0,0,0,0,0,0,0,0,0,0,0,0,0,0,0,0,0,0,0,0,0,0,0
0,0,0,0,0,0,0,0,0,0,0,0,0,0,0,0,0,0,0,0,0,0,0,0,0,0,0
:endlayer
layer: 7
0,0,0,0,0,0,0,0,0,0,0,0,0,0,0,0,0,0,0,0,0,0,0,0,0,0,0
0,0,0,0,0,0,0,0,0,0,0,0,0,0,0,31,0,0,0,0,0,0,0,0,0,0,0
0,0,0,0,0,0,0,0,0,0,0,0,0,0,0,31,0,0,0,0,0,0,0,0,0,0,0
0,0,0,0,0,0,0,6,5,6,5,6,5,6,4,6,0,0,0,0,0,0,0,0,0,0,0
0,0,0,0,0,0,0,2,0,17,0,17,0,4,0,6,4,6,5,6,0,0,0,0,0,0,0
0,0,0,0,0,14,2,15,0,0,0,0,12,6,0,17,0,17,0,5,0,0,0,0,0,0,0
0,0,0,0,0,0,32,20,0,0,0,0,0,4,0,0,0,0,30,6,0,0,0,0,0,0,0
0,0,0,0,0,0,0,2,0,0,0,0,0,4,0,11,0,11,0,5,0,0,0,0,0,0,0
28,28,28,28,28,28,28,6,13,0,0,0,12,6,4,6,4,6,4,6,0,0,0,0,0,0,0
21,26,21,21,21,21,21,21,0,0,0,0,0,21,0,17,0,4,0,0,0,0,0,0,0,0,0
22,26,22,22,22,22,22,22,0,11,0,11,0,22,0,0,0,6,0,0,0,0,0,0,0,0,0
29,29,29,29,29,29,29,6,4,6,4,6,4,6,13,0,12,3,28,28,28,28,28,28,28,28,0
0,0,0,0,0,0,0,4,0,17,0,17,0,17,0,0,0,15,2,25,25,25,25,25,6,9,0
0,0,0,0,0,0,0,6,13,0,0,0,0,0,0,0,0,0,2,29,29,29,29,29,29,29,0
0,0,0,0,0,0,0,5,0,0,0,0,0,0,0,0,0,20,2,0,0,0,0,0,0,0,0
0,0,0,0,0,0,0,5,0,0,0,0,0,0,0,0,12,3,0,0,0,0,0,0,0,0,0
0,0,0,0,0,0,0,6,13,0,0,0,0,0,0,0,0,6,0,0,0,0,0,0,0,0,0
0,0,0,0,0,0,0,4,0,11,0,0,11,0,0,11,0,5,0,0,0,0,0,0,0,0,0
0,0,0,0,0,0,0,6,5,6,5,5,6,5,5,6,5,6,0,0,0,0,0,0,0,0,0
0,0,0,0,0,0,0,0,0,0,0,0,0,0,0,0,0,0,0,0,0,0,0,0,0,0,0
0,0,0,0,0,0,0,0,0,0,0,0,0,0,0,0,0,0,0,0,0,0,0,0,0,0,0
:endlayer
layer: 8
0,0,0,0,0,0,0,0,0,0,0,0,0,0,0,0,0,0,0,0,0,0,0,0,0,0,0
0,0,0,0,0,0,0,0,0,0,0,0,0,0,0,0,0,0,0,0,0,0,0,0,0,0,0
0,0,0,0,0,0,8,9,0,0,0,0,0,0,0,23,24,0,0,0,0,0,0,0,0,0,0
0,0,0,0,0,0,8,6,25,25,25,25,25,25,25,6,24,0,0,0,0,0,0,0,0,0,0
0,0,0,0,0,0,8,26,27,4,27,4,27,26,27,6,25,25,25,6,0,0,0,0,0,0,0
0,0,0,0,0,0,2,26,27,4,27,4,27,26,27,26,27,27,27,26,0,0,0,0,0,0,0
0,0,0,0,0,0,8,26,27,4,27,4,27,26,27,26,27,27,30,26,0,0,0,0,0,0,0
0,0,0,0,0,0,8,26,27,4,27,4,27,26,27,26,27,27,27,26,0,0,0,0,0,0,0
0,0,0,0,0,0,8,26,25,25,25,25,25,25,25,25,25,25,25,6,0,0,0,0,0,0,0
28,28,28,28,28,28,28,26,27,4,27,4,27,26,27,4,27,26,0,0,0,0,0,0,0,0,0
29,29,29,29,29,29,29,26,27,4,27,4,27,26,27,4,27,26,0,0,0,0,0,0,0,0,0
0,0,0,0,0,0,8,26,25,25,25,25,25,25,25,25,25,26,0,0,0,0,0,0,0,0,0
0,0,0,0,0,0,8,26,27,27,27,27,27,27,27,27,27,26,2,31,31,31,31,31,31,31,0
0,0,0,0,0,0,8,26,4,4,4,4,4,4,4,4,4,2,2,0,0,0,0,0,0,0,0
0,0,0,0,0,0,8,26,27,27,27,27,27,27,27,27,27,26,2,0,0,0,0,0,0,0,0
0,0,0,0,0,0,8,26,4,4,4,4,4,4,4,4,4,26,24,0,0,0,0,0,0,0,0
0,0,0,0,0,0,8,26,27,27,27,27,27,27,27,27,27,26,24,0,0,0,0,0,0,0,0
0,0,0,0,0,0,8,26,4,4,4,4,4,4,4,4,4,26,24,0,0,0,0,0,0,0,0
0,0,0,0,0,0,8,6,25,25,25,25,25,25,25,25,25,6,24,0,0,0,0,0,0,0,0
0,0,0,0,0,0,8,9,0,0,0,0,0,0,0,0,0,23,24,0,0,0,0,0,0,0,0
0,0,0,0,0,0,0,0,0,0,0,0,0,0,0,0,0,0,0,0,0,0,0,0,0,0,0
:endlayer
layer: 9
0,0,0,0,0,0,0,0,0,0,0,0,0,0,0,0,0,0,0,0,0,0,0,0,0,0,0
0,0,0,0,0,0,0,0,0,0,0,0,0,0,0,0,0,0,0,0,0,0,0,0,0,0,0
0,0,0,0,0,0,0,8,9,0,0,0,0,0,23,24,0,0,0,0,0,0,0,0,0,0,0
0,0,0,0,0,0,0,8,6,4,4,5,4,4,6,24,0,0,0,0,0,0,0,0,0,0,0
0,0,0,0,0,0,0,8,9,0,0,0,0,0,23,6,4,6,4,6,0,0,0,0,0,0,0
0,0,0,0,0,0,2,8,9,0,0,0,0,0,21,4,0,0,0,4,0,0,0,0,0,0,0
0,0,0,0,0,0,0,8,9,0,0,0,0,0,0,6,0,0,30,6,0,0,0,0,0,0,0
0,0,0,0,0,0,0,8,9,0,0,0,0,0,0,4,0,0,0,4,0,0,0,0,0,0,0
0,0,0,0,0,0,0,8,25,4,4,6,0,6,4,6,0,6,4,6,0,0,0,0,0,0,0
0,0,0,0,0,0,0,8,9,0,0,0,0,0,0,0,0,4,0,0,0,0,0,0,0,0,0
0,0,0,0,0,0,0,8,9,0,0,0,0,0,0,0,0,4,0,0,0,0,0,0,0,0,0
0,0,0,0,0,0,0,8,9,0,0,0,0,6,0,0,23,6,0,0,0,0,0,0,0,0,0
0,0,0,0,0,0,0,8,6,0,0,0,0,0,0,0,23,24,33,0,0,0,0,0,0,0,0
0,0,0,0,0,0,0,8,26,0,0,0,0,0,0,0,23,24,2,0,0,0,0,0,0,0,0
0,0,0,0,0,0,0,8,26,0,0,0,0,0,0,0,23,24,2,0,0,0,0,0,0,0,0
0,0,0,0,0,0,0,8,6,0,0,0,0,0,0,0,23,24,0,0,0,0,0,0,0,0,0
0,0,0,0,0,0,0,8,9,0,0,0,0,0,0,0,23,24,0,0,0,0,0,0,0,0,0
0,0,0,0,0,0,0,8,9,0,0,0,0,0,0,0,23,24,0,0,0,0,0,0,0,0,0
0,0,0,0,0,0,0,8,25,4,4,6,4,6,4,4,25,24,0,0,0,0,0,0,0,0,0
0,0,0,0,0,0,0,8,9,0,0,0,0,0,0,0,23,24,0,0,0,0,0,0,0,0,0
0,0,0,0,0,0,0,0,0,0,0,0,0,0,0,0,0,0,0,0,0,0,0,0,0,0,0
:endlayer
layer: 10
0,0,0,0,0,0,0,0,0,0,0,0,0,0,0,0,0,0,0,0,0,0,0,0,0,0,0
0,0,0,0,0,0,0,0,0,0,0,0,0,0,0,0,0,0,0,0,0,0,0,0,0,0,0
0,0,0,0,0,0,0,0,8,9,0,0,0,23,24,0,0,0,0,0,0,0,0,0,0,0,0
0,0,0,0,0,0,0,0,8,6,4,5,4,6,24,0,0,0,0,0,0,0,0,0,0,0,0
0,0,0,0,0,0,0,0,8,9,0,0,0,23,24,6,5,6,5,6,0,0,0,0,0,0,0
0,0,0,0,0,0,2,0,8,9,0,0,0,23,28,4,0,0,0,5,0,0,0,0,0,0,0
0,0,0,0,0,0,0,0,8,9,0,0,0,23,21,6,0,0,30,6,0,0,0,0,0,0,0
0,0,0,0,0,0,0,0,8,9,0,0,0,0,0,4,0,0,0,5,0,0,0,0,0,0,0
0,0,0,0,0,0,0,0,8,25,4,6,0,6,4,6,0,6,5,6,0,0,0,0,0,0,0
0,0,0,0,0,0,0,0,8,9,0,0,0,0,0,0,0,5,0,0,0,0,0,0,0,0,0
0,0,0,0,0,0,0,0,8,9,0,0,0,0,0,0,0,5,0,0,0,0,0,0,0,0,0
0,0,0,0,0,0,0,0,8,9,0,0,0,6,0,23,4,6,0,0,0,0,0,0,0,0,0
0,0,0,0,0,0,0,0,6,13,0,0,0,0,0,23,24,0,0,0,0,0,0,0,0,0,0
0,0,0,0,0,0,0,0,5,0,0,0,0,0,0,23,24,0,2,0,0,0,0,0,0,0,0
0,0,0,0,0,0,0,0,5,0,0,0,0,0,0,23,24,0,32,0,0,0,0,0,0,0,0
0,0,0,0,0,0,0,0,6,13,0,0,0,0,0,23,24,0,0,0,0,0,0,0,0,0,0
0,0,0,0,0,0,0,0,8,9,0,0,0,0,0,23,24,0,0,0,0,0,0,0,0,0,0
0,0,0,0,0,0,0,0,8,9,0,0,0,0,0,23,24,0,0,0,0,0,0,0,0,0,0
0,0,0,0,0,0,0,0,8,25,4,6,5,6,4,25,24,0,0,0,0,0,0,0,0,0,0
0,0,0,0,0,0,0,0,8,9,0,0,0,0,0,23,24,0,0,0,0,0,0,0,0,0,0
0,0,0,0,0,0,0,0,0,0,0,0,0,0,0,0,0,0,0,0,0,0,0,0,0,0,0
:endlayer
layer: 11
0,0,0,0,0,0,0,0,0,0,0,0,0,0,0,0,0,0,0,0,0,0,0,0,0,0,0
0,0,0,0,0,0,0,0,0,0,0,0,0,0,0,0,0,0,0,0,0,0,0,0,0,0,0
0,0,0,0,0,0,0,0,0,8,9,0,23,24,0,0,0,0,0,0,0,0,0,0,0,0,0
0,0,0,0,0,0,0,0,0,8,6,4,6,24,0,0,0,0,0,0,0,0,0,0,0,0,0
0,0,0,0,0,0,0,0,0,8,9,17,23,24,0,6,5,6,5,6,0,0,0,0,0,0,0
0,0,0,0,0,0,2,0,0,8,9,0,23,24,0,4,0,17,0,5,0,0,0,0,0,0,0
0,0,0,0,0,0,0,0,0,8,9,0,23,24,28,6,13,0,30,6,0,0,0,0,0,0,0
0,0,0,0,0,0,0,0,0,8,9,11,21,21,21,4,0,11,0,5,0,0,0,0,0,0,0
0,0,0,0,0,0,0,0,0,8,25,6,4,6,4,6,4,6,5,6,0,0,0,0,0,0,0
0,0,0,0,0,0,0,0,0,8,9,17,0,17,0,0,0,5,0,0,0,0,0,0,0,0,0
0,0,0,0,0,0,0,0,0,8,9,0,0,11,0,0,0,5,0,0,0,0,0,0,0,0,0
0,0,0,0,0,0,0,28,28,8,9,0,12,6,23,4,4,6,22,0,0,0,0,0,0,0,0
0,0,0,0,0,0,0,21,6,21,21,0,0,17,23,29,29,29,29,0,0,0,0,0,0,0,0
0,0,0,0,0,0,0,0,5,0,0,0,0,0,23,24,0,0,2,0,0,0,0,0,0,0,0
0,0,0,0,0,0,0,0,5,0,0,0,0,0,23,24,0,0,0,0,0,0,0,0,0,0,0
0,0,0,0,0,0,0,22,6,22,9,0,0,0,23,24,0,0,0,0,0,0,0,0,0,0,0
0,0,0,0,0,0,0,29,29,8,9,0,0,0,23,24,0,0,0,0,0,0,0,0,0,0,0
0,0,0,0,0,0,0,0,0,8,9,11,0,11,23,24,0,0,0,0,0,0,0,0,0,0,0
0,0,0,0,0,0,0,0,0,8,25,6,5,6,25,24,0,0,0,0,0,0,0,0,0,0,0
0,0,0,0,0,0,0,0,0,8,9,0,0,0,23,24,0,0,0,0,0,0,0,0,0,0,0
0,0,0,0,0,0,0,0,0,0,0,0,0,0,0,0,0,0,0,0,0,0,0,0,0,0,0
:endlayer
layer: 12
0,0,0,0,0,0,0,0,0,0,0,0,0,0,0,0,0,0,0,0,0,0,0,0,0,0,0
0,0,0,0,0,0,0,0,0,0,0,0,0,0,0,0,0,0,0,0,0,0,0,0,0,0,0
0,0,0,0,0,0,0,0,0,0,8,22,24,0,0,0,0,0,0,0,0,0,0,0,0,0,0
0,0,0,0,0,0,0,0,0,0,8,6,24,0,0,0,0,0,0,0,0,0,0,0,0,0,0
0,0,0,0,0,0,0,0,0,0,8,26,24,0,0,6,25,25,25,6,0,0,0,0,0,0,0
0,0,0,0,0,0,34,0,0,0,8,26,24,0,0,26,27,27,27,26,0,0,0,0,0,0,0
0,0,0,0,0,0,0,0,0,0,8,26,24,0,0,26,27,27,30,26,0,0,0,0,0,0,0
0,0,0,0,0,0,0,0,0,0,8,26,24,23,24,26,27,27,27,26,0,0,0,0,0,0,0
0,0,0,0,0,0,0,0,0,0,8,25,4,25,28,6,25,25,25,6,0,0,0,0,0,0,0
0,0,0,0,0,0,0,0,0,0,8,9,0,26,21,21,21,26,21,0,0,0,0,0,0,0,0
0,0,0,0,0,0,0,0,0,0,8,9,0,26,22,22,22,26,22,0,0,0,0,0,0,0,0
0,0,0,0,0,0,0,0,0,0,8,9,0,6,29,29,29,29,29,0,0,0,0,0,0,0,0
0,0,0,0,0,0,0,28,28,28,28,9,0,23,24,0,0,0,0,0,0,0,0,0,0,0,0
0,0,0,0,0,0,0,21,26,21,21,21,0,23,24,0,0,0,2,0,0,0,0,0,0,0,0
0,0,0,0,0,0,0,22,26,22,22,9,0,23,24,0,0,0,0,0,0,0,0,0,0,0,0
0,0,0,0,0,0,0,29,29,29,8,9,0,23,24,0,0,0,0,0,0,0,0,0,0,0,0
0,0,0,0,0,0,0,0,0,0,8,9,0,23,24,0,0,0,0,0,0,0,0,0,0,0,0
0,0,0,0,0,0,0,0,0,0,8,9,0,23,24,0,0,0,0,0,0,0,0,0,0,0,0
0,0,0,0,0,0,0,0,0,0,8,25,4,25,24,0,0,0,0,0,0,0,0,0,0,0,0
0,0,0,0,0,0,0,0,0,0,8,9,0,23,24,0,0,0,0,0,0,0,0,0,0,0,0
0,0,0,0,0,0,0,0,0,0,0,0,0,0,0,0,0,0,0,0,0,0,0,0,0,0,0
:endlayer
layer: 13
0,0,0,0,0,0,0,0,0,0,0,0,0,0,0,0,0,0,0,0,0,0,0,0,0,0,0
0,0,0,0,0,0,0,0,0,0,0,0,0,0,0,0,0,0,0,0,0,0,0,0,0,0,0
0,0,0,0,0,0,0,0,0,0,0,31,0,0,0,0,0,0,0,0,0,0,0,0,0,0,0
0,0,0,0,0,0,0,0,0,0,0,31,0,0,0,0,0,0,0,0,0,0,0,0,0,0,0
0,0,0,0,0,0,0,0,0,0,0,31,0,0,0,6,4,6,4,6,0,0,0,0,0,0,0
0,0,0,0,0,0,7,0,0,0,0,31,0,0,0,4,0,0,0,4,0,0,0,0,0,0,0
0,0,0,0,0,0,0,0,0,0,0,31,0,0,0,6,0,0,30,6,0,0,0,0,0,0,0
0,0,0,0,0,0,0,0,0,0,0,8,22,24,0,4,0,0,0,4,0,0,0,0,0,0,0
0,0,0,0,0,0,0,0,0,0,0,8,6,24,0,6,4,6,4,6,0,0,0,0,0,0,0
0,0,0,0,0,0,0,0,0,0,0,8,26,24,28,28,28,28,28,0,0,0,0,0,0,0,0
0,0,0,0,0,0,0,0,0,0,0,8,26,29,29,29,29,29,29,0,0,0,0,0,0,0,0
0,0,0,0,0,0,0,0,0,0,0,8,26,24,0,0,0,0,0,0,0,0,0,0,0,0,0
0,0,0,0,0,0,0,0,0,0,0,8,26,24,0,0,0,0,0,0,0,0,0,0,0,0,0
0,0,0,0,0,0,0,28,28,28,28,8,26,24,0,0,0,0,2,0,0,0,0,0,0,0,0
0,0,0,0,0,0,0,29,29,29,29,29,26,24,0,0,0,0,0,0,0,0,0,0,0,0,0
0,0,0,0,0,0,0,0,0,0,0,8,26,24,0,0,0,0,0,0,0,0,0,0,0,0,0
0,0,0,0,0,0,0,0,0,0,0,8,26,24,0,0,0,0,0,0,0,0,0,0,0,0,0
0,0,0,0,0,0,0,0,0,0,0,8,26,24,0,0,0,0,0,0,0,0,0,0,0,0,0
0,0,0,0,0,0,0,0,0,0,0,8,6,24,0,0,0,0,0,0,0,0,0,0,0,0,0
0,0,0,0,0,0,0,0,0,0,0,8,21,24,0,0,0,0,0,0,0,0,0,0,0,0,0
0,0,0,0,0,0,0,0,0,0,0,0,0,0,0,0,0,0,0,0,0,0,0,0,0,0,0
:endlayer
layer: 14
0,0,0,0,0,0,0,0,0,0,0,0,0,0,0,0,0,0,0,0,0,0,0,0,0,0,0
0,0,0,0,0,0,0,0,0,0,0,0,0,0,0,0,0,0,0,0,0,0,0,0,0,0,0
0,0,0,0,0,0,0,0,0,0,0,0,0,0,0,0,0,0,0,0,0,0,0,0,0,0,0
0,0,0,0,0,0,0,0,0,0,0,0,0,0,0,0,0,0,0,0,0,0,0,0,0,0,0
0,0,0,0,0,0,0,0,0,0,0,0,0,0,0,6,5,6,5,6,0,0,0,0,0,0,0
0,0,0,0,0,0,0,0,0,0,0,0,0,0,0,5,0,0,0,5,0,0,0,0,0,0,0
0,0,0,0,0,0,0,0,0,0,0,0,0,0,0,6,0,0,30,6,0,0,0,0,0,0,0
0,0,0,0,0,0,0,0,0,0,0,0,31,0,0,5,0,0,0,5,0,0,0,0,0,0,0
0,0,0,0,0,0,0,0,0,0,0,0,31,0,0,6,5,6,5,6,0,0,0,0,0,0,0
0,0,0,0,0,0,0,0,0,0,0,0,31,0,0,0,0,0,0,0,0,0,0,0,0,0,0
0,0,0,0,0,0,0,0,0,0,0,0,31,0,0,0,0,0,0,0,0,0,0,0,0,0,0
0,0,0,0,0,0,0,0,0,0,0,0,31,0,0,0,0,0,0,0,0,0,0,0,0,0,0
0,0,0,0,0,0,0,0,0,0,0,0,31,0,0,0,0,0,0,0,0,0,0,0,0,0,0
0,0,0,0,0,0,0,0,0,0,0,0,31,0,0,0,0,0,34,0,0,0,0,0,0,0,0
0,0,0,0,0,0,0,0,0,0,0,0,31,0,0,0,0,0,0,0,0,0,0,0,0,0,0
0,0,0,0,0,0,0,0,0,0,0,0,31,0,0,0,0,0,0,0,0,0,0,0,0,0,0
0,0,0,0,0,0,0,0,0,0,0,0,31,0,0,0,0,0,0,0,0,0,0,0,0,0,0
0,0,0,0,0,0,0,0,0,0,0,0,31,0,0,0,0,0,0,0,0,0,0,0,0,0,0
0,0,0,0,0,0,0,0,0,0,0,0,31,0,0,0,0,0,0,0,0,0,0,0,0,0,0
0,0,0,0,0,0,0,0,0,0,0,0,31,0,0,0,0,0,0,0,0,0,0,0,0,0,0
0,0,0,0,0,0,0,0,0,0,0,0,0,0,0,0,0,0,0,0,0,0,0,0,0,0,0
:endlayer
layer: 15
0,0,0,0,0,0,0,0,0,0,0,0,0,0,0,0,0,0,0,0,0,0,0,0,0,0,0
0,0,0,0,0,0,0,0,0,0,0,0,0,0,0,0,0,0,0,0,0,0,0,0,0,0,0
0,0,0,0,0,0,0,0,0,0,0,0,0,0,0,0,0,0,0,0,0,0,0,0,0,0,0
0,0,0,0,0,0,0,0,0,0,0,0,0,0,0,5,0,5,0,5,0,0,0,0,0,0,0
0,0,0,0,0,0,0,0,0,0,0,0,0,0,5,6,5,6,5,6,5,0,0,0,0,0,0
0,0,0,0,0,0,0,0,0,0,0,0,0,0,0,5,0,17,0,5,0,0,0,0,0,0,0
0,0,0,0,0,0,0,0,0,0,0,0,0,0,5,6,13,0,30,6,5,0,0,0,0,0,0
0,0,0,0,0,0,0,0,0,0,0,0,0,0,0,5,0,11,0,5,0,0,0,0,0,0,0
0,0,0,0,0,0,0,0,0,0,0,0,0,0,5,6,5,6,5,6,5,0,0,0,0,0,0
0,0,0,0,0,0,0,0,0,0,0,0,0,0,0,5,0,5,0,5,0,0,0,0,0,0,0
0,0,0,0,0,0,0,0,0,0,0,0,0,0,0,0,0,0,0,0,0,0,0,0,0,0,0
0,0,0,0,0,0,0,0,0,0,0,0,0,0,0,0,0,0,0,0,0,0,0,0,0,0,0
0,0,0,0,0,0,0,0,0,0,0,0,0,0,0,0,0,0,0,0,0,0,0,0,0,0,0
0,0,0,0,0,0,0,0,0,0,0,0,0,0,0,0,0,0,7,0,0,0,0,0,0,0,0
0,0,0,0,0,0,0,0,0,0,0,0,0,0,0,0,0,0,0,0,0,0,0,0,0,0,0
0,0,0,0,0,0,0,0,0,0,0,0,0,0,0,0,0,0,0,0,0,0,0,0,0,0,0
0,0,0,0,0,0,0,0,0,0,0,0,0,0,0,0,0,0,0,0,0,0,0,0,0,0,0
0,0,0,0,0,0,0,0,0,0,0,0,0,0,0,0,0,0,0,0,0,0,0,0,0,0,0
0,0,0,0,0,0,0,0,0,0,0,0,0,0,0,0,0,0,0,0,0,0,0,0,0,0,0
0,0,0,0,0,0,0,0,0,0,0,0,0,0,0,0,0,0,0,0,0,0,0,0,0,0,0
0,0,0,0,0,0,0,0,0,0,0,0,0,0,0,0,0,0,0,0,0,0,0,0,0,0,0
:endlayer
layer: 16
0,0,0,0,0,0,0,0,0,0,0,0,0,0,0,0,0,0,0,0,0,0,0,0,0,0,0
0,0,0,0,0,0,0,0,0,0,0,0,0,0,0,0,0,0,0,0,0,0,0,0,0,0,0
0,0,0,0,0,0,0,0,0,0,0,0,0,0,0,0,0,0,0,0,0,0,0,0,0,0,0
0,0,0,0,0,0,0,0,0,0,0,0,0,0,8,28,28,28,28,28,28,0,0,0,0,0,0
0,0,0,0,0,0,0,0,0,0,0,0,0,0,8,6,25,25,25,6,24,0,0,0,0,0,0
0,0,0,0,0,0,0,0,0,0,0,0,0,0,8,26,0,0,0,26,24,0,0,0,0,0,0
0,0,0,0,0,0,0,0,0,0,0,0,0,0,8,26,0,0,0,26,24,0,0,0,0,0,0
0,0,0,0,0,0,0,0,0,0,0,0,0,0,8,26,0,0,0,26,24,0,0,0,0,0,0
0,0,0,0,0,0,0,0,0,0,0,0,0,0,8,6,25,25,25,6,24,0,0,0,0,0,0
0,0,0,0,0,0,0,0,0,0,0,0,0,0,29,29,29,29,29,29,24,0,0,0,0,0,0
0,0,0,0,0,0,0,0,0,0,0,0,0,0,0,0,0,0,0,0,0,0,0,0,0,0,0
0,0,0,0,0,0,0,0,0,0,0,0,0,0,0,0,0,0,0,0,0,0,0,0,0,0,0
0,0,0,0,0,0,0,0,0,0,0,0,0,0,0,0,0,0,0,0,0,0,0,0,0,0,0
0,0,0,0,0,0,0,0,0,0,0,0,0,0,0,0,0,0,0,0,0,0,0,0,0,0,0
0,0,0,0,0,0,0,0,0,0,0,0,0,0,0,0,0,0,0,0,0,0,0,0,0,0,0
0,0,0,0,0,0,0,0,0,0,0,0,0,0,0,0,0,0,0,0,0,0,0,0,0,0,0
0,0,0,0,0,0,0,0,0,0,0,0,0,0,0,0,0,0,0,0,0,0,0,0,0,0,0
0,0,0,0,0,0,0,0,0,0,0,0,0,0,0,0,0,0,0,0,0,0,0,0,0,0,0
0,0,0,0,0,0,0,0,0,0,0,0,0,0,0,0,0,0,0,0,0,0,0,0,0,0,0
0,0,0,0,0,0,0,0,0,0,0,0,0,0,0,0,0,0,0,0,0,0,0,0,0,0,0
0,0,0,0,0,0,0,0,0,0,0,0,0,0,0,0,0,0,0,0,0,0,0,0,0,0,0
:endlayer
layer: 17
0,0,0,0,0,0,0,0,0,0,0,0,0,0,0,0,0,0,0,0,0,0,0,0,0,0,0
0,0,0,0,0,0,0,0,0,0,0,0,0,0,0,0,0,0,0,0,0,0,0,0,0,0,0
0,0,0,0,0,0,0,0,0,0,0,0,0,0,0,0,0,0,0,0,0,0,0,0,0,0,0
0,0,0,0,0,0,0,0,0,0,0,0,0,0,0,0,0,0,0,0,0,0,0,0,0,0,0
0,0,0,0,0,0,0,0,0,0,0,0,0,0,0,28,28,28,28,24,0,0,0,0,0,0,0
0,0,0,0,0,0,0,0,0,0,0,0,0,0,0,8,21,21,23,24,0,0,0,0,0,0,0
0,0,0,0,0,0,0,0,0,0,0,0,0,0,0,8,9,0,23,24,0,0,0,0,0,0,0
0,0,0,0,0,0,0,0,0,0,0,0,0,0,0,8,9,22,22,24,0,0,0,0,0,0,0
0,0,0,0,0,0,0,0,0,0,0,0,0,0,0,8,29,29,29,29,0,0,0,0,0,0,0
0,0,0,0,0,0,0,0,0,0,0,0,0,0,0,0,0,0,0,0,0,0,0,0,0,0,0
0,0,0,0,0,0,0,0,0,0,0,0,0,0,0,0,0,0,0,0,0,0,0,0,0,0,0
0,0,0,0,0,0,0,0,0,0,0,0,0,0,0,0,0,0,0,0,0,0,0,0,0,0,0
0,0,0,0,0,0,0,0,0,0,0,0,0,0,0,0,0,0,0,0,0,0,0,0,0,0,0
0,0,0,0,0,0,0,0,0,0,0,0,0,0,0,0,0,0,0,0,0,0,0,0,0,0,0
0,0,0,0,0,0,0,0,0,0,0,0,0,0,0,0,0,0,0,0,0,0,0,0,0,0,0
0,0,0,0,0,0,0,0,0,0,0,0,0,0,0,0,0,0,0,0,0,0,0,0,0,0,0
0,0,0,0,0,0,0,0,0,0,0,0,0,0,0,0,0,0,0,0,0,0,0,0,0,0,0
0,0,0,0,0,0,0,0,0,0,0,0,0,0,0,0,0,0,0,0,0,0,0,0,0,0,0
0,0,0,0,0,0,0,0,0,0,0,0,0,0,0,0,0,0,0,0,0,0,0,0,0,0,0
0,0,0,0,0,0,0,0,0,0,0,0,0,0,0,0,0,0,0,0,0,0,0,0,0,0,0
0,0,0,0,0,0,0,0,0,0,0,0,0,0,0,0,0,0,0,0,0,0,0,0,0,0,0
:endlayer
layer: 18
0,0,0,0,0,0,0,0,0,0,0,0,0,0,0,0,0,0,0,0,0,0,0,0,0,0,0
0,0,0,0,0,0,0,0,0,0,0,0,0,0,0,0,0,0,0,0,0,0,0,0,0,0,0
0,0,0,0,0,0,0,0,0,0,0,0,0,0,0,0,0,0,0,0,0,0,0,0,0,0,0
0,0,0,0,0,0,0,0,0,0,0,0,0,0,0,0,0,0,0,0,0,0,0,0,0,0,0
0,0,0,0,0,0,0,0,0,0,0,0,0,0,0,0,0,0,0,0,0,0,0,0,0,0,0
0,0,0,0,0,0,0,0,0,0,0,0,0,0,0,0,28,28,24,0,0,0,0,0,0,0,0
0,0,0,0,0,0,0,0,0,0,0,0,0,0,0,0,8,4,24,0,0,0,0,0,0,0,0
0,0,0,0,0,0,0,0,0,0,0,0,0,0,0,0,8,29,29,0,0,0,0,0,0,0,0
0,0,0,0,0,0,0,0,0,0,0,0,0,0,0,0,0,0,0,0,0,0,0,0,0,0,0
0,0,0,0,0,0,0,0,0,0,0,0,0,0,0,0,0,0,0,0,0,0,0,0,0,0,0
0,0,0,0,0,0,0,0,0,0,0,0,0,0,0,0,0,0,0,0,0,0,0,0,0,0,0
0,0,0,0,0,0,0,0,0,0,0,0,0,0,0,0,0,0,0,0,0,0,0,0,0,0,0
0,0,0,0,0,0,0,0,0,0,0,0,0,0,0,0,0,0,0,0,0,0,0,0,0,0,0
0,0,0,0,0,0,0,0,0,0,0,0,0,0,0,0,0,0,0,0,0,0,0,0,0,0,0
0,0,0,0,0,0,0,0,0,0,0,0,0,0,0,0,0,0,0,0,0,0,0,0,0,0,0
0,0,0,0,0,0,0,0,0,0,0,0,0,0,0,0,0,0,0,0,0,0,0,0,0,0,0
0,0,0,0,0,0,0,0,0,0,0,0,0,0,0,0,0,0,0,0,0,0,0,0,0,0,0
0,0,0,0,0,0,0,0,0,0,0,0,0,0,0,0,0,0,0,0,0,0,0,0,0,0,0
0,0,0,0,0,0,0,0,0,0,0,0,0,0,0,0,0,0,0,0,0,0,0,0,0,0,0
0,0,0,0,0,0,0,0,0,0,0,0,0,0,0,0,0,0,0,0,0,0,0,0,0,0,0
0,0,0,0,0,0,0,0,0,0,0,0,0,0,0,0,0,0,0,0,0,0,0,0,0,0,0
:endlayer
layer: 19
0,0,0,0,0,0,0,0,0,0,0,0,0,0,0,0,0,0,0,0,0,0,0,0,0,0,0
0,0,0,0,0,0,0,0,0,0,0,0,0,0,0,0,0,0,0,0,0,0,0,0,0,0,0
0,0,0,0,0,0,0,0,0,0,0,0,0,0,0,0,0,0,0,0,0,0,0,0,0,0,0
0,0,0,0,0,0,0,0,0,0,0,0,0,0,0,0,0,0,0,0,0,0,0,0,0,0,0
0,0,0,0,0,0,0,0,0,0,0,0,0,0,0,0,0,0,0,0,0,0,0,0,0,0,0
0,0,0,0,0,0,0,0,0,0,0,0,0,0,0,0,0,0,0,0,0,0,0,0,0,0,0
0,0,0,0,0,0,0,0,0,0,0,0,0,0,0,0,0,5,0,0,0,0,0,0,0,0,0
0,0,0,0,0,0,0,0,0,0,0,0,0,0,0,0,0,0,0,0,0,0,0,0,0,0,0
0,0,0,0,0,0,0,0,0,0,0,0,0,0,0,0,0,0,0,0,0,0,0,0,0,0,0
0,0,0,0,0,0,0,0,0,0,0,0,0,0,0,0,0,0,0,0,0,0,0,0,0,0,0
0,0,0,0,0,0,0,0,0,0,0,0,0,0,0,0,0,0,0,0,0,0,0,0,0,0,0
0,0,0,0,0,0,0,0,0,0,0,0,0,0,0,0,0,0,0,0,0,0,0,0,0,0,0
0,0,0,0,0,0,0,0,0,0,0,0,0,0,0,0,0,0,0,0,0,0,0,0,0,0,0
0,0,0,0,0,0,0,0,0,0,0,0,0,0,0,0,0,0,0,0,0,0,0,0,0,0,0
0,0,0,0,0,0,0,0,0,0,0,0,0,0,0,0,0,0,0,0,0,0,0,0,0,0,0
0,0,0,0,0,0,0,0,0,0,0,0,0,0,0,0,0,0,0,0,0,0,0,0,0,0,0
0,0,0,0,0,0,0,0,0,0,0,0,0,0,0,0,0,0,0,0,0,0,0,0,0,0,0
0,0,0,0,0,0,0,0,0,0,0,0,0,0,0,0,0,0,0,0,0,0,0,0,0,0,0
0,0,0,0,0,0,0,0,0,0,0,0,0,0,0,0,0,0,0,0,0,0,0,0,0,0,0
0,0,0,0,0,0,0,0,0,0,0,0,0,0,0,0,0,0,0,0,0,0,0,0,0,0,0
0,0,0,0,0,0,0,0,0,0,0,0,0,0,0,0,0,0,0,0,0,0,0,0,0,0,0
:endlayer
layer: 20
0,0,0,0,0,0,0,0,0,0,0,0,0,0,0,0,0,0,0,0,0,0,0,0,0,0,0
0,0,0,0,0,0,0,0,0,0,0,0,0,0,0,0,0,0,0,0,0,0,0,0,0,0,0
0,0,0,0,0,0,0,0,0,0,0,0,0,0,0,0,0,0,0,0,0,0,0,0,0,0,0
0,0,0,0,0,0,0,0,0,0,0,0,0,0,0,0,0,0,0,0,0,0,0,0,0,0,0
0,0,0,0,0,0,0,0,0,0,0,0,0,0,0,0,0,0,0,0,0,0,0,0,0,0,0
0,0,0,0,0,0,0,0,0,0,0,0,0,0,0,0,0,0,0,0,0,0,0,0,0,0,0
0,0,0,0,0,0,0,0,0,0,0,0,0,0,0,0,0,5,0,0,0,0,0,0,0,0,0
0,0,0,0,0,0,0,0,0,0,0,0,0,0,0,0,0,0,0,0,0,0,0,0,0,0,0
0,0,0,0,0,0,0,0,0,0,0,0,0,0,0,0,0,0,0,0,0,0,0,0,0,0,0
0,0,0,0,0,0,0,0,0,0,0,0,0,0,0,0,0,0,0,0,0,0,0,0,0,0,0
0,0,0,0,0,0,0,0,0,0,0,0,0,0,0,0,0,0,0,0,0,0,0,0,0,0,0
0,0,0,0,0,0,0,0,0,0,0,0,0,0,0,0,0,0,0,0,0,0,0,0,0,0,0
0,0,0,0,0,0,0,0,0,0,0,0,0,0,0,0,0,0,0,0,0,0,0,0,0,0,0
0,0,0,0,0,0,0,0,0,0,0,0,0,0,0,0,0,0,0,0,0,0,0,0,0,0,0
0,0,0,0,0,0,0,0,0,0,0,0,0,0,0,0,0,0,0,0,0,0,0,0,0,0,0
0,0,0,0,0,0,0,0,0,0,0,0,0,0,0,0,0,0,0,0,0,0,0,0,0,0,0
0,0,0,0,0,0,0,0,0,0,0,0,0,0,0,0,0,0,0,0,0,0,0,0,0,0,0
0,0,0,0,0,0,0,0,0,0,0,0,0,0,0,0,0,0,0,0,0,0,0,0,0,0,0
0,0,0,0,0,0,0,0,0,0,0,0,0,0,0,0,0,0,0,0,0,0,0,0,0,0,0
0,0,0,0,0,0,0,0,0,0,0,0,0,0,0,0,0,0,0,0,0,0,0,0,0,0,0
0,0,0,0,0,0,0,0,0,0,0,0,0,0,0,0,0,0,0,0,0,0,0,0,0,0,0
:endlayer
layer: 21
0,0,0,0,0,0,0,0,0,0,0,0,0,0,0,0,0,0,0,0,0,0,0,0,0,0,0
0,0,0,0,0,0,0,0,0,0,0,0,0,0,0,0,0,0,0,0,0,0,0,0,0,0,0
0,0,0,0,0,0,0,0,0,0,0,0,0,0,0,0,0,0,0,0,0,0,0,0,0,0,0
0,0,0,0,0,0,0,0,0,0,0,0,0,0,0,0,0,0,0,0,0,0,0,0,0,0,0
0,0,0,0,0,0,0,0,0,0,0,0,0,0,0,0,0,0,0,0,0,0,0,0,0,0,0
0,0,0,0,0,0,0,0,0,0,0,0,0,0,0,0,0,0,0,0,0,0,0,0,0,0,0
0,0,0,0,0,0,0,0,0,0,0,0,0,0,0,0,0,10,0,0,0,0,0,0,0,0,0
0,0,0,0,0,0,0,0,0,0,0,0,0,0,0,0,0,0,0,0,0,0,0,0,0,0,0
0,0,0,0,0,0,0,0,0,0,0,0,0,0,0,0,0,0,0,0,0,0,0,0,0,0,0
0,0,0,0,0,0,0,0,0,0,0,0,0,0,0,0,0,0,0,0,0,0,0,0,0,0,0
0,0,0,0,0,0,0,0,0,0,0,0,0,0,0,0,0,0,0,0,0,0,0,0,0,0,0
0,0,0,0,0,0,0,0,0,0,0,0,0,0,0,0,0,0,0,0,0,0,0,0,0,0,0
0,0,0,0,0,0,0,0,0,0,0,0,0,0,0,0,0,0,0,0,0,0,0,0,0,0,0
0,0,0,0,0,0,0,0,0,0,0,0,0,0,0,0,0,0,0,0,0,0,0,0,0,0,0
0,0,0,0,0,0,0,0,0,0,0,0,0,0,0,0,0,0,0,0,0,0,0,0,0,0,0
0,0,0,0,0,0,0,0,0,0,0,0,0,0,0,0,0,0,0,0,0,0,0,0,0,0,0
0,0,0,0,0,0,0,0,0,0,0,0,0,0,0,0,0,0,0,0,0,0,0,0,0,0,0
0,0,0,0,0,0,0,0,0,0,0,0,0,0,0,0,0,0,0,0,0,0,0,0,0,0,0
0,0,0,0,0,0,0,0,0,0,0,0,0,0,0,0,0,0,0,0,0,0,0,0,0,0,0
0,0,0,0,0,0,0,0,0,0,0,0,0,0,0,0,0,0,0,0,0,0,0,0,0,0,0
0,0,0,0,0,0,0,0,0,0,0,0,0,0,0,0,0,0,0,0,0,0,0,0,0,0,0
:endlayer

#### RULES ####
rule:
plugin=vanillaBlocks
number=1
data:
JSON:{blockState:{blockName:"minecraft:grass",properties:{snowy:"false"}}}
:enddata
:endrule

rule:
plugin=vanillaBlocks
number=2
data:
JSON:{blockState:{blockName:"minecraft:cobblestone"}}
:enddata
:endrule

rule:
plugin=vanillaBlocks
number=3
data:
JSON:{blockState:{blockName:"minecraft:stonebrick",properties:{variant:"stonebrick"}}}
:enddata
:endrule

rule:
plugin=vanillaBlocks
number=4
data:
JSON:{blockState:{blockName:"biomesoplenty:planks_0",properties:{variant:"mahogany"}}}
:enddata
:endrule

rule:
plugin=vanillaBlocks
number=5
data:
JSON:{blockState:{blockName:"biomesoplenty:mahogany_fence",properties:{east:"false",south:"false",north:"false",west:"false"}}}
:enddata
:endrule

rule:
plugin=vanillaBlocks
number=6
data:
JSON:{blockState:{blockName:"biomesoplenty:log_3",properties:{variant:"mahogany",axis:"y"}}}
:enddata
:endrule

rule:
plugin=vanillaBlocks
number=7
data:
JSON:{blockState:{blockName:"minecraft:stone_slab",properties:{half:"bottom",variant:"cobblestone"}}}
:enddata
:endrule

rule:
plugin=vanillaBlocks
number=8
data:
JSON:{blockState:{blockName:"biomesoplenty:mahogany_stairs",properties:{half:"bottom",shape:"straight",facing:"east"}}}
:enddata
:endrule

rule:
plugin=vanillaBlocks
number=9
data:
JSON:{blockState:{blockName:"biomesoplenty:mahogany_stairs",properties:{half:"top",shape:"straight",facing:"west"}}}
:enddata
:endrule

rule:
plugin=vanillaBlocks
number=10
data:
JSON:{blockState:{blockName:"minecraft:torch",properties:{facing:"up"}}}
:enddata
:endrule

rule:
plugin=vanillaBlocks
number=11
data:
JSON:{blockState:{blockName:"minecraft:torch",properties:{facing:"north"}}}
:enddata
:endrule

rule:
plugin=vanillaBlocks
number=12
data:
JSON:{blockState:{blockName:"minecraft:torch",properties:{facing:"west"}}}
:enddata
:endrule

rule:
plugin=vanillaBlocks
number=13
data:
JSON:{blockState:{blockName:"minecraft:torch",properties:{facing:"east"}}}
:enddata
:endrule

rule:
plugin=vanillaBlocks
number=14
data:
JSON:{blockState:{blockName:"minecraft:stone_stairs",properties:{half:"bottom",shape:"straight",facing:"east"}}}
:enddata
:endrule

rule:
plugin=vanillaBlocks
number=15
data:
JSON:{blockState:{blockName:"minecraft:stone_stairs",properties:{half:"top",shape:"straight",facing:"north"}}}
:enddata
:endrule

rule:
plugin=vanillaBlocks
number=16
data:
JSON:{blockState:{blockName:"minecraft:stone_slab",properties:{half:"top",variant:"cobblestone"}}}
:enddata
:endrule

rule:
plugin=vanillaBlocks
number=17
data:
JSON:{blockState:{blockName:"minecraft:torch",properties:{facing:"south"}}}
:enddata
:endrule

rule:
plugin=vanillaBlocks
number=18
data:
JSON:{blockState:{blockName:"minecraft:stone_stairs",properties:{half:"top",shape:"straight",facing:"west"}}}
:enddata
:endrule

rule:
plugin=vanillaBlocks
number=19
data:
JSON:{blockState:{blockName:"minecraft:stone_stairs",properties:{half:"top",shape:"straight",facing:"east"}}}
:enddata
:endrule

rule:
plugin=vanillaBlocks
number=20
data:
JSON:{blockState:{blockName:"minecraft:stone_stairs",properties:{half:"top",shape:"straight",facing:"south"}}}
:enddata
:endrule

rule:
plugin=vanillaBlocks
number=21
data:
JSON:{blockState:{blockName:"biomesoplenty:mahogany_stairs",properties:{half:"top",shape:"straight",facing:"north"}}}
:enddata
:endrule

rule:
plugin=vanillaBlocks
number=22
data:
JSON:{blockState:{blockName:"biomesoplenty:mahogany_stairs",properties:{half:"top",shape:"straight",facing:"south"}}}
:enddata
:endrule

rule:
plugin=vanillaBlocks
number=23
data:
JSON:{blockState:{blockName:"biomesoplenty:mahogany_stairs",properties:{half:"top",shape:"straight",facing:"east"}}}
:enddata
:endrule

rule:
plugin=vanillaBlocks
number=24
data:
JSON:{blockState:{blockName:"biomesoplenty:mahogany_stairs",properties:{half:"bottom",shape:"straight",facing:"west"}}}
:enddata
:endrule

rule:
plugin=vanillaBlocks
number=25
data:
JSON:{blockState:{blockName:"biomesoplenty:log_3",properties:{variant:"mahogany",axis:"x"}}}
:enddata
:endrule

rule:
plugin=vanillaBlocks
number=26
data:
JSON:{blockState:{blockName:"biomesoplenty:log_3",properties:{variant:"mahogany",axis:"z"}}}
:enddata
:endrule

rule:
plugin=vanillaBlocks
number=27
data:
JSON:{blockState:{blockName:"biomesoplenty:wood_slab_1",properties:{half:"top",variant:"mahogany"}}}
:enddata
:endrule

rule:
plugin=vanillaBlocks
number=28
data:
JSON:{blockState:{blockName:"biomesoplenty:mahogany_stairs",properties:{half:"bottom",shape:"straight",facing:"south"}}}
:enddata
:endrule

rule:
plugin=vanillaBlocks
number=29
data:
JSON:{blockState:{blockName:"biomesoplenty:mahogany_stairs",properties:{half:"bottom",shape:"straight",facing:"north"}}}
:enddata
:endrule

rule:
plugin=vanillaBlocks
number=30
data:
JSON:{blockState:{blockName:"minecraft:ladder",properties:{facing:"west"}}}
:enddata
:endrule

rule:
plugin=vanillaBlocks
number=31
data:
JSON:{blockState:{blockName:"biomesoplenty:wood_slab_1",properties:{half:"bottom",variant:"mahogany"}}}
:enddata
:endrule

rule:
plugin=vanillaBlocks
number=32
data:
JSON:{blockState:{blockName:"minecraft:stone_stairs",properties:{half:"bottom",shape:"straight",facing:"north"}}}
:enddata
:endrule

rule:
plugin=vanillaBlocks
number=33
data:
JSON:{blockState:{blockName:"minecraft:stone_stairs",properties:{half:"bottom",shape:"straight",facing:"south"}}}
:enddata
:endrule

rule:
plugin=vanillaBlocks
number=34
data:
JSON:{blockState:{blockName:"minecraft:cobblestone_wall",properties:{east:"false",south:"false",north:"false",variant:"cobblestone",west:"false",up:"false"}}}
:enddata
:endrule

#### ENTITIES ####
