# Ancient Warfare Structure Template File
# Auto-generated structure template file. created on: 6/4/2023 at: 23:29:42
# Lines beginning with # denote comments

header:
version=2.11
name=SB_MarenCol_House_1H1R_1_ebony
mods=biomesoplenty
size=16,11,11
offset=10,1,10
:endheader

#### VALIDATION ####
validation:
type=ground
structureAuthor=TheOddlySeagull
survival=true
worldGenEnabled=false
unique=false
preserveBlocks=false
preventNaturalHostileSpawns=false
selectionWeight=1
clusterValue=1
minDuplicateDistance=1
dimensionWhiteList=true
dimensionList=
biomeGroupList=
biomeWhiteList=true
biomeList=
leveling=0
fill=0
border=0
blockSwap=false
territoryName=
biomeReplacement=minecraft:
minGenerationHeight=0
maxGenerationHeight=255
:endvalidation

#### LAYERS ####
layer: 0
1,1,1,1,1,1,1,1,1,1,1,1,1,1,1,1
1,1,1,1,1,1,1,1,1,1,2,2,1,1,1,1
1,1,3,4,4,4,4,4,3,2,2,2,2,3,1,1
1,1,5,6,6,6,5,2,2,2,2,2,2,5,1,1
1,1,5,6,6,6,5,2,2,2,2,2,2,5,1,1
1,1,5,6,6,6,5,2,2,2,2,2,2,5,1,1
1,1,5,6,6,6,5,2,2,2,2,2,2,5,1,1
1,1,5,6,6,6,5,2,2,2,2,2,2,5,1,1
1,1,3,4,4,4,4,4,4,4,4,4,4,3,1,1
1,1,1,1,1,1,1,1,1,2,2,2,1,1,1,1
1,1,1,1,1,1,1,1,1,2,2,2,1,1,1,1
:endlayer
layer: 1
0,0,0,0,0,0,0,0,0,0,0,0,0,0,0,0
0,0,0,0,0,0,0,0,0,0,2,2,0,0,0,0
0,0,3,6,3,6,3,6,3,2,7,7,2,3,0,0
0,0,6,0,0,0,6,0,0,0,8,8,0,6,0,0
0,0,3,0,0,0,3,0,0,0,0,0,0,3,0,0
0,0,6,0,0,0,0,0,0,0,0,0,0,6,0,0
0,0,3,0,0,0,3,0,0,0,0,0,0,3,0,0
0,0,6,0,0,0,6,0,0,0,0,0,0,6,0,0
0,0,3,6,6,6,3,6,6,3,9,3,6,3,0,0
0,0,0,0,0,0,0,0,0,0,0,0,0,0,0,0
0,0,0,0,0,0,0,0,0,0,0,0,0,0,0,0
:endlayer
layer: 2
0,0,0,0,0,0,0,0,0,0,0,0,0,0,0,0
0,0,0,0,0,0,0,0,0,0,2,2,0,0,0,0
0,0,3,6,3,10,3,10,3,2,0,0,2,3,0,0
0,0,6,0,0,0,6,0,0,0,0,0,0,6,0,0
0,0,3,0,0,0,3,0,0,0,0,0,0,3,0,0
0,0,10,0,0,0,0,0,0,0,0,0,0,10,0,0
0,0,3,0,0,0,3,0,0,0,0,0,0,3,0,0
0,0,6,0,0,0,6,0,0,0,0,0,0,6,0,0
0,0,3,6,10,6,3,10,10,3,11,3,6,3,0,0
0,0,0,0,0,0,0,0,0,0,0,0,0,0,0,0
0,0,0,0,0,0,0,0,0,0,0,0,0,0,0,0
:endlayer
layer: 3
0,0,0,0,0,0,0,0,0,0,0,0,0,0,0,0
0,0,12,0,0,0,0,0,12,0,2,13,0,12,0,0
0,14,3,6,3,10,3,10,3,2,15,16,2,3,17,0
0,0,6,0,0,0,6,0,18,0,0,0,0,6,0,0
0,0,3,0,0,0,3,0,0,0,0,0,0,3,0,0
0,0,10,0,0,0,6,0,0,0,0,0,0,10,0,0
0,0,3,0,0,0,3,0,0,0,0,0,0,3,0,0
0,0,6,0,0,0,6,0,0,12,0,0,0,6,0,0
0,14,3,6,10,6,3,10,10,3,6,3,6,3,17,0
0,0,18,0,0,0,18,0,0,0,0,0,0,18,0,0
0,0,0,0,0,0,0,0,0,0,0,0,0,0,0,0
:endlayer
layer: 4
0,0,0,0,0,0,0,0,0,0,0,0,0,0,0,0
0,19,19,19,19,19,19,19,19,19,2,19,19,19,19,0
0,20,3,4,4,4,4,4,4,4,4,4,4,3,20,0
0,0,5,0,0,0,5,0,0,0,0,0,0,5,0,0
0,0,5,0,0,0,5,0,0,0,0,0,0,5,0,0
0,0,5,17,0,14,5,17,0,0,0,0,14,5,0,0
0,0,5,0,0,0,5,0,0,0,0,0,0,5,0,0
0,0,5,0,0,0,5,0,0,0,0,0,0,5,0,0
0,21,3,4,4,4,4,4,4,4,4,4,4,3,21,0
0,22,22,22,22,22,22,22,22,22,22,22,22,22,22,0
0,0,0,0,0,0,0,0,0,0,0,0,0,0,0,0
:endlayer
layer: 5
0,0,0,0,0,0,0,0,0,0,0,0,0,0,0,0
0,0,0,0,0,0,0,0,0,0,2,0,0,0,0,0
0,19,19,19,19,19,19,19,19,19,19,19,19,19,19,0
0,20,3,20,20,20,3,20,20,20,20,20,20,3,20,0
0,0,6,0,0,0,6,0,0,0,0,0,0,6,0,0
0,0,6,0,0,0,6,0,0,0,0,0,0,6,0,0
0,0,6,0,0,0,6,0,0,0,0,0,0,6,0,0
0,21,3,21,21,21,3,21,21,21,21,21,21,3,21,0
0,22,22,22,22,22,22,22,22,22,22,22,22,22,22,0
0,0,0,0,0,0,0,0,0,0,0,0,0,0,0,0
0,0,0,0,0,0,0,0,0,0,0,0,0,0,0,0
:endlayer
layer: 6
0,0,0,0,0,0,0,0,0,0,0,0,0,0,0,0
0,0,0,0,0,0,0,0,0,0,2,0,0,0,0,0
0,0,0,0,0,0,0,0,0,0,0,0,0,0,0,0
0,19,19,19,19,19,19,19,19,19,19,19,19,19,19,0
0,20,3,20,20,20,3,20,20,20,20,20,20,3,20,0
0,0,6,0,0,0,6,0,0,0,0,0,0,6,0,0
0,21,3,21,21,21,3,21,21,0,0,21,21,3,21,0
0,22,22,22,22,22,22,22,23,10,10,24,22,22,22,0
0,0,0,0,0,0,0,0,0,0,0,0,0,0,0,0
0,0,0,0,0,0,0,0,0,0,0,0,0,0,0,0
0,0,0,0,0,0,0,0,0,0,0,0,0,0,0,0
:endlayer
layer: 7
0,0,0,0,0,0,0,0,0,0,0,0,0,0,0,0
0,0,0,0,0,0,0,0,0,0,2,0,0,0,0,0
0,0,0,0,0,0,0,0,0,0,0,0,0,0,0,0
0,0,0,0,0,0,0,0,0,0,0,0,0,0,0,0
0,19,19,19,19,19,19,19,19,19,19,19,19,19,19,0
0,25,3,4,4,4,4,4,4,4,4,4,4,3,26,0
0,22,22,22,22,22,22,22,22,22,24,22,22,22,22,0
0,0,0,0,0,0,0,0,0,23,24,0,0,0,0,0
0,0,0,0,0,0,0,0,0,0,0,0,0,0,0,0
0,0,0,0,0,0,0,0,0,0,0,0,0,0,0,0
0,0,0,0,0,0,0,0,0,0,0,0,0,0,0,0
:endlayer
layer: 8
0,0,0,0,0,0,0,0,0,0,0,0,0,0,0,0
0,0,0,0,0,0,0,0,0,0,2,0,0,0,0,0
0,0,0,0,0,0,0,0,0,0,0,0,0,0,0,0
0,0,0,0,0,0,0,0,0,0,0,0,0,0,0,0
0,0,0,0,0,0,0,0,0,0,0,0,0,0,0,0
0,27,27,27,27,27,27,27,27,27,27,27,27,27,27,0
0,0,0,0,0,0,0,0,0,0,0,0,0,0,0,0
0,0,0,0,0,0,0,0,0,0,0,0,0,0,0,0
0,0,0,0,0,0,0,0,0,0,0,0,0,0,0,0
0,0,0,0,0,0,0,0,0,0,0,0,0,0,0,0
0,0,0,0,0,0,0,0,0,0,0,0,0,0,0,0
:endlayer
layer: 9
0,0,0,0,0,0,0,0,0,0,0,0,0,0,0,0
0,0,0,0,0,0,0,0,0,0,28,0,0,0,0,0
0,0,0,0,0,0,0,0,0,0,0,0,0,0,0,0
0,0,0,0,0,0,0,0,0,0,0,0,0,0,0,0
0,0,0,0,0,0,0,0,0,0,0,0,0,0,0,0
0,0,0,0,0,0,0,0,0,0,0,0,0,0,0,0
0,0,0,0,0,0,0,0,0,0,0,0,0,0,0,0
0,0,0,0,0,0,0,0,0,0,0,0,0,0,0,0
0,0,0,0,0,0,0,0,0,0,0,0,0,0,0,0
0,0,0,0,0,0,0,0,0,0,0,0,0,0,0,0
0,0,0,0,0,0,0,0,0,0,0,0,0,0,0,0
:endlayer
layer: 10
0,0,0,0,0,0,0,0,0,0,0,0,0,0,0,0
0,0,0,0,0,0,0,0,0,0,8,0,0,0,0,0
0,0,0,0,0,0,0,0,0,0,0,0,0,0,0,0
0,0,0,0,0,0,0,0,0,0,0,0,0,0,0,0
0,0,0,0,0,0,0,0,0,0,0,0,0,0,0,0
0,0,0,0,0,0,0,0,0,0,0,0,0,0,0,0
0,0,0,0,0,0,0,0,0,0,0,0,0,0,0,0
0,0,0,0,0,0,0,0,0,0,0,0,0,0,0,0
0,0,0,0,0,0,0,0,0,0,0,0,0,0,0,0
0,0,0,0,0,0,0,0,0,0,0,0,0,0,0,0
0,0,0,0,0,0,0,0,0,0,0,0,0,0,0,0
:endlayer

#### RULES ####
rule:
plugin=vanillaBlocks
number=1
data:
JSON:{blockState:{blockName:"minecraft:grass",properties:{snowy:"false"}}}
:enddata
:endrule

rule:
plugin=vanillaBlocks
number=2
data:
JSON:{blockState:{blockName:"minecraft:cobblestone"}}
:enddata
:endrule

rule:
plugin=vanillaBlocks
number=3
data:
JSON:{blockState:{blockName:"biomesoplenty:log_3",properties:{variant:"ebony",axis:"y"}}}
:enddata
:endrule

rule:
plugin=vanillaBlocks
number=4
data:
JSON:{blockState:{blockName:"biomesoplenty:log_3",properties:{variant:"ebony",axis:"x"}}}
:enddata
:endrule

rule:
plugin=vanillaBlocks
number=5
data:
JSON:{blockState:{blockName:"biomesoplenty:log_3",properties:{variant:"ebony",axis:"z"}}}
:enddata
:endrule

rule:
plugin=vanillaBlocks
number=6
data:
JSON:{blockState:{blockName:"biomesoplenty:planks_0",properties:{variant:"ebony"}}}
:enddata
:endrule

rule:
plugin=vanillaBlocks
number=7
data:
JSON:{blockState:{blockName:"ancientwarfarestructure:fire_pit",properties:{lit:"false",variant:"log"}}}
:enddata
:endrule

rule:
plugin=vanillaBlocks
number=8
data:
JSON:{blockState:{blockName:"minecraft:stone_slab",properties:{half:"bottom",variant:"cobblestone"}}}
:enddata
:endrule

rule:
plugin=doors
number=9
data:
JSON:{blockState:{blockName:"minecraft:wooden_door",properties:{hinge:"right",half:"lower",powered:"false",facing:"north",open:"false"}}}
:enddata
:endrule

rule:
plugin=vanillaBlocks
number=10
data:
JSON:{blockState:{blockName:"biomesoplenty:ebony_fence",properties:{east:"false",south:"false",north:"false",west:"false"}}}
:enddata
:endrule

rule:
plugin=doors
number=11
data:
JSON:{blockState:{blockName:"minecraft:wooden_door",properties:{hinge:"right",half:"upper",powered:"false",facing:"north",open:"false"}}}
:enddata
:endrule

rule:
plugin=vanillaBlocks
number=12
data:
JSON:{blockState:{blockName:"minecraft:torch",properties:{facing:"north"}}}
:enddata
:endrule

rule:
plugin=vanillaBlocks
number=13
data:
JSON:{blockState:{blockName:"minecraft:stone_stairs",properties:{half:"bottom",shape:"straight",facing:"west"}}}
:enddata
:endrule

rule:
plugin=vanillaBlocks
number=14
data:
JSON:{blockState:{blockName:"minecraft:torch",properties:{facing:"west"}}}
:enddata
:endrule

rule:
plugin=vanillaBlocks
number=15
data:
JSON:{blockState:{blockName:"minecraft:stone_stairs",properties:{half:"top",shape:"straight",facing:"west"}}}
:enddata
:endrule

rule:
plugin=vanillaBlocks
number=16
data:
JSON:{blockState:{blockName:"minecraft:stone_stairs",properties:{half:"top",shape:"straight",facing:"east"}}}
:enddata
:endrule

rule:
plugin=vanillaBlocks
number=17
data:
JSON:{blockState:{blockName:"minecraft:torch",properties:{facing:"east"}}}
:enddata
:endrule

rule:
plugin=vanillaBlocks
number=18
data:
JSON:{blockState:{blockName:"minecraft:torch",properties:{facing:"south"}}}
:enddata
:endrule

rule:
plugin=vanillaBlocks
number=19
data:
JSON:{blockState:{blockName:"biomesoplenty:ebony_stairs",properties:{half:"bottom",shape:"straight",facing:"south"}}}
:enddata
:endrule

rule:
plugin=vanillaBlocks
number=20
data:
JSON:{blockState:{blockName:"biomesoplenty:ebony_stairs",properties:{half:"top",shape:"straight",facing:"north"}}}
:enddata
:endrule

rule:
plugin=vanillaBlocks
number=21
data:
JSON:{blockState:{blockName:"biomesoplenty:ebony_stairs",properties:{half:"top",shape:"straight",facing:"south"}}}
:enddata
:endrule

rule:
plugin=vanillaBlocks
number=22
data:
JSON:{blockState:{blockName:"biomesoplenty:ebony_stairs",properties:{half:"bottom",shape:"straight",facing:"north"}}}
:enddata
:endrule

rule:
plugin=vanillaBlocks
number=23
data:
JSON:{blockState:{blockName:"biomesoplenty:ebony_stairs",properties:{half:"bottom",shape:"straight",facing:"east"}}}
:enddata
:endrule

rule:
plugin=vanillaBlocks
number=24
data:
JSON:{blockState:{blockName:"biomesoplenty:ebony_stairs",properties:{half:"bottom",shape:"straight",facing:"west"}}}
:enddata
:endrule

rule:
plugin=vanillaBlocks
number=25
data:
JSON:{blockState:{blockName:"biomesoplenty:ebony_stairs",properties:{half:"top",shape:"straight",facing:"east"}}}
:enddata
:endrule

rule:
plugin=vanillaBlocks
number=26
data:
JSON:{blockState:{blockName:"biomesoplenty:ebony_stairs",properties:{half:"top",shape:"straight",facing:"west"}}}
:enddata
:endrule

rule:
plugin=vanillaBlocks
number=27
data:
JSON:{blockState:{blockName:"biomesoplenty:wood_slab_1",properties:{half:"bottom",variant:"ebony"}}}
:enddata
:endrule

rule:
plugin=vanillaBlocks
number=28
data:
JSON:{blockState:{blockName:"minecraft:cobblestone_wall",properties:{east:"false",south:"false",north:"false",variant:"cobblestone",west:"false",up:"false"}}}
:enddata
:endrule

#### ENTITIES ####
