# Ancient Warfare Structure Template File
# Auto-generated structure template file. created on: 6/28/2023 at: 22:19:48
# Lines beginning with # denote comments

header:
version=2.11
name=SB_MarenCol_House_1H2R_3_sacred_oak
mods=biomesoplenty
size=19,13,20
offset=12,1,19
:endheader

#### VALIDATION ####
validation:
type=ground
structureAuthor=TheOddlySeagull
survival=true
worldGenEnabled=false
unique=false
preserveBlocks=false
preventNaturalHostileSpawns=false
selectionWeight=1
clusterValue=1
minDuplicateDistance=1
dimensionWhiteList=true
dimensionList=
biomeGroupList=
biomeWhiteList=true
biomeList=
leveling=0
fill=0
border=0
blockSwap=false
territoryName=
biomeReplacement=minecraft:
minGenerationHeight=0
maxGenerationHeight=255
:endvalidation

#### LAYERS ####
layer: 0
1,1,1,1,1,1,1,1,1,1,1,1,1,1,1,1,1,1,1
1,1,1,1,1,1,1,1,1,1,1,1,1,1,1,1,1,1,1
1,1,1,1,3,3,3,3,3,3,3,1,1,1,1,1,1,1,1
1,1,1,1,3,4,4,4,4,4,3,1,1,1,1,1,1,1,1
1,1,1,1,3,4,4,4,4,4,3,1,1,1,1,1,1,1,1
1,1,1,1,3,4,4,4,4,4,3,3,3,3,3,1,1,1,1
1,1,1,1,3,4,4,4,4,4,3,3,3,3,3,1,1,1,1
1,1,1,1,3,4,4,4,4,4,3,3,3,3,3,1,1,1,1
1,1,1,1,3,4,4,4,4,4,3,3,3,3,3,1,1,1,1
1,1,3,3,3,3,3,3,3,3,3,3,3,3,3,3,3,1,1
1,1,3,3,3,3,3,3,3,3,3,3,3,3,3,3,3,1,1
1,1,3,3,3,3,3,3,3,3,3,3,3,3,3,3,3,1,1
1,1,3,3,3,3,3,3,3,3,3,3,3,3,3,3,3,1,1
1,1,3,3,3,3,3,3,3,3,3,3,3,3,3,3,3,1,1
1,1,3,3,3,3,3,3,3,3,3,3,3,3,3,3,3,1,1
1,1,3,3,3,3,3,3,3,3,3,3,3,3,3,3,3,1,1
1,1,3,3,3,3,3,3,3,3,3,3,3,3,3,3,3,1,1
1,1,1,1,1,1,3,3,1,1,1,2,3,3,2,1,1,1,1
1,1,1,1,1,1,1,1,1,1,1,2,3,3,2,1,1,1,1
1,1,1,1,1,1,1,1,1,1,1,2,3,3,2,1,1,1,1
:endlayer
layer: 1
0,0,0,0,0,0,0,0,0,0,0,0,0,0,0,0,0,0,0
0,0,0,0,0,0,0,0,0,0,0,0,0,0,0,0,0,5,0
0,5,0,0,6,4,6,0,6,4,6,0,0,0,0,0,0,0,0
0,0,0,0,4,0,0,0,0,0,4,0,0,0,0,0,0,0,0
0,0,0,0,6,0,0,0,0,0,4,0,0,0,0,0,0,0,0
0,0,0,0,4,0,0,0,0,0,6,4,6,4,6,0,0,0,0
0,0,0,0,4,0,0,0,0,0,4,10,9,0,4,0,0,0,0
0,0,0,0,6,0,0,0,0,0,6,8,5,0,6,0,0,0,0
0,0,0,0,4,0,0,0,0,0,4,0,0,0,4,0,0,0,0
0,0,6,4,6,4,6,0,6,4,6,0,6,4,6,4,6,0,0
0,0,4,0,0,0,0,0,0,0,0,0,0,0,0,0,4,0,0
0,0,6,0,0,0,0,0,0,0,0,0,0,0,0,0,6,0,0
0,0,4,0,0,0,0,0,0,0,0,0,0,0,0,0,4,0,0
0,0,4,0,0,0,0,0,0,0,0,0,0,0,0,0,4,0,0
0,0,6,0,0,0,0,0,0,0,0,0,0,0,0,0,6,0,0
0,0,4,0,0,7,7,7,7,0,0,0,0,0,0,0,4,0,0
0,0,6,4,6,3,0,0,3,6,4,6,0,0,6,4,6,0,0
0,0,0,0,0,0,3,3,0,0,0,0,0,0,0,0,0,0,0
0,0,0,0,0,0,0,0,5,0,0,0,0,0,0,0,0,5,0
0,0,0,0,0,0,0,0,0,0,0,0,0,0,0,0,0,0,0
:endlayer
layer: 2
0,0,0,0,0,0,0,0,0,0,0,0,0,0,0,0,0,0,0
0,0,0,0,0,0,0,0,0,0,0,0,0,0,0,0,0,11,0
0,11,0,0,6,4,6,0,6,4,6,0,0,0,0,0,0,0,0
0,0,0,0,4,0,0,0,0,0,5,0,0,0,0,0,0,0,0
0,0,0,0,6,0,0,0,0,0,5,0,0,0,0,0,0,0,0
0,0,0,0,5,0,0,0,0,0,6,5,6,5,6,0,0,0,0
0,0,0,0,5,0,0,0,0,0,4,0,8,10,5,0,0,0,0
0,0,0,0,6,0,0,0,0,0,6,0,5,12,6,0,0,0,0
0,0,0,0,4,0,0,0,0,0,4,0,0,0,5,0,0,0,0
0,0,6,4,6,4,6,0,6,4,6,0,6,4,6,4,6,0,0
0,0,4,0,0,0,0,0,0,0,0,0,0,0,0,0,4,0,0
0,0,6,0,0,0,0,0,0,0,0,0,0,0,0,0,6,0,0
0,0,5,0,0,0,0,0,0,0,0,0,0,0,0,0,5,0,0
0,0,5,0,0,0,0,0,0,0,0,0,0,0,0,0,5,0,0
0,0,6,0,0,0,0,0,0,0,0,0,0,0,0,0,6,0,0
0,0,4,0,0,0,0,0,0,0,0,0,0,0,0,0,4,0,0
0,0,6,5,6,3,0,0,3,6,5,6,0,0,6,5,6,0,0
0,0,0,0,0,0,3,3,0,0,0,0,0,0,0,0,0,0,0
0,0,0,0,0,0,0,0,11,0,0,0,0,0,0,0,0,11,0
0,0,0,0,0,0,0,0,0,0,0,0,0,0,0,0,0,0,0
:endlayer
layer: 3
0,0,0,0,0,0,0,0,0,0,0,0,0,0,0,0,0,0,0
0,0,0,0,16,0,0,0,0,0,16,0,0,0,0,0,0,0,0
0,0,0,12,6,4,6,4,6,4,6,18,0,0,0,0,0,0,0
0,0,0,0,4,0,9,0,9,0,5,0,0,0,0,0,0,0,0
0,0,0,0,6,18,0,0,0,0,5,0,0,0,16,0,0,0,0
0,0,0,0,5,0,0,0,0,12,6,5,6,5,6,18,0,0,0
0,0,0,0,5,0,0,0,0,0,4,0,0,0,5,0,0,0,0
0,0,0,0,6,18,0,0,0,12,6,0,5,8,6,0,0,0,0
0,0,16,0,4,0,16,0,16,0,4,0,16,10,5,0,16,0,0
0,12,6,4,6,4,6,4,6,4,6,4,6,4,6,4,6,18,0
0,0,4,0,9,0,9,0,9,19,9,0,9,0,9,0,4,0,0
0,0,6,18,0,0,0,0,0,0,0,0,0,0,0,12,6,0,0
0,0,5,0,0,0,0,0,0,0,0,0,0,0,0,0,5,0,0
0,0,5,0,0,0,0,0,0,0,0,0,0,0,0,0,5,0,0
0,0,6,18,0,0,0,0,0,0,0,0,0,0,0,12,6,0,0
0,0,4,0,16,0,0,0,0,17,0,16,0,0,16,0,4,0,0
0,12,6,5,6,3,15,14,3,6,5,6,4,4,6,5,6,0,0
0,0,9,0,0,0,3,13,0,5,0,5,0,0,5,0,5,0,0
0,0,0,0,0,0,0,0,0,0,0,0,0,0,0,0,0,0,0
0,0,0,0,0,0,0,0,0,0,0,0,0,0,0,0,0,0,0
:endlayer
layer: 4
0,0,0,0,0,0,0,0,0,0,0,0,0,0,0,0,0,0,0
0,0,0,24,27,0,0,0,0,0,26,25,0,0,0,0,0,0,0
0,0,0,24,6,22,22,22,22,22,6,25,0,0,0,0,0,0,0
0,0,0,24,20,0,0,0,0,0,20,25,0,0,0,0,0,0,0
0,0,0,24,20,0,0,0,0,0,20,25,0,0,0,0,0,0,0
0,0,0,24,20,0,0,0,0,0,20,22,22,22,6,0,0,0,0
0,0,0,24,20,0,0,0,0,0,20,0,0,0,20,0,0,0,0
0,0,0,24,20,0,0,0,0,0,20,18,5,0,20,0,0,0,0
0,23,23,23,20,0,0,0,0,0,20,10,8,0,20,0,0,0,0
0,19,6,22,22,22,22,22,22,22,22,22,22,22,22,22,6,0,0
0,0,20,0,0,0,0,0,0,20,10,4,10,4,10,4,20,0,0
0,0,20,0,0,0,0,0,0,20,10,4,10,4,10,4,20,0,0
0,0,20,0,0,0,0,0,0,20,10,4,10,4,10,4,20,0,0
0,0,20,0,0,0,0,0,0,20,10,4,10,4,10,4,20,0,0
0,0,20,0,0,0,0,0,0,20,10,4,10,4,10,4,20,0,0
0,0,20,0,0,0,0,0,0,20,10,4,10,4,10,4,20,0,0
0,17,6,22,6,3,3,3,3,20,22,22,22,22,22,22,20,0,0
0,21,21,21,21,21,3,21,21,20,10,20,10,10,20,10,20,0,0
0,0,0,0,0,0,0,0,0,0,0,0,0,0,0,0,0,0,0
0,0,0,0,0,0,0,0,0,0,0,0,0,0,0,0,0,0,0
:endlayer
layer: 5
0,0,0,0,0,0,0,0,0,0,0,0,0,0,0,0,0,0,0
0,0,0,0,24,27,0,0,0,26,25,0,0,0,0,0,0,0,0
0,0,0,0,24,6,4,4,4,6,25,0,0,0,0,0,0,0,0
0,0,0,0,24,27,0,0,0,26,25,0,0,0,0,0,0,0,0
0,0,0,0,24,27,0,0,0,26,25,0,0,0,0,0,0,0,0
0,0,0,0,24,27,0,0,0,26,6,4,6,4,6,0,0,0,0
0,0,0,0,24,27,0,0,0,26,4,0,9,0,4,0,0,0,0
0,0,0,0,24,27,0,0,0,26,6,5,5,0,6,0,0,0,0
0,0,0,0,24,27,0,0,0,26,4,0,0,0,4,0,0,0,0
0,23,23,23,24,6,4,4,4,6,6,0,6,5,6,4,6,0,0
0,19,6,19,19,19,19,19,19,4,0,0,0,0,0,0,4,0,0
0,0,4,0,0,0,0,0,0,6,0,0,0,0,0,0,6,0,0
0,0,4,0,0,0,0,0,0,4,0,0,0,0,0,0,4,0,0
0,0,4,0,0,0,0,0,0,6,0,0,0,0,0,0,6,0,0
0,0,4,0,0,0,0,0,0,4,0,0,0,0,0,0,4,0,0
0,17,6,17,17,17,17,17,17,6,0,0,0,0,0,0,6,0,0
0,21,21,21,21,21,21,21,21,4,0,0,0,0,0,0,4,0,0
0,0,0,0,0,0,3,0,0,6,4,6,4,4,6,4,6,0,0
0,0,0,0,0,0,0,0,0,0,0,0,0,0,0,0,0,0,0
0,0,0,0,0,0,0,0,0,0,0,0,0,0,0,0,0,0,0
:endlayer
layer: 6
0,0,0,0,0,0,0,0,0,0,0,0,0,0,0,0,0,0,0
0,0,0,0,0,24,27,0,26,25,0,0,0,0,0,0,0,0,0
0,0,0,0,0,24,6,4,6,25,0,0,0,0,0,0,0,0,0
0,0,0,0,0,24,27,0,26,25,0,0,0,0,0,0,0,0,0
0,0,0,0,0,24,27,0,26,25,0,0,0,0,0,0,0,0,0
0,0,0,0,0,24,27,0,26,25,6,5,6,5,6,0,0,0,0
0,0,0,0,0,24,27,0,26,25,5,0,0,0,5,0,0,0,0
0,0,0,0,0,24,27,0,26,25,6,0,5,12,6,0,0,0,0
0,0,0,0,0,24,27,0,26,25,5,0,0,0,5,0,0,0,0
0,0,0,0,0,24,6,4,6,6,6,0,6,5,6,4,6,0,0
0,23,23,23,23,23,4,4,4,4,0,0,0,0,0,0,5,0,0
0,19,6,19,19,19,19,19,19,6,0,0,0,0,0,0,6,0,0
0,0,4,0,0,0,0,0,0,4,0,0,0,0,0,0,5,0,0
0,0,4,0,0,0,0,0,0,6,0,0,0,0,0,0,6,0,0
0,17,6,17,17,17,17,17,17,4,0,0,0,0,0,0,5,0,0
0,21,21,21,21,21,21,21,21,6,0,0,0,0,0,0,6,0,0
0,0,0,0,0,0,0,0,0,4,0,0,0,0,0,0,5,0,0
0,0,0,0,0,0,3,0,0,6,5,6,5,5,6,5,6,0,0
0,0,0,0,0,0,0,0,0,0,0,0,0,0,0,0,0,0,0
0,0,0,0,0,0,0,0,0,0,0,0,0,0,0,0,0,0,0
:endlayer
layer: 7
0,0,0,0,0,0,0,0,0,0,0,0,0,0,0,0,0,0,0
0,0,0,0,0,0,24,17,25,0,0,0,0,0,0,0,0,0,0
0,0,0,0,0,0,24,6,25,0,0,0,0,0,0,0,0,0,0
0,0,0,0,0,0,24,20,25,0,0,0,0,0,0,0,0,0,0
0,0,0,0,0,0,24,20,25,0,5,0,5,0,5,0,0,0,0
0,0,0,0,0,0,24,20,25,5,6,5,6,5,6,5,0,0,0
0,0,0,0,0,0,24,20,25,0,5,0,0,0,5,0,0,0,0
0,0,0,0,0,0,24,20,25,5,6,0,5,0,6,5,0,0,0
0,0,0,0,0,0,24,20,4,0,5,0,16,0,5,0,0,0,0
0,0,0,0,0,0,24,6,4,6,6,0,6,5,6,4,6,0,0
0,0,0,0,0,0,24,4,4,4,9,0,9,0,9,0,5,0,0
0,23,23,23,23,23,23,4,4,6,18,0,0,0,0,12,6,0,0
0,19,20,19,19,19,19,19,19,4,0,0,0,0,0,0,5,0,0
0,17,20,17,17,17,17,17,17,6,18,0,0,0,0,12,6,0,0
0,21,21,21,21,21,21,21,21,4,0,0,0,0,0,0,5,0,0
0,0,0,0,0,0,0,0,0,6,18,0,0,0,0,12,6,0,0
0,0,0,0,0,0,0,0,0,4,0,16,0,0,16,0,5,0,0
0,0,0,0,0,0,3,0,0,6,5,6,5,5,6,5,6,0,0
0,0,0,0,0,0,0,0,0,9,0,0,0,0,0,0,9,0,0
0,0,0,0,0,0,0,0,0,0,0,0,0,0,0,0,0,0,0
:endlayer
layer: 8
0,0,0,0,0,0,0,0,0,0,0,0,0,0,0,0,0,0,0
0,0,0,0,0,0,0,8,0,0,0,0,0,0,0,0,0,0,0
0,0,0,0,0,0,0,8,0,0,0,0,0,0,0,0,0,0,0
0,0,0,0,0,0,0,8,0,0,0,0,0,0,0,0,0,0,0
0,0,0,0,0,0,0,8,0,23,23,23,23,23,23,25,0,0,0
0,0,0,0,0,0,0,8,0,24,6,22,22,22,6,25,0,0,0
0,0,0,0,0,0,0,8,0,24,20,0,0,0,20,25,0,0,0
0,0,0,0,0,0,0,8,0,24,20,18,5,0,20,25,0,0,0
0,0,0,0,0,0,0,8,24,4,20,0,0,0,20,25,26,25,0
0,0,0,0,0,0,0,8,24,6,22,22,22,22,22,22,6,25,0
0,0,0,0,0,0,0,8,24,20,0,0,0,0,0,0,20,25,0
0,0,0,0,0,0,0,8,24,20,0,0,0,0,0,0,20,25,0
0,23,23,23,23,23,23,23,23,20,0,0,0,0,0,0,20,25,0
0,21,21,21,21,21,21,21,21,20,0,0,0,0,0,0,20,25,0
0,0,0,0,0,0,0,0,24,20,0,0,0,0,0,0,20,25,0
0,0,0,0,0,0,0,0,24,20,0,0,0,0,0,0,20,25,0
0,0,0,0,0,0,0,0,24,20,0,0,0,0,0,0,20,25,0
0,0,0,0,0,0,3,0,24,6,22,22,22,22,22,22,6,25,0
0,0,0,0,0,0,0,0,24,27,0,0,0,0,0,0,26,25,0
0,0,0,0,0,0,0,0,0,0,0,0,0,0,0,0,0,0,0
:endlayer
layer: 9
0,0,0,0,0,0,0,0,0,0,0,0,0,0,0,0,0,0,0
0,0,0,0,0,0,0,0,0,0,0,0,0,0,0,0,0,0,0
0,0,0,0,0,0,0,0,0,0,0,0,0,0,0,0,0,0,0
0,0,0,0,0,0,0,0,0,0,0,0,0,0,0,0,0,0,0
0,0,0,0,0,0,0,0,0,0,0,0,0,0,0,0,0,0,0
0,0,0,0,0,0,0,0,0,0,23,23,23,23,25,0,0,0,0
0,0,0,0,0,0,0,0,0,0,24,27,19,26,25,0,0,0,0
0,0,0,0,0,0,0,0,0,0,24,27,5,26,25,0,0,0,0
0,0,0,0,0,0,0,0,0,24,4,17,17,26,25,26,25,0,0
0,0,0,0,0,0,0,0,0,24,6,4,4,4,4,6,25,0,0
0,0,0,0,0,0,0,0,0,24,27,0,0,0,0,26,25,0,0
0,0,0,0,0,0,0,0,0,24,27,0,0,0,0,26,25,0,0
0,0,0,0,0,0,0,0,0,24,27,0,0,0,0,26,25,0,0
0,0,0,0,0,0,0,0,0,24,27,0,0,0,0,26,25,0,0
0,0,0,0,0,0,0,0,0,24,27,0,0,0,0,26,25,0,0
0,0,0,0,0,0,0,0,0,24,27,0,0,0,0,26,25,0,0
0,0,0,0,0,0,0,0,0,24,27,0,0,0,0,26,25,0,0
0,0,0,0,0,0,3,0,0,24,6,4,4,4,4,6,25,0,0
0,0,0,0,0,0,0,0,0,24,27,0,0,0,0,26,25,0,0
0,0,0,0,0,0,0,0,0,0,0,0,0,0,0,0,0,0,0
:endlayer
layer: 10
0,0,0,0,0,0,0,0,0,0,0,0,0,0,0,0,0,0,0
0,0,0,0,0,0,0,0,0,0,0,0,0,0,0,0,0,0,0
0,0,0,0,0,0,0,0,0,0,0,0,0,0,0,0,0,0,0
0,0,0,0,0,0,0,0,0,0,0,0,0,0,0,0,0,0,0
0,0,0,0,0,0,0,0,0,0,0,0,0,0,0,0,0,0,0
0,0,0,0,0,0,0,0,0,0,0,0,0,0,0,0,0,0,0
0,0,0,0,0,0,0,0,0,0,0,24,23,25,0,0,0,0,0
0,0,0,0,0,0,0,0,0,0,0,24,4,25,0,0,0,0,0
0,0,0,0,0,0,0,0,0,0,24,4,21,21,26,25,0,0,0
0,0,0,0,0,0,0,0,0,0,24,6,4,4,6,25,0,0,0
0,0,0,0,0,0,0,0,0,0,24,27,0,0,26,25,0,0,0
0,0,0,0,0,0,0,0,0,0,24,27,0,0,26,25,0,0,0
0,0,0,0,0,0,0,0,0,0,24,27,0,0,26,25,0,0,0
0,0,0,0,0,0,0,0,0,0,24,27,0,0,26,25,0,0,0
0,0,0,0,0,0,0,0,0,0,24,27,0,0,26,25,0,0,0
0,0,0,0,0,0,0,0,0,0,24,27,0,0,26,25,0,0,0
0,0,0,0,0,0,0,0,0,0,24,27,0,0,26,25,0,0,0
0,0,0,0,0,0,28,0,0,0,24,6,4,4,6,25,0,0,0
0,0,0,0,0,0,0,0,0,0,24,27,0,0,26,25,0,0,0
0,0,0,0,0,0,0,0,0,0,0,0,0,0,0,0,0,0,0
:endlayer
layer: 11
0,0,0,0,0,0,0,0,0,0,0,0,0,0,0,0,0,0,0
0,0,0,0,0,0,0,0,0,0,0,0,0,0,0,0,0,0,0
0,0,0,0,0,0,0,0,0,0,0,0,0,0,0,0,0,0,0
0,0,0,0,0,0,0,0,0,0,0,0,0,0,0,0,0,0,0
0,0,0,0,0,0,0,0,0,0,0,0,0,0,0,0,0,0,0
0,0,0,0,0,0,0,0,0,0,0,0,0,0,0,0,0,0,0
0,0,0,0,0,0,0,0,0,0,0,0,0,0,0,0,0,0,0
0,0,0,0,0,0,0,0,0,0,0,0,8,0,0,0,0,0,0
0,0,0,0,0,0,0,0,0,0,0,24,27,26,25,0,0,0,0
0,0,0,0,0,0,0,0,0,0,0,24,22,22,25,0,0,0,0
0,0,0,0,0,0,0,0,0,0,0,24,27,26,25,0,0,0,0
0,0,0,0,0,0,0,0,0,0,0,24,27,26,25,0,0,0,0
0,0,0,0,0,0,0,0,0,0,0,24,27,26,25,0,0,0,0
0,0,0,0,0,0,0,0,0,0,0,24,27,26,25,0,0,0,0
0,0,0,0,0,0,0,0,0,0,0,24,27,26,25,0,0,0,0
0,0,0,0,0,0,0,0,0,0,0,24,27,26,25,0,0,0,0
0,0,0,0,0,0,0,0,0,0,0,24,27,26,25,0,0,0,0
0,0,0,0,0,0,7,0,0,0,0,24,22,22,25,0,0,0,0
0,0,0,0,0,0,0,0,0,0,0,24,27,26,25,0,0,0,0
0,0,0,0,0,0,0,0,0,0,0,0,0,0,0,0,0,0,0
:endlayer
layer: 12
0,0,0,0,0,0,0,0,0,0,0,0,0,0,0,0,0,0,0
0,0,0,0,0,0,0,0,0,0,0,0,0,0,0,0,0,0,0
0,0,0,0,0,0,0,0,0,0,0,0,0,0,0,0,0,0,0
0,0,0,0,0,0,0,0,0,0,0,0,0,0,0,0,0,0,0
0,0,0,0,0,0,0,0,0,0,0,0,0,0,0,0,0,0,0
0,0,0,0,0,0,0,0,0,0,0,0,0,0,0,0,0,0,0
0,0,0,0,0,0,0,0,0,0,0,0,0,0,0,0,0,0,0
0,0,0,0,0,0,0,0,0,0,0,0,0,0,0,0,0,0,0
0,0,0,0,0,0,0,0,0,0,0,0,24,25,0,0,0,0,0
0,0,0,0,0,0,0,0,0,0,0,0,24,25,0,0,0,0,0
0,0,0,0,0,0,0,0,0,0,0,0,24,25,0,0,0,0,0
0,0,0,0,0,0,0,0,0,0,0,0,24,25,0,0,0,0,0
0,0,0,0,0,0,0,0,0,0,0,0,24,25,0,0,0,0,0
0,0,0,0,0,0,0,0,0,0,0,0,24,25,0,0,0,0,0
0,0,0,0,0,0,0,0,0,0,0,0,24,25,0,0,0,0,0
0,0,0,0,0,0,0,0,0,0,0,0,24,25,0,0,0,0,0
0,0,0,0,0,0,0,0,0,0,0,0,24,25,0,0,0,0,0
0,0,0,0,0,0,0,0,0,0,0,0,24,25,0,0,0,0,0
0,0,0,0,0,0,0,0,0,0,0,0,24,25,0,0,0,0,0
0,0,0,0,0,0,0,0,0,0,0,0,0,0,0,0,0,0,0
:endlayer

#### RULES ####
rule:
plugin=vanillaBlocks
number=1
data:
JSON:{blockState:{blockName:"minecraft:grass",properties:{snowy:"false"}}}
:enddata
:endrule

rule:
plugin=vanillaBlocks
number=2
data:
JSON:{blockState:{blockName:"minecraft:stonebrick",properties:{variant:"stonebrick"}}}
:enddata
:endrule

rule:
plugin=vanillaBlocks
number=3
data:
JSON:{blockState:{blockName:"minecraft:cobblestone"}}
:enddata
:endrule

rule:
plugin=vanillaBlocks
number=4
data:
JSON:{blockState:{blockName:"biomesoplenty:planks_0",properties:{variant:"sacred_oak"}}}
:enddata
:endrule

rule:
plugin=vanillaBlocks
number=5
data:
JSON:{blockState:{blockName:"biomesoplenty:sacred_oak_fence",properties:{east:"false",south:"false",north:"false",west:"false"}}}
:enddata
:endrule

rule:
plugin=vanillaBlocks
number=6
data:
JSON:{blockState:{blockName:"biomesoplenty:log_0",properties:{variant:"sacred_oak",axis:"y"}}}
:enddata
:endrule

rule:
plugin=vanillaBlocks
number=7
data:
JSON:{blockState:{blockName:"minecraft:stone_slab",properties:{half:"bottom",variant:"cobblestone"}}}
:enddata
:endrule

rule:
plugin=vanillaBlocks
number=8
data:
JSON:{blockState:{blockName:"biomesoplenty:wood_slab_0",properties:{half:"bottom",variant:"sacred_oak"}}}
:enddata
:endrule

rule:
plugin=vanillaBlocks
number=9
data:
JSON:{blockState:{blockName:"minecraft:torch",properties:{facing:"south"}}}
:enddata
:endrule

rule:
plugin=vanillaBlocks
number=10
data:
JSON:{blockState:{blockName:"biomesoplenty:wood_slab_0",properties:{half:"top",variant:"sacred_oak"}}}
:enddata
:endrule

rule:
plugin=vanillaBlocks
number=11
data:
JSON:{blockState:{blockName:"minecraft:torch",properties:{facing:"up"}}}
:enddata
:endrule

rule:
plugin=vanillaBlocks
number=12
data:
JSON:{blockState:{blockName:"minecraft:torch",properties:{facing:"west"}}}
:enddata
:endrule

rule:
plugin=vanillaBlocks
number=13
data:
JSON:{blockState:{blockName:"minecraft:stone_stairs",properties:{half:"bottom",shape:"straight",facing:"west"}}}
:enddata
:endrule

rule:
plugin=vanillaBlocks
number=14
data:
JSON:{blockState:{blockName:"minecraft:stone_stairs",properties:{half:"top",shape:"straight",facing:"east"}}}
:enddata
:endrule

rule:
plugin=vanillaBlocks
number=15
data:
JSON:{blockState:{blockName:"minecraft:stone_stairs",properties:{half:"top",shape:"straight",facing:"west"}}}
:enddata
:endrule

rule:
plugin=vanillaBlocks
number=16
data:
JSON:{blockState:{blockName:"minecraft:torch",properties:{facing:"north"}}}
:enddata
:endrule

rule:
plugin=vanillaBlocks
number=17
data:
JSON:{blockState:{blockName:"biomesoplenty:sacred_oak_stairs",properties:{half:"top",shape:"straight",facing:"south"}}}
:enddata
:endrule

rule:
plugin=vanillaBlocks
number=18
data:
JSON:{blockState:{blockName:"minecraft:torch",properties:{facing:"east"}}}
:enddata
:endrule

rule:
plugin=vanillaBlocks
number=19
data:
JSON:{blockState:{blockName:"biomesoplenty:sacred_oak_stairs",properties:{half:"top",shape:"straight",facing:"north"}}}
:enddata
:endrule

rule:
plugin=vanillaBlocks
number=20
data:
JSON:{blockState:{blockName:"biomesoplenty:log_0",properties:{variant:"sacred_oak",axis:"z"}}}
:enddata
:endrule

rule:
plugin=vanillaBlocks
number=21
data:
JSON:{blockState:{blockName:"biomesoplenty:sacred_oak_stairs",properties:{half:"bottom",shape:"straight",facing:"north"}}}
:enddata
:endrule

rule:
plugin=vanillaBlocks
number=22
data:
JSON:{blockState:{blockName:"biomesoplenty:log_0",properties:{variant:"sacred_oak",axis:"x"}}}
:enddata
:endrule

rule:
plugin=vanillaBlocks
number=23
data:
JSON:{blockState:{blockName:"biomesoplenty:sacred_oak_stairs",properties:{half:"bottom",shape:"straight",facing:"south"}}}
:enddata
:endrule

rule:
plugin=vanillaBlocks
number=24
data:
JSON:{blockState:{blockName:"biomesoplenty:sacred_oak_stairs",properties:{half:"bottom",shape:"straight",facing:"east"}}}
:enddata
:endrule

rule:
plugin=vanillaBlocks
number=25
data:
JSON:{blockState:{blockName:"biomesoplenty:sacred_oak_stairs",properties:{half:"bottom",shape:"straight",facing:"west"}}}
:enddata
:endrule

rule:
plugin=vanillaBlocks
number=26
data:
JSON:{blockState:{blockName:"biomesoplenty:sacred_oak_stairs",properties:{half:"top",shape:"straight",facing:"east"}}}
:enddata
:endrule

rule:
plugin=vanillaBlocks
number=27
data:
JSON:{blockState:{blockName:"biomesoplenty:sacred_oak_stairs",properties:{half:"top",shape:"straight",facing:"west"}}}
:enddata
:endrule

rule:
plugin=vanillaBlocks
number=28
data:
JSON:{blockState:{blockName:"minecraft:cobblestone_wall",properties:{east:"false",south:"false",north:"false",variant:"cobblestone",west:"false",up:"false"}}}
:enddata
:endrule

#### ENTITIES ####
