# Ancient Warfare Structure Template File
# Auto-generated structure template file. created on: 6/8/2023 at: 23:32:58
# Lines beginning with # denote comments

header:
version=2.11
name=SB_MarenCol_House_1H7R_1_mangrove
mods=biomesoplenty
size=32,17,29
offset=12,1,28
:endheader

#### VALIDATION ####
validation:
type=ground
structureAuthor=TheOddlySeagull
survival=true
worldGenEnabled=false
unique=false
preserveBlocks=false
preventNaturalHostileSpawns=false
selectionWeight=1
clusterValue=1
minDuplicateDistance=1
dimensionWhiteList=true
dimensionList=
biomeGroupList=
biomeWhiteList=true
biomeList=
leveling=0
fill=0
border=0
blockSwap=false
territoryName=
biomeReplacement=minecraft:
minGenerationHeight=0
maxGenerationHeight=255
:endvalidation

#### LAYERS ####
layer: 0
1,1,1,1,1,1,1,1,1,1,2,2,2,2,1,1,1,1,1,1,1,1,1,1,1,1,1,1,1,1,1,1
1,1,1,1,1,1,1,1,1,1,2,2,2,2,1,1,1,1,1,1,1,1,1,1,1,1,1,1,1,1,1,1
1,1,1,1,1,1,1,2,2,2,2,2,2,2,2,2,2,1,1,1,1,1,1,1,1,1,1,1,1,1,1,1
1,1,1,1,1,1,1,2,2,2,2,2,2,2,2,2,2,1,1,1,1,1,1,1,1,1,1,1,1,1,1,1
1,1,1,1,1,1,1,2,2,2,2,2,2,2,2,2,2,1,1,1,1,1,1,1,1,1,1,1,1,1,1,1
1,1,1,1,1,1,1,2,2,2,2,2,2,2,2,2,2,1,1,1,1,1,1,1,1,1,1,1,1,1,1,1
1,1,1,1,1,1,1,2,2,2,2,2,2,2,2,2,2,2,2,2,2,1,1,1,1,1,1,1,1,1,1,1
1,1,1,1,1,1,1,2,2,2,2,2,2,2,3,3,3,3,3,3,2,1,1,2,2,1,1,1,1,1,1,1
1,1,1,1,1,1,1,2,2,2,2,2,2,2,3,3,3,3,3,3,2,2,2,2,2,2,2,2,1,1,1,1
1,1,1,1,1,1,1,2,2,2,2,2,2,2,3,3,3,3,3,3,2,3,3,2,2,3,3,2,1,1,1,1
1,1,1,1,1,1,1,2,2,2,2,2,2,2,2,2,2,2,2,2,2,3,3,3,3,3,3,2,2,2,2,2
1,1,1,1,1,2,2,2,2,2,2,2,2,2,2,2,2,2,2,2,2,3,3,3,3,3,3,2,2,2,2,2
1,1,1,1,1,2,2,2,2,2,2,2,2,2,2,2,2,2,2,2,2,3,3,3,3,3,3,2,2,2,2,2
1,1,1,1,1,2,2,2,2,2,2,2,2,2,2,2,2,2,2,2,2,3,3,3,3,3,3,2,2,2,2,2
1,1,2,2,2,2,2,2,2,2,2,2,2,2,2,2,2,2,2,2,2,3,3,3,3,3,3,2,2,2,2,2
1,1,2,2,2,2,2,2,2,2,2,2,2,2,2,2,2,2,2,2,2,3,3,3,3,3,3,2,2,2,2,2
1,1,2,2,2,2,2,2,2,2,2,2,2,2,2,2,2,2,2,2,2,3,3,3,3,3,3,2,2,2,2,2
1,1,2,2,2,2,2,2,2,2,2,2,2,2,2,2,2,2,2,2,2,3,3,3,3,3,3,2,1,1,1,1
1,1,2,2,2,2,2,2,2,2,2,2,2,2,2,2,2,2,2,2,2,2,2,2,2,2,2,2,1,1,1,1
1,1,2,2,2,2,2,2,2,2,2,2,2,2,2,2,2,2,2,2,1,1,1,1,1,1,1,1,1,1,1,1
1,1,2,2,2,2,2,2,2,2,2,2,2,2,2,2,2,1,1,1,1,1,1,1,1,1,1,1,1,1,1,1
1,1,2,2,2,2,2,2,2,2,2,2,2,2,2,2,2,1,1,1,1,1,1,1,1,1,1,1,1,1,1,1
1,1,1,1,1,2,2,2,2,2,2,2,2,2,2,2,2,1,1,1,1,1,1,1,1,1,1,1,1,1,1,1
1,1,1,1,1,2,2,2,2,2,2,2,2,2,2,2,2,1,1,1,1,1,1,1,1,1,1,1,1,1,1,1
1,1,1,1,1,2,2,2,2,2,2,2,2,2,2,2,2,1,1,1,1,1,1,1,1,1,1,1,1,1,1,1
1,1,1,1,1,2,2,2,2,2,2,2,2,2,2,2,2,1,1,1,1,1,1,1,1,1,1,1,1,1,1,1
1,1,1,1,1,1,1,1,1,1,1,2,2,2,2,1,1,1,1,1,1,1,1,1,1,1,1,1,1,1,1,1
1,1,1,1,1,1,1,1,1,1,1,2,2,2,2,1,1,1,1,1,1,1,1,1,1,1,1,1,1,1,1,1
1,1,1,1,1,1,1,1,1,1,1,2,2,2,2,1,1,1,1,1,1,1,1,1,1,1,1,1,1,1,1,1
:endlayer
layer: 1
0,0,0,0,0,0,0,0,0,0,0,0,0,0,0,0,0,0,0,0,0,0,0,0,0,0,0,0,0,0,0,0
0,4,0,0,0,0,0,0,0,0,0,0,0,0,0,0,0,0,0,0,0,0,0,4,0,0,0,0,0,0,4,0
0,0,0,0,0,0,0,5,3,3,5,0,0,5,3,3,5,0,0,0,0,0,0,0,0,0,0,0,0,0,0,0
0,0,0,0,0,0,0,3,0,0,0,0,0,0,0,0,3,0,0,0,0,0,0,0,0,0,0,0,0,0,0,0
0,0,0,0,0,0,0,5,0,0,0,0,0,0,0,0,5,0,0,0,0,0,0,0,0,0,0,0,0,0,0,0
0,0,0,0,0,0,0,3,0,0,0,0,0,0,0,0,3,0,0,0,0,0,0,0,0,0,0,0,0,0,0,0
0,0,0,0,0,0,0,3,0,0,0,0,0,5,3,3,5,3,5,3,5,0,0,0,0,0,0,0,0,0,4,0
0,0,0,0,0,0,0,5,0,0,0,0,0,3,0,0,0,0,0,0,3,0,0,2,2,0,0,0,0,0,0,0
0,4,0,0,0,0,0,3,0,0,0,0,0,3,0,0,0,0,0,0,5,3,2,6,6,2,3,5,0,0,0,0
0,0,0,0,0,0,0,3,0,0,0,0,0,3,0,0,0,0,0,0,3,0,0,7,7,0,0,3,0,0,0,0
0,0,0,0,0,0,0,5,0,0,0,0,0,5,3,5,0,0,5,3,5,0,0,0,0,0,0,5,4,0,0,4
0,0,0,0,0,0,0,3,0,0,0,0,0,0,0,0,0,0,0,0,3,0,0,0,0,0,0,3,0,0,0,0
0,0,0,0,0,0,0,0,0,0,0,0,0,0,0,0,0,0,0,0,5,0,0,0,0,0,0,3,0,0,0,0
0,0,0,0,0,0,0,3,0,0,0,0,0,0,0,0,0,0,0,0,0,0,0,0,0,0,0,5,0,0,0,0
0,0,5,3,5,3,3,5,3,5,0,0,0,0,0,0,0,0,0,0,0,0,0,0,0,0,0,0,0,0,0,0
0,0,3,0,0,0,0,0,0,3,0,0,0,0,8,0,0,0,0,0,0,0,0,0,0,0,0,0,0,0,0,0
0,0,5,0,0,0,0,0,0,5,0,0,0,0,0,0,0,0,0,0,5,0,0,0,0,0,0,5,4,0,0,4
0,0,3,0,0,0,0,0,0,0,0,0,0,0,0,0,0,7,7,7,3,0,0,0,0,0,0,3,0,0,0,0
0,0,3,0,0,0,0,0,0,0,0,0,0,0,0,0,2,6,6,6,2,3,5,3,3,5,3,5,0,0,0,0
0,0,5,0,0,0,0,0,0,5,0,0,0,0,0,0,3,2,2,2,0,0,0,0,0,0,0,0,0,0,0,0
0,0,3,0,0,0,0,0,0,3,0,0,0,0,0,0,5,0,0,0,0,0,0,0,0,0,0,0,0,0,0,0
0,0,5,3,3,5,3,5,3,5,0,0,0,0,0,0,3,0,0,0,0,0,0,0,0,0,0,0,0,0,0,0
0,0,0,0,0,3,0,0,0,0,0,0,0,0,0,0,3,0,0,0,0,0,0,0,0,0,0,0,0,0,4,0
0,0,0,0,0,5,0,4,9,5,0,0,0,0,0,0,5,0,0,0,0,0,0,4,0,0,0,0,0,0,0,0
0,0,0,0,0,3,0,10,11,3,0,0,0,0,0,0,3,0,0,0,0,0,0,0,0,0,0,0,0,0,0,0
0,0,0,0,0,5,3,5,3,5,3,5,0,0,5,3,5,0,0,0,0,0,0,0,0,0,0,0,0,0,0,0
0,0,0,0,0,0,0,0,0,0,0,4,0,0,4,0,0,0,0,0,0,0,0,0,0,0,0,0,0,0,0,0
0,4,0,0,0,0,0,0,0,0,0,0,0,0,0,0,0,0,0,0,4,0,0,0,0,4,0,0,0,0,4,0
0,0,0,0,0,0,0,0,0,0,0,0,0,0,0,0,0,0,0,0,0,0,0,0,0,0,0,0,0,0,0,0
:endlayer
layer: 2
0,0,0,0,0,0,0,0,0,0,0,0,0,0,0,0,0,0,0,0,0,0,0,0,0,0,0,0,0,0,0,0
0,8,0,0,0,0,0,0,0,0,0,0,0,0,0,0,0,0,0,0,0,0,0,8,0,0,0,0,0,0,8,0
0,0,0,0,0,0,0,5,4,4,5,0,0,5,4,4,5,0,0,0,0,0,0,0,0,0,0,0,0,0,0,0
0,0,0,0,0,0,0,3,0,0,0,0,0,0,0,0,3,0,0,0,0,0,0,0,0,0,0,0,0,0,0,0
0,0,0,0,0,0,0,5,0,0,0,0,0,0,0,0,5,0,0,0,0,0,0,0,0,0,0,0,0,0,0,0
0,0,0,0,0,0,0,4,0,0,0,0,0,0,0,0,3,0,0,0,0,0,0,0,0,0,0,0,0,0,0,0
0,0,0,0,0,0,0,4,0,0,0,0,0,5,3,3,5,4,5,4,5,0,0,0,0,0,0,0,0,0,8,0
0,0,0,0,0,0,0,5,0,0,0,0,0,3,0,0,0,0,0,0,4,0,0,2,2,0,0,0,0,0,0,0
0,8,0,0,0,0,0,4,0,0,0,0,0,3,0,0,0,0,0,0,5,3,2,0,0,2,3,5,0,0,0,0
0,0,0,0,0,0,0,4,0,0,0,0,0,3,0,0,0,0,0,0,3,0,0,0,0,0,0,3,0,0,0,0
0,0,0,0,0,0,0,5,0,0,0,0,0,5,3,5,0,0,5,3,5,0,0,0,0,0,0,5,4,0,0,8
0,0,0,0,0,0,0,3,0,0,0,0,0,0,0,0,0,0,0,0,3,0,0,0,0,0,0,4,0,0,0,0
0,0,0,0,0,0,0,0,0,0,0,0,0,0,0,0,0,0,0,0,5,0,0,0,0,0,0,4,0,0,0,0
0,0,0,0,0,0,0,3,0,0,0,0,0,0,0,0,0,0,0,0,0,0,0,0,0,0,0,5,0,0,0,0
0,0,5,3,5,4,4,5,3,5,0,0,0,0,0,0,0,0,0,0,0,0,0,0,0,0,0,0,0,0,0,0
0,0,3,0,0,0,0,0,0,3,0,0,0,0,0,0,0,0,0,0,0,0,0,0,0,0,0,0,0,0,0,0
0,0,5,0,0,0,0,0,0,5,0,0,0,0,0,0,0,0,0,0,5,0,0,0,0,0,0,5,4,0,0,8
0,0,4,0,0,0,0,0,0,0,0,0,0,0,0,0,0,0,0,0,3,0,0,0,0,0,0,3,0,0,0,0
0,0,4,0,0,0,0,0,0,0,0,0,0,0,0,0,2,0,0,0,2,3,5,4,4,5,3,5,0,0,0,0
0,0,5,0,0,0,0,0,0,5,0,0,0,0,0,0,3,2,2,2,0,0,0,0,0,0,0,0,0,0,0,0
0,0,3,0,0,0,0,0,0,3,0,0,0,0,0,0,5,0,0,0,0,0,0,0,0,0,0,0,0,0,0,0
0,0,5,4,4,5,3,5,3,5,0,0,0,0,0,0,4,0,0,0,0,0,0,0,0,0,0,0,0,0,0,0
0,0,0,0,0,4,0,0,0,0,0,0,0,0,0,0,4,0,0,0,0,0,0,0,0,0,0,0,0,0,8,0
0,0,0,0,0,5,12,4,0,5,0,0,0,0,0,0,5,0,0,0,0,0,0,8,0,0,0,0,0,0,0,0
0,0,0,0,0,4,11,9,0,3,0,0,0,0,0,0,3,0,0,0,0,0,0,0,0,0,0,0,0,0,0,0
0,0,0,0,0,5,4,5,4,5,3,5,0,0,5,3,5,0,0,0,0,0,0,0,0,0,0,0,0,0,0,0
0,0,0,0,0,0,0,0,0,0,0,4,0,0,4,0,0,0,0,0,0,0,0,0,0,0,0,0,0,0,0,0
0,8,0,0,0,0,0,0,0,0,0,0,0,0,0,0,0,0,0,0,8,0,0,0,0,8,0,0,0,0,8,0
0,0,0,0,0,0,0,0,0,0,0,0,0,0,0,0,0,0,0,0,0,0,0,0,0,0,0,0,0,0,0,0
:endlayer
layer: 3
0,0,0,0,0,0,0,0,0,0,0,0,0,0,0,0,0,0,0,0,0,0,0,0,0,0,0,0,0,0,0,0
0,0,0,0,0,0,0,10,0,0,10,0,0,10,0,0,10,0,0,0,0,0,0,0,0,0,0,0,0,0,0,0
0,0,0,0,0,0,13,5,4,4,5,3,3,5,4,4,5,12,0,0,0,0,0,0,0,0,0,0,0,0,0,0
0,0,0,0,0,0,0,3,0,0,14,0,0,14,0,0,3,0,0,0,0,0,0,0,0,0,0,0,0,0,0,0
0,0,0,0,0,0,0,5,12,0,0,0,0,0,0,13,5,0,0,0,0,0,0,0,0,0,0,0,0,0,0,0
0,0,0,0,0,0,0,4,0,0,0,0,0,10,0,0,3,0,0,0,10,0,0,0,0,0,0,0,0,0,0,0
0,0,0,0,0,0,0,4,0,0,0,0,13,5,3,3,5,4,5,4,5,12,0,0,0,0,0,0,0,0,0,0
0,0,0,0,0,0,13,5,12,0,0,0,0,3,0,0,14,0,14,0,4,0,0,2,2,0,0,10,0,0,0,0
0,0,0,0,0,0,0,4,0,0,0,0,0,3,0,0,0,0,0,13,5,3,2,15,16,2,3,5,12,0,0,0
0,0,0,0,0,0,0,4,0,0,0,0,0,3,0,10,0,0,10,0,3,0,0,0,0,0,0,3,0,0,0,0
0,0,0,0,0,0,0,5,17,0,0,0,18,5,3,5,17,18,5,3,5,12,0,0,0,0,13,5,4,0,0,0
0,0,0,0,0,0,0,3,0,0,0,0,0,14,0,14,0,0,14,0,3,0,0,0,0,0,0,4,0,0,0,0
0,0,0,0,0,0,13,3,0,0,0,0,0,0,0,0,0,0,0,13,5,12,0,0,0,0,0,4,0,0,0,0
0,0,10,0,0,0,0,3,0,10,0,0,0,0,0,0,0,0,0,0,19,0,0,0,0,0,13,5,12,0,0,0
0,13,5,3,5,4,4,5,3,5,12,0,0,0,0,0,0,0,0,0,11,0,0,0,0,0,0,3,0,0,0,0
0,0,3,0,14,0,0,14,0,3,0,0,0,0,0,0,0,0,0,0,20,0,0,0,0,0,0,3,0,0,0,0
0,0,5,12,0,0,0,0,13,5,12,0,0,0,0,0,0,0,0,13,5,12,0,0,0,0,13,5,4,0,0,0
0,0,4,0,0,0,0,0,0,19,0,0,0,0,0,0,0,0,0,0,3,0,10,0,0,10,0,3,0,0,0,0
0,0,4,0,0,0,0,0,0,20,0,0,0,0,0,0,2,15,0,16,2,3,5,4,4,5,3,5,12,0,0,0
0,0,5,12,0,0,0,0,13,5,17,0,0,0,0,18,3,2,2,2,0,0,14,0,0,14,0,14,0,0,0,0
0,0,3,0,0,10,0,10,0,3,0,0,0,0,0,13,5,12,0,0,0,0,0,0,0,0,0,0,0,0,0,0
0,13,5,4,4,5,3,5,3,5,12,0,0,0,0,0,4,0,0,0,0,0,0,0,0,0,0,0,0,0,0,0
0,0,14,0,0,4,11,14,0,3,0,0,0,0,0,0,4,0,0,0,0,0,0,0,0,0,0,0,0,0,0,0
0,0,0,0,0,5,9,4,0,5,12,0,0,0,0,13,5,12,0,0,0,0,0,0,0,0,0,0,0,0,0,0
0,0,0,0,0,4,0,0,0,3,0,10,0,0,10,0,3,0,0,0,0,0,0,0,0,0,0,0,0,0,0,0
0,0,0,0,13,5,4,5,4,5,3,5,3,3,5,3,5,12,0,0,0,0,0,0,0,0,0,0,0,0,0,0
0,0,0,0,0,14,0,0,0,14,0,4,0,0,4,0,14,0,0,0,0,0,0,0,0,0,0,0,0,0,0,0
0,0,0,0,0,0,0,0,0,0,0,0,0,0,0,0,0,0,0,0,0,0,0,0,0,0,0,0,0,0,0,0
0,0,0,0,0,0,0,0,0,0,0,0,0,0,0,0,0,0,0,0,0,0,0,0,0,0,0,0,0,0,0,0
:endlayer
layer: 4
0,0,0,0,0,0,0,0,0,0,0,0,0,0,0,0,0,0,0,0,0,0,0,0,0,0,0,0,0,0,0,0
0,0,0,0,0,0,21,17,0,0,0,0,0,0,0,0,18,22,0,0,0,0,0,0,0,0,0,0,0,0,0,0
0,0,0,0,0,0,21,5,23,23,23,23,23,23,23,23,5,22,0,0,0,0,0,0,0,0,0,0,0,0,0,0
0,0,0,0,0,0,21,24,11,3,11,3,11,3,11,3,24,22,0,0,0,0,0,0,0,0,0,0,0,0,0,0
0,0,0,0,0,0,21,24,11,3,11,3,11,3,11,3,24,22,0,0,0,0,0,0,0,0,0,0,0,0,0,0
0,0,0,0,0,0,21,24,11,3,11,3,11,3,11,3,24,25,25,25,25,25,0,0,0,0,0,0,0,0,0,0
0,0,0,0,0,0,21,24,23,23,23,23,23,23,23,23,23,23,23,23,5,19,0,0,0,0,0,0,0,0,0,0
0,0,0,0,0,0,21,24,11,3,11,3,11,24,11,3,11,3,11,3,24,0,0,2,2,0,0,0,0,0,0,0
0,0,0,0,0,0,21,24,11,3,11,3,11,24,11,3,11,3,11,3,24,23,2,2,2,2,23,5,0,0,0,0
0,0,0,0,0,0,21,24,11,3,11,3,11,24,11,3,11,3,11,3,24,11,26,2,2,26,11,24,0,0,0,0
0,0,0,0,0,0,21,24,23,23,23,23,23,23,23,23,23,23,23,23,24,3,3,3,3,3,3,24,23,23,0,0
0,0,0,0,0,0,21,24,0,24,3,11,3,11,3,11,3,11,3,11,24,11,11,11,11,11,11,24,17,11,0,0
0,0,0,0,0,0,21,24,0,24,3,11,3,11,3,11,3,11,3,11,24,3,3,3,3,3,3,24,23,23,0,0
0,25,25,25,25,25,21,24,0,24,3,11,3,11,3,11,3,11,3,11,24,11,11,11,11,11,11,24,17,11,0,0
0,19,5,23,23,23,23,23,23,24,3,11,3,11,3,11,3,11,3,11,24,3,3,3,3,3,3,24,23,23,0,0
0,0,24,0,0,0,0,0,0,24,3,11,3,11,3,11,3,11,3,11,24,11,11,11,11,11,11,24,17,11,0,0
0,0,24,0,0,0,0,0,0,24,3,11,3,11,3,11,3,11,3,11,24,3,3,3,3,3,3,24,23,23,0,0
0,0,24,0,0,0,0,0,0,24,3,11,3,11,3,11,3,2,2,2,2,11,11,11,11,11,11,24,0,0,0,0
0,0,24,0,0,0,0,0,0,24,3,11,3,11,3,11,2,2,2,2,2,23,23,23,23,23,23,5,0,0,0,0
0,0,24,0,0,0,0,0,0,24,23,23,23,23,23,23,24,2,2,2,0,0,0,0,0,0,0,0,0,0,0,0
0,0,24,0,0,0,0,0,0,24,11,11,11,11,11,11,24,23,0,0,0,0,0,0,0,0,0,0,0,0,0,0
0,20,5,23,23,23,23,23,23,5,3,3,3,3,3,3,24,11,0,0,0,0,0,0,0,0,0,0,0,0,0,0
0,27,27,27,27,24,0,9,11,24,11,11,11,11,11,11,24,11,0,0,0,0,0,0,0,0,0,0,0,0,0,0
0,0,0,0,0,24,0,4,11,24,3,3,3,3,3,3,24,23,0,0,0,0,0,0,0,0,0,0,0,0,0,0
0,0,0,0,0,24,0,10,0,24,11,11,11,11,11,11,24,11,0,0,0,0,0,0,0,0,0,0,0,0,0,0
0,0,0,0,0,5,23,23,23,5,23,23,23,23,23,23,23,23,0,0,0,0,0,0,0,0,0,0,0,0,0,0
0,0,0,0,0,0,0,0,0,0,0,24,11,11,24,0,0,0,0,0,0,0,0,0,0,0,0,0,0,0,0,0
0,0,0,0,0,0,0,0,0,0,0,14,0,0,14,0,0,0,0,0,0,0,0,0,0,0,0,0,0,0,0,0
0,0,0,0,0,0,0,0,0,0,0,0,0,0,0,0,0,0,0,0,0,0,0,0,0,0,0,0,0,0,0,0
:endlayer
layer: 5
0,0,0,0,0,0,0,0,0,0,0,0,0,0,0,0,0,0,0,0,0,0,0,0,0,0,0,0,0,0,0,0
0,0,0,0,0,0,0,21,17,0,0,0,0,0,0,18,22,0,0,0,0,0,0,0,0,0,0,0,0,0,0,0
0,0,0,0,0,0,0,21,5,3,5,3,3,5,3,5,22,0,0,0,0,0,0,0,0,0,0,0,0,0,0,0
0,0,0,0,0,0,0,21,17,0,0,0,0,0,0,18,22,0,0,0,0,0,0,0,0,0,0,0,0,0,0,0
0,0,0,0,0,0,0,21,17,0,0,0,0,0,0,18,22,0,0,0,0,0,0,0,0,0,0,0,0,0,0,0
0,0,0,0,0,0,0,21,5,0,0,0,0,0,0,18,22,0,0,0,0,0,0,0,0,0,0,0,0,0,0,0
0,0,0,0,0,0,0,21,3,0,0,0,0,0,0,18,22,25,25,25,25,25,0,0,0,0,0,0,0,0,0,0
0,0,0,0,0,0,0,21,3,0,0,0,0,0,0,18,19,19,19,19,3,19,0,2,2,0,0,0,0,0,0,0
0,0,0,0,0,0,0,21,5,0,0,0,0,0,0,18,0,0,0,0,5,3,2,0,0,2,3,5,0,0,0,0
0,0,0,0,0,0,0,21,17,0,0,0,0,0,0,18,0,0,0,0,3,0,0,7,7,0,0,3,0,0,0,0
0,0,0,0,0,0,0,21,3,5,3,0,0,3,5,5,0,0,0,0,5,0,0,0,0,0,0,5,3,5,0,0
0,0,0,0,0,0,0,21,17,3,0,0,0,0,0,3,0,0,0,0,3,0,0,0,0,0,0,0,0,3,0,0
0,0,0,0,0,0,0,21,17,5,0,0,0,0,0,3,0,0,0,0,3,0,0,0,0,0,0,0,0,5,0,0
0,0,0,0,0,0,0,21,17,3,0,0,0,0,0,5,3,0,0,3,5,0,0,0,0,0,0,0,0,3,0,0
0,25,25,25,25,25,25,21,3,5,0,0,0,0,0,0,0,0,0,0,0,0,0,0,0,0,0,0,0,5,0,0
0,19,5,19,19,19,19,19,19,3,0,0,0,0,0,0,0,0,0,0,0,0,0,0,0,0,0,0,0,3,0,0
0,0,3,0,0,0,0,0,0,5,0,0,0,0,0,0,0,0,0,0,5,0,0,0,0,0,0,5,3,5,0,0
0,0,3,0,0,0,0,0,0,4,0,0,0,0,0,0,0,7,7,7,3,0,0,0,0,0,0,3,0,0,0,0
0,0,3,0,0,0,0,0,0,4,0,0,0,0,0,0,2,0,0,0,2,3,5,3,3,5,3,5,0,0,0,0
0,0,3,0,0,0,0,0,0,5,3,5,0,0,5,3,3,2,2,2,0,0,0,0,0,0,0,0,0,0,0,0
0,20,5,20,20,20,20,20,20,3,0,0,0,0,0,0,0,5,0,0,0,0,0,0,0,0,0,0,0,0,0,0
0,27,27,27,27,5,3,5,3,5,0,0,0,0,0,0,0,3,0,0,0,0,0,0,0,0,0,0,0,0,0,0
0,0,0,0,0,3,0,0,0,0,0,0,0,0,0,0,0,3,0,0,0,0,0,0,0,0,0,0,0,0,0,0
0,0,0,0,0,5,12,4,0,0,0,0,0,0,0,0,0,5,0,0,0,0,0,0,0,0,0,0,0,0,0,0
0,0,0,0,0,3,0,11,9,0,0,0,0,0,0,0,0,3,0,0,0,0,0,0,0,0,0,0,0,0,0,0
0,0,0,0,0,5,3,5,3,5,3,5,0,0,5,3,3,5,0,0,0,0,0,0,0,0,0,0,0,0,0,0
0,0,0,0,0,0,0,0,0,0,0,5,3,3,5,0,0,0,0,0,0,0,0,0,0,0,0,0,0,0,0,0
0,0,0,0,0,0,0,0,0,0,0,0,0,0,0,0,0,0,0,0,0,0,0,0,0,0,0,0,0,0,0,0
0,0,0,0,0,0,0,0,0,0,0,0,0,0,0,0,0,0,0,0,0,0,0,0,0,0,0,0,0,0,0,0
:endlayer
layer: 6
0,0,0,0,0,0,0,0,0,0,0,0,0,0,0,0,0,0,0,0,0,0,0,0,0,0,0,0,0,0,0,0
0,0,0,0,0,0,0,0,21,17,0,0,0,0,18,22,0,0,0,0,0,0,0,0,0,0,0,0,0,0,0,0
0,0,0,0,0,0,0,0,21,5,5,4,4,5,5,22,0,0,0,0,0,0,0,0,0,0,0,0,0,0,0,0
0,0,0,0,0,0,0,0,21,17,14,0,0,14,18,22,0,0,0,0,0,0,0,0,0,0,0,0,0,0,0,0
0,0,0,0,0,0,0,0,21,17,0,0,0,0,18,22,0,0,0,0,0,0,0,0,0,0,0,0,0,0,0,0
0,0,0,0,0,0,0,0,5,12,0,0,0,0,18,22,0,0,0,0,0,0,0,0,0,0,0,0,0,0,0,0
0,0,0,0,0,0,0,0,4,0,0,0,0,0,18,22,0,0,0,0,0,0,0,0,0,0,0,0,0,0,0,0
0,0,0,0,0,0,0,0,4,0,0,0,0,0,18,25,21,4,4,22,25,25,0,2,2,0,0,0,0,0,0,0
0,0,0,0,0,0,0,0,5,12,0,0,0,0,18,3,19,0,0,19,5,3,2,0,0,2,3,5,0,0,0,0
0,0,0,0,0,0,0,0,21,17,10,0,0,10,18,3,0,0,0,0,3,0,0,0,0,0,0,4,0,0,0,0
0,0,0,0,0,0,0,0,21,5,3,0,0,3,5,5,0,0,0,0,5,0,0,0,0,0,0,5,4,5,0,0
0,0,0,0,0,0,0,0,21,3,0,0,0,0,0,3,0,0,0,0,3,0,0,0,0,0,0,0,0,4,0,0
0,0,0,0,0,0,0,0,21,5,0,0,0,0,0,3,0,0,0,0,3,0,0,0,0,0,0,0,0,5,0,0
0,0,0,0,0,0,0,0,21,3,0,0,0,0,0,5,3,0,0,3,5,0,0,0,0,0,0,0,0,4,0,0
0,0,0,0,0,0,0,0,21,5,0,0,0,0,0,0,0,0,0,0,0,0,0,0,0,0,0,0,0,5,0,0
0,25,25,25,25,25,25,25,25,3,0,0,0,0,0,0,0,0,0,0,0,0,0,0,0,0,0,0,0,4,0,0
0,19,5,19,19,19,19,19,19,5,0,0,0,0,0,0,0,0,0,0,5,0,0,0,0,0,0,5,4,5,0,0
0,0,3,0,0,0,0,0,0,0,0,0,0,0,0,0,0,0,0,0,3,0,0,0,0,0,0,4,0,0,0,0
0,0,3,0,0,0,0,0,0,0,0,0,0,0,0,0,2,0,0,0,2,3,5,4,4,5,3,5,0,0,0,0
0,20,5,20,20,20,20,20,20,5,3,5,0,0,5,3,3,2,2,2,0,0,0,0,0,0,0,0,0,0,0,0
0,27,27,27,27,27,27,27,27,3,0,0,0,0,0,0,0,5,0,0,0,0,0,0,0,0,0,0,0,0,0,0
0,0,0,0,0,5,3,5,3,5,0,0,0,0,0,0,0,4,0,0,0,0,0,0,0,0,0,0,0,0,0,0
0,0,0,0,0,4,0,14,0,0,0,0,0,0,0,0,0,4,0,0,0,0,0,0,0,0,0,0,0,0,0,0
0,0,0,0,0,5,11,4,0,0,0,0,0,0,0,0,0,5,0,0,0,0,0,0,0,0,0,0,0,0,0,0
0,0,0,0,0,4,9,0,0,0,0,0,0,0,0,0,0,4,0,0,0,0,0,0,0,0,0,0,0,0,0,0
0,0,0,0,0,5,4,5,4,5,4,5,0,0,5,4,4,5,0,0,0,0,0,0,0,0,0,0,0,0,0,0
0,0,0,0,0,0,0,0,0,0,0,5,4,4,5,0,0,0,0,0,0,0,0,0,0,0,0,0,0,0,0,0
0,0,0,0,0,0,0,0,0,0,0,0,0,0,0,0,0,0,0,0,0,0,0,0,0,0,0,0,0,0,0,0
0,0,0,0,0,0,0,0,0,0,0,0,0,0,0,0,0,0,0,0,0,0,0,0,0,0,0,0,0,0,0,0
:endlayer
layer: 7
0,0,0,0,0,0,0,0,0,0,0,0,0,0,0,0,0,0,0,0,0,0,0,0,0,0,0,0,0,0,0,0
0,0,0,0,0,0,0,0,0,21,17,0,0,18,22,0,0,0,0,0,0,0,0,0,0,0,0,0,0,0,0,0
0,0,0,0,0,0,0,0,0,21,5,4,4,5,22,0,0,0,0,0,0,0,0,0,0,0,0,0,0,0,0,0
0,0,0,0,0,0,0,0,0,21,17,0,0,18,22,0,0,0,0,0,0,0,0,0,0,0,0,0,0,0,0,0
0,0,0,0,0,0,0,25,25,21,17,0,0,18,22,0,0,0,0,0,0,0,0,0,0,0,0,0,0,0,0,0
0,0,0,0,0,0,0,19,5,19,17,0,0,18,22,0,0,0,0,0,0,0,0,0,0,0,0,0,0,0,0,0
0,0,0,0,0,0,0,0,4,0,0,0,0,18,22,0,0,0,0,0,0,0,0,0,0,0,0,0,0,0,0,0
0,0,0,0,0,0,0,0,4,0,0,0,0,18,22,0,0,25,22,0,0,0,0,28,2,0,0,0,0,0,0,0
0,0,0,0,0,0,0,20,5,20,17,0,0,18,22,25,25,21,22,25,5,3,2,15,16,2,3,5,0,0,0,0
0,0,0,0,0,0,0,27,27,21,17,0,0,18,3,3,19,19,19,19,3,0,14,0,0,14,0,4,0,0,0,0
0,0,0,0,0,0,0,0,0,5,3,11,11,3,5,5,12,0,0,13,5,12,0,0,0,0,13,5,4,5,0,0
0,0,0,0,0,0,0,0,0,3,0,0,0,0,14,3,0,0,0,0,3,0,0,0,0,0,0,14,0,4,0,0
0,0,0,0,0,0,0,0,0,5,12,0,0,0,0,3,0,0,0,0,3,0,0,0,0,0,0,0,13,5,0,0
0,0,0,0,0,0,0,0,0,4,0,0,0,0,13,5,3,17,18,3,5,12,0,0,0,0,0,0,0,4,0,0
0,0,0,0,0,0,0,0,0,5,12,0,0,0,0,14,0,0,0,0,19,0,0,0,0,0,0,0,13,5,0,0
0,0,0,0,0,0,0,0,0,3,0,0,0,0,0,0,0,0,0,0,20,0,0,0,0,0,0,10,0,4,0,0
0,25,25,25,25,25,25,25,25,5,12,0,0,0,0,0,0,0,0,13,5,12,0,0,0,0,13,5,4,5,0,0
0,19,24,19,19,19,19,19,19,19,0,0,0,0,0,0,0,0,0,0,3,0,10,0,0,10,0,4,0,0,0,0
0,20,24,20,20,20,20,20,20,20,0,10,0,0,10,0,2,15,0,16,2,3,5,4,4,5,3,5,0,0,0,0
0,27,27,27,27,27,27,27,27,5,3,5,17,18,5,3,3,2,2,2,0,0,0,0,0,0,0,0,0,0,0,0
0,0,0,0,0,0,0,0,0,3,0,14,0,0,14,0,13,5,0,0,0,0,0,0,0,0,0,0,0,0,0,0
0,0,0,0,0,5,3,5,3,5,12,0,0,0,0,0,0,4,0,0,0,0,0,0,0,0,0,0,0,0,0,0
0,0,0,0,0,4,9,11,0,19,0,0,0,0,0,0,0,4,0,0,0,0,0,0,0,0,0,0,0,0,0,0
0,0,0,0,0,5,0,4,0,11,0,0,0,0,0,0,13,5,0,0,0,0,0,0,0,0,0,0,0,0,0,0
0,0,0,0,0,4,0,0,0,20,0,10,0,0,10,0,0,4,0,0,0,0,0,0,0,0,0,0,0,0,0,0
0,0,0,0,0,5,4,5,4,5,4,5,0,0,5,4,4,5,0,0,0,0,0,0,0,0,0,0,0,0,0,0
0,0,0,0,0,0,0,0,0,0,0,5,4,4,5,0,0,0,0,0,0,0,0,0,0,0,0,0,0,0,0,0
0,0,0,0,0,0,0,0,0,0,0,0,0,0,0,0,0,0,0,0,0,0,0,0,0,0,0,0,0,0,0,0
0,0,0,0,0,0,0,0,0,0,0,0,0,0,0,0,0,0,0,0,0,0,0,0,0,0,0,0,0,0,0,0
:endlayer
layer: 8
0,0,0,0,0,0,0,0,0,0,0,0,0,0,0,0,0,0,0,0,0,0,0,0,0,0,0,0,0,0,0,0
0,0,0,0,0,0,0,0,0,0,21,17,18,22,0,0,0,0,0,0,0,0,0,0,0,0,0,0,0,0,0,0
0,0,0,0,0,0,0,0,0,0,21,23,23,22,0,0,0,0,0,0,0,0,0,0,0,0,0,0,0,0,0,0
0,0,0,0,0,0,0,0,0,0,21,17,18,22,0,0,0,0,0,0,0,0,0,0,0,0,0,0,0,0,0,0
0,0,0,0,0,0,0,0,0,0,21,17,18,22,0,0,0,0,0,0,0,0,0,0,0,0,0,0,0,0,0,0
0,0,0,0,0,0,0,25,25,25,25,17,18,22,0,0,0,0,0,0,0,0,0,0,0,0,0,0,0,0,0,0
0,0,0,0,0,0,0,19,24,19,19,19,18,22,0,0,0,0,0,0,0,0,0,0,0,0,0,0,0,0,0,0
0,0,0,0,0,0,0,20,24,20,20,20,18,22,0,0,0,0,0,21,17,0,0,0,2,0,0,18,22,0,0,0
0,0,0,0,0,0,0,27,27,27,27,17,18,22,0,0,0,0,0,21,5,23,23,23,23,23,23,5,22,0,0,0
0,0,0,0,0,0,0,0,25,25,21,17,18,22,25,25,25,25,25,25,24,0,0,0,0,0,0,24,22,25,25,0
0,0,0,0,0,0,0,0,0,5,23,23,23,23,23,23,23,23,23,23,24,0,0,0,0,0,0,24,23,5,19,0
0,0,0,0,0,0,0,0,0,24,11,11,11,11,11,24,11,11,11,11,24,0,0,0,0,0,0,24,0,24,0,0
0,0,0,0,0,0,0,0,0,24,3,3,3,3,3,24,11,11,11,11,24,0,0,0,0,0,0,24,0,24,0,0
0,0,0,0,0,0,0,0,18,24,11,11,11,11,11,24,23,23,23,23,24,0,0,0,0,0,0,24,0,24,0,0
0,0,0,0,0,0,0,0,11,24,3,3,3,3,3,24,3,3,3,3,24,0,0,0,0,0,0,24,0,24,0,0
0,0,0,0,0,0,0,0,18,24,11,11,11,11,11,24,11,11,11,11,24,0,0,0,0,0,0,24,0,24,0,0
0,0,0,0,0,0,0,0,0,24,3,3,3,3,3,24,3,3,3,3,24,0,0,0,0,0,0,24,23,5,20,0
0,25,25,25,25,25,25,25,25,24,11,11,11,11,11,24,11,11,11,11,24,0,0,0,0,0,0,24,22,27,27,0
0,27,27,27,27,27,27,27,27,24,23,23,23,23,23,23,23,2,2,2,2,23,23,23,23,23,23,5,22,0,0,0
0,0,0,0,0,0,0,0,21,24,3,3,3,3,3,3,3,24,2,2,17,0,0,0,0,0,0,18,22,0,0,0
0,0,0,0,0,0,0,0,21,24,11,11,11,11,11,11,11,24,22,0,0,0,0,0,0,0,0,0,0,0,0,0
0,0,0,0,0,5,23,23,23,5,3,3,3,3,3,3,3,24,22,0,0,0,0,0,0,0,0,0,0,0,0,0
0,0,0,0,0,24,0,0,9,24,11,11,11,11,11,11,11,24,22,0,0,0,0,0,0,0,0,0,0,0,0,0
0,0,0,0,0,24,0,4,11,24,3,3,3,3,3,3,3,24,22,0,0,0,0,0,0,0,0,0,0,0,0,0
0,0,0,0,0,24,0,10,11,24,11,11,11,11,11,11,11,24,22,0,0,0,0,0,0,0,0,0,0,0,0,0
0,0,0,0,0,5,23,23,23,5,23,23,23,23,23,23,23,5,22,0,0,0,0,0,0,0,0,0,0,0,0,0
0,0,0,0,0,0,0,0,21,17,21,5,23,23,5,22,0,18,22,0,0,0,0,0,0,0,0,0,0,0,0,0
0,0,0,0,0,0,0,0,0,0,21,17,0,0,18,22,0,0,0,0,0,0,0,0,0,0,0,0,0,0,0,0
0,0,0,0,0,0,0,0,0,0,0,0,0,0,0,0,0,0,0,0,0,0,0,0,0,0,0,0,0,0,0,0
:endlayer
layer: 9
0,0,0,0,0,0,0,0,0,0,0,0,0,0,0,0,0,0,0,0,0,0,0,0,0,0,0,0,0,0,0,0
0,0,0,0,0,0,0,0,0,0,0,21,22,0,0,0,0,0,0,0,0,0,0,0,0,0,0,0,0,0,0,0
0,0,0,0,0,0,0,0,0,0,0,21,22,0,0,0,0,0,0,0,0,0,0,0,0,0,0,0,0,0,0,0
0,0,0,0,0,0,0,0,0,0,0,21,22,0,0,0,0,0,0,0,0,0,0,0,0,0,0,0,0,0,0,0
0,0,0,0,0,0,0,0,0,0,0,21,22,0,0,0,0,0,0,0,0,0,0,0,0,0,0,0,0,0,0,0
0,0,0,0,0,0,0,0,0,0,0,21,22,0,0,0,0,0,0,0,0,0,0,0,0,0,0,0,0,0,0,0
0,0,0,0,0,0,0,25,25,25,25,21,22,0,0,0,0,0,0,0,0,0,0,0,0,0,0,0,0,0,0,0
0,0,0,0,0,0,0,27,27,27,27,27,22,0,0,0,0,0,0,0,21,17,0,0,2,0,18,22,0,0,0,0
0,0,0,0,0,0,0,0,0,0,0,21,22,0,0,0,0,0,0,0,21,5,3,3,3,3,5,22,0,0,0,0
0,0,0,0,0,0,0,0,0,0,0,21,22,0,0,0,0,0,0,0,21,17,0,0,0,0,18,22,0,0,0,0
0,0,0,0,0,0,0,0,25,25,25,25,22,25,25,25,25,25,25,25,25,17,0,0,0,0,18,25,25,25,25,0
0,0,0,0,0,0,0,0,19,5,19,19,19,19,19,19,19,19,19,19,5,17,0,0,0,0,18,19,19,5,19,0
0,0,0,0,0,0,0,0,0,3,0,0,0,0,0,0,0,0,0,0,3,17,0,0,0,0,0,0,0,3,0,0
0,0,0,0,0,0,0,0,4,3,0,0,0,0,0,0,0,0,0,0,3,17,0,0,0,0,0,4,0,3,0,0
0,0,0,0,0,0,0,0,4,0,0,0,0,0,0,0,0,0,0,0,3,17,0,0,0,0,0,0,0,3,0,0
0,0,0,0,0,0,0,0,4,3,0,0,0,0,0,0,0,0,0,0,3,17,0,0,0,0,20,20,20,5,20,0
0,0,0,0,0,0,0,0,0,3,0,0,0,0,0,0,0,0,0,0,3,17,0,0,0,0,18,27,27,27,27,0
0,0,0,0,0,0,0,0,20,5,20,0,0,0,0,0,20,20,20,20,5,17,0,0,0,0,18,22,0,0,0,0
0,0,0,0,0,0,0,0,27,21,17,0,0,0,0,0,18,22,27,27,21,5,3,3,3,3,5,22,0,0,0,0
0,0,0,0,0,0,0,0,0,21,17,0,0,0,0,0,18,22,2,2,21,17,0,0,0,0,18,22,0,0,0,0
0,0,0,0,0,0,0,0,0,21,17,0,0,0,0,0,5,22,0,0,0,0,0,0,0,0,0,0,0,0,0,0
0,0,0,0,0,5,3,5,3,5,19,0,0,0,0,0,24,22,0,0,0,0,0,0,0,0,0,0,0,0,0,0
0,0,0,0,0,3,0,0,0,3,0,0,0,0,0,0,24,22,0,0,0,0,0,0,0,0,0,0,0,0,0,0
0,0,0,0,0,5,0,4,0,0,0,0,0,0,0,0,5,22,0,0,0,0,0,0,0,0,0,0,0,0,0,0
0,0,0,0,0,3,0,4,0,3,0,0,0,0,0,0,18,22,0,0,0,0,0,0,0,0,0,0,0,0,0,0
0,0,0,0,0,5,3,5,3,5,5,3,3,3,3,3,5,22,0,0,0,0,0,0,0,0,0,0,0,0,0,0
0,0,0,0,0,0,0,0,0,21,17,21,3,3,22,0,18,22,0,0,0,0,0,0,0,0,0,0,0,0,0,0
0,0,0,0,0,0,0,0,0,0,0,21,17,18,22,0,0,0,0,0,0,0,0,0,0,0,0,0,0,0,0,0
0,0,0,0,0,0,0,0,0,0,0,0,0,0,0,0,0,0,0,0,0,0,0,0,0,0,0,0,0,0,0,0
:endlayer
layer: 10
0,0,0,0,0,0,0,0,0,0,0,0,0,0,0,0,0,0,0,0,0,0,0,0,0,0,0,0,0,0,0,0
0,0,0,0,0,0,0,0,0,0,0,0,0,0,0,0,0,0,0,0,0,0,0,0,0,0,0,0,0,0,0,0
0,0,0,0,0,0,0,0,0,0,0,0,0,0,0,0,0,0,0,0,0,0,0,0,0,0,0,0,0,0,0,0
0,0,0,0,0,0,0,0,0,0,0,0,0,0,0,0,0,0,0,0,0,0,0,0,0,0,0,0,0,0,0,0
0,0,0,0,0,0,0,0,0,0,0,0,0,0,0,0,0,0,0,0,0,0,0,0,0,0,0,0,0,0,0,0
0,0,0,0,0,0,0,0,0,0,0,0,0,0,0,0,0,0,0,0,0,0,0,0,0,0,0,0,0,0,0,0
0,0,0,0,0,0,0,0,0,0,0,0,0,0,0,0,0,0,0,0,0,0,0,0,0,0,0,0,0,0,0,0
0,0,0,0,0,0,0,0,0,0,0,0,0,0,0,0,0,0,0,0,0,21,17,0,2,18,22,0,0,0,0,0
0,0,0,0,0,0,0,0,0,0,0,0,0,0,0,0,0,0,0,0,0,21,5,3,3,5,22,0,0,0,0,0
0,0,0,0,0,0,0,0,0,0,0,0,0,0,0,0,0,0,0,0,0,21,17,0,0,18,22,0,0,0,0,0
0,0,0,0,0,0,0,0,0,0,0,0,0,0,0,0,0,0,0,0,0,21,17,0,0,18,22,0,0,0,0,0
0,0,0,0,0,0,0,0,25,25,25,25,25,25,25,25,25,25,25,25,25,21,17,0,0,18,25,25,25,25,25,0
0,0,0,0,0,0,0,0,19,5,19,19,19,19,19,19,19,19,19,19,5,3,17,0,0,18,19,19,19,5,19,0
0,0,0,0,0,0,0,0,0,3,12,0,0,0,0,0,0,0,0,13,3,3,17,0,0,0,0,4,0,3,0,0
0,0,0,0,0,0,0,0,0,0,0,0,0,0,0,0,0,0,0,0,3,3,17,0,0,20,20,20,20,5,20,0
0,0,0,0,0,0,0,0,0,3,12,0,0,0,0,0,0,0,0,13,3,3,17,0,0,18,27,27,27,27,27,0
0,0,0,0,0,0,0,0,20,5,20,17,0,0,0,20,20,20,20,20,5,3,17,0,0,18,22,0,0,0,0,0
0,0,0,0,0,0,0,0,27,27,21,17,0,0,0,18,27,27,27,27,27,27,17,0,0,18,22,0,0,0,0,0
0,0,0,0,0,0,0,0,0,0,21,17,0,0,0,18,22,0,0,0,0,21,5,3,3,5,22,0,0,0,0,0
0,0,0,0,0,0,0,0,0,0,21,17,0,0,0,18,22,0,2,29,0,21,17,0,0,18,22,0,0,0,0,0
0,0,0,0,0,0,0,0,0,0,21,17,0,0,0,13,5,0,0,0,0,0,0,0,0,0,0,0,0,0,0,0
0,0,0,0,0,5,4,5,4,5,25,17,0,0,0,0,4,0,0,0,0,0,0,0,0,0,0,0,0,0,0,0
0,0,0,0,0,4,0,0,0,3,19,17,0,0,0,0,4,0,0,0,0,0,0,0,0,0,0,0,0,0,0,0
0,0,0,0,0,5,0,4,0,0,0,0,0,0,0,13,5,0,0,0,0,0,0,0,0,0,0,0,0,0,0,0
0,0,0,0,0,4,0,0,0,3,20,17,0,0,0,18,22,0,0,0,0,0,0,0,0,0,0,0,0,0,0,0
0,0,0,0,0,5,4,5,4,5,27,5,3,3,3,5,22,0,0,0,0,0,0,0,0,0,0,0,0,0,0,0
0,0,0,0,0,0,0,0,0,0,21,17,21,22,0,18,22,0,0,0,0,0,0,0,0,0,0,0,0,0,0,0
0,0,0,0,0,0,0,0,0,0,0,0,21,22,0,0,0,0,0,0,0,0,0,0,0,0,0,0,0,0,0,0
0,0,0,0,0,0,0,0,0,0,0,0,0,0,0,0,0,0,0,0,0,0,0,0,0,0,0,0,0,0,0,0
:endlayer
layer: 11
0,0,0,0,0,0,0,0,0,0,0,0,0,0,0,0,0,0,0,0,0,0,0,0,0,0,0,0,0,0,0,0
0,0,0,0,0,0,0,0,0,0,0,0,0,0,0,0,0,0,0,0,0,0,0,0,0,0,0,0,0,0,0,0
0,0,0,0,0,0,0,0,0,0,0,0,0,0,0,0,0,0,0,0,0,0,0,0,0,0,0,0,0,0,0,0
0,0,0,0,0,0,0,0,0,0,0,0,0,0,0,0,0,0,0,0,0,0,0,0,0,0,0,0,0,0,0,0
0,0,0,0,0,0,0,0,0,0,0,0,0,0,0,0,0,0,0,0,0,0,0,0,0,0,0,0,0,0,0,0
0,0,0,0,0,0,0,0,0,0,0,0,0,0,0,0,0,0,0,0,0,0,0,0,0,0,0,0,0,0,0,0
0,0,0,0,0,0,0,0,0,0,0,0,0,0,0,0,0,0,0,0,0,0,0,0,0,0,0,0,0,0,0,0
0,0,0,0,0,0,0,0,0,0,0,0,0,0,0,0,0,0,0,0,0,0,21,17,2,22,0,0,0,0,0,0
0,0,0,0,0,0,0,0,0,0,0,0,0,0,0,0,0,0,0,0,0,0,21,23,23,22,0,0,0,0,0,0
0,0,0,0,0,0,0,0,0,0,0,0,0,0,0,0,0,0,0,0,0,0,21,17,18,22,0,0,0,0,0,0
0,0,0,0,0,0,0,0,0,0,0,0,0,0,0,0,0,0,0,0,0,0,21,17,18,22,0,0,0,0,0,0
0,0,0,0,0,0,0,0,0,0,0,0,0,0,0,0,0,0,0,0,0,0,21,17,18,22,0,0,0,0,0,0
0,0,0,0,0,0,0,0,25,25,25,21,4,22,25,25,21,4,22,25,25,25,21,17,18,25,25,25,25,25,25,0
0,0,0,0,0,0,0,0,19,5,19,11,0,11,19,19,11,0,11,19,5,3,3,17,18,23,23,23,23,5,17,0
0,0,0,0,0,0,0,0,0,3,0,0,0,0,0,0,0,0,0,0,3,3,3,17,18,22,27,27,27,27,27,0
0,0,0,0,0,0,0,0,20,5,20,20,17,0,20,20,20,20,20,20,5,3,3,17,18,22,0,0,0,0,0,0
0,0,0,0,0,0,0,0,27,27,27,21,17,0,18,22,27,27,27,27,27,27,27,17,18,22,0,0,0,0,0,0
0,0,0,0,0,0,0,0,0,0,0,21,17,0,18,22,0,0,0,0,0,0,21,17,18,22,0,0,0,0,0,0
0,0,0,0,0,0,0,0,0,0,0,21,17,0,18,22,0,0,0,0,0,0,21,23,23,22,0,0,0,0,0,0
0,0,0,0,0,0,0,0,0,0,0,21,17,0,18,22,25,25,2,0,0,0,21,17,18,22,0,0,0,0,0,0
0,0,0,0,0,4,0,4,0,4,0,21,17,0,18,19,5,19,0,0,0,0,0,0,0,0,0,0,0,0,0,0
0,0,0,0,4,5,4,5,4,5,4,21,17,0,0,0,4,0,0,0,0,0,0,0,0,0,0,0,0,0,0,0
0,0,0,0,0,4,0,0,0,3,25,25,17,0,0,0,4,0,0,0,0,0,0,0,0,0,0,0,0,0,0,0
0,0,0,0,4,5,0,4,0,3,23,23,17,0,20,20,5,20,0,0,0,0,0,0,0,0,0,0,0,0,0,0
0,0,0,0,0,4,0,0,0,3,27,21,17,0,18,27,27,27,0,0,0,0,0,0,0,0,0,0,0,0,0,0
0,0,0,0,4,5,4,5,4,5,4,21,5,3,5,22,0,0,0,0,0,0,0,0,0,0,0,0,0,0,0,0
0,0,0,0,0,4,0,4,0,4,0,21,17,0,18,22,0,0,0,0,0,0,0,0,0,0,0,0,0,0,0,0
0,0,0,0,0,0,0,0,0,0,0,0,0,0,0,0,0,0,0,0,0,0,0,0,0,0,0,0,0,0,0,0
0,0,0,0,0,0,0,0,0,0,0,0,0,0,0,0,0,0,0,0,0,0,0,0,0,0,0,0,0,0,0,0
:endlayer
layer: 12
0,0,0,0,0,0,0,0,0,0,0,0,0,0,0,0,0,0,0,0,0,0,0,0,0,0,0,0,0,0,0,0
0,0,0,0,0,0,0,0,0,0,0,0,0,0,0,0,0,0,0,0,0,0,0,0,0,0,0,0,0,0,0,0
0,0,0,0,0,0,0,0,0,0,0,0,0,0,0,0,0,0,0,0,0,0,0,0,0,0,0,0,0,0,0,0
0,0,0,0,0,0,0,0,0,0,0,0,0,0,0,0,0,0,0,0,0,0,0,0,0,0,0,0,0,0,0,0
0,0,0,0,0,0,0,0,0,0,0,0,0,0,0,0,0,0,0,0,0,0,0,0,0,0,0,0,0,0,0,0
0,0,0,0,0,0,0,0,0,0,0,0,0,0,0,0,0,0,0,0,0,0,0,0,0,0,0,0,0,0,0,0
0,0,0,0,0,0,0,0,0,0,0,0,0,0,0,0,0,0,0,0,0,0,0,0,0,0,0,0,0,0,0,0
0,0,0,0,0,0,0,0,0,0,0,0,0,0,0,0,0,0,0,0,0,0,0,21,2,0,0,0,0,0,0,0
0,0,0,0,0,0,0,0,0,0,0,0,0,0,0,0,0,0,0,0,0,0,0,21,22,0,0,0,0,0,0,0
0,0,0,0,0,0,0,0,0,0,0,0,0,0,0,0,0,0,0,0,0,0,0,21,22,0,0,0,0,0,0,0
0,0,0,0,0,0,0,0,0,0,0,0,0,0,0,0,0,0,0,0,0,0,0,21,22,0,0,0,0,0,0,0
0,0,0,0,0,0,0,0,0,0,0,0,0,0,0,0,0,0,0,0,0,0,0,21,22,0,0,0,0,0,0,0
0,0,0,0,0,0,0,0,0,0,0,0,9,0,0,0,0,9,0,0,0,0,0,21,22,0,0,0,0,0,0,0
0,0,0,0,0,0,0,0,25,25,25,25,25,25,25,25,25,25,25,25,25,25,25,21,22,9,9,9,9,9,9,0
0,0,0,0,0,0,0,0,18,5,23,23,23,23,23,23,23,23,23,23,5,3,3,3,22,0,0,0,0,0,0,0
0,0,0,0,0,0,0,0,27,27,27,27,21,24,27,27,27,27,27,27,27,27,27,21,22,0,0,0,0,0,0,0
0,0,0,0,0,0,0,0,0,0,0,0,21,24,22,0,0,0,0,0,0,0,0,21,22,0,0,0,0,0,0,0
0,0,0,0,0,0,0,0,0,0,0,0,21,24,22,0,0,0,0,0,0,0,0,21,22,0,0,0,0,0,0,0
0,0,0,0,0,0,0,0,0,0,0,0,21,24,22,0,0,0,0,0,0,0,0,21,22,0,0,0,0,0,0,0
0,0,0,0,0,0,0,0,0,0,0,0,21,24,22,0,0,0,2,0,0,0,0,21,22,0,0,0,0,0,0,0
0,0,0,0,21,25,25,25,25,25,25,0,21,24,22,25,25,25,0,0,0,0,0,0,0,0,0,0,0,0,0,0
0,0,0,0,21,5,23,23,23,5,22,0,21,24,19,19,24,19,0,0,0,0,0,0,0,0,0,0,0,0,0,0
0,0,0,0,21,24,0,14,0,24,22,0,21,24,20,20,24,20,0,0,0,0,0,0,0,0,0,0,0,0,0,0
0,0,0,0,21,24,12,4,13,24,22,9,21,24,27,27,27,27,0,0,0,0,0,0,0,0,0,0,0,0,0,0
0,0,0,0,21,24,0,10,0,24,22,0,21,24,22,0,0,0,0,0,0,0,0,0,0,0,0,0,0,0,0,0
0,0,0,0,21,5,23,23,23,5,22,0,21,5,22,0,0,0,0,0,0,0,0,0,0,0,0,0,0,0,0,0
0,0,0,0,27,27,27,27,27,27,22,0,21,19,22,0,0,0,0,0,0,0,0,0,0,0,0,0,0,0,0,0
0,0,0,0,0,0,0,0,0,0,0,0,0,0,0,0,0,0,0,0,0,0,0,0,0,0,0,0,0,0,0,0
0,0,0,0,0,0,0,0,0,0,0,0,0,0,0,0,0,0,0,0,0,0,0,0,0,0,0,0,0,0,0,0
:endlayer
layer: 13
0,0,0,0,0,0,0,0,0,0,0,0,0,0,0,0,0,0,0,0,0,0,0,0,0,0,0,0,0,0,0,0
0,0,0,0,0,0,0,0,0,0,0,0,0,0,0,0,0,0,0,0,0,0,0,0,0,0,0,0,0,0,0,0
0,0,0,0,0,0,0,0,0,0,0,0,0,0,0,0,0,0,0,0,0,0,0,0,0,0,0,0,0,0,0,0
0,0,0,0,0,0,0,0,0,0,0,0,0,0,0,0,0,0,0,0,0,0,0,0,0,0,0,0,0,0,0,0
0,0,0,0,0,0,0,0,0,0,0,0,0,0,0,0,0,0,0,0,0,0,0,0,0,0,0,0,0,0,0,0
0,0,0,0,0,0,0,0,0,0,0,0,0,0,0,0,0,0,0,0,0,0,0,0,0,0,0,0,0,0,0,0
0,0,0,0,0,0,0,0,0,0,0,0,0,0,0,0,0,0,0,0,0,0,0,0,0,0,0,0,0,0,0,0
0,0,0,0,0,0,0,0,0,0,0,0,0,0,0,0,0,0,0,0,0,0,0,0,2,0,0,0,0,0,0,0
0,0,0,0,0,0,0,0,0,0,0,0,0,0,0,0,0,0,0,0,0,0,0,0,0,0,0,0,0,0,0,0
0,0,0,0,0,0,0,0,0,0,0,0,0,0,0,0,0,0,0,0,0,0,0,0,0,0,0,0,0,0,0,0
0,0,0,0,0,0,0,0,0,0,0,0,0,0,0,0,0,0,0,0,0,0,0,0,0,0,0,0,0,0,0,0
0,0,0,0,0,0,0,0,0,0,0,0,0,0,0,0,0,0,0,0,0,0,0,0,0,0,0,0,0,0,0,0
0,0,0,0,0,0,0,0,0,0,0,0,0,0,0,0,0,0,0,0,0,0,0,0,0,0,0,0,0,0,0,0
0,0,0,0,0,0,0,0,0,0,0,0,0,0,0,0,0,0,0,0,0,0,0,0,0,0,0,0,0,0,0,0
0,0,0,0,0,0,0,0,9,9,9,9,9,9,9,9,9,9,9,9,9,9,9,9,0,0,0,0,0,0,0,0
0,0,0,0,0,0,0,0,0,0,0,0,0,9,0,0,0,0,0,0,0,0,0,0,0,0,0,0,0,0,0,0
0,0,0,0,0,0,0,0,0,0,0,0,0,9,0,0,0,0,0,0,0,0,0,0,0,0,0,0,0,0,0,0
0,0,0,0,0,0,0,0,0,0,0,0,0,9,0,0,0,0,0,0,0,0,0,0,0,0,0,0,0,0,0,0
0,0,0,0,0,0,0,0,0,0,0,0,0,9,0,0,0,0,0,0,0,0,0,0,0,0,0,0,0,0,0,0
0,0,0,0,0,0,0,0,0,0,0,0,0,9,0,0,0,0,2,0,0,0,0,0,0,0,0,0,0,0,0,0
0,0,0,0,0,0,0,0,0,0,0,0,0,9,0,0,0,0,0,0,0,0,0,0,0,0,0,0,0,0,0,0
0,0,0,0,0,21,25,25,25,25,0,0,0,21,25,25,25,25,0,0,0,0,0,0,0,0,0,0,0,0,0,0
0,0,0,0,0,21,17,19,19,22,0,0,0,21,27,27,27,27,0,0,0,0,0,0,0,0,0,0,0,0,0,0
0,0,0,0,0,21,17,4,18,22,0,0,0,9,0,0,0,0,0,0,0,0,0,0,0,0,0,0,0,0,0,0
0,0,0,0,0,21,20,20,18,22,0,0,0,9,0,0,0,0,0,0,0,0,0,0,0,0,0,0,0,0,0,0
0,0,0,0,0,27,27,27,27,22,0,0,0,9,0,0,0,0,0,0,0,0,0,0,0,0,0,0,0,0,0,0
0,0,0,0,0,0,0,0,0,0,0,0,0,9,0,0,0,0,0,0,0,0,0,0,0,0,0,0,0,0,0,0
0,0,0,0,0,0,0,0,0,0,0,0,0,0,0,0,0,0,0,0,0,0,0,0,0,0,0,0,0,0,0,0
0,0,0,0,0,0,0,0,0,0,0,0,0,0,0,0,0,0,0,0,0,0,0,0,0,0,0,0,0,0,0,0
:endlayer
layer: 14
0,0,0,0,0,0,0,0,0,0,0,0,0,0,0,0,0,0,0,0,0,0,0,0,0,0,0,0,0,0,0,0
0,0,0,0,0,0,0,0,0,0,0,0,0,0,0,0,0,0,0,0,0,0,0,0,0,0,0,0,0,0,0,0
0,0,0,0,0,0,0,0,0,0,0,0,0,0,0,0,0,0,0,0,0,0,0,0,0,0,0,0,0,0,0,0
0,0,0,0,0,0,0,0,0,0,0,0,0,0,0,0,0,0,0,0,0,0,0,0,0,0,0,0,0,0,0,0
0,0,0,0,0,0,0,0,0,0,0,0,0,0,0,0,0,0,0,0,0,0,0,0,0,0,0,0,0,0,0,0
0,0,0,0,0,0,0,0,0,0,0,0,0,0,0,0,0,0,0,0,0,0,0,0,0,0,0,0,0,0,0,0
0,0,0,0,0,0,0,0,0,0,0,0,0,0,0,0,0,0,0,0,0,0,0,0,0,0,0,0,0,0,0,0
0,0,0,0,0,0,0,0,0,0,0,0,0,0,0,0,0,0,0,0,0,0,0,0,2,0,0,0,0,0,0,0
0,0,0,0,0,0,0,0,0,0,0,0,0,0,0,0,0,0,0,0,0,0,0,0,0,0,0,0,0,0,0,0
0,0,0,0,0,0,0,0,0,0,0,0,0,0,0,0,0,0,0,0,0,0,0,0,0,0,0,0,0,0,0,0
0,0,0,0,0,0,0,0,0,0,0,0,0,0,0,0,0,0,0,0,0,0,0,0,0,0,0,0,0,0,0,0
0,0,0,0,0,0,0,0,0,0,0,0,0,0,0,0,0,0,0,0,0,0,0,0,0,0,0,0,0,0,0,0
0,0,0,0,0,0,0,0,0,0,0,0,0,0,0,0,0,0,0,0,0,0,0,0,0,0,0,0,0,0,0,0
0,0,0,0,0,0,0,0,0,0,0,0,0,0,0,0,0,0,0,0,0,0,0,0,0,0,0,0,0,0,0,0
0,0,0,0,0,0,0,0,0,0,0,0,0,0,0,0,0,0,0,0,0,0,0,0,0,0,0,0,0,0,0,0
0,0,0,0,0,0,0,0,0,0,0,0,0,0,0,0,0,0,0,0,0,0,0,0,0,0,0,0,0,0,0,0
0,0,0,0,0,0,0,0,0,0,0,0,0,0,0,0,0,0,0,0,0,0,0,0,0,0,0,0,0,0,0,0
0,0,0,0,0,0,0,0,0,0,0,0,0,0,0,0,0,0,0,0,0,0,0,0,0,0,0,0,0,0,0,0
0,0,0,0,0,0,0,0,0,0,0,0,0,0,0,0,0,0,0,0,0,0,0,0,0,0,0,0,0,0,0,0
0,0,0,0,0,0,0,0,0,0,0,0,0,0,0,0,0,0,2,0,0,0,0,0,0,0,0,0,0,0,0,0
0,0,0,0,0,0,0,0,0,0,0,0,0,0,0,0,0,0,0,0,0,0,0,0,0,0,0,0,0,0,0,0
0,0,0,0,0,0,0,0,0,0,0,0,0,0,0,0,0,0,0,0,0,0,0,0,0,0,0,0,0,0,0,0
0,0,0,0,0,0,25,25,22,0,0,0,0,0,0,0,0,0,0,0,0,0,0,0,0,0,0,0,0,0,0,0
0,0,0,0,0,0,21,3,22,0,0,0,0,0,0,0,0,0,0,0,0,0,0,0,0,0,0,0,0,0,0,0
0,0,0,0,0,0,21,27,27,0,0,0,0,0,0,0,0,0,0,0,0,0,0,0,0,0,0,0,0,0,0,0
0,0,0,0,0,0,0,0,0,0,0,0,0,0,0,0,0,0,0,0,0,0,0,0,0,0,0,0,0,0,0,0
0,0,0,0,0,0,0,0,0,0,0,0,0,0,0,0,0,0,0,0,0,0,0,0,0,0,0,0,0,0,0,0
0,0,0,0,0,0,0,0,0,0,0,0,0,0,0,0,0,0,0,0,0,0,0,0,0,0,0,0,0,0,0,0
0,0,0,0,0,0,0,0,0,0,0,0,0,0,0,0,0,0,0,0,0,0,0,0,0,0,0,0,0,0,0,0
:endlayer
layer: 15
0,0,0,0,0,0,0,0,0,0,0,0,0,0,0,0,0,0,0,0,0,0,0,0,0,0,0,0,0,0,0,0
0,0,0,0,0,0,0,0,0,0,0,0,0,0,0,0,0,0,0,0,0,0,0,0,0,0,0,0,0,0,0,0
0,0,0,0,0,0,0,0,0,0,0,0,0,0,0,0,0,0,0,0,0,0,0,0,0,0,0,0,0,0,0,0
0,0,0,0,0,0,0,0,0,0,0,0,0,0,0,0,0,0,0,0,0,0,0,0,0,0,0,0,0,0,0,0
0,0,0,0,0,0,0,0,0,0,0,0,0,0,0,0,0,0,0,0,0,0,0,0,0,0,0,0,0,0,0,0
0,0,0,0,0,0,0,0,0,0,0,0,0,0,0,0,0,0,0,0,0,0,0,0,0,0,0,0,0,0,0,0
0,0,0,0,0,0,0,0,0,0,0,0,0,0,0,0,0,0,0,0,0,0,0,0,0,0,0,0,0,0,0,0
0,0,0,0,0,0,0,0,0,0,0,0,0,0,0,0,0,0,0,0,0,0,0,0,30,0,0,0,0,0,0,0
0,0,0,0,0,0,0,0,0,0,0,0,0,0,0,0,0,0,0,0,0,0,0,0,0,0,0,0,0,0,0,0
0,0,0,0,0,0,0,0,0,0,0,0,0,0,0,0,0,0,0,0,0,0,0,0,0,0,0,0,0,0,0,0
0,0,0,0,0,0,0,0,0,0,0,0,0,0,0,0,0,0,0,0,0,0,0,0,0,0,0,0,0,0,0,0
0,0,0,0,0,0,0,0,0,0,0,0,0,0,0,0,0,0,0,0,0,0,0,0,0,0,0,0,0,0,0,0
0,0,0,0,0,0,0,0,0,0,0,0,0,0,0,0,0,0,0,0,0,0,0,0,0,0,0,0,0,0,0,0
0,0,0,0,0,0,0,0,0,0,0,0,0,0,0,0,0,0,0,0,0,0,0,0,0,0,0,0,0,0,0,0
0,0,0,0,0,0,0,0,0,0,0,0,0,0,0,0,0,0,0,0,0,0,0,0,0,0,0,0,0,0,0,0
0,0,0,0,0,0,0,0,0,0,0,0,0,0,0,0,0,0,0,0,0,0,0,0,0,0,0,0,0,0,0,0
0,0,0,0,0,0,0,0,0,0,0,0,0,0,0,0,0,0,0,0,0,0,0,0,0,0,0,0,0,0,0,0
0,0,0,0,0,0,0,0,0,0,0,0,0,0,0,0,0,0,0,0,0,0,0,0,0,0,0,0,0,0,0,0
0,0,0,0,0,0,0,0,0,0,0,0,0,0,0,0,0,0,0,0,0,0,0,0,0,0,0,0,0,0,0,0
0,0,0,0,0,0,0,0,0,0,0,0,0,0,0,0,0,0,30,0,0,0,0,0,0,0,0,0,0,0,0,0
0,0,0,0,0,0,0,0,0,0,0,0,0,0,0,0,0,0,0,0,0,0,0,0,0,0,0,0,0,0,0,0
0,0,0,0,0,0,0,0,0,0,0,0,0,0,0,0,0,0,0,0,0,0,0,0,0,0,0,0,0,0,0,0
0,0,0,0,0,0,0,0,0,0,0,0,0,0,0,0,0,0,0,0,0,0,0,0,0,0,0,0,0,0,0,0
0,0,0,0,0,0,0,4,0,0,0,0,0,0,0,0,0,0,0,0,0,0,0,0,0,0,0,0,0,0,0,0
0,0,0,0,0,0,0,0,0,0,0,0,0,0,0,0,0,0,0,0,0,0,0,0,0,0,0,0,0,0,0,0
0,0,0,0,0,0,0,0,0,0,0,0,0,0,0,0,0,0,0,0,0,0,0,0,0,0,0,0,0,0,0,0
0,0,0,0,0,0,0,0,0,0,0,0,0,0,0,0,0,0,0,0,0,0,0,0,0,0,0,0,0,0,0,0
0,0,0,0,0,0,0,0,0,0,0,0,0,0,0,0,0,0,0,0,0,0,0,0,0,0,0,0,0,0,0,0
0,0,0,0,0,0,0,0,0,0,0,0,0,0,0,0,0,0,0,0,0,0,0,0,0,0,0,0,0,0,0,0
:endlayer
layer: 16
0,0,0,0,0,0,0,0,0,0,0,0,0,0,0,0,0,0,0,0,0,0,0,0,0,0,0,0,0,0,0,0
0,0,0,0,0,0,0,0,0,0,0,0,0,0,0,0,0,0,0,0,0,0,0,0,0,0,0,0,0,0,0,0
0,0,0,0,0,0,0,0,0,0,0,0,0,0,0,0,0,0,0,0,0,0,0,0,0,0,0,0,0,0,0,0
0,0,0,0,0,0,0,0,0,0,0,0,0,0,0,0,0,0,0,0,0,0,0,0,0,0,0,0,0,0,0,0
0,0,0,0,0,0,0,0,0,0,0,0,0,0,0,0,0,0,0,0,0,0,0,0,0,0,0,0,0,0,0,0
0,0,0,0,0,0,0,0,0,0,0,0,0,0,0,0,0,0,0,0,0,0,0,0,0,0,0,0,0,0,0,0
0,0,0,0,0,0,0,0,0,0,0,0,0,0,0,0,0,0,0,0,0,0,0,0,0,0,0,0,0,0,0,0
0,0,0,0,0,0,0,0,0,0,0,0,0,0,0,0,0,0,0,0,0,0,0,0,7,0,0,0,0,0,0,0
0,0,0,0,0,0,0,0,0,0,0,0,0,0,0,0,0,0,0,0,0,0,0,0,0,0,0,0,0,0,0,0
0,0,0,0,0,0,0,0,0,0,0,0,0,0,0,0,0,0,0,0,0,0,0,0,0,0,0,0,0,0,0,0
0,0,0,0,0,0,0,0,0,0,0,0,0,0,0,0,0,0,0,0,0,0,0,0,0,0,0,0,0,0,0,0
0,0,0,0,0,0,0,0,0,0,0,0,0,0,0,0,0,0,0,0,0,0,0,0,0,0,0,0,0,0,0,0
0,0,0,0,0,0,0,0,0,0,0,0,0,0,0,0,0,0,0,0,0,0,0,0,0,0,0,0,0,0,0,0
0,0,0,0,0,0,0,0,0,0,0,0,0,0,0,0,0,0,0,0,0,0,0,0,0,0,0,0,0,0,0,0
0,0,0,0,0,0,0,0,0,0,0,0,0,0,0,0,0,0,0,0,0,0,0,0,0,0,0,0,0,0,0,0
0,0,0,0,0,0,0,0,0,0,0,0,0,0,0,0,0,0,0,0,0,0,0,0,0,0,0,0,0,0,0,0
0,0,0,0,0,0,0,0,0,0,0,0,0,0,0,0,0,0,0,0,0,0,0,0,0,0,0,0,0,0,0,0
0,0,0,0,0,0,0,0,0,0,0,0,0,0,0,0,0,0,0,0,0,0,0,0,0,0,0,0,0,0,0,0
0,0,0,0,0,0,0,0,0,0,0,0,0,0,0,0,0,0,0,0,0,0,0,0,0,0,0,0,0,0,0,0
0,0,0,0,0,0,0,0,0,0,0,0,0,0,0,0,0,0,7,0,0,0,0,0,0,0,0,0,0,0,0,0
0,0,0,0,0,0,0,0,0,0,0,0,0,0,0,0,0,0,0,0,0,0,0,0,0,0,0,0,0,0,0,0
0,0,0,0,0,0,0,0,0,0,0,0,0,0,0,0,0,0,0,0,0,0,0,0,0,0,0,0,0,0,0,0
0,0,0,0,0,0,0,0,0,0,0,0,0,0,0,0,0,0,0,0,0,0,0,0,0,0,0,0,0,0,0,0
0,0,0,0,0,0,0,8,0,0,0,0,0,0,0,0,0,0,0,0,0,0,0,0,0,0,0,0,0,0,0,0
0,0,0,0,0,0,0,0,0,0,0,0,0,0,0,0,0,0,0,0,0,0,0,0,0,0,0,0,0,0,0,0
0,0,0,0,0,0,0,0,0,0,0,0,0,0,0,0,0,0,0,0,0,0,0,0,0,0,0,0,0,0,0,0
0,0,0,0,0,0,0,0,0,0,0,0,0,0,0,0,0,0,0,0,0,0,0,0,0,0,0,0,0,0,0,0
0,0,0,0,0,0,0,0,0,0,0,0,0,0,0,0,0,0,0,0,0,0,0,0,0,0,0,0,0,0,0,0
0,0,0,0,0,0,0,0,0,0,0,0,0,0,0,0,0,0,0,0,0,0,0,0,0,0,0,0,0,0,0,0
:endlayer

#### RULES ####
rule:
plugin=vanillaBlocks
number=1
data:
JSON:{blockState:{blockName:"minecraft:grass",properties:{snowy:"false"}}}
:enddata
:endrule

rule:
plugin=vanillaBlocks
number=2
data:
JSON:{blockState:{blockName:"minecraft:cobblestone"}}
:enddata
:endrule

rule:
plugin=vanillaBlocks
number=3
data:
JSON:{blockState:{blockName:"biomesoplenty:planks_0",properties:{variant:"mangrove"}}}
:enddata
:endrule

rule:
plugin=vanillaBlocks
number=4
data:
JSON:{blockState:{blockName:"biomesoplenty:mangrove_fence",properties:{east:"false",south:"false",north:"false",west:"false"}}}
:enddata
:endrule

rule:
plugin=vanillaBlocks
number=5
data:
JSON:{blockState:{blockName:"biomesoplenty:log_1",properties:{variant:"mangrove",axis:"y"}}}
:enddata
:endrule

rule:
plugin=vanillaBlocks
number=6
data:
JSON:{blockState:{blockName:"ancientwarfarestructure:fire_pit",properties:{lit:"false",variant:"log"}}}
:enddata
:endrule

rule:
plugin=vanillaBlocks
number=7
data:
JSON:{blockState:{blockName:"minecraft:stone_slab",properties:{half:"bottom",variant:"cobblestone"}}}
:enddata
:endrule

rule:
plugin=vanillaBlocks
number=8
data:
JSON:{blockState:{blockName:"minecraft:torch",properties:{facing:"up"}}}
:enddata
:endrule

rule:
plugin=vanillaBlocks
number=9
data:
JSON:{blockState:{blockName:"biomesoplenty:wood_slab_0",properties:{half:"bottom",variant:"mangrove"}}}
:enddata
:endrule

rule:
plugin=vanillaBlocks
number=10
data:
JSON:{blockState:{blockName:"minecraft:torch",properties:{facing:"north"}}}
:enddata
:endrule

rule:
plugin=vanillaBlocks
number=11
data:
JSON:{blockState:{blockName:"biomesoplenty:wood_slab_0",properties:{half:"top",variant:"mangrove"}}}
:enddata
:endrule

rule:
plugin=vanillaBlocks
number=12
data:
JSON:{blockState:{blockName:"minecraft:torch",properties:{facing:"east"}}}
:enddata
:endrule

rule:
plugin=vanillaBlocks
number=13
data:
JSON:{blockState:{blockName:"minecraft:torch",properties:{facing:"west"}}}
:enddata
:endrule

rule:
plugin=vanillaBlocks
number=14
data:
JSON:{blockState:{blockName:"minecraft:torch",properties:{facing:"south"}}}
:enddata
:endrule

rule:
plugin=vanillaBlocks
number=15
data:
JSON:{blockState:{blockName:"minecraft:stone_stairs",properties:{half:"top",shape:"straight",facing:"west"}}}
:enddata
:endrule

rule:
plugin=vanillaBlocks
number=16
data:
JSON:{blockState:{blockName:"minecraft:stone_stairs",properties:{half:"top",shape:"straight",facing:"east"}}}
:enddata
:endrule

rule:
plugin=vanillaBlocks
number=17
data:
JSON:{blockState:{blockName:"biomesoplenty:mangrove_stairs",properties:{half:"top",shape:"straight",facing:"west"}}}
:enddata
:endrule

rule:
plugin=vanillaBlocks
number=18
data:
JSON:{blockState:{blockName:"biomesoplenty:mangrove_stairs",properties:{half:"top",shape:"straight",facing:"east"}}}
:enddata
:endrule

rule:
plugin=vanillaBlocks
number=19
data:
JSON:{blockState:{blockName:"biomesoplenty:mangrove_stairs",properties:{half:"top",shape:"straight",facing:"north"}}}
:enddata
:endrule

rule:
plugin=vanillaBlocks
number=20
data:
JSON:{blockState:{blockName:"biomesoplenty:mangrove_stairs",properties:{half:"top",shape:"straight",facing:"south"}}}
:enddata
:endrule

rule:
plugin=vanillaBlocks
number=21
data:
JSON:{blockState:{blockName:"biomesoplenty:mangrove_stairs",properties:{half:"bottom",shape:"straight",facing:"east"}}}
:enddata
:endrule

rule:
plugin=vanillaBlocks
number=22
data:
JSON:{blockState:{blockName:"biomesoplenty:mangrove_stairs",properties:{half:"bottom",shape:"straight",facing:"west"}}}
:enddata
:endrule

rule:
plugin=vanillaBlocks
number=23
data:
JSON:{blockState:{blockName:"biomesoplenty:log_1",properties:{variant:"mangrove",axis:"x"}}}
:enddata
:endrule

rule:
plugin=vanillaBlocks
number=24
data:
JSON:{blockState:{blockName:"biomesoplenty:log_1",properties:{variant:"mangrove",axis:"z"}}}
:enddata
:endrule

rule:
plugin=vanillaBlocks
number=25
data:
JSON:{blockState:{blockName:"biomesoplenty:mangrove_stairs",properties:{half:"bottom",shape:"straight",facing:"south"}}}
:enddata
:endrule

rule:
plugin=vanillaBlocks
number=26
data:
JSON:{blockState:{blockName:"minecraft:stone_stairs",properties:{half:"top",shape:"straight",facing:"north"}}}
:enddata
:endrule

rule:
plugin=vanillaBlocks
number=27
data:
JSON:{blockState:{blockName:"biomesoplenty:mangrove_stairs",properties:{half:"bottom",shape:"straight",facing:"north"}}}
:enddata
:endrule

rule:
plugin=vanillaBlocks
number=28
data:
JSON:{blockState:{blockName:"minecraft:stone_stairs",properties:{half:"bottom",shape:"straight",facing:"east"}}}
:enddata
:endrule

rule:
plugin=vanillaBlocks
number=29
data:
JSON:{blockState:{blockName:"minecraft:stone_stairs",properties:{half:"bottom",shape:"straight",facing:"west"}}}
:enddata
:endrule

rule:
plugin=vanillaBlocks
number=30
data:
JSON:{blockState:{blockName:"minecraft:cobblestone_wall",properties:{east:"false",south:"false",north:"false",variant:"cobblestone",west:"false",up:"false"}}}
:enddata
:endrule

#### ENTITIES ####
