# Ancient Warfare Structure Template File
# Auto-generated structure template file. created on: 4/20/2021 at: 20:20:24
# Lines beginning with # denote comments

header:
version=2.11
name=SurvivalBuild_Moat_type1_X_sandstone
mods=
size=16,6,16
offset=0,5,15
:endheader

#### VALIDATION ####
validation:
type=ground
structureAuthor=TheOddlySeagull
survival=true
worldGenEnabled=false
unique=false
preserveBlocks=false
preventNaturalHostileSpawns=false
selectionWeight=1
clusterValue=1
minDuplicateDistance=1
dimensionWhiteList=true
dimensionList=
biomeGroupList=
biomeWhiteList=true
biomeList=
leveling=0
fill=0
border=0
blockSwap=false
territoryName=
biomeReplacement=minecraft:
minGenerationHeight=0
maxGenerationHeight=255
:endvalidation

#### LAYERS ####
layer: 0
1,1,1,1,2,2,2,2,2,2,2,2,1,1,1,1
1,1,1,1,2,2,2,2,2,2,2,2,1,1,1,1
1,1,1,1,2,2,2,2,2,2,2,2,1,1,1,1
1,1,1,1,2,2,2,2,2,2,2,2,1,1,1,1
2,2,2,2,2,2,2,2,2,2,2,2,2,2,2,2
2,2,2,2,2,2,2,2,2,2,2,2,2,2,2,2
2,2,2,2,2,2,2,2,2,2,2,2,2,2,2,2
2,2,2,2,2,2,2,2,2,2,2,2,2,2,2,2
2,2,2,2,2,2,2,2,2,2,2,2,2,2,2,2
2,2,2,2,2,2,2,2,2,2,2,2,2,2,2,2
2,2,2,2,2,2,2,2,2,2,2,2,2,2,2,2
2,2,2,2,2,2,2,2,2,2,2,2,2,2,2,2
1,1,1,1,2,2,2,2,2,2,2,2,1,1,1,1
1,1,1,1,2,2,2,2,2,2,2,2,1,1,1,1
1,1,1,1,2,2,2,2,2,2,2,2,1,1,1,1
1,1,1,1,2,2,2,2,2,2,2,2,1,1,1,1
:endlayer
layer: 1
1,1,1,1,2,2,0,0,0,0,2,2,1,1,1,1
1,1,1,1,2,0,0,0,0,0,0,2,1,1,1,1
1,1,1,1,2,0,0,0,0,0,0,2,1,1,1,1
1,1,1,1,2,0,0,0,0,0,0,2,1,1,1,1
2,2,2,2,2,0,0,0,0,0,0,2,2,2,2,2
2,0,0,0,0,0,0,0,0,0,0,0,0,0,0,2
0,0,0,0,0,0,0,0,0,0,0,0,0,0,0,0
0,0,0,0,0,0,0,0,0,0,0,0,0,0,0,0
0,0,0,0,0,0,0,0,0,0,0,0,0,0,0,0
0,0,0,0,0,0,0,0,0,0,0,0,0,0,0,0
2,0,0,0,0,0,0,0,0,0,0,0,0,0,0,2
2,2,2,2,2,0,0,0,0,0,0,2,2,2,2,2
1,1,1,1,2,0,0,0,0,0,0,2,1,1,1,1
1,1,1,1,2,0,0,0,0,0,0,2,1,1,1,1
1,1,1,1,2,0,0,0,0,0,0,2,1,1,1,1
1,1,1,1,2,2,0,0,0,0,2,2,1,1,1,1
:endlayer
layer: 2
1,1,1,1,2,2,0,0,0,0,2,2,1,1,1,1
1,1,1,1,2,0,0,0,0,0,0,2,1,1,1,1
1,1,1,1,2,0,0,0,0,0,0,2,1,1,1,1
1,1,1,1,2,0,0,0,0,0,0,2,1,1,1,1
2,2,2,2,2,0,0,0,0,0,0,2,2,2,2,2
2,0,0,0,0,0,0,0,0,0,0,0,0,0,0,2
0,0,0,0,0,0,0,0,0,0,0,0,0,0,0,0
0,0,0,0,0,0,0,0,0,0,0,0,0,0,0,0
0,0,0,0,0,0,0,0,0,0,0,0,0,0,0,0
0,0,0,0,0,0,0,0,0,0,0,0,0,0,0,0
2,0,0,0,0,0,0,0,0,0,0,0,0,0,0,2
2,2,2,2,2,0,0,0,0,0,0,2,2,2,2,2
1,1,1,1,2,0,0,0,0,0,0,2,1,1,1,1
1,1,1,1,2,0,0,0,0,0,0,2,1,1,1,1
1,1,1,1,2,0,0,0,0,0,0,2,1,1,1,1
1,1,1,1,2,2,0,0,0,0,2,2,1,1,1,1
:endlayer
layer: 3
1,1,1,1,2,2,0,0,0,0,2,2,1,1,1,1
1,1,1,1,2,0,0,0,0,0,0,2,1,1,1,1
1,1,1,1,2,0,0,0,0,0,0,2,1,1,1,1
1,1,1,1,2,0,0,0,0,0,0,2,1,1,1,1
2,2,2,2,2,0,0,0,0,0,0,2,2,2,2,2
2,0,0,0,0,0,0,0,0,0,0,0,0,0,0,2
0,0,0,0,0,0,0,0,0,0,0,0,0,0,0,0
0,0,0,0,0,0,0,0,0,0,0,0,0,0,0,0
0,0,0,0,0,0,0,0,0,0,0,0,0,0,0,0
0,0,0,0,0,0,0,0,0,0,0,0,0,0,0,0
2,0,0,0,0,0,0,0,0,0,0,0,0,0,0,2
2,2,2,2,2,0,0,0,0,0,0,2,2,2,2,2
1,1,1,1,2,0,0,0,0,0,0,2,1,1,1,1
1,1,1,1,2,0,0,0,0,0,0,2,1,1,1,1
1,1,1,1,2,0,0,0,0,0,0,2,1,1,1,1
1,1,1,1,2,2,0,0,0,0,2,2,1,1,1,1
:endlayer
layer: 4
1,1,1,1,2,2,0,0,0,0,2,2,1,1,1,1
1,1,1,1,2,0,0,0,0,0,0,2,1,1,1,1
1,1,1,1,2,0,0,0,0,0,0,2,1,1,1,1
1,1,1,1,2,0,0,0,0,0,0,2,1,1,1,1
2,2,2,2,2,0,0,0,0,0,0,2,2,2,2,2
2,0,0,0,0,0,0,0,0,0,0,0,0,0,0,2
0,0,0,0,0,0,0,0,0,0,0,0,0,0,0,0
0,0,0,0,0,0,0,0,0,0,0,0,0,0,0,0
0,0,0,0,0,0,0,0,0,0,0,0,0,0,0,0
0,0,0,0,0,0,0,0,0,0,0,0,0,0,0,0
2,0,0,0,0,0,0,0,0,0,0,0,0,0,0,2
2,2,2,2,2,0,0,0,0,0,0,2,2,2,2,2
1,1,1,1,2,0,0,0,0,0,0,2,1,1,1,1
1,1,1,1,2,0,0,0,0,0,0,2,1,1,1,1
1,1,1,1,2,0,0,0,0,0,0,2,1,1,1,1
1,1,1,1,2,2,0,0,0,0,2,2,1,1,1,1
:endlayer
layer: 5
0,0,0,0,2,3,0,0,0,0,4,2,0,0,0,0
0,0,0,0,5,0,0,0,0,0,0,5,0,0,0,0
0,0,0,0,5,0,0,0,0,0,0,5,0,0,0,0
0,0,0,0,2,0,0,0,0,0,0,2,0,0,0,0
2,5,5,2,2,0,0,0,0,0,0,2,2,5,5,2
6,0,0,0,0,0,0,0,0,0,0,0,0,0,0,6
0,0,0,0,0,0,0,0,0,0,0,0,0,0,0,0
0,0,0,0,0,0,0,0,0,0,0,0,0,0,0,0
0,0,0,0,0,0,0,0,0,0,0,0,0,0,0,0
0,0,0,0,0,0,0,0,0,0,0,0,0,0,0,0
7,0,0,0,0,0,0,0,0,0,0,0,0,0,0,7
2,5,5,2,2,0,0,0,0,0,0,2,2,5,5,2
0,0,0,0,2,0,0,0,0,0,0,2,0,0,0,0
0,0,0,0,5,0,0,0,0,0,0,5,0,0,0,0
0,0,0,0,5,0,0,0,0,0,0,5,0,0,0,0
0,0,0,0,2,3,0,0,0,0,4,2,0,0,0,0
:endlayer

#### RULES ####
rule:
plugin=vanillaBlocks
number=1
data:
JSON:{blockState:{blockName:"minecraft:sand",properties:{variant:"sand"}}}
:enddata
:endrule

rule:
plugin=vanillaBlocks
number=2
data:
JSON:{blockState:{blockName:"minecraft:sandstone",properties:{type:"sandstone"}}}
:enddata
:endrule

rule:
plugin=vanillaBlocks
number=3
data:
JSON:{blockState:{blockName:"minecraft:sandstone_stairs",properties:{half:"bottom",shape:"straight",facing:"west"}}}
:enddata
:endrule

rule:
plugin=vanillaBlocks
number=4
data:
JSON:{blockState:{blockName:"minecraft:sandstone_stairs",properties:{half:"bottom",shape:"straight",facing:"east"}}}
:enddata
:endrule

rule:
plugin=vanillaBlocks
number=5
data:
JSON:{blockState:{blockName:"minecraft:stone_slab",properties:{half:"bottom",variant:"sandstone"}}}
:enddata
:endrule

rule:
plugin=vanillaBlocks
number=6
data:
JSON:{blockState:{blockName:"minecraft:sandstone_stairs",properties:{half:"bottom",shape:"straight",facing:"north"}}}
:enddata
:endrule

rule:
plugin=vanillaBlocks
number=7
data:
JSON:{blockState:{blockName:"minecraft:sandstone_stairs",properties:{half:"bottom",shape:"straight",facing:"south"}}}
:enddata
:endrule

#### ENTITIES ####
