# Ancient Warfare Structure Template File
# Auto-generated structure template file. created on: 4/20/2021 at: 20:24:31
# Lines beginning with # denote comments

header:
version=2.11
name=SurvivalBuild_Moat_type1_angle_bricks
mods=
size=16,6,16
offset=15,5,15
:endheader

#### VALIDATION ####
validation:
type=ground
structureAuthor=TheOddlySeagull
survival=true
worldGenEnabled=false
unique=false
preserveBlocks=false
preventNaturalHostileSpawns=false
selectionWeight=1
clusterValue=1
minDuplicateDistance=1
dimensionWhiteList=true
dimensionList=
biomeGroupList=
biomeWhiteList=true
biomeList=
leveling=0
fill=0
border=0
blockSwap=false
territoryName=
biomeReplacement=minecraft:
minGenerationHeight=0
maxGenerationHeight=255
:endvalidation

#### LAYERS ####
layer: 0
1,1,1,1,2,2,2,2,2,2,2,2,1,1,1,1
1,1,1,1,2,2,2,2,2,2,2,2,1,1,1,1
1,1,1,1,2,2,2,2,2,2,2,2,1,1,1,1
1,1,1,1,2,2,2,2,2,2,2,2,1,1,1,1
2,2,2,2,2,2,2,2,2,2,2,2,1,1,1,1
2,2,2,2,2,2,2,2,2,2,2,2,1,1,1,1
2,2,2,2,2,2,2,2,2,2,2,2,1,1,1,1
2,2,2,2,2,2,2,2,2,2,2,2,1,1,1,1
2,2,2,2,2,2,2,2,2,2,2,2,1,1,1,1
2,2,2,2,2,2,2,2,2,2,2,2,1,1,1,1
2,2,2,2,2,2,2,2,2,2,2,2,1,1,1,1
2,2,2,2,2,2,2,2,2,2,2,2,1,1,1,1
1,1,1,1,1,1,1,1,1,1,1,1,1,1,1,1
1,1,1,1,1,1,1,1,1,1,1,1,1,1,1,1
1,1,1,1,1,1,1,1,1,1,1,1,1,1,1,1
1,1,1,1,1,1,1,1,1,1,1,1,1,1,1,1
:endlayer
layer: 1
1,1,1,1,2,2,0,0,0,0,2,2,1,1,1,1
1,1,1,1,2,0,0,0,0,0,0,2,1,1,1,1
1,1,1,1,2,0,0,0,0,0,0,2,1,1,1,1
1,1,1,1,2,0,0,0,0,0,0,2,1,1,1,1
2,2,2,2,2,0,0,0,0,0,0,2,1,1,1,1
2,0,0,0,0,0,0,0,0,0,0,2,1,1,1,1
0,0,0,0,0,0,0,0,0,0,0,2,1,1,1,1
0,0,0,0,0,0,0,0,0,0,2,2,1,1,1,1
0,0,0,0,0,0,0,0,0,0,2,2,1,1,1,1
0,0,0,0,0,0,0,0,0,0,0,2,1,1,1,1
2,0,0,0,0,0,0,2,2,0,0,2,1,1,1,1
2,2,2,2,2,2,2,2,2,2,2,2,1,1,1,1
1,1,1,1,1,1,1,1,1,1,1,1,1,1,1,1
1,1,1,1,1,1,1,1,1,1,1,1,1,1,1,1
1,1,1,1,1,1,1,1,1,1,1,1,1,1,1,1
1,1,1,1,1,1,1,1,1,1,1,1,1,1,1,1
:endlayer
layer: 2
1,1,1,1,2,2,0,0,0,0,2,2,1,1,1,1
1,1,1,1,2,0,0,0,0,0,0,2,1,1,1,1
1,1,1,1,2,0,0,0,0,0,0,2,1,1,1,1
1,1,1,1,2,0,0,0,0,0,0,2,1,1,1,1
2,2,2,2,2,0,0,0,0,0,0,2,1,1,1,1
2,0,0,0,0,0,0,0,0,0,0,2,1,1,1,1
0,0,0,0,0,0,0,0,0,0,0,2,1,1,1,1
0,0,0,0,0,0,0,0,0,0,2,2,1,1,1,1
0,0,0,0,0,0,0,0,0,0,2,2,1,1,1,1
0,0,0,0,0,0,0,0,0,0,0,2,1,1,1,1
2,0,0,0,0,0,0,2,2,0,0,2,1,1,1,1
2,2,2,2,2,2,2,2,2,2,2,2,1,1,1,1
1,1,1,1,1,1,1,1,1,1,1,1,1,1,1,1
1,1,1,1,1,1,1,1,1,1,1,1,1,1,1,1
1,1,1,1,1,1,1,1,1,1,1,1,1,1,1,1
1,1,1,1,1,1,1,1,1,1,1,1,1,1,1,1
:endlayer
layer: 3
1,1,1,1,2,2,0,0,0,0,2,2,1,1,1,1
1,1,1,1,2,0,0,0,0,0,0,2,1,1,1,1
1,1,1,1,2,0,0,0,0,0,0,2,1,1,1,1
1,1,1,1,2,0,0,0,0,0,0,2,1,1,1,1
2,2,2,2,2,0,0,0,0,0,0,2,1,1,1,1
2,0,0,0,0,0,0,0,0,0,0,2,1,1,1,1
0,0,0,0,0,0,0,0,0,0,0,2,1,1,1,1
0,0,0,0,0,0,0,0,0,0,2,2,1,1,1,1
0,0,0,0,0,0,0,0,0,0,2,2,1,1,1,1
0,0,0,0,0,0,0,0,0,0,0,2,1,1,1,1
2,0,0,0,0,0,0,2,2,0,0,2,1,1,1,1
2,2,2,2,2,2,2,2,2,2,2,2,1,1,1,1
1,1,1,1,1,1,1,1,1,1,1,1,1,1,1,1
1,1,1,1,1,1,1,1,1,1,1,1,1,1,1,1
1,1,1,1,1,1,1,1,1,1,1,1,1,1,1,1
1,1,1,1,1,1,1,1,1,1,1,1,1,1,1,1
:endlayer
layer: 4
3,3,3,3,2,2,0,0,0,0,2,2,3,3,3,3
3,3,3,3,2,0,0,0,0,0,0,2,3,3,3,3
3,3,3,3,2,0,0,0,0,0,0,2,3,3,3,3
3,3,3,3,2,0,0,0,0,0,0,2,3,3,3,3
2,2,2,2,2,0,0,0,0,0,0,2,3,3,3,3
2,0,0,0,0,0,0,0,0,0,0,2,3,3,3,3
0,0,0,0,0,0,0,0,0,0,0,2,3,3,3,3
0,0,0,0,0,0,0,0,0,0,2,2,3,3,3,3
0,0,0,0,0,0,0,0,0,0,2,2,3,3,3,3
0,0,0,0,0,0,0,0,0,0,0,2,3,3,3,3
2,0,0,0,0,0,0,2,2,0,0,2,3,3,3,3
2,2,2,2,2,2,2,2,2,2,2,2,3,3,3,3
3,3,3,3,3,3,3,3,3,3,3,3,3,3,3,3
3,3,3,3,3,3,3,3,3,3,3,3,3,3,3,3
3,3,3,3,3,3,3,3,3,3,3,3,3,3,3,3
3,3,3,3,3,3,3,3,3,3,3,3,3,3,3,3
:endlayer
layer: 5
0,0,0,0,2,7,0,0,0,0,8,2,0,0,0,0
0,0,0,0,6,0,0,0,0,0,0,6,0,0,0,0
0,0,0,0,6,0,0,0,0,0,0,6,0,0,0,0
0,0,0,0,2,0,0,0,0,0,0,2,0,0,0,0
2,6,6,2,2,0,0,0,0,0,0,2,0,0,0,0
5,0,0,0,0,0,0,0,0,0,0,6,0,0,0,0
0,0,0,0,0,0,0,0,0,0,0,6,0,0,0,0
0,0,0,0,0,0,0,0,0,0,8,2,0,0,0,0
0,0,0,0,0,0,0,0,0,0,8,2,0,0,0,0
0,0,0,0,0,0,0,0,0,0,0,6,0,0,0,0
4,0,0,0,0,0,0,4,4,0,0,6,0,0,0,0
2,6,6,2,2,6,6,2,2,6,6,2,0,0,0,0
0,0,0,0,0,0,0,0,0,0,0,0,0,0,0,0
0,0,0,0,0,0,0,0,0,0,0,0,0,0,0,0
0,0,0,0,0,0,0,0,0,0,0,0,0,0,0,0
0,0,0,0,0,0,0,0,0,0,0,0,0,0,0,0
:endlayer

#### RULES ####
rule:
plugin=vanillaBlocks
number=1
data:
JSON:{blockState:{blockName:"minecraft:dirt",properties:{variant:"dirt",snowy:"false"}}}
:enddata
:endrule

rule:
plugin=vanillaBlocks
number=2
data:
JSON:{blockState:{blockName:"minecraft:brick_block"}}
:enddata
:endrule

rule:
plugin=vanillaBlocks
number=3
data:
JSON:{blockState:{blockName:"minecraft:grass",properties:{snowy:"false"}}}
:enddata
:endrule

rule:
plugin=vanillaBlocks
number=4
data:
JSON:{blockState:{blockName:"minecraft:brick_stairs",properties:{half:"bottom",shape:"straight",facing:"south"}}}
:enddata
:endrule

rule:
plugin=vanillaBlocks
number=5
data:
JSON:{blockState:{blockName:"minecraft:brick_stairs",properties:{half:"bottom",shape:"straight",facing:"north"}}}
:enddata
:endrule

rule:
plugin=vanillaBlocks
number=6
data:
JSON:{blockState:{blockName:"minecraft:stone_slab",properties:{half:"bottom",variant:"brick"}}}
:enddata
:endrule

rule:
plugin=vanillaBlocks
number=7
data:
JSON:{blockState:{blockName:"minecraft:brick_stairs",properties:{half:"bottom",shape:"straight",facing:"west"}}}
:enddata
:endrule

rule:
plugin=vanillaBlocks
number=8
data:
JSON:{blockState:{blockName:"minecraft:brick_stairs",properties:{half:"bottom",shape:"straight",facing:"east"}}}
:enddata
:endrule

#### ENTITIES ####
