# Ancient Warfare Structure Template File
# Auto-generated structure template file. created on: 4/27/2021 at: 19:17:11
# Lines beginning with # denote comments

header:
version=2.11
name=SB_T3wall3_Gate_stonebrick
mods=
size=16,17,16
offset=0,4,15
:endheader

#### VALIDATION ####
validation:
type=ground
structureAuthor=TheOddlySeagull
survival=true
worldGenEnabled=false
unique=false
preserveBlocks=false
preventNaturalHostileSpawns=false
selectionWeight=1
clusterValue=1
minDuplicateDistance=1
dimensionWhiteList=true
dimensionList=
biomeGroupList=
biomeWhiteList=true
biomeList=
leveling=0
fill=0
border=0
blockSwap=false
territoryName=
biomeReplacement=minecraft:
minGenerationHeight=0
maxGenerationHeight=255
:endvalidation

#### LAYERS ####
layer: 0
1,1,1,1,1,2,2,2,2,2,2,1,1,1,1,1
1,1,1,1,1,1,2,2,2,2,1,1,1,1,1,1
1,1,1,1,1,2,2,2,2,2,1,1,1,1,1,1
1,1,1,1,1,2,2,2,2,2,2,1,1,1,1,1
1,1,1,1,1,1,2,2,2,2,2,1,1,1,1,1
1,1,1,1,1,2,2,2,2,2,2,1,1,1,1,1
1,1,1,1,1,2,2,2,2,2,2,1,1,1,1,1
1,1,1,1,1,2,2,2,2,2,2,1,1,1,1,1
1,1,1,1,1,2,2,2,2,2,2,1,1,1,1,1
1,1,1,1,1,2,2,2,2,2,2,1,1,1,1,1
1,1,1,1,1,2,2,2,2,2,2,1,1,1,1,1
1,1,1,1,1,1,2,2,2,2,2,1,1,1,1,1
1,1,1,1,1,2,2,2,2,2,2,1,1,1,1,1
1,1,1,1,1,2,2,2,2,2,1,1,1,1,1,1
1,1,1,1,1,1,2,2,2,2,1,1,1,1,1,1
1,1,1,1,1,2,2,2,2,2,2,1,1,1,1,1
:endlayer
layer: 1
1,1,1,1,1,2,2,2,2,2,2,1,1,1,1,1
1,1,1,1,1,1,2,2,2,2,1,1,1,1,1,1
1,1,1,1,1,2,2,2,2,2,1,1,1,1,1,1
1,1,1,1,1,2,2,2,2,2,2,1,1,1,1,1
1,1,1,1,1,1,2,2,2,2,2,1,1,1,1,1
1,1,1,1,1,2,2,2,2,2,2,1,1,1,1,1
1,1,1,1,1,2,2,2,2,2,2,1,1,1,1,1
1,1,1,1,1,2,2,2,2,2,2,1,1,1,1,1
1,1,1,1,1,2,2,2,2,2,2,1,1,1,1,1
1,1,1,1,1,2,2,2,2,2,2,1,1,1,1,1
1,1,1,1,1,2,2,2,2,2,2,1,1,1,1,1
1,1,1,1,1,1,2,2,2,2,2,1,1,1,1,1
1,1,1,1,1,2,2,2,2,2,2,1,1,1,1,1
1,1,1,1,1,2,2,2,2,2,1,1,1,1,1,1
1,1,1,1,1,1,2,2,2,2,1,1,1,1,1,1
1,1,1,1,1,2,2,2,2,2,2,1,1,1,1,1
:endlayer
layer: 2
1,1,1,1,1,2,2,2,2,2,2,1,1,1,1,1
1,1,1,1,1,1,2,2,2,2,1,1,1,1,1,1
1,1,1,1,1,2,2,2,2,2,1,1,1,1,1,1
1,1,1,1,1,2,2,2,2,2,2,1,1,1,1,1
1,1,1,1,1,1,2,2,2,2,2,1,1,1,1,1
1,1,1,1,1,2,2,2,2,2,2,1,1,1,1,1
1,1,1,1,1,2,2,2,2,2,2,1,1,1,1,1
1,1,1,1,1,2,2,2,2,2,2,1,1,1,1,1
1,1,1,1,1,2,2,2,2,2,2,1,1,1,1,1
1,1,1,1,1,2,2,2,2,2,2,1,1,1,1,1
1,1,1,1,1,2,2,2,2,2,2,1,1,1,1,1
1,1,1,1,1,1,2,2,2,2,2,1,1,1,1,1
1,1,1,1,1,2,2,2,2,2,2,1,1,1,1,1
1,1,1,1,1,2,2,2,2,2,1,1,1,1,1,1
1,1,1,1,1,1,2,2,2,2,1,1,1,1,1,1
1,1,1,1,1,2,2,2,2,2,2,1,1,1,1,1
:endlayer
layer: 3
3,3,3,3,3,2,2,2,2,2,2,3,3,3,3,3
3,3,3,3,3,3,2,2,2,2,3,3,3,3,3,3
3,3,3,3,3,2,2,2,2,2,3,3,3,3,3,3
3,3,3,3,3,2,2,2,2,2,2,3,3,3,3,3
3,3,3,3,3,3,2,2,2,2,2,3,3,3,3,3
4,4,4,4,4,4,4,4,4,4,4,4,4,4,4,4
4,4,4,4,4,4,4,4,4,4,4,4,4,4,4,4
4,4,4,4,4,4,4,4,4,4,4,4,4,4,4,4
4,4,4,4,4,4,4,4,4,4,4,4,4,4,4,4
4,4,4,4,4,4,4,4,4,4,4,4,4,4,4,4
4,4,4,4,4,4,4,4,4,4,4,4,4,4,4,4
3,3,3,3,3,3,2,2,2,2,2,3,3,3,3,3
3,3,3,3,3,2,2,2,2,2,2,3,3,3,3,3
3,3,3,3,3,2,2,2,2,2,3,3,3,3,3,3
3,3,3,3,3,3,2,2,2,2,3,3,3,3,3,3
3,3,3,3,3,2,2,2,2,2,2,3,3,3,3,3
:endlayer
layer: 4
0,0,0,0,0,2,2,2,2,2,2,0,0,0,0,0
0,0,0,0,0,0,2,2,2,2,0,0,0,0,0,0
0,0,0,0,0,2,2,2,2,2,0,0,0,0,0,0
0,0,0,0,0,2,2,2,2,2,2,0,0,0,0,0
0,0,0,0,0,0,2,2,2,2,2,0,0,0,0,0
0,0,0,0,0,0,0,0,0,0,0,0,0,0,0,0
0,0,0,0,0,0,0,0,0,0,0,0,0,0,0,0
0,0,0,0,0,0,0,0,0,0,0,0,0,0,0,0
0,0,0,0,0,0,0,0,0,0,0,0,0,0,0,0
0,0,0,0,0,0,0,0,0,0,0,0,0,0,0,0
0,0,0,0,0,0,0,0,0,0,0,0,0,0,0,0
0,0,0,0,0,0,2,2,2,2,2,0,0,0,0,0
0,0,0,0,0,2,2,2,2,2,2,0,0,0,0,0
0,0,0,0,0,2,2,2,2,2,0,0,0,0,0,0
0,0,0,0,0,0,2,2,2,2,0,0,0,0,0,0
0,0,0,0,0,2,2,2,2,2,2,0,0,0,0,0
:endlayer
layer: 5
0,0,0,0,0,2,2,2,2,2,2,0,0,0,0,0
0,0,0,0,0,0,2,2,2,2,0,0,0,0,0,0
0,0,0,0,0,2,2,2,2,2,0,0,0,0,0,0
0,0,0,0,0,2,2,2,2,2,2,0,0,0,0,0
0,0,0,0,0,0,2,2,2,2,2,0,0,0,0,0
0,0,0,0,0,0,0,0,0,0,0,0,0,0,0,0
0,0,0,0,0,0,0,0,0,0,0,0,0,0,0,0
0,0,0,0,0,0,0,0,0,0,0,0,0,0,0,0
0,0,0,0,0,0,0,0,0,0,0,0,0,0,0,0
0,0,0,0,0,0,0,0,0,0,0,0,0,0,0,0
0,0,0,0,0,0,0,0,0,0,0,0,0,0,0,0
0,0,0,0,0,0,2,2,2,2,2,0,0,0,0,0
0,0,0,0,0,2,2,2,2,2,2,0,0,0,0,0
0,0,0,0,0,2,2,2,2,2,0,0,0,0,0,0
0,0,0,0,0,0,2,2,2,2,0,0,0,0,0,0
0,0,0,0,0,2,2,2,2,2,2,0,0,0,0,0
:endlayer
layer: 6
0,0,0,0,0,2,2,2,2,2,2,5,0,0,0,0
0,0,0,0,0,0,2,2,2,2,0,0,0,0,0,0
0,0,0,0,0,2,2,2,2,2,0,0,0,0,0,0
0,0,0,0,6,2,2,2,2,2,2,0,0,0,0,0
0,0,0,0,0,0,2,2,2,2,2,5,0,0,0,0
0,0,0,0,0,0,7,0,0,0,7,0,0,0,0,0
0,0,0,0,0,0,0,0,0,0,0,0,0,0,0,0
0,0,0,0,0,0,0,0,0,0,0,0,0,0,0,0
0,0,0,0,0,0,0,0,0,0,0,0,0,0,0,0
0,0,0,0,0,0,0,0,0,0,0,0,0,0,0,0
0,0,0,0,0,0,8,0,0,0,8,0,0,0,0,0
0,0,0,0,0,0,2,2,2,2,2,5,0,0,0,0
0,0,0,0,6,2,2,2,2,2,2,0,0,0,0,0
0,0,0,0,0,2,2,2,2,2,0,0,0,0,0,0
0,0,0,0,0,0,2,2,2,2,0,0,0,0,0,0
0,0,0,0,0,2,2,2,2,2,2,5,0,0,0,0
:endlayer
layer: 7
0,0,0,0,0,2,2,2,2,2,2,0,0,0,0,0
0,0,0,0,0,0,2,2,2,2,0,0,0,0,0,0
0,0,0,0,0,2,2,2,2,2,0,0,0,0,0,0
0,0,0,0,0,2,2,2,2,2,2,0,0,0,0,0
0,0,0,0,0,0,2,2,2,2,2,0,0,0,0,0
0,0,0,0,0,0,0,0,0,0,0,0,0,0,0,0
0,0,0,0,0,0,0,0,0,0,0,0,0,0,0,0
0,0,0,0,0,0,0,0,0,0,0,0,0,0,0,0
0,0,0,0,0,0,0,0,0,0,0,0,0,0,0,0
0,0,0,0,0,0,0,0,0,0,0,0,0,0,0,0
0,0,0,0,0,0,0,0,0,0,0,0,0,0,0,0
0,0,0,0,0,0,2,2,2,2,2,0,0,0,0,0
0,0,0,0,0,2,2,2,2,2,2,0,0,0,0,0
0,0,0,0,0,2,2,2,2,2,0,0,0,0,0,0
0,0,0,0,0,0,2,2,2,2,0,0,0,0,0,0
0,0,0,0,0,2,2,2,2,2,2,0,0,0,0,0
:endlayer
layer: 8
0,0,0,0,0,2,2,2,2,2,2,0,0,0,0,0
0,0,0,0,0,0,2,2,2,2,0,0,0,0,0,0
0,0,0,0,0,2,2,2,2,2,0,0,0,0,0,0
0,0,0,0,0,2,2,2,2,2,2,0,0,0,0,0
0,0,0,0,0,0,2,2,2,2,2,0,0,0,0,0
0,0,0,0,0,0,9,0,0,0,9,0,0,0,0,0
0,0,0,0,0,0,0,0,0,0,0,0,0,0,0,0
0,0,0,0,0,0,0,0,0,0,0,0,0,0,0,0
0,0,0,0,0,0,0,0,0,0,0,0,0,0,0,0
0,0,0,0,0,0,0,0,0,0,0,0,0,0,0,0
0,0,0,0,0,0,10,0,0,0,10,0,0,0,0,0
0,0,0,0,0,0,2,2,2,2,2,0,0,0,0,0
0,0,0,0,0,2,2,2,2,2,2,0,0,0,0,0
0,0,0,0,0,2,2,2,2,2,0,0,0,0,0,0
0,0,0,0,0,0,2,2,2,2,0,0,0,0,0,0
0,0,0,0,0,2,2,2,2,2,2,0,0,0,0,0
:endlayer
layer: 9
0,0,0,0,0,11,2,2,2,2,2,0,0,0,0,0
0,0,0,0,0,0,2,2,2,2,12,0,0,0,0,0
0,0,0,0,0,11,2,2,2,2,12,0,0,0,0,0
0,0,0,0,0,11,2,2,2,2,2,0,0,0,0,0
0,0,0,0,0,0,2,2,2,2,2,0,0,0,0,0
0,0,0,0,0,0,2,12,0,13,2,0,0,0,0,0
0,0,0,0,0,0,2,12,14,13,2,0,0,0,0,0
0,0,0,0,0,0,13,12,0,13,12,0,0,0,0,0
0,0,0,0,0,0,13,12,0,13,12,0,0,0,0,0
0,0,0,0,0,0,2,12,14,13,2,0,0,0,0,0
0,0,0,0,0,0,2,12,0,13,2,0,0,0,0,0
0,0,0,0,0,0,2,2,2,2,2,0,0,0,0,0
0,0,0,0,0,11,2,2,2,2,2,0,0,0,0,0
0,0,0,0,0,11,2,2,2,2,12,0,0,0,0,0
0,0,0,0,0,0,2,2,2,2,12,0,0,0,0,0
0,0,0,0,0,11,2,2,2,2,2,0,0,0,0,0
:endlayer
layer: 10
0,0,0,0,0,0,2,2,0,0,2,0,0,0,0,0
0,0,0,0,0,0,11,15,0,0,16,0,0,0,0,0
0,0,0,0,0,0,2,2,0,0,16,0,0,0,0,0
0,0,0,0,0,0,2,2,0,0,2,0,0,0,0,0
0,0,0,0,0,0,11,15,0,0,2,0,0,0,0,0
0,0,0,0,0,0,2,2,0,0,16,0,0,0,0,0
0,0,0,0,0,0,11,15,0,0,16,0,0,0,0,0
0,0,0,0,0,0,2,2,0,0,2,0,0,0,0,0
0,0,0,0,0,0,2,2,0,0,2,0,0,0,0,0
0,0,0,0,0,0,11,15,0,0,16,0,0,0,0,0
0,0,0,0,0,0,2,2,0,0,16,0,0,0,0,0
0,0,0,0,0,0,11,15,0,0,2,0,0,0,0,0
0,0,0,0,0,0,2,2,0,0,2,0,0,0,0,0
0,0,0,0,0,0,2,2,0,0,16,0,0,0,0,0
0,0,0,0,0,0,11,15,0,0,16,0,0,0,0,0
0,0,0,0,0,0,2,2,0,0,2,0,0,0,0,0
:endlayer
layer: 11
0,0,0,0,0,0,2,2,0,0,2,0,0,0,0,0
0,0,0,0,0,0,0,0,0,0,0,0,0,0,0,0
0,0,0,0,0,0,2,2,0,0,0,0,0,0,0,0
0,0,0,0,0,0,2,2,0,0,2,0,0,0,0,0
0,0,0,0,0,0,0,0,0,0,2,0,0,0,0,0
0,0,0,0,0,0,2,2,0,0,0,0,0,0,0,0
0,0,0,0,0,0,0,0,0,0,0,0,0,0,0,0
0,0,0,0,0,0,2,2,0,0,2,0,0,0,0,0
0,0,0,0,0,0,2,2,0,0,2,0,0,0,0,0
0,0,0,0,0,0,0,0,0,0,0,0,0,0,0,0
0,0,0,0,0,0,2,2,0,0,0,0,0,0,0,0
0,0,0,0,0,0,0,0,0,0,2,0,0,0,0,0
0,0,0,0,0,0,2,2,0,0,2,0,0,0,0,0
0,0,0,0,0,0,2,2,0,0,0,0,0,0,0,0
0,0,0,0,0,0,0,0,0,0,0,0,0,0,0,0
0,0,0,0,0,0,2,2,0,0,2,0,0,0,0,0
:endlayer
layer: 12
0,0,0,0,0,0,2,2,0,6,2,0,0,0,0,0
0,0,0,0,0,0,14,0,0,0,14,0,0,0,0,0
0,0,0,0,0,0,2,2,0,0,14,0,0,0,0,0
0,0,0,0,0,0,2,2,0,0,2,0,0,0,0,0
0,0,0,0,0,0,14,0,0,0,2,0,0,0,0,0
0,0,0,0,0,0,2,2,0,0,14,0,0,0,0,0
0,0,0,0,0,0,14,0,0,0,14,0,0,0,0,0
0,0,0,0,0,0,2,2,0,6,2,0,0,0,0,0
0,0,0,0,0,0,2,2,0,6,2,0,0,0,0,0
0,0,0,0,0,0,14,0,0,0,14,0,0,0,0,0
0,0,0,0,0,0,2,2,0,0,14,0,0,0,0,0
0,0,0,0,0,0,14,0,0,0,2,0,0,0,0,0
0,0,0,0,0,0,2,2,0,0,2,0,0,0,0,0
0,0,0,0,0,0,2,2,0,0,14,0,0,0,0,0
0,0,0,0,0,0,14,0,0,0,14,0,0,0,0,0
0,0,0,0,0,0,2,2,0,6,2,0,0,0,0,0
:endlayer
layer: 13
0,0,0,0,0,14,2,2,12,13,2,12,0,0,0,0
0,0,0,0,0,14,2,2,12,13,2,14,0,0,0,0
0,0,0,0,0,14,2,2,12,13,2,14,0,0,0,0
0,0,0,0,0,14,2,2,12,13,2,12,0,0,0,0
0,0,0,0,0,14,2,2,12,13,2,12,0,0,0,0
0,0,0,0,0,14,2,2,12,13,2,14,0,0,0,0
0,0,0,0,0,14,2,2,12,13,2,14,0,0,0,0
0,0,0,0,0,14,2,2,12,13,2,12,0,0,0,0
0,0,0,0,0,14,2,2,12,13,2,12,0,0,0,0
0,0,0,0,0,14,2,2,12,13,2,14,0,0,0,0
0,0,0,0,0,14,2,2,12,13,2,14,0,0,0,0
0,0,0,0,0,14,2,2,12,13,2,12,0,0,0,0
0,0,0,0,0,14,2,2,12,13,2,12,0,0,0,0
0,0,0,0,0,14,2,2,12,13,2,14,0,0,0,0
0,0,0,0,0,14,2,2,12,13,2,14,0,0,0,0
0,0,0,0,0,14,2,2,12,13,2,12,0,0,0,0
:endlayer
layer: 14
0,0,0,0,0,17,17,17,17,17,17,17,0,0,0,0
0,0,0,0,0,17,17,17,17,17,17,17,0,0,0,0
0,0,0,0,0,17,17,17,17,17,17,17,0,0,0,0
0,0,0,0,0,17,17,17,17,17,17,17,0,0,0,0
0,0,0,0,0,17,17,17,17,17,17,17,0,0,0,0
0,0,0,0,0,17,17,17,17,17,17,17,0,0,0,0
0,0,0,0,0,17,17,17,17,17,17,17,0,0,0,0
0,0,0,0,0,17,17,17,17,17,17,17,0,0,0,0
0,0,0,0,0,17,17,17,17,17,17,17,0,0,0,0
0,0,0,0,0,17,17,17,17,17,17,17,0,0,0,0
0,0,0,0,0,17,17,17,17,17,17,17,0,0,0,0
0,0,0,0,0,17,17,17,17,17,17,17,0,0,0,0
0,0,0,0,0,17,17,17,17,17,17,17,0,0,0,0
0,0,0,0,0,17,17,17,17,17,17,17,0,0,0,0
0,0,0,0,0,17,17,17,17,17,17,17,0,0,0,0
0,0,0,0,0,17,17,17,17,17,17,17,0,0,0,0
:endlayer
layer: 15
0,0,0,0,0,15,2,2,5,0,0,16,0,0,0,0
0,0,0,0,0,15,2,15,0,0,0,15,0,0,0,0
0,0,0,0,0,15,2,15,0,0,0,15,0,0,0,0
0,0,0,0,0,15,2,2,0,0,0,16,0,0,0,0
0,0,0,0,0,15,2,2,5,0,0,16,0,0,0,0
0,0,0,0,0,15,2,15,0,0,0,15,0,0,0,0
0,0,0,0,0,15,2,15,0,0,0,15,0,0,0,0
0,0,0,0,0,15,2,2,5,0,0,16,0,0,0,0
0,0,0,0,0,15,2,2,5,0,0,16,0,0,0,0
0,0,0,0,0,15,2,15,0,0,0,15,0,0,0,0
0,0,0,0,0,15,2,15,0,0,0,15,0,0,0,0
0,0,0,0,0,15,2,2,5,0,0,16,0,0,0,0
0,0,0,0,0,15,2,2,0,0,0,16,0,0,0,0
0,0,0,0,0,15,2,15,0,0,0,15,0,0,0,0
0,0,0,0,0,15,2,15,0,0,0,15,0,0,0,0
0,0,0,0,0,15,2,2,5,0,0,16,0,0,0,0
:endlayer
layer: 16
0,0,0,0,0,0,2,16,0,0,0,0,0,0,0,0
0,0,0,0,0,0,0,0,0,0,0,0,0,0,0,0
0,0,0,0,0,0,0,0,0,0,0,0,0,0,0,0
0,0,0,0,0,0,2,16,0,0,0,0,0,0,0,0
0,0,0,0,0,0,2,16,0,0,0,0,0,0,0,0
0,0,0,0,0,0,0,0,0,0,0,0,0,0,0,0
0,0,0,0,0,0,0,0,0,0,0,0,0,0,0,0
0,0,0,0,0,0,2,16,0,0,0,0,0,0,0,0
0,0,0,0,0,0,2,16,0,0,0,0,0,0,0,0
0,0,0,0,0,0,0,0,0,0,0,0,0,0,0,0
0,0,0,0,0,0,0,0,0,0,0,0,0,0,0,0
0,0,0,0,0,0,2,16,0,0,0,0,0,0,0,0
0,0,0,0,0,0,2,16,0,0,0,0,0,0,0,0
0,0,0,0,0,0,0,0,0,0,0,0,0,0,0,0
0,0,0,0,0,0,0,0,0,0,0,0,0,0,0,0
0,0,0,0,0,0,2,16,0,0,0,0,0,0,0,0
:endlayer

#### RULES ####
rule:
plugin=vanillaBlocks
number=1
data:
JSON:{blockState:{blockName:"minecraft:dirt",properties:{variant:"dirt",snowy:"false"}}}
:enddata
:endrule

rule:
plugin=vanillaBlocks
number=2
data:
JSON:{blockState:{blockName:"minecraft:stonebrick",properties:{variant:"stonebrick"}}}
:enddata
:endrule

rule:
plugin=vanillaBlocks
number=3
data:
JSON:{blockState:{blockName:"minecraft:grass",properties:{snowy:"false"}}}
:enddata
:endrule

rule:
plugin=vanillaBlocks
number=4
data:
JSON:{blockState:{blockName:"minecraft:cobblestone"}}
:enddata
:endrule

rule:
plugin=vanillaBlocks
number=5
data:
JSON:{blockState:{blockName:"minecraft:torch",properties:{facing:"east"}}}
:enddata
:endrule

rule:
plugin=vanillaBlocks
number=6
data:
JSON:{blockState:{blockName:"minecraft:torch",properties:{facing:"west"}}}
:enddata
:endrule

rule:
plugin=vanillaBlocks
number=7
data:
JSON:{blockState:{blockName:"minecraft:torch",properties:{facing:"south"}}}
:enddata
:endrule

rule:
plugin=vanillaBlocks
number=8
data:
JSON:{blockState:{blockName:"minecraft:torch",properties:{facing:"north"}}}
:enddata
:endrule

rule:
plugin=vanillaBlocks
number=9
data:
JSON:{blockState:{blockName:"minecraft:stone_brick_stairs",properties:{half:"top",shape:"straight",facing:"north"}}}
:enddata
:endrule

rule:
plugin=vanillaBlocks
number=10
data:
JSON:{blockState:{blockName:"minecraft:stone_brick_stairs",properties:{half:"top",shape:"straight",facing:"south"}}}
:enddata
:endrule

rule:
plugin=vanillaBlocks
number=11
data:
JSON:{blockState:{blockName:"minecraft:stone_brick_stairs",properties:{half:"bottom",shape:"straight",facing:"east"}}}
:enddata
:endrule

rule:
plugin=vanillaBlocks
number=12
data:
JSON:{blockState:{blockName:"minecraft:stone_brick_stairs",properties:{half:"top",shape:"straight",facing:"west"}}}
:enddata
:endrule

rule:
plugin=vanillaBlocks
number=13
data:
JSON:{blockState:{blockName:"minecraft:stone_brick_stairs",properties:{half:"top",shape:"straight",facing:"east"}}}
:enddata
:endrule

rule:
plugin=vanillaBlocks
number=14
data:
JSON:{blockState:{blockName:"minecraft:stone_slab",properties:{half:"top",variant:"stone_brick"}}}
:enddata
:endrule

rule:
plugin=vanillaBlocks
number=15
data:
JSON:{blockState:{blockName:"minecraft:stone_slab",properties:{half:"bottom",variant:"stone_brick"}}}
:enddata
:endrule

rule:
plugin=vanillaBlocks
number=16
data:
JSON:{blockState:{blockName:"minecraft:stone_brick_stairs",properties:{half:"bottom",shape:"straight",facing:"west"}}}
:enddata
:endrule

rule:
plugin=vanillaBlocks
number=17
data:
JSON:{blockState:{blockName:"minecraft:stained_hardened_clay",properties:{color:"light_blue"}}}
:enddata
:endrule

#### ENTITIES ####
