# Ancient Warfare Structure Template File
# Auto-generated structure template file. created on: 6/5/2021 at: 11:32:54
# Lines beginning with # denote comments

header:
version=2.11
name=SB_UndefCol_Mansion_1H8R_1
mods=
size=35,40,23
offset=17,1,22
:endheader

#### VALIDATION ####
validation:
type=ground
structureAuthor=theoddlyseagull
survival=true
worldGenEnabled=false
unique=false
preserveBlocks=false
preventNaturalHostileSpawns=false
selectionWeight=1
clusterValue=1
minDuplicateDistance=1
dimensionWhiteList=true
dimensionList=
biomeGroupList=
biomeWhiteList=true
biomeList=
leveling=0
fill=0
border=0
blockSwap=false
territoryName=
biomeReplacement=minecraft:
minGenerationHeight=0
maxGenerationHeight=255
:endvalidation

#### LAYERS ####
layer: 0
1,1,1,1,1,1,1,2,2,1,1,1,1,1,1,1,1,1,1,1,1,1,1,1,1,1,2,2,1,1,1,1,1,1,1
1,1,1,1,1,3,3,2,2,3,3,1,1,1,3,3,1,1,1,3,3,1,1,1,3,3,2,2,3,3,1,1,1,1,1
1,1,1,1,3,3,3,3,3,3,3,3,3,3,3,3,3,3,3,3,3,3,3,3,3,3,3,3,3,3,3,1,1,1,1
2,2,2,2,2,3,2,2,2,2,2,2,2,2,2,2,2,2,2,2,2,2,2,2,2,2,2,2,2,3,2,2,2,2,2
1,1,1,1,3,3,2,2,2,2,2,2,2,2,2,2,2,2,2,2,2,2,2,2,2,2,2,2,2,3,3,1,1,1,1
1,1,1,1,1,3,2,2,2,2,2,2,2,2,2,2,2,2,2,2,2,2,2,2,2,2,2,2,2,3,1,1,1,1,1
1,1,1,1,1,3,2,2,2,2,2,2,2,2,2,2,2,2,2,2,2,2,2,2,2,2,2,2,2,3,1,1,1,1,1
1,1,1,1,1,3,2,2,2,2,2,2,2,2,2,2,2,2,2,2,2,2,2,2,2,2,2,2,2,3,1,1,1,1,1
1,1,1,1,3,3,2,2,2,2,2,2,2,2,2,2,2,2,2,2,2,2,2,2,2,2,2,2,2,3,3,1,1,1,1
1,1,1,1,3,3,2,2,2,2,2,2,2,2,2,2,2,2,2,2,2,2,2,2,2,2,2,2,2,3,3,1,1,1,1
1,1,1,1,1,3,2,2,2,2,2,2,2,2,2,2,2,2,2,2,2,2,2,2,2,2,2,2,2,3,1,1,1,1,1
1,1,1,1,1,3,2,2,2,2,2,2,2,2,2,2,2,2,2,2,2,2,2,2,2,2,2,2,2,3,1,1,1,1,1
1,1,1,1,1,3,2,2,2,2,2,2,2,2,2,2,2,2,2,2,2,2,2,2,2,2,2,2,2,3,1,1,1,1,1
1,1,1,1,3,3,2,2,2,2,2,2,2,2,2,2,2,2,2,2,2,2,2,2,2,2,2,2,2,3,3,1,1,1,1
1,1,1,1,3,3,3,2,2,2,2,2,2,2,2,2,2,2,2,2,2,2,2,2,2,2,2,2,3,3,3,1,1,1,1
1,1,1,3,2,2,2,3,2,2,2,2,2,2,2,2,2,2,2,2,2,2,2,2,2,2,2,3,2,2,2,3,1,1,1
1,1,3,2,2,2,2,2,3,2,2,2,2,2,2,2,2,2,2,2,2,2,2,2,2,2,3,2,2,2,2,2,3,1,1
1,1,3,2,2,2,2,2,3,3,3,3,3,3,3,3,3,3,3,3,3,3,3,3,3,3,3,2,2,2,2,2,3,1,1
1,1,3,2,2,2,2,2,3,4,4,4,3,4,4,4,4,4,4,4,4,4,3,4,4,4,3,2,2,2,2,2,3,1,1
1,1,1,3,2,2,2,3,1,4,4,4,3,4,4,4,4,4,4,4,4,4,3,4,4,4,1,3,2,2,2,3,1,1,1
1,1,1,1,3,3,3,1,1,4,4,1,3,3,3,3,3,3,3,3,3,3,3,1,4,4,1,1,3,3,3,1,1,1,1
1,1,1,1,1,1,1,1,1,4,4,1,1,1,1,3,1,2,1,3,1,1,1,1,4,4,1,1,1,1,1,1,1,1,1
1,1,1,1,1,1,1,1,1,4,4,1,1,1,1,1,1,2,1,1,1,1,1,1,4,4,1,1,1,1,1,1,1,1,1
:endlayer
layer: 1
0,0,0,0,0,0,0,0,0,0,0,0,0,0,0,0,0,0,0,0,0,0,0,0,0,0,0,0,0,0,0,0,0,0,0
0,0,0,0,0,5,5,0,0,5,5,0,0,0,5,5,0,0,0,5,5,0,0,0,5,5,0,0,5,5,0,0,0,0,0
0,0,0,0,5,3,3,0,0,3,3,3,3,3,3,3,3,3,3,3,3,3,3,3,3,3,0,0,3,3,5,0,0,0,0
0,0,0,0,0,0,0,0,0,0,3,0,0,0,0,3,0,0,0,11,3,3,0,0,0,0,0,0,0,0,0,0,0,0,0
0,0,0,0,5,3,0,0,0,0,0,0,0,11,3,3,0,0,0,11,13,3,0,0,0,0,0,0,0,3,5,0,0,0,0
0,0,0,0,0,3,0,0,0,0,0,0,0,11,13,3,0,0,0,11,3,3,3,11,0,0,0,0,0,3,0,0,0,0,0
0,0,0,0,0,3,0,0,0,0,3,0,0,11,3,3,0,0,0,0,0,3,13,11,0,0,0,0,0,3,0,0,0,0,0
0,0,0,0,0,3,0,0,3,3,3,3,3,3,3,3,0,0,0,0,0,3,3,11,0,0,0,0,0,3,0,0,0,0,0
0,0,0,0,5,3,0,0,3,0,0,0,0,0,0,3,0,0,0,0,0,3,0,0,0,0,0,0,0,3,5,0,0,0,0
0,0,0,0,5,3,0,0,3,0,0,0,0,0,0,3,0,0,0,0,0,3,0,0,0,0,0,0,0,3,5,0,0,0,0
0,0,0,0,0,3,0,0,3,0,0,0,0,0,0,3,0,0,0,0,0,3,3,0,0,3,3,3,3,3,0,0,0,0,0
0,0,0,0,0,3,0,0,3,0,0,0,0,0,0,3,0,0,0,0,0,3,0,0,0,0,0,0,0,3,0,0,0,0,0
0,0,0,0,0,3,0,0,3,3,0,0,3,3,3,3,3,0,0,0,3,3,0,0,0,0,0,0,0,3,0,0,0,0,0
0,0,0,0,5,3,0,0,0,0,0,0,0,0,0,0,0,0,0,0,0,0,0,0,0,0,0,0,0,3,5,0,0,0,0
0,0,0,0,3,3,3,0,0,0,0,0,0,0,0,0,0,0,0,0,0,0,0,0,0,0,0,0,3,3,3,0,0,0,0
0,0,0,3,0,0,0,0,0,0,0,0,11,11,11,0,0,0,0,0,0,0,0,0,0,0,0,0,0,9,8,3,0,0,0
0,0,3,0,0,0,0,0,3,0,0,0,3,13,3,0,0,0,0,0,0,0,0,0,0,0,3,0,0,9,8,8,3,0,0
0,0,3,0,0,7,9,9,3,3,3,3,3,3,3,3,3,0,3,3,3,3,3,3,3,3,3,0,0,7,0,16,3,0,0
0,0,3,0,0,0,8,8,3,0,0,0,10,12,0,0,0,0,0,0,0,14,15,0,0,0,3,0,0,0,0,0,3,0,0
0,0,0,3,0,6,8,3,0,0,0,0,10,12,0,0,0,0,0,0,0,14,15,0,0,0,0,3,0,0,0,3,0,0,0
0,0,0,0,3,3,3,0,0,0,0,0,3,3,3,3,3,0,3,3,3,3,3,0,0,0,0,0,3,3,3,0,0,0,0
0,0,0,0,0,0,0,0,0,0,0,0,0,0,0,3,0,0,0,3,0,0,0,0,0,0,0,0,0,0,0,0,0,0,0
0,0,0,0,0,0,0,0,0,0,0,0,0,0,0,0,0,0,0,0,0,0,0,0,0,0,0,0,0,0,0,0,0,0,0
:endlayer
layer: 2
0,0,0,0,0,0,0,0,0,0,0,0,0,0,0,0,0,0,0,0,0,0,0,0,0,0,0,0,0,0,0,0,0,0,0
0,0,0,0,0,5,5,0,0,5,5,0,0,0,5,5,0,0,0,5,5,0,0,0,5,5,0,0,5,5,0,0,0,0,0
0,0,0,0,5,3,3,0,0,3,3,3,18,3,3,3,3,18,3,3,3,3,18,3,3,3,0,0,3,3,5,0,0,0,0
0,0,0,0,0,0,0,0,0,0,3,0,0,0,0,3,0,0,0,0,3,3,0,0,0,0,0,0,0,0,0,0,0,0,0
0,0,0,0,5,3,0,0,0,0,0,0,0,0,3,3,0,0,0,0,0,3,0,0,0,0,0,0,0,3,5,0,0,0,0
0,0,0,0,0,3,0,0,0,0,0,0,0,0,0,3,0,0,0,0,3,3,3,0,0,0,0,0,0,3,0,0,0,0,0
0,0,0,0,0,18,0,0,0,0,3,0,0,0,3,3,0,0,0,0,0,3,0,0,0,0,0,0,0,18,0,0,0,0,0
0,0,0,0,0,3,0,0,3,3,3,3,3,3,3,3,0,0,0,0,0,3,3,0,0,0,0,0,0,3,0,0,0,0,0
0,0,0,0,5,3,0,0,3,0,0,0,0,0,0,3,0,0,0,0,0,3,0,0,0,0,0,0,0,3,5,0,0,0,0
0,0,0,0,5,3,0,0,3,0,0,0,0,0,0,3,0,0,0,0,0,3,0,0,0,0,0,0,0,3,5,0,0,0,0
0,0,0,0,0,3,0,0,3,0,0,0,0,0,0,3,0,0,0,0,0,3,3,0,0,3,3,3,3,3,0,0,0,0,0
0,0,0,0,0,18,0,0,3,0,0,0,0,0,0,3,0,0,0,0,0,3,0,0,0,0,0,0,0,18,0,0,0,0,0
0,0,0,0,0,3,0,0,3,3,0,0,3,3,3,3,3,0,0,0,3,3,0,0,0,0,0,0,0,3,0,0,0,0,0
0,0,0,0,5,3,0,0,0,0,0,0,0,0,0,0,0,0,0,0,0,0,0,0,0,0,0,0,0,3,5,0,0,0,0
0,0,0,0,3,3,3,0,0,0,0,0,0,0,0,0,0,0,0,0,0,0,0,0,0,0,0,0,3,3,3,0,0,0,0
0,0,0,3,0,0,0,0,0,0,0,0,0,0,0,0,0,0,0,0,0,0,0,0,0,0,0,0,0,0,0,3,0,0,0
0,0,3,0,0,0,0,0,3,0,0,0,3,0,3,0,0,0,0,0,0,0,0,0,0,0,3,0,0,0,0,0,3,0,0
0,0,3,17,0,7,0,0,3,3,3,3,3,3,3,3,3,0,3,3,3,3,3,3,3,3,3,0,0,7,9,9,3,0,0
0,0,3,8,8,9,0,0,3,0,0,0,0,10,12,0,0,0,0,0,14,15,0,0,0,0,3,0,0,0,8,8,3,0,0
0,0,0,3,8,9,0,3,0,0,0,0,0,10,12,0,0,0,0,0,14,15,0,0,0,0,0,3,0,6,8,3,0,0,0
0,0,0,0,3,3,3,0,0,0,0,0,19,3,3,3,3,0,3,3,3,3,19,0,0,0,0,0,3,3,3,0,0,0,0
0,0,0,0,0,0,0,0,0,0,0,0,0,20,0,3,0,0,0,3,0,20,0,0,0,0,0,0,0,0,0,0,0,0,0
0,0,0,0,0,0,0,0,0,0,0,0,0,0,0,0,0,0,0,0,0,0,0,0,0,0,0,0,0,0,0,0,0,0,0
:endlayer
layer: 3
0,0,0,0,0,0,0,0,0,0,0,0,0,0,0,0,0,0,0,0,0,0,0,0,0,0,0,0,0,0,0,0,0,0,0
0,0,0,0,0,5,5,0,0,5,5,0,0,0,5,5,0,0,0,5,5,0,0,0,5,5,0,0,5,5,0,0,0,0,0
0,0,0,0,5,3,3,3,3,3,3,3,18,3,3,3,3,18,3,3,3,3,18,3,3,3,3,3,3,3,5,0,0,0,0
0,0,0,0,0,3,0,0,0,16,3,0,0,20,0,3,0,0,20,0,28,3,0,0,0,20,0,0,0,3,0,0,0,0,0
0,0,0,0,5,3,0,0,0,0,23,0,0,0,28,3,0,0,0,0,24,3,0,0,0,0,0,0,0,3,5,0,0,0,0
0,0,0,0,0,3,17,0,0,0,22,0,0,0,24,3,0,0,0,0,27,3,28,0,0,0,0,0,0,3,0,0,0,0,0
0,0,0,0,0,18,0,0,0,0,3,6,0,0,27,3,0,0,0,0,0,3,21,0,0,0,0,0,0,18,0,0,0,0,0
0,0,0,0,0,3,0,0,3,3,3,3,3,3,3,3,0,0,0,0,16,3,27,0,0,0,0,0,16,3,0,0,0,0,0
0,0,0,0,5,3,0,0,3,0,0,0,0,0,0,3,0,0,0,0,0,3,0,0,0,0,0,0,0,3,5,0,0,0,0
0,0,0,0,5,3,0,0,3,0,0,0,0,0,16,3,17,0,0,0,0,3,0,0,0,0,6,0,0,3,5,0,0,0,0
0,0,0,0,0,3,0,16,3,17,0,0,0,0,0,3,0,0,0,0,0,3,3,21,24,3,3,3,3,3,0,0,0,0,0
0,0,0,0,0,18,0,0,3,0,0,0,0,0,0,3,0,0,0,0,0,3,0,0,0,0,20,0,0,18,0,0,0,0,0
0,0,0,0,0,3,0,0,3,3,21,24,3,3,3,3,3,21,29,24,3,3,0,0,0,0,0,0,0,3,0,0,0,0,0
0,0,0,0,5,3,0,0,0,0,0,0,0,20,0,0,0,0,0,0,20,0,0,0,0,0,0,0,0,3,5,0,0,0,0
0,0,0,0,3,3,3,0,0,0,0,0,0,0,0,0,0,0,0,0,0,0,0,0,0,0,0,0,3,3,3,0,0,0,0
0,0,0,3,8,20,0,3,0,0,0,0,0,0,0,0,0,0,0,0,0,0,0,0,0,0,0,3,0,0,0,3,0,0,0
0,0,3,8,8,0,0,0,3,0,6,0,25,22,26,0,0,6,0,0,0,0,0,6,0,0,3,0,0,0,0,0,3,0,0
0,0,3,9,9,7,0,0,3,3,3,3,3,3,3,3,3,3,3,3,3,3,3,3,3,3,3,17,0,7,0,0,18,0,0
0,0,3,0,0,0,0,0,3,0,0,0,0,0,10,12,0,0,0,14,15,0,0,0,0,0,3,8,8,9,0,0,3,0,0
0,0,0,3,0,0,0,3,0,0,0,0,0,0,10,12,0,0,0,14,15,0,0,0,0,0,0,3,8,9,0,3,0,0,0
0,0,0,0,3,18,3,0,0,0,0,0,0,19,3,3,3,3,3,3,3,19,0,0,0,0,0,0,3,3,3,0,0,0,0
0,0,0,0,0,0,0,0,0,0,0,0,0,0,0,27,0,0,0,27,0,0,0,0,0,0,0,0,0,0,0,0,0,0,0
0,0,0,0,0,0,0,0,0,0,0,0,0,0,0,0,0,0,0,0,0,0,0,0,0,0,0,0,0,0,0,0,0,0,0
:endlayer
layer: 4
0,0,0,0,0,0,0,0,0,0,0,0,0,0,0,0,0,0,0,0,0,0,0,0,0,0,0,0,0,0,0,0,0,0,0
0,0,0,0,0,22,22,29,29,22,22,29,29,29,22,22,29,29,29,22,22,29,29,29,22,22,29,29,22,22,0,0,0,0,0
0,0,0,0,24,3,3,3,3,3,3,3,3,3,3,3,3,3,3,3,3,3,3,3,3,3,3,3,3,3,21,0,0,0,0
0,0,0,0,24,3,30,30,30,30,30,30,30,30,30,30,30,30,30,30,30,30,30,30,30,30,30,30,30,3,21,0,0,0,0
0,0,0,0,24,3,30,30,30,30,30,30,30,30,30,30,30,30,30,30,30,30,30,30,30,30,30,30,30,3,21,0,0,0,0
0,0,0,0,29,3,30,30,30,30,30,30,30,30,30,30,30,30,30,30,30,30,30,30,30,30,30,30,30,3,29,0,0,0,0
0,0,0,0,29,3,30,30,30,30,30,30,30,30,30,30,30,30,30,30,30,30,30,30,30,30,30,30,30,3,29,0,0,0,0
0,0,0,0,29,3,30,30,30,30,30,30,30,30,30,30,30,30,30,30,30,30,30,30,30,30,30,30,30,3,29,0,0,0,0
0,0,0,0,24,3,30,30,30,30,30,30,30,30,30,30,30,30,30,30,30,30,30,30,30,30,30,30,30,3,21,0,0,0,0
0,0,0,0,24,3,30,30,30,30,30,30,30,30,30,30,30,30,30,30,30,30,30,30,30,30,30,30,30,3,21,0,0,0,0
0,0,0,0,29,3,30,30,30,30,30,30,30,30,30,30,30,30,30,30,30,30,30,30,30,30,30,30,30,3,29,0,0,0,0
0,0,0,0,29,3,30,30,30,30,30,30,30,30,30,30,30,30,30,30,30,30,30,30,30,30,30,30,30,3,29,0,0,0,0
0,0,0,0,29,3,30,30,30,30,30,30,30,30,30,30,30,30,30,30,30,30,30,30,30,30,30,30,30,3,29,0,0,0,0
0,0,0,0,24,3,30,30,30,30,30,30,30,30,30,30,30,30,30,30,30,30,30,30,30,30,30,30,30,3,21,0,0,0,0
0,0,0,0,3,3,3,30,30,30,30,30,30,30,30,30,30,30,30,30,30,30,30,30,30,30,30,30,3,3,3,0,0,0,0
0,0,0,3,0,9,8,3,30,30,30,30,30,30,30,30,30,30,30,30,30,30,30,30,30,30,30,3,8,20,0,3,0,0,0
0,0,3,0,0,9,8,8,3,30,30,30,30,30,30,30,30,30,30,30,30,30,30,30,30,30,3,8,8,0,0,0,3,0,0
0,0,18,0,0,7,0,16,3,3,3,3,3,3,3,31,3,3,3,31,3,3,3,3,3,3,3,9,9,7,0,0,18,0,0
0,0,3,0,0,0,0,0,3,0,20,0,0,0,0,10,32,32,32,15,0,0,0,0,20,0,3,0,0,0,0,0,3,0,0
0,0,0,3,0,0,0,3,0,0,0,0,0,0,0,10,32,32,32,15,0,0,0,0,0,0,0,3,0,0,0,3,0,0,0
0,0,0,0,3,18,3,0,0,0,0,0,0,0,19,3,3,3,3,3,19,0,0,0,0,0,0,0,3,18,3,0,0,0,0
0,0,0,0,0,0,0,0,0,0,0,0,0,0,0,0,0,0,0,0,0,0,0,0,0,0,0,0,0,0,0,0,0,0,0
0,0,0,0,0,0,0,0,0,0,0,0,0,0,0,0,0,0,0,0,0,0,0,0,0,0,0,0,0,0,0,0,0,0,0
:endlayer
layer: 5
0,0,0,0,0,0,0,0,0,0,0,0,0,0,0,0,0,0,0,0,0,0,0,0,0,0,0,0,0,0,0,0,0,0,0
0,0,0,0,0,31,19,19,19,19,31,19,19,19,31,31,19,19,19,31,31,19,19,19,31,19,19,19,19,31,0,0,0,0,0
0,0,0,0,31,3,3,28,28,3,31,28,28,28,31,31,28,28,28,31,31,28,28,28,31,3,28,28,3,3,31,0,0,0,0
0,0,0,0,19,3,33,33,33,33,33,33,33,33,33,33,33,33,33,33,33,33,33,33,33,33,33,33,33,3,19,0,0,0,0
0,0,0,0,31,31,33,0,0,0,0,0,0,0,0,0,0,0,0,0,33,0,0,0,0,0,0,0,33,31,31,0,0,0,0
0,0,0,0,19,25,33,0,0,0,0,0,0,0,0,0,0,0,0,0,35,0,0,0,0,0,0,0,33,26,19,0,0,0,0
0,0,0,0,19,25,33,0,0,0,0,0,0,0,0,34,0,0,0,0,0,0,0,0,34,0,0,0,33,26,19,0,0,0,0
0,0,0,0,19,25,33,0,0,0,0,0,0,0,0,0,0,0,0,0,0,0,0,0,0,0,0,0,33,26,19,0,0,0,0
0,0,0,0,31,31,33,0,0,34,0,0,0,0,0,0,0,0,0,0,0,0,0,0,0,0,0,0,33,31,31,0,0,0,0
0,0,0,0,31,31,33,0,0,0,0,0,0,0,0,0,0,0,0,0,35,0,0,0,0,0,0,0,33,31,31,0,0,0,0
0,0,0,0,19,25,33,0,0,0,0,0,0,0,0,0,0,0,0,0,33,0,0,0,0,0,0,0,33,26,19,0,0,0,0
0,0,0,0,19,25,33,0,0,0,0,0,0,0,0,0,0,34,11,31,3,3,26,0,34,0,0,0,33,26,19,0,0,0,0
0,0,0,0,19,25,33,0,0,0,0,0,0,0,0,0,0,0,11,13,3,13,11,0,0,0,0,0,33,26,19,0,0,0,0
0,0,0,0,31,31,33,0,0,0,0,34,0,0,0,0,0,0,11,13,3,13,11,0,0,0,0,0,33,31,31,0,0,0,0
0,0,0,0,3,3,5,0,0,0,0,0,0,0,0,0,0,0,11,31,3,3,26,0,0,0,0,0,5,3,3,0,0,0,0
0,0,0,3,0,0,0,0,0,0,0,0,0,0,0,0,0,0,0,0,33,0,0,0,0,0,0,0,0,9,8,3,0,0,0
0,0,3,0,0,0,0,0,5,33,33,33,33,33,33,33,0,0,0,33,33,33,33,33,33,33,5,0,0,9,8,8,3,0,0
0,0,18,0,0,7,9,9,3,3,31,27,27,27,31,7,0,0,0,7,31,27,27,27,31,3,3,0,0,7,0,16,3,0,0
0,0,3,0,0,0,8,8,3,0,0,0,0,0,0,0,0,0,0,0,0,0,0,0,0,0,3,0,0,0,0,0,3,0,0
0,0,0,3,0,6,8,3,0,0,0,0,0,0,0,0,0,0,0,0,0,0,0,0,0,0,0,3,0,0,0,3,0,0,0
0,0,0,0,3,3,3,0,0,0,0,0,0,0,0,19,19,19,19,19,0,0,0,0,0,0,0,0,3,18,3,0,0,0,0
0,0,0,0,0,0,0,0,0,0,0,0,0,0,0,0,0,0,0,0,0,0,0,0,0,0,0,0,0,0,0,0,0,0,0
0,0,0,0,0,0,0,0,0,0,0,0,0,0,0,0,0,0,0,0,0,0,0,0,0,0,0,0,0,0,0,0,0,0,0
:endlayer
layer: 6
0,0,0,0,0,0,0,0,0,0,0,0,0,0,0,0,0,0,0,0,0,0,0,0,0,0,0,0,0,0,0,0,0,0,0
0,0,0,0,0,28,0,0,0,0,28,0,0,0,28,28,0,0,0,28,28,0,0,0,28,0,0,0,0,28,0,0,0,0,0
0,0,0,0,25,3,3,0,0,3,7,0,0,0,7,7,0,0,0,7,7,0,0,0,7,3,0,0,3,3,26,0,0,0,0
0,0,0,0,0,3,33,37,38,33,33,36,37,36,33,33,36,37,36,33,33,36,37,36,33,33,38,37,33,3,0,0,0,0,0
0,0,0,0,25,7,33,0,0,0,0,0,0,0,0,0,0,0,0,0,33,0,0,0,0,0,0,0,33,7,26,0,0,0,0
0,0,0,0,0,0,36,0,0,0,0,0,0,0,0,0,0,0,0,0,35,0,0,0,0,0,0,0,36,0,0,0,0,0,0
0,0,0,0,0,0,37,0,0,0,0,0,0,0,0,0,0,0,0,0,0,0,0,0,0,0,0,0,37,0,0,0,0,0,0
0,0,0,0,0,0,36,0,0,0,0,0,0,0,0,0,0,0,0,0,0,0,0,0,0,0,0,0,36,0,0,0,0,0,0
0,0,0,0,25,7,33,0,0,0,0,0,0,0,0,0,0,0,0,0,0,0,0,0,0,0,0,0,33,7,26,0,0,0,0
0,0,0,0,25,7,33,0,0,0,0,0,0,0,0,0,0,0,0,0,35,0,0,0,0,0,0,0,33,7,26,0,0,0,0
0,0,0,0,0,0,36,0,0,0,0,0,0,0,0,0,0,0,0,0,33,0,0,0,0,0,0,0,36,0,0,0,0,0,0
0,0,0,0,0,0,37,0,0,0,0,0,0,0,0,0,0,0,0,5,3,3,5,0,0,0,0,0,37,0,0,0,0,0,0
0,0,0,0,0,0,36,0,0,0,0,0,0,0,0,0,0,0,0,0,3,0,0,0,0,0,0,0,36,0,0,0,0,0,0
0,0,0,0,25,7,33,0,0,0,0,0,0,0,0,0,0,0,0,0,3,0,0,0,0,0,0,0,33,7,26,0,0,0,0
0,0,0,0,3,3,5,0,0,0,0,0,0,0,0,0,0,0,0,5,3,3,5,0,0,0,0,0,5,3,3,0,0,0,0
0,0,0,3,0,0,0,0,0,0,0,0,0,0,0,0,0,0,0,0,33,0,0,0,0,0,0,0,0,0,0,3,0,0,0
0,0,3,0,0,0,0,0,5,33,33,36,37,36,33,33,0,0,0,33,33,36,37,36,33,33,5,0,0,0,0,0,3,0,0
0,0,3,17,0,7,0,0,3,3,7,0,0,0,7,7,0,0,0,7,7,0,0,0,7,3,3,0,0,7,9,9,3,0,0
0,0,3,8,8,9,0,0,3,0,0,0,0,0,0,0,0,0,0,0,0,0,0,0,0,0,3,0,0,0,8,8,3,0,0
0,0,0,3,8,9,0,3,0,0,0,0,0,0,0,0,0,0,0,0,0,0,0,0,0,0,0,3,0,6,8,3,0,0,0
0,0,0,0,3,3,3,0,0,0,0,0,0,0,0,0,0,0,0,0,0,0,0,0,0,0,0,0,3,3,3,0,0,0,0
0,0,0,0,0,0,0,0,0,0,0,0,0,0,0,0,0,0,0,0,0,0,0,0,0,0,0,0,0,0,0,0,0,0,0
0,0,0,0,0,0,0,0,0,0,0,0,0,0,0,0,0,0,0,0,0,0,0,0,0,0,0,0,0,0,0,0,0,0,0
:endlayer
layer: 7
0,0,0,0,0,0,0,0,0,0,0,0,0,0,0,0,0,0,0,0,0,0,0,0,0,0,0,0,0,0,0,0,0,0,0
0,0,0,0,0,5,0,0,0,0,5,0,0,0,5,5,0,0,0,5,5,0,0,0,5,0,0,0,0,5,0,0,0,0,0
0,0,0,0,5,3,3,0,0,3,7,0,0,0,7,7,0,0,0,7,7,0,0,0,7,3,0,0,3,3,5,0,0,0,0
0,0,0,0,0,3,33,38,37,33,33,38,36,38,33,33,38,36,38,33,33,38,36,38,33,33,37,38,33,3,0,0,0,0,0
0,0,0,0,5,7,33,0,0,0,0,0,0,0,0,0,0,0,0,0,33,0,0,0,0,0,0,0,33,7,5,0,0,0,0
0,0,0,0,0,0,38,0,0,0,0,0,0,0,0,0,0,0,0,0,35,0,0,0,0,0,0,0,38,0,0,0,0,0,0
0,0,0,0,0,0,36,0,0,0,0,0,0,0,0,0,0,0,0,0,0,0,0,0,0,0,0,0,36,0,0,0,0,0,0
0,0,0,0,0,0,38,0,0,0,0,0,0,0,0,0,0,0,0,0,0,0,0,0,0,0,0,0,38,0,0,0,0,0,0
0,0,0,0,5,7,33,0,0,0,0,0,0,0,0,0,0,0,0,0,0,0,0,0,0,0,0,0,33,7,5,0,0,0,0
0,0,0,0,5,7,33,0,0,0,0,0,0,0,0,0,0,0,0,0,35,0,0,0,0,0,0,0,33,7,5,0,0,0,0
0,0,0,0,0,0,38,0,0,0,0,0,0,0,0,0,0,0,0,0,33,0,0,0,0,0,0,0,38,0,0,0,0,0,0
0,0,0,0,0,0,36,0,0,0,0,0,0,0,0,0,0,0,29,31,3,31,11,0,0,0,0,0,36,0,0,0,0,0,0
0,0,0,0,0,0,38,0,0,0,0,0,0,0,0,0,0,0,29,24,3,23,29,0,0,0,0,0,38,0,0,0,0,0,0
0,0,0,0,5,7,33,0,0,0,0,0,0,0,0,0,0,0,29,24,3,22,29,0,0,0,0,0,33,7,5,0,0,0,0
0,0,0,0,3,3,5,0,0,0,0,0,0,0,0,0,0,0,29,31,3,31,11,0,0,0,0,0,5,3,3,0,0,0,0
0,0,0,3,8,20,0,0,0,0,0,0,0,0,0,0,0,0,0,0,33,0,0,0,0,0,0,0,0,0,0,3,0,0,0
0,0,3,8,8,0,0,0,5,33,33,38,36,38,33,33,0,0,0,33,33,38,36,38,33,33,5,0,0,0,0,0,3,0,0
0,0,3,9,9,7,0,0,3,3,7,0,0,0,7,7,0,0,0,7,7,0,0,0,7,3,3,17,0,7,0,0,18,0,0
0,0,3,0,0,0,0,0,3,0,0,0,0,0,0,0,0,0,0,0,0,0,0,0,0,0,3,8,8,9,0,0,3,0,0
0,0,0,3,0,0,0,3,0,0,0,0,0,0,0,0,0,0,0,0,0,0,0,0,0,0,0,3,8,9,0,3,0,0,0
0,0,0,0,3,18,3,0,0,0,0,0,0,0,0,0,0,0,0,0,0,0,0,0,0,0,0,0,3,3,3,0,0,0,0
0,0,0,0,0,0,0,0,0,0,0,0,0,0,0,0,0,0,0,0,0,0,0,0,0,0,0,0,0,0,0,0,0,0,0
0,0,0,0,0,0,0,0,0,0,0,0,0,0,0,0,0,0,0,0,0,0,0,0,0,0,0,0,0,0,0,0,0,0,0
:endlayer
layer: 8
0,0,0,0,0,0,0,0,0,0,0,0,0,0,0,0,0,0,0,0,0,0,0,0,0,0,0,0,0,0,0,0,0,0,0
0,0,0,0,0,5,0,0,0,0,5,0,0,0,5,5,0,0,0,5,5,0,0,0,5,0,0,0,0,5,0,0,0,0,0
0,0,0,0,5,3,3,0,0,3,7,0,0,0,7,7,0,0,0,7,7,0,0,0,7,3,0,0,3,3,5,0,0,0,0
0,0,0,0,0,3,33,37,38,33,33,37,38,37,33,33,37,38,37,33,33,37,38,37,33,33,38,37,33,3,0,0,0,0,0
0,0,0,0,5,7,33,0,0,0,0,0,0,0,0,0,0,0,0,0,33,0,0,0,0,0,0,0,33,7,5,0,0,0,0
0,0,0,0,0,0,37,0,0,0,0,0,0,0,0,0,0,0,0,0,35,0,0,0,0,0,0,0,37,0,0,0,0,0,0
0,0,0,0,0,0,38,0,0,0,0,0,0,0,0,0,0,0,0,0,40,0,0,0,0,0,0,0,38,0,0,0,0,0,0
0,0,0,0,0,0,37,0,0,0,0,0,0,0,0,0,0,0,0,0,0,0,0,0,0,0,0,0,37,0,0,0,0,0,0
0,0,0,0,5,7,33,0,0,0,0,0,0,0,0,0,0,0,0,0,39,0,0,0,0,0,0,0,33,7,5,0,0,0,0
0,0,0,0,5,7,33,0,0,0,0,0,0,0,0,0,0,0,0,0,35,0,0,0,0,0,0,0,33,7,5,0,0,0,0
0,0,0,0,0,0,37,0,0,0,0,0,0,0,0,0,0,0,0,0,33,0,0,0,0,0,0,0,37,0,0,0,0,0,0
0,0,0,0,0,0,38,0,0,0,0,0,0,0,0,0,0,0,0,25,3,28,0,0,0,0,0,0,38,0,0,0,0,0,0
0,0,0,0,0,0,37,0,0,0,0,0,0,0,0,0,0,0,0,31,3,3,0,0,0,0,0,0,37,0,0,0,0,0,0
0,0,0,0,5,7,33,0,0,0,0,0,0,0,0,0,0,0,0,31,3,3,0,0,0,0,0,0,33,7,5,0,0,0,0
0,0,0,0,3,3,3,33,0,0,0,0,0,0,0,0,0,0,0,25,3,27,0,0,0,0,0,33,3,3,3,0,0,0,0
0,0,0,3,0,9,8,3,33,0,0,0,0,0,0,0,0,0,0,0,33,0,0,0,0,0,33,3,8,20,0,3,0,0,0
0,0,3,0,0,9,8,8,3,33,33,37,38,37,33,33,0,0,0,33,33,37,38,37,33,33,3,8,8,0,0,0,3,0,0
0,0,18,0,0,7,0,16,3,3,7,0,0,0,7,7,0,0,0,7,7,0,0,0,7,3,3,9,9,7,0,0,18,0,0
0,0,3,0,0,0,0,0,3,0,0,0,0,0,0,20,0,0,0,20,0,0,0,0,0,0,3,0,0,0,0,0,3,0,0
0,0,0,3,0,0,0,3,0,0,0,0,0,0,0,0,0,0,0,0,0,0,0,0,0,0,0,3,0,0,0,3,0,0,0
0,0,0,0,3,18,3,0,0,0,0,0,0,0,0,0,0,0,0,0,0,0,0,0,0,0,0,0,3,18,3,0,0,0,0
0,0,0,0,0,0,0,0,0,0,0,0,0,0,0,0,0,0,0,0,0,0,0,0,0,0,0,0,0,0,0,0,0,0,0
0,0,0,0,0,0,0,0,0,0,0,0,0,0,0,0,0,0,0,0,0,0,0,0,0,0,0,0,0,0,0,0,0,0,0
:endlayer
layer: 9
0,0,0,0,0,0,0,0,0,0,0,0,0,0,0,0,0,0,0,0,0,0,0,0,0,0,0,0,0,0,0,0,0,0,0
0,0,0,0,0,5,0,0,0,0,5,0,0,0,5,5,0,0,0,5,5,0,0,0,5,0,0,0,0,5,0,0,0,0,0
0,0,0,0,5,3,3,21,24,3,31,21,0,24,31,31,21,0,24,31,31,21,0,24,31,3,21,24,3,3,5,0,0,0,0
0,0,0,0,0,3,33,38,37,33,33,38,37,38,33,33,38,37,38,33,33,38,37,38,33,33,37,38,33,3,0,0,0,0,0
0,0,0,0,5,31,33,0,0,0,0,0,0,0,0,0,0,0,0,0,33,0,0,0,0,0,0,0,33,31,5,0,0,0,0
0,0,0,0,0,23,38,0,0,0,0,0,0,0,0,0,0,0,0,0,33,0,0,0,0,0,0,0,38,23,0,0,0,0,0
0,0,0,0,0,0,37,0,0,0,0,0,0,0,0,0,0,0,0,0,41,0,0,0,0,0,0,0,37,0,0,0,0,0,0
0,0,0,0,0,22,38,0,0,0,0,0,0,0,0,0,0,0,0,0,41,0,0,0,0,0,0,0,38,22,0,0,0,0,0
0,0,0,0,5,31,33,0,0,0,0,0,0,0,0,0,0,0,0,0,41,0,0,0,0,0,0,0,33,31,5,0,0,0,0
0,0,0,0,5,31,33,0,0,0,0,0,0,0,0,0,0,0,0,0,33,0,0,0,0,0,0,0,33,31,5,0,0,0,0
0,0,0,0,0,23,38,0,0,0,0,0,0,0,0,0,0,0,0,0,33,0,0,0,0,0,0,0,38,23,0,0,0,0,0
0,0,0,0,0,0,37,0,0,0,0,0,0,0,0,0,0,0,0,0,3,0,0,0,0,0,0,0,37,0,0,0,0,0,0
0,0,0,0,0,22,38,0,0,0,0,0,0,0,0,0,0,0,0,25,3,3,0,0,0,0,0,0,38,22,0,0,0,0,0
0,0,0,0,5,31,33,33,0,0,0,0,0,0,0,0,0,0,0,25,3,3,0,0,0,0,0,33,33,31,5,0,0,0,0
0,0,0,0,3,3,2,30,33,0,0,0,0,0,0,0,0,0,0,0,3,0,0,0,0,0,33,30,2,3,3,0,0,0,0
0,0,0,3,0,0,0,9,30,33,0,0,0,0,0,0,0,0,0,0,33,0,0,0,0,33,30,9,0,9,8,3,0,0,0
0,0,3,0,0,0,0,0,2,33,33,38,37,38,33,33,0,0,0,33,33,38,37,38,33,33,2,0,0,9,8,8,3,0,0
0,0,18,0,0,7,9,9,3,3,31,21,0,24,31,31,21,0,24,31,31,21,0,24,31,3,3,0,0,7,0,16,3,0,0
0,0,3,0,0,0,8,8,3,0,5,0,0,0,5,5,0,0,0,5,5,0,0,0,5,0,3,0,0,0,0,0,3,0,0
0,0,0,3,0,6,8,3,0,0,0,0,0,0,0,0,0,0,0,0,0,0,0,0,0,0,0,3,0,0,0,3,0,0,0
0,0,0,0,3,3,3,0,0,0,0,0,0,0,0,0,0,0,0,0,0,0,0,0,0,0,0,0,3,18,3,0,0,0,0
0,0,0,0,0,0,0,0,0,0,0,0,0,0,0,0,0,0,0,0,0,0,0,0,0,0,0,0,0,0,0,0,0,0,0
0,0,0,0,0,0,0,0,0,0,0,0,0,0,0,0,0,0,0,0,0,0,0,0,0,0,0,0,0,0,0,0,0,0,0
:endlayer
layer: 10
0,0,0,0,0,0,0,0,0,0,0,0,0,0,0,0,0,0,0,0,0,0,0,0,0,0,0,0,0,0,0,0,0,0,0
0,0,0,0,0,22,22,29,29,22,22,29,29,29,22,22,29,29,29,22,22,29,29,29,22,22,29,29,22,22,0,0,0,0,0
0,0,0,0,24,3,3,3,3,3,3,3,3,3,3,3,3,3,3,3,3,3,3,3,3,3,3,3,3,3,21,0,0,0,0
0,0,0,0,24,3,33,33,33,33,33,33,33,33,33,33,33,33,33,33,33,33,33,33,33,33,33,33,33,3,21,0,0,0,0
0,0,0,0,24,3,33,30,30,30,30,30,30,30,30,30,30,30,30,30,30,30,30,30,30,30,30,30,33,3,21,0,0,0,0
0,0,0,0,29,3,33,30,30,30,30,30,30,30,30,30,30,30,30,30,30,30,30,30,30,30,30,30,33,3,29,0,0,0,0
0,0,0,0,29,3,33,30,30,30,30,30,30,30,30,30,30,30,30,30,30,30,30,30,30,30,30,30,33,3,29,0,0,0,0
0,0,0,0,24,3,33,30,30,30,30,30,30,30,30,30,30,30,30,30,30,30,30,30,30,30,30,30,33,3,21,0,0,0,0
0,0,0,0,24,3,33,30,30,30,30,30,30,30,30,30,30,30,30,30,30,30,30,30,30,30,30,30,33,3,21,0,0,0,0
0,0,0,0,24,3,33,30,30,30,30,30,30,30,30,30,30,30,30,30,30,30,30,30,30,30,30,30,33,3,21,0,0,0,0
0,0,0,0,24,3,33,30,30,30,30,30,30,30,30,30,30,30,30,30,30,30,30,30,30,30,30,30,33,3,21,0,0,0,0
0,0,0,0,29,3,33,30,30,30,30,30,30,30,30,30,30,30,30,30,30,30,30,30,30,30,30,30,33,3,29,0,0,0,0
0,0,0,0,29,3,33,30,30,30,30,30,30,30,30,30,30,30,30,30,30,30,30,30,30,30,30,30,33,3,29,0,0,0,0
0,0,0,0,24,3,42,43,30,30,30,30,30,30,30,30,30,30,30,30,30,30,30,30,30,30,30,43,42,3,21,0,0,0,0
0,0,0,0,3,3,5,0,43,30,30,30,30,30,30,30,30,30,30,30,30,30,30,30,30,30,43,0,5,3,3,0,0,0,0
0,0,0,3,0,0,0,0,0,43,30,30,30,30,30,30,30,30,30,30,30,30,30,30,30,43,0,0,0,0,0,3,0,0,0
0,0,3,0,0,0,0,0,5,42,33,33,33,33,33,33,33,33,33,33,33,33,33,33,33,42,5,0,0,0,0,0,3,0,0
0,0,3,17,0,7,0,0,3,3,3,3,3,3,3,3,3,3,3,3,3,3,3,3,3,3,3,0,0,7,9,9,3,0,0
0,0,3,8,8,9,0,0,3,29,23,29,29,29,23,23,29,29,29,23,23,29,29,29,23,29,3,0,0,0,8,8,3,0,0
0,0,0,3,8,9,0,3,0,0,0,0,0,0,0,0,0,0,0,0,0,0,0,0,0,0,0,3,0,6,8,3,0,0,0
0,0,0,0,3,3,3,0,0,0,0,0,0,0,0,0,0,0,0,0,0,0,0,0,0,0,0,0,3,3,3,0,0,0,0
0,0,0,0,0,0,0,0,0,0,0,0,0,0,0,0,0,0,0,0,0,0,0,0,0,0,0,0,0,0,0,0,0,0,0
0,0,0,0,0,0,0,0,0,0,0,0,0,0,0,0,0,0,0,0,0,0,0,0,0,0,0,0,0,0,0,0,0,0,0
:endlayer
layer: 11
0,0,0,0,0,0,0,0,0,0,0,0,0,0,0,0,0,0,0,0,0,0,0,0,0,0,0,0,0,0,0,0,0,0,0
0,0,0,0,0,31,19,19,19,19,31,19,19,31,19,19,31,19,31,19,19,31,19,19,31,19,19,19,19,31,0,0,0,0,0
0,0,0,0,31,3,3,28,28,3,31,28,28,31,28,28,31,3,31,28,28,31,28,28,31,3,28,28,3,3,31,0,0,0,0
0,0,0,0,19,3,42,42,42,42,42,42,42,42,42,42,42,35,42,42,42,42,42,42,42,42,42,42,42,3,19,0,0,0,0
0,0,0,0,31,31,42,0,0,0,0,0,0,42,0,0,0,0,0,0,0,42,0,0,0,0,0,0,42,31,31,0,0,0,0
0,0,0,0,19,25,42,0,0,0,0,0,0,42,0,0,0,0,0,11,3,3,3,11,0,0,0,0,42,26,19,0,0,0,0
0,0,0,0,19,25,42,0,0,0,0,0,0,42,0,0,0,0,0,11,13,3,13,11,0,34,0,0,42,26,19,0,0,0,0
0,0,0,0,31,31,42,0,0,34,0,0,0,42,0,0,0,0,0,11,3,3,3,11,0,0,0,0,42,31,31,0,0,0,0
0,0,0,0,19,25,42,0,0,0,0,0,0,42,0,0,34,0,0,0,0,42,0,0,0,0,0,0,42,26,19,0,0,0,0
0,0,0,0,19,25,42,0,0,0,0,0,0,42,0,0,0,0,0,0,0,42,0,0,0,0,0,0,42,26,19,0,0,0,0
0,0,0,0,31,31,42,42,35,0,0,35,42,42,0,0,0,0,0,0,0,42,42,35,0,0,35,42,42,31,31,0,0,0,0
0,0,0,0,19,25,42,0,0,0,0,0,0,42,0,0,0,0,0,0,0,42,0,0,34,0,0,0,42,26,19,0,0,0,0
0,0,0,0,19,25,42,0,0,0,0,0,0,35,42,35,0,0,0,35,42,35,0,0,0,0,0,0,42,26,19,0,0,0,0
0,0,0,0,31,31,42,0,0,0,0,0,34,0,0,0,0,0,0,0,0,0,0,0,0,0,0,0,42,31,31,0,0,0,0
0,0,0,0,3,3,5,0,0,0,0,0,0,0,0,0,0,0,0,34,0,0,0,0,0,0,0,0,5,3,3,0,0,0,0
0,0,0,3,8,20,0,0,0,0,0,0,0,0,0,0,0,0,0,0,0,0,0,0,0,0,0,0,0,0,0,3,0,0,0
0,0,3,8,8,0,0,0,5,42,42,42,42,42,42,42,42,35,42,42,42,42,42,42,42,42,5,0,0,0,0,0,3,0,0
0,0,3,9,9,7,0,0,3,3,31,27,27,31,27,27,31,3,31,27,27,31,27,27,31,3,3,17,0,7,0,0,18,0,0
0,0,3,0,0,0,0,0,3,19,31,19,19,31,19,19,31,19,31,19,19,31,19,19,31,19,3,8,8,9,0,0,3,0,0
0,0,0,3,0,0,0,3,0,0,0,0,0,0,0,0,0,0,0,0,0,0,0,0,0,0,0,3,8,9,0,3,0,0,0
0,0,0,0,3,18,3,0,0,0,0,0,0,0,0,0,0,0,0,0,0,0,0,0,0,0,0,0,3,3,3,0,0,0,0
0,0,0,0,0,0,0,0,0,0,0,0,0,0,0,0,0,0,0,0,0,0,0,0,0,0,0,0,0,0,0,0,0,0,0
0,0,0,0,0,0,0,0,0,0,0,0,0,0,0,0,0,0,0,0,0,0,0,0,0,0,0,0,0,0,0,0,0,0,0
:endlayer
layer: 12
0,0,0,0,0,0,0,0,0,0,0,0,0,0,0,0,0,0,0,0,0,0,0,0,0,0,0,0,0,0,0,0,0,0,0
0,0,0,0,0,5,0,0,0,0,5,0,0,5,0,0,5,0,5,0,0,5,0,0,5,0,0,0,0,5,0,0,0,0,0
0,0,0,0,5,3,3,0,0,3,7,0,0,7,0,0,7,3,7,0,0,7,0,0,7,3,0,0,3,3,5,0,0,0,0
0,0,0,0,0,3,42,18,18,42,42,18,18,42,18,18,42,35,42,18,18,42,18,18,42,42,18,18,42,3,0,0,0,0,0
0,0,0,0,5,7,42,0,0,0,0,0,0,42,0,0,0,0,0,0,0,42,0,0,0,0,0,0,42,7,5,0,0,0,0
0,0,0,0,0,0,18,0,0,0,0,0,0,42,0,0,0,0,0,0,3,3,3,0,0,0,0,0,18,0,0,0,0,0,0
0,0,0,0,0,0,18,0,0,0,0,0,0,42,0,0,0,0,0,0,0,3,0,0,0,0,0,0,18,0,0,0,0,0,0
0,0,0,0,5,7,42,0,0,0,0,0,0,42,0,0,0,0,0,0,3,3,3,0,0,0,0,0,42,7,5,0,0,0,0
0,0,0,0,0,0,18,0,0,0,0,0,0,42,0,0,0,0,0,0,0,42,0,0,0,0,0,0,18,0,0,0,0,0,0
0,0,0,0,0,0,18,0,0,0,0,0,0,42,0,0,0,0,0,0,0,42,0,0,0,0,0,0,18,0,0,0,0,0,0
0,0,0,0,5,7,42,42,35,0,0,35,42,42,0,0,0,0,0,0,0,42,42,35,0,0,35,42,42,7,5,0,0,0,0
0,0,0,0,0,0,18,0,0,0,0,0,0,42,0,0,0,0,0,0,0,42,0,0,0,0,0,0,18,0,0,0,0,0,0
0,0,0,0,0,0,18,0,0,0,0,0,0,35,42,35,0,0,0,35,42,35,0,0,0,0,0,0,18,0,0,0,0,0,0
0,0,0,0,5,7,42,0,0,0,0,0,0,0,0,0,0,0,0,0,0,0,0,0,0,0,0,0,42,7,5,0,0,0,0
0,0,0,0,3,3,5,0,0,0,0,0,0,0,0,0,0,0,0,0,0,0,0,0,0,0,0,0,5,3,3,0,0,0,0
0,0,0,3,0,9,8,0,0,0,0,0,0,0,0,0,0,0,0,0,0,0,0,0,0,0,0,0,8,20,0,3,0,0,0
0,0,3,0,0,9,8,8,5,42,42,18,18,42,18,18,42,35,42,18,18,42,18,18,42,42,5,8,8,0,0,0,3,0,0
0,0,18,0,0,7,0,16,3,3,7,0,0,7,0,0,7,3,7,0,0,7,0,0,7,3,3,9,9,7,0,0,18,0,0
0,0,3,0,0,0,0,0,3,0,5,0,0,5,0,0,5,0,5,0,0,5,0,0,5,0,3,0,0,0,0,0,3,0,0
0,0,0,3,0,0,0,3,0,0,0,0,0,0,0,0,0,0,0,0,0,0,0,0,0,0,0,3,0,0,0,3,0,0,0
0,0,0,0,3,18,3,0,0,0,0,0,0,0,0,0,0,0,0,0,0,0,0,0,0,0,0,0,3,18,3,0,0,0,0
0,0,0,0,0,0,0,0,0,0,0,0,0,0,0,0,0,0,0,0,0,0,0,0,0,0,0,0,0,0,0,0,0,0,0
0,0,0,0,0,0,0,0,0,0,0,0,0,0,0,0,0,0,0,0,0,0,0,0,0,0,0,0,0,0,0,0,0,0,0
:endlayer
layer: 13
0,0,0,0,0,0,0,0,0,0,0,0,0,0,0,0,0,0,0,0,0,0,0,0,0,0,0,0,0,0,0,0,0,0,0
0,0,0,0,0,5,0,0,0,0,5,0,0,5,0,0,5,0,5,0,0,5,0,0,5,0,0,0,0,5,0,0,0,0,0
0,0,0,0,5,3,3,0,0,3,7,0,0,7,0,0,7,3,7,0,0,7,0,0,7,3,0,0,3,3,5,0,0,0,0
0,0,0,0,0,3,42,18,18,42,42,18,18,42,18,18,42,35,42,18,18,42,18,18,42,42,18,18,42,3,0,0,0,0,0
0,0,0,0,5,7,42,0,0,0,0,0,0,42,0,0,0,0,0,0,0,42,0,0,0,0,0,0,42,7,5,0,0,0,0
0,0,0,0,0,0,18,0,0,0,0,0,0,42,0,0,0,0,0,0,3,3,3,0,0,0,0,0,18,0,0,0,0,0,0
0,0,0,0,0,0,18,0,0,0,0,0,0,42,0,0,0,0,0,0,24,3,21,0,0,0,0,0,18,0,0,0,0,0,0
0,0,0,0,5,7,42,0,0,0,0,0,0,42,0,0,0,0,0,0,3,3,3,0,0,0,0,0,42,7,5,0,0,0,0
0,0,0,0,0,0,18,0,0,0,0,0,0,42,0,0,0,0,0,0,0,42,0,0,0,0,0,0,18,0,0,0,0,0,0
0,0,0,0,0,0,18,0,0,0,0,0,0,42,0,0,0,0,0,0,0,42,0,0,0,0,0,0,18,0,0,0,0,0,0
0,0,0,0,5,7,42,42,35,44,45,35,42,42,0,0,0,0,0,0,0,42,42,35,44,45,35,42,42,7,5,0,0,0,0
0,0,0,0,0,0,18,0,0,0,0,0,0,42,0,0,0,0,0,0,0,42,0,0,0,0,0,0,18,0,0,0,0,0,0
0,0,0,0,0,0,18,0,0,0,0,0,0,35,42,35,44,0,45,35,42,35,0,0,0,0,0,0,18,0,0,0,0,0,0
0,0,0,0,5,7,42,0,0,0,0,0,0,0,0,0,0,0,0,0,0,0,0,0,0,0,0,0,42,7,5,0,0,0,0
0,0,0,0,3,3,3,29,0,0,0,0,0,0,0,0,0,0,0,0,0,0,0,0,0,0,0,29,3,3,3,0,0,0,0
0,0,0,3,0,0,0,3,29,0,0,0,0,0,0,0,0,0,0,0,0,0,0,0,0,0,29,3,0,9,8,3,0,0,0
0,0,3,0,0,0,0,0,3,42,42,18,18,42,18,18,42,35,42,18,18,42,18,18,42,42,3,0,0,9,8,8,3,0,0
0,0,18,0,0,7,9,9,3,3,7,0,0,7,0,0,7,3,7,0,0,7,0,0,7,3,3,0,0,7,0,16,3,0,0
0,0,3,0,0,0,8,8,3,0,5,0,0,5,0,0,5,0,5,0,0,5,0,0,5,0,3,0,0,0,0,0,3,0,0
0,0,0,3,0,6,8,3,0,0,0,0,0,0,0,0,0,0,0,0,0,0,0,0,0,0,0,3,0,0,0,3,0,0,0
0,0,0,0,3,3,3,0,0,0,0,0,0,0,0,0,0,0,0,0,0,0,0,0,0,0,0,0,3,18,3,0,0,0,0
0,0,0,0,0,0,0,0,0,0,0,0,0,0,0,0,0,0,0,0,0,0,0,0,0,0,0,0,0,0,0,0,0,0,0
0,0,0,0,0,0,0,0,0,0,0,0,0,0,0,0,0,0,0,0,0,0,0,0,0,0,0,0,0,0,0,0,0,0,0
:endlayer
layer: 14
0,0,0,0,0,0,0,0,0,0,0,0,0,0,0,0,0,0,0,0,0,0,0,0,0,0,0,0,0,0,0,0,0,0,0
0,0,0,0,0,5,0,0,0,0,5,0,0,5,0,0,5,0,5,0,0,5,0,0,5,0,0,0,0,5,0,0,0,0,0
0,0,0,0,5,3,3,0,0,3,7,0,0,7,0,0,7,3,7,0,0,7,0,0,7,3,0,0,3,3,5,0,0,0,0
0,0,0,0,0,3,42,18,18,42,42,18,18,42,18,18,42,35,42,18,18,42,18,18,42,42,18,18,42,3,0,0,0,0,0
0,0,0,0,5,7,42,0,0,0,0,0,0,42,0,0,0,0,0,0,0,42,0,0,0,0,0,0,42,7,5,0,0,0,0
0,0,0,0,0,0,18,0,0,0,0,0,0,42,0,0,0,0,0,0,25,42,26,0,0,0,0,0,18,0,0,0,0,0,0
0,0,0,0,0,0,18,0,0,0,0,0,0,42,0,0,0,0,0,0,3,3,3,0,0,0,0,0,18,0,0,0,0,0,0
0,0,0,0,5,7,42,0,0,0,0,0,0,42,0,0,0,0,0,0,25,42,26,0,0,0,0,0,42,7,5,0,0,0,0
0,0,0,0,0,0,18,0,0,0,0,0,0,42,0,0,0,0,0,0,0,42,0,0,0,0,0,0,18,0,0,0,0,0,0
0,0,0,0,0,0,18,0,0,0,0,0,0,42,0,0,0,0,0,0,0,42,0,0,0,0,0,0,18,0,0,0,0,0,0
0,0,0,0,5,7,42,42,42,46,46,42,42,42,0,0,0,0,0,0,0,42,42,42,46,46,42,42,42,7,5,0,0,0,0
0,0,0,0,0,0,18,0,0,0,0,0,0,42,0,0,0,0,0,0,0,42,0,0,0,0,0,0,18,0,0,0,0,0,0
0,0,0,0,0,0,18,0,0,0,0,0,0,35,42,42,46,46,46,42,42,35,0,0,0,0,0,0,18,0,0,0,0,0,0
0,0,0,0,5,7,42,0,0,0,0,0,0,0,0,0,0,0,0,0,0,0,0,0,0,0,0,0,42,7,5,0,0,0,0
0,0,0,0,3,3,3,42,0,0,0,0,0,0,0,0,0,0,0,0,0,0,0,0,0,0,0,42,3,3,3,0,0,0,0
0,0,0,3,0,0,0,3,42,0,0,0,0,0,0,0,0,0,0,0,0,0,0,0,0,0,42,3,0,0,0,3,0,0,0
0,0,3,0,0,0,0,0,3,42,42,18,18,42,18,18,42,35,42,18,18,42,18,18,42,42,3,0,0,0,0,0,3,0,0
0,0,3,17,0,7,0,0,3,3,7,0,0,7,0,0,7,3,7,0,0,7,0,0,7,3,3,0,0,7,9,9,3,0,0
0,0,3,8,8,9,0,0,3,0,5,0,0,5,0,0,5,0,5,0,0,5,0,0,5,0,3,0,0,0,8,8,3,0,0
0,0,0,3,8,9,0,3,0,0,0,0,0,0,0,0,0,0,0,0,0,0,0,0,0,0,0,3,0,6,8,3,0,0,0
0,0,0,0,3,3,3,0,0,0,0,0,0,0,0,0,0,0,0,0,0,0,0,0,0,0,0,0,3,3,3,0,0,0,0
0,0,0,0,0,0,0,0,0,0,0,0,0,0,0,0,0,0,0,0,0,0,0,0,0,0,0,0,0,0,0,0,0,0,0
0,0,0,0,0,0,0,0,0,0,0,0,0,0,0,0,0,0,0,0,0,0,0,0,0,0,0,0,0,0,0,0,0,0,0
:endlayer
layer: 15
0,0,0,0,0,0,0,0,0,0,0,0,0,0,0,0,0,0,0,0,0,0,0,0,0,0,0,0,0,0,0,0,0,0,0
0,0,0,0,0,5,0,0,0,0,5,0,0,5,0,0,5,0,5,0,0,5,0,0,5,0,0,0,0,5,0,0,0,0,0
0,0,0,0,5,3,3,21,24,3,31,21,24,31,21,24,31,3,31,21,24,31,21,24,31,3,21,24,3,3,5,0,0,0,0
0,0,0,0,0,3,42,18,18,42,42,18,18,42,18,18,42,35,42,18,18,42,18,18,42,42,18,18,42,3,0,0,0,0,0
0,0,0,0,5,31,42,0,0,0,0,0,0,42,0,0,0,0,0,0,0,42,0,0,0,0,0,0,42,31,5,0,0,0,0
0,0,0,0,0,23,18,0,0,0,0,0,0,42,0,0,0,0,0,0,0,42,0,0,0,0,0,0,18,23,0,0,0,0,0
0,0,0,0,0,22,18,0,0,0,0,0,0,42,0,0,0,0,0,0,25,3,26,0,0,0,0,0,18,22,0,0,0,0,0
0,0,0,0,5,31,42,0,0,0,0,0,0,42,0,0,0,0,0,0,0,42,0,0,0,0,0,0,42,31,5,0,0,0,0
0,0,0,0,0,23,18,0,0,0,0,0,0,42,0,0,0,0,0,0,0,42,0,0,0,0,0,0,18,23,0,0,0,0,0
0,0,0,0,0,22,18,0,0,0,0,0,0,42,0,0,0,0,0,0,0,42,0,0,0,0,0,0,18,22,0,0,0,0,0
0,0,0,0,5,31,42,42,42,42,42,42,42,42,0,0,0,0,0,0,0,42,42,42,42,42,42,42,42,31,5,0,0,0,0
0,0,0,0,0,23,18,0,0,0,0,0,0,42,0,0,0,0,0,0,0,42,0,0,0,0,0,0,18,23,0,0,0,0,0
0,0,0,0,0,22,18,0,0,0,0,0,0,35,42,42,42,42,42,42,42,35,0,0,0,0,0,0,18,22,0,0,0,0,0
0,0,0,0,5,31,42,0,0,0,0,0,0,0,0,0,0,0,0,0,0,0,0,0,0,0,0,0,42,31,5,0,0,0,0
0,0,0,0,3,3,3,42,0,0,0,0,0,0,0,0,0,0,0,0,0,0,0,0,0,0,0,42,3,3,3,0,0,0,0
0,0,0,3,8,20,0,3,42,0,0,0,0,0,0,0,0,0,0,0,0,0,0,0,0,0,42,3,0,0,0,3,0,0,0
0,0,3,8,8,0,0,0,3,42,42,18,18,42,18,18,42,35,42,18,18,42,18,18,42,42,3,0,0,0,0,0,3,0,0
0,0,3,9,9,7,0,0,3,3,31,21,24,31,21,24,31,3,31,21,24,31,21,24,31,3,3,17,0,7,0,0,18,0,0
0,0,3,0,0,0,0,0,3,0,5,0,0,5,0,0,5,0,5,0,0,5,0,0,5,0,3,8,8,9,0,0,3,0,0
0,0,0,3,0,0,0,3,0,0,0,0,0,0,0,0,0,0,0,0,0,0,0,0,0,0,0,3,8,9,0,3,0,0,0
0,0,0,0,3,18,3,0,0,0,0,0,0,0,0,0,0,0,0,0,0,0,0,0,0,0,0,0,3,3,3,0,0,0,0
0,0,0,0,0,0,0,0,0,0,0,0,0,0,0,0,0,0,0,0,0,0,0,0,0,0,0,0,0,0,0,0,0,0,0
0,0,0,0,0,0,0,0,0,0,0,0,0,0,0,0,0,0,0,0,0,0,0,0,0,0,0,0,0,0,0,0,0,0,0
:endlayer
layer: 16
0,0,0,0,0,0,0,0,0,0,0,0,0,0,0,0,0,0,0,0,0,0,0,0,0,0,0,0,0,0,0,0,0,0,0
0,0,0,0,0,22,11,29,29,11,22,29,29,22,29,29,22,11,22,29,29,22,29,29,22,11,29,29,11,22,0,0,0,0,0
0,0,0,0,24,3,3,3,3,3,3,3,3,3,3,3,3,3,3,3,3,3,3,3,3,3,3,3,3,3,21,0,0,0,0
0,0,0,0,11,3,42,42,42,42,42,42,42,42,42,42,42,35,42,42,42,42,42,42,42,42,42,42,42,3,11,0,0,0,0
0,0,0,0,24,3,42,0,0,0,0,0,0,42,0,0,0,0,0,0,0,42,0,0,0,0,0,0,42,3,21,0,0,0,0
0,0,0,0,29,3,42,0,0,0,0,0,0,42,0,0,0,0,0,0,0,42,0,0,0,0,0,0,42,3,29,0,0,0,0
0,0,0,0,29,3,42,0,0,0,0,0,0,42,0,0,0,0,0,0,0,3,0,0,0,0,0,0,42,3,29,0,0,0,0
0,0,0,0,24,3,42,0,0,0,0,0,0,42,0,0,0,0,0,0,0,42,0,0,0,0,0,0,42,3,21,0,0,0,0
0,0,0,0,29,3,42,0,0,0,0,0,0,42,0,0,0,0,0,0,0,42,0,0,0,0,0,0,42,3,29,0,0,0,0
0,0,0,0,29,3,42,0,0,0,0,0,0,42,0,0,0,0,0,0,0,42,0,0,0,0,0,0,42,3,29,0,0,0,0
0,0,0,0,24,3,42,42,42,42,42,42,42,42,0,0,0,0,0,0,0,42,42,42,42,42,42,42,42,3,21,0,0,0,0
0,0,0,0,29,3,42,0,0,0,0,0,0,42,0,0,0,0,0,0,0,42,0,0,0,0,0,0,42,3,29,0,0,0,0
0,0,0,0,29,3,42,0,0,0,0,0,0,35,42,42,42,42,42,42,42,35,0,0,0,0,0,0,42,3,29,0,0,0,0
0,0,0,0,24,3,42,0,0,0,0,0,0,0,0,0,0,0,0,0,0,0,0,0,0,0,0,0,42,3,21,0,0,0,0
0,0,0,0,3,3,3,42,0,0,0,0,0,0,0,0,0,0,0,0,0,0,0,0,0,0,0,42,3,3,3,0,0,0,0
0,0,0,3,0,9,8,3,42,0,0,0,0,0,0,0,0,0,0,0,0,0,0,0,0,0,42,3,8,20,0,3,0,0,0
0,0,3,0,0,9,8,8,3,42,42,42,42,42,42,42,42,35,42,42,42,42,42,42,42,42,3,8,8,0,0,0,3,0,0
0,0,18,0,0,7,0,16,3,3,3,3,3,3,3,3,3,3,3,3,3,3,3,3,3,3,3,9,9,7,0,0,18,0,0
0,0,3,0,0,0,0,0,3,11,23,29,29,23,29,29,23,11,23,29,29,23,29,29,23,11,3,0,0,0,0,0,3,0,0
0,0,0,3,0,0,0,3,0,0,0,0,0,0,0,0,0,0,0,0,0,0,0,0,0,0,0,3,0,0,0,3,0,0,0
0,0,0,0,3,18,3,0,0,0,0,0,0,0,0,0,0,0,0,0,0,0,0,0,0,0,0,0,3,18,3,0,0,0,0
0,0,0,0,0,0,0,0,0,0,0,0,0,0,0,0,0,0,0,0,0,0,0,0,0,0,0,0,0,0,0,0,0,0,0
0,0,0,0,0,0,0,0,0,0,0,0,0,0,0,0,0,0,0,0,0,0,0,0,0,0,0,0,0,0,0,0,0,0,0
:endlayer
layer: 17
0,0,0,0,0,0,0,0,0,0,0,0,0,0,0,0,0,0,0,0,0,0,0,0,0,0,0,0,0,0,0,0,0,0,0
0,0,0,0,47,48,48,48,48,48,48,48,48,48,48,48,48,48,48,48,48,48,48,48,48,48,48,48,48,48,50,0,0,0,0
0,0,0,0,47,3,3,3,3,3,3,3,3,3,3,3,3,3,3,3,3,3,3,3,3,3,3,3,3,3,50,0,0,0,0
0,0,0,0,47,3,42,42,42,42,42,42,42,42,42,42,42,42,42,42,42,42,42,42,42,42,42,42,42,3,50,0,0,0,0
0,0,0,0,47,3,42,30,30,30,30,30,30,30,30,30,30,30,30,30,30,30,30,30,30,30,30,30,42,3,50,0,0,0,0
0,0,0,0,47,3,42,30,30,30,30,30,30,30,30,30,30,30,30,30,30,3,30,30,30,30,30,30,42,3,50,0,0,0,0
0,0,0,0,47,3,42,30,30,30,30,30,30,30,30,30,30,30,30,30,30,3,30,30,30,30,30,30,42,3,50,0,0,0,0
0,0,0,0,47,3,42,30,30,30,30,30,30,30,30,30,30,30,30,30,30,3,30,30,30,30,30,30,42,3,50,0,0,0,0
0,0,0,0,47,3,42,30,30,30,30,30,30,30,30,30,30,30,30,30,30,30,30,30,30,30,30,30,42,3,50,0,0,0,0
0,0,0,0,47,3,42,30,30,30,30,30,30,30,30,30,30,30,30,30,30,30,30,30,30,30,30,30,42,3,50,0,0,0,0
0,0,0,0,47,3,42,30,30,30,30,30,30,30,30,30,30,30,30,30,30,30,30,30,30,30,30,30,42,3,50,0,0,0,0
0,0,0,0,47,3,42,30,30,30,30,30,30,30,30,30,30,30,30,30,30,30,30,30,30,30,30,30,42,3,50,0,0,0,0
0,0,0,0,47,3,42,30,30,30,30,30,30,30,30,30,30,30,30,30,30,30,30,30,30,30,30,30,42,3,50,0,0,0,0
0,0,0,0,47,3,42,30,30,30,30,30,30,30,30,30,30,30,30,30,30,30,30,30,30,30,30,30,42,3,50,0,0,0,0
0,0,0,0,3,3,3,30,30,30,30,30,30,30,30,30,30,30,30,30,30,30,30,30,30,30,30,30,3,3,3,0,0,0,0
0,0,0,3,0,0,0,9,30,30,30,30,30,30,30,30,30,30,30,30,30,30,30,30,30,30,30,9,0,9,8,3,0,0,0
0,0,3,0,0,0,0,0,3,42,42,42,42,42,42,42,42,42,42,42,42,42,42,42,42,42,3,0,0,9,8,8,3,0,0
0,0,18,0,0,7,9,9,3,3,3,3,3,3,3,3,3,3,3,3,3,3,3,3,3,3,3,0,0,7,0,16,3,0,0
0,0,3,0,0,0,8,8,3,49,49,49,49,49,49,49,49,49,49,49,49,49,49,49,49,49,3,0,0,0,0,0,3,0,0
0,0,0,3,0,6,8,3,0,0,0,0,0,0,0,0,0,0,0,0,0,0,0,0,0,0,0,3,0,0,0,3,0,0,0
0,0,0,0,3,3,3,0,0,0,0,0,0,0,0,0,0,0,0,0,0,0,0,0,0,0,0,0,3,18,3,0,0,0,0
0,0,0,0,0,0,0,0,0,0,0,0,0,0,0,0,0,0,0,0,0,0,0,0,0,0,0,0,0,0,0,0,0,0,0
0,0,0,0,0,0,0,0,0,0,0,0,0,0,0,0,0,0,0,0,0,0,0,0,0,0,0,0,0,0,0,0,0,0,0
:endlayer
layer: 18
0,0,0,0,0,0,0,0,0,0,0,0,0,0,0,0,0,0,0,0,0,0,0,0,0,0,0,0,0,0,0,0,0,0,0
0,0,0,0,0,0,0,0,0,0,6,0,0,6,0,0,6,0,6,0,0,6,0,0,6,0,0,0,0,0,0,0,0,0,0
0,0,0,0,0,48,48,48,48,48,31,48,48,31,48,48,31,48,31,48,48,31,48,48,31,48,48,48,48,48,0,0,0,0,0
0,0,0,0,0,47,3,3,3,3,3,3,3,3,3,3,3,3,3,3,3,3,3,3,3,3,3,3,3,50,0,0,0,0,0
0,0,0,0,0,47,3,0,0,0,0,0,0,0,0,0,0,0,0,0,0,0,0,0,0,0,0,0,3,50,0,0,0,0,0
0,0,0,0,0,47,3,0,0,0,0,0,0,0,0,0,0,0,0,0,0,3,0,0,0,0,0,0,3,50,0,0,0,0,0
0,0,0,0,0,47,3,0,0,34,0,0,0,0,0,0,0,34,0,0,3,3,3,0,0,34,0,0,3,50,0,0,0,0,0
0,0,0,0,16,31,3,0,0,0,0,0,0,0,0,0,0,0,0,0,0,3,0,0,0,0,0,0,3,31,17,0,0,0,0
0,0,0,0,0,47,3,0,0,0,0,0,0,0,0,0,0,0,0,0,0,0,0,0,0,0,0,0,3,50,0,0,0,0,0
0,0,0,0,0,47,3,0,0,0,0,0,0,0,0,0,0,0,0,0,0,0,0,0,0,0,0,0,3,50,0,0,0,0,0
0,0,0,0,16,31,3,0,0,0,0,0,0,0,0,0,0,0,0,0,0,0,0,0,0,0,0,0,3,31,17,0,0,0,0
0,0,0,0,0,47,3,0,0,0,0,0,0,0,0,0,0,0,0,0,0,0,0,0,0,0,0,0,3,50,0,0,0,0,0
0,0,0,0,0,47,3,0,0,0,0,34,0,0,0,0,0,0,34,0,0,3,0,0,0,34,0,0,3,50,0,0,0,0,0
0,0,0,0,0,47,3,19,0,0,0,0,0,0,0,0,0,0,0,0,3,3,3,0,0,0,0,19,3,50,0,0,0,0,0
0,0,0,0,3,3,3,0,0,0,0,0,0,0,0,0,0,0,0,0,0,3,0,0,0,0,0,0,3,3,3,0,0,0,0
0,0,0,3,0,0,0,0,0,19,0,0,0,0,0,0,0,0,0,0,0,0,0,0,0,19,0,0,0,0,0,3,0,0,0
0,0,3,0,0,0,0,0,3,3,3,3,3,3,3,3,3,3,3,3,3,3,3,3,3,3,3,0,0,0,0,0,3,0,0
0,0,3,17,0,7,0,0,3,49,31,49,49,31,49,49,31,49,31,49,49,31,49,49,31,49,3,0,0,7,9,9,3,0,0
0,0,3,8,8,9,0,0,3,0,20,0,0,20,0,0,20,0,20,0,0,20,0,0,20,0,3,0,0,0,8,8,3,0,0
0,0,0,3,8,9,0,3,0,0,0,0,0,0,0,0,0,0,0,0,0,0,0,0,0,0,0,3,0,6,8,3,0,0,0
0,0,0,0,3,3,3,0,0,0,0,0,0,0,0,0,0,0,0,0,0,0,0,0,0,0,0,0,3,3,3,0,0,0,0
0,0,0,0,0,0,0,0,0,0,0,0,0,0,0,0,0,0,0,0,0,0,0,0,0,0,0,0,0,0,0,0,0,0,0
0,0,0,0,0,0,0,0,0,0,0,0,0,0,0,0,0,0,0,0,0,0,0,0,0,0,0,0,0,0,0,0,0,0,0
:endlayer
layer: 19
0,0,0,0,0,0,0,0,0,0,0,0,0,0,0,0,0,0,0,0,0,0,0,0,0,0,0,0,0,0,0,0,0,0,0
0,0,0,0,0,0,0,0,0,0,0,0,0,0,0,0,0,0,0,0,0,0,0,0,0,0,0,0,0,0,0,0,0,0,0
0,0,0,0,0,0,0,0,0,0,19,0,0,19,0,0,19,0,19,0,0,19,0,0,19,0,0,0,0,0,0,0,0,0,0
0,0,0,0,0,0,47,48,48,48,7,18,18,7,18,18,7,48,7,18,18,7,18,18,7,48,48,48,50,0,0,0,0,0,0
0,0,0,0,0,0,47,52,52,52,23,0,0,0,0,0,23,52,23,0,0,0,0,0,23,52,52,52,50,0,0,0,0,0,0
0,0,0,0,0,0,47,51,0,0,0,0,0,0,0,0,0,0,0,0,0,28,0,0,0,0,0,54,50,0,0,0,0,0,0
0,0,0,0,0,0,47,51,0,0,0,0,0,0,0,0,0,0,0,0,25,3,26,0,0,0,0,54,50,0,0,0,0,0,0
0,0,0,0,0,19,7,21,0,0,0,0,0,0,0,0,0,0,0,0,0,27,0,0,0,0,0,24,7,19,0,0,0,0,0
0,0,0,0,0,0,18,0,0,0,0,0,0,0,0,0,0,0,0,0,0,0,0,0,0,0,0,0,18,0,0,0,0,0,0
0,0,0,0,0,0,18,0,0,0,0,0,0,0,0,0,0,0,0,0,0,0,0,0,0,0,0,0,18,0,0,0,0,0,0
0,0,0,0,0,19,7,21,0,0,0,0,0,0,0,0,0,0,0,0,0,0,0,0,0,0,0,24,7,19,0,0,0,0,0
0,0,0,0,0,0,47,51,0,0,0,0,0,0,0,0,0,0,0,0,0,0,0,0,0,0,0,54,50,0,0,0,0,0,0
0,0,0,0,0,0,47,51,0,0,0,0,0,0,0,0,0,0,0,0,0,28,0,0,0,0,0,54,50,0,0,0,0,0,0
0,0,0,0,0,0,47,51,0,0,0,0,0,0,0,0,0,0,0,0,25,3,26,0,0,0,0,54,50,0,0,0,0,0,0
0,0,0,0,3,3,3,0,0,0,0,0,0,0,0,0,0,0,0,0,0,27,0,0,0,0,0,0,3,3,3,0,0,0,0
0,0,0,3,8,20,0,0,0,53,22,0,0,0,0,0,22,53,22,0,0,0,0,0,22,53,0,0,0,0,0,3,0,0,0
0,0,3,8,8,0,0,0,3,49,7,18,18,7,18,18,7,49,7,18,18,7,18,18,7,49,3,0,0,0,0,0,3,0,0
0,0,3,9,9,7,0,0,3,0,19,0,0,19,0,0,19,0,19,0,0,19,0,0,19,0,3,17,0,7,0,0,18,0,0
0,0,3,0,0,0,0,0,3,0,0,0,0,0,0,0,0,0,0,0,0,0,0,0,0,0,3,8,8,9,0,0,3,0,0
0,0,0,3,0,0,0,3,0,0,0,0,0,0,0,0,0,0,0,0,0,0,0,0,0,0,0,3,8,9,0,3,0,0,0
0,0,0,0,3,18,3,0,0,0,0,0,0,0,0,0,0,0,0,0,0,0,0,0,0,0,0,0,3,3,3,0,0,0,0
0,0,0,0,0,0,0,0,0,0,0,0,0,0,0,0,0,0,0,0,0,0,0,0,0,0,0,0,0,0,0,0,0,0,0
0,0,0,0,0,0,0,0,0,0,0,0,0,0,0,0,0,0,0,0,0,0,0,0,0,0,0,0,0,0,0,0,0,0,0
:endlayer
layer: 20
0,0,0,0,0,0,0,0,0,0,0,0,0,0,0,0,0,0,0,0,0,0,0,0,0,0,0,0,0,0,0,0,0,0,0
0,0,0,0,0,0,0,0,0,0,0,0,0,0,0,0,0,0,0,0,0,0,0,0,0,0,0,0,0,0,0,0,0,0,0
0,0,0,0,0,0,0,0,0,0,19,0,0,19,0,0,19,0,19,0,0,19,0,0,19,0,0,0,0,0,0,0,0,0,0
0,0,0,0,0,0,0,0,0,0,7,18,18,7,18,18,7,0,7,18,18,7,18,18,7,0,0,0,0,0,0,0,0,0,0
0,0,0,0,0,0,0,47,48,48,3,0,0,0,0,0,3,48,3,0,0,0,0,0,3,48,48,50,0,0,0,0,0,0,0
0,0,0,0,0,0,0,47,52,52,23,0,0,0,0,0,23,52,23,0,0,0,0,0,23,52,52,50,0,0,0,0,0,0,0
0,0,0,0,0,0,0,47,51,0,0,0,0,0,0,0,0,0,0,0,0,3,0,0,0,0,54,50,0,0,0,0,0,0,0
0,0,0,0,0,19,7,3,21,0,0,0,0,0,0,0,0,0,0,0,0,0,0,0,0,0,24,3,7,19,0,0,0,0,0
0,0,0,0,0,0,18,0,0,0,0,0,0,0,0,0,0,0,0,0,0,0,0,0,0,0,0,0,18,0,0,0,0,0,0
0,0,0,0,0,0,18,0,0,0,0,0,0,0,0,0,0,0,0,0,0,0,0,0,0,0,0,0,18,0,0,0,0,0,0
0,0,0,0,0,19,7,3,21,0,0,0,0,0,0,0,0,0,0,0,0,0,0,0,0,0,24,3,7,19,0,0,0,0,0
0,0,0,0,0,0,0,47,51,0,0,0,0,0,0,0,0,0,0,0,0,0,0,0,0,0,54,50,0,0,0,0,0,0,0
0,0,0,0,0,0,0,47,51,0,0,0,0,0,0,0,0,0,0,0,0,0,0,0,0,0,54,50,0,0,0,0,0,0,0
0,0,0,0,0,0,0,47,51,0,0,0,0,0,0,0,0,0,0,0,0,3,0,0,0,0,54,50,0,0,0,0,0,0,0
0,0,0,0,3,3,3,47,53,53,22,0,0,0,0,0,22,53,22,0,0,0,0,0,22,53,53,50,3,3,3,0,0,0,0
0,0,0,3,0,9,8,3,49,49,3,0,0,0,0,0,3,49,3,0,0,0,0,0,3,49,49,3,8,20,0,3,0,0,0
0,0,3,0,0,9,8,8,3,0,7,18,18,7,18,18,7,0,7,18,18,7,18,18,7,0,3,8,8,0,0,0,3,0,0
0,0,3,0,0,7,0,16,3,0,19,0,0,19,0,0,19,0,19,0,0,19,0,0,19,0,3,9,9,7,0,0,18,0,0
0,0,3,0,0,0,0,0,3,0,0,0,0,0,0,0,0,0,0,0,0,0,0,0,0,0,3,0,0,0,0,0,3,0,0
0,0,0,3,0,0,0,3,0,0,0,0,0,0,0,0,0,0,0,0,0,0,0,0,0,0,0,3,0,0,0,3,0,0,0
0,0,0,0,3,18,3,0,0,0,0,0,0,0,0,0,0,0,0,0,0,0,0,0,0,0,0,0,3,3,3,0,0,0,0
0,0,0,0,0,0,0,0,0,0,0,0,0,0,0,0,0,0,0,0,0,0,0,0,0,0,0,0,0,0,0,0,0,0,0
0,0,0,0,0,0,0,0,0,0,0,0,0,0,0,0,0,0,0,0,0,0,0,0,0,0,0,0,0,0,0,0,0,0,0
:endlayer
layer: 21
0,0,0,0,0,0,0,0,0,0,0,0,0,0,0,0,0,0,0,0,0,0,0,0,0,0,0,0,0,0,0,0,0,0,0
0,0,0,0,0,0,0,0,0,0,0,0,0,0,0,0,0,0,0,0,0,0,0,0,0,0,0,0,0,0,0,0,0,0,0
0,0,0,0,0,0,0,0,0,0,11,29,29,28,29,29,11,0,11,29,29,28,29,29,11,0,0,0,0,0,0,0,0,0,0
0,0,0,0,0,0,0,0,0,0,25,7,7,31,7,7,26,0,25,7,7,31,7,7,26,0,0,0,0,0,0,0,0,0,0
0,0,0,0,0,0,0,0,0,0,47,21,23,29,23,24,50,0,47,21,23,29,23,24,50,0,0,0,0,0,0,0,0,0,0
0,0,0,0,0,0,0,0,48,48,47,21,0,0,0,24,50,48,47,21,0,0,0,24,50,48,48,0,0,0,0,0,0,0,0
0,0,0,0,0,0,0,0,47,21,23,21,0,0,0,23,23,23,23,23,0,3,0,24,23,24,50,0,0,0,0,0,0,0,0
0,0,0,0,0,11,28,48,48,21,0,0,0,0,0,0,0,0,0,0,0,0,0,0,0,24,48,48,28,11,0,0,0,0,0
0,0,0,0,0,29,7,3,3,21,0,0,0,0,0,0,0,0,0,0,0,0,0,0,0,24,3,3,7,29,0,0,0,0,0
0,0,0,0,0,29,7,3,3,21,0,0,0,0,0,0,0,0,0,0,0,0,0,0,0,24,3,3,7,29,0,0,0,0,0
0,0,0,0,0,11,27,49,49,21,0,0,0,0,0,0,0,0,0,0,0,0,0,0,0,24,49,49,27,11,0,0,0,0,0
0,0,0,0,0,0,0,0,47,21,0,0,0,0,0,0,0,0,0,0,0,0,0,0,0,24,50,0,0,0,0,0,0,0,0
0,0,0,0,0,0,0,0,47,21,0,0,0,0,0,0,0,0,0,0,0,0,0,0,0,24,50,0,0,0,0,0,0,0,0
0,0,0,0,0,0,0,0,47,22,22,21,0,0,0,22,22,22,22,22,0,3,0,24,22,22,50,0,0,0,0,0,0,0,0
0,0,0,0,3,3,3,0,49,49,49,21,0,0,0,24,50,49,47,21,0,0,0,24,49,49,49,0,3,3,3,0,0,0,0
0,0,0,3,0,0,0,3,0,0,47,21,22,29,22,24,50,0,47,21,22,29,22,24,50,0,0,3,0,9,8,3,0,0,0
0,0,3,0,0,0,0,0,3,0,25,7,7,31,7,7,26,0,25,7,7,31,7,7,26,0,3,0,0,9,8,8,3,0,0
0,0,3,0,0,7,9,9,3,0,11,29,29,27,29,29,11,0,11,29,29,27,29,29,11,0,3,0,0,7,0,16,3,0,0
0,0,3,0,0,0,8,8,3,0,0,0,0,0,0,0,0,0,0,0,0,0,0,0,0,0,3,0,0,0,0,0,3,0,0
0,0,0,3,0,6,8,3,0,0,0,0,0,0,0,0,0,0,0,0,0,0,0,0,0,0,0,3,0,6,0,3,0,0,0
0,0,0,0,3,3,3,0,0,0,0,0,0,0,0,0,0,0,0,0,0,0,0,0,0,0,0,0,3,3,3,0,0,0,0
0,0,0,0,0,0,0,0,0,0,0,0,0,0,0,0,0,0,0,0,0,0,0,0,0,0,0,0,0,0,0,0,0,0,0
0,0,0,0,0,0,0,0,0,0,0,0,0,0,0,0,0,0,0,0,0,0,0,0,0,0,0,0,0,0,0,0,0,0,0
:endlayer
layer: 22
0,0,0,0,0,0,0,0,0,0,0,0,0,0,0,0,0,0,0,0,0,0,0,0,0,0,0,0,0,0,0,0,0,0,0
0,0,0,0,0,0,0,0,0,0,0,0,0,0,0,0,0,0,0,0,0,0,0,0,0,0,0,0,0,0,0,0,0,0,0
0,0,0,0,0,0,0,0,0,0,0,0,0,0,0,0,0,0,0,0,0,0,0,0,0,0,0,0,0,0,0,0,0,0,0
0,0,0,0,0,0,0,0,0,0,0,11,11,11,11,11,0,0,0,11,11,11,11,11,0,0,0,0,0,0,0,0,0,0,0
0,0,0,0,0,0,0,0,0,0,0,47,48,48,48,50,0,0,0,47,48,48,48,50,0,0,0,0,0,0,0,0,0,0,0
0,0,0,0,0,0,0,0,0,0,0,47,51,52,54,50,0,0,0,47,51,52,54,50,0,0,0,0,0,0,0,0,0,0,0
0,0,0,0,0,0,0,0,0,48,48,47,51,0,54,48,48,48,48,48,51,3,54,50,48,48,0,0,0,0,0,0,0,0,0
0,0,0,0,0,0,0,0,0,47,52,52,52,0,54,52,52,52,52,52,51,0,52,52,52,50,0,0,0,0,0,0,0,0,0
0,0,0,0,0,0,11,48,48,48,51,0,0,0,0,0,0,0,0,0,0,0,0,0,54,48,48,48,11,0,0,0,0,0,0
0,0,0,0,0,0,11,47,49,49,51,0,0,0,0,0,0,0,0,0,0,0,0,0,54,49,49,50,11,0,0,0,0,0,0
0,0,0,0,0,0,0,0,0,47,51,0,0,0,0,0,0,0,0,0,0,0,0,0,54,50,0,0,0,0,0,0,0,0,0
0,0,0,0,0,0,0,0,0,47,51,0,0,0,0,0,0,0,0,0,0,0,0,0,54,50,0,0,0,0,0,0,0,0,0
0,0,0,0,0,0,0,0,0,47,51,53,51,0,53,53,53,53,53,53,53,0,54,53,54,50,0,0,0,0,0,0,0,0,0
0,0,0,0,22,22,22,0,0,49,49,47,51,0,54,50,49,49,49,47,51,3,54,50,49,49,0,0,22,22,22,0,0,0,0
0,0,29,22,3,3,3,22,29,0,0,47,51,53,54,50,0,0,0,47,51,53,54,50,0,0,29,22,3,3,3,22,29,0,0
0,0,24,3,8,20,0,3,21,0,0,47,49,49,49,50,0,0,0,47,49,49,49,50,0,0,24,3,0,0,0,3,21,0,0
0,24,3,8,8,0,0,0,3,21,0,11,11,11,11,11,0,0,0,11,11,11,11,11,0,24,3,0,0,0,0,0,3,21,0
0,24,3,8,8,7,0,0,3,21,0,0,0,0,0,0,0,0,0,0,0,0,0,0,0,24,3,17,0,7,9,9,3,21,0
0,24,3,8,8,9,0,0,3,21,0,0,0,0,0,0,0,0,0,0,0,0,0,0,0,24,3,8,8,8,8,8,3,21,0
0,0,24,3,8,9,0,3,21,0,0,0,0,0,0,0,0,0,0,0,0,0,0,0,0,0,24,3,8,8,8,3,21,0,0
0,0,29,23,3,3,3,23,29,0,0,0,0,0,0,0,0,0,0,0,0,0,0,0,0,0,29,23,3,3,3,23,29,0,0
0,0,0,0,23,23,23,0,0,0,0,0,0,0,0,0,0,0,0,0,0,0,0,0,0,0,0,0,23,23,23,0,0,0,0
0,0,0,0,0,0,0,0,0,0,0,0,0,0,0,0,0,0,0,0,0,0,0,0,0,0,0,0,0,0,0,0,0,0,0
:endlayer
layer: 23
0,0,0,0,0,0,0,0,0,0,0,0,0,0,0,0,0,0,0,0,0,0,0,0,0,0,0,0,0,0,0,0,0,0,0
0,0,0,0,0,0,0,0,0,0,0,0,0,0,0,0,0,0,0,0,0,0,0,0,0,0,0,0,0,0,0,0,0,0,0
0,0,0,0,0,0,0,0,0,0,0,0,0,0,0,0,0,0,0,0,0,0,0,0,0,0,0,0,0,0,0,0,0,0,0
0,0,0,0,0,0,0,0,0,0,0,0,0,0,0,0,0,0,0,0,0,0,0,0,0,0,0,0,0,0,0,0,0,0,0
0,0,0,0,0,0,0,0,0,0,0,0,0,0,0,0,0,0,0,0,0,0,0,0,0,0,0,0,0,0,0,0,0,0,0
0,0,0,0,0,0,0,0,0,0,0,0,47,48,50,0,0,0,0,0,47,48,50,0,0,0,0,0,0,0,0,0,0,0,0
0,0,0,0,0,0,0,0,0,0,0,0,47,30,50,0,0,0,0,0,47,3,50,0,0,0,0,0,0,0,0,0,0,0,0
0,0,0,0,0,0,0,0,0,0,47,48,48,30,50,48,48,48,48,48,47,30,48,48,50,0,0,0,0,0,0,0,0,0,0
0,0,0,0,0,0,0,0,0,0,47,52,52,52,52,52,52,52,52,52,52,52,52,52,50,0,0,0,0,0,0,0,0,0,0
0,0,0,0,0,0,0,0,0,0,47,51,0,0,0,0,0,0,0,0,0,0,0,54,50,0,0,0,0,0,0,0,0,0,0
0,0,0,0,0,0,0,0,0,0,47,51,0,0,0,0,0,0,0,0,0,0,0,54,50,0,0,0,0,0,0,0,0,0,0
0,0,0,0,0,0,0,0,0,0,47,51,53,53,53,53,53,53,53,53,53,53,53,54,50,0,0,0,0,0,0,0,0,0,0
0,0,0,0,0,0,0,0,0,0,47,49,47,30,49,49,49,49,49,49,49,30,50,49,50,0,0,0,0,0,0,0,0,0,0
0,0,0,0,31,28,31,0,0,0,0,0,47,30,50,0,0,0,0,0,47,3,50,0,0,0,0,0,31,28,31,0,0,0,0
0,0,31,3,0,0,0,3,31,0,0,0,47,49,50,0,0,0,0,0,47,49,50,0,0,0,31,3,0,0,0,3,31,0,0
0,0,3,0,19,0,0,0,3,0,0,0,0,0,0,0,0,0,0,0,0,0,0,0,0,0,3,0,0,0,0,0,3,0,0
0,31,0,0,19,0,0,0,0,31,0,0,0,0,0,0,0,0,0,0,0,0,0,0,0,31,0,0,0,0,0,0,0,31,0
0,25,0,0,19,7,0,0,0,26,0,0,0,0,0,0,0,0,0,0,0,0,0,0,0,25,0,0,0,7,0,0,0,26,0
0,31,0,0,0,0,0,0,0,31,0,0,0,0,0,0,0,0,0,0,0,0,0,0,0,31,0,19,19,19,0,0,0,31,0
0,0,3,0,0,0,0,0,3,0,0,0,0,0,0,0,0,0,0,0,0,0,0,0,0,0,3,0,0,0,0,0,3,0,0
0,0,31,3,0,0,0,3,31,0,0,0,0,0,0,0,0,0,0,0,0,0,0,0,0,0,31,3,0,0,0,3,31,0,0
0,0,0,0,31,27,31,0,0,0,0,0,0,0,0,0,0,0,0,0,0,0,0,0,0,0,0,0,31,27,31,0,0,0,0
0,0,0,0,0,0,0,0,0,0,0,0,0,0,0,0,0,0,0,0,0,0,0,0,0,0,0,0,0,0,0,0,0,0,0
:endlayer
layer: 24
0,0,0,0,0,0,0,0,0,0,0,0,0,0,0,0,0,0,0,0,0,0,0,0,0,0,0,0,0,0,0,0,0,0,0
0,0,0,0,0,0,0,0,0,0,0,0,0,0,0,0,0,0,0,0,0,0,0,0,0,0,0,0,0,0,0,0,0,0,0
0,0,0,0,0,0,0,0,0,0,0,0,0,0,0,0,0,0,0,0,0,0,0,0,0,0,0,0,0,0,0,0,0,0,0
0,0,0,0,0,0,0,0,0,0,0,0,0,0,0,0,0,0,0,0,0,0,0,0,0,0,0,0,0,0,0,0,0,0,0
0,0,0,0,0,0,0,0,0,0,0,0,0,0,0,0,0,0,0,0,0,0,0,0,0,0,0,0,0,0,0,0,0,0,0
0,0,0,0,0,0,0,0,0,0,0,0,0,0,0,0,0,0,0,0,0,0,0,0,0,0,0,0,0,0,0,0,0,0,0
0,0,0,0,0,0,0,0,0,0,0,0,0,43,0,0,0,0,0,0,0,3,0,0,0,0,0,0,0,0,0,0,0,0,0
0,0,0,0,0,0,0,0,0,0,0,0,0,43,0,0,0,0,0,0,0,43,0,0,0,0,0,0,0,0,0,0,0,0,0
0,0,0,0,0,0,0,0,0,0,0,47,48,48,48,48,48,48,48,48,48,48,48,50,0,0,0,0,0,0,0,0,0,0,0
0,0,0,0,0,0,0,0,0,0,0,47,51,52,52,52,52,52,52,52,52,52,54,50,0,0,0,0,0,0,0,0,0,0,0
0,0,0,0,0,0,0,0,0,0,0,47,51,53,53,53,53,53,53,53,53,53,54,50,0,0,0,0,0,0,0,0,0,0,0
0,0,0,0,0,0,0,0,0,0,0,49,49,49,49,49,49,49,49,49,49,49,49,49,0,0,0,0,0,0,0,0,0,0,0
0,0,0,0,0,0,0,0,0,0,0,0,0,43,0,0,0,0,0,0,0,43,0,0,0,0,0,0,0,0,0,0,0,0,0
0,0,0,0,7,18,7,0,0,0,0,0,0,43,0,0,0,0,0,0,0,3,0,0,0,0,0,0,7,18,7,0,0,0,0
0,0,7,55,0,0,0,55,7,0,0,0,0,0,0,0,0,0,0,0,0,0,0,0,0,0,7,55,0,0,0,55,7,0,0
0,0,55,0,0,0,0,0,55,0,0,0,0,0,0,0,0,0,0,0,0,0,0,0,0,0,55,0,0,0,0,0,55,0,0
0,7,0,0,0,0,0,0,0,7,0,0,0,0,0,0,0,0,0,0,0,0,0,0,0,7,0,0,0,0,0,0,0,7,0
0,18,0,0,0,7,0,0,0,18,0,0,0,0,0,0,0,0,0,0,0,0,0,0,0,18,0,0,0,7,0,0,0,18,0
0,7,0,0,0,0,0,0,0,7,0,0,0,0,0,0,0,0,0,0,0,0,0,0,0,7,0,0,0,0,0,0,0,7,0
0,0,55,0,0,0,0,0,55,0,0,0,0,0,0,0,0,0,0,0,0,0,0,0,0,0,55,0,0,0,0,0,55,0,0
0,0,7,55,0,0,0,55,7,0,0,0,0,0,0,0,0,0,0,0,0,0,0,0,0,0,7,55,0,0,0,55,7,0,0
0,0,0,0,7,18,7,0,0,0,0,0,0,0,0,0,0,0,0,0,0,0,0,0,0,0,0,0,7,18,7,0,0,0,0
0,0,0,0,0,0,0,0,0,0,0,0,0,0,0,0,0,0,0,0,0,0,0,0,0,0,0,0,0,0,0,0,0,0,0
:endlayer
layer: 25
0,0,0,0,0,0,0,0,0,0,0,0,0,0,0,0,0,0,0,0,0,0,0,0,0,0,0,0,0,0,0,0,0,0,0
0,0,0,0,0,0,0,0,0,0,0,0,0,0,0,0,0,0,0,0,0,0,0,0,0,0,0,0,0,0,0,0,0,0,0
0,0,0,0,0,0,0,0,0,0,0,0,0,0,0,0,0,0,0,0,0,0,0,0,0,0,0,0,0,0,0,0,0,0,0
0,0,0,0,0,0,0,0,0,0,0,0,0,0,0,0,0,0,0,0,0,0,0,0,0,0,0,0,0,0,0,0,0,0,0
0,0,0,0,0,0,0,0,0,0,0,0,0,0,0,0,0,0,0,0,0,0,0,0,0,0,0,0,0,0,0,0,0,0,0
0,0,0,0,0,0,0,0,0,0,0,0,0,0,0,0,0,0,0,0,0,0,0,0,0,0,0,0,0,0,0,0,0,0,0
0,0,0,0,0,0,0,0,0,0,0,0,0,0,0,0,0,0,0,0,0,3,0,0,0,0,0,0,0,0,0,0,0,0,0
0,0,0,0,0,0,0,0,0,0,0,0,0,0,0,0,0,0,0,0,0,0,0,0,0,0,0,0,0,0,0,0,0,0,0
0,0,0,0,0,0,0,0,0,0,0,0,0,0,0,0,0,0,0,0,0,0,0,0,0,0,0,0,0,0,0,0,0,0,0
0,0,0,0,0,0,0,0,0,0,0,0,47,48,48,48,48,48,48,48,48,48,50,0,0,0,0,0,0,0,0,0,0,0,0
0,0,0,0,0,0,0,0,0,0,0,0,47,49,49,49,49,49,49,49,49,49,50,0,0,0,0,0,0,0,0,0,0,0,0
0,0,0,0,0,0,0,0,0,0,0,0,0,0,0,0,0,0,0,0,0,0,0,0,0,0,0,0,0,0,0,0,0,0,0
0,0,0,0,0,0,0,0,0,0,0,0,0,0,0,0,0,0,0,0,0,0,0,0,0,0,0,0,0,0,0,0,0,0,0
0,0,0,0,7,18,7,0,0,0,0,0,0,0,0,0,0,0,0,0,0,3,0,0,0,0,0,0,7,18,7,0,0,0,0
0,0,7,55,0,0,0,55,7,0,0,0,0,0,0,0,0,0,0,0,0,0,0,0,0,0,7,55,0,0,0,55,7,0,0
0,0,55,0,0,0,0,0,55,0,0,0,0,0,0,0,0,0,0,0,0,0,0,0,0,0,55,0,0,0,0,0,55,0,0
0,7,0,0,0,6,0,0,0,7,0,0,0,0,0,0,0,0,0,0,0,0,0,0,0,7,0,0,0,6,0,0,0,7,0
0,18,0,0,16,7,17,0,0,18,0,0,0,0,0,0,0,0,0,0,0,0,0,0,0,18,0,0,16,7,17,0,0,18,0
0,7,0,0,0,20,0,0,0,7,0,0,0,0,0,0,0,0,0,0,0,0,0,0,0,7,0,0,0,20,0,0,0,7,0
0,0,55,0,0,0,0,0,55,0,0,0,0,0,0,0,0,0,0,0,0,0,0,0,0,0,55,0,0,0,0,0,55,0,0
0,0,7,55,0,0,0,55,7,0,0,0,0,0,0,0,0,0,0,0,0,0,0,0,0,0,7,55,0,0,0,55,7,0,0
0,0,0,0,7,18,7,0,0,0,0,0,0,0,0,0,0,0,0,0,0,0,0,0,0,0,0,0,7,18,7,0,0,0,0
0,0,0,0,0,0,0,0,0,0,0,0,0,0,0,0,0,0,0,0,0,0,0,0,0,0,0,0,0,0,0,0,0,0,0
:endlayer
layer: 26
0,0,0,0,0,0,0,0,0,0,0,0,0,0,0,0,0,0,0,0,0,0,0,0,0,0,0,0,0,0,0,0,0,0,0
0,0,0,0,0,0,0,0,0,0,0,0,0,0,0,0,0,0,0,0,0,0,0,0,0,0,0,0,0,0,0,0,0,0,0
0,0,0,0,0,0,0,0,0,0,0,0,0,0,0,0,0,0,0,0,0,0,0,0,0,0,0,0,0,0,0,0,0,0,0
0,0,0,0,0,0,0,0,0,0,0,0,0,0,0,0,0,0,0,0,0,0,0,0,0,0,0,0,0,0,0,0,0,0,0
0,0,0,0,0,0,0,0,0,0,0,0,0,0,0,0,0,0,0,0,0,0,0,0,0,0,0,0,0,0,0,0,0,0,0
0,0,0,0,0,0,0,0,0,0,0,0,0,0,0,0,0,0,0,0,0,0,0,0,0,0,0,0,0,0,0,0,0,0,0
0,0,0,0,0,0,0,0,0,0,0,0,0,0,0,0,0,0,0,0,0,3,0,0,0,0,0,0,0,0,0,0,0,0,0
0,0,0,0,0,0,0,0,0,0,0,0,0,0,0,0,0,0,0,0,0,0,0,0,0,0,0,0,0,0,0,0,0,0,0
0,0,0,0,0,0,0,0,0,0,0,0,0,0,0,0,0,0,0,0,0,0,0,0,0,0,0,0,0,0,0,0,0,0,0
0,0,0,0,0,0,0,0,0,0,0,0,0,0,0,0,0,0,0,0,0,0,0,0,0,0,0,0,0,0,0,0,0,0,0
0,0,0,0,0,0,0,0,0,0,0,0,0,0,0,0,0,0,0,0,0,0,0,0,0,0,0,0,0,0,0,0,0,0,0
0,0,0,0,0,0,0,0,0,0,0,0,0,0,0,0,0,0,0,0,0,0,0,0,0,0,0,0,0,0,0,0,0,0,0
0,0,0,0,0,0,0,0,0,0,0,0,0,0,0,0,0,0,0,0,0,0,0,0,0,0,0,0,0,0,0,0,0,0,0
0,0,0,0,31,22,31,0,0,0,0,0,0,0,0,0,0,0,0,0,0,3,0,0,0,0,0,0,31,22,31,0,0,0,0
0,0,31,3,0,0,0,3,31,0,0,0,0,0,0,0,0,0,0,0,0,0,0,0,0,0,31,3,0,0,0,3,31,0,0
0,0,3,0,0,0,0,0,3,0,0,0,0,0,0,0,0,0,0,0,0,0,0,0,0,0,3,0,0,0,0,0,3,0,0
0,31,0,0,0,0,0,0,0,31,0,0,0,0,0,0,0,0,0,0,0,0,0,0,0,31,0,0,0,0,0,0,0,31,0
0,24,0,0,0,7,0,0,0,21,0,0,0,0,0,0,0,0,0,0,0,0,0,0,0,24,0,0,0,7,0,0,0,21,0
0,31,0,0,0,0,0,0,0,31,0,0,0,0,0,0,0,0,0,0,0,0,0,0,0,31,0,0,0,0,0,0,0,31,0
0,0,3,0,0,0,0,0,3,0,0,0,0,0,0,0,0,0,0,0,0,0,0,0,0,0,3,0,0,0,0,0,3,0,0
0,0,31,3,0,0,0,3,31,0,0,0,0,0,0,0,0,0,0,0,0,0,0,0,0,0,31,3,0,0,0,3,31,0,0
0,0,0,0,31,23,31,0,0,0,0,0,0,0,0,0,0,0,0,0,0,0,0,0,0,0,0,0,31,23,31,0,0,0,0
0,0,0,0,0,0,0,0,0,0,0,0,0,0,0,0,0,0,0,0,0,0,0,0,0,0,0,0,0,0,0,0,0,0,0
:endlayer
layer: 27
0,0,0,0,0,0,0,0,0,0,0,0,0,0,0,0,0,0,0,0,0,0,0,0,0,0,0,0,0,0,0,0,0,0,0
0,0,0,0,0,0,0,0,0,0,0,0,0,0,0,0,0,0,0,0,0,0,0,0,0,0,0,0,0,0,0,0,0,0,0
0,0,0,0,0,0,0,0,0,0,0,0,0,0,0,0,0,0,0,0,0,0,0,0,0,0,0,0,0,0,0,0,0,0,0
0,0,0,0,0,0,0,0,0,0,0,0,0,0,0,0,0,0,0,0,0,0,0,0,0,0,0,0,0,0,0,0,0,0,0
0,0,0,0,0,0,0,0,0,0,0,0,0,0,0,0,0,0,0,0,0,0,0,0,0,0,0,0,0,0,0,0,0,0,0
0,0,0,0,0,0,0,0,0,0,0,0,0,0,0,0,0,0,0,0,0,0,0,0,0,0,0,0,0,0,0,0,0,0,0
0,0,0,0,0,0,0,0,0,0,0,0,0,0,0,0,0,0,0,0,0,5,0,0,0,0,0,0,0,0,0,0,0,0,0
0,0,0,0,0,0,0,0,0,0,0,0,0,0,0,0,0,0,0,0,0,0,0,0,0,0,0,0,0,0,0,0,0,0,0
0,0,0,0,0,0,0,0,0,0,0,0,0,0,0,0,0,0,0,0,0,0,0,0,0,0,0,0,0,0,0,0,0,0,0
0,0,0,0,0,0,0,0,0,0,0,0,0,0,0,0,0,0,0,0,0,0,0,0,0,0,0,0,0,0,0,0,0,0,0
0,0,0,0,0,0,0,0,0,0,0,0,0,0,0,0,0,0,0,0,0,0,0,0,0,0,0,0,0,0,0,0,0,0,0
0,0,0,0,0,0,0,0,0,0,0,0,0,0,0,0,0,0,0,0,0,0,0,0,0,0,0,0,0,0,0,0,0,0,0
0,0,0,0,22,29,22,0,0,0,0,0,0,0,0,0,0,0,0,0,0,0,0,0,0,0,0,0,22,29,22,0,0,0,0
0,0,22,29,3,3,3,29,22,0,0,0,0,0,0,0,0,0,0,0,0,5,0,0,0,0,22,29,3,3,3,29,22,0,0
0,24,3,3,52,52,52,3,3,21,0,0,0,0,0,0,0,0,0,0,0,0,0,0,0,24,3,3,52,52,52,3,3,21,0
0,29,3,56,0,0,0,56,3,29,0,0,0,0,0,0,0,0,0,0,0,0,0,0,0,29,3,56,0,0,0,56,3,29,0
24,3,51,0,0,0,0,0,54,3,21,0,0,0,0,0,0,0,0,0,0,0,0,0,24,3,51,0,0,0,0,0,54,3,21
29,3,51,0,0,7,0,0,54,3,29,0,0,0,0,0,0,0,0,0,0,0,0,0,29,3,51,0,0,7,0,0,54,3,29
24,3,51,0,0,0,0,0,54,3,21,0,0,0,0,0,0,0,0,0,0,0,0,0,24,3,51,0,0,0,0,0,54,3,21
0,29,3,56,0,0,0,56,3,29,0,0,0,0,0,0,0,0,0,0,0,0,0,0,0,29,3,56,0,0,0,56,3,29,0
0,24,3,3,53,53,53,3,3,21,0,0,0,0,0,0,0,0,0,0,0,0,0,0,0,24,3,3,53,53,53,3,3,21,0
0,0,23,29,3,3,3,29,23,0,0,0,0,0,0,0,0,0,0,0,0,0,0,0,0,0,23,29,3,3,3,29,23,0,0
0,0,0,0,23,29,23,0,0,0,0,0,0,0,0,0,0,0,0,0,0,0,0,0,0,0,0,0,23,29,23,0,0,0,0
:endlayer
layer: 28
0,0,0,0,0,0,0,0,0,0,0,0,0,0,0,0,0,0,0,0,0,0,0,0,0,0,0,0,0,0,0,0,0,0,0
0,0,0,0,0,0,0,0,0,0,0,0,0,0,0,0,0,0,0,0,0,0,0,0,0,0,0,0,0,0,0,0,0,0,0
0,0,0,0,0,0,0,0,0,0,0,0,0,0,0,0,0,0,0,0,0,0,0,0,0,0,0,0,0,0,0,0,0,0,0
0,0,0,0,0,0,0,0,0,0,0,0,0,0,0,0,0,0,0,0,0,0,0,0,0,0,0,0,0,0,0,0,0,0,0
0,0,0,0,0,0,0,0,0,0,0,0,0,0,0,0,0,0,0,0,0,0,0,0,0,0,0,0,0,0,0,0,0,0,0
0,0,0,0,0,0,0,0,0,0,0,0,0,0,0,0,0,0,0,0,0,0,0,0,0,0,0,0,0,0,0,0,0,0,0
0,0,0,0,0,0,0,0,0,0,0,0,0,0,0,0,0,0,0,0,0,11,0,0,0,0,0,0,0,0,0,0,0,0,0
0,0,0,0,0,0,0,0,0,0,0,0,0,0,0,0,0,0,0,0,0,0,0,0,0,0,0,0,0,0,0,0,0,0,0
0,0,0,0,0,0,0,0,0,0,0,0,0,0,0,0,0,0,0,0,0,0,0,0,0,0,0,0,0,0,0,0,0,0,0
0,0,0,0,0,0,0,0,0,0,0,0,0,0,0,0,0,0,0,0,0,0,0,0,0,0,0,0,0,0,0,0,0,0,0
0,0,0,0,0,0,0,0,0,0,0,0,0,0,0,0,0,0,0,0,0,0,0,0,0,0,0,0,0,0,0,0,0,0,0
0,0,0,0,0,0,0,0,0,0,0,0,0,0,0,0,0,0,0,0,0,0,0,0,0,0,0,0,0,0,0,0,0,0,0
0,0,0,0,30,30,30,0,0,0,0,0,0,0,0,0,0,0,0,0,0,0,0,0,0,0,0,0,30,30,30,0,0,0,0
0,0,30,30,30,30,30,30,30,0,0,0,0,0,0,0,0,0,0,0,0,11,0,0,0,0,30,30,30,30,30,30,30,0,0
0,30,30,30,49,49,49,30,30,30,0,0,0,0,0,0,0,0,0,0,0,0,0,0,0,30,30,30,49,49,49,30,30,30,0
0,30,30,43,0,0,0,43,30,30,0,0,0,0,0,0,0,0,0,0,0,0,0,0,0,30,30,43,0,0,0,43,30,30,0
30,30,50,0,0,0,0,0,47,30,30,0,0,0,0,0,0,0,0,0,0,0,0,0,30,30,50,0,0,0,0,0,47,30,30
30,30,50,0,0,7,0,0,47,30,30,0,0,0,0,0,0,0,0,0,0,0,0,0,30,30,50,0,0,7,0,0,47,30,30
30,30,50,0,0,0,0,0,47,30,30,0,0,0,0,0,0,0,0,0,0,0,0,0,30,30,50,0,0,0,0,0,47,30,30
0,30,30,43,0,0,0,43,30,30,0,0,0,0,0,0,0,0,0,0,0,0,0,0,0,30,30,43,0,0,0,43,30,30,0
0,30,30,30,48,48,48,30,30,30,0,0,0,0,0,0,0,0,0,0,0,0,0,0,0,30,30,30,48,48,48,30,30,30,0
0,0,30,30,30,30,30,30,30,0,0,0,0,0,0,0,0,0,0,0,0,0,0,0,0,0,30,30,30,30,30,30,30,0,0
0,0,0,0,30,30,30,0,0,0,0,0,0,0,0,0,0,0,0,0,0,0,0,0,0,0,0,0,30,30,30,0,0,0,0
:endlayer
layer: 29
0,0,0,0,0,0,0,0,0,0,0,0,0,0,0,0,0,0,0,0,0,0,0,0,0,0,0,0,0,0,0,0,0,0,0
0,0,0,0,0,0,0,0,0,0,0,0,0,0,0,0,0,0,0,0,0,0,0,0,0,0,0,0,0,0,0,0,0,0,0
0,0,0,0,0,0,0,0,0,0,0,0,0,0,0,0,0,0,0,0,0,0,0,0,0,0,0,0,0,0,0,0,0,0,0
0,0,0,0,0,0,0,0,0,0,0,0,0,0,0,0,0,0,0,0,0,0,0,0,0,0,0,0,0,0,0,0,0,0,0
0,0,0,0,0,0,0,0,0,0,0,0,0,0,0,0,0,0,0,0,0,0,0,0,0,0,0,0,0,0,0,0,0,0,0
0,0,0,0,0,0,0,0,0,0,0,0,0,0,0,0,0,0,0,0,0,0,0,0,0,0,0,0,0,0,0,0,0,0,0
0,0,0,0,0,0,0,0,0,0,0,0,0,0,0,0,0,0,0,0,0,0,0,0,0,0,0,0,0,0,0,0,0,0,0
0,0,0,0,0,0,0,0,0,0,0,0,0,0,0,0,0,0,0,0,0,0,0,0,0,0,0,0,0,0,0,0,0,0,0
0,0,0,0,0,0,0,0,0,0,0,0,0,0,0,0,0,0,0,0,0,0,0,0,0,0,0,0,0,0,0,0,0,0,0
0,0,0,0,0,0,0,0,0,0,0,0,0,0,0,0,0,0,0,0,0,0,0,0,0,0,0,0,0,0,0,0,0,0,0
0,0,0,0,0,0,0,0,0,0,0,0,0,0,0,0,0,0,0,0,0,0,0,0,0,0,0,0,0,0,0,0,0,0,0
0,0,0,0,0,0,0,0,0,0,0,0,0,0,0,0,0,0,0,0,0,0,0,0,0,0,0,0,0,0,0,0,0,0,0
0,0,0,0,47,30,50,0,0,0,0,0,0,0,0,0,0,0,0,0,0,0,0,0,0,0,0,0,47,30,50,0,0,0,0
0,0,47,30,30,30,30,30,50,0,0,0,0,0,0,0,0,0,0,0,0,0,0,0,0,0,47,30,30,30,30,30,50,0,0
0,48,30,30,0,20,0,30,30,48,0,0,0,0,0,0,0,0,0,0,0,0,0,0,0,48,30,30,0,20,0,30,30,48,0
0,30,30,0,0,0,0,0,30,30,0,0,0,0,0,0,0,0,0,0,0,0,0,0,0,30,30,0,0,0,0,0,30,30,0
48,30,0,0,0,0,0,0,0,30,48,0,0,0,0,0,0,0,0,0,0,0,0,0,48,30,0,0,0,0,0,0,0,30,48
30,30,17,0,0,7,0,0,16,30,30,0,0,0,0,0,0,0,0,0,0,0,0,0,30,30,17,0,0,7,0,0,16,30,30
49,30,0,0,0,0,0,0,0,30,49,0,0,0,0,0,0,0,0,0,0,0,0,0,49,30,0,0,0,0,0,0,0,30,49
0,30,30,0,0,0,0,0,30,30,0,0,0,0,0,0,0,0,0,0,0,0,0,0,0,30,30,0,0,0,0,0,30,30,0
0,49,30,30,0,6,0,30,30,49,0,0,0,0,0,0,0,0,0,0,0,0,0,0,0,49,30,30,0,6,0,30,30,49,0
0,0,47,30,30,30,30,30,50,0,0,0,0,0,0,0,0,0,0,0,0,0,0,0,0,0,47,30,30,30,30,30,50,0,0
0,0,0,0,47,30,50,0,0,0,0,0,0,0,0,0,0,0,0,0,0,0,0,0,0,0,0,0,47,30,50,0,0,0,0
:endlayer
layer: 30
0,0,0,0,0,0,0,0,0,0,0,0,0,0,0,0,0,0,0,0,0,0,0,0,0,0,0,0,0,0,0,0,0,0,0
0,0,0,0,0,0,0,0,0,0,0,0,0,0,0,0,0,0,0,0,0,0,0,0,0,0,0,0,0,0,0,0,0,0,0
0,0,0,0,0,0,0,0,0,0,0,0,0,0,0,0,0,0,0,0,0,0,0,0,0,0,0,0,0,0,0,0,0,0,0
0,0,0,0,0,0,0,0,0,0,0,0,0,0,0,0,0,0,0,0,0,0,0,0,0,0,0,0,0,0,0,0,0,0,0
0,0,0,0,0,0,0,0,0,0,0,0,0,0,0,0,0,0,0,0,0,0,0,0,0,0,0,0,0,0,0,0,0,0,0
0,0,0,0,0,0,0,0,0,0,0,0,0,0,0,0,0,0,0,0,0,0,0,0,0,0,0,0,0,0,0,0,0,0,0
0,0,0,0,0,0,0,0,0,0,0,0,0,0,0,0,0,0,0,0,0,0,0,0,0,0,0,0,0,0,0,0,0,0,0
0,0,0,0,0,0,0,0,0,0,0,0,0,0,0,0,0,0,0,0,0,0,0,0,0,0,0,0,0,0,0,0,0,0,0
0,0,0,0,0,0,0,0,0,0,0,0,0,0,0,0,0,0,0,0,0,0,0,0,0,0,0,0,0,0,0,0,0,0,0
0,0,0,0,0,0,0,0,0,0,0,0,0,0,0,0,0,0,0,0,0,0,0,0,0,0,0,0,0,0,0,0,0,0,0
0,0,0,0,0,0,0,0,0,0,0,0,0,0,0,0,0,0,0,0,0,0,0,0,0,0,0,0,0,0,0,0,0,0,0
0,0,0,0,0,0,0,0,0,0,0,0,0,0,0,0,0,0,0,0,0,0,0,0,0,0,0,0,0,0,0,0,0,0,0
0,0,0,0,0,48,0,0,0,0,0,0,0,0,0,0,0,0,0,0,0,0,0,0,0,0,0,0,0,48,0,0,0,0,0
0,0,0,47,30,30,30,50,0,0,0,0,0,0,0,0,0,0,0,0,0,0,0,0,0,0,0,47,30,30,30,50,0,0,0
0,0,43,30,52,52,52,30,43,0,0,0,0,0,0,0,0,0,0,0,0,0,0,0,0,0,43,30,52,52,52,30,43,0,0
0,48,30,56,0,0,0,56,30,48,0,0,0,0,0,0,0,0,0,0,0,0,0,0,0,48,30,56,0,0,0,56,30,48,0
0,30,51,0,0,0,0,0,54,30,0,0,0,0,0,0,0,0,0,0,0,0,0,0,0,30,51,0,0,0,0,0,54,30,0
47,30,51,0,0,7,0,0,54,30,50,0,0,0,0,0,0,0,0,0,0,0,0,0,47,30,51,0,0,7,0,0,54,30,50
0,30,51,0,0,0,0,0,54,30,0,0,0,0,0,0,0,0,0,0,0,0,0,0,0,30,51,0,0,0,0,0,54,30,0
0,49,30,56,0,0,0,56,30,49,0,0,0,0,0,0,0,0,0,0,0,0,0,0,0,49,30,56,0,0,0,56,30,49,0
0,0,43,30,53,53,53,30,43,0,0,0,0,0,0,0,0,0,0,0,0,0,0,0,0,0,43,30,53,53,53,30,43,0,0
0,0,0,47,30,30,30,50,0,0,0,0,0,0,0,0,0,0,0,0,0,0,0,0,0,0,0,47,30,30,30,50,0,0,0
0,0,0,0,0,0,0,0,0,0,0,0,0,0,0,0,0,0,0,0,0,0,0,0,0,0,0,0,0,0,0,0,0,0,0
:endlayer
layer: 31
0,0,0,0,0,0,0,0,0,0,0,0,0,0,0,0,0,0,0,0,0,0,0,0,0,0,0,0,0,0,0,0,0,0,0
0,0,0,0,0,0,0,0,0,0,0,0,0,0,0,0,0,0,0,0,0,0,0,0,0,0,0,0,0,0,0,0,0,0,0
0,0,0,0,0,0,0,0,0,0,0,0,0,0,0,0,0,0,0,0,0,0,0,0,0,0,0,0,0,0,0,0,0,0,0
0,0,0,0,0,0,0,0,0,0,0,0,0,0,0,0,0,0,0,0,0,0,0,0,0,0,0,0,0,0,0,0,0,0,0
0,0,0,0,0,0,0,0,0,0,0,0,0,0,0,0,0,0,0,0,0,0,0,0,0,0,0,0,0,0,0,0,0,0,0
0,0,0,0,0,0,0,0,0,0,0,0,0,0,0,0,0,0,0,0,0,0,0,0,0,0,0,0,0,0,0,0,0,0,0
0,0,0,0,0,0,0,0,0,0,0,0,0,0,0,0,0,0,0,0,0,0,0,0,0,0,0,0,0,0,0,0,0,0,0
0,0,0,0,0,0,0,0,0,0,0,0,0,0,0,0,0,0,0,0,0,0,0,0,0,0,0,0,0,0,0,0,0,0,0
0,0,0,0,0,0,0,0,0,0,0,0,0,0,0,0,0,0,0,0,0,0,0,0,0,0,0,0,0,0,0,0,0,0,0
0,0,0,0,0,0,0,0,0,0,0,0,0,0,0,0,0,0,0,0,0,0,0,0,0,0,0,0,0,0,0,0,0,0,0
0,0,0,0,0,0,0,0,0,0,0,0,0,0,0,0,0,0,0,0,0,0,0,0,0,0,0,0,0,0,0,0,0,0,0
0,0,0,0,0,0,0,0,0,0,0,0,0,0,0,0,0,0,0,0,0,0,0,0,0,0,0,0,0,0,0,0,0,0,0
0,0,0,0,0,0,0,0,0,0,0,0,0,0,0,0,0,0,0,0,0,0,0,0,0,0,0,0,0,0,0,0,0,0,0
0,0,0,0,48,30,48,0,0,0,0,0,0,0,0,0,0,0,0,0,0,0,0,0,0,0,0,0,48,30,48,0,0,0,0
0,0,0,47,30,30,30,50,0,0,0,0,0,0,0,0,0,0,0,0,0,0,0,0,0,0,0,47,30,30,30,50,0,0,0
0,0,48,30,52,52,52,30,48,0,0,0,0,0,0,0,0,0,0,0,0,0,0,0,0,0,48,30,52,52,52,30,48,0,0
0,47,30,51,0,0,0,54,30,50,0,0,0,0,0,0,0,0,0,0,0,0,0,0,0,47,30,51,0,0,0,54,30,50,0
0,30,30,51,0,7,0,54,30,30,0,0,0,0,0,0,0,0,0,0,0,0,0,0,0,30,30,51,0,7,0,54,30,30,0
0,47,30,51,0,0,0,54,30,50,0,0,0,0,0,0,0,0,0,0,0,0,0,0,0,47,30,51,0,0,0,54,30,50,0
0,0,49,30,53,53,53,30,49,0,0,0,0,0,0,0,0,0,0,0,0,0,0,0,0,0,49,30,53,53,53,30,49,0,0
0,0,0,47,30,30,30,50,0,0,0,0,0,0,0,0,0,0,0,0,0,0,0,0,0,0,0,47,30,30,30,50,0,0,0
0,0,0,0,49,30,49,0,0,0,0,0,0,0,0,0,0,0,0,0,0,0,0,0,0,0,0,0,49,30,49,0,0,0,0
0,0,0,0,0,0,0,0,0,0,0,0,0,0,0,0,0,0,0,0,0,0,0,0,0,0,0,0,0,0,0,0,0,0,0
:endlayer
layer: 32
0,0,0,0,0,0,0,0,0,0,0,0,0,0,0,0,0,0,0,0,0,0,0,0,0,0,0,0,0,0,0,0,0,0,0
0,0,0,0,0,0,0,0,0,0,0,0,0,0,0,0,0,0,0,0,0,0,0,0,0,0,0,0,0,0,0,0,0,0,0
0,0,0,0,0,0,0,0,0,0,0,0,0,0,0,0,0,0,0,0,0,0,0,0,0,0,0,0,0,0,0,0,0,0,0
0,0,0,0,0,0,0,0,0,0,0,0,0,0,0,0,0,0,0,0,0,0,0,0,0,0,0,0,0,0,0,0,0,0,0
0,0,0,0,0,0,0,0,0,0,0,0,0,0,0,0,0,0,0,0,0,0,0,0,0,0,0,0,0,0,0,0,0,0,0
0,0,0,0,0,0,0,0,0,0,0,0,0,0,0,0,0,0,0,0,0,0,0,0,0,0,0,0,0,0,0,0,0,0,0
0,0,0,0,0,0,0,0,0,0,0,0,0,0,0,0,0,0,0,0,0,0,0,0,0,0,0,0,0,0,0,0,0,0,0
0,0,0,0,0,0,0,0,0,0,0,0,0,0,0,0,0,0,0,0,0,0,0,0,0,0,0,0,0,0,0,0,0,0,0
0,0,0,0,0,0,0,0,0,0,0,0,0,0,0,0,0,0,0,0,0,0,0,0,0,0,0,0,0,0,0,0,0,0,0
0,0,0,0,0,0,0,0,0,0,0,0,0,0,0,0,0,0,0,0,0,0,0,0,0,0,0,0,0,0,0,0,0,0,0
0,0,0,0,0,0,0,0,0,0,0,0,0,0,0,0,0,0,0,0,0,0,0,0,0,0,0,0,0,0,0,0,0,0,0
0,0,0,0,0,0,0,0,0,0,0,0,0,0,0,0,0,0,0,0,0,0,0,0,0,0,0,0,0,0,0,0,0,0,0
0,0,0,0,0,0,0,0,0,0,0,0,0,0,0,0,0,0,0,0,0,0,0,0,0,0,0,0,0,0,0,0,0,0,0
0,0,0,0,0,48,0,0,0,0,0,0,0,0,0,0,0,0,0,0,0,0,0,0,0,0,0,0,0,48,0,0,0,0,0
0,0,0,0,48,30,48,0,0,0,0,0,0,0,0,0,0,0,0,0,0,0,0,0,0,0,0,0,48,30,48,0,0,0,0
0,0,0,30,30,30,30,30,0,0,0,0,0,0,0,0,0,0,0,0,0,0,0,0,0,0,0,30,30,30,30,30,0,0,0
0,0,47,30,56,0,56,30,50,0,0,0,0,0,0,0,0,0,0,0,0,0,0,0,0,0,47,30,56,0,56,30,50,0,0
0,47,30,30,0,7,0,30,30,50,0,0,0,0,0,0,0,0,0,0,0,0,0,0,0,47,30,30,0,7,0,30,30,50,0
0,0,47,30,56,0,56,30,50,0,0,0,0,0,0,0,0,0,0,0,0,0,0,0,0,0,47,30,56,0,56,30,50,0,0
0,0,0,30,30,30,30,30,0,0,0,0,0,0,0,0,0,0,0,0,0,0,0,0,0,0,0,30,30,30,30,30,0,0,0
0,0,0,0,49,30,49,0,0,0,0,0,0,0,0,0,0,0,0,0,0,0,0,0,0,0,0,0,49,30,49,0,0,0,0
0,0,0,0,0,49,0,0,0,0,0,0,0,0,0,0,0,0,0,0,0,0,0,0,0,0,0,0,0,49,0,0,0,0,0
0,0,0,0,0,0,0,0,0,0,0,0,0,0,0,0,0,0,0,0,0,0,0,0,0,0,0,0,0,0,0,0,0,0,0
:endlayer
layer: 33
0,0,0,0,0,0,0,0,0,0,0,0,0,0,0,0,0,0,0,0,0,0,0,0,0,0,0,0,0,0,0,0,0,0,0
0,0,0,0,0,0,0,0,0,0,0,0,0,0,0,0,0,0,0,0,0,0,0,0,0,0,0,0,0,0,0,0,0,0,0
0,0,0,0,0,0,0,0,0,0,0,0,0,0,0,0,0,0,0,0,0,0,0,0,0,0,0,0,0,0,0,0,0,0,0
0,0,0,0,0,0,0,0,0,0,0,0,0,0,0,0,0,0,0,0,0,0,0,0,0,0,0,0,0,0,0,0,0,0,0
0,0,0,0,0,0,0,0,0,0,0,0,0,0,0,0,0,0,0,0,0,0,0,0,0,0,0,0,0,0,0,0,0,0,0
0,0,0,0,0,0,0,0,0,0,0,0,0,0,0,0,0,0,0,0,0,0,0,0,0,0,0,0,0,0,0,0,0,0,0
0,0,0,0,0,0,0,0,0,0,0,0,0,0,0,0,0,0,0,0,0,0,0,0,0,0,0,0,0,0,0,0,0,0,0
0,0,0,0,0,0,0,0,0,0,0,0,0,0,0,0,0,0,0,0,0,0,0,0,0,0,0,0,0,0,0,0,0,0,0
0,0,0,0,0,0,0,0,0,0,0,0,0,0,0,0,0,0,0,0,0,0,0,0,0,0,0,0,0,0,0,0,0,0,0
0,0,0,0,0,0,0,0,0,0,0,0,0,0,0,0,0,0,0,0,0,0,0,0,0,0,0,0,0,0,0,0,0,0,0
0,0,0,0,0,0,0,0,0,0,0,0,0,0,0,0,0,0,0,0,0,0,0,0,0,0,0,0,0,0,0,0,0,0,0
0,0,0,0,0,0,0,0,0,0,0,0,0,0,0,0,0,0,0,0,0,0,0,0,0,0,0,0,0,0,0,0,0,0,0
0,0,0,0,0,0,0,0,0,0,0,0,0,0,0,0,0,0,0,0,0,0,0,0,0,0,0,0,0,0,0,0,0,0,0
0,0,0,0,0,6,0,0,0,0,0,0,0,0,0,0,0,0,0,0,0,0,0,0,0,0,0,0,0,6,0,0,0,0,0
0,0,0,0,0,30,0,0,0,0,0,0,0,0,0,0,0,0,0,0,0,0,0,0,0,0,0,0,0,30,0,0,0,0,0
0,0,0,0,30,30,30,0,0,0,0,0,0,0,0,0,0,0,0,0,0,0,0,0,0,0,0,0,30,30,30,0,0,0,0
0,0,0,30,30,52,30,30,0,0,0,0,0,0,0,0,0,0,0,0,0,0,0,0,0,0,0,30,30,52,30,30,0,0,0
0,16,30,30,51,7,54,30,30,17,0,0,0,0,0,0,0,0,0,0,0,0,0,0,0,16,30,30,51,7,54,30,30,17,0
0,0,0,30,30,53,30,30,0,0,0,0,0,0,0,0,0,0,0,0,0,0,0,0,0,0,0,30,30,53,30,30,0,0,0
0,0,0,0,30,30,30,0,0,0,0,0,0,0,0,0,0,0,0,0,0,0,0,0,0,0,0,0,30,30,30,0,0,0,0
0,0,0,0,0,30,0,0,0,0,0,0,0,0,0,0,0,0,0,0,0,0,0,0,0,0,0,0,0,30,0,0,0,0,0
0,0,0,0,0,20,0,0,0,0,0,0,0,0,0,0,0,0,0,0,0,0,0,0,0,0,0,0,0,20,0,0,0,0,0
0,0,0,0,0,0,0,0,0,0,0,0,0,0,0,0,0,0,0,0,0,0,0,0,0,0,0,0,0,0,0,0,0,0,0
:endlayer
layer: 34
0,0,0,0,0,0,0,0,0,0,0,0,0,0,0,0,0,0,0,0,0,0,0,0,0,0,0,0,0,0,0,0,0,0,0
0,0,0,0,0,0,0,0,0,0,0,0,0,0,0,0,0,0,0,0,0,0,0,0,0,0,0,0,0,0,0,0,0,0,0
0,0,0,0,0,0,0,0,0,0,0,0,0,0,0,0,0,0,0,0,0,0,0,0,0,0,0,0,0,0,0,0,0,0,0
0,0,0,0,0,0,0,0,0,0,0,0,0,0,0,0,0,0,0,0,0,0,0,0,0,0,0,0,0,0,0,0,0,0,0
0,0,0,0,0,0,0,0,0,0,0,0,0,0,0,0,0,0,0,0,0,0,0,0,0,0,0,0,0,0,0,0,0,0,0
0,0,0,0,0,0,0,0,0,0,0,0,0,0,0,0,0,0,0,0,0,0,0,0,0,0,0,0,0,0,0,0,0,0,0
0,0,0,0,0,0,0,0,0,0,0,0,0,0,0,0,0,0,0,0,0,0,0,0,0,0,0,0,0,0,0,0,0,0,0
0,0,0,0,0,0,0,0,0,0,0,0,0,0,0,0,0,0,0,0,0,0,0,0,0,0,0,0,0,0,0,0,0,0,0
0,0,0,0,0,0,0,0,0,0,0,0,0,0,0,0,0,0,0,0,0,0,0,0,0,0,0,0,0,0,0,0,0,0,0
0,0,0,0,0,0,0,0,0,0,0,0,0,0,0,0,0,0,0,0,0,0,0,0,0,0,0,0,0,0,0,0,0,0,0
0,0,0,0,0,0,0,0,0,0,0,0,0,0,0,0,0,0,0,0,0,0,0,0,0,0,0,0,0,0,0,0,0,0,0
0,0,0,0,0,0,0,0,0,0,0,0,0,0,0,0,0,0,0,0,0,0,0,0,0,0,0,0,0,0,0,0,0,0,0
0,0,0,0,0,0,0,0,0,0,0,0,0,0,0,0,0,0,0,0,0,0,0,0,0,0,0,0,0,0,0,0,0,0,0
0,0,0,0,0,0,0,0,0,0,0,0,0,0,0,0,0,0,0,0,0,0,0,0,0,0,0,0,0,0,0,0,0,0,0
0,0,0,0,0,48,0,0,0,0,0,0,0,0,0,0,0,0,0,0,0,0,0,0,0,0,0,0,0,48,0,0,0,0,0
0,0,0,0,47,30,50,0,0,0,0,0,0,0,0,0,0,0,0,0,0,0,0,0,0,0,0,0,47,30,50,0,0,0,0
0,0,0,48,30,30,30,48,0,0,0,0,0,0,0,0,0,0,0,0,0,0,0,0,0,0,0,48,30,30,30,48,0,0,0
0,0,47,30,30,30,30,30,50,0,0,0,0,0,0,0,0,0,0,0,0,0,0,0,0,0,47,30,30,30,30,30,50,0,0
0,0,0,49,30,30,30,49,0,0,0,0,0,0,0,0,0,0,0,0,0,0,0,0,0,0,0,49,30,30,30,49,0,0,0
0,0,0,0,47,30,50,0,0,0,0,0,0,0,0,0,0,0,0,0,0,0,0,0,0,0,0,0,47,30,50,0,0,0,0
0,0,0,0,0,49,0,0,0,0,0,0,0,0,0,0,0,0,0,0,0,0,0,0,0,0,0,0,0,49,0,0,0,0,0
0,0,0,0,0,0,0,0,0,0,0,0,0,0,0,0,0,0,0,0,0,0,0,0,0,0,0,0,0,0,0,0,0,0,0
0,0,0,0,0,0,0,0,0,0,0,0,0,0,0,0,0,0,0,0,0,0,0,0,0,0,0,0,0,0,0,0,0,0,0
:endlayer
layer: 35
0,0,0,0,0,0,0,0,0,0,0,0,0,0,0,0,0,0,0,0,0,0,0,0,0,0,0,0,0,0,0,0,0,0,0
0,0,0,0,0,0,0,0,0,0,0,0,0,0,0,0,0,0,0,0,0,0,0,0,0,0,0,0,0,0,0,0,0,0,0
0,0,0,0,0,0,0,0,0,0,0,0,0,0,0,0,0,0,0,0,0,0,0,0,0,0,0,0,0,0,0,0,0,0,0
0,0,0,0,0,0,0,0,0,0,0,0,0,0,0,0,0,0,0,0,0,0,0,0,0,0,0,0,0,0,0,0,0,0,0
0,0,0,0,0,0,0,0,0,0,0,0,0,0,0,0,0,0,0,0,0,0,0,0,0,0,0,0,0,0,0,0,0,0,0
0,0,0,0,0,0,0,0,0,0,0,0,0,0,0,0,0,0,0,0,0,0,0,0,0,0,0,0,0,0,0,0,0,0,0
0,0,0,0,0,0,0,0,0,0,0,0,0,0,0,0,0,0,0,0,0,0,0,0,0,0,0,0,0,0,0,0,0,0,0
0,0,0,0,0,0,0,0,0,0,0,0,0,0,0,0,0,0,0,0,0,0,0,0,0,0,0,0,0,0,0,0,0,0,0
0,0,0,0,0,0,0,0,0,0,0,0,0,0,0,0,0,0,0,0,0,0,0,0,0,0,0,0,0,0,0,0,0,0,0
0,0,0,0,0,0,0,0,0,0,0,0,0,0,0,0,0,0,0,0,0,0,0,0,0,0,0,0,0,0,0,0,0,0,0
0,0,0,0,0,0,0,0,0,0,0,0,0,0,0,0,0,0,0,0,0,0,0,0,0,0,0,0,0,0,0,0,0,0,0
0,0,0,0,0,0,0,0,0,0,0,0,0,0,0,0,0,0,0,0,0,0,0,0,0,0,0,0,0,0,0,0,0,0,0
0,0,0,0,0,0,0,0,0,0,0,0,0,0,0,0,0,0,0,0,0,0,0,0,0,0,0,0,0,0,0,0,0,0,0
0,0,0,0,0,0,0,0,0,0,0,0,0,0,0,0,0,0,0,0,0,0,0,0,0,0,0,0,0,0,0,0,0,0,0
0,0,0,0,0,0,0,0,0,0,0,0,0,0,0,0,0,0,0,0,0,0,0,0,0,0,0,0,0,0,0,0,0,0,0
0,0,0,0,0,48,0,0,0,0,0,0,0,0,0,0,0,0,0,0,0,0,0,0,0,0,0,0,0,48,0,0,0,0,0
0,0,0,0,30,30,30,0,0,0,0,0,0,0,0,0,0,0,0,0,0,0,0,0,0,0,0,0,30,30,30,0,0,0,0
0,0,0,47,30,30,30,50,0,0,0,0,0,0,0,0,0,0,0,0,0,0,0,0,0,0,0,47,30,30,30,50,0,0,0
0,0,0,0,30,30,30,0,0,0,0,0,0,0,0,0,0,0,0,0,0,0,0,0,0,0,0,0,30,30,30,0,0,0,0
0,0,0,0,0,49,0,0,0,0,0,0,0,0,0,0,0,0,0,0,0,0,0,0,0,0,0,0,0,49,0,0,0,0,0
0,0,0,0,0,0,0,0,0,0,0,0,0,0,0,0,0,0,0,0,0,0,0,0,0,0,0,0,0,0,0,0,0,0,0
0,0,0,0,0,0,0,0,0,0,0,0,0,0,0,0,0,0,0,0,0,0,0,0,0,0,0,0,0,0,0,0,0,0,0
0,0,0,0,0,0,0,0,0,0,0,0,0,0,0,0,0,0,0,0,0,0,0,0,0,0,0,0,0,0,0,0,0,0,0
:endlayer
layer: 36
0,0,0,0,0,0,0,0,0,0,0,0,0,0,0,0,0,0,0,0,0,0,0,0,0,0,0,0,0,0,0,0,0,0,0
0,0,0,0,0,0,0,0,0,0,0,0,0,0,0,0,0,0,0,0,0,0,0,0,0,0,0,0,0,0,0,0,0,0,0
0,0,0,0,0,0,0,0,0,0,0,0,0,0,0,0,0,0,0,0,0,0,0,0,0,0,0,0,0,0,0,0,0,0,0
0,0,0,0,0,0,0,0,0,0,0,0,0,0,0,0,0,0,0,0,0,0,0,0,0,0,0,0,0,0,0,0,0,0,0
0,0,0,0,0,0,0,0,0,0,0,0,0,0,0,0,0,0,0,0,0,0,0,0,0,0,0,0,0,0,0,0,0,0,0
0,0,0,0,0,0,0,0,0,0,0,0,0,0,0,0,0,0,0,0,0,0,0,0,0,0,0,0,0,0,0,0,0,0,0
0,0,0,0,0,0,0,0,0,0,0,0,0,0,0,0,0,0,0,0,0,0,0,0,0,0,0,0,0,0,0,0,0,0,0
0,0,0,0,0,0,0,0,0,0,0,0,0,0,0,0,0,0,0,0,0,0,0,0,0,0,0,0,0,0,0,0,0,0,0
0,0,0,0,0,0,0,0,0,0,0,0,0,0,0,0,0,0,0,0,0,0,0,0,0,0,0,0,0,0,0,0,0,0,0
0,0,0,0,0,0,0,0,0,0,0,0,0,0,0,0,0,0,0,0,0,0,0,0,0,0,0,0,0,0,0,0,0,0,0
0,0,0,0,0,0,0,0,0,0,0,0,0,0,0,0,0,0,0,0,0,0,0,0,0,0,0,0,0,0,0,0,0,0,0
0,0,0,0,0,0,0,0,0,0,0,0,0,0,0,0,0,0,0,0,0,0,0,0,0,0,0,0,0,0,0,0,0,0,0
0,0,0,0,0,0,0,0,0,0,0,0,0,0,0,0,0,0,0,0,0,0,0,0,0,0,0,0,0,0,0,0,0,0,0
0,0,0,0,0,0,0,0,0,0,0,0,0,0,0,0,0,0,0,0,0,0,0,0,0,0,0,0,0,0,0,0,0,0,0
0,0,0,0,0,0,0,0,0,0,0,0,0,0,0,0,0,0,0,0,0,0,0,0,0,0,0,0,0,0,0,0,0,0,0
0,0,0,0,0,0,0,0,0,0,0,0,0,0,0,0,0,0,0,0,0,0,0,0,0,0,0,0,0,0,0,0,0,0,0
0,0,0,0,43,30,43,0,0,0,0,0,0,0,0,0,0,0,0,0,0,0,0,0,0,0,0,0,43,30,43,0,0,0,0
0,0,0,0,30,30,30,0,0,0,0,0,0,0,0,0,0,0,0,0,0,0,0,0,0,0,0,0,30,30,30,0,0,0,0
0,0,0,0,43,30,43,0,0,0,0,0,0,0,0,0,0,0,0,0,0,0,0,0,0,0,0,0,43,30,43,0,0,0,0
0,0,0,0,0,0,0,0,0,0,0,0,0,0,0,0,0,0,0,0,0,0,0,0,0,0,0,0,0,0,0,0,0,0,0
0,0,0,0,0,0,0,0,0,0,0,0,0,0,0,0,0,0,0,0,0,0,0,0,0,0,0,0,0,0,0,0,0,0,0
0,0,0,0,0,0,0,0,0,0,0,0,0,0,0,0,0,0,0,0,0,0,0,0,0,0,0,0,0,0,0,0,0,0,0
0,0,0,0,0,0,0,0,0,0,0,0,0,0,0,0,0,0,0,0,0,0,0,0,0,0,0,0,0,0,0,0,0,0,0
:endlayer
layer: 37
0,0,0,0,0,0,0,0,0,0,0,0,0,0,0,0,0,0,0,0,0,0,0,0,0,0,0,0,0,0,0,0,0,0,0
0,0,0,0,0,0,0,0,0,0,0,0,0,0,0,0,0,0,0,0,0,0,0,0,0,0,0,0,0,0,0,0,0,0,0
0,0,0,0,0,0,0,0,0,0,0,0,0,0,0,0,0,0,0,0,0,0,0,0,0,0,0,0,0,0,0,0,0,0,0
0,0,0,0,0,0,0,0,0,0,0,0,0,0,0,0,0,0,0,0,0,0,0,0,0,0,0,0,0,0,0,0,0,0,0
0,0,0,0,0,0,0,0,0,0,0,0,0,0,0,0,0,0,0,0,0,0,0,0,0,0,0,0,0,0,0,0,0,0,0
0,0,0,0,0,0,0,0,0,0,0,0,0,0,0,0,0,0,0,0,0,0,0,0,0,0,0,0,0,0,0,0,0,0,0
0,0,0,0,0,0,0,0,0,0,0,0,0,0,0,0,0,0,0,0,0,0,0,0,0,0,0,0,0,0,0,0,0,0,0
0,0,0,0,0,0,0,0,0,0,0,0,0,0,0,0,0,0,0,0,0,0,0,0,0,0,0,0,0,0,0,0,0,0,0
0,0,0,0,0,0,0,0,0,0,0,0,0,0,0,0,0,0,0,0,0,0,0,0,0,0,0,0,0,0,0,0,0,0,0
0,0,0,0,0,0,0,0,0,0,0,0,0,0,0,0,0,0,0,0,0,0,0,0,0,0,0,0,0,0,0,0,0,0,0
0,0,0,0,0,0,0,0,0,0,0,0,0,0,0,0,0,0,0,0,0,0,0,0,0,0,0,0,0,0,0,0,0,0,0
0,0,0,0,0,0,0,0,0,0,0,0,0,0,0,0,0,0,0,0,0,0,0,0,0,0,0,0,0,0,0,0,0,0,0
0,0,0,0,0,0,0,0,0,0,0,0,0,0,0,0,0,0,0,0,0,0,0,0,0,0,0,0,0,0,0,0,0,0,0
0,0,0,0,0,0,0,0,0,0,0,0,0,0,0,0,0,0,0,0,0,0,0,0,0,0,0,0,0,0,0,0,0,0,0
0,0,0,0,0,0,0,0,0,0,0,0,0,0,0,0,0,0,0,0,0,0,0,0,0,0,0,0,0,0,0,0,0,0,0
0,0,0,0,0,0,0,0,0,0,0,0,0,0,0,0,0,0,0,0,0,0,0,0,0,0,0,0,0,0,0,0,0,0,0
0,0,0,0,0,48,0,0,0,0,0,0,0,0,0,0,0,0,0,0,0,0,0,0,0,0,0,0,0,48,0,0,0,0,0
0,0,0,0,47,30,50,0,0,0,0,0,0,0,0,0,0,0,0,0,0,0,0,0,0,0,0,0,47,30,50,0,0,0,0
0,0,0,0,0,49,0,0,0,0,0,0,0,0,0,0,0,0,0,0,0,0,0,0,0,0,0,0,0,49,0,0,0,0,0
0,0,0,0,0,0,0,0,0,0,0,0,0,0,0,0,0,0,0,0,0,0,0,0,0,0,0,0,0,0,0,0,0,0,0
0,0,0,0,0,0,0,0,0,0,0,0,0,0,0,0,0,0,0,0,0,0,0,0,0,0,0,0,0,0,0,0,0,0,0
0,0,0,0,0,0,0,0,0,0,0,0,0,0,0,0,0,0,0,0,0,0,0,0,0,0,0,0,0,0,0,0,0,0,0
0,0,0,0,0,0,0,0,0,0,0,0,0,0,0,0,0,0,0,0,0,0,0,0,0,0,0,0,0,0,0,0,0,0,0
:endlayer
layer: 38
0,0,0,0,0,0,0,0,0,0,0,0,0,0,0,0,0,0,0,0,0,0,0,0,0,0,0,0,0,0,0,0,0,0,0
0,0,0,0,0,0,0,0,0,0,0,0,0,0,0,0,0,0,0,0,0,0,0,0,0,0,0,0,0,0,0,0,0,0,0
0,0,0,0,0,0,0,0,0,0,0,0,0,0,0,0,0,0,0,0,0,0,0,0,0,0,0,0,0,0,0,0,0,0,0
0,0,0,0,0,0,0,0,0,0,0,0,0,0,0,0,0,0,0,0,0,0,0,0,0,0,0,0,0,0,0,0,0,0,0
0,0,0,0,0,0,0,0,0,0,0,0,0,0,0,0,0,0,0,0,0,0,0,0,0,0,0,0,0,0,0,0,0,0,0
0,0,0,0,0,0,0,0,0,0,0,0,0,0,0,0,0,0,0,0,0,0,0,0,0,0,0,0,0,0,0,0,0,0,0
0,0,0,0,0,0,0,0,0,0,0,0,0,0,0,0,0,0,0,0,0,0,0,0,0,0,0,0,0,0,0,0,0,0,0
0,0,0,0,0,0,0,0,0,0,0,0,0,0,0,0,0,0,0,0,0,0,0,0,0,0,0,0,0,0,0,0,0,0,0
0,0,0,0,0,0,0,0,0,0,0,0,0,0,0,0,0,0,0,0,0,0,0,0,0,0,0,0,0,0,0,0,0,0,0
0,0,0,0,0,0,0,0,0,0,0,0,0,0,0,0,0,0,0,0,0,0,0,0,0,0,0,0,0,0,0,0,0,0,0
0,0,0,0,0,0,0,0,0,0,0,0,0,0,0,0,0,0,0,0,0,0,0,0,0,0,0,0,0,0,0,0,0,0,0
0,0,0,0,0,0,0,0,0,0,0,0,0,0,0,0,0,0,0,0,0,0,0,0,0,0,0,0,0,0,0,0,0,0,0
0,0,0,0,0,0,0,0,0,0,0,0,0,0,0,0,0,0,0,0,0,0,0,0,0,0,0,0,0,0,0,0,0,0,0
0,0,0,0,0,0,0,0,0,0,0,0,0,0,0,0,0,0,0,0,0,0,0,0,0,0,0,0,0,0,0,0,0,0,0
0,0,0,0,0,0,0,0,0,0,0,0,0,0,0,0,0,0,0,0,0,0,0,0,0,0,0,0,0,0,0,0,0,0,0
0,0,0,0,0,0,0,0,0,0,0,0,0,0,0,0,0,0,0,0,0,0,0,0,0,0,0,0,0,0,0,0,0,0,0
0,0,0,0,0,0,0,0,0,0,0,0,0,0,0,0,0,0,0,0,0,0,0,0,0,0,0,0,0,0,0,0,0,0,0
0,0,0,0,0,30,0,0,0,0,0,0,0,0,0,0,0,0,0,0,0,0,0,0,0,0,0,0,0,30,0,0,0,0,0
0,0,0,0,0,0,0,0,0,0,0,0,0,0,0,0,0,0,0,0,0,0,0,0,0,0,0,0,0,0,0,0,0,0,0
0,0,0,0,0,0,0,0,0,0,0,0,0,0,0,0,0,0,0,0,0,0,0,0,0,0,0,0,0,0,0,0,0,0,0
0,0,0,0,0,0,0,0,0,0,0,0,0,0,0,0,0,0,0,0,0,0,0,0,0,0,0,0,0,0,0,0,0,0,0
0,0,0,0,0,0,0,0,0,0,0,0,0,0,0,0,0,0,0,0,0,0,0,0,0,0,0,0,0,0,0,0,0,0,0
0,0,0,0,0,0,0,0,0,0,0,0,0,0,0,0,0,0,0,0,0,0,0,0,0,0,0,0,0,0,0,0,0,0,0
:endlayer
layer: 39
0,0,0,0,0,0,0,0,0,0,0,0,0,0,0,0,0,0,0,0,0,0,0,0,0,0,0,0,0,0,0,0,0,0,0
0,0,0,0,0,0,0,0,0,0,0,0,0,0,0,0,0,0,0,0,0,0,0,0,0,0,0,0,0,0,0,0,0,0,0
0,0,0,0,0,0,0,0,0,0,0,0,0,0,0,0,0,0,0,0,0,0,0,0,0,0,0,0,0,0,0,0,0,0,0
0,0,0,0,0,0,0,0,0,0,0,0,0,0,0,0,0,0,0,0,0,0,0,0,0,0,0,0,0,0,0,0,0,0,0
0,0,0,0,0,0,0,0,0,0,0,0,0,0,0,0,0,0,0,0,0,0,0,0,0,0,0,0,0,0,0,0,0,0,0
0,0,0,0,0,0,0,0,0,0,0,0,0,0,0,0,0,0,0,0,0,0,0,0,0,0,0,0,0,0,0,0,0,0,0
0,0,0,0,0,0,0,0,0,0,0,0,0,0,0,0,0,0,0,0,0,0,0,0,0,0,0,0,0,0,0,0,0,0,0
0,0,0,0,0,0,0,0,0,0,0,0,0,0,0,0,0,0,0,0,0,0,0,0,0,0,0,0,0,0,0,0,0,0,0
0,0,0,0,0,0,0,0,0,0,0,0,0,0,0,0,0,0,0,0,0,0,0,0,0,0,0,0,0,0,0,0,0,0,0
0,0,0,0,0,0,0,0,0,0,0,0,0,0,0,0,0,0,0,0,0,0,0,0,0,0,0,0,0,0,0,0,0,0,0
0,0,0,0,0,0,0,0,0,0,0,0,0,0,0,0,0,0,0,0,0,0,0,0,0,0,0,0,0,0,0,0,0,0,0
0,0,0,0,0,0,0,0,0,0,0,0,0,0,0,0,0,0,0,0,0,0,0,0,0,0,0,0,0,0,0,0,0,0,0
0,0,0,0,0,0,0,0,0,0,0,0,0,0,0,0,0,0,0,0,0,0,0,0,0,0,0,0,0,0,0,0,0,0,0
0,0,0,0,0,0,0,0,0,0,0,0,0,0,0,0,0,0,0,0,0,0,0,0,0,0,0,0,0,0,0,0,0,0,0
0,0,0,0,0,0,0,0,0,0,0,0,0,0,0,0,0,0,0,0,0,0,0,0,0,0,0,0,0,0,0,0,0,0,0
0,0,0,0,0,0,0,0,0,0,0,0,0,0,0,0,0,0,0,0,0,0,0,0,0,0,0,0,0,0,0,0,0,0,0
0,0,0,0,0,0,0,0,0,0,0,0,0,0,0,0,0,0,0,0,0,0,0,0,0,0,0,0,0,0,0,0,0,0,0
0,0,0,0,0,43,0,0,0,0,0,0,0,0,0,0,0,0,0,0,0,0,0,0,0,0,0,0,0,43,0,0,0,0,0
0,0,0,0,0,0,0,0,0,0,0,0,0,0,0,0,0,0,0,0,0,0,0,0,0,0,0,0,0,0,0,0,0,0,0
0,0,0,0,0,0,0,0,0,0,0,0,0,0,0,0,0,0,0,0,0,0,0,0,0,0,0,0,0,0,0,0,0,0,0
0,0,0,0,0,0,0,0,0,0,0,0,0,0,0,0,0,0,0,0,0,0,0,0,0,0,0,0,0,0,0,0,0,0,0
0,0,0,0,0,0,0,0,0,0,0,0,0,0,0,0,0,0,0,0,0,0,0,0,0,0,0,0,0,0,0,0,0,0,0
0,0,0,0,0,0,0,0,0,0,0,0,0,0,0,0,0,0,0,0,0,0,0,0,0,0,0,0,0,0,0,0,0,0,0
:endlayer

#### RULES ####
rule:
plugin=vanillaBlocks
number=1
data:
JSON:{blockState:{blockName:"minecraft:grass",properties:{snowy:"false"}}}
:enddata
:endrule

rule:
plugin=vanillaBlocks
number=2
data:
JSON:{blockState:{blockName:"minecraft:cobblestone"}}
:enddata
:endrule

rule:
plugin=vanillaBlocks
number=3
data:
JSON:{blockState:{blockName:"minecraft:stonebrick",properties:{variant:"stonebrick"}}}
:enddata
:endrule

rule:
plugin=vanillaBlocks
number=4
data:
JSON:{blockState:{blockName:"minecraft:stone",properties:{variant:"smooth_andesite"}}}
:enddata
:endrule

rule:
plugin=vanillaBlocks
number=5
data:
JSON:{blockState:{blockName:"minecraft:cobblestone_wall",properties:{east:"false",south:"false",north:"false",variant:"cobblestone",west:"false",up:"false"}}}
:enddata
:endrule

rule:
plugin=vanillaBlocks
number=6
data:
JSON:{blockState:{blockName:"minecraft:torch",properties:{facing:"north"}}}
:enddata
:endrule

rule:
plugin=vanillaBlocks
number=7
data:
JSON:{blockState:{blockName:"minecraft:stone",properties:{variant:"andesite"}}}
:enddata
:endrule

rule:
plugin=vanillaBlocks
number=8
data:
JSON:{blockState:{blockName:"minecraft:stone_slab",properties:{half:"top",variant:"cobblestone"}}}
:enddata
:endrule

rule:
plugin=vanillaBlocks
number=9
data:
JSON:{blockState:{blockName:"minecraft:stone_slab",properties:{half:"bottom",variant:"cobblestone"}}}
:enddata
:endrule

rule:
plugin=vanillaBlocks
number=10
data:
JSON:{blockState:{blockName:"minecraft:brick_stairs",properties:{half:"bottom",shape:"straight",facing:"east"}}}
:enddata
:endrule

rule:
plugin=vanillaBlocks
number=11
data:
JSON:{blockState:{blockName:"minecraft:stone_slab",properties:{half:"bottom",variant:"stone_brick"}}}
:enddata
:endrule

rule:
plugin=vanillaBlocks
number=12
data:
JSON:{blockState:{blockName:"minecraft:brick_stairs",properties:{half:"top",shape:"straight",facing:"west"}}}
:enddata
:endrule

rule:
plugin=vanillaBlocks
number=13
data:
JSON:{blockState:{blockName:"ancientwarfarestructure:fire_pit",properties:{lit:"true",variant:"log"}}}
:enddata
:endrule

rule:
plugin=vanillaBlocks
number=14
data:
JSON:{blockState:{blockName:"minecraft:brick_stairs",properties:{half:"top",shape:"straight",facing:"east"}}}
:enddata
:endrule

rule:
plugin=vanillaBlocks
number=15
data:
JSON:{blockState:{blockName:"minecraft:brick_stairs",properties:{half:"bottom",shape:"straight",facing:"west"}}}
:enddata
:endrule

rule:
plugin=vanillaBlocks
number=16
data:
JSON:{blockState:{blockName:"minecraft:torch",properties:{facing:"west"}}}
:enddata
:endrule

rule:
plugin=vanillaBlocks
number=17
data:
JSON:{blockState:{blockName:"minecraft:torch",properties:{facing:"east"}}}
:enddata
:endrule

rule:
plugin=vanillaBlocks
number=18
data:
JSON:{blockState:{blockName:"minecraft:glass_pane",properties:{east:"false",south:"false",north:"false",west:"false"}}}
:enddata
:endrule

rule:
plugin=vanillaBlocks
number=19
data:
JSON:{blockState:{blockName:"minecraft:dark_oak_fence",properties:{east:"false",south:"false",north:"false",west:"false"}}}
:enddata
:endrule

rule:
plugin=vanillaBlocks
number=20
data:
JSON:{blockState:{blockName:"minecraft:torch",properties:{facing:"south"}}}
:enddata
:endrule

rule:
plugin=vanillaBlocks
number=21
data:
JSON:{blockState:{blockName:"minecraft:stone_brick_stairs",properties:{half:"top",shape:"straight",facing:"west"}}}
:enddata
:endrule

rule:
plugin=vanillaBlocks
number=22
data:
JSON:{blockState:{blockName:"minecraft:stone_brick_stairs",properties:{half:"top",shape:"straight",facing:"south"}}}
:enddata
:endrule

rule:
plugin=vanillaBlocks
number=23
data:
JSON:{blockState:{blockName:"minecraft:stone_brick_stairs",properties:{half:"top",shape:"straight",facing:"north"}}}
:enddata
:endrule

rule:
plugin=vanillaBlocks
number=24
data:
JSON:{blockState:{blockName:"minecraft:stone_brick_stairs",properties:{half:"top",shape:"straight",facing:"east"}}}
:enddata
:endrule

rule:
plugin=vanillaBlocks
number=25
data:
JSON:{blockState:{blockName:"minecraft:stone_brick_stairs",properties:{half:"bottom",shape:"straight",facing:"east"}}}
:enddata
:endrule

rule:
plugin=vanillaBlocks
number=26
data:
JSON:{blockState:{blockName:"minecraft:stone_brick_stairs",properties:{half:"bottom",shape:"straight",facing:"west"}}}
:enddata
:endrule

rule:
plugin=vanillaBlocks
number=27
data:
JSON:{blockState:{blockName:"minecraft:stone_brick_stairs",properties:{half:"bottom",shape:"straight",facing:"north"}}}
:enddata
:endrule

rule:
plugin=vanillaBlocks
number=28
data:
JSON:{blockState:{blockName:"minecraft:stone_brick_stairs",properties:{half:"bottom",shape:"straight",facing:"south"}}}
:enddata
:endrule

rule:
plugin=vanillaBlocks
number=29
data:
JSON:{blockState:{blockName:"minecraft:stone_slab",properties:{half:"top",variant:"stone_brick"}}}
:enddata
:endrule

rule:
plugin=vanillaBlocks
number=30
data:
JSON:{blockState:{blockName:"minecraft:planks",properties:{variant:"spruce"}}}
:enddata
:endrule

rule:
plugin=vanillaBlocks
number=31
data:
JSON:{blockState:{blockName:"minecraft:stonebrick",properties:{variant:"chiseled_stonebrick"}}}
:enddata
:endrule

rule:
plugin=vanillaBlocks
number=32
data:
JSON:{blockState:{blockName:"minecraft:brick_block"}}
:enddata
:endrule

rule:
plugin=vanillaBlocks
number=33
data:
JSON:{blockState:{blockName:"minecraft:stained_hardened_clay",properties:{color:"red"}}}
:enddata
:endrule

rule:
plugin=vanillaBlocks
number=34
data:
JSON:{blockState:{blockName:"minecraft:torch",properties:{facing:"up"}}}
:enddata
:endrule

rule:
plugin=vanillaBlocks
number=35
data:
JSON:{blockState:{blockName:"minecraft:quartz_block",properties:{variant:"lines_y"}}}
:enddata
:endrule

rule:
plugin=vanillaBlocks
number=36
data:
JSON:{blockState:{blockName:"minecraft:stained_glass_pane",properties:{east:"false",color:"yellow",south:"false",north:"false",west:"false"}}}
:enddata
:endrule

rule:
plugin=vanillaBlocks
number=37
data:
JSON:{blockState:{blockName:"minecraft:stained_glass_pane",properties:{east:"false",color:"blue",south:"false",north:"false",west:"false"}}}
:enddata
:endrule

rule:
plugin=vanillaBlocks
number=38
data:
JSON:{blockState:{blockName:"minecraft:stained_glass_pane",properties:{east:"false",color:"green",south:"false",north:"false",west:"false"}}}
:enddata
:endrule

rule:
plugin=vanillaBlocks
number=39
data:
JSON:{blockState:{blockName:"minecraft:quartz_stairs",properties:{half:"top",shape:"straight",facing:"south"}}}
:enddata
:endrule

rule:
plugin=vanillaBlocks
number=40
data:
JSON:{blockState:{blockName:"minecraft:quartz_stairs",properties:{half:"top",shape:"straight",facing:"north"}}}
:enddata
:endrule

rule:
plugin=vanillaBlocks
number=41
data:
JSON:{blockState:{blockName:"minecraft:quartz_block",properties:{variant:"lines_x"}}}
:enddata
:endrule

rule:
plugin=vanillaBlocks
number=42
data:
JSON:{blockState:{blockName:"minecraft:stained_hardened_clay",properties:{color:"pink"}}}
:enddata
:endrule

rule:
plugin=vanillaBlocks
number=43
data:
JSON:{blockState:{blockName:"minecraft:wooden_slab",properties:{half:"bottom",variant:"spruce"}}}
:enddata
:endrule

rule:
plugin=vanillaBlocks
number=44
data:
JSON:{blockState:{blockName:"minecraft:quartz_stairs",properties:{half:"top",shape:"straight",facing:"west"}}}
:enddata
:endrule

rule:
plugin=vanillaBlocks
number=45
data:
JSON:{blockState:{blockName:"minecraft:quartz_stairs",properties:{half:"top",shape:"straight",facing:"east"}}}
:enddata
:endrule

rule:
plugin=vanillaBlocks
number=46
data:
JSON:{blockState:{blockName:"minecraft:quartz_block",properties:{variant:"lines_z"}}}
:enddata
:endrule

rule:
plugin=vanillaBlocks
number=47
data:
JSON:{blockState:{blockName:"minecraft:spruce_stairs",properties:{half:"bottom",shape:"straight",facing:"east"}}}
:enddata
:endrule

rule:
plugin=vanillaBlocks
number=48
data:
JSON:{blockState:{blockName:"minecraft:spruce_stairs",properties:{half:"bottom",shape:"straight",facing:"south"}}}
:enddata
:endrule

rule:
plugin=vanillaBlocks
number=49
data:
JSON:{blockState:{blockName:"minecraft:spruce_stairs",properties:{half:"bottom",shape:"straight",facing:"north"}}}
:enddata
:endrule

rule:
plugin=vanillaBlocks
number=50
data:
JSON:{blockState:{blockName:"minecraft:spruce_stairs",properties:{half:"bottom",shape:"straight",facing:"west"}}}
:enddata
:endrule

rule:
plugin=vanillaBlocks
number=51
data:
JSON:{blockState:{blockName:"minecraft:spruce_stairs",properties:{half:"top",shape:"straight",facing:"west"}}}
:enddata
:endrule

rule:
plugin=vanillaBlocks
number=52
data:
JSON:{blockState:{blockName:"minecraft:spruce_stairs",properties:{half:"top",shape:"straight",facing:"north"}}}
:enddata
:endrule

rule:
plugin=vanillaBlocks
number=53
data:
JSON:{blockState:{blockName:"minecraft:spruce_stairs",properties:{half:"top",shape:"straight",facing:"south"}}}
:enddata
:endrule

rule:
plugin=vanillaBlocks
number=54
data:
JSON:{blockState:{blockName:"minecraft:spruce_stairs",properties:{half:"top",shape:"straight",facing:"east"}}}
:enddata
:endrule

rule:
plugin=vanillaBlocks
number=55
data:
JSON:{blockState:{blockName:"minecraft:glass"}}
:enddata
:endrule

rule:
plugin=vanillaBlocks
number=56
data:
JSON:{blockState:{blockName:"minecraft:wooden_slab",properties:{half:"top",variant:"spruce"}}}
:enddata
:endrule

#### ENTITIES ####
