# Ancient Warfare Structure Template File
# Auto-generated structure template file. created on: 3/19/2021 at: 12:43:3
# Lines beginning with # denote comments

header:
version=2.11
name=SB_T3wall2_Angle_Tower_oak
mods=
size=16,29,16
offset=15,4,15
:endheader

#### VALIDATION ####
validation:
type=ground
structureAuthor=TheOddlySeagull
survival=true
worldGenEnabled=false
unique=false
preserveBlocks=false
preventNaturalHostileSpawns=false
selectionWeight=1
clusterValue=1
minDuplicateDistance=1
dimensionWhiteList=true
dimensionList=
biomeGroupList=
biomeWhiteList=true
biomeList=
leveling=0
fill=0
border=0
blockSwap=false
territoryName=
biomeReplacement=minecraft:
minGenerationHeight=0
maxGenerationHeight=255
:endvalidation

#### LAYERS ####
layer: 0
1,1,1,1,1,2,2,2,2,2,2,2,2,2,2,1
1,1,1,1,1,2,2,2,2,2,2,2,2,2,2,1
1,1,1,1,1,2,2,2,2,2,2,2,2,2,2,1
1,1,1,1,1,2,2,2,2,2,2,2,2,2,2,1
1,1,1,1,1,2,2,2,2,2,2,2,2,2,2,1
2,2,2,2,2,2,2,2,2,2,2,2,2,2,2,1
2,2,2,2,2,2,2,2,2,2,2,2,2,2,2,1
2,2,2,2,2,2,2,2,2,2,2,2,2,2,2,1
2,2,2,2,2,2,2,2,2,2,2,2,2,2,2,1
2,2,2,2,2,2,2,2,2,2,2,2,2,2,2,1
2,2,2,2,2,2,2,2,2,2,2,2,2,2,2,1
2,2,2,2,2,2,2,2,2,2,2,2,2,2,2,1
2,2,2,2,2,2,2,2,2,2,2,2,2,2,2,1
2,2,2,2,2,2,2,2,2,2,2,2,2,2,2,1
2,2,2,2,2,2,2,2,2,2,2,2,2,2,2,1
1,1,1,1,1,1,1,1,1,1,1,1,1,1,1,1
:endlayer
layer: 1
1,1,1,1,1,2,2,2,2,2,0,0,0,0,2,1
1,1,1,1,1,2,2,2,2,2,0,0,0,0,2,1
1,1,1,1,1,2,2,2,2,2,0,0,0,0,2,1
1,1,1,1,1,2,2,2,2,2,0,0,0,0,2,1
1,1,1,1,1,2,2,2,2,2,0,0,0,0,2,1
2,2,2,2,2,2,2,2,2,2,2,0,0,0,2,1
2,2,2,2,2,2,2,2,2,2,2,2,0,0,2,1
2,2,2,2,2,2,2,2,2,2,2,2,0,0,2,1
2,2,2,2,2,2,2,2,2,2,2,2,0,0,2,1
2,2,2,2,2,2,2,2,2,2,2,2,0,0,2,1
0,0,0,0,0,2,2,2,2,2,2,0,0,0,2,1
0,0,0,0,0,0,2,2,2,2,0,0,0,0,2,1
0,0,0,0,0,0,0,0,0,0,0,0,0,0,2,1
0,0,0,0,0,0,0,0,0,0,0,0,0,0,2,1
2,2,2,2,2,2,2,2,2,2,2,2,2,2,2,1
1,1,1,1,1,1,1,1,1,1,1,1,1,1,1,1
:endlayer
layer: 2
1,1,1,1,1,2,2,2,2,2,0,0,0,0,2,1
1,1,1,1,1,2,2,2,2,2,0,0,0,0,2,1
1,1,1,1,1,2,2,2,2,2,0,0,0,0,2,1
1,1,1,1,1,2,2,2,2,2,0,0,0,0,2,1
1,1,1,1,1,2,2,2,2,2,0,0,0,0,2,1
2,2,2,2,2,2,2,2,2,2,2,0,0,0,2,1
2,2,2,2,2,2,2,2,2,2,2,2,0,0,2,1
2,2,2,2,2,2,2,2,2,2,2,2,0,0,2,1
2,2,2,2,2,2,2,2,2,2,2,2,0,0,2,1
2,2,2,2,2,2,2,2,2,2,2,2,0,0,2,1
0,0,0,0,0,2,2,2,2,2,2,0,0,0,2,1
0,0,0,0,0,0,2,2,2,2,0,0,0,0,2,1
0,0,0,0,0,0,0,0,0,0,0,0,0,0,2,1
0,0,0,0,0,0,0,0,0,0,0,0,0,0,2,1
2,2,2,2,2,2,2,2,2,2,2,2,2,2,2,1
1,1,1,1,1,1,1,1,1,1,1,1,1,1,1,1
:endlayer
layer: 3
3,3,3,3,3,2,2,2,2,2,0,0,0,0,2,3
3,3,3,1,1,2,2,2,2,2,0,0,0,0,2,3
3,3,2,2,2,2,2,2,2,2,0,0,0,0,2,3
3,1,2,2,2,2,2,2,2,2,0,0,0,0,2,3
3,1,2,2,2,2,2,2,2,2,0,0,0,0,2,3
2,2,2,2,2,2,2,2,2,2,2,0,0,0,2,3
2,2,2,2,2,2,2,2,2,2,2,2,0,0,2,3
2,2,2,2,2,2,2,2,2,2,2,2,0,0,2,3
2,2,2,2,2,2,2,2,2,2,2,2,0,0,2,3
2,2,2,2,2,2,2,2,2,2,2,2,0,0,2,3
0,0,0,0,0,2,2,2,2,2,2,0,0,0,2,3
0,0,0,0,0,0,2,2,2,2,0,0,0,0,2,3
0,0,0,0,0,0,0,0,0,0,0,0,0,0,2,3
0,0,0,0,0,0,0,0,0,0,0,0,0,0,2,3
2,2,2,2,2,2,2,2,2,2,2,2,2,2,2,3
3,3,3,3,3,3,3,3,3,3,3,3,3,3,3,3
:endlayer
layer: 4
0,0,0,0,7,5,2,2,2,5,0,0,0,0,2,0
0,0,0,5,2,2,2,2,2,8,0,0,0,0,4,0
0,0,0,0,0,4,2,2,2,8,0,0,0,0,4,0
0,5,0,0,4,5,2,2,2,5,0,0,0,0,2,0
7,2,0,4,4,4,2,2,2,2,0,0,0,0,2,0
5,2,4,5,4,2,2,2,2,2,2,0,0,0,4,0
2,2,2,2,2,2,2,2,2,2,2,2,0,0,4,0
2,2,2,2,2,2,2,2,2,2,2,2,0,0,2,0
2,2,2,2,2,2,2,2,2,2,2,2,0,0,2,0
5,6,6,5,2,2,2,2,2,2,2,2,0,0,4,0
0,0,0,0,0,2,2,2,2,2,2,0,0,0,4,0
0,0,0,0,0,0,2,2,2,2,0,0,0,0,2,0
0,0,0,0,0,0,0,0,0,0,0,0,0,0,2,0
0,0,0,0,0,0,0,0,0,0,0,0,0,0,4,0
2,4,4,2,2,4,4,2,2,4,4,2,2,4,4,0
0,0,0,0,0,0,0,0,0,0,0,0,0,0,0,0
:endlayer
layer: 5
0,0,0,0,7,5,2,2,2,5,0,0,0,0,4,0
0,0,0,5,2,2,2,2,2,10,0,0,0,0,0,0
0,0,0,0,0,0,2,2,2,10,0,0,0,0,0,0
0,5,0,0,0,5,2,2,2,5,0,0,0,0,4,0
7,2,0,0,0,0,2,2,2,2,0,0,0,0,4,0
5,2,0,5,0,0,0,4,2,2,2,0,0,0,0,0
2,2,2,2,2,0,0,4,2,2,2,2,0,0,0,0
2,2,2,2,2,2,2,5,2,2,2,2,0,0,4,0
2,2,2,2,2,2,2,2,2,2,2,2,0,0,4,0
5,9,9,5,2,2,2,2,2,2,2,2,0,0,0,0
0,0,0,0,0,2,2,2,2,2,2,0,0,0,0,0
0,0,0,0,0,0,2,2,2,2,0,0,0,0,4,0
0,0,0,0,0,0,0,0,0,0,0,0,0,0,4,0
0,0,0,0,0,0,0,0,0,0,0,0,0,0,0,0
4,0,0,4,4,0,0,4,4,0,0,4,4,0,0,0
0,0,0,0,0,0,0,0,0,0,0,0,0,0,0,0
:endlayer
layer: 6
0,0,0,12,7,5,2,2,2,5,0,0,0,0,0,0
0,0,0,5,2,2,2,2,2,0,0,0,0,0,0,0
0,0,0,0,0,0,2,2,2,0,0,0,0,0,0,0
13,5,0,0,13,5,2,2,2,5,0,0,0,0,0,0
7,2,0,12,0,0,2,2,2,2,0,0,0,0,0,0
5,2,0,5,0,0,0,11,0,2,2,0,0,0,0,0
2,2,2,2,2,0,0,0,0,0,2,2,0,0,0,0
2,2,2,2,2,2,2,5,4,4,2,2,0,0,0,0
2,2,2,2,2,2,2,2,2,2,2,2,0,0,0,0
5,0,0,5,2,2,2,2,2,2,2,2,0,0,0,0
0,0,0,0,0,2,2,2,2,2,2,0,0,0,0,0
0,0,0,0,0,0,2,2,2,2,0,0,0,0,0,0
0,0,0,0,0,0,0,0,0,0,0,0,0,0,0,0
0,0,0,0,0,0,0,0,0,0,0,0,0,0,0,0
0,0,0,0,0,0,0,0,0,0,0,0,0,0,0,0
0,0,0,0,0,0,0,0,0,0,0,0,0,0,0,0
:endlayer
layer: 7
0,0,14,14,16,5,2,2,2,5,0,0,0,0,0,0
0,14,14,5,5,5,2,2,2,0,0,0,0,0,0,0
14,14,5,14,14,14,2,2,2,0,0,0,0,0,0,0
14,5,14,0,0,5,2,2,2,5,0,0,0,0,0,0
15,5,14,0,0,2,2,2,2,2,0,0,0,0,0,0
5,5,14,5,2,14,14,0,0,2,2,0,0,0,0,0
2,2,2,2,2,14,14,0,0,0,2,2,0,0,0,0
2,2,2,2,2,2,2,5,0,13,2,2,0,0,0,0
2,2,2,2,2,2,2,4,0,0,2,2,0,0,0,0
5,0,0,5,2,2,2,4,0,2,2,2,0,0,0,0
0,0,0,0,0,2,2,2,2,2,2,0,0,0,0,0
0,0,0,0,0,0,2,2,2,2,0,0,0,0,0,0
0,0,0,0,0,0,0,0,0,0,0,0,0,0,0,0
0,0,0,0,0,0,0,0,0,0,0,0,0,0,0,0
0,0,0,0,0,0,0,0,0,0,0,0,0,0,0,0
0,0,0,0,0,0,0,0,0,0,0,0,0,0,0,0
:endlayer
layer: 8
0,0,0,0,0,5,2,2,2,5,0,0,0,0,0,0
0,0,0,4,4,4,2,2,2,0,0,0,0,0,0,0
0,0,4,4,2,2,2,2,2,0,0,0,0,0,0,0
0,4,4,2,2,5,2,2,2,5,0,0,0,0,0,0
0,4,2,2,2,2,2,2,2,2,0,0,0,0,0,0
5,4,2,5,2,2,2,2,14,2,2,0,0,0,0,0
2,2,2,2,2,2,2,2,14,14,2,2,0,0,0,0
2,2,2,2,2,4,4,5,0,0,2,2,0,0,0,0
2,2,2,2,2,0,0,0,0,0,2,2,0,0,0,0
5,0,0,5,2,2,0,12,0,2,2,2,0,0,0,0
0,0,0,0,0,2,2,2,2,2,2,0,0,0,0,0
0,0,0,0,0,0,2,2,2,2,0,0,0,0,0,0
0,0,0,0,0,0,0,0,0,0,0,0,0,0,0,0
0,0,0,0,0,0,0,0,0,0,0,0,0,0,0,0
0,0,0,0,0,0,0,0,0,0,0,0,0,0,0,0
0,0,0,0,0,0,0,0,0,0,0,0,0,0,0,0
:endlayer
layer: 9
0,0,0,0,0,5,2,2,2,5,0,0,0,0,0,0
0,0,0,0,0,6,2,2,2,6,0,0,0,0,0,0
0,0,0,0,0,15,2,2,2,15,0,0,0,0,0,0
0,0,0,0,0,5,2,2,2,5,0,0,0,0,0,0
0,0,0,0,2,2,2,2,2,2,0,0,0,0,0,0
5,8,16,5,2,2,0,4,4,2,2,0,0,0,0,0
2,2,2,2,2,0,0,4,4,2,2,2,0,0,0,0
2,2,2,2,2,0,0,5,2,2,2,2,8,0,0,0
2,2,2,2,2,0,0,0,14,2,2,2,8,0,0,0
5,8,16,5,2,2,0,0,14,2,2,2,0,0,0,0
0,0,0,0,0,2,2,2,2,2,2,0,0,0,0,0
0,0,0,0,0,0,2,2,2,2,0,0,0,0,0,0
0,0,0,0,0,0,0,6,6,0,0,0,0,0,0,0
0,0,0,0,0,0,0,0,0,0,0,0,0,0,0,0
0,0,0,0,0,0,0,0,0,0,0,0,0,0,0,0
0,0,0,0,0,0,0,0,0,0,0,0,0,0,0,0
:endlayer
layer: 10
0,0,0,0,16,5,2,2,2,5,8,0,0,0,0,0
0,0,0,0,14,5,2,2,2,5,14,0,0,0,0,0
0,0,0,0,14,5,2,2,2,5,14,0,0,0,0,0
0,0,0,14,16,5,2,4,4,5,8,0,0,0,0,0
15,14,14,15,5,2,2,0,0,2,8,0,0,0,0,0
5,5,5,5,2,2,0,0,0,0,2,7,0,0,0,0
2,2,2,2,2,0,0,12,0,0,4,2,8,0,0,0
2,2,2,2,2,0,13,5,17,0,4,2,2,0,0,0
2,2,2,2,2,0,0,16,10,4,4,2,2,0,0,0
5,5,5,5,2,2,0,16,4,4,4,2,8,0,0,0
6,14,14,6,6,2,2,2,4,4,2,7,0,0,0,0
0,0,0,0,0,7,2,2,2,2,7,0,0,0,0,0
0,0,0,0,0,0,6,2,2,6,0,0,0,0,0,0
0,0,0,0,0,0,0,0,0,0,0,0,0,0,0,0
0,0,0,0,0,0,0,0,0,0,0,0,0,0,0,0
0,0,0,0,0,0,0,0,0,0,0,0,0,0,0,0
:endlayer
layer: 11
0,0,0,0,2,5,0,0,0,5,2,0,0,0,0,0
0,0,0,0,19,0,0,0,0,0,10,0,0,0,0,0
0,0,0,0,2,0,0,0,0,0,10,0,0,0,0,0
0,0,0,2,0,0,0,0,0,0,2,0,0,0,0,0
2,18,2,0,0,0,2,0,0,2,5,0,0,0,0,0
5,0,0,0,0,2,0,0,0,0,2,7,0,0,0,0
0,0,0,0,2,0,0,0,0,0,0,2,5,0,0,0
0,0,0,0,2,0,0,4,0,0,0,0,10,0,0,0
0,0,0,0,2,14,14,5,0,0,0,0,10,0,0,0
5,0,0,0,2,4,4,0,0,0,0,2,5,0,0,0
2,9,9,2,5,2,4,0,0,0,2,7,0,0,0,0
0,0,0,0,0,7,2,0,0,2,7,0,0,0,0,0
0,0,0,0,0,0,5,9,9,5,0,0,0,0,0,0
0,0,0,0,0,0,0,0,0,0,0,0,0,0,0,0
0,0,0,0,0,0,0,0,0,0,0,0,0,0,0,0
0,0,0,0,0,0,0,0,0,0,0,0,0,0,0,0
:endlayer
layer: 12
0,0,0,0,2,5,0,0,0,5,2,0,0,0,0,0
0,0,0,0,0,0,0,0,0,0,0,0,0,0,0,0
0,0,0,0,2,0,0,0,0,0,0,0,0,0,0,0
0,0,0,2,0,0,0,0,0,0,2,0,0,0,0,0
2,0,2,0,0,0,2,0,0,2,5,0,0,0,0,0
5,0,0,0,0,2,17,0,0,13,2,7,0,0,0,0
0,0,0,0,2,4,4,14,0,0,11,2,5,0,0,0
0,0,0,0,2,4,4,14,0,0,0,0,0,0,0,0
0,0,0,0,2,0,0,5,0,0,0,0,0,0,0,0
5,0,0,0,2,12,0,0,0,0,12,2,5,0,0,0
2,0,0,2,5,2,17,0,0,13,2,7,0,0,0,0
0,0,0,0,0,7,2,0,0,2,7,0,0,0,0,0
0,0,0,0,0,0,5,0,0,5,0,0,0,0,0,0
0,0,0,0,0,0,0,0,0,0,0,0,0,0,0,0
0,0,0,0,0,0,0,0,0,0,0,0,0,0,0,0
0,0,0,0,0,0,0,0,0,0,0,0,0,0,0,0
:endlayer
layer: 13
0,0,0,13,2,5,8,0,16,5,2,17,0,0,0,0
0,0,0,0,14,11,0,0,0,11,14,0,0,0,0,0
0,0,0,0,2,0,0,0,0,0,14,0,0,0,0,0
12,0,0,2,0,0,0,0,0,0,2,0,0,0,0,0
2,14,2,0,0,0,2,8,16,2,5,17,0,0,0,0
5,17,0,0,0,2,0,0,0,0,2,7,0,0,0,0
6,0,0,0,2,0,0,0,4,4,0,2,5,0,0,0
0,0,0,0,2,0,0,0,4,4,0,0,14,0,0,0
15,0,0,0,2,0,0,5,14,14,0,0,14,0,0,0
5,17,0,0,2,0,0,0,0,0,0,2,5,0,0,0
2,14,14,2,5,2,0,0,0,0,2,7,0,0,0,0
11,0,0,0,11,7,2,0,0,2,7,0,0,0,0,0
0,0,0,0,0,0,5,14,14,5,0,0,0,0,0,0
0,0,0,0,0,0,0,0,0,0,0,0,0,0,0,0
0,0,0,0,0,0,0,0,0,0,0,0,0,0,0,0
0,0,0,0,0,0,0,0,0,0,0,0,0,0,0,0
:endlayer
layer: 14
0,0,0,14,5,5,5,5,5,5,5,14,0,0,0,0
0,0,0,14,5,8,0,0,0,16,5,14,0,0,0,0
0,0,14,14,5,8,0,0,0,16,5,14,0,0,0,0
14,14,14,5,6,8,0,0,0,16,5,14,0,0,0,0
5,5,5,6,8,0,2,2,2,2,5,14,0,0,0,0
5,6,6,8,0,2,0,0,0,0,2,8,0,0,0,0
5,0,0,0,2,0,0,0,0,0,0,2,18,0,0,0
5,0,0,0,2,0,0,0,0,0,0,16,10,0,0,0
5,0,0,0,2,0,0,5,0,0,0,16,10,0,0,0
5,15,15,15,2,0,0,14,4,4,0,2,9,0,0,0
5,5,5,5,5,2,0,14,4,4,2,7,0,0,0,0
14,14,14,14,14,6,2,15,15,2,7,0,0,0,0,0
0,0,0,0,0,0,19,9,9,10,0,0,0,0,0,0
0,0,0,0,0,0,0,0,0,0,0,0,0,0,0,0
0,0,0,0,0,0,0,0,0,0,0,0,0,0,0,0
0,0,0,0,0,0,0,0,0,0,0,0,0,0,0,0
:endlayer
layer: 15
0,0,0,0,4,4,2,2,2,4,4,0,0,0,0,0
0,0,0,0,4,4,2,2,2,4,4,0,0,0,0,0
0,0,0,0,4,4,2,2,2,4,4,0,0,0,0,0
0,0,0,4,4,4,2,2,2,4,4,0,0,0,0,0
4,4,4,4,4,4,2,2,2,2,4,0,0,0,0,0
4,4,4,4,4,2,8,0,0,16,2,7,0,0,0,0
2,2,2,2,2,0,0,0,0,0,6,2,7,0,0,0
2,2,2,2,2,0,0,0,0,0,0,2,0,0,0,0
2,2,2,2,2,14,14,5,0,0,0,2,0,0,0,0
4,4,4,4,2,4,4,0,0,0,15,2,7,0,0,0
4,4,4,4,4,2,4,0,0,0,2,7,0,0,0,0
0,0,0,0,0,7,2,2,2,2,7,0,0,0,0,0
0,0,0,0,0,0,7,0,0,7,0,0,0,0,0,0
0,0,0,0,0,0,0,0,0,0,0,0,0,0,0,0
0,0,0,0,0,0,0,0,0,0,0,0,0,0,0,0
0,0,0,0,0,0,0,0,0,0,0,0,0,0,0,0
:endlayer
layer: 16
0,0,0,0,0,0,0,0,0,0,0,0,0,0,0,0
0,0,0,0,0,0,0,0,0,0,0,0,0,0,0,0
0,0,0,0,0,0,0,20,0,0,0,0,0,0,0,0
0,0,0,0,0,0,15,14,14,15,0,0,0,0,0,0
0,0,0,0,0,16,2,2,2,2,8,0,0,0,0,0
0,0,0,0,15,2,2,2,2,2,2,15,0,0,0,0
0,0,0,16,2,4,4,14,14,14,2,2,8,0,0,0
0,0,20,14,2,4,4,14,14,14,2,2,14,0,0,0
0,0,0,14,2,0,0,5,14,14,2,2,14,0,0,0
0,0,0,16,2,0,0,0,0,14,2,2,8,0,0,0
0,0,0,0,6,2,0,0,0,14,2,6,0,0,0,0
0,0,0,0,0,16,2,2,2,2,8,0,0,0,0,0
0,0,0,0,0,0,6,14,14,6,0,0,0,0,0,0
0,0,0,0,0,0,0,0,0,0,0,0,0,0,0,0
0,0,0,0,0,0,0,0,0,0,0,0,0,0,0,0
0,0,0,0,0,0,0,0,0,0,0,0,0,0,0,0
:endlayer
layer: 17
0,0,0,0,0,0,0,0,0,0,0,0,0,0,0,0
0,0,0,0,0,0,0,0,0,0,0,0,0,0,0,0
0,0,0,0,0,0,0,0,0,0,0,0,0,0,0,0
0,0,0,0,0,0,5,18,18,5,0,0,0,0,0,0
0,0,0,0,7,2,0,0,0,0,2,7,0,0,0,0
0,0,0,0,2,0,0,0,0,0,0,2,0,0,0,0
0,0,0,5,0,0,0,0,0,0,0,0,5,0,0,0
0,0,0,19,0,0,0,12,0,0,0,0,10,0,0,0
0,0,0,19,0,0,13,5,17,0,0,0,10,0,0,0
0,0,0,5,0,0,0,11,0,0,0,0,5,0,0,0
0,0,0,0,2,0,0,0,0,0,0,2,0,0,0,0
0,0,0,0,7,2,0,0,0,0,2,7,0,0,0,0
0,0,0,0,0,0,5,9,9,5,0,0,0,0,0,0
0,0,0,0,0,0,0,0,0,0,0,0,0,0,0,0
0,0,0,0,0,0,0,0,0,0,0,0,0,0,0,0
0,0,0,0,0,0,0,0,0,0,0,0,0,0,0,0
:endlayer
layer: 18
0,0,0,0,0,0,0,0,0,0,0,0,0,0,0,0
0,0,0,0,0,0,0,0,0,0,0,0,0,0,0,0
0,0,0,0,0,0,0,0,0,0,0,0,0,0,0,0
0,0,0,0,0,0,5,0,0,5,0,0,0,0,0,0
0,0,0,0,7,2,0,0,0,0,2,7,0,0,0,0
0,0,0,0,2,0,0,0,0,0,0,2,0,0,0,0
0,0,0,5,0,0,0,0,0,0,0,0,5,0,0,0
0,0,0,0,0,0,0,0,0,0,0,0,0,0,0,0
0,0,0,0,0,0,0,4,0,0,0,0,0,0,0,0
0,0,0,5,0,0,0,0,0,0,0,0,5,0,0,0
0,0,0,0,2,0,0,0,0,0,0,2,0,0,0,0
0,0,0,0,7,2,0,0,0,0,2,7,0,0,0,0
0,0,0,0,0,0,5,0,0,5,0,0,0,0,0,0
0,0,0,0,0,0,0,0,0,0,0,0,0,0,0,0
0,0,0,0,0,0,0,0,0,0,0,0,0,0,0,0
0,0,0,0,0,0,0,0,0,0,0,0,0,0,0,0
:endlayer
layer: 19
0,0,0,0,0,0,0,0,0,0,0,0,0,0,0,0
0,0,0,0,0,0,0,0,0,0,0,0,0,0,0,0
0,0,0,0,0,0,0,0,0,0,0,0,0,0,0,0
0,0,0,0,0,0,5,14,14,5,0,0,0,0,0,0
0,0,0,0,7,2,0,0,0,0,2,7,0,0,0,0
0,0,0,0,2,7,0,0,0,0,7,2,0,0,0,0
0,0,0,5,0,0,0,0,0,0,0,0,5,0,0,0
0,0,0,14,0,0,0,0,0,0,0,0,14,0,0,0
0,0,0,14,0,0,0,0,0,0,0,0,14,0,0,0
0,0,0,5,0,0,0,0,0,0,0,0,5,0,0,0
0,0,0,0,2,7,0,0,0,0,7,2,0,0,0,0
0,0,0,0,7,2,0,0,0,0,2,7,0,0,0,0
0,0,0,0,0,0,5,14,14,5,0,0,0,0,0,0
0,0,0,0,0,0,0,0,0,0,0,0,0,0,0,0
0,0,0,0,0,0,0,0,0,0,0,0,0,0,0,0
0,0,0,0,0,0,0,0,0,0,0,0,0,0,0,0
:endlayer
layer: 20
0,0,0,0,0,0,0,0,0,0,0,0,0,0,0,0
0,0,0,0,0,0,0,0,0,0,0,0,0,0,0,0
0,0,0,0,0,0,14,14,14,14,0,0,0,0,0,0
0,0,0,0,14,14,5,5,5,5,14,14,0,0,0,0
0,0,0,14,14,5,8,0,0,16,5,14,14,0,0,0
0,0,0,14,5,2,0,0,0,0,2,5,14,0,0,0
0,0,14,5,6,0,0,0,0,0,0,6,5,14,0,0
0,0,14,5,0,0,0,0,0,0,0,0,5,14,0,0
0,0,14,5,0,0,0,0,0,0,0,0,5,14,0,0
0,0,14,5,15,0,0,0,0,0,0,15,5,14,0,0
0,0,0,14,5,2,0,0,0,0,2,5,14,0,0,0
0,0,0,14,14,5,8,0,0,16,5,14,14,0,0,0
0,0,0,0,14,14,5,5,5,5,14,14,0,0,0,0
0,0,0,0,0,0,14,14,14,14,0,0,0,0,0,0
0,0,0,0,0,0,0,0,0,0,0,0,0,0,0,0
0,0,0,0,0,0,0,0,0,0,0,0,0,0,0,0
:endlayer
layer: 21
0,0,0,0,0,0,0,0,0,0,0,0,0,0,0,0
0,0,0,0,0,0,0,0,0,0,0,0,0,0,0,0
0,0,0,0,0,0,0,0,0,0,0,0,0,0,0,0
0,0,0,0,0,0,4,4,4,4,0,0,0,0,0,0
0,0,0,0,20,4,4,2,2,4,4,20,0,0,0,0
0,0,0,0,4,4,2,2,2,2,4,4,0,0,0,0
0,0,0,4,4,2,2,14,14,2,2,4,4,0,0,0
0,0,0,4,2,2,14,14,14,14,2,2,4,0,0,0
0,0,0,4,2,2,14,14,14,14,2,2,4,0,0,0
0,0,0,4,4,2,2,14,14,2,2,4,4,0,0,0
0,0,0,0,4,4,2,2,2,2,4,4,0,0,0,0
0,0,0,0,20,4,4,2,2,4,4,20,0,0,0,0
0,0,0,0,0,0,4,4,4,4,0,0,0,0,0,0
0,0,0,0,0,0,0,0,0,0,0,0,0,0,0,0
0,0,0,0,0,0,0,0,0,0,0,0,0,0,0,0
0,0,0,0,0,0,0,0,0,0,0,0,0,0,0,0
:endlayer
layer: 22
0,0,0,0,0,0,0,0,0,0,0,0,0,0,0,0
0,0,0,0,0,0,0,0,0,0,0,0,0,0,0,0
0,0,0,0,0,0,0,0,0,0,0,0,0,0,0,0
0,0,0,0,0,0,0,0,0,0,0,0,0,0,0,0
0,0,0,0,0,0,0,0,0,0,0,0,0,0,0,0
0,0,0,0,0,0,0,18,18,0,0,0,0,0,0,0
0,0,0,0,0,0,2,2,2,2,0,0,0,0,0,0
0,0,0,0,0,19,2,2,2,2,10,0,0,0,0,0
0,0,0,0,0,19,2,2,2,2,10,0,0,0,0,0
0,0,0,0,0,0,2,2,2,2,0,0,0,0,0,0
0,0,0,0,0,0,0,9,9,0,0,0,0,0,0,0
0,0,0,0,0,0,0,0,0,0,0,0,0,0,0,0
0,0,0,0,0,0,0,0,0,0,0,0,0,0,0,0
0,0,0,0,0,0,0,0,0,0,0,0,0,0,0,0
0,0,0,0,0,0,0,0,0,0,0,0,0,0,0,0
0,0,0,0,0,0,0,0,0,0,0,0,0,0,0,0
:endlayer
layer: 23
0,0,0,0,0,0,0,0,0,0,0,0,0,0,0,0
0,0,0,0,0,0,0,0,0,0,0,0,0,0,0,0
0,0,0,0,0,0,0,0,0,0,0,0,0,0,0,0
0,0,0,0,0,0,0,0,0,0,0,0,0,0,0,0
0,0,0,0,0,0,0,0,0,0,0,0,0,0,0,0
0,0,0,0,0,0,0,0,0,0,0,0,0,0,0,0
0,0,0,0,0,0,7,2,2,7,0,0,0,0,0,0
0,0,0,0,0,0,2,2,2,2,0,0,0,0,0,0
0,0,0,0,0,0,2,2,2,2,0,0,0,0,0,0
0,0,0,0,0,0,7,2,2,7,0,0,0,0,0,0
0,0,0,0,0,0,0,0,0,0,0,0,0,0,0,0
0,0,0,0,0,0,0,0,0,0,0,0,0,0,0,0
0,0,0,0,0,0,0,0,0,0,0,0,0,0,0,0
0,0,0,0,0,0,0,0,0,0,0,0,0,0,0,0
0,0,0,0,0,0,0,0,0,0,0,0,0,0,0,0
0,0,0,0,0,0,0,0,0,0,0,0,0,0,0,0
:endlayer
layer: 24
0,0,0,0,0,0,0,0,0,0,0,0,0,0,0,0
0,0,0,0,0,0,0,0,0,0,0,0,0,0,0,0
0,0,0,0,0,0,0,0,0,0,0,0,0,0,0,0
0,0,0,0,0,0,0,0,0,0,0,0,0,0,0,0
0,0,0,0,0,0,0,0,0,0,0,0,0,0,0,0
0,0,0,0,0,0,0,0,0,0,0,0,0,0,0,0
0,0,0,0,0,0,0,18,18,0,0,0,0,0,0,0
0,0,0,0,0,0,19,2,2,10,0,0,0,0,0,0
0,0,0,0,0,0,19,2,2,10,0,0,0,0,0,0
0,0,0,0,0,0,0,9,9,0,0,0,0,0,0,0
0,0,0,0,0,0,0,0,0,0,0,0,0,0,0,0
0,0,0,0,0,0,0,0,0,0,0,0,0,0,0,0
0,0,0,0,0,0,0,0,0,0,0,0,0,0,0,0
0,0,0,0,0,0,0,0,0,0,0,0,0,0,0,0
0,0,0,0,0,0,0,0,0,0,0,0,0,0,0,0
0,0,0,0,0,0,0,0,0,0,0,0,0,0,0,0
:endlayer
layer: 25
0,0,0,0,0,0,0,0,0,0,0,0,0,0,0,0
0,0,0,0,0,0,0,0,0,0,0,0,0,0,0,0
0,0,0,0,0,0,0,0,0,0,0,0,0,0,0,0
0,0,0,0,0,0,0,0,0,0,0,0,0,0,0,0
0,0,0,0,0,0,0,0,0,0,0,0,0,0,0,0
0,0,0,0,0,0,0,0,0,0,0,0,0,0,0,0
0,0,0,0,0,0,0,0,0,0,0,0,0,0,0,0
0,0,0,0,0,0,0,2,2,0,0,0,0,0,0,0
0,0,0,0,0,0,0,2,2,0,0,0,0,0,0,0
0,0,0,0,0,0,0,0,0,0,0,0,0,0,0,0
0,0,0,0,0,0,0,0,0,0,0,0,0,0,0,0
0,0,0,0,0,0,0,0,0,0,0,0,0,0,0,0
0,0,0,0,0,0,0,0,0,0,0,0,0,0,0,0
0,0,0,0,0,0,0,0,0,0,0,0,0,0,0,0
0,0,0,0,0,0,0,0,0,0,0,0,0,0,0,0
0,0,0,0,0,0,0,0,0,0,0,0,0,0,0,0
:endlayer
layer: 26
0,0,0,0,0,0,0,0,0,0,0,0,0,0,0,0
0,0,0,0,0,0,0,0,0,0,0,0,0,0,0,0
0,0,0,0,0,0,0,0,0,0,0,0,0,0,0,0
0,0,0,0,0,0,0,0,0,0,0,0,0,0,0,0
0,0,0,0,0,0,0,0,0,0,0,0,0,0,0,0
0,0,0,0,0,0,0,0,0,0,0,0,0,0,0,0
0,0,0,0,0,0,0,0,0,0,0,0,0,0,0,0
0,0,0,0,0,0,0,19,18,0,0,0,0,0,0,0
0,0,0,0,0,0,0,9,10,0,0,0,0,0,0,0
0,0,0,0,0,0,0,0,0,0,0,0,0,0,0,0
0,0,0,0,0,0,0,0,0,0,0,0,0,0,0,0
0,0,0,0,0,0,0,0,0,0,0,0,0,0,0,0
0,0,0,0,0,0,0,0,0,0,0,0,0,0,0,0
0,0,0,0,0,0,0,0,0,0,0,0,0,0,0,0
0,0,0,0,0,0,0,0,0,0,0,0,0,0,0,0
0,0,0,0,0,0,0,0,0,0,0,0,0,0,0,0
:endlayer
layer: 27
0,0,0,0,0,0,0,0,0,0,0,0,0,0,0,0
0,0,0,0,0,0,0,0,0,0,0,0,0,0,0,0
0,0,0,0,0,0,0,0,0,0,0,0,0,0,0,0
0,0,0,0,0,0,0,0,0,0,0,0,0,0,0,0
0,0,0,0,0,0,0,0,0,0,0,0,0,0,0,0
0,0,0,0,0,0,0,0,0,0,0,0,0,0,0,0
0,0,0,0,0,0,0,0,0,0,0,0,0,0,0,0
0,0,0,0,0,0,0,7,7,0,0,0,0,0,0,0
0,0,0,0,0,0,0,7,7,0,0,0,0,0,0,0
0,0,0,0,0,0,0,0,0,0,0,0,0,0,0,0
0,0,0,0,0,0,0,0,0,0,0,0,0,0,0,0
0,0,0,0,0,0,0,0,0,0,0,0,0,0,0,0
0,0,0,0,0,0,0,0,0,0,0,0,0,0,0,0
0,0,0,0,0,0,0,0,0,0,0,0,0,0,0,0
0,0,0,0,0,0,0,0,0,0,0,0,0,0,0,0
0,0,0,0,0,0,0,0,0,0,0,0,0,0,0,0
:endlayer
layer: 28
0,0,0,0,0,0,0,0,0,0,0,0,0,0,0,0
0,0,0,0,0,0,0,0,0,0,0,0,0,0,0,0
0,0,0,0,0,0,0,0,0,0,0,0,0,0,0,0
0,0,0,0,0,0,0,0,0,0,0,0,0,0,0,0
0,0,0,0,0,0,0,0,0,0,0,0,0,0,0,0
0,0,0,0,0,0,0,0,0,0,0,0,0,0,0,0
0,0,0,0,0,0,0,0,0,0,0,0,0,0,0,0
0,0,0,0,0,0,0,7,7,0,0,0,0,0,0,0
0,0,0,0,0,0,0,7,7,0,0,0,0,0,0,0
0,0,0,0,0,0,0,0,0,0,0,0,0,0,0,0
0,0,0,0,0,0,0,0,0,0,0,0,0,0,0,0
0,0,0,0,0,0,0,0,0,0,0,0,0,0,0,0
0,0,0,0,0,0,0,0,0,0,0,0,0,0,0,0
0,0,0,0,0,0,0,0,0,0,0,0,0,0,0,0
0,0,0,0,0,0,0,0,0,0,0,0,0,0,0,0
0,0,0,0,0,0,0,0,0,0,0,0,0,0,0,0
:endlayer

#### RULES ####
rule:
plugin=vanillaBlocks
number=1
data:
JSON:{blockState:{blockName:"minecraft:dirt",properties:{variant:"dirt",snowy:"false"}}}
:enddata
:endrule

rule:
plugin=vanillaBlocks
number=2
data:
JSON:{blockState:{blockName:"minecraft:cobblestone"}}
:enddata
:endrule

rule:
plugin=vanillaBlocks
number=3
data:
JSON:{blockState:{blockName:"minecraft:grass",properties:{snowy:"false"}}}
:enddata
:endrule

rule:
plugin=vanillaBlocks
number=4
data:
JSON:{blockState:{blockName:"minecraft:stone_slab",properties:{half:"bottom",variant:"cobblestone"}}}
:enddata
:endrule

rule:
plugin=vanillaBlocks
number=5
data:
JSON:{blockState:{blockName:"minecraft:stonebrick",properties:{variant:"stonebrick"}}}
:enddata
:endrule

rule:
plugin=vanillaBlocks
number=6
data:
JSON:{blockState:{blockName:"minecraft:stone_stairs",properties:{half:"top",shape:"straight",facing:"north"}}}
:enddata
:endrule

rule:
plugin=vanillaBlocks
number=7
data:
JSON:{blockState:{blockName:"minecraft:cobblestone_wall",properties:{east:"false",south:"false",north:"false",variant:"cobblestone",west:"false",up:"false"}}}
:enddata
:endrule

rule:
plugin=vanillaBlocks
number=8
data:
JSON:{blockState:{blockName:"minecraft:stone_stairs",properties:{half:"top",shape:"straight",facing:"west"}}}
:enddata
:endrule

rule:
plugin=vanillaBlocks
number=9
data:
JSON:{blockState:{blockName:"minecraft:stone_stairs",properties:{half:"bottom",shape:"straight",facing:"north"}}}
:enddata
:endrule

rule:
plugin=vanillaBlocks
number=10
data:
JSON:{blockState:{blockName:"minecraft:stone_stairs",properties:{half:"bottom",shape:"straight",facing:"west"}}}
:enddata
:endrule

rule:
plugin=vanillaBlocks
number=11
data:
JSON:{blockState:{blockName:"minecraft:torch",properties:{facing:"south"}}}
:enddata
:endrule

rule:
plugin=vanillaBlocks
number=12
data:
JSON:{blockState:{blockName:"minecraft:torch",properties:{facing:"north"}}}
:enddata
:endrule

rule:
plugin=vanillaBlocks
number=13
data:
JSON:{blockState:{blockName:"minecraft:torch",properties:{facing:"west"}}}
:enddata
:endrule

rule:
plugin=vanillaBlocks
number=14
data:
JSON:{blockState:{blockName:"minecraft:stone_slab",properties:{half:"top",variant:"cobblestone"}}}
:enddata
:endrule

rule:
plugin=vanillaBlocks
number=15
data:
JSON:{blockState:{blockName:"minecraft:stone_stairs",properties:{half:"top",shape:"straight",facing:"south"}}}
:enddata
:endrule

rule:
plugin=vanillaBlocks
number=16
data:
JSON:{blockState:{blockName:"minecraft:stone_stairs",properties:{half:"top",shape:"straight",facing:"east"}}}
:enddata
:endrule

rule:
plugin=vanillaBlocks
number=17
data:
JSON:{blockState:{blockName:"minecraft:torch",properties:{facing:"east"}}}
:enddata
:endrule

rule:
plugin=vanillaBlocks
number=18
data:
JSON:{blockState:{blockName:"minecraft:stone_stairs",properties:{half:"bottom",shape:"straight",facing:"south"}}}
:enddata
:endrule

rule:
plugin=vanillaBlocks
number=19
data:
JSON:{blockState:{blockName:"minecraft:stone_stairs",properties:{half:"bottom",shape:"straight",facing:"east"}}}
:enddata
:endrule

rule:
plugin=vanillaBlocks
number=20
data:
JSON:{blockState:{blockName:"minecraft:torch",properties:{facing:"up"}}}
:enddata
:endrule

#### ENTITIES ####
