# Ancient Warfare Structure Template File
# Auto-generated structure template file. created on: 6/6/2023 at: 19:49:52
# Lines beginning with # denote comments

header:
version=2.11
name=SB_MarenCol_TownHall_1_jacaranda
mods=biomesoplenty
size=34,24,41
offset=16,1,40
:endheader

#### VALIDATION ####
validation:
type=ground
structureAuthor=TheOddlySeagull
survival=true
worldGenEnabled=false
unique=false
preserveBlocks=false
preventNaturalHostileSpawns=false
selectionWeight=1
clusterValue=1
minDuplicateDistance=1
dimensionWhiteList=true
dimensionList=
biomeGroupList=
biomeWhiteList=true
biomeList=
leveling=0
fill=0
border=0
blockSwap=false
territoryName=
biomeReplacement=minecraft:
minGenerationHeight=0
maxGenerationHeight=255
:endvalidation

#### LAYERS ####
layer: 0
1,1,1,1,1,1,2,2,2,2,1,1,1,1,1,2,2,2,2,1,1,1,1,1,2,2,2,2,1,1,1,1,1,1
1,1,1,1,1,1,2,2,2,2,1,1,1,1,1,2,2,2,2,1,1,1,1,1,2,2,2,2,1,1,1,1,1,1
1,1,1,1,1,1,2,2,2,2,2,2,2,1,1,2,2,2,2,1,1,2,2,2,2,2,2,2,1,1,1,1,1,1
1,1,1,1,1,1,2,2,2,2,2,2,2,4,4,2,2,2,2,4,4,2,2,2,2,2,2,2,1,1,1,1,1,1
1,1,1,1,1,1,2,2,2,2,2,2,2,2,2,2,2,2,2,2,2,2,2,2,2,2,2,2,1,1,1,1,1,1
1,1,1,1,1,1,2,2,2,2,2,2,2,2,2,2,2,2,2,2,2,2,2,2,2,2,2,2,1,1,1,1,1,1
1,1,1,1,1,1,2,2,2,2,2,2,2,2,2,2,2,2,2,2,2,2,2,2,2,2,2,2,1,1,1,1,1,1
1,1,1,1,1,1,2,2,2,2,2,2,2,2,2,2,2,2,2,2,2,2,2,2,2,2,2,2,1,1,1,1,1,1
1,1,2,2,2,2,2,2,2,2,2,2,2,4,4,4,4,4,4,4,4,2,2,2,2,2,2,2,2,2,2,2,1,1
1,1,2,2,2,2,2,2,2,2,2,2,5,2,2,4,1,1,4,2,2,5,2,2,2,2,2,2,2,2,2,2,1,1
1,1,2,2,2,2,2,2,2,2,2,2,5,2,6,1,1,1,1,6,2,5,2,2,2,2,2,2,2,2,2,2,1,1
1,2,2,2,2,2,2,2,2,2,2,2,5,5,1,1,1,1,1,1,5,5,2,2,2,2,2,2,2,2,2,2,1,1
1,2,2,2,2,2,2,2,2,2,2,2,5,1,1,1,1,1,1,1,1,5,2,2,2,2,2,2,2,2,2,2,1,1
1,1,2,2,2,2,2,2,2,2,2,2,5,1,1,1,1,1,1,1,1,5,2,2,2,2,2,2,2,2,2,2,1,1
1,1,2,2,2,2,2,2,2,2,2,2,5,1,1,1,1,1,1,1,1,5,2,2,2,2,2,2,2,2,2,2,1,1
2,2,2,2,2,2,2,2,2,2,2,2,5,1,1,1,1,1,1,1,1,5,2,2,2,2,2,2,2,2,2,2,2,2
2,2,2,2,2,2,2,2,2,2,2,2,5,1,1,1,1,1,1,1,1,5,2,2,2,2,2,2,2,2,2,2,2,2
2,2,2,2,2,2,2,2,2,2,2,2,5,1,1,1,1,1,1,1,1,5,2,2,2,2,2,2,2,2,2,2,2,2
2,2,2,2,2,2,2,2,2,2,2,2,5,5,1,1,1,1,1,1,5,5,2,2,2,2,2,2,2,2,2,2,2,2
1,1,2,2,2,2,2,2,2,2,2,2,5,2,6,1,1,1,1,6,2,5,2,2,2,2,2,2,2,2,2,2,1,1
1,1,2,2,2,2,2,2,2,2,2,2,5,2,2,4,1,1,4,2,2,5,2,2,2,2,2,2,2,2,2,2,1,1
1,1,2,2,2,2,2,2,2,2,2,4,4,4,4,4,4,4,4,4,4,4,4,2,2,2,2,2,2,2,2,2,2,1
1,1,2,2,2,2,2,2,2,2,2,2,2,2,2,2,2,2,2,2,2,2,2,2,2,2,2,2,2,2,2,2,2,1
1,1,2,2,2,2,2,2,2,2,2,2,2,2,2,2,2,2,2,2,2,2,2,2,2,2,2,2,2,2,2,2,1,1
1,1,2,2,2,2,2,2,2,2,2,2,2,2,2,2,2,2,2,2,2,2,2,2,2,2,2,2,2,2,2,2,1,1
1,1,2,2,2,2,2,2,2,2,2,2,2,2,2,2,2,2,2,2,2,2,2,2,2,2,2,2,2,2,2,2,1,1
1,1,1,1,2,2,2,2,2,2,2,2,2,2,2,2,2,2,2,2,2,2,2,2,2,2,2,2,2,2,1,1,1,1
1,1,2,2,2,2,2,2,2,2,2,2,2,2,2,2,2,2,2,2,2,2,2,2,2,2,2,2,2,2,2,2,1,1
1,1,2,2,2,2,2,2,2,2,2,2,2,2,2,2,2,2,2,2,2,2,2,2,2,2,2,2,2,2,2,2,1,1
1,1,2,2,2,2,2,2,2,2,2,2,2,2,2,2,2,2,2,2,2,2,2,2,2,2,2,2,2,2,2,2,1,1
1,1,2,2,2,2,2,2,2,2,2,2,2,2,2,2,2,2,2,2,2,2,2,2,2,2,2,2,2,2,2,2,1,1
1,1,1,1,2,2,2,2,2,2,2,2,2,2,2,2,2,2,2,2,2,2,2,2,2,2,2,2,2,2,1,1,1,1
1,1,3,2,3,2,2,2,3,2,2,2,2,2,2,2,2,2,2,2,2,2,2,2,2,3,2,2,2,3,2,3,1,1
1,1,2,2,2,2,2,2,2,2,2,2,2,2,2,2,2,2,2,2,2,2,2,2,2,2,2,2,2,2,2,2,1,1
1,1,3,2,2,2,2,2,2,2,2,2,2,2,2,2,2,2,2,2,2,2,2,2,2,2,2,2,2,2,2,3,1,1
1,1,2,2,2,2,2,2,2,2,2,2,2,2,2,2,2,2,2,2,2,2,2,2,2,2,2,2,2,2,2,2,1,1
1,1,3,2,2,2,2,2,3,2,3,2,2,3,2,3,2,2,3,2,3,2,2,3,2,3,2,2,2,2,2,3,1,1
1,1,2,2,2,2,2,2,2,1,1,1,1,1,3,2,2,2,2,3,1,1,1,1,1,2,2,2,2,2,2,2,1,1
1,1,3,2,3,2,3,2,3,1,1,1,1,1,3,2,2,2,2,3,1,1,1,1,1,3,2,3,2,3,2,3,1,1
1,1,1,1,2,2,2,1,1,1,1,1,1,1,3,2,2,2,2,3,1,1,1,1,1,1,1,2,2,2,1,1,1,1
1,1,1,1,2,2,2,1,1,1,1,1,1,1,3,2,2,2,2,3,1,1,1,1,1,1,1,2,2,2,1,1,1,1
:endlayer
layer: 1
0,0,0,0,0,0,0,0,0,0,0,0,0,0,0,0,0,0,0,0,0,0,0,0,0,0,0,0,0,0,0,0,0,0
0,7,0,0,0,0,0,0,0,0,0,0,0,0,7,0,0,0,0,7,0,0,0,0,0,0,0,0,0,0,0,0,7,0
0,0,0,0,0,0,6,17,16,6,8,8,6,0,0,0,0,0,0,0,0,6,8,8,6,17,16,6,0,0,0,0,0,0
0,0,0,0,0,0,8,0,0,0,0,0,8,0,0,0,0,0,0,0,0,8,0,0,0,0,0,8,0,0,0,0,0,0
0,0,0,0,0,0,8,0,0,0,0,0,8,0,0,0,0,0,0,0,0,8,0,0,0,0,0,8,0,0,0,0,0,0
0,0,0,0,0,0,6,0,0,0,0,0,6,7,6,0,0,0,0,6,7,6,0,0,0,0,0,6,0,0,0,0,0,0
0,0,0,0,0,0,8,0,0,0,0,0,8,0,0,0,0,0,0,0,0,8,0,0,0,0,0,8,0,0,0,0,0,0
0,0,0,0,0,0,8,0,0,0,18,0,8,0,0,0,0,0,0,0,0,8,0,18,0,0,0,8,0,0,0,0,0,0
0,0,6,8,6,8,6,0,0,0,6,8,6,0,0,0,0,0,0,0,0,6,8,6,0,0,0,6,8,6,8,6,0,0
0,0,8,0,0,0,0,0,0,0,8,0,0,0,0,0,0,0,0,0,0,0,0,8,0,0,0,0,0,0,0,8,0,0
0,0,2,0,0,0,0,0,0,0,6,0,0,0,21,0,0,0,0,21,0,0,0,6,0,0,0,0,0,0,0,6,0,0
0,2,11,12,0,0,0,0,0,0,8,0,0,0,0,0,0,0,0,0,0,0,0,8,0,0,0,0,0,0,0,8,0,0
0,2,11,12,0,0,0,0,0,0,8,0,0,0,0,0,0,0,0,0,0,0,0,8,0,0,0,0,0,0,0,8,0,0
0,0,2,0,0,0,0,0,0,0,6,0,0,0,0,0,0,0,0,0,0,0,0,6,0,0,0,0,0,0,0,6,0,0
0,0,8,0,0,0,0,0,0,0,8,0,0,0,0,0,0,0,0,0,0,0,0,8,0,0,0,0,0,0,0,8,0,0
0,0,6,0,0,0,0,0,0,0,6,0,0,0,0,0,0,0,0,0,0,0,0,6,0,0,0,0,0,0,0,6,0,0
0,0,19,0,0,0,0,0,0,0,9,0,0,0,0,0,0,0,0,0,0,0,0,19,0,0,0,0,0,0,0,9,0,0
0,0,20,0,0,0,0,0,0,0,10,0,0,0,0,0,0,0,0,0,0,0,0,20,0,0,0,0,0,0,0,10,0,0
0,0,6,0,0,0,0,0,0,0,6,0,0,0,0,0,0,0,0,0,0,0,0,6,0,0,0,0,0,0,0,6,0,0
0,0,8,0,0,0,0,0,0,0,8,0,0,0,21,0,0,0,0,21,0,0,0,8,0,0,0,0,0,0,0,8,0,0
0,0,6,0,0,0,0,0,0,0,6,0,0,0,0,0,0,0,0,0,0,0,0,6,0,0,0,0,0,0,0,2,0,0
0,0,8,0,0,0,0,0,0,0,8,0,0,0,0,0,0,0,0,0,0,0,0,8,0,0,0,0,0,0,12,11,2,0
0,0,8,0,0,0,0,0,0,0,8,0,0,0,0,0,0,0,0,0,0,0,0,8,0,0,0,0,0,0,12,11,2,0
0,0,6,0,0,0,0,0,0,0,6,0,0,6,8,6,17,16,6,8,6,0,0,6,0,0,0,0,0,0,0,2,0,0
0,0,8,0,0,0,0,0,0,0,8,0,0,8,0,0,0,0,0,0,8,0,0,8,0,0,0,0,0,0,0,8,0,0
0,0,6,8,6,8,8,6,0,0,6,8,8,6,0,0,0,0,0,0,6,8,8,6,0,0,6,8,8,6,8,6,0,0
0,0,0,0,8,0,0,0,0,0,0,0,0,0,0,0,0,0,0,0,0,0,0,0,0,0,0,0,0,8,0,0,0,0
0,0,0,0,6,0,0,0,0,0,0,0,0,0,0,0,0,0,0,0,0,0,0,0,0,0,0,0,0,6,0,0,0,0
0,0,0,0,19,0,0,0,0,0,0,0,0,0,0,0,0,0,0,0,0,0,0,0,0,0,0,0,0,9,0,0,0,0
0,0,0,0,20,0,0,0,0,0,0,0,0,6,0,0,0,0,0,0,6,0,0,0,0,0,0,0,0,10,0,0,0,0
0,0,0,0,6,0,0,0,0,0,0,0,0,0,0,0,0,0,0,0,0,0,0,0,0,0,0,0,0,6,0,0,0,0
0,0,0,0,8,0,0,0,0,0,0,0,0,0,0,0,0,0,0,0,0,0,0,0,0,0,0,0,0,8,0,0,0,0
0,0,3,2,3,0,0,0,3,2,0,0,0,6,0,0,0,0,0,0,6,0,0,0,2,3,0,0,0,3,2,3,0,0
0,0,2,0,0,0,0,0,2,11,12,0,0,0,0,0,0,0,0,0,0,0,0,12,11,2,0,0,0,14,13,2,0,0
0,0,3,0,7,0,0,0,2,11,12,0,0,0,0,0,0,0,0,0,0,0,0,12,11,2,0,0,0,7,0,3,0,0
0,0,2,13,14,0,0,0,2,11,12,0,0,0,0,0,0,0,0,0,0,0,0,12,11,2,0,0,0,0,0,2,0,0
0,0,3,0,0,0,0,0,3,2,3,2,2,3,2,3,15,22,3,2,3,2,2,3,2,3,0,0,0,0,0,3,0,0
0,0,2,0,0,0,0,0,2,0,0,0,0,0,0,0,0,0,0,0,0,0,0,0,0,2,0,0,0,0,0,2,0,0
0,0,3,2,3,15,3,2,3,0,0,0,0,0,0,0,0,0,0,0,0,0,0,0,0,3,2,3,15,3,2,3,0,0
0,0,0,0,0,0,0,0,0,0,0,0,0,0,0,0,0,0,0,0,0,0,0,0,0,0,0,0,0,0,0,0,0,0
0,0,0,0,0,0,0,0,0,0,0,0,0,0,0,0,0,0,0,0,0,0,0,0,0,0,0,0,0,0,0,0,0,0
:endlayer
layer: 2
0,0,0,0,0,0,0,0,0,0,0,0,0,0,0,0,0,0,0,0,0,0,0,0,0,0,0,0,0,0,0,0,0,0
0,21,0,0,0,0,0,0,0,0,0,0,0,0,21,0,0,0,0,21,0,0,0,0,0,0,0,0,0,0,0,0,21,0
0,0,0,0,0,0,6,27,26,6,7,7,6,0,0,0,0,0,0,0,0,6,7,7,6,27,26,6,0,0,0,0,0,0
0,0,0,0,0,0,7,0,0,0,0,0,8,0,0,0,0,0,0,0,0,8,0,0,0,0,0,7,0,0,0,0,0,0
0,0,0,0,0,0,7,0,0,0,0,0,8,0,0,0,0,0,0,0,0,8,0,0,0,0,0,7,0,0,0,0,0,0
0,0,0,0,0,0,6,0,0,0,0,0,6,7,6,0,0,0,0,6,7,6,0,0,0,0,0,6,0,0,0,0,0,0
0,0,0,0,0,0,8,0,0,0,0,0,7,0,0,0,0,0,0,0,0,7,0,0,0,0,0,8,0,0,0,0,0,0
0,0,0,0,0,0,8,0,0,0,18,0,7,0,0,0,0,0,0,0,0,7,0,18,0,0,0,8,0,0,0,0,0,0
0,0,6,8,6,8,6,0,0,0,6,7,6,0,0,0,0,0,0,0,0,6,7,6,0,0,0,6,8,6,8,6,0,0
0,0,8,0,0,0,0,0,0,0,7,0,0,0,0,0,0,0,0,0,0,0,0,7,0,0,0,0,0,0,0,8,0,0
0,0,2,0,0,0,0,0,0,0,6,0,0,0,0,0,0,0,0,0,0,0,0,6,0,0,0,0,0,0,0,6,0,0
0,2,0,0,0,0,0,0,0,0,7,0,0,0,0,0,0,0,0,0,0,0,0,7,0,0,0,0,0,0,0,7,0,0
0,2,0,0,0,0,0,0,0,0,7,0,0,0,0,0,0,0,0,0,0,0,0,7,0,0,0,0,0,0,0,7,0,0
0,0,2,0,0,0,0,0,0,0,6,0,0,0,0,0,0,0,0,0,0,0,0,6,0,0,0,0,0,0,0,6,0,0
0,0,8,0,0,0,0,0,0,0,7,0,0,0,0,0,0,0,0,0,0,0,0,7,0,0,0,0,0,0,0,8,0,0
0,0,6,0,0,0,0,0,0,0,6,0,0,0,0,0,0,0,0,0,0,0,0,6,0,0,0,0,0,0,0,6,0,0
0,0,28,0,0,0,0,0,0,0,23,0,0,0,0,0,0,0,0,0,0,0,0,28,0,0,0,0,0,0,0,23,0,0
0,0,29,0,0,0,0,0,0,0,24,0,0,0,0,0,0,0,0,0,0,0,0,29,0,0,0,0,0,0,0,24,0,0
0,0,6,0,0,0,0,0,0,0,6,0,0,0,0,0,0,0,0,0,0,0,0,6,0,0,0,0,0,0,0,6,0,0
0,0,8,0,0,0,0,0,0,0,7,0,0,0,0,0,0,0,0,0,0,0,0,7,0,0,0,0,0,0,0,8,0,0
0,0,6,0,0,0,0,0,0,0,6,0,0,0,0,0,0,0,0,0,0,0,0,6,0,0,0,0,0,0,0,2,0,0
0,0,7,0,0,0,0,0,0,0,7,0,0,0,0,0,0,0,0,0,0,0,0,7,0,0,0,0,0,0,0,0,2,0
0,0,7,0,0,0,0,0,0,0,7,0,0,0,0,0,0,0,0,0,0,0,0,7,0,0,0,0,0,0,0,0,2,0
0,0,6,0,0,0,0,0,0,0,6,0,0,6,7,6,27,26,6,7,6,0,0,6,0,0,0,0,0,0,0,2,0,0
0,0,8,0,0,0,0,0,0,0,7,0,0,8,0,0,0,0,0,0,8,0,0,7,0,0,0,0,0,0,0,8,0,0
0,0,6,8,6,8,8,6,0,0,6,7,7,6,0,0,0,0,0,0,6,7,7,6,0,0,6,8,8,6,8,6,0,0
0,0,0,0,8,0,0,0,0,0,0,0,0,0,0,0,0,0,0,0,0,0,0,0,0,0,0,0,0,8,0,0,0,0
0,0,0,0,6,0,0,0,0,0,0,0,0,0,0,0,0,0,0,0,0,0,0,0,0,0,0,0,0,6,0,0,0,0
0,0,0,0,28,0,0,0,0,0,0,0,0,0,0,0,0,0,0,0,0,0,0,0,0,0,0,0,0,23,0,0,0,0
0,0,0,0,29,0,0,0,0,0,0,0,0,6,0,0,0,0,0,0,6,0,0,0,0,0,0,0,0,24,0,0,0,0
0,0,0,0,6,0,0,0,0,0,0,0,0,0,0,0,0,0,0,0,0,0,0,0,0,0,0,0,0,6,0,0,0,0
0,0,0,0,8,0,0,0,0,0,0,0,0,0,0,0,0,0,0,0,0,0,0,0,0,0,0,0,0,8,0,0,0,0
0,0,3,2,3,0,0,0,3,2,0,0,0,6,0,0,0,0,0,0,6,0,0,0,2,3,0,0,0,3,2,3,0,0
0,0,2,13,0,0,0,0,2,0,0,0,0,0,0,0,0,0,0,0,0,0,0,0,0,2,0,0,0,0,0,2,0,0
0,0,3,14,7,0,0,0,2,0,0,0,0,0,0,0,0,0,0,0,0,0,0,0,0,2,0,0,0,7,14,3,0,0
0,0,7,0,0,0,0,0,2,0,0,0,0,0,0,0,0,0,0,0,0,0,0,0,0,2,0,0,0,0,13,7,0,0
0,0,3,0,0,0,0,0,3,2,3,7,7,3,2,3,25,30,3,2,3,7,7,3,2,3,0,0,0,0,0,3,0,0
0,0,2,0,0,0,0,0,2,0,0,0,0,0,0,0,0,0,0,0,0,0,0,0,0,2,0,0,0,0,0,2,0,0
0,0,3,2,3,25,3,2,3,0,0,0,0,0,0,0,0,0,0,0,0,0,0,0,0,3,2,3,25,3,2,3,0,0
0,0,0,0,0,0,0,0,0,0,0,0,0,0,0,0,0,0,0,0,0,0,0,0,0,0,0,0,0,0,0,0,0,0
0,0,0,0,0,0,0,0,0,0,0,0,0,0,0,0,0,0,0,0,0,0,0,0,0,0,0,0,0,0,0,0,0,0
:endlayer
layer: 3
0,0,0,0,0,0,0,0,0,0,0,0,0,0,0,0,0,0,0,0,0,0,0,0,0,0,0,0,0,0,0,0,0,0
0,0,0,0,0,0,32,0,0,0,0,0,32,0,0,0,0,0,0,0,0,32,0,0,0,0,0,32,0,0,0,0,0,0
0,0,0,0,0,36,6,8,8,6,7,7,6,31,0,0,0,0,0,0,36,6,7,7,6,8,8,6,31,0,0,0,0,0
0,0,0,0,0,0,7,0,0,35,0,0,8,0,0,0,0,0,0,0,0,8,0,0,35,0,0,7,0,0,0,0,0,0
0,0,0,0,0,0,7,0,0,0,0,0,8,0,32,0,0,0,0,32,0,8,0,0,0,0,0,7,0,0,0,0,0,0
0,0,0,0,0,0,6,31,0,0,0,36,6,7,6,41,0,0,39,6,7,6,31,0,0,0,36,6,0,0,0,0,0,0
0,0,0,0,0,0,8,0,0,0,0,0,7,0,35,0,0,0,0,35,0,7,0,0,0,0,0,8,0,0,0,0,0,0
0,0,32,0,0,0,8,0,0,0,18,0,7,0,0,0,0,0,0,0,0,7,0,18,0,0,0,8,0,0,0,32,0,0
0,36,6,8,6,8,6,41,13,39,6,7,6,0,0,0,0,0,0,0,0,6,7,6,41,13,39,6,8,6,8,6,31,0
0,0,8,0,35,0,35,0,0,0,7,0,0,0,0,0,0,0,0,0,0,0,0,7,0,0,0,35,0,35,0,8,0,0
0,0,2,31,0,0,0,0,0,36,6,0,0,0,0,0,0,0,0,0,0,0,0,6,31,0,0,0,0,0,36,6,0,0
0,2,33,0,0,0,0,0,0,0,7,0,0,0,0,0,0,0,0,0,0,0,0,7,0,0,0,0,0,0,0,7,0,0
0,2,34,0,0,0,0,0,0,0,7,0,0,0,0,0,0,0,0,0,0,0,0,7,0,0,0,0,0,0,0,7,0,0
0,36,2,31,0,0,0,0,0,36,6,0,0,0,0,0,0,0,0,0,0,0,0,6,31,0,0,0,0,0,36,6,31,0
0,0,8,0,0,0,0,0,0,0,7,0,0,0,0,0,0,0,0,0,0,0,0,7,0,0,0,0,0,0,0,8,0,0
0,0,6,31,0,0,0,0,0,36,6,0,0,0,0,0,0,0,0,0,0,0,0,6,31,0,0,0,0,0,36,6,0,0
0,0,8,0,0,0,0,0,0,0,8,0,0,0,0,0,0,0,0,0,0,0,0,8,0,0,0,0,0,0,0,8,0,0
0,0,8,0,0,0,0,0,0,0,8,0,0,0,0,0,0,0,0,0,0,0,0,8,0,0,0,0,0,0,0,8,0,0
0,0,6,31,0,0,0,0,0,36,6,0,0,0,0,0,0,0,0,0,0,0,0,6,31,0,0,0,0,0,36,6,0,0
0,0,8,0,0,0,0,0,0,0,7,0,0,0,0,0,0,0,0,0,0,0,0,7,0,0,0,0,0,0,0,8,0,0
0,36,6,31,0,0,0,0,0,36,6,0,0,0,0,0,0,0,0,0,0,0,0,6,31,0,0,0,0,0,36,2,31,0
0,0,7,0,0,0,0,0,0,0,7,0,0,0,0,0,0,0,0,0,0,0,0,7,0,0,0,0,0,0,0,33,2,0
0,0,7,0,0,0,0,0,0,0,7,0,0,0,0,0,0,0,0,0,0,0,0,7,0,0,0,0,0,0,0,34,2,0
0,0,6,31,0,0,0,0,0,36,6,0,0,6,7,6,8,8,6,7,6,0,0,6,31,0,0,0,0,0,36,2,0,0
0,0,8,0,32,0,0,32,0,0,7,0,0,8,0,35,0,0,35,0,8,0,0,7,0,0,32,0,0,32,0,8,0,0
0,36,6,8,6,8,8,6,8,8,6,7,7,6,0,0,0,0,0,0,6,7,7,6,8,8,6,8,8,6,8,6,31,0
0,0,35,0,8,0,0,35,0,0,35,0,0,35,0,0,0,0,0,0,35,0,0,35,0,0,35,0,0,8,0,35,0,0
0,0,0,7,6,31,0,0,0,0,0,0,0,0,0,0,0,0,0,0,0,0,0,0,0,0,0,0,36,6,7,0,0,0
0,0,0,0,8,0,0,0,0,0,0,0,0,0,0,0,0,0,0,0,0,0,0,0,0,0,0,0,0,8,0,0,0,0
0,0,0,0,8,0,0,0,0,0,0,0,36,6,31,0,0,0,0,36,6,31,0,0,0,0,0,0,0,8,0,0,0,0
0,0,0,7,6,31,0,0,0,0,0,0,0,0,0,0,0,0,0,0,0,0,0,0,0,0,0,0,36,6,7,0,0,0
0,0,32,0,8,0,0,0,32,0,0,0,0,0,0,0,0,0,0,0,0,0,0,0,0,32,0,0,0,8,0,32,0,0
0,36,3,2,3,40,38,37,3,2,0,0,36,6,31,0,0,0,0,36,6,31,0,0,2,3,40,38,37,3,2,3,31,0
0,0,2,0,14,13,0,0,2,33,0,0,0,0,0,0,0,0,0,0,0,0,0,0,33,2,0,0,0,35,0,2,0,0
0,0,3,31,7,0,0,0,2,0,0,0,0,0,0,0,0,0,0,0,0,0,0,0,0,2,0,0,0,7,36,3,0,0
0,0,7,0,0,0,0,0,2,34,0,0,0,0,0,0,0,0,0,0,0,0,0,0,34,2,0,0,13,14,0,7,0,0
0,0,3,31,0,0,0,36,3,2,3,7,7,3,2,3,2,2,3,2,3,7,7,3,2,3,31,0,0,0,36,3,0,0
0,0,2,0,32,0,32,0,2,0,35,0,0,35,0,35,0,0,35,0,35,0,0,35,0,2,0,32,0,32,0,2,0,0
0,36,3,2,3,2,3,2,3,31,0,0,0,0,0,0,0,0,0,0,0,0,0,0,36,3,2,3,2,3,2,3,31,0
0,0,35,0,0,0,0,0,35,0,0,0,0,0,0,0,0,0,0,0,0,0,0,0,0,35,0,0,0,0,0,35,0,0
0,0,0,0,0,0,0,0,0,0,0,0,0,0,0,0,0,0,0,0,0,0,0,0,0,0,0,0,0,0,0,0,0,0
:endlayer
layer: 4
0,0,0,0,0,0,0,0,0,0,0,0,0,0,0,0,0,0,0,0,0,0,0,0,0,0,0,0,0,0,0,0,0,0
0,0,0,0,0,0,0,0,0,0,0,0,0,0,0,0,0,0,0,0,0,0,0,0,0,0,0,0,0,0,0,0,0,0
0,0,0,0,0,0,6,4,4,4,4,4,6,0,0,0,0,0,0,0,0,6,4,4,4,4,4,6,0,0,0,0,0,0
0,0,0,0,0,0,5,13,13,13,13,13,5,0,0,0,0,0,0,0,0,5,13,13,13,13,13,5,0,0,0,0,0,0
0,0,0,0,0,0,5,8,8,8,8,8,5,44,44,44,44,44,44,44,44,5,8,8,8,8,8,5,0,0,0,0,0,0
0,0,0,0,0,0,5,13,13,13,13,13,5,4,4,4,4,4,4,4,4,5,13,13,13,13,13,5,0,0,0,0,0,0
0,0,0,0,0,0,5,8,8,8,8,8,5,45,45,45,45,45,45,45,45,5,8,8,8,8,8,5,0,0,0,0,0,0
0,43,41,0,0,0,5,13,13,13,18,13,5,0,0,0,0,0,0,0,0,5,13,18,13,13,13,5,0,0,0,39,42,0
0,43,6,4,4,4,4,4,4,4,4,4,6,0,0,0,0,0,0,0,0,6,4,4,4,4,4,4,4,4,4,6,42,0
0,43,5,0,0,0,0,0,0,0,5,42,0,0,0,0,0,0,0,0,0,0,43,5,0,0,0,0,0,0,0,5,42,0
0,43,5,0,0,0,0,0,0,0,5,42,0,0,0,0,0,0,0,0,0,0,43,5,0,0,0,0,0,0,0,5,42,0
0,2,5,0,0,0,0,0,0,0,5,42,0,0,0,0,0,0,0,0,0,0,43,5,0,0,0,0,0,0,0,5,42,0
0,2,5,0,0,0,0,0,0,0,5,42,0,0,0,0,0,0,0,0,0,0,43,5,0,0,0,0,0,0,0,5,42,0
0,43,5,0,0,0,0,0,0,0,5,42,0,0,0,0,0,0,0,0,0,0,43,5,0,0,0,0,0,0,0,5,42,0
0,43,5,0,0,0,0,0,0,0,5,42,0,0,0,0,0,0,0,0,0,0,43,5,0,0,0,0,0,0,0,5,42,0
0,43,5,0,0,0,0,0,0,0,5,42,0,0,0,0,0,0,0,0,0,0,43,5,0,0,0,0,0,0,0,5,42,0
0,43,5,0,0,0,0,0,0,0,5,42,0,0,0,0,0,0,0,0,0,0,43,5,0,0,0,0,0,0,0,5,42,0
0,43,5,0,0,0,0,0,0,0,5,42,0,0,0,0,0,0,0,0,0,0,43,5,0,0,0,0,0,0,0,5,42,0
0,43,5,0,0,0,0,0,0,0,5,42,0,0,0,0,0,0,0,0,0,0,43,5,0,0,0,0,0,0,0,5,42,0
0,43,5,0,0,0,0,0,0,0,5,42,0,0,0,0,0,0,0,0,0,0,43,5,0,0,0,0,0,0,0,5,42,0
0,43,5,0,0,0,0,0,0,0,5,42,0,0,0,0,0,0,0,0,0,0,43,5,0,0,0,0,0,0,0,5,42,0
0,43,5,0,0,0,0,0,0,0,5,42,0,0,0,0,0,0,0,0,0,0,43,5,0,0,0,0,0,0,0,5,2,0
0,43,5,0,0,0,0,0,0,0,5,42,0,0,0,0,0,0,0,0,0,0,43,5,0,0,0,0,0,0,0,5,2,0
0,43,5,0,0,0,0,0,0,0,5,42,0,6,4,4,4,4,4,4,6,0,43,5,0,0,0,0,0,0,0,5,42,0
0,43,5,0,0,0,0,0,0,0,5,42,0,5,13,8,13,13,8,13,5,0,43,5,0,0,0,0,0,0,0,5,42,0
0,43,6,4,4,4,4,4,4,4,4,4,4,6,13,8,13,13,8,13,6,4,4,4,4,4,4,4,4,4,4,6,42,0
0,43,41,0,5,8,8,8,5,8,8,8,8,5,13,8,13,13,8,13,5,8,8,8,8,5,8,8,8,5,0,39,42,0
0,0,0,4,5,13,13,13,5,13,13,13,13,5,13,8,13,13,8,13,5,13,13,13,13,5,13,13,13,5,4,0,0,0
0,0,0,13,5,8,8,8,5,8,8,8,8,5,4,4,4,4,4,4,5,8,8,8,8,5,8,8,8,5,13,0,0,0
0,0,0,13,5,13,13,13,5,13,13,13,13,5,0,0,0,0,0,0,5,13,13,13,13,5,13,13,13,5,13,0,0,0
0,0,0,4,5,8,8,8,5,8,8,8,8,5,0,0,0,0,0,0,5,8,8,8,8,5,8,8,8,5,4,0,0,0
0,0,0,0,5,13,13,13,5,13,13,13,13,5,0,0,0,0,0,0,5,13,13,13,13,5,13,13,13,5,0,0,0,0
0,0,3,3,3,3,3,3,3,2,2,8,8,5,0,0,0,0,0,0,5,8,8,2,2,3,3,3,3,3,3,3,0,0
0,0,3,0,0,0,8,13,3,2,2,13,13,5,4,4,4,4,4,4,5,13,13,2,2,3,13,8,13,0,0,3,0,0
0,0,3,0,7,14,8,13,3,2,2,8,8,5,13,8,13,13,8,13,5,8,8,2,2,3,13,8,14,7,0,3,0,0
0,0,3,0,0,13,8,13,3,2,2,13,13,5,13,8,13,13,8,13,5,13,13,2,2,3,13,8,0,0,0,3,0,0
0,0,3,8,8,8,8,8,3,4,4,4,4,4,4,4,4,4,4,4,4,4,4,4,4,3,8,8,8,8,8,3,0,0
0,0,3,13,13,13,8,13,3,0,0,0,0,5,13,5,13,13,5,13,5,0,0,0,0,3,13,8,13,13,13,3,0,0
0,0,3,3,3,3,3,3,3,0,0,0,0,0,0,0,0,0,0,0,0,0,0,0,0,3,3,3,3,3,3,3,0,0
0,0,0,0,0,0,0,0,0,0,0,0,0,0,0,0,0,0,0,0,0,0,0,0,0,0,0,0,0,0,0,0,0,0
0,0,0,0,0,0,0,0,0,0,0,0,0,0,0,0,0,0,0,0,0,0,0,0,0,0,0,0,0,0,0,0,0,0
:endlayer
layer: 5
0,0,0,0,0,0,0,0,0,0,0,0,0,0,0,0,0,0,0,0,0,0,0,0,0,0,0,0,0,0,0,0,0,0
0,0,0,0,0,0,0,0,0,0,0,0,0,0,0,0,0,0,0,0,0,0,0,0,0,0,0,0,0,0,0,0,0,0
0,0,0,0,0,0,6,8,6,8,6,8,6,0,0,0,0,0,0,0,0,6,8,6,8,6,8,6,0,0,0,0,0,0
0,0,0,0,0,0,8,0,0,0,0,0,8,0,0,0,0,0,0,0,0,8,0,0,0,0,0,8,0,0,0,0,0,0
0,0,0,0,0,0,6,0,0,0,0,0,6,0,0,0,0,0,0,0,0,6,0,0,0,0,0,6,0,0,0,0,0,0
0,0,0,0,0,0,8,0,0,0,0,0,8,14,14,14,14,14,14,14,14,8,0,0,0,0,0,8,0,0,0,0,0,0
0,0,0,0,0,0,6,0,0,0,0,0,6,0,0,0,0,0,0,0,0,6,0,0,0,0,0,6,0,0,0,0,0,0
0,0,43,41,0,0,8,0,0,0,18,0,8,0,0,0,0,0,0,0,0,8,0,18,0,0,0,8,0,0,39,42,0,0
0,0,43,6,8,8,6,8,8,6,6,8,6,0,0,0,0,0,0,0,0,6,8,6,6,8,8,6,8,8,6,42,0,0
0,0,43,41,0,0,0,0,0,39,42,0,0,0,0,0,0,0,0,0,0,0,0,43,41,0,0,0,0,0,39,42,0,0
0,0,43,41,0,0,0,0,0,39,42,0,0,0,0,0,0,0,0,0,0,0,0,43,41,0,0,0,0,0,39,42,0,0
0,2,43,41,0,0,0,0,0,39,42,0,0,0,0,0,0,0,0,0,0,0,0,43,41,0,0,0,0,0,39,42,0,0
0,2,43,41,0,0,0,0,0,39,42,0,0,0,0,0,0,0,0,0,0,0,0,43,41,0,0,0,0,0,39,42,0,0
0,0,43,41,0,0,0,0,0,39,42,0,0,0,0,0,0,0,0,0,0,0,0,43,41,0,0,0,0,0,39,42,0,0
0,0,43,41,0,0,0,0,0,39,42,0,0,0,0,0,0,0,0,0,0,0,0,43,41,0,0,0,0,0,39,42,0,0
0,0,43,41,0,0,0,0,0,39,42,0,0,0,0,0,0,0,0,0,0,0,0,43,41,0,0,0,0,0,39,42,0,0
0,0,43,41,0,0,0,0,0,39,42,0,0,0,0,0,0,0,0,0,0,0,0,43,41,0,0,0,0,0,39,42,0,0
0,0,43,41,0,0,0,0,0,39,42,0,0,0,0,0,0,0,0,0,0,0,0,43,41,0,0,0,0,0,39,42,0,0
0,0,43,41,0,0,0,0,0,39,42,0,0,0,0,0,0,0,0,0,0,0,0,43,41,0,0,0,0,0,39,42,0,0
0,0,43,41,0,0,0,0,0,39,42,0,0,0,0,0,0,0,0,0,0,0,0,43,41,0,0,0,0,0,39,42,0,0
0,0,43,41,0,0,0,0,0,39,42,0,0,0,0,0,0,0,0,0,0,0,0,43,41,0,0,0,0,0,39,42,0,0
0,0,43,41,0,0,0,0,0,39,42,0,0,0,0,0,0,0,0,0,0,0,0,43,41,0,0,0,0,0,39,42,2,0
0,0,43,41,0,0,0,0,0,39,42,0,0,0,0,0,0,0,0,0,0,0,0,43,41,0,0,0,0,0,39,42,2,0
0,0,43,41,0,0,0,0,0,39,42,0,0,6,8,6,8,8,6,8,6,0,0,43,41,0,0,0,0,0,39,42,0,0
0,0,43,41,0,0,0,0,0,39,42,0,0,8,0,0,0,0,0,0,8,0,0,43,41,0,0,0,0,0,39,42,0,0
0,0,43,8,6,8,8,6,8,8,6,8,8,6,0,0,0,0,0,0,6,8,8,6,8,8,6,8,8,6,8,42,0,0
0,0,43,41,8,0,0,0,0,0,0,0,0,0,0,0,0,0,0,0,0,0,0,0,0,0,0,0,0,8,43,42,0,0
0,0,0,6,6,0,0,0,0,0,0,0,0,0,0,0,0,0,0,0,0,0,0,0,0,0,0,0,0,6,6,0,0,0
0,0,0,8,0,0,0,0,0,0,0,0,0,7,7,7,7,7,7,7,7,0,0,0,0,0,0,0,0,0,8,0,0,0
0,0,0,8,0,0,0,0,0,0,0,0,0,7,0,0,0,0,0,0,7,0,0,0,0,0,0,0,0,0,8,0,0,0
0,0,0,6,6,0,0,0,0,0,0,0,0,7,0,0,0,0,0,0,7,0,0,0,0,0,0,0,0,6,6,0,0,0
0,0,0,0,8,0,0,0,0,0,0,0,0,7,0,0,0,0,0,0,7,0,0,0,0,0,0,0,0,8,0,0,0,0
0,0,6,8,6,8,6,0,6,2,0,0,0,7,0,0,0,0,0,0,7,0,0,0,2,3,0,0,0,3,2,3,0,0
0,0,8,0,0,0,0,0,2,11,12,0,0,7,7,7,7,7,7,7,7,0,0,12,11,2,0,0,0,14,13,2,0,0
0,0,6,0,7,0,0,0,2,11,12,0,0,0,0,0,0,0,0,0,0,0,0,12,11,2,0,0,0,7,0,2,0,0
0,0,8,13,14,0,0,0,2,2,0,0,0,0,0,0,0,0,0,0,0,0,0,0,2,2,0,0,0,0,0,2,0,0
0,0,6,0,0,0,0,0,6,6,8,6,8,6,0,0,0,0,0,0,6,8,6,8,6,3,0,0,0,0,0,2,0,0
0,0,8,0,0,0,0,0,8,0,0,0,0,6,8,6,8,8,6,8,6,0,0,0,0,2,0,0,0,0,0,2,0,0
0,0,6,8,6,8,6,8,6,0,0,0,0,0,0,0,0,0,0,0,0,0,0,0,0,3,2,2,2,2,2,3,0,0
0,0,0,0,0,0,0,0,0,0,0,0,0,0,0,0,0,0,0,0,0,0,0,0,0,0,0,0,0,0,0,0,0,0
0,0,0,0,0,0,0,0,0,0,0,0,0,0,0,0,0,0,0,0,0,0,0,0,0,0,0,0,0,0,0,0,0,0
:endlayer
layer: 6
0,0,0,0,0,0,0,0,0,0,0,0,0,0,0,0,0,0,0,0,0,0,0,0,0,0,0,0,0,0,0,0,0,0
0,0,0,0,0,0,0,0,0,0,0,0,0,0,0,0,0,0,0,0,0,0,0,0,0,0,0,0,0,0,0,0,0,0
0,0,0,0,0,0,6,7,6,7,6,7,6,0,0,0,0,0,0,0,0,6,7,6,7,6,7,6,0,0,0,0,0,0
0,0,0,0,0,0,7,0,0,0,0,0,7,0,0,0,0,0,0,0,0,7,0,0,0,0,0,7,0,0,0,0,0,0
0,0,0,0,0,0,6,0,0,0,0,0,6,0,0,0,0,0,0,0,0,6,0,0,0,0,0,6,0,0,0,0,0,0
0,0,0,0,0,0,7,0,0,0,0,0,7,0,0,0,0,0,0,0,0,7,0,0,0,0,0,7,0,0,0,0,0,0
0,0,0,0,0,0,6,0,0,0,0,0,6,0,0,0,0,0,0,0,0,6,0,0,0,0,0,6,0,0,0,0,0,0
0,0,0,43,41,0,7,0,0,0,18,0,7,0,0,0,0,0,0,0,0,7,0,18,0,0,0,7,0,39,42,0,0,0
0,0,0,43,6,8,6,8,6,8,6,7,6,0,0,0,0,0,0,0,0,6,7,6,8,6,8,6,8,6,42,0,0,0
0,0,0,43,41,0,0,0,39,42,0,0,0,0,0,0,0,0,0,0,0,0,0,0,43,41,0,0,0,39,42,0,0,0
0,0,0,43,41,0,0,0,39,42,0,0,0,0,0,0,0,0,0,0,0,0,0,0,43,41,0,0,0,39,42,0,0,0
0,46,0,43,41,0,0,0,39,42,0,0,0,0,0,0,0,0,0,0,0,0,0,0,43,41,0,0,0,39,42,0,0,0
0,2,0,43,41,0,0,0,39,42,0,0,0,0,0,0,0,0,0,0,0,0,0,0,43,41,0,0,0,39,42,0,0,0
0,0,0,43,41,0,0,0,39,42,0,0,0,0,0,0,0,0,0,0,0,0,0,0,43,41,0,0,0,39,42,0,0,0
0,0,0,43,41,0,0,0,39,42,0,0,0,0,0,0,0,0,0,0,0,0,0,0,43,41,0,0,0,39,42,0,0,0
0,0,0,43,41,0,0,0,39,42,0,0,0,0,0,0,0,0,0,0,0,0,0,0,43,41,0,0,0,39,42,0,0,0
0,0,0,43,41,0,0,0,39,42,0,0,0,0,0,0,0,0,0,0,0,0,0,0,43,41,0,0,0,39,42,0,0,0
0,0,0,43,41,0,0,0,39,42,0,0,0,0,0,0,0,0,0,0,0,0,0,0,43,41,0,0,0,39,42,0,0,0
0,0,0,43,41,0,0,0,39,42,0,0,0,0,0,0,0,0,0,0,0,0,0,0,43,41,0,0,0,39,42,0,0,0
0,0,0,43,41,0,0,0,39,42,0,0,0,0,0,0,0,0,0,0,0,0,0,0,43,41,0,0,0,39,42,0,0,0
0,0,0,43,41,0,0,0,39,42,0,0,0,0,0,0,0,0,0,0,0,0,0,0,43,41,0,0,0,39,42,0,0,0
0,0,0,43,41,0,0,0,39,42,0,0,0,0,0,0,0,0,0,0,0,0,0,0,43,41,0,0,0,39,42,0,46,0
0,0,0,43,41,0,0,0,39,42,0,0,0,0,0,0,0,0,0,0,0,0,0,0,43,41,0,0,0,39,42,0,2,0
0,0,0,43,41,0,0,0,39,42,0,0,0,6,7,6,7,7,6,7,6,0,0,0,43,41,0,0,0,39,42,0,0,0
0,0,0,43,41,0,0,0,39,42,0,0,0,8,0,0,0,0,0,0,8,0,0,0,43,41,0,0,0,39,42,0,0,0
0,0,0,43,6,8,8,6,8,8,6,7,7,6,0,0,0,0,0,0,6,7,7,6,8,8,6,8,8,6,42,0,0,0
0,0,0,43,8,0,0,0,0,0,0,0,0,0,0,0,0,0,0,0,0,0,0,0,0,0,0,0,0,8,42,0,0,0
0,0,0,6,6,0,0,0,0,0,0,0,0,0,0,0,0,0,0,0,0,0,0,0,0,0,0,0,0,6,6,0,0,0
0,0,0,7,0,0,0,0,0,0,0,0,0,7,0,0,0,0,0,0,7,0,0,0,0,0,0,0,0,0,7,0,0,0
0,0,0,7,0,0,0,0,0,0,0,0,0,0,0,0,0,0,0,0,0,0,0,0,0,0,0,0,0,0,7,0,0,0
0,0,0,6,6,0,0,0,0,0,0,0,0,0,0,0,0,0,0,0,0,0,0,0,0,0,0,0,0,6,6,0,0,0
0,0,0,0,8,0,0,0,0,0,0,0,0,0,0,0,0,0,0,0,0,0,0,0,0,0,0,0,0,8,0,0,0,0
0,0,6,8,6,8,6,0,6,2,0,0,0,0,0,0,0,0,0,0,0,0,0,0,2,3,0,0,0,3,2,3,0,0
0,0,7,13,0,0,0,0,2,0,0,0,0,7,0,0,0,0,0,0,7,0,0,0,0,2,0,0,0,0,0,2,0,0
0,0,6,14,7,0,0,0,2,0,0,0,0,0,0,0,0,0,0,0,0,0,0,0,0,2,0,0,0,7,14,7,0,0
0,0,7,0,0,0,0,0,2,2,0,0,0,0,0,0,0,0,0,0,0,0,0,0,2,2,0,0,0,0,13,2,0,0
0,0,6,0,0,0,0,0,6,6,7,6,7,6,0,0,0,0,0,0,6,7,6,7,6,3,0,0,0,0,0,7,0,0
0,0,7,0,0,0,0,0,7,0,0,0,0,6,7,6,7,7,6,7,6,0,0,0,0,2,0,0,0,0,0,2,0,0
0,0,6,7,6,7,6,7,6,0,0,0,0,0,0,0,0,0,0,0,0,0,0,0,0,3,2,7,2,7,2,3,0,0
0,0,0,0,0,0,0,0,0,0,0,0,0,0,0,0,0,0,0,0,0,0,0,0,0,0,0,0,0,0,0,0,0,0
0,0,0,0,0,0,0,0,0,0,0,0,0,0,0,0,0,0,0,0,0,0,0,0,0,0,0,0,0,0,0,0,0,0
:endlayer
layer: 7
0,0,0,0,0,0,0,0,0,0,0,0,0,0,0,0,0,0,0,0,0,0,0,0,0,0,0,0,0,0,0,0,0,0
0,0,0,0,0,0,7,0,7,0,7,0,7,0,0,0,0,0,0,0,0,7,0,7,0,7,0,7,0,0,0,0,0,0
0,0,0,0,0,7,6,7,6,7,6,7,6,7,0,0,0,0,0,0,7,6,7,6,7,6,7,6,7,0,0,0,0,0
0,0,0,0,0,0,7,0,35,0,35,0,7,0,0,0,0,0,0,0,0,7,0,35,0,35,0,7,0,0,0,0,0,0
0,0,0,0,0,7,6,31,0,0,0,36,6,7,0,0,0,0,0,0,7,6,31,0,0,0,36,6,7,0,0,0,0,0
0,0,0,0,0,0,7,0,0,0,0,0,7,0,0,0,0,0,0,0,0,7,0,0,0,0,0,7,0,0,0,0,0,0
0,0,0,0,0,7,6,31,0,0,0,36,6,7,0,0,0,0,0,0,7,6,31,0,0,0,36,6,7,0,0,0,0,0
0,0,0,0,43,41,7,0,32,0,18,0,7,0,0,0,0,0,0,0,0,7,0,18,0,32,0,7,39,42,0,0,0,0
0,0,0,0,43,6,6,6,8,8,6,7,6,7,0,0,0,0,0,0,7,6,7,6,8,8,6,6,6,42,0,0,0,0
0,0,0,0,43,41,0,39,42,0,7,0,7,0,0,0,0,0,0,0,0,7,0,7,0,43,41,0,39,42,0,0,0,0
0,0,0,0,43,41,0,39,42,0,0,0,0,0,0,0,0,0,0,0,0,0,0,0,0,43,41,0,39,42,0,0,0,0
0,0,0,0,43,41,0,39,42,0,0,0,0,0,0,0,0,0,0,0,0,0,0,0,0,43,41,0,39,42,0,0,0,0
0,2,0,0,43,41,0,39,42,0,0,0,0,0,0,0,0,0,0,0,0,0,0,0,0,43,41,0,39,42,0,0,0,0
0,0,0,0,43,41,0,39,42,0,0,0,0,0,0,0,0,0,0,0,0,0,0,0,0,43,41,0,39,42,0,0,0,0
0,0,0,0,43,41,0,39,42,0,0,0,0,0,0,0,0,0,0,0,0,0,0,0,0,43,41,0,39,42,0,0,0,0
0,0,0,0,43,41,0,39,42,0,0,0,0,0,0,0,0,0,0,0,0,0,0,0,0,43,41,0,39,42,0,0,0,0
0,0,0,0,43,41,0,39,42,0,0,0,0,0,0,0,0,0,0,0,0,0,0,0,0,43,41,0,39,42,0,0,0,0
0,0,0,0,43,41,0,39,42,0,0,0,0,0,0,0,0,0,0,0,0,0,0,0,0,43,41,0,39,42,0,0,0,0
0,0,0,0,43,41,0,39,42,0,0,0,0,0,0,0,0,0,0,0,0,0,0,0,0,43,41,0,39,42,0,0,0,0
0,0,0,0,43,41,0,39,42,0,0,0,0,0,0,0,0,0,0,0,0,0,0,0,0,43,41,0,39,42,0,0,0,0
0,0,0,0,43,41,0,39,42,0,0,0,0,0,0,0,0,0,0,0,0,0,0,0,0,43,41,0,39,42,0,0,0,0
0,0,0,0,43,41,0,39,42,0,0,0,0,0,0,0,0,0,0,0,0,0,0,0,0,43,41,0,39,42,0,0,0,0
0,0,0,0,43,41,0,39,42,0,0,0,0,7,0,0,0,0,0,0,7,0,0,0,0,43,41,0,39,42,0,0,2,0
0,0,0,0,43,41,0,39,42,0,0,0,0,6,7,6,7,7,6,7,6,0,0,0,0,43,41,0,39,42,0,0,0,0
0,0,0,0,43,41,0,39,42,0,0,0,0,8,0,0,0,0,0,0,8,0,0,0,0,43,41,0,39,42,0,0,0,0
0,0,0,0,6,8,8,6,8,8,6,7,7,6,31,0,0,0,0,36,6,7,7,6,8,8,6,8,8,6,0,0,0,0
0,0,0,0,8,0,0,35,0,0,35,0,0,35,0,0,0,0,0,0,35,0,0,35,0,0,35,0,0,8,0,0,0,0
0,0,0,6,6,31,0,0,0,0,0,0,0,0,0,0,0,0,0,0,0,0,0,0,0,0,0,0,36,6,6,0,0,0
0,0,0,7,0,0,0,0,0,0,0,0,0,7,0,0,0,0,0,0,7,0,0,0,0,0,0,0,0,0,7,0,0,0
0,0,0,7,0,0,0,0,0,0,0,0,0,0,0,0,0,0,0,0,0,0,0,0,0,0,0,0,0,0,7,0,0,0
0,0,0,6,6,31,0,0,0,0,0,0,0,0,0,0,0,0,0,0,0,0,0,0,0,0,0,0,36,6,6,0,0,0
0,0,0,0,8,0,32,0,32,0,0,0,0,0,0,0,0,0,0,0,0,0,0,0,0,32,0,0,0,8,0,0,0,0
0,0,6,8,6,8,6,8,6,46,0,0,0,0,0,0,0,0,0,0,0,0,0,0,46,3,40,38,37,3,2,3,0,0
0,0,7,0,14,13,35,0,2,40,0,0,0,7,0,0,0,0,0,0,7,0,0,0,37,2,0,0,0,35,0,2,0,0
0,0,6,31,7,0,0,0,2,40,0,0,0,0,0,0,0,0,0,0,0,0,0,0,37,2,0,0,0,7,0,7,0,0
0,0,7,0,0,0,0,0,2,47,0,32,0,32,0,0,0,0,0,0,32,0,32,0,47,2,0,0,13,14,36,2,0,0
0,0,6,31,0,0,0,36,6,6,7,6,7,6,0,32,0,0,32,0,6,7,6,7,6,3,31,0,0,0,0,7,0,0
0,0,7,0,32,0,32,0,7,0,0,0,0,6,7,6,7,7,6,7,6,0,0,0,0,2,0,0,32,0,0,2,0,0
0,0,6,7,6,7,6,7,6,0,0,0,0,0,0,0,0,0,0,0,0,0,0,0,0,3,2,7,2,7,2,3,0,0
0,0,0,0,0,0,0,0,0,0,0,0,0,0,0,0,0,0,0,0,0,0,0,0,0,0,0,0,0,0,0,0,0,0
0,0,0,0,0,0,0,0,0,0,0,0,0,0,0,0,0,0,0,0,0,0,0,0,0,0,0,0,0,0,0,0,0,0
:endlayer
layer: 8
0,0,0,0,0,0,0,0,0,0,0,0,0,0,0,0,0,0,0,0,0,0,0,0,0,0,0,0,0,0,0,0,0,0
0,0,0,0,0,44,44,44,44,44,44,44,44,44,0,0,0,0,0,0,44,44,44,44,44,44,44,44,44,0,0,0,0,0
0,0,0,0,0,43,6,4,4,4,4,4,6,42,0,0,0,0,0,0,43,6,4,4,4,4,4,6,42,0,0,0,0,0
0,0,0,0,0,43,5,0,0,0,0,0,5,42,0,0,0,0,0,0,43,5,0,0,0,0,0,5,42,0,0,0,0,0
0,0,0,0,0,43,5,0,0,0,0,0,5,42,0,0,0,0,0,0,43,5,0,0,0,0,0,5,42,0,0,0,0,0
0,0,0,0,0,43,5,0,0,0,0,0,5,42,0,0,0,0,0,0,43,5,0,0,0,0,0,5,42,0,0,0,0,0
0,0,0,0,0,43,5,0,0,0,0,0,5,42,0,0,0,0,0,0,43,5,0,0,0,0,0,5,42,0,0,0,0,0
0,0,0,0,0,43,5,0,0,0,0,0,5,42,0,0,0,0,0,0,43,5,0,0,0,0,0,5,42,0,0,0,0,0
0,0,0,0,0,43,6,4,4,4,4,4,6,42,0,0,0,0,0,0,43,6,4,4,4,4,4,6,42,0,0,0,0,0
0,0,0,0,0,43,5,42,45,45,45,45,45,42,0,0,0,0,0,0,43,45,45,45,45,45,43,5,42,0,0,0,0,0
0,0,0,0,0,43,5,42,0,0,0,0,0,0,0,0,0,0,0,0,0,0,0,0,0,0,43,5,42,0,0,0,0,0
0,0,0,0,0,43,5,42,0,0,0,0,0,0,0,0,0,0,0,0,0,0,0,0,0,0,43,5,42,0,0,0,0,0
0,2,0,0,0,43,5,42,0,0,0,0,0,0,0,0,0,0,0,0,0,0,0,0,0,0,43,5,42,0,0,0,0,0
0,0,0,0,0,43,5,42,0,0,0,0,0,0,0,0,0,0,0,0,0,0,0,0,0,0,43,5,42,0,0,0,0,0
0,0,0,0,0,43,5,42,0,0,0,0,0,0,0,0,0,0,0,0,0,0,0,0,0,0,43,5,42,0,0,0,0,0
0,0,0,0,0,43,5,42,0,0,0,0,0,0,0,0,0,0,0,0,0,0,0,0,0,0,43,5,42,0,0,0,0,0
0,0,0,0,0,43,5,42,0,0,0,0,0,0,0,0,0,0,0,0,0,0,0,0,0,0,43,5,42,0,0,0,0,0
0,0,0,0,0,43,5,42,0,0,0,0,0,0,0,0,0,0,0,0,0,0,0,0,0,0,43,5,42,0,0,0,0,0
0,0,0,0,0,43,5,42,0,0,0,0,0,0,0,0,0,0,0,0,0,0,0,0,0,0,43,5,42,0,0,0,0,0
0,0,0,0,0,43,5,42,0,0,0,0,0,0,0,0,0,0,0,0,0,0,0,0,0,0,43,5,42,0,0,0,0,0
0,0,0,0,0,43,5,42,0,0,0,0,0,0,0,0,0,0,0,0,0,0,0,0,0,0,43,5,42,0,0,0,0,0
0,0,0,0,0,43,5,42,0,0,0,0,0,0,0,0,0,0,0,0,0,0,0,0,0,0,43,5,42,0,0,0,0,0
0,0,0,0,0,43,5,42,0,0,0,0,43,41,0,0,0,0,0,0,39,42,0,0,0,0,43,5,42,0,0,0,2,0
0,0,0,0,0,43,5,42,0,0,0,0,43,6,4,4,4,4,4,4,6,42,0,0,0,0,43,5,42,0,0,0,0,0
0,0,0,44,44,44,5,44,44,44,44,44,43,5,13,8,13,13,8,13,5,42,44,44,44,44,44,5,44,44,44,0,0,0
0,0,0,48,6,4,4,4,4,4,4,4,4,4,4,4,4,4,4,4,4,4,4,4,4,4,4,4,4,6,48,0,0,0
0,0,44,44,5,13,13,5,13,13,5,13,13,5,13,5,13,13,5,13,5,13,13,5,13,13,5,13,13,5,44,44,0,0
0,0,48,6,5,8,8,5,8,8,5,8,8,5,8,5,8,8,5,8,5,8,8,5,8,8,5,8,8,5,6,48,0,0
0,0,0,5,5,13,13,5,13,13,5,13,13,5,13,5,13,13,5,13,5,13,13,5,13,13,5,13,13,5,5,0,0,0
0,0,0,5,5,8,8,5,8,8,5,8,8,5,8,5,8,8,5,8,5,8,8,5,8,8,5,8,8,5,5,0,0,0
0,0,49,6,5,13,13,5,13,13,5,13,13,5,13,5,13,13,5,13,5,13,13,5,13,13,5,13,13,5,6,49,0,0
0,0,45,45,5,8,8,5,8,8,5,8,8,5,8,5,8,8,5,8,5,8,8,5,8,8,5,8,8,5,45,45,0,0
0,0,6,4,4,4,4,4,6,13,5,13,13,5,13,5,13,13,5,13,5,13,13,5,13,3,3,3,3,3,3,3,0,0
0,0,5,0,0,0,8,13,5,8,5,8,8,5,8,5,8,8,5,8,5,8,8,5,8,3,13,8,13,0,0,3,0,0
0,0,5,0,7,14,8,13,5,2,5,13,13,5,13,5,13,13,5,13,5,13,13,5,2,3,13,8,14,7,0,3,0,0
0,0,5,13,13,13,8,13,5,8,5,8,8,5,8,5,8,8,5,8,5,8,8,5,8,3,13,8,0,0,0,3,0,0
0,0,5,8,8,8,8,8,5,4,4,4,4,5,13,5,13,13,5,13,5,4,4,4,4,3,8,8,8,8,8,3,0,0
0,0,5,13,13,13,8,13,5,45,45,45,43,6,4,4,4,4,4,4,6,42,45,45,45,3,13,8,13,13,13,3,0,0
0,0,6,4,4,4,4,4,6,0,0,0,43,41,0,0,0,0,0,0,39,42,0,0,0,3,3,3,3,3,3,3,0,0
0,0,0,0,0,0,0,0,0,0,0,0,0,0,0,0,0,0,0,0,0,0,0,0,0,0,0,0,0,0,0,0,0,0
0,0,0,0,0,0,0,0,0,0,0,0,0,0,0,0,0,0,0,0,0,0,0,0,0,0,0,0,0,0,0,0,0,0
:endlayer
layer: 9
0,0,0,0,0,0,0,0,0,0,0,0,0,0,0,0,0,0,0,0,0,0,0,0,0,0,0,0,0,0,0,0,0,0
0,0,0,0,0,0,0,0,0,0,0,0,0,0,0,0,0,0,0,0,0,0,0,0,0,0,0,0,0,0,0,0,0,0
0,0,0,0,0,0,44,44,44,44,44,44,44,0,0,0,0,0,0,0,0,44,44,44,44,44,44,44,0,0,0,0,0,0
0,0,0,0,0,0,43,48,48,48,48,39,42,0,0,0,0,0,0,0,0,43,41,48,48,48,48,42,0,0,0,0,0,0
0,0,0,0,0,0,43,41,0,0,0,39,42,0,0,0,0,0,0,0,0,43,41,0,0,0,39,42,0,0,0,0,0,0
0,0,0,0,0,0,43,41,0,0,0,39,42,0,0,0,0,0,0,0,0,43,41,0,0,0,39,42,0,0,0,0,0,0
0,0,0,0,0,0,43,41,0,0,0,39,42,0,0,0,0,0,0,0,0,43,41,0,0,0,39,42,0,0,0,0,0,0
0,0,0,0,0,0,43,41,49,49,49,49,42,0,0,0,0,0,0,0,0,43,49,49,49,49,39,42,0,0,0,0,0,0
0,0,0,0,0,0,43,45,45,45,45,45,45,0,0,0,0,0,0,0,0,45,45,45,45,45,45,42,0,0,0,0,0,0
0,0,0,0,0,0,14,0,0,0,0,0,0,0,0,0,0,0,0,0,0,0,0,0,0,0,0,14,0,0,0,0,0,0
0,0,0,0,0,0,14,0,0,0,0,0,0,0,0,0,0,0,0,0,0,0,0,0,0,0,0,14,0,0,0,0,0,0
0,0,0,0,0,0,14,0,0,0,0,0,0,0,0,0,0,0,0,0,0,0,0,0,0,0,0,14,0,0,0,0,0,0
0,2,0,0,0,0,14,0,0,0,0,0,0,0,0,0,0,0,0,0,0,0,0,0,0,0,0,14,0,0,0,0,0,0
0,0,0,0,0,0,14,0,0,0,0,0,0,0,0,0,0,0,0,0,0,0,0,0,0,0,0,14,0,0,0,0,0,0
0,0,0,0,0,0,14,0,0,0,0,0,0,0,0,0,0,0,0,0,0,0,0,0,0,0,0,14,0,0,0,0,0,0
0,0,0,0,0,0,14,0,0,0,0,0,0,0,0,0,0,0,0,0,0,0,0,0,0,0,0,14,0,0,0,0,0,0
0,0,0,0,0,0,14,0,0,0,0,0,0,0,0,0,0,0,0,0,0,0,0,0,0,0,0,14,0,0,0,0,0,0
0,0,0,0,0,0,14,0,0,0,0,0,0,0,0,0,0,0,0,0,0,0,0,0,0,0,0,14,0,0,0,0,0,0
0,0,0,0,0,0,14,0,0,0,0,0,0,0,0,0,0,0,0,0,0,0,0,0,0,0,0,14,0,0,0,0,0,0
0,0,0,0,0,0,14,0,0,0,0,0,0,0,0,0,0,0,0,0,0,0,0,0,0,0,0,14,0,0,0,0,0,0
0,0,0,0,0,0,14,0,0,0,0,0,0,0,0,0,0,0,0,0,0,0,0,0,0,0,0,14,0,0,0,0,0,0
0,0,0,0,0,0,14,0,0,0,0,0,0,0,0,0,0,0,0,0,0,0,0,0,0,0,0,14,0,0,0,0,0,0
0,0,0,0,0,0,14,0,0,0,0,0,0,43,41,0,0,0,0,39,42,0,0,0,0,0,0,14,0,0,0,0,2,0
0,0,0,0,0,0,14,0,0,0,0,0,0,43,6,8,8,8,8,6,42,0,0,0,0,0,0,14,0,0,0,0,0,0
0,0,0,0,0,0,14,0,0,0,0,0,0,43,41,35,0,0,35,39,42,0,0,0,0,0,0,14,0,0,0,0,0,0
0,0,0,44,44,44,44,44,44,44,44,44,44,44,41,0,0,0,0,39,44,44,44,44,44,44,44,44,44,44,44,0,0,0
0,0,0,48,6,48,48,48,48,48,48,48,48,6,48,0,0,0,0,48,6,48,48,48,48,48,48,48,48,6,48,0,0,0
0,0,44,44,8,0,0,0,0,0,0,0,0,48,0,0,0,0,0,0,48,0,0,0,0,0,0,0,0,8,44,44,0,0
0,0,48,8,8,0,0,0,0,0,0,0,0,21,0,0,0,0,0,0,21,0,0,0,0,0,0,0,0,8,8,48,0,0
0,0,49,8,6,0,0,0,0,0,0,0,0,0,0,0,0,0,0,0,0,0,0,0,0,0,0,0,0,6,8,49,0,0
0,0,45,45,8,0,0,0,0,0,0,0,0,0,0,0,0,0,0,0,0,0,0,0,0,0,0,0,0,8,45,45,0,0
0,0,0,0,8,0,0,0,0,0,0,0,0,0,0,0,0,0,0,0,0,0,0,0,0,0,0,0,0,8,0,0,0,0
0,0,6,8,6,8,6,0,6,0,0,0,0,0,0,0,0,0,0,0,0,0,0,0,0,6,0,6,8,6,8,6,0,0
0,0,8,0,0,0,0,0,8,0,0,0,0,21,0,0,0,0,0,0,21,0,0,0,0,0,0,0,0,14,13,8,0,0
0,0,6,7,7,0,0,0,6,2,0,0,0,49,0,0,0,0,0,0,49,0,0,0,2,6,0,0,0,7,0,6,0,0
0,0,8,0,0,0,0,0,8,49,49,49,49,6,49,0,0,0,0,49,6,49,49,49,49,8,0,0,0,0,0,8,0,0
0,0,6,0,0,0,0,0,6,45,45,45,45,45,41,32,0,0,32,39,45,45,45,45,45,6,0,0,0,0,0,6,0,0
0,0,8,0,0,0,0,0,8,0,0,0,0,43,6,8,8,8,8,6,42,0,0,0,0,8,0,0,0,0,0,8,0,0
0,0,6,8,6,8,6,8,6,0,0,0,0,43,41,0,0,0,0,39,42,0,0,0,0,6,8,6,8,6,8,6,0,0
0,0,0,0,0,0,0,0,0,0,0,0,0,0,0,0,0,0,0,0,0,0,0,0,0,0,0,0,0,0,0,0,0,0
0,0,0,0,0,0,0,0,0,0,0,0,0,0,0,0,0,0,0,0,0,0,0,0,0,0,0,0,0,0,0,0,0,0
:endlayer
layer: 10
0,0,0,0,0,0,0,0,0,0,0,0,0,0,0,0,0,0,0,0,0,0,0,0,0,0,0,0,0,0,0,0,0,0
0,0,0,0,0,0,0,0,0,0,0,0,0,0,0,0,0,0,0,0,0,0,0,0,0,0,0,0,0,0,0,0,0,0
0,0,0,0,0,0,0,0,0,0,0,0,0,0,0,0,0,0,0,0,0,0,0,0,0,0,0,0,0,0,0,0,0,0
0,0,0,0,0,0,0,43,44,44,44,44,0,0,0,0,0,0,0,0,0,0,44,44,44,44,42,0,0,0,0,0,0,0
0,0,0,0,0,0,0,43,41,48,48,42,0,0,0,0,0,0,0,0,0,0,43,48,48,39,42,0,0,0,0,0,0,0
0,0,0,0,0,0,0,43,41,0,39,42,0,0,0,0,0,0,0,0,0,0,43,41,0,39,42,0,0,0,0,0,0,0
0,0,0,0,0,0,0,43,49,49,39,42,0,0,0,0,0,0,0,0,0,0,43,41,49,49,42,0,0,0,0,0,0,0
0,0,0,0,0,0,0,45,45,45,45,42,0,0,0,0,0,0,0,0,0,0,43,45,45,45,45,0,0,0,0,0,0,0
0,0,0,0,0,0,0,0,0,0,0,0,0,0,0,0,0,0,0,0,0,0,0,0,0,0,0,0,0,0,0,0,0,0
0,0,0,0,0,0,0,0,0,0,0,0,0,0,0,0,0,0,0,0,0,0,0,0,0,0,0,0,0,0,0,0,0,0
0,0,0,0,0,0,0,0,0,0,0,0,0,0,0,0,0,0,0,0,0,0,0,0,0,0,0,0,0,0,0,0,0,0
0,0,0,0,0,0,0,0,0,0,0,0,0,0,0,0,0,0,0,0,0,0,0,0,0,0,0,0,0,0,0,0,0,0
0,50,0,0,0,0,0,0,0,0,0,0,0,0,0,0,0,0,0,0,0,0,0,0,0,0,0,0,0,0,0,0,0,0
0,0,0,0,0,0,0,0,0,0,0,0,0,0,0,0,0,0,0,0,0,0,0,0,0,0,0,0,0,0,0,0,0,0
0,0,0,0,0,0,0,0,0,0,0,0,0,0,0,0,0,0,0,0,0,0,0,0,0,0,0,0,0,0,0,0,0,0
0,0,0,0,0,0,0,0,0,0,0,0,0,0,0,0,0,0,0,0,0,0,0,0,0,0,0,0,0,0,0,0,0,0
0,0,0,0,0,0,0,0,0,0,0,0,0,0,0,0,0,0,0,0,0,0,0,0,0,0,0,0,0,0,0,0,0,0
0,0,0,0,0,0,0,0,0,0,0,0,0,0,0,0,0,0,0,0,0,0,0,0,0,0,0,0,0,0,0,0,0,0
0,0,0,0,0,0,0,0,0,0,0,0,0,0,0,0,0,0,0,0,0,0,0,0,0,0,0,0,0,0,0,0,0,0
0,0,0,0,0,0,0,0,0,0,0,0,0,0,0,0,0,0,0,0,0,0,0,0,0,0,0,0,0,0,0,0,0,0
0,0,0,0,0,0,0,0,0,0,0,0,0,0,0,0,0,0,0,0,0,0,0,0,0,0,0,0,0,0,0,0,0,0
0,0,0,0,0,0,0,0,0,0,0,0,0,0,0,0,0,0,0,0,0,0,0,0,0,0,0,0,0,0,0,0,0,0
0,0,0,0,0,0,0,0,0,0,0,0,0,0,43,41,0,0,39,42,0,0,0,0,0,0,0,0,0,0,0,0,2,0
0,0,0,0,0,0,0,0,0,0,0,0,0,0,43,6,8,8,6,42,0,0,0,0,0,0,0,0,0,0,0,0,0,0
0,0,0,0,0,0,0,0,0,0,0,0,0,0,43,41,0,0,39,42,0,0,0,0,0,0,0,0,0,0,0,0,0,0
0,0,0,0,0,0,0,0,0,0,0,0,0,0,43,41,0,0,39,42,0,0,0,0,0,0,0,0,0,0,0,0,0,0
0,0,0,44,44,44,44,44,44,44,44,44,44,44,44,41,0,0,39,42,44,44,44,44,44,44,44,44,44,44,44,0,0,0
0,0,0,48,6,48,48,48,48,48,48,48,48,6,48,48,0,0,39,48,6,48,48,48,48,48,48,48,48,6,48,0,0,0
0,0,44,44,8,0,0,0,0,0,0,0,0,48,0,0,0,0,0,0,48,0,0,0,0,0,0,0,0,8,44,44,0,0
0,0,45,45,6,0,0,0,0,0,0,0,0,0,0,0,0,0,0,0,0,0,0,0,0,0,0,0,0,6,45,45,0,0
0,0,0,0,7,0,0,0,0,0,0,0,0,0,0,0,0,0,0,0,0,0,0,0,0,0,0,0,0,7,0,0,0,0
0,0,0,0,7,0,0,0,0,0,0,0,0,0,0,0,0,0,0,0,0,0,0,0,0,0,0,0,0,7,0,0,0,0
0,0,6,7,6,8,6,0,6,0,0,0,0,0,0,0,0,0,0,0,0,0,0,0,0,6,0,6,8,6,7,6,0,0
0,0,7,0,0,0,0,0,8,0,0,0,0,49,0,0,0,0,0,0,49,0,0,0,0,0,0,0,0,0,0,7,0,0
0,0,6,0,7,0,0,0,6,2,49,49,49,6,49,41,0,0,49,49,6,49,49,49,2,6,0,0,0,7,14,6,0,0
0,0,7,0,0,0,0,0,8,45,45,45,45,45,43,41,0,0,39,42,45,45,45,45,45,8,0,0,0,0,13,7,0,0
0,0,6,0,0,0,0,0,6,0,0,0,0,0,43,41,0,0,39,42,0,0,0,0,0,6,0,0,0,0,0,6,0,0
0,0,7,0,0,0,0,0,7,0,0,0,0,0,43,6,8,8,6,42,0,0,0,0,0,7,0,0,0,0,0,7,0,0
0,0,6,7,6,7,6,7,6,0,0,0,0,0,43,41,0,0,39,42,0,0,0,0,0,6,7,6,7,6,7,6,0,0
0,0,0,0,0,0,0,0,0,0,0,0,0,0,0,0,0,0,0,0,0,0,0,0,0,0,0,0,0,0,0,0,0,0
0,0,0,0,0,0,0,0,0,0,0,0,0,0,0,0,0,0,0,0,0,0,0,0,0,0,0,0,0,0,0,0,0,0
:endlayer
layer: 11
0,0,0,0,0,0,0,0,0,0,0,0,0,0,0,0,0,0,0,0,0,0,0,0,0,0,0,0,0,0,0,0,0,0
0,0,0,0,0,0,0,0,0,0,0,0,0,0,0,0,0,0,0,0,0,0,0,0,0,0,0,0,0,0,0,0,0,0
0,0,0,0,0,0,0,0,0,0,0,0,0,0,0,0,0,0,0,0,0,0,0,0,0,0,0,0,0,0,0,0,0,0
0,0,0,0,0,0,0,0,0,0,0,0,0,0,0,0,0,0,0,0,0,0,0,0,0,0,0,0,0,0,0,0,0,0
0,0,0,0,0,0,0,0,43,44,44,0,0,0,0,0,0,0,0,0,0,0,0,44,44,42,0,0,0,0,0,0,0,0
0,0,0,0,0,0,0,0,43,8,42,0,0,0,0,0,0,0,0,0,0,0,0,43,8,42,0,0,0,0,0,0,0,0
0,0,0,0,0,0,0,0,45,45,42,0,0,0,0,0,0,0,0,0,0,0,0,43,45,45,0,0,0,0,0,0,0,0
0,0,0,0,0,0,0,0,0,0,0,0,0,0,0,0,0,0,0,0,0,0,0,0,0,0,0,0,0,0,0,0,0,0
0,0,0,0,0,0,0,0,0,0,0,0,0,0,0,0,0,0,0,0,0,0,0,0,0,0,0,0,0,0,0,0,0,0
0,0,0,0,0,0,0,0,0,0,0,0,0,0,0,0,0,0,0,0,0,0,0,0,0,0,0,0,0,0,0,0,0,0
0,0,0,0,0,0,0,0,0,0,0,0,0,0,0,0,0,0,0,0,0,0,0,0,0,0,0,0,0,0,0,0,0,0
0,0,0,0,0,0,0,0,0,0,0,0,0,0,0,0,0,0,0,0,0,0,0,0,0,0,0,0,0,0,0,0,0,0
0,12,0,0,0,0,0,0,0,0,0,0,0,0,0,0,0,0,0,0,0,0,0,0,0,0,0,0,0,0,0,0,0,0
0,0,0,0,0,0,0,0,0,0,0,0,0,0,0,0,0,0,0,0,0,0,0,0,0,0,0,0,0,0,0,0,0,0
0,0,0,0,0,0,0,0,0,0,0,0,0,0,0,0,0,0,0,0,0,0,0,0,0,0,0,0,0,0,0,0,0,0
0,0,0,0,0,0,0,0,0,0,0,0,0,0,0,0,0,0,0,0,0,0,0,0,0,0,0,0,0,0,0,0,0,0
0,0,0,0,0,0,0,0,0,0,0,0,0,0,0,0,0,0,0,0,0,0,0,0,0,0,0,0,0,0,0,0,0,0
0,0,0,0,0,0,0,0,0,0,0,0,0,0,0,0,0,0,0,0,0,0,0,0,0,0,0,0,0,0,0,0,0,0
0,0,0,0,0,0,0,0,0,0,0,0,0,0,0,0,0,0,0,0,0,0,0,0,0,0,0,0,0,0,0,0,0,0
0,0,0,0,0,0,0,0,0,0,0,0,0,0,0,0,0,0,0,0,0,0,0,0,0,0,0,0,0,0,0,0,0,0
0,0,0,0,0,0,0,0,0,0,0,0,0,0,0,0,0,0,0,0,0,0,0,0,0,0,0,0,0,0,0,0,0,0
0,0,0,0,0,0,0,0,0,0,0,0,0,0,0,0,0,0,0,0,0,0,0,0,0,0,0,0,0,0,0,0,0,0
0,0,0,0,0,0,0,0,0,0,0,0,0,0,0,43,41,39,42,0,0,0,0,0,0,0,0,0,0,0,0,0,50,0
0,0,0,0,0,0,0,0,0,0,0,0,0,0,0,43,4,4,42,0,0,0,0,0,0,0,0,0,0,0,0,0,0,0
0,0,0,0,0,0,0,0,0,0,0,0,0,0,0,43,41,39,42,0,0,0,0,0,0,0,0,0,0,0,0,0,0,0
0,0,0,0,0,0,0,0,0,0,0,0,0,0,0,43,41,39,42,0,0,0,0,0,0,0,0,0,0,0,0,0,0,0
0,0,0,0,0,0,0,0,0,0,0,0,0,0,0,43,41,39,42,0,0,0,0,0,0,0,0,0,0,0,0,0,0,0
0,0,0,44,44,44,44,44,44,44,44,44,44,44,44,44,41,39,42,44,44,44,44,44,44,44,44,44,44,44,44,0,0,0
0,0,0,48,6,48,48,48,48,48,48,48,48,6,48,48,41,39,48,48,6,48,48,48,48,48,48,48,48,6,48,0,0,0
0,0,0,0,6,31,0,0,0,0,0,0,0,48,0,0,0,0,0,0,48,0,0,0,0,0,0,0,36,6,0,0,0,0
0,0,0,0,7,0,0,0,0,0,0,0,0,0,0,0,0,0,0,0,0,0,0,0,0,0,0,0,0,7,0,0,0,0
0,0,7,0,7,0,0,0,32,0,0,0,0,0,0,0,0,0,0,0,0,0,0,0,0,32,0,0,0,7,0,0,0,0
0,7,6,7,6,8,6,8,6,31,0,0,0,49,0,0,0,0,0,0,49,0,0,0,36,6,8,6,8,6,7,6,0,0
0,0,7,0,35,0,35,0,8,49,49,49,49,6,49,49,41,49,49,49,6,49,49,49,49,8,0,35,0,35,0,7,0,0
0,7,6,31,7,0,0,36,6,2,45,45,45,45,45,43,41,39,45,45,45,45,45,45,2,6,31,0,0,7,36,6,0,0
0,0,7,0,0,0,0,0,8,0,0,0,0,0,0,43,41,39,42,0,0,0,0,0,0,8,0,0,13,14,0,7,0,0
0,7,6,31,0,0,0,36,6,7,0,0,0,0,0,43,41,39,42,0,0,0,0,0,0,6,31,0,0,0,36,6,0,0
0,0,7,0,32,0,32,0,7,0,0,0,0,0,0,43,4,4,42,0,0,0,0,0,0,7,0,32,0,32,0,7,0,0
0,7,6,7,6,7,6,7,6,7,0,0,0,0,0,43,41,39,42,0,0,0,0,0,0,6,7,6,7,6,7,6,0,0
0,0,7,0,7,0,7,0,7,0,0,0,0,0,0,0,0,0,0,0,0,0,0,0,0,0,0,0,0,0,0,0,0,0
0,0,0,0,0,0,0,0,0,0,0,0,0,0,0,0,0,0,0,0,0,0,0,0,0,0,0,0,0,0,0,0,0,0
:endlayer
layer: 12
0,0,0,0,0,0,0,0,0,0,0,0,0,0,0,0,0,0,0,0,0,0,0,0,0,0,0,0,0,0,0,0,0,0
0,0,0,0,0,0,0,0,0,0,0,0,0,0,0,0,0,0,0,0,0,0,0,0,0,0,0,0,0,0,0,0,0,0
0,0,0,0,0,0,0,0,0,0,0,0,0,0,0,0,0,0,0,0,0,0,0,0,0,0,0,0,0,0,0,0,0,0
0,0,0,0,0,0,0,0,0,0,0,0,0,0,0,0,0,0,0,0,0,0,0,0,0,0,0,0,0,0,0,0,0,0
0,0,0,0,0,0,0,0,0,0,0,0,0,0,0,0,0,0,0,0,0,0,0,0,0,0,0,0,0,0,0,0,0,0
0,0,0,0,0,0,0,0,0,7,0,0,0,0,0,0,0,0,0,0,0,0,0,0,7,0,0,0,0,0,0,0,0,0
0,0,0,0,0,0,0,0,0,0,0,0,0,0,0,0,0,0,0,0,0,0,0,0,0,0,0,0,0,0,0,0,0,0
0,0,0,0,0,0,0,0,0,0,0,0,0,0,0,0,0,0,0,0,0,0,0,0,0,0,0,0,0,0,0,0,0,0
0,0,0,0,0,0,0,0,0,0,0,0,0,0,0,0,0,0,0,0,0,0,0,0,0,0,0,0,0,0,0,0,0,0
0,0,0,0,0,0,0,0,0,0,0,0,0,0,0,0,0,0,0,0,0,0,0,0,0,0,0,0,0,0,0,0,0,0
0,0,0,0,0,0,0,0,0,0,0,0,0,0,0,0,0,0,0,0,0,0,0,0,0,0,0,0,0,0,0,0,0,0
0,0,0,0,0,0,0,0,0,0,0,0,0,0,0,0,0,0,0,0,0,0,0,0,0,0,0,0,0,0,0,0,0,0
0,0,0,0,0,0,0,0,0,0,0,0,0,0,0,0,0,0,0,0,0,0,0,0,0,0,0,0,0,0,0,0,0,0
0,0,0,0,0,0,0,0,0,0,0,0,0,0,0,0,0,0,0,0,0,0,0,0,0,0,0,0,0,0,0,0,0,0
0,0,0,0,0,0,0,0,0,0,0,0,0,0,0,0,0,0,0,0,0,0,0,0,0,0,0,0,0,0,0,0,0,0
0,0,0,0,0,0,0,0,0,0,0,0,0,0,0,0,0,0,0,0,0,0,0,0,0,0,0,0,0,0,0,0,0,0
0,0,0,0,0,0,0,0,0,0,0,0,0,0,0,0,0,0,0,0,0,0,0,0,0,0,0,0,0,0,0,0,0,0
0,0,0,0,0,0,0,0,0,0,0,0,0,0,0,0,0,0,0,0,0,0,0,0,0,0,0,0,0,0,0,0,0,0
0,0,0,0,0,0,0,0,0,0,0,0,0,0,0,0,0,0,0,0,0,0,0,0,0,0,0,0,0,0,0,0,0,0
0,0,0,0,0,0,0,0,0,0,0,0,0,0,0,0,0,0,0,0,0,0,0,0,0,0,0,0,0,0,0,0,0,0
0,0,0,0,0,0,0,0,0,0,0,0,0,0,0,0,0,0,0,0,0,0,0,0,0,0,0,0,0,0,0,0,0,0
0,0,0,0,0,0,0,0,0,0,0,0,0,0,0,0,0,0,0,0,0,0,0,0,0,0,0,0,0,0,0,0,0,0
0,0,0,0,0,0,0,0,0,0,0,0,0,0,0,0,43,42,0,0,0,0,0,0,0,0,0,0,0,0,0,0,12,0
0,0,0,0,0,0,0,0,0,0,0,0,0,0,0,0,43,42,0,0,0,0,0,0,0,0,0,0,0,0,0,0,0,0
0,0,0,0,0,0,0,0,0,0,0,0,0,0,0,0,43,42,0,0,0,0,0,0,0,0,0,0,0,0,0,0,0,0
0,0,0,0,0,0,0,0,0,0,0,0,0,0,0,0,43,42,0,0,0,0,0,0,0,0,0,0,0,0,0,0,0,0
0,0,0,0,0,0,0,0,0,0,0,0,0,0,0,0,43,42,0,0,0,0,0,0,0,0,0,0,0,0,0,0,0,0
0,0,0,0,0,0,0,0,0,0,0,0,0,0,0,0,43,42,0,0,0,0,0,0,0,0,0,0,0,0,0,0,0,0
0,0,0,44,44,44,44,44,44,44,44,44,44,44,44,44,44,42,44,44,44,44,44,44,44,44,44,44,44,44,44,0,0,0
0,0,0,48,6,48,48,48,48,48,48,48,48,6,48,48,48,48,48,48,6,48,48,48,48,48,48,48,48,6,48,0,0,0
0,0,0,0,8,0,0,0,0,0,0,0,0,48,0,0,0,0,0,0,48,0,0,0,0,0,0,0,0,8,0,0,0,0
0,44,44,44,8,0,0,0,0,0,0,0,0,49,0,0,0,0,0,0,49,0,0,0,0,0,0,0,0,8,0,0,0,0
0,43,6,4,4,4,4,4,6,49,49,49,49,6,49,49,49,49,49,49,6,49,49,49,49,6,4,4,4,4,4,6,0,0
0,43,5,0,0,0,0,0,5,42,45,45,45,45,45,45,43,45,45,45,45,45,45,45,45,5,13,8,13,0,0,5,0,0
0,43,5,0,7,0,0,0,5,2,0,0,0,0,0,0,43,42,0,0,0,0,0,0,2,5,13,8,14,7,0,5,0,0
0,43,5,0,0,0,0,0,5,42,0,0,0,0,0,0,43,42,0,0,0,0,0,0,0,5,13,8,0,0,0,5,0,0
0,43,5,0,0,0,0,0,5,42,0,0,0,0,0,0,43,42,0,0,0,0,0,0,0,5,8,8,8,8,8,5,0,0
0,43,5,0,0,0,0,0,5,42,0,0,0,0,0,0,43,42,0,0,0,0,0,0,0,5,13,8,13,13,13,5,0,0
0,43,6,4,4,4,4,4,6,42,0,0,0,0,0,0,43,42,0,0,0,0,0,0,0,6,4,4,4,4,4,6,0,0
0,43,45,45,45,45,45,45,45,45,0,0,0,0,0,0,0,0,0,0,0,0,0,0,0,0,0,0,0,0,0,0,0,0
0,0,0,0,0,0,0,0,0,0,0,0,0,0,0,0,0,0,0,0,0,0,0,0,0,0,0,0,0,0,0,0,0,0
:endlayer
layer: 13
0,0,0,0,0,0,0,0,0,0,0,0,0,0,0,0,0,0,0,0,0,0,0,0,0,0,0,0,0,0,0,0,0,0
0,0,0,0,0,0,0,0,0,0,0,0,0,0,0,0,0,0,0,0,0,0,0,0,0,0,0,0,0,0,0,0,0,0
0,0,0,0,0,0,0,0,0,0,0,0,0,0,0,0,0,0,0,0,0,0,0,0,0,0,0,0,0,0,0,0,0,0
0,0,0,0,0,0,0,0,0,0,0,0,0,0,0,0,0,0,0,0,0,0,0,0,0,0,0,0,0,0,0,0,0,0
0,0,0,0,0,0,0,0,0,0,0,0,0,0,0,0,0,0,0,0,0,0,0,0,0,0,0,0,0,0,0,0,0,0
0,0,0,0,0,0,0,0,0,7,0,0,0,0,0,0,0,0,0,0,0,0,0,0,7,0,0,0,0,0,0,0,0,0
0,0,0,0,0,0,0,0,0,0,0,0,0,0,0,0,0,0,0,0,0,0,0,0,0,0,0,0,0,0,0,0,0,0
0,0,0,0,0,0,0,0,0,0,0,0,0,0,0,0,0,0,0,0,0,0,0,0,0,0,0,0,0,0,0,0,0,0
0,0,0,0,0,0,0,0,0,0,0,0,0,0,0,0,0,0,0,0,0,0,0,0,0,0,0,0,0,0,0,0,0,0
0,0,0,0,0,0,0,0,0,0,0,0,0,0,0,0,0,0,0,0,0,0,0,0,0,0,0,0,0,0,0,0,0,0
0,0,0,0,0,0,0,0,0,0,0,0,0,0,0,0,0,0,0,0,0,0,0,0,0,0,0,0,0,0,0,0,0,0
0,0,0,0,0,0,0,0,0,0,0,0,0,0,0,0,0,0,0,0,0,0,0,0,0,0,0,0,0,0,0,0,0,0
0,0,0,0,0,0,0,0,0,0,0,0,0,0,0,0,0,0,0,0,0,0,0,0,0,0,0,0,0,0,0,0,0,0
0,0,0,0,0,0,0,0,0,0,0,0,0,0,0,0,0,0,0,0,0,0,0,0,0,0,0,0,0,0,0,0,0,0
0,0,0,0,0,0,0,0,0,0,0,0,0,0,0,0,0,0,0,0,0,0,0,0,0,0,0,0,0,0,0,0,0,0
0,0,0,0,0,0,0,0,0,0,0,0,0,0,0,0,0,0,0,0,0,0,0,0,0,0,0,0,0,0,0,0,0,0
0,0,0,0,0,0,0,0,0,0,0,0,0,0,0,0,0,0,0,0,0,0,0,0,0,0,0,0,0,0,0,0,0,0
0,0,0,0,0,0,0,0,0,0,0,0,0,0,0,0,0,0,0,0,0,0,0,0,0,0,0,0,0,0,0,0,0,0
0,0,0,0,0,0,0,0,0,0,0,0,0,0,0,0,0,0,0,0,0,0,0,0,0,0,0,0,0,0,0,0,0,0
0,0,0,0,0,0,0,0,0,0,0,0,0,0,0,0,0,0,0,0,0,0,0,0,0,0,0,0,0,0,0,0,0,0
0,0,0,0,0,0,0,0,0,0,0,0,0,0,0,0,0,0,0,0,0,0,0,0,0,0,0,0,0,0,0,0,0,0
0,0,0,0,0,0,0,0,0,0,0,0,0,0,0,0,0,0,0,0,0,0,0,0,0,0,0,0,0,0,0,0,0,0
0,0,0,0,0,0,0,0,0,0,0,0,0,0,0,0,0,0,0,0,0,0,0,0,0,0,0,0,0,0,0,0,0,0
0,0,0,0,0,0,0,0,0,0,0,0,0,0,0,0,0,0,0,0,0,0,0,0,0,0,0,0,0,0,0,0,0,0
0,0,0,0,0,0,0,0,0,0,0,0,0,0,0,0,0,0,0,0,0,0,0,0,0,0,0,0,0,0,0,0,0,0
0,0,0,0,0,0,0,0,0,0,0,0,0,0,0,0,0,0,0,0,0,0,0,0,0,0,0,0,0,0,0,0,0,0
0,0,0,0,0,0,0,0,0,0,0,0,0,0,0,0,0,0,0,0,0,0,0,0,0,0,0,0,0,0,0,0,0,0
0,0,0,0,0,0,0,0,0,0,0,0,0,0,0,0,0,0,0,0,0,0,0,0,0,0,0,0,0,0,0,0,0,0
0,0,0,0,0,0,0,0,0,0,0,0,0,0,0,0,0,0,0,0,0,0,0,0,0,0,0,0,0,0,0,0,0,0
0,0,0,44,44,44,44,44,44,44,44,44,44,44,44,44,44,44,44,44,44,44,44,44,44,44,44,44,44,44,44,0,0,0
0,0,0,48,5,48,48,48,48,48,48,48,48,5,48,48,48,48,48,48,5,48,48,48,48,48,48,48,48,5,48,0,0,0
0,0,0,49,5,49,49,49,49,49,49,49,49,5,49,49,49,49,49,49,5,49,49,49,49,49,49,49,49,5,49,0,0,0
0,0,44,8,8,8,8,8,45,45,45,45,45,45,45,45,45,45,45,45,45,45,45,45,45,6,8,6,8,6,8,6,0,0
0,0,43,41,48,48,48,48,42,0,0,0,0,0,0,0,0,0,0,0,0,0,0,0,0,8,0,0,0,7,0,8,0,0
0,0,43,41,7,0,0,39,42,2,0,0,0,0,0,0,0,0,0,0,0,0,0,0,2,6,0,0,0,7,0,6,0,0
0,0,43,41,0,0,0,39,42,0,0,0,0,0,0,0,0,0,0,0,0,0,0,0,0,8,0,0,0,0,0,8,0,0
0,0,43,41,0,0,0,39,42,0,0,0,0,0,0,0,0,0,0,0,0,0,0,0,0,6,0,0,0,0,0,6,0,0
0,0,43,49,49,49,49,39,42,0,0,0,0,0,0,0,0,0,0,0,0,0,0,0,0,8,0,0,0,0,0,8,0,0
0,0,45,45,45,45,45,45,42,0,0,0,0,0,0,0,0,0,0,0,0,0,0,0,0,6,8,6,8,6,8,6,0,0
0,0,0,0,0,0,0,0,0,0,0,0,0,0,0,0,0,0,0,0,0,0,0,0,0,0,0,0,0,0,0,0,0,0
0,0,0,0,0,0,0,0,0,0,0,0,0,0,0,0,0,0,0,0,0,0,0,0,0,0,0,0,0,0,0,0,0,0
:endlayer
layer: 14
0,0,0,0,0,0,0,0,0,0,0,0,0,0,0,0,0,0,0,0,0,0,0,0,0,0,0,0,0,0,0,0,0,0
0,0,0,0,0,0,0,0,0,0,0,0,0,0,0,0,0,0,0,0,0,0,0,0,0,0,0,0,0,0,0,0,0,0
0,0,0,0,0,0,0,0,0,0,0,0,0,0,0,0,0,0,0,0,0,0,0,0,0,0,0,0,0,0,0,0,0,0
0,0,0,0,0,0,0,0,0,0,0,0,0,0,0,0,0,0,0,0,0,0,0,0,0,0,0,0,0,0,0,0,0,0
0,0,0,0,0,0,0,0,0,0,0,0,0,0,0,0,0,0,0,0,0,0,0,0,0,0,0,0,0,0,0,0,0,0
0,0,0,0,0,0,0,0,0,21,0,0,0,0,0,0,0,0,0,0,0,0,0,0,21,0,0,0,0,0,0,0,0,0
0,0,0,0,0,0,0,0,0,0,0,0,0,0,0,0,0,0,0,0,0,0,0,0,0,0,0,0,0,0,0,0,0,0
0,0,0,0,0,0,0,0,0,0,0,0,0,0,0,0,0,0,0,0,0,0,0,0,0,0,0,0,0,0,0,0,0,0
0,0,0,0,0,0,0,0,0,0,0,0,0,0,0,0,0,0,0,0,0,0,0,0,0,0,0,0,0,0,0,0,0,0
0,0,0,0,0,0,0,0,0,0,0,0,0,0,0,0,0,0,0,0,0,0,0,0,0,0,0,0,0,0,0,0,0,0
0,0,0,0,0,0,0,0,0,0,0,0,0,0,0,0,0,0,0,0,0,0,0,0,0,0,0,0,0,0,0,0,0,0
0,0,0,0,0,0,0,0,0,0,0,0,0,0,0,0,0,0,0,0,0,0,0,0,0,0,0,0,0,0,0,0,0,0
0,0,0,0,0,0,0,0,0,0,0,0,0,0,0,0,0,0,0,0,0,0,0,0,0,0,0,0,0,0,0,0,0,0
0,0,0,0,0,0,0,0,0,0,0,0,0,0,0,0,0,0,0,0,0,0,0,0,0,0,0,0,0,0,0,0,0,0
0,0,0,0,0,0,0,0,0,0,0,0,0,0,0,0,0,0,0,0,0,0,0,0,0,0,0,0,0,0,0,0,0,0
0,0,0,0,0,0,0,0,0,0,0,0,0,0,0,0,0,0,0,0,0,0,0,0,0,0,0,0,0,0,0,0,0,0
0,0,0,0,0,0,0,0,0,0,0,0,0,0,0,0,0,0,0,0,0,0,0,0,0,0,0,0,0,0,0,0,0,0
0,0,0,0,0,0,0,0,0,0,0,0,0,0,0,0,0,0,0,0,0,0,0,0,0,0,0,0,0,0,0,0,0,0
0,0,0,0,0,0,0,0,0,0,0,0,0,0,0,0,0,0,0,0,0,0,0,0,0,0,0,0,0,0,0,0,0,0
0,0,0,0,0,0,0,0,0,0,0,0,0,0,0,0,0,0,0,0,0,0,0,0,0,0,0,0,0,0,0,0,0,0
0,0,0,0,0,0,0,0,0,0,0,0,0,0,0,0,0,0,0,0,0,0,0,0,0,0,0,0,0,0,0,0,0,0
0,0,0,0,0,0,0,0,0,0,0,0,0,0,0,0,0,0,0,0,0,0,0,0,0,0,0,0,0,0,0,0,0,0
0,0,0,0,0,0,0,0,0,0,0,0,0,0,0,0,0,0,0,0,0,0,0,0,0,0,0,0,0,0,0,0,0,0
0,0,0,0,0,0,0,0,0,0,0,0,0,0,0,0,0,0,0,0,0,0,0,0,0,0,0,0,0,0,0,0,0,0
0,0,0,0,0,0,0,0,0,0,0,0,0,0,0,0,0,0,0,0,0,0,0,0,0,0,0,0,0,0,0,0,0,0
0,0,0,0,0,0,0,0,0,0,0,0,0,0,0,0,0,0,0,0,0,0,0,0,0,0,0,0,0,0,0,0,0,0
0,0,0,0,0,0,0,0,0,0,0,0,0,0,0,0,0,0,0,0,0,0,0,0,0,0,0,0,0,0,0,0,0,0
0,0,0,0,0,0,0,0,0,0,0,0,0,0,0,0,0,0,0,0,0,0,0,0,0,0,0,0,0,0,0,0,0,0
0,0,0,0,0,0,0,0,0,0,0,0,0,0,0,0,0,0,0,0,0,0,0,0,0,0,0,0,0,0,0,0,0,0
0,0,0,0,0,0,0,0,0,0,0,0,0,0,0,0,0,0,0,0,0,0,0,0,0,0,0,0,0,0,0,0,0,0
0,0,0,44,44,44,44,44,44,44,44,44,44,44,44,44,44,44,44,44,44,44,44,44,44,44,44,44,44,44,44,0,0,0
0,0,0,45,45,45,45,45,45,45,45,45,45,45,45,45,45,45,45,45,45,45,45,45,45,45,45,45,45,45,45,0,0,0
0,0,0,0,0,21,0,0,0,0,0,0,0,0,0,0,0,0,0,0,0,0,0,0,0,6,8,6,8,6,8,6,0,0
0,0,0,44,44,44,44,42,0,0,0,0,0,0,0,0,0,0,0,0,0,0,0,0,0,7,0,0,0,0,0,7,0,0
0,0,0,43,48,48,39,42,0,2,0,0,0,0,0,0,0,0,0,0,0,0,0,0,2,6,0,0,0,7,0,6,0,0
0,0,0,43,41,0,39,42,0,0,0,0,0,0,0,0,0,0,0,0,0,0,0,0,0,7,0,0,0,0,0,7,0,0
0,0,0,43,41,49,49,42,0,0,0,0,0,0,0,0,0,0,0,0,0,0,0,0,0,6,0,0,0,0,0,6,0,0
0,0,0,43,45,45,45,45,0,0,0,0,0,0,0,0,0,0,0,0,0,0,0,0,0,7,0,0,0,0,0,7,0,0
0,0,0,0,0,0,0,0,0,0,0,0,0,0,0,0,0,0,0,0,0,0,0,0,0,6,7,6,7,6,7,6,0,0
0,0,0,0,0,0,0,0,0,0,0,0,0,0,0,0,0,0,0,0,0,0,0,0,0,0,0,0,0,0,0,0,0,0
0,0,0,0,0,0,0,0,0,0,0,0,0,0,0,0,0,0,0,0,0,0,0,0,0,0,0,0,0,0,0,0,0,0
:endlayer
layer: 15
0,0,0,0,0,0,0,0,0,0,0,0,0,0,0,0,0,0,0,0,0,0,0,0,0,0,0,0,0,0,0,0,0,0
0,0,0,0,0,0,0,0,0,0,0,0,0,0,0,0,0,0,0,0,0,0,0,0,0,0,0,0,0,0,0,0,0,0
0,0,0,0,0,0,0,0,0,0,0,0,0,0,0,0,0,0,0,0,0,0,0,0,0,0,0,0,0,0,0,0,0,0
0,0,0,0,0,0,0,0,0,0,0,0,0,0,0,0,0,0,0,0,0,0,0,0,0,0,0,0,0,0,0,0,0,0
0,0,0,0,0,0,0,0,0,0,0,0,0,0,0,0,0,0,0,0,0,0,0,0,0,0,0,0,0,0,0,0,0,0
0,0,0,0,0,0,0,0,0,0,0,0,0,0,0,0,0,0,0,0,0,0,0,0,0,0,0,0,0,0,0,0,0,0
0,0,0,0,0,0,0,0,0,0,0,0,0,0,0,0,0,0,0,0,0,0,0,0,0,0,0,0,0,0,0,0,0,0
0,0,0,0,0,0,0,0,0,0,0,0,0,0,0,0,0,0,0,0,0,0,0,0,0,0,0,0,0,0,0,0,0,0
0,0,0,0,0,0,0,0,0,0,0,0,0,0,0,0,0,0,0,0,0,0,0,0,0,0,0,0,0,0,0,0,0,0
0,0,0,0,0,0,0,0,0,0,0,0,0,0,0,0,0,0,0,0,0,0,0,0,0,0,0,0,0,0,0,0,0,0
0,0,0,0,0,0,0,0,0,0,0,0,0,0,0,0,0,0,0,0,0,0,0,0,0,0,0,0,0,0,0,0,0,0
0,0,0,0,0,0,0,0,0,0,0,0,0,0,0,0,0,0,0,0,0,0,0,0,0,0,0,0,0,0,0,0,0,0
0,0,0,0,0,0,0,0,0,0,0,0,0,0,0,0,0,0,0,0,0,0,0,0,0,0,0,0,0,0,0,0,0,0
0,0,0,0,0,0,0,0,0,0,0,0,0,0,0,0,0,0,0,0,0,0,0,0,0,0,0,0,0,0,0,0,0,0
0,0,0,0,0,0,0,0,0,0,0,0,0,0,0,0,0,0,0,0,0,0,0,0,0,0,0,0,0,0,0,0,0,0
0,0,0,0,0,0,0,0,0,0,0,0,0,0,0,0,0,0,0,0,0,0,0,0,0,0,0,0,0,0,0,0,0,0
0,0,0,0,0,0,0,0,0,0,0,0,0,0,0,0,0,0,0,0,0,0,0,0,0,0,0,0,0,0,0,0,0,0
0,0,0,0,0,0,0,0,0,0,0,0,0,0,0,0,0,0,0,0,0,0,0,0,0,0,0,0,0,0,0,0,0,0
0,0,0,0,0,0,0,0,0,0,0,0,0,0,0,0,0,0,0,0,0,0,0,0,0,0,0,0,0,0,0,0,0,0
0,0,0,0,0,0,0,0,0,0,0,0,0,0,0,0,0,0,0,0,0,0,0,0,0,0,0,0,0,0,0,0,0,0
0,0,0,0,0,0,0,0,0,0,0,0,0,0,0,0,0,0,0,0,0,0,0,0,0,0,0,0,0,0,0,0,0,0
0,0,0,0,0,0,0,0,0,0,0,0,0,0,0,0,0,0,0,0,0,0,0,0,0,0,0,0,0,0,0,0,0,0
0,0,0,0,0,0,0,0,0,0,0,0,0,0,0,0,0,0,0,0,0,0,0,0,0,0,0,0,0,0,0,0,0,0
0,0,0,0,0,0,0,0,0,0,0,0,0,0,0,0,0,0,0,0,0,0,0,0,0,0,0,0,0,0,0,0,0,0
0,0,0,0,0,0,0,0,0,0,0,0,0,0,0,0,0,0,0,0,0,0,0,0,0,0,0,0,0,0,0,0,0,0
0,0,0,0,0,0,0,0,0,0,0,0,0,0,0,0,0,0,0,0,0,0,0,0,0,0,0,0,0,0,0,0,0,0
0,0,0,0,0,0,0,0,0,0,0,0,0,0,0,0,0,0,0,0,0,0,0,0,0,0,0,0,0,0,0,0,0,0
0,0,0,0,0,0,0,0,0,0,0,0,0,0,0,0,0,0,0,0,0,0,0,0,0,0,0,0,0,0,0,0,0,0
0,0,0,0,0,0,0,0,0,0,0,0,0,0,0,0,0,0,0,0,0,0,0,0,0,0,0,0,0,0,0,0,0,0
0,0,0,0,0,0,0,0,0,0,0,0,0,0,0,0,0,0,0,0,0,0,0,0,0,0,0,0,0,0,0,0,0,0
0,0,0,0,0,0,0,0,0,0,0,0,0,0,0,0,0,0,0,0,0,0,0,0,0,0,0,0,0,0,0,0,0,0
0,0,0,0,0,0,0,0,0,0,0,0,0,0,0,0,0,0,0,0,0,0,0,0,0,7,0,7,0,7,0,7,0,0
0,0,0,0,0,0,0,0,0,0,0,0,0,0,0,0,0,0,0,0,0,0,0,0,7,6,8,6,8,6,8,6,7,0
0,0,0,0,0,0,0,0,0,0,0,0,0,0,0,0,0,0,0,0,0,0,0,0,0,7,0,35,0,35,0,7,0,0
0,0,0,0,44,44,42,0,0,2,0,0,0,0,0,0,0,0,0,0,0,0,0,0,2,6,31,0,0,7,36,6,7,0
0,0,0,0,43,8,42,0,0,0,0,0,0,0,0,0,0,0,0,0,0,0,0,0,0,7,0,0,0,0,0,7,0,0
0,0,0,0,43,45,45,0,0,0,0,0,0,0,0,0,0,0,0,0,0,0,0,0,7,6,31,0,0,0,36,6,7,0
0,0,0,0,0,0,0,0,0,0,0,0,0,0,0,0,0,0,0,0,0,0,0,0,0,7,0,32,0,32,0,7,0,0
0,0,0,0,0,0,0,0,0,0,0,0,0,0,0,0,0,0,0,0,0,0,0,0,7,6,7,6,7,6,7,6,7,0
0,0,0,0,0,0,0,0,0,0,0,0,0,0,0,0,0,0,0,0,0,0,0,0,0,7,0,7,0,7,0,7,0,0
0,0,0,0,0,0,0,0,0,0,0,0,0,0,0,0,0,0,0,0,0,0,0,0,0,0,0,0,0,0,0,0,0,0
:endlayer
layer: 16
0,0,0,0,0,0,0,0,0,0,0,0,0,0,0,0,0,0,0,0,0,0,0,0,0,0,0,0,0,0,0,0,0,0
0,0,0,0,0,0,0,0,0,0,0,0,0,0,0,0,0,0,0,0,0,0,0,0,0,0,0,0,0,0,0,0,0,0
0,0,0,0,0,0,0,0,0,0,0,0,0,0,0,0,0,0,0,0,0,0,0,0,0,0,0,0,0,0,0,0,0,0
0,0,0,0,0,0,0,0,0,0,0,0,0,0,0,0,0,0,0,0,0,0,0,0,0,0,0,0,0,0,0,0,0,0
0,0,0,0,0,0,0,0,0,0,0,0,0,0,0,0,0,0,0,0,0,0,0,0,0,0,0,0,0,0,0,0,0,0
0,0,0,0,0,0,0,0,0,0,0,0,0,0,0,0,0,0,0,0,0,0,0,0,0,0,0,0,0,0,0,0,0,0
0,0,0,0,0,0,0,0,0,0,0,0,0,0,0,0,0,0,0,0,0,0,0,0,0,0,0,0,0,0,0,0,0,0
0,0,0,0,0,0,0,0,0,0,0,0,0,0,0,0,0,0,0,0,0,0,0,0,0,0,0,0,0,0,0,0,0,0
0,0,0,0,0,0,0,0,0,0,0,0,0,0,0,0,0,0,0,0,0,0,0,0,0,0,0,0,0,0,0,0,0,0
0,0,0,0,0,0,0,0,0,0,0,0,0,0,0,0,0,0,0,0,0,0,0,0,0,0,0,0,0,0,0,0,0,0
0,0,0,0,0,0,0,0,0,0,0,0,0,0,0,0,0,0,0,0,0,0,0,0,0,0,0,0,0,0,0,0,0,0
0,0,0,0,0,0,0,0,0,0,0,0,0,0,0,0,0,0,0,0,0,0,0,0,0,0,0,0,0,0,0,0,0,0
0,0,0,0,0,0,0,0,0,0,0,0,0,0,0,0,0,0,0,0,0,0,0,0,0,0,0,0,0,0,0,0,0,0
0,0,0,0,0,0,0,0,0,0,0,0,0,0,0,0,0,0,0,0,0,0,0,0,0,0,0,0,0,0,0,0,0,0
0,0,0,0,0,0,0,0,0,0,0,0,0,0,0,0,0,0,0,0,0,0,0,0,0,0,0,0,0,0,0,0,0,0
0,0,0,0,0,0,0,0,0,0,0,0,0,0,0,0,0,0,0,0,0,0,0,0,0,0,0,0,0,0,0,0,0,0
0,0,0,0,0,0,0,0,0,0,0,0,0,0,0,0,0,0,0,0,0,0,0,0,0,0,0,0,0,0,0,0,0,0
0,0,0,0,0,0,0,0,0,0,0,0,0,0,0,0,0,0,0,0,0,0,0,0,0,0,0,0,0,0,0,0,0,0
0,0,0,0,0,0,0,0,0,0,0,0,0,0,0,0,0,0,0,0,0,0,0,0,0,0,0,0,0,0,0,0,0,0
0,0,0,0,0,0,0,0,0,0,0,0,0,0,0,0,0,0,0,0,0,0,0,0,0,0,0,0,0,0,0,0,0,0
0,0,0,0,0,0,0,0,0,0,0,0,0,0,0,0,0,0,0,0,0,0,0,0,0,0,0,0,0,0,0,0,0,0
0,0,0,0,0,0,0,0,0,0,0,0,0,0,0,0,0,0,0,0,0,0,0,0,0,0,0,0,0,0,0,0,0,0
0,0,0,0,0,0,0,0,0,0,0,0,0,0,0,0,0,0,0,0,0,0,0,0,0,0,0,0,0,0,0,0,0,0
0,0,0,0,0,0,0,0,0,0,0,0,0,0,0,0,0,0,0,0,0,0,0,0,0,0,0,0,0,0,0,0,0,0
0,0,0,0,0,0,0,0,0,0,0,0,0,0,0,0,0,0,0,0,0,0,0,0,0,0,0,0,0,0,0,0,0,0
0,0,0,0,0,0,0,0,0,0,0,0,0,0,0,0,0,0,0,0,0,0,0,0,0,0,0,0,0,0,0,0,0,0
0,0,0,0,0,0,0,0,0,0,0,0,0,0,0,0,0,0,0,0,0,0,0,0,0,0,0,0,0,0,0,0,0,0
0,0,0,0,0,0,0,0,0,0,0,0,0,0,0,0,0,0,0,0,0,0,0,0,0,0,0,0,0,0,0,0,0,0
0,0,0,0,0,0,0,0,0,0,0,0,0,0,0,0,0,0,0,0,0,0,0,0,0,0,0,0,0,0,0,0,0,0
0,0,0,0,0,0,0,0,0,0,0,0,0,0,0,0,0,0,0,0,0,0,0,0,0,0,0,0,0,0,0,0,0,0
0,0,0,0,0,0,0,0,0,0,0,0,0,0,0,0,0,0,0,0,0,0,0,0,0,0,0,0,0,0,0,0,0,0
0,0,0,0,0,0,0,0,0,0,0,0,0,0,0,0,0,0,0,0,0,0,0,0,44,44,44,44,44,44,44,44,44,0
0,0,0,0,0,0,0,0,0,0,0,0,0,0,0,0,0,0,0,0,0,0,0,0,43,6,4,4,4,4,4,6,42,0
0,0,0,0,0,0,0,0,0,0,0,0,0,0,0,0,0,0,0,0,0,0,0,0,43,5,0,0,0,0,0,5,42,0
0,0,0,0,0,0,0,0,0,2,0,0,0,0,0,0,0,0,0,0,0,0,0,0,2,5,0,0,0,7,0,5,42,0
0,0,0,0,0,7,0,0,0,0,0,0,0,0,0,0,0,0,0,0,0,0,0,0,43,5,0,0,0,0,0,5,42,0
0,0,0,0,0,0,0,0,0,0,0,0,0,0,0,0,0,0,0,0,0,0,0,0,43,5,0,0,0,0,0,5,42,0
0,0,0,0,0,0,0,0,0,0,0,0,0,0,0,0,0,0,0,0,0,0,0,0,43,5,0,0,0,0,0,5,42,0
0,0,0,0,0,0,0,0,0,0,0,0,0,0,0,0,0,0,0,0,0,0,0,0,43,6,4,4,4,4,4,6,42,0
0,0,0,0,0,0,0,0,0,0,0,0,0,0,0,0,0,0,0,0,0,0,0,0,43,45,45,45,45,45,45,45,45,0
0,0,0,0,0,0,0,0,0,0,0,0,0,0,0,0,0,0,0,0,0,0,0,0,0,0,0,0,0,0,0,0,0,0
:endlayer
layer: 17
0,0,0,0,0,0,0,0,0,0,0,0,0,0,0,0,0,0,0,0,0,0,0,0,0,0,0,0,0,0,0,0,0,0
0,0,0,0,0,0,0,0,0,0,0,0,0,0,0,0,0,0,0,0,0,0,0,0,0,0,0,0,0,0,0,0,0,0
0,0,0,0,0,0,0,0,0,0,0,0,0,0,0,0,0,0,0,0,0,0,0,0,0,0,0,0,0,0,0,0,0,0
0,0,0,0,0,0,0,0,0,0,0,0,0,0,0,0,0,0,0,0,0,0,0,0,0,0,0,0,0,0,0,0,0,0
0,0,0,0,0,0,0,0,0,0,0,0,0,0,0,0,0,0,0,0,0,0,0,0,0,0,0,0,0,0,0,0,0,0
0,0,0,0,0,0,0,0,0,0,0,0,0,0,0,0,0,0,0,0,0,0,0,0,0,0,0,0,0,0,0,0,0,0
0,0,0,0,0,0,0,0,0,0,0,0,0,0,0,0,0,0,0,0,0,0,0,0,0,0,0,0,0,0,0,0,0,0
0,0,0,0,0,0,0,0,0,0,0,0,0,0,0,0,0,0,0,0,0,0,0,0,0,0,0,0,0,0,0,0,0,0
0,0,0,0,0,0,0,0,0,0,0,0,0,0,0,0,0,0,0,0,0,0,0,0,0,0,0,0,0,0,0,0,0,0
0,0,0,0,0,0,0,0,0,0,0,0,0,0,0,0,0,0,0,0,0,0,0,0,0,0,0,0,0,0,0,0,0,0
0,0,0,0,0,0,0,0,0,0,0,0,0,0,0,0,0,0,0,0,0,0,0,0,0,0,0,0,0,0,0,0,0,0
0,0,0,0,0,0,0,0,0,0,0,0,0,0,0,0,0,0,0,0,0,0,0,0,0,0,0,0,0,0,0,0,0,0
0,0,0,0,0,0,0,0,0,0,0,0,0,0,0,0,0,0,0,0,0,0,0,0,0,0,0,0,0,0,0,0,0,0
0,0,0,0,0,0,0,0,0,0,0,0,0,0,0,0,0,0,0,0,0,0,0,0,0,0,0,0,0,0,0,0,0,0
0,0,0,0,0,0,0,0,0,0,0,0,0,0,0,0,0,0,0,0,0,0,0,0,0,0,0,0,0,0,0,0,0,0
0,0,0,0,0,0,0,0,0,0,0,0,0,0,0,0,0,0,0,0,0,0,0,0,0,0,0,0,0,0,0,0,0,0
0,0,0,0,0,0,0,0,0,0,0,0,0,0,0,0,0,0,0,0,0,0,0,0,0,0,0,0,0,0,0,0,0,0
0,0,0,0,0,0,0,0,0,0,0,0,0,0,0,0,0,0,0,0,0,0,0,0,0,0,0,0,0,0,0,0,0,0
0,0,0,0,0,0,0,0,0,0,0,0,0,0,0,0,0,0,0,0,0,0,0,0,0,0,0,0,0,0,0,0,0,0
0,0,0,0,0,0,0,0,0,0,0,0,0,0,0,0,0,0,0,0,0,0,0,0,0,0,0,0,0,0,0,0,0,0
0,0,0,0,0,0,0,0,0,0,0,0,0,0,0,0,0,0,0,0,0,0,0,0,0,0,0,0,0,0,0,0,0,0
0,0,0,0,0,0,0,0,0,0,0,0,0,0,0,0,0,0,0,0,0,0,0,0,0,0,0,0,0,0,0,0,0,0
0,0,0,0,0,0,0,0,0,0,0,0,0,0,0,0,0,0,0,0,0,0,0,0,0,0,0,0,0,0,0,0,0,0
0,0,0,0,0,0,0,0,0,0,0,0,0,0,0,0,0,0,0,0,0,0,0,0,0,0,0,0,0,0,0,0,0,0
0,0,0,0,0,0,0,0,0,0,0,0,0,0,0,0,0,0,0,0,0,0,0,0,0,0,0,0,0,0,0,0,0,0
0,0,0,0,0,0,0,0,0,0,0,0,0,0,0,0,0,0,0,0,0,0,0,0,0,0,0,0,0,0,0,0,0,0
0,0,0,0,0,0,0,0,0,0,0,0,0,0,0,0,0,0,0,0,0,0,0,0,0,0,0,0,0,0,0,0,0,0
0,0,0,0,0,0,0,0,0,0,0,0,0,0,0,0,0,0,0,0,0,0,0,0,0,0,0,0,0,0,0,0,0,0
0,0,0,0,0,0,0,0,0,0,0,0,0,0,0,0,0,0,0,0,0,0,0,0,0,0,0,0,0,0,0,0,0,0
0,0,0,0,0,0,0,0,0,0,0,0,0,0,0,0,0,0,0,0,0,0,0,0,0,0,0,0,0,0,0,0,0,0
0,0,0,0,0,0,0,0,0,0,0,0,0,0,0,0,0,0,0,0,0,0,0,0,0,0,0,0,0,0,0,0,0,0
0,0,0,0,0,0,0,0,0,0,0,0,0,0,0,0,0,0,0,0,0,0,0,0,0,0,0,0,0,0,0,0,0,0
0,0,0,0,0,0,0,0,0,0,0,0,0,0,0,0,0,0,0,0,0,0,0,0,0,44,44,44,44,44,44,44,0,0
0,0,0,0,0,0,0,0,0,0,0,0,0,0,0,0,0,0,0,0,0,0,0,0,0,43,41,48,48,48,48,42,0,0
0,0,0,0,0,0,0,0,0,50,0,0,0,0,0,0,0,0,0,0,0,0,0,0,2,43,41,0,0,7,39,42,0,0
0,0,0,0,0,7,0,0,0,0,0,0,0,0,0,0,0,0,0,0,0,0,0,0,0,43,41,0,0,0,39,42,0,0
0,0,0,0,0,0,0,0,0,0,0,0,0,0,0,0,0,0,0,0,0,0,0,0,0,43,41,0,0,0,39,42,0,0
0,0,0,0,0,0,0,0,0,0,0,0,0,0,0,0,0,0,0,0,0,0,0,0,0,43,49,49,49,49,39,42,0,0
0,0,0,0,0,0,0,0,0,0,0,0,0,0,0,0,0,0,0,0,0,0,0,0,0,45,45,45,45,45,45,42,0,0
0,0,0,0,0,0,0,0,0,0,0,0,0,0,0,0,0,0,0,0,0,0,0,0,0,0,0,0,0,0,0,0,0,0
0,0,0,0,0,0,0,0,0,0,0,0,0,0,0,0,0,0,0,0,0,0,0,0,0,0,0,0,0,0,0,0,0,0
:endlayer
layer: 18
0,0,0,0,0,0,0,0,0,0,0,0,0,0,0,0,0,0,0,0,0,0,0,0,0,0,0,0,0,0,0,0,0,0
0,0,0,0,0,0,0,0,0,0,0,0,0,0,0,0,0,0,0,0,0,0,0,0,0,0,0,0,0,0,0,0,0,0
0,0,0,0,0,0,0,0,0,0,0,0,0,0,0,0,0,0,0,0,0,0,0,0,0,0,0,0,0,0,0,0,0,0
0,0,0,0,0,0,0,0,0,0,0,0,0,0,0,0,0,0,0,0,0,0,0,0,0,0,0,0,0,0,0,0,0,0
0,0,0,0,0,0,0,0,0,0,0,0,0,0,0,0,0,0,0,0,0,0,0,0,0,0,0,0,0,0,0,0,0,0
0,0,0,0,0,0,0,0,0,0,0,0,0,0,0,0,0,0,0,0,0,0,0,0,0,0,0,0,0,0,0,0,0,0
0,0,0,0,0,0,0,0,0,0,0,0,0,0,0,0,0,0,0,0,0,0,0,0,0,0,0,0,0,0,0,0,0,0
0,0,0,0,0,0,0,0,0,0,0,0,0,0,0,0,0,0,0,0,0,0,0,0,0,0,0,0,0,0,0,0,0,0
0,0,0,0,0,0,0,0,0,0,0,0,0,0,0,0,0,0,0,0,0,0,0,0,0,0,0,0,0,0,0,0,0,0
0,0,0,0,0,0,0,0,0,0,0,0,0,0,0,0,0,0,0,0,0,0,0,0,0,0,0,0,0,0,0,0,0,0
0,0,0,0,0,0,0,0,0,0,0,0,0,0,0,0,0,0,0,0,0,0,0,0,0,0,0,0,0,0,0,0,0,0
0,0,0,0,0,0,0,0,0,0,0,0,0,0,0,0,0,0,0,0,0,0,0,0,0,0,0,0,0,0,0,0,0,0
0,0,0,0,0,0,0,0,0,0,0,0,0,0,0,0,0,0,0,0,0,0,0,0,0,0,0,0,0,0,0,0,0,0
0,0,0,0,0,0,0,0,0,0,0,0,0,0,0,0,0,0,0,0,0,0,0,0,0,0,0,0,0,0,0,0,0,0
0,0,0,0,0,0,0,0,0,0,0,0,0,0,0,0,0,0,0,0,0,0,0,0,0,0,0,0,0,0,0,0,0,0
0,0,0,0,0,0,0,0,0,0,0,0,0,0,0,0,0,0,0,0,0,0,0,0,0,0,0,0,0,0,0,0,0,0
0,0,0,0,0,0,0,0,0,0,0,0,0,0,0,0,0,0,0,0,0,0,0,0,0,0,0,0,0,0,0,0,0,0
0,0,0,0,0,0,0,0,0,0,0,0,0,0,0,0,0,0,0,0,0,0,0,0,0,0,0,0,0,0,0,0,0,0
0,0,0,0,0,0,0,0,0,0,0,0,0,0,0,0,0,0,0,0,0,0,0,0,0,0,0,0,0,0,0,0,0,0
0,0,0,0,0,0,0,0,0,0,0,0,0,0,0,0,0,0,0,0,0,0,0,0,0,0,0,0,0,0,0,0,0,0
0,0,0,0,0,0,0,0,0,0,0,0,0,0,0,0,0,0,0,0,0,0,0,0,0,0,0,0,0,0,0,0,0,0
0,0,0,0,0,0,0,0,0,0,0,0,0,0,0,0,0,0,0,0,0,0,0,0,0,0,0,0,0,0,0,0,0,0
0,0,0,0,0,0,0,0,0,0,0,0,0,0,0,0,0,0,0,0,0,0,0,0,0,0,0,0,0,0,0,0,0,0
0,0,0,0,0,0,0,0,0,0,0,0,0,0,0,0,0,0,0,0,0,0,0,0,0,0,0,0,0,0,0,0,0,0
0,0,0,0,0,0,0,0,0,0,0,0,0,0,0,0,0,0,0,0,0,0,0,0,0,0,0,0,0,0,0,0,0,0
0,0,0,0,0,0,0,0,0,0,0,0,0,0,0,0,0,0,0,0,0,0,0,0,0,0,0,0,0,0,0,0,0,0
0,0,0,0,0,0,0,0,0,0,0,0,0,0,0,0,0,0,0,0,0,0,0,0,0,0,0,0,0,0,0,0,0,0
0,0,0,0,0,0,0,0,0,0,0,0,0,0,0,0,0,0,0,0,0,0,0,0,0,0,0,0,0,0,0,0,0,0
0,0,0,0,0,0,0,0,0,0,0,0,0,0,0,0,0,0,0,0,0,0,0,0,0,0,0,0,0,0,0,0,0,0
0,0,0,0,0,0,0,0,0,0,0,0,0,0,0,0,0,0,0,0,0,0,0,0,0,0,0,0,0,0,0,0,0,0
0,0,0,0,0,0,0,0,0,0,0,0,0,0,0,0,0,0,0,0,0,0,0,0,0,0,0,0,0,0,0,0,0,0
0,0,0,0,0,0,0,0,0,0,0,0,0,0,0,0,0,0,0,0,0,0,0,0,0,0,0,0,0,0,0,0,0,0
0,0,0,0,0,0,0,0,0,0,0,0,0,0,0,0,0,0,0,0,0,0,0,0,0,0,0,0,0,0,0,0,0,0
0,0,0,0,0,0,0,0,0,0,0,0,0,0,0,0,0,0,0,0,0,0,0,0,0,0,44,44,44,44,42,0,0,0
0,0,0,0,0,0,0,0,0,12,0,0,0,0,0,0,0,0,0,0,0,0,0,0,2,0,43,48,48,39,42,0,0,0
0,0,0,0,0,7,0,0,0,0,0,0,0,0,0,0,0,0,0,0,0,0,0,0,0,0,43,41,0,39,42,0,0,0
0,0,0,0,0,0,0,0,0,0,0,0,0,0,0,0,0,0,0,0,0,0,0,0,0,0,43,41,49,49,42,0,0,0
0,0,0,0,0,0,0,0,0,0,0,0,0,0,0,0,0,0,0,0,0,0,0,0,0,0,43,45,45,45,45,0,0,0
0,0,0,0,0,0,0,0,0,0,0,0,0,0,0,0,0,0,0,0,0,0,0,0,0,0,0,0,0,0,0,0,0,0
0,0,0,0,0,0,0,0,0,0,0,0,0,0,0,0,0,0,0,0,0,0,0,0,0,0,0,0,0,0,0,0,0,0
0,0,0,0,0,0,0,0,0,0,0,0,0,0,0,0,0,0,0,0,0,0,0,0,0,0,0,0,0,0,0,0,0,0
:endlayer
layer: 19
0,0,0,0,0,0,0,0,0,0,0,0,0,0,0,0,0,0,0,0,0,0,0,0,0,0,0,0,0,0,0,0,0,0
0,0,0,0,0,0,0,0,0,0,0,0,0,0,0,0,0,0,0,0,0,0,0,0,0,0,0,0,0,0,0,0,0,0
0,0,0,0,0,0,0,0,0,0,0,0,0,0,0,0,0,0,0,0,0,0,0,0,0,0,0,0,0,0,0,0,0,0
0,0,0,0,0,0,0,0,0,0,0,0,0,0,0,0,0,0,0,0,0,0,0,0,0,0,0,0,0,0,0,0,0,0
0,0,0,0,0,0,0,0,0,0,0,0,0,0,0,0,0,0,0,0,0,0,0,0,0,0,0,0,0,0,0,0,0,0
0,0,0,0,0,0,0,0,0,0,0,0,0,0,0,0,0,0,0,0,0,0,0,0,0,0,0,0,0,0,0,0,0,0
0,0,0,0,0,0,0,0,0,0,0,0,0,0,0,0,0,0,0,0,0,0,0,0,0,0,0,0,0,0,0,0,0,0
0,0,0,0,0,0,0,0,0,0,0,0,0,0,0,0,0,0,0,0,0,0,0,0,0,0,0,0,0,0,0,0,0,0
0,0,0,0,0,0,0,0,0,0,0,0,0,0,0,0,0,0,0,0,0,0,0,0,0,0,0,0,0,0,0,0,0,0
0,0,0,0,0,0,0,0,0,0,0,0,0,0,0,0,0,0,0,0,0,0,0,0,0,0,0,0,0,0,0,0,0,0
0,0,0,0,0,0,0,0,0,0,0,0,0,0,0,0,0,0,0,0,0,0,0,0,0,0,0,0,0,0,0,0,0,0
0,0,0,0,0,0,0,0,0,0,0,0,0,0,0,0,0,0,0,0,0,0,0,0,0,0,0,0,0,0,0,0,0,0
0,0,0,0,0,0,0,0,0,0,0,0,0,0,0,0,0,0,0,0,0,0,0,0,0,0,0,0,0,0,0,0,0,0
0,0,0,0,0,0,0,0,0,0,0,0,0,0,0,0,0,0,0,0,0,0,0,0,0,0,0,0,0,0,0,0,0,0
0,0,0,0,0,0,0,0,0,0,0,0,0,0,0,0,0,0,0,0,0,0,0,0,0,0,0,0,0,0,0,0,0,0
0,0,0,0,0,0,0,0,0,0,0,0,0,0,0,0,0,0,0,0,0,0,0,0,0,0,0,0,0,0,0,0,0,0
0,0,0,0,0,0,0,0,0,0,0,0,0,0,0,0,0,0,0,0,0,0,0,0,0,0,0,0,0,0,0,0,0,0
0,0,0,0,0,0,0,0,0,0,0,0,0,0,0,0,0,0,0,0,0,0,0,0,0,0,0,0,0,0,0,0,0,0
0,0,0,0,0,0,0,0,0,0,0,0,0,0,0,0,0,0,0,0,0,0,0,0,0,0,0,0,0,0,0,0,0,0
0,0,0,0,0,0,0,0,0,0,0,0,0,0,0,0,0,0,0,0,0,0,0,0,0,0,0,0,0,0,0,0,0,0
0,0,0,0,0,0,0,0,0,0,0,0,0,0,0,0,0,0,0,0,0,0,0,0,0,0,0,0,0,0,0,0,0,0
0,0,0,0,0,0,0,0,0,0,0,0,0,0,0,0,0,0,0,0,0,0,0,0,0,0,0,0,0,0,0,0,0,0
0,0,0,0,0,0,0,0,0,0,0,0,0,0,0,0,0,0,0,0,0,0,0,0,0,0,0,0,0,0,0,0,0,0
0,0,0,0,0,0,0,0,0,0,0,0,0,0,0,0,0,0,0,0,0,0,0,0,0,0,0,0,0,0,0,0,0,0
0,0,0,0,0,0,0,0,0,0,0,0,0,0,0,0,0,0,0,0,0,0,0,0,0,0,0,0,0,0,0,0,0,0
0,0,0,0,0,0,0,0,0,0,0,0,0,0,0,0,0,0,0,0,0,0,0,0,0,0,0,0,0,0,0,0,0,0
0,0,0,0,0,0,0,0,0,0,0,0,0,0,0,0,0,0,0,0,0,0,0,0,0,0,0,0,0,0,0,0,0,0
0,0,0,0,0,0,0,0,0,0,0,0,0,0,0,0,0,0,0,0,0,0,0,0,0,0,0,0,0,0,0,0,0,0
0,0,0,0,0,0,0,0,0,0,0,0,0,0,0,0,0,0,0,0,0,0,0,0,0,0,0,0,0,0,0,0,0,0
0,0,0,0,0,0,0,0,0,0,0,0,0,0,0,0,0,0,0,0,0,0,0,0,0,0,0,0,0,0,0,0,0,0
0,0,0,0,0,0,0,0,0,0,0,0,0,0,0,0,0,0,0,0,0,0,0,0,0,0,0,0,0,0,0,0,0,0
0,0,0,0,0,0,0,0,0,0,0,0,0,0,0,0,0,0,0,0,0,0,0,0,0,0,0,0,0,0,0,0,0,0
0,0,0,0,0,0,0,0,0,0,0,0,0,0,0,0,0,0,0,0,0,0,0,0,0,0,0,0,0,0,0,0,0,0
0,0,0,0,0,0,0,0,0,0,0,0,0,0,0,0,0,0,0,0,0,0,0,0,0,0,0,0,0,0,0,0,0,0
0,0,0,0,0,0,0,0,0,0,0,0,0,0,0,0,0,0,0,0,0,0,0,0,2,0,0,44,44,42,0,0,0,0
0,0,0,0,0,21,0,0,0,0,0,0,0,0,0,0,0,0,0,0,0,0,0,0,0,0,0,43,8,42,0,0,0,0
0,0,0,0,0,0,0,0,0,0,0,0,0,0,0,0,0,0,0,0,0,0,0,0,0,0,0,43,45,45,0,0,0,0
0,0,0,0,0,0,0,0,0,0,0,0,0,0,0,0,0,0,0,0,0,0,0,0,0,0,0,0,0,0,0,0,0,0
0,0,0,0,0,0,0,0,0,0,0,0,0,0,0,0,0,0,0,0,0,0,0,0,0,0,0,0,0,0,0,0,0,0
0,0,0,0,0,0,0,0,0,0,0,0,0,0,0,0,0,0,0,0,0,0,0,0,0,0,0,0,0,0,0,0,0,0
0,0,0,0,0,0,0,0,0,0,0,0,0,0,0,0,0,0,0,0,0,0,0,0,0,0,0,0,0,0,0,0,0,0
:endlayer
layer: 20
0,0,0,0,0,0,0,0,0,0,0,0,0,0,0,0,0,0,0,0,0,0,0,0,0,0,0,0,0,0,0,0,0,0
0,0,0,0,0,0,0,0,0,0,0,0,0,0,0,0,0,0,0,0,0,0,0,0,0,0,0,0,0,0,0,0,0,0
0,0,0,0,0,0,0,0,0,0,0,0,0,0,0,0,0,0,0,0,0,0,0,0,0,0,0,0,0,0,0,0,0,0
0,0,0,0,0,0,0,0,0,0,0,0,0,0,0,0,0,0,0,0,0,0,0,0,0,0,0,0,0,0,0,0,0,0
0,0,0,0,0,0,0,0,0,0,0,0,0,0,0,0,0,0,0,0,0,0,0,0,0,0,0,0,0,0,0,0,0,0
0,0,0,0,0,0,0,0,0,0,0,0,0,0,0,0,0,0,0,0,0,0,0,0,0,0,0,0,0,0,0,0,0,0
0,0,0,0,0,0,0,0,0,0,0,0,0,0,0,0,0,0,0,0,0,0,0,0,0,0,0,0,0,0,0,0,0,0
0,0,0,0,0,0,0,0,0,0,0,0,0,0,0,0,0,0,0,0,0,0,0,0,0,0,0,0,0,0,0,0,0,0
0,0,0,0,0,0,0,0,0,0,0,0,0,0,0,0,0,0,0,0,0,0,0,0,0,0,0,0,0,0,0,0,0,0
0,0,0,0,0,0,0,0,0,0,0,0,0,0,0,0,0,0,0,0,0,0,0,0,0,0,0,0,0,0,0,0,0,0
0,0,0,0,0,0,0,0,0,0,0,0,0,0,0,0,0,0,0,0,0,0,0,0,0,0,0,0,0,0,0,0,0,0
0,0,0,0,0,0,0,0,0,0,0,0,0,0,0,0,0,0,0,0,0,0,0,0,0,0,0,0,0,0,0,0,0,0
0,0,0,0,0,0,0,0,0,0,0,0,0,0,0,0,0,0,0,0,0,0,0,0,0,0,0,0,0,0,0,0,0,0
0,0,0,0,0,0,0,0,0,0,0,0,0,0,0,0,0,0,0,0,0,0,0,0,0,0,0,0,0,0,0,0,0,0
0,0,0,0,0,0,0,0,0,0,0,0,0,0,0,0,0,0,0,0,0,0,0,0,0,0,0,0,0,0,0,0,0,0
0,0,0,0,0,0,0,0,0,0,0,0,0,0,0,0,0,0,0,0,0,0,0,0,0,0,0,0,0,0,0,0,0,0
0,0,0,0,0,0,0,0,0,0,0,0,0,0,0,0,0,0,0,0,0,0,0,0,0,0,0,0,0,0,0,0,0,0
0,0,0,0,0,0,0,0,0,0,0,0,0,0,0,0,0,0,0,0,0,0,0,0,0,0,0,0,0,0,0,0,0,0
0,0,0,0,0,0,0,0,0,0,0,0,0,0,0,0,0,0,0,0,0,0,0,0,0,0,0,0,0,0,0,0,0,0
0,0,0,0,0,0,0,0,0,0,0,0,0,0,0,0,0,0,0,0,0,0,0,0,0,0,0,0,0,0,0,0,0,0
0,0,0,0,0,0,0,0,0,0,0,0,0,0,0,0,0,0,0,0,0,0,0,0,0,0,0,0,0,0,0,0,0,0
0,0,0,0,0,0,0,0,0,0,0,0,0,0,0,0,0,0,0,0,0,0,0,0,0,0,0,0,0,0,0,0,0,0
0,0,0,0,0,0,0,0,0,0,0,0,0,0,0,0,0,0,0,0,0,0,0,0,0,0,0,0,0,0,0,0,0,0
0,0,0,0,0,0,0,0,0,0,0,0,0,0,0,0,0,0,0,0,0,0,0,0,0,0,0,0,0,0,0,0,0,0
0,0,0,0,0,0,0,0,0,0,0,0,0,0,0,0,0,0,0,0,0,0,0,0,0,0,0,0,0,0,0,0,0,0
0,0,0,0,0,0,0,0,0,0,0,0,0,0,0,0,0,0,0,0,0,0,0,0,0,0,0,0,0,0,0,0,0,0
0,0,0,0,0,0,0,0,0,0,0,0,0,0,0,0,0,0,0,0,0,0,0,0,0,0,0,0,0,0,0,0,0,0
0,0,0,0,0,0,0,0,0,0,0,0,0,0,0,0,0,0,0,0,0,0,0,0,0,0,0,0,0,0,0,0,0,0
0,0,0,0,0,0,0,0,0,0,0,0,0,0,0,0,0,0,0,0,0,0,0,0,0,0,0,0,0,0,0,0,0,0
0,0,0,0,0,0,0,0,0,0,0,0,0,0,0,0,0,0,0,0,0,0,0,0,0,0,0,0,0,0,0,0,0,0
0,0,0,0,0,0,0,0,0,0,0,0,0,0,0,0,0,0,0,0,0,0,0,0,0,0,0,0,0,0,0,0,0,0
0,0,0,0,0,0,0,0,0,0,0,0,0,0,0,0,0,0,0,0,0,0,0,0,0,0,0,0,0,0,0,0,0,0
0,0,0,0,0,0,0,0,0,0,0,0,0,0,0,0,0,0,0,0,0,0,0,0,0,0,0,0,0,0,0,0,0,0
0,0,0,0,0,0,0,0,0,0,0,0,0,0,0,0,0,0,0,0,0,0,0,0,0,0,0,0,0,0,0,0,0,0
0,0,0,0,0,0,0,0,0,0,0,0,0,0,0,0,0,0,0,0,0,0,0,0,2,0,0,0,0,0,0,0,0,0
0,0,0,0,0,0,0,0,0,0,0,0,0,0,0,0,0,0,0,0,0,0,0,0,0,0,0,0,7,0,0,0,0,0
0,0,0,0,0,0,0,0,0,0,0,0,0,0,0,0,0,0,0,0,0,0,0,0,0,0,0,0,0,0,0,0,0,0
0,0,0,0,0,0,0,0,0,0,0,0,0,0,0,0,0,0,0,0,0,0,0,0,0,0,0,0,0,0,0,0,0,0
0,0,0,0,0,0,0,0,0,0,0,0,0,0,0,0,0,0,0,0,0,0,0,0,0,0,0,0,0,0,0,0,0,0
0,0,0,0,0,0,0,0,0,0,0,0,0,0,0,0,0,0,0,0,0,0,0,0,0,0,0,0,0,0,0,0,0,0
0,0,0,0,0,0,0,0,0,0,0,0,0,0,0,0,0,0,0,0,0,0,0,0,0,0,0,0,0,0,0,0,0,0
:endlayer
layer: 21
0,0,0,0,0,0,0,0,0,0,0,0,0,0,0,0,0,0,0,0,0,0,0,0,0,0,0,0,0,0,0,0,0,0
0,0,0,0,0,0,0,0,0,0,0,0,0,0,0,0,0,0,0,0,0,0,0,0,0,0,0,0,0,0,0,0,0,0
0,0,0,0,0,0,0,0,0,0,0,0,0,0,0,0,0,0,0,0,0,0,0,0,0,0,0,0,0,0,0,0,0,0
0,0,0,0,0,0,0,0,0,0,0,0,0,0,0,0,0,0,0,0,0,0,0,0,0,0,0,0,0,0,0,0,0,0
0,0,0,0,0,0,0,0,0,0,0,0,0,0,0,0,0,0,0,0,0,0,0,0,0,0,0,0,0,0,0,0,0,0
0,0,0,0,0,0,0,0,0,0,0,0,0,0,0,0,0,0,0,0,0,0,0,0,0,0,0,0,0,0,0,0,0,0
0,0,0,0,0,0,0,0,0,0,0,0,0,0,0,0,0,0,0,0,0,0,0,0,0,0,0,0,0,0,0,0,0,0
0,0,0,0,0,0,0,0,0,0,0,0,0,0,0,0,0,0,0,0,0,0,0,0,0,0,0,0,0,0,0,0,0,0
0,0,0,0,0,0,0,0,0,0,0,0,0,0,0,0,0,0,0,0,0,0,0,0,0,0,0,0,0,0,0,0,0,0
0,0,0,0,0,0,0,0,0,0,0,0,0,0,0,0,0,0,0,0,0,0,0,0,0,0,0,0,0,0,0,0,0,0
0,0,0,0,0,0,0,0,0,0,0,0,0,0,0,0,0,0,0,0,0,0,0,0,0,0,0,0,0,0,0,0,0,0
0,0,0,0,0,0,0,0,0,0,0,0,0,0,0,0,0,0,0,0,0,0,0,0,0,0,0,0,0,0,0,0,0,0
0,0,0,0,0,0,0,0,0,0,0,0,0,0,0,0,0,0,0,0,0,0,0,0,0,0,0,0,0,0,0,0,0,0
0,0,0,0,0,0,0,0,0,0,0,0,0,0,0,0,0,0,0,0,0,0,0,0,0,0,0,0,0,0,0,0,0,0
0,0,0,0,0,0,0,0,0,0,0,0,0,0,0,0,0,0,0,0,0,0,0,0,0,0,0,0,0,0,0,0,0,0
0,0,0,0,0,0,0,0,0,0,0,0,0,0,0,0,0,0,0,0,0,0,0,0,0,0,0,0,0,0,0,0,0,0
0,0,0,0,0,0,0,0,0,0,0,0,0,0,0,0,0,0,0,0,0,0,0,0,0,0,0,0,0,0,0,0,0,0
0,0,0,0,0,0,0,0,0,0,0,0,0,0,0,0,0,0,0,0,0,0,0,0,0,0,0,0,0,0,0,0,0,0
0,0,0,0,0,0,0,0,0,0,0,0,0,0,0,0,0,0,0,0,0,0,0,0,0,0,0,0,0,0,0,0,0,0
0,0,0,0,0,0,0,0,0,0,0,0,0,0,0,0,0,0,0,0,0,0,0,0,0,0,0,0,0,0,0,0,0,0
0,0,0,0,0,0,0,0,0,0,0,0,0,0,0,0,0,0,0,0,0,0,0,0,0,0,0,0,0,0,0,0,0,0
0,0,0,0,0,0,0,0,0,0,0,0,0,0,0,0,0,0,0,0,0,0,0,0,0,0,0,0,0,0,0,0,0,0
0,0,0,0,0,0,0,0,0,0,0,0,0,0,0,0,0,0,0,0,0,0,0,0,0,0,0,0,0,0,0,0,0,0
0,0,0,0,0,0,0,0,0,0,0,0,0,0,0,0,0,0,0,0,0,0,0,0,0,0,0,0,0,0,0,0,0,0
0,0,0,0,0,0,0,0,0,0,0,0,0,0,0,0,0,0,0,0,0,0,0,0,0,0,0,0,0,0,0,0,0,0
0,0,0,0,0,0,0,0,0,0,0,0,0,0,0,0,0,0,0,0,0,0,0,0,0,0,0,0,0,0,0,0,0,0
0,0,0,0,0,0,0,0,0,0,0,0,0,0,0,0,0,0,0,0,0,0,0,0,0,0,0,0,0,0,0,0,0,0
0,0,0,0,0,0,0,0,0,0,0,0,0,0,0,0,0,0,0,0,0,0,0,0,0,0,0,0,0,0,0,0,0,0
0,0,0,0,0,0,0,0,0,0,0,0,0,0,0,0,0,0,0,0,0,0,0,0,0,0,0,0,0,0,0,0,0,0
0,0,0,0,0,0,0,0,0,0,0,0,0,0,0,0,0,0,0,0,0,0,0,0,0,0,0,0,0,0,0,0,0,0
0,0,0,0,0,0,0,0,0,0,0,0,0,0,0,0,0,0,0,0,0,0,0,0,0,0,0,0,0,0,0,0,0,0
0,0,0,0,0,0,0,0,0,0,0,0,0,0,0,0,0,0,0,0,0,0,0,0,0,0,0,0,0,0,0,0,0,0
0,0,0,0,0,0,0,0,0,0,0,0,0,0,0,0,0,0,0,0,0,0,0,0,0,0,0,0,0,0,0,0,0,0
0,0,0,0,0,0,0,0,0,0,0,0,0,0,0,0,0,0,0,0,0,0,0,0,0,0,0,0,0,0,0,0,0,0
0,0,0,0,0,0,0,0,0,0,0,0,0,0,0,0,0,0,0,0,0,0,0,0,50,0,0,0,0,0,0,0,0,0
0,0,0,0,0,0,0,0,0,0,0,0,0,0,0,0,0,0,0,0,0,0,0,0,0,0,0,0,7,0,0,0,0,0
0,0,0,0,0,0,0,0,0,0,0,0,0,0,0,0,0,0,0,0,0,0,0,0,0,0,0,0,0,0,0,0,0,0
0,0,0,0,0,0,0,0,0,0,0,0,0,0,0,0,0,0,0,0,0,0,0,0,0,0,0,0,0,0,0,0,0,0
0,0,0,0,0,0,0,0,0,0,0,0,0,0,0,0,0,0,0,0,0,0,0,0,0,0,0,0,0,0,0,0,0,0
0,0,0,0,0,0,0,0,0,0,0,0,0,0,0,0,0,0,0,0,0,0,0,0,0,0,0,0,0,0,0,0,0,0
0,0,0,0,0,0,0,0,0,0,0,0,0,0,0,0,0,0,0,0,0,0,0,0,0,0,0,0,0,0,0,0,0,0
:endlayer
layer: 22
0,0,0,0,0,0,0,0,0,0,0,0,0,0,0,0,0,0,0,0,0,0,0,0,0,0,0,0,0,0,0,0,0,0
0,0,0,0,0,0,0,0,0,0,0,0,0,0,0,0,0,0,0,0,0,0,0,0,0,0,0,0,0,0,0,0,0,0
0,0,0,0,0,0,0,0,0,0,0,0,0,0,0,0,0,0,0,0,0,0,0,0,0,0,0,0,0,0,0,0,0,0
0,0,0,0,0,0,0,0,0,0,0,0,0,0,0,0,0,0,0,0,0,0,0,0,0,0,0,0,0,0,0,0,0,0
0,0,0,0,0,0,0,0,0,0,0,0,0,0,0,0,0,0,0,0,0,0,0,0,0,0,0,0,0,0,0,0,0,0
0,0,0,0,0,0,0,0,0,0,0,0,0,0,0,0,0,0,0,0,0,0,0,0,0,0,0,0,0,0,0,0,0,0
0,0,0,0,0,0,0,0,0,0,0,0,0,0,0,0,0,0,0,0,0,0,0,0,0,0,0,0,0,0,0,0,0,0
0,0,0,0,0,0,0,0,0,0,0,0,0,0,0,0,0,0,0,0,0,0,0,0,0,0,0,0,0,0,0,0,0,0
0,0,0,0,0,0,0,0,0,0,0,0,0,0,0,0,0,0,0,0,0,0,0,0,0,0,0,0,0,0,0,0,0,0
0,0,0,0,0,0,0,0,0,0,0,0,0,0,0,0,0,0,0,0,0,0,0,0,0,0,0,0,0,0,0,0,0,0
0,0,0,0,0,0,0,0,0,0,0,0,0,0,0,0,0,0,0,0,0,0,0,0,0,0,0,0,0,0,0,0,0,0
0,0,0,0,0,0,0,0,0,0,0,0,0,0,0,0,0,0,0,0,0,0,0,0,0,0,0,0,0,0,0,0,0,0
0,0,0,0,0,0,0,0,0,0,0,0,0,0,0,0,0,0,0,0,0,0,0,0,0,0,0,0,0,0,0,0,0,0
0,0,0,0,0,0,0,0,0,0,0,0,0,0,0,0,0,0,0,0,0,0,0,0,0,0,0,0,0,0,0,0,0,0
0,0,0,0,0,0,0,0,0,0,0,0,0,0,0,0,0,0,0,0,0,0,0,0,0,0,0,0,0,0,0,0,0,0
0,0,0,0,0,0,0,0,0,0,0,0,0,0,0,0,0,0,0,0,0,0,0,0,0,0,0,0,0,0,0,0,0,0
0,0,0,0,0,0,0,0,0,0,0,0,0,0,0,0,0,0,0,0,0,0,0,0,0,0,0,0,0,0,0,0,0,0
0,0,0,0,0,0,0,0,0,0,0,0,0,0,0,0,0,0,0,0,0,0,0,0,0,0,0,0,0,0,0,0,0,0
0,0,0,0,0,0,0,0,0,0,0,0,0,0,0,0,0,0,0,0,0,0,0,0,0,0,0,0,0,0,0,0,0,0
0,0,0,0,0,0,0,0,0,0,0,0,0,0,0,0,0,0,0,0,0,0,0,0,0,0,0,0,0,0,0,0,0,0
0,0,0,0,0,0,0,0,0,0,0,0,0,0,0,0,0,0,0,0,0,0,0,0,0,0,0,0,0,0,0,0,0,0
0,0,0,0,0,0,0,0,0,0,0,0,0,0,0,0,0,0,0,0,0,0,0,0,0,0,0,0,0,0,0,0,0,0
0,0,0,0,0,0,0,0,0,0,0,0,0,0,0,0,0,0,0,0,0,0,0,0,0,0,0,0,0,0,0,0,0,0
0,0,0,0,0,0,0,0,0,0,0,0,0,0,0,0,0,0,0,0,0,0,0,0,0,0,0,0,0,0,0,0,0,0
0,0,0,0,0,0,0,0,0,0,0,0,0,0,0,0,0,0,0,0,0,0,0,0,0,0,0,0,0,0,0,0,0,0
0,0,0,0,0,0,0,0,0,0,0,0,0,0,0,0,0,0,0,0,0,0,0,0,0,0,0,0,0,0,0,0,0,0
0,0,0,0,0,0,0,0,0,0,0,0,0,0,0,0,0,0,0,0,0,0,0,0,0,0,0,0,0,0,0,0,0,0
0,0,0,0,0,0,0,0,0,0,0,0,0,0,0,0,0,0,0,0,0,0,0,0,0,0,0,0,0,0,0,0,0,0
0,0,0,0,0,0,0,0,0,0,0,0,0,0,0,0,0,0,0,0,0,0,0,0,0,0,0,0,0,0,0,0,0,0
0,0,0,0,0,0,0,0,0,0,0,0,0,0,0,0,0,0,0,0,0,0,0,0,0,0,0,0,0,0,0,0,0,0
0,0,0,0,0,0,0,0,0,0,0,0,0,0,0,0,0,0,0,0,0,0,0,0,0,0,0,0,0,0,0,0,0,0
0,0,0,0,0,0,0,0,0,0,0,0,0,0,0,0,0,0,0,0,0,0,0,0,0,0,0,0,0,0,0,0,0,0
0,0,0,0,0,0,0,0,0,0,0,0,0,0,0,0,0,0,0,0,0,0,0,0,0,0,0,0,0,0,0,0,0,0
0,0,0,0,0,0,0,0,0,0,0,0,0,0,0,0,0,0,0,0,0,0,0,0,0,0,0,0,0,0,0,0,0,0
0,0,0,0,0,0,0,0,0,0,0,0,0,0,0,0,0,0,0,0,0,0,0,0,12,0,0,0,0,0,0,0,0,0
0,0,0,0,0,0,0,0,0,0,0,0,0,0,0,0,0,0,0,0,0,0,0,0,0,0,0,0,7,0,0,0,0,0
0,0,0,0,0,0,0,0,0,0,0,0,0,0,0,0,0,0,0,0,0,0,0,0,0,0,0,0,0,0,0,0,0,0
0,0,0,0,0,0,0,0,0,0,0,0,0,0,0,0,0,0,0,0,0,0,0,0,0,0,0,0,0,0,0,0,0,0
0,0,0,0,0,0,0,0,0,0,0,0,0,0,0,0,0,0,0,0,0,0,0,0,0,0,0,0,0,0,0,0,0,0
0,0,0,0,0,0,0,0,0,0,0,0,0,0,0,0,0,0,0,0,0,0,0,0,0,0,0,0,0,0,0,0,0,0
0,0,0,0,0,0,0,0,0,0,0,0,0,0,0,0,0,0,0,0,0,0,0,0,0,0,0,0,0,0,0,0,0,0
:endlayer
layer: 23
0,0,0,0,0,0,0,0,0,0,0,0,0,0,0,0,0,0,0,0,0,0,0,0,0,0,0,0,0,0,0,0,0,0
0,0,0,0,0,0,0,0,0,0,0,0,0,0,0,0,0,0,0,0,0,0,0,0,0,0,0,0,0,0,0,0,0,0
0,0,0,0,0,0,0,0,0,0,0,0,0,0,0,0,0,0,0,0,0,0,0,0,0,0,0,0,0,0,0,0,0,0
0,0,0,0,0,0,0,0,0,0,0,0,0,0,0,0,0,0,0,0,0,0,0,0,0,0,0,0,0,0,0,0,0,0
0,0,0,0,0,0,0,0,0,0,0,0,0,0,0,0,0,0,0,0,0,0,0,0,0,0,0,0,0,0,0,0,0,0
0,0,0,0,0,0,0,0,0,0,0,0,0,0,0,0,0,0,0,0,0,0,0,0,0,0,0,0,0,0,0,0,0,0
0,0,0,0,0,0,0,0,0,0,0,0,0,0,0,0,0,0,0,0,0,0,0,0,0,0,0,0,0,0,0,0,0,0
0,0,0,0,0,0,0,0,0,0,0,0,0,0,0,0,0,0,0,0,0,0,0,0,0,0,0,0,0,0,0,0,0,0
0,0,0,0,0,0,0,0,0,0,0,0,0,0,0,0,0,0,0,0,0,0,0,0,0,0,0,0,0,0,0,0,0,0
0,0,0,0,0,0,0,0,0,0,0,0,0,0,0,0,0,0,0,0,0,0,0,0,0,0,0,0,0,0,0,0,0,0
0,0,0,0,0,0,0,0,0,0,0,0,0,0,0,0,0,0,0,0,0,0,0,0,0,0,0,0,0,0,0,0,0,0
0,0,0,0,0,0,0,0,0,0,0,0,0,0,0,0,0,0,0,0,0,0,0,0,0,0,0,0,0,0,0,0,0,0
0,0,0,0,0,0,0,0,0,0,0,0,0,0,0,0,0,0,0,0,0,0,0,0,0,0,0,0,0,0,0,0,0,0
0,0,0,0,0,0,0,0,0,0,0,0,0,0,0,0,0,0,0,0,0,0,0,0,0,0,0,0,0,0,0,0,0,0
0,0,0,0,0,0,0,0,0,0,0,0,0,0,0,0,0,0,0,0,0,0,0,0,0,0,0,0,0,0,0,0,0,0
0,0,0,0,0,0,0,0,0,0,0,0,0,0,0,0,0,0,0,0,0,0,0,0,0,0,0,0,0,0,0,0,0,0
0,0,0,0,0,0,0,0,0,0,0,0,0,0,0,0,0,0,0,0,0,0,0,0,0,0,0,0,0,0,0,0,0,0
0,0,0,0,0,0,0,0,0,0,0,0,0,0,0,0,0,0,0,0,0,0,0,0,0,0,0,0,0,0,0,0,0,0
0,0,0,0,0,0,0,0,0,0,0,0,0,0,0,0,0,0,0,0,0,0,0,0,0,0,0,0,0,0,0,0,0,0
0,0,0,0,0,0,0,0,0,0,0,0,0,0,0,0,0,0,0,0,0,0,0,0,0,0,0,0,0,0,0,0,0,0
0,0,0,0,0,0,0,0,0,0,0,0,0,0,0,0,0,0,0,0,0,0,0,0,0,0,0,0,0,0,0,0,0,0
0,0,0,0,0,0,0,0,0,0,0,0,0,0,0,0,0,0,0,0,0,0,0,0,0,0,0,0,0,0,0,0,0,0
0,0,0,0,0,0,0,0,0,0,0,0,0,0,0,0,0,0,0,0,0,0,0,0,0,0,0,0,0,0,0,0,0,0
0,0,0,0,0,0,0,0,0,0,0,0,0,0,0,0,0,0,0,0,0,0,0,0,0,0,0,0,0,0,0,0,0,0
0,0,0,0,0,0,0,0,0,0,0,0,0,0,0,0,0,0,0,0,0,0,0,0,0,0,0,0,0,0,0,0,0,0
0,0,0,0,0,0,0,0,0,0,0,0,0,0,0,0,0,0,0,0,0,0,0,0,0,0,0,0,0,0,0,0,0,0
0,0,0,0,0,0,0,0,0,0,0,0,0,0,0,0,0,0,0,0,0,0,0,0,0,0,0,0,0,0,0,0,0,0
0,0,0,0,0,0,0,0,0,0,0,0,0,0,0,0,0,0,0,0,0,0,0,0,0,0,0,0,0,0,0,0,0,0
0,0,0,0,0,0,0,0,0,0,0,0,0,0,0,0,0,0,0,0,0,0,0,0,0,0,0,0,0,0,0,0,0,0
0,0,0,0,0,0,0,0,0,0,0,0,0,0,0,0,0,0,0,0,0,0,0,0,0,0,0,0,0,0,0,0,0,0
0,0,0,0,0,0,0,0,0,0,0,0,0,0,0,0,0,0,0,0,0,0,0,0,0,0,0,0,0,0,0,0,0,0
0,0,0,0,0,0,0,0,0,0,0,0,0,0,0,0,0,0,0,0,0,0,0,0,0,0,0,0,0,0,0,0,0,0
0,0,0,0,0,0,0,0,0,0,0,0,0,0,0,0,0,0,0,0,0,0,0,0,0,0,0,0,0,0,0,0,0,0
0,0,0,0,0,0,0,0,0,0,0,0,0,0,0,0,0,0,0,0,0,0,0,0,0,0,0,0,0,0,0,0,0,0
0,0,0,0,0,0,0,0,0,0,0,0,0,0,0,0,0,0,0,0,0,0,0,0,0,0,0,0,0,0,0,0,0,0
0,0,0,0,0,0,0,0,0,0,0,0,0,0,0,0,0,0,0,0,0,0,0,0,0,0,0,0,21,0,0,0,0,0
0,0,0,0,0,0,0,0,0,0,0,0,0,0,0,0,0,0,0,0,0,0,0,0,0,0,0,0,0,0,0,0,0,0
0,0,0,0,0,0,0,0,0,0,0,0,0,0,0,0,0,0,0,0,0,0,0,0,0,0,0,0,0,0,0,0,0,0
0,0,0,0,0,0,0,0,0,0,0,0,0,0,0,0,0,0,0,0,0,0,0,0,0,0,0,0,0,0,0,0,0,0
0,0,0,0,0,0,0,0,0,0,0,0,0,0,0,0,0,0,0,0,0,0,0,0,0,0,0,0,0,0,0,0,0,0
0,0,0,0,0,0,0,0,0,0,0,0,0,0,0,0,0,0,0,0,0,0,0,0,0,0,0,0,0,0,0,0,0,0
:endlayer

#### RULES ####
rule:
plugin=vanillaBlocks
number=1
data:
JSON:{blockState:{blockName:"minecraft:grass",properties:{snowy:"false"}}}
:enddata
:endrule

rule:
plugin=vanillaBlocks
number=2
data:
JSON:{blockState:{blockName:"minecraft:cobblestone"}}
:enddata
:endrule

rule:
plugin=vanillaBlocks
number=3
data:
JSON:{blockState:{blockName:"minecraft:stonebrick",properties:{variant:"stonebrick"}}}
:enddata
:endrule

rule:
plugin=vanillaBlocks
number=4
data:
JSON:{blockState:{blockName:"biomesoplenty:log_3",properties:{variant:"jacaranda",axis:"x"}}}
:enddata
:endrule

rule:
plugin=vanillaBlocks
number=5
data:
JSON:{blockState:{blockName:"biomesoplenty:log_3",properties:{variant:"jacaranda",axis:"z"}}}
:enddata
:endrule

rule:
plugin=vanillaBlocks
number=6
data:
JSON:{blockState:{blockName:"biomesoplenty:log_3",properties:{variant:"jacaranda",axis:"y"}}}
:enddata
:endrule

rule:
plugin=vanillaBlocks
number=7
data:
JSON:{blockState:{blockName:"biomesoplenty:jacaranda_fence",properties:{east:"false",south:"false",north:"false",west:"false"}}}
:enddata
:endrule

rule:
plugin=vanillaBlocks
number=8
data:
JSON:{blockState:{blockName:"biomesoplenty:planks_0",properties:{variant:"jacaranda"}}}
:enddata
:endrule

rule:
plugin=doors
number=9
data:
JSON:{blockState:{blockName:"minecraft:wooden_door",properties:{hinge:"right",half:"lower",powered:"false",facing:"west",open:"false"}}}
:enddata
:endrule

rule:
plugin=doors
number=10
data:
JSON:{blockState:{blockName:"minecraft:wooden_door",properties:{hinge:"left",half:"lower",powered:"false",facing:"west",open:"false"}}}
:enddata
:endrule

rule:
plugin=vanillaBlocks
number=11
data:
JSON:{blockState:{blockName:"ancientwarfarestructure:fire_pit",properties:{lit:"false",variant:"log"}}}
:enddata
:endrule

rule:
plugin=vanillaBlocks
number=12
data:
JSON:{blockState:{blockName:"minecraft:stone_slab",properties:{half:"bottom",variant:"cobblestone"}}}
:enddata
:endrule

rule:
plugin=vanillaBlocks
number=13
data:
JSON:{blockState:{blockName:"biomesoplenty:wood_slab_1",properties:{half:"top",variant:"jacaranda"}}}
:enddata
:endrule

rule:
plugin=vanillaBlocks
number=14
data:
JSON:{blockState:{blockName:"biomesoplenty:wood_slab_1",properties:{half:"bottom",variant:"jacaranda"}}}
:enddata
:endrule

rule:
plugin=doors
number=15
data:
JSON:{blockState:{blockName:"minecraft:wooden_door",properties:{hinge:"left",half:"lower",powered:"false",facing:"north",open:"false"}}}
:enddata
:endrule

rule:
plugin=doors
number=16
data:
JSON:{blockState:{blockName:"minecraft:wooden_door",properties:{hinge:"left",half:"lower",powered:"false",facing:"south",open:"false"}}}
:enddata
:endrule

rule:
plugin=doors
number=17
data:
JSON:{blockState:{blockName:"minecraft:wooden_door",properties:{hinge:"right",half:"lower",powered:"false",facing:"south",open:"false"}}}
:enddata
:endrule

rule:
plugin=vanillaBlocks
number=18
data:
JSON:{blockState:{blockName:"minecraft:ladder",properties:{facing:"north"}}}
:enddata
:endrule

rule:
plugin=doors
number=19
data:
JSON:{blockState:{blockName:"minecraft:wooden_door",properties:{hinge:"left",half:"lower",powered:"false",facing:"east",open:"false"}}}
:enddata
:endrule

rule:
plugin=doors
number=20
data:
JSON:{blockState:{blockName:"minecraft:wooden_door",properties:{hinge:"right",half:"lower",powered:"false",facing:"east",open:"false"}}}
:enddata
:endrule

rule:
plugin=vanillaBlocks
number=21
data:
JSON:{blockState:{blockName:"minecraft:torch",properties:{facing:"up"}}}
:enddata
:endrule

rule:
plugin=doors
number=22
data:
JSON:{blockState:{blockName:"minecraft:wooden_door",properties:{hinge:"right",half:"lower",powered:"false",facing:"north",open:"false"}}}
:enddata
:endrule

rule:
plugin=doors
number=23
data:
JSON:{blockState:{blockName:"minecraft:wooden_door",properties:{hinge:"right",half:"upper",powered:"false",facing:"west",open:"false"}}}
:enddata
:endrule

rule:
plugin=doors
number=24
data:
JSON:{blockState:{blockName:"minecraft:wooden_door",properties:{hinge:"left",half:"upper",powered:"false",facing:"west",open:"false"}}}
:enddata
:endrule

rule:
plugin=doors
number=25
data:
JSON:{blockState:{blockName:"minecraft:wooden_door",properties:{hinge:"left",half:"upper",powered:"false",facing:"north",open:"false"}}}
:enddata
:endrule

rule:
plugin=doors
number=26
data:
JSON:{blockState:{blockName:"minecraft:wooden_door",properties:{hinge:"left",half:"upper",powered:"false",facing:"south",open:"false"}}}
:enddata
:endrule

rule:
plugin=doors
number=27
data:
JSON:{blockState:{blockName:"minecraft:wooden_door",properties:{hinge:"right",half:"upper",powered:"false",facing:"south",open:"false"}}}
:enddata
:endrule

rule:
plugin=doors
number=28
data:
JSON:{blockState:{blockName:"minecraft:wooden_door",properties:{hinge:"left",half:"upper",powered:"false",facing:"east",open:"false"}}}
:enddata
:endrule

rule:
plugin=doors
number=29
data:
JSON:{blockState:{blockName:"minecraft:wooden_door",properties:{hinge:"right",half:"upper",powered:"false",facing:"east",open:"false"}}}
:enddata
:endrule

rule:
plugin=doors
number=30
data:
JSON:{blockState:{blockName:"minecraft:wooden_door",properties:{hinge:"right",half:"upper",powered:"false",facing:"north",open:"false"}}}
:enddata
:endrule

rule:
plugin=vanillaBlocks
number=31
data:
JSON:{blockState:{blockName:"minecraft:torch",properties:{facing:"east"}}}
:enddata
:endrule

rule:
plugin=vanillaBlocks
number=32
data:
JSON:{blockState:{blockName:"minecraft:torch",properties:{facing:"north"}}}
:enddata
:endrule

rule:
plugin=vanillaBlocks
number=33
data:
JSON:{blockState:{blockName:"minecraft:stone_stairs",properties:{half:"top",shape:"straight",facing:"north"}}}
:enddata
:endrule

rule:
plugin=vanillaBlocks
number=34
data:
JSON:{blockState:{blockName:"minecraft:stone_stairs",properties:{half:"top",shape:"straight",facing:"south"}}}
:enddata
:endrule

rule:
plugin=vanillaBlocks
number=35
data:
JSON:{blockState:{blockName:"minecraft:torch",properties:{facing:"south"}}}
:enddata
:endrule

rule:
plugin=vanillaBlocks
number=36
data:
JSON:{blockState:{blockName:"minecraft:torch",properties:{facing:"west"}}}
:enddata
:endrule

rule:
plugin=vanillaBlocks
number=37
data:
JSON:{blockState:{blockName:"minecraft:stone_stairs",properties:{half:"top",shape:"straight",facing:"east"}}}
:enddata
:endrule

rule:
plugin=vanillaBlocks
number=38
data:
JSON:{blockState:{blockName:"minecraft:stone_slab",properties:{half:"top",variant:"cobblestone"}}}
:enddata
:endrule

rule:
plugin=vanillaBlocks
number=39
data:
JSON:{blockState:{blockName:"biomesoplenty:jacaranda_stairs",properties:{half:"top",shape:"straight",facing:"east"}}}
:enddata
:endrule

rule:
plugin=vanillaBlocks
number=40
data:
JSON:{blockState:{blockName:"minecraft:stone_stairs",properties:{half:"top",shape:"straight",facing:"west"}}}
:enddata
:endrule

rule:
plugin=vanillaBlocks
number=41
data:
JSON:{blockState:{blockName:"biomesoplenty:jacaranda_stairs",properties:{half:"top",shape:"straight",facing:"west"}}}
:enddata
:endrule

rule:
plugin=vanillaBlocks
number=42
data:
JSON:{blockState:{blockName:"biomesoplenty:jacaranda_stairs",properties:{half:"bottom",shape:"straight",facing:"west"}}}
:enddata
:endrule

rule:
plugin=vanillaBlocks
number=43
data:
JSON:{blockState:{blockName:"biomesoplenty:jacaranda_stairs",properties:{half:"bottom",shape:"straight",facing:"east"}}}
:enddata
:endrule

rule:
plugin=vanillaBlocks
number=44
data:
JSON:{blockState:{blockName:"biomesoplenty:jacaranda_stairs",properties:{half:"bottom",shape:"straight",facing:"south"}}}
:enddata
:endrule

rule:
plugin=vanillaBlocks
number=45
data:
JSON:{blockState:{blockName:"biomesoplenty:jacaranda_stairs",properties:{half:"bottom",shape:"straight",facing:"north"}}}
:enddata
:endrule

rule:
plugin=vanillaBlocks
number=46
data:
JSON:{blockState:{blockName:"minecraft:stone_stairs",properties:{half:"bottom",shape:"straight",facing:"south"}}}
:enddata
:endrule

rule:
plugin=vanillaBlocks
number=47
data:
JSON:{blockState:{blockName:"minecraft:stone_stairs",properties:{half:"bottom",shape:"straight",facing:"north"}}}
:enddata
:endrule

rule:
plugin=vanillaBlocks
number=48
data:
JSON:{blockState:{blockName:"biomesoplenty:jacaranda_stairs",properties:{half:"top",shape:"straight",facing:"north"}}}
:enddata
:endrule

rule:
plugin=vanillaBlocks
number=49
data:
JSON:{blockState:{blockName:"biomesoplenty:jacaranda_stairs",properties:{half:"top",shape:"straight",facing:"south"}}}
:enddata
:endrule

rule:
plugin=vanillaBlocks
number=50
data:
JSON:{blockState:{blockName:"minecraft:cobblestone_wall",properties:{east:"false",south:"false",north:"false",variant:"cobblestone",west:"false",up:"false"}}}
:enddata
:endrule

#### ENTITIES ####
