# Ancient Warfare Structure Template File
# Auto-generated structure template file. created on: 6/11/2023 at: 13:34:11
# Lines beginning with # denote comments

header:
version=2.11
name=SB_MarenCol_House_1H3R_1_birch
mods=
size=22,14,22
offset=11,1,21
:endheader

#### VALIDATION ####
validation:
type=ground
structureAuthor=TheOddlySeagull
survival=true
worldGenEnabled=false
unique=false
preserveBlocks=false
preventNaturalHostileSpawns=false
selectionWeight=1
clusterValue=1
minDuplicateDistance=1
dimensionWhiteList=true
dimensionList=
biomeGroupList=
biomeWhiteList=true
biomeList=
leveling=0
fill=0
border=0
blockSwap=false
territoryName=
biomeReplacement=minecraft:
minGenerationHeight=0
maxGenerationHeight=255
:endvalidation

#### LAYERS ####
layer: 0
1,1,1,1,1,1,1,1,1,1,1,1,1,1,1,1,1,1,1,1,1,1
1,1,1,1,1,1,1,1,1,1,1,1,1,1,1,1,1,1,1,1,1,1
1,1,1,1,1,1,1,1,1,1,1,2,2,2,2,2,2,2,2,2,1,1
1,1,1,1,1,1,1,1,1,1,1,2,3,3,3,3,3,3,3,2,1,1
1,1,1,1,1,1,1,1,1,1,2,2,2,3,3,3,3,3,3,2,2,2
1,1,2,2,2,2,2,2,2,1,2,2,2,3,3,3,3,3,3,2,2,2
1,1,2,3,3,3,3,3,2,1,1,2,3,3,3,3,3,3,3,2,2,2
1,1,2,3,3,3,3,3,2,2,2,2,2,2,2,2,3,3,3,2,2,2
1,1,2,3,3,3,3,3,2,2,2,2,2,2,2,2,3,3,3,2,1,1
1,1,2,3,3,3,3,3,2,2,2,2,2,2,2,2,2,2,2,2,1,1
1,1,2,3,3,3,3,3,2,2,2,2,2,2,2,2,2,1,1,1,1,1
1,1,2,3,3,3,3,3,2,2,2,2,2,2,2,2,2,1,1,1,1,1
1,1,2,2,2,2,2,2,2,2,2,2,2,2,2,2,1,1,1,1,1,1
1,1,1,1,1,1,1,1,2,2,2,2,2,2,2,2,1,1,1,1,1,1
1,1,1,1,1,1,1,1,2,2,2,2,2,2,2,2,1,1,1,1,1,1
1,1,1,1,1,1,1,1,2,2,2,2,2,2,2,2,1,1,1,1,1,1
1,1,1,1,1,1,1,1,2,2,2,2,2,2,2,2,2,1,1,1,1,1
1,1,1,1,1,1,1,1,2,2,2,2,2,2,2,2,2,1,1,1,1,1
1,1,1,1,1,1,1,1,2,2,2,2,2,2,2,2,1,1,1,1,1,1
1,1,1,1,1,1,1,1,2,2,2,2,2,2,2,2,1,1,1,1,1,1
1,1,1,1,1,1,1,1,1,1,2,2,2,2,1,1,1,1,1,1,1,1
1,1,1,1,1,1,1,1,1,1,2,2,2,2,1,1,1,1,1,1,1,1
:endlayer
layer: 1
0,0,0,0,0,0,0,0,0,0,0,0,0,0,0,0,0,0,0,0,0,0
0,4,0,0,0,4,0,0,0,0,0,0,0,0,0,0,0,0,0,0,0,0
0,0,0,0,0,0,0,0,0,0,0,5,3,5,3,5,3,5,3,5,0,0
0,0,0,0,0,0,0,0,0,0,0,2,0,0,0,0,0,0,0,3,0,0
0,0,0,0,0,0,0,0,0,0,2,0,8,0,0,0,0,0,0,5,0,0
0,0,5,3,5,3,5,3,5,0,2,0,8,0,0,0,0,0,0,0,0,0
0,0,3,0,0,0,0,0,3,0,0,2,0,0,0,0,0,0,0,0,0,0
0,0,5,0,0,0,0,0,5,3,3,5,3,5,0,5,0,0,0,5,0,0
0,0,3,0,0,0,0,0,3,0,0,0,0,0,0,3,0,0,0,3,0,0
0,0,3,0,0,0,0,0,5,0,0,0,0,0,0,5,3,5,3,5,0,0
0,0,5,0,0,0,0,0,0,0,0,0,0,0,0,0,0,0,0,0,0,0
0,0,3,0,0,0,0,0,0,0,0,0,0,0,0,5,0,0,0,0,0,0
0,0,5,3,5,3,5,3,5,7,0,0,0,0,0,3,0,0,0,0,0,0
0,0,0,0,0,0,0,0,3,6,0,0,0,0,0,3,0,0,0,0,0,0
0,0,0,0,0,0,0,0,5,0,0,0,0,0,0,5,0,0,0,0,4,0
0,0,0,0,0,0,0,0,3,0,0,0,0,0,0,2,0,0,0,0,0,0
0,0,0,0,0,0,0,0,3,0,0,0,0,0,8,0,2,0,0,0,0,0
0,0,0,0,4,0,0,0,5,0,0,0,0,0,8,0,2,0,0,0,0,0
0,0,0,0,0,0,0,0,3,0,0,0,0,0,0,2,0,0,0,0,0,0
0,0,0,0,0,0,0,0,5,3,5,0,0,5,3,5,0,0,0,0,0,0
0,4,0,0,0,0,0,0,0,0,0,0,0,0,0,0,0,0,0,0,4,0
0,0,0,0,0,0,0,0,0,0,0,0,0,0,0,0,0,0,0,0,0,0
:endlayer
layer: 2
0,0,0,0,0,0,0,0,0,0,0,0,0,0,0,0,0,0,0,0,0,0
0,9,0,0,0,9,0,0,0,0,0,0,0,0,0,0,0,0,0,0,0,0
0,0,0,0,0,0,0,0,0,0,0,5,4,5,4,5,4,5,4,5,0,0
0,0,0,0,0,0,0,0,0,0,0,2,0,0,0,0,0,0,0,3,0,0
0,0,0,0,0,0,0,0,0,0,2,0,0,0,0,0,0,0,0,5,0,0
0,0,5,4,5,4,5,4,5,0,2,0,0,0,0,0,0,0,0,0,0,0
0,0,4,0,0,0,0,0,3,0,0,2,0,0,0,0,0,0,0,0,0,0
0,0,5,0,0,0,0,0,5,4,4,5,3,5,0,5,0,0,0,5,0,0
0,0,4,0,0,0,0,0,3,0,0,0,0,0,0,3,0,0,0,3,0,0
0,0,4,0,0,0,0,0,5,0,0,0,0,0,0,5,4,5,4,5,0,0
0,0,5,0,0,0,0,0,0,0,0,0,0,0,0,0,0,0,0,0,0,0
0,0,4,0,0,0,0,0,0,0,0,0,0,0,0,5,0,0,0,0,0,0
0,0,5,4,5,4,5,4,5,0,0,0,0,0,0,4,0,0,0,0,0,0
0,0,0,0,0,0,0,0,3,7,0,0,0,0,0,4,0,0,0,0,0,0
0,0,0,0,0,0,0,0,5,6,0,0,0,0,0,5,0,0,0,0,9,0
0,0,0,0,0,0,0,0,4,0,0,0,0,0,0,2,0,0,0,0,0,0
0,0,0,0,0,0,0,0,4,0,0,0,0,0,0,0,2,0,0,0,0,0
0,0,0,0,9,0,0,0,5,0,0,0,0,0,0,0,2,0,0,0,0,0
0,0,0,0,0,0,0,0,3,0,0,0,0,0,0,2,0,0,0,0,0,0
0,0,0,0,0,0,0,0,5,3,5,0,0,5,3,5,0,0,0,0,0,0
0,9,0,0,0,0,0,0,0,0,0,0,0,0,0,0,0,0,0,0,9,0
0,0,0,0,0,0,0,0,0,0,0,0,0,0,0,0,0,0,0,0,0,0
:endlayer
layer: 3
0,0,0,0,0,0,0,0,0,0,0,0,0,0,0,0,0,0,0,0,0,0
0,0,0,0,0,0,0,0,0,0,0,12,0,12,0,12,0,12,0,12,0,0
0,0,0,0,0,0,0,0,0,0,10,5,4,5,4,5,4,5,4,5,13,0
0,0,0,0,0,0,0,0,0,0,0,2,0,11,0,11,0,11,0,3,0,0
0,0,12,0,0,0,0,0,12,0,15,17,0,0,0,0,0,0,10,5,13,0
0,10,5,4,5,4,5,4,5,0,2,16,0,0,0,0,0,0,0,3,0,0
0,0,4,0,6,0,11,0,3,0,0,2,0,12,0,12,0,0,0,3,0,0
0,0,5,13,0,0,0,10,5,4,4,5,3,5,3,5,13,0,10,5,13,0
0,0,4,0,0,0,0,0,3,0,0,11,0,11,0,3,0,12,0,3,0,0
0,0,4,0,0,0,0,10,5,13,0,0,0,0,10,5,4,5,4,5,13,0
0,0,5,13,0,0,0,0,3,0,0,0,0,0,0,3,0,11,0,11,0,0
0,0,4,0,14,0,12,0,3,0,0,0,0,0,10,5,13,0,0,0,0,0
0,10,5,4,5,4,5,4,5,13,0,0,0,0,0,4,0,0,0,0,0,0
0,0,11,0,0,0,0,0,3,0,0,0,0,0,0,4,0,0,0,0,0,0
0,0,0,0,0,0,0,0,5,7,0,0,0,0,10,5,13,0,0,0,0,0
0,0,0,0,0,0,0,0,4,6,0,0,0,0,0,2,0,0,0,0,0,0
0,0,0,0,0,0,0,0,4,0,0,0,0,0,0,17,15,0,0,0,0,0
0,0,0,0,0,0,0,0,5,13,0,0,0,0,0,16,2,0,0,0,0,0
0,0,0,0,0,0,0,0,3,0,12,0,0,12,0,2,0,0,0,0,0,0
0,0,0,0,0,0,0,10,5,3,5,3,3,5,3,5,13,0,0,0,0,0
0,0,0,0,0,0,0,0,11,0,0,0,0,0,0,11,0,0,0,0,0,0
0,0,0,0,0,0,0,0,0,0,0,0,0,0,0,0,0,0,0,0,0,0
:endlayer
layer: 4
0,0,0,0,0,0,0,0,0,0,0,0,0,0,0,0,0,0,0,0,0,0
0,0,0,0,0,0,0,0,0,0,7,7,7,7,7,7,7,7,7,7,7,0
0,0,0,0,0,0,0,0,0,0,6,5,20,20,20,20,20,20,20,5,6,0
0,0,0,0,0,0,0,0,0,0,0,19,0,0,0,0,0,0,0,19,0,0
0,7,7,7,7,7,7,7,7,7,7,19,0,0,0,0,0,0,0,19,0,0
0,6,5,20,20,20,20,20,5,6,2,19,0,0,0,0,0,0,0,19,0,0
0,0,19,0,19,0,0,0,19,0,0,19,0,0,0,0,0,0,0,19,0,0
0,0,19,0,19,0,0,0,19,20,20,20,20,20,20,5,0,0,0,19,0,0
0,0,19,0,19,20,20,20,19,21,21,21,21,21,21,19,0,0,0,19,0,0
0,0,19,0,19,21,3,21,19,3,3,3,3,3,3,19,20,20,20,5,14,0
0,0,19,0,19,21,3,21,19,21,21,21,21,21,21,19,18,18,18,18,18,0
0,0,19,0,19,21,3,21,19,3,3,3,3,3,3,5,0,0,0,0,0,0
0,14,5,20,20,20,20,20,5,0,3,21,21,21,21,19,0,0,0,0,0,0
0,18,18,18,18,18,18,18,19,0,3,3,3,3,3,19,0,0,0,0,0,0
0,0,0,0,0,0,0,0,19,0,3,21,21,21,21,5,0,0,0,0,0,0
0,0,0,0,0,0,0,0,19,7,3,3,3,3,3,19,0,0,0,0,0,0
0,0,0,0,0,0,0,0,19,6,21,21,21,21,21,19,0,0,0,0,0,0
0,0,0,0,0,0,0,0,19,3,3,3,3,3,3,19,2,0,0,0,0,0
0,0,0,0,0,0,0,0,19,21,21,21,21,21,21,19,0,0,0,0,0,0
0,0,0,0,0,0,0,0,5,20,20,20,20,20,20,5,0,0,0,0,0,0
0,0,0,0,0,0,0,0,0,0,6,21,21,6,0,0,0,0,0,0,0,0
0,0,0,0,0,0,0,0,0,0,0,0,0,0,0,0,0,0,0,0,0,0
:endlayer
layer: 5
0,0,0,0,0,0,0,0,0,0,0,0,0,0,0,0,0,0,0,0,0,0
0,0,0,0,0,0,0,0,0,0,0,0,0,0,0,0,0,0,0,0,0,0
0,0,0,0,0,0,0,0,0,0,7,7,7,7,7,7,7,7,7,7,7,0
0,0,0,0,0,0,0,0,0,0,6,5,6,6,6,6,6,6,6,5,6,0
0,0,0,0,0,0,0,0,0,0,0,3,0,0,0,0,0,0,0,3,0,0
0,7,7,7,7,7,7,7,7,7,2,3,0,0,0,0,0,0,0,3,0,0
0,6,5,6,6,6,6,6,5,6,6,3,0,0,0,0,0,0,0,3,0,0
0,0,3,0,0,0,0,0,5,5,3,5,3,5,3,5,0,0,0,3,0,0
0,0,3,0,5,3,5,3,5,0,0,0,0,0,0,3,14,14,14,5,14,0
0,0,3,0,3,0,0,0,0,0,0,0,0,0,0,5,18,18,18,18,18,0
0,0,3,0,5,0,0,0,0,0,0,0,0,0,0,3,0,0,0,0,0,0
0,14,5,14,3,0,0,0,4,4,4,0,0,0,0,5,0,0,0,0,0,0
0,18,18,18,5,3,5,3,5,0,4,0,0,0,0,3,0,0,0,0,0,0
0,0,0,0,0,0,0,0,3,0,4,0,0,0,0,3,0,0,0,0,0,0
0,0,0,0,0,0,0,0,3,0,4,0,0,0,0,5,0,0,0,0,0,0
0,0,0,0,0,0,0,0,3,0,0,0,0,0,0,3,0,0,0,0,0,0
0,0,0,0,0,0,0,0,3,0,0,0,0,0,0,3,0,0,0,0,0,0
0,0,0,0,0,0,0,0,3,0,0,0,0,0,0,3,2,0,0,0,0,0
0,0,0,0,0,0,0,0,3,0,0,0,0,0,0,3,0,0,0,0,0,0
0,0,0,0,0,0,0,0,5,3,5,0,0,5,3,5,0,0,0,0,0,0
0,0,0,0,0,0,0,0,0,0,4,4,4,4,0,0,0,0,0,0,0,0
0,0,0,0,0,0,0,0,0,0,0,0,0,0,0,0,0,0,0,0,0,0
:endlayer
layer: 6
0,0,0,0,0,0,0,0,0,0,0,0,0,0,0,0,0,0,0,0,0,0
0,0,0,0,0,0,0,0,0,0,0,0,0,0,0,0,0,0,0,0,0,0
0,0,0,0,0,0,0,0,0,0,0,0,0,0,0,0,0,0,0,0,0,0
0,0,0,0,0,0,0,0,0,0,7,7,7,7,7,7,7,7,7,7,7,0
0,0,0,0,0,0,0,0,0,0,6,5,6,6,6,6,6,6,6,5,6,0
0,0,0,0,0,0,0,0,0,0,2,3,0,0,0,0,0,0,0,3,0,0
0,7,7,7,7,7,7,22,3,0,0,3,0,0,0,0,0,0,0,3,0,0
0,6,5,6,6,6,6,6,5,5,4,5,3,5,3,5,14,14,14,5,14,0
0,0,3,0,5,3,5,3,5,0,0,0,0,0,0,19,25,18,18,18,18,0
0,0,3,0,3,0,0,0,0,0,0,0,0,0,0,19,25,0,0,0,0,0
0,14,5,14,5,0,0,0,0,0,0,0,0,0,0,19,23,0,0,0,0,0
0,18,18,18,3,0,0,0,0,0,0,0,0,0,10,5,0,0,0,0,0,0
0,0,0,0,5,4,5,3,5,13,0,0,0,0,0,4,0,0,0,0,0,0
0,0,0,0,0,0,0,22,19,0,0,0,0,0,0,4,0,0,0,0,0,0
0,0,0,0,0,0,0,22,19,0,0,0,0,0,10,5,0,0,0,0,0,0
0,0,0,0,0,0,0,22,19,0,0,0,0,0,0,19,23,0,0,0,0,0
0,0,0,0,0,0,0,22,19,0,0,0,0,0,0,19,25,0,0,0,0,0
0,0,0,0,0,0,0,22,19,0,0,0,0,0,0,19,2,0,0,0,0,0
0,0,0,0,0,0,0,22,19,0,0,0,0,0,0,19,25,0,0,0,0,0
0,0,0,0,0,0,0,22,5,3,5,0,0,5,3,5,25,0,0,0,0,0
0,0,0,0,0,0,0,22,23,0,0,0,0,0,0,24,25,0,0,0,0,0
0,0,0,0,0,0,0,0,0,0,0,0,0,0,0,0,0,0,0,0,0,0
:endlayer
layer: 7
0,0,0,0,0,0,0,0,0,0,0,0,0,0,0,0,0,0,0,0,0,0
0,0,0,0,0,0,0,0,0,0,0,0,0,0,0,0,0,0,0,0,0,0
0,0,0,0,0,0,0,0,0,0,0,0,0,0,0,0,0,0,0,0,0,0
0,0,0,0,0,0,0,0,0,0,0,0,0,0,0,0,0,0,0,0,0,0
0,0,0,0,0,0,0,0,0,0,7,7,7,7,7,7,7,7,7,7,7,0
0,0,0,0,0,0,0,0,0,0,2,19,6,6,6,6,6,6,6,19,6,0
0,0,0,0,0,0,0,0,22,23,0,19,14,14,14,14,14,14,14,19,14,0
0,7,7,7,7,7,7,7,7,20,4,5,3,5,20,18,18,18,18,18,18,0
0,6,19,6,5,3,5,3,5,23,0,0,0,0,24,25,0,0,0,0,0,0
0,14,19,14,3,0,11,0,11,21,0,0,0,0,24,25,0,0,0,0,0,0
0,18,18,18,5,13,0,0,0,21,0,0,0,0,24,25,7,0,0,0,0,0
0,0,0,0,3,0,12,0,12,21,0,0,0,0,6,5,6,0,0,0,0,0
0,0,0,4,5,4,5,3,5,23,0,0,0,0,0,4,0,0,0,0,0,0
0,0,0,0,4,0,4,0,22,23,0,0,0,0,0,4,0,0,0,0,0,0
0,0,0,0,0,0,0,0,22,23,0,0,0,0,14,5,14,0,0,0,0,0
0,0,0,0,0,0,0,0,22,23,0,0,0,0,24,18,18,0,0,0,0,0
0,0,0,0,0,0,0,0,22,23,0,0,0,0,24,25,0,0,0,0,0,0
0,0,0,0,0,0,0,0,22,23,0,0,0,0,24,25,2,0,0,0,0,0
0,0,0,0,0,0,0,0,22,23,12,0,0,12,24,25,0,0,0,0,0,0
0,0,0,0,0,0,0,0,22,20,5,4,4,5,20,25,0,0,0,0,0,0
0,0,0,0,0,0,0,0,22,23,0,0,0,0,24,25,0,0,0,0,0,0
0,0,0,0,0,0,0,0,0,0,0,0,0,0,0,0,0,0,0,0,0,0
:endlayer
layer: 8
0,0,0,0,0,0,0,0,0,0,0,0,0,0,0,0,0,0,0,0,0,0
0,0,0,0,0,0,0,0,0,0,0,0,0,0,0,0,0,0,0,0,0,0
0,0,0,0,0,0,0,0,0,0,0,0,0,0,0,0,0,0,0,0,0,0
0,0,0,0,0,0,0,0,0,0,0,0,0,0,0,0,0,0,0,0,0,0
0,0,0,0,0,0,0,0,0,0,0,0,0,0,0,0,0,0,0,0,0,0
0,0,0,0,0,0,0,0,0,0,2,7,7,7,7,7,7,7,7,7,7,0
0,0,0,0,0,0,0,0,0,22,23,3,3,3,25,18,18,18,18,18,18,0
0,0,0,22,7,7,7,7,7,7,20,5,3,20,25,0,0,0,0,0,0,0
0,7,7,7,5,20,20,20,5,3,23,11,0,24,25,0,0,0,0,0,0,0
0,18,18,18,19,0,0,0,19,3,23,0,0,24,25,0,0,0,0,0,0,0
0,0,0,22,19,0,0,0,19,3,23,0,0,24,25,0,0,0,0,0,0,0
0,0,0,22,19,0,0,0,19,3,23,0,0,24,25,7,7,0,0,0,0,0
0,0,0,22,5,20,20,20,5,3,23,0,0,6,6,19,6,0,0,0,0,0
0,0,0,22,18,18,18,18,18,22,23,0,0,14,14,19,14,0,0,0,0,0
0,0,0,0,0,0,0,0,0,22,23,0,0,24,25,18,18,0,0,0,0,0
0,0,0,0,0,0,0,0,0,22,23,0,0,24,25,0,0,0,0,0,0,0
0,0,0,0,0,0,0,0,0,22,23,0,0,24,25,0,0,0,0,0,0,0
0,0,0,0,0,0,0,0,0,22,23,0,0,24,25,0,2,0,0,0,0,0
0,0,0,0,0,0,0,0,0,22,23,0,0,24,25,0,0,0,0,0,0,0
0,0,0,0,0,0,0,0,0,22,20,3,3,20,25,0,0,0,0,0,0,0
0,0,0,0,0,0,0,0,0,22,23,0,0,24,25,0,0,0,0,0,0,0
0,0,0,0,0,0,0,0,0,0,0,0,0,0,0,0,0,0,0,0,0,0
:endlayer
layer: 9
0,0,0,0,0,0,0,0,0,0,0,0,0,0,0,0,0,0,0,0,0,0
0,0,0,0,0,0,0,0,0,0,0,0,0,0,0,0,0,0,0,0,0,0
0,0,0,0,0,0,0,0,0,0,0,0,0,0,0,0,0,0,0,0,0,0
0,0,0,0,0,0,0,0,0,0,0,0,0,0,0,0,0,0,0,0,0,0
0,0,0,0,0,0,0,0,0,0,0,0,0,0,0,0,0,0,0,0,0,0
0,0,0,0,0,0,0,0,0,0,2,0,0,0,0,0,0,0,0,0,0,0
0,0,0,0,0,0,0,0,0,0,22,23,24,25,0,0,0,0,0,0,0,0
0,0,0,0,0,0,0,0,0,0,22,20,20,25,0,0,0,0,0,0,0,0
0,0,0,0,22,7,7,7,7,0,22,23,24,25,0,0,0,0,0,0,0,0
0,0,0,0,22,23,6,6,25,0,22,23,24,25,0,0,0,0,0,0,0,0
0,0,0,0,22,23,0,24,25,9,22,23,24,25,0,0,0,0,0,0,0,0
0,0,0,0,22,14,14,24,25,0,22,23,24,25,0,0,0,0,0,0,0,0
0,0,0,0,18,18,18,18,18,0,22,23,24,25,7,7,7,0,0,0,0,0
0,0,0,0,0,0,0,0,0,0,22,23,24,18,18,18,18,0,0,0,0,0
0,0,0,0,0,0,0,0,0,0,22,23,24,25,0,0,0,0,0,0,0,0
0,0,0,0,0,0,0,0,0,0,22,23,24,25,0,0,0,0,0,0,0,0
0,0,0,0,0,0,0,0,0,0,22,23,24,25,0,0,0,0,0,0,0,0
0,0,0,0,0,0,0,0,0,0,22,23,24,25,0,0,2,0,0,0,0,0
0,0,0,0,0,0,0,0,0,0,22,23,24,25,0,0,0,0,0,0,0,0
0,0,0,0,0,0,0,0,0,0,22,20,20,25,0,0,0,0,0,0,0,0
0,0,0,0,0,0,0,0,0,0,22,23,24,25,0,0,0,0,0,0,0,0
0,0,0,0,0,0,0,0,0,0,0,0,0,0,0,0,0,0,0,0,0,0
:endlayer
layer: 10
0,0,0,0,0,0,0,0,0,0,0,0,0,0,0,0,0,0,0,0,0,0
0,0,0,0,0,0,0,0,0,0,0,0,0,0,0,0,0,0,0,0,0,0
0,0,0,0,0,0,0,0,0,0,0,0,0,0,0,0,0,0,0,0,0,0
0,0,0,0,0,0,0,0,0,0,0,0,0,0,0,0,0,0,0,0,0,0
0,0,0,0,0,0,0,0,0,0,0,0,0,0,0,0,0,0,0,0,0,0
0,0,0,0,0,0,0,0,0,0,2,0,0,0,0,0,0,0,0,0,0,0
0,0,0,0,0,0,0,0,0,0,0,22,25,0,0,0,0,0,0,0,0,0
0,0,0,0,0,0,0,0,0,0,0,22,25,0,0,0,0,0,0,0,0,0
0,0,0,0,0,0,0,0,0,0,0,22,25,0,0,0,0,0,0,0,0,0
0,0,0,0,0,7,7,25,0,0,0,22,25,0,0,0,0,0,0,0,0,0
0,0,0,0,0,22,3,25,0,0,0,22,25,0,0,0,0,0,0,0,0,0
0,0,0,0,0,22,18,18,0,0,0,22,25,0,0,0,0,0,0,0,0,0
0,0,0,0,0,0,0,0,0,0,0,22,25,0,0,0,0,0,0,0,0,0
0,0,0,0,0,0,0,0,0,0,0,22,25,0,0,0,0,0,0,0,0,0
0,0,0,0,0,0,0,0,0,0,0,22,25,0,0,0,0,0,0,0,0,0
0,0,0,0,0,0,0,0,0,0,0,22,25,0,0,0,0,0,0,0,0,0
0,0,0,0,0,0,0,0,0,0,0,22,25,0,0,0,0,0,0,0,0,0
0,0,0,0,0,0,0,0,0,0,0,22,25,0,0,0,26,0,0,0,0,0
0,0,0,0,0,0,0,0,0,0,0,22,25,0,0,0,0,0,0,0,0,0
0,0,0,0,0,0,0,0,0,0,0,22,25,0,0,0,0,0,0,0,0,0
0,0,0,0,0,0,0,0,0,0,0,22,25,0,0,0,0,0,0,0,0,0
0,0,0,0,0,0,0,0,0,0,0,0,0,0,0,0,0,0,0,0,0,0
:endlayer
layer: 11
0,0,0,0,0,0,0,0,0,0,0,0,0,0,0,0,0,0,0,0,0,0
0,0,0,0,0,0,0,0,0,0,0,0,0,0,0,0,0,0,0,0,0,0
0,0,0,0,0,0,0,0,0,0,0,0,0,0,0,0,0,0,0,0,0,0
0,0,0,0,0,0,0,0,0,0,0,0,0,0,0,0,0,0,0,0,0,0
0,0,0,0,0,0,0,0,0,0,0,0,0,0,0,0,0,0,0,0,0,0
0,0,0,0,0,0,0,0,0,0,2,0,0,0,0,0,0,0,0,0,0,0
0,0,0,0,0,0,0,0,0,0,0,0,0,0,0,0,0,0,0,0,0,0
0,0,0,0,0,0,0,0,0,0,0,0,0,0,0,0,0,0,0,0,0,0
0,0,0,0,0,0,0,0,0,0,0,0,0,0,0,0,0,0,0,0,0,0
0,0,0,0,0,0,0,0,0,0,0,0,0,0,0,0,0,0,0,0,0,0
0,0,0,0,0,0,4,0,0,0,0,0,0,0,0,0,0,0,0,0,0,0
0,0,0,0,0,0,0,0,0,0,0,0,0,0,0,0,0,0,0,0,0,0
0,0,0,0,0,0,0,0,0,0,0,0,0,0,0,0,0,0,0,0,0,0
0,0,0,0,0,0,0,0,0,0,0,0,0,0,0,0,0,0,0,0,0,0
0,0,0,0,0,0,0,0,0,0,0,0,0,0,0,0,0,0,0,0,0,0
0,0,0,0,0,0,0,0,0,0,0,0,0,0,0,0,0,0,0,0,0,0
0,0,0,0,0,0,0,0,0,0,0,0,0,0,0,0,0,0,0,0,0,0
0,0,0,0,0,0,0,0,0,0,0,0,0,0,0,0,8,0,0,0,0,0
0,0,0,0,0,0,0,0,0,0,0,0,0,0,0,0,0,0,0,0,0,0
0,0,0,0,0,0,0,0,0,0,0,0,0,0,0,0,0,0,0,0,0,0
0,0,0,0,0,0,0,0,0,0,0,0,0,0,0,0,0,0,0,0,0,0
0,0,0,0,0,0,0,0,0,0,0,0,0,0,0,0,0,0,0,0,0,0
:endlayer
layer: 12
0,0,0,0,0,0,0,0,0,0,0,0,0,0,0,0,0,0,0,0,0,0
0,0,0,0,0,0,0,0,0,0,0,0,0,0,0,0,0,0,0,0,0,0
0,0,0,0,0,0,0,0,0,0,0,0,0,0,0,0,0,0,0,0,0,0
0,0,0,0,0,0,0,0,0,0,0,0,0,0,0,0,0,0,0,0,0,0
0,0,0,0,0,0,0,0,0,0,0,0,0,0,0,0,0,0,0,0,0,0
0,0,0,0,0,0,0,0,0,0,26,0,0,0,0,0,0,0,0,0,0,0
0,0,0,0,0,0,0,0,0,0,0,0,0,0,0,0,0,0,0,0,0,0
0,0,0,0,0,0,0,0,0,0,0,0,0,0,0,0,0,0,0,0,0,0
0,0,0,0,0,0,0,0,0,0,0,0,0,0,0,0,0,0,0,0,0,0
0,0,0,0,0,0,0,0,0,0,0,0,0,0,0,0,0,0,0,0,0,0
0,0,0,0,0,0,9,0,0,0,0,0,0,0,0,0,0,0,0,0,0,0
0,0,0,0,0,0,0,0,0,0,0,0,0,0,0,0,0,0,0,0,0,0
0,0,0,0,0,0,0,0,0,0,0,0,0,0,0,0,0,0,0,0,0,0
0,0,0,0,0,0,0,0,0,0,0,0,0,0,0,0,0,0,0,0,0,0
0,0,0,0,0,0,0,0,0,0,0,0,0,0,0,0,0,0,0,0,0,0
0,0,0,0,0,0,0,0,0,0,0,0,0,0,0,0,0,0,0,0,0,0
0,0,0,0,0,0,0,0,0,0,0,0,0,0,0,0,0,0,0,0,0,0
0,0,0,0,0,0,0,0,0,0,0,0,0,0,0,0,0,0,0,0,0,0
0,0,0,0,0,0,0,0,0,0,0,0,0,0,0,0,0,0,0,0,0,0
0,0,0,0,0,0,0,0,0,0,0,0,0,0,0,0,0,0,0,0,0,0
0,0,0,0,0,0,0,0,0,0,0,0,0,0,0,0,0,0,0,0,0,0
0,0,0,0,0,0,0,0,0,0,0,0,0,0,0,0,0,0,0,0,0,0
:endlayer
layer: 13
0,0,0,0,0,0,0,0,0,0,0,0,0,0,0,0,0,0,0,0,0,0
0,0,0,0,0,0,0,0,0,0,0,0,0,0,0,0,0,0,0,0,0,0
0,0,0,0,0,0,0,0,0,0,0,0,0,0,0,0,0,0,0,0,0,0
0,0,0,0,0,0,0,0,0,0,0,0,0,0,0,0,0,0,0,0,0,0
0,0,0,0,0,0,0,0,0,0,0,0,0,0,0,0,0,0,0,0,0,0
0,0,0,0,0,0,0,0,0,0,8,0,0,0,0,0,0,0,0,0,0,0
0,0,0,0,0,0,0,0,0,0,0,0,0,0,0,0,0,0,0,0,0,0
0,0,0,0,0,0,0,0,0,0,0,0,0,0,0,0,0,0,0,0,0,0
0,0,0,0,0,0,0,0,0,0,0,0,0,0,0,0,0,0,0,0,0,0
0,0,0,0,0,0,0,0,0,0,0,0,0,0,0,0,0,0,0,0,0,0
0,0,0,0,0,0,0,0,0,0,0,0,0,0,0,0,0,0,0,0,0,0
0,0,0,0,0,0,0,0,0,0,0,0,0,0,0,0,0,0,0,0,0,0
0,0,0,0,0,0,0,0,0,0,0,0,0,0,0,0,0,0,0,0,0,0
0,0,0,0,0,0,0,0,0,0,0,0,0,0,0,0,0,0,0,0,0,0
0,0,0,0,0,0,0,0,0,0,0,0,0,0,0,0,0,0,0,0,0,0
0,0,0,0,0,0,0,0,0,0,0,0,0,0,0,0,0,0,0,0,0,0
0,0,0,0,0,0,0,0,0,0,0,0,0,0,0,0,0,0,0,0,0,0
0,0,0,0,0,0,0,0,0,0,0,0,0,0,0,0,0,0,0,0,0,0
0,0,0,0,0,0,0,0,0,0,0,0,0,0,0,0,0,0,0,0,0,0
0,0,0,0,0,0,0,0,0,0,0,0,0,0,0,0,0,0,0,0,0,0
0,0,0,0,0,0,0,0,0,0,0,0,0,0,0,0,0,0,0,0,0,0
0,0,0,0,0,0,0,0,0,0,0,0,0,0,0,0,0,0,0,0,0,0
:endlayer

#### RULES ####
rule:
plugin=vanillaBlocks
number=1
data:
JSON:{blockState:{blockName:"minecraft:grass",properties:{snowy:"false"}}}
:enddata
:endrule

rule:
plugin=vanillaBlocks
number=2
data:
JSON:{blockState:{blockName:"minecraft:cobblestone"}}
:enddata
:endrule

rule:
plugin=vanillaBlocks
number=3
data:
JSON:{blockState:{blockName:"minecraft:planks",properties:{variant:"birch"}}}
:enddata
:endrule

rule:
plugin=vanillaBlocks
number=4
data:
JSON:{blockState:{blockName:"minecraft:birch_fence",properties:{east:"false",south:"false",north:"false",west:"false"}}}
:enddata
:endrule

rule:
plugin=vanillaBlocks
number=5
data:
JSON:{blockState:{blockName:"minecraft:log",properties:{variant:"birch",axis:"y"}}}
:enddata
:endrule

rule:
plugin=vanillaBlocks
number=6
data:
JSON:{blockState:{blockName:"minecraft:birch_stairs",properties:{half:"top",shape:"straight",facing:"north"}}}
:enddata
:endrule

rule:
plugin=vanillaBlocks
number=7
data:
JSON:{blockState:{blockName:"minecraft:birch_stairs",properties:{half:"bottom",shape:"straight",facing:"south"}}}
:enddata
:endrule

rule:
plugin=vanillaBlocks
number=8
data:
JSON:{blockState:{blockName:"minecraft:stone_slab",properties:{half:"bottom",variant:"cobblestone"}}}
:enddata
:endrule

rule:
plugin=vanillaBlocks
number=9
data:
JSON:{blockState:{blockName:"minecraft:torch",properties:{facing:"up"}}}
:enddata
:endrule

rule:
plugin=vanillaBlocks
number=10
data:
JSON:{blockState:{blockName:"minecraft:torch",properties:{facing:"west"}}}
:enddata
:endrule

rule:
plugin=vanillaBlocks
number=11
data:
JSON:{blockState:{blockName:"minecraft:torch",properties:{facing:"south"}}}
:enddata
:endrule

rule:
plugin=vanillaBlocks
number=12
data:
JSON:{blockState:{blockName:"minecraft:torch",properties:{facing:"north"}}}
:enddata
:endrule

rule:
plugin=vanillaBlocks
number=13
data:
JSON:{blockState:{blockName:"minecraft:torch",properties:{facing:"east"}}}
:enddata
:endrule

rule:
plugin=vanillaBlocks
number=14
data:
JSON:{blockState:{blockName:"minecraft:birch_stairs",properties:{half:"top",shape:"straight",facing:"south"}}}
:enddata
:endrule

rule:
plugin=vanillaBlocks
number=15
data:
JSON:{blockState:{blockName:"minecraft:stone_stairs",properties:{half:"bottom",shape:"straight",facing:"south"}}}
:enddata
:endrule

rule:
plugin=vanillaBlocks
number=16
data:
JSON:{blockState:{blockName:"minecraft:stone_stairs",properties:{half:"top",shape:"straight",facing:"south"}}}
:enddata
:endrule

rule:
plugin=vanillaBlocks
number=17
data:
JSON:{blockState:{blockName:"minecraft:stone_stairs",properties:{half:"top",shape:"straight",facing:"north"}}}
:enddata
:endrule

rule:
plugin=vanillaBlocks
number=18
data:
JSON:{blockState:{blockName:"minecraft:birch_stairs",properties:{half:"bottom",shape:"straight",facing:"north"}}}
:enddata
:endrule

rule:
plugin=vanillaBlocks
number=19
data:
JSON:{blockState:{blockName:"minecraft:log",properties:{variant:"birch",axis:"z"}}}
:enddata
:endrule

rule:
plugin=vanillaBlocks
number=20
data:
JSON:{blockState:{blockName:"minecraft:log",properties:{variant:"birch",axis:"x"}}}
:enddata
:endrule

rule:
plugin=vanillaBlocks
number=21
data:
JSON:{blockState:{blockName:"minecraft:wooden_slab",properties:{half:"top",variant:"birch"}}}
:enddata
:endrule

rule:
plugin=vanillaBlocks
number=22
data:
JSON:{blockState:{blockName:"minecraft:birch_stairs",properties:{half:"bottom",shape:"straight",facing:"east"}}}
:enddata
:endrule

rule:
plugin=vanillaBlocks
number=23
data:
JSON:{blockState:{blockName:"minecraft:birch_stairs",properties:{half:"top",shape:"straight",facing:"west"}}}
:enddata
:endrule

rule:
plugin=vanillaBlocks
number=24
data:
JSON:{blockState:{blockName:"minecraft:birch_stairs",properties:{half:"top",shape:"straight",facing:"east"}}}
:enddata
:endrule

rule:
plugin=vanillaBlocks
number=25
data:
JSON:{blockState:{blockName:"minecraft:birch_stairs",properties:{half:"bottom",shape:"straight",facing:"west"}}}
:enddata
:endrule

rule:
plugin=vanillaBlocks
number=26
data:
JSON:{blockState:{blockName:"minecraft:cobblestone_wall",properties:{east:"false",south:"false",north:"false",variant:"cobblestone",west:"false",up:"false"}}}
:enddata
:endrule

#### ENTITIES ####
