# Ancient Warfare Structure Template File
# Auto-generated structure template file. created on: 6/11/2023 at: 13:6:50
# Lines beginning with # denote comments

header:
version=2.11
name=SB_MarenCol_House_1H2R_2_jungle
mods=
size=21,16,16
offset=10,1,15
:endheader

#### VALIDATION ####
validation:
type=ground
structureAuthor=TheOddlySeagull
survival=true
worldGenEnabled=false
unique=false
preserveBlocks=false
preventNaturalHostileSpawns=false
selectionWeight=1
clusterValue=1
minDuplicateDistance=1
dimensionWhiteList=true
dimensionList=
biomeGroupList=
biomeWhiteList=true
biomeList=
leveling=0
fill=0
border=0
blockSwap=false
territoryName=
biomeReplacement=minecraft:
minGenerationHeight=0
maxGenerationHeight=255
:endvalidation

#### LAYERS ####
layer: 0
1,1,1,1,1,1,1,1,1,1,1,1,1,1,1,1,1,1,1,1,1
1,1,1,1,1,1,1,1,1,1,1,3,3,1,1,1,1,1,1,1,1
1,1,1,1,1,1,1,3,3,3,3,3,3,3,3,3,3,1,1,1,1
1,1,1,1,1,3,3,3,3,3,3,3,3,3,3,3,3,1,1,1,1
1,1,3,3,3,3,3,3,3,3,3,3,3,3,3,3,3,2,2,2,2
1,1,3,4,4,4,4,3,3,3,3,3,3,3,3,3,3,3,3,3,3
1,1,3,4,4,4,4,3,3,3,3,3,3,3,3,3,3,3,3,3,3
1,1,3,4,4,4,4,3,3,3,3,3,3,3,3,3,3,2,2,2,2
1,1,3,4,4,4,4,3,3,3,3,3,3,3,3,3,3,1,1,1,1
1,1,3,4,4,4,4,3,3,3,3,3,3,3,3,3,3,3,3,1,1
1,1,3,4,4,4,4,3,3,3,3,3,3,3,3,4,4,4,3,1,1
1,1,3,3,3,3,3,3,3,3,3,3,3,3,3,4,4,4,3,1,1
1,1,1,1,1,1,1,1,1,2,3,3,2,1,3,4,4,4,3,1,1
1,1,1,1,1,1,1,1,1,2,3,3,2,1,3,3,3,3,3,1,1
1,1,1,1,1,1,1,1,1,2,3,3,2,1,1,1,1,1,1,1,1
1,1,1,1,1,1,1,1,1,2,3,3,2,1,1,1,1,1,1,1,1
:endlayer
layer: 1
0,0,0,0,0,0,0,0,0,0,0,0,0,0,0,0,0,0,0,0,0
0,0,5,0,0,0,0,0,0,0,0,3,3,0,0,0,0,0,0,5,0
0,0,0,0,0,0,0,6,4,6,3,0,0,3,6,4,6,0,0,0,0
0,0,0,0,0,5,0,4,0,0,0,9,9,0,0,0,4,0,0,0,0
0,0,6,4,4,6,0,6,0,0,0,0,0,0,0,0,6,0,0,0,0
0,0,4,0,0,0,0,4,0,0,0,0,0,0,0,0,0,0,0,0,0
0,0,6,0,0,0,0,6,0,0,0,0,0,0,0,0,0,0,0,0,0
0,0,4,0,0,0,0,0,0,0,0,0,0,0,0,0,6,0,0,0,0
0,0,4,0,0,0,0,0,0,0,0,0,0,0,0,0,4,0,0,0,0
0,0,6,0,0,0,0,6,0,0,0,0,0,0,6,0,6,4,6,0,0
0,0,4,0,0,0,0,4,0,0,0,0,0,0,0,0,8,7,4,0,0
0,0,6,4,6,4,4,6,4,6,0,0,6,4,6,0,5,0,6,0,0
0,0,0,0,0,0,0,0,0,0,0,0,0,0,4,0,0,0,4,0,0
0,0,0,0,0,0,0,0,0,0,0,0,0,0,6,4,6,4,6,0,0
0,5,0,0,0,0,0,0,0,0,0,0,0,0,0,0,0,0,0,0,0
0,0,0,0,0,0,0,0,0,0,0,0,0,0,0,0,0,0,0,0,0
:endlayer
layer: 2
0,0,0,0,0,0,0,0,0,0,0,0,0,0,0,0,0,0,0,0,0
0,0,10,0,0,0,0,0,0,0,0,3,3,0,0,0,0,0,0,10,0
0,0,0,0,0,0,0,6,5,6,3,0,0,3,6,5,6,0,0,0,0
0,0,0,0,0,5,0,4,0,0,0,0,0,0,0,0,5,0,0,0,0
0,0,6,5,5,6,0,6,0,0,0,0,0,0,0,0,6,0,0,0,0
0,0,4,0,0,0,0,4,0,0,0,0,0,0,0,0,0,0,0,0,0
0,0,6,0,0,0,0,6,0,0,0,0,0,0,0,0,0,0,0,0,0
0,0,5,0,0,0,0,0,0,0,0,0,0,0,0,0,6,0,0,0,0
0,0,5,0,0,0,0,0,0,0,0,0,0,0,0,0,5,0,0,0,0
0,0,6,0,0,0,0,6,0,0,0,0,0,0,6,0,6,5,6,0,0
0,0,4,0,0,0,0,4,0,0,0,0,0,0,0,0,0,0,5,0,0
0,0,6,4,6,5,5,6,4,6,0,0,6,4,6,0,5,8,6,0,0
0,0,0,0,0,0,0,0,0,0,0,0,0,0,5,0,0,7,5,0,0
0,0,0,0,0,0,0,0,0,0,0,0,0,0,6,5,6,5,6,0,0
0,10,0,0,0,0,0,0,0,0,0,0,0,0,0,0,0,0,0,0,0
0,0,0,0,0,0,0,0,0,0,0,0,0,0,0,0,0,0,0,0,0
:endlayer
layer: 3
0,0,0,0,0,0,0,0,0,0,0,0,0,0,0,0,0,0,0,0,0
0,0,0,0,0,0,0,0,0,13,0,3,19,0,13,0,0,0,0,0,0
0,0,0,0,0,0,0,6,5,6,3,18,17,3,6,5,6,0,0,0,0
0,0,13,0,0,5,0,4,0,11,0,0,0,0,11,0,5,0,0,0,0
0,12,6,5,5,6,4,6,14,0,0,0,0,0,0,12,6,14,0,0,0
0,0,4,0,0,11,0,4,0,0,0,0,0,0,0,0,4,0,0,0,0
0,0,6,14,0,0,12,6,14,0,0,0,0,0,0,0,4,0,0,0,0
0,0,5,0,0,0,0,16,0,0,0,0,0,0,0,12,6,14,0,0,0
0,0,5,0,0,0,0,15,0,0,0,0,0,0,13,0,5,0,0,0,0
0,0,6,14,0,0,12,6,14,0,0,0,0,12,6,4,6,5,6,0,0
0,0,4,0,13,0,0,4,0,13,0,0,13,0,4,0,0,0,5,0,0
0,12,6,4,6,5,5,6,4,6,4,4,6,4,6,0,5,0,6,0,0
0,0,11,0,11,0,0,11,0,11,0,0,11,0,5,7,8,0,5,0,0
0,0,0,0,0,0,0,0,0,0,0,0,0,0,6,5,6,5,6,0,0
0,0,0,0,0,0,0,0,0,0,0,0,0,0,0,0,0,0,0,0,0
0,0,0,0,0,0,0,0,0,0,0,0,0,0,0,0,0,0,0,0,0
:endlayer
layer: 4
0,0,0,0,0,0,0,0,0,0,0,0,0,0,0,0,0,0,0,0,0
0,0,0,0,0,0,23,23,23,23,23,3,23,23,23,23,23,23,0,0,0
0,0,0,0,0,0,16,6,20,20,20,20,20,20,20,20,6,16,0,0,0
0,23,23,23,23,23,23,21,7,4,16,4,16,4,7,4,21,0,0,0,0
0,16,6,20,20,20,20,21,7,4,7,4,7,4,7,4,21,0,0,0,0
0,0,21,0,0,0,0,21,7,4,7,4,7,4,7,4,21,0,0,0,0
0,0,21,0,0,0,0,21,7,4,7,4,7,4,7,4,21,0,0,0,0
0,0,21,0,0,0,0,21,7,4,7,4,7,4,7,4,21,0,0,0,0
0,0,21,0,0,0,0,21,7,4,7,4,7,4,7,4,21,0,0,0,0
0,0,21,0,0,0,0,21,7,4,7,4,7,4,6,20,20,20,6,14,0
0,0,21,0,0,0,0,21,7,4,7,4,7,4,21,7,0,0,21,0,0
0,15,6,20,20,20,20,20,20,20,20,20,20,20,21,8,5,0,21,0,0
0,22,22,22,22,22,22,22,22,22,22,22,22,22,21,0,0,0,21,0,0
0,0,0,0,0,0,0,0,0,0,0,0,0,0,6,20,20,20,6,14,0
0,0,0,0,0,0,0,0,0,0,0,0,0,0,11,0,0,0,11,0,0
0,0,0,0,0,0,0,0,0,0,0,0,0,0,0,0,0,0,0,0,0
:endlayer
layer: 5
0,0,0,0,0,0,0,0,0,0,0,0,0,0,0,0,0,0,0,0,0
0,0,0,0,0,0,0,0,0,0,0,3,0,0,0,0,0,0,0,0,0
0,0,0,0,0,0,23,23,23,23,23,23,23,23,23,23,23,23,0,0,0
0,0,0,0,0,0,16,6,16,16,16,6,20,20,6,16,6,16,0,0,0
0,23,23,23,23,23,23,4,0,0,0,0,0,0,0,0,4,0,0,0,0
0,16,6,16,16,16,16,6,0,0,0,0,0,0,0,0,4,0,0,0,0
0,0,4,0,0,0,0,5,0,0,0,0,0,0,0,0,5,0,0,0,0
0,0,4,0,0,0,0,5,0,0,0,0,0,0,0,0,5,0,0,0,0
0,0,4,0,0,0,0,6,0,0,0,0,0,0,0,0,4,0,0,0,0
0,0,4,0,0,0,0,4,0,0,0,0,0,0,6,0,6,4,6,0,0
0,15,6,15,15,15,15,6,15,6,20,20,6,15,4,0,0,0,4,0,0
0,22,22,22,22,22,22,22,22,22,22,22,22,22,6,0,5,0,6,0,0
0,0,0,0,0,0,0,0,0,0,0,0,0,0,4,0,0,0,4,0,0
0,0,0,0,0,0,0,0,0,0,0,0,0,0,6,4,6,4,6,0,0
0,0,0,0,0,0,0,0,0,0,0,0,0,0,0,0,0,0,0,0,0
0,0,0,0,0,0,0,0,0,0,0,0,0,0,0,0,0,0,0,0,0
:endlayer
layer: 6
0,0,0,0,0,0,0,0,0,0,0,0,0,0,0,0,0,0,0,0,0
0,0,0,0,0,0,0,0,0,0,0,3,0,0,0,0,0,0,0,0,0
0,0,0,0,0,0,0,0,0,0,0,0,0,0,0,0,0,0,0,0,0
0,0,0,0,0,0,23,23,23,23,23,6,5,5,6,23,23,23,0,0,0
0,0,0,0,0,0,16,6,16,16,16,11,0,0,11,16,6,16,0,0,0
0,23,23,23,23,23,23,6,14,0,0,0,0,0,0,0,4,0,0,0,0
0,16,6,16,16,16,16,0,0,0,0,0,0,0,0,0,5,0,0,0,0
0,0,4,0,0,0,0,0,0,0,0,0,0,0,0,0,5,0,0,0,0
0,0,4,0,0,0,0,6,14,0,0,0,0,0,13,0,4,0,0,0,0
0,15,6,15,15,15,15,6,15,13,0,0,13,15,6,0,6,4,6,0,0
0,22,22,22,22,22,22,22,22,6,5,5,6,22,4,0,0,0,5,0,0
0,0,0,0,0,0,0,0,0,0,0,0,0,0,6,0,5,0,6,0,0
0,0,0,0,0,0,0,0,0,0,0,0,0,0,5,0,0,0,5,0,0
0,0,0,0,0,0,0,0,0,0,0,0,0,0,6,5,6,5,6,0,0
0,0,0,0,0,0,0,0,0,0,0,0,0,0,0,0,0,0,0,0,0
0,0,0,0,0,0,0,0,0,0,0,0,0,0,0,0,0,0,0,0,0
:endlayer
layer: 7
0,0,0,0,0,0,0,0,0,0,0,0,0,0,0,0,0,0,0,0,0
0,0,0,0,0,0,0,0,0,0,0,3,0,0,0,0,0,0,0,0,0
0,0,0,0,0,0,0,0,0,0,27,26,0,0,25,24,0,0,0,0,0
0,0,0,0,0,0,0,0,0,0,27,6,5,5,6,24,0,0,0,0,0
0,0,0,0,0,0,23,23,23,23,23,26,0,0,25,23,23,23,0,0,0
0,0,0,0,0,0,16,6,16,16,16,26,0,0,25,16,6,16,0,0,0
0,23,23,23,23,23,23,16,0,0,0,0,0,0,0,0,4,0,0,0,0
0,16,21,16,16,16,16,15,0,0,0,0,0,0,0,0,4,0,0,0,0
0,15,21,15,15,15,15,6,15,15,0,0,15,15,15,15,6,15,0,0,0
0,22,22,22,22,22,22,22,27,26,0,0,25,22,6,4,6,4,6,0,0
0,0,0,0,0,0,0,0,27,6,5,5,6,24,4,0,11,0,5,0,0
0,0,0,0,0,0,0,0,27,26,0,0,25,24,6,14,5,12,6,0,0
0,0,0,0,0,0,0,0,0,0,0,0,0,0,5,0,13,0,5,0,0
0,0,0,0,0,0,0,0,0,0,0,0,0,0,6,5,6,5,6,0,0
0,0,0,0,0,0,0,0,0,0,0,0,0,0,0,0,0,0,0,0,0
0,0,0,0,0,0,0,0,0,0,0,0,0,0,0,0,0,0,0,0,0
:endlayer
layer: 8
0,0,0,0,0,0,0,0,0,0,0,0,0,0,0,0,0,0,0,0,0
0,0,0,0,0,0,0,0,0,0,0,3,0,0,0,0,0,0,0,0,0
0,0,0,0,0,0,0,0,0,0,0,27,26,25,24,0,0,0,0,0,0
0,0,0,0,0,0,0,0,0,0,0,27,20,20,24,0,0,0,0,0,0
0,0,0,0,0,0,0,0,0,0,0,27,26,25,24,0,0,0,0,0,0
0,0,0,0,0,0,23,23,23,23,23,23,26,25,24,23,23,23,0,0,0
0,0,0,0,0,0,16,21,16,16,16,16,26,16,16,16,21,16,0,0,0
0,23,23,23,23,23,4,21,15,15,26,15,15,15,15,15,21,15,0,0,0
0,22,22,22,22,22,22,22,22,27,26,25,22,22,22,22,22,22,0,0,0
0,0,0,0,0,0,0,0,0,27,26,25,24,0,6,20,20,20,6,0,0
0,0,0,0,0,0,0,0,0,27,20,20,24,0,21,0,0,0,21,0,0
0,0,0,0,0,0,0,0,0,27,26,25,24,0,21,0,5,0,21,0,0
0,0,0,0,0,0,0,0,0,0,0,0,0,0,21,0,0,0,21,0,0
0,0,0,0,0,0,0,0,0,0,0,0,0,0,6,20,20,20,6,0,0
0,0,0,0,0,0,0,0,0,0,0,0,0,0,0,0,0,0,0,0,0
0,0,0,0,0,0,0,0,0,0,0,0,0,0,0,0,0,0,0,0,0
:endlayer
layer: 9
0,0,0,0,0,0,0,0,0,0,0,0,0,0,0,0,0,0,0,0,0
0,0,0,0,0,0,0,0,0,0,0,3,0,0,0,0,0,0,0,0,0
0,0,0,0,0,0,0,0,0,0,0,0,27,24,0,0,0,0,0,0,0
0,0,0,0,0,0,0,0,0,0,0,0,27,24,0,0,0,0,0,0,0
0,0,0,0,0,0,0,0,0,0,0,0,27,24,0,0,0,0,0,0,0
0,0,0,0,0,0,0,0,0,0,0,0,27,24,0,0,0,0,0,0,0
0,0,0,0,0,0,23,23,23,23,23,23,27,24,23,23,23,23,0,0,0
0,0,0,0,0,0,22,22,22,22,27,22,22,22,22,22,22,22,0,0,0
0,0,0,0,0,0,0,0,0,0,27,24,0,0,5,0,5,0,5,0,0
0,0,0,0,0,0,0,0,0,0,27,24,0,5,6,5,6,5,6,5,0
0,0,0,0,0,0,0,0,0,0,27,24,0,0,5,0,0,0,5,0,0
0,0,0,0,0,0,0,0,0,0,27,24,0,5,6,0,5,0,6,5,0
0,0,0,0,0,0,0,0,0,0,0,0,0,0,5,0,0,0,5,0,0
0,0,0,0,0,0,0,0,0,0,0,0,0,5,6,5,6,5,6,5,0
0,0,0,0,0,0,0,0,0,0,0,0,0,0,5,0,5,0,5,0,0
0,0,0,0,0,0,0,0,0,0,0,0,0,0,0,0,0,0,0,0,0
:endlayer
layer: 10
0,0,0,0,0,0,0,0,0,0,0,0,0,0,0,0,0,0,0,0,0
0,0,0,0,0,0,0,0,0,0,0,28,0,0,0,0,0,0,0,0,0
0,0,0,0,0,0,0,0,0,0,0,0,0,0,0,0,0,0,0,0,0
0,0,0,0,0,0,0,0,0,0,0,0,0,0,0,0,0,0,0,0,0
0,0,0,0,0,0,0,0,0,0,0,0,0,0,0,0,0,0,0,0,0
0,0,0,0,0,0,0,0,0,0,0,0,0,0,0,0,0,0,0,0,0
0,0,0,0,0,0,0,0,0,0,0,0,0,0,0,0,0,0,0,0,0
0,0,0,0,0,0,0,0,0,0,0,0,0,0,0,0,0,0,0,0,0
0,0,0,0,0,0,0,0,0,0,0,0,0,23,23,23,23,23,23,24,0
0,0,0,0,0,0,0,0,0,0,0,0,0,27,6,20,20,20,6,24,0
0,0,0,0,0,0,0,0,0,0,0,0,0,27,21,0,0,0,21,24,0
0,0,0,0,0,0,0,0,0,0,0,0,0,27,21,0,5,0,21,24,0
0,0,0,0,0,0,0,0,0,0,0,0,0,27,21,0,0,0,21,24,0
0,0,0,0,0,0,0,0,0,0,0,0,0,27,6,20,20,20,6,24,0
0,0,0,0,0,0,0,0,0,0,0,0,0,22,22,22,22,22,22,22,0
0,0,0,0,0,0,0,0,0,0,0,0,0,0,0,0,0,0,0,0,0
:endlayer
layer: 11
0,0,0,0,0,0,0,0,0,0,0,0,0,0,0,0,0,0,0,0,0
0,0,0,0,0,0,0,0,0,0,0,9,0,0,0,0,0,0,0,0,0
0,0,0,0,0,0,0,0,0,0,0,0,0,0,0,0,0,0,0,0,0
0,0,0,0,0,0,0,0,0,0,0,0,0,0,0,0,0,0,0,0,0
0,0,0,0,0,0,0,0,0,0,0,0,0,0,0,0,0,0,0,0,0
0,0,0,0,0,0,0,0,0,0,0,0,0,0,0,0,0,0,0,0,0
0,0,0,0,0,0,0,0,0,0,0,0,0,0,0,0,0,0,0,0,0
0,0,0,0,0,0,0,0,0,0,0,0,0,0,0,0,0,0,0,0,0
0,0,0,0,0,0,0,0,0,0,0,0,0,0,0,0,0,0,0,0,0
0,0,0,0,0,0,0,0,0,0,0,0,0,0,27,23,23,23,23,0,0
0,0,0,0,0,0,0,0,0,0,0,0,0,0,27,26,16,16,24,0,0
0,0,0,0,0,0,0,0,0,0,0,0,0,0,27,26,5,25,24,0,0
0,0,0,0,0,0,0,0,0,0,0,0,0,0,27,15,15,25,24,0,0
0,0,0,0,0,0,0,0,0,0,0,0,0,0,22,22,22,22,24,0,0
0,0,0,0,0,0,0,0,0,0,0,0,0,0,0,0,0,0,0,0,0
0,0,0,0,0,0,0,0,0,0,0,0,0,0,0,0,0,0,0,0,0
:endlayer
layer: 12
0,0,0,0,0,0,0,0,0,0,0,0,0,0,0,0,0,0,0,0,0
0,0,0,0,0,0,0,0,0,0,0,0,0,0,0,0,0,0,0,0,0
0,0,0,0,0,0,0,0,0,0,0,0,0,0,0,0,0,0,0,0,0
0,0,0,0,0,0,0,0,0,0,0,0,0,0,0,0,0,0,0,0,0
0,0,0,0,0,0,0,0,0,0,0,0,0,0,0,0,0,0,0,0,0
0,0,0,0,0,0,0,0,0,0,0,0,0,0,0,0,0,0,0,0,0
0,0,0,0,0,0,0,0,0,0,0,0,0,0,0,0,0,0,0,0,0
0,0,0,0,0,0,0,0,0,0,0,0,0,0,0,0,0,0,0,0,0
0,0,0,0,0,0,0,0,0,0,0,0,0,0,0,0,0,0,0,0,0
0,0,0,0,0,0,0,0,0,0,0,0,0,0,0,0,0,0,0,0,0
0,0,0,0,0,0,0,0,0,0,0,0,0,0,0,23,23,24,0,0,0
0,0,0,0,0,0,0,0,0,0,0,0,0,0,0,27,4,24,0,0,0
0,0,0,0,0,0,0,0,0,0,0,0,0,0,0,27,22,22,0,0,0
0,0,0,0,0,0,0,0,0,0,0,0,0,0,0,0,0,0,0,0,0
0,0,0,0,0,0,0,0,0,0,0,0,0,0,0,0,0,0,0,0,0
0,0,0,0,0,0,0,0,0,0,0,0,0,0,0,0,0,0,0,0,0
:endlayer
layer: 13
0,0,0,0,0,0,0,0,0,0,0,0,0,0,0,0,0,0,0,0,0
0,0,0,0,0,0,0,0,0,0,0,0,0,0,0,0,0,0,0,0,0
0,0,0,0,0,0,0,0,0,0,0,0,0,0,0,0,0,0,0,0,0
0,0,0,0,0,0,0,0,0,0,0,0,0,0,0,0,0,0,0,0,0
0,0,0,0,0,0,0,0,0,0,0,0,0,0,0,0,0,0,0,0,0
0,0,0,0,0,0,0,0,0,0,0,0,0,0,0,0,0,0,0,0,0
0,0,0,0,0,0,0,0,0,0,0,0,0,0,0,0,0,0,0,0,0
0,0,0,0,0,0,0,0,0,0,0,0,0,0,0,0,0,0,0,0,0
0,0,0,0,0,0,0,0,0,0,0,0,0,0,0,0,0,0,0,0,0
0,0,0,0,0,0,0,0,0,0,0,0,0,0,0,0,0,0,0,0,0
0,0,0,0,0,0,0,0,0,0,0,0,0,0,0,0,0,0,0,0,0
0,0,0,0,0,0,0,0,0,0,0,0,0,0,0,0,5,0,0,0,0
0,0,0,0,0,0,0,0,0,0,0,0,0,0,0,0,0,0,0,0,0
0,0,0,0,0,0,0,0,0,0,0,0,0,0,0,0,0,0,0,0,0
0,0,0,0,0,0,0,0,0,0,0,0,0,0,0,0,0,0,0,0,0
0,0,0,0,0,0,0,0,0,0,0,0,0,0,0,0,0,0,0,0,0
:endlayer
layer: 14
0,0,0,0,0,0,0,0,0,0,0,0,0,0,0,0,0,0,0,0,0
0,0,0,0,0,0,0,0,0,0,0,0,0,0,0,0,0,0,0,0,0
0,0,0,0,0,0,0,0,0,0,0,0,0,0,0,0,0,0,0,0,0
0,0,0,0,0,0,0,0,0,0,0,0,0,0,0,0,0,0,0,0,0
0,0,0,0,0,0,0,0,0,0,0,0,0,0,0,0,0,0,0,0,0
0,0,0,0,0,0,0,0,0,0,0,0,0,0,0,0,0,0,0,0,0
0,0,0,0,0,0,0,0,0,0,0,0,0,0,0,0,0,0,0,0,0
0,0,0,0,0,0,0,0,0,0,0,0,0,0,0,0,0,0,0,0,0
0,0,0,0,0,0,0,0,0,0,0,0,0,0,0,0,0,0,0,0,0
0,0,0,0,0,0,0,0,0,0,0,0,0,0,0,0,0,0,0,0,0
0,0,0,0,0,0,0,0,0,0,0,0,0,0,0,0,0,0,0,0,0
0,0,0,0,0,0,0,0,0,0,0,0,0,0,0,0,5,0,0,0,0
0,0,0,0,0,0,0,0,0,0,0,0,0,0,0,0,0,0,0,0,0
0,0,0,0,0,0,0,0,0,0,0,0,0,0,0,0,0,0,0,0,0
0,0,0,0,0,0,0,0,0,0,0,0,0,0,0,0,0,0,0,0,0
0,0,0,0,0,0,0,0,0,0,0,0,0,0,0,0,0,0,0,0,0
:endlayer
layer: 15
0,0,0,0,0,0,0,0,0,0,0,0,0,0,0,0,0,0,0,0,0
0,0,0,0,0,0,0,0,0,0,0,0,0,0,0,0,0,0,0,0,0
0,0,0,0,0,0,0,0,0,0,0,0,0,0,0,0,0,0,0,0,0
0,0,0,0,0,0,0,0,0,0,0,0,0,0,0,0,0,0,0,0,0
0,0,0,0,0,0,0,0,0,0,0,0,0,0,0,0,0,0,0,0,0
0,0,0,0,0,0,0,0,0,0,0,0,0,0,0,0,0,0,0,0,0
0,0,0,0,0,0,0,0,0,0,0,0,0,0,0,0,0,0,0,0,0
0,0,0,0,0,0,0,0,0,0,0,0,0,0,0,0,0,0,0,0,0
0,0,0,0,0,0,0,0,0,0,0,0,0,0,0,0,0,0,0,0,0
0,0,0,0,0,0,0,0,0,0,0,0,0,0,0,0,0,0,0,0,0
0,0,0,0,0,0,0,0,0,0,0,0,0,0,0,0,0,0,0,0,0
0,0,0,0,0,0,0,0,0,0,0,0,0,0,0,0,10,0,0,0,0
0,0,0,0,0,0,0,0,0,0,0,0,0,0,0,0,0,0,0,0,0
0,0,0,0,0,0,0,0,0,0,0,0,0,0,0,0,0,0,0,0,0
0,0,0,0,0,0,0,0,0,0,0,0,0,0,0,0,0,0,0,0,0
0,0,0,0,0,0,0,0,0,0,0,0,0,0,0,0,0,0,0,0,0
:endlayer

#### RULES ####
rule:
plugin=vanillaBlocks
number=1
data:
JSON:{blockState:{blockName:"minecraft:grass",properties:{snowy:"false"}}}
:enddata
:endrule

rule:
plugin=vanillaBlocks
number=2
data:
JSON:{blockState:{blockName:"minecraft:stonebrick",properties:{variant:"stonebrick"}}}
:enddata
:endrule

rule:
plugin=vanillaBlocks
number=3
data:
JSON:{blockState:{blockName:"minecraft:cobblestone"}}
:enddata
:endrule

rule:
plugin=vanillaBlocks
number=4
data:
JSON:{blockState:{blockName:"minecraft:planks",properties:{variant:"jungle"}}}
:enddata
:endrule

rule:
plugin=vanillaBlocks
number=5
data:
JSON:{blockState:{blockName:"minecraft:jungle_fence",properties:{east:"false",south:"false",north:"false",west:"false"}}}
:enddata
:endrule

rule:
plugin=vanillaBlocks
number=6
data:
JSON:{blockState:{blockName:"minecraft:log",properties:{variant:"jungle",axis:"y"}}}
:enddata
:endrule

rule:
plugin=vanillaBlocks
number=7
data:
JSON:{blockState:{blockName:"minecraft:wooden_slab",properties:{half:"top",variant:"jungle"}}}
:enddata
:endrule

rule:
plugin=vanillaBlocks
number=8
data:
JSON:{blockState:{blockName:"minecraft:wooden_slab",properties:{half:"bottom",variant:"jungle"}}}
:enddata
:endrule

rule:
plugin=vanillaBlocks
number=9
data:
JSON:{blockState:{blockName:"minecraft:stone_slab",properties:{half:"bottom",variant:"cobblestone"}}}
:enddata
:endrule

rule:
plugin=vanillaBlocks
number=10
data:
JSON:{blockState:{blockName:"minecraft:torch",properties:{facing:"up"}}}
:enddata
:endrule

rule:
plugin=vanillaBlocks
number=11
data:
JSON:{blockState:{blockName:"minecraft:torch",properties:{facing:"south"}}}
:enddata
:endrule

rule:
plugin=vanillaBlocks
number=12
data:
JSON:{blockState:{blockName:"minecraft:torch",properties:{facing:"west"}}}
:enddata
:endrule

rule:
plugin=vanillaBlocks
number=13
data:
JSON:{blockState:{blockName:"minecraft:torch",properties:{facing:"north"}}}
:enddata
:endrule

rule:
plugin=vanillaBlocks
number=14
data:
JSON:{blockState:{blockName:"minecraft:torch",properties:{facing:"east"}}}
:enddata
:endrule

rule:
plugin=vanillaBlocks
number=15
data:
JSON:{blockState:{blockName:"minecraft:jungle_stairs",properties:{half:"top",shape:"straight",facing:"south"}}}
:enddata
:endrule

rule:
plugin=vanillaBlocks
number=16
data:
JSON:{blockState:{blockName:"minecraft:jungle_stairs",properties:{half:"top",shape:"straight",facing:"north"}}}
:enddata
:endrule

rule:
plugin=vanillaBlocks
number=17
data:
JSON:{blockState:{blockName:"minecraft:stone_stairs",properties:{half:"top",shape:"straight",facing:"east"}}}
:enddata
:endrule

rule:
plugin=vanillaBlocks
number=18
data:
JSON:{blockState:{blockName:"minecraft:stone_stairs",properties:{half:"top",shape:"straight",facing:"west"}}}
:enddata
:endrule

rule:
plugin=vanillaBlocks
number=19
data:
JSON:{blockState:{blockName:"minecraft:stone_stairs",properties:{half:"bottom",shape:"straight",facing:"west"}}}
:enddata
:endrule

rule:
plugin=vanillaBlocks
number=20
data:
JSON:{blockState:{blockName:"minecraft:log",properties:{variant:"jungle",axis:"x"}}}
:enddata
:endrule

rule:
plugin=vanillaBlocks
number=21
data:
JSON:{blockState:{blockName:"minecraft:log",properties:{variant:"jungle",axis:"z"}}}
:enddata
:endrule

rule:
plugin=vanillaBlocks
number=22
data:
JSON:{blockState:{blockName:"minecraft:jungle_stairs",properties:{half:"bottom",shape:"straight",facing:"north"}}}
:enddata
:endrule

rule:
plugin=vanillaBlocks
number=23
data:
JSON:{blockState:{blockName:"minecraft:jungle_stairs",properties:{half:"bottom",shape:"straight",facing:"south"}}}
:enddata
:endrule

rule:
plugin=vanillaBlocks
number=24
data:
JSON:{blockState:{blockName:"minecraft:jungle_stairs",properties:{half:"bottom",shape:"straight",facing:"west"}}}
:enddata
:endrule

rule:
plugin=vanillaBlocks
number=25
data:
JSON:{blockState:{blockName:"minecraft:jungle_stairs",properties:{half:"top",shape:"straight",facing:"east"}}}
:enddata
:endrule

rule:
plugin=vanillaBlocks
number=26
data:
JSON:{blockState:{blockName:"minecraft:jungle_stairs",properties:{half:"top",shape:"straight",facing:"west"}}}
:enddata
:endrule

rule:
plugin=vanillaBlocks
number=27
data:
JSON:{blockState:{blockName:"minecraft:jungle_stairs",properties:{half:"bottom",shape:"straight",facing:"east"}}}
:enddata
:endrule

rule:
plugin=vanillaBlocks
number=28
data:
JSON:{blockState:{blockName:"minecraft:cobblestone_wall",properties:{east:"false",south:"false",north:"false",variant:"cobblestone",west:"false",up:"false"}}}
:enddata
:endrule

#### ENTITIES ####
