# Ancient Warfare Structure Template File
# Auto-generated structure template file. created on: 1/9/2024 at: 11:23:52
# Lines beginning with # denote comments

header:
version=2.11
name=SB_DarokCol_FarmClusterMill_1H2R_1
mods=
size=36,22,41
offset=14,1,40
:endheader

#### VALIDATION ####
validation:
type=ground
structureAuthor=TheOddlySeagull
survival=true
worldGenEnabled=false
unique=false
preserveBlocks=false
preventNaturalHostileSpawns=true
selectionWeight=1
clusterValue=1
minDuplicateDistance=1
dimensionWhiteList=true
dimensionList=
biomeGroupList=
biomeWhiteList=true
biomeList=
leveling=10
fill=10
border=5
blockSwap=false
territoryName=
biomeReplacement=minecraft:
minGenerationHeight=0
maxGenerationHeight=255
:endvalidation

#### LAYERS ####
layer: 0
1,1,1,1,1,1,1,1,1,1,1,1,1,1,1,1,1,1,1,1,1,1,1,1,1,1,1,1,1,1,1,1,1,1,1,1
1,1,1,1,1,1,1,1,1,1,1,1,1,1,1,1,1,1,1,1,1,1,1,1,1,1,1,1,1,1,1,1,1,1,1,1
1,1,1,1,1,1,1,1,1,1,1,1,1,1,1,1,1,2,1,1,1,2,1,1,1,1,1,1,1,1,1,1,1,1,1,1
1,1,1,2,3,3,3,3,3,3,3,2,1,1,1,1,1,1,1,1,1,1,1,1,1,1,1,1,1,1,1,1,1,1,1,1
1,1,1,4,5,5,5,5,5,5,5,4,1,1,1,1,1,1,1,1,1,1,1,1,1,1,1,1,1,1,1,1,1,1,1,1
1,1,1,4,5,5,5,5,5,5,5,4,1,1,1,1,1,1,1,1,1,1,1,1,1,1,1,2,3,3,3,3,2,1,1,1
1,1,1,4,5,5,5,5,5,5,5,4,1,6,1,1,1,2,1,1,1,2,1,1,1,1,1,4,5,5,5,5,4,1,1,1
1,1,1,4,5,5,5,5,5,5,5,4,6,6,6,1,1,1,1,1,1,1,1,1,1,1,1,4,5,5,5,5,4,1,1,1
1,1,1,4,5,5,5,5,5,5,5,4,6,6,7,6,1,1,1,1,8,1,1,1,1,1,1,4,5,5,5,5,4,1,1,1
1,1,1,4,5,5,5,5,5,5,5,4,6,6,7,6,1,1,6,8,8,7,1,7,1,1,1,4,3,3,3,3,4,1,1,1
1,1,1,4,5,5,5,5,5,5,5,4,1,6,6,6,7,6,6,6,8,8,7,7,6,1,1,4,5,5,5,5,4,1,1,1
1,1,1,2,3,3,3,3,3,3,3,2,1,7,6,6,6,6,7,7,6,7,6,7,6,7,6,4,5,5,5,5,4,1,1,1
1,1,1,1,1,1,1,1,1,1,1,1,1,1,6,6,6,6,8,6,1,1,7,6,6,7,8,4,5,5,5,5,4,1,1,1
1,1,1,1,1,1,1,1,1,1,1,1,1,1,6,6,6,6,6,1,1,1,1,6,6,6,8,4,5,5,5,5,4,1,1,1
1,1,1,1,1,1,1,1,1,1,1,1,1,1,1,7,8,7,1,1,1,1,1,2,3,3,3,2,5,5,5,5,4,1,1,1
1,1,1,1,1,1,1,1,1,1,1,1,1,1,1,6,8,8,1,1,1,1,1,4,5,5,5,4,5,5,5,5,4,1,1,1
1,1,1,1,1,1,1,1,1,9,1,1,1,1,1,7,6,7,8,1,1,1,1,4,5,5,5,4,5,5,5,5,4,1,1,1
1,1,1,1,1,1,1,1,9,10,9,1,1,1,7,6,8,6,1,1,1,1,1,4,5,5,5,4,5,5,5,5,4,1,1,1
1,1,1,1,1,1,1,1,9,10,9,1,1,8,6,6,7,6,1,1,1,1,1,4,5,5,5,4,5,5,5,5,4,1,1,1
1,1,1,1,1,1,1,1,9,10,9,1,6,6,6,6,6,1,1,1,1,1,1,2,3,3,3,3,3,3,3,3,2,1,1,1
1,1,1,1,1,1,1,1,1,9,1,1,8,7,7,6,1,1,1,1,1,1,1,1,1,1,1,1,1,1,1,1,1,1,1,1
1,1,1,1,1,1,1,1,1,1,1,6,6,6,11,11,11,11,11,1,1,1,1,1,1,1,1,1,1,1,1,1,1,1,1,1
1,1,1,1,1,1,1,1,1,1,6,6,6,6,11,11,11,11,11,1,1,1,1,1,1,1,1,1,1,1,1,1,1,1,1,1
1,1,1,1,2,3,3,2,1,1,1,6,6,6,11,11,11,11,11,1,1,1,1,1,1,1,1,1,1,1,1,1,1,1,1,1
1,1,1,1,4,8,8,4,1,1,7,6,7,1,11,11,11,11,11,1,1,1,1,1,1,1,1,1,1,1,1,1,1,1,1,1
1,1,1,1,4,7,6,4,7,6,8,6,6,1,11,11,11,11,11,1,1,1,1,1,1,1,1,1,1,1,1,1,1,1,1,1
1,1,1,1,4,6,7,4,6,8,6,7,7,6,1,1,1,1,1,1,1,1,1,1,1,1,1,1,1,1,1,1,1,1,1,1
1,1,1,1,4,7,6,4,8,1,7,6,6,6,1,1,1,1,1,1,1,1,1,1,1,1,1,1,1,1,1,1,1,1,1,1
1,1,1,1,2,3,3,2,1,1,1,6,6,8,8,1,1,1,1,1,2,3,3,3,3,3,3,3,3,3,3,3,3,2,1,1
1,1,1,1,4,6,7,4,1,1,1,7,7,8,6,1,1,8,1,1,4,6,6,6,7,7,7,6,7,6,6,7,6,4,1,1
1,1,1,1,4,7,6,4,1,6,8,6,6,8,6,6,8,6,7,1,4,6,8,6,6,7,6,8,7,8,7,6,8,4,1,1
1,1,1,1,4,7,6,4,6,6,6,6,6,7,6,8,7,7,8,7,4,6,7,6,7,7,6,7,6,6,7,6,7,4,1,1
1,1,1,1,4,7,6,4,1,6,1,1,1,7,8,7,6,7,6,7,4,8,8,7,6,6,8,8,8,8,6,8,7,4,1,1
1,1,1,1,2,3,3,2,1,1,1,6,1,8,6,7,1,8,6,8,4,6,7,8,6,8,6,8,7,6,8,6,6,4,1,1
1,1,1,1,4,6,6,4,1,8,8,6,6,8,8,7,6,1,1,7,4,7,8,7,6,7,7,7,7,8,8,8,7,4,1,1
1,1,1,1,4,7,7,4,8,6,6,7,1,8,6,6,1,1,1,1,4,8,7,6,6,6,6,8,6,7,7,7,7,4,1,1
1,1,1,1,4,8,8,4,1,8,1,1,8,6,7,1,1,1,1,1,2,3,3,3,3,3,3,3,3,3,3,3,3,2,1,1
1,1,1,1,4,7,6,4,6,8,6,6,6,8,8,7,1,1,1,1,1,1,1,1,1,1,1,1,1,1,1,1,1,1,1,1
1,1,1,1,2,3,3,2,1,7,1,1,6,6,7,1,1,1,1,1,1,1,1,1,1,1,1,1,1,1,1,1,1,1,1,1
1,1,1,1,1,1,1,1,1,1,1,1,7,6,6,1,1,1,1,1,1,1,1,1,1,1,1,1,1,1,1,1,1,1,1,1
1,1,1,1,1,1,1,1,1,1,1,6,7,6,6,1,1,1,1,1,1,1,1,1,1,1,1,1,1,1,1,1,1,1,1,1
:endlayer
layer: 1
0,0,0,0,0,0,12,0,0,0,0,0,0,0,0,0,0,0,0,0,0,0,0,0,0,0,0,0,0,0,0,0,0,0,0,0
0,0,0,0,0,0,0,0,0,0,0,0,0,0,13,13,13,13,13,13,13,13,0,0,0,0,0,0,12,0,0,0,0,0,0,0
0,0,0,0,0,0,0,0,0,0,0,13,13,13,13,0,0,2,0,0,0,2,13,13,13,0,0,0,0,0,0,0,0,0,0,0
0,0,0,2,14,14,14,14,14,14,14,2,0,0,0,0,0,0,0,0,0,0,0,0,13,13,0,0,0,0,0,0,0,0,12,0
0,0,0,14,0,0,0,0,0,0,0,14,0,0,0,0,0,0,0,13,0,0,0,0,0,13,0,0,0,0,0,0,0,0,0,0
0,0,0,14,0,0,0,0,0,0,0,14,0,0,0,0,0,0,0,0,0,0,0,0,0,13,13,2,14,14,14,14,2,0,0,0
0,0,0,14,0,0,15,15,15,0,0,14,0,0,0,0,0,2,0,0,0,2,0,0,0,0,0,14,0,0,0,0,14,0,0,0
0,0,0,14,0,0,15,16,15,0,0,17,0,0,0,0,0,0,0,0,0,0,0,0,0,0,0,14,0,0,0,0,14,0,0,0
0,0,0,14,18,0,15,15,15,0,0,14,0,0,0,0,0,0,0,0,0,0,0,0,0,0,0,14,0,0,0,0,14,0,0,0
0,0,0,14,19,0,0,0,0,0,0,14,0,0,0,0,0,0,0,0,0,0,0,0,0,0,0,2,14,14,2,0,2,0,0,0
0,0,0,14,0,0,0,0,0,0,0,14,0,0,0,0,0,0,0,0,0,0,0,0,0,0,0,14,0,0,0,0,14,0,0,0
12,0,13,2,14,14,14,14,14,14,14,2,0,0,0,0,0,0,0,0,0,0,0,0,0,0,0,20,0,0,0,0,21,0,0,0
0,0,13,0,0,0,0,0,0,0,0,0,0,0,0,0,0,0,0,0,0,0,0,0,0,0,0,22,0,0,0,0,14,0,0,0
0,0,13,0,0,0,0,0,0,0,0,0,0,0,0,0,0,0,0,0,0,0,0,0,0,0,0,14,0,0,0,0,2,0,0,0
0,13,13,0,0,0,0,0,0,0,0,0,0,0,0,0,0,0,13,0,0,0,0,2,14,14,14,2,0,0,0,0,14,0,0,0
0,13,0,0,0,0,0,0,0,0,0,0,0,0,0,0,0,0,0,0,0,0,0,14,0,0,0,0,0,0,0,0,14,0,0,0
0,13,0,0,0,0,0,0,23,10,23,0,0,0,0,0,0,0,0,0,0,0,0,14,0,0,0,2,0,0,0,0,14,0,0,0
0,13,0,0,0,0,0,0,10,0,10,0,0,0,0,0,0,0,0,0,0,0,0,14,0,0,0,14,0,0,0,0,2,0,0,0
0,13,0,13,0,0,0,24,10,0,10,25,0,0,0,0,0,0,0,0,0,0,0,14,0,0,0,14,0,0,0,0,14,0,0,0
0,13,0,0,0,0,0,0,10,0,10,0,0,0,0,0,0,0,0,0,0,0,0,2,14,14,14,2,14,14,14,14,2,0,0,0
0,13,13,0,0,0,0,0,26,10,26,0,0,0,0,0,0,0,0,0,0,0,0,0,0,0,0,0,0,0,0,0,13,0,0,0
0,0,13,0,0,0,0,0,0,0,0,0,0,0,12,0,0,0,12,0,0,0,0,0,0,0,0,0,0,0,0,0,13,0,0,0
0,0,13,0,0,0,0,0,0,0,0,0,0,0,0,27,11,27,0,0,0,0,0,0,0,0,0,13,0,0,0,0,13,0,0,0
0,0,13,13,2,28,28,2,0,0,0,0,0,0,0,11,0,11,0,0,0,0,0,0,0,0,0,0,0,0,0,0,13,0,12,0
0,12,0,0,25,0,0,29,0,0,0,0,0,0,0,27,11,27,0,0,0,0,0,0,0,0,0,0,0,0,0,0,13,0,0,0
0,0,0,0,25,0,0,30,0,0,0,0,0,0,12,0,0,0,12,0,0,0,0,0,13,0,0,0,0,0,13,0,13,0,0,0
0,0,0,0,25,0,0,30,0,0,0,0,0,0,0,0,0,0,0,0,0,0,0,0,0,0,0,0,0,0,0,0,13,0,0,0
0,0,0,0,25,0,0,29,0,0,0,0,0,0,0,0,0,0,0,0,0,0,0,0,0,0,0,0,0,0,0,0,13,0,0,0
0,0,0,0,2,14,14,2,0,0,0,0,0,0,0,13,0,0,0,0,2,14,14,14,14,14,14,14,14,14,14,14,14,2,0,0
0,0,0,0,25,0,0,29,0,0,0,0,0,0,0,0,0,0,0,0,14,0,0,0,0,0,0,0,0,0,0,0,0,14,0,0
0,0,0,0,25,0,0,30,0,0,0,0,0,0,0,0,0,0,0,0,31,0,0,0,0,0,0,0,0,0,0,0,0,17,0,0
0,0,0,0,25,0,0,30,0,0,0,0,0,0,0,0,0,0,0,0,0,0,0,0,0,0,0,0,0,0,0,0,0,14,0,0
0,0,0,0,25,0,0,29,0,0,0,0,13,0,0,0,0,0,0,0,0,0,0,0,0,0,0,0,12,0,0,0,0,14,0,12
0,12,0,0,2,14,14,2,0,0,0,0,0,0,0,0,0,0,0,0,0,0,0,0,0,0,0,0,0,0,0,0,32,14,0,0
0,0,0,0,25,0,0,29,0,0,0,0,0,0,0,0,0,0,0,0,31,33,0,0,0,0,0,0,0,0,0,0,0,14,0,0
0,0,0,0,25,0,0,30,0,0,0,0,0,0,0,0,0,0,0,0,14,0,0,0,0,0,0,0,0,0,0,0,0,14,0,0
0,0,0,0,25,0,0,30,0,0,0,0,0,0,0,13,0,0,0,0,2,14,14,14,14,14,14,14,14,14,14,14,14,2,0,0
0,0,0,0,25,0,0,29,0,0,0,0,0,0,0,0,0,0,0,0,0,0,0,0,0,0,0,0,0,0,0,0,0,0,0,0
0,0,0,0,2,34,34,2,0,0,0,0,0,0,0,0,0,0,0,0,0,0,0,0,0,0,0,0,0,0,0,0,0,0,0,0
0,0,0,0,0,0,0,0,0,0,0,13,0,0,0,0,0,0,0,13,0,0,0,0,0,0,0,12,0,0,0,0,0,0,12,0
12,0,0,0,0,0,0,0,0,0,0,0,0,0,0,0,0,0,0,0,0,0,0,0,0,0,0,0,0,0,0,0,0,0,0,0
:endlayer
layer: 2
0,0,0,0,0,0,0,0,0,0,0,0,0,0,0,0,0,0,0,0,0,0,0,0,0,0,0,0,0,0,0,0,0,0,0,0
0,0,0,0,0,0,0,0,0,0,0,0,0,0,0,0,0,0,0,0,0,0,0,0,0,0,0,0,0,0,0,0,0,0,0,0
0,0,0,23,0,0,0,0,0,0,0,23,0,0,0,0,0,2,0,0,0,2,0,0,0,0,0,0,0,0,0,0,0,0,0,0
0,0,35,2,14,14,13,14,13,14,14,2,36,0,0,0,0,0,0,0,0,0,0,0,0,0,0,0,0,0,0,0,0,0,0,0
0,0,0,14,0,0,0,0,0,0,0,14,0,0,0,0,0,0,0,12,0,0,0,0,0,0,0,0,0,0,0,0,0,0,0,0
0,0,0,14,0,0,0,0,0,0,0,13,0,0,0,0,0,0,0,0,0,0,0,0,0,0,35,2,14,13,13,14,2,0,0,0
0,0,0,13,0,0,0,0,0,0,0,14,0,0,0,0,0,2,0,0,0,2,0,0,0,0,0,14,0,0,0,0,14,0,0,0
0,0,0,14,18,0,0,37,0,0,0,38,0,0,0,0,0,0,0,0,0,0,0,0,0,0,0,13,0,0,0,0,13,0,0,0
0,0,0,13,19,0,0,0,0,0,0,14,0,0,0,0,0,0,0,0,0,0,0,0,0,0,0,14,0,0,0,0,14,0,0,0
0,0,0,14,0,0,0,0,0,0,0,13,0,0,0,0,0,0,0,0,0,0,0,0,0,0,35,2,14,14,2,0,2,0,0,0
0,0,0,14,0,0,0,0,0,0,0,14,0,0,0,0,0,0,0,0,0,0,0,0,0,0,0,14,0,0,0,0,14,36,0,0
0,0,35,2,14,14,13,14,13,14,14,2,36,0,0,0,0,0,0,0,0,0,0,0,0,0,0,39,0,0,0,0,40,0,0,0
0,0,0,26,0,0,0,0,0,0,0,26,0,0,0,0,0,0,0,0,0,0,0,0,0,0,0,41,0,0,0,0,14,0,0,0
0,0,0,0,0,0,0,0,0,0,0,0,0,0,0,0,0,0,0,0,0,0,0,23,0,0,0,14,0,0,0,0,2,0,0,0
0,0,0,0,0,0,0,0,0,0,0,0,0,0,0,0,0,0,12,0,0,0,0,2,14,13,14,2,0,0,0,0,14,36,0,0
0,0,0,0,0,0,0,0,0,0,0,0,0,0,0,0,0,0,0,0,0,0,0,14,0,0,0,0,0,0,0,0,13,0,0,0
0,0,0,0,0,0,0,0,0,0,0,0,0,0,0,0,0,0,0,0,0,0,0,13,0,0,0,2,0,0,0,0,14,0,0,0
0,0,0,0,0,0,0,0,0,0,0,0,0,0,0,0,0,0,0,0,0,0,0,13,0,0,0,14,0,0,0,0,2,0,0,0
0,0,0,12,0,0,0,0,0,0,0,0,0,0,0,0,0,0,0,0,0,0,0,14,0,0,0,14,0,0,0,0,14,0,0,0
0,0,0,0,0,0,0,0,0,0,0,0,0,0,0,0,0,0,0,0,0,0,0,2,14,13,14,2,14,14,14,14,2,0,0,0
0,0,0,0,0,0,0,0,0,0,0,0,0,0,0,0,0,0,0,0,0,0,0,0,0,0,0,0,0,0,0,0,0,0,0,0
0,0,0,0,0,0,0,0,0,0,0,0,0,0,0,0,0,0,0,0,0,0,0,0,0,0,0,0,0,0,0,0,0,0,0,0
0,0,0,0,0,0,0,0,0,0,0,0,0,0,0,0,0,0,0,0,0,0,0,0,0,0,0,12,0,0,0,0,0,0,0,0
0,0,0,0,2,29,29,2,36,0,0,0,0,0,0,42,0,42,0,0,0,0,0,0,0,0,0,0,0,0,0,0,0,0,0,0
0,0,0,0,29,0,0,0,0,0,0,0,0,0,0,0,0,0,0,0,0,0,0,0,0,0,0,0,0,0,0,0,0,0,0,0
0,0,0,0,29,0,0,0,0,0,0,0,0,0,0,0,0,0,0,0,0,0,0,0,12,0,0,0,0,0,12,0,0,0,0,0
0,0,0,0,29,0,0,0,0,0,0,0,0,0,0,0,0,0,0,0,0,0,0,0,0,0,0,0,0,0,0,0,0,0,0,0
0,0,0,0,29,0,0,0,0,0,0,0,0,0,0,0,0,0,0,0,0,0,0,0,0,0,0,0,0,0,0,0,0,0,0,0
0,0,0,0,2,29,29,2,36,0,0,0,0,0,0,12,0,0,0,0,2,14,14,14,14,14,14,14,14,14,14,14,14,2,0,0
0,0,0,0,29,0,0,0,0,0,0,0,0,0,0,0,0,0,0,0,14,0,0,0,0,0,0,0,0,0,0,0,0,14,0,0
0,0,0,0,29,0,0,0,0,0,0,0,0,0,0,0,0,0,0,0,31,0,0,0,0,0,0,0,0,0,0,0,0,43,0,0
0,0,0,0,29,0,0,0,0,0,0,0,0,0,0,0,0,0,0,0,0,0,0,0,0,0,0,0,0,0,0,0,0,14,0,0
0,0,0,0,29,0,0,0,0,0,0,0,12,0,0,0,0,0,0,0,0,0,0,0,0,0,0,0,0,0,0,0,0,14,0,0
0,0,0,0,2,29,29,2,36,0,0,0,0,0,0,0,0,0,0,0,0,0,0,0,0,0,0,0,0,0,0,0,32,14,0,0
0,0,0,0,29,0,0,0,0,0,0,0,0,0,0,0,0,0,0,0,31,33,0,0,0,0,0,0,0,0,0,0,0,14,0,0
0,0,0,0,29,0,0,0,0,0,0,0,0,0,0,0,0,0,0,0,14,0,0,0,0,0,0,0,0,0,0,0,0,14,0,0
0,0,0,0,29,0,0,0,0,0,0,0,0,0,0,12,0,0,0,0,2,14,14,14,14,14,14,14,14,14,14,14,14,2,0,0
0,0,0,0,29,0,0,0,0,0,0,0,0,0,0,0,0,0,0,0,0,0,0,0,0,0,0,0,0,0,0,0,0,0,0,0
0,0,0,0,2,29,29,2,36,0,0,0,0,0,0,0,0,0,0,0,0,0,0,0,0,0,0,0,0,0,0,0,0,0,0,0
0,0,0,0,0,0,0,0,0,0,0,12,0,0,0,0,0,0,0,12,0,0,0,0,0,0,0,0,0,0,0,0,0,0,0,0
0,0,0,0,0,0,0,0,0,0,0,0,0,0,0,0,0,0,0,0,0,0,0,0,0,0,0,0,0,0,0,0,0,0,0,0
:endlayer
layer: 3
0,0,0,0,0,0,0,0,0,0,0,0,0,0,0,0,0,0,0,0,0,0,0,0,0,0,0,0,0,0,0,0,0,0,0,0
0,0,0,0,0,0,0,0,0,0,0,0,0,0,0,0,0,23,0,0,0,23,0,0,0,0,0,0,0,0,0,0,0,0,0,0
0,0,0,44,0,0,0,0,0,0,0,44,0,0,0,0,35,2,45,0,46,2,36,0,0,0,0,0,0,0,0,0,0,0,0,0
0,0,46,2,14,14,13,14,13,14,14,2,45,0,0,0,0,47,0,0,0,47,0,0,0,0,0,0,0,0,0,0,0,0,0,0
0,0,0,14,26,0,0,0,0,0,26,14,0,0,0,0,0,0,0,0,0,0,0,0,0,0,48,23,0,0,0,0,23,48,0,0
0,0,0,14,0,0,0,0,0,0,0,14,0,0,0,0,0,44,0,0,0,44,0,0,0,0,46,2,14,13,13,14,2,45,0,0
0,0,0,13,18,0,0,0,0,0,0,14,0,0,0,0,35,2,45,0,46,2,36,0,0,0,48,14,26,0,0,26,14,48,0,0
0,0,0,14,19,0,0,49,0,0,0,14,0,0,0,0,0,26,0,0,0,26,0,0,0,0,0,13,0,0,0,0,13,0,0,0
0,0,0,13,0,0,0,0,0,0,0,14,0,0,0,0,0,0,0,0,0,0,0,0,0,0,48,14,0,0,0,0,14,0,0,0
0,0,0,14,0,0,0,0,0,0,0,14,0,0,0,0,0,0,0,0,0,0,0,0,0,0,46,2,14,14,2,14,2,0,0,0
0,0,0,14,23,0,0,0,0,0,23,14,0,0,0,0,0,0,0,0,0,0,0,0,0,0,48,14,0,0,26,0,14,0,0,0
0,0,46,2,14,14,13,14,13,14,14,2,45,0,0,0,0,0,0,0,0,0,0,0,0,0,0,14,0,0,0,0,14,0,0,0
0,0,0,47,0,0,0,0,0,0,0,47,0,0,0,0,0,0,0,0,0,0,0,0,0,0,0,14,0,0,0,0,14,0,0,0
0,0,0,0,0,0,0,0,0,0,0,0,0,0,0,0,0,0,0,0,0,0,48,44,48,0,0,14,0,0,0,35,2,0,0,0
0,0,0,0,0,0,0,0,0,0,0,0,0,0,0,0,0,0,0,0,0,0,35,2,14,13,14,2,36,0,0,0,14,0,0,0
0,0,0,0,0,0,0,0,0,0,0,0,0,0,0,0,0,0,0,0,0,0,0,14,36,0,0,14,0,0,0,0,13,0,0,0
0,0,0,0,0,0,0,0,0,0,0,0,0,0,0,0,0,0,0,0,0,0,0,13,0,0,0,2,36,0,0,0,14,0,0,0
0,0,0,0,0,0,0,0,0,0,0,0,0,0,0,0,0,0,0,0,0,0,0,13,0,0,0,14,0,0,0,35,2,0,0,0
0,0,0,0,0,0,0,0,0,0,0,0,0,0,0,0,0,0,0,0,0,0,0,14,36,0,0,14,0,0,0,0,14,48,0,0
0,0,0,0,0,0,0,0,0,0,0,0,0,0,0,0,0,0,0,0,0,0,35,2,14,13,14,2,14,14,14,14,2,45,0,0
0,0,0,0,0,0,0,0,0,0,0,0,0,0,0,0,0,0,0,0,0,0,48,47,48,0,48,47,48,0,0,48,47,48,0,0
0,0,0,0,0,0,0,0,0,0,0,0,0,0,0,0,0,0,0,0,0,0,0,0,0,0,0,0,0,0,0,0,0,0,0,0
0,0,0,0,23,0,0,23,0,0,0,0,0,0,0,0,0,0,0,0,0,0,0,0,0,0,0,0,0,0,0,0,0,0,0,0
0,0,0,46,2,36,0,2,45,0,0,0,0,0,0,42,0,42,0,0,0,0,0,0,0,0,0,0,0,0,0,0,0,0,0,0
0,0,0,0,29,0,0,26,0,0,0,0,0,0,0,0,0,0,0,0,0,0,0,0,0,0,0,0,0,0,0,0,0,0,0,0
0,0,0,0,0,0,0,0,0,0,0,0,0,0,0,0,0,0,0,0,0,0,0,0,0,0,0,0,0,0,0,0,0,0,0,0
0,0,0,0,0,0,0,0,0,0,0,0,0,0,0,0,0,0,0,0,0,0,0,0,0,0,0,0,0,0,0,0,0,0,0,0
0,0,0,0,29,0,0,23,0,0,0,0,0,0,0,0,0,0,0,0,23,0,0,0,0,0,0,0,0,0,0,0,0,23,0,0
0,0,0,46,2,36,0,2,45,0,0,0,0,0,0,0,0,0,0,35,2,14,14,14,14,14,14,14,14,14,14,14,14,2,36,0
0,0,0,0,29,0,0,26,0,0,0,0,0,0,0,0,0,0,0,0,14,0,0,0,0,0,0,0,0,0,0,0,0,14,0,0
0,0,0,0,0,0,0,0,0,0,0,0,0,0,0,0,0,0,0,35,31,0,0,0,0,0,0,0,0,0,0,0,0,14,0,0
0,0,0,0,0,0,0,0,0,0,0,0,0,0,0,0,0,0,0,0,50,0,0,0,0,0,0,0,0,0,0,0,0,14,0,0
0,0,0,0,29,0,0,23,0,0,0,0,0,0,0,0,0,0,0,0,0,0,0,0,0,0,0,0,0,0,0,0,0,13,0,0
0,0,0,46,2,36,0,2,45,0,0,0,0,0,0,0,0,0,0,0,50,0,0,0,0,0,0,0,0,0,0,0,32,14,0,0
0,0,0,0,29,0,0,26,0,0,0,0,0,0,0,0,0,0,0,35,31,33,0,0,0,0,0,0,0,0,0,0,0,14,0,0
0,0,0,0,0,0,0,0,0,0,0,0,0,0,0,0,0,0,0,0,14,0,0,0,0,0,0,0,0,0,0,0,0,14,0,0
0,0,0,0,0,0,0,0,0,0,0,0,0,0,0,0,0,0,0,35,2,14,14,14,14,14,14,14,14,14,14,14,14,2,36,0
0,0,0,0,29,0,0,23,0,0,0,0,0,0,0,0,0,0,0,0,26,0,0,0,0,0,0,0,0,0,0,0,0,26,0,0
0,0,0,46,2,36,0,2,45,0,0,0,0,0,0,0,0,0,0,0,0,0,0,0,0,0,0,0,0,0,0,0,0,0,0,0
0,0,0,0,26,0,0,26,0,0,0,0,0,0,0,0,0,0,0,0,0,0,0,0,0,0,0,0,0,0,0,0,0,0,0,0
0,0,0,0,0,0,0,0,0,0,0,0,0,0,0,0,0,0,0,0,0,0,0,0,0,0,0,0,0,0,0,0,0,0,0,0
:endlayer
layer: 4
0,0,0,0,0,0,0,0,0,0,0,0,0,0,0,0,0,0,0,0,0,0,0,0,0,0,0,0,0,0,0,0,0,0,0,0
0,0,0,0,0,0,0,0,0,0,0,0,0,0,0,0,0,0,0,0,0,0,0,0,0,0,0,0,0,0,0,0,0,0,0,0
0,0,0,51,45,0,0,0,0,0,46,51,0,0,0,0,0,2,3,3,3,2,0,0,0,0,0,0,0,0,0,0,0,0,0,0
0,0,52,2,3,3,3,3,3,3,3,2,53,0,0,0,0,4,54,54,54,4,0,0,0,0,0,0,0,0,0,0,0,0,0,0
0,0,47,4,55,5,55,5,55,5,55,4,47,0,0,0,0,4,56,5,57,4,0,0,0,0,52,45,0,0,0,0,46,53,0,0
0,0,0,4,18,5,55,5,55,5,55,4,0,0,0,0,0,4,18,18,57,4,0,0,0,0,52,2,3,3,3,3,2,53,0,0
0,0,0,4,19,5,55,5,55,5,55,4,0,0,0,0,0,2,3,3,3,2,0,0,0,0,52,4,0,0,0,0,4,53,0,0
0,0,0,4,0,5,57,58,56,5,55,4,0,0,0,0,0,0,0,0,0,0,0,0,0,0,52,4,0,0,0,0,4,53,0,0
0,0,0,4,0,5,55,5,55,5,55,4,0,0,0,0,0,0,0,0,0,0,0,0,0,0,52,4,0,0,0,0,4,53,0,0
0,0,0,4,0,5,55,5,55,5,55,4,0,0,0,0,0,0,0,0,0,0,0,0,0,0,52,4,3,3,3,3,4,53,0,0
0,0,44,4,0,5,55,5,55,5,55,4,44,0,0,0,0,0,0,0,0,0,0,0,0,0,52,4,0,0,0,0,4,53,0,0
0,0,52,2,3,3,3,3,3,3,3,2,53,0,0,0,0,0,0,0,0,0,0,0,0,0,52,4,0,0,0,0,4,53,0,0
0,0,0,59,45,0,0,0,0,0,46,59,0,0,0,0,0,0,0,0,0,0,0,0,0,0,52,4,0,0,0,0,4,53,0,0
0,0,0,0,0,0,0,0,0,0,0,0,0,0,0,0,0,0,0,0,0,0,51,51,51,51,51,4,0,0,0,0,4,53,0,0
0,0,0,0,0,0,0,0,0,0,0,0,0,0,0,0,0,0,0,0,0,0,47,2,3,3,3,2,0,0,0,0,4,53,0,0
0,0,0,0,0,0,0,0,0,0,0,0,0,0,0,0,0,0,0,0,0,0,0,4,0,0,0,4,0,0,0,0,4,53,0,0
0,0,0,0,0,0,0,0,0,0,0,0,0,0,0,0,0,0,0,0,0,0,0,4,0,0,0,4,0,0,0,0,4,53,0,0
0,0,0,0,0,0,0,0,0,0,0,0,0,0,0,0,0,0,0,0,0,0,0,4,0,0,0,4,0,0,0,0,4,53,0,0
0,0,0,0,0,0,0,0,0,0,0,0,0,0,0,0,0,0,0,0,0,0,0,4,0,0,0,4,0,0,0,0,4,53,0,0
0,0,0,0,0,0,0,0,0,0,0,0,0,0,0,0,0,0,0,0,0,0,44,2,3,3,3,3,3,3,3,3,2,53,0,0
0,0,0,0,0,0,0,0,0,0,0,0,0,0,0,0,0,0,0,0,0,0,59,59,59,59,52,60,59,59,59,59,60,53,0,0
0,0,0,0,0,0,0,0,0,0,0,0,0,0,0,0,0,0,0,0,0,0,0,0,0,0,0,0,0,0,0,0,0,0,0,0
0,0,0,52,45,0,0,46,53,0,0,0,0,0,0,0,0,0,0,0,0,0,0,0,0,0,0,0,0,0,0,0,0,0,0,0
0,0,0,52,2,3,3,2,53,0,0,0,0,0,0,42,42,42,0,0,0,0,0,0,0,0,0,0,0,0,0,0,0,0,0,0
0,0,0,52,4,0,0,4,53,0,0,0,0,0,0,0,0,0,0,0,0,0,0,0,0,0,0,0,0,0,0,0,0,0,0,0
0,0,0,52,4,0,0,4,53,0,0,0,0,0,0,0,0,0,0,0,0,0,0,0,0,0,0,0,0,0,0,0,0,0,0,0
0,0,0,52,4,0,0,4,53,0,0,0,0,0,0,0,0,0,0,0,0,0,0,0,0,0,0,0,0,0,0,0,0,0,0,0
0,0,0,52,4,0,0,4,53,0,0,0,0,0,0,0,0,0,0,60,60,45,0,0,46,45,0,0,46,45,0,0,46,60,60,0
0,0,0,52,2,3,3,2,53,0,0,0,0,0,0,0,0,0,0,0,2,14,13,13,14,14,13,13,14,14,13,13,14,2,0,0
0,0,0,52,4,0,0,4,53,0,0,0,0,0,0,0,0,0,0,0,14,36,0,0,0,26,0,0,26,0,0,0,35,14,0,0
0,0,0,52,4,0,0,4,53,0,0,0,0,0,0,0,0,0,0,0,14,0,0,0,0,0,0,0,0,0,0,0,0,14,0,0
0,0,0,52,4,0,0,4,53,0,0,0,0,0,0,0,0,0,0,0,10,0,0,0,0,0,0,0,0,0,0,0,0,14,0,0
0,0,0,52,4,0,0,4,53,0,0,0,0,0,0,0,0,0,0,0,10,0,0,0,0,0,0,0,0,0,0,0,0,13,0,0
0,0,0,52,2,3,3,2,53,0,0,0,0,0,0,0,0,0,0,0,10,0,0,0,0,0,0,0,0,0,0,0,32,14,0,0
0,0,0,52,4,0,0,4,53,0,0,0,0,0,0,0,0,0,0,0,14,33,0,0,0,0,0,0,0,0,0,0,0,14,0,0
0,0,0,52,4,0,0,4,53,0,0,0,0,0,0,0,0,0,0,0,14,36,0,0,0,23,0,0,23,0,0,0,35,14,0,0
0,0,0,52,4,0,0,4,53,0,0,0,0,0,0,0,0,0,0,0,2,14,13,13,14,14,13,13,14,14,13,13,14,2,0,0
0,0,0,52,4,0,0,4,53,0,0,0,0,0,0,0,0,0,0,60,60,45,0,0,46,45,0,0,46,45,0,0,46,60,60,0
0,0,0,52,2,3,3,2,53,0,0,0,0,0,0,0,0,0,0,0,0,0,0,0,0,0,0,0,0,0,0,0,0,0,0,0
0,0,0,52,45,0,0,46,53,0,0,0,0,0,0,0,0,0,0,0,0,0,0,0,0,0,0,0,0,0,0,0,0,0,0,0
0,0,0,0,0,0,0,0,0,0,0,0,0,0,0,0,0,0,0,0,0,0,0,0,0,0,0,0,0,0,0,0,0,0,0,0
:endlayer
layer: 5
0,0,0,0,0,0,0,0,0,0,0,0,0,0,0,0,0,0,0,0,0,0,0,0,0,0,0,0,0,0,0,0,0,0,0,0
0,0,0,0,0,0,0,0,0,0,0,0,0,0,0,0,0,29,0,0,0,29,0,0,0,0,0,0,0,0,0,0,0,0,0,0
0,0,0,0,60,0,0,0,0,0,60,0,0,0,0,0,29,2,25,14,24,2,29,0,0,0,0,0,0,0,0,0,0,0,0,0
0,0,0,60,2,14,14,14,14,14,2,60,0,0,0,0,0,28,0,0,0,28,0,0,0,0,0,0,0,0,0,0,0,0,0,0
0,0,60,2,0,0,0,0,0,0,0,2,60,0,0,0,0,14,0,0,0,14,0,0,0,0,0,60,0,0,0,0,60,0,0,0
0,0,0,14,0,0,0,0,0,0,61,14,0,0,0,0,0,34,0,0,0,34,0,0,0,0,0,60,2,14,14,2,60,0,0,0
0,0,0,14,0,13,0,0,0,0,54,14,0,0,0,0,29,2,25,14,24,2,29,0,0,0,0,60,0,0,0,0,60,0,0,0
0,0,0,14,0,13,0,62,0,0,0,14,0,0,0,0,0,29,0,0,0,29,0,0,0,0,0,60,0,0,0,0,60,0,0,0
0,0,0,14,0,13,0,0,0,0,0,14,0,0,0,0,0,0,0,0,0,0,0,0,0,0,0,60,0,0,0,0,60,0,0,0
0,0,0,14,0,13,0,0,0,0,0,14,0,0,0,0,0,0,0,0,0,0,0,0,0,0,0,60,14,14,14,14,60,0,0,0
0,0,60,2,0,13,0,0,0,0,0,2,60,0,0,0,0,0,0,0,0,0,0,0,0,0,0,60,0,0,0,0,60,0,0,0
0,0,0,60,2,14,14,14,14,14,2,60,0,0,0,0,0,0,0,0,0,0,0,0,0,0,0,60,0,0,0,0,60,0,0,0
0,0,0,0,60,0,0,0,0,0,60,0,0,0,0,0,0,0,0,0,0,0,0,0,0,0,0,60,0,0,0,0,60,0,0,0
0,0,0,0,0,0,0,0,0,0,0,0,0,0,0,0,0,0,0,0,0,0,0,0,0,0,0,60,0,0,0,0,60,0,0,0
0,0,0,0,0,0,0,0,0,0,0,0,0,0,0,0,0,0,0,0,0,0,51,51,51,51,51,60,0,0,0,0,60,0,0,0
0,0,0,0,0,0,0,0,0,0,0,0,0,0,0,0,0,0,0,0,0,0,47,2,3,3,3,3,2,0,0,0,60,0,0,0
0,0,0,0,0,0,0,0,0,0,0,0,0,0,0,0,0,0,0,0,0,0,0,14,0,0,0,14,0,0,0,0,60,0,0,0
0,0,0,0,0,0,0,0,0,0,0,0,0,0,0,0,0,0,0,0,0,0,0,14,0,0,0,14,0,0,0,0,60,0,0,0
0,0,0,0,0,0,0,0,0,0,0,0,0,0,0,0,0,0,0,0,0,0,44,2,3,3,3,3,2,0,0,0,60,0,0,0
0,0,0,0,0,0,0,0,0,0,0,0,0,0,0,0,0,0,0,0,0,0,59,59,59,59,59,60,2,14,14,2,60,0,0,0
0,0,0,0,0,0,0,0,0,0,0,0,0,0,0,0,0,0,0,0,0,0,0,0,0,0,0,60,0,0,0,0,60,0,0,0
0,0,0,0,0,0,0,0,0,0,0,0,0,0,0,0,0,0,0,0,0,0,0,0,0,0,0,0,0,0,0,0,0,0,0,0
0,0,0,0,52,45,46,53,0,0,0,0,0,0,0,0,0,0,0,0,0,0,0,0,0,0,0,0,0,0,0,0,0,0,0,0
0,0,0,0,52,2,2,53,0,0,0,0,0,0,0,0,12,0,0,0,0,0,0,0,0,0,0,0,0,0,0,0,0,0,0,0
0,0,0,0,52,4,4,53,0,0,0,0,0,0,0,0,0,0,0,0,0,0,0,0,0,0,0,0,0,0,0,0,0,0,0,0
0,0,0,0,52,4,4,53,0,0,0,0,0,0,0,0,0,0,0,0,0,0,0,0,0,0,0,0,0,0,0,0,0,0,0,0
0,0,0,0,52,4,4,53,0,0,0,0,0,0,0,0,0,0,0,0,0,0,0,0,0,0,0,0,0,0,0,0,0,0,0,0
0,0,0,0,52,4,4,53,0,0,0,0,0,0,0,0,0,0,0,51,51,51,51,51,51,51,51,51,51,51,51,51,51,51,51,0
0,0,0,0,52,2,2,53,0,0,0,0,0,0,0,0,0,0,0,47,2,3,3,3,3,3,3,3,3,3,3,3,3,2,47,0
0,0,0,0,52,4,4,53,0,0,0,0,0,0,0,0,0,0,0,0,4,55,55,4,0,0,0,0,0,0,4,55,55,4,0,0
0,0,0,0,52,4,4,53,0,0,0,0,0,0,0,0,0,0,0,0,4,5,5,4,0,0,0,0,0,0,4,5,5,4,0,0
0,0,0,0,52,4,4,53,0,0,0,0,0,0,0,0,0,0,0,0,4,55,55,4,0,0,0,0,0,0,4,55,55,4,0,0
0,0,0,0,52,4,4,53,0,0,0,0,0,0,0,0,0,0,0,0,4,5,5,4,0,0,0,0,0,0,4,5,5,4,0,0
0,0,0,0,52,2,2,53,0,0,0,0,0,0,0,0,0,0,0,0,4,18,56,4,0,0,0,0,0,0,4,55,32,4,0,0
0,0,0,0,52,4,4,53,0,0,0,0,0,0,0,0,0,0,0,0,4,33,5,4,0,0,0,0,0,0,4,5,5,4,0,0
0,0,0,0,52,4,4,53,0,0,0,0,0,0,0,0,0,0,0,0,4,54,56,4,0,0,0,0,0,0,4,55,55,4,0,0
0,0,0,0,52,4,4,53,0,0,0,0,0,0,0,0,0,0,0,44,2,3,3,3,3,3,3,3,3,3,3,3,3,2,44,0
0,0,0,0,52,4,4,53,0,0,0,0,0,0,0,0,0,0,0,59,59,59,59,59,59,59,59,59,59,59,59,59,59,59,59,0
0,0,0,0,52,2,2,53,0,0,0,0,0,0,0,0,0,0,0,0,0,0,0,0,0,0,0,0,0,0,0,0,0,0,0,0
0,0,0,0,52,45,46,53,0,0,0,0,0,0,0,0,0,0,0,0,0,0,0,0,0,0,0,0,0,0,0,0,0,0,0,0
0,0,0,0,0,0,0,0,0,0,0,0,0,0,0,0,0,0,0,0,0,0,0,0,0,0,0,0,0,0,0,0,0,0,0,0
:endlayer
layer: 6
0,0,0,0,0,0,0,0,0,0,0,0,0,0,0,0,0,0,0,0,0,0,0,0,0,0,0,0,0,0,0,0,0,0,0,0
0,0,0,0,0,0,0,0,0,0,0,0,0,0,0,0,0,44,0,29,0,44,0,0,0,0,0,0,0,0,0,0,0,0,0,0
0,0,0,0,60,0,0,0,0,0,60,0,0,0,0,0,46,2,25,14,24,2,45,0,0,0,0,0,0,0,0,0,0,0,0,0
0,0,0,60,2,14,14,13,14,14,2,60,0,0,0,0,0,28,0,0,0,28,0,0,0,0,0,0,0,0,0,0,0,0,0,0
0,0,60,2,0,0,0,0,0,0,0,2,60,0,0,0,29,14,0,0,0,14,29,0,0,0,0,52,45,0,0,46,53,0,0,0
0,0,0,14,0,0,0,0,0,0,0,14,0,0,0,0,0,34,0,0,0,34,0,0,0,0,0,52,2,14,14,2,53,0,0,0
0,0,0,14,0,12,0,0,0,0,61,14,0,0,0,0,46,2,25,14,24,2,45,0,0,0,0,52,4,0,0,4,53,0,0,0
0,0,0,13,0,0,0,63,0,0,54,13,0,0,0,0,0,47,0,29,0,47,0,0,0,0,0,52,4,0,0,4,53,0,0,0
0,0,0,14,0,0,0,0,0,0,0,14,0,0,0,0,0,0,0,0,0,0,0,0,0,0,0,52,4,0,0,4,53,0,0,0
0,0,0,14,0,0,0,0,0,0,0,14,0,0,0,0,0,0,0,0,0,0,0,0,0,0,0,52,4,14,14,4,53,0,0,0
0,0,60,2,0,0,0,0,0,0,0,2,60,0,0,0,0,0,0,0,0,0,0,0,0,0,0,52,4,0,0,4,53,0,0,0
0,0,0,60,2,14,14,13,14,14,2,60,0,0,0,0,0,0,0,0,0,0,0,0,0,0,0,52,4,0,0,4,53,0,0,0
0,0,0,0,60,0,0,0,0,0,60,0,0,0,0,0,0,0,0,0,0,0,0,0,0,0,0,52,4,0,0,4,53,0,0,0
0,0,0,0,0,0,0,0,0,0,0,0,0,0,0,0,0,0,0,0,0,0,0,0,0,0,0,52,4,0,0,4,53,0,0,0
0,0,0,0,0,0,0,0,0,0,0,0,0,0,0,0,0,0,0,0,0,0,0,0,0,0,0,52,4,0,0,4,53,0,0,0
0,0,0,0,0,0,0,0,0,0,0,0,0,0,0,0,0,0,0,0,0,0,51,51,51,51,51,52,4,0,0,4,53,0,0,0
0,0,0,0,0,0,0,0,0,0,0,0,0,0,0,0,0,0,0,0,0,0,47,2,3,3,3,3,2,0,0,4,53,0,0,0
0,0,0,0,0,0,0,0,0,0,0,0,0,0,0,0,0,0,0,0,0,0,44,2,3,3,3,3,2,0,0,4,53,0,0,0
0,0,0,0,0,0,0,0,0,0,0,0,0,0,0,0,0,0,0,0,0,0,59,59,59,59,59,52,4,0,0,4,53,0,0,0
0,0,0,0,0,0,0,0,0,0,0,0,0,0,0,0,0,0,0,0,0,0,0,0,0,0,0,52,2,14,14,2,53,0,0,0
0,0,0,0,0,0,0,0,0,0,0,0,0,0,0,0,0,0,0,0,0,0,0,0,0,0,0,52,45,0,0,46,53,0,0,0
0,0,0,0,0,0,0,0,0,0,0,0,0,0,0,0,0,0,0,0,0,0,0,0,0,0,0,0,0,0,0,0,0,0,0,0
0,0,0,0,0,52,53,0,0,0,0,0,0,0,0,0,0,0,0,0,0,0,0,0,0,0,0,0,0,0,0,0,0,0,0,0
0,0,0,0,0,52,53,0,0,0,0,0,0,0,0,0,0,0,0,0,0,0,0,0,0,0,0,0,0,0,0,0,0,0,0,0
0,0,0,0,0,52,53,0,0,0,0,0,0,0,0,0,0,0,0,0,0,0,0,0,0,0,0,0,0,0,0,0,0,0,0,0
0,0,0,0,0,52,53,0,0,0,0,0,0,0,0,0,0,0,0,0,0,0,0,0,0,0,0,0,0,0,0,0,0,0,0,0
0,0,0,0,0,52,53,0,0,0,0,0,0,0,0,0,0,0,0,0,0,0,0,0,0,0,0,0,0,0,0,0,0,0,0,0
0,0,0,0,0,52,53,0,0,0,0,0,0,0,0,0,0,0,0,0,0,0,0,0,0,0,0,0,0,0,0,0,0,0,0,0
0,0,0,0,0,52,53,0,0,0,0,0,0,0,0,0,0,0,0,60,60,60,60,60,60,60,60,60,60,60,60,60,60,60,60,0
0,0,0,0,0,52,53,0,0,0,0,0,0,0,0,0,0,0,0,0,2,0,0,13,0,0,0,0,0,0,13,0,0,2,0,0
0,0,0,0,0,52,53,0,0,0,0,0,0,0,0,0,0,0,0,0,14,0,0,13,0,0,0,0,0,0,13,0,0,14,0,0
0,0,0,0,0,52,53,0,0,0,0,0,0,0,0,0,0,0,0,0,14,0,0,13,0,0,0,0,0,0,13,0,0,14,0,0
0,0,0,0,0,52,53,0,0,0,0,0,0,0,0,0,0,0,0,0,14,0,0,13,0,0,0,0,0,0,13,0,0,14,0,0
0,0,0,0,0,52,53,0,0,0,0,0,0,0,0,0,0,0,0,0,14,0,0,13,0,0,0,0,0,0,13,0,32,14,0,0
0,0,0,0,0,52,53,0,0,0,0,0,0,0,0,0,0,0,0,0,14,33,0,13,0,0,0,0,0,0,13,0,0,14,0,0
0,0,0,0,0,52,53,0,0,0,0,0,0,0,0,0,0,0,0,0,2,0,0,13,0,0,0,0,0,0,13,0,0,2,0,0
0,0,0,0,0,52,53,0,0,0,0,0,0,0,0,0,0,0,0,60,60,60,60,60,60,60,60,60,60,60,60,60,60,60,60,0
0,0,0,0,0,52,53,0,0,0,0,0,0,0,0,0,0,0,0,0,0,0,0,0,0,0,0,0,0,0,0,0,0,0,0,0
0,0,0,0,0,52,53,0,0,0,0,0,0,0,0,0,0,0,0,0,0,0,0,0,0,0,0,0,0,0,0,0,0,0,0,0
0,0,0,0,0,52,53,0,0,0,0,0,0,0,0,0,0,0,0,0,0,0,0,0,0,0,0,0,0,0,0,0,0,0,0,0
0,0,0,0,0,0,0,0,0,0,0,0,0,0,0,0,0,0,0,0,0,0,0,0,0,0,0,0,0,0,0,0,0,0,0,0
:endlayer
layer: 7
0,0,0,0,0,0,0,0,0,0,0,0,0,0,0,0,0,0,0,0,0,0,0,0,0,0,0,0,0,0,0,0,0,0,0,0
0,0,0,0,0,0,0,0,0,0,0,0,0,0,0,0,51,51,51,51,51,51,51,0,0,0,0,0,0,0,0,0,0,0,0,0
0,0,0,0,60,0,0,0,0,0,60,0,0,0,0,0,52,2,3,3,3,2,53,0,0,0,0,0,0,0,0,0,0,0,0,0
0,0,0,60,2,14,14,13,14,14,2,60,0,0,0,0,52,4,0,0,0,4,53,0,0,0,0,0,0,0,0,0,0,0,0,0
0,0,60,2,26,0,0,0,0,0,26,2,60,0,0,0,52,4,0,0,0,4,53,0,0,0,0,0,60,0,0,60,0,0,0,0
0,0,0,14,0,0,0,0,0,0,0,14,0,0,0,0,52,4,0,0,0,4,53,0,0,0,0,0,60,2,2,60,0,0,0,0
0,0,0,14,0,0,0,0,0,0,0,14,0,0,0,0,52,2,3,3,3,2,53,0,0,0,0,0,60,26,26,60,0,0,0,0
0,0,0,13,0,0,0,64,0,0,61,13,0,0,0,0,52,59,59,59,59,59,59,0,0,0,0,0,60,0,0,60,0,0,0,0
0,0,0,14,0,0,0,0,0,0,54,14,0,0,0,0,0,0,0,0,0,0,0,0,0,0,0,0,60,0,0,60,0,0,0,0
0,0,0,14,0,0,0,0,0,0,0,14,0,0,0,0,0,0,0,0,0,0,0,0,0,0,0,0,60,14,14,60,0,0,0,0
0,0,60,2,23,0,0,0,0,0,23,2,60,0,0,0,0,0,0,0,0,0,0,0,0,0,0,0,60,0,0,60,0,0,0,0
0,0,0,60,2,14,14,13,14,14,2,60,0,0,0,0,0,0,0,0,0,0,0,0,0,0,0,0,60,0,0,60,0,0,0,0
0,0,0,0,60,0,0,0,0,0,60,0,0,0,0,0,0,0,0,0,0,0,0,0,0,0,0,0,60,0,0,60,0,0,0,0
0,0,0,0,0,0,0,0,0,0,0,0,0,0,0,0,0,0,0,0,0,0,0,0,0,0,0,0,60,0,0,60,0,0,0,0
0,0,0,0,0,0,0,0,0,0,0,0,0,0,0,0,0,0,0,0,0,0,0,0,0,0,0,0,60,0,0,60,0,0,0,0
0,0,0,0,0,0,0,0,0,0,0,0,0,0,0,0,0,0,0,0,0,0,0,0,0,0,0,0,60,0,0,60,0,0,0,0
0,0,0,0,0,0,0,0,0,0,0,0,0,0,0,0,0,0,0,0,0,0,51,51,51,51,51,51,60,0,0,60,0,0,0,0
0,0,0,0,0,0,0,0,0,0,0,0,0,0,0,0,0,0,0,0,0,0,59,59,59,59,59,59,60,0,0,60,0,0,0,0
0,0,0,0,0,0,0,0,0,0,0,0,0,0,0,0,0,0,0,0,0,0,0,0,0,0,0,0,60,23,23,60,0,0,0,0
0,0,0,0,0,0,0,0,0,0,0,0,0,0,0,0,0,0,0,0,0,0,0,0,0,0,0,0,60,2,2,60,0,0,0,0
0,0,0,0,0,0,0,0,0,0,0,0,0,0,0,0,0,0,0,0,0,0,0,0,0,0,0,0,60,0,0,60,0,0,0,0
0,0,0,0,0,0,0,0,0,0,0,0,0,0,0,0,0,0,0,0,0,0,0,0,0,0,0,0,0,0,0,0,0,0,0,0
0,0,0,0,0,0,0,0,0,0,0,0,0,0,0,0,0,0,0,0,0,0,0,0,0,0,0,0,0,0,0,0,0,0,0,0
0,0,0,0,0,0,0,0,0,0,0,0,0,0,0,0,0,0,0,0,0,0,0,0,0,0,0,0,0,0,0,0,0,0,0,0
0,0,0,0,0,0,0,0,0,0,0,0,0,0,0,0,0,0,0,0,0,0,0,0,0,0,0,0,0,0,0,0,0,0,0,0
0,0,0,0,0,0,0,0,0,0,0,0,0,0,0,0,0,0,0,0,0,0,0,0,0,0,0,0,0,0,0,0,0,0,0,0
0,0,0,0,0,0,0,0,0,0,0,0,0,0,0,0,0,0,0,0,0,0,0,0,0,0,0,0,0,0,0,0,0,0,0,0
0,0,0,0,0,0,0,0,0,0,0,0,0,0,0,0,0,0,0,0,0,0,0,0,0,0,0,0,0,0,0,0,0,0,0,0
0,0,0,0,0,0,0,0,0,0,0,0,0,0,0,0,0,0,0,51,51,51,51,51,51,51,51,51,51,51,51,51,51,51,51,0
0,0,0,0,0,0,0,0,0,0,0,0,0,0,0,0,0,0,0,47,2,3,3,3,3,3,3,3,3,3,3,3,3,2,47,0
0,0,0,0,0,0,0,0,0,0,0,0,0,0,0,0,0,0,0,0,14,0,0,0,0,0,0,0,0,0,0,0,0,14,0,0
0,0,0,0,0,0,0,0,0,0,0,0,0,0,0,0,0,0,0,0,14,0,0,0,0,0,0,0,0,0,0,0,0,14,0,0
0,0,0,0,0,0,0,0,0,0,0,0,0,0,0,0,0,0,0,0,13,0,0,0,0,0,0,0,0,0,0,0,0,13,0,0
0,0,0,0,0,0,0,0,0,0,0,0,0,0,0,0,0,0,0,0,14,0,0,0,0,0,0,0,0,0,0,0,32,14,0,0
0,0,0,0,0,0,0,0,0,0,0,0,0,0,0,0,0,0,0,0,14,33,0,0,0,0,0,0,0,0,0,0,0,14,0,0
0,0,0,0,0,0,0,0,0,0,0,0,0,0,0,0,0,0,0,44,2,3,3,3,3,3,3,3,3,3,3,3,3,2,44,0
0,0,0,0,0,0,0,0,0,0,0,0,0,0,0,0,0,0,0,59,59,59,59,59,59,59,59,59,59,59,59,59,59,59,59,0
0,0,0,0,0,0,0,0,0,0,0,0,0,0,0,0,0,0,0,0,0,0,0,0,0,0,0,0,0,0,0,0,0,0,0,0
0,0,0,0,0,0,0,0,0,0,0,0,0,0,0,0,0,0,0,0,0,0,0,0,0,0,0,0,0,0,0,0,0,0,0,0
0,0,0,0,0,0,0,0,0,0,0,0,0,0,0,0,0,0,0,0,0,0,0,0,0,0,0,0,0,0,0,0,0,0,0,0
0,0,0,0,0,0,0,0,0,0,0,0,0,0,0,0,0,0,0,0,0,0,0,0,0,0,0,0,0,0,0,0,0,0,0,0
:endlayer
layer: 8
0,0,0,0,0,0,0,0,0,0,0,0,0,0,0,0,0,0,0,0,0,0,0,0,0,0,0,0,0,0,0,0,0,0,0,0
0,0,0,0,0,0,0,0,0,0,0,0,0,0,0,0,0,0,0,0,0,0,0,0,0,0,0,0,0,0,0,0,0,0,0,0
0,0,0,0,52,45,0,0,0,46,53,0,0,0,0,0,0,52,51,51,51,53,0,0,0,0,0,0,0,0,0,0,0,0,0,0
0,0,0,60,2,3,3,3,3,3,2,60,0,0,0,0,0,52,2,3,2,53,0,0,0,0,0,0,0,0,0,0,0,0,0,0
0,0,51,2,55,5,55,5,55,5,0,2,51,0,0,0,0,52,4,0,4,53,0,0,0,0,0,0,52,45,46,53,0,0,0,0
0,0,47,4,55,5,55,5,55,5,0,4,47,0,0,0,0,52,2,3,2,53,0,0,0,0,0,0,52,2,2,53,0,0,0,0
0,0,0,4,55,5,55,5,55,5,0,4,0,0,0,0,0,52,59,59,59,59,0,0,0,0,0,0,52,4,4,53,0,0,0,0
0,0,0,4,55,5,57,65,56,5,0,4,0,0,0,0,0,0,0,0,0,0,0,0,0,0,0,0,52,4,4,53,0,0,0,0
0,0,0,4,55,5,55,5,55,5,61,4,0,0,0,0,0,0,0,0,0,0,0,0,0,0,0,0,52,4,4,53,0,0,0,0
0,0,44,4,55,5,55,5,55,5,54,4,44,0,0,0,0,0,0,0,0,0,0,0,0,0,0,0,52,4,4,53,0,0,0,0
0,0,59,2,55,5,55,5,55,5,55,2,59,0,0,0,0,0,0,0,0,0,0,0,0,0,0,0,52,4,4,53,0,0,0,0
0,0,0,60,2,3,3,3,3,3,2,60,0,0,0,0,0,0,0,0,0,0,0,0,0,0,0,0,52,4,4,53,0,0,0,0
0,0,0,0,52,45,0,0,0,46,53,0,0,0,0,0,0,0,0,0,0,0,0,0,0,0,0,0,52,4,4,53,0,0,0,0
0,0,0,0,0,0,0,0,0,0,0,0,0,0,0,0,0,0,0,0,0,0,0,0,0,0,0,0,52,4,4,53,0,0,0,0
0,0,0,0,0,0,0,0,0,0,0,0,0,0,0,0,0,0,0,0,0,0,0,0,0,0,0,0,52,4,4,53,0,0,0,0
0,0,0,0,0,0,0,0,0,0,0,0,0,0,0,0,0,0,0,0,0,0,0,0,0,0,0,0,52,4,4,53,0,0,0,0
0,0,0,0,0,0,0,0,0,0,0,0,0,0,0,0,0,0,0,0,0,0,0,0,0,0,0,0,52,4,4,53,0,0,0,0
0,0,0,0,0,0,0,0,0,0,0,0,0,0,0,0,0,0,0,0,0,0,0,0,0,0,0,0,52,4,4,53,0,0,0,0
0,0,0,0,0,0,0,0,0,0,0,0,0,0,0,0,0,0,0,0,0,0,0,0,0,0,0,0,52,4,4,53,0,0,0,0
0,0,0,0,0,0,0,0,0,0,0,0,0,0,0,0,0,0,0,0,0,0,0,0,0,0,0,0,52,2,2,53,0,0,0,0
0,0,0,0,0,0,0,0,0,0,0,0,0,0,0,0,0,0,0,0,0,0,0,0,0,0,0,0,52,45,46,53,0,0,0,0
0,0,0,0,0,0,0,0,0,0,0,0,0,0,0,0,0,0,0,0,0,0,0,0,0,0,0,0,0,0,0,0,0,0,0,0
0,0,0,0,0,0,0,0,0,0,0,0,0,0,0,0,0,0,0,0,0,0,0,0,0,0,0,0,0,0,0,0,0,0,0,0
0,0,0,0,0,0,0,0,0,0,0,0,0,0,0,0,0,0,0,0,0,0,0,0,0,0,0,0,0,0,0,0,0,0,0,0
0,0,0,0,0,0,0,0,0,0,0,0,0,0,0,0,0,0,0,0,0,0,0,0,0,0,0,0,0,0,0,0,0,0,0,0
0,0,0,0,0,0,0,0,0,0,0,0,0,0,0,0,0,0,0,0,0,0,0,0,0,0,0,0,0,0,0,0,0,0,0,0
0,0,0,0,0,0,0,0,0,0,0,0,0,0,0,0,0,0,0,0,0,0,0,0,0,0,0,0,0,0,0,0,0,0,0,0
0,0,0,0,0,0,0,0,0,0,0,0,0,0,0,0,0,0,0,0,0,0,0,0,0,0,0,0,0,0,0,0,0,0,0,0
0,0,0,0,0,0,0,0,0,0,0,0,0,0,0,0,0,0,0,0,0,0,0,0,0,0,0,0,0,0,0,0,0,0,0,0
0,0,0,0,0,0,0,0,0,0,0,0,0,0,0,0,0,0,0,51,51,51,51,51,51,51,51,51,51,51,51,51,51,51,51,0
0,0,0,0,0,0,0,0,0,0,0,0,0,0,0,0,0,0,0,47,2,3,3,3,3,3,3,3,3,3,3,3,3,2,47,0
0,0,0,0,0,0,0,0,0,0,0,0,0,0,0,0,0,0,0,0,14,0,0,0,0,0,0,0,0,0,0,0,0,14,0,0
0,0,0,0,0,0,0,0,0,0,0,0,0,0,0,0,0,0,0,0,13,0,0,0,0,0,0,0,0,0,0,0,0,13,0,0
0,0,0,0,0,0,0,0,0,0,0,0,0,0,0,0,0,0,0,0,14,0,0,0,0,0,0,0,0,0,0,0,0,14,0,0
0,0,0,0,0,0,0,0,0,0,0,0,0,0,0,0,0,0,0,44,2,3,3,3,3,3,3,3,3,3,3,3,3,2,44,0
0,0,0,0,0,0,0,0,0,0,0,0,0,0,0,0,0,0,0,59,59,59,59,59,59,59,59,59,59,59,59,59,59,59,59,0
0,0,0,0,0,0,0,0,0,0,0,0,0,0,0,0,0,0,0,0,0,0,0,0,0,0,0,0,0,0,0,0,0,0,0,0
0,0,0,0,0,0,0,0,0,0,0,0,0,0,0,0,0,0,0,0,0,0,0,0,0,0,0,0,0,0,0,0,0,0,0,0
0,0,0,0,0,0,0,0,0,0,0,0,0,0,0,0,0,0,0,0,0,0,0,0,0,0,0,0,0,0,0,0,0,0,0,0
0,0,0,0,0,0,0,0,0,0,0,0,0,0,0,0,0,0,0,0,0,0,0,0,0,0,0,0,0,0,0,0,0,0,0,0
0,0,0,0,0,0,0,0,0,0,0,0,0,0,0,0,0,0,0,0,0,0,0,0,0,0,0,0,0,0,0,0,0,0,0,0
:endlayer
layer: 9
0,0,0,0,0,0,0,0,0,0,0,0,0,0,0,0,0,0,0,0,0,0,0,0,0,0,0,0,0,0,0,0,0,0,0,0
0,0,0,0,0,0,0,0,0,0,0,0,0,0,0,0,0,0,0,0,0,0,0,0,0,0,0,0,0,0,0,0,0,0,0,0
0,0,0,0,0,60,0,0,0,60,0,0,0,0,0,0,0,0,0,0,0,0,0,0,0,0,0,0,0,0,0,0,0,0,0,0
0,0,0,0,60,2,14,14,14,2,60,0,0,0,0,0,0,0,52,51,51,0,0,0,0,0,0,0,0,0,0,0,0,0,0,0
0,0,0,60,14,0,0,0,0,13,14,60,0,0,0,0,0,0,52,2,53,0,0,0,0,0,0,0,0,60,60,0,0,0,0,0
0,0,60,2,0,0,0,0,0,13,0,2,60,0,0,0,0,0,59,59,53,0,0,0,0,0,0,0,0,60,60,0,0,0,0,0
0,0,0,14,0,0,0,0,0,13,0,14,0,0,0,0,0,0,0,0,0,0,0,0,0,0,0,0,0,60,60,0,0,0,0,0
0,0,0,14,0,0,0,66,0,13,0,14,0,0,0,0,0,0,0,0,0,0,0,0,0,0,0,0,0,60,60,0,0,0,0,0
0,0,0,14,0,0,0,0,0,13,0,14,0,0,0,0,0,0,0,0,0,0,0,0,0,0,0,0,0,60,60,0,0,0,0,0
0,0,60,2,0,0,0,0,0,0,0,2,60,0,0,0,0,0,0,0,0,0,0,0,0,0,0,0,0,60,60,0,0,0,0,0
0,0,0,60,14,0,0,0,0,0,14,60,0,0,0,0,0,0,0,0,0,0,0,0,0,0,0,0,0,60,60,0,0,0,0,0
0,0,0,0,60,2,14,14,14,2,60,0,0,0,0,0,0,0,0,0,0,0,0,0,0,0,0,0,0,60,60,0,0,0,0,0
0,0,0,0,0,60,0,0,0,60,0,0,0,0,0,0,0,0,0,0,0,0,0,0,0,0,0,0,0,60,60,0,0,0,0,0
0,0,0,0,0,0,0,0,0,0,0,0,0,0,0,0,0,0,0,0,0,0,0,0,0,0,0,0,0,60,60,0,0,0,0,0
0,67,68,69,70,71,72,73,74,75,76,77,78,79,0,0,0,0,0,0,0,0,0,0,0,0,0,0,0,60,60,0,0,0,0,0
0,0,0,0,0,0,0,0,0,0,0,0,0,0,0,0,0,0,0,0,0,0,0,0,0,0,0,0,0,60,60,0,0,0,0,0
0,0,0,0,0,0,0,0,0,0,0,0,0,0,0,0,0,0,0,0,0,0,0,0,0,0,0,0,0,60,60,0,0,0,0,0
0,0,0,0,0,0,0,0,0,0,0,0,0,0,0,0,0,0,0,0,0,0,0,0,0,0,0,0,0,60,60,0,0,0,0,0
0,0,0,0,0,0,0,0,0,0,0,0,0,0,0,0,0,0,0,0,0,0,0,0,0,0,0,0,0,60,60,0,0,0,0,0
0,0,0,0,0,0,0,0,0,0,0,0,0,0,0,0,0,0,0,0,0,0,0,0,0,0,0,0,0,60,60,0,0,0,0,0
0,0,0,0,0,0,0,0,0,0,0,0,0,0,0,0,0,0,0,0,0,0,0,0,0,0,0,0,0,60,60,0,0,0,0,0
0,0,0,0,0,0,0,0,0,0,0,0,0,0,0,0,0,0,0,0,0,0,0,0,0,0,0,0,0,0,0,0,0,0,0,0
0,0,0,0,0,0,0,0,0,0,0,0,0,0,0,0,0,0,0,0,0,0,0,0,0,0,0,0,0,0,0,0,0,0,0,0
0,0,0,0,0,0,0,0,0,0,0,0,0,0,0,0,0,0,0,0,0,0,0,0,0,0,0,0,0,0,0,0,0,0,0,0
0,0,0,0,0,0,0,0,0,0,0,0,0,0,0,0,0,0,0,0,0,0,0,0,0,0,0,0,0,0,0,0,0,0,0,0
0,0,0,0,0,0,0,0,0,0,0,0,0,0,0,0,0,0,0,0,0,0,0,0,0,0,0,0,0,0,0,0,0,0,0,0
0,0,0,0,0,0,0,0,0,0,0,0,0,0,0,0,0,0,0,0,0,0,0,0,0,0,0,0,0,0,0,0,0,0,0,0
0,0,0,0,0,0,0,0,0,0,0,0,0,0,0,0,0,0,0,0,0,0,0,0,0,0,0,0,0,0,0,0,0,0,0,0
0,0,0,0,0,0,0,0,0,0,0,0,0,0,0,0,0,0,0,0,0,0,0,0,0,0,0,0,0,0,0,0,0,0,0,0
0,0,0,0,0,0,0,0,0,0,0,0,0,0,0,0,0,0,0,0,0,0,0,0,0,0,0,0,0,0,0,0,0,0,0,0
0,0,0,0,0,0,0,0,0,0,0,0,0,0,0,0,0,0,0,51,51,51,51,51,51,51,51,51,51,51,51,51,51,51,51,0
0,0,0,0,0,0,0,0,0,0,0,0,0,0,0,0,0,0,0,47,2,3,3,3,3,3,3,3,3,3,3,3,3,2,47,0
0,0,0,0,0,0,0,0,0,0,0,0,0,0,0,0,0,0,0,46,4,36,0,0,0,0,0,0,0,0,0,0,35,4,45,0
0,0,0,0,0,0,0,0,0,0,0,0,0,0,0,0,0,0,0,44,2,3,3,3,3,3,3,3,3,3,3,3,3,2,44,0
0,0,0,0,0,0,0,0,0,0,0,0,0,0,0,0,0,0,0,59,59,59,59,59,59,59,59,59,59,59,59,59,59,59,59,0
0,0,0,0,0,0,0,0,0,0,0,0,0,0,0,0,0,0,0,0,0,0,0,0,0,0,0,0,0,0,0,0,0,0,0,0
0,0,0,0,0,0,0,0,0,0,0,0,0,0,0,0,0,0,0,0,0,0,0,0,0,0,0,0,0,0,0,0,0,0,0,0
0,0,0,0,0,0,0,0,0,0,0,0,0,0,0,0,0,0,0,0,0,0,0,0,0,0,0,0,0,0,0,0,0,0,0,0
0,0,0,0,0,0,0,0,0,0,0,0,0,0,0,0,0,0,0,0,0,0,0,0,0,0,0,0,0,0,0,0,0,0,0,0
0,0,0,0,0,0,0,0,0,0,0,0,0,0,0,0,0,0,0,0,0,0,0,0,0,0,0,0,0,0,0,0,0,0,0,0
0,0,0,0,0,0,0,0,0,0,0,0,0,0,0,0,0,0,0,0,0,0,0,0,0,0,0,0,0,0,0,0,0,0,0,0
:endlayer
layer: 10
0,0,0,0,0,0,0,0,0,0,0,0,0,0,0,0,0,0,0,0,0,0,0,0,0,0,0,0,0,0,0,0,0,0,0,0
0,0,0,0,0,0,0,0,0,0,0,0,0,0,0,0,0,0,0,0,0,0,0,0,0,0,0,0,0,0,0,0,0,0,0,0
0,0,0,0,0,60,0,0,0,60,0,0,0,0,0,0,0,0,0,0,0,0,0,0,0,0,0,0,0,0,0,0,0,0,0,0
0,0,0,0,60,2,14,13,14,2,60,0,0,0,0,0,0,0,0,0,0,0,0,0,0,0,0,0,0,0,0,0,0,0,0,0
0,0,0,60,14,0,0,0,0,0,14,60,0,0,0,0,0,0,0,80,0,0,0,0,0,0,0,0,0,52,53,0,0,0,0,0
0,0,60,2,0,0,0,0,0,0,0,2,60,0,0,0,0,0,0,0,0,0,0,0,0,0,0,0,0,52,53,0,0,0,0,0
0,0,0,14,0,0,0,0,0,0,0,14,0,0,0,0,0,0,0,0,0,0,0,0,0,0,0,0,0,52,53,0,0,0,0,0
0,0,0,13,0,0,0,81,0,0,0,13,0,0,0,0,0,0,0,0,0,0,0,0,0,0,0,0,0,52,53,0,0,0,0,0
0,0,0,14,0,0,0,0,0,12,0,14,0,0,0,0,0,0,0,0,0,0,0,0,0,0,0,0,0,52,53,0,0,0,0,0
0,0,60,2,0,0,0,0,0,0,0,2,60,0,0,0,0,0,0,0,0,0,0,0,0,0,0,0,0,52,53,0,0,0,0,0
0,0,0,60,14,0,0,0,0,0,14,60,0,0,0,0,0,0,0,0,0,0,0,0,0,0,0,0,0,52,53,0,0,0,0,0
0,0,0,0,60,2,14,13,14,2,60,0,0,0,0,0,0,0,0,0,0,0,0,0,0,0,0,0,0,52,53,0,0,0,0,0
0,0,0,0,0,60,0,0,0,60,0,0,0,0,0,0,0,0,0,0,0,0,0,0,0,0,0,0,0,52,53,0,0,0,0,0
0,0,0,0,0,0,0,0,0,0,0,0,0,0,0,0,0,0,0,0,0,0,0,0,0,0,0,0,0,52,53,0,0,0,0,0
0,82,83,84,85,86,87,88,89,90,91,92,93,94,0,0,0,0,0,0,0,0,0,0,0,0,0,0,0,52,53,0,0,0,0,0
0,0,0,0,0,0,0,0,0,0,0,0,0,0,0,0,0,0,0,0,0,0,0,0,0,0,0,0,0,52,53,0,0,0,0,0
0,0,0,0,0,0,0,0,0,0,0,0,0,0,0,0,0,0,0,0,0,0,0,0,0,0,0,0,0,52,53,0,0,0,0,0
0,0,0,0,0,0,0,0,0,0,0,0,0,0,0,0,0,0,0,0,0,0,0,0,0,0,0,0,0,52,53,0,0,0,0,0
0,0,0,0,0,0,0,0,0,0,0,0,0,0,0,0,0,0,0,0,0,0,0,0,0,0,0,0,0,52,53,0,0,0,0,0
0,0,0,0,0,0,0,0,0,0,0,0,0,0,0,0,0,0,0,0,0,0,0,0,0,0,0,0,0,52,53,0,0,0,0,0
0,0,0,0,0,0,0,0,0,0,0,0,0,0,0,0,0,0,0,0,0,0,0,0,0,0,0,0,0,52,53,0,0,0,0,0
0,0,0,0,0,0,0,0,0,0,0,0,0,0,0,0,0,0,0,0,0,0,0,0,0,0,0,0,0,0,0,0,0,0,0,0
0,0,0,0,0,0,0,0,0,0,0,0,0,0,0,0,0,0,0,0,0,0,0,0,0,0,0,0,0,0,0,0,0,0,0,0
0,0,0,0,0,0,0,0,0,0,0,0,0,0,0,0,0,0,0,0,0,0,0,0,0,0,0,0,0,0,0,0,0,0,0,0
0,0,0,0,0,0,0,0,0,0,0,0,0,0,0,0,0,0,0,0,0,0,0,0,0,0,0,0,0,0,0,0,0,0,0,0
0,0,0,0,0,0,0,0,0,0,0,0,0,0,0,0,0,0,0,0,0,0,0,0,0,0,0,0,0,0,0,0,0,0,0,0
0,0,0,0,0,0,0,0,0,0,0,0,0,0,0,0,0,0,0,0,0,0,0,0,0,0,0,0,0,0,0,0,0,0,0,0
0,0,0,0,0,0,0,0,0,0,0,0,0,0,0,0,0,0,0,0,0,0,0,0,0,0,0,0,0,0,0,0,0,0,0,0
0,0,0,0,0,0,0,0,0,0,0,0,0,0,0,0,0,0,0,0,0,0,0,0,0,0,0,0,0,0,0,0,0,0,0,0
0,0,0,0,0,0,0,0,0,0,0,0,0,0,0,0,0,0,0,0,0,0,0,0,0,0,0,0,0,0,0,0,0,0,0,0
0,0,0,0,0,0,0,0,0,0,0,0,0,0,0,0,0,0,0,0,0,0,0,0,0,0,0,0,0,0,0,0,0,0,0,0
0,0,0,0,0,0,0,0,0,0,0,0,0,0,0,0,0,0,0,80,80,80,80,80,80,80,80,80,80,80,80,80,80,80,80,0
0,0,0,0,0,0,0,0,0,0,0,0,0,0,0,0,0,0,0,80,80,80,80,80,80,80,80,80,80,80,80,80,80,80,80,0
0,0,0,0,0,0,0,0,0,0,0,0,0,0,0,0,0,0,0,80,80,80,80,80,80,80,80,80,80,80,80,80,80,80,80,0
0,0,0,0,0,0,0,0,0,0,0,0,0,0,0,0,0,0,0,0,0,0,0,0,0,0,0,0,0,0,0,0,0,0,0,0
0,0,0,0,0,0,0,0,0,0,0,0,0,0,0,0,0,0,0,0,0,0,0,0,0,0,0,0,0,0,0,0,0,0,0,0
0,0,0,0,0,0,0,0,0,0,0,0,0,0,0,0,0,0,0,0,0,0,0,0,0,0,0,0,0,0,0,0,0,0,0,0
0,0,0,0,0,0,0,0,0,0,0,0,0,0,0,0,0,0,0,0,0,0,0,0,0,0,0,0,0,0,0,0,0,0,0,0
0,0,0,0,0,0,0,0,0,0,0,0,0,0,0,0,0,0,0,0,0,0,0,0,0,0,0,0,0,0,0,0,0,0,0,0
0,0,0,0,0,0,0,0,0,0,0,0,0,0,0,0,0,0,0,0,0,0,0,0,0,0,0,0,0,0,0,0,0,0,0,0
0,0,0,0,0,0,0,0,0,0,0,0,0,0,0,0,0,0,0,0,0,0,0,0,0,0,0,0,0,0,0,0,0,0,0,0
:endlayer
layer: 11
0,0,0,0,0,0,0,0,0,0,0,0,0,0,0,0,0,0,0,0,0,0,0,0,0,0,0,0,0,0,0,0,0,0,0,0
0,0,0,0,0,0,0,0,0,0,0,0,0,0,0,0,0,0,0,0,0,0,0,0,0,0,0,0,0,0,0,0,0,0,0,0
0,0,0,0,0,60,0,0,0,60,0,0,0,0,0,0,0,0,0,0,0,0,0,0,0,0,0,0,0,0,0,0,0,0,0,0
0,0,0,0,60,2,14,13,14,2,60,0,0,0,0,0,0,0,0,0,0,0,0,0,0,0,0,0,0,0,0,0,0,0,0,0
0,0,0,60,14,0,0,0,0,0,14,60,0,0,0,0,0,0,0,0,0,0,0,0,0,0,0,0,0,0,0,0,0,0,0,0
0,0,60,2,0,0,0,0,0,0,0,2,60,0,0,0,0,0,0,0,0,0,0,0,0,0,0,0,0,0,0,0,0,0,0,0
0,0,0,14,0,0,0,0,0,0,0,14,0,0,0,0,0,0,0,0,0,0,0,0,0,0,0,0,0,0,0,0,0,0,0,0
0,0,0,13,0,0,0,95,0,0,0,13,0,0,0,0,0,0,0,0,0,0,0,0,0,0,0,0,0,0,0,0,0,0,0,0
0,0,0,14,0,0,0,0,0,0,0,14,0,0,0,0,0,0,0,0,0,0,0,0,0,0,0,0,0,0,0,0,0,0,0,0
0,0,60,2,0,0,0,0,0,0,0,2,60,0,0,0,0,0,0,0,0,0,0,0,0,0,0,0,0,0,0,0,0,0,0,0
0,0,0,60,14,0,0,0,0,0,14,60,0,0,0,0,0,0,0,0,0,0,0,0,0,0,0,0,0,0,0,0,0,0,0,0
0,0,0,0,60,2,14,13,14,2,60,0,0,0,0,0,0,0,0,0,0,0,0,0,0,0,0,0,0,0,0,0,0,0,0,0
0,0,0,0,0,60,0,0,0,60,0,0,0,0,0,0,0,0,0,0,0,0,0,0,0,0,0,0,0,0,0,0,0,0,0,0
0,0,0,0,0,0,0,0,0,0,0,0,0,0,0,0,0,0,0,0,0,0,0,0,0,0,0,0,0,0,0,0,0,0,0,0
0,96,97,98,99,100,101,102,103,104,105,106,107,108,0,0,0,0,0,0,0,0,0,0,0,0,0,0,0,0,0,0,0,0,0,0
0,0,0,0,0,0,0,0,0,0,0,0,0,0,0,0,0,0,0,0,0,0,0,0,0,0,0,0,0,0,0,0,0,0,0,0
0,0,0,0,0,0,0,0,0,0,0,0,0,0,0,0,0,0,0,0,0,0,0,0,0,0,0,0,0,0,0,0,0,0,0,0
0,0,0,0,0,0,0,0,0,0,0,0,0,0,0,0,0,0,0,0,0,0,0,0,0,0,0,0,0,0,0,0,0,0,0,0
0,0,0,0,0,0,0,0,0,0,0,0,0,0,0,0,0,0,0,0,0,0,0,0,0,0,0,0,0,0,0,0,0,0,0,0
0,0,0,0,0,0,0,0,0,0,0,0,0,0,0,0,0,0,0,0,0,0,0,0,0,0,0,0,0,0,0,0,0,0,0,0
0,0,0,0,0,0,0,0,0,0,0,0,0,0,0,0,0,0,0,0,0,0,0,0,0,0,0,0,0,0,0,0,0,0,0,0
0,0,0,0,0,0,0,0,0,0,0,0,0,0,0,0,0,0,0,0,0,0,0,0,0,0,0,0,0,0,0,0,0,0,0,0
0,0,0,0,0,0,0,0,0,0,0,0,0,0,0,0,0,0,0,0,0,0,0,0,0,0,0,0,0,0,0,0,0,0,0,0
0,0,0,0,0,0,0,0,0,0,0,0,0,0,0,0,0,0,0,0,0,0,0,0,0,0,0,0,0,0,0,0,0,0,0,0
0,0,0,0,0,0,0,0,0,0,0,0,0,0,0,0,0,0,0,0,0,0,0,0,0,0,0,0,0,0,0,0,0,0,0,0
0,0,0,0,0,0,0,0,0,0,0,0,0,0,0,0,0,0,0,0,0,0,0,0,0,0,0,0,0,0,0,0,0,0,0,0
0,0,0,0,0,0,0,0,0,0,0,0,0,0,0,0,0,0,0,0,0,0,0,0,0,0,0,0,0,0,0,0,0,0,0,0
0,0,0,0,0,0,0,0,0,0,0,0,0,0,0,0,0,0,0,0,0,0,0,0,0,0,0,0,0,0,0,0,0,0,0,0
0,0,0,0,0,0,0,0,0,0,0,0,0,0,0,0,0,0,0,0,0,0,0,0,0,0,0,0,0,0,0,0,0,0,0,0
0,0,0,0,0,0,0,0,0,0,0,0,0,0,0,0,0,0,0,0,0,0,0,0,0,0,0,0,0,0,0,0,0,0,0,0
0,0,0,0,0,0,0,0,0,0,0,0,0,0,0,0,0,0,0,0,0,0,0,0,0,0,0,0,0,0,0,0,0,0,0,0
0,0,0,0,0,0,0,0,0,0,0,0,0,0,0,0,0,0,0,0,0,0,0,0,0,0,0,0,0,0,0,0,0,0,0,0
0,0,0,0,0,0,0,0,0,0,0,0,0,0,0,0,0,0,0,0,0,0,0,0,0,0,0,0,0,0,0,0,0,0,0,0
0,0,0,0,0,0,0,0,0,0,0,0,0,0,0,0,0,0,0,0,0,0,0,0,0,0,0,0,0,0,0,0,0,0,0,0
0,0,0,0,0,0,0,0,0,0,0,0,0,0,0,0,0,0,0,0,0,0,0,0,0,0,0,0,0,0,0,0,0,0,0,0
0,0,0,0,0,0,0,0,0,0,0,0,0,0,0,0,0,0,0,0,0,0,0,0,0,0,0,0,0,0,0,0,0,0,0,0
0,0,0,0,0,0,0,0,0,0,0,0,0,0,0,0,0,0,0,0,0,0,0,0,0,0,0,0,0,0,0,0,0,0,0,0
0,0,0,0,0,0,0,0,0,0,0,0,0,0,0,0,0,0,0,0,0,0,0,0,0,0,0,0,0,0,0,0,0,0,0,0
0,0,0,0,0,0,0,0,0,0,0,0,0,0,0,0,0,0,0,0,0,0,0,0,0,0,0,0,0,0,0,0,0,0,0,0
0,0,0,0,0,0,0,0,0,0,0,0,0,0,0,0,0,0,0,0,0,0,0,0,0,0,0,0,0,0,0,0,0,0,0,0
0,0,0,0,0,0,0,0,0,0,0,0,0,0,0,0,0,0,0,0,0,0,0,0,0,0,0,0,0,0,0,0,0,0,0,0
:endlayer
layer: 12
0,0,0,0,0,0,0,0,0,0,0,0,0,0,0,0,0,0,0,0,0,0,0,0,0,0,0,0,0,0,0,0,0,0,0,0
0,0,0,0,0,0,0,0,0,0,0,0,0,0,0,0,0,0,0,0,0,0,0,0,0,0,0,0,0,0,0,0,0,0,0,0
0,0,0,0,0,52,45,0,46,53,0,0,0,0,0,0,0,0,0,0,0,0,0,0,0,0,0,0,0,0,0,0,0,0,0,0
0,0,0,0,51,2,3,3,3,2,51,0,0,0,0,0,0,0,0,0,0,0,0,0,0,0,0,0,0,0,0,0,0,0,0,0
0,0,0,52,2,36,0,0,0,35,2,53,0,0,0,0,0,0,0,0,0,0,0,0,0,0,0,0,0,0,0,0,0,0,0,0
0,0,51,2,26,0,0,0,0,0,26,2,51,0,0,0,0,0,0,0,0,0,0,0,0,0,0,0,0,0,0,0,0,0,0,0
0,0,47,4,0,0,0,0,0,0,0,4,47,0,0,0,0,0,0,0,0,0,0,0,0,0,0,0,0,0,0,0,0,0,0,0
0,0,0,4,0,0,0,109,0,0,0,4,0,0,0,0,0,0,0,0,0,0,0,0,0,0,0,0,0,0,0,0,0,0,0,0
0,0,44,4,0,0,0,0,0,0,0,4,44,0,0,0,0,0,0,0,0,0,0,0,0,0,0,0,0,0,0,0,0,0,0,0
0,0,59,2,23,0,0,0,0,0,23,2,59,0,0,0,0,0,0,0,0,0,0,0,0,0,0,0,0,0,0,0,0,0,0,0
0,0,0,52,2,36,0,0,0,35,2,53,0,0,0,0,0,0,0,0,0,0,0,0,0,0,0,0,0,0,0,0,0,0,0,0
0,0,0,0,59,2,3,3,3,2,59,0,0,0,0,0,0,0,0,0,0,0,0,0,0,0,0,0,0,0,0,0,0,0,0,0
0,0,0,0,0,52,45,0,46,53,0,0,0,0,0,0,0,0,0,0,0,0,0,0,0,0,0,0,0,0,0,0,0,0,0,0
0,0,0,0,0,0,0,0,0,0,0,0,0,0,0,0,0,0,0,0,0,0,0,0,0,0,0,0,0,0,0,0,0,0,0,0
0,110,111,112,113,114,115,116,117,118,119,120,121,122,0,0,0,0,0,0,0,0,0,0,0,0,0,0,0,0,0,0,0,0,0,0
0,0,0,0,0,0,0,0,0,0,0,0,0,0,0,0,0,0,0,0,0,0,0,0,0,0,0,0,0,0,0,0,0,0,0,0
0,0,0,0,0,0,0,0,0,0,0,0,0,0,0,0,0,0,0,0,0,0,0,0,0,0,0,0,0,0,0,0,0,0,0,0
0,0,0,0,0,0,0,0,0,0,0,0,0,0,0,0,0,0,0,0,0,0,0,0,0,0,0,0,0,0,0,0,0,0,0,0
0,0,0,0,0,0,0,0,0,0,0,0,0,0,0,0,0,0,0,0,0,0,0,0,0,0,0,0,0,0,0,0,0,0,0,0
0,0,0,0,0,0,0,0,0,0,0,0,0,0,0,0,0,0,0,0,0,0,0,0,0,0,0,0,0,0,0,0,0,0,0,0
0,0,0,0,0,0,0,0,0,0,0,0,0,0,0,0,0,0,0,0,0,0,0,0,0,0,0,0,0,0,0,0,0,0,0,0
0,0,0,0,0,0,0,0,0,0,0,0,0,0,0,0,0,0,0,0,0,0,0,0,0,0,0,0,0,0,0,0,0,0,0,0
0,0,0,0,0,0,0,0,0,0,0,0,0,0,0,0,0,0,0,0,0,0,0,0,0,0,0,0,0,0,0,0,0,0,0,0
0,0,0,0,0,0,0,0,0,0,0,0,0,0,0,0,0,0,0,0,0,0,0,0,0,0,0,0,0,0,0,0,0,0,0,0
0,0,0,0,0,0,0,0,0,0,0,0,0,0,0,0,0,0,0,0,0,0,0,0,0,0,0,0,0,0,0,0,0,0,0,0
0,0,0,0,0,0,0,0,0,0,0,0,0,0,0,0,0,0,0,0,0,0,0,0,0,0,0,0,0,0,0,0,0,0,0,0
0,0,0,0,0,0,0,0,0,0,0,0,0,0,0,0,0,0,0,0,0,0,0,0,0,0,0,0,0,0,0,0,0,0,0,0
0,0,0,0,0,0,0,0,0,0,0,0,0,0,0,0,0,0,0,0,0,0,0,0,0,0,0,0,0,0,0,0,0,0,0,0
0,0,0,0,0,0,0,0,0,0,0,0,0,0,0,0,0,0,0,0,0,0,0,0,0,0,0,0,0,0,0,0,0,0,0,0
0,0,0,0,0,0,0,0,0,0,0,0,0,0,0,0,0,0,0,0,0,0,0,0,0,0,0,0,0,0,0,0,0,0,0,0
0,0,0,0,0,0,0,0,0,0,0,0,0,0,0,0,0,0,0,0,0,0,0,0,0,0,0,0,0,0,0,0,0,0,0,0
0,0,0,0,0,0,0,0,0,0,0,0,0,0,0,0,0,0,0,0,0,0,0,0,0,0,0,0,0,0,0,0,0,0,0,0
0,0,0,0,0,0,0,0,0,0,0,0,0,0,0,0,0,0,0,0,0,0,0,0,0,0,0,0,0,0,0,0,0,0,0,0
0,0,0,0,0,0,0,0,0,0,0,0,0,0,0,0,0,0,0,0,0,0,0,0,0,0,0,0,0,0,0,0,0,0,0,0
0,0,0,0,0,0,0,0,0,0,0,0,0,0,0,0,0,0,0,0,0,0,0,0,0,0,0,0,0,0,0,0,0,0,0,0
0,0,0,0,0,0,0,0,0,0,0,0,0,0,0,0,0,0,0,0,0,0,0,0,0,0,0,0,0,0,0,0,0,0,0,0
0,0,0,0,0,0,0,0,0,0,0,0,0,0,0,0,0,0,0,0,0,0,0,0,0,0,0,0,0,0,0,0,0,0,0,0
0,0,0,0,0,0,0,0,0,0,0,0,0,0,0,0,0,0,0,0,0,0,0,0,0,0,0,0,0,0,0,0,0,0,0,0
0,0,0,0,0,0,0,0,0,0,0,0,0,0,0,0,0,0,0,0,0,0,0,0,0,0,0,0,0,0,0,0,0,0,0,0
0,0,0,0,0,0,0,0,0,0,0,0,0,0,0,0,0,0,0,0,0,0,0,0,0,0,0,0,0,0,0,0,0,0,0,0
0,0,0,0,0,0,0,0,0,0,0,0,0,0,0,0,0,0,0,0,0,0,0,0,0,0,0,0,0,0,0,0,0,0,0,0
:endlayer
layer: 13
0,0,0,0,0,0,0,0,0,0,0,0,0,0,0,0,0,0,0,0,0,0,0,0,0,0,0,0,0,0,0,0,0,0,0,0
0,0,0,0,0,0,0,0,0,0,0,0,0,0,0,0,0,0,0,0,0,0,0,0,0,0,0,0,0,0,0,0,0,0,0,0
0,0,0,0,0,0,60,60,60,0,0,0,0,0,0,0,0,0,0,0,0,0,0,0,0,0,0,0,0,0,0,0,0,0,0,0
0,0,0,0,0,60,2,14,2,60,0,0,0,0,0,0,0,0,0,0,0,0,0,0,0,0,0,0,0,0,0,0,0,0,0,0
0,0,0,0,60,0,0,0,0,0,60,0,0,0,0,0,0,0,0,0,0,0,0,0,0,0,0,0,0,0,0,0,0,0,0,0
0,0,0,60,0,0,0,0,0,0,0,60,0,0,0,0,0,0,0,0,0,0,0,0,0,0,0,0,0,0,0,0,0,0,0,0
0,0,60,2,0,0,0,0,0,0,0,2,60,0,0,0,0,0,0,0,0,0,0,0,0,0,0,0,0,0,0,0,0,0,0,0
0,0,60,14,0,0,0,123,0,0,0,14,60,0,0,0,0,0,0,0,0,0,0,0,0,0,0,0,0,0,0,0,0,0,0,0
0,0,60,2,0,0,0,0,0,0,0,2,60,0,0,0,0,0,0,0,0,0,0,0,0,0,0,0,0,0,0,0,0,0,0,0
0,0,0,60,0,0,0,0,0,0,0,60,0,0,0,0,0,0,0,0,0,0,0,0,0,0,0,0,0,0,0,0,0,0,0,0
0,0,0,0,60,0,0,0,0,0,60,0,0,0,0,0,0,0,0,0,0,0,0,0,0,0,0,0,0,0,0,0,0,0,0,0
0,0,0,0,0,60,2,14,2,60,0,0,0,0,0,0,0,0,0,0,0,0,0,0,0,0,0,0,0,0,0,0,0,0,0,0
0,0,0,0,0,0,60,60,60,0,0,0,0,0,0,0,0,0,0,0,0,0,0,0,0,0,0,0,0,0,0,0,0,0,0,0
0,0,0,0,0,0,0,0,0,0,0,0,0,0,0,0,0,0,0,0,0,0,0,0,0,0,0,0,0,0,0,0,0,0,0,0
0,124,125,126,127,128,129,130,131,132,133,134,135,136,0,0,0,0,0,0,0,0,0,0,0,0,0,0,0,0,0,0,0,0,0,0
0,0,0,0,0,0,0,0,0,0,0,0,0,0,0,0,0,0,0,0,0,0,0,0,0,0,0,0,0,0,0,0,0,0,0,0
0,0,0,0,0,0,0,0,0,0,0,0,0,0,0,0,0,0,0,0,0,0,0,0,0,0,0,0,0,0,0,0,0,0,0,0
0,0,0,0,0,0,0,0,0,0,0,0,0,0,0,0,0,0,0,0,0,0,0,0,0,0,0,0,0,0,0,0,0,0,0,0
0,0,0,0,0,0,0,0,0,0,0,0,0,0,0,0,0,0,0,0,0,0,0,0,0,0,0,0,0,0,0,0,0,0,0,0
0,0,0,0,0,0,0,0,0,0,0,0,0,0,0,0,0,0,0,0,0,0,0,0,0,0,0,0,0,0,0,0,0,0,0,0
0,0,0,0,0,0,0,0,0,0,0,0,0,0,0,0,0,0,0,0,0,0,0,0,0,0,0,0,0,0,0,0,0,0,0,0
0,0,0,0,0,0,0,0,0,0,0,0,0,0,0,0,0,0,0,0,0,0,0,0,0,0,0,0,0,0,0,0,0,0,0,0
0,0,0,0,0,0,0,0,0,0,0,0,0,0,0,0,0,0,0,0,0,0,0,0,0,0,0,0,0,0,0,0,0,0,0,0
0,0,0,0,0,0,0,0,0,0,0,0,0,0,0,0,0,0,0,0,0,0,0,0,0,0,0,0,0,0,0,0,0,0,0,0
0,0,0,0,0,0,0,0,0,0,0,0,0,0,0,0,0,0,0,0,0,0,0,0,0,0,0,0,0,0,0,0,0,0,0,0
0,0,0,0,0,0,0,0,0,0,0,0,0,0,0,0,0,0,0,0,0,0,0,0,0,0,0,0,0,0,0,0,0,0,0,0
0,0,0,0,0,0,0,0,0,0,0,0,0,0,0,0,0,0,0,0,0,0,0,0,0,0,0,0,0,0,0,0,0,0,0,0
0,0,0,0,0,0,0,0,0,0,0,0,0,0,0,0,0,0,0,0,0,0,0,0,0,0,0,0,0,0,0,0,0,0,0,0
0,0,0,0,0,0,0,0,0,0,0,0,0,0,0,0,0,0,0,0,0,0,0,0,0,0,0,0,0,0,0,0,0,0,0,0
0,0,0,0,0,0,0,0,0,0,0,0,0,0,0,0,0,0,0,0,0,0,0,0,0,0,0,0,0,0,0,0,0,0,0,0
0,0,0,0,0,0,0,0,0,0,0,0,0,0,0,0,0,0,0,0,0,0,0,0,0,0,0,0,0,0,0,0,0,0,0,0
0,0,0,0,0,0,0,0,0,0,0,0,0,0,0,0,0,0,0,0,0,0,0,0,0,0,0,0,0,0,0,0,0,0,0,0
0,0,0,0,0,0,0,0,0,0,0,0,0,0,0,0,0,0,0,0,0,0,0,0,0,0,0,0,0,0,0,0,0,0,0,0
0,0,0,0,0,0,0,0,0,0,0,0,0,0,0,0,0,0,0,0,0,0,0,0,0,0,0,0,0,0,0,0,0,0,0,0
0,0,0,0,0,0,0,0,0,0,0,0,0,0,0,0,0,0,0,0,0,0,0,0,0,0,0,0,0,0,0,0,0,0,0,0
0,0,0,0,0,0,0,0,0,0,0,0,0,0,0,0,0,0,0,0,0,0,0,0,0,0,0,0,0,0,0,0,0,0,0,0
0,0,0,0,0,0,0,0,0,0,0,0,0,0,0,0,0,0,0,0,0,0,0,0,0,0,0,0,0,0,0,0,0,0,0,0
0,0,0,0,0,0,0,0,0,0,0,0,0,0,0,0,0,0,0,0,0,0,0,0,0,0,0,0,0,0,0,0,0,0,0,0
0,0,0,0,0,0,0,0,0,0,0,0,0,0,0,0,0,0,0,0,0,0,0,0,0,0,0,0,0,0,0,0,0,0,0,0
0,0,0,0,0,0,0,0,0,0,0,0,0,0,0,0,0,0,0,0,0,0,0,0,0,0,0,0,0,0,0,0,0,0,0,0
0,0,0,0,0,0,0,0,0,0,0,0,0,0,0,0,0,0,0,0,0,0,0,0,0,0,0,0,0,0,0,0,0,0,0,0
:endlayer
layer: 14
0,0,0,0,0,0,0,0,0,0,0,0,0,0,0,0,0,0,0,0,0,0,0,0,0,0,0,0,0,0,0,0,0,0,0,0
0,0,0,0,0,0,0,0,0,0,0,0,0,0,0,0,0,0,0,0,0,0,0,0,0,0,0,0,0,0,0,0,0,0,0,0
0,0,0,0,0,0,52,51,53,0,0,0,0,0,0,0,0,0,0,0,0,0,0,0,0,0,0,0,0,0,0,0,0,0,0,0
0,0,0,0,0,51,2,14,2,51,0,0,0,0,0,0,0,0,0,0,0,0,0,0,0,0,0,0,0,0,0,0,0,0,0,0
0,0,0,0,60,2,0,0,0,2,60,0,0,0,0,0,0,0,0,0,0,0,0,0,0,0,0,0,0,0,0,0,0,0,0,0
0,0,0,52,2,0,0,0,0,0,2,53,0,0,0,0,0,0,0,0,0,0,0,0,0,0,0,0,0,0,0,0,0,0,0,0
0,0,51,2,0,0,0,0,0,0,0,2,51,0,0,0,0,0,0,0,0,0,0,0,0,0,0,0,0,0,0,0,0,0,0,0
0,0,52,14,0,0,0,137,0,0,0,14,53,0,0,0,0,0,0,0,0,0,0,0,0,0,0,0,0,0,0,0,0,0,0,0
0,0,59,2,0,0,0,0,0,0,0,2,59,0,0,0,0,0,0,0,0,0,0,0,0,0,0,0,0,0,0,0,0,0,0,0
0,0,0,52,2,0,0,0,0,0,2,53,0,0,0,0,0,0,0,0,0,0,0,0,0,0,0,0,0,0,0,0,0,0,0,0
0,0,0,0,60,2,0,0,0,2,60,0,0,0,0,0,0,0,0,0,0,0,0,0,0,0,0,0,0,0,0,0,0,0,0,0
0,0,0,0,0,59,2,14,2,59,0,0,0,0,0,0,0,0,0,0,0,0,0,0,0,0,0,0,0,0,0,0,0,0,0,0
0,0,0,0,0,0,52,4,53,0,0,0,0,0,0,0,0,0,0,0,0,0,0,0,0,0,0,0,0,0,0,0,0,0,0,0
0,0,0,0,0,0,0,47,0,0,0,0,0,0,0,0,0,0,0,0,0,0,0,0,0,0,0,0,0,0,0,0,0,0,0,0
0,138,139,140,141,142,143,144,145,146,147,148,149,150,0,0,0,0,0,0,0,0,0,0,0,0,0,0,0,0,0,0,0,0,0,0
0,0,0,0,0,0,0,0,0,0,0,0,0,0,0,0,0,0,0,0,0,0,0,0,0,0,0,0,0,0,0,0,0,0,0,0
0,0,0,0,0,0,0,0,0,0,0,0,0,0,0,0,0,0,0,0,0,0,0,0,0,0,0,0,0,0,0,0,0,0,0,0
0,0,0,0,0,0,0,0,0,0,0,0,0,0,0,0,0,0,0,0,0,0,0,0,0,0,0,0,0,0,0,0,0,0,0,0
0,0,0,0,0,0,0,0,0,0,0,0,0,0,0,0,0,0,0,0,0,0,0,0,0,0,0,0,0,0,0,0,0,0,0,0
0,0,0,0,0,0,0,0,0,0,0,0,0,0,0,0,0,0,0,0,0,0,0,0,0,0,0,0,0,0,0,0,0,0,0,0
0,0,0,0,0,0,0,0,0,0,0,0,0,0,0,0,0,0,0,0,0,0,0,0,0,0,0,0,0,0,0,0,0,0,0,0
0,0,0,0,0,0,0,0,0,0,0,0,0,0,0,0,0,0,0,0,0,0,0,0,0,0,0,0,0,0,0,0,0,0,0,0
0,0,0,0,0,0,0,0,0,0,0,0,0,0,0,0,0,0,0,0,0,0,0,0,0,0,0,0,0,0,0,0,0,0,0,0
0,0,0,0,0,0,0,0,0,0,0,0,0,0,0,0,0,0,0,0,0,0,0,0,0,0,0,0,0,0,0,0,0,0,0,0
0,0,0,0,0,0,0,0,0,0,0,0,0,0,0,0,0,0,0,0,0,0,0,0,0,0,0,0,0,0,0,0,0,0,0,0
0,0,0,0,0,0,0,0,0,0,0,0,0,0,0,0,0,0,0,0,0,0,0,0,0,0,0,0,0,0,0,0,0,0,0,0
0,0,0,0,0,0,0,0,0,0,0,0,0,0,0,0,0,0,0,0,0,0,0,0,0,0,0,0,0,0,0,0,0,0,0,0
0,0,0,0,0,0,0,0,0,0,0,0,0,0,0,0,0,0,0,0,0,0,0,0,0,0,0,0,0,0,0,0,0,0,0,0
0,0,0,0,0,0,0,0,0,0,0,0,0,0,0,0,0,0,0,0,0,0,0,0,0,0,0,0,0,0,0,0,0,0,0,0
0,0,0,0,0,0,0,0,0,0,0,0,0,0,0,0,0,0,0,0,0,0,0,0,0,0,0,0,0,0,0,0,0,0,0,0
0,0,0,0,0,0,0,0,0,0,0,0,0,0,0,0,0,0,0,0,0,0,0,0,0,0,0,0,0,0,0,0,0,0,0,0
0,0,0,0,0,0,0,0,0,0,0,0,0,0,0,0,0,0,0,0,0,0,0,0,0,0,0,0,0,0,0,0,0,0,0,0
0,0,0,0,0,0,0,0,0,0,0,0,0,0,0,0,0,0,0,0,0,0,0,0,0,0,0,0,0,0,0,0,0,0,0,0
0,0,0,0,0,0,0,0,0,0,0,0,0,0,0,0,0,0,0,0,0,0,0,0,0,0,0,0,0,0,0,0,0,0,0,0
0,0,0,0,0,0,0,0,0,0,0,0,0,0,0,0,0,0,0,0,0,0,0,0,0,0,0,0,0,0,0,0,0,0,0,0
0,0,0,0,0,0,0,0,0,0,0,0,0,0,0,0,0,0,0,0,0,0,0,0,0,0,0,0,0,0,0,0,0,0,0,0
0,0,0,0,0,0,0,0,0,0,0,0,0,0,0,0,0,0,0,0,0,0,0,0,0,0,0,0,0,0,0,0,0,0,0,0
0,0,0,0,0,0,0,0,0,0,0,0,0,0,0,0,0,0,0,0,0,0,0,0,0,0,0,0,0,0,0,0,0,0,0,0
0,0,0,0,0,0,0,0,0,0,0,0,0,0,0,0,0,0,0,0,0,0,0,0,0,0,0,0,0,0,0,0,0,0,0,0
0,0,0,0,0,0,0,0,0,0,0,0,0,0,0,0,0,0,0,0,0,0,0,0,0,0,0,0,0,0,0,0,0,0,0,0
0,0,0,0,0,0,0,0,0,0,0,0,0,0,0,0,0,0,0,0,0,0,0,0,0,0,0,0,0,0,0,0,0,0,0,0
:endlayer
layer: 15
0,0,0,0,0,0,0,0,0,0,0,0,0,0,0,0,0,0,0,0,0,0,0,0,0,0,0,0,0,0,0,0,0,0,0,0
0,0,0,0,0,0,0,0,0,0,0,0,0,0,0,0,0,0,0,0,0,0,0,0,0,0,0,0,0,0,0,0,0,0,0,0
0,0,0,0,0,0,0,0,0,0,0,0,0,0,0,0,0,0,0,0,0,0,0,0,0,0,0,0,0,0,0,0,0,0,0,0
0,0,0,0,0,0,60,2,60,0,0,0,0,0,0,0,0,0,0,0,0,0,0,0,0,0,0,0,0,0,0,0,0,0,0,0
0,0,0,0,0,60,0,0,0,60,0,0,0,0,0,0,0,0,0,0,0,0,0,0,0,0,0,0,0,0,0,0,0,0,0,0
0,0,0,0,60,0,0,0,0,0,60,0,0,0,0,0,0,0,0,0,0,0,0,0,0,0,0,0,0,0,0,0,0,0,0,0
0,0,0,60,0,0,0,0,0,0,0,60,0,0,0,0,0,0,0,0,0,0,0,0,0,0,0,0,0,0,0,0,0,0,0,0
0,0,0,2,0,0,0,151,0,0,0,2,0,0,0,0,0,0,0,0,0,0,0,0,0,0,0,0,0,0,0,0,0,0,0,0
0,0,0,60,0,0,0,152,0,0,0,60,0,0,0,0,0,0,0,0,0,0,0,0,0,0,0,0,0,0,0,0,0,0,0,0
0,0,0,0,60,0,0,153,0,0,60,0,0,0,0,0,0,0,0,0,0,0,0,0,0,0,0,0,0,0,0,0,0,0,0,0
0,0,0,0,0,60,0,154,0,60,0,0,0,0,0,0,0,0,0,0,0,0,0,0,0,0,0,0,0,0,0,0,0,0,0,0
0,0,0,0,0,0,60,155,60,0,0,0,0,0,0,0,0,0,0,0,0,0,0,0,0,0,0,0,0,0,0,0,0,0,0,0
0,0,0,0,0,0,29,156,29,0,0,0,0,0,0,0,0,0,0,0,0,0,0,0,0,0,0,0,0,0,0,0,0,0,0,0
0,0,0,0,0,0,0,157,0,0,0,0,0,0,0,0,0,0,0,0,0,0,0,0,0,0,0,0,0,0,0,0,0,0,0,0
0,158,159,160,161,162,163,164,165,166,167,168,169,170,0,0,0,0,0,0,0,0,0,0,0,0,0,0,0,0,0,0,0,0,0,0
0,0,0,0,0,0,0,0,0,0,0,0,0,0,0,0,0,0,0,0,0,0,0,0,0,0,0,0,0,0,0,0,0,0,0,0
0,0,0,0,0,0,0,0,0,0,0,0,0,0,0,0,0,0,0,0,0,0,0,0,0,0,0,0,0,0,0,0,0,0,0,0
0,0,0,0,0,0,0,0,0,0,0,0,0,0,0,0,0,0,0,0,0,0,0,0,0,0,0,0,0,0,0,0,0,0,0,0
0,0,0,0,0,0,0,0,0,0,0,0,0,0,0,0,0,0,0,0,0,0,0,0,0,0,0,0,0,0,0,0,0,0,0,0
0,0,0,0,0,0,0,0,0,0,0,0,0,0,0,0,0,0,0,0,0,0,0,0,0,0,0,0,0,0,0,0,0,0,0,0
0,0,0,0,0,0,0,0,0,0,0,0,0,0,0,0,0,0,0,0,0,0,0,0,0,0,0,0,0,0,0,0,0,0,0,0
0,0,0,0,0,0,0,0,0,0,0,0,0,0,0,0,0,0,0,0,0,0,0,0,0,0,0,0,0,0,0,0,0,0,0,0
0,0,0,0,0,0,0,0,0,0,0,0,0,0,0,0,0,0,0,0,0,0,0,0,0,0,0,0,0,0,0,0,0,0,0,0
0,0,0,0,0,0,0,0,0,0,0,0,0,0,0,0,0,0,0,0,0,0,0,0,0,0,0,0,0,0,0,0,0,0,0,0
0,0,0,0,0,0,0,0,0,0,0,0,0,0,0,0,0,0,0,0,0,0,0,0,0,0,0,0,0,0,0,0,0,0,0,0
0,0,0,0,0,0,0,0,0,0,0,0,0,0,0,0,0,0,0,0,0,0,0,0,0,0,0,0,0,0,0,0,0,0,0,0
0,0,0,0,0,0,0,0,0,0,0,0,0,0,0,0,0,0,0,0,0,0,0,0,0,0,0,0,0,0,0,0,0,0,0,0
0,0,0,0,0,0,0,0,0,0,0,0,0,0,0,0,0,0,0,0,0,0,0,0,0,0,0,0,0,0,0,0,0,0,0,0
0,0,0,0,0,0,0,0,0,0,0,0,0,0,0,0,0,0,0,0,0,0,0,0,0,0,0,0,0,0,0,0,0,0,0,0
0,0,0,0,0,0,0,0,0,0,0,0,0,0,0,0,0,0,0,0,0,0,0,0,0,0,0,0,0,0,0,0,0,0,0,0
0,0,0,0,0,0,0,0,0,0,0,0,0,0,0,0,0,0,0,0,0,0,0,0,0,0,0,0,0,0,0,0,0,0,0,0
0,0,0,0,0,0,0,0,0,0,0,0,0,0,0,0,0,0,0,0,0,0,0,0,0,0,0,0,0,0,0,0,0,0,0,0
0,0,0,0,0,0,0,0,0,0,0,0,0,0,0,0,0,0,0,0,0,0,0,0,0,0,0,0,0,0,0,0,0,0,0,0
0,0,0,0,0,0,0,0,0,0,0,0,0,0,0,0,0,0,0,0,0,0,0,0,0,0,0,0,0,0,0,0,0,0,0,0
0,0,0,0,0,0,0,0,0,0,0,0,0,0,0,0,0,0,0,0,0,0,0,0,0,0,0,0,0,0,0,0,0,0,0,0
0,0,0,0,0,0,0,0,0,0,0,0,0,0,0,0,0,0,0,0,0,0,0,0,0,0,0,0,0,0,0,0,0,0,0,0
0,0,0,0,0,0,0,0,0,0,0,0,0,0,0,0,0,0,0,0,0,0,0,0,0,0,0,0,0,0,0,0,0,0,0,0
0,0,0,0,0,0,0,0,0,0,0,0,0,0,0,0,0,0,0,0,0,0,0,0,0,0,0,0,0,0,0,0,0,0,0,0
0,0,0,0,0,0,0,0,0,0,0,0,0,0,0,0,0,0,0,0,0,0,0,0,0,0,0,0,0,0,0,0,0,0,0,0
0,0,0,0,0,0,0,0,0,0,0,0,0,0,0,0,0,0,0,0,0,0,0,0,0,0,0,0,0,0,0,0,0,0,0,0
0,0,0,0,0,0,0,0,0,0,0,0,0,0,0,0,0,0,0,0,0,0,0,0,0,0,0,0,0,0,0,0,0,0,0,0
:endlayer
layer: 16
0,0,0,0,0,0,0,0,0,0,0,0,0,0,0,0,0,0,0,0,0,0,0,0,0,0,0,0,0,0,0,0,0,0,0,0
0,0,0,0,0,0,0,0,0,0,0,0,0,0,0,0,0,0,0,0,0,0,0,0,0,0,0,0,0,0,0,0,0,0,0,0
0,0,0,0,0,0,0,0,0,0,0,0,0,0,0,0,0,0,0,0,0,0,0,0,0,0,0,0,0,0,0,0,0,0,0,0
0,0,0,0,0,0,51,2,51,0,0,0,0,0,0,0,0,0,0,0,0,0,0,0,0,0,0,0,0,0,0,0,0,0,0,0
0,0,0,0,0,51,2,26,2,51,0,0,0,0,0,0,0,0,0,0,0,0,0,0,0,0,0,0,0,0,0,0,0,0,0,0
0,0,0,0,52,2,0,0,0,2,53,0,0,0,0,0,0,0,0,0,0,0,0,0,0,0,0,0,0,0,0,0,0,0,0,0
0,0,0,52,2,0,0,0,0,0,2,53,0,0,0,0,0,0,0,0,0,0,0,0,0,0,0,0,0,0,0,0,0,0,0,0
0,0,0,2,36,0,0,0,0,0,35,2,0,0,0,0,0,0,0,0,0,0,0,0,0,0,0,0,0,0,0,0,0,0,0,0
0,0,0,52,2,0,0,0,0,0,2,53,0,0,0,0,0,0,0,0,0,0,0,0,0,0,0,0,0,0,0,0,0,0,0,0
0,0,0,0,52,2,0,0,0,2,53,0,0,0,0,0,0,0,0,0,0,0,0,0,0,0,0,0,0,0,0,0,0,0,0,0
0,0,0,0,0,59,2,23,2,59,0,0,0,0,0,0,0,0,0,0,0,0,0,0,0,0,0,0,0,0,0,0,0,0,0,0
0,0,0,0,0,0,59,2,59,0,0,0,0,0,0,0,0,0,0,0,0,0,0,0,0,0,0,0,0,0,0,0,0,0,0,0
0,0,0,0,0,0,80,48,80,0,0,0,0,0,0,0,0,0,0,0,0,0,0,0,0,0,0,0,0,0,0,0,0,0,0,0
0,0,0,0,0,0,0,0,0,0,0,0,0,0,0,0,0,0,0,0,0,0,0,0,0,0,0,0,0,0,0,0,0,0,0,0
0,171,172,173,174,175,176,177,178,179,180,181,182,183,0,0,0,0,0,0,0,0,0,0,0,0,0,0,0,0,0,0,0,0,0,0
0,0,0,0,0,0,0,0,0,0,0,0,0,0,0,0,0,0,0,0,0,0,0,0,0,0,0,0,0,0,0,0,0,0,0,0
0,0,0,0,0,0,0,0,0,0,0,0,0,0,0,0,0,0,0,0,0,0,0,0,0,0,0,0,0,0,0,0,0,0,0,0
0,0,0,0,0,0,0,0,0,0,0,0,0,0,0,0,0,0,0,0,0,0,0,0,0,0,0,0,0,0,0,0,0,0,0,0
0,0,0,0,0,0,0,0,0,0,0,0,0,0,0,0,0,0,0,0,0,0,0,0,0,0,0,0,0,0,0,0,0,0,0,0
0,0,0,0,0,0,0,0,0,0,0,0,0,0,0,0,0,0,0,0,0,0,0,0,0,0,0,0,0,0,0,0,0,0,0,0
0,0,0,0,0,0,0,0,0,0,0,0,0,0,0,0,0,0,0,0,0,0,0,0,0,0,0,0,0,0,0,0,0,0,0,0
0,0,0,0,0,0,0,0,0,0,0,0,0,0,0,0,0,0,0,0,0,0,0,0,0,0,0,0,0,0,0,0,0,0,0,0
0,0,0,0,0,0,0,0,0,0,0,0,0,0,0,0,0,0,0,0,0,0,0,0,0,0,0,0,0,0,0,0,0,0,0,0
0,0,0,0,0,0,0,0,0,0,0,0,0,0,0,0,0,0,0,0,0,0,0,0,0,0,0,0,0,0,0,0,0,0,0,0
0,0,0,0,0,0,0,0,0,0,0,0,0,0,0,0,0,0,0,0,0,0,0,0,0,0,0,0,0,0,0,0,0,0,0,0
0,0,0,0,0,0,0,0,0,0,0,0,0,0,0,0,0,0,0,0,0,0,0,0,0,0,0,0,0,0,0,0,0,0,0,0
0,0,0,0,0,0,0,0,0,0,0,0,0,0,0,0,0,0,0,0,0,0,0,0,0,0,0,0,0,0,0,0,0,0,0,0
0,0,0,0,0,0,0,0,0,0,0,0,0,0,0,0,0,0,0,0,0,0,0,0,0,0,0,0,0,0,0,0,0,0,0,0
0,0,0,0,0,0,0,0,0,0,0,0,0,0,0,0,0,0,0,0,0,0,0,0,0,0,0,0,0,0,0,0,0,0,0,0
0,0,0,0,0,0,0,0,0,0,0,0,0,0,0,0,0,0,0,0,0,0,0,0,0,0,0,0,0,0,0,0,0,0,0,0
0,0,0,0,0,0,0,0,0,0,0,0,0,0,0,0,0,0,0,0,0,0,0,0,0,0,0,0,0,0,0,0,0,0,0,0
0,0,0,0,0,0,0,0,0,0,0,0,0,0,0,0,0,0,0,0,0,0,0,0,0,0,0,0,0,0,0,0,0,0,0,0
0,0,0,0,0,0,0,0,0,0,0,0,0,0,0,0,0,0,0,0,0,0,0,0,0,0,0,0,0,0,0,0,0,0,0,0
0,0,0,0,0,0,0,0,0,0,0,0,0,0,0,0,0,0,0,0,0,0,0,0,0,0,0,0,0,0,0,0,0,0,0,0
0,0,0,0,0,0,0,0,0,0,0,0,0,0,0,0,0,0,0,0,0,0,0,0,0,0,0,0,0,0,0,0,0,0,0,0
0,0,0,0,0,0,0,0,0,0,0,0,0,0,0,0,0,0,0,0,0,0,0,0,0,0,0,0,0,0,0,0,0,0,0,0
0,0,0,0,0,0,0,0,0,0,0,0,0,0,0,0,0,0,0,0,0,0,0,0,0,0,0,0,0,0,0,0,0,0,0,0
0,0,0,0,0,0,0,0,0,0,0,0,0,0,0,0,0,0,0,0,0,0,0,0,0,0,0,0,0,0,0,0,0,0,0,0
0,0,0,0,0,0,0,0,0,0,0,0,0,0,0,0,0,0,0,0,0,0,0,0,0,0,0,0,0,0,0,0,0,0,0,0
0,0,0,0,0,0,0,0,0,0,0,0,0,0,0,0,0,0,0,0,0,0,0,0,0,0,0,0,0,0,0,0,0,0,0,0
0,0,0,0,0,0,0,0,0,0,0,0,0,0,0,0,0,0,0,0,0,0,0,0,0,0,0,0,0,0,0,0,0,0,0,0
:endlayer
layer: 17
0,0,0,0,0,0,0,0,0,0,0,0,0,0,0,0,0,0,0,0,0,0,0,0,0,0,0,0,0,0,0,0,0,0,0,0
0,0,0,0,0,0,0,0,0,0,0,0,0,0,0,0,0,0,0,0,0,0,0,0,0,0,0,0,0,0,0,0,0,0,0,0
0,0,0,0,0,0,0,0,0,0,0,0,0,0,0,0,0,0,0,0,0,0,0,0,0,0,0,0,0,0,0,0,0,0,0,0
0,0,0,0,0,0,0,51,0,0,0,0,0,0,0,0,0,0,0,0,0,0,0,0,0,0,0,0,0,0,0,0,0,0,0,0
0,0,0,0,0,0,51,2,51,0,0,0,0,0,0,0,0,0,0,0,0,0,0,0,0,0,0,0,0,0,0,0,0,0,0,0
0,0,0,0,0,60,2,0,2,60,0,0,0,0,0,0,0,0,0,0,0,0,0,0,0,0,0,0,0,0,0,0,0,0,0,0
0,0,0,0,52,2,0,0,0,2,53,0,0,0,0,0,0,0,0,0,0,0,0,0,0,0,0,0,0,0,0,0,0,0,0,0
0,0,0,52,2,0,0,0,0,0,2,53,0,0,0,0,0,0,0,0,0,0,0,0,0,0,0,0,0,0,0,0,0,0,0,0
0,0,0,0,52,2,0,0,0,2,53,0,0,0,0,0,0,0,0,0,0,0,0,0,0,0,0,0,0,0,0,0,0,0,0,0
0,0,0,0,0,60,2,0,2,60,0,0,0,0,0,0,0,0,0,0,0,0,0,0,0,0,0,0,0,0,0,0,0,0,0,0
0,0,0,0,0,0,59,2,59,0,0,0,0,0,0,0,0,0,0,0,0,0,0,0,0,0,0,0,0,0,0,0,0,0,0,0
0,0,0,0,0,0,0,59,0,0,0,0,0,0,0,0,0,0,0,0,0,0,0,0,0,0,0,0,0,0,0,0,0,0,0,0
0,0,0,0,0,0,0,0,0,0,0,0,0,0,0,0,0,0,0,0,0,0,0,0,0,0,0,0,0,0,0,0,0,0,0,0
0,0,0,0,0,0,0,0,0,0,0,0,0,0,0,0,0,0,0,0,0,0,0,0,0,0,0,0,0,0,0,0,0,0,0,0
0,184,185,186,187,188,189,190,191,192,193,194,195,196,0,0,0,0,0,0,0,0,0,0,0,0,0,0,0,0,0,0,0,0,0,0
0,0,0,0,0,0,0,0,0,0,0,0,0,0,0,0,0,0,0,0,0,0,0,0,0,0,0,0,0,0,0,0,0,0,0,0
0,0,0,0,0,0,0,0,0,0,0,0,0,0,0,0,0,0,0,0,0,0,0,0,0,0,0,0,0,0,0,0,0,0,0,0
0,0,0,0,0,0,0,0,0,0,0,0,0,0,0,0,0,0,0,0,0,0,0,0,0,0,0,0,0,0,0,0,0,0,0,0
0,0,0,0,0,0,0,0,0,0,0,0,0,0,0,0,0,0,0,0,0,0,0,0,0,0,0,0,0,0,0,0,0,0,0,0
0,0,0,0,0,0,0,0,0,0,0,0,0,0,0,0,0,0,0,0,0,0,0,0,0,0,0,0,0,0,0,0,0,0,0,0
0,0,0,0,0,0,0,0,0,0,0,0,0,0,0,0,0,0,0,0,0,0,0,0,0,0,0,0,0,0,0,0,0,0,0,0
0,0,0,0,0,0,0,0,0,0,0,0,0,0,0,0,0,0,0,0,0,0,0,0,0,0,0,0,0,0,0,0,0,0,0,0
0,0,0,0,0,0,0,0,0,0,0,0,0,0,0,0,0,0,0,0,0,0,0,0,0,0,0,0,0,0,0,0,0,0,0,0
0,0,0,0,0,0,0,0,0,0,0,0,0,0,0,0,0,0,0,0,0,0,0,0,0,0,0,0,0,0,0,0,0,0,0,0
0,0,0,0,0,0,0,0,0,0,0,0,0,0,0,0,0,0,0,0,0,0,0,0,0,0,0,0,0,0,0,0,0,0,0,0
0,0,0,0,0,0,0,0,0,0,0,0,0,0,0,0,0,0,0,0,0,0,0,0,0,0,0,0,0,0,0,0,0,0,0,0
0,0,0,0,0,0,0,0,0,0,0,0,0,0,0,0,0,0,0,0,0,0,0,0,0,0,0,0,0,0,0,0,0,0,0,0
0,0,0,0,0,0,0,0,0,0,0,0,0,0,0,0,0,0,0,0,0,0,0,0,0,0,0,0,0,0,0,0,0,0,0,0
0,0,0,0,0,0,0,0,0,0,0,0,0,0,0,0,0,0,0,0,0,0,0,0,0,0,0,0,0,0,0,0,0,0,0,0
0,0,0,0,0,0,0,0,0,0,0,0,0,0,0,0,0,0,0,0,0,0,0,0,0,0,0,0,0,0,0,0,0,0,0,0
0,0,0,0,0,0,0,0,0,0,0,0,0,0,0,0,0,0,0,0,0,0,0,0,0,0,0,0,0,0,0,0,0,0,0,0
0,0,0,0,0,0,0,0,0,0,0,0,0,0,0,0,0,0,0,0,0,0,0,0,0,0,0,0,0,0,0,0,0,0,0,0
0,0,0,0,0,0,0,0,0,0,0,0,0,0,0,0,0,0,0,0,0,0,0,0,0,0,0,0,0,0,0,0,0,0,0,0
0,0,0,0,0,0,0,0,0,0,0,0,0,0,0,0,0,0,0,0,0,0,0,0,0,0,0,0,0,0,0,0,0,0,0,0
0,0,0,0,0,0,0,0,0,0,0,0,0,0,0,0,0,0,0,0,0,0,0,0,0,0,0,0,0,0,0,0,0,0,0,0
0,0,0,0,0,0,0,0,0,0,0,0,0,0,0,0,0,0,0,0,0,0,0,0,0,0,0,0,0,0,0,0,0,0,0,0
0,0,0,0,0,0,0,0,0,0,0,0,0,0,0,0,0,0,0,0,0,0,0,0,0,0,0,0,0,0,0,0,0,0,0,0
0,0,0,0,0,0,0,0,0,0,0,0,0,0,0,0,0,0,0,0,0,0,0,0,0,0,0,0,0,0,0,0,0,0,0,0
0,0,0,0,0,0,0,0,0,0,0,0,0,0,0,0,0,0,0,0,0,0,0,0,0,0,0,0,0,0,0,0,0,0,0,0
0,0,0,0,0,0,0,0,0,0,0,0,0,0,0,0,0,0,0,0,0,0,0,0,0,0,0,0,0,0,0,0,0,0,0,0
0,0,0,0,0,0,0,0,0,0,0,0,0,0,0,0,0,0,0,0,0,0,0,0,0,0,0,0,0,0,0,0,0,0,0,0
:endlayer
layer: 18
0,0,0,0,0,0,0,0,0,0,0,0,0,0,0,0,0,0,0,0,0,0,0,0,0,0,0,0,0,0,0,0,0,0,0,0
0,0,0,0,0,0,0,0,0,0,0,0,0,0,0,0,0,0,0,0,0,0,0,0,0,0,0,0,0,0,0,0,0,0,0,0
0,0,0,0,0,0,0,0,0,0,0,0,0,0,0,0,0,0,0,0,0,0,0,0,0,0,0,0,0,0,0,0,0,0,0,0
0,0,0,0,0,0,0,0,0,0,0,0,0,0,0,0,0,0,0,0,0,0,0,0,0,0,0,0,0,0,0,0,0,0,0,0
0,0,0,0,0,0,0,51,0,0,0,0,0,0,0,0,0,0,0,0,0,0,0,0,0,0,0,0,0,0,0,0,0,0,0,0
0,0,0,0,0,0,51,2,51,0,0,0,0,0,0,0,0,0,0,0,0,0,0,0,0,0,0,0,0,0,0,0,0,0,0,0
0,0,0,0,0,52,2,26,2,53,0,0,0,0,0,0,0,0,0,0,0,0,0,0,0,0,0,0,0,0,0,0,0,0,0,0
0,0,0,0,52,2,36,0,35,2,53,0,0,0,0,0,0,0,0,0,0,0,0,0,0,0,0,0,0,0,0,0,0,0,0,0
0,0,0,0,0,52,2,23,2,53,0,0,0,0,0,0,0,0,0,0,0,0,0,0,0,0,0,0,0,0,0,0,0,0,0,0
0,0,0,0,0,0,59,2,59,0,0,0,0,0,0,0,0,0,0,0,0,0,0,0,0,0,0,0,0,0,0,0,0,0,0,0
0,0,0,0,0,0,0,59,0,0,0,0,0,0,0,0,0,0,0,0,0,0,0,0,0,0,0,0,0,0,0,0,0,0,0,0
0,0,0,0,0,0,0,0,0,0,0,0,0,0,0,0,0,0,0,0,0,0,0,0,0,0,0,0,0,0,0,0,0,0,0,0
0,0,0,0,0,0,0,0,0,0,0,0,0,0,0,0,0,0,0,0,0,0,0,0,0,0,0,0,0,0,0,0,0,0,0,0
0,0,0,0,0,0,0,0,0,0,0,0,0,0,0,0,0,0,0,0,0,0,0,0,0,0,0,0,0,0,0,0,0,0,0,0
0,197,198,199,200,201,202,203,204,205,206,207,208,209,0,0,0,0,0,0,0,0,0,0,0,0,0,0,0,0,0,0,0,0,0,0
0,0,0,0,0,0,0,0,0,0,0,0,0,0,0,0,0,0,0,0,0,0,0,0,0,0,0,0,0,0,0,0,0,0,0,0
0,0,0,0,0,0,0,0,0,0,0,0,0,0,0,0,0,0,0,0,0,0,0,0,0,0,0,0,0,0,0,0,0,0,0,0
0,0,0,0,0,0,0,0,0,0,0,0,0,0,0,0,0,0,0,0,0,0,0,0,0,0,0,0,0,0,0,0,0,0,0,0
0,0,0,0,0,0,0,0,0,0,0,0,0,0,0,0,0,0,0,0,0,0,0,0,0,0,0,0,0,0,0,0,0,0,0,0
0,0,0,0,0,0,0,0,0,0,0,0,0,0,0,0,0,0,0,0,0,0,0,0,0,0,0,0,0,0,0,0,0,0,0,0
0,0,0,0,0,0,0,0,0,0,0,0,0,0,0,0,0,0,0,0,0,0,0,0,0,0,0,0,0,0,0,0,0,0,0,0
0,0,0,0,0,0,0,0,0,0,0,0,0,0,0,0,0,0,0,0,0,0,0,0,0,0,0,0,0,0,0,0,0,0,0,0
0,0,0,0,0,0,0,0,0,0,0,0,0,0,0,0,0,0,0,0,0,0,0,0,0,0,0,0,0,0,0,0,0,0,0,0
0,0,0,0,0,0,0,0,0,0,0,0,0,0,0,0,0,0,0,0,0,0,0,0,0,0,0,0,0,0,0,0,0,0,0,0
0,0,0,0,0,0,0,0,0,0,0,0,0,0,0,0,0,0,0,0,0,0,0,0,0,0,0,0,0,0,0,0,0,0,0,0
0,0,0,0,0,0,0,0,0,0,0,0,0,0,0,0,0,0,0,0,0,0,0,0,0,0,0,0,0,0,0,0,0,0,0,0
0,0,0,0,0,0,0,0,0,0,0,0,0,0,0,0,0,0,0,0,0,0,0,0,0,0,0,0,0,0,0,0,0,0,0,0
0,0,0,0,0,0,0,0,0,0,0,0,0,0,0,0,0,0,0,0,0,0,0,0,0,0,0,0,0,0,0,0,0,0,0,0
0,0,0,0,0,0,0,0,0,0,0,0,0,0,0,0,0,0,0,0,0,0,0,0,0,0,0,0,0,0,0,0,0,0,0,0
0,0,0,0,0,0,0,0,0,0,0,0,0,0,0,0,0,0,0,0,0,0,0,0,0,0,0,0,0,0,0,0,0,0,0,0
0,0,0,0,0,0,0,0,0,0,0,0,0,0,0,0,0,0,0,0,0,0,0,0,0,0,0,0,0,0,0,0,0,0,0,0
0,0,0,0,0,0,0,0,0,0,0,0,0,0,0,0,0,0,0,0,0,0,0,0,0,0,0,0,0,0,0,0,0,0,0,0
0,0,0,0,0,0,0,0,0,0,0,0,0,0,0,0,0,0,0,0,0,0,0,0,0,0,0,0,0,0,0,0,0,0,0,0
0,0,0,0,0,0,0,0,0,0,0,0,0,0,0,0,0,0,0,0,0,0,0,0,0,0,0,0,0,0,0,0,0,0,0,0
0,0,0,0,0,0,0,0,0,0,0,0,0,0,0,0,0,0,0,0,0,0,0,0,0,0,0,0,0,0,0,0,0,0,0,0
0,0,0,0,0,0,0,0,0,0,0,0,0,0,0,0,0,0,0,0,0,0,0,0,0,0,0,0,0,0,0,0,0,0,0,0
0,0,0,0,0,0,0,0,0,0,0,0,0,0,0,0,0,0,0,0,0,0,0,0,0,0,0,0,0,0,0,0,0,0,0,0
0,0,0,0,0,0,0,0,0,0,0,0,0,0,0,0,0,0,0,0,0,0,0,0,0,0,0,0,0,0,0,0,0,0,0,0
0,0,0,0,0,0,0,0,0,0,0,0,0,0,0,0,0,0,0,0,0,0,0,0,0,0,0,0,0,0,0,0,0,0,0,0
0,0,0,0,0,0,0,0,0,0,0,0,0,0,0,0,0,0,0,0,0,0,0,0,0,0,0,0,0,0,0,0,0,0,0,0
0,0,0,0,0,0,0,0,0,0,0,0,0,0,0,0,0,0,0,0,0,0,0,0,0,0,0,0,0,0,0,0,0,0,0,0
:endlayer
layer: 19
0,0,0,0,0,0,0,0,0,0,0,0,0,0,0,0,0,0,0,0,0,0,0,0,0,0,0,0,0,0,0,0,0,0,0,0
0,0,0,0,0,0,0,0,0,0,0,0,0,0,0,0,0,0,0,0,0,0,0,0,0,0,0,0,0,0,0,0,0,0,0,0
0,0,0,0,0,0,0,0,0,0,0,0,0,0,0,0,0,0,0,0,0,0,0,0,0,0,0,0,0,0,0,0,0,0,0,0
0,0,0,0,0,0,0,0,0,0,0,0,0,0,0,0,0,0,0,0,0,0,0,0,0,0,0,0,0,0,0,0,0,0,0,0
0,0,0,0,0,0,0,0,0,0,0,0,0,0,0,0,0,0,0,0,0,0,0,0,0,0,0,0,0,0,0,0,0,0,0,0
0,0,0,0,0,0,0,51,0,0,0,0,0,0,0,0,0,0,0,0,0,0,0,0,0,0,0,0,0,0,0,0,0,0,0,0
0,0,0,0,0,0,60,2,60,0,0,0,0,0,0,0,0,0,0,0,0,0,0,0,0,0,0,0,0,0,0,0,0,0,0,0
0,0,0,0,0,52,2,0,2,53,0,0,0,0,0,0,0,0,0,0,0,0,0,0,0,0,0,0,0,0,0,0,0,0,0,0
0,0,0,0,0,0,60,2,60,0,0,0,0,0,0,0,0,0,0,0,0,0,0,0,0,0,0,0,0,0,0,0,0,0,0,0
0,0,0,0,0,0,0,59,0,0,0,0,0,0,0,0,0,0,0,0,0,0,0,0,0,0,0,0,0,0,0,0,0,0,0,0
0,0,0,0,0,0,0,0,0,0,0,0,0,0,0,0,0,0,0,0,0,0,0,0,0,0,0,0,0,0,0,0,0,0,0,0
0,0,0,0,0,0,0,0,0,0,0,0,0,0,0,0,0,0,0,0,0,0,0,0,0,0,0,0,0,0,0,0,0,0,0,0
0,0,0,0,0,0,0,0,0,0,0,0,0,0,0,0,0,0,0,0,0,0,0,0,0,0,0,0,0,0,0,0,0,0,0,0
0,0,0,0,0,0,0,0,0,0,0,0,0,0,0,0,0,0,0,0,0,0,0,0,0,0,0,0,0,0,0,0,0,0,0,0
0,210,211,212,213,214,215,216,217,218,219,220,221,222,0,0,0,0,0,0,0,0,0,0,0,0,0,0,0,0,0,0,0,0,0,0
0,0,0,0,0,0,0,0,0,0,0,0,0,0,0,0,0,0,0,0,0,0,0,0,0,0,0,0,0,0,0,0,0,0,0,0
0,0,0,0,0,0,0,0,0,0,0,0,0,0,0,0,0,0,0,0,0,0,0,0,0,0,0,0,0,0,0,0,0,0,0,0
0,0,0,0,0,0,0,0,0,0,0,0,0,0,0,0,0,0,0,0,0,0,0,0,0,0,0,0,0,0,0,0,0,0,0,0
0,0,0,0,0,0,0,0,0,0,0,0,0,0,0,0,0,0,0,0,0,0,0,0,0,0,0,0,0,0,0,0,0,0,0,0
0,0,0,0,0,0,0,0,0,0,0,0,0,0,0,0,0,0,0,0,0,0,0,0,0,0,0,0,0,0,0,0,0,0,0,0
0,0,0,0,0,0,0,0,0,0,0,0,0,0,0,0,0,0,0,0,0,0,0,0,0,0,0,0,0,0,0,0,0,0,0,0
0,0,0,0,0,0,0,0,0,0,0,0,0,0,0,0,0,0,0,0,0,0,0,0,0,0,0,0,0,0,0,0,0,0,0,0
0,0,0,0,0,0,0,0,0,0,0,0,0,0,0,0,0,0,0,0,0,0,0,0,0,0,0,0,0,0,0,0,0,0,0,0
0,0,0,0,0,0,0,0,0,0,0,0,0,0,0,0,0,0,0,0,0,0,0,0,0,0,0,0,0,0,0,0,0,0,0,0
0,0,0,0,0,0,0,0,0,0,0,0,0,0,0,0,0,0,0,0,0,0,0,0,0,0,0,0,0,0,0,0,0,0,0,0
0,0,0,0,0,0,0,0,0,0,0,0,0,0,0,0,0,0,0,0,0,0,0,0,0,0,0,0,0,0,0,0,0,0,0,0
0,0,0,0,0,0,0,0,0,0,0,0,0,0,0,0,0,0,0,0,0,0,0,0,0,0,0,0,0,0,0,0,0,0,0,0
0,0,0,0,0,0,0,0,0,0,0,0,0,0,0,0,0,0,0,0,0,0,0,0,0,0,0,0,0,0,0,0,0,0,0,0
0,0,0,0,0,0,0,0,0,0,0,0,0,0,0,0,0,0,0,0,0,0,0,0,0,0,0,0,0,0,0,0,0,0,0,0
0,0,0,0,0,0,0,0,0,0,0,0,0,0,0,0,0,0,0,0,0,0,0,0,0,0,0,0,0,0,0,0,0,0,0,0
0,0,0,0,0,0,0,0,0,0,0,0,0,0,0,0,0,0,0,0,0,0,0,0,0,0,0,0,0,0,0,0,0,0,0,0
0,0,0,0,0,0,0,0,0,0,0,0,0,0,0,0,0,0,0,0,0,0,0,0,0,0,0,0,0,0,0,0,0,0,0,0
0,0,0,0,0,0,0,0,0,0,0,0,0,0,0,0,0,0,0,0,0,0,0,0,0,0,0,0,0,0,0,0,0,0,0,0
0,0,0,0,0,0,0,0,0,0,0,0,0,0,0,0,0,0,0,0,0,0,0,0,0,0,0,0,0,0,0,0,0,0,0,0
0,0,0,0,0,0,0,0,0,0,0,0,0,0,0,0,0,0,0,0,0,0,0,0,0,0,0,0,0,0,0,0,0,0,0,0
0,0,0,0,0,0,0,0,0,0,0,0,0,0,0,0,0,0,0,0,0,0,0,0,0,0,0,0,0,0,0,0,0,0,0,0
0,0,0,0,0,0,0,0,0,0,0,0,0,0,0,0,0,0,0,0,0,0,0,0,0,0,0,0,0,0,0,0,0,0,0,0
0,0,0,0,0,0,0,0,0,0,0,0,0,0,0,0,0,0,0,0,0,0,0,0,0,0,0,0,0,0,0,0,0,0,0,0
0,0,0,0,0,0,0,0,0,0,0,0,0,0,0,0,0,0,0,0,0,0,0,0,0,0,0,0,0,0,0,0,0,0,0,0
0,0,0,0,0,0,0,0,0,0,0,0,0,0,0,0,0,0,0,0,0,0,0,0,0,0,0,0,0,0,0,0,0,0,0,0
0,0,0,0,0,0,0,0,0,0,0,0,0,0,0,0,0,0,0,0,0,0,0,0,0,0,0,0,0,0,0,0,0,0,0,0
:endlayer
layer: 20
0,0,0,0,0,0,0,0,0,0,0,0,0,0,0,0,0,0,0,0,0,0,0,0,0,0,0,0,0,0,0,0,0,0,0,0
0,0,0,0,0,0,0,0,0,0,0,0,0,0,0,0,0,0,0,0,0,0,0,0,0,0,0,0,0,0,0,0,0,0,0,0
0,0,0,0,0,0,0,0,0,0,0,0,0,0,0,0,0,0,0,0,0,0,0,0,0,0,0,0,0,0,0,0,0,0,0,0
0,0,0,0,0,0,0,0,0,0,0,0,0,0,0,0,0,0,0,0,0,0,0,0,0,0,0,0,0,0,0,0,0,0,0,0
0,0,0,0,0,0,0,0,0,0,0,0,0,0,0,0,0,0,0,0,0,0,0,0,0,0,0,0,0,0,0,0,0,0,0,0
0,0,0,0,0,0,0,0,0,0,0,0,0,0,0,0,0,0,0,0,0,0,0,0,0,0,0,0,0,0,0,0,0,0,0,0
0,0,0,0,0,0,0,51,0,0,0,0,0,0,0,0,0,0,0,0,0,0,0,0,0,0,0,0,0,0,0,0,0,0,0,0
0,0,0,0,0,0,52,2,53,0,0,0,0,0,0,0,0,0,0,0,0,0,0,0,0,0,0,0,0,0,0,0,0,0,0,0
0,0,0,0,0,0,0,59,0,0,0,0,0,0,0,0,0,0,0,0,0,0,0,0,0,0,0,0,0,0,0,0,0,0,0,0
0,0,0,0,0,0,0,0,0,0,0,0,0,0,0,0,0,0,0,0,0,0,0,0,0,0,0,0,0,0,0,0,0,0,0,0
0,0,0,0,0,0,0,0,0,0,0,0,0,0,0,0,0,0,0,0,0,0,0,0,0,0,0,0,0,0,0,0,0,0,0,0
0,0,0,0,0,0,0,0,0,0,0,0,0,0,0,0,0,0,0,0,0,0,0,0,0,0,0,0,0,0,0,0,0,0,0,0
0,0,0,0,0,0,0,0,0,0,0,0,0,0,0,0,0,0,0,0,0,0,0,0,0,0,0,0,0,0,0,0,0,0,0,0
0,0,0,0,0,0,0,0,0,0,0,0,0,0,0,0,0,0,0,0,0,0,0,0,0,0,0,0,0,0,0,0,0,0,0,0
0,223,224,225,226,227,228,229,230,231,232,233,234,235,0,0,0,0,0,0,0,0,0,0,0,0,0,0,0,0,0,0,0,0,0,0
0,0,0,0,0,0,0,0,0,0,0,0,0,0,0,0,0,0,0,0,0,0,0,0,0,0,0,0,0,0,0,0,0,0,0,0
0,0,0,0,0,0,0,0,0,0,0,0,0,0,0,0,0,0,0,0,0,0,0,0,0,0,0,0,0,0,0,0,0,0,0,0
0,0,0,0,0,0,0,0,0,0,0,0,0,0,0,0,0,0,0,0,0,0,0,0,0,0,0,0,0,0,0,0,0,0,0,0
0,0,0,0,0,0,0,0,0,0,0,0,0,0,0,0,0,0,0,0,0,0,0,0,0,0,0,0,0,0,0,0,0,0,0,0
0,0,0,0,0,0,0,0,0,0,0,0,0,0,0,0,0,0,0,0,0,0,0,0,0,0,0,0,0,0,0,0,0,0,0,0
0,0,0,0,0,0,0,0,0,0,0,0,0,0,0,0,0,0,0,0,0,0,0,0,0,0,0,0,0,0,0,0,0,0,0,0
0,0,0,0,0,0,0,0,0,0,0,0,0,0,0,0,0,0,0,0,0,0,0,0,0,0,0,0,0,0,0,0,0,0,0,0
0,0,0,0,0,0,0,0,0,0,0,0,0,0,0,0,0,0,0,0,0,0,0,0,0,0,0,0,0,0,0,0,0,0,0,0
0,0,0,0,0,0,0,0,0,0,0,0,0,0,0,0,0,0,0,0,0,0,0,0,0,0,0,0,0,0,0,0,0,0,0,0
0,0,0,0,0,0,0,0,0,0,0,0,0,0,0,0,0,0,0,0,0,0,0,0,0,0,0,0,0,0,0,0,0,0,0,0
0,0,0,0,0,0,0,0,0,0,0,0,0,0,0,0,0,0,0,0,0,0,0,0,0,0,0,0,0,0,0,0,0,0,0,0
0,0,0,0,0,0,0,0,0,0,0,0,0,0,0,0,0,0,0,0,0,0,0,0,0,0,0,0,0,0,0,0,0,0,0,0
0,0,0,0,0,0,0,0,0,0,0,0,0,0,0,0,0,0,0,0,0,0,0,0,0,0,0,0,0,0,0,0,0,0,0,0
0,0,0,0,0,0,0,0,0,0,0,0,0,0,0,0,0,0,0,0,0,0,0,0,0,0,0,0,0,0,0,0,0,0,0,0
0,0,0,0,0,0,0,0,0,0,0,0,0,0,0,0,0,0,0,0,0,0,0,0,0,0,0,0,0,0,0,0,0,0,0,0
0,0,0,0,0,0,0,0,0,0,0,0,0,0,0,0,0,0,0,0,0,0,0,0,0,0,0,0,0,0,0,0,0,0,0,0
0,0,0,0,0,0,0,0,0,0,0,0,0,0,0,0,0,0,0,0,0,0,0,0,0,0,0,0,0,0,0,0,0,0,0,0
0,0,0,0,0,0,0,0,0,0,0,0,0,0,0,0,0,0,0,0,0,0,0,0,0,0,0,0,0,0,0,0,0,0,0,0
0,0,0,0,0,0,0,0,0,0,0,0,0,0,0,0,0,0,0,0,0,0,0,0,0,0,0,0,0,0,0,0,0,0,0,0
0,0,0,0,0,0,0,0,0,0,0,0,0,0,0,0,0,0,0,0,0,0,0,0,0,0,0,0,0,0,0,0,0,0,0,0
0,0,0,0,0,0,0,0,0,0,0,0,0,0,0,0,0,0,0,0,0,0,0,0,0,0,0,0,0,0,0,0,0,0,0,0
0,0,0,0,0,0,0,0,0,0,0,0,0,0,0,0,0,0,0,0,0,0,0,0,0,0,0,0,0,0,0,0,0,0,0,0
0,0,0,0,0,0,0,0,0,0,0,0,0,0,0,0,0,0,0,0,0,0,0,0,0,0,0,0,0,0,0,0,0,0,0,0
0,0,0,0,0,0,0,0,0,0,0,0,0,0,0,0,0,0,0,0,0,0,0,0,0,0,0,0,0,0,0,0,0,0,0,0
0,0,0,0,0,0,0,0,0,0,0,0,0,0,0,0,0,0,0,0,0,0,0,0,0,0,0,0,0,0,0,0,0,0,0,0
0,0,0,0,0,0,0,0,0,0,0,0,0,0,0,0,0,0,0,0,0,0,0,0,0,0,0,0,0,0,0,0,0,0,0,0
:endlayer
layer: 21
0,0,0,0,0,0,0,0,0,0,0,0,0,0,0,0,0,0,0,0,0,0,0,0,0,0,0,0,0,0,0,0,0,0,0,0
0,0,0,0,0,0,0,0,0,0,0,0,0,0,0,0,0,0,0,0,0,0,0,0,0,0,0,0,0,0,0,0,0,0,0,0
0,0,0,0,0,0,0,0,0,0,0,0,0,0,0,0,0,0,0,0,0,0,0,0,0,0,0,0,0,0,0,0,0,0,0,0
0,0,0,0,0,0,0,0,0,0,0,0,0,0,0,0,0,0,0,0,0,0,0,0,0,0,0,0,0,0,0,0,0,0,0,0
0,0,0,0,0,0,0,0,0,0,0,0,0,0,0,0,0,0,0,0,0,0,0,0,0,0,0,0,0,0,0,0,0,0,0,0
0,0,0,0,0,0,0,0,0,0,0,0,0,0,0,0,0,0,0,0,0,0,0,0,0,0,0,0,0,0,0,0,0,0,0,0
0,0,0,0,0,0,0,0,0,0,0,0,0,0,0,0,0,0,0,0,0,0,0,0,0,0,0,0,0,0,0,0,0,0,0,0
0,0,0,0,0,0,0,80,0,0,0,0,0,0,0,0,0,0,0,0,0,0,0,0,0,0,0,0,0,0,0,0,0,0,0,0
0,0,0,0,0,0,0,0,0,0,0,0,0,0,0,0,0,0,0,0,0,0,0,0,0,0,0,0,0,0,0,0,0,0,0,0
0,0,0,0,0,0,0,0,0,0,0,0,0,0,0,0,0,0,0,0,0,0,0,0,0,0,0,0,0,0,0,0,0,0,0,0
0,0,0,0,0,0,0,0,0,0,0,0,0,0,0,0,0,0,0,0,0,0,0,0,0,0,0,0,0,0,0,0,0,0,0,0
0,0,0,0,0,0,0,0,0,0,0,0,0,0,0,0,0,0,0,0,0,0,0,0,0,0,0,0,0,0,0,0,0,0,0,0
0,0,0,0,0,0,0,0,0,0,0,0,0,0,0,0,0,0,0,0,0,0,0,0,0,0,0,0,0,0,0,0,0,0,0,0
0,0,0,0,0,0,0,0,0,0,0,0,0,0,0,0,0,0,0,0,0,0,0,0,0,0,0,0,0,0,0,0,0,0,0,0
0,236,237,238,239,240,241,242,243,244,245,246,247,248,0,0,0,0,0,0,0,0,0,0,0,0,0,0,0,0,0,0,0,0,0,0
0,0,0,0,0,0,0,0,0,0,0,0,0,0,0,0,0,0,0,0,0,0,0,0,0,0,0,0,0,0,0,0,0,0,0,0
0,0,0,0,0,0,0,0,0,0,0,0,0,0,0,0,0,0,0,0,0,0,0,0,0,0,0,0,0,0,0,0,0,0,0,0
0,0,0,0,0,0,0,0,0,0,0,0,0,0,0,0,0,0,0,0,0,0,0,0,0,0,0,0,0,0,0,0,0,0,0,0
0,0,0,0,0,0,0,0,0,0,0,0,0,0,0,0,0,0,0,0,0,0,0,0,0,0,0,0,0,0,0,0,0,0,0,0
0,0,0,0,0,0,0,0,0,0,0,0,0,0,0,0,0,0,0,0,0,0,0,0,0,0,0,0,0,0,0,0,0,0,0,0
0,0,0,0,0,0,0,0,0,0,0,0,0,0,0,0,0,0,0,0,0,0,0,0,0,0,0,0,0,0,0,0,0,0,0,0
0,0,0,0,0,0,0,0,0,0,0,0,0,0,0,0,0,0,0,0,0,0,0,0,0,0,0,0,0,0,0,0,0,0,0,0
0,0,0,0,0,0,0,0,0,0,0,0,0,0,0,0,0,0,0,0,0,0,0,0,0,0,0,0,0,0,0,0,0,0,0,0
0,0,0,0,0,0,0,0,0,0,0,0,0,0,0,0,0,0,0,0,0,0,0,0,0,0,0,0,0,0,0,0,0,0,0,0
0,0,0,0,0,0,0,0,0,0,0,0,0,0,0,0,0,0,0,0,0,0,0,0,0,0,0,0,0,0,0,0,0,0,0,0
0,0,0,0,0,0,0,0,0,0,0,0,0,0,0,0,0,0,0,0,0,0,0,0,0,0,0,0,0,0,0,0,0,0,0,0
0,0,0,0,0,0,0,0,0,0,0,0,0,0,0,0,0,0,0,0,0,0,0,0,0,0,0,0,0,0,0,0,0,0,0,0
0,0,0,0,0,0,0,0,0,0,0,0,0,0,0,0,0,0,0,0,0,0,0,0,0,0,0,0,0,0,0,0,0,0,0,0
0,0,0,0,0,0,0,0,0,0,0,0,0,0,0,0,0,0,0,0,0,0,0,0,0,0,0,0,0,0,0,0,0,0,0,0
0,0,0,0,0,0,0,0,0,0,0,0,0,0,0,0,0,0,0,0,0,0,0,0,0,0,0,0,0,0,0,0,0,0,0,0
0,0,0,0,0,0,0,0,0,0,0,0,0,0,0,0,0,0,0,0,0,0,0,0,0,0,0,0,0,0,0,0,0,0,0,0
0,0,0,0,0,0,0,0,0,0,0,0,0,0,0,0,0,0,0,0,0,0,0,0,0,0,0,0,0,0,0,0,0,0,0,0
0,0,0,0,0,0,0,0,0,0,0,0,0,0,0,0,0,0,0,0,0,0,0,0,0,0,0,0,0,0,0,0,0,0,0,0
0,0,0,0,0,0,0,0,0,0,0,0,0,0,0,0,0,0,0,0,0,0,0,0,0,0,0,0,0,0,0,0,0,0,0,0
0,0,0,0,0,0,0,0,0,0,0,0,0,0,0,0,0,0,0,0,0,0,0,0,0,0,0,0,0,0,0,0,0,0,0,0
0,0,0,0,0,0,0,0,0,0,0,0,0,0,0,0,0,0,0,0,0,0,0,0,0,0,0,0,0,0,0,0,0,0,0,0
0,0,0,0,0,0,0,0,0,0,0,0,0,0,0,0,0,0,0,0,0,0,0,0,0,0,0,0,0,0,0,0,0,0,0,0
0,0,0,0,0,0,0,0,0,0,0,0,0,0,0,0,0,0,0,0,0,0,0,0,0,0,0,0,0,0,0,0,0,0,0,0
0,0,0,0,0,0,0,0,0,0,0,0,0,0,0,0,0,0,0,0,0,0,0,0,0,0,0,0,0,0,0,0,0,0,0,0
0,0,0,0,0,0,0,0,0,0,0,0,0,0,0,0,0,0,0,0,0,0,0,0,0,0,0,0,0,0,0,0,0,0,0,0
0,0,0,0,0,0,0,0,0,0,0,0,0,0,0,0,0,0,0,0,0,0,0,0,0,0,0,0,0,0,0,0,0,0,0,0
:endlayer

#### RULES ####
rule:
plugin=vanillaBlocks
number=1
data:
JSON:{blockState:{blockName:"minecraft:grass",properties:{snowy:"false"}}}
:enddata
:endrule

rule:
plugin=vanillaBlocks
number=2
data:
JSON:{blockState:{blockName:"minecraft:log",properties:{variant:"spruce",axis:"y"}}}
:enddata
:endrule

rule:
plugin=vanillaBlocks
number=3
data:
JSON:{blockState:{blockName:"minecraft:log",properties:{variant:"spruce",axis:"x"}}}
:enddata
:endrule

rule:
plugin=vanillaBlocks
number=4
data:
JSON:{blockState:{blockName:"minecraft:log",properties:{variant:"spruce",axis:"z"}}}
:enddata
:endrule

rule:
plugin=vanillaBlocks
number=5
data:
JSON:{blockState:{blockName:"minecraft:planks",properties:{variant:"dark_oak"}}}
:enddata
:endrule

rule:
plugin=vanillaBlocks
number=6
data:
JSON:{blockState:{blockName:"minecraft:grass_path"}}
:enddata
:endrule

rule:
plugin=vanillaBlocks
number=7
data:
JSON:{blockState:{blockName:"minecraft:gravel"}}
:enddata
:endrule

rule:
plugin=vanillaBlocks
number=8
data:
JSON:{blockState:{blockName:"minecraft:dirt",properties:{variant:"coarse_dirt",snowy:"false"}}}
:enddata
:endrule

rule:
plugin=vanillaBlocks
number=9
data:
JSON:{blockState:{blockName:"minecraft:dirt",properties:{variant:"dirt",snowy:"false"}}}
:enddata
:endrule

rule:
plugin=vanillaBlocks
number=10
data:
JSON:{blockState:{blockName:"minecraft:log",properties:{variant:"oak",axis:"z"}}}
:enddata
:endrule

rule:
plugin=vanillaBlocks
number=11
data:
JSON:{blockState:{blockName:"minecraft:cobblestone"}}
:enddata
:endrule

rule:
plugin=vanillaBlocks
number=12
data:
JSON:{blockState:{blockName:"minecraft:torch",properties:{facing:"up"}}}
:enddata
:endrule

rule:
plugin=vanillaBlocks
number=13
data:
JSON:{blockState:{blockName:"minecraft:acacia_fence",properties:{east:"false",south:"false",north:"false",west:"false"}}}
:enddata
:endrule

rule:
plugin=vanillaBlocks
number=14
data:
JSON:{blockState:{blockName:"minecraft:planks",properties:{variant:"oak"}}}
:enddata
:endrule

rule:
plugin=vanillaBlocks
number=15
data:
JSON:{blockState:{blockName:"minecraft:stone",properties:{variant:"andesite"}}}
:enddata
:endrule

rule:
plugin=vanillaBlocks
number=16
data:
JSON:{blockState:{blockName:"minecraft:stone",properties:{variant:"smooth_andesite"}}}
:enddata
:endrule

rule:
plugin=doors
number=17
data:
JSON:{blockState:{blockName:"minecraft:spruce_door",properties:{hinge:"left",half:"lower",powered:"false",facing:"west",open:"false"}}}
:enddata
:endrule

rule:
plugin=vanillaBlocks
number=18
data:
JSON:{blockState:{blockName:"minecraft:dark_oak_stairs",properties:{half:"top",shape:"straight",facing:"south"}}}
:enddata
:endrule

rule:
plugin=vanillaBlocks
number=19
data:
JSON:{blockState:{blockName:"minecraft:dark_oak_stairs",properties:{half:"bottom",shape:"straight",facing:"north"}}}
:enddata
:endrule

rule:
plugin=doors
number=20
data:
JSON:{blockState:{blockName:"minecraft:spruce_door",properties:{hinge:"left",half:"lower",powered:"false",facing:"east",open:"false"}}}
:enddata
:endrule

rule:
plugin=doors
number=21
data:
JSON:{blockState:{blockName:"minecraft:spruce_door",properties:{hinge:"right",half:"lower",powered:"false",facing:"west",open:"false"}}}
:enddata
:endrule

rule:
plugin=doors
number=22
data:
JSON:{blockState:{blockName:"minecraft:spruce_door",properties:{hinge:"right",half:"lower",powered:"false",facing:"east",open:"false"}}}
:enddata
:endrule

rule:
plugin=vanillaBlocks
number=23
data:
JSON:{blockState:{blockName:"minecraft:torch",properties:{facing:"north"}}}
:enddata
:endrule

rule:
plugin=vanillaBlocks
number=24
data:
JSON:{blockState:{blockName:"minecraft:oak_stairs",properties:{half:"bottom",shape:"straight",facing:"east"}}}
:enddata
:endrule

rule:
plugin=vanillaBlocks
number=25
data:
JSON:{blockState:{blockName:"minecraft:oak_stairs",properties:{half:"bottom",shape:"straight",facing:"west"}}}
:enddata
:endrule

rule:
plugin=vanillaBlocks
number=26
data:
JSON:{blockState:{blockName:"minecraft:torch",properties:{facing:"south"}}}
:enddata
:endrule

rule:
plugin=vanillaBlocks
number=27
data:
JSON:{blockState:{blockName:"minecraft:stone_slab",properties:{half:"bottom",variant:"cobblestone"}}}
:enddata
:endrule

rule:
plugin=vanillaBlocks
number=28
data:
JSON:{blockState:{blockName:"minecraft:oak_stairs",properties:{half:"bottom",shape:"straight",facing:"north"}}}
:enddata
:endrule

rule:
plugin=vanillaBlocks
number=29
data:
JSON:{blockState:{blockName:"minecraft:fence",properties:{east:"false",south:"false",north:"false",west:"false"}}}
:enddata
:endrule

rule:
plugin=vanillaBlocks
number=30
data:
JSON:{blockState:{blockName:"minecraft:fence_gate",properties:{in_wall:"false",powered:"false",facing:"west",open:"false"}}}
:enddata
:endrule

rule:
plugin=vanillaBlocks
number=31
data:
JSON:{blockState:{blockName:"minecraft:log",properties:{variant:"oak",axis:"y"}}}
:enddata
:endrule

rule:
plugin=vanillaBlocks
number=32
data:
JSON:{blockState:{blockName:"minecraft:ladder",properties:{facing:"west"}}}
:enddata
:endrule

rule:
plugin=vanillaBlocks
number=33
data:
JSON:{blockState:{blockName:"minecraft:ladder",properties:{facing:"east"}}}
:enddata
:endrule

rule:
plugin=vanillaBlocks
number=34
data:
JSON:{blockState:{blockName:"minecraft:oak_stairs",properties:{half:"bottom",shape:"straight",facing:"south"}}}
:enddata
:endrule

rule:
plugin=vanillaBlocks
number=35
data:
JSON:{blockState:{blockName:"minecraft:torch",properties:{facing:"west"}}}
:enddata
:endrule

rule:
plugin=vanillaBlocks
number=36
data:
JSON:{blockState:{blockName:"minecraft:torch",properties:{facing:"east"}}}
:enddata
:endrule

rule:
plugin=rotatable
number=37
data:
JSON:{blockState:{blockName:"ancientwarfareautomation:torque_shaft",properties:{tier:"light"}},orientation:0,teData:{orientation:0,x:270,y:8,z:-81,id:"ancientwarfareautomation:torque_shaft_light_tile",torqueEnergy:32.0d,clientEnergy:0}}
:enddata
:endrule

rule:
plugin=doors
number=38
data:
JSON:{blockState:{blockName:"minecraft:spruce_door",properties:{hinge:"left",half:"upper",powered:"false",facing:"north",open:"false"}}}
:enddata
:endrule

rule:
plugin=doors
number=39
data:
JSON:{blockState:{blockName:"minecraft:spruce_door",properties:{hinge:"left",half:"upper",powered:"false",facing:"east",open:"false"}}}
:enddata
:endrule

rule:
plugin=doors
number=40
data:
JSON:{blockState:{blockName:"minecraft:spruce_door",properties:{hinge:"right",half:"upper",powered:"false",facing:"west",open:"false"}}}
:enddata
:endrule

rule:
plugin=doors
number=41
data:
JSON:{blockState:{blockName:"minecraft:spruce_door",properties:{hinge:"right",half:"upper",powered:"false",facing:"east",open:"false"}}}
:enddata
:endrule

rule:
plugin=vanillaBlocks
number=42
data:
JSON:{blockState:{blockName:"minecraft:spruce_fence",properties:{east:"false",south:"false",north:"false",west:"false"}}}
:enddata
:endrule

rule:
plugin=doors
number=43
data:
JSON:{blockState:{blockName:"minecraft:spruce_door",properties:{hinge:"right",half:"upper",powered:"false",facing:"north",open:"false"}}}
:enddata
:endrule

rule:
plugin=vanillaBlocks
number=44
data:
JSON:{blockState:{blockName:"minecraft:spruce_stairs",properties:{half:"top",shape:"straight",facing:"south"}}}
:enddata
:endrule

rule:
plugin=vanillaBlocks
number=45
data:
JSON:{blockState:{blockName:"minecraft:spruce_stairs",properties:{half:"top",shape:"straight",facing:"west"}}}
:enddata
:endrule

rule:
plugin=vanillaBlocks
number=46
data:
JSON:{blockState:{blockName:"minecraft:spruce_stairs",properties:{half:"top",shape:"straight",facing:"east"}}}
:enddata
:endrule

rule:
plugin=vanillaBlocks
number=47
data:
JSON:{blockState:{blockName:"minecraft:spruce_stairs",properties:{half:"top",shape:"straight",facing:"north"}}}
:enddata
:endrule

rule:
plugin=vanillaBlocks
number=48
data:
JSON:{blockState:{blockName:"minecraft:wooden_slab",properties:{half:"top",variant:"spruce"}}}
:enddata
:endrule

rule:
plugin=rotatable
number=49
data:
JSON:{blockState:{blockName:"ancientwarfareautomation:torque_shaft",properties:{tier:"light"}},orientation:0,teData:{orientation:0,x:270,y:9,z:-81,id:"ancientwarfareautomation:torque_shaft_light_tile",torqueEnergy:32.0d,clientEnergy:0}}
:enddata
:endrule

rule:
plugin=vanillaBlocks
number=50
data:
JSON:{blockState:{blockName:"minecraft:wooden_slab",properties:{half:"top",variant:"oak"}}}
:enddata
:endrule

rule:
plugin=vanillaBlocks
number=51
data:
JSON:{blockState:{blockName:"minecraft:spruce_stairs",properties:{half:"bottom",shape:"straight",facing:"south"}}}
:enddata
:endrule

rule:
plugin=vanillaBlocks
number=52
data:
JSON:{blockState:{blockName:"minecraft:spruce_stairs",properties:{half:"bottom",shape:"straight",facing:"east"}}}
:enddata
:endrule

rule:
plugin=vanillaBlocks
number=53
data:
JSON:{blockState:{blockName:"minecraft:spruce_stairs",properties:{half:"bottom",shape:"straight",facing:"west"}}}
:enddata
:endrule

rule:
plugin=vanillaBlocks
number=54
data:
JSON:{blockState:{blockName:"minecraft:dark_oak_stairs",properties:{half:"top",shape:"straight",facing:"north"}}}
:enddata
:endrule

rule:
plugin=vanillaBlocks
number=55
data:
JSON:{blockState:{blockName:"minecraft:wooden_slab",properties:{half:"top",variant:"dark_oak"}}}
:enddata
:endrule

rule:
plugin=vanillaBlocks
number=56
data:
JSON:{blockState:{blockName:"minecraft:dark_oak_stairs",properties:{half:"top",shape:"straight",facing:"west"}}}
:enddata
:endrule

rule:
plugin=vanillaBlocks
number=57
data:
JSON:{blockState:{blockName:"minecraft:dark_oak_stairs",properties:{half:"top",shape:"straight",facing:"east"}}}
:enddata
:endrule

rule:
plugin=rotatable
number=58
data:
JSON:{blockState:{blockName:"ancientwarfareautomation:torque_shaft",properties:{tier:"light"}},orientation:0,teData:{orientation:0,x:270,y:10,z:-81,id:"ancientwarfareautomation:torque_shaft_light_tile",torqueEnergy:32.0d,clientEnergy:0}}
:enddata
:endrule

rule:
plugin=vanillaBlocks
number=59
data:
JSON:{blockState:{blockName:"minecraft:spruce_stairs",properties:{half:"bottom",shape:"straight",facing:"north"}}}
:enddata
:endrule

rule:
plugin=vanillaBlocks
number=60
data:
JSON:{blockState:{blockName:"minecraft:planks",properties:{variant:"spruce"}}}
:enddata
:endrule

rule:
plugin=vanillaBlocks
number=61
data:
JSON:{blockState:{blockName:"minecraft:dark_oak_stairs",properties:{half:"bottom",shape:"straight",facing:"south"}}}
:enddata
:endrule

rule:
plugin=rotatable
number=62
data:
JSON:{blockState:{blockName:"ancientwarfareautomation:torque_shaft",properties:{tier:"light"}},orientation:0,teData:{orientation:0,x:270,y:11,z:-81,id:"ancientwarfareautomation:torque_shaft_light_tile",torqueEnergy:32.0d,clientEnergy:0}}
:enddata
:endrule

rule:
plugin=rotatable
number=63
data:
JSON:{blockState:{blockName:"ancientwarfareautomation:torque_shaft",properties:{tier:"light"}},orientation:0,teData:{orientation:0,x:270,y:12,z:-81,id:"ancientwarfareautomation:torque_shaft_light_tile",torqueEnergy:32.0d,clientEnergy:0}}
:enddata
:endrule

rule:
plugin=rotatable
number=64
data:
JSON:{blockState:{blockName:"ancientwarfareautomation:torque_shaft",properties:{tier:"light"}},orientation:0,teData:{orientation:0,x:270,y:13,z:-81,id:"ancientwarfareautomation:torque_shaft_light_tile",torqueEnergy:32.0d,clientEnergy:0}}
:enddata
:endrule

rule:
plugin=rotatable
number=65
data:
JSON:{blockState:{blockName:"ancientwarfareautomation:torque_shaft",properties:{tier:"light"}},orientation:0,teData:{orientation:0,x:270,y:14,z:-81,id:"ancientwarfareautomation:torque_shaft_light_tile",torqueEnergy:32.0d,clientEnergy:0}}
:enddata
:endrule

rule:
plugin=rotatable
number=66
data:
JSON:{blockState:{blockName:"ancientwarfareautomation:torque_shaft",properties:{tier:"light"}},orientation:0,teData:{orientation:0,x:270,y:15,z:-81,id:"ancientwarfareautomation:torque_shaft_light_tile",torqueEnergy:32.0d,clientEnergy:0}}
:enddata
:endrule

rule:
plugin=awTorqueMulti
number=67
data:
JSON:{blockState:{blockName:"ancientwarfareautomation:windmill_blade"},teData:{x:264,y:15,z:-74,controlPos:74218511269814L,id:"ancientwarfareautomation:windmill_blade_tile",isControl:0b}}
:enddata
:endrule

rule:
plugin=awTorqueMulti
number=68
data:
JSON:{blockState:{blockName:"ancientwarfareautomation:windmill_blade"},teData:{x:265,y:15,z:-74,controlPos:74218511269814L,id:"ancientwarfareautomation:windmill_blade_tile",isControl:0b}}
:enddata
:endrule

rule:
plugin=awTorqueMulti
number=69
data:
JSON:{blockState:{blockName:"ancientwarfareautomation:windmill_blade"},teData:{x:266,y:15,z:-74,controlPos:74218511269814L,id:"ancientwarfareautomation:windmill_blade_tile",isControl:0b}}
:enddata
:endrule

rule:
plugin=awTorqueMulti
number=70
data:
JSON:{blockState:{blockName:"ancientwarfareautomation:windmill_blade"},teData:{x:267,y:15,z:-74,controlPos:74218511269814L,id:"ancientwarfareautomation:windmill_blade_tile",isControl:0b}}
:enddata
:endrule

rule:
plugin=awTorqueMulti
number=71
data:
JSON:{blockState:{blockName:"ancientwarfareautomation:windmill_blade"},teData:{x:268,y:15,z:-74,controlPos:74218511269814L,id:"ancientwarfareautomation:windmill_blade_tile",isControl:0b}}
:enddata
:endrule

rule:
plugin=awTorqueMulti
number=72
data:
JSON:{blockState:{blockName:"ancientwarfareautomation:windmill_blade"},teData:{x:269,y:15,z:-74,controlPos:74218511269814L,id:"ancientwarfareautomation:windmill_blade_tile",isControl:0b}}
:enddata
:endrule

rule:
plugin=awTorqueMulti
number=73
data:
JSON:{blockState:{blockName:"ancientwarfareautomation:windmill_blade"},teData:{x:270,y:15,z:-74,controlPos:74218511269814L,id:"ancientwarfareautomation:windmill_blade_tile",isControl:0b}}
:enddata
:endrule

rule:
plugin=awTorqueMulti
number=74
data:
JSON:{blockState:{blockName:"ancientwarfareautomation:windmill_blade"},teData:{x:271,y:15,z:-74,controlPos:74218511269814L,id:"ancientwarfareautomation:windmill_blade_tile",isControl:0b}}
:enddata
:endrule

rule:
plugin=awTorqueMulti
number=75
data:
JSON:{blockState:{blockName:"ancientwarfareautomation:windmill_blade"},teData:{x:272,y:15,z:-74,controlPos:74218511269814L,id:"ancientwarfareautomation:windmill_blade_tile",isControl:0b}}
:enddata
:endrule

rule:
plugin=awTorqueMulti
number=76
data:
JSON:{blockState:{blockName:"ancientwarfareautomation:windmill_blade"},teData:{x:273,y:15,z:-74,controlPos:74218511269814L,id:"ancientwarfareautomation:windmill_blade_tile",isControl:0b}}
:enddata
:endrule

rule:
plugin=awTorqueMulti
number=77
data:
JSON:{blockState:{blockName:"ancientwarfareautomation:windmill_blade"},teData:{x:274,y:15,z:-74,controlPos:74218511269814L,id:"ancientwarfareautomation:windmill_blade_tile",isControl:0b}}
:enddata
:endrule

rule:
plugin=awTorqueMulti
number=78
data:
JSON:{blockState:{blockName:"ancientwarfareautomation:windmill_blade"},teData:{x:275,y:15,z:-74,controlPos:74218511269814L,id:"ancientwarfareautomation:windmill_blade_tile",isControl:0b}}
:enddata
:endrule

rule:
plugin=awTorqueMulti
number=79
data:
JSON:{blockState:{blockName:"ancientwarfareautomation:windmill_blade"},teData:{x:276,y:15,z:-74,controlPos:74218511269814L,id:"ancientwarfareautomation:windmill_blade_tile",isControl:0b}}
:enddata
:endrule

rule:
plugin=vanillaBlocks
number=80
data:
JSON:{blockState:{blockName:"minecraft:wooden_slab",properties:{half:"bottom",variant:"spruce"}}}
:enddata
:endrule

rule:
plugin=rotatable
number=81
data:
JSON:{blockState:{blockName:"ancientwarfareautomation:torque_shaft",properties:{tier:"light"}},orientation:0,teData:{orientation:0,x:270,y:16,z:-81,id:"ancientwarfareautomation:torque_shaft_light_tile",torqueEnergy:32.0d,clientEnergy:0}}
:enddata
:endrule

rule:
plugin=awTorqueMulti
number=82
data:
JSON:{blockState:{blockName:"ancientwarfareautomation:windmill_blade"},teData:{x:264,y:16,z:-74,controlPos:74218511269814L,id:"ancientwarfareautomation:windmill_blade_tile",isControl:0b}}
:enddata
:endrule

rule:
plugin=awTorqueMulti
number=83
data:
JSON:{blockState:{blockName:"ancientwarfareautomation:windmill_blade"},teData:{x:265,y:16,z:-74,controlPos:74218511269814L,id:"ancientwarfareautomation:windmill_blade_tile",isControl:0b}}
:enddata
:endrule

rule:
plugin=awTorqueMulti
number=84
data:
JSON:{blockState:{blockName:"ancientwarfareautomation:windmill_blade"},teData:{x:266,y:16,z:-74,controlPos:74218511269814L,id:"ancientwarfareautomation:windmill_blade_tile",isControl:0b}}
:enddata
:endrule

rule:
plugin=awTorqueMulti
number=85
data:
JSON:{blockState:{blockName:"ancientwarfareautomation:windmill_blade"},teData:{x:267,y:16,z:-74,controlPos:74218511269814L,id:"ancientwarfareautomation:windmill_blade_tile",isControl:0b}}
:enddata
:endrule

rule:
plugin=awTorqueMulti
number=86
data:
JSON:{blockState:{blockName:"ancientwarfareautomation:windmill_blade"},teData:{x:268,y:16,z:-74,controlPos:74218511269814L,id:"ancientwarfareautomation:windmill_blade_tile",isControl:0b}}
:enddata
:endrule

rule:
plugin=awTorqueMulti
number=87
data:
JSON:{blockState:{blockName:"ancientwarfareautomation:windmill_blade"},teData:{x:269,y:16,z:-74,controlPos:74218511269814L,id:"ancientwarfareautomation:windmill_blade_tile",isControl:0b}}
:enddata
:endrule

rule:
plugin=awTorqueMulti
number=88
data:
JSON:{blockState:{blockName:"ancientwarfareautomation:windmill_blade"},teData:{x:270,y:16,z:-74,controlPos:74218511269814L,id:"ancientwarfareautomation:windmill_blade_tile",isControl:0b}}
:enddata
:endrule

rule:
plugin=awTorqueMulti
number=89
data:
JSON:{blockState:{blockName:"ancientwarfareautomation:windmill_blade"},teData:{x:271,y:16,z:-74,controlPos:74218511269814L,id:"ancientwarfareautomation:windmill_blade_tile",isControl:0b}}
:enddata
:endrule

rule:
plugin=awTorqueMulti
number=90
data:
JSON:{blockState:{blockName:"ancientwarfareautomation:windmill_blade"},teData:{x:272,y:16,z:-74,controlPos:74218511269814L,id:"ancientwarfareautomation:windmill_blade_tile",isControl:0b}}
:enddata
:endrule

rule:
plugin=awTorqueMulti
number=91
data:
JSON:{blockState:{blockName:"ancientwarfareautomation:windmill_blade"},teData:{x:273,y:16,z:-74,controlPos:74218511269814L,id:"ancientwarfareautomation:windmill_blade_tile",isControl:0b}}
:enddata
:endrule

rule:
plugin=awTorqueMulti
number=92
data:
JSON:{blockState:{blockName:"ancientwarfareautomation:windmill_blade"},teData:{x:274,y:16,z:-74,controlPos:74218511269814L,id:"ancientwarfareautomation:windmill_blade_tile",isControl:0b}}
:enddata
:endrule

rule:
plugin=awTorqueMulti
number=93
data:
JSON:{blockState:{blockName:"ancientwarfareautomation:windmill_blade"},teData:{x:275,y:16,z:-74,controlPos:74218511269814L,id:"ancientwarfareautomation:windmill_blade_tile",isControl:0b}}
:enddata
:endrule

rule:
plugin=awTorqueMulti
number=94
data:
JSON:{blockState:{blockName:"ancientwarfareautomation:windmill_blade"},teData:{x:276,y:16,z:-74,controlPos:74218511269814L,id:"ancientwarfareautomation:windmill_blade_tile",isControl:0b}}
:enddata
:endrule

rule:
plugin=rotatable
number=95
data:
JSON:{blockState:{blockName:"ancientwarfareautomation:torque_shaft",properties:{tier:"light"}},orientation:0,teData:{orientation:0,x:270,y:17,z:-81,id:"ancientwarfareautomation:torque_shaft_light_tile",torqueEnergy:32.0d,clientEnergy:0}}
:enddata
:endrule

rule:
plugin=awTorqueMulti
number=96
data:
JSON:{blockState:{blockName:"ancientwarfareautomation:windmill_blade"},teData:{x:264,y:17,z:-74,controlPos:74218511269814L,id:"ancientwarfareautomation:windmill_blade_tile",isControl:0b}}
:enddata
:endrule

rule:
plugin=awTorqueMulti
number=97
data:
JSON:{blockState:{blockName:"ancientwarfareautomation:windmill_blade"},teData:{x:265,y:17,z:-74,controlPos:74218511269814L,id:"ancientwarfareautomation:windmill_blade_tile",isControl:0b}}
:enddata
:endrule

rule:
plugin=awTorqueMulti
number=98
data:
JSON:{blockState:{blockName:"ancientwarfareautomation:windmill_blade"},teData:{x:266,y:17,z:-74,controlPos:74218511269814L,id:"ancientwarfareautomation:windmill_blade_tile",isControl:0b}}
:enddata
:endrule

rule:
plugin=awTorqueMulti
number=99
data:
JSON:{blockState:{blockName:"ancientwarfareautomation:windmill_blade"},teData:{x:267,y:17,z:-74,controlPos:74218511269814L,id:"ancientwarfareautomation:windmill_blade_tile",isControl:0b}}
:enddata
:endrule

rule:
plugin=awTorqueMulti
number=100
data:
JSON:{blockState:{blockName:"ancientwarfareautomation:windmill_blade"},teData:{x:268,y:17,z:-74,controlPos:74218511269814L,id:"ancientwarfareautomation:windmill_blade_tile",isControl:0b}}
:enddata
:endrule

rule:
plugin=awTorqueMulti
number=101
data:
JSON:{blockState:{blockName:"ancientwarfareautomation:windmill_blade"},teData:{x:269,y:17,z:-74,controlPos:74218511269814L,id:"ancientwarfareautomation:windmill_blade_tile",isControl:0b}}
:enddata
:endrule

rule:
plugin=awTorqueMulti
number=102
data:
JSON:{blockState:{blockName:"ancientwarfareautomation:windmill_blade"},teData:{x:270,y:17,z:-74,controlPos:74218511269814L,id:"ancientwarfareautomation:windmill_blade_tile",isControl:0b}}
:enddata
:endrule

rule:
plugin=awTorqueMulti
number=103
data:
JSON:{blockState:{blockName:"ancientwarfareautomation:windmill_blade"},teData:{x:271,y:17,z:-74,controlPos:74218511269814L,id:"ancientwarfareautomation:windmill_blade_tile",isControl:0b}}
:enddata
:endrule

rule:
plugin=awTorqueMulti
number=104
data:
JSON:{blockState:{blockName:"ancientwarfareautomation:windmill_blade"},teData:{x:272,y:17,z:-74,controlPos:74218511269814L,id:"ancientwarfareautomation:windmill_blade_tile",isControl:0b}}
:enddata
:endrule

rule:
plugin=awTorqueMulti
number=105
data:
JSON:{blockState:{blockName:"ancientwarfareautomation:windmill_blade"},teData:{x:273,y:17,z:-74,controlPos:74218511269814L,id:"ancientwarfareautomation:windmill_blade_tile",isControl:0b}}
:enddata
:endrule

rule:
plugin=awTorqueMulti
number=106
data:
JSON:{blockState:{blockName:"ancientwarfareautomation:windmill_blade"},teData:{x:274,y:17,z:-74,controlPos:74218511269814L,id:"ancientwarfareautomation:windmill_blade_tile",isControl:0b}}
:enddata
:endrule

rule:
plugin=awTorqueMulti
number=107
data:
JSON:{blockState:{blockName:"ancientwarfareautomation:windmill_blade"},teData:{x:275,y:17,z:-74,controlPos:74218511269814L,id:"ancientwarfareautomation:windmill_blade_tile",isControl:0b}}
:enddata
:endrule

rule:
plugin=awTorqueMulti
number=108
data:
JSON:{blockState:{blockName:"ancientwarfareautomation:windmill_blade"},teData:{x:276,y:17,z:-74,controlPos:74218511269814L,id:"ancientwarfareautomation:windmill_blade_tile",isControl:0b}}
:enddata
:endrule

rule:
plugin=rotatable
number=109
data:
JSON:{blockState:{blockName:"ancientwarfareautomation:torque_shaft",properties:{tier:"light"}},orientation:0,teData:{orientation:0,x:270,y:18,z:-81,id:"ancientwarfareautomation:torque_shaft_light_tile",torqueEnergy:32.0d,clientEnergy:0}}
:enddata
:endrule

rule:
plugin=awTorqueMulti
number=110
data:
JSON:{blockState:{blockName:"ancientwarfareautomation:windmill_blade"},teData:{x:264,y:18,z:-74,controlPos:74218511269814L,id:"ancientwarfareautomation:windmill_blade_tile",isControl:0b}}
:enddata
:endrule

rule:
plugin=awTorqueMulti
number=111
data:
JSON:{blockState:{blockName:"ancientwarfareautomation:windmill_blade"},teData:{x:265,y:18,z:-74,controlPos:74218511269814L,id:"ancientwarfareautomation:windmill_blade_tile",isControl:0b}}
:enddata
:endrule

rule:
plugin=awTorqueMulti
number=112
data:
JSON:{blockState:{blockName:"ancientwarfareautomation:windmill_blade"},teData:{x:266,y:18,z:-74,controlPos:74218511269814L,id:"ancientwarfareautomation:windmill_blade_tile",isControl:0b}}
:enddata
:endrule

rule:
plugin=awTorqueMulti
number=113
data:
JSON:{blockState:{blockName:"ancientwarfareautomation:windmill_blade"},teData:{x:267,y:18,z:-74,controlPos:74218511269814L,id:"ancientwarfareautomation:windmill_blade_tile",isControl:0b}}
:enddata
:endrule

rule:
plugin=awTorqueMulti
number=114
data:
JSON:{blockState:{blockName:"ancientwarfareautomation:windmill_blade"},teData:{x:268,y:18,z:-74,controlPos:74218511269814L,id:"ancientwarfareautomation:windmill_blade_tile",isControl:0b}}
:enddata
:endrule

rule:
plugin=awTorqueMulti
number=115
data:
JSON:{blockState:{blockName:"ancientwarfareautomation:windmill_blade"},teData:{x:269,y:18,z:-74,controlPos:74218511269814L,id:"ancientwarfareautomation:windmill_blade_tile",isControl:0b}}
:enddata
:endrule

rule:
plugin=awTorqueMulti
number=116
data:
JSON:{blockState:{blockName:"ancientwarfareautomation:windmill_blade"},teData:{x:270,y:18,z:-74,controlPos:74218511269814L,id:"ancientwarfareautomation:windmill_blade_tile",isControl:0b}}
:enddata
:endrule

rule:
plugin=awTorqueMulti
number=117
data:
JSON:{blockState:{blockName:"ancientwarfareautomation:windmill_blade"},teData:{x:271,y:18,z:-74,controlPos:74218511269814L,id:"ancientwarfareautomation:windmill_blade_tile",isControl:0b}}
:enddata
:endrule

rule:
plugin=awTorqueMulti
number=118
data:
JSON:{blockState:{blockName:"ancientwarfareautomation:windmill_blade"},teData:{x:272,y:18,z:-74,controlPos:74218511269814L,id:"ancientwarfareautomation:windmill_blade_tile",isControl:0b}}
:enddata
:endrule

rule:
plugin=awTorqueMulti
number=119
data:
JSON:{blockState:{blockName:"ancientwarfareautomation:windmill_blade"},teData:{x:273,y:18,z:-74,controlPos:74218511269814L,id:"ancientwarfareautomation:windmill_blade_tile",isControl:0b}}
:enddata
:endrule

rule:
plugin=awTorqueMulti
number=120
data:
JSON:{blockState:{blockName:"ancientwarfareautomation:windmill_blade"},teData:{x:274,y:18,z:-74,controlPos:74218511269814L,id:"ancientwarfareautomation:windmill_blade_tile",isControl:0b}}
:enddata
:endrule

rule:
plugin=awTorqueMulti
number=121
data:
JSON:{blockState:{blockName:"ancientwarfareautomation:windmill_blade"},teData:{x:275,y:18,z:-74,controlPos:74218511269814L,id:"ancientwarfareautomation:windmill_blade_tile",isControl:0b}}
:enddata
:endrule

rule:
plugin=awTorqueMulti
number=122
data:
JSON:{blockState:{blockName:"ancientwarfareautomation:windmill_blade"},teData:{x:276,y:18,z:-74,controlPos:74218511269814L,id:"ancientwarfareautomation:windmill_blade_tile",isControl:0b}}
:enddata
:endrule

rule:
plugin=rotatable
number=123
data:
JSON:{blockState:{blockName:"ancientwarfareautomation:torque_shaft",properties:{tier:"light"}},orientation:0,teData:{orientation:0,x:270,y:19,z:-81,id:"ancientwarfareautomation:torque_shaft_light_tile",torqueEnergy:31.961600000000004d,clientEnergy:0}}
:enddata
:endrule

rule:
plugin=awTorqueMulti
number=124
data:
JSON:{blockState:{blockName:"ancientwarfareautomation:windmill_blade"},teData:{x:264,y:19,z:-74,controlPos:74218511269814L,id:"ancientwarfareautomation:windmill_blade_tile",isControl:0b}}
:enddata
:endrule

rule:
plugin=awTorqueMulti
number=125
data:
JSON:{blockState:{blockName:"ancientwarfareautomation:windmill_blade"},teData:{x:265,y:19,z:-74,controlPos:74218511269814L,id:"ancientwarfareautomation:windmill_blade_tile",isControl:0b}}
:enddata
:endrule

rule:
plugin=awTorqueMulti
number=126
data:
JSON:{blockState:{blockName:"ancientwarfareautomation:windmill_blade"},teData:{x:266,y:19,z:-74,controlPos:74218511269814L,id:"ancientwarfareautomation:windmill_blade_tile",isControl:0b}}
:enddata
:endrule

rule:
plugin=awTorqueMulti
number=127
data:
JSON:{blockState:{blockName:"ancientwarfareautomation:windmill_blade"},teData:{x:267,y:19,z:-74,controlPos:74218511269814L,id:"ancientwarfareautomation:windmill_blade_tile",isControl:0b}}
:enddata
:endrule

rule:
plugin=awTorqueMulti
number=128
data:
JSON:{blockState:{blockName:"ancientwarfareautomation:windmill_blade"},teData:{x:268,y:19,z:-74,controlPos:74218511269814L,id:"ancientwarfareautomation:windmill_blade_tile",isControl:0b}}
:enddata
:endrule

rule:
plugin=awTorqueMulti
number=129
data:
JSON:{blockState:{blockName:"ancientwarfareautomation:windmill_blade"},teData:{x:269,y:19,z:-74,controlPos:74218511269814L,id:"ancientwarfareautomation:windmill_blade_tile",isControl:0b}}
:enddata
:endrule

rule:
plugin=awTorqueMulti
number=130
data:
JSON:{blockState:{blockName:"ancientwarfareautomation:windmill_blade"},teData:{x:270,y:19,z:-74,controlPos:74218511269814L,id:"ancientwarfareautomation:windmill_blade_tile",isControl:0b}}
:enddata
:endrule

rule:
plugin=awTorqueMulti
number=131
data:
JSON:{blockState:{blockName:"ancientwarfareautomation:windmill_blade"},teData:{x:271,y:19,z:-74,controlPos:74218511269814L,id:"ancientwarfareautomation:windmill_blade_tile",isControl:0b}}
:enddata
:endrule

rule:
plugin=awTorqueMulti
number=132
data:
JSON:{blockState:{blockName:"ancientwarfareautomation:windmill_blade"},teData:{x:272,y:19,z:-74,controlPos:74218511269814L,id:"ancientwarfareautomation:windmill_blade_tile",isControl:0b}}
:enddata
:endrule

rule:
plugin=awTorqueMulti
number=133
data:
JSON:{blockState:{blockName:"ancientwarfareautomation:windmill_blade"},teData:{x:273,y:19,z:-74,controlPos:74218511269814L,id:"ancientwarfareautomation:windmill_blade_tile",isControl:0b}}
:enddata
:endrule

rule:
plugin=awTorqueMulti
number=134
data:
JSON:{blockState:{blockName:"ancientwarfareautomation:windmill_blade"},teData:{x:274,y:19,z:-74,controlPos:74218511269814L,id:"ancientwarfareautomation:windmill_blade_tile",isControl:0b}}
:enddata
:endrule

rule:
plugin=awTorqueMulti
number=135
data:
JSON:{blockState:{blockName:"ancientwarfareautomation:windmill_blade"},teData:{x:275,y:19,z:-74,controlPos:74218511269814L,id:"ancientwarfareautomation:windmill_blade_tile",isControl:0b}}
:enddata
:endrule

rule:
plugin=awTorqueMulti
number=136
data:
JSON:{blockState:{blockName:"ancientwarfareautomation:windmill_blade"},teData:{x:276,y:19,z:-74,controlPos:74218511269814L,id:"ancientwarfareautomation:windmill_blade_tile",isControl:0b}}
:enddata
:endrule

rule:
