# Ancient Warfare Structure Template File
# Auto-generated structure template file. created on: 1/9/2024 at: 11:35:34
# Lines beginning with # denote comments

header:
version=2.11
name=SB_DarokCol_Fisherman_1H2R_1
mods=
size=16,18,15
offset=4,0,14
:endheader

#### VALIDATION ####
validation:
type=ground
structureAuthor=TheOddlySeagull
survival=true
worldGenEnabled=false
unique=false
preserveBlocks=false
preventNaturalHostileSpawns=true
selectionWeight=1
clusterValue=1
minDuplicateDistance=1
dimensionWhiteList=true
dimensionList=
biomeGroupList=
biomeWhiteList=true
biomeList=
leveling=10
fill=10
border=5
blockSwap=false
territoryName=
biomeReplacement=minecraft:
minGenerationHeight=0
maxGenerationHeight=255
:endvalidation

#### LAYERS ####
layer: 0
0,0,0,0,0,0,0,0,0,0,0,0,0,0,0,0
0,0,0,0,0,0,0,0,0,0,0,0,0,0,0,0
0,0,3,4,0,0,0,0,4,3,4,0,4,3,0,0
0,0,4,0,0,0,0,0,0,4,0,0,0,0,0,0
0,0,0,0,0,0,0,0,0,0,0,0,0,0,0,0
0,0,0,0,0,0,0,0,0,0,0,0,0,0,0,0
0,0,0,0,0,0,0,0,0,0,0,0,0,0,0,0
0,0,4,0,0,0,0,0,0,4,0,0,0,0,0,0
0,0,3,4,0,0,0,0,4,3,4,0,4,3,0,0
0,0,0,0,0,0,0,0,0,0,0,0,0,0,0,0
0,0,0,0,0,0,0,0,0,0,0,0,0,0,0,0
0,0,3,0,0,0,3,0,0,0,0,0,0,0,0,0
0,0,2,6,6,6,2,0,0,0,0,0,0,0,0,0
0,0,2,5,5,5,2,0,0,0,0,0,0,0,0,0
0,0,1,0,0,0,1,0,0,0,0,0,0,0,0,0
:endlayer
layer: 1
0,0,0,0,0,0,0,0,0,0,0,0,0,0,0,0
0,0,0,0,0,0,0,0,0,0,0,0,0,0,0,0
0,0,3,9,9,9,9,9,9,3,9,9,9,3,0,0
0,0,2,4,4,4,4,4,4,2,4,10,4,11,0,0
0,0,2,10,10,10,10,10,10,2,4,10,4,11,0,0
0,0,2,4,4,4,4,4,4,2,4,10,4,11,0,0
0,0,2,10,10,10,10,10,10,2,4,10,4,11,0,0
0,0,2,4,4,4,4,4,4,2,4,10,4,11,0,0
0,0,3,9,9,9,9,9,9,3,9,9,9,3,0,0
0,0,2,8,8,8,2,0,0,0,0,0,0,0,0,0
0,0,2,8,8,8,2,0,0,0,0,0,0,0,0,0
0,0,3,5,5,5,3,0,0,0,0,0,0,0,0,0
0,0,1,0,0,0,1,0,0,0,0,0,0,0,0,0
0,0,1,0,0,0,1,0,0,0,0,0,0,0,0,0
0,0,7,0,0,0,7,0,0,0,0,0,0,0,0,0
:endlayer
layer: 2
0,0,0,0,0,0,0,0,0,0,0,0,0,0,0,0
0,0,0,0,0,16,16,0,0,0,0,0,0,0,0,0
0,0,3,13,13,13,13,13,13,3,18,18,18,3,0,0
0,0,13,0,15,11,0,0,0,13,0,0,0,18,0,0
0,12,13,0,0,0,0,0,0,13,0,0,0,0,0,0
0,0,13,0,0,0,0,0,0,17,0,0,0,0,0,0
0,12,13,0,0,0,0,0,0,13,0,0,0,0,0,0
0,0,13,0,0,0,0,0,0,13,0,0,0,18,0,0
0,0,3,13,14,13,13,13,13,3,18,18,18,3,0,0
0,0,1,0,0,0,1,0,0,0,0,0,0,0,0,0
0,0,1,0,0,0,1,0,0,0,0,0,0,0,0,0
0,0,3,0,0,0,3,0,0,0,0,0,0,0,0,0
0,0,0,0,0,0,0,0,0,0,0,0,0,0,0,0
0,0,0,0,0,0,0,0,0,0,0,0,0,0,0,0
0,0,0,0,0,0,0,0,0,0,0,0,0,0,0,0
:endlayer
layer: 3
0,0,0,0,0,0,0,0,0,0,0,0,0,0,0,0
0,0,20,0,0,0,0,0,0,20,0,0,0,0,0,0
0,0,3,13,13,18,18,13,13,3,0,0,0,3,0,0
0,0,13,0,0,15,11,0,0,24,0,0,0,0,0,0
0,0,18,0,0,0,0,0,0,13,0,0,0,0,0,0
0,0,13,0,0,0,0,0,0,23,0,0,0,0,0,0
0,0,18,0,0,0,0,0,0,13,0,0,0,0,0,0
0,0,13,0,0,0,0,0,0,22,0,0,0,0,0,0
0,0,3,13,21,13,18,18,13,3,0,0,0,3,0,0
0,0,19,0,0,0,0,0,0,19,0,0,0,0,0,0
0,0,0,0,0,0,0,0,0,0,0,0,0,0,0,0
0,0,1,0,0,0,1,0,0,0,0,0,0,0,0,0
0,0,0,0,0,0,0,0,0,0,0,0,0,0,0,0
0,0,0,0,0,0,0,0,0,0,0,0,0,0,0,0
0,0,0,0,0,0,0,0,0,0,0,0,0,0,0,0
:endlayer
layer: 4
0,0,0,0,0,0,0,0,0,0,0,0,0,0,0,0
0,0,0,0,0,0,0,0,0,0,0,0,0,0,0,0
0,0,3,13,13,18,18,13,13,3,25,0,26,3,0,0
0,0,13,0,0,0,15,11,0,28,0,0,0,19,0,0
0,0,18,0,0,0,0,0,0,13,0,0,0,0,0,0
0,0,13,25,0,0,0,0,26,13,0,0,0,0,0,0
0,0,18,0,0,0,0,0,0,13,0,0,0,0,0,0
0,0,13,0,0,20,0,0,0,27,0,0,0,20,0,0
0,0,3,13,13,13,18,18,13,3,25,0,26,3,0,0
0,0,0,0,0,0,0,0,0,0,0,0,0,0,0,0
0,0,0,0,0,0,0,0,0,0,0,0,0,0,0,0
0,0,7,0,0,0,7,0,0,0,0,0,0,0,0,0
0,0,0,0,0,0,0,0,0,0,0,0,0,0,0,0
0,0,0,0,0,0,0,0,0,0,0,0,0,0,0,0
0,0,0,0,0,0,0,0,0,0,0,0,0,0,0,0
:endlayer
layer: 5
0,0,0,0,0,0,0,0,0,0,0,0,0,0,0,0
0,0,0,0,0,0,0,0,0,0,0,0,0,0,0,0
0,0,3,9,9,9,9,9,9,3,9,9,9,3,0,0
0,0,2,0,0,0,0,15,10,2,4,4,4,2,0,0
0,0,2,29,10,29,10,29,10,2,10,10,10,2,0,0
0,0,2,4,10,4,10,4,10,2,4,4,4,2,0,0
0,0,2,4,10,4,10,4,10,2,10,10,10,2,0,0
0,0,2,4,10,4,10,4,10,2,4,4,4,2,0,0
0,0,3,9,9,9,9,9,9,3,9,9,9,3,0,0
0,0,0,0,0,0,0,0,0,0,0,0,0,0,0,0
0,0,0,0,0,0,0,0,0,0,0,0,0,0,0,0
0,0,0,0,0,0,0,0,0,0,0,0,0,0,0,0
0,0,0,0,0,0,0,0,0,0,0,0,0,0,0,0
0,0,0,0,0,0,0,0,0,0,0,0,0,0,0,0
0,0,0,0,0,0,0,0,0,0,0,0,0,0,0,0
:endlayer
layer: 6
0,0,0,0,0,0,0,0,0,0,0,0,0,0,0,0
0,0,0,0,0,16,16,0,0,0,0,16,0,0,0,0
0,0,3,13,13,13,13,13,13,3,13,13,13,3,0,0
0,0,13,0,0,0,0,0,0,13,0,0,0,13,0,0
0,12,13,18,18,18,18,0,0,3,0,0,0,13,11,0
0,0,13,0,0,0,0,0,0,13,0,0,0,13,0,0
0,12,13,16,0,0,0,0,0,0,0,0,0,13,11,0
0,0,13,30,0,0,0,0,0,13,0,0,0,13,0,0
0,0,3,13,13,13,13,13,13,3,13,13,13,3,0,0
0,0,0,0,0,29,29,0,0,0,0,29,0,0,0,0
0,0,0,0,0,0,0,0,0,0,0,0,0,0,0,0
0,0,0,0,0,0,0,0,0,0,0,0,0,0,0,0
0,0,0,0,0,0,0,0,0,0,0,0,0,0,0,0
0,0,0,0,0,0,0,0,0,0,0,0,0,0,0,0
0,0,0,0,0,0,0,0,0,0,0,0,0,0,0,0
:endlayer
layer: 7
0,0,0,0,0,0,0,0,0,0,0,0,0,0,0,0
0,0,0,0,0,0,0,0,0,0,0,0,0,0,0,0
0,0,3,13,13,18,18,13,13,3,13,18,13,3,0,0
0,0,13,0,0,0,0,0,0,13,0,0,0,13,0,0
0,0,18,0,0,0,0,0,0,3,0,0,0,18,0,0
0,0,13,16,0,0,0,0,0,13,0,0,0,13,0,0
0,0,18,31,0,0,0,0,0,0,0,0,0,18,0,0
0,0,13,0,0,0,0,0,0,13,0,0,0,13,0,0
0,0,3,13,13,18,18,13,13,3,13,18,13,3,0,0
0,0,0,0,0,0,0,0,0,0,0,0,0,0,0,0
0,0,0,0,0,0,0,0,0,0,0,0,0,0,0,0
0,0,0,0,0,0,0,0,0,0,0,0,0,0,0,0
0,0,0,0,0,0,0,0,0,0,0,0,0,0,0,0
0,0,0,0,0,0,0,0,0,0,0,0,0,0,0,0
0,0,0,0,0,0,0,0,0,0,0,0,0,0,0,0
:endlayer
layer: 8
0,0,0,0,0,0,0,0,0,0,0,0,0,0,0,0
0,0,1,0,0,0,0,0,0,1,0,0,0,1,0,0
0,0,3,13,13,18,18,13,13,3,13,18,13,3,0,0
0,0,13,0,19,0,0,19,0,13,0,0,0,13,0,0
0,0,18,16,0,0,0,0,26,3,25,0,0,18,0,0
0,0,13,31,0,0,0,0,0,13,0,0,26,13,0,0
0,0,18,0,0,0,0,0,0,13,0,0,0,18,0,0
0,0,13,0,20,0,0,20,0,13,0,0,0,13,0,0
0,0,3,13,13,18,18,13,13,3,13,18,13,3,0,0
0,0,1,0,0,0,0,0,0,1,0,0,0,1,0,0
0,0,0,0,0,0,0,0,0,0,0,0,0,0,0,0
0,0,0,0,0,0,0,0,0,0,0,0,0,0,0,0
0,0,0,0,0,0,0,0,0,0,0,0,0,0,0,0
0,0,0,0,0,0,0,0,0,0,0,0,0,0,0,0
0,0,0,0,0,0,0,0,0,0,0,0,0,0,0,0
:endlayer
layer: 9
0,0,0,0,0,0,0,0,0,0,0,0,0,0,0,0
0,32,32,32,32,32,32,32,32,32,32,32,32,32,32,0
0,1,3,9,9,9,9,9,9,3,9,9,9,3,1,0
0,0,2,16,4,10,4,10,4,2,4,4,4,2,0,0
0,0,2,31,4,10,4,10,4,2,10,10,10,2,0,0
0,0,2,0,4,10,4,10,4,2,4,4,4,2,0,0
0,0,2,0,4,10,4,10,4,2,10,10,10,2,0,0
0,0,2,0,4,10,4,10,4,2,4,4,4,2,0,0
0,1,3,9,9,9,9,9,9,3,9,9,9,3,1,0
0,31,31,31,31,31,31,31,31,31,31,31,31,31,31,0
0,0,0,0,0,0,0,0,0,0,0,0,0,0,0,0
0,0,0,0,0,0,0,0,0,0,0,0,0,0,0,0
0,0,0,0,0,0,0,0,0,0,0,0,0,0,0,0
0,0,0,0,0,0,0,0,0,0,0,0,0,0,0,0
0,0,0,0,0,0,0,0,0,0,0,0,0,0,0,0
:endlayer
layer: 10
0,0,0,0,0,0,0,0,0,0,0,0,0,0,0,0
0,0,0,0,0,0,0,0,0,0,0,0,0,0,0,0
0,10,10,10,10,10,10,10,10,10,10,10,10,10,10,0
0,1,3,0,0,0,0,0,0,3,0,0,0,3,1,0
0,0,13,0,0,0,0,0,0,0,0,0,0,13,0,0
0,0,13,0,18,0,0,0,0,0,0,0,0,13,0,0
0,0,13,0,18,0,0,0,0,0,0,0,0,13,0,0
0,1,3,0,18,0,0,0,0,3,0,0,0,3,1,0
0,10,10,10,10,10,10,10,10,10,10,10,10,10,10,0
0,0,0,0,0,0,0,0,0,0,0,0,0,0,0,0
0,0,0,0,0,0,0,0,0,0,0,0,0,0,0,0
0,0,0,0,0,0,0,0,0,0,0,0,0,0,0,0
0,0,0,0,0,0,0,0,0,0,0,0,0,0,0,0
0,0,0,0,0,0,0,0,0,0,0,0,0,0,0,0
0,0,0,0,0,0,0,0,0,0,0,0,0,0,0,0
:endlayer
layer: 11
0,0,0,0,0,0,0,0,0,0,0,0,0,0,0,0
0,0,0,0,0,0,0,0,0,0,0,0,0,0,0,0
0,32,32,32,32,32,32,32,32,32,32,32,32,32,32,0
0,1,3,9,9,9,9,9,9,3,9,9,9,3,1,0
0,0,13,0,0,0,0,0,0,19,0,0,0,13,0,0
0,0,18,0,0,0,0,0,0,0,0,0,0,18,0,0
0,0,13,0,0,0,0,0,0,20,0,0,0,13,0,0
0,1,3,9,9,9,9,9,9,3,9,9,9,3,1,0
0,31,31,31,31,31,31,31,31,31,31,31,31,31,31,0
0,0,0,0,0,0,0,0,0,0,0,0,0,0,0,0
0,0,0,0,0,0,0,0,0,0,0,0,0,0,0,0
0,0,0,0,0,0,0,0,0,0,0,0,0,0,0,0
0,0,0,0,0,0,0,0,0,0,0,0,0,0,0,0
0,0,0,0,0,0,0,0,0,0,0,0,0,0,0,0
0,0,0,0,0,0,0,0,0,0,0,0,0,0,0,0
:endlayer
layer: 12
0,0,0,0,0,0,0,0,0,0,0,0,0,0,0,0
0,0,0,0,0,0,0,0,0,0,0,0,0,0,0,0
0,0,0,0,0,0,0,0,0,0,0,0,0,0,0,0
0,10,10,10,10,10,10,10,10,10,10,10,10,10,10,0
0,1,3,0,0,0,0,0,0,3,0,0,0,3,1,0
0,0,13,0,0,0,0,0,0,0,0,0,0,13,0,0
0,1,3,0,0,0,0,0,0,3,0,0,0,3,1,0
0,10,10,10,10,10,10,10,10,10,10,10,10,10,10,0
0,0,0,0,0,0,0,0,0,0,0,0,0,0,0,0
0,0,0,0,0,0,0,0,0,0,0,0,0,0,0,0
0,0,0,0,0,0,0,0,0,0,0,0,0,0,0,0
0,0,0,0,0,0,0,0,0,0,0,0,0,0,0,0
0,0,0,0,0,0,0,0,0,0,0,0,0,0,0,0
0,0,0,0,0,0,0,0,0,0,0,0,0,0,0,0
0,0,0,0,0,0,0,0,0,0,0,0,0,0,0,0
:endlayer
layer: 13
0,0,0,0,0,0,0,0,0,0,0,0,0,0,0,0
0,0,0,0,0,0,0,0,0,0,0,0,0,0,0,0
0,0,0,0,0,0,0,0,0,0,0,0,0,0,0,0
0,32,32,32,32,32,32,32,32,32,32,32,32,32,32,0
0,1,3,9,9,9,9,9,9,3,9,9,9,3,1,0
0,0,13,25,0,0,0,0,0,0,0,0,26,13,0,0
0,1,3,9,9,9,9,9,9,3,9,9,9,3,1,0
0,31,31,31,31,31,31,31,31,31,31,31,31,31,31,0
0,0,0,0,0,0,0,0,0,0,0,0,0,0,0,0
0,0,0,0,0,0,0,0,0,0,0,0,0,0,0,0
0,0,0,0,0,0,0,0,0,0,0,0,0,0,0,0
0,0,0,0,0,0,0,0,0,0,0,0,0,0,0,0
0,0,0,0,0,0,0,0,0,0,0,0,0,0,0,0
0,0,0,0,0,0,0,0,0,0,0,0,0,0,0,0
0,0,0,0,0,0,0,0,0,0,0,0,0,0,0,0
:endlayer
layer: 14
0,0,0,0,0,0,0,0,0,0,0,0,0,0,0,0
0,0,0,0,0,0,0,0,0,0,0,0,0,0,0,0
0,0,0,0,0,0,0,0,0,0,0,0,0,0,0,0
0,0,0,0,0,0,0,0,0,0,0,0,0,0,0,0
0,10,10,10,10,10,10,10,10,10,10,10,10,10,10,0
0,1,3,0,0,0,0,0,0,3,0,0,0,3,1,0
0,10,10,10,10,10,10,10,10,10,10,10,10,10,10,0
0,0,0,0,0,0,0,0,0,0,0,0,0,0,0,0
0,0,0,0,0,0,0,0,0,0,0,0,0,0,0,0
0,0,0,0,0,0,0,0,0,0,0,0,0,0,0,0
0,0,0,0,0,0,0,0,0,0,0,0,0,0,0,0
0,0,0,0,0,0,0,0,0,0,0,0,0,0,0,0
0,0,0,0,0,0,0,0,0,0,0,0,0,0,0,0
0,0,0,0,0,0,0,0,0,0,0,0,0,0,0,0
0,0,0,0,0,0,0,0,0,0,0,0,0,0,0,0
:endlayer
layer: 15
0,0,0,0,0,0,0,0,0,0,0,0,0,0,0,0
0,0,0,0,0,0,0,0,0,0,0,0,0,0,0,0
0,0,0,0,0,0,0,0,0,0,0,0,0,0,0,0
0,0,0,0,0,0,0,0,0,0,0,0,0,0,0,0
0,32,32,32,32,32,32,32,32,32,32,32,32,32,32,0
0,1,3,9,9,9,9,9,9,3,9,9,9,3,1,0
0,31,31,31,31,31,31,31,31,31,31,31,31,31,31,0
0,0,0,0,0,0,0,0,0,0,0,0,0,0,0,0
0,0,0,0,0,0,0,0,0,0,0,0,0,0,0,0
0,0,0,0,0,0,0,0,0,0,0,0,0,0,0,0
0,0,0,0,0,0,0,0,0,0,0,0,0,0,0,0
0,0,0,0,0,0,0,0,0,0,0,0,0,0,0,0
0,0,0,0,0,0,0,0,0,0,0,0,0,0,0,0
0,0,0,0,0,0,0,0,0,0,0,0,0,0,0,0
0,0,0,0,0,0,0,0,0,0,0,0,0,0,0,0
:endlayer
layer: 16
0,0,0,0,0,0,0,0,0,0,0,0,0,0,0,0
0,0,0,0,0,0,0,0,0,0,0,0,0,0,0,0
0,0,0,0,0,0,0,0,0,0,0,0,0,0,0,0
0,0,0,0,0,0,0,0,0,0,0,0,0,0,0,0
0,0,0,0,0,0,0,0,0,0,0,0,0,0,0,0
0,10,10,10,10,10,10,10,10,10,10,10,10,10,10,0
0,0,0,0,0,0,0,0,0,0,0,0,0,0,0,0
0,0,0,0,0,0,0,0,0,0,0,0,0,0,0,0
0,0,0,0,0,0,0,0,0,0,0,0,0,0,0,0
0,0,0,0,0,0,0,0,0,0,0,0,0,0,0,0
0,0,0,0,0,0,0,0,0,0,0,0,0,0,0,0
0,0,0,0,0,0,0,0,0,0,0,0,0,0,0,0
0,0,0,0,0,0,0,0,0,0,0,0,0,0,0,0
0,0,0,0,0,0,0,0,0,0,0,0,0,0,0,0
0,0,0,0,0,0,0,0,0,0,0,0,0,0,0,0
:endlayer
layer: 17
0,0,0,0,0,0,0,0,0,0,0,0,0,0,0,0
0,0,0,0,0,0,0,0,0,0,0,0,0,0,0,0
0,0,0,0,0,0,0,0,0,0,0,0,0,0,0,0
0,0,0,0,0,0,0,0,0,0,0,0,0,0,0,0
0,0,0,0,0,0,0,0,0,0,0,0,0,0,0,0
0,0,7,0,0,0,0,0,0,0,0,0,0,7,0,0
0,0,0,0,0,0,0,0,0,0,0,0,0,0,0,0
0,0,0,0,0,0,0,0,0,0,0,0,0,0,0,0
0,0,0,0,0,0,0,0,0,0,0,0,0,0,0,0
0,0,0,0,0,0,0,0,0,0,0,0,0,0,0,0
0,0,0,0,0,0,0,0,0,0,0,0,0,0,0,0
0,0,0,0,0,0,0,0,0,0,0,0,0,0,0,0
0,0,0,0,0,0,0,0,0,0,0,0,0,0,0,0
0,0,0,0,0,0,0,0,0,0,0,0,0,0,0,0
0,0,0,0,0,0,0,0,0,0,0,0,0,0,0,0
:endlayer

#### RULES ####
rule:
plugin=vanillaBlocks
number=1
data:
JSON:{blockState:{blockName:"minecraft:spruce_fence",properties:{east:"false",south:"false",north:"false",west:"false"}}}
:enddata
:endrule

rule:
plugin=vanillaBlocks
number=2
data:
JSON:{blockState:{blockName:"minecraft:log",properties:{variant:"spruce",axis:"z"}}}
:enddata
:endrule

rule:
plugin=vanillaBlocks
number=3
data:
JSON:{blockState:{blockName:"minecraft:log",properties:{variant:"spruce",axis:"y"}}}
:enddata
:endrule

rule:
plugin=vanillaBlocks
number=4
data:
JSON:{blockState:{blockName:"minecraft:wooden_slab",properties:{half:"top",variant:"spruce"}}}
:enddata
:endrule

rule:
plugin=vanillaBlocks
number=5
data:
JSON:{blockState:{blockName:"minecraft:wooden_slab",properties:{half:"bottom",variant:"oak"}}}
:enddata
:endrule

rule:
plugin=vanillaBlocks
number=6
data:
JSON:{blockState:{blockName:"minecraft:wooden_slab",properties:{half:"top",variant:"oak"}}}
:enddata
:endrule

rule:
plugin=vanillaBlocks
number=7
data:
JSON:{blockState:{blockName:"minecraft:torch",properties:{facing:"up"}}}
:enddata
:endrule

rule:
plugin=vanillaBlocks
number=8
data:
JSON:{blockState:{blockName:"minecraft:oak_stairs",properties:{half:"top",shape:"straight",facing:"west"}}}
:enddata
:endrule

rule:
plugin=vanillaBlocks
number=9
data:
JSON:{blockState:{blockName:"minecraft:log",properties:{variant:"spruce",axis:"x"}}}
:enddata
:endrule

rule:
plugin=vanillaBlocks
number=10
data:
JSON:{blockState:{blockName:"minecraft:planks",properties:{variant:"spruce"}}}
:enddata
:endrule

rule:
plugin=vanillaBlocks
number=11
data:
JSON:{blockState:{blockName:"minecraft:spruce_stairs",properties:{half:"top",shape:"straight",facing:"west"}}}
:enddata
:endrule

rule:
plugin=vanillaBlocks
number=12
data:
JSON:{blockState:{blockName:"minecraft:spruce_stairs",properties:{half:"top",shape:"straight",facing:"east"}}}
:enddata
:endrule

rule:
plugin=vanillaBlocks
number=13
data:
JSON:{blockState:{blockName:"minecraft:planks",properties:{variant:"oak"}}}
:enddata
:endrule

rule:
plugin=doors
number=14
data:
JSON:{blockState:{blockName:"minecraft:spruce_door",properties:{hinge:"left",half:"lower",powered:"false",facing:"north",open:"false"}}}
:enddata
:endrule

rule:
plugin=vanillaBlocks
number=15
data:
JSON:{blockState:{blockName:"minecraft:spruce_stairs",properties:{half:"bottom",shape:"straight",facing:"east"}}}
:enddata
:endrule

rule:
plugin=vanillaBlocks
number=16
data:
JSON:{blockState:{blockName:"minecraft:spruce_stairs",properties:{half:"top",shape:"straight",facing:"south"}}}
:enddata
:endrule

rule:
plugin=doors
number=17
data:
JSON:{blockState:{blockName:"minecraft:spruce_door",properties:{hinge:"right",half:"lower",powered:"false",facing:"west",open:"false"}}}
:enddata
:endrule

rule:
plugin=vanillaBlocks
number=18
data:
JSON:{blockState:{blockName:"minecraft:acacia_fence",properties:{east:"false",south:"false",north:"false",west:"false"}}}
:enddata
:endrule

rule:
plugin=vanillaBlocks
number=19
data:
JSON:{blockState:{blockName:"minecraft:torch",properties:{facing:"south"}}}
:enddata
:endrule

rule:
plugin=vanillaBlocks
number=20
data:
JSON:{blockState:{blockName:"minecraft:torch",properties:{facing:"north"}}}
:enddata
:endrule

rule:
plugin=doors
number=21
data:
JSON:{blockState:{blockName:"minecraft:spruce_door",properties:{hinge:"left",half:"upper",powered:"false",facing:"north",open:"false"}}}
:enddata
:endrule

rule:
plugin=vanillaBlocks
number=22
data:
JSON:{blockState:{blockName:"minecraft:oak_stairs",properties:{half:"bottom",shape:"straight",facing:"south"}}}
:enddata
:endrule

rule:
plugin=doors
number=23
data:
JSON:{blockState:{blockName:"minecraft:spruce_door",properties:{hinge:"right",half:"upper",powered:"false",facing:"west",open:"false"}}}
:enddata
:endrule

rule:
plugin=vanillaBlocks
number=24
data:
JSON:{blockState:{blockName:"minecraft:oak_stairs",properties:{half:"bottom",shape:"straight",facing:"north"}}}
:enddata
:endrule

rule:
plugin=vanillaBlocks
number=25
data:
JSON:{blockState:{blockName:"minecraft:torch",properties:{facing:"east"}}}
:enddata
:endrule

rule:
plugin=vanillaBlocks
number=26
data:
JSON:{blockState:{blockName:"minecraft:torch",properties:{facing:"west"}}}
:enddata
:endrule

rule:
plugin=vanillaBlocks
number=27
data:
JSON:{blockState:{blockName:"minecraft:oak_stairs",properties:{half:"top",shape:"straight",facing:"south"}}}
:enddata
:endrule

rule:
plugin=vanillaBlocks
number=28
data:
JSON:{blockState:{blockName:"minecraft:oak_stairs",properties:{half:"top",shape:"straight",facing:"north"}}}
:enddata
:endrule

rule:
plugin=vanillaBlocks
number=29
data:
JSON:{blockState:{blockName:"minecraft:spruce_stairs",properties:{half:"top",shape:"straight",facing:"north"}}}
:enddata
:endrule

rule:
plugin=vanillaBlocks
number=30
data:
JSON:{blockState:{blockName:"minecraft:spruce_stairs",properties:{half:"bottom",shape:"straight",facing:"west"}}}
:enddata
:endrule

rule:
plugin=vanillaBlocks
number=31
data:
JSON:{blockState:{blockName:"minecraft:spruce_stairs",properties:{half:"bottom",shape:"straight",facing:"north"}}}
:enddata
:endrule

rule:
plugin=vanillaBlocks
number=32
data:
JSON:{blockState:{blockName:"minecraft:spruce_stairs",properties:{half:"bottom",shape:"straight",facing:"south"}}}
:enddata
:endrule

#### ENTITIES ####
