# Ancient Warfare Structure Template File
# Auto-generated structure template file. created on: 1/9/2024 at: 0:36:51
# Lines beginning with # denote comments

header:
version=2.11
name=SB_DarokCol_LargeWarehouse_1
mods=
size=17,21,30
offset=8,3,29
:endheader

#### VALIDATION ####
validation:
type=ground
structureAuthor=TheOddlySeagull
survival=true
worldGenEnabled=false
unique=false
preserveBlocks=false
preventNaturalHostileSpawns=true
selectionWeight=1
clusterValue=1
minDuplicateDistance=1
dimensionWhiteList=true
dimensionList=
biomeGroupList=
biomeWhiteList=true
biomeList=
leveling=10
fill=10
border=5
blockSwap=false
territoryName=
biomeReplacement=minecraft:
minGenerationHeight=0
maxGenerationHeight=255
:endvalidation

#### LAYERS ####
layer: 0
1,1,1,1,1,1,1,1,1,1,1,1,1,1,1,1,1
1,1,1,1,1,1,1,1,1,1,1,1,1,1,1,1,1
1,1,1,1,1,1,1,1,1,1,1,1,1,1,1,1,1
1,1,1,1,1,1,1,1,1,1,1,1,1,1,1,1,1
1,1,1,1,1,1,1,1,1,1,1,1,1,1,1,1,1
1,1,1,1,1,1,1,1,1,1,1,1,1,1,1,1,1
1,1,1,1,1,1,1,1,1,1,1,1,1,1,1,1,1
1,1,1,1,1,1,1,1,1,1,1,1,1,1,1,1,1
1,1,1,1,1,1,1,1,1,1,1,1,1,1,1,1,1
1,1,1,1,1,1,1,1,1,1,1,1,1,1,1,1,1
1,1,1,1,1,1,1,1,1,1,1,1,1,1,1,1,1
1,1,1,1,1,1,1,1,1,1,1,1,1,1,1,1,1
1,1,1,1,1,1,1,1,1,1,1,1,1,1,1,1,1
1,1,1,1,1,1,1,1,1,1,1,1,1,1,1,1,1
1,1,1,1,1,1,1,1,1,1,1,1,1,1,1,1,1
1,1,1,1,1,1,1,1,1,1,1,1,1,1,1,1,1
1,1,1,1,1,1,1,1,1,1,1,1,1,1,1,1,1
1,1,1,1,1,1,1,1,1,1,1,1,1,1,1,1,1
1,1,1,1,1,1,1,1,1,1,1,1,1,1,1,1,1
1,1,1,1,1,1,1,1,1,1,1,1,1,1,1,1,1
1,1,1,1,1,1,1,1,1,1,1,1,1,1,1,1,1
1,1,1,1,1,1,1,1,1,1,1,1,1,1,1,1,1
1,1,1,1,1,1,1,1,1,1,1,1,1,1,1,1,1
1,1,1,1,1,1,1,1,1,1,1,1,1,1,1,1,1
1,1,1,1,1,1,1,1,1,1,1,1,1,1,1,1,1
1,1,1,1,1,1,1,1,1,1,1,1,1,1,1,1,1
1,1,1,1,1,1,1,1,1,1,1,1,1,1,1,1,1
1,1,1,1,1,1,1,1,1,1,1,1,1,1,1,1,1
1,1,1,1,1,1,1,1,1,1,1,1,1,1,1,1,1
1,1,1,1,1,1,1,1,1,1,1,1,1,1,1,1,1
:endlayer
layer: 1
1,1,1,1,1,1,1,1,1,1,1,1,1,1,1,1,1
1,1,1,1,1,1,1,1,1,1,1,1,1,1,1,1,1
1,1,1,1,1,1,1,1,1,1,1,1,1,1,1,1,1
1,1,1,1,1,1,1,1,1,1,1,1,1,1,1,1,1
1,1,1,1,1,1,1,1,1,1,1,1,1,1,1,1,1
1,1,1,1,1,1,1,1,1,1,1,1,1,1,1,1,1
1,1,1,1,1,1,1,1,1,1,1,1,1,1,1,1,1
1,1,1,1,1,1,1,1,1,1,1,1,1,1,1,1,1
1,1,1,1,1,1,1,1,1,1,1,1,1,1,1,1,1
1,1,1,1,1,1,1,1,1,1,1,1,1,1,1,1,1
1,1,1,1,1,1,1,1,1,1,1,1,1,1,1,1,1
1,1,1,1,1,1,1,1,1,1,1,1,1,1,1,1,1
1,1,1,1,1,1,1,1,1,1,1,1,1,1,1,1,1
1,1,1,1,1,1,1,1,1,1,1,1,1,1,1,1,1
1,1,1,1,1,1,1,1,1,1,1,1,1,1,1,1,1
1,1,1,1,1,1,1,1,1,1,1,1,1,1,1,1,1
1,1,1,1,1,1,1,1,1,1,1,1,1,1,1,1,1
1,1,1,1,1,1,1,1,1,1,1,1,1,1,1,1,1
1,1,1,1,1,1,1,1,1,1,1,1,1,1,1,1,1
1,1,1,1,1,1,1,1,1,1,1,1,1,1,1,1,1
1,1,1,1,1,1,1,1,1,1,1,1,1,1,1,1,1
1,1,1,1,1,1,1,1,1,1,1,1,1,1,1,1,1
1,1,1,1,1,1,1,1,1,1,1,1,1,1,1,1,1
1,1,1,1,1,1,1,1,1,1,1,1,1,1,1,1,1
1,1,1,1,1,1,1,1,1,1,1,1,1,1,1,1,1
1,1,1,1,1,1,1,1,1,1,1,1,1,1,1,1,1
1,1,1,1,1,1,1,1,1,1,1,1,1,1,1,1,1
1,1,1,1,1,1,1,1,1,1,1,1,1,1,1,1,1
1,1,1,1,1,1,1,1,1,1,1,1,1,1,1,1,1
1,1,1,1,1,1,1,1,1,1,1,1,1,1,1,1,1
:endlayer
layer: 2
2,2,2,2,2,2,2,2,2,2,2,2,2,2,2,2,2
2,2,2,2,2,2,2,2,2,2,2,2,2,2,2,2,2
2,2,3,5,5,5,3,5,5,5,3,5,5,5,3,2,2
2,2,4,6,6,6,4,6,6,6,4,6,6,6,4,2,2
2,2,4,6,6,6,4,6,6,6,4,6,6,6,4,2,2
2,2,4,6,6,6,4,6,6,6,4,6,6,6,4,2,2
2,2,4,6,6,6,4,6,6,6,4,6,6,6,4,2,2
2,2,3,5,5,5,5,5,5,5,5,5,5,5,3,2,2
2,2,4,6,6,6,4,6,6,6,4,6,6,6,4,2,2
2,2,4,6,6,6,4,6,6,6,4,6,6,6,4,2,2
2,2,4,6,6,6,4,6,6,6,4,6,6,6,4,2,2
2,2,4,6,6,6,4,6,6,6,4,6,6,6,4,2,2
2,2,3,5,5,5,5,5,5,5,5,5,5,5,3,2,2
2,2,4,6,6,6,4,6,6,6,4,6,6,6,4,2,2
2,2,4,6,6,6,4,6,6,6,4,6,6,6,4,2,2
2,2,4,6,6,6,4,6,6,6,4,6,6,6,4,2,2
2,2,4,6,6,6,4,6,6,6,4,6,6,6,4,2,2
2,2,3,5,5,5,5,5,5,5,5,5,5,5,3,2,2
2,2,4,6,6,6,4,6,6,6,4,6,6,6,4,2,2
2,2,4,6,6,6,4,6,6,6,4,6,6,6,4,2,2
2,2,4,6,6,6,4,6,6,6,4,6,6,6,4,2,2
2,2,4,6,6,6,4,6,6,6,4,6,6,6,4,2,2
2,2,3,5,5,5,5,5,5,5,5,5,5,5,3,2,2
2,2,4,6,6,6,4,6,6,6,4,6,6,6,4,2,2
2,2,4,6,6,6,4,6,6,6,4,6,6,6,4,2,2
2,2,4,6,6,6,4,6,6,6,4,6,6,6,4,2,2
2,2,4,6,6,6,4,6,6,6,4,6,6,6,4,2,2
2,2,3,5,5,5,5,5,5,5,5,5,5,5,3,2,2
2,2,2,2,2,2,2,2,2,2,2,2,2,2,2,2,2
2,2,2,2,2,2,2,2,2,2,2,2,2,2,2,2,2
:endlayer
layer: 3
0,0,0,0,0,0,0,0,0,0,0,0,0,0,0,0,0
0,0,0,0,0,0,0,0,0,0,0,0,0,0,0,0,0
0,0,3,7,7,7,3,7,10,7,3,7,7,7,3,0,0
0,0,1,0,0,0,0,0,0,0,0,0,0,0,1,0,0
0,0,1,0,0,0,0,0,0,0,0,0,0,0,1,0,0
0,0,1,0,0,0,0,0,0,0,0,0,0,0,1,0,0
0,0,1,0,0,0,0,0,0,0,0,0,0,0,1,0,0
0,0,3,0,0,0,9,0,0,0,9,0,0,0,3,0,0
0,0,1,0,0,0,0,0,0,0,0,0,0,0,1,0,0
0,0,1,0,0,0,0,0,0,0,0,0,0,0,1,0,0
0,0,1,0,0,0,0,0,0,0,0,0,0,0,1,0,0
0,0,1,0,0,0,0,0,0,0,0,0,0,0,1,0,0
0,0,3,0,0,0,9,0,0,0,9,0,0,0,3,0,0
0,0,1,0,0,0,0,0,0,0,0,0,0,0,1,0,0
0,0,1,0,0,0,0,0,0,0,0,0,0,0,1,0,0
0,0,1,0,0,0,0,0,0,0,0,0,0,0,1,0,0
0,0,1,0,0,0,0,0,0,0,0,0,0,0,1,0,0
0,0,3,0,0,0,9,0,0,0,9,0,0,0,3,0,0
0,0,1,0,0,0,0,0,0,0,0,0,0,0,1,0,0
0,0,1,0,0,0,0,0,0,0,0,0,0,0,1,0,0
0,0,1,0,0,0,0,0,0,0,0,0,0,0,1,0,0
0,0,1,0,0,0,0,0,0,0,0,8,0,0,1,0,0
0,0,3,0,0,0,9,0,0,0,9,3,0,0,3,0,0
0,0,1,0,0,0,0,0,0,0,0,0,0,0,1,0,0
0,0,1,0,0,0,0,0,0,0,0,0,0,0,1,0,0
0,0,1,0,0,0,0,0,0,0,0,0,0,0,1,0,0
0,0,1,0,0,0,0,0,0,0,0,0,0,0,1,0,0
0,0,3,7,3,0,0,0,0,0,0,0,3,7,3,0,0
0,0,0,0,0,0,0,0,0,0,0,0,0,0,0,0,0
0,0,0,0,0,0,0,0,0,0,0,0,0,0,0,0,0
:endlayer
layer: 4
0,0,0,0,0,0,0,0,0,0,0,0,0,0,0,0,0
0,0,0,0,0,0,0,0,0,0,0,0,0,0,0,0,0
0,15,3,7,12,7,3,7,14,7,3,7,12,7,3,11,0
0,0,1,0,0,0,0,0,0,0,0,0,0,0,1,0,0
0,0,1,0,0,0,0,0,0,0,0,0,0,0,1,0,0
0,0,1,0,0,0,0,0,0,0,0,0,0,0,1,0,0
0,0,1,0,0,0,0,0,0,0,0,0,0,0,1,0,0
0,15,3,0,0,0,0,0,0,0,0,0,0,0,3,11,0
0,0,1,0,0,0,0,0,0,0,0,0,0,0,1,0,0
0,0,12,0,0,0,0,0,0,0,0,0,0,0,12,0,0
0,0,12,0,0,0,0,0,0,0,0,0,0,0,12,0,0
0,0,1,0,0,0,0,0,0,0,0,0,0,0,1,0,0
0,15,3,0,0,0,0,0,0,0,0,0,0,0,3,11,0
0,0,1,0,0,0,0,0,0,0,0,0,0,0,1,0,0
0,0,1,0,0,0,0,0,0,0,0,0,0,0,1,0,0
0,0,1,0,0,0,0,0,0,0,0,0,0,0,1,0,0
0,0,1,0,0,0,0,0,0,0,0,0,0,0,1,0,0
0,15,3,0,0,0,0,0,0,0,0,0,0,0,3,11,0
0,0,1,0,0,0,0,0,0,0,0,0,0,0,1,0,0
0,0,12,0,0,0,0,0,0,0,0,0,0,0,12,0,0
0,0,12,0,0,0,0,0,0,0,0,0,0,0,12,0,0
0,0,1,0,0,0,0,0,0,0,0,8,0,0,1,0,0
0,15,3,0,0,0,0,0,0,0,0,3,0,0,3,11,0
0,0,1,0,0,0,0,0,0,0,0,0,0,0,1,0,0
0,0,1,0,0,0,0,0,0,0,0,0,0,0,1,0,0
0,0,1,0,0,0,0,0,0,0,0,0,0,0,1,0,0
0,0,1,0,0,0,0,0,0,0,0,0,0,0,1,0,0
0,15,3,7,3,0,0,0,0,0,0,0,3,7,3,11,0
0,0,0,0,13,0,0,0,0,0,0,0,13,0,0,0,0
0,0,0,0,0,0,0,0,0,0,0,0,0,0,0,0,0
:endlayer
layer: 5
0,0,0,0,0,0,0,0,0,0,0,0,0,0,0,0,0
0,16,18,0,0,0,18,0,0,0,18,0,0,0,18,16,0
0,21,3,7,12,7,3,7,7,7,3,7,12,7,3,17,0
0,16,1,0,0,0,13,0,0,0,13,0,0,0,1,16,0
0,0,1,0,0,0,0,0,0,0,0,0,0,0,1,0,0
0,0,1,0,0,0,0,0,0,0,0,0,0,0,1,0,0
0,16,1,0,0,0,0,0,0,0,0,0,0,0,1,16,0
0,21,3,11,0,0,0,0,0,0,0,0,0,15,3,17,0
0,16,1,0,0,0,0,0,0,0,0,0,0,0,1,16,0
0,0,1,0,0,0,0,0,0,0,0,0,0,0,1,0,0
0,0,1,0,0,0,0,0,0,0,0,0,0,0,1,0,0
0,16,1,0,0,0,0,0,0,0,0,0,0,0,1,16,0
0,21,3,11,0,0,0,0,0,0,0,0,0,15,3,17,0
0,16,1,0,0,0,0,0,0,0,0,0,0,0,1,16,0
0,0,1,0,0,0,0,0,0,0,0,0,0,0,1,0,0
0,0,1,0,0,0,0,0,0,0,0,0,0,0,1,0,0
0,16,1,0,0,0,0,0,0,0,0,0,0,0,1,16,0
0,21,3,11,0,0,0,0,0,0,0,0,0,15,3,17,0
0,16,1,0,0,0,0,0,0,0,0,0,0,0,1,16,0
0,0,1,0,0,0,0,0,0,0,0,0,0,0,1,0,0
0,0,1,0,0,0,0,0,0,0,0,0,0,0,1,0,0
0,16,1,0,0,0,0,0,0,0,0,8,0,0,1,16,0
0,21,3,11,0,0,0,0,0,0,0,3,0,15,3,17,0
0,16,1,0,0,0,0,0,0,0,0,0,0,0,1,16,0
0,0,1,0,0,0,0,0,0,0,0,0,0,0,1,0,0
0,0,1,0,0,0,0,0,0,0,0,0,0,0,1,0,0
0,16,1,0,18,0,0,0,0,0,0,0,18,0,1,16,0
0,21,3,7,3,20,0,0,0,0,0,19,3,7,3,17,0
0,16,13,0,0,0,0,0,0,0,0,0,0,0,13,16,0
0,0,0,0,0,0,0,0,0,0,0,0,0,0,0,0,0
:endlayer
layer: 6
0,0,0,0,0,0,0,0,0,0,0,0,0,0,0,0,0
0,26,25,0,0,0,0,0,0,0,0,0,0,0,23,22,0
0,26,3,5,5,5,3,5,5,5,3,5,5,5,3,22,0
0,26,4,0,0,0,0,0,0,0,0,0,0,0,4,22,0
0,26,4,0,0,0,0,0,0,0,0,0,0,0,4,22,0
0,26,4,0,0,0,0,0,0,0,0,0,0,0,4,22,0
0,26,4,0,0,0,0,0,0,0,0,0,0,0,4,22,0
0,26,3,17,0,0,0,0,0,0,0,0,0,21,3,22,0
0,26,4,0,0,0,0,0,0,0,0,0,0,0,4,22,0
0,26,4,0,0,0,0,0,0,0,0,0,0,0,4,22,0
0,26,4,0,0,0,0,0,0,0,0,0,0,0,4,22,0
0,26,4,0,0,0,0,0,0,0,0,0,0,0,4,22,0
0,26,3,17,0,0,0,0,0,0,0,0,0,21,3,22,0
0,26,4,0,0,0,0,0,0,0,0,0,0,0,4,22,0
0,26,4,0,0,0,0,0,0,0,0,0,0,0,4,22,0
0,26,4,0,0,0,0,0,0,0,0,0,0,0,4,22,0
0,26,4,0,0,0,0,0,0,0,0,0,0,0,4,22,0
0,26,3,17,0,0,0,0,0,0,0,0,0,21,3,22,0
0,26,4,0,0,0,0,0,0,0,0,0,0,0,4,22,0
0,26,4,0,0,0,0,0,0,0,0,0,0,0,4,22,0
0,26,4,0,0,0,0,0,0,0,0,0,0,0,4,22,0
0,26,4,0,0,0,0,0,0,0,0,8,0,0,4,22,0
0,26,3,17,0,0,0,0,0,0,0,3,0,21,3,22,0
0,26,4,0,0,0,0,0,0,0,0,0,0,0,4,22,0
0,26,4,0,0,0,0,0,0,0,0,0,0,0,4,22,0
0,26,4,0,0,0,0,0,0,0,0,0,0,0,4,22,0
0,26,4,0,0,0,0,0,0,0,0,0,0,0,4,22,0
0,26,3,7,3,7,7,24,24,24,7,7,3,7,3,22,0
0,26,25,0,0,0,0,0,0,0,0,0,0,0,23,22,0
0,0,0,0,0,0,0,0,0,0,0,0,0,0,0,0,0
:endlayer
layer: 7
0,0,0,0,0,0,0,0,0,0,0,0,0,0,0,0,0
0,0,27,0,0,0,0,0,0,0,0,0,0,0,27,0,0
0,0,27,3,7,7,3,7,7,7,3,7,7,3,27,0,0
0,0,27,0,0,0,0,0,0,0,0,0,0,0,27,0,0
0,0,27,0,0,0,0,0,0,0,0,0,0,0,27,0,0
0,0,27,0,0,0,0,0,0,0,0,0,0,0,27,0,0
0,0,27,0,0,0,0,0,0,0,0,0,0,0,27,0,0
0,0,27,3,16,0,0,0,0,0,0,0,16,3,27,0,0
0,0,27,0,0,0,0,0,0,0,0,0,0,0,27,0,0
0,0,27,0,0,0,0,0,0,0,0,0,0,0,27,0,0
0,0,27,0,0,0,0,0,0,0,0,0,0,0,27,0,0
0,0,27,0,0,0,0,0,0,0,0,0,0,0,27,0,0
0,0,27,3,16,0,0,0,0,0,0,0,16,3,27,0,0
0,0,27,0,0,0,0,0,0,0,0,0,0,0,27,0,0
0,0,27,0,0,0,0,0,0,0,0,0,0,0,27,0,0
0,0,27,0,0,0,0,0,0,0,0,0,0,0,27,0,0
0,0,27,0,0,0,0,0,0,0,0,0,0,0,27,0,0
0,0,27,3,16,0,0,0,0,0,0,0,16,3,27,0,0
0,0,27,0,0,0,0,0,0,0,0,0,0,0,27,0,0
0,0,27,0,0,0,0,0,0,0,0,0,0,0,27,0,0
0,0,27,0,0,0,0,0,0,0,0,0,0,0,27,0,0
0,0,27,0,0,0,0,0,0,0,0,8,0,0,27,0,0
0,0,27,3,16,0,0,0,0,0,0,3,16,3,27,0,0
0,0,27,0,0,0,0,0,0,0,0,0,0,0,27,0,0
0,0,27,0,0,0,0,0,0,0,0,0,0,0,27,0,0
0,0,27,0,0,0,0,0,0,0,0,0,0,0,27,0,0
0,0,27,0,0,0,0,0,0,0,0,0,0,0,27,0,0
0,0,27,3,5,5,5,5,5,5,5,5,5,3,27,0,0
0,0,27,0,0,0,0,0,0,0,0,0,0,0,27,0,0
0,0,0,0,0,0,0,0,0,0,0,0,0,0,0,0,0
:endlayer
layer: 8
0,0,0,0,0,0,0,0,0,0,0,0,0,0,0,0,0
0,0,26,25,0,0,0,0,0,0,0,0,0,23,22,0,0
0,0,26,3,7,7,3,7,12,7,3,7,7,3,22,0,0
0,0,26,4,0,0,0,0,0,0,0,0,0,4,22,0,0
0,0,26,4,0,0,0,0,0,0,0,0,0,4,22,0,0
0,0,26,4,0,0,0,0,0,0,0,0,0,4,22,0,0
0,0,26,4,0,0,0,0,0,0,0,0,0,4,22,0,0
0,0,26,3,5,5,16,16,0,16,16,5,5,3,22,0,0
0,0,26,4,0,0,0,0,0,0,0,0,0,4,22,0,0
0,0,26,4,0,0,0,0,0,0,0,0,0,4,22,0,0
0,0,26,4,0,0,0,0,0,0,0,0,0,4,22,0,0
0,0,26,4,0,0,0,0,0,0,0,0,0,4,22,0,0
0,0,26,3,5,5,16,16,0,16,16,5,5,3,22,0,0
0,0,26,4,0,0,0,0,0,0,0,0,0,4,22,0,0
0,0,26,4,0,0,0,0,0,0,0,0,0,4,22,0,0
0,0,26,4,0,0,0,0,0,0,0,0,0,4,22,0,0
0,0,26,4,0,0,0,0,0,0,0,0,0,4,22,0,0
0,0,26,3,5,5,16,16,0,16,16,5,5,3,22,0,0
0,0,26,4,0,0,0,0,0,0,0,0,0,4,22,0,0
0,0,26,4,0,0,0,0,0,0,0,0,0,4,22,0,0
0,0,26,4,0,0,0,0,0,0,0,0,0,4,22,0,0
0,0,26,4,28,16,28,16,16,16,28,8,28,4,22,0,0
0,0,26,3,5,5,5,5,5,5,5,5,5,3,22,0,0
0,0,26,4,29,29,4,29,29,29,4,29,29,4,22,0,0
0,0,26,4,29,29,4,29,29,29,4,29,29,4,22,0,0
0,0,26,4,29,29,4,29,29,29,4,29,29,4,22,0,0
0,0,26,4,29,29,4,29,29,29,4,29,29,4,22,0,0
0,0,26,3,7,7,7,7,7,7,7,7,7,3,22,0,0
0,0,26,25,0,0,0,16,16,16,0,0,0,23,22,0,0
0,0,0,0,0,0,0,0,0,0,0,0,0,0,0,0,0
:endlayer
layer: 9
0,0,0,0,0,0,0,0,0,0,0,0,0,0,0,0,0
0,0,0,27,0,0,0,0,0,0,0,0,0,27,0,0,0
0,0,0,27,3,7,3,7,12,7,3,7,3,27,0,0,0
0,0,0,27,0,0,0,0,0,0,0,0,0,27,0,0,0
0,0,0,27,0,0,0,0,0,0,0,0,0,27,0,0,0
0,0,0,27,0,0,0,0,0,0,0,0,0,27,0,0,0
0,0,0,27,0,0,0,0,0,0,0,0,0,27,0,0,0
0,0,0,27,3,30,5,5,5,5,5,30,3,27,0,0,0
0,0,0,27,0,0,0,0,0,0,0,0,0,27,0,0,0
0,0,0,27,0,0,0,0,0,0,0,0,0,27,0,0,0
0,0,0,27,0,0,0,0,0,0,0,0,0,27,0,0,0
0,0,0,27,0,0,0,0,0,0,0,0,0,27,0,0,0
0,0,0,27,3,30,5,5,5,5,5,30,3,27,0,0,0
0,0,0,27,0,0,0,0,0,0,0,0,0,27,0,0,0
0,0,0,27,0,0,0,0,0,0,0,0,0,27,0,0,0
0,0,0,27,0,0,0,0,0,0,0,0,0,27,0,0,0
0,0,0,27,0,0,0,0,0,0,0,0,0,27,0,0,0
0,0,0,27,3,30,5,5,5,5,5,30,3,27,0,0,0
0,0,0,27,0,0,0,0,0,0,0,0,0,27,0,0,0
0,0,0,27,0,0,0,0,0,0,0,0,0,27,0,0,0
0,0,0,27,0,0,0,0,0,0,0,0,0,27,0,0,0
0,0,0,27,12,12,12,12,12,12,12,0,12,27,0,0,0
0,0,0,27,3,0,0,0,0,0,0,0,3,27,0,0,0
0,0,0,27,0,0,0,0,0,0,0,0,0,27,0,0,0
0,0,0,27,0,0,0,0,0,0,0,0,0,27,0,0,0
0,0,0,27,0,0,0,0,0,0,0,0,0,27,0,0,0
0,0,0,27,0,0,0,0,0,0,0,0,0,27,0,0,0
0,0,0,27,3,7,7,0,0,0,7,7,3,27,0,0,0
0,0,0,27,0,0,0,0,0,0,0,0,0,27,0,0,0
0,0,0,0,0,0,0,0,0,0,0,0,0,0,0,0,0
:endlayer
layer: 10
0,0,0,0,0,0,0,0,0,0,0,0,0,0,0,0,0
0,0,0,26,25,0,0,0,0,0,0,0,23,22,0,0,0
0,0,0,26,3,7,3,5,5,5,3,7,3,22,0,0,0
0,0,0,26,4,0,0,0,0,0,0,0,4,22,0,0,0
0,0,0,26,4,0,0,0,0,0,0,0,4,22,0,0,0
0,0,0,26,4,0,0,0,0,0,0,0,4,22,0,0,0
0,0,0,26,4,0,0,0,0,0,0,0,4,22,0,0,0
0,0,0,26,3,11,0,3,0,3,0,15,3,22,0,0,0
0,0,0,26,4,0,0,0,0,0,0,0,4,22,0,0,0
0,0,0,26,4,0,0,0,0,0,0,0,4,22,0,0,0
0,0,0,26,4,0,0,0,0,0,0,0,4,22,0,0,0
0,0,0,26,4,0,0,0,0,0,0,0,4,22,0,0,0
0,0,0,26,3,11,0,3,0,3,0,15,3,22,0,0,0
0,0,0,26,4,0,0,0,0,0,0,0,4,22,0,0,0
0,0,0,26,4,0,0,0,0,0,0,0,4,22,0,0,0
0,0,0,26,4,0,0,0,0,0,0,0,4,22,0,0,0
0,0,0,26,4,0,0,0,0,0,0,0,4,22,0,0,0
0,0,0,26,3,11,0,3,0,3,0,15,3,22,0,0,0
0,0,0,26,4,0,0,0,0,0,0,0,4,22,0,0,0
0,0,0,26,4,0,0,0,0,0,0,0,4,22,0,0,0
0,0,0,26,4,0,0,0,0,0,0,0,4,22,0,0,0
0,0,0,26,4,0,0,0,0,0,0,0,4,22,0,0,0
0,0,0,26,3,11,0,0,0,0,0,15,3,22,0,0,0
0,0,0,26,4,0,0,0,0,0,0,0,4,22,0,0,0
0,0,0,26,4,0,0,0,0,0,0,0,4,22,0,0,0
0,0,0,26,4,0,0,0,0,0,0,0,4,22,0,0,0
0,0,0,26,4,0,0,0,0,0,0,0,4,22,0,0,0
0,0,0,26,3,7,7,0,0,0,7,7,3,22,0,0,0
0,0,0,26,25,0,13,0,0,0,13,0,23,22,0,0,0
0,0,0,0,0,0,0,0,0,0,0,0,0,0,0,0,0
:endlayer
layer: 11
0,0,0,0,0,0,0,0,0,0,0,0,0,0,0,0,0
0,0,0,0,27,0,0,0,0,0,0,0,27,0,0,0,0
0,0,0,0,27,3,3,7,7,7,3,3,27,0,0,0,0
0,0,0,0,27,0,0,0,0,0,0,0,27,0,0,0,0
0,0,0,0,27,0,0,0,0,0,0,0,27,0,0,0,0
0,0,0,0,27,0,0,0,0,0,0,0,27,0,0,0,0
0,0,0,0,27,0,0,0,0,0,0,0,27,0,0,0,0
0,0,0,0,27,17,0,3,16,3,0,21,27,0,0,0,0
0,0,0,0,3,0,0,0,0,0,0,0,3,0,0,0,0
0,0,0,0,12,0,0,0,0,0,0,0,12,0,0,0,0
0,0,0,0,12,0,0,0,0,0,0,0,12,0,0,0,0
0,0,0,0,3,0,0,0,0,0,0,0,3,0,0,0,0
0,0,0,0,27,17,0,3,16,3,0,21,27,0,0,0,0
0,0,0,0,27,0,0,0,0,0,0,0,27,0,0,0,0
0,0,0,0,27,0,0,0,0,0,0,0,27,0,0,0,0
0,0,0,0,27,0,0,0,0,0,0,0,27,0,0,0,0
0,0,0,0,27,0,0,0,0,0,0,0,27,0,0,0,0
0,0,0,0,27,17,0,3,16,3,0,21,27,0,0,0,0
0,0,0,0,3,0,0,0,0,0,0,0,3,0,0,0,0
0,0,0,0,12,0,0,0,0,0,0,0,12,0,0,0,0
0,0,0,0,12,0,0,0,0,0,0,0,12,0,0,0,0
0,0,0,0,3,0,0,0,0,0,0,0,3,0,0,0,0
0,0,0,0,27,17,0,0,0,0,0,21,27,0,0,0,0
0,0,0,0,27,0,0,0,0,0,0,0,27,0,0,0,0
0,0,0,0,27,0,0,0,0,0,0,0,27,0,0,0,0
0,0,0,0,27,0,0,0,0,0,0,0,27,0,0,0,0
0,0,0,0,27,18,0,0,0,0,0,18,27,0,0,0,0
0,0,0,0,27,3,7,20,24,19,7,3,27,0,0,0,0
0,0,0,0,27,0,0,0,0,0,0,0,27,0,0,0,0
0,0,0,0,0,0,0,0,0,0,0,0,0,0,0,0,0
:endlayer
layer: 12
0,0,0,0,0,0,0,0,0,0,0,0,0,0,0,0,0
0,0,0,0,26,25,0,0,0,0,0,23,22,0,0,0,0
0,0,0,0,26,3,3,7,12,7,3,3,22,0,0,0,0
0,0,0,0,26,4,0,0,0,0,0,4,22,0,0,0,0
0,0,0,0,26,4,0,0,0,0,0,4,22,0,0,0,0
0,0,0,0,26,4,0,0,0,0,0,4,22,0,0,0,0
0,0,0,0,26,4,0,0,0,0,0,4,22,0,0,0,0
0,0,0,31,26,3,21,38,0,36,17,3,22,31,0,0,0
0,0,0,32,3,35,0,0,0,0,0,35,3,32,0,0,0
0,0,0,0,12,0,0,0,0,0,0,0,12,0,0,0,0
0,0,0,0,12,0,0,0,0,0,0,0,12,0,0,0,0
0,0,0,33,3,28,0,0,0,0,0,28,3,33,0,0,0
0,0,0,34,26,3,21,38,0,36,17,3,22,34,0,0,0
0,0,0,0,26,4,0,0,0,0,0,4,22,0,0,0,0
0,0,0,0,26,4,0,0,0,0,0,4,22,0,0,0,0
0,0,0,0,26,4,0,0,0,0,0,4,22,0,0,0,0
0,0,0,0,26,4,0,0,0,0,0,4,22,0,0,0,0
0,0,0,31,26,3,21,38,0,36,17,3,22,31,0,0,0
0,0,0,32,3,35,0,0,0,0,0,35,3,32,0,0,0
0,0,0,0,12,0,0,0,0,0,0,0,12,0,0,0,0
0,0,0,0,12,0,0,0,0,0,0,0,12,0,0,0,0
0,0,0,33,3,28,0,0,0,0,0,28,3,33,0,0,0
0,0,0,34,26,3,0,0,0,0,0,3,22,34,0,0,0
0,0,0,0,26,4,0,0,0,0,0,4,22,0,0,0,0
0,0,0,0,26,4,0,0,0,0,0,4,22,0,0,0,0
0,0,0,0,26,4,0,0,0,0,0,4,22,0,0,0,0
0,0,0,0,26,4,0,0,0,0,0,4,22,0,0,0,0
0,0,0,0,26,3,5,5,5,5,5,3,22,0,0,0,0
0,0,0,0,26,25,0,0,37,0,0,23,22,0,0,0,0
0,0,0,0,0,0,0,0,37,0,0,0,0,0,0,0,0
:endlayer
layer: 13
0,0,0,0,0,0,0,0,0,0,0,0,0,0,0,0,0
0,0,0,0,0,27,0,0,0,0,0,27,0,0,0,0,0
0,0,0,0,0,27,3,7,12,7,3,27,0,0,0,0,0
0,0,0,0,0,27,0,0,0,0,0,27,0,0,0,0,0
0,0,0,0,0,27,0,0,0,0,0,27,0,0,0,0,0
0,0,0,0,0,27,0,0,0,0,0,27,0,0,0,0,0
0,0,0,0,0,27,0,0,0,0,0,27,0,0,0,0,0
0,0,0,0,0,27,3,17,0,21,3,27,0,0,0,0,0
0,0,0,31,31,27,0,0,0,0,0,27,31,31,0,0,0
0,0,0,32,4,17,0,0,0,0,0,21,4,32,0,0,0
0,0,0,33,4,17,0,0,0,0,0,21,4,33,0,0,0
0,0,0,34,34,27,0,0,0,0,0,27,34,34,0,0,0
0,0,0,0,0,27,3,17,0,21,3,27,0,0,0,0,0
0,0,0,0,0,27,0,0,0,0,0,27,0,0,0,0,0
0,0,0,0,0,27,0,0,0,0,0,27,0,0,0,0,0
0,0,0,0,0,27,0,0,0,0,0,27,0,0,0,0,0
0,0,0,0,0,27,0,0,0,0,0,27,0,0,0,0,0
0,0,0,0,0,27,3,17,0,21,3,27,0,0,0,0,0
0,0,0,31,31,27,0,0,0,0,0,27,31,31,0,0,0
0,0,0,32,4,17,0,0,0,0,0,21,4,32,0,0,0
0,0,0,33,4,17,0,0,0,0,0,21,4,33,0,0,0
0,0,0,34,34,27,0,0,0,0,0,27,34,34,0,0,0
0,0,0,0,0,27,17,0,0,0,21,27,0,0,0,0,0
0,0,0,0,0,27,0,0,0,0,0,27,0,0,0,0,0
0,0,0,0,0,27,0,0,0,0,0,27,0,0,0,0,0
0,0,0,0,0,27,0,0,0,0,0,27,0,0,0,0,0
0,0,0,0,0,27,0,0,0,0,0,27,0,0,0,0,0
0,0,0,0,0,27,3,7,7,7,3,27,0,0,0,0,0
0,0,0,0,0,27,0,0,0,0,0,27,0,0,0,0,0
0,0,0,0,0,0,0,0,0,0,0,0,0,0,0,0,0
:endlayer
layer: 14
0,0,0,0,0,0,0,0,0,0,0,0,0,0,0,0,0
0,0,0,0,0,26,25,0,0,0,23,22,0,0,0,0,0
0,0,0,0,0,26,3,5,5,5,3,22,0,0,0,0,0
0,0,0,0,0,26,4,0,0,0,4,22,0,0,0,0,0
0,0,0,0,0,26,4,0,0,0,4,22,0,0,0,0,0
0,0,0,0,0,26,4,0,0,0,4,22,0,0,0,0,0
0,0,0,0,0,26,4,0,0,0,4,22,0,0,0,0,0
0,0,0,0,0,26,3,11,30,15,3,22,0,0,0,0,0
0,0,0,0,0,26,4,0,0,0,4,22,0,0,0,0,0
0,0,0,31,31,31,4,0,0,0,4,31,31,31,0,0,0
0,0,0,34,34,26,4,0,0,0,4,22,34,34,0,0,0
0,0,0,0,0,26,4,0,0,0,4,22,0,0,0,0,0
0,0,0,0,0,26,3,11,30,15,3,22,0,0,0,0,0
0,0,0,0,0,26,4,0,0,0,4,22,0,0,0,0,0
0,0,0,0,0,26,4,0,0,0,4,22,0,0,0,0,0
0,0,0,0,0,26,4,0,0,0,4,22,0,0,0,0,0
0,0,0,0,0,26,4,0,0,0,4,22,0,0,0,0,0
0,0,0,0,0,26,3,11,30,15,3,22,0,0,0,0,0
0,0,0,0,0,26,4,0,0,0,4,22,0,0,0,0,0
0,0,0,31,31,31,4,0,0,0,4,31,31,31,0,0,0
0,0,0,34,34,26,4,0,0,0,4,22,34,34,0,0,0
0,0,0,0,0,26,4,0,0,0,4,22,0,0,0,0,0
0,0,0,0,0,26,3,11,0,15,3,22,0,0,0,0,0
0,0,0,0,0,26,4,0,0,0,4,22,0,0,0,0,0
0,0,0,0,0,26,4,0,0,0,4,22,0,0,0,0,0
0,0,0,0,0,26,4,0,0,0,4,22,0,0,0,0,0
0,0,0,0,0,26,4,0,0,0,4,22,0,0,0,0,0
0,0,0,0,0,26,3,5,5,5,3,22,0,0,0,0,0
0,0,0,0,0,26,25,0,0,0,23,22,0,0,0,0,0
0,0,0,0,0,0,0,0,0,0,0,0,0,0,0,0,0
:endlayer
layer: 15
0,0,0,0,0,0,0,0,0,0,0,0,0,0,0,0,0
0,0,0,0,0,0,27,0,0,0,27,0,0,0,0,0,0
0,0,0,0,0,0,27,3,7,3,27,0,0,0,0,0,0
0,0,0,0,0,0,27,0,0,0,27,0,0,0,0,0,0
0,0,0,0,0,0,27,0,0,0,27,0,0,0,0,0,0
0,0,0,0,0,0,27,0,0,0,27,0,0,0,0,0,0
0,0,0,0,0,0,27,0,0,0,27,0,0,0,0,0,0
0,0,0,0,0,0,27,17,0,21,27,0,0,0,0,0,0
0,0,0,0,0,0,27,0,0,0,27,0,0,0,0,0,0
0,0,0,0,0,0,27,0,0,0,27,0,0,0,0,0,0
0,0,0,0,0,0,27,0,0,0,27,0,0,0,0,0,0
0,0,0,0,0,0,27,0,0,0,27,0,0,0,0,0,0
0,0,0,0,0,0,27,17,0,21,27,0,0,0,0,0,0
0,0,0,0,0,0,27,0,0,0,27,0,0,0,0,0,0
0,0,0,0,0,0,27,0,0,0,27,0,0,0,0,0,0
0,0,0,0,0,0,27,0,0,0,27,0,0,0,0,0,0
0,0,0,0,0,0,27,0,0,0,27,0,0,0,0,0,0
0,0,0,0,0,0,27,17,0,21,27,0,0,0,0,0,0
0,0,0,0,0,0,27,0,0,0,27,0,0,0,0,0,0
0,0,0,0,0,0,27,0,0,0,27,0,0,0,0,0,0
0,0,0,0,0,0,27,0,0,0,27,0,0,0,0,0,0
0,0,0,0,0,0,27,0,0,0,27,0,0,0,0,0,0
0,0,0,0,0,0,27,17,0,21,27,0,0,0,0,0,0
0,0,0,0,0,0,27,0,0,0,27,0,0,0,0,0,0
0,0,0,0,0,0,27,0,0,0,27,0,0,0,0,0,0
0,0,0,0,0,0,27,0,0,0,27,0,0,0,0,0,0
0,0,0,0,0,0,27,0,0,0,27,0,0,0,0,0,0
0,0,0,0,0,0,27,3,7,3,27,0,0,0,0,0,0
0,0,0,0,0,0,27,0,0,0,27,0,0,0,0,0,0
0,0,0,0,0,0,0,0,0,0,0,0,0,0,0,0,0
:endlayer
layer: 16
0,0,0,0,0,0,0,0,0,0,0,0,0,0,0,0,0
0,0,0,0,0,0,26,25,0,23,22,0,0,0,0,0,0
0,0,0,0,0,0,26,3,7,3,22,0,0,0,0,0,0
0,0,0,0,0,0,26,4,0,4,22,0,0,0,0,0,0
0,0,0,0,0,0,26,4,0,4,22,0,0,0,0,0,0
0,0,0,0,0,0,26,4,0,4,22,0,0,0,0,0,0
0,0,0,0,0,0,26,4,0,4,22,0,0,0,0,0,0
0,0,0,0,0,0,26,3,16,3,22,0,0,0,0,0,0
0,0,0,0,0,0,26,4,0,4,22,0,0,0,0,0,0
0,0,0,0,0,0,26,4,0,4,22,0,0,0,0,0,0
0,0,0,0,0,0,26,4,0,4,22,0,0,0,0,0,0
0,0,0,0,0,0,26,4,0,4,22,0,0,0,0,0,0
0,0,0,0,0,0,26,3,16,3,22,0,0,0,0,0,0
0,0,0,0,0,0,26,4,0,4,22,0,0,0,0,0,0
0,0,0,0,0,0,26,4,0,4,22,0,0,0,0,0,0
0,0,0,0,0,0,26,4,0,4,22,0,0,0,0,0,0
0,0,0,0,0,0,26,4,0,4,22,0,0,0,0,0,0
0,0,0,0,0,0,26,3,16,3,22,0,0,0,0,0,0
0,0,0,0,0,0,26,4,0,4,22,0,0,0,0,0,0
0,0,0,0,0,0,26,4,0,4,22,0,0,0,0,0,0
0,0,0,0,0,0,26,4,0,4,22,0,0,0,0,0,0
0,0,0,0,0,0,26,4,0,4,22,0,0,0,0,0,0
0,0,0,0,0,0,26,3,16,3,22,0,0,0,0,0,0
0,0,0,0,0,0,26,4,0,4,22,0,0,0,0,0,0
0,0,0,0,0,0,26,4,0,4,22,0,0,0,0,0,0
0,0,0,0,0,0,26,4,0,4,22,0,0,0,0,0,0
0,0,0,0,0,0,26,4,0,4,22,0,0,0,0,0,0
0,0,0,0,0,0,26,3,7,3,22,0,0,0,0,0,0
0,0,0,0,0,0,26,25,0,23,22,0,0,0,0,0,0
0,0,0,0,0,0,0,0,0,0,0,0,0,0,0,0,0
:endlayer
layer: 17
0,0,0,0,0,0,0,0,0,0,0,0,0,0,0,0,0
0,0,0,0,0,0,0,27,33,27,0,0,0,0,0,0,0
0,0,0,0,0,0,0,27,3,27,0,0,0,0,0,0,0
0,0,0,0,0,0,0,27,0,27,0,0,0,0,0,0,0
0,0,0,0,0,0,0,27,0,27,0,0,0,0,0,0,0
0,0,0,0,0,0,0,27,0,27,0,0,0,0,0,0,0
0,0,0,0,0,0,0,27,0,27,0,0,0,0,0,0,0
0,0,0,0,0,0,0,27,3,27,0,0,0,0,0,0,0
0,0,0,0,0,0,0,27,0,27,0,0,0,0,0,0,0
0,0,0,0,0,0,0,27,0,27,0,0,0,0,0,0,0
0,0,0,0,0,0,0,27,0,27,0,0,0,0,0,0,0
0,0,0,0,0,0,0,27,0,27,0,0,0,0,0,0,0
0,0,0,0,0,0,0,27,3,27,0,0,0,0,0,0,0
0,0,0,0,0,0,0,27,0,27,0,0,0,0,0,0,0
0,0,0,0,0,0,0,27,0,27,0,0,0,0,0,0,0
0,0,0,0,0,0,0,27,0,27,0,0,0,0,0,0,0
0,0,0,0,0,0,0,27,0,27,0,0,0,0,0,0,0
0,0,0,0,0,0,0,27,3,27,0,0,0,0,0,0,0
0,0,0,0,0,0,0,27,0,27,0,0,0,0,0,0,0
0,0,0,0,0,0,0,27,0,27,0,0,0,0,0,0,0
0,0,0,0,0,0,0,27,0,27,0,0,0,0,0,0,0
0,0,0,0,0,0,0,27,0,27,0,0,0,0,0,0,0
0,0,0,0,0,0,0,27,3,27,0,0,0,0,0,0,0
0,0,0,0,0,0,0,27,0,27,0,0,0,0,0,0,0
0,0,0,0,0,0,0,27,0,27,0,0,0,0,0,0,0
0,0,0,0,0,0,0,27,0,27,0,0,0,0,0,0,0
0,0,0,0,0,0,0,27,0,27,0,0,0,0,0,0,0
0,0,0,0,0,0,0,27,3,27,0,0,0,0,0,0,0
0,0,0,0,0,0,0,27,32,27,0,0,0,0,0,0,0
0,0,0,0,0,0,0,0,0,0,0,0,0,0,0,0,0
:endlayer
layer: 18
0,0,0,0,0,0,0,0,0,0,0,0,0,0,0,0,0
0,0,0,0,0,0,0,26,27,22,0,0,0,0,0,0,0
0,0,0,0,0,0,0,26,3,22,0,0,0,0,0,0,0
0,0,0,0,0,0,0,26,4,22,0,0,0,0,0,0,0
0,0,0,0,0,0,0,26,4,22,0,0,0,0,0,0,0
0,0,0,0,0,0,0,26,4,22,0,0,0,0,0,0,0
0,0,0,0,0,0,0,26,4,22,0,0,0,0,0,0,0
0,0,0,0,0,0,0,26,3,22,0,0,0,0,0,0,0
0,0,0,0,0,0,0,26,4,22,0,0,0,0,0,0,0
0,0,0,0,0,0,0,26,4,22,0,0,0,0,0,0,0
0,0,0,0,0,0,0,26,4,22,0,0,0,0,0,0,0
0,0,0,0,0,0,0,26,4,22,0,0,0,0,0,0,0
0,0,0,0,0,0,0,26,3,22,0,0,0,0,0,0,0
0,0,0,0,0,0,0,26,4,22,0,0,0,0,0,0,0
0,0,0,0,0,0,0,26,4,22,0,0,0,0,0,0,0
0,0,0,0,0,0,0,26,4,22,0,0,0,0,0,0,0
0,0,0,0,0,0,0,26,4,22,0,0,0,0,0,0,0
0,0,0,0,0,0,0,26,3,22,0,0,0,0,0,0,0
0,0,0,0,0,0,0,26,4,22,0,0,0,0,0,0,0
0,0,0,0,0,0,0,26,4,22,0,0,0,0,0,0,0
0,0,0,0,0,0,0,26,4,22,0,0,0,0,0,0,0
0,0,0,0,0,0,0,26,4,22,0,0,0,0,0,0,0
0,0,0,0,0,0,0,26,3,22,0,0,0,0,0,0,0
0,0,0,0,0,0,0,26,4,22,0,0,0,0,0,0,0
0,0,0,0,0,0,0,26,4,22,0,0,0,0,0,0,0
0,0,0,0,0,0,0,26,4,22,0,0,0,0,0,0,0
0,0,0,0,0,0,0,26,4,22,0,0,0,0,0,0,0
0,0,0,0,0,0,0,26,3,22,0,0,0,0,0,0,0
0,0,0,0,0,0,0,26,27,22,0,0,0,0,0,0,0
0,0,0,0,0,0,0,0,0,0,0,0,0,0,0,0,0
:endlayer
layer: 19
0,0,0,0,0,0,0,0,0,0,0,0,0,0,0,0,0
0,0,0,0,0,0,0,0,27,0,0,0,0,0,0,0,0
0,0,0,0,0,0,0,0,27,0,0,0,0,0,0,0,0
0,0,0,0,0,0,0,0,27,0,0,0,0,0,0,0,0
0,0,0,0,0,0,0,0,27,0,0,0,0,0,0,0,0
0,0,0,0,0,0,0,0,27,0,0,0,0,0,0,0,0
0,0,0,0,0,0,0,0,27,0,0,0,0,0,0,0,0
0,0,0,0,0,0,0,0,27,0,0,0,0,0,0,0,0
0,0,0,0,0,0,0,0,27,0,0,0,0,0,0,0,0
0,0,0,0,0,0,0,0,27,0,0,0,0,0,0,0,0
0,0,0,0,0,0,0,0,27,0,0,0,0,0,0,0,0
0,0,0,0,0,0,0,0,27,0,0,0,0,0,0,0,0
0,0,0,0,0,0,0,0,27,0,0,0,0,0,0,0,0
0,0,0,0,0,0,0,0,27,0,0,0,0,0,0,0,0
0,0,0,0,0,0,0,0,27,0,0,0,0,0,0,0,0
0,0,0,0,0,0,0,0,27,0,0,0,0,0,0,0,0
0,0,0,0,0,0,0,0,27,0,0,0,0,0,0,0,0
0,0,0,0,0,0,0,0,27,0,0,0,0,0,0,0,0
0,0,0,0,0,0,0,0,27,0,0,0,0,0,0,0,0
0,0,0,0,0,0,0,0,27,0,0,0,0,0,0,0,0
0,0,0,0,0,0,0,0,27,0,0,0,0,0,0,0,0
0,0,0,0,0,0,0,0,27,0,0,0,0,0,0,0,0
0,0,0,0,0,0,0,0,27,0,0,0,0,0,0,0,0
0,0,0,0,0,0,0,0,27,0,0,0,0,0,0,0,0
0,0,0,0,0,0,0,0,27,0,0,0,0,0,0,0,0
0,0,0,0,0,0,0,0,27,0,0,0,0,0,0,0,0
0,0,0,0,0,0,0,0,27,0,0,0,0,0,0,0,0
0,0,0,0,0,0,0,0,27,0,0,0,0,0,0,0,0
0,0,0,0,0,0,0,0,27,0,0,0,0,0,0,0,0
0,0,0,0,0,0,0,0,0,0,0,0,0,0,0,0,0
:endlayer
layer: 20
0,0,0,0,0,0,0,0,0,0,0,0,0,0,0,0,0
0,0,0,0,0,0,0,0,39,0,0,0,0,0,0,0,0
0,0,0,0,0,0,0,0,39,0,0,0,0,0,0,0,0
0,0,0,0,0,0,0,0,39,0,0,0,0,0,0,0,0
0,0,0,0,0,0,0,0,39,0,0,0,0,0,0,0,0
0,0,0,0,0,0,0,0,39,0,0,0,0,0,0,0,0
0,0,0,0,0,0,0,0,39,0,0,0,0,0,0,0,0
0,0,0,0,0,0,0,0,39,0,0,0,0,0,0,0,0
0,0,0,0,0,0,0,0,39,0,0,0,0,0,0,0,0
0,0,0,0,0,0,0,0,39,0,0,0,0,0,0,0,0
0,0,0,0,0,0,0,0,39,0,0,0,0,0,0,0,0
0,0,0,0,0,0,0,0,39,0,0,0,0,0,0,0,0
0,0,0,0,0,0,0,0,39,0,0,0,0,0,0,0,0
0,0,0,0,0,0,0,0,39,0,0,0,0,0,0,0,0
0,0,0,0,0,0,0,0,39,0,0,0,0,0,0,0,0
0,0,0,0,0,0,0,0,39,0,0,0,0,0,0,0,0
0,0,0,0,0,0,0,0,39,0,0,0,0,0,0,0,0
0,0,0,0,0,0,0,0,39,0,0,0,0,0,0,0,0
0,0,0,0,0,0,0,0,39,0,0,0,0,0,0,0,0
0,0,0,0,0,0,0,0,39,0,0,0,0,0,0,0,0
0,0,0,0,0,0,0,0,39,0,0,0,0,0,0,0,0
0,0,0,0,0,0,0,0,39,0,0,0,0,0,0,0,0
0,0,0,0,0,0,0,0,39,0,0,0,0,0,0,0,0
0,0,0,0,0,0,0,0,39,0,0,0,0,0,0,0,0
0,0,0,0,0,0,0,0,39,0,0,0,0,0,0,0,0
0,0,0,0,0,0,0,0,39,0,0,0,0,0,0,0,0
0,0,0,0,0,0,0,0,39,0,0,0,0,0,0,0,0
0,0,0,0,0,0,0,0,39,0,0,0,0,0,0,0,0
0,0,0,0,0,0,0,0,39,0,0,0,0,0,0,0,0
0,0,0,0,0,0,0,0,0,0,0,0,0,0,0,0,0
:endlayer

#### RULES ####
rule:
plugin=vanillaBlocks
number=1
data:
JSON:{blockState:{blockName:"minecraft:cobblestone"}}
:enddata
:endrule

rule:
plugin=vanillaBlocks
number=2
data:
JSON:{blockState:{blockName:"minecraft:grass",properties:{snowy:"false"}}}
:enddata
:endrule

rule:
plugin=vanillaBlocks
number=3
data:
JSON:{blockState:{blockName:"minecraft:log",properties:{variant:"spruce",axis:"y"}}}
:enddata
:endrule

rule:
plugin=vanillaBlocks
number=4
data:
JSON:{blockState:{blockName:"minecraft:log",properties:{variant:"spruce",axis:"z"}}}
:enddata
:endrule

rule:
plugin=vanillaBlocks
number=5
data:
JSON:{blockState:{blockName:"minecraft:log",properties:{variant:"spruce",axis:"x"}}}
:enddata
:endrule

rule:
plugin=vanillaBlocks
number=6
data:
JSON:{blockState:{blockName:"minecraft:stone",properties:{variant:"smooth_andesite"}}}
:enddata
:endrule

rule:
plugin=vanillaBlocks
number=7
data:
JSON:{blockState:{blockName:"minecraft:planks",properties:{variant:"oak"}}}
:enddata
:endrule

rule:
plugin=vanillaBlocks
number=8
data:
JSON:{blockState:{blockName:"minecraft:ladder",properties:{facing:"north"}}}
:enddata
:endrule

rule:
plugin=vanillaBlocks
number=9
data:
JSON:{blockState:{blockName:"minecraft:torch",properties:{facing:"up"}}}
:enddata
:endrule

rule:
plugin=doors
number=10
data:
JSON:{blockState:{blockName:"minecraft:spruce_door",properties:{hinge:"left",half:"lower",powered:"false",facing:"south",open:"false"}}}
:enddata
:endrule

rule:
plugin=vanillaBlocks
number=11
data:
JSON:{blockState:{blockName:"minecraft:torch",properties:{facing:"east"}}}
:enddata
:endrule

rule:
plugin=vanillaBlocks
number=12
data:
JSON:{blockState:{blockName:"minecraft:acacia_fence",properties:{east:"false",south:"false",north:"false",west:"false"}}}
:enddata
:endrule

rule:
plugin=vanillaBlocks
number=13
data:
JSON:{blockState:{blockName:"minecraft:torch",properties:{facing:"south"}}}
:enddata
:endrule

rule:
plugin=doors
number=14
data:
JSON:{blockState:{blockName:"minecraft:spruce_door",properties:{hinge:"left",half:"upper",powered:"false",facing:"east",open:"false"}}}
:enddata
:endrule

rule:
plugin=vanillaBlocks
number=15
data:
JSON:{blockState:{blockName:"minecraft:torch",properties:{facing:"west"}}}
:enddata
:endrule

rule:
plugin=vanillaBlocks
number=16
data:
JSON:{blockState:{blockName:"minecraft:wooden_slab",properties:{half:"top",variant:"dark_oak"}}}
:enddata
:endrule

rule:
plugin=vanillaBlocks
number=17
data:
JSON:{blockState:{blockName:"minecraft:dark_oak_stairs",properties:{half:"top",shape:"straight",facing:"west"}}}
:enddata
:endrule

rule:
plugin=vanillaBlocks
number=18
data:
JSON:{blockState:{blockName:"minecraft:torch",properties:{facing:"north"}}}
:enddata
:endrule

rule:
plugin=vanillaBlocks
number=19
data:
JSON:{blockState:{blockName:"minecraft:oak_stairs",properties:{half:"top",shape:"straight",facing:"east"}}}
:enddata
:endrule

rule:
plugin=vanillaBlocks
number=20
data:
JSON:{blockState:{blockName:"minecraft:oak_stairs",properties:{half:"top",shape:"straight",facing:"west"}}}
:enddata
:endrule

rule:
plugin=vanillaBlocks
number=21
data:
JSON:{blockState:{blockName:"minecraft:dark_oak_stairs",properties:{half:"top",shape:"straight",facing:"east"}}}
:enddata
:endrule

rule:
plugin=vanillaBlocks
number=22
data:
JSON:{blockState:{blockName:"minecraft:spruce_stairs",properties:{half:"bottom",shape:"straight",facing:"west"}}}
:enddata
:endrule

rule:
plugin=vanillaBlocks
number=23
data:
JSON:{blockState:{blockName:"minecraft:spruce_stairs",properties:{half:"top",shape:"straight",facing:"east"}}}
:enddata
:endrule

rule:
plugin=vanillaBlocks
number=24
data:
JSON:{blockState:{blockName:"minecraft:wooden_slab",properties:{half:"top",variant:"oak"}}}
:enddata
:endrule

rule:
plugin=vanillaBlocks
number=25
data:
JSON:{blockState:{blockName:"minecraft:spruce_stairs",properties:{half:"top",shape:"straight",facing:"west"}}}
:enddata
:endrule

rule:
plugin=vanillaBlocks
number=26
data:
JSON:{blockState:{blockName:"minecraft:spruce_stairs",properties:{half:"bottom",shape:"straight",facing:"east"}}}
:enddata
:endrule

rule:
plugin=vanillaBlocks
number=27
data:
JSON:{blockState:{blockName:"minecraft:planks",properties:{variant:"spruce"}}}
:enddata
:endrule

rule:
plugin=vanillaBlocks
number=28
data:
JSON:{blockState:{blockName:"minecraft:dark_oak_stairs",properties:{half:"top",shape:"straight",facing:"south"}}}
:enddata
:endrule

rule:
plugin=vanillaBlocks
number=29
data:
JSON:{blockState:{blockName:"minecraft:wooden_slab",properties:{half:"top",variant:"spruce"}}}
:enddata
:endrule

rule:
plugin=vanillaBlocks
number=30
data:
JSON:{blockState:{blockName:"minecraft:wooden_slab",properties:{half:"bottom",variant:"dark_oak"}}}
:enddata
:endrule

rule:
plugin=vanillaBlocks
number=31
data:
JSON:{blockState:{blockName:"minecraft:spruce_stairs",properties:{half:"bottom",shape:"straight",facing:"south"}}}
:enddata
:endrule

rule:
plugin=vanillaBlocks
number=32
data:
JSON:{blockState:{blockName:"minecraft:spruce_stairs",properties:{half:"top",shape:"straight",facing:"north"}}}
:enddata
:endrule

rule:
plugin=vanillaBlocks
number=33
data:
JSON:{blockState:{blockName:"minecraft:spruce_stairs",properties:{half:"top",shape:"straight",facing:"south"}}}
:enddata
:endrule

rule:
plugin=vanillaBlocks
number=34
data:
JSON:{blockState:{blockName:"minecraft:spruce_stairs",properties:{half:"bottom",shape:"straight",facing:"north"}}}
:enddata
:endrule

rule:
plugin=vanillaBlocks
number=35
data:
JSON:{blockState:{blockName:"minecraft:dark_oak_stairs",properties:{half:"top",shape:"straight",facing:"north"}}}
:enddata
:endrule

rule:
plugin=vanillaBlocks
number=36
data:
JSON:{blockState:{blockName:"minecraft:dark_oak_stairs",properties:{half:"bottom",shape:"straight",facing:"east"}}}
:enddata
:endrule

rule:
plugin=vanillaBlocks
number=37
data:
JSON:{blockState:{blockName:"minecraft:spruce_fence",properties:{east:"false",south:"false",north:"false",west:"false"}}}
:enddata
:endrule

rule:
plugin=vanillaBlocks
number=38
data:
JSON:{blockState:{blockName:"minecraft:dark_oak_stairs",properties:{half:"bottom",shape:"straight",facing:"west"}}}
:enddata
:endrule

rule:
plugin=vanillaBlocks
number=39
data:
JSON:{blockState:{blockName:"minecraft:wooden_slab",properties:{half:"bottom",variant:"spruce"}}}
:enddata
:endrule

#### ENTITIES ####
entity:
plugin=entity
number=0
data:
JSON:{yOffset:0.0f,xOffset:0.875f,rotation:348.96106f,mobID:"minecraft:item",zOffset:0.875f,position:3023858302992L,entityData:{Motion:[0.0d,-0.0d,0.0d],ForgeData:{},Health:5s,Invulnerable:0b,Air:300s,OnGround:1b,Dimension:0,PortalCooldown:0,Rotation:[258.96106f,0.0f],UpdateBlocked:0b,FallDistance:0.0f,Item:{ForgeCaps:{"customnpcs:itemscripteddata":{}},id:"minecraft:torch",Count:1b,Damage:0s},Pos:[209.875d,7.0d,-142.875d],PickupDelay:0s,Fire:-1s,ForgeCaps:{"llibrary:extendedentitydatacapability":{},"metallurgy:punch_effect":{hasAiDisabled:1b,knockbackTicks:0,ticks:0}},Lifespan:6000,Age:3073s}}
:enddata
:endentity

