# Ancient Warfare Structure Template File
# Auto-generated structure template file. created on: 4/19/2023 at: 17:46:3
# Lines beginning with # denote comments

header:
version=2.11
name=SB_kennel_medium_oak
mods=
size=19,7,13
offset=2,1,12
:endheader

#### VALIDATION ####
validation:
type=ground
structureAuthor=TheOddlySeagull
survival=true
worldGenEnabled=false
unique=false
preserveBlocks=false
preventNaturalHostileSpawns=false
selectionWeight=1
clusterValue=1
minDuplicateDistance=1
dimensionWhiteList=true
dimensionList=
biomeGroupList=
biomeWhiteList=true
biomeList=
leveling=0
fill=0
border=0
blockSwap=false
territoryName=
biomeReplacement=minecraft:
minGenerationHeight=0
maxGenerationHeight=255
:endvalidation

#### LAYERS ####
layer: 0
2,2,2,2,2,2,2,2,2,2,2,2,2,2,2,1,2,2,1
2,2,2,2,3,2,3,3,3,2,3,3,2,3,4,4,3,3,2
2,2,2,2,3,2,2,2,3,3,2,3,2,4,3,3,3,3,2
2,2,2,2,3,3,2,3,3,2,2,2,2,4,3,4,4,4,1
2,2,2,2,3,2,2,2,3,2,3,2,2,3,3,4,3,3,2
2,2,2,2,3,2,3,2,2,3,3,2,2,4,4,3,4,3,2
2,2,2,2,2,2,2,2,2,2,2,2,2,4,4,4,4,3,1
2,4,3,4,4,3,4,3,4,4,4,4,4,4,3,4,4,3,2
2,3,4,3,3,4,4,4,3,3,3,3,4,4,3,4,3,4,2
2,4,3,3,4,3,3,3,4,4,4,4,4,3,3,4,4,3,1
2,4,3,4,3,4,3,4,4,4,4,4,4,3,3,3,4,4,2
2,4,3,3,3,3,3,3,4,3,3,3,3,4,3,4,4,4,2
2,2,2,1,2,2,1,2,2,1,2,2,1,2,2,1,2,2,1
:endlayer
layer: 1
5,0,0,5,7,7,5,7,7,5,7,7,5,2,2,1,2,2,1
0,0,0,8,0,0,0,0,0,0,0,0,6,0,0,0,0,0,2
0,0,0,8,0,0,0,0,0,0,0,0,6,0,0,0,0,0,2
5,0,0,5,0,0,0,0,0,0,0,0,5,0,0,0,0,0,1
11,0,0,8,0,0,0,0,0,0,0,0,6,0,0,0,0,0,2
11,9,9,8,0,0,0,0,0,0,0,0,6,0,0,0,0,0,2
5,10,10,5,0,0,5,0,0,5,0,0,5,0,0,0,0,0,1
8,0,0,0,0,0,0,0,0,0,0,0,0,0,0,0,0,0,2
8,0,0,0,0,0,0,0,0,0,0,0,0,0,0,0,0,0,2
5,0,0,0,0,0,0,0,0,0,0,0,0,0,0,0,0,0,1
8,0,0,0,0,0,0,0,0,0,0,0,0,0,0,0,0,0,2
8,0,0,0,0,0,0,0,0,0,0,0,0,0,0,0,0,0,2
5,0,0,1,2,2,1,2,2,1,2,2,1,2,2,1,2,2,1
:endlayer
layer: 2
5,0,0,5,7,7,5,7,7,5,7,7,5,11,11,1,11,11,1
0,0,0,8,0,0,0,0,0,0,0,0,6,0,0,13,0,0,11
0,0,0,8,0,0,0,0,0,0,0,0,6,0,0,0,0,0,11
5,0,0,5,0,0,0,0,0,0,0,0,5,0,0,0,0,12,1
11,9,9,8,0,0,0,0,0,0,0,0,6,0,0,0,0,0,11
11,10,10,8,0,0,0,0,0,0,0,0,6,0,0,0,0,0,11
5,0,0,5,0,0,5,0,0,5,0,0,5,0,0,0,0,12,1
8,0,0,0,0,0,0,0,0,0,0,0,0,0,0,0,0,0,11
8,0,0,0,0,0,0,0,0,0,0,0,0,0,0,0,0,0,11
5,0,0,0,0,0,0,0,0,0,0,0,0,0,0,0,0,12,1
8,0,0,0,0,0,0,0,0,0,0,0,0,0,0,0,0,0,11
8,0,0,14,0,0,14,0,0,14,0,0,14,0,0,14,0,0,11
5,0,0,1,11,11,1,11,11,1,11,11,1,11,11,1,11,11,1
:endlayer
layer: 3
5,11,11,5,7,7,5,7,7,5,7,7,5,15,15,15,15,15,15
11,0,0,8,0,0,13,0,0,13,0,0,6,0,0,0,0,0,15
11,0,12,8,0,0,0,0,0,0,0,0,6,0,0,0,0,0,15
5,9,9,5,18,0,0,0,0,0,0,12,5,0,0,0,0,0,15
11,10,10,8,0,0,0,0,0,0,0,0,6,0,0,0,0,0,15
11,0,0,8,0,0,14,0,0,14,0,0,6,0,0,0,0,0,15
5,0,0,5,17,16,5,17,16,5,17,16,5,0,0,0,0,0,15
8,0,0,0,0,0,0,0,0,0,0,0,0,0,0,0,0,0,15
8,0,0,0,0,0,0,0,0,0,0,0,0,0,0,0,0,0,15
5,0,0,0,0,0,0,0,0,0,0,0,0,0,0,0,0,0,15
8,0,0,0,0,0,0,0,0,0,0,0,0,0,0,0,0,0,15
8,0,0,0,0,0,0,0,0,0,0,0,0,0,0,0,0,0,15
5,0,0,15,15,15,15,15,15,15,15,15,15,15,15,15,15,15,15
:endlayer
layer: 4
5,20,20,5,20,20,5,20,20,5,20,20,5,18,0,0,0,0,0
19,2,2,19,21,8,21,8,21,8,21,8,19,0,0,0,0,0,0
19,2,2,19,21,8,21,8,21,8,21,8,19,0,0,0,0,0,0
5,10,10,5,21,8,21,8,21,8,21,8,5,18,0,0,0,0,0
19,0,0,19,21,8,21,8,21,8,21,8,19,0,0,0,0,0,0
19,0,0,19,21,8,21,8,21,8,21,8,19,0,0,0,0,0,0
5,0,0,5,20,20,5,20,20,5,20,20,5,18,0,0,0,0,0
22,0,0,13,0,0,13,0,0,13,0,0,13,0,0,0,0,0,0
22,0,0,0,0,0,0,0,0,0,0,0,0,0,0,0,0,0,0
5,0,0,0,0,0,0,0,0,0,0,0,0,0,0,0,0,0,0
22,0,0,0,0,0,0,0,0,0,0,0,0,0,0,0,0,0,0
22,0,0,0,0,0,0,0,0,0,0,0,0,0,0,0,0,0,0
5,0,0,0,0,0,0,0,0,0,0,0,0,0,0,0,0,0,0
:endlayer
layer: 5
5,11,11,5,11,11,5,11,11,5,11,11,5,0,0,0,0,0,0
11,0,0,13,0,0,13,0,0,13,0,0,11,0,0,0,0,0,0
11,0,0,14,0,0,0,0,0,0,0,0,11,0,0,0,0,0,0
5,0,12,5,18,0,0,0,0,0,0,12,5,0,0,0,0,0,0
11,0,0,11,0,0,0,0,0,0,0,0,11,0,0,0,0,0,0
11,0,0,11,0,0,14,0,0,14,0,0,11,0,0,0,0,0,0
5,0,0,5,11,11,5,11,11,5,11,11,5,0,0,0,0,0,0
0,0,0,0,0,0,0,0,0,0,0,0,0,0,0,0,0,0,0
0,0,0,0,0,0,0,0,0,0,0,0,0,0,0,0,0,0,0
22,0,0,0,0,0,0,0,0,0,0,0,0,0,0,0,0,0,0
0,0,0,0,0,0,0,0,0,0,0,0,0,0,0,0,0,0,0
0,0,0,0,0,0,0,0,0,0,0,0,0,0,0,0,0,0,0
22,0,0,0,0,0,0,0,0,0,0,0,0,0,0,0,0,0,0
:endlayer
layer: 6
22,0,0,22,0,0,22,0,0,22,0,0,22,0,0,0,0,0,0
0,0,0,0,0,0,0,0,0,0,0,0,0,0,0,0,0,0,0
0,0,0,0,0,0,0,0,0,0,0,0,0,0,0,0,0,0,0
22,0,0,22,0,0,0,0,0,0,0,0,22,0,0,0,0,0,0
0,0,0,0,0,0,0,0,0,0,0,0,0,0,0,0,0,0,0
0,0,0,0,0,0,0,0,0,0,0,0,0,0,0,0,0,0,0
22,0,0,22,0,0,22,0,0,22,0,0,22,0,0,0,0,0,0
0,0,0,0,0,0,0,0,0,0,0,0,0,0,0,0,0,0,0
0,0,0,0,0,0,0,0,0,0,0,0,0,0,0,0,0,0,0
0,0,0,0,0,0,0,0,0,0,0,0,0,0,0,0,0,0,0
0,0,0,0,0,0,0,0,0,0,0,0,0,0,0,0,0,0,0
0,0,0,0,0,0,0,0,0,0,0,0,0,0,0,0,0,0,0
0,0,0,0,0,0,0,0,0,0,0,0,0,0,0,0,0,0,0
:endlayer

#### RULES ####
rule:
plugin=vanillaBlocks
number=1
data:
JSON:{blockState:{blockName:"minecraft:stonebrick",properties:{variant:"stonebrick"}}}
:enddata
:endrule

rule:
plugin=vanillaBlocks
number=2
data:
JSON:{blockState:{blockName:"minecraft:cobblestone"}}
:enddata
:endrule

rule:
plugin=vanillaBlocks
number=3
data:
JSON:{blockState:{blockName:"minecraft:dirt",properties:{variant:"coarse_dirt",snowy:"false"}}}
:enddata
:endrule

rule:
plugin=vanillaBlocks
number=4
data:
JSON:{blockState:{blockName:"minecraft:grass",properties:{snowy:"false"}}}
:enddata
:endrule

rule:
plugin=vanillaBlocks
number=5
data:
JSON:{blockState:{blockName:"minecraft:log",properties:{variant:"oak",axis:"y"}}}
:enddata
:endrule

rule:
plugin=vanillaBlocks
number=6
data:
JSON:{blockState:{blockName:"minecraft:oak_stairs",properties:{half:"bottom",shape:"straight",facing:"west"}}}
:enddata
:endrule

rule:
plugin=vanillaBlocks
number=7
data:
JSON:{blockState:{blockName:"minecraft:oak_stairs",properties:{half:"bottom",shape:"straight",facing:"south"}}}
:enddata
:endrule

rule:
plugin=vanillaBlocks
number=8
data:
JSON:{blockState:{blockName:"minecraft:planks",properties:{variant:"oak"}}}
:enddata
:endrule

rule:
plugin=vanillaBlocks
number=9
data:
JSON:{blockState:{blockName:"minecraft:stone_stairs",properties:{half:"top",shape:"straight",facing:"south"}}}
:enddata
:endrule

rule:
plugin=vanillaBlocks
number=10
data:
JSON:{blockState:{blockName:"minecraft:stone_stairs",properties:{half:"bottom",shape:"straight",facing:"north"}}}
:enddata
:endrule

rule:
plugin=vanillaBlocks
number=11
data:
JSON:{blockState:{blockName:"minecraft:fence",properties:{east:"false",south:"false",north:"false",west:"false"}}}
:enddata
:endrule

rule:
plugin=vanillaBlocks
number=12
data:
JSON:{blockState:{blockName:"minecraft:torch",properties:{facing:"west"}}}
:enddata
:endrule

rule:
plugin=vanillaBlocks
number=13
data:
JSON:{blockState:{blockName:"minecraft:torch",properties:{facing:"south"}}}
:enddata
:endrule

rule:
plugin=vanillaBlocks
number=14
data:
JSON:{blockState:{blockName:"minecraft:torch",properties:{facing:"north"}}}
:enddata
:endrule

rule:
plugin=vanillaBlocks
number=15
data:
JSON:{blockState:{blockName:"minecraft:stone_slab",properties:{half:"bottom",variant:"cobblestone"}}}
:enddata
:endrule

rule:
plugin=vanillaBlocks
number=16
data:
JSON:{blockState:{blockName:"minecraft:oak_stairs",properties:{half:"top",shape:"straight",facing:"east"}}}
:enddata
:endrule

rule:
plugin=vanillaBlocks
number=17
data:
JSON:{blockState:{blockName:"minecraft:oak_stairs",properties:{half:"top",shape:"straight",facing:"west"}}}
:enddata
:endrule

rule:
plugin=vanillaBlocks
number=18
data:
JSON:{blockState:{blockName:"minecraft:torch",properties:{facing:"east"}}}
:enddata
:endrule

rule:
plugin=vanillaBlocks
number=19
data:
JSON:{blockState:{blockName:"minecraft:log",properties:{variant:"oak",axis:"z"}}}
:enddata
:endrule

rule:
plugin=vanillaBlocks
number=20
data:
JSON:{blockState:{blockName:"minecraft:log",properties:{variant:"oak",axis:"x"}}}
:enddata
:endrule

rule:
plugin=vanillaBlocks
number=21
data:
JSON:{blockState:{blockName:"minecraft:wooden_slab",properties:{half:"top",variant:"oak"}}}
:enddata
:endrule

rule:
plugin=vanillaBlocks
number=22
data:
JSON:{blockState:{blockName:"minecraft:wooden_slab",properties:{half:"bottom",variant:"oak"}}}
:enddata
:endrule

#### ENTITIES ####
