# Ancient Warfare Structure Template File
# Auto-generated structure template file. created on: 3/13/2021 at: 14:30:26
# Lines beginning with # denote comments

header:
version=2.11
name=SurvivalBuild_FortWall_large_type1_StraightTower_jungle
mods=
size=16,29,16
offset=15,4,0
:endheader

#### VALIDATION ####
validation:
type=ground
structureAuthor=TheOddlySeagull
survival=true
worldGenEnabled=false
unique=false
preserveBlocks=false
preventNaturalHostileSpawns=false
selectionWeight=1
clusterValue=1
minDuplicateDistance=1
dimensionWhiteList=true
dimensionList=
biomeGroupList=
biomeWhiteList=true
biomeList=
leveling=0
fill=0
border=0
blockSwap=false
territoryName=
biomeReplacement=minecraft:
minGenerationHeight=0
maxGenerationHeight=255
:endvalidation

#### LAYERS ####
layer: 0
1,1,1,1,1,2,2,2,2,2,2,2,2,2,2,1
1,1,1,1,1,2,2,2,2,2,2,2,2,2,2,1
1,1,1,1,1,2,2,2,2,2,2,2,2,2,2,1
1,1,1,1,1,2,2,2,2,2,2,2,2,2,2,1
1,1,1,1,1,2,2,2,2,2,2,2,2,2,2,1
1,1,1,1,1,2,2,2,2,2,2,2,2,2,2,1
1,1,1,1,2,2,2,2,2,2,2,2,2,2,2,1
1,1,1,1,2,2,2,2,2,2,2,2,2,2,2,1
1,1,1,1,2,2,2,2,2,2,2,2,2,2,2,1
1,1,1,1,2,2,2,2,2,2,2,2,2,2,2,1
1,1,1,1,1,2,2,2,2,2,2,2,2,2,2,1
1,1,1,1,1,2,2,2,2,2,2,2,2,2,2,1
1,1,1,1,1,2,2,2,2,2,2,2,2,2,2,1
1,1,1,1,1,2,2,2,2,2,2,2,2,2,2,1
1,1,1,1,1,2,2,2,2,2,2,2,2,2,2,1
1,1,1,1,1,2,2,2,2,2,2,2,2,2,2,1
:endlayer
layer: 1
1,1,1,1,1,2,2,2,2,2,0,0,0,0,2,1
1,1,1,1,1,2,2,2,2,2,0,0,0,0,2,1
1,1,1,1,1,2,2,2,2,2,0,0,0,0,2,1
1,1,1,1,1,2,2,2,2,2,0,0,0,0,2,1
1,1,1,1,1,2,2,2,2,2,0,0,0,0,2,1
1,1,1,1,1,2,2,2,2,2,2,0,0,0,2,1
1,1,1,1,2,2,2,2,2,2,2,2,0,0,2,1
1,1,1,1,2,2,2,2,2,2,2,2,0,0,2,1
1,1,1,1,2,2,2,2,2,2,2,2,0,0,2,1
1,1,1,1,2,2,2,2,2,2,2,2,0,0,2,1
1,1,1,1,1,2,2,2,2,2,2,0,0,0,2,1
1,1,1,1,1,2,2,2,2,2,0,0,0,0,2,1
1,1,1,1,1,2,2,2,2,2,0,0,0,0,2,1
1,1,1,1,1,2,2,2,2,2,0,0,0,0,2,1
1,1,1,1,1,2,2,2,2,2,0,0,0,0,2,1
1,1,1,1,1,2,2,2,2,2,0,0,0,0,2,1
:endlayer
layer: 2
1,1,1,1,1,2,2,2,2,2,0,0,0,0,2,1
1,1,1,1,1,2,2,2,2,2,0,0,0,0,2,1
1,1,1,1,1,2,2,2,2,2,0,0,0,0,2,1
1,1,1,1,1,2,2,2,2,2,0,0,0,0,2,1
1,1,1,1,1,2,2,2,2,2,0,0,0,0,2,1
1,1,1,1,1,2,2,2,2,2,2,0,0,0,2,1
1,1,1,1,2,2,2,2,2,2,2,2,0,0,2,1
1,1,1,1,2,2,2,2,2,2,2,2,0,0,2,1
1,1,1,1,2,2,2,2,2,2,2,2,0,0,2,1
1,1,1,1,2,2,2,2,2,2,2,2,0,0,2,1
1,1,1,1,1,2,2,2,2,2,2,0,0,0,2,1
1,1,1,1,1,2,2,2,2,2,0,0,0,0,2,1
1,1,1,1,1,2,2,2,2,2,0,0,0,0,2,1
1,1,1,1,1,2,2,2,2,2,0,0,0,0,2,1
1,1,1,1,1,2,2,2,2,2,0,0,0,0,2,1
1,1,1,1,1,2,2,2,2,2,0,0,0,0,2,1
:endlayer
layer: 3
3,3,3,3,3,2,2,2,2,2,0,0,0,0,2,3
3,3,3,3,3,2,2,2,2,2,0,0,0,0,2,3
3,3,3,3,3,2,2,2,2,2,0,0,0,0,2,3
3,3,3,3,3,2,2,2,2,2,0,0,0,0,2,3
3,3,3,3,3,2,2,2,2,2,0,0,0,0,2,3
3,3,3,3,3,2,2,2,2,2,2,0,0,0,2,3
3,3,3,2,2,2,2,2,2,2,2,2,0,0,2,3
3,3,3,2,2,2,2,2,2,2,2,2,0,0,2,3
3,3,3,2,2,2,2,2,2,2,2,2,0,0,2,3
3,3,3,2,2,2,2,2,2,2,2,2,0,0,2,3
3,3,3,3,3,2,2,2,2,2,2,0,0,0,2,3
3,3,3,3,3,2,2,2,2,2,0,0,0,0,2,3
3,3,3,3,3,2,2,2,2,2,0,0,0,0,2,3
3,3,3,3,3,2,2,2,2,2,0,0,0,0,2,3
3,3,3,3,3,2,2,2,2,2,0,0,0,0,2,3
3,3,3,3,3,2,2,2,2,2,0,0,0,0,2,3
:endlayer
layer: 4
0,0,0,0,0,4,2,2,2,4,0,0,0,0,2,0
0,0,0,0,0,7,2,2,2,6,0,0,0,0,5,0
0,0,0,0,0,7,2,2,2,6,0,0,0,0,5,0
0,0,0,0,0,4,2,2,2,4,0,0,0,0,2,0
0,0,0,0,0,4,2,2,2,2,0,0,0,0,2,0
0,0,0,0,0,2,2,2,2,2,2,0,0,0,5,0
0,0,0,8,2,2,2,2,2,2,2,2,0,0,5,0
0,0,0,0,0,5,5,2,2,2,2,2,0,0,2,0
0,0,0,0,0,5,5,4,2,2,2,2,0,0,2,0
0,0,0,8,2,2,2,2,2,2,2,2,0,0,5,0
0,0,0,0,0,2,2,2,2,2,2,0,0,0,5,0
0,0,0,0,0,4,2,2,2,2,0,0,0,0,2,0
0,0,0,0,0,4,2,2,2,4,0,0,0,0,2,0
0,0,0,0,0,7,2,2,2,6,0,0,0,0,5,0
0,0,0,0,0,7,2,2,2,6,0,0,0,0,5,0
0,0,0,0,0,4,2,2,2,4,0,0,0,0,2,0
:endlayer
layer: 5
0,0,0,0,0,4,2,2,2,4,0,0,0,0,5,0
0,0,0,0,0,0,2,2,2,9,0,0,0,0,0,0
0,0,0,0,0,0,2,2,2,9,0,0,0,0,0,0
0,0,0,0,0,4,2,2,2,4,0,0,0,0,5,0
0,0,0,0,0,4,2,2,2,2,0,0,0,0,5,0
0,0,0,0,0,2,2,2,2,2,2,0,0,0,0,0
0,0,0,8,2,2,2,2,2,2,2,2,0,0,0,0
0,0,0,0,0,0,0,2,2,2,2,2,0,0,5,0
0,0,0,0,0,0,0,4,2,2,2,2,0,0,5,0
0,0,0,8,2,0,0,5,2,2,2,2,0,0,0,0
0,0,0,0,0,2,0,5,2,2,2,0,0,0,0,0
0,0,0,0,0,4,2,2,2,2,0,0,0,0,5,0
0,0,0,0,0,4,2,2,2,4,0,0,0,0,5,0
0,0,0,0,0,0,2,2,2,9,0,0,0,0,0,0
0,0,0,0,0,0,2,2,2,9,0,0,0,0,0,0
0,0,0,0,0,4,2,2,2,4,0,0,0,0,5,0
:endlayer
layer: 6
0,0,0,0,0,4,2,2,2,4,0,0,0,0,0,0
0,0,0,0,0,0,2,2,2,0,0,0,0,0,0,0
0,0,0,0,0,0,2,2,2,0,0,0,0,0,0,0
0,0,0,0,0,4,2,2,2,4,0,0,0,0,0,0
0,0,0,0,0,4,2,2,2,2,0,0,0,0,0,0
0,0,0,0,10,2,2,2,2,2,2,0,0,0,0,0
0,0,0,8,2,2,2,2,2,2,2,2,0,0,0,0
0,0,0,0,0,0,0,2,2,2,2,2,0,0,0,0
0,0,0,0,0,0,0,4,5,5,2,2,0,0,0,0
0,0,0,8,2,0,0,0,0,0,2,2,0,0,0,0
0,0,0,0,11,2,0,10,0,2,2,0,0,0,0,0
0,0,0,0,0,4,2,2,2,2,0,0,0,0,0,0
0,0,0,0,0,4,2,2,2,4,0,0,0,0,0,0
0,0,0,0,0,0,2,2,2,0,0,0,0,0,0,0
0,0,0,0,0,0,2,2,2,0,0,0,0,0,0,0
0,0,0,0,0,4,2,2,2,4,0,0,0,0,0,0
:endlayer
layer: 7
0,0,0,0,0,4,2,2,2,4,0,0,0,0,0,0
0,0,0,0,0,0,2,2,2,0,0,0,0,0,0,0
0,0,0,0,0,0,2,2,2,0,0,0,0,0,0,0
0,0,0,0,0,4,2,2,2,4,0,0,0,0,0,0
0,0,0,0,0,4,2,2,2,2,0,0,0,0,0,0
0,0,0,0,0,2,2,2,2,2,2,0,0,0,0,0
0,0,0,12,2,2,2,5,0,2,2,2,0,0,0,0
0,0,0,16,17,14,14,5,0,0,2,2,0,0,0,0
0,0,0,16,15,14,14,4,0,13,2,2,0,0,0,0
0,0,0,12,2,0,0,0,0,0,2,2,0,0,0,0
0,0,0,0,0,2,0,0,0,2,2,0,0,0,0,0
0,0,0,0,0,4,2,2,2,2,0,0,0,0,0,0
0,0,0,0,0,4,2,2,2,4,0,0,0,0,0,0
0,0,0,0,0,0,2,2,2,0,0,0,0,0,0,0
0,0,0,0,0,0,2,2,2,0,0,0,0,0,0,0
0,0,0,0,0,4,2,2,2,4,0,0,0,0,0,0
:endlayer
layer: 8
0,0,0,0,0,4,2,2,2,4,0,0,0,0,0,0
0,0,0,0,0,0,2,2,2,0,0,0,0,0,0,0
0,0,0,0,0,0,2,2,2,0,0,0,0,0,0,0
0,0,0,0,0,4,2,2,2,4,0,0,0,0,0,0
0,0,0,0,0,4,2,2,2,2,0,0,0,0,0,0
0,0,0,0,0,2,2,2,2,2,2,0,0,0,0,0
0,0,0,0,2,2,0,11,0,2,2,2,0,0,0,0
0,0,0,7,2,0,0,0,0,0,2,2,0,0,0,0
0,0,0,7,2,5,5,4,0,0,2,2,0,0,0,0
0,0,0,0,2,2,2,14,0,0,2,2,0,0,0,0
0,0,0,0,0,2,2,14,0,2,2,0,0,0,0,0
0,0,0,0,0,4,2,2,2,2,0,0,0,0,0,0
0,0,0,0,0,4,2,2,2,4,0,0,0,0,0,0
0,0,0,0,0,0,2,2,2,0,0,0,0,0,0,0
0,0,0,0,0,0,2,2,2,0,0,0,0,0,0,0
0,0,0,0,0,4,2,2,2,4,0,0,0,0,0,0
:endlayer
layer: 9
0,0,0,0,0,4,2,2,2,4,0,0,0,0,0,0
0,0,0,0,0,19,2,2,2,19,0,0,0,0,0,0
0,0,0,0,0,18,2,2,2,18,0,0,0,0,0,0
0,0,0,0,0,4,2,2,2,4,0,0,0,0,0,0
0,0,0,0,0,4,2,2,2,2,8,0,0,0,0,0
0,0,0,0,0,2,2,2,2,2,2,0,0,0,0,0
0,0,0,0,2,2,0,0,0,2,2,2,0,0,0,0
0,0,0,0,2,0,0,0,0,0,2,2,6,0,0,0
0,0,0,0,5,0,0,4,14,14,2,2,6,0,0,0
0,0,0,0,2,0,0,21,2,2,2,2,0,0,0,0
0,0,0,0,0,2,20,20,2,2,2,0,0,0,0,0
0,0,0,0,0,4,2,2,2,2,8,0,0,0,0,0
0,0,0,0,0,4,2,2,2,4,0,0,0,0,0,0
0,0,0,0,0,19,2,2,2,19,0,0,0,0,0,0
0,0,0,0,0,18,2,2,2,18,0,0,0,0,0,0
0,0,0,0,0,4,2,2,2,4,0,0,0,0,0,0
:endlayer
layer: 10
0,0,0,0,12,4,2,2,2,4,6,0,0,0,0,0
0,0,0,0,16,22,2,2,2,22,16,0,0,0,0,0
0,0,0,0,16,22,2,2,2,22,16,0,0,0,0,0
0,0,0,0,12,22,2,2,2,22,6,0,0,0,0,0
0,0,0,0,12,22,2,2,2,2,6,0,0,0,0,0
0,0,0,0,16,2,2,2,2,2,2,8,0,0,0,0
0,0,0,0,2,2,0,2,2,2,2,2,6,0,0,0
0,0,0,0,2,0,0,2,2,2,2,2,23,0,0,0
0,0,0,0,0,0,0,4,24,2,2,2,23,0,0,0
0,0,0,0,2,0,0,0,21,2,2,2,6,0,0,0
0,0,0,0,16,2,0,0,21,2,2,8,0,0,0,0
0,0,0,0,12,22,2,20,21,2,6,0,0,0,0,0
0,0,0,0,12,22,2,2,2,22,6,0,0,0,0,0
0,0,0,0,16,22,2,2,2,22,16,0,0,0,0,0
0,0,0,0,16,22,2,2,2,22,16,0,0,0,0,0
0,0,0,0,12,4,2,2,2,4,6,0,0,0,0,0
:endlayer
layer: 11
0,0,0,0,23,4,0,0,0,4,23,0,0,0,0,0
0,0,0,0,25,0,0,0,0,0,9,0,0,0,0,0
0,0,0,0,23,0,0,0,0,0,9,0,0,0,0,0
0,0,0,0,23,0,0,0,0,0,23,0,0,0,0,0
0,0,0,0,25,0,2,0,0,2,4,0,0,0,0,0
0,0,0,0,23,2,9,0,0,0,2,8,0,0,0,0
0,0,0,0,2,23,27,0,0,0,0,2,4,0,0,0
0,0,0,0,2,23,23,0,0,0,0,0,9,0,0,0
0,0,0,0,26,0,0,4,0,0,0,0,9,0,0,0
0,0,0,0,2,0,0,0,0,0,0,2,4,0,0,0
0,0,0,0,23,2,0,0,0,0,2,8,0,0,0,0
0,0,0,0,25,0,2,0,0,2,4,0,0,0,0,0
0,0,0,0,23,0,0,0,0,0,23,0,0,0,0,0
0,0,0,0,23,0,0,0,0,0,9,0,0,0,0,0
0,0,0,0,25,0,0,0,0,0,9,0,0,0,0,0
0,0,0,0,23,4,0,0,0,4,23,0,0,0,0,0
:endlayer
layer: 12
0,0,0,0,23,4,0,0,0,4,23,0,0,0,0,0
0,0,0,0,0,0,0,0,0,0,0,0,0,0,0,0
0,0,0,0,23,0,0,0,0,0,0,0,0,0,0,0
0,0,0,0,23,0,0,0,0,0,23,0,0,0,0,0
0,0,0,0,0,0,2,0,0,2,4,0,0,0,0,0
0,0,0,0,23,2,0,0,0,0,2,8,0,0,0,0
0,0,0,0,2,0,0,0,0,0,0,2,4,0,0,0
0,0,0,0,2,27,27,0,0,0,0,0,0,0,0,0
0,0,0,0,2,19,19,4,0,0,0,0,0,0,0,0
0,0,0,0,2,0,0,0,0,0,0,2,4,0,0,0
0,0,0,0,23,2,0,0,0,0,2,8,0,0,0,0
0,0,0,0,0,0,2,0,0,2,4,0,0,0,0,0
0,0,0,0,23,0,0,0,0,0,23,0,0,0,0,0
0,0,0,0,23,0,0,0,0,0,0,0,0,0,0,0
0,0,0,0,0,0,0,0,0,0,0,0,0,0,0,0
0,0,0,0,23,4,0,0,0,4,23,0,0,0,0,0
:endlayer
layer: 13
0,0,0,13,23,4,6,0,12,4,23,28,0,0,0,0
0,0,0,0,16,11,0,0,0,11,16,0,0,0,0,0
0,0,0,0,23,0,0,0,0,0,16,0,0,0,0,0
0,0,0,0,23,0,0,0,0,0,23,0,0,0,0,0
0,0,0,0,16,0,2,29,26,2,4,28,0,0,0,0
0,0,0,13,23,2,28,0,0,13,2,8,0,0,0,0
0,0,0,0,2,11,0,0,0,0,11,2,4,0,0,0
0,0,0,0,2,0,0,0,0,0,0,0,16,0,0,0
0,0,0,0,2,27,27,4,0,0,0,0,16,0,0,0
0,0,0,0,2,23,19,0,0,0,10,2,4,0,0,0
0,0,0,13,23,2,6,0,0,13,2,8,0,0,0,0
0,0,0,0,16,0,2,29,26,2,4,28,0,0,0,0
0,0,0,0,23,0,0,0,0,0,23,0,0,0,0,0
0,0,0,0,23,0,0,0,0,0,16,0,0,0,0,0
0,0,0,0,16,10,0,0,0,10,16,0,0,0,0,0
0,0,0,13,23,4,6,0,12,4,23,28,0,0,0,0
:endlayer
layer: 14
0,0,0,16,22,30,30,30,30,30,22,16,0,0,0,0
0,0,0,16,22,6,0,0,0,12,22,16,0,0,0,0
0,0,0,16,22,6,0,0,0,12,22,16,0,0,0,0
0,0,0,16,22,6,0,0,0,12,22,16,0,0,0,0
0,0,0,16,22,6,2,2,2,2,22,16,0,0,0,0
0,0,0,16,22,2,0,0,0,0,2,6,0,0,0,0
0,0,0,16,2,0,0,0,0,0,0,2,27,0,0,0
0,0,0,12,2,0,0,0,0,0,0,26,9,0,0,0
0,0,0,12,2,0,0,4,0,0,0,26,9,0,0,0
0,0,0,16,2,27,25,6,0,0,0,2,31,0,0,0
0,0,0,16,22,2,23,6,0,0,2,6,0,0,0,0
0,0,0,16,22,6,2,2,2,2,22,16,0,0,0,0
0,0,0,16,22,6,0,0,0,12,22,16,0,0,0,0
0,0,0,16,22,6,0,0,0,12,22,16,0,0,0,0
0,0,0,16,22,6,0,0,0,12,22,16,0,0,0,0
0,0,0,16,22,30,30,30,30,30,22,16,0,0,0,0
:endlayer
layer: 15
0,0,0,0,7,7,23,23,23,7,7,0,0,0,0,0
0,0,0,0,7,7,23,23,23,7,7,0,0,0,0,0
0,0,0,0,7,7,23,23,23,7,7,0,0,0,0,0
0,0,0,0,7,7,23,23,23,7,7,0,0,0,0,0
0,0,0,0,7,7,2,2,2,2,7,0,0,0,0,0
0,0,0,0,7,2,0,0,0,0,2,8,0,0,0,0
0,0,0,8,2,0,0,0,0,0,0,2,8,0,0,0
0,0,0,0,2,0,0,0,0,0,0,2,0,0,0,0
0,0,0,0,2,0,0,4,18,0,0,2,0,0,0,0
0,0,0,8,2,0,0,25,6,0,0,2,8,0,0,0
0,0,0,0,7,2,0,25,6,0,2,8,0,0,0,0
0,0,0,0,7,7,2,2,2,2,7,0,0,0,0,0
0,0,0,0,7,7,23,23,23,7,7,0,0,0,0,0
0,0,0,0,7,7,23,23,23,7,7,0,0,0,0,0
0,0,0,0,7,7,23,23,23,7,7,0,0,0,0,0
0,0,0,0,7,7,23,23,23,7,7,0,0,0,0,0
:endlayer
layer: 16
0,0,0,0,0,0,0,0,0,0,0,0,0,0,0,0
0,0,0,0,0,0,0,0,0,0,0,0,0,0,0,0
0,0,0,0,0,0,0,32,0,0,0,0,0,0,0,0
0,0,0,0,0,0,18,16,16,18,0,0,0,0,0,0
0,0,0,0,0,12,2,2,2,2,6,0,0,0,0,0
0,0,0,0,18,2,16,22,16,16,2,18,0,0,0,0
0,0,0,12,2,16,16,22,16,16,16,2,6,0,0,0
0,0,0,16,2,30,30,22,16,16,16,2,16,0,0,0
0,0,0,16,2,0,0,4,30,30,30,2,16,0,0,0
0,0,0,12,2,0,0,0,25,23,23,2,6,0,0,0
0,0,0,0,19,2,0,0,25,23,2,19,0,0,0,0
0,0,0,0,0,12,2,2,2,2,6,0,0,0,0,0
0,0,0,0,0,0,19,16,16,19,0,0,0,0,0,0
0,0,0,0,0,0,0,32,0,0,0,0,0,0,0,0
0,0,0,0,0,0,0,0,0,0,0,0,0,0,0,0
0,0,0,0,0,0,0,0,0,0,0,0,0,0,0,0
:endlayer
layer: 17
0,0,0,0,0,0,0,0,0,0,0,0,0,0,0,0
0,0,0,0,0,0,0,0,0,0,0,0,0,0,0,0
0,0,0,0,0,0,0,0,0,0,0,0,0,0,0,0
0,0,0,0,0,0,4,27,27,4,0,0,0,0,0,0
0,0,0,0,8,23,0,0,0,0,23,8,0,0,0,0
0,0,0,0,23,0,0,0,0,0,0,23,0,0,0,0
0,0,0,4,0,0,0,0,0,0,0,0,4,0,0,0
0,0,0,25,0,8,8,8,0,0,0,0,9,0,0,0
0,0,0,25,0,0,13,4,28,0,0,0,9,0,0,0
0,0,0,4,0,0,0,11,0,0,0,0,4,0,0,0
0,0,0,0,23,0,0,0,0,0,0,23,0,0,0,0
0,0,0,0,8,23,0,0,0,0,23,8,0,0,0,0
0,0,0,0,0,0,4,31,31,4,0,0,0,0,0,0
0,0,0,0,0,0,0,0,0,0,0,0,0,0,0,0
0,0,0,0,0,0,0,0,0,0,0,0,0,0,0,0
0,0,0,0,0,0,0,0,0,0,0,0,0,0,0,0
:endlayer
layer: 18
0,0,0,0,0,0,0,0,0,0,0,0,0,0,0,0
0,0,0,0,0,0,0,0,0,0,0,0,0,0,0,0
0,0,0,0,0,0,0,0,0,0,0,0,0,0,0,0
0,0,0,0,0,0,4,0,0,4,0,0,0,0,0,0
0,0,0,0,8,23,0,0,0,0,23,8,0,0,0,0
0,0,0,0,23,0,0,0,0,0,0,23,0,0,0,0
0,0,0,4,0,0,0,0,0,0,0,0,4,0,0,0
0,0,0,0,0,0,0,0,0,0,0,0,0,0,0,0
0,0,0,0,0,0,0,7,0,0,0,0,0,0,0,0
0,0,0,4,0,0,0,0,0,0,0,0,4,0,0,0
0,0,0,0,23,0,0,0,0,0,0,23,0,0,0,0
0,0,0,0,8,23,0,0,0,0,23,8,0,0,0,0
0,0,0,0,0,0,4,0,0,4,0,0,0,0,0,0
0,0,0,0,0,0,0,0,0,0,0,0,0,0,0,0
0,0,0,0,0,0,0,0,0,0,0,0,0,0,0,0
0,0,0,0,0,0,0,0,0,0,0,0,0,0,0,0
:endlayer
layer: 19
0,0,0,0,0,0,0,0,0,0,0,0,0,0,0,0
0,0,0,0,0,0,0,0,0,0,0,0,0,0,0,0
0,0,0,0,0,0,0,0,0,0,0,0,0,0,0,0
0,0,0,0,0,0,4,16,16,4,0,0,0,0,0,0
0,0,0,0,8,23,0,0,0,0,23,8,0,0,0,0
0,0,0,0,23,8,0,0,0,0,8,23,0,0,0,0
0,0,0,4,0,0,0,0,0,0,0,0,4,0,0,0
0,0,0,16,0,0,0,0,0,0,0,0,16,0,0,0
0,0,0,16,0,0,0,0,0,0,0,0,16,0,0,0
0,0,0,4,0,0,0,0,0,0,0,0,4,0,0,0
0,0,0,0,23,8,0,0,0,0,8,23,0,0,0,0
0,0,0,0,8,23,0,0,0,0,23,8,0,0,0,0
0,0,0,0,0,0,4,16,16,4,0,0,0,0,0,0
0,0,0,0,0,0,0,0,0,0,0,0,0,0,0,0
0,0,0,0,0,0,0,0,0,0,0,0,0,0,0,0
0,0,0,0,0,0,0,0,0,0,0,0,0,0,0,0
:endlayer
layer: 20
0,0,0,0,0,0,0,0,0,0,0,0,0,0,0,0
0,0,0,0,0,0,0,0,0,0,0,0,0,0,0,0
0,0,0,0,0,0,16,16,16,16,0,0,0,0,0,0
0,0,0,0,16,16,4,30,30,4,16,16,0,0,0,0
0,0,0,16,16,4,6,0,0,12,4,16,16,0,0,0
0,0,0,16,4,23,0,0,0,0,23,4,16,0,0,0
0,0,16,4,19,0,0,0,0,0,0,19,4,16,0,0
0,0,16,22,0,0,0,0,0,0,0,0,22,16,0,0
0,0,16,22,0,0,0,0,0,0,0,0,22,16,0,0
0,0,16,4,18,0,0,0,0,0,0,18,4,16,0,0
0,0,0,16,4,23,0,0,0,0,23,4,16,0,0,0
0,0,0,16,16,4,6,0,0,12,4,16,16,0,0,0
0,0,0,0,16,16,4,30,30,4,16,16,0,0,0,0
0,0,0,0,0,0,16,16,16,16,0,0,0,0,0,0
0,0,0,0,0,0,0,0,0,0,0,0,0,0,0,0
0,0,0,0,0,0,0,0,0,0,0,0,0,0,0,0
:endlayer
layer: 21
0,0,0,0,0,0,0,0,0,0,0,0,0,0,0,0
0,0,0,0,0,0,0,0,0,0,0,0,0,0,0,0
0,0,0,0,0,0,0,0,0,0,0,0,0,0,0,0
0,0,0,0,0,0,7,7,7,7,0,0,0,0,0,0
0,0,0,0,32,7,7,23,23,7,7,32,0,0,0,0
0,0,0,0,7,7,23,23,23,23,7,7,0,0,0,0
0,0,0,7,7,23,23,16,16,23,23,7,7,0,0,0
0,0,0,7,23,23,16,16,16,16,23,23,7,0,0,0
0,0,0,7,23,23,16,16,16,16,23,23,7,0,0,0
0,0,0,7,7,23,23,16,16,23,23,7,7,0,0,0
0,0,0,0,7,7,23,23,23,23,7,7,0,0,0,0
0,0,0,0,32,7,7,23,23,7,7,32,0,0,0,0
0,0,0,0,0,0,7,7,7,7,0,0,0,0,0,0
0,0,0,0,0,0,0,0,0,0,0,0,0,0,0,0
0,0,0,0,0,0,0,0,0,0,0,0,0,0,0,0
0,0,0,0,0,0,0,0,0,0,0,0,0,0,0,0
:endlayer
layer: 22
0,0,0,0,0,0,0,0,0,0,0,0,0,0,0,0
0,0,0,0,0,0,0,0,0,0,0,0,0,0,0,0
0,0,0,0,0,0,0,0,0,0,0,0,0,0,0,0
0,0,0,0,0,0,0,0,0,0,0,0,0,0,0,0
0,0,0,0,0,0,0,0,0,0,0,0,0,0,0,0
0,0,0,0,0,0,0,27,27,0,0,0,0,0,0,0
0,0,0,0,0,0,23,23,23,23,0,0,0,0,0,0
0,0,0,0,0,25,23,23,23,23,9,0,0,0,0,0
0,0,0,0,0,25,23,23,23,23,9,0,0,0,0,0
0,0,0,0,0,0,23,23,23,23,0,0,0,0,0,0
0,0,0,0,0,0,0,31,31,0,0,0,0,0,0,0
0,0,0,0,0,0,0,0,0,0,0,0,0,0,0,0
0,0,0,0,0,0,0,0,0,0,0,0,0,0,0,0
0,0,0,0,0,0,0,0,0,0,0,0,0,0,0,0
0,0,0,0,0,0,0,0,0,0,0,0,0,0,0,0
0,0,0,0,0,0,0,0,0,0,0,0,0,0,0,0
:endlayer
layer: 23
0,0,0,0,0,0,0,0,0,0,0,0,0,0,0,0
0,0,0,0,0,0,0,0,0,0,0,0,0,0,0,0
0,0,0,0,0,0,0,0,0,0,0,0,0,0,0,0
0,0,0,0,0,0,0,0,0,0,0,0,0,0,0,0
0,0,0,0,0,0,0,0,0,0,0,0,0,0,0,0
0,0,0,0,0,0,0,0,0,0,0,0,0,0,0,0
0,0,0,0,0,0,8,23,23,8,0,0,0,0,0,0
0,0,0,0,0,0,23,23,23,23,0,0,0,0,0,0
0,0,0,0,0,0,23,23,23,23,0,0,0,0,0,0
0,0,0,0,0,0,8,23,23,8,0,0,0,0,0,0
0,0,0,0,0,0,0,0,0,0,0,0,0,0,0,0
0,0,0,0,0,0,0,0,0,0,0,0,0,0,0,0
0,0,0,0,0,0,0,0,0,0,0,0,0,0,0,0
0,0,0,0,0,0,0,0,0,0,0,0,0,0,0,0
0,0,0,0,0,0,0,0,0,0,0,0,0,0,0,0
0,0,0,0,0,0,0,0,0,0,0,0,0,0,0,0
:endlayer
layer: 24
0,0,0,0,0,0,0,0,0,0,0,0,0,0,0,0
0,0,0,0,0,0,0,0,0,0,0,0,0,0,0,0
0,0,0,0,0,0,0,0,0,0,0,0,0,0,0,0
0,0,0,0,0,0,0,0,0,0,0,0,0,0,0,0
0,0,0,0,0,0,0,0,0,0,0,0,0,0,0,0
0,0,0,0,0,0,0,0,0,0,0,0,0,0,0,0
0,0,0,0,0,0,0,27,27,0,0,0,0,0,0,0
0,0,0,0,0,0,25,23,23,9,0,0,0,0,0,0
0,0,0,0,0,0,25,23,23,9,0,0,0,0,0,0
0,0,0,0,0,0,0,31,31,0,0,0,0,0,0,0
0,0,0,0,0,0,0,0,0,0,0,0,0,0,0,0
0,0,0,0,0,0,0,0,0,0,0,0,0,0,0,0
0,0,0,0,0,0,0,0,0,0,0,0,0,0,0,0
0,0,0,0,0,0,0,0,0,0,0,0,0,0,0,0
0,0,0,0,0,0,0,0,0,0,0,0,0,0,0,0
0,0,0,0,0,0,0,0,0,0,0,0,0,0,0,0
:endlayer
layer: 25
0,0,0,0,0,0,0,0,0,0,0,0,0,0,0,0
0,0,0,0,0,0,0,0,0,0,0,0,0,0,0,0
0,0,0,0,0,0,0,0,0,0,0,0,0,0,0,0
0,0,0,0,0,0,0,0,0,0,0,0,0,0,0,0
0,0,0,0,0,0,0,0,0,0,0,0,0,0,0,0
0,0,0,0,0,0,0,0,0,0,0,0,0,0,0,0
0,0,0,0,0,0,0,0,0,0,0,0,0,0,0,0
0,0,0,0,0,0,0,23,23,0,0,0,0,0,0,0
0,0,0,0,0,0,0,23,23,0,0,0,0,0,0,0
0,0,0,0,0,0,0,0,0,0,0,0,0,0,0,0
0,0,0,0,0,0,0,0,0,0,0,0,0,0,0,0
0,0,0,0,0,0,0,0,0,0,0,0,0,0,0,0
0,0,0,0,0,0,0,0,0,0,0,0,0,0,0,0
0,0,0,0,0,0,0,0,0,0,0,0,0,0,0,0
0,0,0,0,0,0,0,0,0,0,0,0,0,0,0,0
0,0,0,0,0,0,0,0,0,0,0,0,0,0,0,0
:endlayer
layer: 26
0,0,0,0,0,0,0,0,0,0,0,0,0,0,0,0
0,0,0,0,0,0,0,0,0,0,0,0,0,0,0,0
0,0,0,0,0,0,0,0,0,0,0,0,0,0,0,0
0,0,0,0,0,0,0,0,0,0,0,0,0,0,0,0
0,0,0,0,0,0,0,0,0,0,0,0,0,0,0,0
0,0,0,0,0,0,0,0,0,0,0,0,0,0,0,0
0,0,0,0,0,0,0,0,0,0,0,0,0,0,0,0
0,0,0,0,0,0,0,25,27,0,0,0,0,0,0,0
0,0,0,0,0,0,0,31,9,0,0,0,0,0,0,0
0,0,0,0,0,0,0,0,0,0,0,0,0,0,0,0
0,0,0,0,0,0,0,0,0,0,0,0,0,0,0,0
0,0,0,0,0,0,0,0,0,0,0,0,0,0,0,0
0,0,0,0,0,0,0,0,0,0,0,0,0,0,0,0
0,0,0,0,0,0,0,0,0,0,0,0,0,0,0,0
0,0,0,0,0,0,0,0,0,0,0,0,0,0,0,0
0,0,0,0,0,0,0,0,0,0,0,0,0,0,0,0
:endlayer
layer: 27
0,0,0,0,0,0,0,0,0,0,0,0,0,0,0,0
0,0,0,0,0,0,0,0,0,0,0,0,0,0,0,0
0,0,0,0,0,0,0,0,0,0,0,0,0,0,0,0
0,0,0,0,0,0,0,0,0,0,0,0,0,0,0,0
0,0,0,0,0,0,0,0,0,0,0,0,0,0,0,0
0,0,0,0,0,0,0,0,0,0,0,0,0,0,0,0
0,0,0,0,0,0,0,0,0,0,0,0,0,0,0,0
0,0,0,0,0,0,0,8,8,0,0,0,0,0,0,0
0,0,0,0,0,0,0,8,8,0,0,0,0,0,0,0
0,0,0,0,0,0,0,0,0,0,0,0,0,0,0,0
0,0,0,0,0,0,0,0,0,0,0,0,0,0,0,0
0,0,0,0,0,0,0,0,0,0,0,0,0,0,0,0
0,0,0,0,0,0,0,0,0,0,0,0,0,0,0,0
0,0,0,0,0,0,0,0,0,0,0,0,0,0,0,0
0,0,0,0,0,0,0,0,0,0,0,0,0,0,0,0
0,0,0,0,0,0,0,0,0,0,0,0,0,0,0,0
:endlayer
layer: 28
0,0,0,0,0,0,0,0,0,0,0,0,0,0,0,0
0,0,0,0,0,0,0,0,0,0,0,0,0,0,0,0
0,0,0,0,0,0,0,0,0,0,0,0,0,0,0,0
0,0,0,0,0,0,0,0,0,0,0,0,0,0,0,0
0,0,0,0,0,0,0,0,0,0,0,0,0,0,0,0
0,0,0,0,0,0,0,0,0,0,0,0,0,0,0,0
0,0,0,0,0,0,0,0,0,0,0,0,0,0,0,0
0,0,0,0,0,0,0,8,8,0,0,0,0,0,0,0
0,0,0,0,0,0,0,8,8,0,0,0,0,0,0,0
0,0,0,0,0,0,0,0,0,0,0,0,0,0,0,0
0,0,0,0,0,0,0,0,0,0,0,0,0,0,0,0
0,0,0,0,0,0,0,0,0,0,0,0,0,0,0,0
0,0,0,0,0,0,0,0,0,0,0,0,0,0,0,0
0,0,0,0,0,0,0,0,0,0,0,0,0,0,0,0
0,0,0,0,0,0,0,0,0,0,0,0,0,0,0,0
0,0,0,0,0,0,0,0,0,0,0,0,0,0,0,0
:endlayer

#### RULES ####
rule:
plugin=vanillaBlocks
number=1
data:
JSON:{blockState:{blockName:"minecraft:dirt",properties:{variant:"dirt",snowy:"false"}}}
:enddata
:endrule

rule:
plugin=vanillaBlocks
number=2
data:
JSON:{blockState:{blockName:"minecraft:cobblestone"}}
:enddata
:endrule

rule:
plugin=vanillaBlocks
number=3
data:
JSON:{blockState:{blockName:"minecraft:grass",properties:{snowy:"false"}}}
:enddata
:endrule

rule:
plugin=vanillaBlocks
number=4
data:
JSON:{blockState:{blockName:"minecraft:log",properties:{variant:"jungle",axis:"y"}}}
:enddata
:endrule

rule:
plugin=vanillaBlocks
number=5
data:
JSON:{blockState:{blockName:"minecraft:stone_slab",properties:{half:"bottom",variant:"cobblestone"}}}
:enddata
:endrule

rule:
plugin=vanillaBlocks
number=6
data:
JSON:{blockState:{blockName:"minecraft:jungle_stairs",properties:{half:"top",shape:"straight",facing:"west"}}}
:enddata
:endrule

rule:
plugin=vanillaBlocks
number=7
data:
JSON:{blockState:{blockName:"minecraft:wooden_slab",properties:{half:"bottom",variant:"jungle"}}}
:enddata
:endrule

rule:
plugin=vanillaBlocks
number=8
data:
JSON:{blockState:{blockName:"minecraft:jungle_fence",properties:{east:"false",south:"false",north:"false",west:"false"}}}
:enddata
:endrule

rule:
plugin=vanillaBlocks
number=9
data:
JSON:{blockState:{blockName:"minecraft:jungle_stairs",properties:{half:"bottom",shape:"straight",facing:"west"}}}
:enddata
:endrule

rule:
plugin=vanillaBlocks
number=10
data:
JSON:{blockState:{blockName:"minecraft:torch",properties:{facing:"north"}}}
:enddata
:endrule

rule:
plugin=vanillaBlocks
number=11
data:
JSON:{blockState:{blockName:"minecraft:torch",properties:{facing:"south"}}}
:enddata
:endrule

rule:
plugin=vanillaBlocks
number=12
data:
JSON:{blockState:{blockName:"minecraft:jungle_stairs",properties:{half:"top",shape:"straight",facing:"east"}}}
:enddata
:endrule

rule:
plugin=vanillaBlocks
number=13
data:
JSON:{blockState:{blockName:"minecraft:torch",properties:{facing:"west"}}}
:enddata
:endrule

rule:
plugin=vanillaBlocks
number=14
data:
JSON:{blockState:{blockName:"minecraft:stone_slab",properties:{half:"top",variant:"cobblestone"}}}
:enddata
:endrule

rule:
plugin=vanillaBlocks
number=15
data:
JSON:{blockState:{blockName:"minecraft:stone_stairs",properties:{half:"top",shape:"straight",facing:"south"}}}
:enddata
:endrule

rule:
plugin=vanillaBlocks
number=16
data:
JSON:{blockState:{blockName:"minecraft:wooden_slab",properties:{half:"top",variant:"jungle"}}}
:enddata
:endrule

rule:
plugin=vanillaBlocks
number=17
data:
JSON:{blockState:{blockName:"minecraft:stone_stairs",properties:{half:"top",shape:"straight",facing:"north"}}}
:enddata
:endrule

rule:
plugin=vanillaBlocks
number=18
data:
JSON:{blockState:{blockName:"minecraft:jungle_stairs",properties:{half:"top",shape:"straight",facing:"south"}}}
:enddata
:endrule

rule:
plugin=vanillaBlocks
number=19
data:
JSON:{blockState:{blockName:"minecraft:jungle_stairs",properties:{half:"top",shape:"straight",facing:"north"}}}
:enddata
:endrule

rule:
plugin=vanillaBlocks
number=20
data:
JSON:{blockState:{blockName:"minecraft:stone_stairs",properties:{half:"bottom",shape:"straight",facing:"south"}}}
:enddata
:endrule

rule:
plugin=vanillaBlocks
number=21
data:
JSON:{blockState:{blockName:"minecraft:stone_stairs",properties:{half:"bottom",shape:"straight",facing:"east"}}}
:enddata
:endrule

rule:
plugin=vanillaBlocks
number=22
data:
JSON:{blockState:{blockName:"minecraft:log",properties:{variant:"jungle",axis:"z"}}}
:enddata
:endrule

rule:
plugin=vanillaBlocks
number=23
data:
JSON:{blockState:{blockName:"minecraft:planks",properties:{variant:"jungle"}}}
:enddata
:endrule

rule:
plugin=vanillaBlocks
number=24
data:
JSON:{blockState:{blockName:"minecraft:stone_stairs",properties:{half:"bottom",shape:"straight",facing:"north"}}}
:enddata
:endrule

rule:
plugin=vanillaBlocks
number=25
data:
JSON:{blockState:{blockName:"minecraft:jungle_stairs",properties:{half:"bottom",shape:"straight",facing:"east"}}}
:enddata
:endrule

rule:
plugin=vanillaBlocks
number=26
data:
JSON:{blockState:{blockName:"minecraft:stone_stairs",properties:{half:"top",shape:"straight",facing:"east"}}}
:enddata
:endrule

rule:
plugin=vanillaBlocks
number=27
data:
JSON:{blockState:{blockName:"minecraft:jungle_stairs",properties:{half:"bottom",shape:"straight",facing:"south"}}}
:enddata
:endrule

rule:
plugin=vanillaBlocks
number=28
data:
JSON:{blockState:{blockName:"minecraft:torch",properties:{facing:"east"}}}
:enddata
:endrule

rule:
plugin=vanillaBlocks
number=29
data:
JSON:{blockState:{blockName:"minecraft:stone_stairs",properties:{half:"top",shape:"straight",facing:"west"}}}
:enddata
:endrule

rule:
plugin=vanillaBlocks
number=30
data:
JSON:{blockState:{blockName:"minecraft:log",properties:{variant:"jungle",axis:"x"}}}
:enddata
:endrule

rule:
plugin=vanillaBlocks
number=31
data:
JSON:{blockState:{blockName:"minecraft:jungle_stairs",properties:{half:"bottom",shape:"straight",facing:"north"}}}
:enddata
:endrule

rule:
plugin=vanillaBlocks
number=32
data:
JSON:{blockState:{blockName:"minecraft:torch",properties:{facing:"up"}}}
:enddata
:endrule

#### ENTITIES ####
