# Ancient Warfare Structure Template File
# Auto-generated structure template file. created on: 3/18/2021 at: 20:32:49
# Lines beginning with # denote comments

header:
version=2.11
name=SurvivalBuild_FortWall_large_type1_OutterCornerBastion_BOPfir
mods=biomesoplenty
size=16,19,16
offset=0,4,0
:endheader

#### VALIDATION ####
validation:
type=ground
structureAuthor=TheOddlySeagull
survival=true
worldGenEnabled=false
unique=false
preserveBlocks=false
preventNaturalHostileSpawns=false
selectionWeight=1
clusterValue=1
minDuplicateDistance=1
dimensionWhiteList=true
dimensionList=
biomeGroupList=
biomeWhiteList=true
biomeList=
leveling=0
fill=0
border=0
blockSwap=false
territoryName=
biomeReplacement=minecraft:
minGenerationHeight=0
maxGenerationHeight=255
:endvalidation

#### LAYERS ####
layer: 0
1,1,1,1,1,1,1,1,1,1,1,1,1,1,1,1
1,2,2,2,2,2,2,2,2,2,2,2,2,2,2,2
1,2,2,2,2,2,2,2,2,2,2,2,2,2,2,2
1,2,2,2,2,2,2,2,2,2,2,2,2,2,2,2
1,2,2,2,2,2,2,2,2,2,2,2,2,2,2,2
1,2,2,2,2,2,2,2,2,2,2,2,2,2,2,2
1,2,2,2,2,2,2,2,2,2,2,2,2,2,2,2
1,2,2,2,2,2,2,2,2,2,2,2,2,2,2,2
1,2,2,2,2,2,2,2,2,2,2,2,2,2,2,2
1,2,2,2,2,2,2,2,2,2,2,2,2,2,2,2
1,2,2,2,2,2,2,2,2,2,2,2,2,2,2,2
1,2,2,2,2,2,2,2,2,2,2,1,1,1,1,1
1,2,2,2,2,2,2,2,2,2,2,1,1,1,1,1
1,2,2,2,2,2,2,2,2,2,2,1,1,1,1,1
1,2,2,2,2,2,2,2,2,2,2,1,1,1,1,1
1,2,2,2,2,2,2,2,2,2,2,1,1,1,1,1
:endlayer
layer: 1
1,1,1,1,1,1,1,1,1,1,1,1,1,1,1,1
1,2,2,2,2,2,2,2,2,2,2,2,2,2,2,2
1,2,0,0,0,0,0,0,0,0,0,0,0,0,0,0
1,2,0,0,0,0,0,0,0,0,0,0,0,0,0,0
1,2,0,0,0,0,2,2,2,2,0,0,0,0,0,0
1,2,0,0,0,2,2,2,2,2,2,0,0,0,0,0
1,2,0,0,2,2,2,2,2,2,2,2,2,2,2,2
1,2,0,0,2,2,2,2,2,2,2,2,2,2,2,2
1,2,0,0,2,2,2,2,2,2,2,2,2,2,2,2
1,2,0,0,2,2,2,2,2,2,2,2,2,2,2,2
1,2,0,0,0,2,2,2,2,2,2,2,2,2,2,2
1,2,0,0,0,0,2,2,2,2,2,1,1,1,1,1
1,2,0,0,0,0,2,2,2,2,2,1,1,1,1,1
1,2,0,0,0,0,2,2,2,2,2,1,1,1,1,1
1,2,0,0,0,0,2,2,2,2,2,1,1,1,1,1
1,2,0,0,0,0,2,2,2,2,2,1,1,1,1,1
:endlayer
layer: 2
1,1,1,1,1,1,1,1,1,1,1,1,1,1,1,1
1,2,2,2,2,2,2,2,2,2,2,2,2,2,2,2
1,2,0,0,0,0,0,0,0,0,0,0,0,0,0,0
1,2,0,0,0,0,0,0,0,0,0,0,0,0,0,0
1,2,0,0,0,0,2,2,2,2,0,0,0,0,0,0
1,2,0,0,0,2,2,2,2,2,2,0,0,0,0,0
1,2,0,0,2,2,2,2,2,2,2,2,2,2,2,2
1,2,0,0,2,2,2,2,2,2,2,2,2,2,2,2
1,2,0,0,2,2,2,2,2,2,2,2,2,2,2,2
1,2,0,0,2,2,2,2,2,2,2,2,2,2,2,2
1,2,0,0,0,2,2,2,2,2,2,2,2,2,2,2
1,2,0,0,0,0,2,2,2,2,2,1,1,1,1,1
1,2,0,0,0,0,2,2,2,2,2,1,1,1,1,1
1,2,0,0,0,0,2,2,2,2,2,1,1,1,1,1
1,2,0,0,0,0,2,2,2,2,2,1,1,1,1,1
1,2,0,0,0,0,2,2,2,2,2,1,1,1,1,1
:endlayer
layer: 3
3,3,3,3,3,3,3,3,3,3,3,3,3,3,3,3
3,2,2,2,2,2,2,2,2,2,2,2,2,2,2,2
3,2,0,0,0,0,0,0,0,0,0,0,0,0,0,0
3,2,0,0,0,0,0,0,0,0,0,0,0,0,0,0
3,2,0,0,0,0,2,2,2,2,0,0,0,0,0,0
3,2,0,0,0,2,2,2,2,2,2,0,0,0,0,0
3,2,0,0,2,2,2,2,2,2,2,2,2,2,2,2
3,2,0,0,2,2,2,2,2,2,2,2,2,2,2,2
3,2,0,0,2,2,2,2,2,2,2,2,2,2,2,2
3,2,0,0,2,2,2,2,2,2,2,2,2,2,2,2
3,2,0,0,0,2,2,2,2,2,2,2,2,2,2,2
3,2,0,0,0,0,2,2,2,2,2,2,2,2,1,3
3,2,0,0,0,0,2,2,2,2,2,2,2,2,1,3
3,2,0,0,0,0,2,2,2,2,2,2,2,2,3,3
3,2,0,0,0,0,2,2,2,2,2,1,1,3,3,3
3,2,0,0,0,0,2,2,2,2,2,3,3,3,3,3
:endlayer
layer: 4
0,0,0,0,0,0,0,0,0,0,0,0,0,0,0,0
0,4,4,2,2,4,4,2,2,4,4,2,2,4,4,2
0,4,0,0,0,0,0,0,0,0,0,0,0,0,0,0
0,2,0,0,0,0,0,0,0,0,0,0,0,0,0,0
0,2,0,0,0,0,2,2,2,2,0,0,0,0,0,0
0,4,0,0,0,2,2,2,2,2,2,0,0,0,0,0
0,4,0,0,2,2,2,2,2,2,2,2,5,6,6,5
0,2,0,0,2,2,2,2,2,2,2,2,2,2,2,2
0,2,0,0,2,2,2,2,2,2,2,2,2,2,2,2
0,4,0,0,2,2,2,2,2,2,2,2,2,2,2,2
0,4,0,0,0,2,2,2,2,2,2,4,5,7,8,5
0,2,0,0,0,0,2,2,2,2,4,4,4,0,8,9
0,2,0,0,0,0,5,2,2,2,5,4,0,0,5,0
0,4,0,0,0,0,10,2,2,2,7,0,0,0,0,0
0,4,0,0,0,0,10,2,2,2,8,8,5,0,0,0
0,2,0,0,0,0,5,2,2,2,5,9,0,0,0,0
:endlayer
layer: 5
0,0,0,0,0,0,0,0,0,0,0,0,0,0,0,0
0,0,0,4,4,0,0,4,4,0,0,4,4,0,0,4
0,0,0,0,0,0,0,0,0,0,0,0,0,0,0,0
0,4,0,0,0,0,0,0,0,0,0,0,0,0,0,0
0,4,0,0,0,0,2,2,2,2,0,0,0,0,0,0
0,0,0,0,0,2,2,2,2,2,2,0,0,0,0,0
0,0,0,0,2,2,2,2,2,2,2,2,5,11,11,5
0,4,0,0,2,2,2,2,2,2,2,2,2,2,2,2
0,4,0,0,2,2,2,2,5,2,2,2,2,2,2,2
0,0,0,0,2,2,2,2,4,0,0,2,2,2,2,2
0,0,0,0,0,2,2,2,4,0,0,0,5,0,8,5
0,4,0,0,0,0,2,2,2,2,0,0,0,0,8,9
0,4,0,0,0,0,5,2,2,2,5,0,0,0,5,0
0,0,0,0,0,0,12,2,2,2,0,0,0,0,0,0
0,0,0,0,0,0,12,2,2,2,8,8,5,0,0,0
0,4,0,0,0,0,5,2,2,2,5,9,0,0,0,0
:endlayer
layer: 6
0,0,0,0,0,0,0,0,0,0,0,0,0,0,0,0
0,0,0,0,0,0,0,0,0,0,0,0,0,0,0,0
0,0,0,0,0,0,0,0,0,0,0,0,0,0,0,0
0,0,0,0,0,0,0,0,0,0,0,0,0,0,0,0
0,0,0,0,0,0,2,2,2,2,0,0,0,0,0,0
0,0,0,0,0,2,2,2,2,2,2,0,0,0,0,0
0,0,0,0,2,2,2,2,2,2,2,2,5,0,0,5
0,0,0,0,2,2,2,2,2,2,2,2,2,2,2,2
0,0,0,0,2,2,4,4,5,2,2,2,2,2,2,2
0,0,0,0,2,2,0,0,0,0,0,2,2,2,2,2
0,0,0,0,0,2,2,0,13,0,0,0,5,0,8,5
0,0,0,0,0,0,2,2,2,2,0,0,14,0,8,9
0,0,0,0,0,0,5,2,2,2,5,15,0,0,5,15
0,0,0,0,0,0,0,2,2,2,0,0,0,0,0,0
0,0,0,0,0,0,0,2,2,2,8,8,5,0,0,0
0,0,0,0,0,0,5,2,2,2,5,9,14,0,0,0
:endlayer
layer: 7
0,0,0,0,0,0,0,0,0,0,0,0,0,0,0,0
0,0,0,0,0,0,0,0,0,0,0,0,0,0,0,0
0,0,0,0,0,0,0,0,0,0,0,0,0,0,0,0
0,0,0,0,0,0,0,0,0,0,0,0,0,0,0,0
0,0,0,0,0,0,2,2,2,2,0,0,0,0,0,0
0,0,0,0,0,2,2,2,2,2,2,0,0,0,0,0
0,0,0,0,2,2,2,0,4,2,2,2,5,0,0,5
0,0,0,0,2,2,0,0,4,2,2,2,2,2,2,2
0,0,0,0,2,2,15,0,5,2,2,2,2,2,2,2
0,0,0,0,2,2,0,0,0,16,16,2,2,2,2,2
0,0,0,0,0,2,2,0,0,16,16,2,5,17,18,5
0,0,0,0,0,0,2,2,2,2,2,0,0,17,18,19
0,0,0,0,0,0,5,2,2,2,5,0,0,17,5,17
0,0,0,0,0,0,0,2,2,2,17,17,17,5,17,17
0,0,0,0,0,0,0,2,2,2,20,20,5,17,17,0
0,0,0,0,0,0,5,2,2,2,5,21,17,17,0,0
:endlayer
layer: 8
0,0,0,0,0,0,0,0,0,0,0,0,0,0,0,0
0,0,0,0,0,0,0,0,0,0,0,0,0,0,0,0
0,0,0,0,0,0,0,0,0,0,0,0,0,0,0,0
0,0,0,0,0,0,0,0,0,0,0,0,0,0,0,0
0,0,0,0,0,0,2,2,2,2,0,0,0,0,0,0
0,0,0,0,0,2,2,2,2,2,2,0,0,0,0,0
0,0,0,0,2,2,2,0,14,0,2,2,5,0,0,5
0,0,0,0,2,2,0,0,0,0,0,2,2,2,2,2
0,0,0,0,2,2,0,0,5,4,4,2,2,2,2,2
0,0,0,0,2,2,16,16,2,2,2,2,2,2,2,2
0,0,0,0,0,2,2,16,2,2,2,2,5,8,7,5
0,0,0,0,0,0,2,2,2,2,2,8,8,8,7,0
0,0,0,0,0,0,5,2,2,2,5,8,8,7,7,0
0,0,0,0,0,0,0,2,2,2,8,8,7,7,0,0
0,0,0,0,0,0,0,2,2,2,7,7,7,0,0,0
0,0,0,0,0,0,5,2,2,2,5,0,0,0,0,0
:endlayer
layer: 9
0,0,0,0,0,0,0,0,0,0,0,0,0,0,0,0
0,0,0,0,0,0,0,0,0,0,0,0,0,0,0,0
0,0,0,0,0,0,0,0,0,0,0,0,0,0,0,0
0,0,0,0,0,0,0,6,6,0,0,0,0,0,0,0
0,0,0,0,0,0,2,2,2,2,0,0,0,0,0,0
0,0,0,0,0,2,2,2,2,2,2,0,0,0,0,0
0,0,0,0,2,2,2,16,0,0,2,2,5,21,10,5
0,0,0,10,2,2,2,16,0,0,0,2,2,2,2,2
0,0,0,10,2,2,2,2,5,0,22,2,2,2,2,2
0,0,0,0,2,2,2,4,4,0,0,2,2,2,2,2
0,0,0,0,0,2,2,4,4,0,2,2,5,21,10,5
0,0,0,0,0,0,2,2,2,2,2,8,0,0,0,0
0,0,0,0,0,0,5,2,2,2,5,0,0,0,0,0
0,0,0,0,0,0,19,2,2,2,19,0,0,0,0,0
0,0,0,0,0,0,6,2,2,2,6,0,0,0,0,0
0,0,0,0,0,0,5,2,2,2,5,0,0,0,0,0
:endlayer
layer: 10
0,0,0,0,0,0,0,0,0,0,0,0,0,0,0,0
0,0,0,0,0,0,0,0,0,0,0,0,0,0,0,0
0,0,0,0,0,0,0,0,0,0,0,0,0,0,0,0
0,0,0,0,0,0,6,8,8,6,0,0,0,0,0,0
0,0,0,0,0,9,2,2,2,2,9,0,0,0,0,0
0,0,0,0,9,2,4,4,2,2,2,6,6,17,17,6
0,0,0,10,2,4,4,4,23,0,2,2,20,20,20,20
0,0,0,8,2,4,4,24,23,0,0,2,2,2,2,2
0,0,0,8,2,4,0,22,5,15,0,2,2,2,2,2
0,0,0,10,2,4,0,0,14,0,0,2,2,2,2,2
0,0,0,0,9,2,0,0,0,0,2,2,20,20,20,20
0,0,0,0,0,10,2,0,0,2,2,5,19,17,17,19
0,0,0,0,0,10,18,4,4,2,18,21,17,0,0,0
0,0,0,0,0,17,18,2,2,2,18,17,0,0,0,0
0,0,0,0,0,17,18,2,2,2,18,17,0,0,0,0
0,0,0,0,0,10,5,2,2,2,5,21,0,0,0,0
:endlayer
layer: 11
0,0,0,0,0,0,0,0,0,0,0,0,0,0,0,0
0,0,0,0,0,0,0,0,0,0,0,0,0,0,0,0
0,0,0,0,0,0,0,0,0,0,0,0,0,0,0,0
0,0,0,0,0,0,5,11,11,5,0,0,0,0,0,0
0,0,0,0,0,9,2,0,0,2,9,0,0,0,0,0
0,0,0,0,9,2,0,0,0,7,2,5,8,11,11,8
0,0,0,5,2,0,0,0,0,7,7,2,0,0,0,5
0,0,0,12,0,0,0,0,5,17,17,2,0,0,0,0
0,0,0,12,0,0,0,0,7,0,0,2,0,0,0,0
0,0,0,5,2,0,0,0,0,0,0,2,0,0,0,0
0,0,0,0,9,2,0,0,0,0,2,0,0,0,0,5
0,0,0,0,0,5,2,0,0,2,0,0,0,8,25,8
0,0,0,0,0,8,0,0,0,0,0,0,8,0,0,0
0,0,0,0,0,12,0,0,0,0,0,8,0,0,0,0
0,0,0,0,0,12,0,0,0,0,0,26,0,0,0,0
0,0,0,0,0,8,5,0,0,0,5,8,0,0,0,0
:endlayer
layer: 12
0,0,0,0,0,0,0,0,0,0,0,0,0,0,0,0
0,0,0,0,0,0,0,0,0,0,0,0,0,0,0,0
0,0,0,0,0,0,0,0,0,0,0,0,0,0,0,0
0,0,0,0,0,0,5,0,0,5,0,0,0,0,0,0
0,0,0,0,0,9,2,0,0,2,9,0,0,0,0,0
0,0,0,0,9,2,15,0,0,22,2,5,8,0,0,8
0,0,0,5,2,14,0,0,0,0,14,2,0,0,0,5
0,0,0,0,0,0,0,0,5,0,0,2,0,0,0,0
0,0,0,0,0,0,0,0,17,7,7,2,0,0,0,0
0,0,0,5,2,13,0,0,17,7,7,2,0,0,0,0
0,0,0,0,9,2,15,0,0,22,2,0,0,0,0,5
0,0,0,0,0,5,2,0,0,2,0,0,0,8,0,8
0,0,0,0,0,8,0,0,0,0,0,0,8,0,0,0
0,0,0,0,0,0,0,0,0,0,0,8,0,0,0,0
0,0,0,0,0,0,0,0,0,0,0,0,0,0,0,0
0,0,0,0,0,8,5,0,0,0,5,8,0,0,0,0
:endlayer
layer: 13
0,0,0,0,0,0,0,0,0,0,0,0,0,0,0,0
0,0,0,0,0,0,0,0,0,0,0,0,0,0,0,0
0,0,0,0,0,0,0,0,0,0,0,0,0,0,0,0
0,0,0,0,0,0,5,17,17,5,0,0,0,0,0,0
0,0,0,0,0,9,2,0,0,2,9,0,0,0,0,0
0,0,0,0,9,2,0,0,0,0,2,5,8,17,17,8
0,0,0,5,2,0,0,0,0,0,0,2,0,0,22,5
0,0,0,17,0,0,17,17,5,0,0,2,0,0,0,19
0,0,0,17,0,0,7,7,0,0,0,2,0,0,0,0
0,0,0,5,2,0,7,7,0,0,0,2,0,0,0,6
0,0,0,0,9,2,0,0,0,0,2,0,0,0,22,5
0,0,0,0,0,5,2,23,27,2,0,0,0,8,17,8
0,0,0,0,0,8,0,0,0,0,0,0,8,0,0,0
0,0,0,0,0,17,0,0,0,0,0,8,0,0,0,0
0,0,0,0,0,17,13,0,0,0,13,17,0,0,0,0
0,0,0,0,0,8,5,21,0,10,5,8,0,0,0,0
:endlayer
layer: 14
0,0,0,0,0,0,0,0,0,0,0,0,0,0,0,0
0,0,0,0,0,0,0,0,0,0,0,0,0,0,0,0
0,0,0,0,0,0,0,0,0,0,0,0,0,0,0,0
0,0,0,0,0,0,12,11,11,26,0,0,0,0,0,0
0,0,0,0,0,9,2,28,28,2,6,17,17,17,17,17
0,0,0,0,9,2,7,7,17,0,2,20,20,20,20,20
0,0,0,11,2,28,7,7,17,0,0,2,19,19,19,18
0,0,0,12,23,0,0,0,5,0,0,2,0,0,0,18
0,0,0,12,23,0,0,0,0,0,0,2,0,0,0,18
0,0,0,25,2,29,0,0,0,0,0,2,0,0,0,18
0,0,0,0,10,2,23,0,0,27,2,0,10,6,6,18
0,0,0,0,17,18,2,2,2,2,0,10,6,20,20,20
0,0,0,0,17,18,21,0,0,0,10,6,5,17,17,17
0,0,0,0,17,18,21,0,0,0,10,18,17,17,0,0
0,0,0,0,17,18,21,0,0,0,10,18,17,0,0,0
0,0,0,0,17,18,20,20,20,20,20,18,17,0,0,0
:endlayer
layer: 15
0,0,0,0,0,0,0,0,0,0,0,0,0,0,0,0
0,0,0,0,0,0,0,0,0,0,0,0,0,0,0,0
0,0,0,0,0,0,0,0,0,0,0,0,0,0,0,0
0,0,0,0,0,27,29,29,29,29,23,0,0,0,0,0
0,0,0,0,27,29,2,2,2,2,29,23,0,0,0,0
0,0,0,29,29,2,0,0,0,7,2,2,2,7,7,7
0,0,0,27,2,2,0,0,0,7,7,2,2,7,7,7
0,0,0,27,2,2,0,0,5,17,17,2,2,8,8,8
0,0,0,27,2,2,0,0,0,0,0,2,2,8,8,8
0,0,0,27,2,2,0,0,0,0,0,2,2,8,8,8
0,0,0,28,27,2,2,2,2,2,2,2,2,7,7,7
0,0,0,0,28,2,2,2,2,2,2,2,7,7,7,7
0,0,0,0,0,2,2,2,2,2,2,7,7,0,0,0
0,0,0,0,0,7,7,8,8,8,7,7,0,30,0,0
0,0,0,0,0,7,7,8,8,8,7,7,0,0,0,0
0,0,0,0,0,7,7,8,8,8,7,7,0,0,0,0
:endlayer
layer: 16
0,0,0,0,0,0,0,0,0,0,0,0,0,0,0,0
0,0,0,0,0,0,0,0,0,0,0,0,0,0,0,0
0,0,0,0,0,0,29,16,16,29,0,0,0,0,0,0
0,0,0,0,27,2,2,2,2,2,2,23,0,0,0,0
0,0,0,29,2,2,2,2,2,2,2,2,29,0,0,0
0,0,0,2,2,2,0,0,0,0,2,2,2,0,0,0
0,0,27,2,2,31,0,0,13,0,0,2,2,23,0,0
0,0,16,2,2,31,0,22,5,15,0,2,2,16,0,0
0,0,16,2,2,31,7,7,7,7,7,2,2,16,30,0
0,0,27,2,2,31,7,7,7,7,7,2,2,23,0,0
0,0,0,2,2,2,32,32,32,32,2,2,2,0,0,0
0,0,0,28,2,2,2,2,2,2,2,2,28,0,0,0
0,0,0,0,27,2,2,2,2,2,2,23,0,0,0,0
0,0,0,0,0,0,28,16,16,28,0,0,0,0,0,0
0,0,0,0,0,0,0,0,30,0,0,0,0,0,0,0
0,0,0,0,0,0,0,0,0,0,0,0,0,0,0,0
:endlayer
layer: 17
0,0,0,0,0,0,0,0,0,0,0,0,0,0,0,0
0,0,0,0,0,0,0,0,0,0,0,0,0,0,0,0
0,0,0,0,0,0,2,32,32,2,0,0,0,0,0,0
0,0,0,0,2,32,33,0,0,33,32,2,0,0,0,0
0,0,0,2,4,0,0,0,0,0,0,4,2,0,0,0
0,0,0,24,0,0,0,0,0,0,0,0,31,0,0,0
0,0,2,31,0,0,0,0,0,0,0,0,24,2,0,0
0,0,24,0,0,0,0,0,7,0,0,0,0,31,0,0
0,0,24,0,0,0,0,0,0,0,0,0,0,31,0,0
0,0,2,31,0,0,0,0,0,0,0,0,24,2,0,0
0,0,0,24,0,0,0,0,0,0,0,0,31,0,0,0
0,0,0,2,4,0,0,0,0,0,0,4,2,0,0,0
0,0,0,0,2,33,32,0,0,32,33,2,0,0,0,0
0,0,0,0,0,0,2,33,33,2,0,0,0,0,0,0
0,0,0,0,0,0,0,0,0,0,0,0,0,0,0,0
0,0,0,0,0,0,0,0,0,0,0,0,0,0,0,0
:endlayer
layer: 18
0,0,0,0,0,0,0,0,0,0,0,0,0,0,0,0
0,0,0,0,0,0,0,0,0,0,0,0,0,0,0,0
0,0,0,0,0,0,32,0,0,32,0,0,0,0,0,0
0,0,0,0,32,0,0,0,0,0,0,32,0,0,0,0
0,0,0,24,14,0,0,0,0,0,0,22,31,0,0,0
0,0,0,0,0,0,0,0,0,0,0,0,0,0,0,0
0,0,24,0,0,0,0,0,0,0,0,0,0,31,0,0
0,0,0,0,0,0,0,0,0,0,0,0,0,0,0,0
0,0,0,0,0,0,0,0,0,0,0,0,0,0,0,0
0,0,24,0,0,0,0,0,0,0,0,0,0,31,0,0
0,0,0,0,0,0,0,0,0,0,0,0,0,0,0,0
0,0,0,24,15,0,0,0,0,0,0,13,31,0,0,0
0,0,0,0,33,0,0,0,0,0,0,33,0,0,0,0
0,0,0,0,0,0,33,0,0,33,0,0,0,0,0,0
0,0,0,0,0,0,0,0,0,0,0,0,0,0,0,0
0,0,0,0,0,0,0,0,0,0,0,0,0,0,0,0
:endlayer

#### RULES ####
rule:
plugin=vanillaBlocks
number=1
data:
JSON:{blockState:{blockName:"minecraft:dirt",properties:{variant:"dirt",snowy:"false"}}}
:enddata
:endrule

rule:
plugin=vanillaBlocks
number=2
data:
JSON:{blockState:{blockName:"minecraft:cobblestone"}}
:enddata
:endrule

rule:
plugin=vanillaBlocks
number=3
data:
JSON:{blockState:{blockName:"minecraft:grass",properties:{snowy:"false"}}}
:enddata
:endrule

rule:
plugin=vanillaBlocks
number=4
data:
JSON:{blockState:{blockName:"minecraft:stone_slab",properties:{half:"bottom",variant:"cobblestone"}}}
:enddata
:endrule

rule:
plugin=vanillaBlocks
number=5
data:
JSON:{blockState:{blockName:"biomesoplenty:log_0",properties:{variant:"fir",axis:"y"}}}
:enddata
:endrule

rule:
plugin=vanillaBlocks
number=6
data:
JSON:{blockState:{blockName:"biomesoplenty:fir_stairs",properties:{half:"top",shape:"straight",facing:"south"}}}
:enddata
:endrule

rule:
plugin=vanillaBlocks
number=7
data:
JSON:{blockState:{blockName:"biomesoplenty:wood_slab_0",properties:{half:"bottom",variant:"fir"}}}
:enddata
:endrule

rule:
plugin=vanillaBlocks
number=8
data:
JSON:{blockState:{blockName:"biomesoplenty:planks_0",properties:{variant:"fir"}}}
:enddata
:endrule

rule:
plugin=vanillaBlocks
number=9
data:
JSON:{blockState:{blockName:"biomesoplenty:fir_fence",properties:{east:"false",south:"false",north:"false",west:"false"}}}
:enddata
:endrule

rule:
plugin=vanillaBlocks
number=10
data:
JSON:{blockState:{blockName:"biomesoplenty:fir_stairs",properties:{half:"top",shape:"straight",facing:"east"}}}
:enddata
:endrule

rule:
plugin=vanillaBlocks
number=11
data:
JSON:{blockState:{blockName:"biomesoplenty:fir_stairs",properties:{half:"bottom",shape:"straight",facing:"south"}}}
:enddata
:endrule

rule:
plugin=vanillaBlocks
number=12
data:
JSON:{blockState:{blockName:"biomesoplenty:fir_stairs",properties:{half:"bottom",shape:"straight",facing:"east"}}}
:enddata
:endrule

rule:
plugin=vanillaBlocks
number=13
data:
JSON:{blockState:{blockName:"minecraft:torch",properties:{facing:"north"}}}
:enddata
:endrule

rule:
plugin=vanillaBlocks
number=14
data:
JSON:{blockState:{blockName:"minecraft:torch",properties:{facing:"south"}}}
:enddata
:endrule

rule:
plugin=vanillaBlocks
number=15
data:
JSON:{blockState:{blockName:"minecraft:torch",properties:{facing:"east"}}}
:enddata
:endrule

rule:
plugin=vanillaBlocks
number=16
data:
JSON:{blockState:{blockName:"minecraft:stone_slab",properties:{half:"top",variant:"cobblestone"}}}
:enddata
:endrule

rule:
plugin=vanillaBlocks
number=17
data:
JSON:{blockState:{blockName:"biomesoplenty:wood_slab_0",properties:{half:"top",variant:"fir"}}}
:enddata
:endrule

rule:
plugin=vanillaBlocks
number=18
data:
JSON:{blockState:{blockName:"biomesoplenty:log_0",properties:{variant:"fir",axis:"z"}}}
:enddata
:endrule

rule:
plugin=vanillaBlocks
number=19
data:
JSON:{blockState:{blockName:"biomesoplenty:fir_stairs",properties:{half:"top",shape:"straight",facing:"north"}}}
:enddata
:endrule

rule:
plugin=vanillaBlocks
number=20
data:
JSON:{blockState:{blockName:"biomesoplenty:log_0",properties:{variant:"fir",axis:"x"}}}
:enddata
:endrule

rule:
plugin=vanillaBlocks
number=21
data:
JSON:{blockState:{blockName:"biomesoplenty:fir_stairs",properties:{half:"top",shape:"straight",facing:"west"}}}
:enddata
:endrule

rule:
plugin=vanillaBlocks
number=22
data:
JSON:{blockState:{blockName:"minecraft:torch",properties:{facing:"west"}}}
:enddata
:endrule

rule:
plugin=vanillaBlocks
number=23
data:
JSON:{blockState:{blockName:"minecraft:stone_stairs",properties:{half:"top",shape:"straight",facing:"west"}}}
:enddata
:endrule

rule:
plugin=vanillaBlocks
number=24
data:
JSON:{blockState:{blockName:"minecraft:stone_stairs",properties:{half:"bottom",shape:"straight",facing:"east"}}}
:enddata
:endrule

rule:
plugin=vanillaBlocks
number=25
data:
JSON:{blockState:{blockName:"biomesoplenty:fir_stairs",properties:{half:"bottom",shape:"straight",facing:"north"}}}
:enddata
:endrule

rule:
plugin=vanillaBlocks
number=26
data:
JSON:{blockState:{blockName:"biomesoplenty:fir_stairs",properties:{half:"bottom",shape:"straight",facing:"west"}}}
:enddata
:endrule

rule:
plugin=vanillaBlocks
number=27
data:
JSON:{blockState:{blockName:"minecraft:stone_stairs",properties:{half:"top",shape:"straight",facing:"east"}}}
:enddata
:endrule

rule:
plugin=vanillaBlocks
number=28
data:
JSON:{blockState:{blockName:"minecraft:stone_stairs",properties:{half:"top",shape:"straight",facing:"north"}}}
:enddata
:endrule

rule:
plugin=vanillaBlocks
number=29
data:
JSON:{blockState:{blockName:"minecraft:stone_stairs",properties:{half:"top",shape:"straight",facing:"south"}}}
:enddata
:endrule

rule:
plugin=vanillaBlocks
number=30
data:
JSON:{blockState:{blockName:"minecraft:torch",properties:{facing:"up"}}}
:enddata
:endrule

rule:
plugin=vanillaBlocks
number=31
data:
JSON:{blockState:{blockName:"minecraft:stone_stairs",properties:{half:"bottom",shape:"straight",facing:"west"}}}
:enddata
:endrule

rule:
plugin=vanillaBlocks
number=32
data:
JSON:{blockState:{blockName:"minecraft:stone_stairs",properties:{half:"bottom",shape:"straight",facing:"south"}}}
:enddata
:endrule

rule:
plugin=vanillaBlocks
number=33
data:
JSON:{blockState:{blockName:"minecraft:stone_stairs",properties:{half:"bottom",shape:"straight",facing:"north"}}}
:enddata
:endrule

#### ENTITIES ####
