# Ancient Warfare Structure Template File
# Auto-generated structure template file. created on: 3/19/2021 at: 13:6:51
# Lines beginning with # denote comments

header:
version=2.11
name=SurvivalBuild_FortWall_large_type1_InnerCornerTower_ENVIRONSfrozen
mods=environs
size=16,29,16
offset=15,4,15
:endheader

#### VALIDATION ####
validation:
type=ground
structureAuthor=TheOddlySeagull
survival=true
worldGenEnabled=false
unique=false
preserveBlocks=false
preventNaturalHostileSpawns=false
selectionWeight=1
clusterValue=1
minDuplicateDistance=1
dimensionWhiteList=true
dimensionList=
biomeGroupList=
biomeWhiteList=true
biomeList=
leveling=0
fill=0
border=0
blockSwap=false
territoryName=
biomeReplacement=minecraft:
minGenerationHeight=0
maxGenerationHeight=255
:endvalidation

#### LAYERS ####
layer: 0
1,1,1,1,1,1,1,1,1,1,1,1,1,1,1,1
1,1,1,1,1,1,1,1,1,1,1,1,1,1,1,1
1,1,1,1,1,1,1,1,1,1,1,1,1,1,1,1
1,1,1,1,1,1,1,1,1,1,1,1,1,1,1,1
1,1,1,1,1,1,2,2,2,2,2,1,1,1,1,1
1,1,1,1,1,2,2,2,2,2,2,2,2,2,2,2
1,1,1,1,2,2,2,2,2,2,2,2,2,2,2,2
1,1,1,1,2,2,2,2,2,2,2,2,2,2,2,2
1,1,1,1,2,2,2,2,2,2,2,2,2,2,2,2
1,1,1,1,2,2,2,2,2,2,2,2,2,2,2,2
1,1,1,1,1,2,2,2,2,2,2,2,2,2,2,2
1,1,1,1,1,2,2,2,2,2,2,2,2,2,2,2
1,1,1,1,1,2,2,2,2,2,2,2,2,2,2,2
1,1,1,1,1,2,2,2,2,2,2,2,2,2,2,2
1,1,1,1,1,2,2,2,2,2,2,2,2,2,2,2
1,1,1,1,1,2,2,2,2,2,2,2,2,2,2,1
:endlayer
layer: 1
1,1,1,1,1,1,1,1,1,1,1,1,1,1,1,1
1,1,1,1,1,1,1,1,1,1,1,1,1,1,1,1
1,1,1,1,1,1,1,1,1,1,1,1,1,1,1,1
1,1,1,1,1,1,1,1,1,1,1,1,1,1,1,1
1,1,1,1,1,1,2,2,2,2,2,1,1,1,1,1
1,1,1,1,1,2,2,2,2,2,2,2,2,2,2,2
1,1,1,1,2,2,2,2,2,2,2,2,2,2,2,2
1,1,1,1,2,2,2,2,2,2,2,2,2,2,2,2
1,1,1,1,2,2,2,2,2,2,2,2,2,2,2,2
1,1,1,1,2,2,2,2,2,2,2,2,2,2,2,2
1,1,1,1,1,2,2,2,2,2,2,0,0,0,0,0
1,1,1,1,1,2,2,2,2,2,0,0,0,0,0,0
1,1,1,1,1,2,2,2,2,2,0,0,0,0,0,0
1,1,1,1,1,2,2,2,2,2,0,0,0,0,0,0
1,1,1,1,1,2,2,2,2,2,0,0,0,0,2,2
1,1,1,1,1,2,2,2,2,2,0,0,0,0,2,1
:endlayer
layer: 2
1,1,1,1,1,1,1,1,1,1,1,1,1,1,1,1
1,1,1,1,1,1,1,1,1,1,1,1,1,1,1,1
1,1,1,1,1,1,1,1,1,1,1,1,1,1,1,1
1,1,1,1,1,1,1,1,1,1,1,1,1,1,1,1
1,1,1,1,1,1,2,2,2,2,2,1,1,1,1,1
1,1,1,1,1,2,2,2,2,2,2,2,2,2,2,2
1,1,1,1,2,2,2,2,2,2,2,2,2,2,2,2
1,1,1,1,2,2,2,2,2,2,2,2,2,2,2,2
1,1,1,1,2,2,2,2,2,2,2,2,2,2,2,2
1,1,1,1,2,2,2,2,2,2,2,2,2,2,2,2
1,1,1,1,1,2,2,2,2,2,2,0,0,0,0,0
1,1,1,1,1,2,2,2,2,2,0,0,0,0,0,0
1,1,1,1,1,2,2,2,2,2,0,0,0,0,0,0
1,1,1,1,1,2,2,2,2,2,0,0,0,0,0,0
1,1,1,1,1,2,2,2,2,2,0,0,0,0,2,2
1,1,1,1,1,2,2,2,2,2,0,0,0,0,2,1
:endlayer
layer: 3
3,3,3,3,3,3,3,3,3,3,3,3,3,3,3,3
3,3,3,3,3,3,3,3,3,3,3,3,3,3,3,3
3,3,3,3,3,3,3,3,3,3,3,3,3,3,3,3
3,3,3,3,3,3,3,3,3,3,3,3,3,3,3,3
3,3,3,3,3,3,2,2,2,2,3,3,3,3,3,3
3,3,3,3,3,2,2,2,2,2,2,2,2,2,2,2
3,3,3,3,2,2,2,2,2,2,2,2,2,2,2,2
3,3,3,3,2,2,2,2,2,2,2,2,2,2,2,2
3,3,3,3,2,2,2,2,2,2,2,2,2,2,2,2
3,3,3,3,2,2,2,2,2,2,2,2,2,2,2,2
3,3,3,3,3,2,2,2,2,2,2,0,0,0,0,0
3,3,3,3,3,2,2,2,2,2,0,0,0,0,0,0
3,3,3,3,3,2,2,2,2,2,0,0,0,0,0,0
3,3,3,3,3,2,2,2,2,2,0,0,0,0,0,0
3,3,3,3,3,2,2,2,2,2,0,0,0,0,2,2
3,3,3,3,3,2,2,2,2,2,0,0,0,0,2,3
:endlayer
layer: 4
0,0,0,0,0,0,0,0,0,0,0,0,0,0,0,0
0,0,0,0,0,0,0,0,0,0,0,0,0,0,0,0
0,0,0,0,0,0,0,0,0,0,0,0,0,0,0,0
0,0,0,0,0,0,0,0,0,0,0,0,0,0,0,0
0,0,0,0,0,0,2,0,0,2,0,0,0,0,0,0
0,0,0,0,0,2,2,6,6,2,2,4,4,5,5,4
0,0,0,0,2,2,2,6,6,2,2,2,2,2,2,2
0,0,0,0,2,2,2,2,4,2,2,2,2,2,2,2
0,0,0,0,2,2,2,2,2,2,2,2,2,2,2,2
0,0,0,0,2,2,2,2,2,2,2,2,4,8,8,4
0,0,0,0,0,2,2,2,2,2,2,0,0,0,0,0
0,0,0,0,0,4,2,2,2,2,0,0,0,0,0,0
0,0,0,0,0,4,2,2,2,4,0,0,0,0,0,0
0,0,0,0,0,5,2,2,2,7,0,0,0,0,0,0
0,0,0,0,0,5,2,2,2,7,0,0,0,0,2,2
0,0,0,0,0,4,2,2,2,4,0,0,0,0,2,0
:endlayer
layer: 5
0,0,0,0,0,0,0,0,0,0,0,0,0,0,0,0
0,0,0,0,0,0,0,0,0,0,0,0,0,0,0,0
0,0,0,0,0,0,0,0,0,0,0,0,0,0,0,0
0,0,0,0,0,0,9,0,0,9,0,0,0,0,0,0
0,0,0,0,0,0,2,0,0,2,0,0,0,0,0,0
0,0,0,0,0,2,2,0,0,0,2,4,4,0,0,4
0,0,0,0,2,2,2,0,0,0,0,2,2,2,2,2
0,0,0,0,2,2,2,0,4,6,6,2,2,2,2,2
0,0,0,0,2,2,2,2,2,2,2,2,2,2,2,2
0,0,0,0,2,2,2,2,2,2,2,2,4,11,11,4
0,0,0,0,0,2,2,2,2,2,2,0,0,0,0,0
0,0,0,0,0,4,2,2,2,2,0,0,0,0,0,0
0,0,0,0,0,4,2,2,2,4,0,0,0,0,0,0
0,0,0,0,0,0,2,2,2,10,0,0,0,0,0,0
0,0,0,0,0,0,2,2,2,10,0,0,0,0,6,6
0,0,0,0,0,4,2,2,2,4,0,0,0,0,6,0
:endlayer
layer: 6
0,0,0,0,0,0,0,0,0,0,0,0,0,0,0,0
0,0,0,0,0,0,0,0,0,0,0,0,0,0,0,0
0,0,0,0,0,0,0,0,0,0,0,0,0,0,0,0
0,0,0,0,0,0,0,0,0,0,0,0,0,0,0,0
0,0,0,0,0,0,2,0,0,2,0,0,0,0,0,0
0,0,0,0,0,2,2,0,0,0,2,4,4,0,0,4
0,0,0,0,2,2,2,0,0,0,0,2,2,2,2,2
0,0,0,0,2,2,2,12,4,0,13,2,2,2,2,2
0,0,0,0,2,2,2,2,6,0,0,2,2,2,2,2
0,0,0,0,2,2,2,2,6,0,2,2,4,0,0,4
0,0,0,0,0,2,2,2,2,2,2,0,0,0,0,0
0,0,0,0,0,4,2,2,2,2,0,0,0,0,0,0
0,0,0,0,0,4,2,2,2,4,0,0,0,0,0,0
0,0,0,0,0,0,2,2,2,0,0,0,0,0,0,0
0,0,0,0,0,0,2,2,2,0,0,0,0,0,0,0
0,0,0,0,0,4,2,2,2,4,0,0,0,0,0,0
:endlayer
layer: 7
0,0,0,0,0,0,0,0,0,0,0,0,0,0,0,0
0,0,0,0,0,0,0,0,0,0,0,0,0,0,0,0
0,0,0,0,0,0,0,0,0,0,0,0,0,0,0,0
0,0,0,0,0,0,0,0,0,0,0,0,0,0,0,0
0,0,0,0,0,0,2,14,15,2,0,0,0,0,0,0
0,0,0,0,0,2,2,2,2,16,2,4,4,0,0,4
0,0,0,0,2,2,2,2,2,16,16,2,2,2,2,2
0,0,0,0,2,2,6,6,4,0,0,2,2,2,2,2
0,0,0,0,2,2,0,0,0,0,0,2,2,2,2,2
0,0,0,0,2,2,2,0,9,0,2,2,4,0,0,4
0,0,0,0,0,2,2,2,2,2,2,0,0,0,0,0
0,0,0,0,0,4,2,2,2,2,0,0,0,0,0,0
0,0,0,0,0,4,2,2,2,4,0,0,0,0,0,0
0,0,0,0,0,0,2,2,2,0,0,0,0,0,0,0
0,0,0,0,0,0,2,2,2,0,0,0,0,0,0,0
0,0,0,0,0,4,2,2,2,4,0,0,0,0,0,0
:endlayer
layer: 8
0,0,0,0,0,0,0,0,0,0,0,0,0,0,0,0
0,0,0,0,0,0,0,0,0,0,0,0,0,0,0,0
0,0,0,0,0,0,0,0,0,0,0,0,0,0,0,0
0,0,0,0,0,0,0,0,0,0,0,0,0,0,0,0
0,0,0,0,0,0,2,2,2,2,0,0,0,0,0,0
0,0,0,0,0,2,2,0,6,2,2,4,4,0,0,4
0,0,0,0,2,2,0,0,6,2,2,2,2,2,2,2
0,0,0,0,2,2,17,0,4,2,2,2,2,2,2,2
0,0,0,0,2,2,0,0,0,16,16,2,2,2,2,2
0,0,0,0,2,2,2,0,0,16,2,2,4,0,0,4
0,0,0,0,0,2,2,2,2,2,2,0,0,0,0,0
0,0,0,0,0,4,2,2,2,2,0,0,0,0,0,0
0,0,0,0,0,4,2,2,2,4,0,0,0,0,0,0
0,0,0,0,0,0,2,2,2,0,0,0,0,0,0,0
0,0,0,0,0,0,2,2,2,0,0,0,0,0,0,0
0,0,0,0,0,4,2,2,2,4,0,0,0,0,0,0
:endlayer
layer: 9
0,0,0,0,0,0,0,0,0,0,0,0,0,0,0,0
0,0,0,0,0,0,0,0,0,0,0,0,0,0,0,0
0,0,0,0,0,0,0,0,0,0,0,0,0,0,0,0
0,0,0,0,0,0,0,19,19,0,0,0,0,0,0,0
0,0,0,0,0,0,2,2,2,2,0,0,0,0,0,0
0,0,0,0,0,2,2,0,0,0,2,4,4,7,18,4
0,0,0,0,2,2,0,0,0,0,0,2,2,2,2,2
0,0,0,18,2,2,0,0,4,6,6,2,2,2,2,2
0,0,0,18,2,2,16,16,2,6,6,2,2,2,2,2
0,0,0,0,2,2,2,2,2,2,2,2,4,7,18,4
0,0,0,0,0,2,2,2,2,2,2,0,0,0,0,0
0,0,0,0,0,4,2,2,2,2,0,0,0,0,0,0
0,0,0,0,0,4,2,2,2,4,0,0,0,0,0,0
0,0,0,0,0,8,2,2,2,8,0,0,0,0,0,0
0,0,0,0,0,19,2,2,2,19,0,0,0,0,0,0
0,0,0,0,0,4,2,2,2,4,0,0,0,0,0,0
:endlayer
layer: 10
0,0,0,0,0,0,0,0,0,0,0,0,0,0,0,0
0,0,0,0,0,0,0,0,0,0,0,0,0,0,0,0
0,0,0,0,0,0,0,0,0,0,0,0,0,0,0,0
0,0,0,0,0,0,19,20,20,19,0,0,0,0,0,0
0,0,0,0,0,22,2,2,2,2,21,19,19,21,21,19
0,0,0,0,22,2,2,0,0,0,2,4,4,4,4,4
0,0,0,18,2,2,0,0,0,0,0,2,2,2,2,2
0,0,0,20,2,2,12,12,4,0,0,0,6,2,2,2
0,0,0,20,2,6,6,23,0,0,0,0,6,2,2,2
0,0,0,18,2,6,6,6,0,0,0,2,4,4,4,4
0,0,0,0,21,2,6,6,6,6,2,8,8,21,21,8
0,0,0,0,18,4,2,2,2,2,7,0,0,0,0,0
0,0,0,0,18,4,2,2,2,4,7,0,0,0,0,0
0,0,0,0,21,4,2,2,2,4,21,0,0,0,0,0
0,0,0,0,21,4,2,2,2,4,21,0,0,0,0,0
0,0,0,0,18,4,2,2,2,4,7,0,0,0,0,0
:endlayer
layer: 11
0,0,0,0,0,0,0,0,0,0,0,0,0,0,0,0
0,0,0,0,0,0,0,0,0,0,0,0,0,0,0,0
0,0,0,0,0,0,0,0,0,0,0,0,0,0,0,0
0,0,0,0,0,0,4,25,25,4,0,0,0,0,0,0
0,0,0,0,0,22,2,2,2,2,20,25,20,20,25,20
0,0,0,0,22,2,5,21,0,0,2,0,0,0,0,4
0,0,0,4,2,5,5,21,0,0,0,2,0,0,0,0
0,0,0,24,0,0,0,4,5,0,0,0,0,0,0,0
0,0,0,24,0,0,0,0,0,0,0,0,0,0,0,0
0,0,0,4,2,0,0,0,0,0,0,2,0,0,0,4
0,0,0,0,20,2,0,0,0,0,2,4,20,11,11,20
0,0,0,0,24,0,2,0,0,2,4,0,0,0,0,0
0,0,0,0,20,0,0,0,0,0,20,0,0,0,0,0
0,0,0,0,20,0,0,0,0,0,10,0,0,0,0,0
0,0,0,0,24,0,0,0,0,0,10,0,0,0,0,0
0,0,0,0,20,4,0,0,0,4,20,0,0,0,0,0
:endlayer
layer: 12
0,0,0,0,0,0,0,0,0,0,0,0,0,0,0,0
0,0,0,0,0,0,0,0,0,0,0,0,0,0,0,0
0,0,0,0,0,0,0,0,0,0,0,0,0,0,0,0
0,0,0,0,0,0,4,0,0,4,0,0,0,0,0,0
0,0,0,0,0,22,2,0,0,2,20,0,20,20,0,20
0,0,0,0,22,2,17,0,5,5,2,0,0,0,0,4
0,0,0,4,2,26,0,0,5,5,26,2,0,0,0,0
0,0,0,0,0,0,0,4,21,21,0,0,0,0,0,0
0,0,0,0,0,0,0,0,0,0,0,0,0,0,0,0
0,0,0,4,2,9,0,0,0,0,9,2,0,0,0,4
0,0,0,0,20,2,17,0,0,13,2,4,20,0,0,20
0,0,0,0,0,0,2,0,0,2,4,0,0,0,0,0
0,0,0,0,20,0,0,0,0,0,20,0,0,0,0,0
0,0,0,0,20,0,0,0,0,0,0,0,0,0,0,0
0,0,0,0,0,0,0,0,0,0,0,0,0,0,0,0
0,0,0,0,20,4,0,0,0,4,20,0,0,0,0,0
:endlayer
layer: 13
0,0,0,0,0,0,0,0,0,0,0,0,0,0,0,0
0,0,0,0,0,0,0,0,0,0,0,0,0,0,0,0
0,0,0,0,0,0,0,0,0,0,0,0,0,0,0,0
0,0,0,0,0,0,4,21,21,4,9,0,0,0,0,9
0,0,0,0,0,22,2,0,0,2,20,21,20,20,21,20
0,0,0,0,22,2,0,0,0,0,2,0,0,0,13,4
0,0,0,4,2,0,0,0,0,0,0,2,0,0,0,8
0,0,0,21,0,0,0,4,0,0,0,27,0,0,0,0
0,0,0,21,0,0,0,21,5,5,0,12,0,0,0,19
0,0,0,4,2,0,0,21,5,5,0,2,0,0,13,4
0,0,0,13,20,2,0,0,0,0,2,4,20,21,21,20
0,0,0,0,21,0,2,14,15,2,4,26,0,0,0,26
0,0,0,0,20,0,0,0,0,0,20,0,0,0,0,0
0,0,0,0,20,0,0,0,0,0,21,0,0,0,0,0
0,0,0,0,21,9,0,0,0,9,21,0,0,0,0,0
0,0,0,13,20,4,7,0,18,4,20,17,0,0,0,0
:endlayer
layer: 14
0,0,0,0,0,0,0,0,0,0,0,0,0,0,0,0
0,0,0,0,0,0,0,0,0,0,0,0,0,0,0,0
0,0,0,0,0,0,0,0,0,0,0,0,0,0,0,0
0,0,0,0,0,0,24,25,25,24,21,21,21,21,21,21
0,0,0,0,0,22,2,2,2,2,4,4,4,4,4,4
0,0,0,0,22,2,0,0,0,0,2,8,8,8,8,4
0,0,0,25,2,0,0,0,0,0,0,2,0,0,0,4
0,0,0,24,14,21,21,4,0,0,0,2,0,0,0,4
0,0,0,24,14,5,5,0,0,0,0,2,0,0,0,4
0,0,0,25,2,5,5,0,0,0,0,2,19,19,19,4
0,0,0,21,4,2,0,0,0,0,2,4,4,4,4,4
0,0,0,21,4,7,2,2,2,2,4,21,21,21,21,21
0,0,0,21,4,7,0,0,0,18,4,21,0,0,0,0
0,0,0,21,4,7,0,0,0,18,4,21,0,0,0,0
0,0,0,21,4,7,0,0,0,18,4,21,0,0,0,0
0,0,0,21,4,4,4,4,4,4,4,21,0,0,0,0
:endlayer
layer: 15
0,0,0,0,0,0,0,0,0,0,0,0,0,0,0,0
0,0,0,0,0,0,0,0,0,0,0,0,0,0,0,0
0,0,0,0,0,0,0,0,0,0,0,0,0,0,0,0
0,0,0,0,0,0,0,0,0,0,0,0,0,0,0,0
0,0,0,0,0,22,2,2,2,2,5,5,5,5,5,5
0,0,0,0,22,2,5,21,0,0,2,5,5,5,5,5
0,0,0,22,2,5,5,21,0,0,27,2,20,20,20,20
0,0,0,0,2,0,0,4,0,0,0,2,20,20,20,20
0,0,0,0,2,0,0,0,0,0,0,2,20,20,20,20
0,0,0,22,2,0,0,0,0,0,12,2,5,5,5,5
0,0,0,0,5,2,14,0,0,15,2,5,5,5,5,5
0,0,0,0,5,5,2,2,2,2,5,0,0,0,0,0
0,0,0,0,5,5,20,20,20,5,5,0,0,0,0,0
0,0,0,0,5,5,20,20,20,5,5,0,0,0,0,0
0,0,0,0,5,5,20,20,20,5,5,0,0,0,0,0
0,0,0,0,5,5,20,20,20,5,5,0,0,0,0,0
:endlayer
layer: 16
0,0,0,0,0,0,0,0,0,0,0,0,0,0,0,0
0,0,0,0,0,0,0,0,0,0,0,0,0,0,0,0
0,0,0,0,0,0,0,0,0,0,0,0,0,0,0,0
0,0,0,0,0,0,19,21,21,19,0,0,0,0,0,0
0,0,0,0,0,18,2,2,2,2,7,0,0,0,0,0
0,0,0,0,19,2,0,0,5,5,2,19,0,0,0,0
0,0,0,18,2,0,0,0,5,5,2,2,7,0,0,0
0,0,0,21,2,0,0,4,21,21,2,2,21,28,0,0
0,0,0,21,2,0,0,21,21,21,2,2,21,0,0,0
0,0,0,18,2,21,21,21,21,21,2,2,7,0,0,0
0,0,0,0,8,2,2,2,2,2,2,8,0,0,0,0
0,0,0,0,0,18,2,2,2,2,7,0,0,0,0,0
0,0,0,0,0,0,8,21,21,8,0,0,0,0,0,0
0,0,0,0,0,0,0,28,0,0,0,0,0,0,0,0
0,0,0,0,0,0,0,0,0,0,0,0,0,0,0,0
0,0,0,0,0,0,0,0,0,0,0,0,0,0,0,0
:endlayer
layer: 17
0,0,0,0,0,0,0,0,0,0,0,0,0,0,0,0
0,0,0,0,0,0,0,0,0,0,0,0,0,0,0,0
0,0,0,0,0,0,0,0,0,0,0,0,0,0,0,0
0,0,0,0,0,0,4,25,25,4,0,0,0,0,0,0
0,0,0,0,22,20,0,0,0,0,20,22,0,0,0,0
0,0,0,0,20,0,0,0,0,0,0,20,0,0,0,0
0,0,0,4,0,0,0,9,0,0,0,0,4,0,0,0
0,0,0,24,0,0,13,4,17,0,0,0,10,0,0,0
0,0,0,24,0,0,0,26,0,0,0,0,10,0,0,0
0,0,0,4,0,0,0,0,0,0,0,0,4,0,0,0
0,0,0,0,20,0,0,0,0,0,0,20,0,0,0,0
0,0,0,0,22,20,0,0,0,0,20,22,0,0,0,0
0,0,0,0,0,0,4,11,11,4,0,0,0,0,0,0
0,0,0,0,0,0,0,0,0,0,0,0,0,0,0,0
0,0,0,0,0,0,0,0,0,0,0,0,0,0,0,0
0,0,0,0,0,0,0,0,0,0,0,0,0,0,0,0
:endlayer
layer: 18
0,0,0,0,0,0,0,0,0,0,0,0,0,0,0,0
0,0,0,0,0,0,0,0,0,0,0,0,0,0,0,0
0,0,0,0,0,0,0,0,0,0,0,0,0,0,0,0
0,0,0,0,0,0,4,0,0,4,0,0,0,0,0,0
0,0,0,0,22,20,0,0,0,0,20,22,0,0,0,0
0,0,0,0,20,0,0,0,0,0,0,20,0,0,0,0
0,0,0,4,0,0,0,0,0,0,0,0,4,0,0,0
0,0,0,0,0,0,0,5,0,0,0,0,0,0,0,0
0,0,0,0,0,0,0,0,0,0,0,0,0,0,0,0
0,0,0,4,0,0,0,0,0,0,0,0,4,0,0,0
0,0,0,0,20,0,0,0,0,0,0,20,0,0,0,0
0,0,0,0,22,20,0,0,0,0,20,22,0,0,0,0
0,0,0,0,0,0,4,0,0,4,0,0,0,0,0,0
0,0,0,0,0,0,0,0,0,0,0,0,0,0,0,0
0,0,0,0,0,0,0,0,0,0,0,0,0,0,0,0
0,0,0,0,0,0,0,0,0,0,0,0,0,0,0,0
:endlayer
layer: 19
0,0,0,0,0,0,0,0,0,0,0,0,0,0,0,0
0,0,0,0,0,0,0,0,0,0,0,0,0,0,0,0
0,0,0,0,0,0,0,0,0,0,0,0,0,0,0,0
0,0,0,0,0,0,4,21,21,4,0,0,0,0,0,0
0,0,0,0,22,20,0,0,0,0,20,22,0,0,0,0
0,0,0,0,20,22,0,0,0,0,22,20,0,0,0,0
0,0,0,4,0,0,0,0,0,0,0,0,4,0,0,0
0,0,0,21,0,0,0,0,0,0,0,0,21,0,0,0
0,0,0,21,0,0,0,0,0,0,0,0,21,0,0,0
0,0,0,4,0,0,0,0,0,0,0,0,4,0,0,0
0,0,0,0,20,22,0,0,0,0,22,20,0,0,0,0
0,0,0,0,22,20,0,0,0,0,20,22,0,0,0,0
0,0,0,0,0,0,4,21,21,4,0,0,0,0,0,0
0,0,0,0,0,0,0,0,0,0,0,0,0,0,0,0
0,0,0,0,0,0,0,0,0,0,0,0,0,0,0,0
0,0,0,0,0,0,0,0,0,0,0,0,0,0,0,0
:endlayer
layer: 20
0,0,0,0,0,0,0,0,0,0,0,0,0,0,0,0
0,0,0,0,0,0,0,0,0,0,0,0,0,0,0,0
0,0,0,0,0,0,21,21,21,21,0,0,0,0,0,0
0,0,0,0,21,21,4,4,4,4,21,21,0,0,0,0
0,0,0,21,21,4,7,0,0,18,4,21,21,0,0,0
0,0,0,21,4,20,0,0,0,0,20,4,21,0,0,0
0,0,21,4,8,0,0,0,0,0,0,8,4,21,0,0
0,0,21,4,0,0,0,0,0,0,0,0,4,21,0,0
0,0,21,4,0,0,0,0,0,0,0,0,4,21,0,0
0,0,21,4,19,0,0,0,0,0,0,19,4,21,0,0
0,0,0,21,4,20,0,0,0,0,20,4,21,0,0,0
0,0,0,21,21,4,7,0,0,18,4,21,21,0,0,0
0,0,0,0,21,21,4,4,4,4,21,21,0,0,0,0
0,0,0,0,0,0,21,21,21,21,0,0,0,0,0,0
0,0,0,0,0,0,0,0,0,0,0,0,0,0,0,0
0,0,0,0,0,0,0,0,0,0,0,0,0,0,0,0
:endlayer
layer: 21
0,0,0,0,0,0,0,0,0,0,0,0,0,0,0,0
0,0,0,0,0,0,0,0,0,0,0,0,0,0,0,0
0,0,0,0,0,0,0,0,0,0,0,0,0,0,0,0
0,0,0,0,0,0,5,5,5,5,0,0,0,0,0,0
0,0,0,0,28,5,5,20,20,5,5,28,0,0,0,0
0,0,0,0,5,5,20,20,20,20,5,5,0,0,0,0
0,0,0,5,5,20,20,21,21,20,20,5,5,0,0,0
0,0,0,5,20,20,21,21,21,21,20,20,5,0,0,0
0,0,0,5,20,20,21,21,21,21,20,20,5,0,0,0
0,0,0,5,5,20,20,21,21,20,20,5,5,0,0,0
0,0,0,0,5,5,20,20,20,20,5,5,0,0,0,0
0,0,0,0,28,5,5,20,20,5,5,28,0,0,0,0
0,0,0,0,0,0,5,5,5,5,0,0,0,0,0,0
0,0,0,0,0,0,0,0,0,0,0,0,0,0,0,0
0,0,0,0,0,0,0,0,0,0,0,0,0,0,0,0
0,0,0,0,0,0,0,0,0,0,0,0,0,0,0,0
:endlayer
layer: 22
0,0,0,0,0,0,0,0,0,0,0,0,0,0,0,0
0,0,0,0,0,0,0,0,0,0,0,0,0,0,0,0
0,0,0,0,0,0,0,0,0,0,0,0,0,0,0,0
0,0,0,0,0,0,0,0,0,0,0,0,0,0,0,0
0,0,0,0,0,0,0,0,0,0,0,0,0,0,0,0
0,0,0,0,0,0,0,25,25,0,0,0,0,0,0,0
0,0,0,0,0,0,20,20,20,20,0,0,0,0,0,0
0,0,0,0,0,24,20,20,20,20,10,0,0,0,0,0
0,0,0,0,0,24,20,20,20,20,10,0,0,0,0,0
0,0,0,0,0,0,20,20,20,20,0,0,0,0,0,0
0,0,0,0,0,0,0,11,11,0,0,0,0,0,0,0
0,0,0,0,0,0,0,0,0,0,0,0,0,0,0,0
0,0,0,0,0,0,0,0,0,0,0,0,0,0,0,0
0,0,0,0,0,0,0,0,0,0,0,0,0,0,0,0
0,0,0,0,0,0,0,0,0,0,0,0,0,0,0,0
0,0,0,0,0,0,0,0,0,0,0,0,0,0,0,0
:endlayer
layer: 23
0,0,0,0,0,0,0,0,0,0,0,0,0,0,0,0
0,0,0,0,0,0,0,0,0,0,0,0,0,0,0,0
0,0,0,0,0,0,0,0,0,0,0,0,0,0,0,0
0,0,0,0,0,0,0,0,0,0,0,0,0,0,0,0
0,0,0,0,0,0,0,0,0,0,0,0,0,0,0,0
0,0,0,0,0,0,0,0,0,0,0,0,0,0,0,0
0,0,0,0,0,0,22,20,20,22,0,0,0,0,0,0
0,0,0,0,0,0,20,20,20,20,0,0,0,0,0,0
0,0,0,0,0,0,20,20,20,20,0,0,0,0,0,0
0,0,0,0,0,0,22,20,20,22,0,0,0,0,0,0
0,0,0,0,0,0,0,0,0,0,0,0,0,0,0,0
0,0,0,0,0,0,0,0,0,0,0,0,0,0,0,0
0,0,0,0,0,0,0,0,0,0,0,0,0,0,0,0
0,0,0,0,0,0,0,0,0,0,0,0,0,0,0,0
0,0,0,0,0,0,0,0,0,0,0,0,0,0,0,0
0,0,0,0,0,0,0,0,0,0,0,0,0,0,0,0
:endlayer
layer: 24
0,0,0,0,0,0,0,0,0,0,0,0,0,0,0,0
0,0,0,0,0,0,0,0,0,0,0,0,0,0,0,0
0,0,0,0,0,0,0,0,0,0,0,0,0,0,0,0
0,0,0,0,0,0,0,0,0,0,0,0,0,0,0,0
0,0,0,0,0,0,0,0,0,0,0,0,0,0,0,0
0,0,0,0,0,0,0,0,0,0,0,0,0,0,0,0
0,0,0,0,0,0,0,25,25,0,0,0,0,0,0,0
0,0,0,0,0,0,24,20,20,10,0,0,0,0,0,0
0,0,0,0,0,0,24,20,20,10,0,0,0,0,0,0
0,0,0,0,0,0,0,11,11,0,0,0,0,0,0,0
0,0,0,0,0,0,0,0,0,0,0,0,0,0,0,0
0,0,0,0,0,0,0,0,0,0,0,0,0,0,0,0
0,0,0,0,0,0,0,0,0,0,0,0,0,0,0,0
0,0,0,0,0,0,0,0,0,0,0,0,0,0,0,0
0,0,0,0,0,0,0,0,0,0,0,0,0,0,0,0
0,0,0,0,0,0,0,0,0,0,0,0,0,0,0,0
:endlayer
layer: 25
0,0,0,0,0,0,0,0,0,0,0,0,0,0,0,0
0,0,0,0,0,0,0,0,0,0,0,0,0,0,0,0
0,0,0,0,0,0,0,0,0,0,0,0,0,0,0,0
0,0,0,0,0,0,0,0,0,0,0,0,0,0,0,0
0,0,0,0,0,0,0,0,0,0,0,0,0,0,0,0
0,0,0,0,0,0,0,0,0,0,0,0,0,0,0,0
0,0,0,0,0,0,0,0,0,0,0,0,0,0,0,0
0,0,0,0,0,0,0,20,20,0,0,0,0,0,0,0
0,0,0,0,0,0,0,20,20,0,0,0,0,0,0,0
0,0,0,0,0,0,0,0,0,0,0,0,0,0,0,0
0,0,0,0,0,0,0,0,0,0,0,0,0,0,0,0
0,0,0,0,0,0,0,0,0,0,0,0,0,0,0,0
0,0,0,0,0,0,0,0,0,0,0,0,0,0,0,0
0,0,0,0,0,0,0,0,0,0,0,0,0,0,0,0
0,0,0,0,0,0,0,0,0,0,0,0,0,0,0,0
0,0,0,0,0,0,0,0,0,0,0,0,0,0,0,0
:endlayer
layer: 26
0,0,0,0,0,0,0,0,0,0,0,0,0,0,0,0
0,0,0,0,0,0,0,0,0,0,0,0,0,0,0,0
0,0,0,0,0,0,0,0,0,0,0,0,0,0,0,0
0,0,0,0,0,0,0,0,0,0,0,0,0,0,0,0
0,0,0,0,0,0,0,0,0,0,0,0,0,0,0,0
0,0,0,0,0,0,0,0,0,0,0,0,0,0,0,0
0,0,0,0,0,0,0,0,0,0,0,0,0,0,0,0
0,0,0,0,0,0,0,24,25,0,0,0,0,0,0,0
0,0,0,0,0,0,0,11,10,0,0,0,0,0,0,0
0,0,0,0,0,0,0,0,0,0,0,0,0,0,0,0
0,0,0,0,0,0,0,0,0,0,0,0,0,0,0,0
0,0,0,0,0,0,0,0,0,0,0,0,0,0,0,0
0,0,0,0,0,0,0,0,0,0,0,0,0,0,0,0
0,0,0,0,0,0,0,0,0,0,0,0,0,0,0,0
0,0,0,0,0,0,0,0,0,0,0,0,0,0,0,0
0,0,0,0,0,0,0,0,0,0,0,0,0,0,0,0
:endlayer
layer: 27
0,0,0,0,0,0,0,0,0,0,0,0,0,0,0,0
0,0,0,0,0,0,0,0,0,0,0,0,0,0,0,0
0,0,0,0,0,0,0,0,0,0,0,0,0,0,0,0
0,0,0,0,0,0,0,0,0,0,0,0,0,0,0,0
0,0,0,0,0,0,0,0,0,0,0,0,0,0,0,0
0,0,0,0,0,0,0,0,0,0,0,0,0,0,0,0
0,0,0,0,0,0,0,0,0,0,0,0,0,0,0,0
0,0,0,0,0,0,0,22,22,0,0,0,0,0,0,0
0,0,0,0,0,0,0,22,22,0,0,0,0,0,0,0
0,0,0,0,0,0,0,0,0,0,0,0,0,0,0,0
0,0,0,0,0,0,0,0,0,0,0,0,0,0,0,0
0,0,0,0,0,0,0,0,0,0,0,0,0,0,0,0
0,0,0,0,0,0,0,0,0,0,0,0,0,0,0,0
0,0,0,0,0,0,0,0,0,0,0,0,0,0,0,0
0,0,0,0,0,0,0,0,0,0,0,0,0,0,0,0
0,0,0,0,0,0,0,0,0,0,0,0,0,0,0,0
:endlayer
layer: 28
0,0,0,0,0,0,0,0,0,0,0,0,0,0,0,0
0,0,0,0,0,0,0,0,0,0,0,0,0,0,0,0
0,0,0,0,0,0,0,0,0,0,0,0,0,0,0,0
0,0,0,0,0,0,0,0,0,0,0,0,0,0,0,0
0,0,0,0,0,0,0,0,0,0,0,0,0,0,0,0
0,0,0,0,0,0,0,0,0,0,0,0,0,0,0,0
0,0,0,0,0,0,0,0,0,0,0,0,0,0,0,0
0,0,0,0,0,0,0,22,22,0,0,0,0,0,0,0
0,0,0,0,0,0,0,22,22,0,0,0,0,0,0,0
0,0,0,0,0,0,0,0,0,0,0,0,0,0,0,0
0,0,0,0,0,0,0,0,0,0,0,0,0,0,0,0
0,0,0,0,0,0,0,0,0,0,0,0,0,0,0,0
0,0,0,0,0,0,0,0,0,0,0,0,0,0,0,0
0,0,0,0,0,0,0,0,0,0,0,0,0,0,0,0
0,0,0,0,0,0,0,0,0,0,0,0,0,0,0,0
0,0,0,0,0,0,0,0,0,0,0,0,0,0,0,0
:endlayer

#### RULES ####
rule:
plugin=vanillaBlocks
number=1
data:
JSON:{blockState:{blockName:"minecraft:dirt",properties:{variant:"dirt",snowy:"false"}}}
:enddata
:endrule

rule:
plugin=vanillaBlocks
number=2
data:
JSON:{blockState:{blockName:"minecraft:cobblestone"}}
:enddata
:endrule

rule:
plugin=vanillaBlocks
number=3
data:
JSON:{blockState:{blockName:"minecraft:grass",properties:{snowy:"false"}}}
:enddata
:endrule

rule:
plugin=vanillaBlocks
number=4
data:
JSON:{blockState:{blockName:"environs:frozen_log",properties:{axis:"y"}}}
:enddata
:endrule

rule:
plugin=vanillaBlocks
number=5
data:
JSON:{blockState:{blockName:"environs:frozen_slab",properties:{half:"bottom",variant:"default"}}}
:enddata
:endrule

rule:
plugin=vanillaBlocks
number=6
data:
JSON:{blockState:{blockName:"minecraft:stone_slab",properties:{half:"bottom",variant:"cobblestone"}}}
:enddata
:endrule

rule:
plugin=vanillaBlocks
number=7
data:
JSON:{blockState:{blockName:"environs:frozen_stairs",properties:{half:"top",shape:"straight",facing:"west"}}}
:enddata
:endrule

rule:
plugin=vanillaBlocks
number=8
data:
JSON:{blockState:{blockName:"environs:frozen_stairs",properties:{half:"top",shape:"straight",facing:"north"}}}
:enddata
:endrule

rule:
plugin=vanillaBlocks
number=9
data:
JSON:{blockState:{blockName:"minecraft:torch",properties:{facing:"north"}}}
:enddata
:endrule

rule:
plugin=vanillaBlocks
number=10
data:
JSON:{blockState:{blockName:"environs:frozen_stairs",properties:{half:"bottom",shape:"straight",facing:"west"}}}
:enddata
:endrule

rule:
plugin=vanillaBlocks
number=11
data:
JSON:{blockState:{blockName:"environs:frozen_stairs",properties:{half:"bottom",shape:"straight",facing:"north"}}}
:enddata
:endrule

rule:
plugin=vanillaBlocks
number=12
data:
JSON:{blockState:{blockName:"minecraft:stone_stairs",properties:{half:"top",shape:"straight",facing:"south"}}}
:enddata
:endrule

rule:
plugin=vanillaBlocks
number=13
data:
JSON:{blockState:{blockName:"minecraft:torch",properties:{facing:"west"}}}
:enddata
:endrule

rule:
plugin=vanillaBlocks
number=14
data:
JSON:{blockState:{blockName:"minecraft:stone_stairs",properties:{half:"top",shape:"straight",facing:"west"}}}
:enddata
:endrule

rule:
plugin=vanillaBlocks
number=15
data:
JSON:{blockState:{blockName:"minecraft:stone_stairs",properties:{half:"top",shape:"straight",facing:"east"}}}
:enddata
:endrule

rule:
plugin=vanillaBlocks
number=16
data:
JSON:{blockState:{blockName:"minecraft:stone_slab",properties:{half:"top",variant:"cobblestone"}}}
:enddata
:endrule

rule:
plugin=vanillaBlocks
number=17
data:
JSON:{blockState:{blockName:"minecraft:torch",properties:{facing:"east"}}}
:enddata
:endrule

rule:
plugin=vanillaBlocks
number=18
data:
JSON:{blockState:{blockName:"environs:frozen_stairs",properties:{half:"top",shape:"straight",facing:"east"}}}
:enddata
:endrule

rule:
plugin=vanillaBlocks
number=19
data:
JSON:{blockState:{blockName:"environs:frozen_stairs",properties:{half:"top",shape:"straight",facing:"south"}}}
:enddata
:endrule

rule:
plugin=vanillaBlocks
number=20
data:
JSON:{blockState:{blockName:"environs:frozen_planks"}}
:enddata
:endrule

rule:
plugin=vanillaBlocks
number=21
data:
JSON:{blockState:{blockName:"environs:frozen_slab",properties:{half:"top",variant:"default"}}}
:enddata
:endrule

rule:
plugin=vanillaBlocks
number=22
data:
JSON:{blockState:{blockName:"environs:frozen_fence",properties:{east:"false",south:"false",north:"false",west:"false"}}}
:enddata
:endrule

rule:
plugin=vanillaBlocks
number=23
data:
JSON:{blockState:{blockName:"minecraft:stone_stairs",properties:{half:"bottom",shape:"straight",facing:"north"}}}
:enddata
:endrule

rule:
plugin=vanillaBlocks
number=24
data:
JSON:{blockState:{blockName:"environs:frozen_stairs",properties:{half:"bottom",shape:"straight",facing:"east"}}}
:enddata
:endrule

rule:
plugin=vanillaBlocks
number=25
data:
JSON:{blockState:{blockName:"environs:frozen_stairs",properties:{half:"bottom",shape:"straight",facing:"south"}}}
:enddata
:endrule

rule:
plugin=vanillaBlocks
number=26
data:
JSON:{blockState:{blockName:"minecraft:torch",properties:{facing:"south"}}}
:enddata
:endrule

rule:
plugin=vanillaBlocks
number=27
data:
JSON:{blockState:{blockName:"minecraft:stone_stairs",properties:{half:"top",shape:"straight",facing:"north"}}}
:enddata
:endrule

rule:
plugin=vanillaBlocks
number=28
data:
JSON:{blockState:{blockName:"minecraft:torch",properties:{facing:"up"}}}
:enddata
:endrule

#### ENTITIES ####
