# Ancient Warfare Structure Template File
# Auto-generated structure template file. created on: 4/27/2021 at: 19:24:54
# Lines beginning with # denote comments

header:
version=2.11
name=SurvivalBuild_FortWall_large_type2_StraightTower_QUARKgranite
mods=quark
size=16,23,16
offset=15,4,15
:endheader

#### VALIDATION ####
validation:
type=ground
structureAuthor=TheOddlySeagull
survival=true
worldGenEnabled=false
unique=false
preserveBlocks=false
preventNaturalHostileSpawns=false
selectionWeight=1
clusterValue=1
minDuplicateDistance=1
dimensionWhiteList=true
dimensionList=
biomeGroupList=
biomeWhiteList=true
biomeList=
leveling=0
fill=0
border=0
blockSwap=false
territoryName=
biomeReplacement=minecraft:
minGenerationHeight=0
maxGenerationHeight=255
:endvalidation

#### LAYERS ####
layer: 0
1,1,1,1,1,1,1,1,1,1,1,1,1,1,1,1
1,1,2,2,1,2,1,1,1,1,2,1,2,2,1,1
1,2,2,2,2,2,2,2,2,2,2,2,2,2,2,1
1,2,2,2,2,2,2,2,2,2,2,2,2,2,2,1
1,1,2,2,2,2,2,2,2,2,2,2,2,2,1,1
2,1,2,2,2,2,2,2,2,2,2,2,2,2,1,2
2,2,2,2,2,2,2,2,2,2,2,2,2,2,2,2
2,2,2,2,2,2,2,2,2,2,2,2,2,2,2,2
2,2,2,2,2,2,2,2,2,2,2,2,2,2,2,2
2,2,2,2,2,2,2,2,2,2,2,2,2,2,2,2
2,2,2,2,2,2,2,2,2,2,2,2,2,2,2,2
1,1,2,2,2,2,2,2,2,2,2,2,2,2,1,1
1,2,2,2,2,2,2,2,2,2,2,2,2,2,2,1
1,2,2,2,2,2,2,2,2,2,2,2,2,2,2,1
1,1,2,2,1,2,1,2,2,1,2,1,2,2,1,1
1,1,1,1,1,1,1,1,1,1,1,1,1,1,1,1
:endlayer
layer: 1
1,1,1,1,1,1,1,1,1,1,1,1,1,1,1,1
1,1,2,2,1,2,1,1,1,1,2,1,2,2,1,1
1,2,2,2,2,2,2,2,2,2,2,2,2,2,2,1
1,2,2,2,2,2,2,2,2,2,2,2,2,2,2,1
1,1,2,2,2,2,2,2,2,2,2,2,2,2,1,1
2,1,2,2,2,2,2,2,2,2,2,2,2,2,1,2
2,2,2,2,2,2,2,2,2,2,2,2,2,2,2,2
2,2,2,2,2,2,2,2,2,2,2,2,2,2,2,2
2,2,2,2,2,2,2,2,2,2,2,2,2,2,2,2
2,2,2,2,2,2,2,2,2,2,2,2,2,2,2,2
2,2,2,2,2,2,2,2,2,2,2,2,2,2,2,2
1,1,2,2,2,2,2,2,2,2,2,2,2,2,1,1
1,2,2,2,2,2,2,2,2,2,2,2,2,2,2,1
1,2,2,2,2,2,2,2,2,2,2,2,2,2,2,1
1,1,2,2,1,2,1,2,2,1,2,1,2,2,1,1
1,1,1,1,1,1,1,1,1,1,1,1,1,1,1,1
:endlayer
layer: 2
1,1,1,1,1,1,1,1,1,1,1,1,1,1,1,1
1,1,2,2,1,2,1,1,1,1,2,1,2,2,1,1
1,2,2,2,2,2,2,2,2,2,2,2,2,2,2,1
1,2,2,2,2,2,2,2,2,2,2,2,2,2,2,1
1,1,2,2,2,2,2,2,2,2,2,2,2,2,1,1
2,1,2,2,2,2,2,2,2,2,2,2,2,2,1,2
2,2,2,2,2,2,2,2,2,2,2,2,2,2,2,2
2,2,2,2,2,2,2,2,2,2,2,2,2,2,2,2
2,2,2,2,2,2,2,2,2,2,2,2,2,2,2,2
2,2,2,2,2,2,2,2,2,2,2,2,2,2,2,2
2,2,2,2,2,2,2,2,2,2,2,2,2,2,2,2
1,1,2,2,2,2,2,2,2,2,2,2,2,2,1,1
1,2,2,2,2,2,2,2,2,2,2,2,2,2,2,1
1,2,2,2,2,2,2,2,2,2,2,2,2,2,2,1
1,1,2,2,1,2,1,2,2,1,2,1,2,2,1,1
1,1,1,1,1,1,1,1,1,1,1,1,1,1,1,1
:endlayer
layer: 3
3,3,3,3,3,3,3,3,3,3,3,3,3,3,3,3
3,3,2,2,3,2,3,3,3,3,2,3,2,2,3,3
3,2,2,2,2,2,2,2,2,2,2,2,2,2,2,3
3,2,2,2,2,2,2,2,2,2,2,2,2,2,2,3
3,3,2,2,2,2,2,2,2,2,2,2,2,2,3,3
2,3,2,2,2,2,2,2,2,2,2,2,2,2,3,2
2,2,2,2,2,2,2,2,2,2,2,2,2,2,2,2
2,2,2,2,2,2,2,2,2,2,2,2,2,2,2,2
2,2,2,2,2,2,2,2,2,2,2,2,2,2,2,2
2,2,2,2,2,2,2,2,2,2,2,2,2,2,2,2
2,2,2,2,2,2,2,2,2,2,2,2,2,2,2,2
3,3,2,2,2,2,2,2,2,2,2,2,2,2,3,3
3,2,2,2,2,2,2,2,2,2,2,2,2,2,2,3
3,2,2,2,2,2,2,2,2,2,2,2,2,2,2,3
3,3,2,2,3,2,3,2,2,3,2,3,2,2,3,3
3,3,3,3,3,3,3,3,3,3,3,3,3,3,3,3
:endlayer
layer: 4
0,0,0,0,0,0,0,0,0,0,0,0,0,0,0,0
0,0,2,2,0,2,0,0,0,0,2,0,2,2,0,0
0,2,2,2,2,2,2,0,0,2,2,2,2,2,2,0
0,2,2,2,2,2,2,0,0,2,2,2,2,2,2,0
0,0,2,2,2,2,2,0,0,2,2,2,2,2,0,0
2,0,2,2,2,2,2,4,2,2,2,2,2,2,0,2
2,2,2,2,2,2,2,2,2,2,2,2,2,2,2,2
2,2,2,2,2,2,2,2,2,2,2,2,2,2,2,2
2,2,2,2,2,2,2,2,2,2,2,2,2,2,2,2
2,2,2,2,2,2,2,2,2,2,2,2,2,2,2,2
2,2,2,2,2,2,2,2,2,2,2,2,2,2,2,2
0,0,2,2,2,2,2,2,2,2,2,2,2,2,0,0
0,2,2,2,2,2,2,2,2,2,2,2,2,2,2,0
0,2,2,2,2,2,2,2,2,2,2,2,2,2,2,0
0,0,2,2,0,2,0,2,2,0,2,0,2,2,0,0
0,0,0,0,0,0,0,0,0,0,0,0,0,0,0,0
:endlayer
layer: 5
0,0,0,0,0,0,0,0,0,0,0,0,0,0,0,0
0,0,2,2,0,2,0,0,0,0,2,0,2,2,0,0
0,2,2,2,2,2,2,0,0,2,2,2,2,2,2,0
0,2,2,2,2,2,2,0,0,2,2,2,2,2,2,0
0,0,2,2,2,2,2,5,0,2,2,2,2,2,0,0
2,0,2,2,2,2,2,0,0,4,2,2,2,2,0,2
2,2,2,2,2,2,2,2,2,2,2,2,2,2,2,2
2,2,2,2,2,2,2,2,2,2,2,2,2,2,2,2
2,2,2,2,2,2,2,2,2,2,2,2,2,2,2,2
2,2,2,2,2,2,2,2,2,2,2,2,2,2,2,2
2,2,2,2,2,2,2,2,2,2,2,2,2,2,2,2
0,0,2,2,2,2,2,2,2,2,2,2,2,2,0,0
0,2,2,2,2,2,2,2,2,2,2,2,2,2,2,0
0,2,2,2,2,2,2,2,2,2,2,2,2,2,2,0
0,0,2,2,0,2,0,2,2,0,2,0,2,2,0,0
0,0,0,0,0,0,0,0,0,0,0,0,0,0,0,0
:endlayer
layer: 6
0,0,0,0,0,6,0,0,0,0,6,0,0,0,0,0
0,0,2,2,0,2,7,0,0,9,2,0,2,2,0,0
0,2,2,2,2,2,2,7,9,2,2,2,2,2,2,0
0,2,2,2,2,2,2,0,8,4,2,2,2,2,2,0
6,0,2,2,2,2,2,0,0,0,2,2,2,2,0,6
2,0,2,2,2,2,2,0,0,0,2,2,2,2,0,2
2,2,2,2,2,2,2,2,2,2,2,2,2,2,2,2
2,2,2,2,2,2,2,2,2,2,2,2,2,2,2,2
2,2,2,2,2,2,2,2,2,2,2,2,2,2,2,2
2,2,2,2,2,2,2,2,2,2,2,2,2,2,2,2
2,2,2,2,2,2,2,2,2,2,2,2,2,2,2,2
0,0,2,2,2,2,2,2,2,2,2,2,2,2,0,0
0,2,2,2,2,2,2,2,2,2,2,2,2,2,2,0
0,2,2,2,2,2,2,2,2,2,2,2,2,2,2,0
0,0,2,2,0,2,0,2,2,0,2,0,2,2,0,0
0,0,0,0,0,0,0,0,0,0,0,0,0,0,0,0
:endlayer
layer: 7
0,0,0,0,0,0,0,0,0,0,0,0,0,0,0,0
0,0,2,2,0,2,2,2,2,2,2,0,2,2,0,0
0,2,2,2,2,2,2,2,2,2,2,2,2,2,2,0
0,2,2,2,2,2,2,4,0,0,2,2,2,2,2,0
0,0,2,2,2,2,2,0,0,10,2,2,2,2,0,0
2,0,2,2,2,2,2,0,0,0,2,2,2,2,0,2
2,2,2,2,2,2,2,2,2,2,2,2,2,2,2,2
2,2,2,2,2,2,2,2,2,2,2,2,2,2,2,2
2,2,2,2,2,2,2,2,2,2,2,2,2,2,2,2
2,2,2,2,2,2,2,2,2,2,2,2,2,2,2,2
2,2,2,2,2,2,2,2,2,2,2,2,2,2,2,2
0,0,2,2,2,2,2,2,2,2,2,2,2,2,0,0
0,2,2,2,2,2,2,2,2,2,2,2,2,2,2,0
0,2,2,2,2,2,2,2,2,2,2,2,2,2,2,0
0,0,2,2,0,2,0,2,2,0,2,0,2,2,0,0
0,0,0,0,0,0,0,0,0,0,0,0,0,0,0,0
:endlayer
layer: 8
0,0,0,0,0,0,0,0,0,0,0,0,0,0,0,0
0,0,2,2,0,2,12,2,2,13,2,0,2,2,0,0
0,2,2,2,2,2,2,2,2,2,2,2,2,2,2,0
0,2,2,2,2,2,0,0,0,0,2,2,2,2,2,0
0,0,2,2,2,2,4,0,0,0,2,2,2,2,0,0
2,0,2,2,2,2,2,2,8,0,2,2,2,2,0,2
2,2,2,2,2,2,2,2,2,2,2,2,2,2,2,2
2,2,2,2,2,2,2,2,2,2,2,2,2,2,2,2
2,2,2,2,2,2,2,2,2,2,2,2,2,2,2,2
2,2,2,2,2,2,2,2,2,2,2,2,2,2,2,2
2,11,2,2,2,2,2,2,2,2,2,2,2,2,11,2
0,0,2,2,2,2,2,2,2,2,2,2,2,2,0,0
0,2,2,2,2,2,2,2,2,2,2,2,2,2,2,0
0,2,2,2,2,2,2,2,2,2,2,2,2,2,2,0
0,0,2,2,0,11,0,2,2,0,11,0,2,2,0,0
0,0,0,0,0,0,0,0,0,0,0,0,0,0,0,0
:endlayer
layer: 9
0,0,0,0,0,0,0,0,0,0,0,0,0,0,0,0
0,0,2,2,0,14,0,2,2,0,14,0,2,2,0,0
0,2,2,2,2,2,2,2,2,2,2,2,2,2,2,0
0,2,2,2,2,2,0,0,0,0,2,2,2,2,2,0
0,0,2,2,2,2,0,0,0,8,2,2,2,2,0,0
2,0,2,2,2,2,0,4,2,2,2,2,2,2,0,2
2,2,2,2,2,2,2,2,2,2,2,2,2,2,2,2
2,2,2,2,2,2,2,2,2,2,2,2,2,2,2,2
2,2,2,2,2,2,2,2,2,2,2,2,2,2,2,2
2,2,2,2,2,2,2,2,2,2,2,2,2,2,2,2
11,0,2,2,2,2,2,2,2,2,2,2,2,2,0,11
0,0,2,2,2,2,2,2,2,2,2,2,2,2,0,0
0,2,2,2,2,2,2,2,2,2,2,2,2,2,2,0
0,2,2,2,2,2,2,2,2,2,2,2,2,2,2,0
0,0,2,2,0,0,0,2,2,0,0,0,2,2,0,0
0,0,0,0,0,0,0,0,0,0,0,0,0,0,0,0
:endlayer
layer: 10
0,0,0,0,0,0,0,0,0,0,0,0,0,0,0,0
0,0,2,2,0,0,0,2,2,0,0,0,2,2,0,0
0,2,2,2,14,2,14,2,2,14,2,14,2,2,2,0
0,2,2,2,0,2,0,0,8,2,2,0,2,2,2,0
0,0,2,2,0,2,5,0,0,2,2,0,2,2,0,0
2,15,2,2,0,2,0,0,0,4,2,0,2,2,15,2
0,0,0,0,0,0,2,0,0,2,0,0,0,0,0,0
0,0,0,0,0,0,0,0,0,0,0,0,0,0,0,0
2,4,2,2,0,0,0,0,0,0,0,0,2,2,4,2
2,2,2,2,2,0,0,2,2,0,0,2,2,2,2,2
0,0,2,2,0,0,0,0,0,0,0,0,2,2,0,0
0,0,12,4,0,0,0,0,0,0,0,0,4,13,0,0
0,2,2,2,4,2,4,2,2,4,2,4,2,2,2,0
0,2,2,2,11,2,11,2,2,11,2,11,2,2,2,0
0,0,2,2,0,0,0,2,2,0,0,0,2,2,0,0
0,0,0,0,0,0,0,0,0,0,0,0,0,0,0,0
:endlayer
layer: 11
0,0,0,0,0,0,0,0,0,0,0,0,0,0,0,0
0,0,2,2,0,0,0,2,2,0,0,0,2,2,0,0
0,2,2,2,0,2,0,2,2,0,2,0,2,2,2,0
0,2,2,2,0,2,8,2,2,4,2,0,2,2,2,0
0,0,2,2,0,2,0,0,0,0,2,0,2,2,0,0
2,2,2,2,0,2,0,0,0,0,2,0,2,2,2,2
0,0,0,0,0,0,2,0,0,2,0,0,0,0,0,0
0,0,0,0,0,0,0,0,0,0,0,0,0,0,0,0
2,0,2,2,0,0,0,0,0,0,0,0,2,2,0,2
2,2,2,2,2,0,0,2,2,0,0,2,2,2,2,2
0,0,2,2,0,0,0,0,0,0,0,0,2,2,0,0
0,0,0,0,0,0,0,0,0,0,0,0,0,0,0,0
0,2,2,2,0,2,0,2,2,0,2,0,2,2,2,0
0,2,2,2,0,2,0,2,2,0,2,0,2,2,2,0
0,0,2,2,0,0,0,2,2,0,0,0,2,2,0,0
0,0,0,0,0,0,0,0,0,0,0,0,0,0,0,0
:endlayer
layer: 12
0,0,0,0,0,0,0,0,0,0,0,0,0,0,0,0
0,0,2,2,0,0,0,2,2,0,0,0,2,2,0,0
0,2,2,2,8,2,8,2,2,8,2,8,2,2,2,0
0,2,2,2,0,2,2,4,0,0,2,0,2,2,2,0
0,0,2,2,0,2,2,0,0,10,2,0,2,2,0,0
2,2,2,2,8,2,8,0,0,0,2,2,2,2,2,2
16,0,0,0,0,16,2,8,8,2,16,0,0,0,0,16
0,0,0,0,0,0,0,0,0,0,0,0,0,0,0,0
2,0,2,2,0,0,0,0,0,0,0,0,2,2,0,2
2,2,2,2,2,0,0,2,2,0,0,2,2,2,2,2
0,0,2,2,0,0,0,0,0,0,0,0,2,2,0,0
0,0,8,0,0,6,0,0,0,0,6,0,0,8,0,0
0,2,2,2,0,2,0,2,2,0,2,0,2,2,2,0
0,2,2,2,8,2,8,2,2,8,2,8,2,2,2,0
0,0,2,2,0,0,0,2,2,0,0,0,2,2,0,0
0,0,0,0,0,0,0,0,0,0,0,0,0,0,0,0
:endlayer
layer: 13
0,0,0,0,0,0,0,0,0,0,0,0,0,0,0,0
0,0,14,14,0,0,0,14,14,0,0,0,14,14,0,0
0,12,2,2,2,2,2,2,2,2,2,2,2,2,13,0
0,12,2,2,2,2,0,0,0,0,2,2,2,2,13,0
15,15,2,2,2,2,4,0,0,0,2,2,2,2,15,15
2,2,2,2,2,2,2,2,8,0,2,2,2,2,2,2
17,17,17,17,17,9,2,2,2,2,7,17,17,17,17,17
15,15,15,15,7,9,17,17,17,17,17,9,15,15,15,15
2,2,2,2,15,7,15,15,15,15,9,15,2,2,2,2
2,2,2,2,2,7,9,2,2,7,9,2,2,2,2,2
8,8,2,2,7,17,9,17,17,7,17,9,2,2,8,8
0,0,2,2,7,15,15,15,15,15,15,9,2,2,0,0
0,12,2,2,2,2,2,2,2,2,2,2,2,2,13,0
0,12,2,2,2,2,2,2,2,2,2,2,2,2,13,0
0,0,11,11,0,0,0,11,11,0,0,0,11,11,0,0
0,0,0,0,0,0,0,0,0,0,0,0,0,0,0,0
:endlayer
layer: 14
0,0,0,0,0,0,0,0,0,0,0,0,0,0,0,0
0,0,0,0,0,0,0,0,0,0,0,0,0,0,0,0
0,0,18,18,18,18,18,18,18,18,18,18,18,18,0,0
0,0,18,18,18,18,0,0,0,0,18,18,18,18,0,0
18,18,18,18,18,18,0,0,0,8,18,18,18,18,18,18
18,18,18,18,18,18,0,4,2,2,18,18,18,18,18,18
18,18,18,18,18,18,18,18,18,18,18,18,18,18,18,18
18,18,18,18,18,18,18,18,18,18,18,18,18,18,18,18
18,18,18,18,18,18,18,18,18,18,18,18,18,18,18,18
18,18,18,18,18,18,18,18,18,18,18,18,18,18,18,18
18,18,18,18,18,18,18,18,18,18,18,18,18,18,18,18
0,0,18,18,18,18,18,18,18,18,18,18,18,18,0,0
0,0,18,18,18,18,18,18,18,18,18,18,18,18,0,0
0,0,18,18,18,18,18,18,18,18,18,18,18,18,0,0
0,0,0,0,0,0,0,0,0,0,0,0,0,0,0,0
0,0,0,0,0,0,0,0,0,0,0,0,0,0,0,0
:endlayer
layer: 15
0,0,0,0,0,0,0,0,0,0,0,0,0,0,0,0
0,0,0,0,0,0,0,0,0,0,0,0,0,0,0,0
0,0,2,2,14,2,14,2,2,14,2,14,2,2,0,0
0,0,2,2,4,2,0,0,8,2,2,4,2,2,0,0
14,4,2,0,0,2,5,0,0,2,2,0,0,2,4,14
0,0,0,0,0,2,0,0,0,4,2,0,0,0,0,0
0,0,0,0,0,0,2,0,0,2,0,0,0,0,0,0
6,0,0,0,0,0,0,0,0,0,0,0,0,0,0,6
2,0,2,0,0,0,0,0,0,0,0,0,0,2,0,2
2,2,2,2,0,0,0,0,0,0,0,0,2,2,2,2
4,4,2,2,0,0,0,0,0,0,0,0,2,2,4,4
0,0,12,4,0,0,0,0,0,0,0,0,4,13,0,0
0,0,2,2,4,2,4,2,2,4,2,4,2,2,0,0
0,0,2,2,11,2,11,2,2,11,2,11,2,2,0,0
0,0,0,0,0,0,0,0,0,0,0,0,0,0,0,0
0,0,0,0,0,0,0,0,0,0,0,0,0,0,0,0
:endlayer
layer: 16
0,0,0,0,0,0,0,0,0,0,0,0,0,0,0,0
0,0,0,0,0,0,0,0,0,0,0,0,0,0,0,0
0,0,2,2,0,2,0,2,2,0,2,0,2,2,0,0
0,0,2,2,0,2,8,2,2,4,2,0,2,2,0,0
0,0,2,0,0,2,0,0,0,0,2,0,0,2,0,0
0,0,0,0,0,2,0,0,0,0,2,0,0,0,0,0
0,0,0,0,0,0,2,0,0,2,0,0,0,0,0,0
0,0,0,0,0,0,0,0,0,0,0,0,0,0,0,0
14,0,2,0,0,0,0,0,0,0,0,0,0,2,0,14
2,0,2,2,0,0,0,0,0,0,0,0,2,2,0,2
0,0,2,2,0,0,0,0,0,0,0,0,2,2,0,0
0,0,0,0,0,0,0,0,0,0,0,0,0,0,0,0
0,0,2,2,0,2,0,2,2,0,2,0,2,2,0,0
0,0,2,2,0,2,0,2,2,0,2,0,2,2,0,0
0,0,0,0,0,0,0,0,0,0,0,0,0,0,0,0
0,0,0,0,0,0,0,0,0,0,0,0,0,0,0,0
:endlayer
layer: 17
0,0,0,0,0,0,0,0,0,0,0,0,0,0,0,0
0,0,0,0,0,0,0,0,0,0,0,0,0,0,0,0
0,0,2,2,8,2,8,2,2,8,2,8,2,2,0,0
0,0,2,2,0,2,2,4,0,0,2,0,2,2,0,0
0,0,2,0,0,2,2,0,0,10,2,0,0,2,0,0
0,0,17,0,0,2,8,0,0,0,2,0,0,17,0,0
0,0,8,0,0,16,2,7,9,2,16,0,0,8,0,0
0,0,15,0,0,0,0,0,0,0,0,0,0,15,0,0
0,0,2,0,0,0,0,0,0,0,0,0,0,2,0,0
0,0,2,2,0,0,0,0,0,0,0,0,2,2,0,0
0,0,2,2,5,0,0,0,0,0,0,10,2,2,0,0
0,0,0,0,0,6,0,0,0,0,6,0,0,0,0,0
0,0,2,2,0,2,0,2,2,0,2,0,2,2,0,0
0,0,2,2,0,2,0,2,2,0,2,0,2,2,0,0
0,0,0,0,0,0,0,0,0,0,0,0,0,0,0,0
0,0,0,0,0,0,0,0,0,0,0,0,0,0,0,0
:endlayer
layer: 18
0,0,0,0,0,0,0,0,0,0,0,0,0,0,0,0
0,0,8,8,8,8,8,8,8,8,8,8,8,8,0,0
0,8,2,2,2,2,2,2,2,2,2,2,2,2,8,0
0,8,2,2,17,2,0,0,0,0,2,17,2,2,8,0
0,8,2,17,0,2,4,0,0,0,2,0,17,2,8,0
0,8,2,0,0,2,2,2,8,0,2,0,0,2,8,0
0,8,2,0,0,0,2,2,2,2,0,0,0,2,8,0
0,8,2,0,0,0,0,0,0,0,0,0,0,2,8,0
0,8,2,15,0,0,0,0,0,0,0,0,15,2,8,0
0,8,2,2,0,0,0,0,0,0,0,0,2,2,8,0
0,8,2,2,0,0,0,0,0,0,0,0,2,2,8,0
0,8,2,7,0,0,0,0,0,0,0,0,9,2,8,0
0,8,2,2,15,2,15,2,2,15,2,15,2,2,8,0
0,8,2,2,2,2,2,2,2,2,2,2,2,2,8,0
0,0,8,8,8,8,8,8,8,8,8,8,8,8,0,0
0,0,0,0,0,0,0,0,0,0,0,0,0,0,0,0
:endlayer
layer: 19
0,0,0,0,0,0,0,0,0,0,0,0,0,0,0,0
0,0,18,18,18,18,18,18,18,18,18,18,18,18,0,0
0,18,18,18,18,18,18,18,18,18,18,18,18,18,18,0
0,18,18,18,18,18,0,0,0,0,18,18,18,18,18,0
0,18,18,18,18,18,0,0,0,0,18,18,18,18,18,0
0,18,18,18,18,18,0,4,2,2,18,18,18,18,18,0
0,18,18,18,18,18,18,18,18,18,18,18,18,18,18,0
0,18,18,18,18,18,18,18,18,18,18,18,18,18,18,0
0,18,18,18,18,18,18,18,18,18,18,18,18,18,18,0
0,18,18,18,18,18,18,18,18,18,18,18,18,18,18,0
0,18,18,18,18,18,18,18,18,18,18,18,18,18,18,0
0,18,18,18,18,18,18,18,18,18,18,18,18,18,18,0
0,18,18,18,18,18,18,18,18,18,18,18,18,18,18,0
0,18,18,18,18,18,18,18,18,18,18,18,18,18,18,0
0,0,18,18,18,18,18,18,18,18,18,18,18,18,0,0
0,0,0,0,0,0,0,0,0,0,0,0,0,0,0,0
:endlayer
layer: 20
0,0,0,0,0,0,0,0,0,0,0,0,0,0,0,0
0,0,4,4,4,4,4,4,4,4,4,4,4,4,0,0
0,4,2,2,2,2,2,2,2,2,2,2,2,2,4,0
0,4,2,2,4,2,0,0,0,0,2,4,2,2,4,0
0,4,2,4,0,4,0,0,0,0,4,0,4,2,4,0
0,4,2,2,5,4,0,0,0,0,4,10,2,2,4,0
0,4,2,4,0,0,0,0,0,0,0,0,4,2,4,0
0,4,2,2,0,0,0,0,0,0,0,0,2,2,4,0
0,4,2,2,0,0,0,0,0,0,0,0,2,2,4,0
0,4,2,4,0,4,4,4,4,4,4,0,4,2,4,0
0,4,2,2,5,4,2,2,2,2,4,10,2,2,4,0
0,4,2,4,0,4,2,2,2,2,4,0,4,2,4,0
0,4,2,2,4,2,2,2,2,2,2,4,2,2,4,0
0,4,2,2,2,2,2,2,2,2,2,2,2,2,4,0
0,0,4,4,4,4,4,4,4,4,4,4,4,4,0,0
0,0,0,0,0,0,0,0,0,0,0,0,0,0,0,0
:endlayer
layer: 21
0,0,0,0,0,0,0,0,0,0,0,0,0,0,0,0
0,0,0,0,0,0,0,0,0,0,0,0,0,0,0,0
0,0,2,2,0,2,0,2,2,0,2,0,2,2,0,0
0,0,2,2,0,11,0,0,0,0,11,0,2,2,0,0
0,0,0,0,0,0,0,0,0,0,0,0,0,0,0,0
0,0,2,13,0,0,0,0,0,0,0,0,12,2,0,0
0,0,0,0,0,0,0,0,0,0,0,0,0,0,0,0
0,0,2,13,0,0,0,0,0,0,0,0,12,2,0,0
0,0,2,13,0,0,0,0,0,0,0,0,12,2,0,0
0,0,0,0,0,0,0,0,0,0,0,0,0,0,0,0
0,0,2,13,0,0,0,0,0,0,0,0,12,2,0,0
0,0,0,0,0,0,0,0,0,0,0,0,0,0,0,0
0,0,2,2,0,14,0,0,0,0,14,0,2,2,0,0
0,0,2,2,0,2,13,0,0,12,2,0,2,2,0,0
0,0,0,0,0,0,0,0,0,0,0,0,0,0,0,0
0,0,0,0,0,0,0,0,0,0,0,0,0,0,0,0
:endlayer
layer: 22
0,0,0,0,0,0,0,0,0,0,0,0,0,0,0,0
0,0,0,0,0,0,0,0,0,0,0,0,0,0,0,0
0,0,0,0,0,0,0,0,0,0,0,0,0,0,0,0
0,0,0,19,0,0,0,0,0,0,0,0,19,0,0,0
0,0,0,0,0,0,0,0,0,0,0,0,0,0,0,0
0,0,0,0,0,0,0,0,0,0,0,0,0,0,0,0
0,0,0,0,0,0,0,0,0,0,0,0,0,0,0,0
0,0,0,0,0,0,0,0,0,0,0,0,0,0,0,0
0,0,0,0,0,0,0,0,0,0,0,0,0,0,0,0
0,0,0,0,0,0,0,0,0,0,0,0,0,0,0,0
0,0,0,0,0,0,0,0,0,0,0,0,0,0,0,0
0,0,0,0,0,0,0,0,0,0,0,0,0,0,0,0
0,0,0,19,0,0,0,0,0,0,0,0,19,0,0,0
0,0,0,0,0,0,0,0,0,0,0,0,0,0,0,0
0,0,0,0,0,0,0,0,0,0,0,0,0,0,0,0
0,0,0,0,0,0,0,0,0,0,0,0,0,0,0,0
:endlayer

#### RULES ####
rule:
plugin=vanillaBlocks
number=1
data:
JSON:{blockState:{blockName:"minecraft:dirt",properties:{variant:"dirt",snowy:"false"}}}
:enddata
:endrule

rule:
plugin=vanillaBlocks
number=2
data:
JSON:{blockState:{blockName:"quark:world_stone_bricks",properties:{variant:"stone_granite_bricks"}}}
:enddata
:endrule

rule:
plugin=vanillaBlocks
number=3
data:
JSON:{blockState:{blockName:"minecraft:grass",properties:{snowy:"false"}}}
:enddata
:endrule

rule:
plugin=vanillaBlocks
number=4
data:
JSON:{blockState:{blockName:"quark:stone_granite_bricks_slab",properties:{half:"bottom",prop:"blarg"}}}
:enddata
:endrule

rule:
plugin=vanillaBlocks
number=5
data:
JSON:{blockState:{blockName:"minecraft:torch",properties:{facing:"east"}}}
:enddata
:endrule

rule:
plugin=vanillaBlocks
number=6
data:
JSON:{blockState:{blockName:"minecraft:torch",properties:{facing:"north"}}}
:enddata
:endrule

rule:
plugin=vanillaBlocks
number=7
data:
JSON:{blockState:{blockName:"quark:stone_granite_bricks_stairs",properties:{half:"top",shape:"straight",facing:"west"}}}
:enddata
:endrule

rule:
plugin=vanillaBlocks
number=8
data:
JSON:{blockState:{blockName:"quark:stone_granite_bricks_slab",properties:{half:"top",prop:"blarg"}}}
:enddata
:endrule

rule:
plugin=vanillaBlocks
number=9
data:
JSON:{blockState:{blockName:"quark:stone_granite_bricks_stairs",properties:{half:"top",shape:"straight",facing:"east"}}}
:enddata
:endrule

rule:
plugin=vanillaBlocks
number=10
data:
JSON:{blockState:{blockName:"minecraft:torch",properties:{facing:"west"}}}
:enddata
:endrule

rule:
plugin=vanillaBlocks
number=11
data:
JSON:{blockState:{blockName:"quark:stone_granite_bricks_stairs",properties:{half:"bottom",shape:"straight",facing:"north"}}}
:enddata
:endrule

rule:
plugin=vanillaBlocks
number=12
data:
JSON:{blockState:{blockName:"quark:stone_granite_bricks_stairs",properties:{half:"bottom",shape:"straight",facing:"east"}}}
:enddata
:endrule

rule:
plugin=vanillaBlocks
number=13
data:
JSON:{blockState:{blockName:"quark:stone_granite_bricks_stairs",properties:{half:"bottom",shape:"straight",facing:"west"}}}
:enddata
:endrule

rule:
plugin=vanillaBlocks
number=14
data:
JSON:{blockState:{blockName:"quark:stone_granite_bricks_stairs",properties:{half:"bottom",shape:"straight",facing:"south"}}}
:enddata
:endrule

rule:
plugin=vanillaBlocks
number=15
data:
JSON:{blockState:{blockName:"quark:stone_granite_bricks_stairs",properties:{half:"top",shape:"straight",facing:"south"}}}
:enddata
:endrule

rule:
plugin=vanillaBlocks
number=16
data:
JSON:{blockState:{blockName:"minecraft:torch",properties:{facing:"south"}}}
:enddata
:endrule

rule:
plugin=vanillaBlocks
number=17
data:
JSON:{blockState:{blockName:"quark:stone_granite_bricks_stairs",properties:{half:"top",shape:"straight",facing:"north"}}}
:enddata
:endrule

rule:
plugin=vanillaBlocks
number=18
data:
JSON:{blockState:{blockName:"minecraft:stained_hardened_clay",properties:{color:"red"}}}
:enddata
:endrule

rule:
plugin=vanillaBlocks
number=19
data:
JSON:{blockState:{blockName:"minecraft:torch",properties:{facing:"up"}}}
:enddata
:endrule

#### ENTITIES ####
