# Ancient Warfare Structure Template File
# Auto-generated structure template file. created on: 3/19/2021 at: 13:7:18
# Lines beginning with # denote comments

header:
version=2.11
name=SurvivalBuild_FortWall_large_type1_OutterCornerBastion_ENVIRONSfrozen
mods=environs
size=16,19,16
offset=15,4,15
:endheader

#### VALIDATION ####
validation:
type=ground
structureAuthor=TheOddlySeagull
survival=true
worldGenEnabled=false
unique=false
preserveBlocks=false
preventNaturalHostileSpawns=false
selectionWeight=1
clusterValue=1
minDuplicateDistance=1
dimensionWhiteList=true
dimensionList=
biomeGroupList=
biomeWhiteList=true
biomeList=
leveling=0
fill=0
border=0
blockSwap=false
territoryName=
biomeReplacement=minecraft:
minGenerationHeight=0
maxGenerationHeight=255
:endvalidation

#### LAYERS ####
layer: 0
1,1,1,1,1,2,2,2,2,2,2,2,2,2,2,1
1,1,1,1,1,2,2,2,2,2,2,2,2,2,2,1
1,1,1,1,1,2,2,2,2,2,2,2,2,2,2,1
1,1,1,1,1,2,2,2,2,2,2,2,2,2,2,1
1,1,1,1,1,2,2,2,2,2,2,2,2,2,2,1
2,2,2,2,2,2,2,2,2,2,2,2,2,2,2,1
2,2,2,2,2,2,2,2,2,2,2,2,2,2,2,1
2,2,2,2,2,2,2,2,2,2,2,2,2,2,2,1
2,2,2,2,2,2,2,2,2,2,2,2,2,2,2,1
2,2,2,2,2,2,2,2,2,2,2,2,2,2,2,1
2,2,2,2,2,2,2,2,2,2,2,2,2,2,2,1
2,2,2,2,2,2,2,2,2,2,2,2,2,2,2,1
2,2,2,2,2,2,2,2,2,2,2,2,2,2,2,1
2,2,2,2,2,2,2,2,2,2,2,2,2,2,2,1
2,2,2,2,2,2,2,2,2,2,2,2,2,2,2,1
1,1,1,1,1,1,1,1,1,1,1,1,1,1,1,1
:endlayer
layer: 1
1,1,1,1,1,2,2,2,2,2,0,0,0,0,2,1
1,1,1,1,1,2,2,2,2,2,0,0,0,0,2,1
1,1,1,1,1,2,2,2,2,2,0,0,0,0,2,1
1,1,1,1,1,2,2,2,2,2,0,0,0,0,2,1
1,1,1,1,1,2,2,2,2,2,0,0,0,0,2,1
2,2,2,2,2,2,2,2,2,2,2,0,0,0,2,1
2,2,2,2,2,2,2,2,2,2,2,2,0,0,2,1
2,2,2,2,2,2,2,2,2,2,2,2,0,0,2,1
2,2,2,2,2,2,2,2,2,2,2,2,0,0,2,1
2,2,2,2,2,2,2,2,2,2,2,2,0,0,2,1
0,0,0,0,0,2,2,2,2,2,2,0,0,0,2,1
0,0,0,0,0,0,2,2,2,2,0,0,0,0,2,1
0,0,0,0,0,0,0,0,0,0,0,0,0,0,2,1
0,0,0,0,0,0,0,0,0,0,0,0,0,0,2,1
2,2,2,2,2,2,2,2,2,2,2,2,2,2,2,1
1,1,1,1,1,1,1,1,1,1,1,1,1,1,1,1
:endlayer
layer: 2
1,1,1,1,1,2,2,2,2,2,0,0,0,0,2,1
1,1,1,1,1,2,2,2,2,2,0,0,0,0,2,1
1,1,1,1,1,2,2,2,2,2,0,0,0,0,2,1
1,1,1,1,1,2,2,2,2,2,0,0,0,0,2,1
1,1,1,1,1,2,2,2,2,2,0,0,0,0,2,1
2,2,2,2,2,2,2,2,2,2,2,0,0,0,2,1
2,2,2,2,2,2,2,2,2,2,2,2,0,0,2,1
2,2,2,2,2,2,2,2,2,2,2,2,0,0,2,1
2,2,2,2,2,2,2,2,2,2,2,2,0,0,2,1
2,2,2,2,2,2,2,2,2,2,2,2,0,0,2,1
0,0,0,0,0,2,2,2,2,2,2,0,0,0,2,1
0,0,0,0,0,0,2,2,2,2,0,0,0,0,2,1
0,0,0,0,0,0,0,0,0,0,0,0,0,0,2,1
0,0,0,0,0,0,0,0,0,0,0,0,0,0,2,1
2,2,2,2,2,2,2,2,2,2,2,2,2,2,2,1
1,1,1,1,1,1,1,1,1,1,1,1,1,1,1,1
:endlayer
layer: 3
3,3,3,3,3,2,2,2,2,2,0,0,0,0,2,3
3,3,3,1,1,2,2,2,2,2,0,0,0,0,2,3
3,3,2,2,2,2,2,2,2,2,0,0,0,0,2,3
3,1,2,2,2,2,2,2,2,2,0,0,0,0,2,3
3,1,2,2,2,2,2,2,2,2,0,0,0,0,2,3
2,2,2,2,2,2,2,2,2,2,2,0,0,0,2,3
2,2,2,2,2,2,2,2,2,2,2,2,0,0,2,3
2,2,2,2,2,2,2,2,2,2,2,2,0,0,2,3
2,2,2,2,2,2,2,2,2,2,2,2,0,0,2,3
2,2,2,2,2,2,2,2,2,2,2,2,0,0,2,3
0,0,0,0,0,2,2,2,2,2,2,0,0,0,2,3
0,0,0,0,0,0,2,2,2,2,0,0,0,0,2,3
0,0,0,0,0,0,0,0,0,0,0,0,0,0,2,3
0,0,0,0,0,0,0,0,0,0,0,0,0,0,2,3
2,2,2,2,2,2,2,2,2,2,2,2,2,2,2,3
3,3,3,3,3,3,3,3,3,3,3,3,3,3,3,3
:endlayer
layer: 4
0,0,0,0,9,5,2,2,2,5,0,0,0,0,2,0
0,0,0,5,8,8,2,2,2,10,0,0,0,0,4,0
0,0,0,0,0,7,2,2,2,10,0,0,0,0,4,0
0,5,0,0,4,5,2,2,2,5,0,0,0,0,2,0
9,8,0,4,4,4,2,2,2,2,0,0,0,0,2,0
5,8,7,5,4,2,2,2,2,2,2,0,0,0,4,0
2,2,2,2,2,2,2,2,2,2,2,2,0,0,4,0
2,2,2,2,2,2,2,2,2,2,2,2,0,0,2,0
2,2,2,2,2,2,2,2,2,2,2,2,0,0,2,0
5,6,6,5,2,2,2,2,2,2,2,2,0,0,4,0
0,0,0,0,0,2,2,2,2,2,2,0,0,0,4,0
0,0,0,0,0,0,2,2,2,2,0,0,0,0,2,0
0,0,0,0,0,0,0,0,0,0,0,0,0,0,2,0
0,0,0,0,0,0,0,0,0,0,0,0,0,0,4,0
2,4,4,2,2,4,4,2,2,4,4,2,2,4,4,0
0,0,0,0,0,0,0,0,0,0,0,0,0,0,0,0
:endlayer
layer: 5
0,0,0,0,9,5,2,2,2,5,0,0,0,0,4,0
0,0,0,5,8,8,2,2,2,12,0,0,0,0,0,0
0,0,0,0,0,0,2,2,2,12,0,0,0,0,0,0
0,5,0,0,0,5,2,2,2,5,0,0,0,0,4,0
9,8,0,0,0,0,2,2,2,2,0,0,0,0,4,0
5,8,0,5,0,0,0,4,2,2,2,0,0,0,0,0
2,2,2,2,2,0,0,4,2,2,2,2,0,0,0,0
2,2,2,2,2,2,2,5,2,2,2,2,0,0,4,0
2,2,2,2,2,2,2,2,2,2,2,2,0,0,4,0
5,11,11,5,2,2,2,2,2,2,2,2,0,0,0,0
0,0,0,0,0,2,2,2,2,2,2,0,0,0,0,0
0,0,0,0,0,0,2,2,2,2,0,0,0,0,4,0
0,0,0,0,0,0,0,0,0,0,0,0,0,0,4,0
0,0,0,0,0,0,0,0,0,0,0,0,0,0,0,0
4,0,0,4,4,0,0,4,4,0,0,4,4,0,0,0
0,0,0,0,0,0,0,0,0,0,0,0,0,0,0,0
:endlayer
layer: 6
0,0,0,14,9,5,2,2,2,5,0,0,0,0,0,0
0,0,0,5,8,8,2,2,2,0,0,0,0,0,0,0
0,0,0,0,0,0,2,2,2,0,0,0,0,0,0,0
15,5,0,0,15,5,2,2,2,5,0,0,0,0,0,0
9,8,0,14,0,0,2,2,2,2,0,0,0,0,0,0
5,8,0,5,0,0,0,13,0,2,2,0,0,0,0,0
2,2,2,2,2,0,0,0,0,0,2,2,0,0,0,0
2,2,2,2,2,2,2,5,4,4,2,2,0,0,0,0
2,2,2,2,2,2,2,2,2,2,2,2,0,0,0,0
5,0,0,5,2,2,2,2,2,2,2,2,0,0,0,0
0,0,0,0,0,2,2,2,2,2,2,0,0,0,0,0
0,0,0,0,0,0,2,2,2,2,0,0,0,0,0,0
0,0,0,0,0,0,0,0,0,0,0,0,0,0,0,0
0,0,0,0,0,0,0,0,0,0,0,0,0,0,0,0
0,0,0,0,0,0,0,0,0,0,0,0,0,0,0,0
0,0,0,0,0,0,0,0,0,0,0,0,0,0,0,0
:endlayer
layer: 7
0,0,17,17,19,5,2,2,2,5,0,0,0,0,0,0
0,17,17,5,5,5,2,2,2,0,0,0,0,0,0,0
17,17,5,17,17,17,2,2,2,0,0,0,0,0,0,0
17,5,17,0,0,5,2,2,2,5,0,0,0,0,0,0
18,5,17,0,0,2,2,2,2,2,0,0,0,0,0,0
5,5,17,5,2,16,16,0,0,2,2,0,0,0,0,0
2,2,2,2,2,16,16,0,0,0,2,2,0,0,0,0
2,2,2,2,2,2,2,5,0,15,2,2,0,0,0,0
2,2,2,2,2,2,2,4,0,0,2,2,0,0,0,0
5,0,0,5,2,2,2,4,0,2,2,2,0,0,0,0
0,0,0,0,0,2,2,2,2,2,2,0,0,0,0,0
0,0,0,0,0,0,2,2,2,2,0,0,0,0,0,0
0,0,0,0,0,0,0,0,0,0,0,0,0,0,0,0
0,0,0,0,0,0,0,0,0,0,0,0,0,0,0,0
0,0,0,0,0,0,0,0,0,0,0,0,0,0,0,0
0,0,0,0,0,0,0,0,0,0,0,0,0,0,0,0
:endlayer
layer: 8
0,0,0,0,0,5,2,2,2,5,0,0,0,0,0,0
0,0,0,7,7,7,2,2,2,0,0,0,0,0,0,0
0,0,7,7,8,8,2,2,2,0,0,0,0,0,0,0
0,7,7,8,8,5,2,2,2,5,0,0,0,0,0,0
0,7,8,8,8,2,2,2,2,2,0,0,0,0,0,0
5,7,8,5,2,2,2,2,16,2,2,0,0,0,0,0
2,2,2,2,2,2,2,2,16,16,2,2,0,0,0,0
2,2,2,2,2,4,4,5,0,0,2,2,0,0,0,0
2,2,2,2,2,0,0,0,0,0,2,2,0,0,0,0
5,0,0,5,2,2,0,14,0,2,2,2,0,0,0,0
0,0,0,0,0,2,2,2,2,2,2,0,0,0,0,0
0,0,0,0,0,0,2,2,2,2,0,0,0,0,0,0
0,0,0,0,0,0,0,0,0,0,0,0,0,0,0,0
0,0,0,0,0,0,0,0,0,0,0,0,0,0,0,0
0,0,0,0,0,0,0,0,0,0,0,0,0,0,0,0
0,0,0,0,0,0,0,0,0,0,0,0,0,0,0,0
:endlayer
layer: 9
0,0,0,0,0,5,2,2,2,5,0,0,0,0,0,0
0,0,0,0,0,6,2,2,2,6,0,0,0,0,0,0
0,0,0,0,0,18,2,2,2,18,0,0,0,0,0,0
0,0,0,0,0,5,2,2,2,5,0,0,0,0,0,0
0,0,0,0,8,2,2,2,2,2,0,0,0,0,0,0
5,10,19,5,2,2,0,4,4,2,2,0,0,0,0,0
2,2,2,2,2,0,0,4,4,2,2,2,0,0,0,0
2,2,2,2,2,20,0,5,2,2,2,2,10,0,0,0
2,2,2,2,2,0,0,0,16,2,2,2,10,0,0,0
5,10,19,5,2,2,0,0,16,2,2,2,0,0,0,0
0,0,0,0,0,2,2,2,2,2,2,0,0,0,0,0
0,0,0,0,0,0,2,2,2,2,0,0,0,0,0,0
0,0,0,0,0,0,0,6,6,0,0,0,0,0,0,0
0,0,0,0,0,0,0,0,0,0,0,0,0,0,0,0
0,0,0,0,0,0,0,0,0,0,0,0,0,0,0,0
0,0,0,0,0,0,0,0,0,0,0,0,0,0,0,0
:endlayer
layer: 10
0,0,0,0,19,5,2,2,2,5,10,0,0,0,0,0
0,0,0,0,17,5,2,2,2,5,17,0,0,0,0,0
0,0,0,0,17,5,2,2,2,5,17,0,0,0,0,0
0,0,0,17,19,5,2,4,4,5,10,0,0,0,0,0
18,17,17,18,5,2,2,0,0,2,10,0,0,0,0,0
5,5,5,5,2,2,0,0,0,0,2,9,0,0,0,0
2,2,2,2,2,0,0,14,0,0,4,2,10,0,0,0
2,2,2,2,2,0,15,5,20,0,4,2,8,0,0,0
2,2,2,2,2,0,0,21,22,4,4,2,8,0,0,0
5,5,5,5,2,2,0,21,4,4,4,2,10,0,0,0
6,17,17,6,6,2,2,2,4,4,2,9,0,0,0,0
0,0,0,0,0,9,2,2,2,2,9,0,0,0,0,0
0,0,0,0,0,0,6,8,8,6,0,0,0,0,0,0
0,0,0,0,0,0,0,0,0,0,0,0,0,0,0,0
0,0,0,0,0,0,0,0,0,0,0,0,0,0,0,0
0,0,0,0,0,0,0,0,0,0,0,0,0,0,0,0
:endlayer
layer: 11
0,0,0,0,8,5,0,0,0,5,8,0,0,0,0,0
0,0,0,0,24,0,0,0,0,0,12,0,0,0,0,0
0,0,0,0,8,0,0,0,0,0,12,0,0,0,0,0
0,0,0,8,0,0,0,0,0,0,8,0,0,0,0,0
8,23,8,0,0,0,2,0,0,2,5,0,0,0,0,0
5,0,0,0,0,2,0,0,0,0,2,9,0,0,0,0
0,0,0,0,2,0,0,0,0,0,0,2,5,0,0,0
0,0,0,0,2,0,0,7,0,0,0,0,12,0,0,0
0,0,0,0,2,17,17,5,0,0,0,0,12,0,0,0
5,0,0,0,2,7,7,0,0,0,0,2,5,0,0,0
8,11,11,8,5,2,7,0,0,0,2,9,0,0,0,0
0,0,0,0,0,9,2,0,0,2,9,0,0,0,0,0
0,0,0,0,0,0,5,11,11,5,0,0,0,0,0,0
0,0,0,0,0,0,0,0,0,0,0,0,0,0,0,0
0,0,0,0,0,0,0,0,0,0,0,0,0,0,0,0
0,0,0,0,0,0,0,0,0,0,0,0,0,0,0,0
:endlayer
layer: 12
0,0,0,0,8,5,0,0,0,5,8,0,0,0,0,0
0,0,0,0,0,0,0,0,0,0,0,0,0,0,0,0
0,0,0,0,8,0,0,0,0,0,0,0,0,0,0,0
0,0,0,8,0,0,0,0,0,0,8,0,0,0,0,0
8,0,8,0,0,0,2,0,0,2,5,0,0,0,0,0
5,0,0,0,0,2,20,0,0,15,2,9,0,0,0,0
0,0,0,0,2,7,7,17,0,0,13,2,5,0,0,0
0,0,0,0,2,7,7,17,0,0,0,0,0,0,0,0
0,0,0,0,2,0,0,5,0,0,0,0,0,0,0,0
5,0,0,0,2,14,0,0,0,0,14,2,5,0,0,0
8,0,0,8,5,2,20,0,0,15,2,9,0,0,0,0
0,0,0,0,0,9,2,0,0,2,9,0,0,0,0,0
0,0,0,0,0,0,5,0,0,5,0,0,0,0,0,0
0,0,0,0,0,0,0,0,0,0,0,0,0,0,0,0
0,0,0,0,0,0,0,0,0,0,0,0,0,0,0,0
0,0,0,0,0,0,0,0,0,0,0,0,0,0,0,0
:endlayer
layer: 13
0,0,0,0,8,5,10,0,19,5,8,0,0,0,0,0
0,0,0,0,17,13,0,0,0,13,17,0,0,0,0,0
0,0,0,0,8,0,0,0,0,0,17,0,0,0,0,0
0,0,0,8,0,0,0,0,0,0,8,0,0,0,0,0
8,17,8,0,0,0,2,25,21,2,5,0,0,0,0,0
5,20,0,0,0,2,0,0,0,0,2,9,0,0,0,0
6,0,0,0,2,0,0,0,7,7,0,2,5,0,0,0
0,0,0,0,2,0,0,0,7,7,0,0,17,0,0,0
18,0,0,0,2,0,0,5,17,17,0,0,17,0,0,0
5,20,0,0,2,0,0,0,0,0,0,2,5,0,0,0
8,17,17,8,5,2,0,0,0,0,2,9,0,0,0,0
0,0,0,0,0,9,2,0,0,2,9,0,0,0,0,0
0,0,0,0,0,0,5,17,17,5,0,0,0,0,0,0
0,0,0,0,0,0,0,0,0,0,0,0,0,0,0,0
0,0,0,0,0,0,0,0,0,0,0,0,0,0,0,0
0,0,0,0,0,0,0,0,0,0,0,0,0,0,0,0
:endlayer
layer: 14
0,0,0,17,5,5,5,5,5,5,5,17,0,0,0,0
0,0,0,17,5,10,0,0,0,19,5,17,0,0,0,0
0,0,17,17,5,10,0,0,0,19,5,17,0,0,0,0
17,17,17,5,6,10,0,0,0,19,5,17,0,0,0,0
5,5,5,6,10,0,2,2,2,2,5,17,0,0,0,0
5,6,6,10,0,2,25,0,0,21,2,10,0,0,0,0
5,0,0,0,2,0,0,0,0,0,27,2,23,0,0,0
5,0,0,0,2,0,0,0,0,0,0,21,12,0,0,0
5,0,0,0,2,0,0,5,0,0,0,21,12,0,0,0
5,18,18,18,2,0,0,17,7,7,26,2,11,0,0,0
5,5,5,5,5,2,0,17,7,7,2,9,0,0,0,0
17,17,17,17,17,6,2,26,26,2,9,0,0,0,0,0
0,0,0,0,0,0,24,11,11,12,0,0,0,0,0,0
0,0,0,0,0,0,0,0,0,0,0,0,0,0,0,0
0,0,0,0,0,0,0,0,0,0,0,0,0,0,0,0
0,0,0,0,0,0,0,0,0,0,0,0,0,0,0,0
:endlayer
layer: 15
0,0,0,0,7,7,8,8,8,7,7,0,0,0,0,0
0,0,0,0,7,7,8,8,8,7,7,0,0,0,0,0
0,0,28,0,7,7,8,8,8,7,7,0,0,0,0,0
0,0,0,7,7,2,2,2,2,2,2,0,0,0,0,0
7,7,7,7,2,2,2,2,2,2,2,26,0,0,0,0
7,7,7,2,2,2,2,2,2,2,2,25,26,0,0,0
8,8,8,2,2,0,0,0,0,0,2,2,25,0,0,0
8,8,8,2,2,0,0,0,0,0,2,2,25,0,0,0
8,8,8,2,2,17,17,5,0,0,2,2,25,0,0,0
7,7,7,2,2,7,7,0,0,0,2,2,25,0,0,0
7,7,7,2,2,2,7,0,0,0,2,27,27,0,0,0
0,0,0,0,21,27,2,2,2,2,27,25,0,0,0,0
0,0,0,0,0,21,27,27,27,27,25,0,0,0,0,0
0,0,0,0,0,0,0,0,0,0,0,0,0,0,0,0
0,0,0,0,0,0,0,0,0,0,0,0,0,0,0,0
0,0,0,0,0,0,0,0,0,0,0,0,0,0,0,0
:endlayer
layer: 16
0,0,0,0,0,0,0,0,0,0,0,0,0,0,0,0
0,0,0,0,0,0,0,28,0,0,0,0,0,0,0,0
0,0,0,0,0,0,26,16,16,26,0,0,0,0,0,0
0,0,0,0,21,2,2,2,2,2,2,25,0,0,0,0
0,0,0,26,2,2,2,2,2,2,2,2,26,0,0,0
0,0,0,2,2,2,30,30,30,30,2,2,2,0,0,0
0,0,21,2,2,7,7,7,7,7,29,2,2,25,0,0
0,28,16,2,2,7,7,7,7,7,29,2,2,16,0,0
0,0,16,2,2,0,15,5,20,0,29,2,2,16,0,0
0,0,21,2,2,0,0,13,0,0,29,2,2,25,0,0
0,0,0,2,2,2,0,0,0,0,2,2,2,0,0,0
0,0,0,27,2,2,2,2,2,2,2,2,27,0,0,0
0,0,0,0,21,2,2,2,2,2,2,25,0,0,0,0
0,0,0,0,0,0,27,16,16,27,0,0,0,0,0,0
0,0,0,0,0,0,0,0,0,0,0,0,0,0,0,0
0,0,0,0,0,0,0,0,0,0,0,0,0,0,0,0
:endlayer
layer: 17
0,0,0,0,0,0,0,0,0,0,0,0,0,0,0,0
0,0,0,0,0,0,0,0,0,0,0,0,0,0,0,0
0,0,0,0,0,0,2,31,31,2,0,0,0,0,0,0
0,0,0,0,2,31,30,0,0,30,31,2,0,0,0,0
0,0,0,2,4,0,0,0,0,0,0,4,2,0,0,0
0,0,0,29,0,0,0,0,0,0,0,0,22,0,0,0
0,0,2,22,0,0,0,0,0,0,0,0,29,2,0,0
0,0,29,0,0,0,0,0,0,0,0,0,0,22,0,0
0,0,29,0,0,0,0,7,0,0,0,0,0,22,0,0
0,0,2,22,0,0,0,0,0,0,0,0,29,2,0,0
0,0,0,29,0,0,0,0,0,0,0,0,22,0,0,0
0,0,0,2,4,0,0,0,0,0,0,4,2,0,0,0
0,0,0,0,2,30,31,0,0,31,30,2,0,0,0,0
0,0,0,0,0,0,2,30,30,2,0,0,0,0,0,0
0,0,0,0,0,0,0,0,0,0,0,0,0,0,0,0
0,0,0,0,0,0,0,0,0,0,0,0,0,0,0,0
:endlayer
layer: 18
0,0,0,0,0,0,0,0,0,0,0,0,0,0,0,0
0,0,0,0,0,0,0,0,0,0,0,0,0,0,0,0
0,0,0,0,0,0,31,0,0,31,0,0,0,0,0,0
0,0,0,0,31,0,0,0,0,0,0,31,0,0,0,0
0,0,0,29,13,0,0,0,0,0,0,15,22,0,0,0
0,0,0,0,0,0,0,0,0,0,0,0,0,0,0,0
0,0,29,0,0,0,0,0,0,0,0,0,0,22,0,0
0,0,0,0,0,0,0,0,0,0,0,0,0,0,0,0
0,0,0,0,0,0,0,0,0,0,0,0,0,0,0,0
0,0,29,0,0,0,0,0,0,0,0,0,0,22,0,0
0,0,0,0,0,0,0,0,0,0,0,0,0,0,0,0
0,0,0,29,20,0,0,0,0,0,0,14,22,0,0,0
0,0,0,0,30,0,0,0,0,0,0,30,0,0,0,0
0,0,0,0,0,0,30,0,0,30,0,0,0,0,0,0
0,0,0,0,0,0,0,0,0,0,0,0,0,0,0,0
0,0,0,0,0,0,0,0,0,0,0,0,0,0,0,0
:endlayer

#### RULES ####
rule:
plugin=vanillaBlocks
number=1
data:
JSON:{blockState:{blockName:"minecraft:dirt",properties:{variant:"dirt",snowy:"false"}}}
:enddata
:endrule

rule:
plugin=vanillaBlocks
number=2
data:
JSON:{blockState:{blockName:"minecraft:cobblestone"}}
:enddata
:endrule

rule:
plugin=vanillaBlocks
number=3
data:
JSON:{blockState:{blockName:"minecraft:grass",properties:{snowy:"false"}}}
:enddata
:endrule

rule:
plugin=vanillaBlocks
number=4
data:
JSON:{blockState:{blockName:"minecraft:stone_slab",properties:{half:"bottom",variant:"cobblestone"}}}
:enddata
:endrule

rule:
plugin=vanillaBlocks
number=5
data:
JSON:{blockState:{blockName:"environs:frozen_log",properties:{axis:"y"}}}
:enddata
:endrule

rule:
plugin=vanillaBlocks
number=6
data:
JSON:{blockState:{blockName:"environs:frozen_stairs",properties:{half:"top",shape:"straight",facing:"north"}}}
:enddata
:endrule

rule:
plugin=vanillaBlocks
number=7
data:
JSON:{blockState:{blockName:"environs:frozen_slab",properties:{half:"bottom",variant:"default"}}}
:enddata
:endrule

rule:
plugin=vanillaBlocks
number=8
data:
JSON:{blockState:{blockName:"environs:frozen_planks"}}
:enddata
:endrule

rule:
plugin=vanillaBlocks
number=9
data:
JSON:{blockState:{blockName:"environs:frozen_fence",properties:{east:"false",south:"false",north:"false",west:"false"}}}
:enddata
:endrule

rule:
plugin=vanillaBlocks
number=10
data:
JSON:{blockState:{blockName:"environs:frozen_stairs",properties:{half:"top",shape:"straight",facing:"west"}}}
:enddata
:endrule

rule:
plugin=vanillaBlocks
number=11
data:
JSON:{blockState:{blockName:"environs:frozen_stairs",properties:{half:"bottom",shape:"straight",facing:"north"}}}
:enddata
:endrule

rule:
plugin=vanillaBlocks
number=12
data:
JSON:{blockState:{blockName:"environs:frozen_stairs",properties:{half:"bottom",shape:"straight",facing:"west"}}}
:enddata
:endrule

rule:
plugin=vanillaBlocks
number=13
data:
JSON:{blockState:{blockName:"minecraft:torch",properties:{facing:"south"}}}
:enddata
:endrule

rule:
plugin=vanillaBlocks
number=14
data:
JSON:{blockState:{blockName:"minecraft:torch",properties:{facing:"north"}}}
:enddata
:endrule

rule:
plugin=vanillaBlocks
number=15
data:
JSON:{blockState:{blockName:"minecraft:torch",properties:{facing:"west"}}}
:enddata
:endrule

rule:
plugin=vanillaBlocks
number=16
data:
JSON:{blockState:{blockName:"minecraft:stone_slab",properties:{half:"top",variant:"cobblestone"}}}
:enddata
:endrule

rule:
plugin=vanillaBlocks
number=17
data:
JSON:{blockState:{blockName:"environs:frozen_slab",properties:{half:"top",variant:"default"}}}
:enddata
:endrule

rule:
plugin=vanillaBlocks
number=18
data:
JSON:{blockState:{blockName:"environs:frozen_stairs",properties:{half:"top",shape:"straight",facing:"south"}}}
:enddata
:endrule

rule:
plugin=vanillaBlocks
number=19
data:
JSON:{blockState:{blockName:"environs:frozen_stairs",properties:{half:"top",shape:"straight",facing:"east"}}}
:enddata
:endrule

rule:
plugin=vanillaBlocks
number=20
data:
JSON:{blockState:{blockName:"minecraft:torch",properties:{facing:"east"}}}
:enddata
:endrule

rule:
plugin=vanillaBlocks
number=21
data:
JSON:{blockState:{blockName:"minecraft:stone_stairs",properties:{half:"top",shape:"straight",facing:"east"}}}
:enddata
:endrule

rule:
plugin=vanillaBlocks
number=22
data:
JSON:{blockState:{blockName:"minecraft:stone_stairs",properties:{half:"bottom",shape:"straight",facing:"west"}}}
:enddata
:endrule

rule:
plugin=vanillaBlocks
number=23
data:
JSON:{blockState:{blockName:"environs:frozen_stairs",properties:{half:"bottom",shape:"straight",facing:"south"}}}
:enddata
:endrule

rule:
plugin=vanillaBlocks
number=24
data:
JSON:{blockState:{blockName:"environs:frozen_stairs",properties:{half:"bottom",shape:"straight",facing:"east"}}}
:enddata
:endrule

rule:
plugin=vanillaBlocks
number=25
data:
JSON:{blockState:{blockName:"minecraft:stone_stairs",properties:{half:"top",shape:"straight",facing:"west"}}}
:enddata
:endrule

rule:
plugin=vanillaBlocks
number=26
data:
JSON:{blockState:{blockName:"minecraft:stone_stairs",properties:{half:"top",shape:"straight",facing:"south"}}}
:enddata
:endrule

rule:
plugin=vanillaBlocks
number=27
data:
JSON:{blockState:{blockName:"minecraft:stone_stairs",properties:{half:"top",shape:"straight",facing:"north"}}}
:enddata
:endrule

rule:
plugin=vanillaBlocks
number=28
data:
JSON:{blockState:{blockName:"minecraft:torch",properties:{facing:"up"}}}
:enddata
:endrule

rule:
plugin=vanillaBlocks
number=29
data:
JSON:{blockState:{blockName:"minecraft:stone_stairs",properties:{half:"bottom",shape:"straight",facing:"east"}}}
:enddata
:endrule

rule:
plugin=vanillaBlocks
number=30
data:
JSON:{blockState:{blockName:"minecraft:stone_stairs",properties:{half:"bottom",shape:"straight",facing:"north"}}}
:enddata
:endrule

rule:
plugin=vanillaBlocks
number=31
data:
JSON:{blockState:{blockName:"minecraft:stone_stairs",properties:{half:"bottom",shape:"straight",facing:"south"}}}
:enddata
:endrule

#### ENTITIES ####
