# Ancient Warfare Structure Template File
# Auto-generated structure template file. created on: 3/13/2021 at: 14:43:59
# Lines beginning with # denote comments

header:
version=2.11
name=SurvivalBuild_FortWall_large_type1_StraightTrebuchet_acacia
mods=
size=16,17,16
offset=15,4,0
:endheader

#### VALIDATION ####
validation:
type=ground
structureAuthor=TheOddlySeagull
survival=true
worldGenEnabled=false
unique=false
preserveBlocks=false
preventNaturalHostileSpawns=false
selectionWeight=1
clusterValue=1
minDuplicateDistance=1
dimensionWhiteList=true
dimensionList=
biomeGroupList=
biomeWhiteList=true
biomeList=
leveling=0
fill=0
border=0
blockSwap=false
territoryName=
biomeReplacement=minecraft:
minGenerationHeight=0
maxGenerationHeight=255
:endvalidation

#### LAYERS ####
layer: 0
1,1,1,1,1,2,2,2,2,2,2,2,2,2,2,1
1,1,1,1,1,2,2,2,2,2,2,2,2,2,2,1
1,1,1,1,1,2,2,2,2,2,2,2,2,2,2,1
1,1,1,1,1,2,2,2,2,2,2,2,2,2,2,1
1,1,1,1,1,2,2,2,2,2,2,2,2,2,2,1
1,1,1,1,1,2,2,2,2,2,2,2,2,2,2,1
1,1,1,1,1,2,2,2,2,2,2,2,2,2,2,1
1,1,1,1,1,2,2,2,2,2,2,2,2,2,2,1
1,1,1,1,1,2,2,2,2,2,2,2,2,2,2,1
1,1,1,1,1,2,2,2,2,2,2,2,2,2,2,1
1,1,1,1,1,2,2,2,2,2,2,2,2,2,2,1
1,1,1,1,1,2,2,2,2,2,2,2,2,2,2,1
1,1,1,1,1,2,2,2,2,2,2,2,2,2,2,1
1,1,1,1,1,2,2,2,2,2,2,2,2,2,2,1
1,1,1,1,1,2,2,2,2,2,2,2,2,2,2,1
1,1,1,1,1,2,2,2,2,2,2,2,2,2,2,1
:endlayer
layer: 1
1,1,1,1,1,2,2,2,2,2,0,0,0,0,2,1
1,1,1,1,1,2,2,2,2,2,0,0,0,0,2,1
1,1,1,1,1,2,2,2,2,2,0,0,0,0,2,1
1,1,1,1,1,2,2,2,2,2,0,0,0,0,2,1
1,1,1,1,1,2,2,2,2,2,0,0,0,0,2,1
1,1,1,1,1,2,2,2,2,2,0,0,0,0,2,1
1,1,1,1,1,2,2,2,2,2,0,0,0,0,2,1
1,1,1,1,1,2,2,2,2,2,0,0,0,0,2,1
1,1,1,1,1,2,2,2,2,2,0,0,0,0,2,1
1,1,1,1,1,2,2,2,2,2,0,0,0,0,2,1
1,1,1,1,1,2,2,2,2,2,0,0,0,0,2,1
1,1,1,1,1,2,2,2,2,2,0,0,0,0,2,1
1,1,1,1,1,2,2,2,2,2,0,0,0,0,2,1
1,1,1,1,1,2,2,2,2,2,0,0,0,0,2,1
1,1,1,1,1,2,2,2,2,2,0,0,0,0,2,1
1,1,1,1,1,2,2,2,2,2,0,0,0,0,2,1
:endlayer
layer: 2
1,1,1,1,1,2,2,2,2,2,0,0,0,0,2,1
1,1,1,1,1,2,2,2,2,2,0,0,0,0,2,1
1,1,1,1,1,2,2,2,2,2,0,0,0,0,2,1
1,1,1,1,1,2,2,2,2,2,0,0,0,0,2,1
1,1,1,1,1,2,2,2,2,2,0,0,0,0,2,1
1,1,1,1,1,2,2,2,2,2,0,0,0,0,2,1
1,1,1,1,1,2,2,2,2,2,0,0,0,0,2,1
1,1,1,1,1,2,2,2,2,2,0,0,0,0,2,1
1,1,1,1,1,2,2,2,2,2,0,0,0,0,2,1
1,1,1,1,1,2,2,2,2,2,0,0,0,0,2,1
1,1,1,1,1,2,2,2,2,2,0,0,0,0,2,1
1,1,1,1,1,2,2,2,2,2,0,0,0,0,2,1
1,1,1,1,1,2,2,2,2,2,0,0,0,0,2,1
1,1,1,1,1,2,2,2,2,2,0,0,0,0,2,1
1,1,1,1,1,2,2,2,2,2,0,0,0,0,2,1
1,1,1,1,1,2,2,2,2,2,0,0,0,0,2,1
:endlayer
layer: 3
3,3,3,3,3,2,2,2,2,2,0,0,0,0,2,3
3,3,3,3,3,2,2,2,2,2,0,0,0,0,2,3
3,3,3,3,3,2,2,2,2,2,0,0,0,0,2,3
3,3,3,3,3,2,2,2,2,2,0,0,0,0,2,3
3,3,3,3,3,2,2,2,2,2,0,0,0,0,2,3
3,3,3,3,3,2,2,2,2,2,0,0,0,0,2,3
3,3,3,3,3,2,2,2,2,2,0,0,0,0,2,3
3,3,3,3,3,2,2,2,2,2,0,0,0,0,2,3
3,3,3,3,3,2,2,2,2,2,0,0,0,0,2,3
3,3,3,3,3,2,2,2,2,2,0,0,0,0,2,3
3,3,3,3,3,2,2,2,2,2,0,0,0,0,2,3
3,3,3,3,3,2,2,2,2,2,0,0,0,0,2,3
3,3,3,3,3,2,2,2,2,2,0,0,0,0,2,3
3,3,3,3,3,2,2,2,2,2,0,0,0,0,2,3
3,3,3,3,3,2,2,2,2,2,0,0,0,0,2,3
3,3,3,3,3,2,2,2,2,2,0,0,0,0,2,3
:endlayer
layer: 4
0,0,0,0,0,4,2,2,2,4,0,0,0,0,2,0
0,0,0,0,0,7,2,2,2,6,0,0,0,0,5,0
0,0,0,0,0,7,2,2,2,6,0,0,0,0,5,0
0,0,0,0,0,4,2,2,2,4,0,0,0,0,2,0
0,0,0,0,0,4,2,2,2,4,0,0,0,0,2,0
0,0,0,0,0,7,2,2,2,6,0,0,0,0,5,0
0,0,0,0,0,7,2,2,2,6,0,0,0,0,5,0
0,0,0,0,0,4,2,2,2,4,0,0,0,0,2,0
0,0,0,0,0,4,2,2,2,4,0,0,0,0,2,0
0,0,0,0,0,7,2,2,2,6,0,0,0,0,5,0
0,0,0,0,0,7,2,2,2,6,0,0,0,0,5,0
0,0,0,0,0,4,2,2,2,4,0,0,0,0,2,0
0,0,0,0,0,4,2,2,2,4,0,0,0,0,2,0
0,0,0,0,0,7,2,2,2,6,0,0,0,0,5,0
0,0,0,0,0,7,2,2,2,6,0,0,0,0,5,0
0,0,0,0,0,4,2,2,2,4,0,0,0,0,2,0
:endlayer
layer: 5
0,0,0,0,0,4,2,2,2,4,0,0,0,0,5,0
0,0,0,0,0,0,2,2,2,8,0,0,0,0,0,0
0,0,0,0,0,0,2,2,2,8,0,0,0,0,0,0
0,0,0,0,0,4,2,2,2,4,0,0,0,0,5,0
0,0,0,0,0,4,2,2,2,4,0,0,0,0,5,0
0,0,0,0,0,0,2,2,2,8,0,0,0,0,0,0
0,0,0,0,0,0,2,2,2,8,0,0,0,0,0,0
0,0,0,0,0,4,2,2,2,4,0,0,0,0,5,0
0,0,0,0,0,4,2,2,2,4,0,0,0,0,5,0
0,0,0,0,0,0,2,2,2,8,0,0,0,0,0,0
0,0,0,0,0,0,2,2,2,8,0,0,0,0,0,0
0,0,0,0,0,4,2,2,2,4,0,0,0,0,5,0
0,0,0,0,0,4,2,2,2,4,0,0,0,0,5,0
0,0,0,0,0,0,2,2,2,8,0,0,0,0,0,0
0,0,0,0,0,0,2,2,2,8,0,0,0,0,0,0
0,0,0,0,0,4,2,2,2,4,0,0,0,0,5,0
:endlayer
layer: 6
0,0,0,0,0,4,2,2,2,4,0,0,0,0,0,0
0,0,0,0,0,0,2,2,2,0,0,0,0,0,0,0
0,0,0,0,0,0,2,2,2,0,0,0,0,0,0,0
0,0,0,0,0,4,2,2,2,4,0,0,0,0,0,0
0,0,0,0,0,4,2,2,2,4,0,0,0,0,0,0
0,0,0,0,0,0,2,2,2,0,0,0,0,0,0,0
0,0,0,0,0,0,2,2,2,0,0,0,0,0,0,0
0,0,0,0,0,4,2,2,2,4,0,0,0,0,0,0
0,0,0,0,0,4,2,2,2,4,0,0,0,0,0,0
0,0,0,0,0,0,2,2,2,0,0,0,0,0,0,0
0,0,0,0,0,0,2,2,2,0,0,0,0,0,0,0
0,0,0,0,0,4,2,2,2,4,0,0,0,0,0,0
0,0,0,0,0,4,2,2,2,4,0,0,0,0,0,0
0,0,0,0,0,0,2,2,2,0,0,0,0,0,0,0
0,0,0,0,0,0,2,2,2,0,0,0,0,0,0,0
0,0,0,0,0,4,2,2,2,4,0,0,0,0,0,0
:endlayer
layer: 7
0,0,0,0,0,4,2,2,2,4,0,0,0,0,0,0
0,0,0,0,0,0,2,2,2,0,0,0,0,0,0,0
0,0,0,0,0,0,2,2,2,0,0,0,0,0,0,0
0,0,0,0,0,4,2,2,2,4,0,0,0,0,0,0
0,0,0,0,0,4,2,2,2,4,0,0,0,0,0,0
0,0,0,0,0,0,2,2,2,0,0,0,0,0,0,0
0,0,0,0,0,0,2,2,2,0,0,0,0,0,0,0
0,0,0,0,0,4,2,2,2,4,0,0,0,0,0,0
0,0,0,0,0,4,2,2,2,4,0,0,0,0,0,0
0,0,0,0,0,0,2,2,2,0,0,0,0,0,0,0
0,0,0,0,0,0,2,2,2,0,0,0,0,0,0,0
0,0,0,0,0,4,2,2,2,4,0,0,0,0,0,0
0,0,0,0,0,4,2,2,2,4,0,0,0,0,0,0
0,0,0,0,0,0,2,2,2,0,0,0,0,0,0,0
0,0,0,0,0,0,2,2,2,0,0,0,0,0,0,0
0,0,0,0,0,4,2,2,2,4,0,0,0,0,0,0
:endlayer
layer: 8
0,0,0,0,0,4,2,2,2,4,0,0,0,0,0,0
0,0,0,0,0,0,2,2,2,0,0,0,0,0,0,0
0,0,0,0,0,0,2,2,2,0,0,0,0,0,0,0
0,0,0,0,0,4,2,2,2,4,0,0,0,0,0,0
0,0,0,0,0,4,2,2,2,4,0,0,0,0,0,0
0,0,0,0,0,0,2,2,2,0,0,0,0,0,0,0
0,0,0,0,0,0,2,2,2,0,0,0,0,0,0,0
0,0,0,0,0,4,2,2,2,4,0,0,0,0,0,0
0,0,0,0,0,4,2,2,2,4,0,0,0,0,0,0
0,0,0,0,0,0,2,2,2,0,0,0,0,0,0,0
0,0,0,0,0,0,2,2,2,0,0,0,0,0,0,0
0,0,0,0,0,4,2,2,2,4,0,0,0,0,0,0
0,0,0,0,0,4,2,2,2,4,0,0,0,0,0,0
0,0,0,0,0,0,2,2,2,0,0,0,0,0,0,0
0,0,0,0,0,0,2,2,2,0,0,0,0,0,0,0
0,0,0,0,0,4,2,2,2,4,0,0,0,0,0,0
:endlayer
layer: 9
0,0,0,0,0,4,2,2,2,4,0,0,0,0,0,0
0,0,0,0,0,10,2,2,2,10,0,0,0,0,0,0
0,0,0,0,0,9,2,2,2,9,0,0,0,0,0,0
0,0,0,0,0,4,2,2,2,4,0,0,0,0,0,0
0,0,0,0,0,4,2,2,2,4,0,0,0,0,0,0
0,0,0,0,0,10,2,2,2,10,0,0,0,0,0,0
0,0,0,0,0,9,2,2,2,9,0,0,0,0,0,0
0,0,0,0,0,4,2,2,2,4,6,0,0,0,0,0
0,0,0,0,0,4,2,2,2,4,6,0,0,0,0,0
0,0,0,0,0,10,2,2,2,10,0,0,0,0,0,0
0,0,0,0,0,9,2,2,2,9,0,0,0,0,0,0
0,0,0,0,0,4,2,2,2,4,0,0,0,0,0,0
0,0,0,0,0,4,2,2,2,4,0,0,0,0,0,0
0,0,0,0,0,10,2,2,2,10,0,0,0,0,0,0
0,0,0,0,0,9,2,2,2,9,0,0,0,0,0,0
0,0,0,0,0,4,2,2,2,4,0,0,0,0,0,0
:endlayer
layer: 10
0,0,0,0,11,4,2,2,2,4,6,0,0,0,0,0
0,0,0,0,12,13,2,2,2,13,12,0,0,0,0,0
0,0,0,0,12,13,2,2,2,13,12,0,0,0,0,0
0,0,0,0,11,13,2,2,2,13,6,0,0,0,0,0
0,0,0,0,11,13,2,2,2,13,6,0,0,0,0,0
0,0,0,0,12,13,2,2,2,13,12,0,0,0,0,0
0,0,0,0,11,13,2,2,2,13,9,0,0,0,0,0
0,0,0,0,11,13,2,2,2,13,14,6,0,0,0,0
0,0,0,0,11,13,2,2,2,13,14,6,0,0,0,0
0,0,0,0,11,13,2,2,2,13,10,0,0,0,0,0
0,0,0,0,12,13,2,2,2,13,12,0,0,0,0,0
0,0,0,0,11,13,2,2,2,13,6,0,0,0,0,0
0,0,0,0,11,13,2,2,2,13,6,0,0,0,0,0
0,0,0,0,12,13,2,2,2,13,12,0,0,0,0,0
0,0,0,0,12,13,2,2,2,13,12,0,0,0,0,0
0,0,0,0,11,4,2,2,2,4,6,0,0,0,0,0
:endlayer
layer: 11
0,0,0,0,14,4,0,0,0,4,14,0,0,0,0,0
0,0,0,0,15,0,0,0,0,0,8,0,0,0,0,0
0,0,0,0,14,0,0,0,0,0,14,0,0,0,0,0
0,0,0,0,14,0,0,0,0,0,14,0,0,0,0,0
0,0,0,0,4,4,0,0,0,4,4,0,0,0,0,0
0,0,0,0,14,0,0,0,0,7,14,0,0,0,0,0
0,0,0,0,15,7,7,7,7,14,14,6,0,0,0,0
0,0,0,0,14,14,14,14,14,14,14,14,0,0,0,0
0,0,0,0,14,14,14,14,14,14,14,14,0,0,0,0
0,0,0,0,15,7,7,7,7,14,14,6,0,0,0,0
0,0,0,0,14,0,0,0,0,7,14,0,0,0,0,0
0,0,0,0,4,4,0,0,0,4,4,0,0,0,0,0
0,0,0,0,14,0,0,0,0,0,14,0,0,0,0,0
0,0,0,0,14,0,0,0,0,0,14,0,0,0,0,0
0,0,0,0,15,0,0,0,0,0,8,0,0,0,0,0
0,0,0,0,14,4,0,0,0,4,14,0,0,0,0,0
:endlayer
layer: 12
0,0,0,0,14,4,0,0,0,4,14,0,0,0,0,0
0,0,0,0,0,0,0,0,0,0,0,0,0,0,0,0
0,0,0,0,14,0,0,0,0,0,14,0,0,0,0,0
0,0,0,0,14,0,0,0,0,0,14,0,0,0,0,0
0,0,0,0,4,4,0,0,0,4,4,0,0,0,0,0
0,0,0,0,15,0,0,0,0,0,7,0,0,0,0,0
0,0,0,0,0,0,0,0,0,0,0,7,0,0,0,0
0,0,0,0,15,0,0,0,0,0,0,7,0,0,0,0
0,0,0,0,15,0,0,0,0,0,0,7,0,0,0,0
0,0,0,0,0,0,0,0,0,0,0,7,0,0,0,0
0,0,0,0,15,0,0,0,0,0,7,0,0,0,0,0
0,0,0,0,4,4,0,0,0,4,4,0,0,0,0,0
0,0,0,0,14,0,0,0,0,0,14,0,0,0,0,0
0,0,0,0,14,0,0,0,0,0,14,0,0,0,0,0
0,0,0,0,0,0,0,0,0,0,0,0,0,0,0,0
0,0,0,0,14,4,0,0,0,4,14,0,0,0,0,0
:endlayer
layer: 13
0,0,0,0,14,4,6,0,11,4,14,0,0,0,0,0
0,0,0,0,12,19,0,0,0,19,12,0,0,0,0,0
0,0,0,18,14,0,0,0,0,0,14,17,0,0,0,0
0,0,0,0,14,16,0,0,0,16,14,0,0,0,0,0
0,0,0,0,4,4,6,0,11,4,4,0,0,0,0,0
0,0,0,0,0,19,0,0,0,19,0,0,0,0,0,0
0,0,0,0,0,0,0,0,0,0,0,0,0,0,0,0
0,0,0,0,0,0,0,0,0,0,0,0,0,0,0,0
0,0,0,0,0,0,0,0,0,0,0,0,0,0,0,0
0,0,0,0,0,0,0,0,0,0,0,0,0,0,0,0
0,0,0,0,0,16,0,0,0,16,0,0,0,0,0,0
0,0,0,0,4,4,6,0,11,4,4,0,0,0,0,0
0,0,0,0,14,19,0,0,0,19,14,0,0,0,0,0
0,0,0,18,14,0,0,0,0,0,14,17,0,0,0,0
0,0,0,0,12,16,0,0,0,16,12,0,0,0,0,0
0,0,0,0,14,4,6,0,11,4,14,0,0,0,0,0
:endlayer
layer: 14
0,0,0,12,13,20,20,20,20,20,13,12,0,0,0,0
0,0,0,12,13,6,0,0,0,11,13,12,0,0,0,0
0,0,0,12,13,6,0,0,0,11,13,12,0,0,0,0
0,0,0,12,13,6,0,0,0,11,13,12,0,0,0,0
0,0,0,12,4,20,20,20,20,20,4,12,0,0,0,0
0,0,0,12,12,12,12,12,12,12,12,12,0,0,0,0
0,0,0,0,0,0,0,0,0,0,0,0,0,0,0,0
0,0,0,0,0,0,0,0,0,0,0,0,0,0,0,0
0,0,0,0,0,0,0,0,0,0,0,0,0,0,0,0
0,0,0,0,0,0,0,0,0,0,0,0,0,0,0,0
0,0,0,12,12,12,12,12,12,12,12,12,0,0,0,0
0,0,0,12,4,20,20,20,20,20,4,12,0,0,0,0
0,0,0,12,13,6,0,0,0,11,13,12,0,0,0,0
0,0,0,12,13,6,0,0,0,11,13,12,0,0,0,0
0,0,0,12,13,6,0,0,0,11,13,12,0,0,0,0
0,0,0,12,13,20,20,20,20,20,13,12,0,0,0,0
:endlayer
layer: 15
0,0,0,0,7,7,14,14,14,7,7,0,0,0,0,0
0,0,0,0,7,7,14,14,14,7,7,0,0,0,0,0
0,0,0,0,7,7,14,14,14,7,7,0,0,0,0,0
0,0,0,0,7,7,14,14,14,7,7,0,0,0,0,0
0,0,0,0,7,7,7,7,7,7,7,0,0,0,0,0
0,0,0,0,0,0,0,0,0,0,0,0,0,0,0,0
0,0,0,0,0,0,0,0,0,0,0,0,0,0,0,0
0,0,0,0,0,0,0,0,0,0,0,0,0,0,0,0
0,0,0,0,0,0,0,0,0,0,0,0,0,0,0,0
0,0,0,0,0,0,0,0,0,0,0,0,0,0,0,0
0,0,0,0,0,0,0,0,0,0,0,0,0,0,0,0
0,0,0,0,7,7,7,7,7,7,7,0,0,0,0,0
0,0,0,0,7,7,14,14,14,7,7,0,0,0,0,0
0,0,0,0,7,7,14,14,14,7,7,0,0,0,0,0
0,0,0,0,7,7,14,14,14,7,7,0,0,0,0,0
0,0,0,0,7,7,14,14,14,7,7,0,0,0,0,0
:endlayer
layer: 16
0,0,0,0,0,0,0,0,0,0,0,0,0,0,0,0
0,0,0,0,0,0,0,0,0,0,0,0,0,0,0,0
0,0,0,0,0,0,0,21,0,0,0,0,0,0,0,0
0,0,0,0,0,0,0,0,0,0,0,0,0,0,0,0
0,0,0,0,0,0,0,0,0,0,0,0,0,0,0,0
0,0,0,0,0,0,0,0,0,0,0,0,0,0,0,0
0,0,0,0,0,0,0,0,0,0,0,0,0,0,0,0
0,0,0,0,0,0,0,0,0,0,0,0,0,0,0,0
0,0,0,0,0,0,0,0,0,0,0,0,0,0,0,0
0,0,0,0,0,0,0,0,0,0,0,0,0,0,0,0
0,0,0,0,0,0,0,0,0,0,0,0,0,0,0,0
0,0,0,0,0,0,0,0,0,0,0,0,0,0,0,0
0,0,0,0,0,0,0,0,0,0,0,0,0,0,0,0
0,0,0,0,0,0,0,21,0,0,0,0,0,0,0,0
0,0,0,0,0,0,0,0,0,0,0,0,0,0,0,0
0,0,0,0,0,0,0,0,0,0,0,0,0,0,0,0
:endlayer

#### RULES ####
rule:
plugin=vanillaBlocks
number=1
data:
JSON:{blockState:{blockName:"minecraft:dirt",properties:{variant:"dirt",snowy:"false"}}}
:enddata
:endrule

rule:
plugin=vanillaBlocks
number=2
data:
JSON:{blockState:{blockName:"minecraft:cobblestone"}}
:enddata
:endrule

rule:
plugin=vanillaBlocks
number=3
data:
JSON:{blockState:{blockName:"minecraft:grass",properties:{snowy:"false"}}}
:enddata
:endrule

rule:
plugin=vanillaBlocks
number=4
data:
JSON:{blockState:{blockName:"minecraft:log2",properties:{variant:"acacia",axis:"y"}}}
:enddata
:endrule

rule:
plugin=vanillaBlocks
number=5
data:
JSON:{blockState:{blockName:"minecraft:stone_slab",properties:{half:"bottom",variant:"cobblestone"}}}
:enddata
:endrule

rule:
plugin=vanillaBlocks
number=6
data:
JSON:{blockState:{blockName:"minecraft:acacia_stairs",properties:{half:"top",shape:"straight",facing:"west"}}}
:enddata
:endrule

rule:
plugin=vanillaBlocks
number=7
data:
JSON:{blockState:{blockName:"minecraft:wooden_slab",properties:{half:"bottom",variant:"acacia"}}}
:enddata
:endrule

rule:
plugin=vanillaBlocks
number=8
data:
JSON:{blockState:{blockName:"minecraft:acacia_stairs",properties:{half:"bottom",shape:"straight",facing:"west"}}}
:enddata
:endrule

rule:
plugin=vanillaBlocks
number=9
data:
JSON:{blockState:{blockName:"minecraft:acacia_stairs",properties:{half:"top",shape:"straight",facing:"south"}}}
:enddata
:endrule

rule:
plugin=vanillaBlocks
number=10
data:
JSON:{blockState:{blockName:"minecraft:acacia_stairs",properties:{half:"top",shape:"straight",facing:"north"}}}
:enddata
:endrule

rule:
plugin=vanillaBlocks
number=11
data:
JSON:{blockState:{blockName:"minecraft:acacia_stairs",properties:{half:"top",shape:"straight",facing:"east"}}}
:enddata
:endrule

rule:
plugin=vanillaBlocks
number=12
data:
JSON:{blockState:{blockName:"minecraft:wooden_slab",properties:{half:"top",variant:"acacia"}}}
:enddata
:endrule

rule:
plugin=vanillaBlocks
number=13
data:
JSON:{blockState:{blockName:"minecraft:log2",properties:{variant:"acacia",axis:"z"}}}
:enddata
:endrule

rule:
plugin=vanillaBlocks
number=14
data:
JSON:{blockState:{blockName:"minecraft:planks",properties:{variant:"acacia"}}}
:enddata
:endrule

rule:
plugin=vanillaBlocks
number=15
data:
JSON:{blockState:{blockName:"minecraft:acacia_stairs",properties:{half:"bottom",shape:"straight",facing:"east"}}}
:enddata
:endrule

rule:
plugin=vanillaBlocks
number=16
data:
JSON:{blockState:{blockName:"minecraft:torch",properties:{facing:"north"}}}
:enddata
:endrule

rule:
plugin=vanillaBlocks
number=17
data:
JSON:{blockState:{blockName:"minecraft:torch",properties:{facing:"east"}}}
:enddata
:endrule

rule:
plugin=vanillaBlocks
number=18
data:
JSON:{blockState:{blockName:"minecraft:torch",properties:{facing:"west"}}}
:enddata
:endrule

rule:
plugin=vanillaBlocks
number=19
data:
JSON:{blockState:{blockName:"minecraft:torch",properties:{facing:"south"}}}
:enddata
:endrule

rule:
plugin=vanillaBlocks
number=20
data:
JSON:{blockState:{blockName:"minecraft:log2",properties:{variant:"acacia",axis:"x"}}}
:enddata
:endrule

rule:
plugin=vanillaBlocks
number=21
data:
JSON:{blockState:{blockName:"minecraft:torch",properties:{facing:"up"}}}
:enddata
:endrule

#### ENTITIES ####
