# Ancient Warfare Structure Template File
# Auto-generated structure template file. created on: 3/13/2021 at: 14:29:29
# Lines beginning with # denote comments

header:
version=2.11
name=SurvivalBuild_FortWall_large_type1_OutterCornerBastion_jungle
mods=
size=16,19,16
offset=0,4,15
:endheader

#### VALIDATION ####
validation:
type=ground
structureAuthor=TheOddlySeagull
survival=true
worldGenEnabled=false
unique=false
preserveBlocks=false
preventNaturalHostileSpawns=false
selectionWeight=1
clusterValue=1
minDuplicateDistance=1
dimensionWhiteList=true
dimensionList=
biomeGroupList=
biomeWhiteList=true
biomeList=
leveling=0
fill=0
border=0
blockSwap=false
territoryName=
biomeReplacement=minecraft:
minGenerationHeight=0
maxGenerationHeight=255
:endvalidation

#### LAYERS ####
layer: 0
1,2,2,2,2,2,2,2,2,2,2,1,1,1,1,1
1,2,2,2,2,2,2,2,2,2,2,1,1,1,1,1
1,2,2,2,2,2,2,2,2,2,2,1,1,1,1,1
1,2,2,2,2,2,2,2,2,2,2,1,1,1,1,1
1,2,2,2,2,2,2,2,2,2,2,1,1,1,1,1
1,2,2,2,2,2,2,2,2,2,2,2,2,2,2,2
1,2,2,2,2,2,2,2,2,2,2,2,2,2,2,2
1,2,2,2,2,2,2,2,2,2,2,2,2,2,2,2
1,2,2,2,2,2,2,2,2,2,2,2,2,2,2,2
1,2,2,2,2,2,2,2,2,2,2,2,2,2,2,2
1,2,2,2,2,2,2,2,2,2,2,2,2,2,2,2
1,2,2,2,2,2,2,2,2,2,2,2,2,2,2,2
1,2,2,2,2,2,2,2,2,2,2,2,2,2,2,2
1,2,2,2,2,2,2,2,2,2,2,2,2,2,2,2
1,2,2,2,2,2,2,2,2,2,2,2,2,2,2,2
1,1,1,1,1,1,1,1,1,1,1,1,1,1,1,1
:endlayer
layer: 1
1,2,0,0,0,0,2,2,2,2,2,1,1,1,1,1
1,2,0,0,0,0,2,2,2,2,2,1,1,1,1,1
1,2,0,0,0,0,2,2,2,2,2,1,1,1,1,1
1,2,0,0,0,0,2,2,2,2,2,1,1,1,1,1
1,2,0,0,0,0,2,2,2,2,2,1,1,1,1,1
1,2,0,0,0,2,2,2,2,2,2,2,2,2,2,2
1,2,0,0,2,2,2,2,2,2,2,2,2,2,2,2
1,2,0,0,2,2,2,2,2,2,2,2,2,2,2,2
1,2,0,0,2,2,2,2,2,2,2,2,2,2,2,2
1,2,0,0,2,2,2,2,2,2,2,2,2,2,2,2
1,2,0,0,0,2,2,2,2,2,2,0,0,0,0,0
1,2,0,0,0,0,2,2,2,2,0,0,0,0,0,0
1,2,0,0,0,0,0,0,0,0,0,0,0,0,0,0
1,2,0,0,0,0,0,0,0,0,0,0,0,0,0,0
1,2,2,2,2,2,2,2,2,2,2,2,2,2,2,2
1,1,1,1,1,1,1,1,1,1,1,1,1,1,1,1
:endlayer
layer: 2
1,2,0,0,0,0,2,2,2,2,2,1,1,1,1,1
1,2,0,0,0,0,2,2,2,2,2,1,1,1,1,1
1,2,0,0,0,0,2,2,2,2,2,1,1,1,1,1
1,2,0,0,0,0,2,2,2,2,2,1,1,1,1,1
1,2,0,0,0,0,2,2,2,2,2,1,1,1,1,1
1,2,0,0,0,2,2,2,2,2,2,2,2,2,2,2
1,2,0,0,2,2,2,2,2,2,2,2,2,2,2,2
1,2,0,0,2,2,2,2,2,2,2,2,2,2,2,2
1,2,0,0,2,2,2,2,2,2,2,2,2,2,2,2
1,2,0,0,2,2,2,2,2,2,2,2,2,2,2,2
1,2,0,0,0,2,2,2,2,2,2,0,0,0,0,0
1,2,0,0,0,0,2,2,2,2,0,0,0,0,0,0
1,2,0,0,0,0,0,0,0,0,0,0,0,0,0,0
1,2,0,0,0,0,0,0,0,0,0,0,0,0,0,0
1,2,2,2,2,2,2,2,2,2,2,2,2,2,2,2
1,1,1,1,1,1,1,1,1,1,1,1,1,1,1,1
:endlayer
layer: 3
3,2,0,0,0,0,2,2,2,2,2,3,3,3,3,3
3,2,0,0,0,0,2,2,2,2,2,1,1,3,3,3
3,2,0,0,0,0,2,2,2,2,2,2,2,2,3,3
3,2,0,0,0,0,2,2,2,2,2,2,2,2,1,3
3,2,0,0,0,0,2,2,2,2,2,2,2,2,1,3
3,2,0,0,0,2,2,2,2,2,2,2,2,2,2,2
3,2,0,0,2,2,2,2,2,2,2,2,2,2,2,2
3,2,0,0,2,2,2,2,2,2,2,2,2,2,2,2
3,2,0,0,2,2,2,2,2,2,2,2,2,2,2,2
3,2,0,0,2,2,2,2,2,2,2,2,2,2,2,2
3,2,0,0,0,2,2,2,2,2,2,0,0,0,0,0
3,2,0,0,0,0,2,2,2,2,0,0,0,0,0,0
3,2,0,0,0,0,0,0,0,0,0,0,0,0,0,0
3,2,0,0,0,0,0,0,0,0,0,0,0,0,0,0
3,2,2,2,2,2,2,2,2,2,2,2,2,2,2,2
3,3,3,3,3,3,3,3,3,3,3,3,3,3,3,3
:endlayer
layer: 4
0,2,0,0,0,0,5,2,2,2,5,9,0,0,0,0
0,4,0,0,0,0,6,2,2,2,8,8,5,0,0,0
0,4,0,0,0,0,6,2,2,2,7,0,0,0,0,0
0,2,0,0,0,0,5,2,2,2,5,4,0,0,5,0
0,2,0,0,0,0,2,2,2,2,4,4,4,0,8,9
0,4,0,0,0,2,2,2,2,2,2,4,5,7,8,5
0,4,0,0,2,2,2,2,2,2,2,2,2,2,2,2
0,2,0,0,2,2,2,2,2,2,2,2,2,2,2,2
0,2,0,0,2,2,2,2,2,2,2,2,2,2,2,2
0,4,0,0,2,2,2,2,2,2,2,2,5,10,10,5
0,4,0,0,0,2,2,2,2,2,2,0,0,0,0,0
0,2,0,0,0,0,2,2,2,2,0,0,0,0,0,0
0,2,0,0,0,0,0,0,0,0,0,0,0,0,0,0
0,4,0,0,0,0,0,0,0,0,0,0,0,0,0,0
0,4,4,2,2,4,4,2,2,4,4,2,2,4,4,2
0,0,0,0,0,0,0,0,0,0,0,0,0,0,0,0
:endlayer
layer: 5
0,4,0,0,0,0,5,2,2,2,5,9,0,0,0,0
0,0,0,0,0,0,11,2,2,2,8,8,5,0,0,0
0,0,0,0,0,0,11,2,2,2,0,0,0,0,0,0
0,4,0,0,0,0,5,2,2,2,5,0,0,0,5,0
0,4,0,0,0,0,2,2,2,2,0,0,0,0,8,9
0,0,0,0,0,2,2,2,2,0,0,0,5,0,8,5
0,0,0,0,2,2,2,2,2,0,0,2,2,2,2,2
0,4,0,0,2,2,2,2,5,4,4,2,2,2,2,2
0,4,0,0,2,2,2,2,2,2,2,2,2,2,2,2
0,0,0,0,2,2,2,2,2,2,2,2,5,12,12,5
0,0,0,0,0,2,2,2,2,2,2,0,0,0,0,0
0,4,0,0,0,0,2,2,2,2,0,0,0,0,0,0
0,4,0,0,0,0,0,0,0,0,0,0,0,0,0,0
0,0,0,0,0,0,0,0,0,0,0,0,0,0,0,0
0,0,0,4,4,0,0,4,4,0,0,4,4,0,0,4
0,0,0,0,0,0,0,0,0,0,0,0,0,0,0,0
:endlayer
layer: 6
0,0,0,0,0,0,5,2,2,2,5,9,15,0,0,0
0,0,0,0,0,0,0,2,2,2,8,8,5,0,0,0
0,0,0,0,0,0,0,2,2,2,0,0,0,0,0,0
0,0,0,0,0,0,5,2,2,2,5,14,0,0,5,14
0,0,0,0,0,0,2,2,2,2,0,0,15,0,8,9
0,0,0,0,0,2,2,2,2,0,0,0,5,0,8,5
0,0,0,0,2,2,2,2,2,0,0,2,2,2,2,2
0,0,0,0,2,2,2,2,5,0,13,2,2,2,2,2
0,0,0,0,2,2,2,2,4,0,0,2,2,2,2,2
0,0,0,0,2,2,2,2,4,0,2,2,5,0,0,5
0,0,0,0,0,2,2,2,2,2,2,0,0,0,0,0
0,0,0,0,0,0,2,2,2,2,0,0,0,0,0,0
0,0,0,0,0,0,0,0,0,0,0,0,0,0,0,0
0,0,0,0,0,0,0,0,0,0,0,0,0,0,0,0
0,0,0,0,0,0,0,0,0,0,0,0,0,0,0,0
0,0,0,0,0,0,0,0,0,0,0,0,0,0,0,0
:endlayer
layer: 7
0,0,0,0,0,0,5,2,2,2,5,19,17,17,0,0
0,0,0,0,0,0,0,2,2,2,18,18,5,17,17,0
0,0,0,0,0,0,0,2,2,2,17,17,17,5,17,17
0,0,0,0,0,0,5,2,2,2,5,0,0,17,5,17
0,0,0,0,0,0,2,2,2,2,2,0,0,17,20,21
0,0,0,0,0,2,2,2,2,16,16,2,5,17,20,5
0,0,0,0,2,2,2,2,2,16,16,2,2,2,2,2
0,0,0,0,2,2,4,4,5,0,0,2,2,2,2,2
0,0,0,0,2,2,0,0,0,0,0,2,2,2,2,2
0,0,0,0,2,2,2,0,15,0,2,2,5,0,0,5
0,0,0,0,0,2,2,2,2,2,2,0,0,0,0,0
0,0,0,0,0,0,2,2,2,2,0,0,0,0,0,0
0,0,0,0,0,0,0,0,0,0,0,0,0,0,0,0
0,0,0,0,0,0,0,0,0,0,0,0,0,0,0,0
0,0,0,0,0,0,0,0,0,0,0,0,0,0,0,0
0,0,0,0,0,0,0,0,0,0,0,0,0,0,0,0
:endlayer
layer: 8
0,0,0,0,0,0,5,2,2,2,5,0,0,0,0,0
0,0,0,0,0,0,0,2,2,2,7,7,7,0,0,0
0,0,0,0,0,0,0,2,2,2,8,8,7,7,0,0
0,0,0,0,0,0,5,2,2,2,5,8,8,7,7,0
0,0,0,0,0,0,2,2,2,2,2,8,8,8,7,0
0,0,0,0,0,2,2,0,4,2,2,2,5,8,7,5
0,0,0,0,2,2,0,0,4,2,2,2,2,2,2,2
0,0,0,0,2,2,14,0,5,2,2,2,2,2,2,2
0,0,0,0,2,2,0,0,0,16,16,2,2,2,2,2
0,0,0,0,2,2,2,0,0,16,2,2,5,0,0,5
0,0,0,0,0,2,2,2,2,2,2,0,0,0,0,0
0,0,0,0,0,0,2,2,2,2,0,0,0,0,0,0
0,0,0,0,0,0,0,0,0,0,0,0,0,0,0,0
0,0,0,0,0,0,0,0,0,0,0,0,0,0,0,0
0,0,0,0,0,0,0,0,0,0,0,0,0,0,0,0
0,0,0,0,0,0,0,0,0,0,0,0,0,0,0,0
:endlayer
layer: 9
0,0,0,0,0,0,5,2,2,2,5,0,0,0,0,0
0,0,0,0,0,0,10,2,2,2,10,0,0,0,0,0
0,0,0,0,0,0,21,2,2,2,21,0,0,0,0,0
0,0,0,0,0,0,5,2,2,2,5,0,0,0,0,0
0,0,0,0,0,0,2,2,2,2,2,8,0,0,0,0
0,0,0,0,0,2,2,0,22,0,2,2,5,19,6,5
0,0,0,0,2,2,0,0,0,0,0,2,2,2,2,2
0,0,0,6,2,2,0,0,5,4,4,2,2,2,2,2
0,0,0,6,2,2,16,16,2,4,4,2,2,2,2,2
0,0,0,0,2,2,2,2,2,2,2,2,5,19,6,5
0,0,0,0,0,2,2,2,2,2,2,0,0,0,0,0
0,0,0,0,0,0,2,2,2,2,0,0,0,0,0,0
0,0,0,0,0,0,0,10,10,0,0,0,0,0,0,0
0,0,0,0,0,0,0,0,0,0,0,0,0,0,0,0
0,0,0,0,0,0,0,0,0,0,0,0,0,0,0,0
0,0,0,0,0,0,0,0,0,0,0,0,0,0,0,0
:endlayer
layer: 10
0,0,0,0,0,6,20,2,2,2,20,19,0,0,0,0
0,0,0,0,0,17,20,2,2,2,20,17,0,0,0,0
0,0,0,0,0,17,20,2,2,2,20,17,0,0,0,0
0,0,0,0,0,6,20,2,2,2,20,19,17,0,0,0
0,0,0,0,0,6,2,2,2,2,2,5,21,17,17,21
0,0,0,0,9,2,2,0,0,0,2,2,18,18,18,5
0,0,0,6,2,2,0,0,15,0,0,2,2,2,2,2
0,0,0,8,2,2,23,23,5,14,0,0,4,2,2,2
0,0,0,8,2,4,4,24,22,0,0,0,4,2,2,2
0,0,0,6,2,4,4,4,0,0,0,2,18,18,18,5
0,0,0,0,9,2,4,4,4,4,2,10,10,17,17,10
0,0,0,0,0,9,2,2,2,2,9,0,0,0,0,0
0,0,0,0,0,0,10,8,8,10,0,0,0,0,0,0
0,0,0,0,0,0,0,0,0,0,0,0,0,0,0,0
0,0,0,0,0,0,0,0,0,0,0,0,0,0,0,0
0,0,0,0,0,0,0,0,0,0,0,0,0,0,0,0
:endlayer
layer: 11
0,0,0,0,0,8,5,0,0,0,5,8,0,0,0,0
0,0,0,0,0,11,0,0,0,0,0,25,0,0,0,0
0,0,0,0,0,11,0,0,0,0,0,8,0,0,0,0
0,0,0,0,0,8,0,0,0,0,0,0,8,0,0,0
0,0,0,0,0,5,2,2,2,2,0,0,0,8,26,8
0,0,0,0,9,2,7,17,0,0,2,0,0,0,0,5
0,0,0,5,2,7,7,17,0,0,0,2,0,0,0,0
0,0,0,11,0,0,0,5,7,0,0,0,0,0,0,0
0,0,0,11,0,0,0,0,0,0,0,0,0,0,0,0
0,0,0,5,2,0,0,0,0,0,0,2,0,0,0,5
0,0,0,0,9,2,0,0,0,0,2,5,8,12,12,8
0,0,0,0,0,9,2,0,0,2,9,0,0,0,0,0
0,0,0,0,0,0,5,12,12,5,0,0,0,0,0,0
0,0,0,0,0,0,0,0,0,0,0,0,0,0,0,0
0,0,0,0,0,0,0,0,0,0,0,0,0,0,0,0
0,0,0,0,0,0,0,0,0,0,0,0,0,0,0,0
:endlayer
layer: 12
0,0,0,0,0,8,5,0,0,0,5,8,0,0,0,0
0,0,0,0,0,0,0,0,0,0,0,0,0,0,0,0
0,0,0,0,0,0,0,0,0,0,0,8,0,0,0,0
0,0,0,0,0,8,0,0,0,0,0,0,8,0,0,0
0,0,0,0,0,5,2,2,2,2,0,0,0,8,0,8
0,0,0,0,9,2,14,0,7,7,2,0,0,0,0,5
0,0,0,5,2,22,0,0,7,7,22,2,0,0,0,0
0,0,0,0,0,0,0,5,17,17,0,0,0,0,0,0
0,0,0,0,0,0,0,0,0,0,0,0,0,0,0,0
0,0,0,5,2,15,0,0,0,0,15,2,0,0,0,5
0,0,0,0,9,2,14,0,0,13,2,5,8,0,0,8
0,0,0,0,0,9,2,0,0,2,9,0,0,0,0,0
0,0,0,0,0,0,5,0,0,5,0,0,0,0,0,0
0,0,0,0,0,0,0,0,0,0,0,0,0,0,0,0
0,0,0,0,0,0,0,0,0,0,0,0,0,0,0,0
0,0,0,0,0,0,0,0,0,0,0,0,0,0,0,0
:endlayer
layer: 13
0,0,0,0,0,8,5,19,0,6,5,8,0,0,0,0
0,0,0,0,0,17,22,0,0,0,22,17,0,0,0,0
0,0,0,0,0,17,0,0,0,0,0,8,0,0,0,0
0,0,0,0,0,8,0,0,0,0,0,0,8,0,0,0
0,0,0,0,0,5,2,2,2,2,0,0,0,8,17,8
0,0,0,0,9,2,0,0,0,0,2,0,0,0,13,5
0,0,0,5,2,0,0,0,0,0,0,2,0,0,0,10
0,0,0,17,0,0,0,5,0,0,0,27,0,0,0,0
0,0,0,17,0,0,0,17,7,7,0,23,0,0,0,21
0,0,0,5,2,0,0,17,7,7,0,2,0,0,13,5
0,0,0,0,9,2,0,0,0,0,2,5,8,17,17,8
0,0,0,0,0,9,2,0,0,2,9,0,0,0,0,0
0,0,0,0,0,0,5,17,17,5,0,0,0,0,0,0
0,0,0,0,0,0,0,0,0,0,0,0,0,0,0,0
0,0,0,0,0,0,0,0,0,0,0,0,0,0,0,0
0,0,0,0,0,0,0,0,0,0,0,0,0,0,0,0
:endlayer
layer: 14
0,0,0,0,17,20,18,18,18,18,18,20,17,0,0,0
0,0,0,0,17,20,19,0,0,0,6,20,17,0,0,0
0,0,0,0,17,20,19,0,0,0,6,20,17,17,0,0
0,0,0,0,17,20,19,0,0,0,10,6,5,17,17,17
0,0,0,0,17,20,2,2,2,2,0,10,6,18,18,18
0,0,0,0,6,2,0,0,0,0,2,0,10,10,10,20
0,0,0,26,2,0,0,0,0,0,27,2,0,0,0,20
0,0,0,11,28,17,17,5,0,0,0,2,0,0,0,20
0,0,0,11,28,7,7,0,0,0,0,2,0,0,0,20
0,0,0,12,2,7,7,0,0,0,23,2,21,21,21,20
0,0,0,0,9,2,28,0,0,29,2,18,18,18,18,18
0,0,0,0,0,9,2,23,23,2,10,17,17,17,17,17
0,0,0,0,0,0,11,12,12,25,0,0,0,0,0,0
0,0,0,0,0,0,0,0,0,0,0,0,0,0,0,0
0,0,0,0,0,0,0,0,0,0,0,0,0,0,0,0
0,0,0,0,0,0,0,0,0,0,0,0,0,0,0,0
:endlayer
layer: 15
0,0,0,0,0,7,7,8,8,8,7,7,0,0,0,0
0,0,0,0,0,7,7,8,8,8,7,7,0,0,0,0
0,0,0,0,0,7,7,8,8,8,7,7,0,30,0,0
0,0,0,0,0,2,2,2,2,2,2,7,7,0,0,0
0,0,0,0,23,2,2,2,2,2,2,2,7,7,7,7
0,0,0,23,29,2,7,17,0,0,2,2,2,7,7,7
0,0,0,29,2,7,7,17,0,0,2,2,2,8,8,8
0,0,0,29,2,0,0,5,0,0,2,2,2,8,8,8
0,0,0,29,2,0,0,0,0,0,2,2,2,8,8,8
0,0,0,29,2,0,0,0,0,0,2,2,2,7,7,7
0,0,0,27,29,2,2,2,2,2,2,2,2,7,7,7
0,0,0,0,27,29,2,2,2,2,27,28,0,0,0,0
0,0,0,0,0,29,27,27,27,27,28,0,0,0,0,0
0,0,0,0,0,0,0,0,0,0,0,0,0,0,0,0
0,0,0,0,0,0,0,0,0,0,0,0,0,0,0,0
0,0,0,0,0,0,0,0,0,0,0,0,0,0,0,0
:endlayer
layer: 16
0,0,0,0,0,0,0,0,0,0,0,0,0,0,0,0
0,0,0,0,0,0,0,0,30,0,0,0,0,0,0,0
0,0,0,0,0,0,23,16,16,23,0,0,0,0,0,0
0,0,0,0,29,2,2,2,2,2,2,28,0,0,0,0
0,0,0,23,2,2,2,2,2,2,2,2,23,0,0,0
0,0,0,2,2,2,0,0,7,7,2,2,2,0,0,0
0,0,29,2,2,0,0,15,7,7,32,2,2,28,0,0
0,0,16,2,2,0,13,5,7,7,32,2,2,16,30,0
0,0,16,2,2,0,0,22,7,7,32,2,2,16,0,0
0,0,29,2,2,0,0,0,7,7,32,2,2,28,0,0
0,0,0,2,2,2,31,31,31,31,2,2,2,0,0,0
0,0,0,27,2,2,2,2,2,2,2,2,27,0,0,0
0,0,0,0,29,2,2,2,2,2,2,28,0,0,0,0
0,0,0,0,0,0,27,16,16,27,0,0,0,0,0,0
0,0,0,0,0,0,0,0,0,0,0,0,0,0,0,0
0,0,0,0,0,0,0,0,0,0,0,0,0,0,0,0
:endlayer
layer: 17
0,0,0,0,0,0,0,0,0,0,0,0,0,0,0,0
0,0,0,0,0,0,0,0,0,0,0,0,0,0,0,0
0,0,0,0,0,0,2,31,31,2,0,0,0,0,0,0
0,0,0,0,2,31,24,0,0,24,31,2,0,0,0,0
0,0,0,2,4,0,0,0,0,0,0,4,2,0,0,0
0,0,0,32,0,0,0,0,0,0,0,0,33,0,0,0
0,0,2,33,0,0,0,0,0,0,0,0,32,2,0,0
0,0,32,0,0,0,0,7,0,0,0,0,0,33,0,0
0,0,32,0,0,0,0,0,0,0,0,0,0,33,0,0
0,0,2,33,0,0,0,0,0,0,0,0,32,2,0,0
0,0,0,32,0,0,0,0,0,0,0,0,33,0,0,0
0,0,0,2,4,0,0,0,0,0,0,4,2,0,0,0
0,0,0,0,2,24,31,0,0,31,24,2,0,0,0,0
0,0,0,0,0,0,2,24,24,2,0,0,0,0,0,0
0,0,0,0,0,0,0,0,0,0,0,0,0,0,0,0
0,0,0,0,0,0,0,0,0,0,0,0,0,0,0,0
:endlayer
layer: 18
0,0,0,0,0,0,0,0,0,0,0,0,0,0,0,0
0,0,0,0,0,0,0,0,0,0,0,0,0,0,0,0
0,0,0,0,0,0,31,0,0,31,0,0,0,0,0,0
0,0,0,0,31,0,0,0,0,0,0,31,0,0,0,0
0,0,0,32,22,0,0,0,0,0,0,13,33,0,0,0
0,0,0,0,0,0,0,0,0,0,0,0,0,0,0,0
0,0,32,0,0,0,0,0,0,0,0,0,0,33,0,0
0,0,0,0,0,0,0,0,0,0,0,0,0,0,0,0
0,0,0,0,0,0,0,0,0,0,0,0,0,0,0,0
0,0,32,0,0,0,0,0,0,0,0,0,0,33,0,0
0,0,0,0,0,0,0,0,0,0,0,0,0,0,0,0
0,0,0,32,14,0,0,0,0,0,0,15,33,0,0,0
0,0,0,0,24,0,0,0,0,0,0,24,0,0,0,0
0,0,0,0,0,0,24,0,0,24,0,0,0,0,0,0
0,0,0,0,0,0,0,0,0,0,0,0,0,0,0,0
0,0,0,0,0,0,0,0,0,0,0,0,0,0,0,0
:endlayer

#### RULES ####
rule:
plugin=vanillaBlocks
number=1
data:
JSON:{blockState:{blockName:"minecraft:dirt",properties:{variant:"dirt",snowy:"false"}}}
:enddata
:endrule

rule:
plugin=vanillaBlocks
number=2
data:
JSON:{blockState:{blockName:"minecraft:cobblestone"}}
:enddata
:endrule

rule:
plugin=vanillaBlocks
number=3
data:
JSON:{blockState:{blockName:"minecraft:grass",properties:{snowy:"false"}}}
:enddata
:endrule

rule:
plugin=vanillaBlocks
number=4
data:
JSON:{blockState:{blockName:"minecraft:stone_slab",properties:{half:"bottom",variant:"cobblestone"}}}
:enddata
:endrule

rule:
plugin=vanillaBlocks
number=5
data:
JSON:{blockState:{blockName:"minecraft:log",properties:{variant:"jungle",axis:"y"}}}
:enddata
:endrule

rule:
plugin=vanillaBlocks
number=6
data:
JSON:{blockState:{blockName:"minecraft:jungle_stairs",properties:{half:"top",shape:"straight",facing:"east"}}}
:enddata
:endrule

rule:
plugin=vanillaBlocks
number=7
data:
JSON:{blockState:{blockName:"minecraft:wooden_slab",properties:{half:"bottom",variant:"jungle"}}}
:enddata
:endrule

rule:
plugin=vanillaBlocks
number=8
data:
JSON:{blockState:{blockName:"minecraft:planks",properties:{variant:"jungle"}}}
:enddata
:endrule

rule:
plugin=vanillaBlocks
number=9
data:
JSON:{blockState:{blockName:"minecraft:jungle_fence",properties:{east:"false",south:"false",north:"false",west:"false"}}}
:enddata
:endrule

rule:
plugin=vanillaBlocks
number=10
data:
JSON:{blockState:{blockName:"minecraft:jungle_stairs",properties:{half:"top",shape:"straight",facing:"north"}}}
:enddata
:endrule

rule:
plugin=vanillaBlocks
number=11
data:
JSON:{blockState:{blockName:"minecraft:jungle_stairs",properties:{half:"bottom",shape:"straight",facing:"east"}}}
:enddata
:endrule

rule:
plugin=vanillaBlocks
number=12
data:
JSON:{blockState:{blockName:"minecraft:jungle_stairs",properties:{half:"bottom",shape:"straight",facing:"north"}}}
:enddata
:endrule

rule:
plugin=vanillaBlocks
number=13
data:
JSON:{blockState:{blockName:"minecraft:torch",properties:{facing:"west"}}}
:enddata
:endrule

rule:
plugin=vanillaBlocks
number=14
data:
JSON:{blockState:{blockName:"minecraft:torch",properties:{facing:"east"}}}
:enddata
:endrule

rule:
plugin=vanillaBlocks
number=15
data:
JSON:{blockState:{blockName:"minecraft:torch",properties:{facing:"north"}}}
:enddata
:endrule

rule:
plugin=vanillaBlocks
number=16
data:
JSON:{blockState:{blockName:"minecraft:stone_slab",properties:{half:"top",variant:"cobblestone"}}}
:enddata
:endrule

rule:
plugin=vanillaBlocks
number=17
data:
JSON:{blockState:{blockName:"minecraft:wooden_slab",properties:{half:"top",variant:"jungle"}}}
:enddata
:endrule

rule:
plugin=vanillaBlocks
number=18
data:
JSON:{blockState:{blockName:"minecraft:log",properties:{variant:"jungle",axis:"x"}}}
:enddata
:endrule

rule:
plugin=vanillaBlocks
number=19
data:
JSON:{blockState:{blockName:"minecraft:jungle_stairs",properties:{half:"top",shape:"straight",facing:"west"}}}
:enddata
:endrule

rule:
plugin=vanillaBlocks
number=20
data:
JSON:{blockState:{blockName:"minecraft:log",properties:{variant:"jungle",axis:"z"}}}
:enddata
:endrule

rule:
plugin=vanillaBlocks
number=21
data:
JSON:{blockState:{blockName:"minecraft:jungle_stairs",properties:{half:"top",shape:"straight",facing:"south"}}}
:enddata
:endrule

rule:
plugin=vanillaBlocks
number=22
data:
JSON:{blockState:{blockName:"minecraft:torch",properties:{facing:"south"}}}
:enddata
:endrule

rule:
plugin=vanillaBlocks
number=23
data:
JSON:{blockState:{blockName:"minecraft:stone_stairs",properties:{half:"top",shape:"straight",facing:"south"}}}
:enddata
:endrule

rule:
plugin=vanillaBlocks
number=24
data:
JSON:{blockState:{blockName:"minecraft:stone_stairs",properties:{half:"bottom",shape:"straight",facing:"north"}}}
:enddata
:endrule

rule:
plugin=vanillaBlocks
number=25
data:
JSON:{blockState:{blockName:"minecraft:jungle_stairs",properties:{half:"bottom",shape:"straight",facing:"west"}}}
:enddata
:endrule

rule:
plugin=vanillaBlocks
number=26
data:
JSON:{blockState:{blockName:"minecraft:jungle_stairs",properties:{half:"bottom",shape:"straight",facing:"south"}}}
:enddata
:endrule

rule:
plugin=vanillaBlocks
number=27
data:
JSON:{blockState:{blockName:"minecraft:stone_stairs",properties:{half:"top",shape:"straight",facing:"north"}}}
:enddata
:endrule

rule:
plugin=vanillaBlocks
number=28
data:
JSON:{blockState:{blockName:"minecraft:stone_stairs",properties:{half:"top",shape:"straight",facing:"west"}}}
:enddata
:endrule

rule:
plugin=vanillaBlocks
number=29
data:
JSON:{blockState:{blockName:"minecraft:stone_stairs",properties:{half:"top",shape:"straight",facing:"east"}}}
:enddata
:endrule

rule:
plugin=vanillaBlocks
number=30
data:
JSON:{blockState:{blockName:"minecraft:torch",properties:{facing:"up"}}}
:enddata
:endrule

rule:
plugin=vanillaBlocks
number=31
data:
JSON:{blockState:{blockName:"minecraft:stone_stairs",properties:{half:"bottom",shape:"straight",facing:"south"}}}
:enddata
:endrule

rule:
plugin=vanillaBlocks
number=32
data:
JSON:{blockState:{blockName:"minecraft:stone_stairs",properties:{half:"bottom",shape:"straight",facing:"east"}}}
:enddata
:endrule

rule:
plugin=vanillaBlocks
number=33
data:
JSON:{blockState:{blockName:"minecraft:stone_stairs",properties:{half:"bottom",shape:"straight",facing:"west"}}}
:enddata
:endrule

#### ENTITIES ####
