# Ancient Warfare Structure Template File
# Auto-generated structure template file. created on: 4/11/2021 at: 17:31:49
# Lines beginning with # denote comments

header:
version=2.11
name=SurvivalBuild_Moat_type2_angle_cobblestone
mods=
size=16,9,16
offset=0,8,15
:endheader

#### VALIDATION ####
validation:
type=ground
structureAuthor=TheOddlySeagull
survival=true
worldGenEnabled=false
unique=false
preserveBlocks=false
preventNaturalHostileSpawns=false
selectionWeight=1
clusterValue=1
minDuplicateDistance=1
dimensionWhiteList=true
dimensionList=
biomeGroupList=
biomeWhiteList=true
biomeList=
leveling=0
fill=0
border=0
blockSwap=false
territoryName=
biomeReplacement=minecraft:
minGenerationHeight=0
maxGenerationHeight=255
:endvalidation

#### LAYERS ####
layer: 0
1,1,1,1,1,1,1,1,1,1,1,1,1,1,1,1
1,1,1,1,1,1,1,1,1,1,1,1,1,1,1,1
1,1,1,1,1,1,1,1,1,1,1,1,1,1,1,1
1,1,1,1,1,1,1,1,1,1,1,1,1,1,1,1
1,1,1,1,1,1,1,1,1,1,1,1,1,1,1,1
1,1,1,1,1,1,1,1,1,1,1,1,1,1,1,1
1,1,1,1,1,1,1,1,1,1,1,1,1,1,1,1
1,1,1,1,1,1,1,1,1,1,1,1,1,1,1,1
1,1,1,1,1,1,1,1,1,1,1,1,1,1,1,1
1,1,1,1,1,1,1,1,1,1,1,1,1,1,1,1
1,1,1,1,1,1,1,1,1,1,1,1,1,1,1,1
1,1,1,1,1,1,1,1,1,1,1,1,1,1,1,1
1,1,1,1,1,1,1,1,1,1,1,1,1,1,1,1
1,1,1,1,1,1,1,1,1,1,1,1,1,1,1,1
1,1,1,1,1,1,1,1,1,1,1,1,1,1,1,1
1,1,1,1,1,1,1,1,1,1,1,1,1,1,1,1
:endlayer
layer: 1
1,1,1,0,0,0,0,0,0,0,0,0,0,1,1,1
1,1,0,0,0,0,0,0,0,0,0,0,0,0,1,1
1,1,0,0,0,0,0,0,0,0,0,0,0,0,0,1
1,1,0,0,0,0,0,0,0,0,0,0,0,0,0,0
1,1,0,0,0,0,0,0,0,0,0,0,0,0,0,0
1,1,0,0,0,0,0,0,0,0,0,0,0,0,0,0
1,1,0,0,0,0,0,0,0,0,0,0,0,0,0,0
1,1,1,0,0,0,0,0,0,0,0,0,0,0,0,0
1,1,1,0,0,0,0,0,0,0,0,0,0,0,0,0
1,1,0,0,0,0,0,0,0,0,0,0,0,0,0,0
1,1,0,0,0,0,0,0,0,0,0,0,0,0,0,0
1,1,0,0,0,0,0,0,0,0,0,0,0,0,0,0
1,1,0,0,0,0,0,0,0,0,0,0,0,0,0,0
1,1,0,0,0,0,0,1,1,0,0,0,0,0,0,1
1,1,1,1,1,1,1,1,1,1,1,1,1,1,1,1
1,1,1,1,1,1,1,1,1,1,1,1,1,1,1,1
:endlayer
layer: 2
1,1,1,0,0,0,0,0,0,0,0,0,0,1,1,1
1,1,0,0,0,0,0,0,0,0,0,0,0,0,1,1
1,1,0,0,0,0,0,0,0,0,0,0,0,0,0,1
1,1,0,0,0,0,0,0,0,0,0,0,0,0,0,0
1,1,0,0,0,0,0,0,0,0,0,0,0,0,0,0
1,1,0,0,0,0,0,0,0,0,0,0,0,0,0,0
1,1,0,0,0,0,0,0,0,0,0,0,0,0,0,0
1,1,1,0,0,0,0,0,0,0,0,0,0,0,0,0
1,1,1,0,0,0,0,0,0,0,0,0,0,0,0,0
1,1,0,0,0,0,0,0,0,0,0,0,0,0,0,0
1,1,0,0,0,0,0,0,0,0,0,0,0,0,0,0
1,1,0,0,0,0,0,0,0,0,0,0,0,0,0,0
1,1,0,0,0,0,0,0,0,0,0,0,0,0,0,0
1,1,0,0,0,0,0,1,1,0,0,0,0,0,0,1
1,1,1,1,1,1,1,1,1,1,1,1,1,1,1,1
1,1,1,1,1,1,1,1,1,1,1,1,1,1,1,1
:endlayer
layer: 3
1,1,1,0,0,0,0,0,0,0,0,0,0,1,1,1
1,1,0,0,0,0,0,0,0,0,0,0,0,0,1,1
1,1,0,0,0,0,0,0,0,0,0,0,0,0,0,1
1,1,0,0,0,0,0,0,0,0,0,0,0,0,0,0
1,1,0,0,0,0,0,0,0,0,0,0,0,0,0,0
1,1,0,0,0,0,0,0,0,0,0,0,0,0,0,0
1,1,0,0,0,0,0,0,0,0,0,0,0,0,0,0
1,1,1,0,0,0,0,0,0,0,0,0,0,0,0,0
1,1,1,0,0,0,0,0,0,0,0,0,0,0,0,0
1,1,0,0,0,0,0,0,0,0,0,0,0,0,0,0
1,1,0,0,0,0,0,0,0,0,0,0,0,0,0,0
1,1,0,0,0,0,0,0,0,0,0,0,0,0,0,0
1,1,0,0,0,0,0,0,0,0,0,0,0,0,0,0
1,1,0,0,0,0,0,1,1,0,0,0,0,0,0,1
1,1,1,1,1,1,1,1,1,1,1,1,1,1,1,1
1,1,1,1,1,1,1,1,1,1,1,1,1,1,1,1
:endlayer
layer: 4
1,1,1,0,0,0,0,0,0,0,0,0,0,1,1,1
1,1,0,0,0,0,0,0,0,0,0,0,0,0,1,1
1,1,0,0,0,0,0,0,0,0,0,0,0,0,0,1
1,1,0,0,0,0,0,0,0,0,0,0,0,0,0,0
1,1,0,0,0,0,0,0,0,0,0,0,0,0,0,0
1,1,0,0,0,0,0,0,0,0,0,0,0,0,0,0
1,1,0,0,0,0,0,0,0,0,0,0,0,0,0,0
1,1,1,0,0,0,0,0,0,0,0,0,0,0,0,0
1,1,1,0,0,0,0,0,0,0,0,0,0,0,0,0
1,1,0,0,0,0,0,0,0,0,0,0,0,0,0,0
1,1,0,0,0,0,0,0,0,0,0,0,0,0,0,0
1,1,0,0,0,0,0,0,0,0,0,0,0,0,0,0
1,1,0,0,0,0,0,0,0,0,0,0,0,0,0,0
1,1,0,0,0,0,0,1,1,0,0,0,0,0,0,1
1,1,1,1,1,1,1,1,1,1,1,1,1,1,1,1
1,1,1,1,1,1,1,1,1,1,1,1,1,1,1,1
:endlayer
layer: 5
1,1,1,0,0,0,0,0,0,0,0,0,0,1,1,1
1,1,0,0,0,0,0,0,0,0,0,0,0,0,1,1
1,1,0,0,0,0,0,0,0,0,0,0,0,0,0,1
1,1,0,0,0,0,0,0,0,0,0,0,0,0,0,0
1,1,0,0,0,0,0,0,0,0,0,0,0,0,0,0
1,1,0,0,0,0,0,0,0,0,0,0,0,0,0,0
1,1,0,0,0,0,0,0,0,0,0,0,0,0,0,0
1,1,1,0,0,0,0,0,0,0,0,0,0,0,0,0
1,1,1,0,0,0,0,0,0,0,0,0,0,0,0,0
1,1,0,0,0,0,0,0,0,0,0,0,0,0,0,0
1,1,0,0,0,0,0,0,0,0,0,0,0,0,0,0
1,1,0,0,0,0,0,0,0,0,0,0,0,0,0,0
1,1,0,0,0,0,0,0,0,0,0,0,0,0,0,0
1,1,0,0,0,0,0,1,1,0,0,0,0,0,0,1
1,1,1,1,1,1,1,1,1,1,1,1,1,1,1,1
1,1,1,1,1,1,1,1,1,1,1,1,1,1,1,1
:endlayer
layer: 6
1,1,1,0,0,0,0,0,0,0,0,0,0,1,1,1
1,1,0,0,0,0,0,0,0,0,0,0,0,0,1,1
1,1,0,0,0,0,0,0,0,0,0,0,0,0,0,1
1,1,0,0,0,0,0,0,0,0,0,0,0,0,0,0
1,1,0,0,0,0,0,0,0,0,0,0,0,0,0,0
1,1,0,0,0,0,0,0,0,0,0,0,0,0,0,0
1,1,0,0,0,0,0,0,0,0,0,0,0,0,0,0
1,1,1,0,0,0,0,0,0,0,0,0,0,0,0,0
1,1,1,0,0,0,0,0,0,0,0,0,0,0,0,0
1,1,0,0,0,0,0,0,0,0,0,0,0,0,0,0
1,1,0,0,0,0,0,0,0,0,0,0,0,0,0,0
1,1,0,0,0,0,0,0,0,0,0,0,0,0,0,0
1,1,0,0,0,0,0,0,0,0,0,0,0,0,0,0
1,1,0,0,0,0,0,1,1,0,0,0,0,0,0,1
1,1,1,1,1,1,1,1,1,1,1,1,1,1,1,1
1,1,1,1,1,1,1,1,1,1,1,1,1,1,1,1
:endlayer
layer: 7
1,1,1,2,0,0,0,0,0,0,0,0,3,1,1,1
4,1,5,0,0,0,0,0,0,0,0,0,0,5,1,1
4,1,2,0,0,0,0,0,0,0,0,0,0,0,5,1
4,1,5,0,0,0,0,0,0,0,0,0,0,0,0,6
4,1,5,0,0,0,0,0,0,0,0,0,0,0,0,0
4,1,2,0,0,0,0,0,0,0,0,0,0,0,0,0
4,1,5,0,0,0,0,0,0,0,0,0,0,0,0,0
1,1,1,2,0,0,0,0,0,0,0,0,0,0,0,0
1,1,1,2,0,0,0,0,0,0,0,0,0,0,0,0
4,1,5,0,0,0,0,0,0,0,0,0,0,0,0,0
4,1,2,0,0,0,0,0,0,0,0,0,0,0,0,0
4,1,5,0,0,0,0,0,0,0,0,0,0,0,0,0
4,1,5,0,0,0,0,7,7,0,0,0,0,0,0,7
4,1,1,5,5,7,5,1,1,5,7,5,5,7,5,1
4,1,1,1,1,1,1,1,1,1,1,1,1,1,1,1
4,4,4,4,4,4,4,1,1,4,4,4,4,4,4,1
:endlayer
layer: 8
8,1,1,9,0,0,0,0,0,0,0,0,8,1,1,10
0,0,10,0,0,0,0,0,0,0,0,0,0,10,1,1
0,0,10,0,0,0,0,0,0,0,0,0,0,0,10,1
0,0,10,0,0,0,0,0,0,0,0,0,0,0,0,11
0,0,10,0,0,0,0,0,0,0,0,0,0,0,0,0
0,0,10,0,0,0,0,0,0,0,0,0,0,0,0,0
0,0,10,0,0,0,0,0,0,0,0,0,0,0,0,0
8,1,1,9,0,0,0,0,0,0,0,0,0,0,0,0
8,1,1,9,0,0,0,0,0,0,0,0,0,0,0,0
0,0,10,0,0,0,0,0,0,0,0,0,0,0,0,0
0,0,10,0,0,0,0,0,0,0,0,0,0,0,0,0
0,0,10,0,0,0,0,0,0,0,0,0,0,0,0,0
0,0,10,0,0,0,0,12,12,0,0,0,0,0,0,12
0,0,10,10,10,10,10,1,1,10,10,10,10,10,10,1
0,0,0,0,0,0,0,1,1,0,0,0,0,0,0,1
0,0,0,0,0,0,0,11,11,0,0,0,0,0,0,11
:endlayer

#### RULES ####
rule:
plugin=vanillaBlocks
number=1
data:
JSON:{blockState:{blockName:"minecraft:cobblestone"}}
:enddata
:endrule

rule:
plugin=vanillaBlocks
number=2
data:
JSON:{blockState:{blockName:"minecraft:stone_stairs",properties:{half:"top",shape:"straight",facing:"west"}}}
:enddata
:endrule

rule:
plugin=vanillaBlocks
number=3
data:
JSON:{blockState:{blockName:"minecraft:stone_stairs",properties:{half:"top",shape:"straight",facing:"east"}}}
:enddata
:endrule

rule:
plugin=vanillaBlocks
number=4
data:
JSON:{blockState:{blockName:"minecraft:grass",properties:{snowy:"false"}}}
:enddata
:endrule

rule:
plugin=vanillaBlocks
number=5
data:
JSON:{blockState:{blockName:"minecraft:stone_slab",properties:{half:"top",variant:"cobblestone"}}}
:enddata
:endrule

rule:
plugin=vanillaBlocks
number=6
data:
JSON:{blockState:{blockName:"minecraft:stone_stairs",properties:{half:"top",shape:"straight",facing:"north"}}}
:enddata
:endrule

rule:
plugin=vanillaBlocks
number=7
data:
JSON:{blockState:{blockName:"minecraft:stone_stairs",properties:{half:"top",shape:"straight",facing:"south"}}}
:enddata
:endrule

rule:
plugin=vanillaBlocks
number=8
data:
JSON:{blockState:{blockName:"minecraft:stone_stairs",properties:{half:"bottom",shape:"straight",facing:"east"}}}
:enddata
:endrule

rule:
plugin=vanillaBlocks
number=9
data:
JSON:{blockState:{blockName:"minecraft:stone_stairs",properties:{half:"bottom",shape:"straight",facing:"west"}}}
:enddata
:endrule

rule:
plugin=vanillaBlocks
number=10
data:
JSON:{blockState:{blockName:"minecraft:stone_slab",properties:{half:"bottom",variant:"cobblestone"}}}
:enddata
:endrule

rule:
plugin=vanillaBlocks
number=11
data:
JSON:{blockState:{blockName:"minecraft:stone_stairs",properties:{half:"bottom",shape:"straight",facing:"north"}}}
:enddata
:endrule

rule:
plugin=vanillaBlocks
number=12
data:
JSON:{blockState:{blockName:"minecraft:stone_stairs",properties:{half:"bottom",shape:"straight",facing:"south"}}}
:enddata
:endrule

#### ENTITIES ####
