# Ancient Warfare Structure Template File
# Auto-generated structure template file. created on: 3/12/2021 at: 23:54:2
# Lines beginning with # denote comments

header:
version=2.11
name=SB_T3wall2_Angle_Bastion_jacaranda
mods=biomesoplenty
size=16,19,16
offset=15,4,15
:endheader

#### VALIDATION ####
validation:
type=ground
structureAuthor=TheOddlySeagull
survival=true
worldGenEnabled=false
unique=false
preserveBlocks=false
preventNaturalHostileSpawns=false
selectionWeight=1
clusterValue=1
minDuplicateDistance=1
dimensionWhiteList=true
dimensionList=
biomeGroupList=
biomeWhiteList=true
biomeList=
leveling=0
fill=0
border=0
blockSwap=false
territoryName=
biomeReplacement=minecraft:
minGenerationHeight=0
maxGenerationHeight=255
:endvalidation

#### LAYERS ####
layer: 0
1,1,1,1,1,2,2,2,2,2,2,2,2,2,2,1
1,1,1,1,1,2,2,2,2,2,2,2,2,2,2,1
1,1,1,1,1,2,2,2,2,2,2,2,2,2,2,1
1,1,1,1,1,2,2,2,2,2,2,2,2,2,2,1
1,1,1,1,1,2,2,2,2,2,2,2,2,2,2,1
2,2,2,2,2,2,2,2,2,2,2,2,2,2,2,1
2,2,2,2,2,2,2,2,2,2,2,2,2,2,2,1
2,2,2,2,2,2,2,2,2,2,2,2,2,2,2,1
2,2,2,2,2,2,2,2,2,2,2,2,2,2,2,1
2,2,2,2,2,2,2,2,2,2,2,2,2,2,2,1
2,2,2,2,2,2,2,2,2,2,2,2,2,2,2,1
2,2,2,2,2,2,2,2,2,2,2,2,2,2,2,1
2,2,2,2,2,2,2,2,2,2,2,2,2,2,2,1
2,2,2,2,2,2,2,2,2,2,2,2,2,2,2,1
2,2,2,2,2,2,2,2,2,2,2,2,2,2,2,1
1,1,1,1,1,1,1,1,1,1,1,1,1,1,1,1
:endlayer
layer: 1
1,1,1,1,1,2,2,2,2,2,0,0,0,0,2,1
1,1,1,1,1,2,2,2,2,2,0,0,0,0,2,1
1,1,1,1,1,2,2,2,2,2,0,0,0,0,2,1
1,1,1,1,1,2,2,2,2,2,0,0,0,0,2,1
1,1,1,1,1,2,2,2,2,2,0,0,0,0,2,1
2,2,2,2,2,2,2,2,2,2,2,0,0,0,2,1
2,2,2,2,2,2,2,2,2,2,2,2,0,0,2,1
2,2,2,2,2,2,2,2,2,2,2,2,0,0,2,1
2,2,2,2,2,2,2,2,2,2,2,2,0,0,2,1
2,2,2,2,2,2,2,2,2,2,2,2,0,0,2,1
0,0,0,0,0,2,2,2,2,2,2,0,0,0,2,1
0,0,0,0,0,0,2,2,2,2,0,0,0,0,2,1
0,0,0,0,0,0,0,0,0,0,0,0,0,0,2,1
0,0,0,0,0,0,0,0,0,0,0,0,0,0,2,1
2,2,2,2,2,2,2,2,2,2,2,2,2,2,2,1
1,1,1,1,1,1,1,1,1,1,1,1,1,1,1,1
:endlayer
layer: 2
1,1,1,1,1,2,2,2,2,2,0,0,0,0,2,1
1,1,1,1,1,2,2,2,2,2,0,0,0,0,2,1
1,1,1,1,1,2,2,2,2,2,0,0,0,0,2,1
1,1,1,1,1,2,2,2,2,2,0,0,0,0,2,1
1,1,1,1,1,2,2,2,2,2,0,0,0,0,2,1
2,2,2,2,2,2,2,2,2,2,2,0,0,0,2,1
2,2,2,2,2,2,2,2,2,2,2,2,0,0,2,1
2,2,2,2,2,2,2,2,2,2,2,2,0,0,2,1
2,2,2,2,2,2,2,2,2,2,2,2,0,0,2,1
2,2,2,2,2,2,2,2,2,2,2,2,0,0,2,1
0,0,0,0,0,2,2,2,2,2,2,0,0,0,2,1
0,0,0,0,0,0,2,2,2,2,0,0,0,0,2,1
0,0,0,0,0,0,0,0,0,0,0,0,0,0,2,1
0,0,0,0,0,0,0,0,0,0,0,0,0,0,2,1
2,2,2,2,2,2,2,2,2,2,2,2,2,2,2,1
1,1,1,1,1,1,1,1,1,1,1,1,1,1,1,1
:endlayer
layer: 3
3,3,3,3,3,2,2,2,2,2,0,0,0,0,2,3
3,3,3,1,1,2,2,2,2,2,0,0,0,0,2,3
3,3,2,2,2,2,2,2,2,2,0,0,0,0,2,3
3,1,2,2,2,2,2,2,2,2,0,0,0,0,2,3
3,1,2,2,2,2,2,2,2,2,0,0,0,0,2,3
2,2,2,2,2,2,2,2,2,2,2,0,0,0,2,3
2,2,2,2,2,2,2,2,2,2,2,2,0,0,2,3
2,2,2,2,2,2,2,2,2,2,2,2,0,0,2,3
2,2,2,2,2,2,2,2,2,2,2,2,0,0,2,3
2,2,2,2,2,2,2,2,2,2,2,2,0,0,2,3
0,0,0,0,0,2,2,2,2,2,2,0,0,0,2,3
0,0,0,0,0,0,2,2,2,2,0,0,0,0,2,3
0,0,0,0,0,0,0,0,0,0,0,0,0,0,2,3
0,0,0,0,0,0,0,0,0,0,0,0,0,0,2,3
2,2,2,2,2,2,2,2,2,2,2,2,2,2,2,3
3,3,3,3,3,3,3,3,3,3,3,3,3,3,3,3
:endlayer
layer: 4
0,0,0,0,9,5,2,2,2,5,0,0,0,0,2,0
0,0,0,5,8,8,2,2,2,10,0,0,0,0,4,0
0,0,0,0,0,7,2,2,2,10,0,0,0,0,4,0
0,5,0,0,4,5,2,2,2,5,0,0,0,0,2,0
9,8,0,4,4,4,2,2,2,2,0,0,0,0,2,0
5,8,7,5,4,2,2,2,2,2,2,0,0,0,4,0
2,2,2,2,2,2,2,2,2,2,2,2,0,0,4,0
2,2,2,2,2,2,2,2,2,2,2,2,0,0,2,0
2,2,2,2,2,2,2,2,2,2,2,2,0,0,2,0
5,6,6,5,2,2,2,2,2,2,2,2,0,0,4,0
0,0,0,0,0,2,2,2,2,2,2,0,0,0,4,0
0,0,0,0,0,0,2,2,2,2,0,0,0,0,2,0
0,0,0,0,0,0,0,0,0,0,0,0,0,0,2,0
0,0,0,0,0,0,0,0,0,0,0,0,0,0,4,0
2,4,4,2,2,4,4,2,2,4,4,2,2,4,4,0
0,0,0,0,0,0,0,0,0,0,0,0,0,0,0,0
:endlayer
layer: 5
0,0,0,0,9,5,2,2,2,5,0,0,0,0,4,0
0,0,0,5,8,8,2,2,2,12,0,0,0,0,0,0
0,0,0,0,0,0,2,2,2,12,0,0,0,0,0,0
0,5,0,0,0,5,2,2,2,5,0,0,0,0,4,0
9,8,0,0,0,0,2,2,2,2,0,0,0,0,4,0
5,8,0,5,0,0,0,4,2,2,2,0,0,0,0,0
2,2,2,2,2,0,0,4,2,2,2,2,0,0,0,0
2,2,2,2,2,2,2,5,2,2,2,2,0,0,4,0
2,2,2,2,2,2,2,2,2,2,2,2,0,0,4,0
5,11,11,5,2,2,2,2,2,2,2,2,0,0,0,0
0,0,0,0,0,2,2,2,2,2,2,0,0,0,0,0
0,0,0,0,0,0,2,2,2,2,0,0,0,0,4,0
0,0,0,0,0,0,0,0,0,0,0,0,0,0,4,0
0,0,0,0,0,0,0,0,0,0,0,0,0,0,0,0
4,0,0,4,4,0,0,4,4,0,0,4,4,0,0,0
0,0,0,0,0,0,0,0,0,0,0,0,0,0,0,0
:endlayer
layer: 6
0,0,0,14,9,5,2,2,2,5,0,0,0,0,0,0
0,0,0,5,8,8,2,2,2,0,0,0,0,0,0,0
0,0,0,0,0,0,2,2,2,0,0,0,0,0,0,0
15,5,0,0,15,5,2,2,2,5,0,0,0,0,0,0
9,8,0,14,0,0,2,2,2,2,0,0,0,0,0,0
5,8,0,5,0,0,0,13,0,2,2,0,0,0,0,0
2,2,2,2,2,0,0,0,0,0,2,2,0,0,0,0
2,2,2,2,2,2,2,5,4,4,2,2,0,0,0,0
2,2,2,2,2,2,2,2,2,2,2,2,0,0,0,0
5,0,0,5,2,2,2,2,2,2,2,2,0,0,0,0
0,0,0,0,0,2,2,2,2,2,2,0,0,0,0,0
0,0,0,0,0,0,2,2,2,2,0,0,0,0,0,0
0,0,0,0,0,0,0,0,0,0,0,0,0,0,0,0
0,0,0,0,0,0,0,0,0,0,0,0,0,0,0,0
0,0,0,0,0,0,0,0,0,0,0,0,0,0,0,0
0,0,0,0,0,0,0,0,0,0,0,0,0,0,0,0
:endlayer
layer: 7
0,0,17,17,21,5,2,2,2,5,0,0,0,0,0,0
0,17,17,5,20,20,2,2,2,0,0,0,0,0,0,0
17,17,5,17,17,17,2,2,2,0,0,0,0,0,0,0
17,5,17,0,0,5,2,2,2,5,0,0,0,0,0,0
19,18,17,0,0,2,2,2,2,2,0,0,0,0,0,0
5,18,17,5,2,16,16,0,0,2,2,0,0,0,0,0
2,2,2,2,2,16,16,0,0,0,2,2,0,0,0,0
2,2,2,2,2,2,2,5,0,15,2,2,0,0,0,0
2,2,2,2,2,2,2,4,0,0,2,2,0,0,0,0
5,0,0,5,2,2,2,4,0,2,2,2,0,0,0,0
0,0,0,0,0,2,2,2,2,2,2,0,0,0,0,0
0,0,0,0,0,0,2,2,2,2,0,0,0,0,0,0
0,0,0,0,0,0,0,0,0,0,0,0,0,0,0,0
0,0,0,0,0,0,0,0,0,0,0,0,0,0,0,0
0,0,0,0,0,0,0,0,0,0,0,0,0,0,0,0
0,0,0,0,0,0,0,0,0,0,0,0,0,0,0,0
:endlayer
layer: 8
0,0,0,0,0,5,2,2,2,5,0,0,0,0,0,0
0,0,0,7,7,7,2,2,2,0,0,0,0,0,0,0
0,0,7,7,8,8,2,2,2,0,0,0,0,0,0,0
0,7,7,8,8,5,2,2,2,5,0,0,0,0,0,0
0,7,8,8,8,2,2,2,2,2,0,0,0,0,0,0
5,7,8,5,2,2,2,2,16,2,2,0,0,0,0,0
2,2,2,2,2,2,2,2,16,16,2,2,0,0,0,0
2,2,2,2,2,4,4,5,0,0,2,2,0,0,0,0
2,2,2,2,2,0,0,0,0,0,2,2,0,0,0,0
5,0,0,5,2,2,0,14,0,2,2,2,0,0,0,0
0,0,0,0,0,2,2,2,2,2,2,0,0,0,0,0
0,0,0,0,0,0,2,2,2,2,0,0,0,0,0,0
0,0,0,0,0,0,0,0,0,0,0,0,0,0,0,0
0,0,0,0,0,0,0,0,0,0,0,0,0,0,0,0
0,0,0,0,0,0,0,0,0,0,0,0,0,0,0,0
0,0,0,0,0,0,0,0,0,0,0,0,0,0,0,0
:endlayer
layer: 9
0,0,0,0,0,5,2,2,2,5,0,0,0,0,0,0
0,0,0,0,0,6,2,2,2,6,0,0,0,0,0,0
0,0,0,0,0,19,2,2,2,19,0,0,0,0,0,0
0,0,0,0,0,5,2,2,2,5,0,0,0,0,0,0
0,0,0,0,8,2,2,2,2,2,0,0,0,0,0,0
5,10,21,5,2,2,0,4,4,2,2,0,0,0,0,0
2,2,2,2,2,0,0,4,4,2,2,2,0,0,0,0
2,2,2,2,2,22,0,5,2,2,2,2,10,0,0,0
2,2,2,2,2,0,0,0,16,2,2,2,10,0,0,0
5,10,21,5,2,2,0,0,16,2,2,2,0,0,0,0
0,0,0,0,0,2,2,2,2,2,2,0,0,0,0,0
0,0,0,0,0,0,2,2,2,2,0,0,0,0,0,0
0,0,0,0,0,0,0,6,6,0,0,0,0,0,0,0
0,0,0,0,0,0,0,0,0,0,0,0,0,0,0,0
0,0,0,0,0,0,0,0,0,0,0,0,0,0,0,0
0,0,0,0,0,0,0,0,0,0,0,0,0,0,0,0
:endlayer
layer: 10
0,0,0,0,21,5,2,2,2,5,10,0,0,0,0,0
0,0,0,0,17,18,2,2,2,18,17,0,0,0,0,0
0,0,0,0,17,18,2,2,2,18,17,0,0,0,0,0
0,0,0,17,21,18,2,4,4,18,10,0,0,0,0,0
19,17,17,19,5,2,2,0,0,2,10,0,0,0,0,0
20,20,20,20,2,2,0,0,0,0,2,9,0,0,0,0
2,2,2,2,2,0,0,14,0,0,4,2,10,0,0,0
2,2,2,2,2,0,15,5,22,0,4,2,8,0,0,0
2,2,2,2,2,0,0,23,24,4,4,2,8,0,0,0
20,20,20,20,2,2,0,23,4,4,4,2,10,0,0,0
6,17,17,6,6,2,2,2,4,4,2,9,0,0,0,0
0,0,0,0,0,9,2,2,2,2,9,0,0,0,0,0
0,0,0,0,0,0,6,8,8,6,0,0,0,0,0,0
0,0,0,0,0,0,0,0,0,0,0,0,0,0,0,0
0,0,0,0,0,0,0,0,0,0,0,0,0,0,0,0
0,0,0,0,0,0,0,0,0,0,0,0,0,0,0,0
:endlayer
layer: 11
0,0,0,0,8,5,0,0,0,5,8,0,0,0,0,0
0,0,0,0,26,0,0,0,0,0,12,0,0,0,0,0
0,0,0,0,8,0,0,0,0,0,12,0,0,0,0,0
0,0,0,8,0,0,0,0,0,0,8,0,0,0,0,0
8,25,8,0,0,0,2,0,0,2,5,0,0,0,0,0
5,0,0,0,0,2,0,0,0,0,2,9,0,0,0,0
0,0,0,0,2,0,0,0,0,0,0,2,5,0,0,0
0,0,0,0,2,0,0,7,0,0,0,0,12,0,0,0
0,0,0,0,2,17,17,5,0,0,0,0,12,0,0,0
5,0,0,0,2,7,7,0,0,0,0,2,5,0,0,0
8,11,11,8,5,2,7,0,0,0,2,9,0,0,0,0
0,0,0,0,0,9,2,0,0,2,9,0,0,0,0,0
0,0,0,0,0,0,5,11,11,5,0,0,0,0,0,0
0,0,0,0,0,0,0,0,0,0,0,0,0,0,0,0
0,0,0,0,0,0,0,0,0,0,0,0,0,0,0,0
0,0,0,0,0,0,0,0,0,0,0,0,0,0,0,0
:endlayer
layer: 12
0,0,0,0,8,5,0,0,0,5,8,0,0,0,0,0
0,0,0,0,0,0,0,0,0,0,0,0,0,0,0,0
0,0,0,0,8,0,0,0,0,0,0,0,0,0,0,0
0,0,0,8,0,0,0,0,0,0,8,0,0,0,0,0
8,0,8,0,0,0,2,0,0,2,5,0,0,0,0,0
5,0,0,0,0,2,22,0,0,15,2,9,0,0,0,0
0,0,0,0,2,7,7,17,0,0,13,2,5,0,0,0
0,0,0,0,2,7,7,17,0,0,0,0,0,0,0,0
0,0,0,0,2,0,0,5,0,0,0,0,0,0,0,0
5,0,0,0,2,14,0,0,0,0,14,2,5,0,0,0
8,0,0,8,5,2,22,0,0,15,2,9,0,0,0,0
0,0,0,0,0,9,2,0,0,2,9,0,0,0,0,0
0,0,0,0,0,0,5,0,0,5,0,0,0,0,0,0
0,0,0,0,0,0,0,0,0,0,0,0,0,0,0,0
0,0,0,0,0,0,0,0,0,0,0,0,0,0,0,0
0,0,0,0,0,0,0,0,0,0,0,0,0,0,0,0
:endlayer
layer: 13
0,0,0,0,8,5,10,0,21,5,8,0,0,0,0,0
0,0,0,0,17,13,0,0,0,13,17,0,0,0,0,0
0,0,0,0,8,0,0,0,0,0,17,0,0,0,0,0
0,0,0,8,0,0,0,0,0,0,8,0,0,0,0,0
8,17,8,0,0,0,2,27,23,2,5,0,0,0,0,0
5,22,0,0,0,2,0,0,0,0,2,9,0,0,0,0
6,0,0,0,2,0,0,0,7,7,0,2,5,0,0,0
0,0,0,0,2,0,0,0,7,7,0,0,17,0,0,0
19,0,0,0,2,0,0,5,17,17,0,0,17,0,0,0
5,22,0,0,2,0,0,0,0,0,0,2,5,0,0,0
8,17,17,8,5,2,0,0,0,0,2,9,0,0,0,0
0,0,0,0,0,9,2,0,0,2,9,0,0,0,0,0
0,0,0,0,0,0,5,17,17,5,0,0,0,0,0,0
0,0,0,0,0,0,0,0,0,0,0,0,0,0,0,0
0,0,0,0,0,0,0,0,0,0,0,0,0,0,0,0
0,0,0,0,0,0,0,0,0,0,0,0,0,0,0,0
:endlayer
layer: 14
0,0,0,17,18,20,20,20,20,20,18,17,0,0,0,0
0,0,0,17,18,10,0,0,0,21,18,17,0,0,0,0
0,0,17,17,18,10,0,0,0,21,18,17,0,0,0,0
17,17,17,5,6,10,0,0,0,21,18,17,0,0,0,0
20,20,20,6,10,0,2,2,2,2,18,17,0,0,0,0
18,6,6,10,0,2,27,0,0,23,2,10,0,0,0,0
18,0,0,0,2,0,0,0,0,0,29,2,25,0,0,0
18,0,0,0,2,0,0,0,0,0,0,23,12,0,0,0
18,0,0,0,2,0,0,5,0,0,0,23,12,0,0,0
18,19,19,19,2,0,0,17,7,7,28,2,11,0,0,0
20,20,20,20,20,2,0,17,7,7,2,9,0,0,0,0
17,17,17,17,17,6,2,28,28,2,9,0,0,0,0,0
0,0,0,0,0,0,26,11,11,12,0,0,0,0,0,0
0,0,0,0,0,0,0,0,0,0,0,0,0,0,0,0
0,0,0,0,0,0,0,0,0,0,0,0,0,0,0,0
0,0,0,0,0,0,0,0,0,0,0,0,0,0,0,0
:endlayer
layer: 15
0,0,0,0,7,7,8,8,8,7,7,0,0,0,0,0
0,0,0,0,7,7,8,8,8,7,7,0,0,0,0,0
0,0,30,0,7,7,8,8,8,7,7,0,0,0,0,0
0,0,0,7,7,2,2,2,2,2,2,0,0,0,0,0
7,7,7,7,2,2,2,2,2,2,2,28,0,0,0,0
7,7,7,2,2,2,2,2,2,2,2,27,28,0,0,0
8,8,8,2,2,0,0,0,0,0,2,2,27,0,0,0
8,8,8,2,2,0,0,0,0,0,2,2,27,0,0,0
8,8,8,2,2,17,17,5,0,0,2,2,27,0,0,0
7,7,7,2,2,7,7,0,0,0,2,2,27,0,0,0
7,7,7,2,2,2,7,0,0,0,2,29,29,0,0,0
0,0,0,0,23,29,2,2,2,2,29,27,0,0,0,0
0,0,0,0,0,23,29,29,29,29,27,0,0,0,0,0
0,0,0,0,0,0,0,0,0,0,0,0,0,0,0,0
0,0,0,0,0,0,0,0,0,0,0,0,0,0,0,0
0,0,0,0,0,0,0,0,0,0,0,0,0,0,0,0
:endlayer
layer: 16
0,0,0,0,0,0,0,0,0,0,0,0,0,0,0,0
0,0,0,0,0,0,0,30,0,0,0,0,0,0,0,0
0,0,0,0,0,0,28,16,16,28,0,0,0,0,0,0
0,0,0,0,23,2,2,2,2,2,2,27,0,0,0,0
0,0,0,28,2,2,2,2,2,2,2,2,28,0,0,0
0,0,0,2,2,2,32,32,32,32,2,2,2,0,0,0
0,0,23,2,2,7,7,7,7,7,31,2,2,27,0,0
0,30,16,2,2,7,7,7,7,7,31,2,2,16,0,0
0,0,16,2,2,0,15,5,22,0,31,2,2,16,0,0
0,0,23,2,2,0,0,13,0,0,31,2,2,27,0,0
0,0,0,2,2,2,0,0,0,0,2,2,2,0,0,0
0,0,0,29,2,2,2,2,2,2,2,2,29,0,0,0
0,0,0,0,23,2,2,2,2,2,2,27,0,0,0,0
0,0,0,0,0,0,29,16,16,29,0,0,0,0,0,0
0,0,0,0,0,0,0,0,0,0,0,0,0,0,0,0
0,0,0,0,0,0,0,0,0,0,0,0,0,0,0,0
:endlayer
layer: 17
0,0,0,0,0,0,0,0,0,0,0,0,0,0,0,0
0,0,0,0,0,0,0,0,0,0,0,0,0,0,0,0
0,0,0,0,0,0,2,33,33,2,0,0,0,0,0,0
0,0,0,0,2,33,32,0,0,32,33,2,0,0,0,0
0,0,0,2,4,0,0,0,0,0,0,4,2,0,0,0
0,0,0,31,0,0,0,0,0,0,0,0,24,0,0,0
0,0,2,24,0,0,0,0,0,0,0,0,31,2,0,0
0,0,31,0,0,0,0,0,0,0,0,0,0,24,0,0
0,0,31,0,0,0,0,7,0,0,0,0,0,24,0,0
0,0,2,24,0,0,0,0,0,0,0,0,31,2,0,0
0,0,0,31,0,0,0,0,0,0,0,0,24,0,0,0
0,0,0,2,4,0,0,0,0,0,0,4,2,0,0,0
0,0,0,0,2,32,33,0,0,33,32,2,0,0,0,0
0,0,0,0,0,0,2,32,32,2,0,0,0,0,0,0
0,0,0,0,0,0,0,0,0,0,0,0,0,0,0,0
0,0,0,0,0,0,0,0,0,0,0,0,0,0,0,0
:endlayer
layer: 18
0,0,0,0,0,0,0,0,0,0,0,0,0,0,0,0
0,0,0,0,0,0,0,0,0,0,0,0,0,0,0,0
0,0,0,0,0,0,33,0,0,33,0,0,0,0,0,0
0,0,0,0,33,0,0,0,0,0,0,33,0,0,0,0
0,0,0,31,13,0,0,0,0,0,0,15,24,0,0,0
0,0,0,0,0,0,0,0,0,0,0,0,0,0,0,0
0,0,31,0,0,0,0,0,0,0,0,0,0,24,0,0
0,0,0,0,0,0,0,0,0,0,0,0,0,0,0,0
0,0,0,0,0,0,0,0,0,0,0,0,0,0,0,0
0,0,31,0,0,0,0,0,0,0,0,0,0,24,0,0
0,0,0,0,0,0,0,0,0,0,0,0,0,0,0,0
0,0,0,31,22,0,0,0,0,0,0,14,24,0,0,0
0,0,0,0,32,0,0,0,0,0,0,32,0,0,0,0
0,0,0,0,0,0,32,0,0,32,0,0,0,0,0,0
0,0,0,0,0,0,0,0,0,0,0,0,0,0,0,0
0,0,0,0,0,0,0,0,0,0,0,0,0,0,0,0
:endlayer

#### RULES ####
rule:
plugin=vanillaBlocks
number=1
data:
JSON:{blockState:{blockName:"minecraft:dirt",properties:{variant:"dirt",snowy:"false"}}}
:enddata
:endrule

rule:
plugin=vanillaBlocks
number=2
data:
JSON:{blockState:{blockName:"minecraft:cobblestone"}}
:enddata
:endrule

rule:
plugin=vanillaBlocks
number=3
data:
JSON:{blockState:{blockName:"minecraft:grass",properties:{snowy:"false"}}}
:enddata
:endrule

rule:
plugin=vanillaBlocks
number=4
data:
JSON:{blockState:{blockName:"minecraft:stone_slab",properties:{half:"bottom",variant:"cobblestone"}}}
:enddata
:endrule

rule:
plugin=vanillaBlocks
number=5
data:
JSON:{blockState:{blockName:"biomesoplenty:log_3",properties:{variant:"jacaranda",axis:"y"}}}
:enddata
:endrule

rule:
plugin=vanillaBlocks
number=6
data:
JSON:{blockState:{blockName:"biomesoplenty:jacaranda_stairs",properties:{half:"top",shape:"straight",facing:"north"}}}
:enddata
:endrule

rule:
plugin=vanillaBlocks
number=7
data:
JSON:{blockState:{blockName:"biomesoplenty:wood_slab_1",properties:{half:"bottom",variant:"jacaranda"}}}
:enddata
:endrule

rule:
plugin=vanillaBlocks
number=8
data:
JSON:{blockState:{blockName:"biomesoplenty:planks_0",properties:{variant:"jacaranda"}}}
:enddata
:endrule

rule:
plugin=vanillaBlocks
number=9
data:
JSON:{blockState:{blockName:"biomesoplenty:jacaranda_fence",properties:{east:"false",south:"false",north:"false",west:"false"}}}
:enddata
:endrule

rule:
plugin=vanillaBlocks
number=10
data:
JSON:{blockState:{blockName:"biomesoplenty:jacaranda_stairs",properties:{half:"top",shape:"straight",facing:"west"}}}
:enddata
:endrule

rule:
plugin=vanillaBlocks
number=11
data:
JSON:{blockState:{blockName:"biomesoplenty:jacaranda_stairs",properties:{half:"bottom",shape:"straight",facing:"north"}}}
:enddata
:endrule

rule:
plugin=vanillaBlocks
number=12
data:
JSON:{blockState:{blockName:"biomesoplenty:jacaranda_stairs",properties:{half:"bottom",shape:"straight",facing:"west"}}}
:enddata
:endrule

rule:
plugin=vanillaBlocks
number=13
data:
JSON:{blockState:{blockName:"minecraft:torch",properties:{facing:"south"}}}
:enddata
:endrule

rule:
plugin=vanillaBlocks
number=14
data:
JSON:{blockState:{blockName:"minecraft:torch",properties:{facing:"north"}}}
:enddata
:endrule

rule:
plugin=vanillaBlocks
number=15
data:
JSON:{blockState:{blockName:"minecraft:torch",properties:{facing:"west"}}}
:enddata
:endrule

rule:
plugin=vanillaBlocks
number=16
data:
JSON:{blockState:{blockName:"minecraft:stone_slab",properties:{half:"top",variant:"cobblestone"}}}
:enddata
:endrule

rule:
plugin=vanillaBlocks
number=17
data:
JSON:{blockState:{blockName:"biomesoplenty:wood_slab_1",properties:{half:"top",variant:"jacaranda"}}}
:enddata
:endrule

rule:
plugin=vanillaBlocks
number=18
data:
JSON:{blockState:{blockName:"biomesoplenty:log_3",properties:{variant:"jacaranda",axis:"z"}}}
:enddata
:endrule

rule:
plugin=vanillaBlocks
number=19
data:
JSON:{blockState:{blockName:"biomesoplenty:jacaranda_stairs",properties:{half:"top",shape:"straight",facing:"south"}}}
:enddata
:endrule

rule:
plugin=vanillaBlocks
number=20
data:
JSON:{blockState:{blockName:"biomesoplenty:log_3",properties:{variant:"jacaranda",axis:"x"}}}
:enddata
:endrule

rule:
plugin=vanillaBlocks
number=21
data:
JSON:{blockState:{blockName:"biomesoplenty:jacaranda_stairs",properties:{half:"top",shape:"straight",facing:"east"}}}
:enddata
:endrule

rule:
plugin=vanillaBlocks
number=22
data:
JSON:{blockState:{blockName:"minecraft:torch",properties:{facing:"east"}}}
:enddata
:endrule

rule:
plugin=vanillaBlocks
number=23
data:
JSON:{blockState:{blockName:"minecraft:stone_stairs",properties:{half:"top",shape:"straight",facing:"east"}}}
:enddata
:endrule

rule:
plugin=vanillaBlocks
number=24
data:
JSON:{blockState:{blockName:"minecraft:stone_stairs",properties:{half:"bottom",shape:"straight",facing:"west"}}}
:enddata
:endrule

rule:
plugin=vanillaBlocks
number=25
data:
JSON:{blockState:{blockName:"biomesoplenty:jacaranda_stairs",properties:{half:"bottom",shape:"straight",facing:"south"}}}
:enddata
:endrule

rule:
plugin=vanillaBlocks
number=26
data:
JSON:{blockState:{blockName:"biomesoplenty:jacaranda_stairs",properties:{half:"bottom",shape:"straight",facing:"east"}}}
:enddata
:endrule

rule:
plugin=vanillaBlocks
number=27
data:
JSON:{blockState:{blockName:"minecraft:stone_stairs",properties:{half:"top",shape:"straight",facing:"west"}}}
:enddata
:endrule

rule:
plugin=vanillaBlocks
number=28
data:
JSON:{blockState:{blockName:"minecraft:stone_stairs",properties:{half:"top",shape:"straight",facing:"south"}}}
:enddata
:endrule

rule:
plugin=vanillaBlocks
number=29
data:
JSON:{blockState:{blockName:"minecraft:stone_stairs",properties:{half:"top",shape:"straight",facing:"north"}}}
:enddata
:endrule

rule:
plugin=vanillaBlocks
number=30
data:
JSON:{blockState:{blockName:"minecraft:torch",properties:{facing:"up"}}}
:enddata
:endrule

rule:
plugin=vanillaBlocks
number=31
data:
JSON:{blockState:{blockName:"minecraft:stone_stairs",properties:{half:"bottom",shape:"straight",facing:"east"}}}
:enddata
:endrule

rule:
plugin=vanillaBlocks
number=32
data:
JSON:{blockState:{blockName:"minecraft:stone_stairs",properties:{half:"bottom",shape:"straight",facing:"north"}}}
:enddata
:endrule

rule:
plugin=vanillaBlocks
number=33
data:
JSON:{blockState:{blockName:"minecraft:stone_stairs",properties:{half:"bottom",shape:"straight",facing:"south"}}}
:enddata
:endrule

#### ENTITIES ####
