# Ancient Warfare Structure Template File
# Auto-generated structure template file. created on: 4/19/2023 at: 17:45:32
# Lines beginning with # denote comments

header:
version=2.11
name=SB_kennel_large_jungle
mods=
size=28,8,23
offset=3,1,22
:endheader

#### VALIDATION ####
validation:
type=ground
structureAuthor=TheOddlySeagull
survival=true
worldGenEnabled=false
unique=false
preserveBlocks=false
preventNaturalHostileSpawns=false
selectionWeight=1
clusterValue=1
minDuplicateDistance=1
dimensionWhiteList=true
dimensionList=
biomeGroupList=
biomeWhiteList=true
biomeList=
leveling=0
fill=0
border=0
blockSwap=false
territoryName=
biomeReplacement=minecraft:
minGenerationHeight=0
maxGenerationHeight=255
:endvalidation

#### LAYERS ####
layer: 0
1,1,1,1,1,1,1,1,1,1,1,1,1,1,1,1,1,1,1,1,1,1,1,1,1,1,1,1
1,2,3,3,3,2,3,3,2,3,3,2,3,3,2,3,3,2,3,3,2,3,3,2,3,3,2,1
1,3,3,3,3,3,4,3,3,3,4,3,3,4,4,3,4,3,4,4,4,3,3,3,4,3,3,1
1,3,3,3,3,3,4,4,3,3,4,3,4,4,4,3,3,3,4,3,4,4,4,4,4,3,3,1
1,3,3,3,3,3,3,3,2,4,3,3,3,3,4,3,3,4,3,3,4,3,3,3,4,3,2,1
1,2,3,3,3,2,4,4,3,4,4,4,4,3,3,3,3,3,3,3,4,4,3,4,3,3,3,1
1,3,3,3,3,3,3,3,3,3,3,4,3,4,4,3,4,3,4,3,4,3,4,3,4,3,3,1
1,3,3,3,3,3,4,4,2,4,4,2,3,3,2,3,3,2,3,3,2,4,3,3,4,3,2,1
1,3,3,3,3,3,3,3,3,3,3,3,4,4,4,4,1,4,4,4,3,3,4,4,4,4,3,1
1,2,3,3,3,2,3,3,3,3,4,3,1,1,4,4,1,1,4,1,3,3,3,3,4,4,3,1
1,3,4,4,4,1,4,4,2,3,4,2,4,4,4,1,1,1,4,1,2,4,3,4,3,3,2,1
1,3,4,4,1,4,1,1,3,3,3,3,4,4,1,1,4,4,4,4,3,4,4,3,3,4,3,1
1,2,1,1,1,4,1,1,3,3,4,3,1,4,1,4,4,1,1,1,3,4,3,3,4,4,3,1
1,3,1,1,4,1,4,1,2,3,3,2,4,1,1,4,4,4,1,1,2,4,4,4,3,3,2,1
1,3,4,4,4,1,4,1,4,4,1,1,1,4,1,1,1,4,1,4,3,3,3,3,4,3,3,1
1,2,4,4,1,1,4,4,4,4,4,4,1,1,4,1,4,4,1,4,3,4,3,4,4,3,3,1
1,3,1,1,4,4,1,4,1,4,4,4,1,1,1,4,4,4,1,1,2,4,4,3,3,4,2,1
1,3,1,4,4,1,4,1,1,4,1,4,4,1,1,4,1,1,1,1,3,4,3,4,4,4,3,1
1,2,3,3,3,2,4,1,4,1,4,1,4,4,1,1,4,4,4,1,3,3,3,3,3,3,3,1
1,1,1,1,1,3,1,4,1,1,4,1,1,4,4,1,1,4,4,4,2,3,3,2,3,3,2,1
1,1,1,1,1,3,1,1,4,4,1,4,1,1,4,1,1,4,1,4,3,3,3,3,3,3,3,1
1,1,1,1,1,3,4,1,4,4,4,1,4,4,4,1,1,1,4,1,3,3,3,3,3,3,3,1
1,1,1,1,1,2,3,3,2,3,3,2,3,3,2,3,3,2,3,3,2,3,3,2,3,3,2,1
:endlayer
layer: 1
0,0,0,0,0,0,0,0,0,0,0,0,0,0,0,0,0,0,0,0,0,0,0,0,0,0,0,0
0,5,6,6,6,5,3,3,5,6,6,5,8,8,5,8,8,5,8,8,5,8,8,5,6,6,5,0
0,6,0,0,0,6,0,0,9,0,0,0,0,0,0,0,0,0,0,0,0,0,0,0,0,0,6,0
0,6,0,0,0,0,0,0,9,0,0,0,0,0,0,0,0,0,0,0,0,0,0,0,0,0,6,0
0,6,0,0,0,6,0,0,5,0,0,0,0,0,0,0,0,0,0,0,0,0,0,0,0,0,5,0
0,5,0,0,0,5,0,0,9,0,0,0,0,0,0,0,0,0,0,0,0,0,0,0,0,0,7,0
0,6,0,0,0,6,0,0,9,0,0,0,0,0,0,0,0,0,0,0,0,0,0,0,0,0,7,0
0,0,0,0,0,6,0,0,5,0,0,5,0,0,5,11,11,5,0,0,5,0,0,0,0,0,5,0
0,6,0,0,0,6,0,0,6,0,0,0,0,0,0,0,0,0,0,0,9,0,0,0,0,0,7,0
0,5,6,6,6,5,0,0,6,0,0,0,0,0,0,0,0,0,0,0,9,0,0,0,0,0,7,0
0,3,0,0,0,0,0,0,5,0,0,5,0,0,0,0,0,0,0,0,5,0,0,0,0,0,5,0
0,3,0,0,0,0,0,0,9,0,0,0,0,0,0,0,0,0,0,0,0,0,0,0,0,0,7,0
0,2,0,0,0,0,0,0,9,0,0,0,0,0,0,0,0,0,0,0,0,0,0,0,0,0,7,0
0,3,0,0,0,0,0,0,5,11,11,5,0,0,0,0,0,0,0,0,5,0,0,0,0,0,5,0
0,3,0,0,0,0,0,0,0,0,0,0,0,0,0,0,0,0,0,0,0,0,0,0,0,0,7,0
0,2,0,0,0,0,0,0,0,0,0,0,0,0,0,12,0,0,0,0,0,0,0,0,0,0,7,0
0,3,0,0,0,0,0,0,0,0,0,0,0,0,0,0,0,0,0,0,5,0,0,0,0,0,5,0
0,3,0,0,0,0,0,0,0,0,0,0,0,0,0,0,0,0,0,0,9,0,0,0,0,0,6,0
0,2,0,0,0,2,0,0,0,0,0,0,0,0,0,0,0,0,0,0,9,0,0,0,0,0,6,0
0,0,0,0,0,3,0,0,0,0,0,0,0,0,0,0,0,0,0,0,5,6,6,5,6,6,5,0
0,0,0,0,0,3,0,0,0,0,0,0,0,0,0,0,0,0,0,0,10,3,3,3,3,3,7,0
0,0,0,0,0,3,0,0,0,0,0,0,0,0,0,0,0,0,0,0,10,3,3,3,3,3,7,0
12,0,0,0,0,2,3,3,2,3,3,2,3,3,2,3,3,2,3,3,5,6,6,5,6,6,5,0
:endlayer
layer: 2
0,0,0,0,0,0,0,0,0,0,0,0,0,0,0,0,0,0,0,0,0,0,0,0,0,0,0,0
0,5,6,12,6,5,12,12,5,6,6,5,8,8,5,8,8,5,8,8,5,8,8,5,6,6,5,0
0,6,0,0,0,6,0,0,9,0,0,0,0,0,0,0,0,0,0,0,0,0,0,0,0,0,6,0
0,12,0,0,0,0,0,0,9,0,0,0,0,0,0,0,0,0,0,0,0,0,0,0,0,0,6,0
0,6,0,0,0,6,0,0,5,0,0,0,0,0,0,0,0,0,0,0,0,0,0,0,0,0,5,0
0,5,0,0,0,5,0,0,9,0,0,0,0,0,0,0,0,0,0,0,0,0,0,0,0,0,7,0
0,6,0,0,0,6,0,0,9,0,0,0,0,0,0,0,0,0,0,0,0,0,0,0,0,0,7,0
0,0,0,0,0,6,0,0,5,0,0,5,0,0,5,11,11,5,0,0,5,0,0,0,0,0,5,0
0,6,0,0,0,6,0,0,6,0,0,0,0,0,0,0,0,0,0,0,9,0,0,0,0,0,7,0
0,5,6,12,6,5,0,0,6,0,0,0,0,0,0,0,0,0,0,0,9,0,0,0,0,0,7,0
0,12,0,0,0,0,0,0,5,0,0,5,0,0,0,0,0,0,0,0,5,0,0,0,0,0,5,0
0,12,0,0,0,0,0,0,9,0,0,0,0,0,0,0,0,0,0,0,0,0,0,0,0,0,7,0
0,2,15,0,0,0,0,0,9,0,0,0,0,0,0,0,0,0,0,0,0,0,0,0,0,0,7,0
0,12,0,0,0,0,0,0,5,11,11,5,0,0,0,0,0,0,0,0,5,0,0,0,0,0,5,0
0,12,0,0,0,0,0,0,0,0,0,0,0,0,0,0,0,0,0,0,0,0,0,0,0,0,7,0
0,2,15,0,0,0,0,0,0,0,0,0,0,0,0,14,0,0,0,0,0,0,0,0,0,0,7,0
0,12,0,0,0,0,0,0,0,0,0,0,0,0,0,0,0,0,0,0,5,0,0,0,0,0,5,0
0,12,0,0,0,0,0,0,0,0,0,0,0,0,0,0,0,0,0,0,9,0,0,0,0,0,6,0
0,2,0,0,0,2,15,0,0,0,0,0,0,0,0,0,0,0,0,0,9,0,0,0,0,0,6,0
0,0,0,0,0,12,0,0,0,0,0,0,0,0,0,0,0,0,0,0,5,6,6,5,6,6,5,0
0,0,0,0,0,12,0,0,0,0,0,0,0,0,0,0,0,0,0,0,0,10,3,3,3,3,7,0
0,0,0,0,0,12,0,0,13,0,0,13,0,0,13,0,0,13,0,0,0,10,3,3,3,3,7,0
14,0,0,0,0,2,12,12,2,12,12,2,12,12,2,12,12,2,12,12,5,6,6,5,6,6,5,0
:endlayer
layer: 3
0,13,0,0,0,13,0,0,13,0,0,13,0,0,13,0,0,13,0,0,13,0,0,13,0,0,13,0
16,5,6,12,6,5,22,22,5,6,6,5,8,8,5,12,12,5,12,12,5,8,8,5,6,6,5,15
0,6,0,0,0,6,0,0,9,0,0,18,0,0,18,0,0,18,0,0,18,0,0,18,0,0,6,0
0,12,0,0,0,6,0,0,9,0,0,0,0,0,0,0,0,0,0,0,0,0,0,0,0,0,6,0
0,6,0,0,0,6,0,16,5,15,0,0,0,0,0,0,0,0,0,0,0,0,0,0,0,16,5,15
16,5,15,0,16,5,0,0,9,0,0,0,0,0,0,0,0,0,0,0,0,0,0,0,0,0,7,0
0,6,0,0,0,6,0,0,9,0,0,13,0,0,13,0,0,13,0,0,13,0,0,0,0,0,7,0
0,6,0,0,0,6,0,16,5,15,0,5,19,17,5,11,11,5,19,17,5,19,0,0,0,17,5,15
0,6,0,0,0,6,0,0,6,0,0,20,0,0,18,0,0,18,0,0,9,0,0,0,0,0,12,0
0,5,6,12,6,5,12,12,6,0,0,21,0,0,0,0,0,0,0,0,9,0,0,0,0,0,12,0
0,22,0,0,0,18,0,16,5,15,0,5,15,0,0,0,0,0,0,16,5,15,0,0,0,16,5,15
0,22,0,0,0,0,0,0,9,0,0,20,0,0,0,0,0,0,0,0,20,0,0,0,0,0,12,0
0,22,0,0,0,0,0,0,9,0,0,21,0,0,0,0,0,0,0,0,21,0,0,0,0,0,12,0
0,22,0,0,0,0,0,16,5,11,11,5,15,0,0,0,0,0,0,16,5,15,0,0,0,16,5,15
0,22,0,0,0,0,0,0,18,0,0,18,0,0,0,0,0,0,0,0,20,0,0,0,0,0,7,0
0,22,0,0,0,0,0,0,0,0,0,0,0,0,0,0,0,0,0,0,21,0,0,0,0,0,7,0
0,22,0,0,0,0,0,0,0,0,0,0,0,0,0,0,0,0,0,16,5,15,0,0,0,16,5,15
0,22,0,0,0,0,0,0,0,0,0,0,0,0,0,0,0,0,0,0,9,0,0,0,0,0,6,0
0,2,0,0,0,2,0,0,0,0,0,0,0,0,0,0,0,0,0,0,9,0,0,13,0,0,6,0
0,0,0,0,0,22,0,0,0,0,0,0,0,0,0,0,0,0,0,16,5,6,6,5,6,6,5,15
0,0,0,0,0,22,0,0,0,0,0,0,0,0,0,0,0,0,0,0,0,0,10,3,3,3,7,0
0,0,0,0,0,22,0,0,0,0,0,0,0,0,0,0,0,0,0,0,0,0,10,3,3,3,7,0
0,0,0,0,0,22,22,22,22,22,22,22,22,22,22,22,22,22,22,22,5,6,6,5,6,6,5,15
:endlayer
layer: 4
9,19,0,0,0,17,7,9,19,0,0,17,7,8,8,8,8,8,8,8,8,8,8,8,8,8,8,7
9,5,24,24,24,5,7,9,5,24,24,24,24,24,24,24,24,24,24,24,24,24,24,24,24,24,5,7
9,23,0,0,0,23,7,9,23,0,0,23,25,6,25,6,25,6,25,6,25,6,25,6,25,6,23,7
9,23,0,0,0,23,7,9,23,0,0,23,25,6,25,6,25,6,25,6,25,6,25,6,25,6,23,7
9,23,0,0,0,23,7,9,23,0,0,23,25,6,25,6,25,6,25,6,25,6,25,6,25,6,23,7
9,23,24,24,24,23,7,9,23,0,0,23,25,6,25,6,25,6,25,6,25,6,25,6,25,6,23,7
9,23,0,0,0,23,7,9,23,0,0,23,25,6,25,6,25,6,25,6,25,6,25,6,25,6,23,7
9,23,0,0,0,23,7,9,23,0,0,23,24,24,24,24,24,24,24,24,5,24,24,24,24,24,23,7
9,23,0,0,0,23,7,9,23,0,0,23,7,11,11,11,11,11,11,11,23,25,25,25,25,25,23,7
9,5,24,24,24,5,7,9,23,0,0,23,7,0,0,0,0,0,0,9,23,6,6,6,6,6,23,7
9,19,0,0,0,17,7,9,23,0,0,23,7,0,0,0,0,0,0,9,23,25,25,25,25,25,23,7
0,0,0,0,0,0,0,9,23,0,0,23,7,0,0,0,0,0,0,9,23,6,6,6,6,6,23,7
0,0,0,0,0,0,0,9,23,0,0,23,7,0,0,0,0,0,0,9,23,25,25,25,25,25,23,7
0,0,0,0,0,0,0,9,5,24,24,5,7,0,0,0,0,0,0,9,23,6,6,6,6,6,23,7
0,0,0,0,0,0,0,9,19,0,0,17,7,0,0,0,0,0,0,9,23,25,25,25,25,25,23,7
0,0,0,0,0,0,0,0,0,0,0,0,0,0,0,0,0,0,0,9,23,6,6,6,6,6,23,7
0,0,0,0,0,0,0,0,0,0,0,0,0,0,0,0,0,0,0,9,23,25,25,25,25,25,23,7
0,0,0,0,0,0,0,0,0,0,0,0,0,0,0,0,0,0,0,9,23,6,6,6,6,6,23,7
0,26,29,28,27,26,0,0,0,0,0,0,0,0,0,0,0,0,0,9,23,25,25,25,25,25,23,7
0,0,0,0,0,0,0,0,0,0,0,0,0,0,0,0,0,0,0,9,5,24,24,24,24,24,23,7
0,0,0,0,0,0,0,0,0,0,0,0,0,0,0,0,0,0,0,0,0,0,0,10,3,3,23,0
0,0,0,0,0,0,0,0,0,0,0,0,0,0,0,0,0,0,0,0,0,0,0,10,3,3,23,0
0,0,0,0,0,0,0,0,0,0,0,0,0,0,0,0,0,0,0,0,5,24,24,5,24,24,5,0
:endlayer
layer: 5
0,9,19,0,17,7,0,0,9,19,17,7,0,0,0,0,0,0,0,0,0,0,0,0,0,0,0,0
0,9,6,6,6,7,0,0,9,6,6,5,12,12,5,12,12,5,12,12,5,12,12,5,12,12,5,0
0,9,19,0,17,7,0,0,9,19,17,6,0,0,18,0,0,18,0,0,18,0,0,18,0,0,12,0
0,9,19,0,17,7,0,0,9,19,17,6,0,0,0,0,0,0,0,0,0,0,0,0,0,0,12,0
0,9,19,0,17,7,0,0,9,19,17,5,15,0,0,0,0,0,0,0,0,0,0,0,0,16,5,0
0,9,19,12,17,7,0,0,9,19,17,6,0,0,0,0,0,0,0,0,0,0,0,0,0,0,12,0
0,9,19,0,17,7,0,0,9,19,17,6,0,0,13,0,0,13,0,0,13,0,0,0,0,0,12,0
0,9,19,0,17,7,0,0,9,19,17,5,12,12,5,12,12,5,12,12,5,15,0,0,0,16,5,0
0,9,19,0,17,7,0,0,9,19,17,7,0,0,0,0,0,0,0,0,12,0,0,0,0,0,12,0
0,9,6,6,6,7,0,0,9,19,17,7,0,0,0,0,0,0,0,0,12,0,0,0,0,0,12,0
0,9,19,0,17,7,0,0,9,19,17,7,0,0,0,0,0,0,0,0,5,15,0,0,0,16,5,0
0,0,0,0,0,0,0,0,9,19,17,7,0,0,0,0,0,0,0,0,12,0,0,0,0,0,12,0
0,0,0,0,0,0,0,0,9,19,17,7,0,0,0,0,0,0,0,0,12,0,0,0,0,0,12,0
0,0,0,0,0,0,0,0,9,6,6,7,0,0,0,0,0,0,0,0,5,15,0,0,0,16,5,0
0,0,0,0,0,0,0,0,9,19,17,7,0,0,0,0,0,0,0,0,12,0,0,0,0,0,12,0
0,0,0,0,0,0,0,0,0,0,0,0,0,0,0,0,0,0,0,0,12,0,0,0,0,0,12,0
0,0,0,0,0,0,0,0,0,0,0,0,0,0,0,0,0,0,0,0,5,15,0,0,0,16,5,0
0,0,0,0,0,0,0,0,0,0,0,0,0,0,0,0,0,0,0,0,12,0,0,0,0,0,12,0
0,0,0,14,0,0,0,0,0,0,0,0,0,0,0,0,0,0,0,0,12,0,0,13,0,0,12,0
0,0,0,0,0,0,0,0,0,0,0,0,0,0,0,0,0,0,0,0,5,12,12,5,0,0,5,0
0,0,0,0,0,0,0,0,0,0,0,0,0,0,0,0,0,0,0,0,0,0,0,0,0,0,12,0
0,0,0,0,0,0,0,0,0,0,0,0,0,0,0,0,0,0,0,0,0,0,0,13,0,0,12,0
0,0,0,0,0,0,0,0,0,0,0,0,0,0,0,0,0,0,0,0,5,12,12,5,12,12,5,0
:endlayer
layer: 6
0,0,9,21,7,0,0,0,0,8,7,0,0,0,0,0,0,0,0,0,0,0,0,0,0,0,0,0
0,0,9,6,7,0,0,0,0,9,7,5,22,22,22,22,22,22,22,22,22,22,22,22,22,22,22,0
0,0,9,23,7,0,0,0,0,9,7,12,0,0,0,0,0,0,0,0,0,0,0,0,0,0,22,0
0,0,9,23,7,0,0,0,0,9,7,12,0,0,0,0,0,0,0,0,0,0,0,0,0,0,22,0
0,0,9,23,7,0,0,0,0,9,7,5,0,0,0,0,0,0,0,0,0,0,0,0,0,0,22,0
0,0,9,23,7,0,0,0,0,9,7,12,0,0,0,0,0,0,0,0,0,0,0,0,0,0,22,0
0,0,9,23,7,0,0,0,0,9,7,12,0,0,0,0,0,0,0,0,0,0,0,0,0,0,22,0
0,0,9,23,7,0,0,0,0,9,7,5,22,22,22,22,22,22,22,22,22,0,0,0,0,0,22,0
0,0,9,23,7,0,0,0,0,9,7,0,0,0,0,0,0,0,0,0,22,0,0,0,0,0,22,0
0,0,9,6,7,0,0,0,0,9,7,0,0,0,0,0,0,0,0,0,22,0,0,0,0,0,22,0
0,0,9,20,7,0,0,0,0,9,7,0,0,0,0,0,0,0,0,0,22,0,0,0,0,0,22,0
0,0,0,0,0,0,0,0,0,9,7,0,0,0,0,0,0,0,0,0,22,0,0,0,0,0,22,0
0,0,0,0,0,0,0,0,0,9,7,0,0,0,0,0,0,0,0,0,22,0,0,0,0,0,22,0
0,0,0,0,0,0,0,0,0,9,7,0,0,0,0,0,0,0,0,0,22,0,0,0,0,0,22,0
0,0,0,0,0,0,0,0,0,11,11,0,0,0,0,0,0,0,0,0,22,0,0,0,0,0,22,0
0,0,0,0,0,0,0,0,0,0,0,0,0,0,0,0,0,0,0,0,22,0,0,0,0,0,22,0
0,0,0,0,0,0,0,0,0,0,0,0,0,0,0,0,0,0,0,0,22,0,0,0,0,0,22,0
0,0,0,0,0,0,0,0,0,0,0,0,0,0,0,0,0,0,0,0,22,0,0,0,0,0,22,0
0,0,0,0,0,0,0,0,0,0,0,0,0,0,0,0,0,0,0,0,22,0,0,0,0,0,22,0
0,0,0,0,0,0,0,0,0,0,0,0,0,0,0,0,0,0,0,0,22,22,22,22,0,0,22,0
0,0,0,0,0,0,0,0,0,0,0,0,0,0,0,0,0,0,0,0,0,0,0,0,0,0,22,0
0,0,0,0,0,0,0,0,0,0,0,0,0,0,0,0,0,0,0,0,0,0,0,0,0,0,22,0
0,0,0,0,0,0,0,0,0,0,0,0,0,0,0,0,0,0,0,0,22,22,22,22,22,22,22,0
:endlayer
layer: 7
0,0,0,22,0,0,0,0,0,0,0,0,0,0,0,0,0,0,0,0,0,0,0,0,0,0,0,0
0,0,0,22,0,0,0,0,0,0,0,22,0,0,0,0,0,0,0,0,0,0,0,0,0,0,0,0
0,0,0,22,0,0,0,0,0,0,0,22,0,0,0,0,0,0,0,0,0,0,0,0,0,0,0,0
0,0,0,22,0,0,0,0,0,0,0,22,0,0,0,0,0,0,0,0,0,0,0,0,0,0,0,0
0,0,0,22,0,0,0,0,0,0,0,22,0,0,0,0,0,0,0,0,0,0,0,0,0,0,0,0
0,0,0,22,0,0,0,0,0,0,0,22,0,0,0,0,0,0,0,0,0,0,0,0,0,0,0,0
0,0,0,22,0,0,0,0,0,0,0,22,0,0,0,0,0,0,0,0,0,0,0,0,0,0,0,0
0,0,0,22,0,0,0,0,0,0,0,22,0,0,0,0,0,0,0,0,0,0,0,0,0,0,0,0
0,0,0,22,0,0,0,0,0,0,0,0,0,0,0,0,0,0,0,0,0,0,0,0,0,0,0,0
0,0,0,22,0,0,0,0,0,0,0,0,0,0,0,0,0,0,0,0,0,0,0,0,0,0,0,0
0,0,0,22,0,0,0,0,0,0,0,0,0,0,0,0,0,0,0,0,0,0,0,0,0,0,0,0
0,0,0,0,0,0,0,0,0,0,0,0,0,0,0,0,0,0,0,0,0,0,0,0,0,0,0,0
0,0,0,0,0,0,0,0,0,0,0,0,0,0,0,0,0,0,0,0,0,0,0,0,0,0,0,0
0,0,0,0,0,0,0,0,0,0,0,0,0,0,0,0,0,0,0,0,0,0,0,0,0,0,0,0
0,0,0,0,0,0,0,0,0,0,0,0,0,0,0,0,0,0,0,0,0,0,0,0,0,0,0,0
0,0,0,0,0,0,0,0,0,0,0,0,0,0,0,0,0,0,0,0,0,0,0,0,0,0,0,0
0,0,0,0,0,0,0,0,0,0,0,0,0,0,0,0,0,0,0,0,0,0,0,0,0,0,0,0
0,0,0,0,0,0,0,0,0,0,0,0,0,0,0,0,0,0,0,0,0,0,0,0,0,0,0,0
0,0,0,0,0,0,0,0,0,0,0,0,0,0,0,0,0,0,0,0,0,0,0,0,0,0,0,0
0,0,0,0,0,0,0,0,0,0,0,0,0,0,0,0,0,0,0,0,0,0,0,0,0,0,0,0
0,0,0,0,0,0,0,0,0,0,0,0,0,0,0,0,0,0,0,0,0,0,0,0,0,0,0,0
0,0,0,0,0,0,0,0,0,0,0,0,0,0,0,0,0,0,0,0,0,0,0,0,0,0,0,0
0,0,0,0,0,0,0,0,0,0,0,0,0,0,0,0,0,0,0,0,0,0,0,0,0,0,0,0
:endlayer

#### RULES ####
rule:
plugin=vanillaBlocks
number=1
data:
JSON:{blockState:{blockName:"minecraft:grass",properties:{snowy:"false"}}}
:enddata
:endrule

rule:
plugin=vanillaBlocks
number=2
data:
JSON:{blockState:{blockName:"minecraft:stonebrick",properties:{variant:"stonebrick"}}}
:enddata
:endrule

rule:
plugin=vanillaBlocks
number=3
data:
JSON:{blockState:{blockName:"minecraft:cobblestone"}}
:enddata
:endrule

rule:
plugin=vanillaBlocks
number=4
data:
JSON:{blockState:{blockName:"minecraft:dirt",properties:{variant:"coarse_dirt",snowy:"false"}}}
:enddata
:endrule

rule:
plugin=vanillaBlocks
number=5
data:
JSON:{blockState:{blockName:"minecraft:log",properties:{variant:"jungle",axis:"y"}}}
:enddata
:endrule

rule:
plugin=vanillaBlocks
number=6
data:
JSON:{blockState:{blockName:"minecraft:planks",properties:{variant:"jungle"}}}
:enddata
:endrule

rule:
plugin=vanillaBlocks
number=7
data:
JSON:{blockState:{blockName:"minecraft:jungle_stairs",properties:{half:"bottom",shape:"straight",facing:"west"}}}
:enddata
:endrule

rule:
plugin=vanillaBlocks
number=8
data:
JSON:{blockState:{blockName:"minecraft:jungle_stairs",properties:{half:"bottom",shape:"straight",facing:"south"}}}
:enddata
:endrule

rule:
plugin=vanillaBlocks
number=9
data:
JSON:{blockState:{blockName:"minecraft:jungle_stairs",properties:{half:"bottom",shape:"straight",facing:"east"}}}
:enddata
:endrule

rule:
plugin=vanillaBlocks
number=10
data:
JSON:{blockState:{blockName:"minecraft:stone_brick_stairs",properties:{half:"bottom",shape:"straight",facing:"east"}}}
:enddata
:endrule

rule:
plugin=vanillaBlocks
number=11
data:
JSON:{blockState:{blockName:"minecraft:jungle_stairs",properties:{half:"bottom",shape:"straight",facing:"north"}}}
:enddata
:endrule

rule:
plugin=vanillaBlocks
number=12
data:
JSON:{blockState:{blockName:"minecraft:jungle_fence",properties:{east:"false",south:"false",north:"false",west:"false"}}}
:enddata
:endrule

rule:
plugin=vanillaBlocks
number=13
data:
JSON:{blockState:{blockName:"minecraft:torch",properties:{facing:"north"}}}
:enddata
:endrule

rule:
plugin=vanillaBlocks
number=14
data:
JSON:{blockState:{blockName:"minecraft:torch",properties:{facing:"up"}}}
:enddata
:endrule

rule:
plugin=vanillaBlocks
number=15
data:
JSON:{blockState:{blockName:"minecraft:torch",properties:{facing:"east"}}}
:enddata
:endrule

rule:
plugin=vanillaBlocks
number=16
data:
JSON:{blockState:{blockName:"minecraft:torch",properties:{facing:"west"}}}
:enddata
:endrule

rule:
plugin=vanillaBlocks
number=17
data:
JSON:{blockState:{blockName:"minecraft:jungle_stairs",properties:{half:"top",shape:"straight",facing:"east"}}}
:enddata
:endrule

rule:
plugin=vanillaBlocks
number=18
data:
JSON:{blockState:{blockName:"minecraft:torch",properties:{facing:"south"}}}
:enddata
:endrule

rule:
plugin=vanillaBlocks
number=19
data:
JSON:{blockState:{blockName:"minecraft:jungle_stairs",properties:{half:"top",shape:"straight",facing:"west"}}}
:enddata
:endrule

rule:
plugin=vanillaBlocks
number=20
data:
JSON:{blockState:{blockName:"minecraft:jungle_stairs",properties:{half:"top",shape:"straight",facing:"north"}}}
:enddata
:endrule

rule:
plugin=vanillaBlocks
number=21
data:
JSON:{blockState:{blockName:"minecraft:jungle_stairs",properties:{half:"top",shape:"straight",facing:"south"}}}
:enddata
:endrule

rule:
plugin=vanillaBlocks
number=22
data:
JSON:{blockState:{blockName:"minecraft:wooden_slab",properties:{half:"bottom",variant:"jungle"}}}
:enddata
:endrule

rule:
plugin=vanillaBlocks
number=23
data:
JSON:{blockState:{blockName:"minecraft:log",properties:{variant:"jungle",axis:"z"}}}
:enddata
:endrule

rule:
plugin=vanillaBlocks
number=24
data:
JSON:{blockState:{blockName:"minecraft:log",properties:{variant:"jungle",axis:"x"}}}
:enddata
:endrule

rule:
plugin=vanillaBlocks
number=25
data:
JSON:{blockState:{blockName:"minecraft:wooden_slab",properties:{half:"top",variant:"jungle"}}}
:enddata
:endrule

rule:
plugin=vanillaBlocks
number=26
data:
JSON:{blockState:{blockName:"minecraft:stone_slab",properties:{half:"bottom",variant:"stone_brick"}}}
:enddata
:endrule

rule:
plugin=vanillaBlocks
number=27
data:
JSON:{blockState:{blockName:"minecraft:stone_brick_stairs",properties:{half:"top",shape:"straight",facing:"east"}}}
:enddata
:endrule

rule:
plugin=vanillaBlocks
number=28
data:
JSON:{blockState:{blockName:"minecraft:stone_slab",properties:{half:"top",variant:"stone_brick"}}}
:enddata
:endrule

rule:
plugin=vanillaBlocks
number=29
data:
JSON:{blockState:{blockName:"minecraft:stone_brick_stairs",properties:{half:"top",shape:"straight",facing:"west"}}}
:enddata
:endrule

#### ENTITIES ####
