# Ancient Warfare Structure Template File
# Auto-generated structure template file. created on: 5/7/2021 at: 0:9:25
# Lines beginning with # denote comments

header:
version=2.11
name=SurvivalBuild_RuralLife_FarmStructure_FortifiedVillaA
mods=
size=28,15,37
offset=14,1,36
:endheader

#### VALIDATION ####
validation:
type=ground
structureAuthor=TheOddlySeagull
survival=true
worldGenEnabled=false
unique=false
preserveBlocks=false
preventNaturalHostileSpawns=false
selectionWeight=1
clusterValue=1
minDuplicateDistance=1
dimensionWhiteList=true
dimensionList=
biomeGroupList=
biomeWhiteList=true
biomeList=
leveling=0
fill=0
border=0
blockSwap=false
territoryName=
biomeReplacement=minecraft:
minGenerationHeight=0
maxGenerationHeight=255
:endvalidation

#### LAYERS ####
layer: 0
1,1,1,1,1,1,1,1,1,1,1,1,1,1,1,1,1,1,1,1,1,1,1,1,1,1,1,1
1,1,1,1,1,1,1,1,1,1,1,1,1,1,1,1,1,1,1,1,1,1,1,1,1,1,1,1
1,1,1,2,2,2,2,2,2,2,2,2,2,2,2,1,1,1,1,1,1,1,1,1,1,1,1,1
1,1,1,2,2,2,2,2,2,2,2,2,2,2,2,2,2,2,2,2,2,2,2,2,2,1,1,1
1,1,1,2,2,2,2,2,2,2,2,2,2,2,2,1,1,1,6,1,1,9,6,6,2,1,1,1
1,1,1,2,2,2,2,2,2,2,2,2,2,2,2,1,1,6,5,6,1,9,6,6,2,1,1,1
1,1,1,2,2,2,2,2,2,2,2,2,2,2,2,1,1,6,1,1,1,9,2,2,2,1,1,1
1,1,1,2,2,2,2,2,2,2,2,2,2,2,2,1,6,1,5,1,1,9,6,6,2,1,1,1
1,1,1,2,2,2,2,2,2,2,2,2,2,2,2,6,6,6,5,1,1,9,6,6,2,1,1,1
1,1,1,2,6,6,6,2,1,1,5,1,6,1,5,1,6,6,5,1,6,9,2,2,2,1,1,1
1,1,1,2,6,6,6,2,1,6,6,5,1,5,5,6,6,1,5,6,1,9,6,6,2,1,1,1
1,1,1,2,6,6,6,2,6,1,5,6,1,1,1,6,5,5,6,1,1,9,6,6,2,1,1,1
1,1,1,2,6,6,6,2,6,5,1,6,5,5,5,5,6,1,6,2,2,2,2,2,2,2,1,1
1,1,1,2,6,6,6,2,1,1,5,1,6,6,6,1,5,1,1,2,6,6,6,6,6,2,1,1
1,1,2,2,2,2,2,2,2,2,2,6,6,5,6,6,5,1,1,2,6,6,6,6,6,2,1,1
1,1,2,8,4,4,4,8,4,4,2,1,5,6,5,5,5,5,5,2,6,6,6,6,6,2,1,1
1,1,2,4,4,8,4,4,4,8,2,1,6,1,5,5,6,5,6,2,6,6,6,6,6,2,1,1
1,1,2,8,4,4,4,4,4,4,2,6,1,5,1,1,5,1,1,2,6,6,6,6,6,2,1,1
1,1,2,4,4,4,4,8,8,4,2,6,6,5,5,5,6,6,5,2,6,6,6,6,6,2,1,1
1,1,2,2,2,2,2,2,2,2,2,5,1,6,5,6,6,1,5,2,6,6,6,6,6,2,1,1
1,7,2,8,8,8,8,8,8,8,8,6,6,5,5,1,6,1,1,2,6,6,6,6,6,2,1,1
1,7,2,8,8,8,8,8,8,8,8,6,1,5,6,6,6,5,1,2,2,2,2,2,2,2,2,1
1,7,2,8,8,8,8,8,8,8,8,1,1,5,5,6,6,1,1,1,1,1,2,6,6,6,2,1
1,1,2,8,8,8,8,8,8,8,8,1,5,1,5,5,5,1,1,1,5,1,2,6,6,6,2,1
1,1,2,2,2,2,2,2,2,2,2,1,1,6,5,1,5,6,1,6,5,5,2,6,6,6,2,1
1,1,2,8,8,8,8,2,1,5,1,1,1,5,1,1,6,1,6,1,5,5,2,6,6,6,2,1
1,1,2,8,8,8,8,2,1,6,6,6,5,5,6,6,1,6,5,5,6,5,2,6,6,6,2,1
1,1,2,8,8,8,8,2,5,6,5,6,5,1,6,6,5,5,1,5,6,5,2,6,6,6,2,1
1,1,2,2,2,2,2,2,1,6,5,5,6,5,1,6,5,1,5,5,1,6,2,2,2,2,2,1
1,1,2,6,6,2,6,1,5,6,1,1,6,5,1,5,6,5,6,4,4,4,4,4,4,2,1,1
1,1,2,6,6,6,6,1,6,6,6,1,5,5,5,6,6,5,5,4,7,7,7,7,4,2,1,1
1,1,2,6,6,6,1,6,6,5,5,1,5,5,5,6,6,6,6,4,7,0,0,7,4,2,1,1
1,1,2,2,2,2,6,6,1,5,5,1,1,6,6,5,6,6,5,4,7,0,0,7,4,2,1,1
1,1,2,2,2,2,6,5,6,6,6,1,6,1,5,6,1,1,5,4,7,7,7,7,4,2,1,1
1,1,2,2,2,2,5,6,6,6,1,1,1,1,6,1,1,5,1,4,4,4,4,4,4,2,1,1
1,1,2,2,2,2,2,2,2,2,2,2,3,3,3,3,3,3,2,2,2,2,2,2,2,2,1,1
1,1,1,1,1,1,1,1,1,1,1,1,1,1,1,1,1,1,1,1,1,1,1,1,1,1,1,1
:endlayer
layer: 1
0,0,0,0,0,0,0,0,0,0,0,0,0,0,0,0,0,0,0,0,0,0,0,0,0,0,0,0
0,0,0,0,0,0,0,0,0,0,0,0,0,0,0,0,0,0,0,0,0,0,0,0,0,0,0,0
0,0,0,10,7,7,7,7,7,7,7,7,7,7,10,0,0,0,0,0,0,0,0,0,0,0,0,0
0,0,0,7,0,0,0,0,0,0,0,0,0,0,23,7,7,7,7,7,7,7,7,7,10,0,0,0
0,0,0,7,0,0,0,0,0,0,0,0,0,0,23,0,0,0,0,0,22,0,0,0,7,0,0,0
0,0,0,7,0,0,0,0,0,0,0,0,0,0,10,0,0,0,0,0,22,0,0,0,7,0,0,0
0,0,0,7,0,0,0,0,0,0,0,0,0,0,23,0,0,0,0,0,17,10,17,17,7,0,0,0
0,0,0,7,0,0,0,0,0,0,0,0,0,0,23,0,0,0,0,0,22,0,0,0,7,0,0,0
0,0,0,10,23,10,23,23,10,25,24,10,23,23,10,0,0,0,0,0,22,0,0,0,7,0,0,0
0,0,0,7,0,0,0,10,0,0,0,0,0,0,0,0,0,0,0,0,17,10,17,17,7,0,0,0
0,0,0,7,0,0,0,0,0,0,0,0,0,0,0,0,0,0,0,0,22,0,0,0,7,0,0,0
0,0,0,7,0,0,0,0,0,0,0,0,0,0,0,0,0,0,0,0,22,0,0,0,7,0,0,0
0,0,0,7,0,0,0,0,0,0,0,0,0,0,0,0,0,0,0,10,20,20,10,20,20,10,0,0
0,0,0,7,0,0,0,10,0,0,0,0,0,0,0,0,0,0,0,20,0,0,0,0,0,7,0,0
0,0,10,7,7,7,7,10,2,2,10,0,0,0,0,0,0,0,0,10,0,0,0,0,0,7,0,0
0,0,7,0,0,0,0,0,0,0,2,0,0,0,0,0,0,0,0,20,0,0,0,0,0,7,0,0
0,0,7,0,0,0,0,0,0,0,21,0,0,0,0,0,0,0,0,10,0,0,0,0,0,7,0,0
0,0,10,0,0,0,0,0,0,0,19,0,0,0,0,0,0,0,0,0,0,0,0,0,0,7,0,0
0,0,7,0,0,0,0,0,0,0,2,0,0,0,0,0,0,0,0,0,0,0,0,0,0,7,0,0
0,0,7,2,2,2,2,2,2,2,10,0,0,0,0,0,0,0,0,10,0,0,0,0,0,7,0,0
0,7,7,0,0,0,0,0,0,0,8,0,0,0,0,0,0,0,0,20,0,0,0,0,0,7,0,0
0,7,7,0,0,0,0,0,0,0,21,0,0,0,0,0,0,0,0,10,20,10,20,10,20,10,10,0
0,7,7,0,0,0,0,0,0,0,19,0,0,0,0,0,0,0,0,0,0,0,17,0,0,0,7,0
0,0,7,0,0,0,0,0,0,0,8,0,0,0,0,0,0,0,0,0,0,0,0,0,0,0,7,0
0,0,7,2,2,2,2,2,2,2,10,0,0,0,0,0,0,0,0,0,0,0,0,0,0,0,7,0
0,0,10,0,0,0,0,2,0,0,0,0,0,0,0,0,0,0,0,0,0,0,17,0,0,0,7,0
0,0,7,0,0,0,0,18,0,0,0,0,0,0,0,0,0,0,0,0,0,0,0,0,0,0,7,0
0,0,7,0,0,0,0,2,0,0,0,0,0,0,0,0,0,0,0,0,0,0,17,0,0,0,7,0
0,0,10,2,2,2,2,10,0,0,0,0,0,0,0,0,0,0,0,0,0,0,10,7,7,7,10,0
0,0,7,0,0,10,0,0,0,0,0,0,0,0,0,0,0,0,0,0,0,0,0,0,0,7,0,0
0,0,7,0,0,0,0,0,0,0,0,0,0,0,0,0,0,0,0,0,16,16,7,16,0,7,0,0
0,0,7,15,15,0,0,0,0,0,0,0,0,0,0,0,0,0,0,0,12,0,0,13,0,7,0,0
0,0,7,14,14,10,0,0,0,0,0,0,0,0,0,0,0,0,0,0,12,0,0,13,0,7,0,0
0,0,7,0,0,0,0,0,0,0,0,0,0,0,0,0,0,0,0,0,12,11,7,11,0,7,0,0
0,0,7,0,0,0,0,0,0,0,0,0,0,0,0,0,0,0,0,0,0,0,0,0,0,7,0,0
0,0,10,7,7,7,7,7,7,7,7,10,0,0,0,0,0,0,10,7,7,7,7,7,7,10,0,0
0,0,0,0,0,0,0,0,0,0,0,0,0,0,0,0,0,0,0,0,0,0,0,0,0,0,0,0
:endlayer
layer: 2
0,0,0,0,0,0,0,0,0,0,0,0,0,0,0,0,0,0,0,0,0,0,0,0,0,0,0,0
0,0,0,0,0,0,0,0,0,0,0,0,0,0,0,0,0,0,0,0,0,0,0,0,0,0,0,0
0,0,0,10,7,7,7,7,7,7,7,7,7,7,10,0,0,0,0,0,0,0,0,0,0,0,0,0
0,0,0,7,0,0,0,0,0,0,0,0,0,0,23,7,7,7,7,7,7,7,7,7,10,0,0,0
0,0,0,7,0,0,0,0,0,0,0,0,0,0,23,0,0,0,0,0,0,0,0,0,7,0,0,0
0,0,0,7,0,0,0,0,0,0,0,0,0,0,10,0,0,0,0,0,0,0,0,0,7,0,0,0
0,0,0,7,0,0,0,0,0,0,0,0,0,0,23,0,0,0,0,0,17,10,17,17,7,0,0,0
0,0,0,7,0,0,0,0,0,0,0,0,0,0,23,0,0,0,0,0,0,0,0,0,7,0,0,0
0,0,0,10,23,10,23,23,10,30,29,10,23,23,10,0,0,0,0,0,0,0,0,0,7,0,0,0
0,0,0,7,0,0,0,10,0,0,0,0,0,0,0,0,0,0,0,0,17,10,17,17,7,0,0,0
0,0,0,7,0,0,0,0,0,0,0,0,0,0,0,0,0,0,0,0,0,0,0,0,7,0,0,0
0,0,0,7,0,0,0,0,0,0,0,0,0,0,0,0,0,0,0,0,0,0,0,0,7,0,0,0
0,0,0,7,0,0,0,0,0,0,0,0,0,0,0,0,0,0,0,10,20,20,10,20,20,10,0,0
0,0,0,7,0,0,0,10,0,0,0,0,0,0,0,0,0,0,0,20,0,0,0,0,0,7,0,0
0,0,10,7,7,7,7,10,2,2,10,0,0,0,0,0,0,0,0,10,0,0,0,0,0,7,0,0
0,0,7,0,0,0,0,0,0,0,2,0,0,0,0,0,0,0,0,20,0,0,0,0,0,7,0,0
0,0,7,0,0,0,0,0,0,0,28,0,0,0,0,0,0,0,0,10,0,0,0,0,0,7,0,0
0,0,10,0,0,0,0,0,0,0,27,0,0,0,0,0,0,0,0,0,0,0,0,0,0,7,0,0
0,0,7,0,0,0,0,0,0,0,2,0,0,0,0,0,0,0,0,0,0,0,0,0,0,7,0,0
0,0,7,2,2,2,2,2,2,2,10,0,0,0,0,0,0,0,0,10,0,0,0,0,0,7,0,0
0,7,7,0,0,0,0,0,0,0,8,0,0,0,0,0,0,0,0,20,0,0,0,0,0,7,0,0
0,7,7,0,0,0,0,0,0,0,28,0,0,0,0,0,0,0,0,10,20,10,20,10,20,10,10,0
0,7,7,0,0,0,0,0,0,0,27,0,0,0,0,0,0,0,0,0,0,0,17,0,0,0,7,0
0,0,7,0,0,0,0,0,0,0,8,0,0,0,0,0,0,0,0,0,0,0,0,0,0,0,7,0
0,0,7,2,2,2,2,2,2,2,10,0,0,0,0,0,0,0,0,0,0,0,0,0,0,0,7,0
0,0,10,0,0,0,0,2,0,0,0,0,0,0,0,0,0,0,0,0,0,0,17,0,0,0,7,0
0,0,7,0,0,0,0,26,0,0,0,0,0,0,0,0,0,0,0,0,0,0,0,0,0,0,7,0
0,0,7,0,0,0,0,2,0,0,0,0,0,0,0,0,0,0,0,0,0,0,17,0,0,0,7,0
0,0,10,2,2,2,2,10,0,0,0,0,0,0,0,0,0,0,0,0,0,0,10,7,7,7,10,0
0,0,7,0,0,10,0,0,0,0,0,0,0,0,0,0,0,0,0,0,0,0,0,0,0,7,0,0
0,0,7,15,15,0,0,0,0,0,0,0,0,0,0,0,0,0,0,0,0,0,7,0,0,7,0,0
0,0,7,14,14,0,0,0,0,0,0,0,0,0,0,0,0,0,0,0,0,0,0,0,0,7,0,0
0,0,7,0,0,10,0,0,0,0,0,0,0,0,0,0,0,0,0,0,0,0,0,0,0,7,0,0
0,0,7,0,0,0,0,0,0,0,0,0,0,0,0,0,0,0,0,0,0,0,7,0,0,7,0,0
0,0,7,0,0,0,0,0,0,0,0,0,0,0,0,0,0,0,0,0,0,0,0,0,0,7,0,0
0,0,10,7,7,7,7,7,7,7,7,10,0,0,0,0,0,0,10,7,7,7,7,7,7,10,0,0
0,0,0,0,0,0,0,0,0,0,0,0,0,0,0,0,0,0,0,0,0,0,0,0,0,0,0,0
:endlayer
layer: 3
0,0,0,0,0,0,0,0,0,0,0,0,0,0,0,0,0,0,0,0,0,0,0,0,0,0,0,0
0,0,0,0,0,0,0,0,0,0,0,0,0,0,0,0,0,0,0,0,0,0,0,0,0,0,0,0
0,0,0,10,7,7,7,7,7,7,7,7,7,7,10,0,0,0,0,0,0,0,0,0,0,0,0,0
0,0,0,7,0,0,0,0,0,0,0,0,0,0,9,7,7,7,7,7,7,7,7,7,10,0,0,0
0,0,0,7,0,0,0,0,0,0,0,0,0,0,9,0,0,0,0,0,33,0,0,0,7,0,0,0
0,0,0,7,0,0,0,0,0,0,0,0,0,0,10,0,0,0,0,0,33,0,0,0,7,0,0,0
0,0,0,7,0,0,0,0,0,0,0,0,0,0,9,0,0,0,0,0,34,10,3,3,7,0,0,0
0,0,0,7,0,0,0,0,0,0,0,0,0,0,9,0,0,0,0,0,33,0,0,0,7,0,0,0
0,0,0,10,23,10,3,3,10,35,35,10,3,3,10,0,0,0,0,0,33,0,0,0,7,0,0,0
0,0,0,7,0,0,0,10,33,0,0,0,0,0,0,0,0,0,0,0,34,10,3,3,7,0,0,0
0,0,0,7,0,0,0,0,33,0,0,0,0,0,0,0,0,0,0,0,33,0,0,0,7,0,0,0
0,0,0,7,0,0,0,0,33,0,0,0,0,0,0,0,0,0,0,17,33,0,0,0,7,0,0,0
0,0,0,7,0,0,0,0,33,0,0,0,0,0,0,0,0,0,17,10,20,20,10,20,20,10,0,0
0,0,0,7,0,0,0,10,33,0,0,0,0,0,0,0,0,0,0,20,0,0,0,0,0,7,0,0
0,0,10,7,7,7,7,10,2,2,10,0,0,0,0,0,0,0,0,10,0,0,0,0,0,7,0,0
0,0,7,32,32,32,32,32,32,32,2,0,0,0,0,0,0,0,0,20,0,0,0,0,0,7,0,0
0,0,7,0,0,0,0,0,0,0,2,0,0,0,0,0,0,0,0,10,0,0,0,0,0,7,0,0
0,0,10,0,0,0,0,0,0,0,2,0,0,0,0,0,0,0,0,20,0,0,0,0,0,7,0,0
0,0,7,31,31,31,31,31,31,31,2,0,0,0,0,0,0,0,0,20,0,0,0,0,0,7,0,0
0,0,7,2,2,2,2,2,2,2,10,0,0,0,0,0,0,0,0,10,0,0,0,0,0,7,0,0
0,7,7,32,32,32,32,32,32,32,8,0,0,0,0,0,0,0,0,20,0,0,0,0,0,7,0,0
0,7,7,0,0,0,0,0,0,0,8,0,0,0,0,0,0,0,17,10,20,10,20,10,20,10,10,0
0,7,7,0,0,0,0,0,0,0,8,0,0,0,0,0,0,0,0,17,0,0,17,0,0,0,7,0
0,0,7,31,31,31,31,31,31,31,8,0,0,0,0,0,0,0,0,0,0,0,17,0,0,0,7,0
0,0,7,2,2,2,2,2,2,2,10,0,0,0,0,0,0,0,0,0,0,0,17,0,0,0,7,0
0,0,10,0,0,0,0,2,0,0,0,0,0,0,0,0,0,0,0,0,0,0,17,0,0,0,7,0
0,0,7,0,0,0,0,2,0,0,0,0,0,0,0,0,0,0,0,0,0,0,17,0,0,0,7,0
0,0,7,0,0,0,0,2,0,0,0,0,0,0,0,0,0,0,0,0,0,0,17,0,0,0,7,0
0,0,10,2,2,2,2,10,0,0,0,0,0,0,0,0,0,0,0,0,0,0,10,7,7,7,10,0
0,0,7,15,15,10,0,0,0,0,0,0,0,0,0,0,0,0,0,0,0,0,0,0,0,7,0,0
0,0,7,14,14,9,0,0,0,0,0,0,0,0,0,0,0,0,0,0,0,0,16,0,0,7,0,0
0,0,7,0,0,9,0,0,0,0,0,0,0,0,0,0,0,0,0,0,0,0,17,0,0,7,0,0
0,0,7,0,0,10,0,0,0,0,0,0,0,0,0,0,0,0,0,0,0,0,17,0,0,7,0,0
0,0,7,0,0,0,0,0,0,0,0,0,0,0,0,0,0,0,0,0,0,0,11,0,0,7,0,0
0,0,7,0,0,0,0,0,0,0,0,0,0,0,0,0,0,0,0,0,0,0,0,0,0,7,0,0
0,0,10,7,7,7,7,7,7,7,7,10,0,0,0,0,0,0,10,7,7,7,7,7,7,10,0,0
0,0,0,0,0,0,0,0,0,0,0,0,0,0,0,0,0,0,0,0,0,0,0,0,0,0,0,0
:endlayer
layer: 4
0,0,0,0,0,0,0,0,0,0,0,0,0,0,0,0,0,0,0,0,0,0,0,0,0,0,0,0
0,0,0,17,0,0,0,0,0,0,0,0,0,0,17,0,0,0,0,0,0,0,0,0,0,0,0,0
0,0,17,10,7,7,7,7,7,7,7,7,7,7,10,17,0,0,0,0,0,0,0,0,0,0,0,0
0,0,0,7,0,0,0,0,0,0,0,0,0,0,23,7,7,7,7,7,7,7,7,7,10,0,0,0
0,0,0,7,0,0,0,0,0,0,0,0,0,0,23,0,0,0,0,0,0,36,36,33,7,0,0,0
0,0,0,7,0,0,0,0,0,0,0,0,0,0,10,0,0,0,0,0,0,36,36,33,7,0,0,0
0,0,0,7,0,0,0,0,0,0,0,0,0,0,23,0,0,0,0,0,0,36,36,33,7,0,0,0
0,0,0,7,0,0,0,0,0,0,0,0,0,0,23,0,0,0,0,0,0,36,36,33,7,0,0,0
0,0,17,10,23,10,23,23,10,23,23,10,23,23,10,17,0,0,0,0,0,36,36,33,7,0,0,0
0,0,33,7,33,33,36,36,17,0,0,17,0,0,17,0,0,0,0,0,0,36,36,33,7,0,0,0
0,0,33,7,33,33,36,36,0,0,0,0,0,0,0,0,0,0,0,0,0,36,36,33,7,0,0,0
0,0,33,7,33,33,36,36,0,0,0,0,0,0,0,0,0,0,39,38,0,36,36,33,7,34,37,0
0,0,33,7,33,33,36,36,0,0,0,0,0,0,0,0,0,0,39,10,3,3,3,3,3,10,37,0
0,0,33,7,33,33,36,36,0,0,0,0,0,0,0,0,0,0,39,9,0,0,0,0,0,7,37,0
0,0,10,3,3,3,3,3,3,3,10,0,0,0,0,0,0,0,39,9,0,0,0,0,0,7,37,0
0,0,9,4,4,4,4,4,4,4,9,0,0,0,0,0,0,0,39,9,0,0,0,0,0,7,37,0
0,0,9,4,4,4,4,4,4,4,9,0,0,0,0,0,0,0,39,9,0,0,0,0,0,7,37,0
0,0,9,4,4,4,4,4,4,4,9,38,0,0,0,0,0,0,39,9,0,0,0,0,0,7,37,0
0,0,9,4,4,4,4,4,4,4,9,33,0,0,0,0,0,0,39,9,0,0,0,0,0,7,37,0
0,0,9,4,4,4,4,4,4,4,9,38,0,0,0,0,0,0,39,9,0,0,0,0,0,7,37,0
0,7,7,4,4,4,4,4,4,4,9,33,0,0,0,0,0,0,39,9,0,0,0,0,0,7,23,37
0,7,7,4,4,4,4,4,4,4,9,38,0,0,0,0,0,0,39,10,3,3,3,3,3,3,10,37
0,7,7,4,4,4,4,4,4,4,9,0,0,0,0,0,0,0,39,38,0,39,9,0,0,0,9,37
0,0,9,4,4,4,4,4,4,4,9,0,0,0,0,0,0,0,0,0,0,39,9,0,0,0,9,37
0,0,9,3,3,3,3,3,3,3,10,0,0,0,0,0,0,0,0,0,0,39,9,0,0,0,9,37
0,0,9,33,33,33,33,9,0,0,0,0,0,0,0,0,0,0,0,0,0,39,9,0,0,0,9,37
0,0,9,33,33,33,33,9,0,0,0,0,0,0,0,0,0,0,0,0,0,39,9,0,0,0,9,37
0,0,9,33,33,33,33,9,0,0,0,0,0,0,0,0,0,0,0,0,0,39,9,0,0,0,9,37
0,0,10,3,3,3,3,10,0,0,0,0,0,0,0,0,0,0,0,0,0,39,10,3,3,3,10,37
0,0,7,14,14,10,0,0,0,0,0,0,0,0,0,0,0,0,0,0,0,39,38,0,0,7,34,37
0,0,7,0,0,0,0,0,0,0,0,0,0,0,0,0,0,0,0,0,0,0,0,0,0,7,0,0
0,0,7,0,0,0,0,0,0,0,0,0,0,0,0,0,0,0,0,0,0,0,0,0,0,7,0,0
0,0,7,0,0,36,0,0,0,0,0,0,0,0,0,0,0,0,0,0,0,0,0,0,0,7,0,0
0,0,7,0,0,0,0,0,0,0,0,0,0,0,0,0,0,0,0,0,0,0,0,0,0,7,0,0
0,0,7,0,0,0,0,0,0,0,0,0,0,0,0,0,0,0,0,0,0,0,0,0,0,7,0,0
0,0,10,7,7,7,7,7,7,7,7,10,0,0,0,0,0,0,10,7,7,7,7,7,7,10,0,0
0,0,0,0,0,0,0,0,0,0,0,0,0,0,0,0,0,0,0,0,0,0,0,0,0,0,0,0
:endlayer
layer: 5
0,0,0,0,0,0,0,0,0,0,0,0,0,0,0,0,0,0,0,0,0,0,0,0,0,0,0,0
0,0,43,43,43,43,43,43,43,43,43,43,43,43,43,43,0,0,0,0,0,0,0,0,0,0,0,0
0,0,35,10,3,3,3,3,3,3,3,3,3,3,10,35,0,0,0,0,0,0,0,0,0,0,0,0
0,0,0,9,0,0,0,0,0,0,0,0,0,0,9,17,17,17,17,17,17,17,17,17,10,0,0,0
0,0,0,9,0,0,0,0,0,0,0,0,0,0,9,0,0,0,0,0,0,0,0,0,17,0,0,0
0,0,0,9,0,0,0,0,0,0,0,0,0,0,9,0,0,0,0,0,0,0,0,0,17,0,0,0
0,0,0,9,0,0,0,0,0,0,0,0,0,0,9,0,0,0,0,0,0,0,0,0,17,0,0,0
0,0,0,9,0,0,0,0,0,0,0,0,0,0,9,0,0,0,0,0,0,0,0,0,17,0,0,0
0,0,15,10,3,3,3,3,3,3,3,3,3,3,10,15,0,0,0,0,0,0,0,0,17,0,0,0
0,0,14,14,14,14,14,14,14,14,14,14,14,14,14,14,0,0,0,0,0,0,0,0,17,0,0,0
0,0,0,36,0,0,0,0,0,0,0,0,0,0,0,0,0,0,0,0,0,0,0,0,17,0,0,0
0,0,0,36,0,0,0,0,0,0,0,0,0,0,0,0,0,0,0,39,38,0,0,0,23,37,0,0
0,0,0,36,0,0,0,0,0,0,0,0,0,0,0,0,0,0,0,39,10,20,20,20,10,37,0,0
0,0,0,36,0,0,0,0,0,0,0,0,0,0,0,0,0,0,0,39,38,0,0,0,34,37,0,0
0,0,10,20,10,20,10,20,10,20,10,0,0,0,0,0,0,0,0,39,38,0,0,0,34,37,0,0
0,0,20,0,0,0,23,0,0,0,20,0,0,0,0,0,0,0,0,39,38,0,0,0,34,37,0,0
0,0,10,0,0,0,10,0,0,0,10,0,0,0,0,0,0,0,0,39,38,0,0,0,34,37,0,0
0,0,20,0,0,0,23,0,0,0,20,17,0,0,0,0,0,0,0,39,38,0,0,0,34,37,0,0
0,0,10,0,10,23,10,0,10,23,10,17,0,0,0,0,0,0,0,39,38,0,0,0,34,37,0,0
0,0,20,0,0,0,0,0,0,0,42,17,0,0,0,0,0,0,0,39,38,0,0,0,34,37,0,0
0,7,11,0,0,0,10,0,0,0,10,17,0,0,0,0,0,0,0,39,38,0,0,0,34,23,37,0
0,7,41,0,0,0,23,0,0,0,20,17,0,0,0,0,0,0,0,39,10,20,20,10,10,10,37,0
0,7,16,0,0,0,10,0,0,0,10,0,0,0,0,0,0,0,0,39,38,0,39,38,0,34,37,0
0,0,20,40,0,0,0,0,0,0,20,0,0,0,0,0,0,0,0,0,0,0,39,38,0,34,37,0
0,0,10,0,0,0,10,20,10,20,10,0,0,0,0,0,0,0,0,0,0,0,39,38,0,34,37,0
0,0,23,0,0,0,0,23,0,0,0,0,0,0,0,0,0,0,0,0,0,0,39,38,0,34,37,0
0,0,39,0,0,0,0,23,0,0,0,0,0,0,0,0,0,0,0,0,0,0,39,38,0,34,37,0
0,0,23,0,0,0,0,23,0,0,0,0,0,0,0,0,0,0,0,0,0,0,39,38,0,34,37,0
0,0,10,25,24,10,23,10,0,0,0,0,0,0,0,0,0,0,0,0,0,0,39,10,23,10,37,0
0,0,17,0,0,36,0,0,0,0,0,0,0,0,0,0,0,0,0,0,0,0,39,38,0,23,37,0
0,0,17,0,0,0,0,0,0,0,0,0,0,0,0,0,0,0,0,0,0,0,0,0,0,17,0,0
0,0,17,0,0,0,0,0,0,0,0,0,0,0,0,0,0,0,0,0,0,0,0,0,0,17,0,0
0,0,17,0,0,0,0,0,0,0,0,0,0,0,0,0,0,0,0,0,0,0,0,0,0,17,0,0
0,0,17,0,0,0,0,0,0,0,0,0,0,0,0,0,0,0,0,0,0,0,0,0,0,17,0,0
0,0,17,0,0,0,0,0,0,0,0,0,0,0,0,0,0,0,0,0,0,0,0,0,0,17,0,0
0,0,10,17,17,17,17,17,17,17,17,10,0,0,0,0,0,0,10,17,17,17,17,17,17,10,0,0
0,0,0,0,0,0,0,0,0,0,0,0,0,0,0,0,0,0,0,0,0,0,0,0,0,0,0,0
:endlayer
layer: 6
0,0,0,0,0,0,0,0,0,0,0,0,0,0,0,0,0,0,0,0,0,0,0,0,0,0,0,0
0,0,0,0,0,0,0,0,0,0,0,0,0,0,0,0,0,0,0,0,0,0,0,0,0,0,0,0
0,0,43,43,43,43,43,43,43,43,43,43,43,43,43,43,0,0,0,0,0,0,0,0,0,0,0,0
0,0,35,10,0,0,0,0,0,0,0,0,0,0,10,35,0,0,0,0,0,0,0,0,36,0,0,0
0,0,0,23,0,0,0,0,0,0,0,0,0,0,23,0,0,0,0,0,0,0,0,0,0,0,0,0
0,0,0,23,0,0,0,0,0,0,0,0,0,0,23,0,0,0,0,0,0,0,0,0,0,0,0,0
0,0,0,23,0,0,0,0,0,0,0,0,0,0,23,0,0,0,0,0,0,0,0,0,0,0,0,0
0,0,15,10,0,0,0,0,0,0,0,0,0,0,10,15,0,0,0,0,0,0,0,0,0,0,0,0
0,0,14,14,14,14,14,14,14,14,14,14,14,14,14,14,0,0,0,0,0,0,0,0,0,0,0,0
0,0,0,0,0,0,0,0,0,0,0,0,0,0,0,0,0,0,0,0,0,0,0,0,0,0,0,0
0,0,0,0,0,0,0,0,0,0,0,0,0,0,0,0,0,0,0,0,0,0,0,0,0,0,0,0
0,0,0,0,0,0,0,0,0,0,0,0,0,0,0,0,0,0,0,0,39,38,0,34,37,0,0,0
0,0,0,0,0,0,0,0,0,0,0,0,0,0,0,0,0,0,0,0,39,10,20,10,37,0,0,0
0,0,0,0,0,0,0,0,0,0,0,0,0,0,0,0,0,0,0,0,39,38,0,34,37,0,0,0
0,0,10,20,10,46,10,46,10,20,10,0,0,0,0,0,0,0,0,0,39,38,0,34,37,0,0,0
0,0,20,0,0,0,23,0,0,0,20,0,0,0,0,0,0,0,0,0,39,38,0,34,37,0,0,0
0,0,10,0,0,0,10,0,0,0,10,0,0,0,0,0,0,0,0,0,39,38,0,34,37,0,0,0
0,0,46,0,0,0,23,0,0,0,46,0,0,0,0,0,0,0,0,0,39,38,0,34,37,0,0,0
0,0,10,0,10,23,10,0,10,23,10,0,0,0,0,0,0,0,0,0,39,38,0,34,37,0,0,0
0,0,20,0,0,0,0,0,0,0,48,0,0,0,0,0,0,0,0,0,39,38,0,34,37,0,0,0
0,12,47,0,0,0,10,0,0,0,10,0,0,0,0,0,0,0,0,0,39,38,0,34,23,37,0,0
0,7,0,0,0,0,23,0,0,0,46,0,0,0,0,0,0,0,0,0,39,10,20,10,10,37,0,0
0,12,45,0,0,0,10,0,0,0,10,0,0,0,0,0,0,0,0,0,39,38,0,23,9,37,0,0
0,0,20,40,0,0,0,0,0,0,20,0,0,0,0,0,0,0,0,0,0,0,0,39,9,37,0,0
0,0,10,0,0,0,10,20,10,20,10,0,0,0,0,0,0,0,0,0,0,0,0,39,9,37,0,0
0,0,23,0,0,0,0,23,0,0,0,0,0,0,0,0,0,0,0,0,0,0,0,39,9,37,0,0
0,0,44,0,0,0,0,23,0,0,0,0,0,0,0,0,0,0,0,0,0,0,0,39,9,37,0,0
0,0,23,0,0,0,0,23,0,0,0,0,0,0,0,0,0,0,0,0,0,0,0,39,9,37,0,0
0,0,10,30,29,10,23,10,0,0,0,0,0,0,0,0,0,0,0,0,0,0,0,39,10,37,0,0
0,0,0,0,0,0,0,0,0,0,0,0,0,0,0,0,0,0,0,0,0,0,0,39,14,37,0,0
0,0,0,0,0,0,0,0,0,0,0,0,0,0,0,0,0,0,0,0,0,0,0,0,0,0,0,0
0,0,0,0,0,0,0,0,0,0,0,0,0,0,0,0,0,0,0,0,0,0,0,0,0,0,0,0
0,0,0,0,0,0,0,0,0,0,0,0,0,0,0,0,0,0,0,0,0,0,0,0,0,0,0,0
0,0,0,0,0,0,0,0,0,0,0,0,0,0,0,0,0,0,0,0,0,0,0,0,0,0,0,0
0,0,0,0,0,0,0,0,0,0,0,0,0,0,0,0,0,0,0,0,0,0,0,0,0,0,0,0
0,0,36,0,0,0,0,0,0,0,0,36,0,0,0,0,0,0,36,0,0,0,0,0,0,36,0,0
0,0,0,0,0,0,0,0,0,0,0,0,0,0,0,0,0,0,0,0,0,0,0,0,0,0,0,0
:endlayer
layer: 7
0,0,0,0,0,0,0,0,0,0,0,0,0,0,0,0,0,0,0,0,0,0,0,0,0,0,0,0
0,0,0,0,0,0,0,0,0,0,0,0,0,0,0,0,0,0,0,0,0,0,0,0,0,0,0,0
0,0,0,0,0,0,0,0,0,0,0,0,0,0,0,0,0,0,0,0,0,0,0,0,0,0,0,0
0,0,43,43,43,43,43,43,43,43,43,43,43,43,43,43,0,0,0,0,0,0,0,0,0,0,0,0
0,0,35,10,0,0,0,0,0,0,0,0,0,0,10,35,0,0,0,0,0,0,0,0,0,0,0,0
0,0,0,23,0,0,0,0,0,0,0,0,0,0,23,0,0,0,0,0,0,0,0,0,0,0,0,0
0,0,15,10,0,0,0,0,0,0,0,0,0,0,10,15,0,0,0,0,0,0,0,0,0,0,0,0
0,0,14,14,14,14,14,14,14,14,14,14,14,14,14,14,0,0,0,0,0,0,0,0,0,0,0,0
0,0,0,0,0,0,0,0,0,0,0,0,0,0,0,0,0,0,0,0,0,0,0,0,0,0,0,0
0,0,0,0,0,0,0,0,0,0,0,0,0,0,0,0,0,0,0,0,0,0,0,0,0,0,0,0
0,0,0,0,0,0,0,0,0,0,0,0,0,0,0,0,0,0,0,0,0,0,0,0,0,0,0,0
0,0,0,0,0,0,0,0,0,0,0,0,0,0,0,0,0,0,0,0,0,39,43,37,0,0,0,0
0,0,0,0,0,0,0,0,0,0,0,0,0,0,0,0,0,0,0,0,0,39,10,37,0,0,0,0
0,0,17,0,0,0,0,0,0,0,17,0,0,0,0,0,0,0,0,0,0,39,9,37,0,0,0,0
0,17,10,20,10,46,10,46,10,20,10,17,0,0,0,0,0,0,0,0,0,39,9,37,0,0,0,0
0,0,20,0,0,0,23,0,0,0,20,0,0,0,0,0,0,0,0,0,0,39,9,37,0,0,0,0
0,0,10,0,0,0,10,0,0,0,10,0,0,0,0,0,0,0,0,0,0,39,9,37,0,0,0,0
0,0,46,0,0,0,23,0,0,0,46,0,0,0,0,0,0,0,0,0,0,39,9,37,0,0,0,0
0,0,10,23,10,23,10,23,10,23,10,0,0,0,0,0,0,0,0,0,0,39,9,37,0,0,0,0
0,0,20,0,0,0,0,0,0,0,20,0,0,0,0,0,0,0,0,0,0,39,9,37,0,0,0,0
0,0,7,0,0,0,10,38,0,34,10,0,0,0,0,0,0,0,0,0,0,39,9,37,36,0,0,0
0,7,49,0,0,0,23,0,0,0,46,0,0,0,0,0,0,0,0,0,0,39,10,37,36,0,0,0
0,0,7,0,0,0,10,0,0,0,10,0,0,0,0,0,0,0,0,0,0,39,14,37,36,0,0,0
0,0,20,40,0,0,23,0,0,0,20,0,0,0,0,0,0,0,0,0,0,0,0,0,36,0,0,0
0,33,10,38,0,34,10,20,10,20,10,17,0,0,0,0,0,0,0,0,0,0,0,0,36,0,0,0
0,33,9,38,0,0,34,9,33,0,17,0,0,0,0,0,0,0,0,0,0,0,0,0,36,0,0,0
0,33,9,38,0,0,34,9,33,0,0,0,0,0,0,0,0,0,0,0,0,0,0,0,36,0,0,0
0,33,9,38,15,15,34,9,33,0,0,0,0,0,0,0,0,0,0,0,0,0,0,0,36,0,0,0
0,33,10,3,3,3,3,10,33,0,0,0,0,0,0,0,0,0,0,0,0,0,0,0,36,0,0,0
0,33,33,33,33,33,33,33,33,0,0,0,0,0,0,0,0,0,0,0,0,0,0,0,0,0,0,0
0,0,0,0,0,0,0,0,0,0,0,0,0,0,0,0,0,0,0,0,0,0,0,0,0,0,0,0
0,0,0,0,0,0,0,0,0,0,0,0,0,0,0,0,0,0,0,0,0,0,0,0,0,0,0,0
0,0,0,0,0,0,0,0,0,0,0,0,0,0,0,0,0,0,0,0,0,0,0,0,0,0,0,0
0,0,0,0,0,0,0,0,0,0,0,0,0,0,0,0,0,0,0,0,0,0,0,0,0,0,0,0
0,0,0,0,0,0,0,0,0,0,0,0,0,0,0,0,0,0,0,0,0,0,0,0,0,0,0,0
0,0,0,0,0,0,0,0,0,0,0,0,0,0,0,0,0,0,0,0,0,0,0,0,0,0,0,0
0,0,0,0,0,0,0,0,0,0,0,0,0,0,0,0,0,0,0,0,0,0,0,0,0,0,0,0
:endlayer
layer: 8
0,0,0,0,0,0,0,0,0,0,0,0,0,0,0,0,0,0,0,0,0,0,0,0,0,0,0,0
0,0,0,0,0,0,0,0,0,0,0,0,0,0,0,0,0,0,0,0,0,0,0,0,0,0,0,0
0,0,0,0,0,0,0,0,0,0,0,0,0,0,0,0,0,0,0,0,0,0,0,0,0,0,0,0
0,0,0,0,0,0,0,0,0,0,0,0,0,0,0,0,0,0,0,0,0,0,0,0,0,0,0,0
0,0,43,43,43,43,43,43,43,43,43,43,43,43,43,43,0,0,0,0,0,0,0,0,0,0,0,0
0,0,39,10,3,3,3,3,3,3,3,3,3,3,10,37,0,0,0,0,0,0,0,0,0,0,0,0
0,0,14,14,14,14,14,14,14,14,14,14,14,14,14,14,0,0,0,0,0,0,0,0,0,0,0,0
0,0,0,0,0,0,0,0,0,0,0,0,0,0,0,0,0,0,0,0,0,0,0,0,0,0,0,0
0,0,0,0,0,0,0,0,0,0,0,0,0,0,0,0,0,0,0,0,0,0,0,0,0,0,0,0
0,0,0,0,0,0,0,0,0,0,0,0,0,0,0,0,0,0,0,0,0,0,0,0,0,0,0,0
0,0,0,0,0,0,0,0,0,0,0,0,0,0,0,0,0,0,0,0,0,0,0,0,0,0,0,0
0,0,0,0,0,0,0,0,0,0,0,0,0,0,0,0,0,0,0,0,0,0,0,0,0,0,0,0
0,0,0,0,0,0,0,0,0,0,0,0,0,0,0,0,0,0,0,0,0,0,36,0,0,0,0,0
0,39,38,0,0,0,0,0,0,0,34,37,0,0,0,0,0,0,0,0,0,0,36,0,0,0,0,0
0,39,10,3,3,3,3,3,3,3,10,37,0,0,0,0,0,0,0,0,0,0,36,0,0,0,0,0
0,39,9,33,33,33,9,33,33,33,9,37,0,0,0,0,0,0,0,0,0,0,36,0,0,0,0,0
0,39,9,33,33,33,9,33,33,33,9,37,0,0,0,0,0,0,0,0,0,0,36,0,0,0,0,0
0,39,9,33,33,33,9,33,33,33,9,37,0,0,0,0,0,0,0,0,0,0,36,0,0,0,0,0
0,39,9,3,3,3,3,3,3,3,9,37,0,0,0,0,0,0,0,0,0,0,36,0,0,0,0,0
0,39,9,33,33,33,9,33,33,33,9,37,0,0,0,0,0,0,0,0,0,0,36,0,0,0,0,0
0,39,9,33,33,33,9,3,3,3,9,37,0,0,0,0,0,0,0,0,0,0,36,0,0,0,0,0
0,7,9,33,33,33,9,33,33,33,9,37,0,0,0,0,0,0,0,0,0,0,36,0,0,0,0,0
0,39,9,33,33,33,9,33,33,33,9,37,0,0,0,0,0,0,0,0,0,0,0,0,0,0,0,0
0,39,9,40,33,33,9,33,33,33,9,37,0,0,0,0,0,0,0,0,0,0,0,0,0,0,0,0
0,39,10,3,3,3,3,3,3,3,10,37,0,0,0,0,0,0,0,0,0,0,0,0,0,0,0,0
0,39,23,23,38,34,23,36,0,0,34,37,0,0,0,0,0,0,0,0,0,0,0,0,0,0,0,0
0,0,36,23,38,15,23,36,0,0,0,0,0,0,0,0,0,0,0,0,0,0,0,0,0,0,0,0
0,0,36,23,23,23,23,36,0,0,0,0,0,0,0,0,0,0,0,0,0,0,0,0,0,0,0,0
0,0,36,36,36,36,36,36,0,0,0,0,0,0,0,0,0,0,0,0,0,0,0,0,0,0,0,0
0,0,0,0,0,0,0,0,0,0,0,0,0,0,0,0,0,0,0,0,0,0,0,0,0,0,0,0
0,0,0,0,0,0,0,0,0,0,0,0,0,0,0,0,0,0,0,0,0,0,0,0,0,0,0,0
0,0,0,0,0,0,0,0,0,0,0,0,0,0,0,0,0,0,0,0,0,0,0,0,0,0,0,0
0,0,0,0,0,0,0,0,0,0,0,0,0,0,0,0,0,0,0,0,0,0,0,0,0,0,0,0
0,0,0,0,0,0,0,0,0,0,0,0,0,0,0,0,0,0,0,0,0,0,0,0,0,0,0,0
0,0,0,0,0,0,0,0,0,0,0,0,0,0,0,0,0,0,0,0,0,0,0,0,0,0,0,0
0,0,0,0,0,0,0,0,0,0,0,0,0,0,0,0,0,0,0,0,0,0,0,0,0,0,0,0
0,0,0,0,0,0,0,0,0,0,0,0,0,0,0,0,0,0,0,0,0,0,0,0,0,0,0,0
:endlayer
layer: 9
0,0,0,0,0,0,0,0,0,0,0,0,0,0,0,0,0,0,0,0,0,0,0,0,0,0,0,0
0,0,0,0,0,0,0,0,0,0,0,0,0,0,0,0,0,0,0,0,0,0,0,0,0,0,0,0
0,0,0,0,0,0,0,0,0,0,0,0,0,0,0,0,0,0,0,0,0,0,0,0,0,0,0,0
0,0,0,0,0,0,0,0,0,0,0,0,0,0,0,0,0,0,0,0,0,0,0,0,0,0,0,0
0,0,0,0,0,0,0,0,0,0,0,0,0,0,0,0,0,0,0,0,0,0,0,0,0,0,0,0
0,0,0,36,36,36,36,36,36,36,36,36,36,36,36,0,0,0,0,0,0,0,0,0,0,0,0,0
0,0,0,0,0,0,0,0,0,0,0,0,0,0,0,0,0,0,0,0,0,0,0,0,0,0,0,0
0,0,0,0,0,0,0,0,0,0,0,0,0,0,0,0,0,0,0,0,0,0,0,0,0,0,0,0
0,0,0,0,0,0,0,0,0,0,0,0,0,0,0,0,0,0,0,0,0,0,0,0,0,0,0,0
0,0,0,0,0,0,0,0,0,0,0,0,0,0,0,0,0,0,0,0,0,0,0,0,0,0,0,0
0,0,0,0,0,0,0,0,0,0,0,0,0,0,0,0,0,0,0,0,0,0,0,0,0,0,0,0
0,0,0,0,0,0,0,0,0,0,0,0,0,0,0,0,0,0,0,0,0,0,0,0,0,0,0,0
0,0,0,0,0,0,0,0,0,0,0,0,0,0,0,0,0,0,0,0,0,0,0,0,0,0,0,0
0,0,39,38,0,0,0,0,0,34,37,0,0,0,0,0,0,0,0,0,0,0,0,0,0,0,0,0
0,0,39,10,20,20,20,20,20,10,37,0,0,0,0,0,0,0,0,0,0,0,0,0,0,0,0,0
0,0,39,38,0,0,0,0,0,34,37,0,0,0,0,0,0,0,0,0,0,0,0,0,0,0,0,0
0,0,39,38,0,0,0,0,0,34,37,0,0,0,0,0,0,0,0,0,0,0,0,0,0,0,0,0
0,0,39,38,0,0,0,0,0,34,37,0,0,0,0,0,0,0,0,0,0,0,0,0,0,0,0,0
0,0,39,38,0,0,0,0,0,34,37,0,0,0,0,0,0,0,0,0,0,0,0,0,0,0,0,0
0,0,39,38,0,0,0,0,0,34,10,17,0,0,0,0,0,0,0,0,0,0,0,0,0,0,0,0
0,0,39,38,0,0,0,0,0,0,44,0,0,0,0,0,0,0,0,0,0,0,0,0,0,0,0,0
0,7,10,38,0,0,0,0,0,0,44,0,0,0,0,0,0,0,0,0,0,0,0,0,0,0,0,0
0,0,44,0,0,0,0,0,0,34,10,17,0,0,0,0,0,0,0,0,0,0,0,0,0,0,0,0
0,0,44,0,0,0,0,0,0,34,37,0,0,0,0,0,0,0,0,0,0,0,0,0,0,0,0,0
0,17,10,20,20,20,20,20,20,10,37,0,0,0,0,0,0,0,0,0,0,0,0,0,0,0,0,0
0,0,39,38,36,36,0,0,0,34,37,0,0,0,0,0,0,0,0,0,0,0,0,0,0,0,0,0
0,0,0,0,36,36,0,0,0,0,0,0,0,0,0,0,0,0,0,0,0,0,0,0,0,0,0,0
0,0,0,0,0,0,0,0,0,0,0,0,0,0,0,0,0,0,0,0,0,0,0,0,0,0,0,0
0,0,0,0,0,0,0,0,0,0,0,0,0,0,0,0,0,0,0,0,0,0,0,0,0,0,0,0
0,0,0,0,0,0,0,0,0,0,0,0,0,0,0,0,0,0,0,0,0,0,0,0,0,0,0,0
0,0,0,0,0,0,0,0,0,0,0,0,0,0,0,0,0,0,0,0,0,0,0,0,0,0,0,0
0,0,0,0,0,0,0,0,0,0,0,0,0,0,0,0,0,0,0,0,0,0,0,0,0,0,0,0
0,0,0,0,0,0,0,0,0,0,0,0,0,0,0,0,0,0,0,0,0,0,0,0,0,0,0,0
0,0,0,0,0,0,0,0,0,0,0,0,0,0,0,0,0,0,0,0,0,0,0,0,0,0,0,0
0,0,0,0,0,0,0,0,0,0,0,0,0,0,0,0,0,0,0,0,0,0,0,0,0,0,0,0
0,0,0,0,0,0,0,0,0,0,0,0,0,0,0,0,0,0,0,0,0,0,0,0,0,0,0,0
0,0,0,0,0,0,0,0,0,0,0,0,0,0,0,0,0,0,0,0,0,0,0,0,0,0,0,0
:endlayer
layer: 10
0,0,0,0,0,0,0,0,0,0,0,0,0,0,0,0,0,0,0,0,0,0,0,0,0,0,0,0
0,0,0,0,0,0,0,0,0,0,0,0,0,0,0,0,0,0,0,0,0,0,0,0,0,0,0,0
0,0,0,0,0,0,0,0,0,0,0,0,0,0,0,0,0,0,0,0,0,0,0,0,0,0,0,0
0,0,0,0,0,0,0,0,0,0,0,0,0,0,0,0,0,0,0,0,0,0,0,0,0,0,0,0
0,0,0,0,0,0,0,0,0,0,0,0,0,0,0,0,0,0,0,0,0,0,0,0,0,0,0,0
0,0,0,0,0,0,0,0,0,0,0,0,0,0,0,0,0,0,0,0,0,0,0,0,0,0,0,0
0,0,0,0,0,0,0,0,0,0,0,0,0,0,0,0,0,0,0,0,0,0,0,0,0,0,0,0
0,0,0,0,0,0,0,0,0,0,0,0,0,0,0,0,0,0,0,0,0,0,0,0,0,0,0,0
0,0,0,0,0,0,0,0,0,0,0,0,0,0,0,0,0,0,0,0,0,0,0,0,0,0,0,0
0,0,0,0,0,0,0,0,0,0,0,0,0,0,0,0,0,0,0,0,0,0,0,0,0,0,0,0
0,0,0,0,0,0,0,0,0,0,0,0,0,0,0,0,0,0,0,0,0,0,0,0,0,0,0,0
0,0,0,0,0,0,0,0,0,0,0,0,0,0,0,0,0,0,0,0,0,0,0,0,0,0,0,0
0,0,0,0,0,0,0,0,0,0,0,0,0,0,0,0,0,0,0,0,0,0,0,0,0,0,0,0
0,0,0,39,38,0,0,0,34,37,0,0,0,0,0,0,0,0,0,0,0,0,0,0,0,0,0,0
0,0,0,39,10,20,20,20,10,37,0,0,0,0,0,0,0,0,0,0,0,0,0,0,0,0,0,0
0,0,0,39,38,0,0,0,34,37,0,0,0,0,0,0,0,0,0,0,0,0,0,0,0,0,0,0
0,0,0,39,38,0,0,0,34,37,0,0,0,0,0,0,0,0,0,0,0,0,0,0,0,0,0,0
0,0,0,39,38,0,0,0,34,37,0,0,0,0,0,0,0,0,0,0,0,0,0,0,0,0,0,0
0,0,0,39,38,0,0,0,34,37,43,43,0,0,0,0,0,0,0,0,0,0,0,0,0,0,0,0
0,0,0,39,38,0,0,0,34,23,10,35,0,0,0,0,0,0,0,0,0,0,0,0,0,0,0,0
0,43,43,39,38,0,0,0,0,0,44,0,0,0,0,0,0,0,0,0,0,0,0,0,0,0,0,0
0,7,10,23,38,0,0,0,0,0,44,0,0,0,0,0,0,0,0,0,0,0,0,0,0,0,0,0
0,0,44,0,0,0,0,0,34,23,10,15,0,0,0,0,0,0,0,0,0,0,0,0,0,0,0,0
0,0,44,0,0,0,0,0,34,37,14,14,0,0,0,0,0,0,0,0,0,0,0,0,0,0,0,0
0,15,10,3,3,20,20,20,10,37,0,0,0,0,0,0,0,0,0,0,0,0,0,0,0,0,0,0
0,14,14,39,38,0,0,0,34,37,0,0,0,0,0,0,0,0,0,0,0,0,0,0,0,0,0,0
0,0,0,0,0,0,0,0,0,0,0,0,0,0,0,0,0,0,0,0,0,0,0,0,0,0,0,0
0,0,0,0,0,0,0,0,0,0,0,0,0,0,0,0,0,0,0,0,0,0,0,0,0,0,0,0
0,0,0,0,0,0,0,0,0,0,0,0,0,0,0,0,0,0,0,0,0,0,0,0,0,0,0,0
0,0,0,0,0,0,0,0,0,0,0,0,0,0,0,0,0,0,0,0,0,0,0,0,0,0,0,0
0,0,0,0,0,0,0,0,0,0,0,0,0,0,0,0,0,0,0,0,0,0,0,0,0,0,0,0
0,0,0,0,0,0,0,0,0,0,0,0,0,0,0,0,0,0,0,0,0,0,0,0,0,0,0,0
0,0,0,0,0,0,0,0,0,0,0,0,0,0,0,0,0,0,0,0,0,0,0,0,0,0,0,0
0,0,0,0,0,0,0,0,0,0,0,0,0,0,0,0,0,0,0,0,0,0,0,0,0,0,0,0
0,0,0,0,0,0,0,0,0,0,0,0,0,0,0,0,0,0,0,0,0,0,0,0,0,0,0,0
0,0,0,0,0,0,0,0,0,0,0,0,0,0,0,0,0,0,0,0,0,0,0,0,0,0,0,0
0,0,0,0,0,0,0,0,0,0,0,0,0,0,0,0,0,0,0,0,0,0,0,0,0,0,0,0
:endlayer
layer: 11
0,0,0,0,0,0,0,0,0,0,0,0,0,0,0,0,0,0,0,0,0,0,0,0,0,0,0,0
0,0,0,0,0,0,0,0,0,0,0,0,0,0,0,0,0,0,0,0,0,0,0,0,0,0,0,0
0,0,0,0,0,0,0,0,0,0,0,0,0,0,0,0,0,0,0,0,0,0,0,0,0,0,0,0
0,0,0,0,0,0,0,0,0,0,0,0,0,0,0,0,0,0,0,0,0,0,0,0,0,0,0,0
0,0,0,0,0,0,0,0,0,0,0,0,0,0,0,0,0,0,0,0,0,0,0,0,0,0,0,0
0,0,0,0,0,0,0,0,0,0,0,0,0,0,0,0,0,0,0,0,0,0,0,0,0,0,0,0
0,0,0,0,0,0,0,0,0,0,0,0,0,0,0,0,0,0,0,0,0,0,0,0,0,0,0,0
0,0,0,0,0,0,0,0,0,0,0,0,0,0,0,0,0,0,0,0,0,0,0,0,0,0,0,0
0,0,0,0,0,0,0,0,0,0,0,0,0,0,0,0,0,0,0,0,0,0,0,0,0,0,0,0
0,0,0,0,0,0,0,0,0,0,0,0,0,0,0,0,0,0,0,0,0,0,0,0,0,0,0,0
0,0,0,0,0,0,0,0,0,0,0,0,0,0,0,0,0,0,0,0,0,0,0,0,0,0,0,0
0,0,0,0,0,0,0,0,0,0,0,0,0,0,0,0,0,0,0,0,0,0,0,0,0,0,0,0
0,0,0,0,0,0,0,0,0,0,0,0,0,0,0,0,0,0,0,0,0,0,0,0,0,0,0,0
0,0,0,0,39,38,0,34,37,0,0,0,0,0,0,0,0,0,0,0,0,0,0,0,0,0,0,0
0,0,0,0,39,10,20,10,37,0,0,0,0,0,0,0,0,0,0,0,0,0,0,0,0,0,0,0
0,0,0,0,39,38,0,34,37,0,0,0,0,0,0,0,0,0,0,0,0,0,0,0,0,0,0,0
0,0,0,0,39,38,0,34,37,0,0,0,0,0,0,0,0,0,0,0,0,0,0,0,0,0,0,0
0,0,0,0,39,38,0,34,37,0,0,0,0,0,0,0,0,0,0,0,0,0,0,0,0,0,0,0
0,0,0,0,39,38,0,34,37,0,0,0,0,0,0,0,0,0,0,0,0,0,0,0,0,0,0,0
0,0,0,0,39,38,0,34,37,43,43,43,0,0,0,0,0,0,0,0,0,0,0,0,0,0,0,0
0,0,0,0,39,38,0,35,35,35,9,37,0,0,0,0,0,0,0,0,0,0,0,0,0,0,0,0
0,7,43,43,43,38,0,15,15,15,9,37,0,0,0,0,0,0,0,0,0,0,0,0,0,0,0,0
0,39,9,35,35,35,0,34,14,14,14,14,0,0,0,0,0,0,0,0,0,0,0,0,0,0,0,0
0,39,9,15,15,38,0,34,37,0,0,0,0,0,0,0,0,0,0,0,0,0,0,0,0,0,0,0
0,14,14,14,14,10,20,10,37,0,0,0,0,0,0,0,0,0,0,0,0,0,0,0,0,0,0,0
0,0,0,0,39,38,0,34,37,0,0,0,0,0,0,0,0,0,0,0,0,0,0,0,0,0,0,0
0,0,0,0,0,0,0,0,0,0,0,0,0,0,0,0,0,0,0,0,0,0,0,0,0,0,0,0
0,0,0,0,0,0,0,0,0,0,0,0,0,0,0,0,0,0,0,0,0,0,0,0,0,0,0,0
0,0,0,0,0,0,0,0,0,0,0,0,0,0,0,0,0,0,0,0,0,0,0,0,0,0,0,0
0,0,0,0,0,0,0,0,0,0,0,0,0,0,0,0,0,0,0,0,0,0,0,0,0,0,0,0
0,0,0,0,0,0,0,0,0,0,0,0,0,0,0,0,0,0,0,0,0,0,0,0,0,0,0,0
0,0,0,0,0,0,0,0,0,0,0,0,0,0,0,0,0,0,0,0,0,0,0,0,0,0,0,0
0,0,0,0,0,0,0,0,0,0,0,0,0,0,0,0,0,0,0,0,0,0,0,0,0,0,0,0
0,0,0,0,0,0,0,0,0,0,0,0,0,0,0,0,0,0,0,0,0,0,0,0,0,0,0,0
0,0,0,0,0,0,0,0,0,0,0,0,0,0,0,0,0,0,0,0,0,0,0,0,0,0,0,0
0,0,0,0,0,0,0,0,0,0,0,0,0,0,0,0,0,0,0,0,0,0,0,0,0,0,0,0
0,0,0,0,0,0,0,0,0,0,0,0,0,0,0,0,0,0,0,0,0,0,0,0,0,0,0,0
:endlayer
layer: 12
0,0,0,0,0,0,0,0,0,0,0,0,0,0,0,0,0,0,0,0,0,0,0,0,0,0,0,0
0,0,0,0,0,0,0,0,0,0,0,0,0,0,0,0,0,0,0,0,0,0,0,0,0,0,0,0
0,0,0,0,0,0,0,0,0,0,0,0,0,0,0,0,0,0,0,0,0,0,0,0,0,0,0,0
0,0,0,0,0,0,0,0,0,0,0,0,0,0,0,0,0,0,0,0,0,0,0,0,0,0,0,0
0,0,0,0,0,0,0,0,0,0,0,0,0,0,0,0,0,0,0,0,0,0,0,0,0,0,0,0
0,0,0,0,0,0,0,0,0,0,0,0,0,0,0,0,0,0,0,0,0,0,0,0,0,0,0,0
0,0,0,0,0,0,0,0,0,0,0,0,0,0,0,0,0,0,0,0,0,0,0,0,0,0,0,0
0,0,0,0,0,0,0,0,0,0,0,0,0,0,0,0,0,0,0,0,0,0,0,0,0,0,0,0
0,0,0,0,0,0,0,0,0,0,0,0,0,0,0,0,0,0,0,0,0,0,0,0,0,0,0,0
0,0,0,0,0,0,0,0,0,0,0,0,0,0,0,0,0,0,0,0,0,0,0,0,0,0,0,0
0,0,0,0,0,0,0,0,0,0,0,0,0,0,0,0,0,0,0,0,0,0,0,0,0,0,0,0
0,0,0,0,0,0,0,0,0,0,0,0,0,0,0,0,0,0,0,0,0,0,0,0,0,0,0,0
0,0,0,0,0,0,0,0,0,0,0,0,0,0,0,0,0,0,0,0,0,0,0,0,0,0,0,0
0,0,0,0,0,39,43,37,0,0,0,0,0,0,0,0,0,0,0,0,0,0,0,0,0,0,0,0
0,0,0,0,0,39,10,37,0,0,0,0,0,0,0,0,0,0,0,0,0,0,0,0,0,0,0,0
0,0,0,0,0,39,9,37,0,0,0,0,0,0,0,0,0,0,0,0,0,0,0,0,0,0,0,0
0,0,0,0,0,39,9,37,0,0,0,0,0,0,0,0,0,0,0,0,0,0,0,0,0,0,0,0
0,0,0,0,0,39,9,37,0,0,0,0,0,0,0,0,0,0,0,0,0,0,0,0,0,0,0,0
0,0,0,0,0,39,9,37,0,0,0,0,0,0,0,0,0,0,0,0,0,0,0,0,0,0,0,0
0,0,0,0,0,39,9,37,0,0,0,0,0,0,0,0,0,0,0,0,0,0,0,0,0,0,0,0
0,0,0,0,0,39,9,43,43,43,37,0,0,0,0,0,0,0,0,0,0,0,0,0,0,0,0,0
0,7,0,0,0,39,9,14,14,14,37,0,0,0,0,0,0,0,0,0,0,0,0,0,0,0,0,0
0,0,39,43,43,43,9,37,0,0,0,0,0,0,0,0,0,0,0,0,0,0,0,0,0,0,0,0
0,0,39,14,14,14,9,37,0,0,0,0,0,0,0,0,0,0,0,0,0,0,0,0,0,0,0,0
0,0,0,0,0,39,10,37,0,0,0,0,0,0,0,0,0,0,0,0,0,0,0,0,0,0,0,0
0,0,0,0,0,14,14,37,0,0,0,0,0,0,0,0,0,0,0,0,0,0,0,0,0,0,0,0
0,0,0,0,0,0,0,0,0,0,0,0,0,0,0,0,0,0,0,0,0,0,0,0,0,0,0,0
0,0,0,0,0,0,0,0,0,0,0,0,0,0,0,0,0,0,0,0,0,0,0,0,0,0,0,0
0,0,0,0,0,0,0,0,0,0,0,0,0,0,0,0,0,0,0,0,0,0,0,0,0,0,0,0
0,0,0,0,0,0,0,0,0,0,0,0,0,0,0,0,0,0,0,0,0,0,0,0,0,0,0,0
0,0,0,0,0,0,0,0,0,0,0,0,0,0,0,0,0,0,0,0,0,0,0,0,0,0,0,0
0,0,0,0,0,0,0,0,0,0,0,0,0,0,0,0,0,0,0,0,0,0,0,0,0,0,0,0
0,0,0,0,0,0,0,0,0,0,0,0,0,0,0,0,0,0,0,0,0,0,0,0,0,0,0,0
0,0,0,0,0,0,0,0,0,0,0,0,0,0,0,0,0,0,0,0,0,0,0,0,0,0,0,0
0,0,0,0,0,0,0,0,0,0,0,0,0,0,0,0,0,0,0,0,0,0,0,0,0,0,0,0
0,0,0,0,0,0,0,0,0,0,0,0,0,0,0,0,0,0,0,0,0,0,0,0,0,0,0,0
0,0,0,0,0,0,0,0,0,0,0,0,0,0,0,0,0,0,0,0,0,0,0,0,0,0,0,0
:endlayer
layer: 13
0,0,0,0,0,0,0,0,0,0,0,0,0,0,0,0,0,0,0,0,0,0,0,0,0,0,0,0
0,0,0,0,0,0,0,0,0,0,0,0,0,0,0,0,0,0,0,0,0,0,0,0,0,0,0,0
0,0,0,0,0,0,0,0,0,0,0,0,0,0,0,0,0,0,0,0,0,0,0,0,0,0,0,0
0,0,0,0,0,0,0,0,0,0,0,0,0,0,0,0,0,0,0,0,0,0,0,0,0,0,0,0
0,0,0,0,0,0,0,0,0,0,0,0,0,0,0,0,0,0,0,0,0,0,0,0,0,0,0,0
0,0,0,0,0,0,0,0,0,0,0,0,0,0,0,0,0,0,0,0,0,0,0,0,0,0,0,0
0,0,0,0,0,0,0,0,0,0,0,0,0,0,0,0,0,0,0,0,0,0,0,0,0,0,0,0
0,0,0,0,0,0,0,0,0,0,0,0,0,0,0,0,0,0,0,0,0,0,0,0,0,0,0,0
0,0,0,0,0,0,0,0,0,0,0,0,0,0,0,0,0,0,0,0,0,0,0,0,0,0,0,0
0,0,0,0,0,0,0,0,0,0,0,0,0,0,0,0,0,0,0,0,0,0,0,0,0,0,0,0
0,0,0,0,0,0,0,0,0,0,0,0,0,0,0,0,0,0,0,0,0,0,0,0,0,0,0,0
0,0,0,0,0,0,0,0,0,0,0,0,0,0,0,0,0,0,0,0,0,0,0,0,0,0,0,0
0,0,0,0,0,0,0,0,0,0,0,0,0,0,0,0,0,0,0,0,0,0,0,0,0,0,0,0
0,0,0,0,0,0,0,0,0,0,0,0,0,0,0,0,0,0,0,0,0,0,0,0,0,0,0,0
0,0,0,0,0,0,36,0,0,0,0,0,0,0,0,0,0,0,0,0,0,0,0,0,0,0,0,0
0,0,0,0,0,0,36,0,0,0,0,0,0,0,0,0,0,0,0,0,0,0,0,0,0,0,0,0
0,0,0,0,0,0,36,0,0,0,0,0,0,0,0,0,0,0,0,0,0,0,0,0,0,0,0,0
0,0,0,0,0,0,36,0,0,0,0,0,0,0,0,0,0,0,0,0,0,0,0,0,0,0,0,0
0,0,0,0,0,0,36,0,0,0,0,0,0,0,0,0,0,0,0,0,0,0,0,0,0,0,0,0
0,0,0,0,0,0,36,0,0,0,0,0,0,0,0,0,0,0,0,0,0,0,0,0,0,0,0,0
0,0,0,0,0,0,36,0,0,0,0,0,0,0,0,0,0,0,0,0,0,0,0,0,0,0,0,0
0,50,0,0,0,0,36,0,0,0,0,0,0,0,0,0,0,0,0,0,0,0,0,0,0,0,0,0
0,0,0,0,0,0,36,0,0,0,0,0,0,0,0,0,0,0,0,0,0,0,0,0,0,0,0,0
0,0,0,0,0,0,36,0,0,0,0,0,0,0,0,0,0,0,0,0,0,0,0,0,0,0,0,0
0,0,0,0,0,0,36,0,0,0,0,0,0,0,0,0,0,0,0,0,0,0,0,0,0,0,0,0
0,0,0,0,0,0,0,0,0,0,0,0,0,0,0,0,0,0,0,0,0,0,0,0,0,0,0,0
0,0,0,0,0,0,0,0,0,0,0,0,0,0,0,0,0,0,0,0,0,0,0,0,0,0,0,0
0,0,0,0,0,0,0,0,0,0,0,0,0,0,0,0,0,0,0,0,0,0,0,0,0,0,0,0
0,0,0,0,0,0,0,0,0,0,0,0,0,0,0,0,0,0,0,0,0,0,0,0,0,0,0,0
0,0,0,0,0,0,0,0,0,0,0,0,0,0,0,0,0,0,0,0,0,0,0,0,0,0,0,0
0,0,0,0,0,0,0,0,0,0,0,0,0,0,0,0,0,0,0,0,0,0,0,0,0,0,0,0
0,0,0,0,0,0,0,0,0,0,0,0,0,0,0,0,0,0,0,0,0,0,0,0,0,0,0,0
0,0,0,0,0,0,0,0,0,0,0,0,0,0,0,0,0,0,0,0,0,0,0,0,0,0,0,0
0,0,0,0,0,0,0,0,0,0,0,0,0,0,0,0,0,0,0,0,0,0,0,0,0,0,0,0
0,0,0,0,0,0,0,0,0,0,0,0,0,0,0,0,0,0,0,0,0,0,0,0,0,0,0,0
0,0,0,0,0,0,0,0,0,0,0,0,0,0,0,0,0,0,0,0,0,0,0,0,0,0,0,0
0,0,0,0,0,0,0,0,0,0,0,0,0,0,0,0,0,0,0,0,0,0,0,0,0,0,0,0
:endlayer
layer: 14
0,0,0,0,0,0,0,0,0,0,0,0,0,0,0,0,0,0,0,0,0,0,0,0,0,0,0,0
0,0,0,0,0,0,0,0,0,0,0,0,0,0,0,0,0,0,0,0,0,0,0,0,0,0,0,0
0,0,0,0,0,0,0,0,0,0,0,0,0,0,0,0,0,0,0,0,0,0,0,0,0,0,0,0
0,0,0,0,0,0,0,0,0,0,0,0,0,0,0,0,0,0,0,0,0,0,0,0,0,0,0,0
0,0,0,0,0,0,0,0,0,0,0,0,0,0,0,0,0,0,0,0,0,0,0,0,0,0,0,0
0,0,0,0,0,0,0,0,0,0,0,0,0,0,0,0,0,0,0,0,0,0,0,0,0,0,0,0
0,0,0,0,0,0,0,0,0,0,0,0,0,0,0,0,0,0,0,0,0,0,0,0,0,0,0,0
0,0,0,0,0,0,0,0,0,0,0,0,0,0,0,0,0,0,0,0,0,0,0,0,0,0,0,0
0,0,0,0,0,0,0,0,0,0,0,0,0,0,0,0,0,0,0,0,0,0,0,0,0,0,0,0
0,0,0,0,0,0,0,0,0,0,0,0,0,0,0,0,0,0,0,0,0,0,0,0,0,0,0,0
0,0,0,0,0,0,0,0,0,0,0,0,0,0,0,0,0,0,0,0,0,0,0,0,0,0,0,0
0,0,0,0,0,0,0,0,0,0,0,0,0,0,0,0,0,0,0,0,0,0,0,0,0,0,0,0
0,0,0,0,0,0,0,0,0,0,0,0,0,0,0,0,0,0,0,0,0,0,0,0,0,0,0,0
0,0,0,0,0,0,0,0,0,0,0,0,0,0,0,0,0,0,0,0,0,0,0,0,0,0,0,0
0,0,0,0,0,0,0,0,0,0,0,0,0,0,0,0,0,0,0,0,0,0,0,0,0,0,0,0
0,0,0,0,0,0,0,0,0,0,0,0,0,0,0,0,0,0,0,0,0,0,0,0,0,0,0,0
0,0,0,0,0,0,0,0,0,0,0,0,0,0,0,0,0,0,0,0,0,0,0,0,0,0,0,0
0,0,0,0,0,0,0,0,0,0,0,0,0,0,0,0,0,0,0,0,0,0,0,0,0,0,0,0
0,0,0,0,0,0,0,0,0,0,0,0,0,0,0,0,0,0,0,0,0,0,0,0,0,0,0,0
0,0,0,0,0,0,0,0,0,0,0,0,0,0,0,0,0,0,0,0,0,0,0,0,0,0,0,0
0,0,0,0,0,0,0,0,0,0,0,0,0,0,0,0,0,0,0,0,0,0,0,0,0,0,0,0
0,36,0,0,0,0,0,0,0,0,0,0,0,0,0,0,0,0,0,0,0,0,0,0,0,0,0,0
0,0,0,0,0,0,0,0,0,0,0,0,0,0,0,0,0,0,0,0,0,0,0,0,0,0,0,0
0,0,0,0,0,0,0,0,0,0,0,0,0,0,0,0,0,0,0,0,0,0,0,0,0,0,0,0
0,0,0,0,0,0,0,0,0,0,0,0,0,0,0,0,0,0,0,0,0,0,0,0,0,0,0,0
0,0,0,0,0,0,0,0,0,0,0,0,0,0,0,0,0,0,0,0,0,0,0,0,0,0,0,0
0,0,0,0,0,0,0,0,0,0,0,0,0,0,0,0,0,0,0,0,0,0,0,0,0,0,0,0
0,0,0,0,0,0,0,0,0,0,0,0,0,0,0,0,0,0,0,0,0,0,0,0,0,0,0,0
0,0,0,0,0,0,0,0,0,0,0,0,0,0,0,0,0,0,0,0,0,0,0,0,0,0,0,0
0,0,0,0,0,0,0,0,0,0,0,0,0,0,0,0,0,0,0,0,0,0,0,0,0,0,0,0
0,0,0,0,0,0,0,0,0,0,0,0,0,0,0,0,0,0,0,0,0,0,0,0,0,0,0,0
0,0,0,0,0,0,0,0,0,0,0,0,0,0,0,0,0,0,0,0,0,0,0,0,0,0,0,0
0,0,0,0,0,0,0,0,0,0,0,0,0,0,0,0,0,0,0,0,0,0,0,0,0,0,0,0
0,0,0,0,0,0,0,0,0,0,0,0,0,0,0,0,0,0,0,0,0,0,0,0,0,0,0,0
0,0,0,0,0,0,0,0,0,0,0,0,0,0,0,0,0,0,0,0,0,0,0,0,0,0,0,0
0,0,0,0,0,0,0,0,0,0,0,0,0,0,0,0,0,0,0,0,0,0,0,0,0,0,0,0
0,0,0,0,0,0,0,0,0,0,0,0,0,0,0,0,0,0,0,0,0,0,0,0,0,0,0,0
:endlayer

#### RULES ####
rule:
plugin=vanillaBlocks
number=1
data:
JSON:{blockState:{blockName:"minecraft:grass",properties:{snowy:"false"}}}
:enddata
:endrule

rule:
plugin=vanillaBlocks
number=2
data:
JSON:{blockState:{blockName:"minecraft:cobblestone"}}
:enddata
:endrule

rule:
plugin=vanillaBlocks
number=3
data:
JSON:{blockState:{blockName:"minecraft:log",properties:{variant:"spruce",axis:"x"}}}
:enddata
:endrule

rule:
plugin=vanillaBlocks
number=4
data:
JSON:{blockState:{blockName:"minecraft:stone",properties:{variant:"smooth_andesite"}}}
:enddata
:endrule

rule:
plugin=vanillaBlocks
number=5
data:
JSON:{blockState:{blockName:"minecraft:grass_path"}}
:enddata
:endrule

rule:
plugin=vanillaBlocks
number=6
data:
JSON:{blockState:{blockName:"minecraft:dirt",properties:{variant:"coarse_dirt",snowy:"false"}}}
:enddata
:endrule

rule:
plugin=vanillaBlocks
number=7
data:
JSON:{blockState:{blockName:"minecraft:stonebrick",properties:{variant:"stonebrick"}}}
:enddata
:endrule

rule:
plugin=vanillaBlocks
number=8
data:
JSON:{blockState:{blockName:"minecraft:stone",properties:{variant:"andesite"}}}
:enddata
:endrule

rule:
plugin=vanillaBlocks
number=9
data:
JSON:{blockState:{blockName:"minecraft:log",properties:{variant:"spruce",axis:"z"}}}
:enddata
:endrule

rule:
plugin=vanillaBlocks
number=10
data:
JSON:{blockState:{blockName:"minecraft:log",properties:{variant:"spruce",axis:"y"}}}
:enddata
:endrule

rule:
plugin=vanillaBlocks
number=11
data:
JSON:{blockState:{blockName:"minecraft:stone_brick_stairs",properties:{half:"bottom",shape:"straight",facing:"north"}}}
:enddata
:endrule

rule:
plugin=vanillaBlocks
number=12
data:
JSON:{blockState:{blockName:"minecraft:stone_brick_stairs",properties:{half:"bottom",shape:"straight",facing:"east"}}}
:enddata
:endrule

rule:
plugin=vanillaBlocks
number=13
data:
JSON:{blockState:{blockName:"minecraft:stone_brick_stairs",properties:{half:"bottom",shape:"straight",facing:"west"}}}
:enddata
:endrule

rule:
plugin=vanillaBlocks
number=14
data:
JSON:{blockState:{blockName:"minecraft:spruce_stairs",properties:{half:"bottom",shape:"straight",facing:"north"}}}
:enddata
:endrule

rule:
plugin=vanillaBlocks
number=15
data:
JSON:{blockState:{blockName:"minecraft:spruce_stairs",properties:{half:"top",shape:"straight",facing:"south"}}}
:enddata
:endrule

rule:
plugin=vanillaBlocks
number=16
data:
JSON:{blockState:{blockName:"minecraft:stone_brick_stairs",properties:{half:"bottom",shape:"straight",facing:"south"}}}
:enddata
:endrule

rule:
plugin=vanillaBlocks
number=17
data:
JSON:{blockState:{blockName:"minecraft:spruce_fence",properties:{east:"false",south:"false",north:"false",west:"false"}}}
:enddata
:endrule

rule:
plugin=doors
number=18
data:
JSON:{blockState:{blockName:"minecraft:spruce_door",properties:{hinge:"right",half:"lower",powered:"false",facing:"west",open:"false"}}}
:enddata
:endrule

rule:
plugin=doors
number=19
data:
JSON:{blockState:{blockName:"minecraft:spruce_door",properties:{hinge:"right",half:"lower",powered:"false",facing:"east",open:"false"}}}
:enddata
:endrule

rule:
plugin=vanillaBlocks
number=20
data:
JSON:{blockState:{blockName:"minecraft:stained_hardened_clay",properties:{color:"silver"}}}
:enddata
:endrule

rule:
plugin=doors
number=21
data:
JSON:{blockState:{blockName:"minecraft:spruce_door",properties:{hinge:"left",half:"lower",powered:"false",facing:"east",open:"false"}}}
:enddata
:endrule

rule:
plugin=vanillaBlocks
number=22
data:
JSON:{blockState:{blockName:"minecraft:spruce_fence_gate",properties:{in_wall:"false",powered:"false",facing:"east",open:"false"}}}
:enddata
:endrule

rule:
plugin=vanillaBlocks
number=23
data:
JSON:{blockState:{blockName:"minecraft:planks",properties:{variant:"spruce"}}}
:enddata
:endrule

rule:
plugin=doors
number=24
data:
JSON:{blockState:{blockName:"minecraft:spruce_door",properties:{hinge:"left",half:"lower",powered:"false",facing:"south",open:"false"}}}
:enddata
:endrule

rule:
plugin=doors
number=25
data:
JSON:{blockState:{blockName:"minecraft:spruce_door",properties:{hinge:"right",half:"lower",powered:"false",facing:"south",open:"false"}}}
:enddata
:endrule

rule:
plugin=doors
number=26
data:
JSON:{blockState:{blockName:"minecraft:spruce_door",properties:{hinge:"right",half:"upper",powered:"false",facing:"west",open:"false"}}}
:enddata
:endrule

rule:
plugin=doors
number=27
data:
JSON:{blockState:{blockName:"minecraft:spruce_door",properties:{hinge:"right",half:"upper",powered:"false",facing:"east",open:"false"}}}
:enddata
:endrule

rule:
plugin=doors
number=28
data:
JSON:{blockState:{blockName:"minecraft:spruce_door",properties:{hinge:"left",half:"upper",powered:"false",facing:"east",open:"false"}}}
:enddata
:endrule

rule:
plugin=doors
number=29
data:
JSON:{blockState:{blockName:"minecraft:spruce_door",properties:{hinge:"left",half:"upper",powered:"false",facing:"south",open:"false"}}}
:enddata
:endrule

rule:
plugin=doors
number=30
data:
JSON:{blockState:{blockName:"minecraft:spruce_door",properties:{hinge:"right",half:"upper",powered:"false",facing:"south",open:"false"}}}
:enddata
:endrule

rule:
plugin=vanillaBlocks
number=31
data:
JSON:{blockState:{blockName:"minecraft:stone_stairs",properties:{half:"top",shape:"straight",facing:"south"}}}
:enddata
:endrule

rule:
plugin=vanillaBlocks
number=32
data:
JSON:{blockState:{blockName:"minecraft:stone_stairs",properties:{half:"top",shape:"straight",facing:"north"}}}
:enddata
:endrule

rule:
plugin=vanillaBlocks
number=33
data:
JSON:{blockState:{blockName:"minecraft:wooden_slab",properties:{half:"top",variant:"spruce"}}}
:enddata
:endrule

rule:
plugin=vanillaBlocks
number=34
data:
JSON:{blockState:{blockName:"minecraft:spruce_stairs",properties:{half:"top",shape:"straight",facing:"east"}}}
:enddata
:endrule

rule:
plugin=vanillaBlocks
number=35
data:
JSON:{blockState:{blockName:"minecraft:spruce_stairs",properties:{half:"top",shape:"straight",facing:"north"}}}
:enddata
:endrule

rule:
plugin=vanillaBlocks
number=36
data:
JSON:{blockState:{blockName:"minecraft:wooden_slab",properties:{half:"bottom",variant:"spruce"}}}
:enddata
:endrule

rule:
plugin=vanillaBlocks
number=37
data:
JSON:{blockState:{blockName:"minecraft:spruce_stairs",properties:{half:"bottom",shape:"straight",facing:"west"}}}
:enddata
:endrule

rule:
plugin=vanillaBlocks
number=38
data:
JSON:{blockState:{blockName:"minecraft:spruce_stairs",properties:{half:"top",shape:"straight",facing:"west"}}}
:enddata
:endrule

rule:
plugin=vanillaBlocks
number=39
data:
JSON:{blockState:{blockName:"minecraft:spruce_stairs",properties:{half:"bottom",shape:"straight",facing:"east"}}}
:enddata
:endrule

rule:
plugin=vanillaBlocks
number=40
data:
JSON:{blockState:{blockName:"minecraft:ladder",properties:{facing:"east"}}}
:enddata
:endrule

rule:
plugin=vanillaBlocks
number=41
data:
JSON:{blockState:{blockName:"ancientwarfarestructure:fire_pit",properties:{lit:"true",variant:"log"}}}
:enddata
:endrule

rule:
plugin=doors
number=42
data:
JSON:{blockState:{blockName:"minecraft:wooden_door",properties:{hinge:"right",half:"lower",powered:"false",facing:"west",open:"false"}}}
:enddata
:endrule

rule:
plugin=vanillaBlocks
number=43
data:
JSON:{blockState:{blockName:"minecraft:spruce_stairs",properties:{half:"bottom",shape:"straight",facing:"south"}}}
:enddata
:endrule

rule:
plugin=vanillaBlocks
number=44
data:
JSON:{blockState:{blockName:"minecraft:fence",properties:{east:"false",south:"false",north:"false",west:"false"}}}
:enddata
:endrule

rule:
plugin=vanillaBlocks
number=45
data:
JSON:{blockState:{blockName:"minecraft:stone_brick_stairs",properties:{half:"top",shape:"straight",facing:"south"}}}
:enddata
:endrule

rule:
plugin=vanillaBlocks
number=46
data:
JSON:{blockState:{blockName:"minecraft:stained_glass_pane",properties:{east:"false",color:"gray",south:"false",north:"false",west:"false"}}}
:enddata
:endrule

rule:
plugin=vanillaBlocks
number=47
data:
JSON:{blockState:{blockName:"minecraft:stone_brick_stairs",properties:{half:"top",shape:"straight",facing:"north"}}}
:enddata
:endrule

rule:
plugin=doors
number=48
data:
JSON:{blockState:{blockName:"minecraft:wooden_door",properties:{hinge:"right",half:"upper",powered:"false",facing:"west",open:"false"}}}
:enddata
:endrule

rule:
plugin=vanillaBlocks
number=49
data:
JSON:{blockState:{blockName:"minecraft:stone_brick_stairs",properties:{half:"top",shape:"straight",facing:"west"}}}
:enddata
:endrule

rule:
plugin=vanillaBlocks
number=50
data:
JSON:{blockState:{blockName:"minecraft:cobblestone_wall",properties:{east:"false",south:"false",north:"false",variant:"cobblestone",west:"false",up:"false"}}}
:enddata
:endrule

#### ENTITIES ####
