# Ancient Warfare Structure Template File
# Auto-generated structure template file. created on: 2/4/2022 at: 18:50:29
# Lines beginning with # denote comments

header:
version=2.11
name=SB_T1Keep_pine
mods=biomesoplenty
size=25,17,23
offset=12,1,22
:endheader

#### VALIDATION ####
validation:
type=ground
structureAuthor=TheOddlySeagull
survival=true
worldGenEnabled=false
unique=false
preserveBlocks=false
preventNaturalHostileSpawns=false
selectionWeight=1
clusterValue=1
minDuplicateDistance=1
dimensionWhiteList=true
dimensionList=
biomeGroupList=
biomeWhiteList=true
biomeList=
leveling=0
fill=0
border=0
blockSwap=false
territoryName=
biomeReplacement=minecraft:
minGenerationHeight=0
maxGenerationHeight=255
:endvalidation

#### LAYERS ####
layer: 0
1,1,1,1,1,1,1,1,1,1,1,1,1,1,1,1,1,1,1,1,1,1,1,1,1
1,2,2,2,2,2,1,1,1,1,1,1,1,1,1,1,1,1,1,1,1,1,1,1,1
1,2,2,2,2,2,1,1,1,2,1,1,1,1,1,2,1,1,1,2,1,1,1,1,1
1,2,2,2,2,2,2,2,2,2,2,2,2,2,2,2,2,2,2,2,2,2,1,1,1
1,2,2,2,2,2,3,3,3,3,3,3,3,3,3,3,3,1,1,1,1,2,1,1,1
1,2,2,2,2,2,3,3,3,3,3,3,3,3,3,3,3,1,1,4,1,2,2,1,1
1,1,1,2,3,3,3,3,3,3,3,3,3,3,3,3,3,1,1,1,1,2,1,1,1
1,1,1,2,3,3,3,3,3,3,3,3,3,3,3,3,3,1,1,1,1,2,1,1,1
1,1,1,2,3,3,3,3,3,3,3,3,3,3,3,3,3,1,1,1,1,2,1,1,1
1,1,2,2,3,3,3,3,3,3,3,3,3,3,3,3,3,1,1,1,1,2,2,1,1
1,1,1,2,3,3,3,3,3,3,3,3,3,3,3,3,3,1,1,1,1,2,1,1,1
1,1,1,2,3,3,3,3,3,3,3,3,3,3,3,3,3,1,1,1,1,2,1,1,1
1,1,1,2,3,3,3,3,3,3,3,3,3,3,3,3,3,1,1,1,1,2,1,1,1
1,1,2,2,3,3,3,3,3,3,3,3,3,3,3,3,3,1,1,1,1,2,2,1,1
1,1,1,2,3,3,3,3,3,3,3,3,3,3,3,3,3,1,1,1,1,2,1,1,1
1,1,1,2,3,3,3,3,3,3,3,3,3,3,3,3,3,1,1,1,1,2,1,1,1
1,1,1,2,3,3,3,3,3,3,3,3,3,3,3,3,3,1,1,1,1,2,1,1,1
1,1,2,2,2,2,3,3,3,2,2,2,2,2,2,2,3,1,1,2,2,2,2,2,1
1,1,1,2,2,2,3,3,3,2,2,2,2,2,2,2,1,1,1,2,2,2,2,2,1
1,1,1,2,2,2,2,2,2,2,2,2,2,2,2,2,2,2,2,2,2,2,2,2,1
1,1,1,1,1,2,1,1,1,2,1,2,2,2,1,2,1,1,1,2,2,2,2,2,1
1,1,1,1,1,1,1,1,1,1,1,2,2,2,1,1,1,1,1,2,2,2,2,2,1
1,1,1,1,1,1,1,1,1,1,1,2,2,2,1,1,1,1,1,1,1,1,1,1,1
:endlayer
layer: 1
0,0,0,0,0,0,0,0,0,0,0,0,0,0,0,0,0,0,0,0,0,0,0,0,0
0,4,2,2,2,4,0,0,0,0,0,0,0,0,0,0,0,0,0,0,0,0,0,0,0
0,2,0,0,0,2,0,0,0,4,0,0,0,0,0,4,0,0,0,4,0,0,0,0,0
0,2,0,4,0,2,2,2,2,2,2,2,2,2,2,2,2,2,2,2,2,2,0,0,0
0,2,5,6,0,0,0,0,0,5,5,5,5,5,5,5,5,0,0,0,0,2,0,0,0
0,4,2,2,2,4,0,0,4,4,0,0,0,0,0,4,4,0,0,4,0,2,4,0,0
0,0,0,2,0,5,7,0,5,0,0,0,0,0,0,0,5,0,0,0,0,2,0,0,0
0,0,0,2,0,5,5,0,0,0,0,0,0,0,0,0,5,0,0,0,8,2,0,0,0
0,0,0,2,0,0,0,0,5,0,0,0,0,0,0,0,5,0,0,0,9,2,0,0,0
0,0,4,2,4,5,5,5,4,4,0,0,0,0,0,4,4,0,0,0,10,2,4,0,0
0,0,0,2,0,0,0,0,5,0,0,0,0,0,0,0,5,0,0,0,0,2,0,0,0
0,0,0,2,0,0,0,0,0,0,0,0,0,0,0,0,5,0,0,0,0,2,0,0,0
0,0,0,2,0,0,0,0,5,0,0,0,0,0,0,0,5,0,0,0,0,2,0,0,0
0,0,4,2,4,0,0,0,4,4,0,0,0,0,0,4,4,0,0,0,0,2,4,0,0
0,0,0,2,0,0,0,0,5,0,0,0,0,0,0,0,0,0,0,0,0,2,0,0,0
0,0,0,2,0,0,0,0,5,0,0,0,0,0,0,0,0,0,0,0,0,2,0,0,0
0,0,0,2,0,0,0,0,5,0,0,0,0,0,0,0,0,0,0,0,0,2,0,0,0
0,0,4,2,2,4,0,0,0,4,2,0,0,0,2,4,4,0,0,4,2,2,2,4,0
0,0,0,2,2,2,0,0,0,2,2,0,0,0,2,2,0,0,0,0,0,11,0,2,0
0,0,0,2,2,2,2,2,2,2,2,0,0,0,2,2,2,2,2,2,0,4,12,2,0
0,0,0,0,0,4,0,0,0,4,0,0,0,0,0,4,0,0,0,2,0,0,0,2,0
0,0,0,0,0,0,0,0,0,0,0,0,0,0,0,0,0,0,0,4,2,2,2,4,0
0,0,0,0,0,0,0,0,0,0,0,0,0,0,0,0,0,0,0,0,0,0,0,0,0
:endlayer
layer: 2
0,0,0,0,0,0,0,0,0,0,0,0,0,0,0,0,0,0,0,0,0,0,0,0,0
0,4,2,2,2,4,0,0,0,0,0,0,0,0,0,0,0,0,0,0,0,0,0,0,0
0,2,0,13,0,2,0,0,0,4,0,0,0,0,0,4,0,0,0,4,0,0,0,0,0
0,2,9,4,0,2,2,2,2,2,2,2,2,2,2,2,2,2,2,2,2,2,0,0,0
0,2,14,0,0,0,0,0,0,5,5,5,5,5,5,5,5,0,0,0,0,2,0,0,0
0,4,2,2,2,4,0,0,4,4,0,0,0,0,0,4,4,0,0,4,0,2,4,0,0
0,0,0,2,0,15,0,0,5,0,0,0,0,0,0,0,5,0,0,0,0,2,0,0,0
0,0,0,2,12,15,7,0,0,0,0,0,0,0,0,0,16,0,0,0,9,2,0,0,0
0,0,0,2,0,0,0,0,5,0,0,0,0,0,0,0,5,0,0,0,10,2,0,0,0
0,0,4,2,4,5,5,5,4,4,0,0,0,0,0,4,4,0,0,0,0,2,4,0,0
0,0,0,2,0,0,0,0,5,0,0,0,0,0,0,0,5,0,0,0,0,2,0,0,0
0,0,0,2,0,0,0,0,0,0,0,0,0,0,0,0,16,0,0,0,0,2,0,0,0
0,0,0,2,0,0,0,0,5,0,0,0,0,0,0,0,5,0,0,0,0,2,0,0,0
0,0,4,2,4,0,0,0,4,4,0,0,0,0,0,4,4,0,0,0,0,2,4,0,0
0,0,0,2,0,0,0,0,5,0,0,0,0,0,0,0,0,0,0,0,0,2,0,0,0
0,0,0,2,0,0,0,0,5,0,0,0,0,0,0,0,0,0,0,0,0,2,0,0,0
0,0,0,2,0,0,0,0,5,0,0,0,0,0,0,0,0,0,0,0,0,2,0,0,0
0,0,4,2,2,4,0,0,0,4,2,0,0,0,2,4,4,0,0,4,2,2,2,4,0
0,0,0,2,2,2,0,0,0,2,2,0,0,0,2,2,0,0,0,0,0,0,14,2,0
0,0,0,2,2,2,2,2,2,2,2,0,0,0,2,2,2,2,2,2,0,4,17,2,0
0,0,0,0,0,4,0,0,0,4,0,0,0,0,0,4,0,0,0,2,0,0,0,2,0
0,0,0,0,0,0,0,0,0,0,0,0,0,0,0,0,0,0,0,4,2,2,2,4,0
0,0,0,0,0,0,0,0,0,0,0,0,0,0,0,0,0,0,0,0,0,0,0,0,0
:endlayer
layer: 3
0,0,0,13,0,0,0,0,0,0,0,0,0,0,0,0,0,0,0,0,0,0,0,0,0
0,4,2,2,2,4,0,0,0,0,0,0,0,0,0,0,0,0,0,0,0,0,0,0,0
0,2,10,18,0,2,0,13,0,4,0,0,13,0,0,4,0,13,0,4,0,0,0,0,0
19,2,0,4,0,2,2,2,2,2,2,2,2,2,2,2,2,2,2,2,2,2,0,0,0
0,2,0,0,0,2,0,20,0,5,5,5,5,5,5,5,5,0,0,0,0,2,0,0,0
0,4,2,2,2,4,0,0,4,4,12,0,0,0,19,4,4,12,0,4,0,2,4,0,0
0,0,0,2,21,0,0,0,5,0,0,0,0,0,0,0,5,0,0,0,9,2,0,0,0
0,0,19,2,0,0,0,0,5,0,0,0,0,0,0,0,16,0,0,0,10,2,12,0,0
0,0,0,2,9,0,7,9,5,0,0,0,0,0,0,0,5,0,0,0,0,2,0,0,0
0,0,4,2,4,5,5,5,4,4,12,0,0,0,19,4,4,12,0,0,0,2,4,0,0
0,0,0,2,21,0,0,0,5,0,0,0,0,0,0,0,5,0,0,0,19,2,0,0,0
0,0,19,2,12,0,0,0,5,0,0,0,0,0,0,0,16,0,0,0,0,2,12,0,0
0,0,0,2,9,0,0,0,5,0,0,0,0,0,0,0,5,0,0,0,0,2,0,0,0
0,0,4,2,4,0,0,19,4,4,12,0,0,0,19,4,4,12,0,0,0,2,4,0,0
0,0,0,2,21,0,0,0,5,0,0,0,0,0,0,0,21,0,0,0,0,2,0,0,0
0,0,19,2,12,0,0,0,5,0,0,0,0,0,0,0,0,0,0,0,19,2,12,0,0
0,0,0,2,9,0,0,0,5,0,13,0,0,0,13,0,9,0,0,0,0,2,0,0,0
0,0,4,2,2,4,22,0,23,4,2,22,0,23,2,4,4,12,0,4,2,2,2,4,0
0,0,0,2,2,2,0,13,0,2,2,0,0,0,2,2,0,0,0,2,0,0,0,2,0
0,0,0,2,2,2,2,2,2,2,2,22,0,23,2,2,2,2,2,2,0,4,0,2,12
0,0,0,0,0,4,0,20,0,4,0,0,0,0,0,4,0,20,0,2,0,17,14,2,0
0,0,0,0,0,0,0,0,0,0,0,0,0,0,0,0,0,0,0,4,2,2,2,4,0
0,0,0,0,0,0,0,0,0,0,0,0,0,0,0,0,0,0,0,0,0,20,0,0,0
:endlayer
layer: 4
0,0,0,0,0,0,0,0,0,0,0,0,0,0,0,0,0,0,0,0,0,0,0,0,0
0,4,2,2,2,4,0,0,0,0,0,0,0,0,0,0,0,0,0,0,0,0,0,0,0
0,2,0,11,21,2,0,0,0,4,0,0,0,0,0,4,0,0,0,4,24,0,0,0,0
0,2,0,4,0,2,2,2,2,2,2,2,2,2,2,2,2,2,2,2,2,2,0,0,0
0,2,0,20,0,2,0,0,0,5,5,5,5,5,5,5,5,0,0,0,0,2,22,0,0
0,4,2,2,2,4,18,25,4,4,18,0,0,0,25,4,4,0,0,4,9,2,4,0,0
0,0,0,2,5,0,0,0,5,21,0,0,0,0,0,21,6,0,0,0,10,2,0,0,0
0,0,0,2,5,0,0,0,5,0,0,0,0,0,0,0,6,0,0,0,0,2,0,0,0
0,0,0,2,5,0,0,11,5,9,0,0,0,0,0,9,6,0,0,0,0,2,0,0,0
0,0,4,2,4,5,5,5,4,4,18,0,0,0,25,4,4,0,0,0,0,2,4,0,0
0,0,0,2,5,0,0,0,5,21,0,0,0,0,0,21,6,0,0,0,0,2,0,0,0
0,0,0,2,5,0,0,0,5,0,0,0,0,0,0,0,6,0,0,0,0,2,0,0,0
0,0,0,2,5,0,0,0,5,9,0,0,0,0,0,9,6,0,0,0,0,2,0,0,0
0,0,4,2,4,0,0,0,4,4,18,0,0,0,25,4,4,0,0,0,0,2,4,0,0
0,0,0,2,5,0,0,0,5,21,0,0,0,0,0,21,6,0,0,0,0,2,0,0,0
0,0,0,2,5,0,0,0,5,0,0,0,0,0,0,0,6,0,0,0,0,2,0,0,0
0,0,0,2,5,0,0,0,5,9,0,0,0,0,0,9,6,0,0,0,0,2,0,0,0
0,0,4,2,2,4,2,2,2,4,2,2,2,2,2,4,4,17,17,4,2,2,2,4,0
0,0,23,2,2,2,26,26,26,2,2,22,0,23,2,2,0,0,0,2,0,0,0,2,0
0,0,0,2,2,2,2,2,2,2,2,2,2,2,2,2,2,2,2,2,19,4,0,2,0
0,0,0,0,27,4,0,0,0,4,0,0,0,0,0,4,0,0,0,2,6,0,0,2,0
0,0,0,0,0,0,0,0,0,0,0,0,0,0,0,0,0,0,0,4,2,2,2,4,0
0,0,0,0,0,0,0,0,0,0,0,0,0,0,0,0,0,0,0,0,0,0,0,0,0
:endlayer
layer: 5
0,0,0,0,0,0,0,0,0,0,0,0,0,0,0,0,0,0,0,0,0,0,0,0,0
0,4,28,28,28,4,0,0,0,0,0,0,0,0,0,0,0,0,0,0,0,0,0,0,0
0,29,0,0,0,29,9,17,9,4,9,17,9,17,9,4,9,17,9,4,2,2,0,0,0
0,29,0,4,14,29,28,28,28,28,28,28,28,28,28,28,28,28,28,28,28,2,2,0,0
0,29,0,17,17,29,5,5,5,5,5,5,5,5,5,5,5,5,5,5,5,29,2,0,0
0,4,28,28,28,4,28,28,28,4,28,28,28,28,28,4,28,28,28,4,10,29,4,0,0
0,0,25,29,5,29,5,5,5,29,17,17,17,17,17,29,0,0,0,29,0,29,18,0,0
0,0,17,29,5,29,0,0,5,29,17,17,17,17,17,29,0,0,0,29,0,29,17,0,0
0,0,25,29,5,29,0,0,11,29,17,17,17,17,17,29,0,0,0,29,0,29,18,0,0
0,0,4,29,5,29,28,28,28,29,28,28,28,28,28,29,6,0,0,29,0,29,4,0,0
0,0,25,29,5,29,17,17,5,29,17,17,17,17,17,29,0,0,0,29,9,29,18,0,0
0,0,17,29,5,29,17,17,5,29,17,17,17,17,17,29,0,0,0,29,5,29,17,0,0
0,0,25,29,5,29,17,17,5,29,17,17,17,17,17,29,0,0,0,29,5,29,18,0,0
0,0,4,29,5,29,28,28,28,29,28,28,28,28,28,29,6,0,0,29,5,29,4,0,0
0,0,25,29,5,29,17,17,5,29,17,17,17,17,17,29,0,0,0,29,5,29,18,0,0
0,0,17,29,5,29,17,17,5,29,17,17,17,17,17,29,0,0,0,29,5,29,17,0,0
0,0,25,29,5,29,17,17,5,29,17,17,17,17,17,29,0,0,0,29,5,29,18,0,0
0,0,4,29,5,4,28,28,28,28,28,28,28,28,28,28,28,28,28,4,28,28,28,4,0
0,0,2,29,5,5,5,5,5,5,5,6,0,11,5,5,5,5,5,29,17,17,0,29,0
0,0,2,2,28,28,28,28,28,28,28,28,28,28,28,28,28,28,28,29,10,4,12,29,0
0,0,0,2,2,4,21,17,21,4,21,17,21,17,21,4,21,17,21,29,0,0,0,29,0
0,0,0,0,0,0,0,0,0,0,0,0,0,0,0,0,0,0,0,4,28,28,28,4,0
0,0,0,0,0,0,0,0,0,0,0,0,0,0,0,0,0,0,0,0,0,0,0,0,0
:endlayer
layer: 6
0,0,0,0,0,0,0,0,0,0,0,0,0,0,0,0,0,0,0,0,0,0,0,0,0
0,4,5,5,5,4,0,0,0,0,0,0,0,0,0,0,0,0,0,0,0,0,0,0,0
0,5,0,13,0,5,7,5,7,5,7,5,7,5,7,5,7,5,7,5,30,30,0,0,0
0,11,17,4,0,0,0,0,0,0,0,0,0,0,0,0,0,0,0,0,0,0,30,0,0
0,5,14,0,0,5,0,0,0,0,0,0,0,0,0,0,0,0,0,0,0,0,30,0,0
0,4,5,0,5,4,5,0,5,4,5,0,5,5,5,4,15,15,15,15,0,0,5,0,0
0,0,11,0,0,5,0,0,0,5,0,0,0,0,0,5,0,0,0,15,0,0,6,0,0
0,0,5,0,0,5,0,0,0,0,0,0,0,0,0,5,0,0,0,15,0,19,5,0,0
0,0,11,0,0,5,0,0,0,5,0,0,0,0,0,5,0,0,0,15,0,0,6,0,0
0,0,5,12,0,4,5,5,5,4,0,0,0,0,0,4,0,0,0,15,0,0,5,0,0
0,0,11,0,0,0,0,0,0,5,0,0,0,0,0,5,0,0,0,15,0,0,6,0,0
0,0,5,0,0,0,0,0,0,0,0,0,0,0,0,5,0,0,0,15,0,0,5,0,0
0,0,11,0,0,0,0,0,0,5,0,0,0,0,0,5,0,0,0,15,0,0,6,0,0
0,0,5,12,0,0,0,0,0,4,5,5,5,5,5,4,0,0,0,15,0,0,5,0,0
0,0,11,0,0,0,0,0,0,0,0,0,0,0,0,15,0,0,0,15,0,0,6,0,0
0,0,5,0,0,0,0,0,0,0,0,0,0,0,0,15,0,0,0,15,0,19,5,0,0
0,0,11,0,0,0,0,0,0,0,0,0,0,0,0,15,0,0,0,15,0,0,6,0,0
0,0,5,12,0,0,0,0,0,0,0,0,0,0,0,15,15,15,15,4,5,0,5,4,0
0,0,30,0,0,0,0,0,0,0,0,0,0,0,0,0,0,0,0,5,0,0,14,5,0
0,0,30,0,0,0,0,0,0,13,0,0,0,0,0,13,0,0,0,0,0,4,17,6,0
0,0,0,30,30,5,10,5,10,5,10,5,10,5,10,5,10,5,10,5,0,0,0,5,0
0,0,0,0,0,0,0,0,0,0,0,0,0,0,0,0,0,0,0,4,5,5,5,4,0
0,0,0,0,0,0,0,0,0,0,0,0,0,0,0,0,0,0,0,0,0,0,0,0,0
:endlayer
layer: 7
0,0,0,0,0,0,0,0,0,0,0,0,0,0,0,0,0,0,0,0,0,0,0,0,0
0,4,5,7,5,4,0,0,0,0,0,0,0,0,0,0,0,0,0,0,0,0,0,0,0
0,5,14,17,0,5,0,14,0,14,0,14,0,14,0,14,0,14,0,14,0,0,0,0,0
0,0,0,4,0,0,0,0,0,0,0,0,0,0,0,0,0,0,0,0,0,0,0,0,0
0,5,0,0,0,5,0,0,0,0,0,0,0,0,0,0,0,0,0,0,0,0,0,0,0
0,4,5,0,5,4,5,0,5,4,5,0,5,16,5,4,0,0,0,0,0,0,14,0,0
0,0,0,0,0,5,0,0,0,5,0,0,0,0,0,5,0,0,0,0,0,0,0,0,0
0,0,14,0,0,16,0,0,0,0,0,0,0,0,0,16,0,0,0,0,0,0,14,0,0
0,0,0,0,0,5,0,0,0,5,0,0,0,0,0,5,0,0,0,0,0,0,0,0,0
0,0,14,0,0,4,5,16,5,4,0,0,0,0,0,4,0,0,0,0,0,0,14,0,0
0,0,0,0,0,0,0,0,0,5,0,0,0,0,0,5,0,0,0,0,0,0,0,0,0
0,0,14,0,0,0,0,0,0,0,0,0,0,0,0,16,0,0,0,0,0,0,14,0,0
0,0,0,0,0,0,0,0,0,5,0,0,0,0,0,5,0,0,0,0,0,0,0,0,0
0,0,14,0,0,0,0,0,0,4,5,16,5,16,5,4,0,0,0,0,0,0,14,0,0
0,0,0,0,0,0,0,0,0,0,0,0,0,0,0,0,0,0,0,0,0,0,0,0,0
0,0,14,0,0,0,0,0,0,0,0,0,0,0,0,0,0,0,0,0,0,0,14,0,0
0,0,0,0,0,0,0,0,0,0,0,0,0,0,0,0,0,0,0,0,0,0,0,0,0
0,0,14,0,0,0,0,0,0,0,0,0,0,0,0,0,0,0,0,4,5,0,5,4,0
0,0,0,0,0,0,0,0,0,0,0,0,0,0,0,0,0,0,0,5,0,0,0,5,0
0,0,0,0,0,0,0,0,0,0,0,0,0,0,0,0,0,0,0,0,19,4,0,0,0
0,0,0,0,0,14,0,14,0,14,0,14,0,14,0,14,0,14,0,5,0,17,14,5,0
0,0,0,0,0,0,0,0,0,0,0,0,0,0,0,0,0,0,0,4,5,10,5,4,0
0,0,0,0,0,0,0,0,0,0,0,0,0,0,0,0,0,0,0,0,0,0,0,0,0
:endlayer
layer: 8
0,0,0,0,0,0,0,0,0,0,0,0,0,0,0,0,0,0,0,0,0,0,0,0,0
0,4,5,0,5,4,0,0,0,0,0,0,0,0,0,0,0,0,0,0,0,0,0,0,0
0,5,0,0,14,5,0,0,0,0,0,0,0,0,0,0,0,0,0,0,0,0,0,0,0
0,17,0,4,17,18,0,0,0,0,0,0,0,0,0,0,0,0,0,0,0,0,0,0,0
0,5,0,20,0,5,0,0,0,13,0,0,0,0,0,13,0,0,0,0,0,0,0,0,0
0,4,5,21,5,4,5,5,5,4,5,5,5,16,5,4,12,0,0,0,0,0,0,0,0
0,0,0,0,0,5,0,20,0,5,0,0,20,0,0,5,0,0,0,0,0,0,0,0,0
0,0,0,0,0,5,12,0,19,5,0,0,0,0,0,16,0,0,0,0,0,0,0,0,0
0,0,0,0,0,5,0,13,0,5,0,0,0,0,0,5,0,0,0,0,0,0,0,0,0
0,0,0,0,19,4,5,5,5,4,12,0,0,0,19,4,12,0,0,0,0,0,0,0,0
0,0,0,0,0,20,0,0,0,5,0,0,0,0,0,5,0,0,0,0,0,0,0,0,0
0,0,0,0,0,0,0,0,0,5,0,0,0,0,0,16,0,0,0,0,0,0,0,0,0
0,0,0,0,0,0,0,0,0,5,0,0,13,0,0,5,0,0,0,0,0,0,0,0,0
0,0,0,0,0,0,0,0,19,4,5,16,5,16,5,4,12,0,0,0,0,0,0,0,0
0,0,0,0,0,0,0,0,0,20,0,0,0,0,0,20,0,0,0,0,0,0,0,0,0
0,0,0,0,0,0,0,0,0,0,0,0,0,0,0,0,0,0,0,0,0,0,0,0,0
0,0,0,0,0,0,0,0,0,0,0,0,0,0,0,0,0,0,0,0,0,0,0,0,0
0,0,0,0,0,0,0,0,0,0,0,0,0,0,0,0,0,0,0,4,5,9,5,4,0
0,0,0,0,0,0,0,0,0,0,0,0,0,0,0,0,0,0,0,5,0,0,0,5,0
0,0,0,0,0,0,0,0,0,0,0,0,0,0,0,0,0,0,0,25,17,4,0,17,0
0,0,0,0,0,0,0,0,0,0,0,0,0,0,0,0,0,0,0,5,14,0,0,5,0
0,0,0,0,0,0,0,0,0,0,0,0,0,0,0,0,0,0,0,4,5,0,5,4,0
0,0,0,0,0,0,0,0,0,0,0,0,0,0,0,0,0,0,0,0,0,0,0,0,0
:endlayer
layer: 9
0,0,0,0,0,0,0,0,0,0,0,0,0,0,0,0,0,0,0,0,0,0,0,0,0
0,4,5,17,5,4,0,0,0,0,0,0,0,0,0,0,0,0,0,0,0,0,0,0,0
0,29,0,0,0,5,0,0,0,0,0,0,0,0,0,0,0,0,0,0,0,0,0,0,0
0,29,0,4,0,0,0,0,0,0,0,0,0,0,0,0,0,0,0,0,0,0,0,0,0
0,29,0,17,14,5,17,17,17,17,17,17,17,17,17,17,17,0,0,0,0,0,0,0,0
0,4,5,10,5,4,28,28,28,4,28,28,28,28,28,4,17,0,0,0,0,0,0,0,0
0,0,0,0,17,29,0,0,0,29,0,0,0,0,0,29,17,0,0,0,0,0,0,0,0
0,0,0,0,17,29,0,0,0,29,0,0,0,0,0,29,17,0,0,0,0,0,0,0,0
0,0,0,0,17,29,0,0,0,29,0,0,0,0,0,29,17,0,0,0,0,0,0,0,0
0,0,0,0,17,4,28,28,28,29,0,0,0,0,0,29,17,0,0,0,0,0,0,0,0
0,0,0,0,17,17,17,17,17,29,0,0,0,0,0,29,17,0,0,0,0,0,0,0,0
0,0,0,0,0,0,0,0,17,29,0,0,0,0,0,29,17,0,0,0,0,0,0,0,0
0,0,0,0,0,0,0,0,17,29,0,0,0,0,0,29,17,0,0,0,0,0,0,0,0
0,0,0,0,0,0,0,0,17,4,28,28,28,28,28,4,17,0,0,0,0,0,0,0,0
0,0,0,0,0,0,0,0,17,17,17,17,17,17,17,17,17,0,0,0,0,0,0,0,0
0,0,0,0,0,0,0,0,0,0,0,0,0,0,0,0,0,0,0,0,0,0,0,0,0
0,0,0,0,0,0,0,0,0,0,0,0,0,0,0,0,0,0,0,0,0,0,0,0,0
0,0,0,0,0,0,0,0,0,0,0,0,0,0,0,0,0,0,0,4,5,7,5,4,0
0,0,0,0,0,0,0,0,0,0,0,0,0,0,0,0,0,0,0,5,14,17,0,29,0
0,0,0,0,0,0,0,0,0,0,0,0,0,0,0,0,0,0,0,0,0,4,12,29,0
0,0,0,0,0,0,0,0,0,0,0,0,0,0,0,0,0,0,0,5,0,0,0,29,0
0,0,0,0,0,0,0,0,0,0,0,0,0,0,0,0,0,0,0,4,5,17,5,4,0
0,0,0,0,0,0,0,0,0,0,0,0,0,0,0,0,0,0,0,0,0,0,0,0,0
:endlayer
layer: 10
0,0,0,0,0,0,0,0,0,0,0,0,0,0,0,0,0,0,0,0,0,0,0,0,0
0,4,28,28,28,4,0,0,0,0,0,0,0,0,0,0,0,0,0,0,0,0,0,0,0
0,5,0,13,0,5,0,0,0,0,0,0,0,0,0,0,0,0,0,0,0,0,0,0,0
0,5,17,4,0,17,0,0,0,0,0,0,0,0,0,0,0,0,0,0,0,0,0,0,0
0,5,14,0,0,5,0,0,0,0,0,0,8,0,0,0,0,0,0,0,0,0,0,0,0
0,4,5,0,5,4,14,14,14,14,14,14,14,14,14,14,0,0,0,0,0,0,0,0,0
0,0,0,0,0,14,5,5,5,5,5,5,5,5,5,14,0,0,0,0,0,0,0,0,0
0,0,0,0,0,14,5,17,5,5,5,17,17,17,5,14,0,0,0,0,0,0,0,0,0
0,0,0,0,0,14,5,5,5,5,5,17,0,17,5,14,0,0,0,0,0,0,0,0,0
0,0,0,0,0,14,14,14,14,14,5,17,0,17,5,14,0,0,0,0,0,0,0,0,0
0,0,0,0,0,0,0,0,0,14,5,17,0,17,5,14,0,0,0,0,0,0,0,0,0
0,0,0,0,0,0,0,0,0,14,5,17,17,17,5,14,0,0,0,0,0,0,0,0,0
0,0,0,0,0,0,0,0,0,14,5,5,5,5,5,14,0,0,0,0,0,0,0,0,0
0,0,0,0,0,0,0,0,0,14,14,14,14,14,14,14,0,0,0,0,0,0,0,0,0
0,0,0,0,0,0,0,0,0,0,0,0,8,0,0,0,0,0,0,0,0,0,0,0,0
0,0,0,0,0,0,0,0,0,0,0,0,0,0,0,0,0,0,0,0,0,0,0,0,0
0,0,0,0,0,0,0,0,0,0,0,0,0,0,0,0,0,0,0,0,0,0,0,0,0
0,0,0,0,0,0,0,0,0,0,0,0,0,0,0,0,0,0,0,4,5,0,5,4,0
0,0,0,0,0,0,0,0,0,0,0,0,0,0,0,0,0,0,0,5,0,0,14,5,0
0,0,0,0,0,0,0,0,0,0,0,0,0,0,0,0,0,0,0,17,0,4,17,5,0
0,0,0,0,0,0,0,0,0,0,0,0,0,0,0,0,0,0,0,5,0,0,0,5,0
0,0,0,0,0,0,0,0,0,0,0,0,0,0,0,0,0,0,0,4,28,28,28,4,0
0,0,0,0,0,0,0,0,0,0,0,0,0,0,0,0,0,0,0,0,0,0,0,0,0
:endlayer
layer: 11
0,15,0,0,0,15,0,0,0,0,0,0,0,0,0,0,0,0,0,0,0,0,0,0,0
15,4,5,5,5,4,15,0,0,0,0,0,0,0,0,0,0,0,0,0,0,0,0,0,0
0,5,14,17,0,5,0,0,0,0,0,0,0,0,0,0,0,0,0,0,0,0,0,0,0
0,5,0,4,0,5,0,0,0,0,0,0,0,0,0,0,0,0,0,0,0,0,0,0,0
0,5,0,20,0,5,0,0,0,0,0,0,0,0,0,0,0,0,0,0,0,0,0,0,0
15,4,5,17,5,4,15,0,0,0,0,0,0,0,0,0,0,0,0,0,0,0,0,0,0
0,15,0,0,0,15,0,0,0,0,0,0,0,0,0,0,0,0,0,0,0,0,0,0,0
0,0,0,0,0,0,8,14,14,14,14,14,14,14,0,0,0,0,0,0,0,0,0,0,0
0,0,0,0,0,0,0,0,0,0,0,14,5,14,0,0,0,0,0,0,0,0,0,0,0
0,0,0,0,0,0,0,0,0,0,0,14,5,14,0,0,0,0,0,0,0,0,0,0,0
0,0,0,0,0,0,0,0,0,0,0,14,5,14,0,0,0,0,0,0,0,0,0,0,0
0,0,0,0,0,0,0,0,0,0,0,14,14,14,0,0,0,0,0,0,0,0,0,0,0
0,0,0,0,0,0,0,0,0,0,0,0,0,0,0,0,0,0,0,0,0,0,0,0,0
0,0,0,0,0,0,0,0,0,0,0,0,0,0,0,0,0,0,0,0,0,0,0,0,0
0,0,0,0,0,0,0,0,0,0,0,0,0,0,0,0,0,0,0,0,0,0,0,0,0
0,0,0,0,0,0,0,0,0,0,0,0,0,0,0,0,0,0,0,0,0,0,0,0,0
0,0,0,0,0,0,0,0,0,0,0,0,0,0,0,0,0,0,0,15,0,0,0,15,0
0,0,0,0,0,0,0,0,0,0,0,0,0,0,0,0,0,0,15,4,5,17,5,4,15
0,0,0,0,0,0,0,0,0,0,0,0,0,0,0,0,0,0,0,5,0,0,0,5,0
0,0,0,0,0,0,0,0,0,0,0,0,0,0,0,0,0,0,0,5,19,4,0,5,0
0,0,0,0,0,0,0,0,0,0,0,0,0,0,0,0,0,0,0,5,0,17,14,5,0
0,0,0,0,0,0,0,0,0,0,0,0,0,0,0,0,0,0,15,4,5,5,5,4,15
0,0,0,0,0,0,0,0,0,0,0,0,0,0,0,0,0,0,0,15,0,0,0,15,0
:endlayer
layer: 12
9,9,17,9,17,9,9,0,0,0,0,0,0,0,0,0,0,0,0,0,0,0,0,0,0
25,4,28,28,28,4,18,0,0,0,0,0,0,0,0,0,0,0,0,0,0,0,0,0,0
17,29,0,0,14,29,17,0,0,0,0,0,0,0,0,0,0,0,0,0,0,0,0,0,0
25,29,0,4,17,29,18,0,0,0,0,0,0,0,0,0,0,0,0,0,0,0,0,0,0
17,29,0,17,17,29,17,0,0,0,0,0,0,0,0,0,0,0,0,0,0,0,0,0,0
25,4,28,28,28,4,18,0,0,0,0,0,0,0,0,0,0,0,0,0,0,0,0,0,0
25,21,17,21,17,21,21,0,0,0,0,0,0,0,0,0,0,0,0,0,0,0,0,0,0
0,0,0,0,0,0,0,0,0,0,0,0,0,0,0,0,0,0,0,0,0,0,0,0,0
0,0,0,0,0,0,0,0,0,0,0,0,0,0,0,0,0,0,0,0,0,0,0,0,0
0,0,0,0,0,0,0,0,0,0,0,0,8,0,0,0,0,0,0,0,0,0,0,0,0
0,0,0,0,0,0,0,0,0,0,0,0,0,0,0,0,0,0,0,0,0,0,0,0,0
0,0,0,0,0,0,0,0,0,0,0,0,0,0,0,0,0,0,0,0,0,0,0,0,0
0,0,0,0,0,0,0,0,0,0,0,0,0,0,0,0,0,0,0,0,0,0,0,0,0
0,0,0,0,0,0,0,0,0,0,0,0,0,0,0,0,0,0,0,0,0,0,0,0,0
0,0,0,0,0,0,0,0,0,0,0,0,0,0,0,0,0,0,0,0,0,0,0,0,0
0,0,0,0,0,0,0,0,0,0,0,0,0,0,0,0,0,0,0,0,0,0,0,0,0
0,0,0,0,0,0,0,0,0,0,0,0,0,0,0,0,0,0,9,9,17,9,17,9,9
0,0,0,0,0,0,0,0,0,0,0,0,0,0,0,0,0,0,25,4,28,28,28,4,18
0,0,0,0,0,0,0,0,0,0,0,0,0,0,0,0,0,0,17,29,17,17,0,29,17
0,0,0,0,0,0,0,0,0,0,0,0,0,0,0,0,0,0,25,29,17,4,0,29,18
0,0,0,0,0,0,0,0,0,0,0,0,0,0,0,0,0,0,17,29,14,0,0,29,17
0,0,0,0,0,0,0,0,0,0,0,0,0,0,0,0,0,0,25,4,28,28,28,4,18
0,0,0,0,0,0,0,0,0,0,0,0,0,0,0,0,0,0,25,21,17,21,17,21,21
:endlayer
layer: 13
5,7,5,7,5,7,5,0,0,0,0,0,0,0,0,0,0,0,0,0,0,0,0,0,0
11,8,0,0,0,8,6,0,0,0,0,0,0,0,0,0,0,0,0,0,0,0,0,0,0
5,0,0,0,0,0,5,0,0,0,0,0,0,0,0,0,0,0,0,0,0,0,0,0,0
11,0,0,4,0,0,6,0,0,0,0,0,0,0,0,0,0,0,0,0,0,0,0,0,0
5,0,0,0,0,0,5,0,0,0,0,0,0,0,0,0,0,0,0,0,0,0,0,0,0
11,8,0,0,0,8,6,0,0,0,0,0,0,0,0,0,0,0,0,0,0,0,0,0,0
5,10,5,10,5,10,5,0,0,0,0,0,0,0,0,0,0,0,0,0,0,0,0,0,0
0,0,0,0,0,0,0,0,0,0,0,0,0,0,0,0,0,0,0,0,0,0,0,0,0
0,0,0,0,0,0,0,0,0,0,0,0,0,0,0,0,0,0,0,0,0,0,0,0,0
0,0,0,0,0,0,0,0,0,0,0,0,0,0,0,0,0,0,0,0,0,0,0,0,0
0,0,0,0,0,0,0,0,0,0,0,0,0,0,0,0,0,0,0,0,0,0,0,0,0
0,0,0,0,0,0,0,0,0,0,0,0,0,0,0,0,0,0,0,0,0,0,0,0,0
0,0,0,0,0,0,0,0,0,0,0,0,0,0,0,0,0,0,0,0,0,0,0,0,0
0,0,0,0,0,0,0,0,0,0,0,0,0,0,0,0,0,0,0,0,0,0,0,0,0
0,0,0,0,0,0,0,0,0,0,0,0,0,0,0,0,0,0,0,0,0,0,0,0,0
0,0,0,0,0,0,0,0,0,0,0,0,0,0,0,0,0,0,0,0,0,0,0,0,0
0,0,0,0,0,0,0,0,0,0,0,0,0,0,0,0,0,0,5,7,5,7,5,7,5
0,0,0,0,0,0,0,0,0,0,0,0,0,0,0,0,0,0,11,8,0,0,0,8,6
0,0,0,0,0,0,0,0,0,0,0,0,0,0,0,0,0,0,5,0,0,0,0,0,5
0,0,0,0,0,0,0,0,0,0,0,0,0,0,0,0,0,0,11,0,0,4,0,0,6
0,0,0,0,0,0,0,0,0,0,0,0,0,0,0,0,0,0,5,0,0,0,0,0,5
0,0,0,0,0,0,0,0,0,0,0,0,0,0,0,0,0,0,11,8,0,0,0,8,6
0,0,0,0,0,0,0,0,0,0,0,0,0,0,0,0,0,0,5,10,5,10,5,10,5
:endlayer
layer: 14
14,0,14,0,14,0,14,0,0,0,0,0,0,0,0,0,0,0,0,0,0,0,0,0,0
0,0,0,0,0,0,0,0,0,0,0,0,0,0,0,0,0,0,0,0,0,0,0,0,0
14,0,0,0,0,0,14,0,0,0,0,0,0,0,0,0,0,0,0,0,0,0,0,0,0
0,0,0,15,0,0,0,0,0,0,0,0,0,0,0,0,0,0,0,0,0,0,0,0,0
14,0,0,0,0,0,14,0,0,0,0,0,0,0,0,0,0,0,0,0,0,0,0,0,0
0,0,0,0,0,0,0,0,0,0,0,0,0,0,0,0,0,0,0,0,0,0,0,0,0
14,0,14,0,14,0,14,0,0,0,0,0,0,0,0,0,0,0,0,0,0,0,0,0,0
0,0,0,0,0,0,0,0,0,0,0,0,0,0,0,0,0,0,0,0,0,0,0,0,0
0,0,0,0,0,0,0,0,0,0,0,0,0,0,0,0,0,0,0,0,0,0,0,0,0
0,0,0,0,0,0,0,0,0,0,0,0,0,0,0,0,0,0,0,0,0,0,0,0,0
0,0,0,0,0,0,0,0,0,0,0,0,0,0,0,0,0,0,0,0,0,0,0,0,0
0,0,0,0,0,0,0,0,0,0,0,0,0,0,0,0,0,0,0,0,0,0,0,0,0
0,0,0,0,0,0,0,0,0,0,0,0,0,0,0,0,0,0,0,0,0,0,0,0,0
0,0,0,0,0,0,0,0,0,0,0,0,0,0,0,0,0,0,0,0,0,0,0,0,0
0,0,0,0,0,0,0,0,0,0,0,0,0,0,0,0,0,0,0,0,0,0,0,0,0
0,0,0,0,0,0,0,0,0,0,0,0,0,0,0,0,0,0,0,0,0,0,0,0,0
0,0,0,0,0,0,0,0,0,0,0,0,0,0,0,0,0,0,14,0,14,0,14,0,14
0,0,0,0,0,0,0,0,0,0,0,0,0,0,0,0,0,0,0,0,0,0,0,0,0
0,0,0,0,0,0,0,0,0,0,0,0,0,0,0,0,0,0,14,0,0,0,0,0,14
0,0,0,0,0,0,0,0,0,0,0,0,0,0,0,0,0,0,0,0,0,15,0,0,0
0,0,0,0,0,0,0,0,0,0,0,0,0,0,0,0,0,0,14,0,0,0,0,0,14
0,0,0,0,0,0,0,0,0,0,0,0,0,0,0,0,0,0,0,0,0,0,0,0,0
0,0,0,0,0,0,0,0,0,0,0,0,0,0,0,0,0,0,14,0,14,0,14,0,14
:endlayer
layer: 15
0,0,0,0,0,0,0,0,0,0,0,0,0,0,0,0,0,0,0,0,0,0,0,0,0
0,0,0,0,0,0,0,0,0,0,0,0,0,0,0,0,0,0,0,0,0,0,0,0,0
0,0,0,0,0,0,0,0,0,0,0,0,0,0,0,0,0,0,0,0,0,0,0,0,0
0,0,0,15,0,0,0,0,0,0,0,0,0,0,0,0,0,0,0,0,0,0,0,0,0
0,0,0,0,0,0,0,0,0,0,0,0,0,0,0,0,0,0,0,0,0,0,0,0,0
0,0,0,0,0,0,0,0,0,0,0,0,0,0,0,0,0,0,0,0,0,0,0,0,0
0,0,0,0,0,0,0,0,0,0,0,0,0,0,0,0,0,0,0,0,0,0,0,0,0
0,0,0,0,0,0,0,0,0,0,0,0,0,0,0,0,0,0,0,0,0,0,0,0,0
0,0,0,0,0,0,0,0,0,0,0,0,0,0,0,0,0,0,0,0,0,0,0,0,0
0,0,0,0,0,0,0,0,0,0,0,0,0,0,0,0,0,0,0,0,0,0,0,0,0
0,0,0,0,0,0,0,0,0,0,0,0,0,0,0,0,0,0,0,0,0,0,0,0,0
0,0,0,0,0,0,0,0,0,0,0,0,0,0,0,0,0,0,0,0,0,0,0,0,0
0,0,0,0,0,0,0,0,0,0,0,0,0,0,0,0,0,0,0,0,0,0,0,0,0
0,0,0,0,0,0,0,0,0,0,0,0,0,0,0,0,0,0,0,0,0,0,0,0,0
0,0,0,0,0,0,0,0,0,0,0,0,0,0,0,0,0,0,0,0,0,0,0,0,0
0,0,0,0,0,0,0,0,0,0,0,0,0,0,0,0,0,0,0,0,0,0,0,0,0
0,0,0,0,0,0,0,0,0,0,0,0,0,0,0,0,0,0,0,0,0,0,0,0,0
0,0,0,0,0,0,0,0,0,0,0,0,0,0,0,0,0,0,0,0,0,0,0,0,0
0,0,0,0,0,0,0,0,0,0,0,0,0,0,0,0,0,0,0,0,0,0,0,0,0
0,0,0,0,0,0,0,0,0,0,0,0,0,0,0,0,0,0,0,0,0,15,0,0,0
0,0,0,0,0,0,0,0,0,0,0,0,0,0,0,0,0,0,0,0,0,0,0,0,0
0,0,0,0,0,0,0,0,0,0,0,0,0,0,0,0,0,0,0,0,0,0,0,0,0
0,0,0,0,0,0,0,0,0,0,0,0,0,0,0,0,0,0,0,0,0,0,0,0,0
:endlayer
layer: 16
0,0,0,0,0,0,0,0,0,0,0,0,0,0,0,0,0,0,0,0,0,0,0,0,0
0,0,0,0,0,0,0,0,0,0,0,0,0,0,0,0,0,0,0,0,0,0,0,0,0
0,0,0,0,0,0,0,0,0,0,0,0,0,0,0,0,0,0,0,0,0,0,0,0,0
0,0,0,8,0,0,0,0,0,0,0,0,0,0,0,0,0,0,0,0,0,0,0,0,0
0,0,0,0,0,0,0,0,0,0,0,0,0,0,0,0,0,0,0,0,0,0,0,0,0
0,0,0,0,0,0,0,0,0,0,0,0,0,0,0,0,0,0,0,0,0,0,0,0,0
0,0,0,0,0,0,0,0,0,0,0,0,0,0,0,0,0,0,0,0,0,0,0,0,0
0,0,0,0,0,0,0,0,0,0,0,0,0,0,0,0,0,0,0,0,0,0,0,0,0
0,0,0,0,0,0,0,0,0,0,0,0,0,0,0,0,0,0,0,0,0,0,0,0,0
0,0,0,0,0,0,0,0,0,0,0,0,0,0,0,0,0,0,0,0,0,0,0,0,0
0,0,0,0,0,0,0,0,0,0,0,0,0,0,0,0,0,0,0,0,0,0,0,0,0
0,0,0,0,0,0,0,0,0,0,0,0,0,0,0,0,0,0,0,0,0,0,0,0,0
0,0,0,0,0,0,0,0,0,0,0,0,0,0,0,0,0,0,0,0,0,0,0,0,0
0,0,0,0,0,0,0,0,0,0,0,0,0,0,0,0,0,0,0,0,0,0,0,0,0
0,0,0,0,0,0,0,0,0,0,0,0,0,0,0,0,0,0,0,0,0,0,0,0,0
0,0,0,0,0,0,0,0,0,0,0,0,0,0,0,0,0,0,0,0,0,0,0,0,0
0,0,0,0,0,0,0,0,0,0,0,0,0,0,0,0,0,0,0,0,0,0,0,0,0
0,0,0,0,0,0,0,0,0,0,0,0,0,0,0,0,0,0,0,0,0,0,0,0,0
0,0,0,0,0,0,0,0,0,0,0,0,0,0,0,0,0,0,0,0,0,0,0,0,0
0,0,0,0,0,0,0,0,0,0,0,0,0,0,0,0,0,0,0,0,0,8,0,0,0
0,0,0,0,0,0,0,0,0,0,0,0,0,0,0,0,0,0,0,0,0,0,0,0,0
0,0,0,0,0,0,0,0,0,0,0,0,0,0,0,0,0,0,0,0,0,0,0,0,0
0,0,0,0,0,0,0,0,0,0,0,0,0,0,0,0,0,0,0,0,0,0,0,0,0
:endlayer

#### RULES ####
rule:
plugin=vanillaBlocks
number=1
data:
JSON:{blockState:{blockName:"minecraft:dirt",properties:{variant:"dirt",snowy:"false"}}}
:enddata
:endrule

rule:
plugin=vanillaBlocks
number=2
data:
JSON:{blockState:{blockName:"minecraft:cobblestone"}}
:enddata
:endrule

rule:
plugin=vanillaBlocks
number=3
data:
JSON:{blockState:{blockName:"minecraft:stonebrick",properties:{variant:"stonebrick"}}}
:enddata
:endrule

rule:
plugin=vanillaBlocks
number=4
data:
JSON:{blockState:{blockName:"biomesoplenty:log_2",properties:{variant:"pine",axis:"y"}}}
:enddata
:endrule

rule:
plugin=vanillaBlocks
number=5
data:
JSON:{blockState:{blockName:"biomesoplenty:planks_0",properties:{variant:"pine"}}}
:enddata
:endrule

rule:
plugin=vanillaBlocks
number=6
data:
JSON:{blockState:{blockName:"biomesoplenty:pine_stairs",properties:{half:"bottom",shape:"straight",facing:"west"}}}
:enddata
:endrule

rule:
plugin=vanillaBlocks
number=7
data:
JSON:{blockState:{blockName:"biomesoplenty:pine_stairs",properties:{half:"bottom",shape:"straight",facing:"south"}}}
:enddata
:endrule

rule:
plugin=vanillaBlocks
number=8
data:
JSON:{blockState:{blockName:"minecraft:torch",properties:{facing:"up"}}}
:enddata
:endrule

rule:
plugin=vanillaBlocks
number=9
data:
JSON:{blockState:{blockName:"biomesoplenty:pine_stairs",properties:{half:"top",shape:"straight",facing:"south"}}}
:enddata
:endrule

rule:
plugin=vanillaBlocks
number=10
data:
JSON:{blockState:{blockName:"biomesoplenty:pine_stairs",properties:{half:"bottom",shape:"straight",facing:"north"}}}
:enddata
:endrule

rule:
plugin=vanillaBlocks
number=11
data:
JSON:{blockState:{blockName:"biomesoplenty:pine_stairs",properties:{half:"bottom",shape:"straight",facing:"east"}}}
:enddata
:endrule

rule:
plugin=vanillaBlocks
number=12
data:
JSON:{blockState:{blockName:"minecraft:torch",properties:{facing:"east"}}}
:enddata
:endrule

rule:
plugin=vanillaBlocks
number=13
data:
JSON:{blockState:{blockName:"minecraft:torch",properties:{facing:"north"}}}
:enddata
:endrule

rule:
plugin=vanillaBlocks
number=14
data:
JSON:{blockState:{blockName:"biomesoplenty:wood_slab_1",properties:{half:"bottom",variant:"pine"}}}
:enddata
:endrule

rule:
plugin=vanillaBlocks
number=15
data:
JSON:{blockState:{blockName:"biomesoplenty:pine_fence",properties:{east:"false",south:"false",north:"false",west:"false"}}}
:enddata
:endrule

rule:
plugin=vanillaBlocks
number=16
data:
JSON:{blockState:{blockName:"minecraft:glass_pane",properties:{east:"false",south:"false",north:"false",west:"false"}}}
:enddata
:endrule

rule:
plugin=vanillaBlocks
number=17
data:
JSON:{blockState:{blockName:"biomesoplenty:wood_slab_1",properties:{half:"top",variant:"pine"}}}
:enddata
:endrule

rule:
plugin=vanillaBlocks
number=18
data:
JSON:{blockState:{blockName:"biomesoplenty:pine_stairs",properties:{half:"top",shape:"straight",facing:"west"}}}
:enddata
:endrule

rule:
plugin=vanillaBlocks
number=19
data:
JSON:{blockState:{blockName:"minecraft:torch",properties:{facing:"west"}}}
:enddata
:endrule

rule:
plugin=vanillaBlocks
number=20
data:
JSON:{blockState:{blockName:"minecraft:torch",properties:{facing:"south"}}}
:enddata
:endrule

rule:
plugin=vanillaBlocks
number=21
data:
JSON:{blockState:{blockName:"biomesoplenty:pine_stairs",properties:{half:"top",shape:"straight",facing:"north"}}}
:enddata
:endrule

rule:
plugin=vanillaBlocks
number=22
data:
JSON:{blockState:{blockName:"minecraft:stone_stairs",properties:{half:"top",shape:"straight",facing:"west"}}}
:enddata
:endrule

rule:
plugin=vanillaBlocks
number=23
data:
JSON:{blockState:{blockName:"minecraft:stone_stairs",properties:{half:"top",shape:"straight",facing:"east"}}}
:enddata
:endrule

rule:
plugin=vanillaBlocks
number=24
data:
JSON:{blockState:{blockName:"minecraft:stone_stairs",properties:{half:"top",shape:"straight",facing:"south"}}}
:enddata
:endrule

rule:
plugin=vanillaBlocks
number=25
data:
JSON:{blockState:{blockName:"biomesoplenty:pine_stairs",properties:{half:"top",shape:"straight",facing:"east"}}}
:enddata
:endrule

rule:
plugin=vanillaBlocks
number=26
data:
JSON:{blockState:{blockName:"minecraft:stone_slab",properties:{half:"top",variant:"cobblestone"}}}
:enddata
:endrule

rule:
plugin=vanillaBlocks
number=27
data:
JSON:{blockState:{blockName:"minecraft:stone_stairs",properties:{half:"top",shape:"straight",facing:"north"}}}
:enddata
:endrule

rule:
plugin=vanillaBlocks
number=28
data:
JSON:{blockState:{blockName:"biomesoplenty:log_2",properties:{variant:"pine",axis:"x"}}}
:enddata
:endrule

rule:
plugin=vanillaBlocks
number=29
data:
JSON:{blockState:{blockName:"biomesoplenty:log_2",properties:{variant:"pine",axis:"z"}}}
:enddata
:endrule

rule:
plugin=vanillaBlocks
number=30
data:
JSON:{blockState:{blockName:"minecraft:stone_slab",properties:{half:"bottom",variant:"cobblestone"}}}
:enddata
:endrule

#### ENTITIES ####
