# Ancient Warfare Structure Template File
# Auto-generated structure template file. created on: 3/12/2021 at: 23:33:39
# Lines beginning with # denote comments

header:
version=2.11
name=SurvivalBuild_FortWall_small_type1_StraightGate_sacred_oak
mods=biomesoplenty
size=16,7,16
offset=15,0,15
:endheader

#### VALIDATION ####
validation:
type=ground
structureAuthor=TheOddlySeagull
survival=true
worldGenEnabled=false
unique=false
preserveBlocks=false
preventNaturalHostileSpawns=false
selectionWeight=1
clusterValue=1
minDuplicateDistance=1
dimensionWhiteList=true
dimensionList=
biomeGroupList=
biomeWhiteList=true
biomeList=
leveling=0
fill=0
border=0
blockSwap=false
territoryName=
biomeReplacement=minecraft:
minGenerationHeight=0
maxGenerationHeight=255
:endvalidation

#### LAYERS ####
layer: 0
0,0,0,0,0,0,0,0,0,0,0,0,0,0,0,0
0,0,0,0,0,0,0,0,0,0,0,0,0,0,0,0
0,0,0,0,0,0,0,0,0,0,0,0,0,0,0,0
0,0,3,3,0,0,0,0,0,0,0,0,3,3,0,0
0,0,2,2,0,0,0,0,0,0,0,0,2,2,0,0
0,0,2,2,0,0,0,0,0,0,0,0,2,2,0,0
0,1,2,2,1,0,0,0,0,0,0,1,2,2,1,0
0,2,2,2,2,0,0,0,0,0,0,2,2,2,2,0
1,2,2,2,2,1,0,0,0,0,1,2,2,2,2,1
0,1,2,2,1,0,0,0,0,0,0,1,2,2,1,0
0,0,0,0,0,0,0,0,0,0,0,0,0,0,0,0
0,0,0,0,0,0,0,0,0,0,0,0,0,0,0,0
0,0,0,0,0,0,0,0,0,0,0,0,0,0,0,0
0,0,0,0,0,0,0,0,0,0,0,0,0,0,0,0
0,0,0,0,0,0,0,0,0,0,0,0,0,0,0,0
0,0,0,0,0,0,0,0,0,0,0,0,0,0,0,0
:endlayer
layer: 1
0,0,0,0,0,0,0,0,0,0,0,0,0,0,0,0
0,0,0,0,0,0,0,0,0,0,0,0,0,0,0,0
0,0,0,0,0,0,0,0,0,0,0,0,0,0,0,0
0,0,0,0,0,0,0,0,0,0,0,0,0,0,0,0
0,0,3,3,0,0,0,0,0,0,0,0,3,3,0,0
0,5,2,2,7,0,0,0,0,0,0,5,2,2,7,0
0,1,6,6,1,0,0,0,0,0,0,1,6,6,1,0
0,4,2,2,4,0,0,0,0,0,0,4,2,2,4,0
1,4,2,2,4,1,0,0,0,0,1,4,2,2,4,1
0,1,6,6,1,0,0,0,0,0,0,1,6,6,1,0
0,0,0,0,0,0,0,0,0,0,0,0,0,0,0,0
0,0,0,0,0,0,0,0,0,0,0,0,0,0,0,0
0,0,0,0,0,0,0,0,0,0,0,0,0,0,0,0
0,0,0,0,0,0,0,0,0,0,0,0,0,0,0,0
0,0,0,0,0,0,0,0,0,0,0,0,0,0,0,0
0,0,0,0,0,0,0,0,0,0,0,0,0,0,0,0
:endlayer
layer: 2
0,0,0,0,0,0,0,0,0,0,0,0,0,0,0,0
0,0,0,0,0,0,0,0,0,0,0,0,0,0,0,0
0,0,0,0,0,0,0,0,0,0,0,0,0,0,0,0
0,0,0,0,0,0,0,0,0,0,0,0,0,0,0,0
0,0,0,0,0,0,0,0,0,0,0,0,0,0,0,0
0,0,0,0,0,0,0,0,0,0,0,0,0,0,0,0
0,1,0,0,1,0,0,0,0,0,0,1,0,0,1,0
0,2,0,0,9,0,0,0,0,0,0,10,0,0,2,0
1,2,0,0,2,1,0,0,0,0,1,2,0,0,2,1
0,1,8,8,1,0,0,0,0,0,0,1,8,8,1,0
0,0,0,0,0,0,0,0,0,0,0,0,0,0,0,0
0,0,0,0,0,0,0,0,0,0,0,0,0,0,0,0
0,0,0,0,0,0,0,0,0,0,0,0,0,0,0,0
0,0,0,0,0,0,0,0,0,0,0,0,0,0,0,0
0,0,0,0,0,0,0,0,0,0,0,0,0,0,0,0
0,0,0,0,0,0,0,0,0,0,0,0,0,0,0,0
:endlayer
layer: 3
0,0,0,0,0,0,0,0,0,0,0,0,0,0,0,0
0,0,0,0,0,0,0,0,0,0,0,0,0,0,0,0
0,0,0,0,0,0,0,0,0,0,0,0,0,0,0,0
0,0,0,0,0,0,0,0,0,0,0,0,0,0,0,0
0,0,0,0,0,0,0,0,0,0,0,0,0,0,0,0
0,0,0,0,0,0,0,0,0,0,0,0,0,0,0,0
0,1,0,0,1,0,0,0,0,0,0,1,0,0,1,0
0,2,0,0,0,0,0,0,0,0,0,0,0,0,2,0
9,2,0,0,2,1,12,0,0,13,1,2,0,0,2,10
0,1,0,0,1,11,0,0,0,0,11,1,0,0,1,0
0,0,0,0,0,0,0,0,0,0,0,0,0,0,0,0
0,0,0,0,0,0,0,0,0,0,0,0,0,0,0,0
0,0,0,0,0,0,0,0,0,0,0,0,0,0,0,0
0,0,0,0,0,0,0,0,0,0,0,0,0,0,0,0
0,0,0,0,0,0,0,0,0,0,0,0,0,0,0,0
0,0,0,0,0,0,0,0,0,0,0,0,0,0,0,0
:endlayer
layer: 4
0,0,0,0,0,0,0,0,0,0,0,0,0,0,0,0
0,0,0,0,0,0,0,0,0,0,0,0,0,0,0,0
0,0,0,0,0,0,0,0,0,0,0,0,0,0,0,0
0,0,0,0,0,0,0,0,0,0,0,0,0,0,0,0
0,0,0,0,0,0,0,0,0,0,0,0,0,0,0,0
0,14,0,0,14,0,0,0,0,0,0,14,0,0,14,0
14,1,16,16,1,14,0,0,0,0,14,1,16,16,1,14
0,2,0,0,12,17,0,0,0,0,17,13,0,0,2,0
0,2,0,0,2,1,6,6,6,6,1,2,0,0,2,0
14,1,15,15,1,14,0,0,0,0,14,1,15,15,1,14
0,14,0,0,14,0,0,0,0,0,0,14,0,0,14,0
0,0,0,0,0,0,0,0,0,0,0,0,0,0,0,0
0,0,0,0,0,0,0,0,0,0,0,0,0,0,0,0
0,0,0,0,0,0,0,0,0,0,0,0,0,0,0,0
0,0,0,0,0,0,0,0,0,0,0,0,0,0,0,0
0,0,0,0,0,0,0,0,0,0,0,0,0,0,0,0
:endlayer
layer: 5
0,0,0,0,0,0,0,0,0,0,0,0,0,0,0,0
0,0,0,0,0,0,0,0,0,0,0,0,0,0,0,0
0,0,0,0,0,0,0,0,0,0,0,0,0,0,0,0
0,0,0,0,0,0,0,0,0,0,0,0,0,0,0,0
0,0,0,0,0,0,0,0,0,0,0,0,0,0,0,0
10,3,3,3,3,3,0,0,0,0,3,3,3,3,3,9
10,1,6,6,1,9,0,0,0,0,10,1,6,6,1,9
10,4,0,0,4,9,3,3,3,3,10,4,0,0,4,9
10,4,0,0,4,6,6,6,6,6,6,4,0,0,4,9
10,1,6,6,1,9,8,8,8,8,10,1,6,6,1,9
10,8,8,8,8,8,0,0,0,0,8,8,8,8,8,9
0,0,0,0,0,0,0,0,0,0,0,0,0,0,0,0
0,0,0,0,0,0,0,0,0,0,0,0,0,0,0,0
0,0,0,0,0,0,0,0,0,0,0,0,0,0,0,0
0,0,0,0,0,0,0,0,0,0,0,0,0,0,0,0
0,0,0,0,0,0,0,0,0,0,0,0,0,0,0,0
:endlayer
layer: 6
0,0,0,0,0,0,0,0,0,0,0,0,0,0,0,0
0,0,0,0,0,0,0,0,0,0,0,0,0,0,0,0
0,0,0,0,0,0,0,0,0,0,0,0,0,0,0,0
0,0,0,0,0,0,0,0,0,0,0,0,0,0,0,0
0,0,0,0,0,0,0,0,0,0,0,0,0,0,0,0
0,0,0,0,0,0,0,0,0,0,0,0,0,0,0,0
0,18,18,18,18,0,0,0,0,0,0,18,18,18,18,0
0,18,2,2,18,0,0,0,0,0,0,18,2,2,18,0
0,18,2,2,18,18,18,18,18,18,18,18,2,2,18,0
0,18,18,18,18,0,0,0,0,0,0,18,18,18,18,0
0,0,0,0,0,0,0,0,0,0,0,0,0,0,0,0
0,0,0,0,0,0,0,0,0,0,0,0,0,0,0,0
0,0,0,0,0,0,0,0,0,0,0,0,0,0,0,0
0,0,0,0,0,0,0,0,0,0,0,0,0,0,0,0
0,0,0,0,0,0,0,0,0,0,0,0,0,0,0,0
0,0,0,0,0,0,0,0,0,0,0,0,0,0,0,0
:endlayer

#### RULES ####
rule:
plugin=vanillaBlocks
number=1
data:
JSON:{blockState:{blockName:"biomesoplenty:log_0",properties:{variant:"sacred_oak",axis:"y"}}}
:enddata
:endrule

rule:
plugin=vanillaBlocks
number=2
data:
JSON:{blockState:{blockName:"biomesoplenty:planks_0",properties:{variant:"sacred_oak"}}}
:enddata
:endrule

rule:
plugin=vanillaBlocks
number=3
data:
JSON:{blockState:{blockName:"biomesoplenty:sacred_oak_stairs",properties:{half:"bottom",shape:"straight",facing:"south"}}}
:enddata
:endrule

rule:
plugin=vanillaBlocks
number=4
data:
JSON:{blockState:{blockName:"biomesoplenty:log_0",properties:{variant:"sacred_oak",axis:"z"}}}
:enddata
:endrule

rule:
plugin=vanillaBlocks
number=5
data:
JSON:{blockState:{blockName:"minecraft:torch",properties:{facing:"west"}}}
:enddata
:endrule

rule:
plugin=vanillaBlocks
number=6
data:
JSON:{blockState:{blockName:"biomesoplenty:log_0",properties:{variant:"sacred_oak",axis:"x"}}}
:enddata
:endrule

rule:
plugin=vanillaBlocks
number=7
data:
JSON:{blockState:{blockName:"minecraft:torch",properties:{facing:"east"}}}
:enddata
:endrule

rule:
plugin=vanillaBlocks
number=8
data:
JSON:{blockState:{blockName:"biomesoplenty:sacred_oak_stairs",properties:{half:"bottom",shape:"straight",facing:"north"}}}
:enddata
:endrule

rule:
plugin=vanillaBlocks
number=9
data:
JSON:{blockState:{blockName:"biomesoplenty:sacred_oak_stairs",properties:{half:"bottom",shape:"straight",facing:"west"}}}
:enddata
:endrule

rule:
plugin=vanillaBlocks
number=10
data:
JSON:{blockState:{blockName:"biomesoplenty:sacred_oak_stairs",properties:{half:"bottom",shape:"straight",facing:"east"}}}
:enddata
:endrule

rule:
plugin=vanillaBlocks
number=11
data:
JSON:{blockState:{blockName:"minecraft:torch",properties:{facing:"south"}}}
:enddata
:endrule

rule:
plugin=vanillaBlocks
number=12
data:
JSON:{blockState:{blockName:"biomesoplenty:sacred_oak_stairs",properties:{half:"top",shape:"straight",facing:"west"}}}
:enddata
:endrule

rule:
plugin=vanillaBlocks
number=13
data:
JSON:{blockState:{blockName:"biomesoplenty:sacred_oak_stairs",properties:{half:"top",shape:"straight",facing:"east"}}}
:enddata
:endrule

rule:
plugin=vanillaBlocks
number=14
data:
JSON:{blockState:{blockName:"biomesoplenty:sacred_oak_fence",properties:{east:"false",south:"false",north:"false",west:"false"}}}
:enddata
:endrule

rule:
plugin=vanillaBlocks
number=15
data:
JSON:{blockState:{blockName:"biomesoplenty:sacred_oak_stairs",properties:{half:"top",shape:"straight",facing:"north"}}}
:enddata
:endrule

rule:
plugin=vanillaBlocks
number=16
data:
JSON:{blockState:{blockName:"biomesoplenty:sacred_oak_stairs",properties:{half:"top",shape:"straight",facing:"south"}}}
:enddata
:endrule

rule:
plugin=vanillaBlocks
number=17
data:
JSON:{blockState:{blockName:"minecraft:torch",properties:{facing:"north"}}}
:enddata
:endrule

rule:
plugin=vanillaBlocks
number=18
data:
JSON:{blockState:{blockName:"biomesoplenty:wood_slab_0",properties:{half:"bottom",variant:"sacred_oak"}}}
:enddata
:endrule

#### ENTITIES ####
