# Ancient Warfare Structure Template File
# Auto-generated structure template file. created on: 4/15/2023 at: 14:6:16
# Lines beginning with # denote comments

header:
version=2.11
name=SB_brewery_house_ebony
mods=biomesoplenty
size=14,15,16
offset=6,1,15
:endheader

#### VALIDATION ####
validation:
type=ground
structureAuthor=TheOddlySeagull
survival=true
worldGenEnabled=false
unique=false
preserveBlocks=false
preventNaturalHostileSpawns=false
selectionWeight=1
clusterValue=1
minDuplicateDistance=1
dimensionWhiteList=true
dimensionList=
biomeGroupList=
biomeWhiteList=true
biomeList=
leveling=0
fill=0
border=0
blockSwap=false
territoryName=
biomeReplacement=minecraft:
minGenerationHeight=0
maxGenerationHeight=255
:endvalidation

#### LAYERS ####
layer: 0
1,1,1,1,3,3,3,3,3,1,1,1,1,1
2,2,2,2,3,2,2,2,3,1,1,1,1,1
2,3,3,2,3,3,3,3,3,2,2,2,2,1
2,3,3,2,2,2,2,2,2,2,2,2,2,1
2,3,3,2,2,2,2,2,2,2,2,2,2,1
2,3,3,2,2,2,2,2,2,2,2,2,2,1
2,3,3,2,2,2,2,2,2,2,2,2,2,1
2,3,3,2,2,2,2,2,2,2,2,1,1,1
2,2,2,2,2,2,2,2,2,2,2,1,1,1
1,1,1,2,2,2,2,2,2,2,2,1,1,1
1,1,1,2,2,2,2,2,2,2,2,1,1,1
1,1,1,2,2,2,2,2,2,2,2,1,1,1
1,1,1,2,2,2,2,2,2,2,2,1,1,1
1,1,1,2,2,2,2,2,2,2,2,1,1,1
1,1,1,1,2,2,2,2,2,2,1,1,1,1
1,1,1,1,2,2,2,2,2,2,1,1,1,1
:endlayer
layer: 1
0,0,0,0,10,2,2,2,10,0,0,0,0,0
8,0,0,4,2,0,0,0,2,0,0,0,0,0
0,0,0,5,2,9,9,9,2,5,4,5,4,0
0,0,0,4,0,0,0,0,0,0,0,0,5,0
0,0,0,0,0,0,0,0,0,0,0,0,5,0
0,0,0,0,0,0,0,0,0,0,0,0,5,0
0,0,0,4,0,0,0,0,0,0,4,5,4,0
0,0,0,5,0,0,0,0,0,0,5,0,0,0
8,0,0,4,0,0,0,0,0,0,4,0,0,0
0,0,0,0,0,0,0,0,8,0,5,0,0,0
0,0,0,0,0,0,0,0,0,7,5,0,0,0
0,0,0,4,0,0,0,0,0,6,4,0,0,0
0,0,0,5,0,0,0,0,0,0,5,0,0,0
0,0,0,4,5,4,0,0,4,5,4,0,0,0
0,0,0,0,0,0,0,0,0,0,0,0,0,0
0,0,0,0,0,0,0,0,0,0,0,0,0,0
:endlayer
layer: 2
0,0,0,0,10,2,2,2,10,0,0,0,0,0
8,0,0,4,2,0,0,0,2,0,0,0,0,0
0,0,0,5,2,0,0,0,2,5,4,5,4,0
0,0,0,4,11,0,0,0,11,0,0,0,5,0
0,0,0,0,0,0,0,0,0,0,0,0,5,0
0,0,0,0,0,0,0,0,0,0,0,0,5,0
0,0,0,4,0,0,0,0,0,0,4,5,4,0
0,0,0,5,0,0,0,0,0,0,5,0,0,0
8,0,0,4,0,0,0,0,0,0,4,0,0,0
0,0,0,0,0,0,0,0,8,7,8,0,0,0
0,0,0,0,0,0,0,0,0,6,8,0,0,0
0,0,0,4,0,0,0,0,0,0,4,0,0,0
0,0,0,5,0,0,0,0,0,0,5,0,0,0
0,0,0,4,5,4,0,0,4,5,4,0,0,0
0,0,0,0,0,0,0,0,0,0,0,0,0,0
0,0,0,0,0,0,0,0,0,0,0,0,0,0
:endlayer
layer: 3
0,0,0,16,0,2,2,2,0,0,0,0,0,0
8,8,8,4,2,0,0,0,2,0,16,0,0,0
0,0,0,5,18,21,20,19,18,5,4,5,4,12
0,0,15,4,0,0,0,0,0,0,0,0,5,0
0,0,0,17,0,0,0,0,0,0,0,0,5,0
0,0,0,7,0,0,0,0,0,0,0,0,5,0
0,0,15,4,12,0,0,0,0,15,4,5,4,12
0,0,0,5,0,0,0,0,0,0,5,0,0,0
8,8,8,4,12,0,0,0,0,7,4,12,0,0
0,0,0,17,0,0,0,0,8,6,8,0,0,0
0,0,0,7,0,0,0,0,0,0,8,0,0,0
0,0,15,4,0,0,0,0,0,0,4,12,0,0
0,0,0,5,0,16,0,0,16,0,5,0,0,0
0,0,15,4,5,4,14,13,4,5,4,12,0,0
0,0,0,0,0,11,0,0,11,0,0,0,0,0
0,0,0,0,0,0,0,0,0,0,0,0,0,0
:endlayer
layer: 4
0,0,0,0,0,26,2,26,0,0,0,0,0,0
24,23,0,4,2,2,2,2,2,0,0,0,0,23
24,23,0,5,0,0,0,0,0,5,4,22,4,23
24,23,0,4,0,0,0,0,0,0,0,0,25,23
24,23,0,5,0,0,0,0,0,0,0,0,25,23
24,23,0,5,0,0,0,0,0,0,0,0,25,23
24,23,0,4,0,0,0,0,0,0,4,22,4,23
24,23,0,5,0,0,0,0,0,7,5,0,0,23
24,23,0,4,0,0,0,0,0,6,4,0,0,0
0,0,0,5,0,0,0,0,8,0,5,0,0,0
0,0,0,5,0,0,0,0,0,0,5,0,0,0
0,0,0,4,0,0,0,0,0,0,4,0,0,0
0,0,0,5,0,0,0,0,0,0,5,0,0,0
0,0,0,4,22,4,8,8,4,22,4,0,0,0
0,0,0,0,0,0,0,0,0,0,0,0,0,0
0,0,0,0,0,0,0,0,0,0,0,0,0,0
:endlayer
layer: 5
0,0,28,14,0,0,2,0,0,0,0,0,0,0
0,0,28,4,22,22,22,22,4,0,0,23,24,0
0,29,28,25,23,23,23,23,13,22,4,5,24,0
0,0,28,25,5,5,5,5,5,5,25,23,24,0
0,0,28,25,23,23,23,23,23,23,25,23,24,0
0,0,28,25,5,5,5,5,5,5,25,23,24,0
0,0,28,25,23,23,23,23,23,23,25,5,24,0
0,29,28,25,5,5,5,5,5,6,25,5,24,0
0,0,28,25,23,23,23,23,14,0,25,27,0,0
0,0,28,25,5,5,5,5,14,0,25,27,0,0
0,0,28,25,0,0,0,0,0,0,25,27,0,0
0,0,28,25,0,0,0,0,0,0,25,27,0,0
0,0,28,25,0,0,0,0,0,0,25,27,0,0
0,0,28,4,5,5,22,22,5,5,4,27,0,0
0,0,28,14,0,0,0,0,0,0,13,27,0,0
0,0,0,0,0,0,0,0,0,0,0,0,0,0
:endlayer
layer: 6
0,0,0,28,14,0,2,0,0,0,0,0,0,0
0,0,0,28,4,5,4,5,4,13,27,0,0,0
0,0,0,28,14,0,0,0,5,5,27,0,0,0
0,0,0,28,14,0,4,0,4,13,27,0,0,0
0,0,0,28,14,0,0,0,0,13,27,0,0,0
0,0,0,28,14,0,0,0,0,13,27,0,0,0
0,0,0,28,14,0,0,0,0,0,4,0,0,0
0,0,0,28,14,0,0,0,0,0,8,0,0,0
0,0,0,28,14,0,0,0,0,0,8,0,0,0
0,0,0,28,5,8,8,8,8,0,4,0,0,0
0,0,0,28,14,0,0,0,0,7,27,0,0,0
0,0,0,28,14,0,0,0,0,13,27,0,0,0
0,0,0,28,14,16,0,0,16,13,27,0,0,0
0,0,0,28,4,5,5,5,5,4,27,0,0,0
0,0,0,28,14,0,0,0,0,13,27,0,0,0
0,0,0,0,0,0,0,0,0,0,0,0,0,0
:endlayer
layer: 7
0,0,0,0,28,14,2,0,0,0,0,0,0,0
0,0,0,0,28,4,4,5,4,27,0,0,0,0
0,0,0,0,28,14,0,0,5,27,0,0,0,0
0,0,0,0,28,14,4,0,4,27,0,0,0,0
0,0,0,0,28,14,11,0,13,27,0,0,0,0
0,0,0,0,28,14,0,0,13,27,30,30,0,0
0,0,0,0,28,14,0,0,13,17,4,17,0,0
0,0,0,0,28,14,0,0,0,0,8,0,0,0
0,0,0,0,28,14,0,0,0,0,8,0,0,0
0,0,0,0,28,14,0,0,13,7,4,7,0,0
0,0,0,0,28,14,0,0,13,27,6,6,0,0
0,0,0,0,28,14,0,0,13,27,0,0,0,0
0,0,0,0,28,14,0,0,13,27,0,0,0,0
0,0,0,0,28,4,5,5,4,27,0,0,0,0
0,0,0,0,28,14,0,0,13,27,0,0,0,0
0,0,0,0,0,0,0,0,0,0,0,0,0,0
:endlayer
layer: 8
0,0,0,0,0,28,2,0,0,0,0,0,0,0
0,0,0,0,0,28,4,5,4,0,0,0,0,0
0,0,0,0,0,28,14,0,8,0,0,0,0,0
0,0,0,0,0,28,4,13,4,0,0,0,0,0
0,0,0,0,0,28,14,13,27,0,0,0,0,0
0,0,0,0,0,28,14,13,27,0,0,0,0,0
0,0,0,0,0,28,14,13,30,30,30,30,0,0
0,0,0,0,0,28,14,13,17,17,25,17,0,0
0,0,0,0,0,28,14,7,7,7,25,7,0,0
0,0,0,0,0,28,14,13,27,6,6,6,0,0
0,0,0,0,0,28,14,13,27,0,0,0,0,0
0,0,0,0,0,28,14,13,27,0,0,0,0,0
0,0,0,0,0,28,14,13,27,0,0,0,0,0
0,0,0,0,0,28,22,22,27,0,0,0,0,0
0,0,0,0,0,28,14,13,27,0,0,0,0,0
0,0,0,0,0,0,0,0,0,0,0,0,0,0
:endlayer
layer: 9
0,0,0,0,0,0,2,0,16,0,0,0,0,0
0,0,0,0,0,15,4,5,4,12,0,0,0,0
0,0,0,0,0,0,8,0,8,0,0,0,0,0
0,0,0,0,0,15,4,5,4,12,0,0,0,0
0,0,0,0,0,0,28,27,11,0,0,0,0,0
0,0,0,0,0,0,28,27,0,0,0,0,0,0
0,0,0,0,0,0,28,27,0,0,0,0,0,0
0,0,0,0,0,0,28,27,30,30,30,30,0,0
0,0,0,0,0,0,28,6,6,6,6,6,0,0
0,0,0,0,0,0,28,27,0,0,0,0,0,0
0,0,0,0,0,0,28,27,0,0,0,0,0,0
0,0,0,0,0,0,28,27,0,0,0,0,0,0
0,0,0,0,0,0,28,27,0,0,0,0,0,0
0,0,0,0,0,0,28,27,0,0,0,0,0,0
0,0,0,0,0,0,28,27,0,0,0,0,0,0
0,0,0,0,0,0,0,0,0,0,0,0,0,0
:endlayer
layer: 10
0,0,0,0,0,30,2,30,30,30,0,0,0,0
0,0,0,0,0,28,4,22,4,27,0,0,0,0
0,0,0,0,0,28,25,11,25,27,0,0,0,0
0,0,0,0,0,28,4,22,4,27,0,0,0,0
0,0,0,0,0,6,6,6,6,27,0,0,0,0
0,0,0,0,0,0,0,0,0,0,0,0,0,0
0,0,0,0,0,0,0,0,0,0,0,0,0,0
0,0,0,0,0,0,0,0,0,0,0,0,0,0
0,0,0,0,0,0,0,0,0,0,0,0,0,0
0,0,0,0,0,0,0,0,0,0,0,0,0,0
0,0,0,0,0,0,0,0,0,0,0,0,0,0
0,0,0,0,0,0,0,0,0,0,0,0,0,0
0,0,0,0,0,0,0,0,0,0,0,0,0,0
0,0,0,0,0,0,0,0,0,0,0,0,0,0
0,0,0,0,0,0,0,0,0,0,0,0,0,0
0,0,0,0,0,0,0,0,0,0,0,0,0,0
:endlayer
layer: 11
0,0,0,0,0,0,2,0,0,0,0,0,0,0
0,0,0,0,0,0,28,30,30,0,0,0,0,0
0,0,0,0,0,0,28,5,27,0,0,0,0,0
0,0,0,0,0,0,6,6,27,0,0,0,0,0
0,0,0,0,0,0,0,0,0,0,0,0,0,0
0,0,0,0,0,0,0,0,0,0,0,0,0,0
0,0,0,0,0,0,0,0,0,0,0,0,0,0
0,0,0,0,0,0,0,0,0,0,0,0,0,0
0,0,0,0,0,0,0,0,0,0,0,0,0,0
0,0,0,0,0,0,0,0,0,0,0,0,0,0
0,0,0,0,0,0,0,0,0,0,0,0,0,0
0,0,0,0,0,0,0,0,0,0,0,0,0,0
0,0,0,0,0,0,0,0,0,0,0,0,0,0
0,0,0,0,0,0,0,0,0,0,0,0,0,0
0,0,0,0,0,0,0,0,0,0,0,0,0,0
0,0,0,0,0,0,0,0,0,0,0,0,0,0
:endlayer
layer: 12
0,0,0,0,0,0,2,0,0,0,0,0,0,0
0,0,0,0,0,0,0,0,0,0,0,0,0,0
0,0,0,0,0,0,0,8,0,0,0,0,0,0
0,0,0,0,0,0,0,0,0,0,0,0,0,0
0,0,0,0,0,0,0,0,0,0,0,0,0,0
0,0,0,0,0,0,0,0,0,0,0,0,0,0
0,0,0,0,0,0,0,0,0,0,0,0,0,0
0,0,0,0,0,0,0,0,0,0,0,0,0,0
0,0,0,0,0,0,0,0,0,0,0,0,0,0
0,0,0,0,0,0,0,0,0,0,0,0,0,0
0,0,0,0,0,0,0,0,0,0,0,0,0,0
0,0,0,0,0,0,0,0,0,0,0,0,0,0
0,0,0,0,0,0,0,0,0,0,0,0,0,0
0,0,0,0,0,0,0,0,0,0,0,0,0,0
0,0,0,0,0,0,0,0,0,0,0,0,0,0
0,0,0,0,0,0,0,0,0,0,0,0,0,0
:endlayer
layer: 13
0,0,0,0,0,0,10,0,0,0,0,0,0,0
0,0,0,0,0,0,0,0,0,0,0,0,0,0
0,0,0,0,0,0,0,29,0,0,0,0,0,0
0,0,0,0,0,0,0,0,0,0,0,0,0,0
0,0,0,0,0,0,0,0,0,0,0,0,0,0
0,0,0,0,0,0,0,0,0,0,0,0,0,0
0,0,0,0,0,0,0,0,0,0,0,0,0,0
0,0,0,0,0,0,0,0,0,0,0,0,0,0
0,0,0,0,0,0,0,0,0,0,0,0,0,0
0,0,0,0,0,0,0,0,0,0,0,0,0,0
0,0,0,0,0,0,0,0,0,0,0,0,0,0
0,0,0,0,0,0,0,0,0,0,0,0,0,0
0,0,0,0,0,0,0,0,0,0,0,0,0,0
0,0,0,0,0,0,0,0,0,0,0,0,0,0
0,0,0,0,0,0,0,0,0,0,0,0,0,0
0,0,0,0,0,0,0,0,0,0,0,0,0,0
:endlayer
layer: 14
0,0,0,0,0,0,31,0,0,0,0,0,0,0
0,0,0,0,0,0,0,0,0,0,0,0,0,0
0,0,0,0,0,0,0,0,0,0,0,0,0,0
0,0,0,0,0,0,0,0,0,0,0,0,0,0
0,0,0,0,0,0,0,0,0,0,0,0,0,0
0,0,0,0,0,0,0,0,0,0,0,0,0,0
0,0,0,0,0,0,0,0,0,0,0,0,0,0
0,0,0,0,0,0,0,0,0,0,0,0,0,0
0,0,0,0,0,0,0,0,0,0,0,0,0,0
0,0,0,0,0,0,0,0,0,0,0,0,0,0
0,0,0,0,0,0,0,0,0,0,0,0,0,0
0,0,0,0,0,0,0,0,0,0,0,0,0,0
0,0,0,0,0,0,0,0,0,0,0,0,0,0
0,0,0,0,0,0,0,0,0,0,0,0,0,0
0,0,0,0,0,0,0,0,0,0,0,0,0,0
0,0,0,0,0,0,0,0,0,0,0,0,0,0
:endlayer

#### RULES ####
rule:
plugin=vanillaBlocks
number=1
data:
JSON:{blockState:{blockName:"minecraft:grass",properties:{snowy:"false"}}}
:enddata
:endrule

rule:
plugin=vanillaBlocks
number=2
data:
JSON:{blockState:{blockName:"minecraft:cobblestone"}}
:enddata
:endrule

rule:
plugin=vanillaBlocks
number=3
data:
JSON:{blockState:{blockName:"minecraft:stonebrick",properties:{variant:"stonebrick"}}}
:enddata
:endrule

rule:
plugin=vanillaBlocks
number=4
data:
JSON:{blockState:{blockName:"biomesoplenty:log_3",properties:{variant:ebony,axis:"y"}}}
:enddata
:endrule

rule:
plugin=vanillaBlocks
number=5
data:
JSON:{blockState:{blockName:"biomesoplenty:planks_0",properties:{variant:ebony}}}
:enddata
:endrule

rule:
plugin=vanillaBlocks
number=6
data:
JSON:{blockState:{blockName:"biomesoplenty:ebony_stairs",properties:{half:"bottom",shape:"straight",facing:"north"}}}
:enddata
:endrule

rule:
plugin=vanillaBlocks
number=7
data:
JSON:{blockState:{blockName:"biomesoplenty:ebony_stairs",properties:{half:"top",shape:"straight",facing:"south"}}}
:enddata
:endrule

rule:
plugin=vanillaBlocks
number=8
data:
JSON:{blockState:{blockName:"biomesoplenty:ebony_fence",properties:{east:"false",south:"false",north:"false",west:"false"}}}
:enddata
:endrule

rule:
plugin=vanillaBlocks
number=9
data:
JSON:{blockState:{blockName:"minecraft:stone_slab",properties:{half:"bottom",variant:"stone_brick"}}}
:enddata
:endrule

rule:
plugin=vanillaBlocks
number=10
data:
JSON:{blockState:{blockName:"minecraft:cobblestone_wall",properties:{east:"false",south:"false",north:"false",variant:"cobblestone",west:"false",up:"false"}}}
:enddata
:endrule

rule:
plugin=vanillaBlocks
number=11
data:
JSON:{blockState:{blockName:"minecraft:torch",properties:{facing:"south"}}}
:enddata
:endrule

rule:
plugin=vanillaBlocks
number=12
data:
JSON:{blockState:{blockName:"minecraft:torch",properties:{facing:"east"}}}
:enddata
:endrule

rule:
plugin=vanillaBlocks
number=13
data:
JSON:{blockState:{blockName:"biomesoplenty:ebony_stairs",properties:{half:"top",shape:"straight",facing:"east"}}}
:enddata
:endrule

rule:
plugin=vanillaBlocks
number=14
data:
JSON:{blockState:{blockName:"biomesoplenty:ebony_stairs",properties:{half:"top",shape:"straight",facing:"west"}}}
:enddata
:endrule

rule:
plugin=vanillaBlocks
number=15
data:
JSON:{blockState:{blockName:"minecraft:torch",properties:{facing:"west"}}}
:enddata
:endrule

rule:
plugin=vanillaBlocks
number=16
data:
JSON:{blockState:{blockName:"minecraft:torch",properties:{facing:"north"}}}
:enddata
:endrule

rule:
plugin=vanillaBlocks
number=17
data:
JSON:{blockState:{blockName:"biomesoplenty:ebony_stairs",properties:{half:"top",shape:"straight",facing:"north"}}}
:enddata
:endrule

rule:
plugin=vanillaBlocks
number=18
data:
JSON:{blockState:{blockName:"minecraft:stone_stairs",properties:{half:"bottom",shape:"straight",facing:"north"}}}
:enddata
:endrule

rule:
plugin=vanillaBlocks
number=19
data:
JSON:{blockState:{blockName:"minecraft:stone_brick_stairs",properties:{half:"top",shape:"straight",facing:"east"}}}
:enddata
:endrule

rule:
plugin=vanillaBlocks
number=20
data:
JSON:{blockState:{blockName:"minecraft:stone_slab",properties:{half:"top",variant:"stone"}}}
:enddata
:endrule

rule:
plugin=vanillaBlocks
number=21
data:
JSON:{blockState:{blockName:"minecraft:stone_brick_stairs",properties:{half:"top",shape:"straight",facing:"west"}}}
:enddata
:endrule

rule:
plugin=vanillaBlocks
number=22
data:
JSON:{blockState:{blockName:"biomesoplenty:log_3",properties:{variant:ebony,axis:"x"}}}
:enddata
:endrule

rule:
plugin=vanillaBlocks
number=23
data:
JSON:{blockState:{blockName:"biomesoplenty:wood_slab_1",properties:{half:"top",variant:"ebony"}}}
:enddata
:endrule

rule:
plugin=vanillaBlocks
number=24
data:
JSON:{blockState:{blockName:"biomesoplenty:wood_slab_1",properties:{half:"bottom",variant:"ebony"}}}
:enddata
:endrule

rule:
plugin=vanillaBlocks
number=25
data:
JSON:{blockState:{blockName:"biomesoplenty:log_3",properties:{variant:ebony,axis:"z"}}}
:enddata
:endrule

rule:
plugin=vanillaBlocks
number=26
data:
JSON:{blockState:{blockName:"minecraft:stone_stairs",properties:{half:"bottom",shape:"straight",facing:"south"}}}
:enddata
:endrule

rule:
plugin=vanillaBlocks
number=27
data:
JSON:{blockState:{blockName:"biomesoplenty:ebony_stairs",properties:{half:"bottom",shape:"straight",facing:"west"}}}
:enddata
:endrule

rule:
plugin=vanillaBlocks
number=28
data:
JSON:{blockState:{blockName:"biomesoplenty:ebony_stairs",properties:{half:"bottom",shape:"straight",facing:"east"}}}
:enddata
:endrule

rule:
plugin=vanillaBlocks
number=29
data:
JSON:{blockState:{blockName:"minecraft:torch",properties:{facing:"up"}}}
:enddata
:endrule

rule:
plugin=vanillaBlocks
number=30
data:
JSON:{blockState:{blockName:"biomesoplenty:ebony_stairs",properties:{half:"bottom",shape:"straight",facing:"south"}}}
:enddata
:endrule

rule:
plugin=vanillaBlocks
number=31
data:
JSON:{blockState:{blockName:"minecraft:stone_slab",properties:{half:"bottom",variant:"stone"}}}
:enddata
:endrule

#### ENTITIES ####
